Workbook

Sheet 数据来源
B1: 精度：全国
B3: 人口与总建面均来自世行模型
B4: 注1:2014 2015数据缺失，暂时按2016数据填入
B5: 注2:农村住宅年增长率按1.003考虑，同城镇住宅增长率
B7: https://www.docin.com/p-1660623922.html 家电价格来源 家用电器期刊 2015年7月主要家用电器产品前10名型号价格变动分析
B9: 人均家电拥有量来源 国家统计年鉴
B11: 住宅供暖设备安装费用来源 齐鲁网报道 济南出台水、电、暖、气配套工程安装收费标准
B12: http://news.iqilu.com/shandong/shandonggedi/20111028/1031974.shtml
B14: 住宅照明设备安装费用来源 原创力文档 照明工程设计收费标准
B15: https://max.book118.com/html/2019/0419/8115050126002017.shtm
B17: 公建其他组件来源 共享赵丽雅文件夹
B19: 每年新建建筑来源：中国房地产统计年鉴（房地产数据，算城市）
B20: 住宅总竣工面积（城市+农村）来源：山东统计年鉴

Sheet 人口源表
A1: City | C1: 2016城镇化率 | D1: 2016 | E1: 2017 | F1: 2018 | G1: 2019 | H1: 2020 | I1: 2021 | J1: 2022 | K1: 2023 | L1: 2024 | M1: 2025 | N1: 2026 | O1: 2027 | P1: 2028 | Q1: 2029 | R1: 2030 | S1: 2031 | T1: 2032 | U1: 2033 | V1: 2034 | W1: 2035 | X1: 2036 | Y1: 2037 | Z1: 2038 | AA1: 2039 | AB1: 2040 | AC1: 2041 | AD1: 2042 | AE1: 2043 | AF1: 2044 | AG1: 2045 | AH1: 2046 | AI1: 2047 | AJ1: 2048 | AK1: 2049 | AL1: 2050 | AM1: 2051 | AN1: 2052 | AO1: 2053 | AP1: 2054 | AQ1: 2055 | AR1: 2056 | AS1: 2057 | AT1: 2058 | AU1: 2059 | AV1: 2060
A2: 北京市 | B2: 北京 | C2: 87.86 | D2: 20876818 | E2: 21043312 | F2: 21192712 | G2: 21641222 | H2: 21891193 | I2: 22092349 | J2: 22249167 | K2: 22365919 | L2: 22446671 | M2: 22495287 | N2: 22515425 | O2: 22510539 | P2: 22483879 | Q2: 22438490 | R2: 22377211 | S2: 22302681 | T2: 22217329 | U2: 22123385 | V2: 22022870 | W2: 21917603 | X2: 21809199 | Y2: 21699066 | Z2: 21588410 | AA2: 21478232 | AB2: 21369328 | AC2: 21262290 | AD2: 21157505 | AE2: 21055156 | AF2: 20955222 | AG2: 20857477 | AH2: 20761490 | AI2: 20666628 | AJ2: 20572049 | AK2: 20476712 | AL2: 20379368 | AM2: 20278564 | AN2: 20172643 | AO2: 20059744 | AP2: 19937802 | AQ2: 19804545 | AR2: 19657500 | AS2: 19493987 | AT2: 19311122 | AU2: 19105817 | AV2: 18874781
A3: 天津市 | B3: 天津 | C3: 84.29 | D3: 13567334 | E3: 13653977 | F3: 13732217 | G3: 13739203 | H3: 13864934 | I3: 13965579 | J3: 14043199 | K3: 14099770 | L3: 14137179 | M3: 14157227 | N3: 14161631 | O3: 14152018 | P3: 14129932 | Q3: 14096828 | R3: 14054075 | S3: 14002956 | T3: 13944668 | U3: 13880322 | V3: 13810939 | W3: 13737458 | X3: 13660729 | Y3: 13581517 | Z3: 13500498 | AA3: 13418265 | AB3: 13335323 | AC3: 13252088 | AD3: 13168894 | AE3: 13085986 | AF3: 13003523 | AG3: 12921577 | AH3: 12840135 | AI3: 12759095 | AJ3: 12678272 | AK3: 12597391 | AL3: 12516094 | AM3: 12433933 | AN3: 12350377 | AO3: 12264805 | AP3: 12176513 | AQ3: 12084708 | AR3: 11988512 | AS3: 11886960 | AT3: 11779000 | AU3: 11663494 | AV3: 11539219
A4: 石家庄市 | B4: 石家庄 | C4: 58.346 | D4: 10686651 | E4: 10759180 | F4: 10826289 | G4: 11135097 | H4: 11234139 | I4: 11322464 | J4: 11400612 | K4: 11469108 | L4: 11528463 | M4: 11579176 | N4: 11621729 | O4: 11656594 | P4: 11684227 | Q4: 11705069 | R4: 11719549 | S4: 11728082 | T4: 11731069 | U4: 11728896 | V4: 11721937 | W4: 11710551 | X4: 11695084 | Y4: 11675867 | Z4: 11653217 | AA4: 11627439 | AB4: 11598822 | AC4: 11567644 | AD4: 11534165 | AE4: 11498636 | AF4: 11461289 | AG4: 11422347 | AH4: 11382015 | AI4: 11340488 | AJ4: 11297944 | AK4: 11254549 | AL4: 11210455 | AM4: 11165798 | AN4: 11120704 | AO4: 11075281 | AP4: 11029627 | AQ4: 10983823 | AR4: 10937938 | AS4: 10892027 | AT4: 10846130 | AU4: 10800274 | AV4: 10754473
A5: 唐山市 | B5: 唐山 | C5: 55.68 | D5: 7874731.2 | E5: 7909764 | F5: 7940411.9 | G5: 7678887 | H5: 7717136 | I5: 7749822 | J5: 7777124 | K5: 7799223 | L5: 7816298 | M5: 7828530 | N5: 7836100 | O5: 7839190 | P5: 7837984 | Q5: 7832663 | R5: 7823411 | S5: 7810414 | T5: 7793854 | U5: 7773918 | V5: 7750791 | W5: 7724660 | X5: 7695713 | Y5: 7664135 | Z5: 7630116 | AA5: 7593844 | AB5: 7555509 | AC5: 7515300 | AD5: 7473408 | AE5: 7430023 | AF5: 7385337 | AG5: 7339543 | AH5: 7292832 | AI5: 7245399 | AJ5: 7197436 | AK5: 7149139 | AL5: 7100701 | AM5: 7052320 | AN5: 7004189 | AO5: 6956507 | AP5: 6909471 | AQ5: 6863277 | AR5: 6818125 | AS5: 6774213 | AT5: 6731741 | AU5: 6690909 | AV5: 6651916
A6: 秦皇岛市 | B6: 秦皇岛 | C6: 55.68 | D6: 3106235 | E6: 3121107.7 | F6: 3134335.6 | G6: 3118115 | H6: 3136546 | I6: 3152301 | J6: 3165496 | K6: 3176243 | L6: 3184654 | M6: 3190839 | N6: 3194906 | O6: 3196962 | P6: 3197112 | Q6: 3195459 | R6: 3192105 | S6: 3187150 | T6: 3180692 | U6: 3172828 | V6: 3163652 | W6: 3153260 | X6: 3141741 | Y6: 3129187 | Z6: 3115685 | AA6: 3101323 | AB6: 3086185 | AC6: 3070356 | AD6: 3053917 | AE6: 3036948 | AF6: 3019527 | AG6: 3001732 | AH6: 2983639 | AI6: 2965319 | AJ6: 2946846 | AK6: 2928290 | AL6: 2909719 | AM6: 2891201 | AN6: 2872800 | AO6: 2854581 | AP6: 2836605 | AQ6: 2818933 | AR6: 2801623 | AS6: 2784733 | AT6: 2768318 | AU6: 2752432 | AV6: 2737126
A7: 邯郸市 | B7: 邯郸 | C7: 55.68 | D7: 9673167.1 | E7: 9731065.4 | F7: 9783611.7 | G7: 9366372 | H7: 9413329 | I7: 9462180 | J7: 9512262 | K7: 9562952 | L7: 9613662 | M7: 9663844 | N7: 9712987 | O7: 9760617 | P7: 9806298 | Q7: 9849633 | R7: 9890260 | S7: 9927857 | T7: 9962140 | U7: 9992860 | V7: 10019810 | W7: 10042816 | X7: 10061745 | Y7: 10076500 | Z7: 10087024 | AA7: 10093294 | AB7: 10095328 | AC7: 10093180 | AD7: 10086943 | AE7: 10076746 | AF7: 10062758 | AG7: 10045183 | AH7: 10024266 | AI7: 10000285 | AJ7: 9973561 | AK7: 9944450 | AL7: 9913345 | AM7: 9880678 | AN7: 9846919 | AO7: 9812575 | AP7: 9778191 | AQ7: 9744349 | AR7: 9711669 | AS7: 9680811 | AT7: 9652468 | AU7: 9627376 | AV7: 9606304
A8: 邢台市 | B8: 邢台 | C8: 55.68 | D8: 7482383 | E8: 7531475.8 | F8: 7576754.7 | G8: 7058880 | H8: 7110576 | I8: 7159488 | J8: 7205534 | K8: 7248644 | L8: 7288757 | M8: 7325823 | N8: 7359802 | O8: 7390663 | P8: 7418388 | Q8: 7442968 | R8: 7464404 | S8: 7482708 | T8: 7497902 | U8: 7510018 | V8: 7519098 | W8: 7525196 | X8: 7528375 | Y8: 7528709 | Z8: 7526282 | AA8: 7521187 | AB8: 7513531 | AC8: 7503427 | AD8: 7491001 | AE8: 7476388 | AF8: 7459735 | AG8: 7441198 | AH8: 7420943 | AI8: 7399148 | AJ8: 7376000 | AK8: 7351696 | AL8: 7326444 | AM8: 7300463 | AN8: 7273981 | AO8: 7247237 | AP8: 7220481 | AQ8: 7193972 | AR8: 7167980 | AS8: 7142785 | AT8: 7118678 | AU8: 7095960 | AV8: 7074941
A9: 保定市 | B9: 保定 | C9: 58.346 | D9: 11726942 | E9: 11792754 | F9: 11852313 | G9: 11475860 | H9: 11542974 | I9: 11605691 | J9: 11663886 | K9: 11717453 | L9: 11766300 | M9: 11810353 | N9: 11849553 | O9: 11883859 | P9: 11913244 | Q9: 11937700 | R9: 11957233 | S9: 11971868 | T9: 11981643 | U9: 11986615 | V9: 11986856 | W9: 11982455 | X9: 11973518 | Y9: 11960165 | Z9: 11942535 | AA9: 11920781 | AB9: 11895075 | AC9: 11865602 | AD9: 11832567 | AE9: 11796189 | AF9: 11756704 | AG9: 11714363 | AH9: 11669436 | AI9: 11622207 | AJ9: 11572979 | AK9: 11522067 | AL9: 11469807 | AM9: 11416549 | AN9: 11362659 | AO9: 11308520 | AP9: 11254532 | AQ9: 11201110 | AR9: 11148687 | AS9: 11097710 | AT9: 11048645 | AU9: 11001973 | AV9: 10958191
A10: 张家口市 | B10: 张家口 | C10: 50.348 | D10: 4466424.4 | E10: 4479270 | F10: 4490122.7 | G10: 4107476 | H10: 4118494 | I10: 4128506 | J10: 4137368 | K10: 4144948 | L10: 4151128 | M10: 4155802 | N10: 4158876 | O10: 4160270 | P10: 4159916 | Q10: 4157759 | R10: 4153756 | S10: 4147879 | T10: 4140110 | U10: 4130445 | V10: 4118892 | W10: 4105474 | X10: 4090223 | Y10: 4073187 | Z10: 4054425 | AA10: 4034009 | AB10: 4012024 | AC10: 3988568 | AD10: 3963751 | AE10: 3937696 | AF10: 3910540 | AG10: 3882430 | AH10: 3853528 | AI10: 3824008 | AJ10: 3794056 | AK10: 3763873 | AL10: 3733669 | AM10: 3703671 | AN10: 3674116 | AO10: 3645253 | AP10: 3617347 | AQ10: 3590673 | AR10: 3565519 | AS10: 3542188 | AT10: 3520991 | AU10: 3502258 | AV10: 3486326
A11: 承德市 | B11: 承德 | C11: 50.348 | D11: 3599572.4 | E11: 3613787.7 | F11: 3626369.1 | G11: 3341797 | H11: 3354153 | I11: 3366260 | J11: 3377932 | K11: 3388991 | L11: 3399277 | M11: 3408640 | N11: 3416946 | O11: 3424074 | P11: 3429915 | Q11: 3434376 | R11: 3437374 | S11: 3438844 | T11: 3438731 | U11: 3436994 | V11: 3433608 | W11: 3428558 | X11: 3421844 | Y11: 3413481 | Z11: 3403495 | AA11: 3391928 | AB11: 3378833 | AC11: 3364277 | AD11: 3348343 | AE11: 3331125 | AF11: 3312731 | AG11: 3293283 | AH11: 3272915 | AI11: 3251777 | AJ11: 3230032 | AK11: 3207853 | AL11: 3185432 | AM11: 3162970 | AN11: 3140684 | AO11: 3118803 | AP11: 3097571 | AQ11: 3077245 | AR11: 3058094 | AS11: 3040403 | AT11: 3024468 | AU11: 3010602 | AV11: 2999127
A12: 沧州市 | B12: 沧州 | C12: 55.68 | D12: 7456414.9 | E12: 7494078.1 | F12: 7527827.4 | G12: 7266521 | H12: 7300129 | I12: 7332887 | J12: 7364507 | K12: 7394719 | L12: 7423274 | M12: 7449946 | N12: 7474526 | O12: 7496828 | P12: 7516685 | Q12: 7533952 | R12: 7548503 | S12: 7560233 | T12: 7569060 | U12: 7574918 | V12: 7577765 | W12: 7577579 | X12: 7574358 | Y12: 7568120 | Z12: 7558904 | AA12: 7546770 | AB12: 7531799 | AC12: 7514091 | AD12: 7493768 | AE12: 7470971 | AF12: 7445863 | AG12: 7418628 | AH12: 7389467 | AI12: 7358607 | AJ12: 7326291 | AK12: 7292785 | AL12: 7258374 | AM12: 7223364 | AN12: 7188084 | AO12: 7152879 | AP12: 7118118 | AQ12: 7084189 | AR12: 7051502 | AS12: 7020485 | AT12: 6991590 | AU12: 6965287 | AV12: 6942067
A13: 廊坊市 | B13: 廊坊 | C13: 58.346 | D13: 4593015.8 | E13: 4625006.9 | F13: 4654532.2 | G13: 5414885 | H13: 5463661 | I13: 5507146 | J13: 5545612 | K13: 5579322 | L13: 5608534 | M13: 5633497 | N13: 5654453 | O13: 5671636 | P13: 5685274 | Q13: 5695585 | R13: 5702781 | S13: 5707067 | T13: 5708639 | U13: 5707688 | V13: 5704394 | W13: 5698931 | X13: 5691468 | Y13: 5682163 | Z13: 5671168 | AA13: 5658627 | AB13: 5644677 | AC13: 5629447 | AD13: 5613060 | AE13: 5595629 | AF13: 5577261 | AG13: 5558056 | AH13: 5538104 | AI13: 5517492 | AJ13: 5496295 | AK13: 5474582 | AL13: 5452416 | AM13: 5429850 | AN13: 5406932 | AO13: 5383701 | AP13: 5360187 | AQ13: 5336417 | AR13: 5312406 | AS13: 5288163 | AT13: 5263691 | AU13: 5238983 | AV13: 5214027
... A368: 胡杨河市 | B368: 胡杨河 | C368: 69.322783 | D368: 84392.012 | E368: 84943.323 | F368: 85454.48 | G368: 247189 | H368: 248110 | I368: 248922 | J368: 249616 | K368: 250186 | L368: 250624 | M368: 250926 | N368: 251084 | O368: 251097 | P368: 250960 | Q368: 250671 | R368: 250228 | S368: 249630 | T368: 248878 | U368: 247972 | V368: 246914 | W368: 245707 | X368: 244354 | Y368: 242859 | Z368: 241228 | AA368: 239465 | AB368: 237579 | AC368: 235577 | AD368: 233467 | AE368: 231258 | AF368: 228960 | AG368: 226586 | AH368: 224145 | AI368: 221651 | AJ368: 219118 | AK368: 216559 | AL368: 213991 | AM368: 211428 | AN368: 208888 | AO368: 206389 | AP368: 203948 | AQ368: 201586 | AR368: 199322 | AS368: 197178 | AT368: 195175 | AU368: 193336 | AV368: 191685
A369: sum | D369: 1.3860024e+09 | E369: 1.3934428e+09 | F369: 1.4003134e+09 | G369: 1400793135 | H369: 1410976903 | I369: 1420266066 | J369: 1428670957 | K369: 1436203098 | L369: 1442875150 | M369: 1448701015 | N369: 1453695689 | O369: 1457875428 | P369: 1461257603 | Q369: 1463860785 | R369: 1465704725 | S369: 1466810320 | T369: 1467199701 | U369: 1466896114 | V369: 1465924022 | W369: 1464309042 | X369: 1462077972 | Y369: 1459258813 | Z369: 1455880691 | AA369: 1451973938 | AB369: 1447570066 | AC369: 1442701773 | AD369: 1437402901 | AE369: 1431708470 | AF369: 1425654722 | AG369: 1419279033 | AH369: 1412619937 | AI369: 1405717218 | AJ369: 1398611771 | AK369: 1391345677 | AL369: 1383962233 | AM369: 1376505845 | AN369: 1369022176 | AO369: 1361557975 | AP369: 1354161244 | AQ369: 1346881133 | AR369: 1339767961 | AS369: 1332873221 | AT369: 1326249585 | AU369: 1319950938 | AV369: 1314032289

Sheet 城镇化率
D1: 城镇化微调系数
D2: 16-20增速 | E2: 20-30增速 | F2: 30-40 | G2: 40-60
D3: =POWER(0.639/0.588,1/4)-0.004 -> 1.0170121 | E3: 1.01 | F3: 1.005 | G3: =POWER(0.8/0.742,1/20) -> 1.0037702
A5: City | C5: 2016城镇化率 | D5: 2016 | E5: 2017 | F5: 2018 | G5: 2019 | H5: 2020 | I5: 2021 | J5: 2022 | K5: 2023 | L5: 2024 | M5: 2025 | N5: 2026 | O5: 2027 | P5: 2028 | Q5: 2029 | R5: 2030 | S5: 2031 | T5: 2032 | U5: 2033 | V5: 2034 | W5: 2035 | X5: 2036 | Y5: 2037 | Z5: 2038 | AA5: 2039 | AB5: 2040 | AC5: 2041 | AD5: 2042 | AE5: 2043 | AF5: 2044 | AG5: 2045 | AH5: 2046 | AI5: 2047 | AJ5: 2048 | AK5: 2049 | AL5: 2050 | AM5: 2051 | AN5: 2052 | AO5: 2053 | AP5: 2054 | AQ5: 2055 | AR5: 2056 | AS5: 2057 | AT5: 2058 | AU5: 2059 | AV5: 2060
A6: 北京市 | B6: 北京 | C6: 87.86 | D6: =C6 -> 87.86 | E6: =IF($C6*$D$3^(E$5-$D$5)<100,$C6*$D$3^(E$5-$D$5),100) -> 89.354682 | F6: =IF($C6*$D$3^(F$5-$D$5)<100,$C6*$D$3^(F$5-$D$5),100) -> 90.874791 | G6: =IF($C6*$D$3^(G$5-$D$5)<100,$C6*$D$3^(G$5-$D$5),100) -> 92.420761 | H6: =IF($C6*$D$3^(H$5-$D$5)<100,$C6*$D$3^(H$5-$D$5),100) -> 93.993031 | I6: =IF($H6*$E$3^(I$5-$H$5)<100,$H6*$E$3^(I$5-$H$5),100) -> 94.932961 | J6: =IF($H6*$E$3^(J$5-$H$5)<100,$H6*$E$3^(J$5-$H$5),100) -> 95.882291 | K6: =IF($H6*$E$3^(K$5-$H$5)<100,$H6*$E$3^(K$5-$H$5),100) -> 96.841114 | L6: =IF($H6*$E$3^(L$5-$H$5)<100,$H6*$E$3^(L$5-$H$5),100) -> 97.809525 | M6: =IF($H6*$E$3^(M$5-$H$5)<100,$H6*$E$3^(M$5-$H$5),100) -> 98.78762 | N6: =IF($H6*$E$3^(N$5-$H$5)<100,$H6*$E$3^(N$5-$H$5),100) -> 99.775497 | O6: =IF($H6*$E$3^(O$5-$H$5)<100,$H6*$E$3^(O$5-$H$5),100) -> 100 | P6: =IF($H6*$E$3^(P$5-$H$5)<100,$H6*$E$3^(P$5-$H$5),100) -> 100 | ... R6: =IF($H6*$E$3^(R$5-$H$5)<100,$H6*$E$3^(R$5-$H$5),100) -> 100 | S6: =IF($R6*$F$3^(S$5-$R$5)<100,$R6*$F$3^(S$5-$R$5),100) -> 100 | T6: =IF($R6*$F$3^(T$5-$R$5)<100,$R6*$F$3^(T$5-$R$5),100) -> 100 | U6: =IF($R6*$F$3^(U$5-$R$5)<100,$R6*$F$3^(U$5-$R$5),100) -> 100 | V6: =IF($R6*$F$3^(V$5-$R$5)<100,$R6*$F$3^(V$5-$R$5),100) -> 100 | W6: =IF($R6*$F$3^(W$5-$R$5)<100,$R6*$F$3^(W$5-$R$5),100) -> 100 | X6: =IF($R6*$F$3^(X$5-$R$5)<100,$R6*$F$3^(X$5-$R$5),100) -> 100 | Y6: =IF($R6*$F$3^(Y$5-$R$5)<100,$R6*$F$3^(Y$5-$R$5),100) -> 100 | Z6: =IF($R6*$F$3^(Z$5-$R$5)<100,$R6*$F$3^(Z$5-$R$5),100) -> 100 | ... AB6: =IF($R6*$F$3^(AB$5-$R$5)<100,$R6*$F$3^(AB$5-$R$5),100) -> 100 | AC6: =IF($AB6*$G$3^(AC$5-$AB$5)<100,$AB6*$G$3^(AC$5-$AB$5),100) -> 100 | AD6: =IF($AB6*$G$3^(AD$5-$AB$5)<100,$AB6*$G$3^(AD$5-$AB$5),100) -> 100 | AE6: =IF($AB6*$G$3^(AE$5-$AB$5)<100,$AB6*$G$3^(AE$5-$AB$5),100) -> 100 | AF6: =IF($AB6*$G$3^(AF$5-$AB$5)<100,$AB6*$G$3^(AF$5-$AB$5),100) -> 100 | AG6: =IF($AB6*$G$3^(AG$5-$AB$5)<100,$AB6*$G$3^(AG$5-$AB$5),100) -> 100 | AH6: =IF($AB6*$G$3^(AH$5-$AB$5)<100,$AB6*$G$3^(AH$5-$AB$5),100) -> 100 | AI6: =IF($AB6*$G$3^(AI$5-$AB$5)<100,$AB6*$G$3^(AI$5-$AB$5),100) -> 100 | AJ6: =IF($AB6*$G$3^(AJ$5-$AB$5)<100,$AB6*$G$3^(AJ$5-$AB$5),100) -> 100 | ... AV6: =IF($AB6*$G$3^(AV$5-$AB$5)<100,$AB6*$G$3^(AV$5-$AB$5),100) -> 100
A7: 天津市 | B7: 天津 | C7: 84.29 | D7: =C7 -> 84.29 | E7: =IF($C7*$D$3^(E$5-$D$5)<100,$C7*$D$3^(E$5-$D$5),100) -> 85.723949 | F7: =IF($C7*$D$3^(F$5-$D$5)<100,$C7*$D$3^(F$5-$D$5),100) -> 87.182292 | G7: =IF($C7*$D$3^(G$5-$D$5)<100,$C7*$D$3^(G$5-$D$5),100) -> 88.665445 | H7: =IF($C7*$D$3^(H$5-$D$5)<100,$C7*$D$3^(H$5-$D$5),100) -> 90.173829 | I7: =IF($H7*$E$3^(I$5-$H$5)<100,$H7*$E$3^(I$5-$H$5),100) -> 91.075567 | J7: =IF($H7*$E$3^(J$5-$H$5)<100,$H7*$E$3^(J$5-$H$5),100) -> 91.986323 | K7: =IF($H7*$E$3^(K$5-$H$5)<100,$H7*$E$3^(K$5-$H$5),100) -> 92.906186 | L7: =IF($H7*$E$3^(L$5-$H$5)<100,$H7*$E$3^(L$5-$H$5),100) -> 93.835248 | M7: =IF($H7*$E$3^(M$5-$H$5)<100,$H7*$E$3^(M$5-$H$5),100) -> 94.7736 | N7: =IF($H7*$E$3^(N$5-$H$5)<100,$H7*$E$3^(N$5-$H$5),100) -> 95.721336 | O7: =IF($H7*$E$3^(O$5-$H$5)<100,$H7*$E$3^(O$5-$H$5),100) -> 96.67855 | P7: =IF($H7*$E$3^(P$5-$H$5)<100,$H7*$E$3^(P$5-$H$5),100) -> 97.645335 | ... R7: =IF($H7*$E$3^(R$5-$H$5)<100,$H7*$E$3^(R$5-$H$5),100) -> 99.608006 | S7: =IF($R7*$F$3^(S$5-$R$5)<100,$R7*$F$3^(S$5-$R$5),100) -> 100 | T7: =IF($R7*$F$3^(T$5-$R$5)<100,$R7*$F$3^(T$5-$R$5),100) -> 100 | U7: =IF($R7*$F$3^(U$5-$R$5)<100,$R7*$F$3^(U$5-$R$5),100) -> 100 | V7: =IF($R7*$F$3^(V$5-$R$5)<100,$R7*$F$3^(V$5-$R$5),100) -> 100 | W7: =IF($R7*$F$3^(W$5-$R$5)<100,$R7*$F$3^(W$5-$R$5),100) -> 100 | X7: =IF($R7*$F$3^(X$5-$R$5)<100,$R7*$F$3^(X$5-$R$5),100) -> 100 | Y7: =IF($R7*$F$3^(Y$5-$R$5)<100,$R7*$F$3^(Y$5-$R$5),100) -> 100 | Z7: =IF($R7*$F$3^(Z$5-$R$5)<100,$R7*$F$3^(Z$5-$R$5),100) -> 100 | ... AB7: =IF($R7*$F$3^(AB$5-$R$5)<100,$R7*$F$3^(AB$5-$R$5),100) -> 100 | AC7: =IF($AB7*$G$3^(AC$5-$AB$5)<100,$AB7*$G$3^(AC$5-$AB$5),100) -> 100 | AD7: =IF($AB7*$G$3^(AD$5-$AB$5)<100,$AB7*$G$3^(AD$5-$AB$5),100) -> 100 | AE7: =IF($AB7*$G$3^(AE$5-$AB$5)<100,$AB7*$G$3^(AE$5-$AB$5),100) -> 100 | AF7: =IF($AB7*$G$3^(AF$5-$AB$5)<100,$AB7*$G$3^(AF$5-$AB$5),100) -> 100 | AG7: =IF($AB7*$G$3^(AG$5-$AB$5)<100,$AB7*$G$3^(AG$5-$AB$5),100) -> 100 | AH7: =IF($AB7*$G$3^(AH$5-$AB$5)<100,$AB7*$G$3^(AH$5-$AB$5),100) -> 100 | AI7: =IF($AB7*$G$3^(AI$5-$AB$5)<100,$AB7*$G$3^(AI$5-$AB$5),100) -> 100 | AJ7: =IF($AB7*$G$3^(AJ$5-$AB$5)<100,$AB7*$G$3^(AJ$5-$AB$5),100) -> 100 | ... AV7: =IF($AB7*$G$3^(AV$5-$AB$5)<100,$AB7*$G$3^(AV$5-$AB$5),100) -> 100
A8: 石家庄市 | B8: 石家庄 | C8: 58.346 | D8: =C8 -> 58.346 | E8: =IF($C8*$D$3^(E$5-$D$5)<100,$C8*$D$3^(E$5-$D$5),100) -> 59.338587 | F8: =IF($C8*$D$3^(F$5-$D$5)<100,$C8*$D$3^(F$5-$D$5),100) -> 60.34806 | G8: =IF($C8*$D$3^(G$5-$D$5)<100,$C8*$D$3^(G$5-$D$5),100) -> 61.374707 | H8: =IF($C8*$D$3^(H$5-$D$5)<100,$C8*$D$3^(H$5-$D$5),100) -> 62.418819 | I8: =IF($H8*$E$3^(I$5-$H$5)<100,$H8*$E$3^(I$5-$H$5),100) -> 63.043007 | J8: =IF($H8*$E$3^(J$5-$H$5)<100,$H8*$E$3^(J$5-$H$5),100) -> 63.673437 | K8: =IF($H8*$E$3^(K$5-$H$5)<100,$H8*$E$3^(K$5-$H$5),100) -> 64.310171 | L8: =IF($H8*$E$3^(L$5-$H$5)<100,$H8*$E$3^(L$5-$H$5),100) -> 64.953273 | M8: =IF($H8*$E$3^(M$5-$H$5)<100,$H8*$E$3^(M$5-$H$5),100) -> 65.602806 | N8: =IF($H8*$E$3^(N$5-$H$5)<100,$H8*$E$3^(N$5-$H$5),100) -> 66.258834 | O8: =IF($H8*$E$3^(O$5-$H$5)<100,$H8*$E$3^(O$5-$H$5),100) -> 66.921422 | P8: =IF($H8*$E$3^(P$5-$H$5)<100,$H8*$E$3^(P$5-$H$5),100) -> 67.590636 | ... R8: =IF($H8*$E$3^(R$5-$H$5)<100,$H8*$E$3^(R$5-$H$5),100) -> 68.949208 | S8: =IF($R8*$F$3^(S$5-$R$5)<100,$R8*$F$3^(S$5-$R$5),100) -> 69.293954 | T8: =IF($R8*$F$3^(T$5-$R$5)<100,$R8*$F$3^(T$5-$R$5),100) -> 69.640424 | U8: =IF($R8*$F$3^(U$5-$R$5)<100,$R8*$F$3^(U$5-$R$5),100) -> 69.988626 | V8: =IF($R8*$F$3^(V$5-$R$5)<100,$R8*$F$3^(V$5-$R$5),100) -> 70.338569 | W8: =IF($R8*$F$3^(W$5-$R$5)<100,$R8*$F$3^(W$5-$R$5),100) -> 70.690262 | X8: =IF($R8*$F$3^(X$5-$R$5)<100,$R8*$F$3^(X$5-$R$5),100) -> 71.043713 | Y8: =IF($R8*$F$3^(Y$5-$R$5)<100,$R8*$F$3^(Y$5-$R$5),100) -> 71.398932 | Z8: =IF($R8*$F$3^(Z$5-$R$5)<100,$R8*$F$3^(Z$5-$R$5),100) -> 71.755926 | ... AB8: =IF($R8*$F$3^(AB$5-$R$5)<100,$R8*$F$3^(AB$5-$R$5),100) -> 72.47528 | AC8: =IF($AB8*$G$3^(AC$5-$AB$5)<100,$AB8*$G$3^(AC$5-$AB$5),100) -> 72.748527 | AD8: =IF($AB8*$G$3^(AD$5-$AB$5)<100,$AB8*$G$3^(AD$5-$AB$5),100) -> 73.022804 | AE8: =IF($AB8*$G$3^(AE$5-$AB$5)<100,$AB8*$G$3^(AE$5-$AB$5),100) -> 73.298116 | AF8: =IF($AB8*$G$3^(AF$5-$AB$5)<100,$AB8*$G$3^(AF$5-$AB$5),100) -> 73.574465 | AG8: =IF($AB8*$G$3^(AG$5-$AB$5)<100,$AB8*$G$3^(AG$5-$AB$5),100) -> 73.851857 | AH8: =IF($AB8*$G$3^(AH$5-$AB$5)<100,$AB8*$G$3^(AH$5-$AB$5),100) -> 74.130294 | AI8: =IF($AB8*$G$3^(AI$5-$AB$5)<100,$AB8*$G$3^(AI$5-$AB$5),100) -> 74.409781 | AJ8: =IF($AB8*$G$3^(AJ$5-$AB$5)<100,$AB8*$G$3^(AJ$5-$AB$5),100) -> 74.690322 | ... AV8: =IF($AB8*$G$3^(AV$5-$AB$5)<100,$AB8*$G$3^(AV$5-$AB$5),100) -> 78.140463
A9: 唐山市 | B9: 唐山 | C9: 55.68 | D9: =C9 -> 55.68 | E9: =IF($C9*$D$3^(E$5-$D$5)<100,$C9*$D$3^(E$5-$D$5),100) -> 56.627233 | F9: =IF($C9*$D$3^(F$5-$D$5)<100,$C9*$D$3^(F$5-$D$5),100) -> 57.59058 | G9: =IF($C9*$D$3^(G$5-$D$5)<100,$C9*$D$3^(G$5-$D$5),100) -> 58.570316 | H9: =IF($C9*$D$3^(H$5-$D$5)<100,$C9*$D$3^(H$5-$D$5),100) -> 59.566719 | I9: =IF($H9*$E$3^(I$5-$H$5)<100,$H9*$E$3^(I$5-$H$5),100) -> 60.162387 | J9: =IF($H9*$E$3^(J$5-$H$5)<100,$H9*$E$3^(J$5-$H$5),100) -> 60.764011 | K9: =IF($H9*$E$3^(K$5-$H$5)<100,$H9*$E$3^(K$5-$H$5),100) -> 61.371651 | L9: =IF($H9*$E$3^(L$5-$H$5)<100,$H9*$E$3^(L$5-$H$5),100) -> 61.985367 | M9: =IF($H9*$E$3^(M$5-$H$5)<100,$H9*$E$3^(M$5-$H$5),100) -> 62.605221 | N9: =IF($H9*$E$3^(N$5-$H$5)<100,$H9*$E$3^(N$5-$H$5),100) -> 63.231273 | O9: =IF($H9*$E$3^(O$5-$H$5)<100,$H9*$E$3^(O$5-$H$5),100) -> 63.863586 | P9: =IF($H9*$E$3^(P$5-$H$5)<100,$H9*$E$3^(P$5-$H$5),100) -> 64.502222 | ... R9: =IF($H9*$E$3^(R$5-$H$5)<100,$H9*$E$3^(R$5-$H$5),100) -> 65.798716 | S9: =IF($R9*$F$3^(S$5-$R$5)<100,$R9*$F$3^(S$5-$R$5),100) -> 66.12771 | T9: =IF($R9*$F$3^(T$5-$R$5)<100,$R9*$F$3^(T$5-$R$5),100) -> 66.458348 | U9: =IF($R9*$F$3^(U$5-$R$5)<100,$R9*$F$3^(U$5-$R$5),100) -> 66.79064 | V9: =IF($R9*$F$3^(V$5-$R$5)<100,$R9*$F$3^(V$5-$R$5),100) -> 67.124593 | W9: =IF($R9*$F$3^(W$5-$R$5)<100,$R9*$F$3^(W$5-$R$5),100) -> 67.460216 | X9: =IF($R9*$F$3^(X$5-$R$5)<100,$R9*$F$3^(X$5-$R$5),100) -> 67.797517 | Y9: =IF($R9*$F$3^(Y$5-$R$5)<100,$R9*$F$3^(Y$5-$R$5),100) -> 68.136505 | Z9: =IF($R9*$F$3^(Z$5-$R$5)<100,$R9*$F$3^(Z$5-$R$5),100) -> 68.477188 | ... AB9: =IF($R9*$F$3^(AB$5-$R$5)<100,$R9*$F$3^(AB$5-$R$5),100) -> 69.163671 | AC9: =IF($AB9*$G$3^(AC$5-$AB$5)<100,$AB9*$G$3^(AC$5-$AB$5),100) -> 69.424433 | AD9: =IF($AB9*$G$3^(AD$5-$AB$5)<100,$AB9*$G$3^(AD$5-$AB$5),100) -> 69.686178 | AE9: =IF($AB9*$G$3^(AE$5-$AB$5)<100,$AB9*$G$3^(AE$5-$AB$5),100) -> 69.94891 | AF9: =IF($AB9*$G$3^(AF$5-$AB$5)<100,$AB9*$G$3^(AF$5-$AB$5),100) -> 70.212632 | AG9: =IF($AB9*$G$3^(AG$5-$AB$5)<100,$AB9*$G$3^(AG$5-$AB$5),100) -> 70.477349 | AH9: =IF($AB9*$G$3^(AH$5-$AB$5)<100,$AB9*$G$3^(AH$5-$AB$5),100) -> 70.743063 | AI9: =IF($AB9*$G$3^(AI$5-$AB$5)<100,$AB9*$G$3^(AI$5-$AB$5),100) -> 71.00978 | AJ9: =IF($AB9*$G$3^(AJ$5-$AB$5)<100,$AB9*$G$3^(AJ$5-$AB$5),100) -> 71.277502 | ... AV9: =IF($AB9*$G$3^(AV$5-$AB$5)<100,$AB9*$G$3^(AV$5-$AB$5),100) -> 74.569996
A10: 秦皇岛市 | B10: 秦皇岛 | C10: 55.68 | D10: =C10 -> 55.68 | E10: =IF($C10*$D$3^(E$5-$D$5)<100,$C10*$D$3^(E$5-$D$5),100) -> 56.627233 | F10: =IF($C10*$D$3^(F$5-$D$5)<100,$C10*$D$3^(F$5-$D$5),100) -> 57.59058 | G10: =IF($C10*$D$3^(G$5-$D$5)<100,$C10*$D$3^(G$5-$D$5),100) -> 58.570316 | H10: =IF($C10*$D$3^(H$5-$D$5)<100,$C10*$D$3^(H$5-$D$5),100) -> 59.566719 | I10: =IF($H10*$E$3^(I$5-$H$5)<100,$H10*$E$3^(I$5-$H$5),100) -> 60.162387 | J10: =IF($H10*$E$3^(J$5-$H$5)<100,$H10*$E$3^(J$5-$H$5),100) -> 60.764011 | K10: =IF($H10*$E$3^(K$5-$H$5)<100,$H10*$E$3^(K$5-$H$5),100) -> 61.371651 | L10: =IF($H10*$E$3^(L$5-$H$5)<100,$H10*$E$3^(L$5-$H$5),100) -> 61.985367 | M10: =IF($H10*$E$3^(M$5-$H$5)<100,$H10*$E$3^(M$5-$H$5),100) -> 62.605221 | N10: =IF($H10*$E$3^(N$5-$H$5)<100,$H10*$E$3^(N$5-$H$5),100) -> 63.231273 | O10: =IF($H10*$E$3^(O$5-$H$5)<100,$H10*$E$3^(O$5-$H$5),100) -> 63.863586 | P10: =IF($H10*$E$3^(P$5-$H$5)<100,$H10*$E$3^(P$5-$H$5),100) -> 64.502222 | ... R10: =IF($H10*$E$3^(R$5-$H$5)<100,$H10*$E$3^(R$5-$H$5),100) -> 65.798716 | S10: =IF($R10*$F$3^(S$5-$R$5)<100,$R10*$F$3^(S$5-$R$5),100) -> 66.12771 | T10: =IF($R10*$F$3^(T$5-$R$5)<100,$R10*$F$3^(T$5-$R$5),100) -> 66.458348 | U10: =IF($R10*$F$3^(U$5-$R$5)<100,$R10*$F$3^(U$5-$R$5),100) -> 66.79064 | V10: =IF($R10*$F$3^(V$5-$R$5)<100,$R10*$F$3^(V$5-$R$5),100) -> 67.124593 | W10: =IF($R10*$F$3^(W$5-$R$5)<100,$R10*$F$3^(W$5-$R$5),100) -> 67.460216 | X10: =IF($R10*$F$3^(X$5-$R$5)<100,$R10*$F$3^(X$5-$R$5),100) -> 67.797517 | Y10: =IF($R10*$F$3^(Y$5-$R$5)<100,$R10*$F$3^(Y$5-$R$5),100) -> 68.136505 | Z10: =IF($R10*$F$3^(Z$5-$R$5)<100,$R10*$F$3^(Z$5-$R$5),100) -> 68.477188 | ... AB10: =IF($R10*$F$3^(AB$5-$R$5)<100,$R10*$F$3^(AB$5-$R$5),100) -> 69.163671 | AC10: =IF($AB10*$G$3^(AC$5-$AB$5)<100,$AB10*$G$3^(AC$5-$AB$5),100) -> 69.424433 | AD10: =IF($AB10*$G$3^(AD$5-$AB$5)<100,$AB10*$G$3^(AD$5-$AB$5),100) -> 69.686178 | AE10: =IF($AB10*$G$3^(AE$5-$AB$5)<100,$AB10*$G$3^(AE$5-$AB$5),100) -> 69.94891 | AF10: =IF($AB10*$G$3^(AF$5-$AB$5)<100,$AB10*$G$3^(AF$5-$AB$5),100) -> 70.212632 | AG10: =IF($AB10*$G$3^(AG$5-$AB$5)<100,$AB10*$G$3^(AG$5-$AB$5),100) -> 70.477349 | AH10: =IF($AB10*$G$3^(AH$5-$AB$5)<100,$AB10*$G$3^(AH$5-$AB$5),100) -> 70.743063 | AI10: =IF($AB10*$G$3^(AI$5-$AB$5)<100,$AB10*$G$3^(AI$5-$AB$5),100) -> 71.00978 | AJ10: =IF($AB10*$G$3^(AJ$5-$AB$5)<100,$AB10*$G$3^(AJ$5-$AB$5),100) -> 71.277502 | ... AV10: =IF($AB10*$G$3^(AV$5-$AB$5)<100,$AB10*$G$3^(AV$5-$AB$5),100) -> 74.569996
A11: 邯郸市 | B11: 邯郸 | C11: 55.68 | D11: =C11 -> 55.68 | E11: =IF($C11*$D$3^(E$5-$D$5)<100,$C11*$D$3^(E$5-$D$5),100) -> 56.627233 | F11: =IF($C11*$D$3^(F$5-$D$5)<100,$C11*$D$3^(F$5-$D$5),100) -> 57.59058 | G11: =IF($C11*$D$3^(G$5-$D$5)<100,$C11*$D$3^(G$5-$D$5),100) -> 58.570316 | H11: =IF($C11*$D$3^(H$5-$D$5)<100,$C11*$D$3^(H$5-$D$5),100) -> 59.566719 | I11: =IF($H11*$E$3^(I$5-$H$5)<100,$H11*$E$3^(I$5-$H$5),100) -> 60.162387 | J11: =IF($H11*$E$3^(J$5-$H$5)<100,$H11*$E$3^(J$5-$H$5),100) -> 60.764011 | K11: =IF($H11*$E$3^(K$5-$H$5)<100,$H11*$E$3^(K$5-$H$5),100) -> 61.371651 | L11: =IF($H11*$E$3^(L$5-$H$5)<100,$H11*$E$3^(L$5-$H$5),100) -> 61.985367 | M11: =IF($H11*$E$3^(M$5-$H$5)<100,$H11*$E$3^(M$5-$H$5),100) -> 62.605221 | N11: =IF($H11*$E$3^(N$5-$H$5)<100,$H11*$E$3^(N$5-$H$5),100) -> 63.231273 | O11: =IF($H11*$E$3^(O$5-$H$5)<100,$H11*$E$3^(O$5-$H$5),100) -> 63.863586 | P11: =IF($H11*$E$3^(P$5-$H$5)<100,$H11*$E$3^(P$5-$H$5),100) -> 64.502222 | ... R11: =IF($H11*$E$3^(R$5-$H$5)<100,$H11*$E$3^(R$5-$H$5),100) -> 65.798716 | S11: =IF($R11*$F$3^(S$5-$R$5)<100,$R11*$F$3^(S$5-$R$5),100) -> 66.12771 | T11: =IF($R11*$F$3^(T$5-$R$5)<100,$R11*$F$3^(T$5-$R$5),100) -> 66.458348 | U11: =IF($R11*$F$3^(U$5-$R$5)<100,$R11*$F$3^(U$5-$R$5),100) -> 66.79064 | V11: =IF($R11*$F$3^(V$5-$R$5)<100,$R11*$F$3^(V$5-$R$5),100) -> 67.124593 | W11: =IF($R11*$F$3^(W$5-$R$5)<100,$R11*$F$3^(W$5-$R$5),100) -> 67.460216 | X11: =IF($R11*$F$3^(X$5-$R$5)<100,$R11*$F$3^(X$5-$R$5),100) -> 67.797517 | Y11: =IF($R11*$F$3^(Y$5-$R$5)<100,$R11*$F$3^(Y$5-$R$5),100) -> 68.136505 | Z11: =IF($R11*$F$3^(Z$5-$R$5)<100,$R11*$F$3^(Z$5-$R$5),100) -> 68.477188 | ... AB11: =IF($R11*$F$3^(AB$5-$R$5)<100,$R11*$F$3^(AB$5-$R$5),100) -> 69.163671 | AC11: =IF($AB11*$G$3^(AC$5-$AB$5)<100,$AB11*$G$3^(AC$5-$AB$5),100) -> 69.424433 | AD11: =IF($AB11*$G$3^(AD$5-$AB$5)<100,$AB11*$G$3^(AD$5-$AB$5),100) -> 69.686178 | AE11: =IF($AB11*$G$3^(AE$5-$AB$5)<100,$AB11*$G$3^(AE$5-$AB$5),100) -> 69.94891 | AF11: =IF($AB11*$G$3^(AF$5-$AB$5)<100,$AB11*$G$3^(AF$5-$AB$5),100) -> 70.212632 | AG11: =IF($AB11*$G$3^(AG$5-$AB$5)<100,$AB11*$G$3^(AG$5-$AB$5),100) -> 70.477349 | AH11: =IF($AB11*$G$3^(AH$5-$AB$5)<100,$AB11*$G$3^(AH$5-$AB$5),100) -> 70.743063 | AI11: =IF($AB11*$G$3^(AI$5-$AB$5)<100,$AB11*$G$3^(AI$5-$AB$5),100) -> 71.00978 | AJ11: =IF($AB11*$G$3^(AJ$5-$AB$5)<100,$AB11*$G$3^(AJ$5-$AB$5),100) -> 71.277502 | ... AV11: =IF($AB11*$G$3^(AV$5-$AB$5)<100,$AB11*$G$3^(AV$5-$AB$5),100) -> 74.569996
A12: 邢台市 | B12: 邢台 | C12: 55.68 | D12: =C12 -> 55.68 | E12: =IF($C12*$D$3^(E$5-$D$5)<100,$C12*$D$3^(E$5-$D$5),100) -> 56.627233 | F12: =IF($C12*$D$3^(F$5-$D$5)<100,$C12*$D$3^(F$5-$D$5),100) -> 57.59058 | G12: =IF($C12*$D$3^(G$5-$D$5)<100,$C12*$D$3^(G$5-$D$5),100) -> 58.570316 | H12: =IF($C12*$D$3^(H$5-$D$5)<100,$C12*$D$3^(H$5-$D$5),100) -> 59.566719 | I12: =IF($H12*$E$3^(I$5-$H$5)<100,$H12*$E$3^(I$5-$H$5),100) -> 60.162387 | J12: =IF($H12*$E$3^(J$5-$H$5)<100,$H12*$E$3^(J$5-$H$5),100) -> 60.764011 | K12: =IF($H12*$E$3^(K$5-$H$5)<100,$H12*$E$3^(K$5-$H$5),100) -> 61.371651 | L12: =IF($H12*$E$3^(L$5-$H$5)<100,$H12*$E$3^(L$5-$H$5),100) -> 61.985367 | M12: =IF($H12*$E$3^(M$5-$H$5)<100,$H12*$E$3^(M$5-$H$5),100) -> 62.605221 | N12: =IF($H12*$E$3^(N$5-$H$5)<100,$H12*$E$3^(N$5-$H$5),100) -> 63.231273 | O12: =IF($H12*$E$3^(O$5-$H$5)<100,$H12*$E$3^(O$5-$H$5),100) -> 63.863586 | P12: =IF($H12*$E$3^(P$5-$H$5)<100,$H12*$E$3^(P$5-$H$5),100) -> 64.502222 | ... R12: =IF($H12*$E$3^(R$5-$H$5)<100,$H12*$E$3^(R$5-$H$5),100) -> 65.798716 | S12: =IF($R12*$F$3^(S$5-$R$5)<100,$R12*$F$3^(S$5-$R$5),100) -> 66.12771 | T12: =IF($R12*$F$3^(T$5-$R$5)<100,$R12*$F$3^(T$5-$R$5),100) -> 66.458348 | U12: =IF($R12*$F$3^(U$5-$R$5)<100,$R12*$F$3^(U$5-$R$5),100) -> 66.79064 | V12: =IF($R12*$F$3^(V$5-$R$5)<100,$R12*$F$3^(V$5-$R$5),100) -> 67.124593 | W12: =IF($R12*$F$3^(W$5-$R$5)<100,$R12*$F$3^(W$5-$R$5),100) -> 67.460216 | X12: =IF($R12*$F$3^(X$5-$R$5)<100,$R12*$F$3^(X$5-$R$5),100) -> 67.797517 | Y12: =IF($R12*$F$3^(Y$5-$R$5)<100,$R12*$F$3^(Y$5-$R$5),100) -> 68.136505 | Z12: =IF($R12*$F$3^(Z$5-$R$5)<100,$R12*$F$3^(Z$5-$R$5),100) -> 68.477188 | ... AB12: =IF($R12*$F$3^(AB$5-$R$5)<100,$R12*$F$3^(AB$5-$R$5),100) -> 69.163671 | AC12: =IF($AB12*$G$3^(AC$5-$AB$5)<100,$AB12*$G$3^(AC$5-$AB$5),100) -> 69.424433 | AD12: =IF($AB12*$G$3^(AD$5-$AB$5)<100,$AB12*$G$3^(AD$5-$AB$5),100) -> 69.686178 | AE12: =IF($AB12*$G$3^(AE$5-$AB$5)<100,$AB12*$G$3^(AE$5-$AB$5),100) -> 69.94891 | AF12: =IF($AB12*$G$3^(AF$5-$AB$5)<100,$AB12*$G$3^(AF$5-$AB$5),100) -> 70.212632 | AG12: =IF($AB12*$G$3^(AG$5-$AB$5)<100,$AB12*$G$3^(AG$5-$AB$5),100) -> 70.477349 | AH12: =IF($AB12*$G$3^(AH$5-$AB$5)<100,$AB12*$G$3^(AH$5-$AB$5),100) -> 70.743063 | AI12: =IF($AB12*$G$3^(AI$5-$AB$5)<100,$AB12*$G$3^(AI$5-$AB$5),100) -> 71.00978 | AJ12: =IF($AB12*$G$3^(AJ$5-$AB$5)<100,$AB12*$G$3^(AJ$5-$AB$5),100) -> 71.277502 | ... AV12: =IF($AB12*$G$3^(AV$5-$AB$5)<100,$AB12*$G$3^(AV$5-$AB$5),100) -> 74.569996
A13: 保定市 | B13: 保定 | C13: 58.346 | D13: =C13 -> 58.346 | E13: =IF($C13*$D$3^(E$5-$D$5)<100,$C13*$D$3^(E$5-$D$5),100) -> 59.338587 | F13: =IF($C13*$D$3^(F$5-$D$5)<100,$C13*$D$3^(F$5-$D$5),100) -> 60.34806 | G13: =IF($C13*$D$3^(G$5-$D$5)<100,$C13*$D$3^(G$5-$D$5),100) -> 61.374707 | H13: =IF($C13*$D$3^(H$5-$D$5)<100,$C13*$D$3^(H$5-$D$5),100) -> 62.418819 | I13: =IF($H13*$E$3^(I$5-$H$5)<100,$H13*$E$3^(I$5-$H$5),100) -> 63.043007 | J13: =IF($H13*$E$3^(J$5-$H$5)<100,$H13*$E$3^(J$5-$H$5),100) -> 63.673437 | K13: =IF($H13*$E$3^(K$5-$H$5)<100,$H13*$E$3^(K$5-$H$5),100) -> 64.310171 | L13: =IF($H13*$E$3^(L$5-$H$5)<100,$H13*$E$3^(L$5-$H$5),100) -> 64.953273 | M13: =IF($H13*$E$3^(M$5-$H$5)<100,$H13*$E$3^(M$5-$H$5),100) -> 65.602806 | N13: =IF($H13*$E$3^(N$5-$H$5)<100,$H13*$E$3^(N$5-$H$5),100) -> 66.258834 | O13: =IF($H13*$E$3^(O$5-$H$5)<100,$H13*$E$3^(O$5-$H$5),100) -> 66.921422 | P13: =IF($H13*$E$3^(P$5-$H$5)<100,$H13*$E$3^(P$5-$H$5),100) -> 67.590636 | ... R13: =IF($H13*$E$3^(R$5-$H$5)<100,$H13*$E$3^(R$5-$H$5),100) -> 68.949208 | S13: =IF($R13*$F$3^(S$5-$R$5)<100,$R13*$F$3^(S$5-$R$5),100) -> 69.293954 | T13: =IF($R13*$F$3^(T$5-$R$5)<100,$R13*$F$3^(T$5-$R$5),100) -> 69.640424 | U13: =IF($R13*$F$3^(U$5-$R$5)<100,$R13*$F$3^(U$5-$R$5),100) -> 69.988626 | V13: =IF($R13*$F$3^(V$5-$R$5)<100,$R13*$F$3^(V$5-$R$5),100) -> 70.338569 | W13: =IF($R13*$F$3^(W$5-$R$5)<100,$R13*$F$3^(W$5-$R$5),100) -> 70.690262 | X13: =IF($R13*$F$3^(X$5-$R$5)<100,$R13*$F$3^(X$5-$R$5),100) -> 71.043713 | Y13: =IF($R13*$F$3^(Y$5-$R$5)<100,$R13*$F$3^(Y$5-$R$5),100) -> 71.398932 | Z13: =IF($R13*$F$3^(Z$5-$R$5)<100,$R13*$F$3^(Z$5-$R$5),100) -> 71.755926 | ... AB13: =IF($R13*$F$3^(AB$5-$R$5)<100,$R13*$F$3^(AB$5-$R$5),100) -> 72.47528 | AC13: =IF($AB13*$G$3^(AC$5-$AB$5)<100,$AB13*$G$3^(AC$5-$AB$5),100) -> 72.748527 | AD13: =IF($AB13*$G$3^(AD$5-$AB$5)<100,$AB13*$G$3^(AD$5-$AB$5),100) -> 73.022804 | AE13: =IF($AB13*$G$3^(AE$5-$AB$5)<100,$AB13*$G$3^(AE$5-$AB$5),100) -> 73.298116 | AF13: =IF($AB13*$G$3^(AF$5-$AB$5)<100,$AB13*$G$3^(AF$5-$AB$5),100) -> 73.574465 | AG13: =IF($AB13*$G$3^(AG$5-$AB$5)<100,$AB13*$G$3^(AG$5-$AB$5),100) -> 73.851857 | AH13: =IF($AB13*$G$3^(AH$5-$AB$5)<100,$AB13*$G$3^(AH$5-$AB$5),100) -> 74.130294 | AI13: =IF($AB13*$G$3^(AI$5-$AB$5)<100,$AB13*$G$3^(AI$5-$AB$5),100) -> 74.409781 | AJ13: =IF($AB13*$G$3^(AJ$5-$AB$5)<100,$AB13*$G$3^(AJ$5-$AB$5),100) -> 74.690322 | ... AV13: =IF($AB13*$G$3^(AV$5-$AB$5)<100,$AB13*$G$3^(AV$5-$AB$5),100) -> 78.140463
A14: 张家口市 | B14: 张家口 | C14: 50.348 | D14: =C14 -> 50.348 | E14: =IF($C14*$D$3^(E$5-$D$5)<100,$C14*$D$3^(E$5-$D$5),100) -> 51.204525 | F14: =IF($C14*$D$3^(F$5-$D$5)<100,$C14*$D$3^(F$5-$D$5),100) -> 52.07562 | G14: =IF($C14*$D$3^(G$5-$D$5)<100,$C14*$D$3^(G$5-$D$5),100) -> 52.961535 | H14: =IF($C14*$D$3^(H$5-$D$5)<100,$C14*$D$3^(H$5-$D$5),100) -> 53.862521 | I14: =IF($H14*$E$3^(I$5-$H$5)<100,$H14*$E$3^(I$5-$H$5),100) -> 54.401147 | J14: =IF($H14*$E$3^(J$5-$H$5)<100,$H14*$E$3^(J$5-$H$5),100) -> 54.945158 | K14: =IF($H14*$E$3^(K$5-$H$5)<100,$H14*$E$3^(K$5-$H$5),100) -> 55.49461 | L14: =IF($H14*$E$3^(L$5-$H$5)<100,$H14*$E$3^(L$5-$H$5),100) -> 56.049556 | M14: =IF($H14*$E$3^(M$5-$H$5)<100,$H14*$E$3^(M$5-$H$5),100) -> 56.610051 | N14: =IF($H14*$E$3^(N$5-$H$5)<100,$H14*$E$3^(N$5-$H$5),100) -> 57.176152 | O14: =IF($H14*$E$3^(O$5-$H$5)<100,$H14*$E$3^(O$5-$H$5),100) -> 57.747913 | P14: =IF($H14*$E$3^(P$5-$H$5)<100,$H14*$E$3^(P$5-$H$5),100) -> 58.325393 | ... R14: =IF($H14*$E$3^(R$5-$H$5)<100,$H14*$E$3^(R$5-$H$5),100) -> 59.497733 | S14: =IF($R14*$F$3^(S$5-$R$5)<100,$R14*$F$3^(S$5-$R$5),100) -> 59.795222 | T14: =IF($R14*$F$3^(T$5-$R$5)<100,$R14*$F$3^(T$5-$R$5),100) -> 60.094198 | U14: =IF($R14*$F$3^(U$5-$R$5)<100,$R14*$F$3^(U$5-$R$5),100) -> 60.394669 | V14: =IF($R14*$F$3^(V$5-$R$5)<100,$R14*$F$3^(V$5-$R$5),100) -> 60.696642 | W14: =IF($R14*$F$3^(W$5-$R$5)<100,$R14*$F$3^(W$5-$R$5),100) -> 61.000125 | X14: =IF($R14*$F$3^(X$5-$R$5)<100,$R14*$F$3^(X$5-$R$5),100) -> 61.305126 | Y14: =IF($R14*$F$3^(Y$5-$R$5)<100,$R14*$F$3^(Y$5-$R$5),100) -> 61.611651 | Z14: =IF($R14*$F$3^(Z$5-$R$5)<100,$R14*$F$3^(Z$5-$R$5),100) -> 61.91971 | ... AB14: =IF($R14*$F$3^(AB$5-$R$5)<100,$R14*$F$3^(AB$5-$R$5),100) -> 62.540455 | AC14: =IF($AB14*$G$3^(AC$5-$AB$5)<100,$AB14*$G$3^(AC$5-$AB$5),100) -> 62.776246 | AD14: =IF($AB14*$G$3^(AD$5-$AB$5)<100,$AB14*$G$3^(AD$5-$AB$5),100) -> 63.012926 | AE14: =IF($AB14*$G$3^(AE$5-$AB$5)<100,$AB14*$G$3^(AE$5-$AB$5),100) -> 63.250498 | AF14: =IF($AB14*$G$3^(AF$5-$AB$5)<100,$AB14*$G$3^(AF$5-$AB$5),100) -> 63.488966 | AG14: =IF($AB14*$G$3^(AG$5-$AB$5)<100,$AB14*$G$3^(AG$5-$AB$5),100) -> 63.728333 | AH14: =IF($AB14*$G$3^(AH$5-$AB$5)<100,$AB14*$G$3^(AH$5-$AB$5),100) -> 63.968602 | AI14: =IF($AB14*$G$3^(AI$5-$AB$5)<100,$AB14*$G$3^(AI$5-$AB$5),100) -> 64.209777 | AJ14: =IF($AB14*$G$3^(AJ$5-$AB$5)<100,$AB14*$G$3^(AJ$5-$AB$5),100) -> 64.451862 | ... AV14: =IF($AB14*$G$3^(AV$5-$AB$5)<100,$AB14*$G$3^(AV$5-$AB$5),100) -> 67.429062
A15: 承德市 | B15: 承德 | C15: 50.348 | D15: =C15 -> 50.348 | E15: =IF($C15*$D$3^(E$5-$D$5)<100,$C15*$D$3^(E$5-$D$5),100) -> 51.204525 | F15: =IF($C15*$D$3^(F$5-$D$5)<100,$C15*$D$3^(F$5-$D$5),100) -> 52.07562 | G15: =IF($C15*$D$3^(G$5-$D$5)<100,$C15*$D$3^(G$5-$D$5),100) -> 52.961535 | H15: =IF($C15*$D$3^(H$5-$D$5)<100,$C15*$D$3^(H$5-$D$5),100) -> 53.862521 | I15: =IF($H15*$E$3^(I$5-$H$5)<100,$H15*$E$3^(I$5-$H$5),100) -> 54.401147 | J15: =IF($H15*$E$3^(J$5-$H$5)<100,$H15*$E$3^(J$5-$H$5),100) -> 54.945158 | K15: =IF($H15*$E$3^(K$5-$H$5)<100,$H15*$E$3^(K$5-$H$5),100) -> 55.49461 | L15: =IF($H15*$E$3^(L$5-$H$5)<100,$H15*$E$3^(L$5-$H$5),100) -> 56.049556 | M15: =IF($H15*$E$3^(M$5-$H$5)<100,$H15*$E$3^(M$5-$H$5),100) -> 56.610051 | N15: =IF($H15*$E$3^(N$5-$H$5)<100,$H15*$E$3^(N$5-$H$5),100) -> 57.176152 | O15: =IF($H15*$E$3^(O$5-$H$5)<100,$H15*$E$3^(O$5-$H$5),100) -> 57.747913 | P15: =IF($H15*$E$3^(P$5-$H$5)<100,$H15*$E$3^(P$5-$H$5),100) -> 58.325393 | ... R15: =IF($H15*$E$3^(R$5-$H$5)<100,$H15*$E$3^(R$5-$H$5),100) -> 59.497733 | S15: =IF($R15*$F$3^(S$5-$R$5)<100,$R15*$F$3^(S$5-$R$5),100) -> 59.795222 | T15: =IF($R15*$F$3^(T$5-$R$5)<100,$R15*$F$3^(T$5-$R$5),100) -> 60.094198 | U15: =IF($R15*$F$3^(U$5-$R$5)<100,$R15*$F$3^(U$5-$R$5),100) -> 60.394669 | V15: =IF($R15*$F$3^(V$5-$R$5)<100,$R15*$F$3^(V$5-$R$5),100) -> 60.696642 | W15: =IF($R15*$F$3^(W$5-$R$5)<100,$R15*$F$3^(W$5-$R$5),100) -> 61.000125 | X15: =IF($R15*$F$3^(X$5-$R$5)<100,$R15*$F$3^(X$5-$R$5),100) -> 61.305126 | Y15: =IF($R15*$F$3^(Y$5-$R$5)<100,$R15*$F$3^(Y$5-$R$5),100) -> 61.611651 | Z15: =IF($R15*$F$3^(Z$5-$R$5)<100,$R15*$F$3^(Z$5-$R$5),100) -> 61.91971 | ... AB15: =IF($R15*$F$3^(AB$5-$R$5)<100,$R15*$F$3^(AB$5-$R$5),100) -> 62.540455 | AC15: =IF($AB15*$G$3^(AC$5-$AB$5)<100,$AB15*$G$3^(AC$5-$AB$5),100) -> 62.776246 | AD15: =IF($AB15*$G$3^(AD$5-$AB$5)<100,$AB15*$G$3^(AD$5-$AB$5),100) -> 63.012926 | AE15: =IF($AB15*$G$3^(AE$5-$AB$5)<100,$AB15*$G$3^(AE$5-$AB$5),100) -> 63.250498 | AF15: =IF($AB15*$G$3^(AF$5-$AB$5)<100,$AB15*$G$3^(AF$5-$AB$5),100) -> 63.488966 | AG15: =IF($AB15*$G$3^(AG$5-$AB$5)<100,$AB15*$G$3^(AG$5-$AB$5),100) -> 63.728333 | AH15: =IF($AB15*$G$3^(AH$5-$AB$5)<100,$AB15*$G$3^(AH$5-$AB$5),100) -> 63.968602 | AI15: =IF($AB15*$G$3^(AI$5-$AB$5)<100,$AB15*$G$3^(AI$5-$AB$5),100) -> 64.209777 | AJ15: =IF($AB15*$G$3^(AJ$5-$AB$5)<100,$AB15*$G$3^(AJ$5-$AB$5),100) -> 64.451862 | ... AV15: =IF($AB15*$G$3^(AV$5-$AB$5)<100,$AB15*$G$3^(AV$5-$AB$5),100) -> 67.429062
A16: 沧州市 | B16: 沧州 | C16: 55.68 | D16: =C16 -> 55.68 | E16: =IF($C16*$D$3^(E$5-$D$5)<100,$C16*$D$3^(E$5-$D$5),100) -> 56.627233 | F16: =IF($C16*$D$3^(F$5-$D$5)<100,$C16*$D$3^(F$5-$D$5),100) -> 57.59058 | G16: =IF($C16*$D$3^(G$5-$D$5)<100,$C16*$D$3^(G$5-$D$5),100) -> 58.570316 | H16: =IF($C16*$D$3^(H$5-$D$5)<100,$C16*$D$3^(H$5-$D$5),100) -> 59.566719 | I16: =IF($H16*$E$3^(I$5-$H$5)<100,$H16*$E$3^(I$5-$H$5),100) -> 60.162387 | J16: =IF($H16*$E$3^(J$5-$H$5)<100,$H16*$E$3^(J$5-$H$5),100) -> 60.764011 | K16: =IF($H16*$E$3^(K$5-$H$5)<100,$H16*$E$3^(K$5-$H$5),100) -> 61.371651 | L16: =IF($H16*$E$3^(L$5-$H$5)<100,$H16*$E$3^(L$5-$H$5),100) -> 61.985367 | M16: =IF($H16*$E$3^(M$5-$H$5)<100,$H16*$E$3^(M$5-$H$5),100) -> 62.605221 | N16: =IF($H16*$E$3^(N$5-$H$5)<100,$H16*$E$3^(N$5-$H$5),100) -> 63.231273 | O16: =IF($H16*$E$3^(O$5-$H$5)<100,$H16*$E$3^(O$5-$H$5),100) -> 63.863586 | P16: =IF($H16*$E$3^(P$5-$H$5)<100,$H16*$E$3^(P$5-$H$5),100) -> 64.502222 | ... R16: =IF($H16*$E$3^(R$5-$H$5)<100,$H16*$E$3^(R$5-$H$5),100) -> 65.798716 | S16: =IF($R16*$F$3^(S$5-$R$5)<100,$R16*$F$3^(S$5-$R$5),100) -> 66.12771 | T16: =IF($R16*$F$3^(T$5-$R$5)<100,$R16*$F$3^(T$5-$R$5),100) -> 66.458348 | U16: =IF($R16*$F$3^(U$5-$R$5)<100,$R16*$F$3^(U$5-$R$5),100) -> 66.79064 | V16: =IF($R16*$F$3^(V$5-$R$5)<100,$R16*$F$3^(V$5-$R$5),100) -> 67.124593 | W16: =IF($R16*$F$3^(W$5-$R$5)<100,$R16*$F$3^(W$5-$R$5),100) -> 67.460216 | X16: =IF($R16*$F$3^(X$5-$R$5)<100,$R16*$F$3^(X$5-$R$5),100) -> 67.797517 | Y16: =IF($R16*$F$3^(Y$5-$R$5)<100,$R16*$F$3^(Y$5-$R$5),100) -> 68.136505 | Z16: =IF($R16*$F$3^(Z$5-$R$5)<100,$R16*$F$3^(Z$5-$R$5),100) -> 68.477188 | ... AB16: =IF($R16*$F$3^(AB$5-$R$5)<100,$R16*$F$3^(AB$5-$R$5),100) -> 69.163671 | AC16: =IF($AB16*$G$3^(AC$5-$AB$5)<100,$AB16*$G$3^(AC$5-$AB$5),100) -> 69.424433 | AD16: =IF($AB16*$G$3^(AD$5-$AB$5)<100,$AB16*$G$3^(AD$5-$AB$5),100) -> 69.686178 | AE16: =IF($AB16*$G$3^(AE$5-$AB$5)<100,$AB16*$G$3^(AE$5-$AB$5),100) -> 69.94891 | AF16: =IF($AB16*$G$3^(AF$5-$AB$5)<100,$AB16*$G$3^(AF$5-$AB$5),100) -> 70.212632 | AG16: =IF($AB16*$G$3^(AG$5-$AB$5)<100,$AB16*$G$3^(AG$5-$AB$5),100) -> 70.477349 | AH16: =IF($AB16*$G$3^(AH$5-$AB$5)<100,$AB16*$G$3^(AH$5-$AB$5),100) -> 70.743063 | AI16: =IF($AB16*$G$3^(AI$5-$AB$5)<100,$AB16*$G$3^(AI$5-$AB$5),100) -> 71.00978 | AJ16: =IF($AB16*$G$3^(AJ$5-$AB$5)<100,$AB16*$G$3^(AJ$5-$AB$5),100) -> 71.277502 | ... AV16: =IF($AB16*$G$3^(AV$5-$AB$5)<100,$AB16*$G$3^(AV$5-$AB$5),100) -> 74.569996
A17: 廊坊市 | B17: 廊坊 | C17: 58.346 | D17: =C17 -> 58.346 | E17: =IF($C17*$D$3^(E$5-$D$5)<100,$C17*$D$3^(E$5-$D$5),100) -> 59.338587 | F17: =IF($C17*$D$3^(F$5-$D$5)<100,$C17*$D$3^(F$5-$D$5),100) -> 60.34806 | G17: =IF($C17*$D$3^(G$5-$D$5)<100,$C17*$D$3^(G$5-$D$5),100) -> 61.374707 | H17: =IF($C17*$D$3^(H$5-$D$5)<100,$C17*$D$3^(H$5-$D$5),100) -> 62.418819 | I17: =IF($H17*$E$3^(I$5-$H$5)<100,$H17*$E$3^(I$5-$H$5),100) -> 63.043007 | J17: =IF($H17*$E$3^(J$5-$H$5)<100,$H17*$E$3^(J$5-$H$5),100) -> 63.673437 | K17: =IF($H17*$E$3^(K$5-$H$5)<100,$H17*$E$3^(K$5-$H$5),100) -> 64.310171 | L17: =IF($H17*$E$3^(L$5-$H$5)<100,$H17*$E$3^(L$5-$H$5),100) -> 64.953273 | M17: =IF($H17*$E$3^(M$5-$H$5)<100,$H17*$E$3^(M$5-$H$5),100) -> 65.602806 | N17: =IF($H17*$E$3^(N$5-$H$5)<100,$H17*$E$3^(N$5-$H$5),100) -> 66.258834 | O17: =IF($H17*$E$3^(O$5-$H$5)<100,$H17*$E$3^(O$5-$H$5),100) -> 66.921422 | P17: =IF($H17*$E$3^(P$5-$H$5)<100,$H17*$E$3^(P$5-$H$5),100) -> 67.590636 | ... R17: =IF($H17*$E$3^(R$5-$H$5)<100,$H17*$E$3^(R$5-$H$5),100) -> 68.949208 | S17: =IF($R17*$F$3^(S$5-$R$5)<100,$R17*$F$3^(S$5-$R$5),100) -> 69.293954 | T17: =IF($R17*$F$3^(T$5-$R$5)<100,$R17*$F$3^(T$5-$R$5),100) -> 69.640424 | U17: =IF($R17*$F$3^(U$5-$R$5)<100,$R17*$F$3^(U$5-$R$5),100) -> 69.988626 | V17: =IF($R17*$F$3^(V$5-$R$5)<100,$R17*$F$3^(V$5-$R$5),100) -> 70.338569 | W17: =IF($R17*$F$3^(W$5-$R$5)<100,$R17*$F$3^(W$5-$R$5),100) -> 70.690262 | X17: =IF($R17*$F$3^(X$5-$R$5)<100,$R17*$F$3^(X$5-$R$5),100) -> 71.043713 | Y17: =IF($R17*$F$3^(Y$5-$R$5)<100,$R17*$F$3^(Y$5-$R$5),100) -> 71.398932 | Z17: =IF($R17*$F$3^(Z$5-$R$5)<100,$R17*$F$3^(Z$5-$R$5),100) -> 71.755926 | ... AB17: =IF($R17*$F$3^(AB$5-$R$5)<100,$R17*$F$3^(AB$5-$R$5),100) -> 72.47528 | AC17: =IF($AB17*$G$3^(AC$5-$AB$5)<100,$AB17*$G$3^(AC$5-$AB$5),100) -> 72.748527 | AD17: =IF($AB17*$G$3^(AD$5-$AB$5)<100,$AB17*$G$3^(AD$5-$AB$5),100) -> 73.022804 | AE17: =IF($AB17*$G$3^(AE$5-$AB$5)<100,$AB17*$G$3^(AE$5-$AB$5),100) -> 73.298116 | AF17: =IF($AB17*$G$3^(AF$5-$AB$5)<100,$AB17*$G$3^(AF$5-$AB$5),100) -> 73.574465 | AG17: =IF($AB17*$G$3^(AG$5-$AB$5)<100,$AB17*$G$3^(AG$5-$AB$5),100) -> 73.851857 | AH17: =IF($AB17*$G$3^(AH$5-$AB$5)<100,$AB17*$G$3^(AH$5-$AB$5),100) -> 74.130294 | AI17: =IF($AB17*$G$3^(AI$5-$AB$5)<100,$AB17*$G$3^(AI$5-$AB$5),100) -> 74.409781 | AJ17: =IF($AB17*$G$3^(AJ$5-$AB$5)<100,$AB17*$G$3^(AJ$5-$AB$5),100) -> 74.690322 | ... AV17: =IF($AB17*$G$3^(AV$5-$AB$5)<100,$AB17*$G$3^(AV$5-$AB$5),100) -> 78.140463
... A372: 胡杨河市 | B372: 胡杨河 | C372: 69.322783 | D372: =C372 -> 69.322783 | E372: =IF($C372*$D$3^(E$5-$D$5)<100,$C372*$D$3^(E$5-$D$5),100) -> 70.502109 | F372: =IF($C372*$D$3^(F$5-$D$5)<100,$C372*$D$3^(F$5-$D$5),100) -> 71.701497 | G372: =IF($C372*$D$3^(G$5-$D$5)<100,$C372*$D$3^(G$5-$D$5),100) -> 72.921289 | H372: =IF($C372*$D$3^(H$5-$D$5)<100,$C372*$D$3^(H$5-$D$5),100) -> 74.161832 | I372: =IF($H372*$E$3^(I$5-$H$5)<100,$H372*$E$3^(I$5-$H$5),100) -> 74.90345 | J372: =IF($H372*$E$3^(J$5-$H$5)<100,$H372*$E$3^(J$5-$H$5),100) -> 75.652485 | K372: =IF($H372*$E$3^(K$5-$H$5)<100,$H372*$E$3^(K$5-$H$5),100) -> 76.409009 | L372: =IF($H372*$E$3^(L$5-$H$5)<100,$H372*$E$3^(L$5-$H$5),100) -> 77.1731 | M372: =IF($H372*$E$3^(M$5-$H$5)<100,$H372*$E$3^(M$5-$H$5),100) -> 77.944831 | N372: =IF($H372*$E$3^(N$5-$H$5)<100,$H372*$E$3^(N$5-$H$5),100) -> 78.724279 | O372: =IF($H372*$E$3^(O$5-$H$5)<100,$H372*$E$3^(O$5-$H$5),100) -> 79.511522 | P372: =IF($H372*$E$3^(P$5-$H$5)<100,$H372*$E$3^(P$5-$H$5),100) -> 80.306637 | ... R372: =IF($H372*$E$3^(R$5-$H$5)<100,$H372*$E$3^(R$5-$H$5),100) -> 81.9208 | S372: =IF($R372*$F$3^(S$5-$R$5)<100,$R372*$F$3^(S$5-$R$5),100) -> 82.330404 | T372: =IF($R372*$F$3^(T$5-$R$5)<100,$R372*$F$3^(T$5-$R$5),100) -> 82.742056 | U372: =IF($R372*$F$3^(U$5-$R$5)<100,$R372*$F$3^(U$5-$R$5),100) -> 83.155767 | V372: =IF($R372*$F$3^(V$5-$R$5)<100,$R372*$F$3^(V$5-$R$5),100) -> 83.571545 | W372: =IF($R372*$F$3^(W$5-$R$5)<100,$R372*$F$3^(W$5-$R$5),100) -> 83.989403 | X372: =IF($R372*$F$3^(X$5-$R$5)<100,$R372*$F$3^(X$5-$R$5),100) -> 84.40935 | Y372: =IF($R372*$F$3^(Y$5-$R$5)<100,$R372*$F$3^(Y$5-$R$5),100) -> 84.831397 | Z372: =IF($R372*$F$3^(Z$5-$R$5)<100,$R372*$F$3^(Z$5-$R$5),100) -> 85.255554 | ... AB372: =IF($R372*$F$3^(AB$5-$R$5)<100,$R372*$F$3^(AB$5-$R$5),100) -> 86.110241 | AC372: =IF($AB372*$G$3^(AC$5-$AB$5)<100,$AB372*$G$3^(AC$5-$AB$5),100) -> 86.434895 | AD372: =IF($AB372*$G$3^(AD$5-$AB$5)<100,$AB372*$G$3^(AD$5-$AB$5),100) -> 86.760773 | AE372: =IF($AB372*$G$3^(AE$5-$AB$5)<100,$AB372*$G$3^(AE$5-$AB$5),100) -> 87.087879 | AF372: =IF($AB372*$G$3^(AF$5-$AB$5)<100,$AB372*$G$3^(AF$5-$AB$5),100) -> 87.416219 | AG372: =IF($AB372*$G$3^(AG$5-$AB$5)<100,$AB372*$G$3^(AG$5-$AB$5),100) -> 87.745797 | AH372: =IF($AB372*$G$3^(AH$5-$AB$5)<100,$AB372*$G$3^(AH$5-$AB$5),100) -> 88.076618 | AI372: =IF($AB372*$G$3^(AI$5-$AB$5)<100,$AB372*$G$3^(AI$5-$AB$5),100) -> 88.408685 | AJ372: =IF($AB372*$G$3^(AJ$5-$AB$5)<100,$AB372*$G$3^(AJ$5-$AB$5),100) -> 88.742005 | ... AV372: =IF($AB372*$G$3^(AV$5-$AB$5)<100,$AB372*$G$3^(AV$5-$AB$5),100) -> 92.84123
A373: sum

Sheet 城镇人口
A1: Province | B1: City | C1: 2016城镇化率 | D1: 2016 | E1: 2017 | F1: 2018 | G1: 2019 | H1: 2020 | I1: 2021 | J1: 2022 | K1: 2023 | L1: 2024 | M1: 2025 | N1: 2026 | O1: 2027 | P1: 2028 | Q1: 2029 | R1: 2030 | S1: 2031 | T1: 2032 | U1: 2033 | V1: 2034 | W1: 2035 | X1: 2036 | Y1: 2037 | Z1: 2038 | AA1: 2039 | AB1: 2040 | AC1: 2041 | AD1: 2042 | AE1: 2043 | AF1: 2044 | AG1: 2045 | AH1: 2046 | AI1: 2047 | AJ1: 2048 | AK1: 2049 | AL1: 2050 | AM1: 2051 | AN1: 2052 | AO1: 2053 | AP1: 2054 | AQ1: 2055 | AR1: 2056 | AS1: 2057 | AT1: 2058 | AU1: 2059 | AV1: 2060
A2: 北京市 | B2: 北京市 | C2: =VLOOKUP(B2,'[1]2016省城人口总结（根）'!B:C,2,FALSE)/100 -> 0.8786 | D2: =INDEX(人口源表!$1:$1048576,MATCH($B2,人口源表!$A:$A,0),MATCH(D$1,人口源表!$1:$1,0))*INDEX(城镇化率!$1:$1048576,MATCH($B2,城镇化率!$A:$A,0),MATCH(D$1,城镇化率!$5:$5,0))/100 -> 18342372 | E2: =INDEX(人口源表!$1:$1048576,MATCH($B2,人口源表!$A:$A,0),MATCH(E$1,人口源表!$1:$1,0))*INDEX(城镇化率!$1:$1048576,MATCH($B2,城镇化率!$A:$A,0),MATCH(E$1,城镇化率!$5:$5,0))/100 -> 18803184 | F2: =INDEX(人口源表!$1:$1048576,MATCH($B2,人口源表!$A:$A,0),MATCH(F$1,人口源表!$1:$1,0))*INDEX(城镇化率!$1:$1048576,MATCH($B2,城镇化率!$A:$A,0),MATCH(F$1,城镇化率!$5:$5,0))/100 -> 19258833 | G2: =INDEX(人口源表!$1:$1048576,MATCH($B2,人口源表!$A:$A,0),MATCH(G$1,人口源表!$1:$1,0))*INDEX(城镇化率!$1:$1048576,MATCH($B2,城镇化率!$A:$A,0),MATCH(G$1,城镇化率!$5:$5,0))/100 -> 20000982 | H2: =INDEX(人口源表!$1:$1048576,MATCH($B2,人口源表!$A:$A,0),MATCH(H$1,人口源表!$1:$1,0))*INDEX(城镇化率!$1:$1048576,MATCH($B2,城镇化率!$A:$A,0),MATCH(H$1,城镇化率!$5:$5,0))/100 -> 20576196 | I2: =INDEX(人口源表!$1:$1048576,MATCH($B2,人口源表!$A:$A,0),MATCH(I$1,人口源表!$1:$1,0))*INDEX(城镇化率!$1:$1048576,MATCH($B2,城镇化率!$A:$A,0),MATCH(I$1,城镇化率!$5:$5,0))/100 -> 20972921 | J2: =INDEX(人口源表!$1:$1048576,MATCH($B2,人口源表!$A:$A,0),MATCH(J$1,人口源表!$1:$1,0))*INDEX(城镇化率!$1:$1048576,MATCH($B2,城镇化率!$A:$A,0),MATCH(J$1,城镇化率!$5:$5,0))/100 -> 21333011 | K2: =INDEX(人口源表!$1:$1048576,MATCH($B2,人口源表!$A:$A,0),MATCH(K$1,人口源表!$1:$1,0))*INDEX(城镇化率!$1:$1048576,MATCH($B2,城镇化率!$A:$A,0),MATCH(K$1,城镇化率!$5:$5,0))/100 -> 21659405 | ... AV2: =INDEX(人口源表!$1:$1048576,MATCH($B2,人口源表!$A:$A,0),MATCH(AV$1,人口源表!$1:$1,0))*INDEX(城镇化率!$1:$1048576,MATCH($B2,城镇化率!$A:$A,0),MATCH(AV$1,城镇化率!$5:$5,0))/100 -> 18874781
A3: 天津市 | B3: 天津市 | C3: =VLOOKUP(B3,'[1]2016省城人口总结（根）'!B:C,2,FALSE)/100 -> 0.8429 | D3: =INDEX(人口源表!$1:$1048576,MATCH($B3,人口源表!$A:$A,0),MATCH(D$1,人口源表!$1:$1,0))*INDEX(城镇化率!$1:$1048576,MATCH($B3,城镇化率!$A:$A,0),MATCH(D$1,城镇化率!$5:$5,0))/100 -> 11435906 | E3: =INDEX(人口源表!$1:$1048576,MATCH($B3,人口源表!$A:$A,0),MATCH(E$1,人口源表!$1:$1,0))*INDEX(城镇化率!$1:$1048576,MATCH($B3,城镇化率!$A:$A,0),MATCH(E$1,城镇化率!$5:$5,0))/100 -> 11704728 | F3: =INDEX(人口源表!$1:$1048576,MATCH($B3,人口源表!$A:$A,0),MATCH(F$1,人口源表!$1:$1,0))*INDEX(城镇化率!$1:$1048576,MATCH($B3,城镇化率!$A:$A,0),MATCH(F$1,城镇化率!$5:$5,0))/100 -> 11972061 | G3: =INDEX(人口源表!$1:$1048576,MATCH($B3,人口源表!$A:$A,0),MATCH(G$1,人口源表!$1:$1,0))*INDEX(城镇化率!$1:$1048576,MATCH($B3,城镇化率!$A:$A,0),MATCH(G$1,城镇化率!$5:$5,0))/100 -> 12181925 | H3: =INDEX(人口源表!$1:$1048576,MATCH($B3,人口源表!$A:$A,0),MATCH(H$1,人口源表!$1:$1,0))*INDEX(城镇化率!$1:$1048576,MATCH($B3,城镇化率!$A:$A,0),MATCH(H$1,城镇化率!$5:$5,0))/100 -> 12502542 | I3: =INDEX(人口源表!$1:$1048576,MATCH($B3,人口源表!$A:$A,0),MATCH(I$1,人口源表!$1:$1,0))*INDEX(城镇化率!$1:$1048576,MATCH($B3,城镇化率!$A:$A,0),MATCH(I$1,城镇化率!$5:$5,0))/100 -> 12719230 | J3: =INDEX(人口源表!$1:$1048576,MATCH($B3,人口源表!$A:$A,0),MATCH(J$1,人口源表!$1:$1,0))*INDEX(城镇化率!$1:$1048576,MATCH($B3,城镇化率!$A:$A,0),MATCH(J$1,城镇化率!$5:$5,0))/100 -> 12917822 | K3: =INDEX(人口源表!$1:$1048576,MATCH($B3,人口源表!$A:$A,0),MATCH(K$1,人口源表!$1:$1,0))*INDEX(城镇化率!$1:$1048576,MATCH($B3,城镇化率!$A:$A,0),MATCH(K$1,城镇化率!$5:$5,0))/100 -> 13099559 | ... AV3: =INDEX(人口源表!$1:$1048576,MATCH($B3,人口源表!$A:$A,0),MATCH(AV$1,人口源表!$1:$1,0))*INDEX(城镇化率!$1:$1048576,MATCH($B3,城镇化率!$A:$A,0),MATCH(AV$1,城镇化率!$5:$5,0))/100 -> 11539219
A4: 河北省 | B4: 石家庄市 | C4: =VLOOKUP(B4,'[1]2016省城人口总结（根）'!B:C,2,FALSE)/100 -> 0.58346 | D4: =INDEX(人口源表!$1:$1048576,MATCH($B4,人口源表!$A:$A,0),MATCH(D$1,人口源表!$1:$1,0))*INDEX(城镇化率!$1:$1048576,MATCH($B4,城镇化率!$A:$A,0),MATCH(D$1,城镇化率!$5:$5,0))/100 -> 6235233.3 | E4: =INDEX(人口源表!$1:$1048576,MATCH($B4,人口源表!$A:$A,0),MATCH(E$1,人口源表!$1:$1,0))*INDEX(城镇化率!$1:$1048576,MATCH($B4,城镇化率!$A:$A,0),MATCH(E$1,城镇化率!$5:$5,0))/100 -> 6384345.3 | F4: =INDEX(人口源表!$1:$1048576,MATCH($B4,人口源表!$A:$A,0),MATCH(F$1,人口源表!$1:$1,0))*INDEX(城镇化率!$1:$1048576,MATCH($B4,城镇化率!$A:$A,0),MATCH(F$1,城镇化率!$5:$5,0))/100 -> 6533455.3 | G4: =INDEX(人口源表!$1:$1048576,MATCH($B4,人口源表!$A:$A,0),MATCH(G$1,人口源表!$1:$1,0))*INDEX(城镇化率!$1:$1048576,MATCH($B4,城镇化率!$A:$A,0),MATCH(G$1,城镇化率!$5:$5,0))/100 -> 6834133.1 | H4: =INDEX(人口源表!$1:$1048576,MATCH($B4,人口源表!$A:$A,0),MATCH(H$1,人口源表!$1:$1,0))*INDEX(城镇化率!$1:$1048576,MATCH($B4,城镇化率!$A:$A,0),MATCH(H$1,城镇化率!$5:$5,0))/100 -> 7012216.8 | I4: =INDEX(人口源表!$1:$1048576,MATCH($B4,人口源表!$A:$A,0),MATCH(I$1,人口源表!$1:$1,0))*INDEX(城镇化率!$1:$1048576,MATCH($B4,城镇化率!$A:$A,0),MATCH(I$1,城镇化率!$5:$5,0))/100 -> 7138021.7 | J4: =INDEX(人口源表!$1:$1048576,MATCH($B4,人口源表!$A:$A,0),MATCH(J$1,人口源表!$1:$1,0))*INDEX(城镇化率!$1:$1048576,MATCH($B4,城镇化率!$A:$A,0),MATCH(J$1,城镇化率!$5:$5,0))/100 -> 7259161.5 | K4: =INDEX(人口源表!$1:$1048576,MATCH($B4,人口源表!$A:$A,0),MATCH(K$1,人口源表!$1:$1,0))*INDEX(城镇化率!$1:$1048576,MATCH($B4,城镇化率!$A:$A,0),MATCH(K$1,城镇化率!$5:$5,0))/100 -> 7375803 | ... AV4: =INDEX(人口源表!$1:$1048576,MATCH($B4,人口源表!$A:$A,0),MATCH(AV$1,人口源表!$1:$1,0))*INDEX(城镇化率!$1:$1048576,MATCH($B4,城镇化率!$A:$A,0),MATCH(AV$1,城镇化率!$5:$5,0))/100 -> 8403595
A5: 河北省 | B5: 唐山市 | C5: =VLOOKUP(B5,'[1]2016省城人口总结（根）'!B:C,2,FALSE)/100 -> 0.5568 | D5: =INDEX(人口源表!$1:$1048576,MATCH($B5,人口源表!$A:$A,0),MATCH(D$1,人口源表!$1:$1,0))*INDEX(城镇化率!$1:$1048576,MATCH($B5,城镇化率!$A:$A,0),MATCH(D$1,城镇化率!$5:$5,0))/100 -> 4384650.3 | E5: =INDEX(人口源表!$1:$1048576,MATCH($B5,人口源表!$A:$A,0),MATCH(E$1,人口源表!$1:$1,0))*INDEX(城镇化率!$1:$1048576,MATCH($B5,城镇化率!$A:$A,0),MATCH(E$1,城镇化率!$5:$5,0))/100 -> 4479080.5 | F5: =INDEX(人口源表!$1:$1048576,MATCH($B5,人口源表!$A:$A,0),MATCH(F$1,人口源表!$1:$1,0))*INDEX(城镇化率!$1:$1048576,MATCH($B5,城镇化率!$A:$A,0),MATCH(F$1,城镇化率!$5:$5,0))/100 -> 4572929.3 | G5: =INDEX(人口源表!$1:$1048576,MATCH($B5,人口源表!$A:$A,0),MATCH(G$1,人口源表!$1:$1,0))*INDEX(城镇化率!$1:$1048576,MATCH($B5,城镇化率!$A:$A,0),MATCH(G$1,城镇化率!$5:$5,0))/100 -> 4497548.4 | H5: =INDEX(人口源表!$1:$1048576,MATCH($B5,人口源表!$A:$A,0),MATCH(H$1,人口源表!$1:$1,0))*INDEX(城镇化率!$1:$1048576,MATCH($B5,城镇化率!$A:$A,0),MATCH(H$1,城镇化率!$5:$5,0))/100 -> 4596844.8 | I5: =INDEX(人口源表!$1:$1048576,MATCH($B5,人口源表!$A:$A,0),MATCH(I$1,人口源表!$1:$1,0))*INDEX(城镇化率!$1:$1048576,MATCH($B5,城镇化率!$A:$A,0),MATCH(I$1,城镇化率!$5:$5,0))/100 -> 4662477.9 | J5: =INDEX(人口源表!$1:$1048576,MATCH($B5,人口源表!$A:$A,0),MATCH(J$1,人口源表!$1:$1,0))*INDEX(城镇化率!$1:$1048576,MATCH($B5,城镇化率!$A:$A,0),MATCH(J$1,城镇化率!$5:$5,0))/100 -> 4725692.4 | K5: =INDEX(人口源表!$1:$1048576,MATCH($B5,人口源表!$A:$A,0),MATCH(K$1,人口源表!$1:$1,0))*INDEX(城镇化率!$1:$1048576,MATCH($B5,城镇化率!$A:$A,0),MATCH(K$1,城镇化率!$5:$5,0))/100 -> 4786511.9 | ... AV5: =INDEX(人口源表!$1:$1048576,MATCH($B5,人口源表!$A:$A,0),MATCH(AV$1,人口源表!$1:$1,0))*INDEX(城镇化率!$1:$1048576,MATCH($B5,城镇化率!$A:$A,0),MATCH(AV$1,城镇化率!$5:$5,0))/100 -> 4960333.5
A6: 河北省 | B6: 秦皇岛市 | C6: =VLOOKUP(B6,'[1]2016省城人口总结（根）'!B:C,2,FALSE)/100 -> 0.5568 | D6: =INDEX(人口源表!$1:$1048576,MATCH($B6,人口源表!$A:$A,0),MATCH(D$1,人口源表!$1:$1,0))*INDEX(城镇化率!$1:$1048576,MATCH($B6,城镇化率!$A:$A,0),MATCH(D$1,城镇化率!$5:$5,0))/100 -> 1729551.7 | E6: =INDEX(人口源表!$1:$1048576,MATCH($B6,人口源表!$A:$A,0),MATCH(E$1,人口源表!$1:$1,0))*INDEX(城镇化率!$1:$1048576,MATCH($B6,城镇化率!$A:$A,0),MATCH(E$1,城镇化率!$5:$5,0))/100 -> 1767397 | F6: =INDEX(人口源表!$1:$1048576,MATCH($B6,人口源表!$A:$A,0),MATCH(F$1,人口源表!$1:$1,0))*INDEX(城镇化率!$1:$1048576,MATCH($B6,城镇化率!$A:$A,0),MATCH(F$1,城镇化率!$5:$5,0))/100 -> 1805082.1 | G6: =INDEX(人口源表!$1:$1048576,MATCH($B6,人口源表!$A:$A,0),MATCH(G$1,人口源表!$1:$1,0))*INDEX(城镇化率!$1:$1048576,MATCH($B6,城镇化率!$A:$A,0),MATCH(G$1,城镇化率!$5:$5,0))/100 -> 1826289.8 | H6: =INDEX(人口源表!$1:$1048576,MATCH($B6,人口源表!$A:$A,0),MATCH(H$1,人口源表!$1:$1,0))*INDEX(城镇化率!$1:$1048576,MATCH($B6,城镇化率!$A:$A,0),MATCH(H$1,城镇化率!$5:$5,0))/100 -> 1868337.6 | I6: =INDEX(人口源表!$1:$1048576,MATCH($B6,人口源表!$A:$A,0),MATCH(I$1,人口源表!$1:$1,0))*INDEX(城镇化率!$1:$1048576,MATCH($B6,城镇化率!$A:$A,0),MATCH(I$1,城镇化率!$5:$5,0))/100 -> 1896499.5 | J6: =INDEX(人口源表!$1:$1048576,MATCH($B6,人口源表!$A:$A,0),MATCH(J$1,人口源表!$1:$1,0))*INDEX(城镇化率!$1:$1048576,MATCH($B6,城镇化率!$A:$A,0),MATCH(J$1,城镇化率!$5:$5,0))/100 -> 1923482.3 | K6: =INDEX(人口源表!$1:$1048576,MATCH($B6,人口源表!$A:$A,0),MATCH(K$1,人口源表!$1:$1,0))*INDEX(城镇化率!$1:$1048576,MATCH($B6,城镇化率!$A:$A,0),MATCH(K$1,城镇化率!$5:$5,0))/100 -> 1949312.8 | ... AV6: =INDEX(人口源表!$1:$1048576,MATCH($B6,人口源表!$A:$A,0),MATCH(AV$1,人口源表!$1:$1,0))*INDEX(城镇化率!$1:$1048576,MATCH($B6,城镇化率!$A:$A,0),MATCH(AV$1,城镇化率!$5:$5,0))/100 -> 2041074.7
A7: 河北省 | B7: 邯郸市 | C7: =VLOOKUP(B7,'[1]2016省城人口总结（根）'!B:C,2,FALSE)/100 -> 0.5568 | D7: =INDEX(人口源表!$1:$1048576,MATCH($B7,人口源表!$A:$A,0),MATCH(D$1,人口源表!$1:$1,0))*INDEX(城镇化率!$1:$1048576,MATCH($B7,城镇化率!$A:$A,0),MATCH(D$1,城镇化率!$5:$5,0))/100 -> 5386019.5 | E7: =INDEX(人口源表!$1:$1048576,MATCH($B7,人口源表!$A:$A,0),MATCH(E$1,人口源表!$1:$1,0))*INDEX(城镇化率!$1:$1048576,MATCH($B7,城镇化率!$A:$A,0),MATCH(E$1,城镇化率!$5:$5,0))/100 -> 5510433.1 | F7: =INDEX(人口源表!$1:$1048576,MATCH($B7,人口源表!$A:$A,0),MATCH(F$1,人口源表!$1:$1,0))*INDEX(城镇化率!$1:$1048576,MATCH($B7,城镇化率!$A:$A,0),MATCH(F$1,城镇化率!$5:$5,0))/100 -> 5634438.8 | G7: =INDEX(人口源表!$1:$1048576,MATCH($B7,人口源表!$A:$A,0),MATCH(G$1,人口源表!$1:$1,0))*INDEX(城镇化率!$1:$1048576,MATCH($B7,城镇化率!$A:$A,0),MATCH(G$1,城镇化率!$5:$5,0))/100 -> 5485913.7 | H7: =INDEX(人口源表!$1:$1048576,MATCH($B7,人口源表!$A:$A,0),MATCH(H$1,人口源表!$1:$1,0))*INDEX(城镇化率!$1:$1048576,MATCH($B7,城镇化率!$A:$A,0),MATCH(H$1,城镇化率!$5:$5,0))/100 -> 5607211.3 | I7: =INDEX(人口源表!$1:$1048576,MATCH($B7,人口源表!$A:$A,0),MATCH(I$1,人口源表!$1:$1,0))*INDEX(城镇化率!$1:$1048576,MATCH($B7,城镇化率!$A:$A,0),MATCH(I$1,城镇化率!$5:$5,0))/100 -> 5692673.3 | J7: =INDEX(人口源表!$1:$1048576,MATCH($B7,人口源表!$A:$A,0),MATCH(J$1,人口源表!$1:$1,0))*INDEX(城镇化率!$1:$1048576,MATCH($B7,城镇化率!$A:$A,0),MATCH(J$1,城镇化率!$5:$5,0))/100 -> 5780031.9 | K7: =INDEX(人口源表!$1:$1048576,MATCH($B7,人口源表!$A:$A,0),MATCH(K$1,人口源表!$1:$1,0))*INDEX(城镇化率!$1:$1048576,MATCH($B7,城镇化率!$A:$A,0),MATCH(K$1,城镇化率!$5:$5,0))/100 -> 5868941.5 | ... AV7: =INDEX(人口源表!$1:$1048576,MATCH($B7,人口源表!$A:$A,0),MATCH(AV$1,人口源表!$1:$1,0))*INDEX(城镇化率!$1:$1048576,MATCH($B7,城镇化率!$A:$A,0),MATCH(AV$1,城镇化率!$5:$5,0))/100 -> 7163420.5
A8: 河北省 | B8: 邢台市 | C8: =VLOOKUP(B8,'[1]2016省城人口总结（根）'!B:C,2,FALSE)/100 -> 0.5568 | D8: =INDEX(人口源表!$1:$1048576,MATCH($B8,人口源表!$A:$A,0),MATCH(D$1,人口源表!$1:$1,0))*INDEX(城镇化率!$1:$1048576,MATCH($B8,城镇化率!$A:$A,0),MATCH(D$1,城镇化率!$5:$5,0))/100 -> 4166190.8 | E8: =INDEX(人口源表!$1:$1048576,MATCH($B8,人口源表!$A:$A,0),MATCH(E$1,人口源表!$1:$1,0))*INDEX(城镇化率!$1:$1048576,MATCH($B8,城镇化率!$A:$A,0),MATCH(E$1,城镇化率!$5:$5,0))/100 -> 4264866.3 | F8: =INDEX(人口源表!$1:$1048576,MATCH($B8,人口源表!$A:$A,0),MATCH(F$1,人口源表!$1:$1,0))*INDEX(城镇化率!$1:$1048576,MATCH($B8,城镇化率!$A:$A,0),MATCH(F$1,城镇化率!$5:$5,0))/100 -> 4363497 | G8: =INDEX(人口源表!$1:$1048576,MATCH($B8,人口源表!$A:$A,0),MATCH(G$1,人口源表!$1:$1,0))*INDEX(城镇化率!$1:$1048576,MATCH($B8,城镇化率!$A:$A,0),MATCH(G$1,城镇化率!$5:$5,0))/100 -> 4134408.3 | H8: =INDEX(人口源表!$1:$1048576,MATCH($B8,人口源表!$A:$A,0),MATCH(H$1,人口源表!$1:$1,0))*INDEX(城镇化率!$1:$1048576,MATCH($B8,城镇化率!$A:$A,0),MATCH(H$1,城镇化率!$5:$5,0))/100 -> 4235536.9 | I8: =INDEX(人口源表!$1:$1048576,MATCH($B8,人口源表!$A:$A,0),MATCH(I$1,人口源表!$1:$1,0))*INDEX(城镇化率!$1:$1048576,MATCH($B8,城镇化率!$A:$A,0),MATCH(I$1,城镇化率!$5:$5,0))/100 -> 4307318.9 | J8: =INDEX(人口源表!$1:$1048576,MATCH($B8,人口源表!$A:$A,0),MATCH(J$1,人口源表!$1:$1,0))*INDEX(城镇化率!$1:$1048576,MATCH($B8,城镇化率!$A:$A,0),MATCH(J$1,城镇化率!$5:$5,0))/100 -> 4378371.4 | K8: =INDEX(人口源表!$1:$1048576,MATCH($B8,人口源表!$A:$A,0),MATCH(K$1,人口源表!$1:$1,0))*INDEX(城镇化率!$1:$1048576,MATCH($B8,城镇化率!$A:$A,0),MATCH(K$1,城镇化率!$5:$5,0))/100 -> 4448612.5 | ... AV8: =INDEX(人口源表!$1:$1048576,MATCH($B8,人口源表!$A:$A,0),MATCH(AV$1,人口源表!$1:$1,0))*INDEX(城镇化率!$1:$1048576,MATCH($B8,城镇化率!$A:$A,0),MATCH(AV$1,城镇化率!$5:$5,0))/100 -> 5275783.2
A9: 河北省 | B9: 保定市 | C9: =VLOOKUP(B9,'[1]2016省城人口总结（根）'!B:C,2,FALSE)/100 -> 0.58346 | D9: =INDEX(人口源表!$1:$1048576,MATCH($B9,人口源表!$A:$A,0),MATCH(D$1,人口源表!$1:$1,0))*INDEX(城镇化率!$1:$1048576,MATCH($B9,城镇化率!$A:$A,0),MATCH(D$1,城镇化率!$5:$5,0))/100 -> 6842201.7 | E9: =INDEX(人口源表!$1:$1048576,MATCH($B9,人口源表!$A:$A,0),MATCH(E$1,人口源表!$1:$1,0))*INDEX(城镇化率!$1:$1048576,MATCH($B9,城镇化率!$A:$A,0),MATCH(E$1,城镇化率!$5:$5,0))/100 -> 6997653.7 | F9: =INDEX(人口源表!$1:$1048576,MATCH($B9,人口源表!$A:$A,0),MATCH(F$1,人口源表!$1:$1,0))*INDEX(城镇化率!$1:$1048576,MATCH($B9,城镇化率!$A:$A,0),MATCH(F$1,城镇化率!$5:$5,0))/100 -> 7152641 | G9: =INDEX(人口源表!$1:$1048576,MATCH($B9,人口源表!$A:$A,0),MATCH(G$1,人口源表!$1:$1,0))*INDEX(城镇化率!$1:$1048576,MATCH($B9,城镇化率!$A:$A,0),MATCH(G$1,城镇化率!$5:$5,0))/100 -> 7043275.4 | H9: =INDEX(人口源表!$1:$1048576,MATCH($B9,人口源表!$A:$A,0),MATCH(H$1,人口源表!$1:$1,0))*INDEX(城镇化率!$1:$1048576,MATCH($B9,城镇化率!$A:$A,0),MATCH(H$1,城镇化率!$5:$5,0))/100 -> 7204988 | I9: =INDEX(人口源表!$1:$1048576,MATCH($B9,人口源表!$A:$A,0),MATCH(I$1,人口源表!$1:$1,0))*INDEX(城镇化率!$1:$1048576,MATCH($B9,城镇化率!$A:$A,0),MATCH(I$1,城镇化率!$5:$5,0))/100 -> 7316576.6 | J9: =INDEX(人口源表!$1:$1048576,MATCH($B9,人口源表!$A:$A,0),MATCH(J$1,人口源表!$1:$1,0))*INDEX(城镇化率!$1:$1048576,MATCH($B9,城镇化率!$A:$A,0),MATCH(J$1,城镇化率!$5:$5,0))/100 -> 7426797.1 | K9: =INDEX(人口源表!$1:$1048576,MATCH($B9,人口源表!$A:$A,0),MATCH(K$1,人口源表!$1:$1,0))*INDEX(城镇化率!$1:$1048576,MATCH($B9,城镇化率!$A:$A,0),MATCH(K$1,城镇化率!$5:$5,0))/100 -> 7535514.1 | ... AV9: =INDEX(人口源表!$1:$1048576,MATCH($B9,人口源表!$A:$A,0),MATCH(AV$1,人口源表!$1:$1,0))*INDEX(城镇化率!$1:$1048576,MATCH($B9,城镇化率!$A:$A,0),MATCH(AV$1,城镇化率!$5:$5,0))/100 -> 8562781.2
A10: 河北省 | B10: 张家口市 | C10: =VLOOKUP(B10,'[1]2016省城人口总结（根）'!B:C,2,FALSE)/100 -> 0.50348 | D10: =INDEX(人口源表!$1:$1048576,MATCH($B10,人口源表!$A:$A,0),MATCH(D$1,人口源表!$1:$1,0))*INDEX(城镇化率!$1:$1048576,MATCH($B10,城镇化率!$A:$A,0),MATCH(D$1,城镇化率!$5:$5,0))/100 -> 2248755.3 | E10: =INDEX(人口源表!$1:$1048576,MATCH($B10,人口源表!$A:$A,0),MATCH(E$1,人口源表!$1:$1,0))*INDEX(城镇化率!$1:$1048576,MATCH($B10,城镇化率!$A:$A,0),MATCH(E$1,城镇化率!$5:$5,0))/100 -> 2293588.9 | F10: =INDEX(人口源表!$1:$1048576,MATCH($B10,人口源表!$A:$A,0),MATCH(F$1,人口源表!$1:$1,0))*INDEX(城镇化率!$1:$1048576,MATCH($B10,城镇化率!$A:$A,0),MATCH(F$1,城镇化率!$5:$5,0))/100 -> 2338259.3 | G10: =INDEX(人口源表!$1:$1048576,MATCH($B10,人口源表!$A:$A,0),MATCH(G$1,人口源表!$1:$1,0))*INDEX(城镇化率!$1:$1048576,MATCH($B10,城镇化率!$A:$A,0),MATCH(G$1,城镇化率!$5:$5,0))/100 -> 2175382.3 | H10: =INDEX(人口源表!$1:$1048576,MATCH($B10,人口源表!$A:$A,0),MATCH(H$1,人口源表!$1:$1,0))*INDEX(城镇化率!$1:$1048576,MATCH($B10,城镇化率!$A:$A,0),MATCH(H$1,城镇化率!$5:$5,0))/100 -> 2218324.7 | I10: =INDEX(人口源表!$1:$1048576,MATCH($B10,人口源表!$A:$A,0),MATCH(I$1,人口源表!$1:$1,0))*INDEX(城镇化率!$1:$1048576,MATCH($B10,城镇化率!$A:$A,0),MATCH(I$1,城镇化率!$5:$5,0))/100 -> 2245954.6 | J10: =INDEX(人口源表!$1:$1048576,MATCH($B10,人口源表!$A:$A,0),MATCH(J$1,人口源表!$1:$1,0))*INDEX(城镇化率!$1:$1048576,MATCH($B10,城镇化率!$A:$A,0),MATCH(J$1,城镇化率!$5:$5,0))/100 -> 2273283.4 | K10: =INDEX(人口源表!$1:$1048576,MATCH($B10,人口源表!$A:$A,0),MATCH(K$1,人口源表!$1:$1,0))*INDEX(城镇化率!$1:$1048576,MATCH($B10,城镇化率!$A:$A,0),MATCH(K$1,城镇化率!$5:$5,0))/100 -> 2300222.7 | ... AV10: =INDEX(人口源表!$1:$1048576,MATCH($B10,人口源表!$A:$A,0),MATCH(AV$1,人口源表!$1:$1,0))*INDEX(城镇化率!$1:$1048576,MATCH($B10,城镇化率!$A:$A,0),MATCH(AV$1,城镇化率!$5:$5,0))/100 -> 2350796.9
