Workbook

Sheet 草稿
A1: EPS 行业 | G1: CGE | H1: 2017年排放 | K1: 电力 | N1: 电力中分为
A2: agriculture and forestry | G2: 1 Crops | H2: 56.202104 | K2: hard coal | N2: hard coal - 硬煤 | T2: 含碳量70%-90%
A3: coal mining | G3: 2 Forestry | H3: 5.372654 | K3: natural gas nonpeaker | N3: natural gas nonpeaker - 非调峰天然气
A4: oil and gas extraction | G4: 3 Livestock | H4: 18.047048 | K4: nuclear (NOT USED) | N4: nuclear (NOT USED) - 核能（未使用）
A5: other mining and quarrying | G5: 4 Fishing | H5: 14.087549 | K5: hydro (NOT USED) | N5: hydro (NOT USED) - 水力（未使用）
A6: food, beverage, and tobacco | G6: 5 AgriSrvces | H6: 21.008646 | K6: onshore wind (NOT USED) | N6: onshore wind (NOT USED) - 陆上风能（未使用）
A7: textiles, apparel, and leather | G7: 6 CoalMineProc | H7: 71.750786 | K7: solar PV (NOT USED) | N7: solar PV (NOT USED) - 太阳能光伏（未使用）
A8: wood products | G8: 7 CrudeOil | H8: 4.362614 | K8: solar thermal (NOT USED) | N8: solar thermal (NOT USED) - 太阳能热能（未使用）
A9: pulp, paper, and printing | G9: 8 Gas_Cnv | H9: 21.296943 | K9: biomass | N9: biomass - 生物质能
A10: refined petroleum and coke | G10: 9 Gas_NCnv | H10: 10.572858 | K10: geothermal (NOT USED) | N10: geothermal (NOT USED) - 地热能（未使用）
A11: chemicals | G11: 10 FerrOre | H11: 25.915607 | K11: petroleum | N11: petroleum - 石油
A12: rubber and plastic products | G12: 11 NFerrOre | H12: 4.008664 | K12: natural gas peaker | N12: natural gas peaker - 调峰天然气
A13: glass and glass products | G13: 12 NMtlMine | H13: 8.697023 | K13: lignite | N13: lignite - 褐煤 | T13: 含碳量25%-35%
A14: cement and other nonmetallic minerals | G14: 13 MiningSrvces | H14: 4.180484 | K14: offshore wind (NOT USED) | N14: offshore wind (NOT USED) - 海上风能（未使用）
A15: iron and steel | G15: 14 GrainMillOil | H15: 8.778113 | K15: crude oil | N15: crude oil - 原油
A16: other metals | G16: 15 AnimalFood | H16: 4.249709 | K16: heavy or residual fuel oil | N16: heavy or residual fuel oil - 重油或残余燃料油
A17: metal products except machinery and vehicles | G17: 16 VegetOils | H17: 4.648614 | K17: municipal solid waste | N17: municipal solid waste - 城市固体废物
A18: computers and electronics | G18: 17 SugarRef | H18: 3.04089
A19: appliances and electrical equipment | G19: 18 MeatProds | H19: 5.657073
A20: other machinery | G20: 19 FishProc | H20: 2.973913
A21: road vehicles | G21: 20 VegFrtNuts | H21: 16.23853 | K21: 燃烧排放选择 | M21: 过程排放选择 | P21: 电力安装CCS选择
A22: nonroad vehicles | G22: 21 ConvenFoods | H22: 3.183953 | K22: 电力 | M22: 水泥 | P22: 硬煤
A23: other manufacturing | G23: 22 DairyProds | H23: 1.775251 | K23: 钢铁 | M23: 钢铁 | P23: 天然气
A24: energy pipelines and gas processing | G24: 23 FlavFermPrds | H24: 7.829698 | K24: 水泥 | M24: 化工 | P24: 油
A25: water and waste | G25: 24 OtherFood | H25: 14.174824 | K25: 化工 | M25: 能源管道与天然气处理 | P25: 生物质能
A26: construction | G26: 25 AlcoholBev | H26: 11.01269 | K26: 精炼油 | P26: 城市固体废物
G27: 26 OtherBev | H27: 8.312559
G28: 27 PurifiedTea | H28: 1.150088 | K28: 过程排放 | L28: ipcc_code_2006_for_standard_report | M28: ipcc_code_2006_for_standard_report_name | N28: Y_2020
A29: 水泥在非金属的燃料排放占比 | D29: =SUM(H57:H58)/SUM(H57:H63) -> 0.550791 | G29: 28 Tobacco | H29: 0.651222 | L29: 1.A.1.a | M29: Main Activity Electricity and Heat Production | N29: 158781
A30: 水泥在非金属的过程排放占比 | D30: =O51 -> 0.96524913 | G30: 29 CottonSpin | H30: 15.803229 | L30: 1.A.2 | M30: Manufacturing Industries and Construction | N30: 104044.6
A31: 天然气加工的过程排放占比 | G31: 30 WoolSpin | H31: 2.261156 | L31: 1.A.3.b_noRES | M31: Road Transportation no resuspension | N31: 6827.549
G32: 31 HempSpin | H32: 3.155488 | L32: 1.A.4 | M32: Residential and other sectors | N32: 314514.53
G33: 32 KnitMill | H33: 2.916804 | L33: 1.B.2 | M33: Oil and Natural Gas | N33: 11774.625
G34: 33 TextProc | H34: 2.799638 | L34: 3.C.1 | M34: Emissions from biomass burning | N34: 11323.531
G35: 34 Apparel | H35: 4.270617 | L35: 4.C | M35: Incineration and Open Burning of Waste | N35: 199.67625
G36: 35 Leather | H36: 1.159386 | L36: 1.A.1.a | M36: Main Activity Electricity and Heat Production | N36: 5288987.7
G37: 36 Footwear | H37: 1.311105 | L37: 1.A.1.bc | M37: Petroleum Refining - Manufacture of Solid Fuels and Other Energy Industries | N37: 353073.37
G38: 37 WoodProds | H38: 6.306221 | L38: 1.A.2 | M38: Manufacturing Industries and Construction | N38: 2815411
G39: 38 Furniture | H39: 2.564429 | L39: 1.A.3.a | M39: Civil Aviation | N39: 66154.027
G40: 39 PaperProd | H40: 34.052002 | L40: 1.A.3.b_noRES | M40: Road Transportation no resuspension | N40: 739119.56
...

Sheet 应用行业
A1: Unit: dimentionless (fraction of CO2 capturable) | E1: Unit: dimentionless (fraction of CO2 capturable) | F1: energy related emissions | G1: process emissions
A2: hard coal | B2: 1 | E2: agriculture and forestry 01T03 | F2: 0 | G2: 0
A3: natural gas nonpeaker | B3: 1 | E3: coal mining 05 | F3: 0 | G3: 0
A4: nuclear | B4: 0 | E4: oil and gas extraction 06 | F4: 0 | G4: 0
A5: hydro | B5: 0 | E5: other mining and quarrying 07T08 | F5: 0 | G5: 0
A6: onshore wind | B6: 0 | E6: food beverage and tobacco 10T12 | F6: 0 | G6: 0
A7: solar PV | B7: 0 | E7: textiles apparel and leather 13T15 | F7: 0 | G7: 0
A8: solar thermal | B8: 0 | E8: wood products 16 | F8: 0 | G8: 0
A9: biomass | B9: 1 | E9: pulp paper and printing 17T18 | F9: 0 | G9: 0
A10: geothermal | B10: 0 | E10: refined petroleum and coke 19 | F10: 1 | G10: 0
A11: petroleum | B11: 0 | E11: chemicals 20 | F11: 1 | G11: 1
A12: natural gas peaker | B12: 1 | E12: rubber and plastic products 22 | F12: 0 | G12: 0
A13: lignite | B13: 1 | E13: glass and glass products 231 | F13: 0 | G13: 0
... A17: municipal solid waste | B17: 1 | E17: metal products except machinery and vehicles 25 | F17: 0 | G17: 0
E18: computers and electronics 26 | F18: 0 | G18: 0
E19: appliances and electrical equipment 27 | F19: 0 | G19: 0
E20: other machinery 28 | F20: 0 | G20: 0
E21: road vehicles 29 | F21: 0 | G21: 0
E22: nonroad vehicles 30 | F22: 0 | G22: 0
E23: other manufacturing 31T33 | F23: 0 | G23: 0
E24: energy pipelines and gas processing 352T353 | F24: 0 | G24: 1
E25: water and waste 36T39 | F25: 0 | G25: 0
E26: construction 41T43 | F26: 0 | G26: 0

Sheet 工业燃料渗透率
A1: Unit: dimensionless (fraction of potential achieved) | B1: 2020 | C1: 2021 | D1: 2022 | E1: 2023 | F1: 2024 | G1: 2025 | H1: 2026 | I1: 2027 | J1: 2028 | K1: 2029 | L1: 2030 | M1: 2031 | N1: 2032 | O1: 2033 | P1: 2034 | Q1: 2035 | R1: 2036 | S1: 2037 | T1: 2038 | U1: 2039 | V1: 2040 | W1: 2041 | X1: 2042 | Y1: 2043 | Z1: 2044 | AA1: 2045 | AB1: 2046 | AC1: 2047 | AD1: 2048 | AE1: 2049 | AF1: 2050 | AG1: 2051 | AH1: 2052 | AI1: 2053 | AJ1: 2054 | AK1: 2055 | AL1: 2056 | AM1: 2057 | AN1: 2058 | AO1: 2059 | AP1: 2060
A2: agriculture and forestry 01T03 | B2: 0 | C2: 0 | D2: 0 | E2: 0 | F2: 0 | G2: 0 | H2: 0 | I2: 0 | J2: 0 | K2: 0 | L2: 0 | M2: 0 | N2: 0 | O2: 0 | P2: 0 | Q2: 0 | R2: 0 | S2: 0 | T2: 0 | U2: 0 | V2: 0 | W2: 0 | X2: 0 | Y2: 0 | Z2: 0 | AA2: 0 | AB2: 0 | AC2: 0 | AD2: 0 | AE2: 0 | AF2: 0 | AG2: 0 | AH2: 0 | AI2: 0 | AJ2: 0 | AK2: 0 | AL2: 0 | AM2: 0 | AN2: 0 | AO2: 0 | AP2: 0
A3: coal mining 05 | B3: 0 | C3: 0 | D3: 0 | E3: 0 | F3: 0 | G3: 0 | H3: 0 | I3: 0 | J3: 0 | K3: 0 | L3: 0 | M3: 0 | N3: 0 | O3: 0 | P3: 0 | Q3: 0 | R3: 0 | S3: 0 | T3: 0 | U3: 0 | V3: 0 | W3: 0 | X3: 0 | Y3: 0 | Z3: 0 | AA3: 0 | AB3: 0 | AC3: 0 | AD3: 0 | AE3: 0 | AF3: 0 | AG3: 0 | AH3: 0 | AI3: 0 | AJ3: 0 | AK3: 0 | AL3: 0 | AM3: 0 | AN3: 0 | AO3: 0 | AP3: 0
A4: oil and gas extraction 06 | B4: 0 | C4: 0 | D4: 0 | E4: 0 | F4: 0 | G4: 0 | H4: 0 | I4: 0 | J4: 0 | K4: 0 | L4: 0 | M4: 0 | N4: 0 | O4: 0 | P4: 0 | Q4: 0 | R4: 0 | S4: 0 | T4: 0 | U4: 0 | V4: 0 | W4: 0 | X4: 0 | Y4: 0 | Z4: 0 | AA4: 0 | AB4: 0 | AC4: 0 | AD4: 0 | AE4: 0 | AF4: 0 | AG4: 0 | AH4: 0 | AI4: 0 | AJ4: 0 | AK4: 0 | AL4: 0 | AM4: 0 | AN4: 0 | AO4: 0 | AP4: 0
A5: other mining and quarrying 07T08 | B5: 0 | C5: 0 | D5: 0 | E5: 0 | F5: 0 | G5: 0 | H5: 0 | I5: 0 | J5: 0 | K5: 0 | L5: 0 | M5: 0 | N5: 0 | O5: 0 | P5: 0 | Q5: 0 | R5: 0 | S5: 0 | T5: 0 | U5: 0 | V5: 0 | W5: 0 | X5: 0 | Y5: 0 | Z5: 0 | AA5: 0 | AB5: 0 | AC5: 0 | AD5: 0 | AE5: 0 | AF5: 0 | AG5: 0 | AH5: 0 | AI5: 0 | AJ5: 0 | AK5: 0 | AL5: 0 | AM5: 0 | AN5: 0 | AO5: 0 | AP5: 0
A6: food beverage and tobacco 10T12 | B6: 0 | C6: 0 | D6: 0 | E6: 0 | F6: 0 | G6: 0 | H6: 0 | I6: 0 | J6: 0 | K6: 0 | L6: 0 | M6: 0 | N6: 0 | O6: 0 | P6: 0 | Q6: 0 | R6: 0 | S6: 0 | T6: 0 | U6: 0 | V6: 0 | W6: 0 | X6: 0 | Y6: 0 | Z6: 0 | AA6: 0 | AB6: 0 | AC6: 0 | AD6: 0 | AE6: 0 | AF6: 0 | AG6: 0 | AH6: 0 | AI6: 0 | AJ6: 0 | AK6: 0 | AL6: 0 | AM6: 0 | AN6: 0 | AO6: 0 | AP6: 0
A7: textiles apparel and leather 13T15 | B7: 0 | C7: 0 | D7: 0 | E7: 0 | F7: 0 | G7: 0 | H7: 0 | I7: 0 | J7: 0 | K7: 0 | L7: 0 | M7: 0 | N7: 0 | O7: 0 | P7: 0 | Q7: 0 | R7: 0 | S7: 0 | T7: 0 | U7: 0 | V7: 0 | W7: 0 | X7: 0 | Y7: 0 | Z7: 0 | AA7: 0 | AB7: 0 | AC7: 0 | AD7: 0 | AE7: 0 | AF7: 0 | AG7: 0 | AH7: 0 | AI7: 0 | AJ7: 0 | AK7: 0 | AL7: 0 | AM7: 0 | AN7: 0 | AO7: 0 | AP7: 0
A8: wood products 16 | B8: 0 | C8: 0 | D8: 0 | E8: 0 | F8: 0 | G8: 0 | H8: 0 | I8: 0 | J8: 0 | K8: 0 | L8: 0 | M8: 0 | N8: 0 | O8: 0 | P8: 0 | Q8: 0 | R8: 0 | S8: 0 | T8: 0 | U8: 0 | V8: 0 | W8: 0 | X8: 0 | Y8: 0 | Z8: 0 | AA8: 0 | AB8: 0 | AC8: 0 | AD8: 0 | AE8: 0 | AF8: 0 | AG8: 0 | AH8: 0 | AI8: 0 | AJ8: 0 | AK8: 0 | AL8: 0 | AM8: 0 | AN8: 0 | AO8: 0 | AP8: 0
A9: pulp paper and printing 17T18 | B9: 0 | C9: 0 | D9: 0 | E9: 0 | F9: 0 | G9: 0 | H9: 0 | I9: 0 | J9: 0 | K9: 0 | L9: 0 | M9: 0 | N9: 0 | O9: 0 | P9: 0 | Q9: 0 | R9: 0 | S9: 0 | T9: 0 | U9: 0 | V9: 0 | W9: 0 | X9: 0 | Y9: 0 | Z9: 0 | AA9: 0 | AB9: 0 | AC9: 0 | AD9: 0 | AE9: 0 | AF9: 0 | AG9: 0 | AH9: 0 | AI9: 0 | AJ9: 0 | AK9: 0 | AL9: 0 | AM9: 0 | AN9: 0 | AO9: 0 | AP9: 0
A10: refined petroleum and coke 19 | B10: 0.00686252 | C10: 0.00845858 | D10: 0.01041712 | E10: 0.011749746 | F10: 0.014450124 | G10: 0.017744254 | H10: 0.021926316 | I10: 0.027220963 | J10: 0.033419613 | K10: 0.040878126 | L10: 0.049753517 | M10: 0.060209991 | N10: 0.072364713 | O10: 0.086278513 | P10: 0.10337328 | Q10: 0.12254473 | R10: 0.14352035 | S10: 0.16606045 | T10: 0.18975975 | U10: 0.21395778 | V10: 0.23818071 | W10: 0.26180997 | X10: 0.28425247 | Y10: 0.30525285 | Z10: 0.32442965 | AA10: 0.34183012 | AB10: 0.35698073 | AC10: 0.37034765 | AD10: 0.38215586 | AE10: 0.39233734 | AF10: 0.40136924 | AG10: 0.40919866 | AH10: 0.41622293 | AI10: 0.42233918 | AJ10: 0.42796581 | AK10: 0.43293647 | AL10: 0.4376372 | AM10: 0.44186859 | AN10: 0.44583404 | AO10: 0.44975368 | AP10: 0.45255937
A11: chemicals 20 | B11: 0.00686252 | C11: 0.00845858 | D11: 0.01041712 | E11: 0.011749746 | F11: 0.014450124 | G11: 0.017744254 | H11: 0.021926316 | I11: 0.027220963 | J11: 0.033419613 | K11: 0.040878126 | L11: 0.049753517 | M11: 0.060209991 | N11: 0.072364713 | O11: 0.086278513 | P11: 0.10337328 | Q11: 0.12254473 | R11: 0.14352035 | S11: 0.16606045 | T11: 0.18975975 | U11: 0.21395778 | V11: 0.23818071 | W11: 0.26180997 | X11: 0.28425247 | Y11: 0.30525285 | Z11: 0.32442965 | AA11: 0.34183012 | AB11: 0.35698073 | AC11: 0.37034765 | AD11: 0.38215586 | AE11: 0.39233734 | AF11: 0.40136924 | AG11: 0.40919866 | AH11: 0.41622293 | AI11: 0.42233918 | AJ11: 0.42796581 | AK11: 0.43293647 | AL11: 0.4376372 | AM11: 0.44186859 | AN11: 0.44583404 | AO11: 0.44975368 | AP11: 0.45255937
A12: rubber and plastic products 22 | B12: 0 | C12: 0 | D12: 0 | E12: 0 | F12: 0 | G12: 0 | H12: 0 | I12: 0 | J12: 0 | K12: 0 | L12: 0 | M12: 0 | N12: 0 | O12: 0 | P12: 0 | Q12: 0 | R12: 0 | S12: 0 | T12: 0 | U12: 0 | V12: 0 | W12: 0 | X12: 0 | Y12: 0 | Z12: 0 | AA12: 0 | AB12: 0 | AC12: 0 | AD12: 0 | AE12: 0 | AF12: 0 | AG12: 0 | AH12: 0 | AI12: 0 | AJ12: 0 | AK12: 0 | AL12: 0 | AM12: 0 | AN12: 0 | AO12: 0 | AP12: 0
... A28: Unit: dimensionless (fraction of potential achieved) | B28: 2020 | C28: 2021 | D28: 2022 | E28: 2023 | F28: 2024 | G28: 2025 | H28: 2026 | I28: 2027 | J28: 2028 | K28: 2029 | L28: 2030 | M28: 2031 | N28: 2032 | O28: 2033 | P28: 2034 | Q28: 2035 | R28: 2036 | S28: 2037 | T28: 2038 | U28: 2039 | V28: 2040 | W28: 2041 | X28: 2042 | Y28: 2043 | Z28: 2044 | AA28: 2045 | AB28: 2046 | AC28: 2047 | AD28: 2048 | AE28: 2049 | AF28: 2050 | AG28: 2051 | AH28: 2052 | AI28: 2053 | AJ28: 2054 | AK28: 2055 | AL28: 2056 | AM28: 2057 | AN28: 2058 | AO28: 2059 | AP28: 2060
A29: Unit: dimensionless (fraction of potential achieved)
A30: agriculture and forestry 01T03
A31: coal mining 05
A32: oil and gas extraction 06
A33: other mining and quarrying 07T08
A34: food beverage and tobacco 10T12
A35: textiles apparel and leather 13T15
A36: wood products 16
A37: pulp paper and printing 17T18
A38: refined petroleum and coke 19 | B38: =B10/$AP10 -> 0.0151638 | C38: =C10/$AP10 -> 0.018690542 | D38: =D10/$AP10 -> 0.02301824 | E38: =E10/$AP10 -> 0.025962883 | F38: =F10/$AP10 -> 0.031929787 | G38: =G10/$AP10 -> 0.039208677 | H38: =H10/$AP10 -> 0.04844959 | I38: =I10/$AP10 -> 0.060148933 | ... AP38: =AP10/$AP10 -> 1
A39: chemicals 20 | B39: =B11/$AP11 -> 0.0151638 | C39: =C11/$AP11 -> 0.018690542 | D39: =D11/$AP11 -> 0.02301824 | E39: =E11/$AP11 -> 0.025962883 | F39: =F11/$AP11 -> 0.031929787 | G39: =G11/$AP11 -> 0.039208677 | H39: =H11/$AP11 -> 0.04844959 | I39: =I11/$AP11 -> 0.060148933 | ... AP39: =AP11/$AP11 -> 1
A40: rubber and plastic products 22
A41: glass and glass products 231
A42: cement and other nonmetallic minerals 239 | B42: =B14/$AP14 -> 0 | C42: =C14/$AP14 -> 0 | D42: =D14/$AP14 -> 0 | E42: =E14/$AP14 -> 0 | F42: =F14/$AP14 -> 0 | G42: =G14/$AP14 -> 0 | H42: =H14/$AP14 -> 0 | I42: =I14/$AP14 -> 0 | ... AP42: =AP14/$AP14 -> 1
A43: iron and steel 241 | B43: =B15/$AP15 -> 0 | C43: =C15/$AP15 -> 0 | D43: =D15/$AP15 -> 0 | E43: =E15/$AP15 -> 0 | F43: =F15/$AP15 -> 0 | G43: =G15/$AP15 -> 0.005235439 | H43: =H15/$AP15 -> 0.0058559245 | I43: =I15/$AP15 -> 0.0073243389 | ... AP43: =AP15/$AP15 -> 1
A44: other metals 242
A45: metal products except machinery and vehicles 25
A46: computers and electronics 26
A47: appliances and electrical equipment 27
A48: other machinery 28
A49: road vehicles 29
A50: nonroad vehicles 30
A51: other manufacturing 31T33
A52: energy pipelines and gas processing 352T353
A53: water and waste 36T39
A54: construction 41T43

Sheet 工业过程渗透率
A1: Unit: dimensionless (fraction of potential achieved) | B1: 2020 | C1: 2021 | D1: 2022 | E1: 2023 | F1: 2024 | G1: 2025 | H1: 2026 | I1: 2027 | J1: 2028 | K1: 2029 | L1: 2030 | M1: 2031 | N1: 2032 | O1: 2033 | P1: 2034 | Q1: 2035 | R1: 2036 | S1: 2037 | T1: 2038 | U1: 2039 | V1: 2040 | W1: 2041 | X1: 2042 | Y1: 2043 | Z1: 2044 | AA1: 2045 | AB1: 2046 | AC1: 2047 | AD1: 2048 | AE1: 2049 | AF1: 2050 | AG1: 2051 | AH1: 2052 | AI1: 2053 | AJ1: 2054 | AK1: 2055 | AL1: 2056 | AM1: 2057 | AN1: 2058 | AO1: 2059 | AP1: 2060
A2: agriculture and forestry 01T03 | B2: 0 | C2: 0 | D2: 0 | E2: 0 | F2: 0 | G2: 0 | H2: 0 | I2: 0 | J2: 0 | K2: 0 | L2: 0 | M2: 0 | N2: 0 | O2: 0 | P2: 0 | Q2: 0 | R2: 0 | S2: 0 | T2: 0 | U2: 0 | V2: 0 | W2: 0 | X2: 0 | Y2: 0 | Z2: 0 | AA2: 0 | AB2: 0 | AC2: 0 | AD2: 0 | AE2: 0 | AF2: 0 | AG2: 0 | AH2: 0 | AI2: 0 | AJ2: 0 | AK2: 0 | AL2: 0 | AM2: 0 | AN2: 0 | AO2: 0 | AP2: 0
A3: coal mining 05 | B3: 0 | C3: 0 | D3: 0 | E3: 0 | F3: 0 | G3: 0 | H3: 0 | I3: 0 | J3: 0 | K3: 0 | L3: 0 | M3: 0 | N3: 0 | O3: 0 | P3: 0 | Q3: 0 | R3: 0 | S3: 0 | T3: 0 | U3: 0 | V3: 0 | W3: 0 | X3: 0 | Y3: 0 | Z3: 0 | AA3: 0 | AB3: 0 | AC3: 0 | AD3: 0 | AE3: 0 | AF3: 0 | AG3: 0 | AH3: 0 | AI3: 0 | AJ3: 0 | AK3: 0 | AL3: 0 | AM3: 0 | AN3: 0 | AO3: 0 | AP3: 0
A4: oil and gas extraction 06 | B4: 0 | C4: 0 | D4: 0 | E4: 0 | F4: 0 | G4: 0 | H4: 0 | I4: 0 | J4: 0 | K4: 0 | L4: 0 | M4: 0 | N4: 0 | O4: 0 | P4: 0 | Q4: 0 | R4: 0 | S4: 0 | T4: 0 | U4: 0 | V4: 0 | W4: 0 | X4: 0 | Y4: 0 | Z4: 0 | AA4: 0 | AB4: 0 | AC4: 0 | AD4: 0 | AE4: 0 | AF4: 0 | AG4: 0 | AH4: 0 | AI4: 0 | AJ4: 0 | AK4: 0 | AL4: 0 | AM4: 0 | AN4: 0 | AO4: 0 | AP4: 0
A5: other mining and quarrying 07T08 | B5: 0 | C5: 0 | D5: 0 | E5: 0 | F5: 0 | G5: 0 | H5: 0 | I5: 0 | J5: 0 | K5: 0 | L5: 0 | M5: 0 | N5: 0 | O5: 0 | P5: 0 | Q5: 0 | R5: 0 | S5: 0 | T5: 0 | U5: 0 | V5: 0 | W5: 0 | X5: 0 | Y5: 0 | Z5: 0 | AA5: 0 | AB5: 0 | AC5: 0 | AD5: 0 | AE5: 0 | AF5: 0 | AG5: 0 | AH5: 0 | AI5: 0 | AJ5: 0 | AK5: 0 | AL5: 0 | AM5: 0 | AN5: 0 | AO5: 0 | AP5: 0
A6: food beverage and tobacco 10T12 | B6: 0 | C6: 0 | D6: 0 | E6: 0 | F6: 0 | G6: 0 | H6: 0 | I6: 0 | J6: 0 | K6: 0 | L6: 0 | M6: 0 | N6: 0 | O6: 0 | P6: 0 | Q6: 0 | R6: 0 | S6: 0 | T6: 0 | U6: 0 | V6: 0 | W6: 0 | X6: 0 | Y6: 0 | Z6: 0 | AA6: 0 | AB6: 0 | AC6: 0 | AD6: 0 | AE6: 0 | AF6: 0 | AG6: 0 | AH6: 0 | AI6: 0 | AJ6: 0 | AK6: 0 | AL6: 0 | AM6: 0 | AN6: 0 | AO6: 0 | AP6: 0
A7: textiles apparel and leather 13T15 | B7: 0 | C7: 0 | D7: 0 | E7: 0 | F7: 0 | G7: 0 | H7: 0 | I7: 0 | J7: 0 | K7: 0 | L7: 0 | M7: 0 | N7: 0 | O7: 0 | P7: 0 | Q7: 0 | R7: 0 | S7: 0 | T7: 0 | U7: 0 | V7: 0 | W7: 0 | X7: 0 | Y7: 0 | Z7: 0 | AA7: 0 | AB7: 0 | AC7: 0 | AD7: 0 | AE7: 0 | AF7: 0 | AG7: 0 | AH7: 0 | AI7: 0 | AJ7: 0 | AK7: 0 | AL7: 0 | AM7: 0 | AN7: 0 | AO7: 0 | AP7: 0
A8: wood products 16 | B8: 0 | C8: 0 | D8: 0 | E8: 0 | F8: 0 | G8: 0 | H8: 0 | I8: 0 | J8: 0 | K8: 0 | L8: 0 | M8: 0 | N8: 0 | O8: 0 | P8: 0 | Q8: 0 | R8: 0 | S8: 0 | T8: 0 | U8: 0 | V8: 0 | W8: 0 | X8: 0 | Y8: 0 | Z8: 0 | AA8: 0 | AB8: 0 | AC8: 0 | AD8: 0 | AE8: 0 | AF8: 0 | AG8: 0 | AH8: 0 | AI8: 0 | AJ8: 0 | AK8: 0 | AL8: 0 | AM8: 0 | AN8: 0 | AO8: 0 | AP8: 0
A9: pulp paper and printing 17T18 | B9: 0 | C9: 0 | D9: 0 | E9: 0 | F9: 0 | G9: 0 | H9: 0 | I9: 0 | J9: 0 | K9: 0 | L9: 0 | M9: 0 | N9: 0 | O9: 0 | P9: 0 | Q9: 0 | R9: 0 | S9: 0 | T9: 0 | U9: 0 | V9: 0 | W9: 0 | X9: 0 | Y9: 0 | Z9: 0 | AA9: 0 | AB9: 0 | AC9: 0 | AD9: 0 | AE9: 0 | AF9: 0 | AG9: 0 | AH9: 0 | AI9: 0 | AJ9: 0 | AK9: 0 | AL9: 0 | AM9: 0 | AN9: 0 | AO9: 0 | AP9: 0
A10: refined petroleum and coke 19 | B10: 0 | C10: 0 | D10: 0 | E10: 0 | F10: 0 | G10: 0 | H10: 0 | I10: 0 | J10: 0 | K10: 0 | L10: 0 | M10: 0 | N10: 0 | O10: 0 | P10: 0 | Q10: 0 | R10: 0 | S10: 0 | T10: 0 | U10: 0 | V10: 0 | W10: 0 | X10: 0 | Y10: 0 | Z10: 0 | AA10: 0 | AB10: 0 | AC10: 0 | AD10: 0 | AE10: 0 | AF10: 0 | AG10: 0 | AH10: 0 | AI10: 0 | AJ10: 0 | AK10: 0 | AL10: 0 | AM10: 0 | AN10: 0 | AO10: 0 | AP10: 0
A11: chemicals 20 | B11: 0.0014961 | C11: 0.00184927 | D11: 0.00228393 | E11: 0.0016080355 | F11: 0.002307143 | G11: 0.0031382469 | H11: 0.0041735787 | I11: 0.0054665608 | J11: 0.0069779432 | K11: 0.0087844396 | L11: 0.010913141 | M11: 0.013466052 | N11: 0.016444248 | O11: 0.019835551 | P11: 0.023779099 | Q11: 0.028153389 | R11: 0.033031426 | S11: 0.03822671 | T11: 0.043652069 | U11: 0.049129563 | V11: 0.05457269 | W11: 0.059927937 | X11: 0.065069812 | Y11: 0.069790602 | Z11: 0.074087044 | AA11: 0.077937555 | AB11: 0.0814204 | AC11: 0.084548174 | AD11: 0.087177354 | AE11: 0.089505655 | AF11: 0.091610342 | AG11: 0.093405314 | AH11: 0.095046714 | AI11: 0.096433215 | AJ11: 0.097749793 | AK11: 0.098883537 | AL11: 0.09992964 | AM11: 0.1009425 | AN11: 0.10182606 | AO11: 0.10274842 | AP11: 0.10337113
A12: rubber and plastic products 22 | B12: 0 | C12: 0 | D12: 0 | E12: 0 | F12: 0 | G12: 0 | H12: 0 | I12: 0 | J12: 0 | K12: 0 | L12: 0 | M12: 0 | N12: 0 | O12: 0 | P12: 0 | Q12: 0 | R12: 0 | S12: 0 | T12: 0 | U12: 0 | V12: 0 | W12: 0 | X12: 0 | Y12: 0 | Z12: 0 | AA12: 0 | AB12: 0 | AC12: 0 | AD12: 0 | AE12: 0 | AF12: 0 | AG12: 0 | AH12: 0 | AI12: 0 | AJ12: 0 | AK12: 0 | AL12: 0 | AM12: 0 | AN12: 0 | AO12: 0 | AP12: 0
... A30: Unit: dimensionless (fraction of potential achieved) | B30: 2020 | C30: 2021 | D30: 2022 | E30: 2023 | F30: 2024 | G30: 2025 | H30: 2026 | I30: 2027 | J30: 2028 | K30: 2029 | L30: 2030 | M30: 2031 | N30: 2032 | O30: 2033 | P30: 2034 | Q30: 2035 | R30: 2036 | S30: 2037 | T30: 2038 | U30: 2039 | V30: 2040 | W30: 2041 | X30: 2042 | Y30: 2043 | Z30: 2044 | AA30: 2045 | AB30: 2046 | AC30: 2047 | AD30: 2048 | AE30: 2049 | AF30: 2050 | AG30: 2051 | AH30: 2052 | AI30: 2053 | AJ30: 2054 | AK30: 2055 | AL30: 2056 | AM30: 2057 | AN30: 2058 | AO30: 2059 | AP30: 2060
A31: agriculture and forestry 01T03
A32: coal mining 05
A33: oil and gas extraction 06
A34: other mining and quarrying 07T08
A35: food beverage and tobacco 10T12
A36: textiles apparel and leather 13T15
A37: wood products 16
A38: pulp paper and printing 17T18
A39: refined petroleum and coke 19
A40: chemicals 20 | B40: =B11/$AP11 -> 0.014473094 | C40: =C11/$AP11 -> 0.017889618 | D40: =D11/$AP11 -> 0.022094468 | E40: =E11/$AP11 -> 0.015555945 | F40: =F11/$AP11 -> 0.022319027 | G40: =G11/$AP11 -> 0.030359028 | H40: =H11/$AP11 -> 0.040374704 | I40: =I11/$AP11 -> 0.05288286 | ... AP40: =AP11/$AP11 -> 1
A41: rubber and plastic products 22
A42: glass and glass products 231
A43: cement and other nonmetallic minerals 239 | B43: =B14/$AP14 -> 0 | C43: =C14/$AP14 -> 0 | D43: =D14/$AP14 -> 0 | E43: =E14/$AP14 -> 0 | F43: =F14/$AP14 -> 0 | G43: =G14/$AP14 -> 0 | H43: =H14/$AP14 -> 0 | I43: =I14/$AP14 -> 0 | ... AP43: =AP14/$AP14 -> 1
A44: iron and steel 241 | B44: =B15/$AP15 -> 0 | C44: =C15/$AP15 -> 0 | D44: =D15/$AP15 -> 0 | E44: =E15/$AP15 -> 0 | F44: =F15/$AP15 -> 0 | G44: =G15/$AP15 -> 0.004942674 | H44: =H15/$AP15 -> 0.0056847644 | I44: =I15/$AP15 -> 0.0072534268 | ... AP44: =AP15/$AP15 -> 1
A45: other metals 242
A46: metal products except machinery and vehicles 25
A47: computers and electronics 26
A48: appliances and electrical equipment 27
A49: other machinery 28
A50: road vehicles 29
A51: nonroad vehicles 30
A52: other manufacturing 31T33
A53: energy pipelines and gas processing 352T353 | B53: =B24/$AP24 -> 0.037750567 | C53: =C24/$AP24 -> 0.041750503 | D53: =D24/$AP24 -> 0.046162647 | E53: =E24/$AP24 -> 0.051026904 | F53: =F24/$AP24 -> 0.056386476 | G53: =G24/$AP24 -> 0.062288006 | H53: =H24/$AP24 -> 0.068781702 | I53: =I24/$AP24 -> 0.075921423 | ... AP53: =AP24/$AP24 -> 1
A54: water and waste 36T39
A55: construction 41T43

Sheet 电力渗透率
A1: Unit: dimensionless (fraction of potential achieved) | B1: 2020 | C1: 2021 | D1: 2022 | E1: 2023 | F1: 2024 | G1: 2025 | H1: 2026 | I1: 2027 | J1: 2028 | K1: 2029 | L1: 2030 | M1: 2031 | N1: 2032 | O1: 2033 | P1: 2034 | Q1: 2035 | R1: 2036 | S1: 2037 | T1: 2038 | U1: 2039 | V1: 2040 | W1: 2041 | X1: 2042 | Y1: 2043 | Z1: 2044 | AA1: 2045 | AB1: 2046 | AC1: 2047 | AD1: 2048 | AE1: 2049 | AF1: 2050 | AG1: 2051 | AH1: 2052 | AI1: 2053 | AJ1: 2054 | AK1: 2055 | AL1: 2056 | AM1: 2057 | AN1: 2058 | AO1: 2059 | AP1: 2060
A2: hard coal | B2: 0 | C2: 0 | D2: 0 | E2: 0 | F2: 0 | G2: 0 | H2: 0.0039536237 | I2: 0.0089321928 | J2: 0.017822072 | K2: 0.024576802 | L2: 0.033521495 | M2: 0.045303045 | N2: 0.060712441 | O2: 0.080682479 | P2: 0.10625706 | Q2: 0.13851495 | R2: 0.17843149 | S2: 0.22667167 | T2: 0.28333403 | U2: 0.34770441 | V2: 0.4181167 | W2: 0.49202123 | X2: 0.56630315 | Y2: 0.63778415 | Z2: 0.70374583 | AA2: 0.76230101 | AB2: 0.81252008 | AC2: 0.85433217 | AD2: 0.88829414 | AE2: 0.91532989 | AF2: 0.93650901 | AG2: 0.95289237 | AH2: 0.96544276 | AI2: 0.97498519 | AJ2: 0.98219936 | AK2: 0.98762986 | AL2: 0.99170445 | AM2: 0.99475424 | AN2: 0.99703281 | AO2: 0.99873287 | AP2: 1
A3: natural gas nonpeaker | B3: 0 | C3: 0 | D3: 0 | E3: 0 | F3: 0 | G3: 0 | H3: 0 | I3: 0 | J3: 0 | K3: 0 | L3: 0 | M3: 0.00070209845 | N3: 0.012043304 | O3: 0.026430789 | P3: 0.044550532 | Q3: 0.067162848 | R3: 0.095061565 | S3: 0.12900217 | T3: 0.16959415 | U3: 0.21716142 | V3: 0.27158912 | W3: 0.33219324 | X3: 0.39766177 | Y3: 0.46611162 | Z3: 0.53527668 | AA3: 0.60279522 | AB3: 0.66652346 | AC3: 0.72479032 | AD3: 0.77653426 | AE3: 0.82131008 | AF3: 0.85919552 | AG3: 0.89064643 | AH3: 0.91634559 | AI3: 0.93707462 | AJ3: 0.95362072 | AK3: 0.96671802 | AL3: 0.97701695 | AM3: 0.98507331 | AN3: 0.99134975 | AO3: 0.99622401 | AP3: 1
A4: nuclear (NOT USED) | B4: 0 | C4: 0 | D4: 0 | E4: 0 | F4: 0 | G4: 0 | H4: 0 | I4: 0 | J4: 0 | K4: 0 | L4: 0 | M4: 0 | N4: 0 | O4: 0 | P4: 0 | Q4: 0 | R4: 0 | S4: 0 | T4: 0 | U4: 0 | V4: 0 | W4: 0 | X4: 0 | Y4: 0 | Z4: 0 | AA4: 0 | AB4: 0 | AC4: 0 | AD4: 0 | AE4: 0 | AF4: 0 | AG4: 0 | AH4: 0 | AI4: 0 | AJ4: 0 | AK4: 0 | AL4: 0 | AM4: 0 | AN4: 0 | AO4: 0 | AP4: 0
A5: hydro (NOT USED) | B5: 0 | C5: 0 | D5: 0 | E5: 0 | F5: 0 | G5: 0 | H5: 0 | I5: 0 | J5: 0 | K5: 0 | L5: 0 | M5: 0 | N5: 0 | O5: 0 | P5: 0 | Q5: 0 | R5: 0 | S5: 0 | T5: 0 | U5: 0 | V5: 0 | W5: 0 | X5: 0 | Y5: 0 | Z5: 0 | AA5: 0 | AB5: 0 | AC5: 0 | AD5: 0 | AE5: 0 | AF5: 0 | AG5: 0 | AH5: 0 | AI5: 0 | AJ5: 0 | AK5: 0 | AL5: 0 | AM5: 0 | AN5: 0 | AO5: 0 | AP5: 0
A6: onshore wind (NOT USED) | B6: 0 | C6: 0 | D6: 0 | E6: 0 | F6: 0 | G6: 0 | H6: 0 | I6: 0 | J6: 0 | K6: 0 | L6: 0 | M6: 0 | N6: 0 | O6: 0 | P6: 0 | Q6: 0 | R6: 0 | S6: 0 | T6: 0 | U6: 0 | V6: 0 | W6: 0 | X6: 0 | Y6: 0 | Z6: 0 | AA6: 0 | AB6: 0 | AC6: 0 | AD6: 0 | AE6: 0 | AF6: 0 | AG6: 0 | AH6: 0 | AI6: 0 | AJ6: 0 | AK6: 0 | AL6: 0 | AM6: 0 | AN6: 0 | AO6: 0 | AP6: 0
A7: solar PV (NOT USED) | B7: 0 | C7: 0 | D7: 0 | E7: 0 | F7: 0 | G7: 0 | H7: 0 | I7: 0 | J7: 0 | K7: 0 | L7: 0 | M7: 0 | N7: 0 | O7: 0 | P7: 0 | Q7: 0 | R7: 0 | S7: 0 | T7: 0 | U7: 0 | V7: 0 | W7: 0 | X7: 0 | Y7: 0 | Z7: 0 | AA7: 0 | AB7: 0 | AC7: 0 | AD7: 0 | AE7: 0 | AF7: 0 | AG7: 0 | AH7: 0 | AI7: 0 | AJ7: 0 | AK7: 0 | AL7: 0 | AM7: 0 | AN7: 0 | AO7: 0 | AP7: 0
A8: solar thermal (NOT USED) | B8: 0 | C8: 0 | D8: 0 | E8: 0 | F8: 0 | G8: 0 | H8: 0 | I8: 0 | J8: 0 | K8: 0 | L8: 0 | M8: 0 | N8: 0 | O8: 0 | P8: 0 | Q8: 0 | R8: 0 | S8: 0 | T8: 0 | U8: 0 | V8: 0 | W8: 0 | X8: 0 | Y8: 0 | Z8: 0 | AA8: 0 | AB8: 0 | AC8: 0 | AD8: 0 | AE8: 0 | AF8: 0 | AG8: 0 | AH8: 0 | AI8: 0 | AJ8: 0 | AK8: 0 | AL8: 0 | AM8: 0 | AN8: 0 | AO8: 0 | AP8: 0
A9: biomass | B9: 0 | C9: 0 | D9: 0 | E9: 0 | F9: 0 | G9: 0 | H9: 0.010392074 | I9: 0.026436402 | J9: 0.043467414 | K9: 0.061399988 | L9: 0.080149002 | M9: 0.099629332 | N9: 0.11975586 | O9: 0.14044345 | P9: 0.161607 | Q9: 0.18316137 | R9: 0.20502145 | S9: 0.2271021 | T9: 0.24931822 | U9: 0.27158467 | V9: 0.29381633 | W9: 0.31592808 | X9: 0.3378348 | Y9: 0.35945137 | Z9: 0.38069266 | AA9: 0.40147355 | AB9: 0.42170891 | AC9: 0.44131363 | AD9: 0.46020258 | AE9: 0.47829064 | AF9: 0.49549269 | AG9: 0.5117236 | AH9: 0.52689825 | AI9: 0.54093152 | AJ9: 0.55373829 | AK9: 0.56523343 | AL9: 0.57533182 | AM9: 0.58394834 | AN9: 0.59099786 | AO9: 0.59639527 | AP9: 0.60005543
A10: geothermal (NOT USED) | B10: 0 | C10: 0 | D10: 0 | E10: 0 | F10: 0 | G10: 0 | H10: 0 | I10: 0 | J10: 0 | K10: 0 | L10: 0 | M10: 0 | N10: 0 | O10: 0 | P10: 0 | Q10: 0 | R10: 0 | S10: 0 | T10: 0 | U10: 0 | V10: 0 | W10: 0 | X10: 0 | Y10: 0 | Z10: 0 | AA10: 0 | AB10: 0 | AC10: 0 | AD10: 0 | AE10: 0 | AF10: 0 | AG10: 0 | AH10: 0 | AI10: 0 | AJ10: 0 | AK10: 0 | AL10: 0 | AM10: 0 | AN10: 0 | AO10: 0 | AP10: 0
A11: petroleum | B11: 0 | C11: 0 | D11: 0 | E11: 0 | F11: 0 | G11: 0 | H11: 0 | I11: 0 | J11: 0 | K11: 0 | L11: 0 | M11: 0 | N11: 0 | O11: 0 | P11: 0 | Q11: 0 | R11: 0 | S11: 0 | T11: 0 | U11: 0 | V11: 0 | W11: 0 | X11: 0 | Y11: 0 | Z11: 0 | AA11: 0 | AB11: 0 | AC11: 0 | AD11: 0 | AE11: 0 | AF11: 0 | AG11: 0 | AH11: 0 | AI11: 0 | AJ11: 0 | AK11: 0 | AL11: 0 | AM11: 0 | AN11: 0 | AO11: 0 | AP11: 0
A12: natural gas peaker | B12: 0 | C12: 0 | D12: 0 | E12: 0 | F12: 0 | G12: 0 | H12: 0 | I12: 0 | J12: 0 | K12: 0 | L12: 0 | M12: 0.00070209845 | N12: 0.012043304 | O12: 0.026430789 | P12: 0.044550532 | Q12: 0.067162848 | R12: 0.095061565 | S12: 0.12900217 | T12: 0.16959415 | U12: 0.21716142 | V12: 0.27158912 | W12: 0.33219324 | X12: 0.39766177 | Y12: 0.46611162 | Z12: 0.53527668 | AA12: 0.60279522 | AB12: 0.66652346 | AC12: 0.72479032 | AD12: 0.77653426 | AE12: 0.82131008 | AF12: 0.85919552 | AG12: 0.89064643 | AH12: 0.91634559 | AI12: 0.93707462 | AJ12: 0.95362072 | AK12: 0.96671802 | AL12: 0.97701695 | AM12: 0.98507331 | AN12: 0.99134975 | AO12: 0.99622401 | AP12: 1
... A17: municipal solid waste | B17: 0 | C17: 0 | D17: 0 | E17: 0 | F17: 0 | G17: 0 | H17: 0.010392074 | I17: 0.026436402 | J17: 0.043467414 | K17: 0.061399988 | L17: 0.080149002 | M17: 0.099629332 | N17: 0.11975586 | O17: 0.14044345 | P17: 0.161607 | Q17: 0.18316137 | R17: 0.20502145 | S17: 0.2271021 | T17: 0.24931822 | U17: 0.27158467 | V17: 0.29381633 | W17: 0.31592808 | X17: 0.3378348 | Y17: 0.35945137 | Z17: 0.38069266 | AA17: 0.40147355 | AB17: 0.42170891 | AC17: 0.44131363 | AD17: 0.46020258 | AE17: 0.47829064 | AF17: 0.49549269 | AG17: 0.5117236 | AH17: 0.52689825 | AI17: 0.54093152 | AJ17: 0.55373829 | AK17: 0.56523343 | AL17: 0.57533182 | AM17: 0.58394834 | AN17: 0.59099786 | AO17: 0.59639527 | AP17: 0.60005543
A21: Data source | E21: https://doi.org/10.1016/j.ccst.2023.100112 | K21: Obtain the pathway data for achieving 2030 peak emissions.
E23: 2020 | F23: 2025 | G23: 2030 | H23: 2035 | I23: 2040 | J23: 2045 | K23: 2050 | L23: 2055 | M23: 2060
D24: Coal | E24: 1079.1 | F24: 1215.7 | G24: 1227 | H24: 1036.1 | I24: 699.3 | J24: 198.1 | K24: 0 | L24: 0 | M24: 0
D25: Gas | E25: 99.7 | F25: 139.4 | G25: 188.8 | H25: 220.3 | I25: 231.5 | J25: 161.1 | K25: 48.1 | L25: 0 | M25: 0
D26: Nuclear | E26: 49.8 | F26: 72.5 | G26: 92.7 | H26: 122.4 | I26: 151.2 | J26: 182.6 | K26: 216.6 | L26: 253.2 | M26: 288.7
D27: Hydro | E27: 370.2 | F27: 418.2 | G27: 480.7 | H27: 571.2 | I27: 638 | J27: 698.4 | K27: 752.3 | L27: 799.7 | M27: 794
D28: Wind | E28: 281.6 | F28: 404.3 | G28: 583.7 | H28: 816 | I28: 1086.9 | J28: 1396.8 | K28: 1745.3 | L28: 2066 | M28: 2310
D29: Solar PV | E29: 253.5 | F29: 432.2 | G29: 618.1 | H29: 897.6 | I29: 1181.5 | J29: 1504.2 | K29: 1805.5 | L29: 2132.7 | M29: 2526.6
D30: Biomass | E30: 26.9 | F30: 83.6 | G30: 95.8 | H30: 104.4 | I30: 109.1 | J30: 109.5 | K30: 105.3 | L30: 98.6 | M30: 144.3
D31: Coal CCS | E31: 0 | F31: 0 | G31: 136.3 | H31: 259 | I31: 466.2 | J31: 792.6 | K31: 792.6 | L31: 594.4 | M31: 416.1
D32: NGCCS | E32: 0 | F32: 0 | G32: 0 | H32: 24.4 | I32: 99.2 | J32: 241.7 | K32: 433.3 | L32: 546.5 | M32: 454.7
D33: BECCS | E33: 0 | F33: 0 | G33: 10.6 | H33: 26.1 | I33: 46.7 | J33: 73 | K33: 105.3 | L33: 147.9 | M33: 216.5
D35: 百分比
E36: 2020 | F36: 2025 | G36: 2030 | H36: 2035 | I36: 2040 | J36: 2045 | K36: 2050 | L36: 2055 | M36: 2060
D37: Coal CCS | E37: =E31/SUM(E24+E31) -> 0 | F37: =F31/SUM(F24+F31) -> 0 | G37: =G31/SUM(G24+G31) -> 0.099977995 | H37: =H31/SUM(H24+H31) -> 0.19998456 | I37: =I31/SUM(I24+I31) -> 0.4 | J37: =J31/SUM(J24+J31) -> 0.80004038 | K37: =K31/SUM(K24+K31) -> 1 | L37: =L31/SUM(L24+L31) -> 1 | M37: =M31/SUM(M24+M31) -> 1
D38: NGCCS | E38: =E32/SUM(E25+E32) -> 0 | F38: =F32/SUM(F25+F32) -> 0 | G38: =G32/SUM(G25+G32) -> 0 | H38: =H32/SUM(H25+H32) -> 0.099713935 | I38: =I32/SUM(I25+I32) -> 0.29996976 | J38: =J32/SUM(J25+J32) -> 0.60004965 | K38: =K32/SUM(K25+K32) -> 0.90008309 | L38: =L32/SUM(L25+L32) -> 1 | M38: =M32/SUM(M25+M32) -> 1
D39: BECCS | E39: =E33/SUM(E30,E33) -> 0 | F39: =F33/SUM(F30,F33) -> 0 | G39: =G33/SUM(G30,G33) -> 0.09962406 | H39: =H33/SUM(H30,H33) -> 0.2 | I39: =I33/SUM(I30,I33) -> 0.29974326 | J39: =J33/SUM(J30,J33) -> 0.4 | K39: =K33/SUM(K30,K33) -> 0.5 | L39: =L33/SUM(L30,L33) -> 0.6 | M39: =M33/SUM(M30,M33) -> 0.60005543
D41: waste adopts same as BECCS | H41: https://iopscience.iop.org/article/10.1088/1755-1315/1108/1/012030/meta
A45: Unit: dimensionless (fraction of potential achieved) | B45: 2020 | C45: 2021 | D45: 2022 | E45: 2023 | F45: 2024 | G45: 2025 | H45: 2026 | I45: 2027 | J45: 2028 | K45: 2029 | L45: 2030 | M45: 2031 | N45: 2032 | O45: 2033 | P45: 2034 | Q45: 2035 | R45: 2036 | S45: 2037 | T45: 2038 | U45: 2039 | V45: 2040 | W45: 2041 | X45: 2042 | Y45: 2043 | Z45: 2044 | AA45: 2045 | AB45: 2046 | AC45: 2047 | AD45: 2048 | AE45: 2049 | AF45: 2050 | AG45: 2051 | AH45: 2052 | AI45: 2053 | AJ45: 2054 | AK45: 2055 | AL45: 2056 | AM45: 2057 | AN45: 2058 | AO45: 2059 | AP45: 2060
A46: hard coal | H46: =H2/$AP2 -> 0.0039536237 | I46: =I2/$AP2 -> 0.0089321928 | J46: =J2/$AP2 -> 0.017822072 | K46: =K2/$AP2 -> 0.024576802 | L46: =L2/$AP2 -> 0.033521495 | M46: =M2/$AP2 -> 0.045303045 | N46: =N2/$AP2 -> 0.060712441 | O46: =O2/$AP2 -> 0.080682479 | ... AP46: =AP2/$AP2 -> 1
A47: natural gas nonpeaker | H47: =H3/$AP3 -> 0 | I47: =I3/$AP3 -> 0 | J47: =J3/$AP3 -> 0 | K47: =K3/$AP3 -> 0 | L47: =L3/$AP3 -> 0 | M47: =M3/$AP3 -> 0.00070209845 | N47: =N3/$AP3 -> 0.012043304 | O47: =O3/$AP3 -> 0.026430789 | ... AP47: =AP3/$AP3 -> 1
A48: nuclear (NOT USED)
A49: hydro (NOT USED)
A50: onshore wind (NOT USED)
A51: solar PV (NOT USED)
A52: solar thermal (NOT USED)
A53: biomass | H53: =H9/$AP9 -> 0.017318524 | I53: =I9/$AP9 -> 0.044056599 | J53: =J9/$AP9 -> 0.072438997 | K53: =K9/$AP9 -> 0.10232386 | L53: =L9/$AP9 -> 0.13356933 | M53: =M9/$AP9 -> 0.16603355 | N53: =N9/$AP9 -> 0.19957466 | O53: =O9/$AP9 -> 0.2340508 | ... AP53: =AP9/$AP9 -> 1
...

Sheet 资本成本
C1: Capital cost ($/(metric ton CO2e*yr))
A2: electricity sector | B2: nature gas | C2: =E36 -> 819.50482
B3: coal | C3: =E26 -> 228.48348
B4: waste | C4: =E55 -> 808.33333
B5: biomass | C5: =E46 -> 410.12006
A6: industry-fuel | B6: refined petroleum and coke | C6: =C66*J67 -> 78
B7: chemicals | C7: =C10/2 -> 29.842005
B8: cement and other nonmetallic minerals | C8: =F78 -> 107.27969
B9: iron and steel | C9: =71 -> 71
A10: industry-process | B10: chemicals | C10: =D71 -> 59.684011
B11: cement and other nonmetallic minerals | C11: =F77 -> 84.899813
B12: iron and steel | C12: =E61 -> 95.598217
B13: energy pipelines and gas processing | C13: =E88 -> 26.964
A18: Data Source | C18: https://github.com/remindmodel/remind | D18: generisdata_emi.prn | G18: generisdata_tech.prn
C19: https://pubs.acs.org/doi/full/10.1021/acs.est.1c01144 | G19: Supporting information
C20: https://doi.org/10.1016/j.jclepro.2022.131384 | G20: Table1 | H20: TableA2 | I20: TableA3
B23: coal
B24: Capacity | C24: 1000 | D24: MW | E24: total cost | G24: From 2020 $ to 2012
B25: Total CO2 | C25: 838 | D25: g/kWh | E25: =C24*10^3*(C29+C28)*0.88 -> 763215200 | G25: 0.88
B26: Capture | C26: =C24*1000*C30*C25*C27/10^6/10^6 -> 3.3403518 | D26: Mt/a | E26: =E25/C26/10^6 -> 228.48348 | G26: https://stats.areppim.com/calc/calc_usdlrxdeflator.php
B27: capture rate | C27: 0.9
B28: Initial investment | C28: 496.02 | D28: $/kW
B29: Initial capture cost | C29: 371.27 | D29: $/kW
B30: Operation hour | C30: 4429 | D30: h
B33: nature gas
B34: Capacity | C34: 1000 | D34: MW | E34: total cost
B35: Total CO2 | C35: 428 | D35: g/kWh | E35: =C34*10^3*(C39+C38)*0.88 -> 837091200
B36: Capture | C36: =C34*1000*C40*C35*C37/10^6/10^6 -> 1.0214598 | D36: Mt/a | E36: =E35/C36/10^6 -> 819.50482
B37: capture rate | C37: =13.8/15.3 -> 0.90196078
B38: Initial investment | C38: 387.98 | D38: $/kW
B39: Initial capture cost | C39: 563.26 | D39: $/kW
B40: Operation hour | C40: 2646 | D40: h
B43: biomass
B44: Capacity | C44: 1000 | D44: MW | E44: total cost
B45: Total CO2 | C45: 838 | D45: g/kWh | E45: =C44*10^3*(C49+C48)*0.88 -> 1969633600
B46: Capture | C46: =C44*1000*C50*C45*C47/10^6/10^6 -> 4.802578 | D46: Mt/a | E46: =E45/C46/10^6 -> 410.12006
B47: capture rate | C47: =1 -> 1
B48: Initial investment | C48: 1674.96 | D48: $/kW
B49: Initial capture cost | C49: 563.26 | D49: $/kW
B50: Operation hour | C50: 5731 | D50: h
...

Sheet 运维成本
C1: O&M Cost per Ton ($/metric ton CO2e)
A2: electricity sector | B2: nature gas | C2: =F2/[1]资本成本!E40*0.88 -> 21.244552 | D2: 0.05 | E2: {=SUMPRODUCT(C2:C5,D2:D5)} -> 9.5909926 | F2: =(16.43+10.91)*10^6 -> 27340000
B3: coal | C3: =F3/[1]资本成本!E30*0.88 -> 8.9481832 | D3: 0.94 | F3: =(20.62+17.12)*10^6 -> 37740000
B4: waste | C4: =29*[1]资本成本!G57*[1]资本成本!C57 -> 10.9707 | D4: 0.002
B5: biomass | C5: =F5/[1]资本成本!E50*0.88 -> 11.94142 | D5: 0.008 | F5: =(54.26+10.91)*10^6 -> 65170000
A6: industry-fuel | B6: refined petroleum and coke
B7: chemicals
B8: cement and other nonmetallic minerals
B9: iron and steel | C9: =(14+58.63)/360*[1]资本成本!C9 -> 14.32425
A10: industry-process | B10: chemicals
B11: cement and other nonmetallic minerals | C11: =8.9/[1]资本成本!C82*[1]资本成本!F77 -> 5.9826472
B12: iron and steel
B13: energy pipelines and gas processing
A16: industry | C16: =C9*1/3+C11*2/3 -> 8.7631814

Sheet 能源消耗
C1: Energy Use per Ton Sequestered (BTU/metric ton CO2e)
A2: electricity sector | B2: nature gas | C2: =C35 -> 228804.85 | D2: 0.05 | E2: {=SUMPRODUCT(C2:C5,D2:D5)} -> 246048.59
B3: coal | C3: =C26 -> 244713.29 | D3: 0.94
B4: waste | C4: =C53 -> 432204.65 | D4: 0.002
B5: biomass | C5: =C44 -> 464181.61 | D5: 0.008
A6: industry-fuel | B6: refined petroleum and coke
B7: chemicals
B8: cement and other nonmetallic minerals
B9: iron and steel | C9: =C63 -> 484524.16
A10: industry-process | B10: chemicals
B11: cement and other nonmetallic minerals | C11: =C59 -> 924978.25
B12: iron and steel
B13: energy pipelines and gas processing
C15: =C9*1/3+C11*2/3 -> 778160.22
B18: coal | E18: https://www.ipcc.ch/site/assets/uploads/2018/03/srccs_spm_ts_cn-1.pdf
B19: 自用率 | C19: 0.0601
B20: 排放因子 | C20: 838 | D20: g/kwh
B21: 发电量 | C21: =资本成本!C24*资本成本!C30*10^3 -> 4429000000 | D21: kwh
B22: 总排放 | C22: =C20*C21/10^6 -> 3711502 | D22: t
B23: 电力需求 | C23: =C21*C19 -> 266182900 | D23: kwh
B24: 需要能量 | C24: =C23/C22 -> 71.718377 | D24: kwh/t
B25: 1kwh | C25: 3412.142 | D25: BTU
C26: =C25*C24 -> 244713.29
B28: nature gas
B29: 自用率 | C29: 0.0287
B30: 排放因子 | C30: 428
B31: 发电量 | C31: =资本成本!C34*资本成本!C40*10^3 -> 2646000000
B32: 总排放 | C32: =C31*资本成本!C35/10^6 -> 1132488
B33: 电力需求 | C33: =C31*C29 -> 75940200
B34: 需要能量 | C34: =C33/C32 -> 67.056075
C35: =C34*C25 -> 228804.85
B37: beccs
B38: 自用率 | C38: 11.4
B39: 排放因子 | C39: 838
B40: 发电量 | C40: =资本成本!C44*资本成本!C50*1000 -> 5731000000
B41: 总排放 | C41: =C40*C39/10^6 -> 4802578
B42: 电力需求 | C42: =C40*C38/100 -> 653334000
B43: 需要能量 | C43: =C42/C41 -> 136.03819
C44: =C43*C25 -> 464181.61
B46: waste
...
