Workbook

Sheet 增加值 (2001-2060, 2012USD)
A1: 全国 | B1: 2001 | C1: 2002 | D1: 2003 | E1: 2004 | F1: 2005 | G1: 2006 | H1: 2007 | I1: 2008 | J1: 2009 | K1: 2010 | L1: 2011 | M1: 2012 | N1: 2013 | O1: 2014 | P1: 2015 | Q1: 2016 | R1: 2017 | S1: 2018 | T1: 2019 | U1: 2020 | V1: 2021 | W1: 2022 | X1: 2023 | Y1: 2024 | Z1: 2025 | AA1: 2026 | AB1: 2027 | AC1: 2028 | AD1: 2029 | AE1: 2030 | AF1: 2031 | AG1: 2032 | AH1: 2033 | AI1: 2034 | AJ1: 2035 | AK1: 2036 | AL1: 2037 | AM1: 2038 | AN1: 2039 | AO1: 2040 | AP1: 2041 | AQ1: 2042 | AR1: 2043 | AS1: 2044 | AT1: 2045 | AU1: 2046 | AV1: 2047 | AW1: 2048 | AX1: 2049 | AY1: 2050 | AZ1: 2051 | BA1: 2052 | BB1: 2053 | BC1: 2054 | BD1: 2055 | BE1: 2056 | BF1: 2057 | BG1: 2058 | BH1: 2059 | BI1: 2060
A2: 地区生产总值 | B2: ='增加值 (2001-2060, 2020RMB)'!B2*$B$73 -> 28718.704 | C2: ='增加值 (2001-2060, 2020RMB)'!C2*$B$73 -> 31332.106 | D2: ='增加值 (2001-2060, 2020RMB)'!D2*$B$73 -> 34465.316 | E2: ='增加值 (2001-2060, 2020RMB)'!E2*$B$73 -> 37946.313 | F2: ='增加值 (2001-2060, 2020RMB)'!F2*$B$73 -> 42272.193 | G2: ='增加值 (2001-2060, 2020RMB)'!G2*$B$73 -> 47640.761 | H2: ='增加值 (2001-2060, 2020RMB)'!H2*$B$73 -> 54405.75 | I2: ='增加值 (2001-2060, 2020RMB)'!I2*$B$73 -> 59683.107 | ... BI2: ='增加值 (2001-2060, 2020RMB)'!BI2*$B$73 -> 454814.2
A3: 农业 | B3: ='增加值 (2001-2060, 2020RMB)'!B3*$B$73 -> 4087.7546 | C3: ='增加值 (2001-2060, 2020RMB)'!C3*$B$73 -> 4256.5673 | D3: ='增加值 (2001-2060, 2020RMB)'!D3*$B$73 -> 4359.0391 | E3: ='增加值 (2001-2060, 2020RMB)'!E3*$B$73 -> 5020.1194 | F3: ='增加值 (2001-2060, 2020RMB)'!F3*$B$73 -> 5058.6563 | G3: ='增加值 (2001-2060, 2020RMB)'!G3*$B$73 -> 5218.3751 | H3: ='增加值 (2001-2060, 2020RMB)'!H3*$B$73 -> 5737.5832 | I3: ='增加值 (2001-2060, 2020RMB)'!I3*$B$73 -> 6249.4178 | ... BI3: ='增加值 (2001-2060, 2020RMB)'!BI3*$B$73 -> 23650.339
A4: 工业 | B4: ='增加值 (2001-2060, 2020RMB)'!B4*$B$73 -> 11360.305 | C4: ='增加值 (2001-2060, 2020RMB)'!C4*$B$73 -> 12298.063 | D4: ='增加值 (2001-2060, 2020RMB)'!D4*$B$73 -> 13884.791 | E4: ='增加值 (2001-2060, 2020RMB)'!E4*$B$73 -> 15422.095 | F4: ='增加值 (2001-2060, 2020RMB)'!F4*$B$73 -> 17592.823 | G4: ='增加值 (2001-2060, 2020RMB)'!G4*$B$73 -> 20024.671 | H4: ='增加值 (2001-2060, 2020RMB)'!H4*$B$73 -> 22498.315 | I4: ='增加值 (2001-2060, 2020RMB)'!I4*$B$73 -> 24625.938 | ... BI4: ='增加值 (2001-2060, 2020RMB)'!BI4*$B$73 -> 85505.07
A5: 建筑业 | B5: ='增加值 (2001-2060, 2020RMB)'!B5*$B$73 -> 1540.1613 | C5: ='增加值 (2001-2060, 2020RMB)'!C5*$B$73 -> 1668.6015 | D5: ='增加值 (2001-2060, 2020RMB)'!D5*$B$73 -> 1883.702 | E5: ='增加值 (2001-2060, 2020RMB)'!E5*$B$73 -> 2044.6763 | F5: ='增加值 (2001-2060, 2020RMB)'!F5*$B$73 -> 2347.0773 | G5: ='增加值 (2001-2060, 2020RMB)'!G5*$B$73 -> 2702.9543 | H5: ='增加值 (2001-2060, 2020RMB)'!H5*$B$73 -> 3091.6077 | I5: ='增加值 (2001-2060, 2020RMB)'!I5*$B$73 -> 3516.1002 | ... BI5: ='增加值 (2001-2060, 2020RMB)'!BI5*$B$73 -> 22740.71
A6: 交运仓邮 | B6: ='增加值 (2001-2060, 2020RMB)'!B6*$B$73 -> 1779.9866 | C6: ='增加值 (2001-2060, 2020RMB)'!C6*$B$73 -> 1929.1589 | D6: ='增加值 (2001-2060, 2020RMB)'!D6*$B$73 -> 1985.0249 | E6: ='增加值 (2001-2060, 2020RMB)'!E6*$B$73 -> 2182.0744 | F6: ='增加值 (2001-2060, 2020RMB)'!F6*$B$73 -> 2407.6245 | G6: ='增加值 (2001-2060, 2020RMB)'!G6*$B$73 -> 2645.6826 | H6: ='增加值 (2001-2060, 2020RMB)'!H6*$B$73 -> 2941.9625 | I6: ='增加值 (2001-2060, 2020RMB)'!I6*$B$73 -> 3059.9397 | ... BI6: ='增加值 (2001-2060, 2020RMB)'!BI6*$B$73 -> 9957.8341
A7: 批发零售 | B7: ='增加值 (2001-2060, 2020RMB)'!B7*$B$73 -> 2362.7118 | C7: ='增加值 (2001-2060, 2020RMB)'!C7*$B$73 -> 2573.3444 | D7: ='增加值 (2001-2060, 2020RMB)'!D7*$B$73 -> 2801.7271 | E7: ='增加值 (2001-2060, 2020RMB)'!E7*$B$73 -> 2920.4838 | F7: ='增加值 (2001-2060, 2020RMB)'!F7*$B$73 -> 3152.2667 | G7: ='增加值 (2001-2060, 2020RMB)'!G7*$B$73 -> 3589.4511 | H7: ='增加值 (2001-2060, 2020RMB)'!H7*$B$73 -> 4218.2478 | I7: ='增加值 (2001-2060, 2020RMB)'!I7*$B$73 -> 4895.5371 | ... BI7: ='增加值 (2001-2060, 2020RMB)'!BI7*$B$73 -> 24521.958
A8: 餐饮住宿 | B8: ='增加值 (2001-2060, 2020RMB)'!B8*$B$73 -> 621.73763 | C8: ='增加值 (2001-2060, 2020RMB)'!C8*$B$73 -> 701.40934 | D8: ='增加值 (2001-2060, 2020RMB)'!D8*$B$73 -> 784.02312 | E8: ='增加值 (2001-2060, 2020RMB)'!E8*$B$73 -> 859.27754 | F8: ='增加值 (2001-2060, 2020RMB)'!F8*$B$73 -> 946.8422 | G8: ='增加值 (2001-2060, 2020RMB)'!G8*$B$73 -> 1040.4879 | H8: ='增加值 (2001-2060, 2020RMB)'!H8*$B$73 -> 1117.5755 | I8: ='增加值 (2001-2060, 2020RMB)'!I8*$B$73 -> 1236.8867 | ... BI8: ='增加值 (2001-2060, 2020RMB)'!BI8*$B$73 -> 4234.2312
A9: 金融业 | B9: ='增加值 (2001-2060, 2020RMB)'!B9*$B$73 -> 1347.7674 | C9: ='增加值 (2001-2060, 2020RMB)'!C9*$B$73 -> 1430.1564 | D9: ='增加值 (2001-2060, 2020RMB)'!D9*$B$73 -> 1516.2562 | E9: ='增加值 (2001-2060, 2020RMB)'!E9*$B$73 -> 1547.5343 | F9: ='增加值 (2001-2060, 2020RMB)'!F9*$B$73 -> 1689.3631 | G9: ='增加值 (2001-2060, 2020RMB)'!G9*$B$73 -> 2165.0165 | H9: ='增加值 (2001-2060, 2020RMB)'!H9*$B$73 -> 3061.7955 | I9: ='增加值 (2001-2060, 2020RMB)'!I9*$B$73 -> 3429.7288 | ... BI9: ='增加值 (2001-2060, 2020RMB)'!BI9*$B$73 -> 20881.758
A10: 房地产 | B10: ='增加值 (2001-2060, 2020RMB)'!B10*$B$73 -> 1219.0213 | C10: ='增加值 (2001-2060, 2020RMB)'!C10*$B$73 -> 1373.19 | D10: ='增加值 (2001-2060, 2020RMB)'!D10*$B$73 -> 1544.1702 | E10: ='增加值 (2001-2060, 2020RMB)'!E10*$B$73 -> 1676.937 | F10: ='增加值 (2001-2060, 2020RMB)'!F10*$B$73 -> 1914.288 | G10: ='增加值 (2001-2060, 2020RMB)'!G10*$B$73 -> 2240.6986 | H10: ='增加值 (2001-2060, 2020RMB)'!H10*$B$73 -> 2762.4647 | I10: ='增加值 (2001-2060, 2020RMB)'!I10*$B$73 -> 2729.5411 | ... BI10: ='增加值 (2001-2060, 2020RMB)'!BI10*$B$73 -> 18896.877
A11: 其他三产 | B11: ='增加值 (2001-2060, 2020RMB)'!B11*$B$73 -> 4399.284 | C11: ='增加值 (2001-2060, 2020RMB)'!C11*$B$73 -> 5101.6409 | D11: ='增加值 (2001-2060, 2020RMB)'!D11*$B$73 -> 5706.6329 | E11: ='增加值 (2001-2060, 2020RMB)'!E11*$B$73 -> 6273.0918 | F11: ='增加值 (2001-2060, 2020RMB)'!F11*$B$73 -> 7163.229 | G11: ='增加值 (2001-2060, 2020RMB)'!G11*$B$73 -> 8013.4462 | H11: ='增加值 (2001-2060, 2020RMB)'!H11*$B$73 -> 8976.1974 | I11: ='增加值 (2001-2060, 2020RMB)'!I11*$B$73 -> 9940.0555 | ... BI11: ='增加值 (2001-2060, 2020RMB)'!BI11*$B$73 -> 244425.43
A13: 工业 | B13: ='增加值 (2001-2060, 2020RMB)'!B13*$B$73 -> 11360.305 | C13: ='增加值 (2001-2060, 2020RMB)'!C13*$B$73 -> 12298.063 | D13: ='增加值 (2001-2060, 2020RMB)'!D13*$B$73 -> 13884.791 | E13: ='增加值 (2001-2060, 2020RMB)'!E13*$B$73 -> 15422.095 | F13: ='增加值 (2001-2060, 2020RMB)'!F13*$B$73 -> 17592.823 | G13: ='增加值 (2001-2060, 2020RMB)'!G13*$B$73 -> 20024.671 | H13: ='增加值 (2001-2060, 2020RMB)'!H13*$B$73 -> 22498.315 | I13: ='增加值 (2001-2060, 2020RMB)'!I13*$B$73 -> 24625.938 | ... BI13: ='增加值 (2001-2060, 2020RMB)'!BI13*$B$73 -> 85505.07
A14: 煤炭开采和洗选业 | I14: ='增加值 (2001-2060, 2020RMB)'!I14*$B$73 -> 1608.2849 | J14: ='增加值 (2001-2060, 2020RMB)'!J14*$B$73 -> 1651.0989 | K14: ='增加值 (2001-2060, 2020RMB)'!K14*$B$73 -> 1879.1923 | L14: ='增加值 (2001-2060, 2020RMB)'!L14*$B$73 -> 2105.4222 | M14: ='增加值 (2001-2060, 2020RMB)'!M14*$B$73 -> 2200.7749 | N14: ='增加值 (2001-2060, 2020RMB)'!N14*$B$73 -> 2209.8175 | O14: ='增加值 (2001-2060, 2020RMB)'!O14*$B$73 -> 2171.5798 | P14: ='增加值 (2001-2060, 2020RMB)'!P14*$B$73 -> 2099.3377 | ... BI14: ='增加值 (2001-2060, 2020RMB)'!BI14*$B$73 -> 1951.3615
A15: 石油和天然气开采业 | I15: ='增加值 (2001-2060, 2020RMB)'!I15*$B$73 -> 1691.9642 | J15: ='增加值 (2001-2060, 2020RMB)'!J15*$B$73 -> 1680.87 | K15: ='增加值 (2001-2060, 2020RMB)'!K15*$B$73 -> 1629.0529 | L15: ='增加值 (2001-2060, 2020RMB)'!L15*$B$73 -> 1645.1569 | M15: ='增加值 (2001-2060, 2020RMB)'!M15*$B$73 -> 1616.2967 | N15: ='增加值 (2001-2060, 2020RMB)'!N15*$B$73 -> 1570.7336 | O15: ='增加值 (2001-2060, 2020RMB)'!O15*$B$73 -> 1558.6134 | P15: ='增加值 (2001-2060, 2020RMB)'!P15*$B$73 -> 1540.7723 | ... BI15: ='增加值 (2001-2060, 2020RMB)'!BI15*$B$73 -> 1180.5176
A16: 黑色金属矿采选业 | I16: ='增加值 (2001-2060, 2020RMB)'!I16*$B$73 -> 281.4176 | J16: ='增加值 (2001-2060, 2020RMB)'!J16*$B$73 -> 334.25968 | K16: ='增加值 (2001-2060, 2020RMB)'!K16*$B$73 -> 391.47301 | L16: ='增加值 (2001-2060, 2020RMB)'!L16*$B$73 -> 451.39058 | M16: ='增加值 (2001-2060, 2020RMB)'!M16*$B$73 -> 518.24352 | N16: ='增加值 (2001-2060, 2020RMB)'!N16*$B$73 -> 566.15783 | O16: ='增加值 (2001-2060, 2020RMB)'!O16*$B$73 -> 600.32741 | P16: ='增加值 (2001-2060, 2020RMB)'!P16*$B$73 -> 583.77348 | ... BI16: ='增加值 (2001-2060, 2020RMB)'!BI16*$B$73 -> 383.84455
A17: 有色金属矿采选业 | I17: ='增加值 (2001-2060, 2020RMB)'!I17*$B$73 -> 180.55744 | J17: ='增加值 (2001-2060, 2020RMB)'!J17*$B$73 -> 205.04722 | K17: ='增加值 (2001-2060, 2020RMB)'!K17*$B$73 -> 221.42629 | L17: ='增加值 (2001-2060, 2020RMB)'!L17*$B$73 -> 245.74268 | M17: ='增加值 (2001-2060, 2020RMB)'!M17*$B$73 -> 269.73915 | N17: ='增加值 (2001-2060, 2020RMB)'!N17*$B$73 -> 280.58464 | O17: ='增加值 (2001-2060, 2020RMB)'!O17*$B$73 -> 288.91076 | P17: ='增加值 (2001-2060, 2020RMB)'!P17*$B$73 -> 285.87774 | ... BI17: ='增加值 (2001-2060, 2020RMB)'!BI17*$B$73 -> 146.32156
A18: 非金属矿采选业 | I18: ='增加值 (2001-2060, 2020RMB)'!I18*$B$73 -> 102.03795 | J18: ='增加值 (2001-2060, 2020RMB)'!J18*$B$73 -> 116.26469 | K18: ='增加值 (2001-2060, 2020RMB)'!K18*$B$73 -> 140.90713 | L18: ='增加值 (2001-2060, 2020RMB)'!L18*$B$73 -> 167.34813 | M18: ='增加值 (2001-2060, 2020RMB)'!M18*$B$73 -> 175.56443 | N18: ='增加值 (2001-2060, 2020RMB)'!N18*$B$73 -> 186.7929 | O18: ='增加值 (2001-2060, 2020RMB)'!O18*$B$73 -> 193.05215 | P18: ='增加值 (2001-2060, 2020RMB)'!P18*$B$73 -> 195.23792 | ... BI18: ='增加值 (2001-2060, 2020RMB)'!BI18*$B$73 -> 110.83225
A19: 开采专业及辅助性活动 | I19: ='增加值 (2001-2060, 2020RMB)'!I19*$B$73 -> 85.717113 | J19: ='增加值 (2001-2060, 2020RMB)'!J19*$B$73 -> 97.654766 | K19: ='增加值 (2001-2060, 2020RMB)'!K19*$B$73 -> 109.73872 | L19: ='增加值 (2001-2060, 2020RMB)'!L19*$B$73 -> 123.65278 | M19: ='增加值 (2001-2060, 2020RMB)'!M19*$B$73 -> 134.43244 | N19: ='增加值 (2001-2060, 2020RMB)'!N19*$B$73 -> 134.21856 | O19: ='增加值 (2001-2060, 2020RMB)'!O19*$B$73 -> 124.43272 | P19: ='增加值 (2001-2060, 2020RMB)'!P19*$B$73 -> 104.00227 | ... BI19: ='增加值 (2001-2060, 2020RMB)'!BI19*$B$73 -> 292.65875
A20: 其他采矿业 | I20: ='增加值 (2001-2060, 2020RMB)'!I20*$B$73 -> 0.57954864 | J20: ='增加值 (2001-2060, 2020RMB)'!J20*$B$73 -> 0.78396292 | K20: ='增加值 (2001-2060, 2020RMB)'!K20*$B$73 -> 0.91891072 | L20: ='增加值 (2001-2060, 2020RMB)'!L20*$B$73 -> 1.0842792 | M20: ='增加值 (2001-2060, 2020RMB)'!M20*$B$73 -> 1.0889994 | N20: ='增加值 (2001-2060, 2020RMB)'!N20*$B$73 -> 1.1648549 | O20: ='增加值 (2001-2060, 2020RMB)'!O20*$B$73 -> 1.083276 | P20: ='增加值 (2001-2060, 2020RMB)'!P20*$B$73 -> 1.0523771 | ... BI20: ='增加值 (2001-2060, 2020RMB)'!BI20*$B$73 -> 1.237257
A21: 农副食品加工业 | I21: ='增加值 (2001-2060, 2020RMB)'!I21*$B$73 -> 833.39094 | J21: ='增加值 (2001-2060, 2020RMB)'!J21*$B$73 -> 915.61705 | K21: ='增加值 (2001-2060, 2020RMB)'!K21*$B$73 -> 1022.5446 | L21: ='增加值 (2001-2060, 2020RMB)'!L21*$B$73 -> 1121.0818 | M21: ='增加值 (2001-2060, 2020RMB)'!M21*$B$73 -> 1212.4106 | N21: ='增加值 (2001-2060, 2020RMB)'!N21*$B$73 -> 1260.0066 | O21: ='增加值 (2001-2060, 2020RMB)'!O21*$B$73 -> 1301.0203 | P21: ='增加值 (2001-2060, 2020RMB)'!P21*$B$73 -> 1302.1735 | ... BI21: ='增加值 (2001-2060, 2020RMB)'!BI21*$B$73 -> 1184.203
A22: 食品制造业 | I22: ='增加值 (2001-2060, 2020RMB)'!I22*$B$73 -> 391.28881 | J22: ='增加值 (2001-2060, 2020RMB)'!J22*$B$73 -> 423.21858 | K22: ='增加值 (2001-2060, 2020RMB)'!K22*$B$73 -> 473.46484 | L22: ='增加值 (2001-2060, 2020RMB)'!L22*$B$73 -> 532.73846 | M22: ='增加值 (2001-2060, 2020RMB)'!M22*$B$73 -> 567.00898 | N22: ='增加值 (2001-2060, 2020RMB)'!N22*$B$73 -> 592.50009 | O22: ='增加值 (2001-2060, 2020RMB)'!O22*$B$73 -> 616.89858 | P22: ='增加值 (2001-2060, 2020RMB)'!P22*$B$73 -> 629.15052 | ... BI22: ='增加值 (2001-2060, 2020RMB)'!BI22*$B$73 -> 838.57401
A23: 酒、饮料和精制茶制造业 | I23: ='增加值 (2001-2060, 2020RMB)'!I23*$B$73 -> 416.04114 | J23: ='增加值 (2001-2060, 2020RMB)'!J23*$B$73 -> 451.96266 | K23: ='增加值 (2001-2060, 2020RMB)'!K23*$B$73 -> 502.98809 | L23: ='增加值 (2001-2060, 2020RMB)'!L23*$B$73 -> 574.65737 | M23: ='增加值 (2001-2060, 2020RMB)'!M23*$B$73 -> 615.45397 | N23: ='增加值 (2001-2060, 2020RMB)'!N23*$B$73 -> 644.29235 | O23: ='增加值 (2001-2060, 2020RMB)'!O23*$B$73 -> 657.85187 | P23: ='增加值 (2001-2060, 2020RMB)'!P23*$B$73 -> 672.16537 | ... BI23: ='增加值 (2001-2060, 2020RMB)'!BI23*$B$73 -> 993.34649
A24: 烟草制品业 | I24: ='增加值 (2001-2060, 2020RMB)'!I24*$B$73 -> 814.11627 | J24: ='增加值 (2001-2060, 2020RMB)'!J24*$B$73 -> 835.01708 | K24: ='增加值 (2001-2060, 2020RMB)'!K24*$B$73 -> 907.39414 | L24: ='增加值 (2001-2060, 2020RMB)'!L24*$B$73 -> 981.75649 | M24: ='增加值 (2001-2060, 2020RMB)'!M24*$B$73 -> 1021.5462 | N24: ='增加值 (2001-2060, 2020RMB)'!N24*$B$73 -> 1040.3 | O24: ='增加值 (2001-2060, 2020RMB)'!O24*$B$73 -> 1079.149 | P24: ='增加值 (2001-2060, 2020RMB)'!P24*$B$73 -> 1058.6058 | ... BI24: ='增加值 (2001-2060, 2020RMB)'!BI24*$B$73 -> 1040.1779
A25: 纺织业 | I25: ='增加值 (2001-2060, 2020RMB)'!I25*$B$73 -> 777.95992 | J25: ='增加值 (2001-2060, 2020RMB)'!J25*$B$73 -> 800.14486 | K25: ='增加值 (2001-2060, 2020RMB)'!K25*$B$73 -> 867.1682 | L25: ='增加值 (2001-2060, 2020RMB)'!L25*$B$73 -> 902.40443 | M25: ='增加值 (2001-2060, 2020RMB)'!M25*$B$73 -> 963.89151 | N25: ='增加值 (2001-2060, 2020RMB)'!N25*$B$73 -> 995.32176 | O25: ='增加值 (2001-2060, 2020RMB)'!O25*$B$73 -> 1018.1774 | P25: ='增加值 (2001-2060, 2020RMB)'!P25*$B$73 -> 1033.5692 | ... BI25: ='增加值 (2001-2060, 2020RMB)'!BI25*$B$73 -> 587.64392
... A54: 水的生产和供应业 | I54: ='增加值 (2001-2060, 2020RMB)'!I54*$B$73 -> 106.41261 | J54: ='增加值 (2001-2060, 2020RMB)'!J54*$B$73 -> 106.01748 | K54: ='增加值 (2001-2060, 2020RMB)'!K54*$B$73 -> 108.72062 | L54: ='增加值 (2001-2060, 2020RMB)'!L54*$B$73 -> 112.09366 | M54: ='增加值 (2001-2060, 2020RMB)'!M54*$B$73 -> 111.51452 | N54: ='增加值 (2001-2060, 2020RMB)'!N54*$B$73 -> 113.03206 | O54: ='增加值 (2001-2060, 2020RMB)'!O54*$B$73 -> 116.38619 | P54: ='增加值 (2001-2060, 2020RMB)'!P54*$B$73 -> 116.59977 | ... BI54: ='增加值 (2001-2060, 2020RMB)'!BI54*$B$73 -> 401.03685
A56: 第三产业 | B56: ='增加值 (2001-2060, 2020RMB)'!B56*$B$73 -> 11730.483 | C56: ='增加值 (2001-2060, 2020RMB)'!C56*$B$73 -> 13108.874 | D56: ='增加值 (2001-2060, 2020RMB)'!D56*$B$73 -> 14337.784 | E56: ='增加值 (2001-2060, 2020RMB)'!E56*$B$73 -> 15459.422 | F56: ='增加值 (2001-2060, 2020RMB)'!F56*$B$73 -> 17273.636 | G56: ='增加值 (2001-2060, 2020RMB)'!G56*$B$73 -> 19694.761 | H56: ='增加值 (2001-2060, 2020RMB)'!H56*$B$73 -> 23078.243 | I56: ='增加值 (2001-2060, 2020RMB)'!I56*$B$73 -> 25291.652 | ... BI56: ='增加值 (2001-2060, 2020RMB)'!BI56*$B$73 -> 322918.08
A57: 交运仓邮 | B57: ='增加值 (2001-2060, 2020RMB)'!B57*$B$73 -> 1779.9866 | C57: ='增加值 (2001-2060, 2020RMB)'!C57*$B$73 -> 1929.1589 | D57: ='增加值 (2001-2060, 2020RMB)'!D57*$B$73 -> 1985.0249 | E57: ='增加值 (2001-2060, 2020RMB)'!E57*$B$73 -> 2182.0744 | F57: ='增加值 (2001-2060, 2020RMB)'!F57*$B$73 -> 2407.6245 | G57: ='增加值 (2001-2060, 2020RMB)'!G57*$B$73 -> 2645.6826 | H57: ='增加值 (2001-2060, 2020RMB)'!H57*$B$73 -> 2941.9625 | I57: ='增加值 (2001-2060, 2020RMB)'!I57*$B$73 -> 3059.9397 | ... BI57: ='增加值 (2001-2060, 2020RMB)'!BI57*$B$73 -> 9957.8341
A58: 批发零售 | B58: ='增加值 (2001-2060, 2020RMB)'!B58*$B$73 -> 2362.7118 | C58: ='增加值 (2001-2060, 2020RMB)'!C58*$B$73 -> 2573.3444 | D58: ='增加值 (2001-2060, 2020RMB)'!D58*$B$73 -> 2801.7271 | E58: ='增加值 (2001-2060, 2020RMB)'!E58*$B$73 -> 2920.4838 | F58: ='增加值 (2001-2060, 2020RMB)'!F58*$B$73 -> 3152.2667 | G58: ='增加值 (2001-2060, 2020RMB)'!G58*$B$73 -> 3589.4511 | H58: ='增加值 (2001-2060, 2020RMB)'!H58*$B$73 -> 4218.2478 | I58: ='增加值 (2001-2060, 2020RMB)'!I58*$B$73 -> 4895.5371 | ... BI58: ='增加值 (2001-2060, 2020RMB)'!BI58*$B$73 -> 24521.958
A59: 餐饮住宿 | B59: ='增加值 (2001-2060, 2020RMB)'!B59*$B$73 -> 621.73763 | C59: ='增加值 (2001-2060, 2020RMB)'!C59*$B$73 -> 701.40934 | D59: ='增加值 (2001-2060, 2020RMB)'!D59*$B$73 -> 784.02312 | E59: ='增加值 (2001-2060, 2020RMB)'!E59*$B$73 -> 859.27754 | F59: ='增加值 (2001-2060, 2020RMB)'!F59*$B$73 -> 946.8422 | G59: ='增加值 (2001-2060, 2020RMB)'!G59*$B$73 -> 1040.4879 | H59: ='增加值 (2001-2060, 2020RMB)'!H59*$B$73 -> 1117.5755 | I59: ='增加值 (2001-2060, 2020RMB)'!I59*$B$73 -> 1236.8867 | ... BI59: ='增加值 (2001-2060, 2020RMB)'!BI59*$B$73 -> 4234.2312
A60: 金融业 | B60: ='增加值 (2001-2060, 2020RMB)'!B60*$B$73 -> 1347.7674 | C60: ='增加值 (2001-2060, 2020RMB)'!C60*$B$73 -> 1430.1564 | D60: ='增加值 (2001-2060, 2020RMB)'!D60*$B$73 -> 1516.2562 | E60: ='增加值 (2001-2060, 2020RMB)'!E60*$B$73 -> 1547.5343 | F60: ='增加值 (2001-2060, 2020RMB)'!F60*$B$73 -> 1689.3631 | G60: ='增加值 (2001-2060, 2020RMB)'!G60*$B$73 -> 2165.0165 | H60: ='增加值 (2001-2060, 2020RMB)'!H60*$B$73 -> 3061.7955 | I60: ='增加值 (2001-2060, 2020RMB)'!I60*$B$73 -> 3429.7288 | ... BI60: ='增加值 (2001-2060, 2020RMB)'!BI60*$B$73 -> 20881.758
A61: 房地产 | B61: ='增加值 (2001-2060, 2020RMB)'!B61*$B$73 -> 1219.0213 | C61: ='增加值 (2001-2060, 2020RMB)'!C61*$B$73 -> 1373.19 | D61: ='增加值 (2001-2060, 2020RMB)'!D61*$B$73 -> 1544.1702 | E61: ='增加值 (2001-2060, 2020RMB)'!E61*$B$73 -> 1676.937 | F61: ='增加值 (2001-2060, 2020RMB)'!F61*$B$73 -> 1914.288 | G61: ='增加值 (2001-2060, 2020RMB)'!G61*$B$73 -> 2240.6986 | H61: ='增加值 (2001-2060, 2020RMB)'!H61*$B$73 -> 2762.4647 | I61: ='增加值 (2001-2060, 2020RMB)'!I61*$B$73 -> 2729.5411 | ... BI61: ='增加值 (2001-2060, 2020RMB)'!BI61*$B$73 -> 18896.877
A62: 信息传输、软件和信息技术服务 | K62: ='增加值 (2001-2060, 2020RMB)'!K62*$B$73 -> 1585.7514 | L62: ='增加值 (2001-2060, 2020RMB)'!L62*$B$73 -> 1671.5039 | M62: ='增加值 (2001-2060, 2020RMB)'!M62*$B$73 -> 1891.467 | N62: ='增加值 (2001-2060, 2020RMB)'!N62*$B$73 -> 2131.6109 | O62: ='增加值 (2001-2060, 2020RMB)'!O62*$B$73 -> 2376.8126 | P62: ='增加值 (2001-2060, 2020RMB)'!P62*$B$73 -> 2690.219 | Q62: ='增加值 (2001-2060, 2020RMB)'!Q62*$B$73 -> 3046.3629 | R62: ='增加值 (2001-2060, 2020RMB)'!R62*$B$73 -> 3456.28 | ... BI62: ='增加值 (2001-2060, 2020RMB)'!BI62*$B$73 -> 100707.38
A63: 租赁和商务服务 | K63: ='增加值 (2001-2060, 2020RMB)'!K63*$B$73 -> 1272.1127 | L63: ='增加值 (2001-2060, 2020RMB)'!L63*$B$73 -> 1484.2205 | M63: ='增加值 (2001-2060, 2020RMB)'!M63*$B$73 -> 1726.3539 | N63: ='增加值 (2001-2060, 2020RMB)'!N63*$B$73 -> 2003.5562 | O63: ='增加值 (2001-2060, 2020RMB)'!O63*$B$73 -> 2373.8474 | P63: ='增加值 (2001-2060, 2020RMB)'!P63*$B$73 -> 2778.2046 | Q63: ='增加值 (2001-2060, 2020RMB)'!Q63*$B$73 -> 3258.9744 | R63: ='增加值 (2001-2060, 2020RMB)'!R63*$B$73 -> 3668.8634 | ... BI63: ='增加值 (2001-2060, 2020RMB)'!BI63*$B$73 -> 38869.914
A64: 科学研究和技术服务 | K64: ='增加值 (2001-2060, 2020RMB)'!K64*$B$73 -> 1132.7196 | L64: ='增加值 (2001-2060, 2020RMB)'!L64*$B$73 -> 1288.6969 | M64: ='增加值 (2001-2060, 2020RMB)'!M64*$B$73 -> 1499.4007 | N64: ='增加值 (2001-2060, 2020RMB)'!N64*$B$73 -> 1711.412 | O64: ='增加值 (2001-2060, 2020RMB)'!O64*$B$73 -> 1916.7397 | P64: ='增加值 (2001-2060, 2020RMB)'!P64*$B$73 -> 2132.7873 | Q64: ='增加值 (2001-2060, 2020RMB)'!Q64*$B$73 -> 2330.3561 | R64: ='增加值 (2001-2060, 2020RMB)'!R64*$B$73 -> 2532.4046 | ... BI64: ='增加值 (2001-2060, 2020RMB)'!BI64*$B$73 -> 22096.603
A65: 水利、环境和公共设施管理 | K65: ='增加值 (2001-2060, 2020RMB)'!K65*$B$73 -> 356.60438 | L65: ='增加值 (2001-2060, 2020RMB)'!L65*$B$73 -> 405.40231 | M65: ='增加值 (2001-2060, 2020RMB)'!M65*$B$73 -> 479.6097 | N65: ='增加值 (2001-2060, 2020RMB)'!N65*$B$73 -> 569.0268 | O65: ='增加值 (2001-2060, 2020RMB)'!O65*$B$73 -> 605.45685 | P65: ='增加值 (2001-2060, 2020RMB)'!P65*$B$73 -> 634.06776 | Q65: ='增加值 (2001-2060, 2020RMB)'!Q65*$B$73 -> 659.19429 | R65: ='增加值 (2001-2060, 2020RMB)'!R65*$B$73 -> 668.14822 | ... BI65: ='增加值 (2001-2060, 2020RMB)'!BI65*$B$73 -> 2512.0379
A66: 居民服务、修理和其他服务 | K66: ='增加值 (2001-2060, 2020RMB)'!K66*$B$73 -> 1131.6157 | L66: ='增加值 (2001-2060, 2020RMB)'!L66*$B$73 -> 1228.6644 | M66: ='增加值 (2001-2060, 2020RMB)'!M66*$B$73 -> 1304.6361 | N66: ='增加值 (2001-2060, 2020RMB)'!N66*$B$73 -> 1351.918 | O66: ='增加值 (2001-2060, 2020RMB)'!O66*$B$73 -> 1480.0346 | P66: ='增加值 (2001-2060, 2020RMB)'!P66*$B$73 -> 1625.8986 | Q66: ='增加值 (2001-2060, 2020RMB)'!Q66*$B$73 -> 1844.3241 | R66: ='增加值 (2001-2060, 2020RMB)'!R66*$B$73 -> 1992.4829 | ... BI66: ='增加值 (2001-2060, 2020RMB)'!BI66*$B$73 -> 9468.9113
A67: 教育 | K67: ='增加值 (2001-2060, 2020RMB)'!K67*$B$73 -> 2167.1895 | L67: ='增加值 (2001-2060, 2020RMB)'!L67*$B$73 -> 2396.5338 | M67: ='增加值 (2001-2060, 2020RMB)'!M67*$B$73 -> 2639.4152 | N67: ='增加值 (2001-2060, 2020RMB)'!N67*$B$73 -> 2942.3084 | O67: ='增加值 (2001-2060, 2020RMB)'!O67*$B$73 -> 3258.7341 | P67: ='增加值 (2001-2060, 2020RMB)'!P67*$B$73 -> 3742.8059 | Q67: ='增加值 (2001-2060, 2020RMB)'!Q67*$B$73 -> 4081.9152 | R67: ='增加值 (2001-2060, 2020RMB)'!R67*$B$73 -> 4385.2798 | ... BI67: ='增加值 (2001-2060, 2020RMB)'!BI67*$B$73 -> 25121.793
A68: 卫生和社会工作 | K68: ='增加值 (2001-2060, 2020RMB)'!K68*$B$73 -> 1031.9816 | L68: ='增加值 (2001-2060, 2020RMB)'!L68*$B$73 -> 1204.9985 | M68: ='增加值 (2001-2060, 2020RMB)'!M68*$B$73 -> 1428.8554 | N68: ='增加值 (2001-2060, 2020RMB)'!N68*$B$73 -> 1713.1509 | O68: ='增加值 (2001-2060, 2020RMB)'!O68*$B$73 -> 1943.9791 | P68: ='增加值 (2001-2060, 2020RMB)'!P68*$B$73 -> 2267.6607 | Q68: ='增加值 (2001-2060, 2020RMB)'!Q68*$B$73 -> 2538.1387 | R68: ='增加值 (2001-2060, 2020RMB)'!R68*$B$73 -> 2692.6841 | ... BI68: ='增加值 (2001-2060, 2020RMB)'!BI68*$B$73 -> 9633.5457
A69: 文化、体育和娱乐 | K69: ='增加值 (2001-2060, 2020RMB)'!K69*$B$73 -> 495.48927 | L69: ='增加值 (2001-2060, 2020RMB)'!L69*$B$73 -> 539.48207 | M69: ='增加值 (2001-2060, 2020RMB)'!M69*$B$73 -> 595.91668 | N69: ='增加值 (2001-2060, 2020RMB)'!N69*$B$73 -> 642.43158 | O69: ='增加值 (2001-2060, 2020RMB)'!O69*$B$73 -> 688.38857 | P69: ='增加值 (2001-2060, 2020RMB)'!P69*$B$73 -> 777.69518 | Q69: ='增加值 (2001-2060, 2020RMB)'!Q69*$B$73 -> 844.66364 | R69: ='增加值 (2001-2060, 2020RMB)'!R69*$B$73 -> 961.79317 | ... BI69: ='增加值 (2001-2060, 2020RMB)'!BI69*$B$73 -> 4163.278
A70: 公共管理、社会保障和社会组织 | K70: ='增加值 (2001-2060, 2020RMB)'!K70*$B$73 -> 2856.6725 | L70: ='增加值 (2001-2060, 2020RMB)'!L70*$B$73 -> 2932.5284 | M70: ='增加值 (2001-2060, 2020RMB)'!M70*$B$73 -> 3187.4137 | N70: ='增加值 (2001-2060, 2020RMB)'!N70*$B$73 -> 3367.9568 | O70: ='增加值 (2001-2060, 2020RMB)'!O70*$B$73 -> 3733.4944 | P70: ='增加值 (2001-2060, 2020RMB)'!P70*$B$73 -> 4368.995 | Q70: ='增加值 (2001-2060, 2020RMB)'!Q70*$B$73 -> 5123.8406 | R70: ='增加值 (2001-2060, 2020RMB)'!R70*$B$73 -> 5639.5856 | ... BI70: ='增加值 (2001-2060, 2020RMB)'!BI70*$B$73 -> 31851.959
...

Sheet 情景假设
A1: GDP增速
B2: 不变价GDP年均增速
A3: 十四五 | B3: 0.053
A4: 十五五 | B4: 0.05
A5: 十六五 | B5: 0.036
A6: 2035-2050 | B6: 0.026
A7: 2035-2060 | B7: 0.02
A8: 参考依据
A9: 2023政府工作报告
A10: 二十大报告：2035年人均GDP达到中等发达国家水平。GDP总量/人均GDP翻一番多
A11: 能源基金会《中国经济社会发展的中长期目标、战略与路径》2035-2050%年均增速3.5%左右
A13: 产业结构
B14: 第一产业 | C14: 第二产业 | D14: 工业 | E14: 建筑业 | F14: 第三产业
A15: 2025 | B15: =1-C15-F15 -> 0.074 | C15: =SUM(D15:E15) -> 0.386 | D15: 0.318 | E15: 0.068 | F15: 0.54
A16: 2030 | B16: =1-C16-F16 -> 0.072 | C16: =SUM(D16:E16) -> 0.358 | D16: 0.293 | E16: 0.065 | F16: 0.57
A17: 2035 | B17: =1-C17-F17 -> 0.065 | C17: =SUM(D17:E17) -> 0.335 | D17: 0.275 | E17: 0.06 | F17: 0.6
A18: 2050 | B18: =1-C18-F18 -> 0.058 | C18: =SUM(D18:E18) -> 0.26 | D18: 0.208 | E18: 0.052 | F18: 0.682
A19: 2060 | B19: =1-C19-F19 -> 0.052 | C19: =SUM(D19:E19) -> 0.238 | D19: 0.188 | E19: 0.05 | F19: 0.71
A20: 参考依据
A21: 能源基金会《中国经济社会发展的中长期目标、战略与路径》
A22: 建筑十四五规划：建筑增加值占比稳定在6%左右
A23: 2018年美国建筑业增加值比重为4.1%，欧盟为4.89%。2017年日本5.7%。
A26: 第三产业年均增速
C27: 2016-2019年均增速 | D27: 2019-2022年均增速 | E27: 十四五增速系数 | F27: 十五五增速系数 | G27: 十六五增速系数 | H27: 2035-2050增速系数 | I27: 2050-2060增速系数 | J27: 十四五年均增速 | K27: 十五五年均增速 | L27: 十六五年均增速 | M27: 2035-2050年均增速 | N27: 2050-2060年均增速 | O27: 2025增加值 | P27: 2030 增加值 | Q27: 2035增加值 | R27: 2050增加值 | S27: 2060增加值
B28: 第三产业 | C28: =(VLOOKUP($B28,'增加值 (2001-2060, 2020RMB)'!$A$56:$W$70,20,0)/VLOOKUP($B28,'增加值 (2001-2060, 2020RMB)'!$A$56:$W$70,17,0))^(1/3)-1 -> 0.078274323 | D28: =(VLOOKUP($B28,'增加值 (2001-2060, 2020RMB)'!$A$56:$W$70,23,0)/VLOOKUP($B28,'增加值 (2001-2060, 2020RMB)'!$A$56:$W$70,20,0))^(1/3)-1 -> 0.035189478 | J28: =('增加值 (2001-2060, 2020RMB)'!Z56/'增加值 (2001-2060, 2020RMB)'!W56)^(1/3)-1 -> 0.064478925 | K28: =('增加值 (2001-2060, 2020RMB)'!AE56/'增加值 (2001-2060, 2020RMB)'!Z56)^0.2-1 -> 0.061415727 | L28: =('增加值 (2001-2060, 2020RMB)'!AJ56/'增加值 (2001-2060, 2020RMB)'!AE56)^0.2-1 -> 0.046682672 | M28: =('增加值 (2001-2060, 2020RMB)'!AY56/'增加值 (2001-2060, 2020RMB)'!AJ56)^(1/15)-1 -> 0.034799561 | N28: =('增加值 (2001-2060, 2020RMB)'!BI56/'增加值 (2001-2060, 2020RMB)'!AY56)^0.1-1 -> 0.015141975 | O28: =SUM(O29:O42) -> 721139.95 | P28: =SUM(P29:P42) -> 969229.55 | Q28: =SUM(Q29:Q42) -> 1266130.8 | R28: =SUM(R29:R42) -> 2584528.2 | S28: =SUM(S29:S42) -> 3546701.9 | T28: ='增加值 (2001-2060, 2020RMB)'!Z56/O28 -> 0.98941454
A29: 传统服务业 | B29: 批发零售 | C29: =(VLOOKUP($B29,'增加值 (2001-2060, 2020RMB)'!$A$56:$W$70,20,0)/VLOOKUP($B29,'增加值 (2001-2060, 2020RMB)'!$A$56:$W$70,17,0))^(1/3)-1 -> 0.05875808 | D29: =(VLOOKUP($B29,'增加值 (2001-2060, 2020RMB)'!$A$56:$W$70,23,0)/VLOOKUP($B29,'增加值 (2001-2060, 2020RMB)'!$A$56:$W$70,20,0))^(1/3)-1 -> 0.036529506 | E29: 0.8 | F29: 0.7 | G29: 0.6 | H29: 0.5 | I29: 0.5 | J29: =$C29*E29 -> 0.047006464 | K29: =$C29*F29 -> 0.041130656 | L29: =$C29*G29 -> 0.035254848 | M29: =$C29*H29 -> 0.02937904 | N29: =$C29*I29 -> 0.02937904 | O29: =VLOOKUP($B29,'增加值 (2001-2060, 2020RMB)'!$A$56:$BI$70,23,0)*(1+J29)^3 -> 122907.94 | P29: =VLOOKUP($B29,'增加值 (2001-2060, 2020RMB)'!$A$56:$BI$70,26,0)*(1+K29)^5 -> 148759.39 | Q29: =VLOOKUP($B29,'增加值 (2001-2060, 2020RMB)'!$A$56:$BI$70,31,0)*(1+L29)^5 -> 175436.34 | R29: =VLOOKUP($B29,'增加值 (2001-2060, 2020RMB)'!$A$56:$BI$70,36,0)*(1+M29)^15 -> 258327.95 | S29: =VLOOKUP($B29,'增加值 (2001-2060, 2020RMB)'!$A$56:$BI$70,51,0)*(1+N29)^10 -> 269331.7 | T29: =O29*$T$28 -> 121606.9
B30: 餐饮住宿 | C30: =(VLOOKUP($B30,'增加值 (2001-2060, 2020RMB)'!$A$56:$W$70,20,0)/VLOOKUP($B30,'增加值 (2001-2060, 2020RMB)'!$A$56:$W$70,17,0))^(1/3)-1 -> 0.063696596 | D30: =(VLOOKUP($B30,'增加值 (2001-2060, 2020RMB)'!$A$56:$W$70,23,0)/VLOOKUP($B30,'增加值 (2001-2060, 2020RMB)'!$A$56:$W$70,20,0))^(1/3)-1 -> -0.02471071 | E30: 0.8 | F30: 0.7 | G30: 0.6 | H30: 0.5 | I30: 0.5 | J30: =$C30*E30 -> 0.050957277 | K30: =$C30*F30 -> 0.044587617 | L30: =$C30*G30 -> 0.038217958 | M30: =$C30*H30 -> 0.031848298 | N30: =$C30*I30 -> 0.031848298 | O30: =VLOOKUP($B30,'增加值 (2001-2060, 2020RMB)'!$A$56:$BI$70,23,0)*(1+J30)^3 -> 19381.241 | P30: =VLOOKUP($B30,'增加值 (2001-2060, 2020RMB)'!$A$56:$BI$70,26,0)*(1+K30)^5 -> 23849.772 | Q30: =VLOOKUP($B30,'增加值 (2001-2060, 2020RMB)'!$A$56:$BI$70,31,0)*(1+L30)^5 -> 28531.572 | R30: =VLOOKUP($B30,'增加值 (2001-2060, 2020RMB)'!$A$56:$BI$70,36,0)*(1+M30)^15 -> 43549.734 | S30: =VLOOKUP($B30,'增加值 (2001-2060, 2020RMB)'!$A$56:$BI$70,51,0)*(1+N30)^10 -> 46505.775 | T30: =O30*$T$28 -> 19176.081
B31: 交运仓邮 | C31: =(VLOOKUP($B31,'增加值 (2001-2060, 2020RMB)'!$A$56:$W$70,20,0)/VLOOKUP($B31,'增加值 (2001-2060, 2020RMB)'!$A$56:$W$70,17,0))^(1/3)-1 -> 0.055573901 | D31: =(VLOOKUP($B31,'增加值 (2001-2060, 2020RMB)'!$A$56:$W$70,23,0)/VLOOKUP($B31,'增加值 (2001-2060, 2020RMB)'!$A$56:$W$70,20,0))^(1/3)-1 -> 0.028524195 | E31: 0.8 | F31: 0.7 | G31: 0.6 | H31: 0.5 | I31: 0.5 | J31: =$C31*E31 -> 0.044459121 | K31: =$C31*F31 -> 0.038901731 | L31: =$C31*G31 -> 0.033344341 | M31: =$C31*H31 -> 0.027786951 | N31: =$C31*I31 -> 0.027786951 | O31: =VLOOKUP($B31,'增加值 (2001-2060, 2020RMB)'!$A$56:$BI$70,23,0)*(1+J31)^3 -> 52924.905 | P31: =VLOOKUP($B31,'增加值 (2001-2060, 2020RMB)'!$A$56:$BI$70,26,0)*(1+K31)^5 -> 63373.942 | Q31: =VLOOKUP($B31,'增加值 (2001-2060, 2020RMB)'!$A$56:$BI$70,31,0)*(1+L31)^5 -> 74051.667 | R31: =VLOOKUP($B31,'增加值 (2001-2060, 2020RMB)'!$A$56:$BI$70,36,0)*(1+M31)^15 -> 106537.71 | S31: =VLOOKUP($B31,'增加值 (2001-2060, 2020RMB)'!$A$56:$BI$70,51,0)*(1+N31)^10 -> 109369.75 | T31: =O31*$T$28 -> 52364.67
A32: 现代服务业 | B32: 金融业 | C32: =(VLOOKUP($B32,'增加值 (2001-2060, 2020RMB)'!$A$56:$W$70,20,0)/VLOOKUP($B32,'增加值 (2001-2060, 2020RMB)'!$A$56:$W$70,17,0))^(1/3)-1 -> 0.051691957 | D32: =(VLOOKUP($B32,'增加值 (2001-2060, 2020RMB)'!$A$56:$W$70,23,0)/VLOOKUP($B32,'增加值 (2001-2060, 2020RMB)'!$A$56:$W$70,20,0))^(1/3)-1 -> 0.057014547 | E32: 1 | F32: 1 | G32: 0.8 | H32: 0.5 | I32: 0.5 | J32: =$C32*E32 -> 0.051691957 | K32: =$C32*F32 -> 0.051691957 | L32: =$C32*G32 -> 0.041353566 | M32: =$C32*H32 -> 0.025845979 | N32: =$C32*I32 -> 0.025845979 | O32: =VLOOKUP($B32,'增加值 (2001-2060, 2020RMB)'!$A$56:$BI$70,23,0)*(1+J32)^3 -> 105305.15 | P32: =VLOOKUP($B32,'增加值 (2001-2060, 2020RMB)'!$A$56:$BI$70,26,0)*(1+K32)^5 -> 134051.18 | Q32: =VLOOKUP($B32,'增加值 (2001-2060, 2020RMB)'!$A$56:$BI$70,31,0)*(1+L32)^5 -> 162802.28 | R32: =VLOOKUP($B32,'增加值 (2001-2060, 2020RMB)'!$A$56:$BI$70,36,0)*(1+M32)^15 -> 227674.78 | S32: =VLOOKUP($B32,'增加值 (2001-2060, 2020RMB)'!$A$56:$BI$70,51,0)*(1+N32)^10 -> 229350.33 | T32: =O32*$T$28 -> 104190.44
B33: 房地产 | C33: =(VLOOKUP($B33,'增加值 (2001-2060, 2020RMB)'!$A$56:$W$70,20,0)/VLOOKUP($B33,'增加值 (2001-2060, 2020RMB)'!$A$56:$W$70,17,0))^(1/3)-1 -> 0.08847702 | D33: =(VLOOKUP($B33,'增加值 (2001-2060, 2020RMB)'!$A$56:$W$70,23,0)/VLOOKUP($B33,'增加值 (2001-2060, 2020RMB)'!$A$56:$W$70,20,0))^(1/3)-1 -> -0.0084877902 | E33: 0.6 | F33: 0.5 | G33: 0.4 | H33: 0.4 | I33: 0.4 | J33: =$C33*E33 -> 0.053086212 | K33: =$C33*F33 -> 0.04423851 | L33: =$C33*G33 -> 0.035390808 | M33: =$C33*H33 -> 0.035390808 | N33: =$C33*I33 -> 0.035390808 | O33: =VLOOKUP($B33,'增加值 (2001-2060, 2020RMB)'!$A$56:$BI$70,23,0)*(1+J33)^3 -> 80618.127 | P33: =VLOOKUP($B33,'增加值 (2001-2060, 2020RMB)'!$A$56:$BI$70,26,0)*(1+K33)^5 -> 99039.746 | Q33: =VLOOKUP($B33,'增加值 (2001-2060, 2020RMB)'!$A$56:$BI$70,31,0)*(1+L33)^5 -> 116877.21 | R33: =VLOOKUP($B33,'增加值 (2001-2060, 2020RMB)'!$A$56:$BI$70,36,0)*(1+M33)^15 -> 187809.02 | S33: =VLOOKUP($B33,'增加值 (2001-2060, 2020RMB)'!$A$56:$BI$70,51,0)*(1+N33)^10 -> 207549.81 | T33: =O33*$T$28 -> 79764.747
B34: 信息传输、软件和信息技术服务 | C34: =(VLOOKUP($B34,'增加值 (2001-2060, 2020RMB)'!$A$56:$W$70,20,0)/VLOOKUP($B34,'增加值 (2001-2060, 2020RMB)'!$A$56:$W$70,17,0))^(1/3)-1 -> 0.14924366 | D34: =(VLOOKUP($B34,'增加值 (2001-2060, 2020RMB)'!$A$56:$W$70,23,0)/VLOOKUP($B34,'增加值 (2001-2060, 2020RMB)'!$A$56:$W$70,20,0))^(1/3)-1 -> 0.078333639 | E34: 0.9 | F34: 0.8 | G34: 0.7 | H34: 0.6 | I34: 0.6 | J34: =$C34*E34 -> 0.1343193 | K34: =$C34*F34 -> 0.11939493 | L34: =$C34*G34 -> 0.10447056 | M34: =$C34*H34 -> 0.089546197 | N34: =$C34*I34 -> 0.089546197 | O34: =VLOOKUP($B34,'增加值 (2001-2060, 2020RMB)'!$A$56:$BI$70,23,0)*(1+J34)^3 -> 61433.186 | P34: =VLOOKUP($B34,'增加值 (2001-2060, 2020RMB)'!$A$56:$BI$70,26,0)*(1+K34)^5 -> 106831.17 | Q34: =VLOOKUP($B34,'增加值 (2001-2060, 2020RMB)'!$A$56:$BI$70,31,0)*(1+L34)^5 -> 174127.56 | R34: =VLOOKUP($B34,'增加值 (2001-2060, 2020RMB)'!$A$56:$BI$70,36,0)*(1+M34)^15 -> 601138.14 | S34: =VLOOKUP($B34,'增加值 (2001-2060, 2020RMB)'!$A$56:$BI$70,51,0)*(1+N34)^10 -> 1106098.1 | T34: =O34*$T$28 -> 60782.887
B35: 租赁和商务服务 | C35: =(VLOOKUP($B35,'增加值 (2001-2060, 2020RMB)'!$A$56:$W$70,20,0)/VLOOKUP($B35,'增加值 (2001-2060, 2020RMB)'!$A$56:$W$70,17,0))^(1/3)-1 -> 0.11516786 | D35: =(VLOOKUP($B35,'增加值 (2001-2060, 2020RMB)'!$A$56:$W$70,23,0)/VLOOKUP($B35,'增加值 (2001-2060, 2020RMB)'!$A$56:$W$70,20,0))^(1/3)-1 -> 0.028854192 | E35: 0.9 | F35: 0.8 | G35: 0.7 | H35: 0.6 | I35: 0.6 | J35: =$C35*E35 -> 0.10365108 | K35: =$C35*F35 -> 0.092134292 | L35: =$C35*G35 -> 0.080617505 | M35: =$C35*H35 -> 0.069100719 | N35: =$C35*I35 -> 0.069100719 | O35: =VLOOKUP($B35,'增加值 (2001-2060, 2020RMB)'!$A$56:$BI$70,23,0)*(1+J35)^3 -> 48037.256 | P35: =VLOOKUP($B35,'增加值 (2001-2060, 2020RMB)'!$A$56:$BI$70,26,0)*(1+K35)^5 -> 73847.653 | Q35: =VLOOKUP($B35,'增加值 (2001-2060, 2020RMB)'!$A$56:$BI$70,31,0)*(1+L35)^5 -> 107918.4 | R35: =VLOOKUP($B35,'增加值 (2001-2060, 2020RMB)'!$A$56:$BI$70,36,0)*(1+M35)^15 -> 280412.15 | S35: =VLOOKUP($B35,'增加值 (2001-2060, 2020RMB)'!$A$56:$BI$70,51,0)*(1+N35)^10 -> 426919.41 | T35: =O35*$T$28 -> 47528.76
B36: 科学研究和技术服务 | C36: =(VLOOKUP($B36,'增加值 (2001-2060, 2020RMB)'!$A$56:$W$70,20,0)/VLOOKUP($B36,'增加值 (2001-2060, 2020RMB)'!$A$56:$W$70,17,0))^(1/3)-1 -> 0.10368127 | D36: =(VLOOKUP($B36,'增加值 (2001-2060, 2020RMB)'!$A$56:$W$70,23,0)/VLOOKUP($B36,'增加值 (2001-2060, 2020RMB)'!$A$56:$W$70,20,0))^(1/3)-1 -> 0.053552107 | E36: 0.9 | F36: 0.8 | G36: 0.7 | H36: 0.6 | I36: 0.6 | J36: =$C36*E36 -> 0.093313141 | K36: =$C36*F36 -> 0.082945014 | L36: =$C36*G36 -> 0.072576888 | M36: =$C36*H36 -> 0.062208761 | N36: =$C36*I36 -> 0.062208761 | O36: =VLOOKUP($B36,'增加值 (2001-2060, 2020RMB)'!$A$56:$BI$70,23,0)*(1+J36)^3 -> 34759.594 | P36: =VLOOKUP($B36,'增加值 (2001-2060, 2020RMB)'!$A$56:$BI$70,26,0)*(1+K36)^5 -> 51225.36 | Q36: =VLOOKUP($B36,'增加值 (2001-2060, 2020RMB)'!$A$56:$BI$70,31,0)*(1+L36)^5 -> 72115.061 | R36: =VLOOKUP($B36,'增加值 (2001-2060, 2020RMB)'!$A$56:$BI$70,36,0)*(1+M36)^15 -> 170057.66 | S36: =VLOOKUP($B36,'增加值 (2001-2060, 2020RMB)'!$A$56:$BI$70,51,0)*(1+N36)^10 -> 242693.33 | T36: =O36*$T$28 -> 34391.648
B37: 水利、环境和公共设施管理 | C37: =(VLOOKUP($B37,'增加值 (2001-2060, 2020RMB)'!$A$56:$W$70,20,0)/VLOOKUP($B37,'增加值 (2001-2060, 2020RMB)'!$A$56:$W$70,17,0))^(1/3)-1 -> 0.071814324 | D37: =(VLOOKUP($B37,'增加值 (2001-2060, 2020RMB)'!$A$56:$W$70,23,0)/VLOOKUP($B37,'增加值 (2001-2060, 2020RMB)'!$A$56:$W$70,20,0))^(1/3)-1 -> 0.03075646 | E37: 0.9 | F37: 0.8 | G37: 0.7 | H37: 0.6 | I37: 0.6 | J37: =$C37*E37 -> 0.064632892 | K37: =$C37*F37 -> 0.057451459 | L37: =$C37*G37 -> 0.050270027 | M37: =$C37*H37 -> 0.043088595 | N37: =$C37*I37 -> 0.043088595 | O37: =VLOOKUP($B37,'增加值 (2001-2060, 2020RMB)'!$A$56:$BI$70,23,0)*(1+J37)^3 -> 7786.8099 | P37: =VLOOKUP($B37,'增加值 (2001-2060, 2020RMB)'!$A$56:$BI$70,26,0)*(1+K37)^5 -> 10186.854 | Q37: =VLOOKUP($B37,'增加值 (2001-2060, 2020RMB)'!$A$56:$BI$70,31,0)*(1+L37)^5 -> 12910.519 | R37: =VLOOKUP($B37,'增加值 (2001-2060, 2020RMB)'!$A$56:$BI$70,36,0)*(1+M37)^15 -> 23183.75 | S37: =VLOOKUP($B37,'增加值 (2001-2060, 2020RMB)'!$A$56:$BI$70,51,0)*(1+N37)^10 -> 27590.433 | T37: =O37*$T$28 -> 7704.3829
B38: 居民服务、修理和其他服务 | C38: =(VLOOKUP($B38,'增加值 (2001-2060, 2020RMB)'!$A$56:$W$70,20,0)/VLOOKUP($B38,'增加值 (2001-2060, 2020RMB)'!$A$56:$W$70,17,0))^(1/3)-1 -> 0.08439753 | D38: =(VLOOKUP($B38,'增加值 (2001-2060, 2020RMB)'!$A$56:$W$70,23,0)/VLOOKUP($B38,'增加值 (2001-2060, 2020RMB)'!$A$56:$W$70,20,0))^(1/3)-1 -> 0.017741893 | E38: 0.9 | F38: 0.8 | G38: 0.7 | H38: 0.6 | I38: 0.6 | J38: =$C38*E38 -> 0.075957777 | K38: =$C38*F38 -> 0.067518024 | L38: =$C38*G38 -> 0.059078271 | M38: =$C38*H38 -> 0.050638518 | N38: =$C38*I38 -> 0.050638518 | O38: =VLOOKUP($B38,'增加值 (2001-2060, 2020RMB)'!$A$56:$BI$70,23,0)*(1+J38)^3 -> 22419.249 | P38: =VLOOKUP($B38,'增加值 (2001-2060, 2020RMB)'!$A$56:$BI$70,26,0)*(1+K38)^5 -> 30752.147 | Q38: =VLOOKUP($B38,'增加值 (2001-2060, 2020RMB)'!$A$56:$BI$70,31,0)*(1+L38)^5 -> 40636.333 | R38: =VLOOKUP($B38,'增加值 (2001-2060, 2020RMB)'!$A$56:$BI$70,36,0)*(1+M38)^15 -> 81308.569 | S38: =VLOOKUP($B38,'增加值 (2001-2060, 2020RMB)'!$A$56:$BI$70,51,0)*(1+N38)^10 -> 103999.77 | T38: =O38*$T$28 -> 22181.931
B39: 教育 | C39: =(VLOOKUP($B39,'增加值 (2001-2060, 2020RMB)'!$A$56:$W$70,20,0)/VLOOKUP($B39,'增加值 (2001-2060, 2020RMB)'!$A$56:$W$70,17,0))^(1/3)-1 -> 0.087713836 | D39: =(VLOOKUP($B39,'增加值 (2001-2060, 2020RMB)'!$A$56:$W$70,23,0)/VLOOKUP($B39,'增加值 (2001-2060, 2020RMB)'!$A$56:$W$70,20,0))^(1/3)-1 -> 0.049833837 | E39: 0.9 | F39: 0.8 | G39: 0.7 | H39: 0.6 | I39: 0.6 | J39: =$C39*E39 -> 0.078942453 | K39: =$C39*F39 -> 0.070171069 | L39: =$C39*G39 -> 0.061399685 | M39: =$C39*H39 -> 0.052628302 | N39: =$C39*I39 -> 0.052628302 | O39: =VLOOKUP($B39,'增加值 (2001-2060, 2020RMB)'!$A$56:$BI$70,23,0)*(1+J39)^3 -> 55422.245 | P39: =VLOOKUP($B39,'增加值 (2001-2060, 2020RMB)'!$A$56:$BI$70,26,0)*(1+K39)^5 -> 76971.231 | Q39: =VLOOKUP($B39,'增加值 (2001-2060, 2020RMB)'!$A$56:$BI$70,31,0)*(1+L39)^5 -> 102830.51 | R39: =VLOOKUP($B39,'增加值 (2001-2060, 2020RMB)'!$A$56:$BI$70,36,0)*(1+M39)^15 -> 211675.04 | S39: =VLOOKUP($B39,'增加值 (2001-2060, 2020RMB)'!$A$56:$BI$70,51,0)*(1+N39)^10 -> 275919.85 | T39: =O39*$T$28 -> 54835.575
B40: 卫生和社会工作 | C40: =(VLOOKUP($B40,'增加值 (2001-2060, 2020RMB)'!$A$56:$W$70,20,0)/VLOOKUP($B40,'增加值 (2001-2060, 2020RMB)'!$A$56:$W$70,17,0))^(1/3)-1 -> 0.068423018 | D40: =(VLOOKUP($B40,'增加值 (2001-2060, 2020RMB)'!$A$56:$W$70,23,0)/VLOOKUP($B40,'增加值 (2001-2060, 2020RMB)'!$A$56:$W$70,20,0))^(1/3)-1 -> 0.061115803 | E40: 0.9 | F40: 0.8 | G40: 0.7 | H40: 0.6 | I40: 0.6 | J40: =$C40*E40 -> 0.061580716 | K40: =$C40*F40 -> 0.054738415 | L40: =$C40*G40 -> 0.047896113 | M40: =$C40*H40 -> 0.041053811 | N40: =$C40*I40 -> 0.041053811 | O40: =VLOOKUP($B40,'增加值 (2001-2060, 2020RMB)'!$A$56:$BI$70,23,0)*(1+J40)^3 -> 32122.704 | P40: =VLOOKUP($B40,'增加值 (2001-2060, 2020RMB)'!$A$56:$BI$70,26,0)*(1+K40)^5 -> 41487.208 | Q40: =VLOOKUP($B40,'增加值 (2001-2060, 2020RMB)'!$A$56:$BI$70,31,0)*(1+L40)^5 -> 51988.123 | R40: =VLOOKUP($B40,'增加值 (2001-2060, 2020RMB)'!$A$56:$BI$70,36,0)*(1+M40)^15 -> 90661.696 | S40: =VLOOKUP($B40,'增加值 (2001-2060, 2020RMB)'!$A$56:$BI$70,51,0)*(1+N40)^10 -> 105807.99 | T40: =O40*$T$28 -> 31782.671
B41: 文化、体育和娱乐 | C41: =(VLOOKUP($B41,'增加值 (2001-2060, 2020RMB)'!$A$56:$W$70,20,0)/VLOOKUP($B41,'增加值 (2001-2060, 2020RMB)'!$A$56:$W$70,17,0))^(1/3)-1 -> 0.1008643 | D41: =(VLOOKUP($B41,'增加值 (2001-2060, 2020RMB)'!$A$56:$W$70,23,0)/VLOOKUP($B41,'增加值 (2001-2060, 2020RMB)'!$A$56:$W$70,20,0))^(1/3)-1 -> -0.020691995 | E41: 0.8 | F41: 0.7 | G41: 0.6 | H41: 0.5 | I41: 0.5 | J41: =$C41*E41 -> 0.080691442 | K41: =$C41*F41 -> 0.070605012 | L41: =$C41*G41 -> 0.060518582 | M41: =$C41*H41 -> 0.050432151 | N41: =$C41*I41 -> 0.050432151 | O41: =VLOOKUP($B41,'增加值 (2001-2060, 2020RMB)'!$A$56:$BI$70,23,0)*(1+J41)^3 -> 9697.68 | P41: =VLOOKUP($B41,'增加值 (2001-2060, 2020RMB)'!$A$56:$BI$70,26,0)*(1+K41)^5 -> 13495.609 | Q41: =VLOOKUP($B41,'增加值 (2001-2060, 2020RMB)'!$A$56:$BI$70,31,0)*(1+L41)^5 -> 17954.888 | R41: =VLOOKUP($B41,'增加值 (2001-2060, 2020RMB)'!$A$56:$BI$70,36,0)*(1+M41)^15 -> 35819.937 | S41: =VLOOKUP($B41,'增加值 (2001-2060, 2020RMB)'!$A$56:$BI$70,51,0)*(1+N41)^10 -> 45726.476 | T41: =O41*$T$28 -> 9595.0255
B42: 公共管理、社会保障和社会组织 | C42: =(VLOOKUP($B42,'增加值 (2001-2060, 2020RMB)'!$A$56:$W$70,20,0)/VLOOKUP($B42,'增加值 (2001-2060, 2020RMB)'!$A$56:$W$70,17,0))^(1/3)-1 -> 0.089033833 | D42: =(VLOOKUP($B42,'增加值 (2001-2060, 2020RMB)'!$A$56:$W$70,23,0)/VLOOKUP($B42,'增加值 (2001-2060, 2020RMB)'!$A$56:$W$70,20,0))^(1/3)-1 -> 0.041121647 | E42: 0.9 | F42: 0.8 | G42: 0.7 | H42: 0.6 | I42: 0.6 | J42: =$C42*E42 -> 0.08013045 | K42: =$C42*F42 -> 0.071227066 | L42: =$C42*G42 -> 0.062323683 | M42: =$C42*H42 -> 0.0534203 | N42: =$C42*I42 -> 0.0534203 | O42: =VLOOKUP($B42,'增加值 (2001-2060, 2020RMB)'!$A$56:$BI$70,23,0)*(1+J42)^3 -> 68323.864 | P42: =VLOOKUP($B42,'增加值 (2001-2060, 2020RMB)'!$A$56:$BI$70,26,0)*(1+K42)^5 -> 95358.276 | Q42: =VLOOKUP($B42,'增加值 (2001-2060, 2020RMB)'!$A$56:$BI$70,31,0)*(1+L42)^5 -> 127950.36 | R42: =VLOOKUP($B42,'增加值 (2001-2060, 2020RMB)'!$A$56:$BI$70,36,0)*(1+M42)^15 -> 266372.12 | S42: =VLOOKUP($B42,'增加值 (2001-2060, 2020RMB)'!$A$56:$BI$70,51,0)*(1+N42)^10 -> 349839.19 | T42: =O42*$T$28 -> 67600.624
A45: 工业年均增速
...

Sheet 增加值 (2001-2060, 2020RMB)
A1: 全国 | B1: 2001 | C1: 2002 | D1: 2003 | E1: 2004 | F1: 2005 | G1: 2006 | H1: 2007 | I1: 2008 | J1: 2009 | K1: 2010 | L1: 2011 | M1: 2012 | N1: 2013 | O1: 2014 | P1: 2015 | Q1: 2016 | R1: 2017 | S1: 2018 | T1: 2019 | U1: 2020 | V1: 2021 | W1: 2022 | X1: 2023 | Y1: 2024 | Z1: 2025 | AA1: 2026 | AB1: 2027 | AC1: 2028 | AD1: 2029 | AE1: 2030 | AF1: 2031 | AG1: 2032 | AH1: 2033 | AI1: 2034 | AJ1: 2035 | AK1: 2036 | AL1: 2037 | AM1: 2038 | AN1: 2039 | AO1: 2040 | AP1: 2041 | AQ1: 2042 | AR1: 2043 | AS1: 2044 | AT1: 2045 | AU1: 2046 | AV1: 2047 | AW1: 2048 | AX1: 2049 | AY1: 2050 | AZ1: 2051 | BA1: 2052 | BB1: 2053 | BC1: 2054 | BD1: 2055 | BE1: 2056 | BF1: 2057 | BG1: 2058 | BH1: 2059 | BI1: 2060
A2: 地区生产总值 | B2: ='增加值 (2001-2022, 当年价) '!B2*B$77 -> 208489.63 | C2: ='增加值 (2001-2022, 当年价) '!C2*C$77 -> 227462.19 | D2: ='增加值 (2001-2022, 当年价) '!D2*D$77 -> 250208.41 | E2: ='增加值 (2001-2022, 当年价) '!E2*E$77 -> 275479.46 | F2: ='增加值 (2001-2022, 当年价) '!F2*F$77 -> 306884.11 | G2: ='增加值 (2001-2022, 当年价) '!G2*G$77 -> 345858.4 | H2: ='增加值 (2001-2022, 当年价) '!H2*H$77 -> 394970.29 | I2: ='增加值 (2001-2022, 当年价) '!I2*I$77 -> 433282.41 | ... W2: ='增加值 (2001-2022, 当年价) '!W2*W$77 -> 1131667.8 | X2: =VLOOKUP($A2,平滑数据导入!$A$1:$AN$61,COLUMN(平滑数据导入!C$1),0) -> 1190492.2 | Y2: =VLOOKUP($A2,平滑数据导入!$A$1:$AN$61,COLUMN(平滑数据导入!D$1),0) -> 1253892.6 | Z2: =W2*(1+情景假设!B3)^3 -> 1321308.1 | AA2: =VLOOKUP($A2,平滑数据导入!$A$1:$AN$61,COLUMN(平滑数据导入!F$1),0) -> 1392021.9 | AB2: =VLOOKUP($A2,平滑数据导入!$A$1:$AN$61,COLUMN(平滑数据导入!G$1),0) -> 1465126.8 | AC2: =VLOOKUP($A2,平滑数据导入!$A$1:$AN$61,COLUMN(平滑数据导入!H$1),0) -> 1539497 | AD2: =VLOOKUP($A2,平滑数据导入!$A$1:$AN$61,COLUMN(平滑数据导入!I$1),0) -> 1613772.7 | AE2: =Z2*(1+情景假设!B4)^5 -> 1686361.1 | AF2: =VLOOKUP($A2,平滑数据导入!$A$1:$AN$61,COLUMN(平滑数据导入!K$1),0) -> 1755860.5 | AG2: =VLOOKUP($A2,平滑数据导入!$A$1:$AN$61,COLUMN(平滑数据导入!L$1),0) -> 1822426.3 | AH2: =VLOOKUP($A2,平滑数据导入!$A$1:$AN$61,COLUMN(平滑数据导入!M$1),0) -> 1886777.8 | AI2: =VLOOKUP($A2,平滑数据导入!$A$1:$AN$61,COLUMN(平滑数据导入!N$1),0) -> 1949806.5 | AJ2: =AE2*(1+情景假设!B5)^5 -> 2012562.4 | AK2: =VLOOKUP($A2,平滑数据导入!$A$1:$AN$61,COLUMN(平滑数据导入!P$1),0) -> 2076007.5 | AL2: =VLOOKUP($A2,平滑数据导入!$A$1:$AN$61,COLUMN(平滑数据导入!Q$1),0) -> 2140230.3 | AM2: =VLOOKUP($A2,平滑数据导入!$A$1:$AN$61,COLUMN(平滑数据导入!R$1),0) -> 2205080.5 | AN2: =VLOOKUP($A2,平滑数据导入!$A$1:$AN$61,COLUMN(平滑数据导入!S$1),0) -> 2270396.7 | AO2: =VLOOKUP($A2,平滑数据导入!$A$1:$AN$61,COLUMN(平滑数据导入!T$1),0) -> 2336004.9 | AP2: =VLOOKUP($A2,平滑数据导入!$A$1:$AN$61,COLUMN(平滑数据导入!U$1),0) -> 2401715.9 | AQ2: =VLOOKUP($A2,平滑数据导入!$A$1:$AN$61,COLUMN(平滑数据导入!V$1),0) -> 2467324.1 | AR2: =VLOOKUP($A2,平滑数据导入!$A$1:$AN$61,COLUMN(平滑数据导入!W$1),0) -> 2532606.2 | ... AX2: =VLOOKUP($A2,平滑数据导入!$A$1:$AN$61,COLUMN(平滑数据导入!AC$1),0) -> 2902558.8 | AY2: =AJ2*(1+情景假设!B6)^15 -> 2957738.4 | AZ2: =VLOOKUP($A2,平滑数据导入!$A$1:$AN$61,COLUMN(平滑数据导入!AE$1),0) -> 3010164.4 | BA2: =VLOOKUP($A2,平滑数据导入!$A$1:$AN$61,COLUMN(平滑数据导入!AF$1),0) -> 3059479.1 | BB2: =VLOOKUP($A2,平滑数据导入!$A$1:$AN$61,COLUMN(平滑数据导入!AG$1),0) -> 3105325 | BC2: =VLOOKUP($A2,平滑数据导入!$A$1:$AN$61,COLUMN(平滑数据导入!AH$1),0) -> 3147350 | BD2: =VLOOKUP($A2,平滑数据导入!$A$1:$AN$61,COLUMN(平滑数据导入!AI$1),0) -> 3185213.2 | BE2: =VLOOKUP($A2,平滑数据导入!$A$1:$AN$61,COLUMN(平滑数据导入!AJ$1),0) -> 3218592.1 | BF2: =VLOOKUP($A2,平滑数据导入!$A$1:$AN$61,COLUMN(平滑数据导入!AK$1),0) -> 3247188.5 | BG2: =VLOOKUP($A2,平滑数据导入!$A$1:$AN$61,COLUMN(平滑数据导入!AL$1),0) -> 3270736.3 | BH2: =VLOOKUP($A2,平滑数据导入!$A$1:$AN$61,COLUMN(平滑数据导入!AM$1),0) -> 3289007.9 | BI2: =AJ2*(1+情景假设!B7)^25 -> 3301821.9
A3: 农业 | B3: ='增加值 (2001-2022, 当年价) '!B3*B$77 -> 29675.937 | C3: ='增加值 (2001-2022, 当年价) '!C3*C$77 -> 30901.469 | D3: ='增加值 (2001-2022, 当年价) '!D3*D$77 -> 31645.386 | E3: ='增加值 (2001-2022, 当年价) '!E3*E$77 -> 36444.641 | F3: ='增加值 (2001-2022, 当年价) '!F3*F$77 -> 36724.408 | G3: ='增加值 (2001-2022, 当年价) '!G3*G$77 -> 37883.921 | H3: ='增加值 (2001-2022, 当年价) '!H3*H$77 -> 41653.225 | I3: ='增加值 (2001-2022, 当年价) '!I3*I$77 -> 45368.998 | ... W3: ='增加值 (2001-2022, 当年价) '!W3*W$77 -> 86574.037 | X3: =VLOOKUP($A3,平滑数据导入!$A$1:$AN$61,COLUMN(平滑数据导入!C$1),0) -> 89593.858 | Y3: =VLOOKUP($A3,平滑数据导入!$A$1:$AN$61,COLUMN(平滑数据导入!D$1),0) -> 93377.236 | Z3: =Z2*情景假设!B15 -> 97776.796 | AA3: =VLOOKUP($A3,平滑数据导入!$A$1:$AN$61,COLUMN(平滑数据导入!F$1),0) -> 102617.73 | AB3: =VLOOKUP($A3,平滑数据导入!$A$1:$AN$61,COLUMN(平滑数据导入!G$1),0) -> 107686.34 | AC3: =VLOOKUP($A3,平滑数据导入!$A$1:$AN$61,COLUMN(平滑数据导入!H$1),0) -> 112722.42 | AD3: =VLOOKUP($A3,平滑数据导入!$A$1:$AN$61,COLUMN(平滑数据导入!I$1),0) -> 117417.05 | AE3: =AE2*情景假设!B16 -> 121418 | AF3: =VLOOKUP($A3,平滑数据导入!$A$1:$AN$61,COLUMN(平滑数据导入!K$1),0) -> 124444.1 | AG3: =VLOOKUP($A3,平滑数据导入!$A$1:$AN$61,COLUMN(平滑数据导入!L$1),0) -> 126621.41 | AH3: =VLOOKUP($A3,平滑数据导入!$A$1:$AN$61,COLUMN(平滑数据导入!M$1),0) -> 128213.07 | AI3: =VLOOKUP($A3,平滑数据导入!$A$1:$AN$61,COLUMN(平滑数据导入!N$1),0) -> 129509.19 | AJ3: =AJ2*情景假设!B17 -> 130816.56 | AK3: =VLOOKUP($A3,平滑数据导入!$A$1:$AN$61,COLUMN(平滑数据导入!P$1),0) -> 132395.57 | AL3: =VLOOKUP($A3,平滑数据导入!$A$1:$AN$61,COLUMN(平滑数据导入!Q$1),0) -> 134277.6 | AM3: =VLOOKUP($A3,平滑数据导入!$A$1:$AN$61,COLUMN(平滑数据导入!R$1),0) -> 136435.66 | AN3: =VLOOKUP($A3,平滑数据导入!$A$1:$AN$61,COLUMN(平滑数据导入!S$1),0) -> 138842.1 | AO3: =VLOOKUP($A3,平滑数据导入!$A$1:$AN$61,COLUMN(平滑数据导入!T$1),0) -> 141468 | AP3: =VLOOKUP($A3,平滑数据导入!$A$1:$AN$61,COLUMN(平滑数据导入!U$1),0) -> 144282.54 | AQ3: =VLOOKUP($A3,平滑数据导入!$A$1:$AN$61,COLUMN(平滑数据导入!V$1),0) -> 147252.5 | AR3: =VLOOKUP($A3,平滑数据导入!$A$1:$AN$61,COLUMN(平滑数据导入!W$1),0) -> 150341.77 | ... AX3: =VLOOKUP($A3,平滑数据导入!$A$1:$AN$61,COLUMN(平滑数据导入!AC$1),0) -> 168927.36 | AY3: =AY2*情景假设!B18 -> 171548.83 | AZ3: =VLOOKUP($A3,平滑数据导入!$A$1:$AN$61,COLUMN(平滑数据导入!AE$1),0) -> 173876.92 | BA3: =VLOOKUP($A3,平滑数据导入!$A$1:$AN$61,COLUMN(平滑数据导入!AF$1),0) -> 175847.94 | BB3: =VLOOKUP($A3,平滑数据导入!$A$1:$AN$61,COLUMN(平滑数据导入!AG$1),0) -> 177397.95 | BC3: =VLOOKUP($A3,平滑数据导入!$A$1:$AN$61,COLUMN(平滑数据导入!AH$1),0) -> 178464.02 | BD3: =VLOOKUP($A3,平滑数据导入!$A$1:$AN$61,COLUMN(平滑数据导入!AI$1),0) -> 178985.68 | BE3: =VLOOKUP($A3,平滑数据导入!$A$1:$AN$61,COLUMN(平滑数据导入!AJ$1),0) -> 178906.55 | BF3: =VLOOKUP($A3,平滑数据导入!$A$1:$AN$61,COLUMN(平滑数据导入!AK$1),0) -> 178176.04 | BG3: =VLOOKUP($A3,平滑数据导入!$A$1:$AN$61,COLUMN(平滑数据导入!AL$1),0) -> 176751.15 | BH3: =VLOOKUP($A3,平滑数据导入!$A$1:$AN$61,COLUMN(平滑数据导入!AM$1),0) -> 174598.25 | BI3: =BI2*情景假设!B19 -> 171694.74
A4: 工业 | B4: ='增加值 (2001-2022, 当年价) '!B4*B$77 -> 82472.589 | C4: ='增加值 (2001-2022, 当年价) '!C4*C$77 -> 89280.442 | D4: ='增加值 (2001-2022, 当年价) '!D4*D$77 -> 100799.64 | E4: ='增加值 (2001-2022, 当年价) '!E4*E$77 -> 111960.03 | F4: ='增加值 (2001-2022, 当年价) '!F4*F$77 -> 127718.9 | G4: ='增加值 (2001-2022, 当年价) '!G4*G$77 -> 145373.42 | H4: ='增加值 (2001-2022, 当年价) '!H4*H$77 -> 163331.38 | I4: ='增加值 (2001-2022, 当年价) '!I4*I$77 -> 178777.31 | ... W4: ='增加值 (2001-2022, 当年价) '!W4*W$77 -> 375578.61 | X4: =VLOOKUP($A4,平滑数据导入!$A$1:$AN$61,COLUMN(平滑数据导入!C$1),0) -> 390173.76 | Y4: =VLOOKUP($A4,平滑数据导入!$A$1:$AN$61,COLUMN(平滑数据导入!D$1),0) -> 405076.36 | Z4: =Z2*情景假设!D15 -> 420175.96 | AA4: =VLOOKUP($A4,平滑数据导入!$A$1:$AN$61,COLUMN(平滑数据导入!F$1),0) -> 435354.15 | AB4: =VLOOKUP($A4,平滑数据导入!$A$1:$AN$61,COLUMN(平滑数据导入!G$1),0) -> 450482.34 | AC4: =VLOOKUP($A4,平滑数据导入!$A$1:$AN$61,COLUMN(平滑数据导入!H$1),0) -> 465420.25 | AD4: =VLOOKUP($A4,平滑数据导入!$A$1:$AN$61,COLUMN(平滑数据导入!I$1),0) -> 480015.42 | AE4: =AE2*情景假设!D16 -> 494103.81 | AF4: =VLOOKUP($A4,平滑数据导入!$A$1:$AN$61,COLUMN(平滑数据导入!K$1),0) -> 507532.59 | AG4: =VLOOKUP($A4,平滑数据导入!$A$1:$AN$61,COLUMN(平滑数据导入!L$1),0) -> 520228.48 | AH4: =VLOOKUP($A4,平滑数据导入!$A$1:$AN$61,COLUMN(平滑数据导入!M$1),0) -> 532142.76 | AI4: =VLOOKUP($A4,平滑数据导入!$A$1:$AN$61,COLUMN(平滑数据导入!N$1),0) -> 543231.31 | AJ4: =AJ2*情景假设!D17 -> 553454.66 | AK4: =VLOOKUP($A4,平滑数据导入!$A$1:$AN$61,COLUMN(平滑数据导入!P$1),0) -> 562783.57 | AL4: =VLOOKUP($A4,平滑数据导入!$A$1:$AN$61,COLUMN(平滑数据导入!Q$1),0) -> 571217.09 | AM4: =VLOOKUP($A4,平滑数据导入!$A$1:$AN$61,COLUMN(平滑数据导入!R$1),0) -> 578768.78 | AN4: =VLOOKUP($A4,平滑数据导入!$A$1:$AN$61,COLUMN(平滑数据导入!S$1),0) -> 585461.07 | AO4: =VLOOKUP($A4,平滑数据导入!$A$1:$AN$61,COLUMN(平滑数据导入!T$1),0) -> 591324.45 | AP4: =VLOOKUP($A4,平滑数据导入!$A$1:$AN$61,COLUMN(平滑数据导入!U$1),0) -> 596396.74 | AQ4: =VLOOKUP($A4,平滑数据导入!$A$1:$AN$61,COLUMN(平滑数据导入!V$1),0) -> 600722.16 | AR4: =VLOOKUP($A4,平滑数据导入!$A$1:$AN$61,COLUMN(平滑数据导入!W$1),0) -> 604350.52 | ... AX4: =VLOOKUP($A4,平滑数据导入!$A$1:$AN$61,COLUMN(平滑数据导入!AC$1),0) -> 614766.03 | AY4: =AY2*情景假设!D18 -> 615209.6 | AZ4: =VLOOKUP($A4,平滑数据导入!$A$1:$AN$61,COLUMN(平滑数据导入!AE$1),0) -> 615463.74 | BA4: =VLOOKUP($A4,平滑数据导入!$A$1:$AN$61,COLUMN(平滑数据导入!AF$1),0) -> 615597.33 | BB4: =VLOOKUP($A4,平滑数据导入!$A$1:$AN$61,COLUMN(平滑数据导入!AG$1),0) -> 615679.48 | BC4: =VLOOKUP($A4,平滑数据导入!$A$1:$AN$61,COLUMN(平滑数据导入!AH$1),0) -> 615779.6 | BD4: =VLOOKUP($A4,平滑数据导入!$A$1:$AN$61,COLUMN(平滑数据导入!AI$1),0) -> 615967.53 | BE4: =VLOOKUP($A4,平滑数据导入!$A$1:$AN$61,COLUMN(平滑数据导入!AJ$1),0) -> 616313.8 | BF4: =VLOOKUP($A4,平滑数据导入!$A$1:$AN$61,COLUMN(平滑数据导入!AK$1),0) -> 616890 | BG4: =VLOOKUP($A4,平滑数据导入!$A$1:$AN$61,COLUMN(平滑数据导入!AL$1),0) -> 617769.34 | BH4: =VLOOKUP($A4,平滑数据导入!$A$1:$AN$61,COLUMN(平滑数据导入!AM$1),0) -> 619027.31 | BI4: =BI2*情景假设!D19 -> 620742.52
A5: 建筑业 | B5: ='增加值 (2001-2022, 当年价) '!B5*B$77 -> 11181.133 | C5: ='增加值 (2001-2022, 当年价) '!C5*C$77 -> 12113.573 | D5: ='增加值 (2001-2022, 当年价) '!D5*D$77 -> 13675.142 | E5: ='增加值 (2001-2022, 当年价) '!E5*E$77 -> 14843.769 | F5: ='增加值 (2001-2022, 当年价) '!F5*F$77 -> 17039.115 | G5: ='增加值 (2001-2022, 当年价) '!G5*G$77 -> 19622.681 | H5: ='增加值 (2001-2022, 当年价) '!H5*H$77 -> 22444.194 | I5: ='增加值 (2001-2022, 当年价) '!I5*I$77 -> 25525.889 | ... W5: ='增加值 (2001-2022, 当年价) '!W5*W$77 -> 77971.749 | X5: =VLOOKUP($A5,平滑数据导入!$A$1:$AN$61,COLUMN(平滑数据导入!C$1),0) -> 81718.592 | Y5: =VLOOKUP($A5,平滑数据导入!$A$1:$AN$61,COLUMN(平滑数据导入!D$1),0) -> 85700.351 | Z5: =Z2*情景假设!E15 -> 89848.948 | AA5: =VLOOKUP($A5,平滑数据导入!$A$1:$AN$61,COLUMN(平滑数据导入!F$1),0) -> 94081.146 | AB5: =VLOOKUP($A5,平滑数据导入!$A$1:$AN$61,COLUMN(平滑数据导入!G$1),0) -> 98297.382 | AC5: =VLOOKUP($A5,平滑数据导入!$A$1:$AN$61,COLUMN(平滑数据导入!H$1),0) -> 102381.53 | AD5: =VLOOKUP($A5,平滑数据导入!$A$1:$AN$61,COLUMN(平滑数据导入!I$1),0) -> 106201.85 | AE5: =AE2*情景假设!E16 -> 109613.47 | AF5: =VLOOKUP($A5,平滑数据导入!$A$1:$AN$61,COLUMN(平滑数据导入!K$1),0) -> 112504.74 | AG5: =VLOOKUP($A5,平滑数据导入!$A$1:$AN$61,COLUMN(平滑数据导入!L$1),0) -> 114936.71 | AH5: =VLOOKUP($A5,平滑数据导入!$A$1:$AN$61,COLUMN(平滑数据导入!M$1),0) -> 117029.93 | AI5: =VLOOKUP($A5,平滑数据导入!$A$1:$AN$61,COLUMN(平滑数据导入!N$1),0) -> 118919.89 | AJ5: =AJ2*情景假设!E17 -> 120753.74 | AK5: =VLOOKUP($A5,平滑数据导入!$A$1:$AN$61,COLUMN(平滑数据导入!P$1),0) -> 122659.84 | AL5: =VLOOKUP($A5,平滑数据导入!$A$1:$AN$61,COLUMN(平滑数据导入!Q$1),0) -> 124657.65 | AM5: =VLOOKUP($A5,平滑数据导入!$A$1:$AN$61,COLUMN(平滑数据导入!R$1),0) -> 126738.16 | AN5: =VLOOKUP($A5,平滑数据导入!$A$1:$AN$61,COLUMN(平滑数据导入!S$1),0) -> 128891.68 | AO5: =VLOOKUP($A5,平滑数据导入!$A$1:$AN$61,COLUMN(平滑数据导入!T$1),0) -> 131107.78 | AP5: =VLOOKUP($A5,平滑数据导入!$A$1:$AN$61,COLUMN(平滑数据导入!U$1),0) -> 133375.25 | AQ5: =VLOOKUP($A5,平滑数据导入!$A$1:$AN$61,COLUMN(平滑数据导入!V$1),0) -> 135682.03 | AR5: =VLOOKUP($A5,平滑数据导入!$A$1:$AN$61,COLUMN(平滑数据导入!W$1),0) -> 138015.18 | ... AX5: =VLOOKUP($A5,平滑数据导入!$A$1:$AN$61,COLUMN(平滑数据导入!AC$1),0) -> 151725.2 | AY5: =AY2*情景假设!E18 -> 153802.4 | AZ5: =VLOOKUP($A5,平滑数据导入!$A$1:$AN$61,COLUMN(平滑数据导入!AE$1),0) -> 155769.62 | BA5: =VLOOKUP($A5,平滑数据导入!$A$1:$AN$61,COLUMN(平滑数据导入!AF$1),0) -> 157606.38 | BB5: =VLOOKUP($A5,平滑数据导入!$A$1:$AN$61,COLUMN(平滑数据导入!AG$1),0) -> 159291.75 | BC5: =VLOOKUP($A5,平滑数据导入!$A$1:$AN$61,COLUMN(平滑数据导入!AH$1),0) -> 160804.56 | BD5: =VLOOKUP($A5,平滑数据导入!$A$1:$AN$61,COLUMN(平滑数据导入!AI$1),0) -> 162123.55 | BE5: =VLOOKUP($A5,平滑数据导入!$A$1:$AN$61,COLUMN(平滑数据导入!AJ$1),0) -> 163227.61 | BF5: =VLOOKUP($A5,平滑数据导入!$A$1:$AN$61,COLUMN(平滑数据导入!AK$1),0) -> 164096.02 | BG5: =VLOOKUP($A5,平滑数据导入!$A$1:$AN$61,COLUMN(平滑数据导入!AL$1),0) -> 164708.66 | BH5: =VLOOKUP($A5,平滑数据导入!$A$1:$AN$61,COLUMN(平滑数据导入!AM$1),0) -> 165046.36 | BI5: =BI2*情景假设!E19 -> 165091.1
A6: 交运仓邮 | B6: ='增加值 (2001-2022, 当年价) '!B6*B$77 -> 12922.197 | C6: ='增加值 (2001-2022, 当年价) '!C6*C$77 -> 14005.145 | D6: ='增加值 (2001-2022, 当年价) '!D6*D$77 -> 14410.717 | E6: ='增加值 (2001-2022, 当年价) '!E6*E$77 -> 15841.241 | F6: ='增加值 (2001-2022, 当年价) '!F6*F$77 -> 17478.67 | G6: ='增加值 (2001-2022, 当年价) '!G6*G$77 -> 19206.904 | H6: ='增加值 (2001-2022, 当年价) '!H6*H$77 -> 21357.812 | I6: ='增加值 (2001-2022, 当年价) '!I6*I$77 -> 22214.293 | ... W6: ='增加值 (2001-2022, 当年价) '!W6*W$77 -> 46450.003 | X6: =VLOOKUP($A6,平滑数据导入!$A$1:$AN$61,COLUMN(平滑数据导入!C$1),0) -> 48311.096 | Y6: =VLOOKUP($A6,平滑数据导入!$A$1:$AN$61,COLUMN(平滑数据导入!D$1),0) -> 50291.271 | Z6: =Z57 -> 52364.67 | AA6: =VLOOKUP($A6,平滑数据导入!$A$1:$AN$61,COLUMN(平滑数据导入!F$1),0) -> 54500.397 | AB6: =VLOOKUP($A6,平滑数据导入!$A$1:$AN$61,COLUMN(平滑数据导入!G$1),0) -> 56662.006 | AC6: =VLOOKUP($A6,平滑数据导入!$A$1:$AN$61,COLUMN(平滑数据导入!H$1),0) -> 58807.227 | AD6: =VLOOKUP($A6,平滑数据导入!$A$1:$AN$61,COLUMN(平滑数据导入!I$1),0) -> 60887.956 | AE6: =AE57 -> 62850.612 | AF6: =VLOOKUP($A6,平滑数据导入!$A$1:$AN$61,COLUMN(平滑数据导入!K$1),0) -> 64650.658 | AG6: =VLOOKUP($A6,平滑数据导入!$A$1:$AN$61,COLUMN(平滑数据导入!L$1),0) -> 66297.833 | AH6: =VLOOKUP($A6,平滑数据导入!$A$1:$AN$61,COLUMN(平滑数据导入!M$1),0) -> 67820.15 | AI6: =VLOOKUP($A6,平滑数据导入!$A$1:$AN$61,COLUMN(平滑数据导入!N$1),0) -> 69250.232 | AJ6: =AJ57 -> 70624.741 | AK6: =VLOOKUP($A6,平滑数据导入!$A$1:$AN$61,COLUMN(平滑数据导入!P$1),0) -> 71975.237 | AL6: =VLOOKUP($A6,平滑数据导入!$A$1:$AN$61,COLUMN(平滑数据导入!Q$1),0) -> 73300.506 | AM6: =VLOOKUP($A6,平滑数据导入!$A$1:$AN$61,COLUMN(平滑数据导入!R$1),0) -> 74590.395 | AN6: =VLOOKUP($A6,平滑数据导入!$A$1:$AN$61,COLUMN(平滑数据导入!S$1),0) -> 75834.238 | AO6: =VLOOKUP($A6,平滑数据导入!$A$1:$AN$61,COLUMN(平滑数据导入!T$1),0) -> 77020.914 | AP6: =VLOOKUP($A6,平滑数据导入!$A$1:$AN$61,COLUMN(平滑数据导入!U$1),0) -> 78138.909 | AQ6: =VLOOKUP($A6,平滑数据导入!$A$1:$AN$61,COLUMN(平滑数据导入!V$1),0) -> 79176.407 | AR6: =VLOOKUP($A6,平滑数据导入!$A$1:$AN$61,COLUMN(平滑数据导入!W$1),0) -> 80121.382 | ... AX6: =VLOOKUP($A6,平滑数据导入!$A$1:$AN$61,COLUMN(平滑数据导入!AC$1),0) -> 83180.258 | AY6: =AY57 -> 83150.758 | AZ6: =VLOOKUP($A6,平滑数据导入!$A$1:$AN$61,COLUMN(平滑数据导入!AE$1),0) -> 82941.478 | BA6: =VLOOKUP($A6,平滑数据导入!$A$1:$AN$61,COLUMN(平滑数据导入!AF$1),0) -> 82545.112 | BB6: =VLOOKUP($A6,平滑数据导入!$A$1:$AN$61,COLUMN(平滑数据导入!AG$1),0) -> 81955.747 | BC6: =VLOOKUP($A6,平滑数据导入!$A$1:$AN$61,COLUMN(平滑数据导入!AH$1),0) -> 81169.03 | BD6: =VLOOKUP($A6,平滑数据导入!$A$1:$AN$61,COLUMN(平滑数据导入!AI$1),0) -> 80182.318 | BE6: =VLOOKUP($A6,平滑数据导入!$A$1:$AN$61,COLUMN(平滑数据导入!AJ$1),0) -> 78994.818 | BF6: =VLOOKUP($A6,平滑数据导入!$A$1:$AN$61,COLUMN(平滑数据导入!AK$1),0) -> 77607.692 | BG6: =VLOOKUP($A6,平滑数据导入!$A$1:$AN$61,COLUMN(平滑数据导入!AL$1),0) -> 76024.141 | BH6: =VLOOKUP($A6,平滑数据导入!$A$1:$AN$61,COLUMN(平滑数据导入!AM$1),0) -> 74249.46 | BI6: =BI57 -> 72291.048
A7: 批发零售 | B7: ='增加值 (2001-2022, 当年价) '!B7*B$77 -> 17152.616 | C7: ='增加值 (2001-2022, 当年价) '!C7*C$77 -> 18681.75 | D7: ='增加值 (2001-2022, 当年价) '!D7*D$77 -> 20339.743 | E7: ='增加值 (2001-2022, 当年价) '!E7*E$77 -> 21201.883 | F7: ='增加值 (2001-2022, 当年价) '!F7*F$77 -> 22884.561 | G7: ='增加值 (2001-2022, 当年价) '!G7*G$77 -> 26058.396 | H7: ='增加值 (2001-2022, 当年价) '!H7*H$77 -> 30623.281 | I7: ='增加值 (2001-2022, 当年价) '!I7*I$77 -> 35540.209 | ... W7: ='增加值 (2001-2022, 当年价) '!W7*W$77 -> 107085.79 | X7: =VLOOKUP($A7,平滑数据导入!$A$1:$AN$61,COLUMN(平滑数据导入!C$1),0) -> 111656.94 | Y7: =VLOOKUP($A7,平滑数据导入!$A$1:$AN$61,COLUMN(平滑数据导入!D$1),0) -> 116516.9 | Z7: =Z58 -> 121606.9 | AA7: =VLOOKUP($A7,平滑数据导入!$A$1:$AN$61,COLUMN(平滑数据导入!F$1),0) -> 126855.82 | AB7: =VLOOKUP($A7,平滑数据导入!$A$1:$AN$61,COLUMN(平滑数据导入!G$1),0) -> 132178.92 | AC7: =VLOOKUP($A7,平滑数据导入!$A$1:$AN$61,COLUMN(平滑数据导入!H$1),0) -> 137477.11 | AD7: =VLOOKUP($A7,平滑数据导入!$A$1:$AN$61,COLUMN(平滑数据导入!I$1),0) -> 142636.87 | AE7: =AE58 -> 147530.97 | AF7: =VLOOKUP($A7,平滑数据导入!$A$1:$AN$61,COLUMN(平滑数据导入!K$1),0) -> 152052.59 | AG7: =VLOOKUP($A7,平滑数据导入!$A$1:$AN$61,COLUMN(平滑数据导入!L$1),0) -> 156222.33 | AH7: =VLOOKUP($A7,平滑数据导入!$A$1:$AN$61,COLUMN(平滑数据导入!M$1),0) -> 160104.26 | AI7: =VLOOKUP($A7,平滑数据导入!$A$1:$AN$61,COLUMN(平滑数据导入!N$1),0) -> 163774.05 | AJ7: =AJ58 -> 167317.58 | AK7: =VLOOKUP($A7,平滑数据导入!$A$1:$AN$61,COLUMN(平滑数据导入!P$1),0) -> 170809.32 | AL7: =VLOOKUP($A7,平滑数据导入!$A$1:$AN$61,COLUMN(平滑数据导入!Q$1),0) -> 174246.24 | AM7: =VLOOKUP($A7,平滑数据导入!$A$1:$AN$61,COLUMN(平滑数据导入!R$1),0) -> 177604.05 | AN7: =VLOOKUP($A7,平滑数据导入!$A$1:$AN$61,COLUMN(平滑数据导入!S$1),0) -> 180857.12 | AO7: =VLOOKUP($A7,平滑数据导入!$A$1:$AN$61,COLUMN(平滑数据导入!T$1),0) -> 183978.61 | AP7: =VLOOKUP($A7,平滑数据导入!$A$1:$AN$61,COLUMN(平滑数据导入!U$1),0) -> 186940.66 | AQ7: =VLOOKUP($A7,平滑数据导入!$A$1:$AN$61,COLUMN(平滑数据导入!V$1),0) -> 189714.54 | AR7: =VLOOKUP($A7,平滑数据导入!$A$1:$AN$61,COLUMN(平滑数据导入!W$1),0) -> 192270.9 | ... AX7: =VLOOKUP($A7,平滑数据导入!$A$1:$AN$61,COLUMN(平滑数据导入!AC$1),0) -> 201395.08 | AY7: =AY58 -> 201620.3 | AZ7: =VLOOKUP($A7,平滑数据导入!$A$1:$AN$61,COLUMN(平滑数据导入!AE$1),0) -> 201410.17 | BA7: =VLOOKUP($A7,平滑数据导入!$A$1:$AN$61,COLUMN(平滑数据导入!AF$1),0) -> 200745.56 | BB7: =VLOOKUP($A7,平滑数据导入!$A$1:$AN$61,COLUMN(平滑数据导入!AG$1),0) -> 199610.63 | BC7: =VLOOKUP($A7,平滑数据导入!$A$1:$AN$61,COLUMN(平滑数据导入!AH$1),0) -> 197993.18 | BD7: =VLOOKUP($A7,平滑数据导入!$A$1:$AN$61,COLUMN(平滑数据导入!AI$1),0) -> 195885.07 | BE7: =VLOOKUP($A7,平滑数据导入!$A$1:$AN$61,COLUMN(平滑数据导入!AJ$1),0) -> 193282.57 | BF7: =VLOOKUP($A7,平滑数据导入!$A$1:$AN$61,COLUMN(平滑数据导入!AK$1),0) -> 190186.65 | BG7: =VLOOKUP($A7,平滑数据导入!$A$1:$AN$61,COLUMN(平滑数据导入!AL$1),0) -> 186603.17 | BH7: =VLOOKUP($A7,平滑数据导入!$A$1:$AN$61,COLUMN(平滑数据导入!AM$1),0) -> 182543.07 | BI7: =BI58 -> 178022.45
A8: 餐饮住宿 | B8: ='增加值 (2001-2022, 当年价) '!B8*B$77 -> 4513.6386 | C8: ='增加值 (2001-2022, 当年价) '!C8*C$77 -> 5092.0326 | D8: ='增加值 (2001-2022, 当年价) '!D8*D$77 -> 5691.7852 | E8: ='增加值 (2001-2022, 当年价) '!E8*E$77 -> 6238.1109 | F8: ='增加值 (2001-2022, 当年价) '!F8*F$77 -> 6873.8055 | G8: ='增加值 (2001-2022, 当年价) '!G8*G$77 -> 7553.6469 | H8: ='增加值 (2001-2022, 当年价) '!H8*H$77 -> 8113.2808 | I8: ='增加值 (2001-2022, 当年价) '!I8*I$77 -> 8979.4463 | ... W8: ='增加值 (2001-2022, 当年价) '!W8*W$77 -> 16696.536 | X8: =VLOOKUP($A8,平滑数据导入!$A$1:$AN$61,COLUMN(平滑数据导入!C$1),0) -> 17477.111 | Y8: =VLOOKUP($A8,平滑数据导入!$A$1:$AN$61,COLUMN(平滑数据导入!D$1),0) -> 18306.608 | Z8: =Z59 -> 19176.081 | AA8: =VLOOKUP($A8,平滑数据导入!$A$1:$AN$61,COLUMN(平滑数据导入!F$1),0) -> 20074.482 | AB8: =VLOOKUP($A8,平滑数据导入!$A$1:$AN$61,COLUMN(平滑数据导入!G$1),0) -> 20988.439 | AC8: =VLOOKUP($A8,平滑数据导入!$A$1:$AN$61,COLUMN(平滑数据导入!H$1),0) -> 21902.112 | AD8: =VLOOKUP($A8,平滑数据导入!$A$1:$AN$61,COLUMN(平滑数据导入!I$1),0) -> 22797.157 | AE8: =AE59 -> 23652.825 | AF8: =VLOOKUP($A8,平滑数据导入!$A$1:$AN$61,COLUMN(平滑数据导入!K$1),0) -> 24451.437 | AG8: =VLOOKUP($A8,平滑数据导入!$A$1:$AN$61,COLUMN(平滑数据导入!L$1),0) -> 25195.724 | AH8: =VLOOKUP($A8,平滑数据导入!$A$1:$AN$61,COLUMN(平滑数据导入!M$1),0) -> 25895.546 | AI8: =VLOOKUP($A8,平滑数据导入!$A$1:$AN$61,COLUMN(平滑数据导入!N$1),0) -> 26562.797 | AJ8: =AJ59 -> 27211.202 | AK8: =VLOOKUP($A8,平滑数据导入!$A$1:$AN$61,COLUMN(平滑数据导入!P$1),0) -> 27852.789 | AL8: =VLOOKUP($A8,平滑数据导入!$A$1:$AN$61,COLUMN(平滑数据导入!Q$1),0) -> 28487.032 | AM8: =VLOOKUP($A8,平滑数据导入!$A$1:$AN$61,COLUMN(平滑数据导入!R$1),0) -> 29109.916 | AN8: =VLOOKUP($A8,平滑数据导入!$A$1:$AN$61,COLUMN(平滑数据导入!S$1),0) -> 29717.182 | AO8: =VLOOKUP($A8,平滑数据导入!$A$1:$AN$61,COLUMN(平滑数据导入!T$1),0) -> 30304.343 | AP8: =VLOOKUP($A8,平滑数据导入!$A$1:$AN$61,COLUMN(平滑数据导入!U$1),0) -> 30866.713 | AQ8: =VLOOKUP($A8,平滑数据导入!$A$1:$AN$61,COLUMN(平滑数据导入!V$1),0) -> 31399.435 | AR8: =VLOOKUP($A8,平滑数据导入!$A$1:$AN$61,COLUMN(平滑数据导入!W$1),0) -> 31897.519 | ... AX8: =VLOOKUP($A8,平滑数据导入!$A$1:$AN$61,COLUMN(平滑数据导入!AC$1),0) -> 33874.513 | AY8: =AY59 -> 33989.781 | AZ8: =VLOOKUP($A8,平滑数据导入!$A$1:$AN$61,COLUMN(平滑数据导入!AE$1),0) -> 34032.095 | BA8: =VLOOKUP($A8,平滑数据导入!$A$1:$AN$61,COLUMN(平滑数据导入!AF$1),0) -> 33997.87 | BB8: =VLOOKUP($A8,平滑数据导入!$A$1:$AN$61,COLUMN(平滑数据导入!AG$1),0) -> 33884.034 | BC8: =VLOOKUP($A8,平滑数据导入!$A$1:$AN$61,COLUMN(平滑数据导入!AH$1),0) -> 33688.103 | BD8: =VLOOKUP($A8,平滑数据导入!$A$1:$AN$61,COLUMN(平滑数据导入!AI$1),0) -> 33408.251 | BE8: =VLOOKUP($A8,平滑数据导入!$A$1:$AN$61,COLUMN(平滑数据导入!AJ$1),0) -> 33043.369 | BF8: =VLOOKUP($A8,平滑数据导入!$A$1:$AN$61,COLUMN(平滑数据导入!AK$1),0) -> 32593.123 | BG8: =VLOOKUP($A8,平滑数据导入!$A$1:$AN$61,COLUMN(平滑数据导入!AL$1),0) -> 32057.998 | BH8: =VLOOKUP($A8,平滑数据导入!$A$1:$AN$61,COLUMN(平滑数据导入!AM$1),0) -> 31439.327 | BI8: =BI59 -> 30739.316
