Workbook

Sheet 高情景
A1: 行业 | B1: 计量指标 | C1: 计量单位 | D1: 数据来源 | E1: 2020 | F1: 2021 | G1: 2022 | H1: 2023 | I1: 2024 | J1: 2025 | K1: 2026 | L1: 2027 | M1: 2028 | N1: 2029 | O1: 2030 | P1: 2031 | Q1: 2032 | R1: 2033 | S1: 2034 | T1: 2035 | U1: 2036 | V1: 2037 | W1: 2038 | X1: 2039 | Y1: 2040 | Z1: 2041 | AA1: 2042 | AB1: 2043 | AC1: 2044 | AD1: 2045 | AE1: 2046 | AF1: 2047 | AG1: 2048 | AH1: 2049 | AI1: 2050 | AJ1: 2051 | AK1: 2052 | AL1: 2053 | AM1: 2054 | AN1: 2055 | AO1: 2056 | AP1: 2057 | AQ1: 2058 | AR1: 2059 | AS1: 2060
A2: 煤炭开采和洗选业 | B2: 原煤 | C2: 亿吨 | D2: 中石化《中国能源展望2060》 | E2: 39.02 | F2: 41.26 | G2: 45.59 | H2: =G2+($J2-$G2)/3 -> 46.393333 | I2: =H2+($J2-$G2)/3 -> 47.196667 | J2: 48 | K2: =J2+($O2-$J2)/5 -> 47.6 | L2: =K2+($O2-$J2)/5 -> 47.2 | M2: =L2+($O2-$J2)/5 -> 46.8 | N2: =M2+($O2-$J2)/5 -> 46.4 | O2: =46 -> 46 | P2: =O2+($T2-$O2)/5 -> 44.601961 | Q2: =P2+($T2-$O2)/5 -> 43.203922 | R2: =Q2+($T2-$O2)/5 -> 41.805882 | S2: =R2+($T2-$O2)/5 -> 40.407843 | T2: =O2*(34.6/40.8) -> 39.009804 | U2: =T2+($Y2-$T2)/5 -> 37.544118 | V2: =U2+($Y2-$T2)/5 -> 36.078431 | W2: =V2+($Y2-$T2)/5 -> 34.612745 | X2: =W2+($Y2-$T2)/5 -> 33.147059 | Y2: =T2*(28.1/34.6) -> 31.681373 | Z2: =Y2+($AD2-$Y2)/5 -> 30.148039 | AA2: =Z2+($AD2-$Y2)/5 -> 28.614706 | AB2: =AA2+($AD2-$Y2)/5 -> 27.081373 | AC2: =AB2+($AD2-$Y2)/5 -> 25.548039 | AD2: =Y2*(21.3/28.1) -> 24.014706 | AE2: =AD2+($AI2-$AD2)/5 -> 22.391176 | AF2: =AE2+($AI2-$AD2)/5 -> 20.767647 | AG2: =AF2+($AI2-$AD2)/5 -> 19.144118 | AH2: =AG2+($AI2-$AD2)/5 -> 17.520588 | AI2: =AD2*(14.1/21.3) -> 15.897059 | AJ2: =AI2+($AN2-$AI2)/5 -> 14.634314 | AK2: =AJ2+($AN2-$AI2)/5 -> 13.371569 | AL2: =AK2+($AN2-$AI2)/5 -> 12.108824 | AM2: =AL2+($AN2-$AI2)/5 -> 10.846078 | AN2: =AI2*(8.5/14.1) -> 9.5833333 | AO2: =AN2+($AS2-$AN2)/5 -> 8.5235294 | AP2: =AO2+($AS2-$AN2)/5 -> 7.4637255 | AQ2: =AP2+($AS2-$AN2)/5 -> 6.4039216 | AR2: =AQ2+($AS2-$AN2)/5 -> 5.3441176 | AS2: =AN2*(3.8/8.5) -> 4.2843137
A3: 石油和天然气开采业 | B3: 原油 | C3: 亿吨 | D3: 中石油《世界与中国能源展望2021》 | E3: 1.9477 | F3: 1.9888 | G3: 2.0472 | H3: =G3+($J3-$G3)/3 -> 2.0781333 | I3: =H3+($J3-$G3)/3 -> 2.1090667 | J3: 2.14 | K3: =J3+($O3-$J3)/5 -> 2.146 | L3: =K3+($O3-$J3)/5 -> 2.152 | M3: =L3+($O3-$J3)/5 -> 2.158 | N3: =M3+($O3-$J3)/5 -> 2.164 | O3: 2.17 | P3: =O3+($T3-$O3)/5 -> 2.156 | Q3: =P3+($T3-$O3)/5 -> 2.142 | R3: =Q3+($T3-$O3)/5 -> 2.128 | S3: =R3+($T3-$O3)/5 -> 2.114 | T3: 2.1 | U3: =T3+($Y3-$T3)/5 -> 2.08 | V3: =U3+($Y3-$T3)/5 -> 2.06 | W3: =V3+($Y3-$T3)/5 -> 2.04 | X3: =W3+($Y3-$T3)/5 -> 2.02 | Y3: 2 | Z3: =Y3+($AD3-$Y3)/5 -> 1.98 | AA3: =Z3+($AD3-$Y3)/5 -> 1.96 | AB3: =AA3+($AD3-$Y3)/5 -> 1.94 | AC3: =AB3+($AD3-$Y3)/5 -> 1.92 | AD3: 1.9 | AE3: =AD3+($AI3-$AD3)/5 -> 1.884 | AF3: =AE3+($AI3-$AD3)/5 -> 1.868 | AG3: =AF3+($AI3-$AD3)/5 -> 1.852 | AH3: =AG3+($AI3-$AD3)/5 -> 1.836 | AI3: 1.82 | AJ3: =AI3+($AN3-$AI3)/5 -> 1.806 | AK3: =AJ3+($AN3-$AI3)/5 -> 1.792 | AL3: =AK3+($AN3-$AI3)/5 -> 1.778 | AM3: =AL3+($AN3-$AI3)/5 -> 1.764 | AN3: 1.75 | AO3: =AN3+($AS3-$AN3)/5 -> 1.74 | AP3: =AO3+($AS3-$AN3)/5 -> 1.73 | AQ3: =AP3+($AS3-$AN3)/5 -> 1.72 | AR3: =AQ3+($AS3-$AN3)/5 -> 1.71 | AS3: 1.7
A4: 石油和天然气开采业 | B4: 天然气 | C4: 亿立方米 | D4: 中石油《世界与中国能源展望2021》 | E4: 1924.95 | F4: 2075.84 | G4: 2201.1 | H4: =G4+($J4-$G4)/3 -> 2298.4 | I4: =H4+($J4-$G4)/3 -> 2395.7 | J4: 2493 | K4: =J4+($O4-$J4)/5 -> 2554.4 | L4: =K4+($O4-$J4)/5 -> 2615.8 | M4: =L4+($O4-$J4)/5 -> 2677.2 | N4: =M4+($O4-$J4)/5 -> 2738.6 | O4: 2800 | P4: =O4+($T4-$O4)/5 -> 2840 | Q4: =P4+($T4-$O4)/5 -> 2880 | R4: =Q4+($T4-$O4)/5 -> 2920 | S4: =R4+($T4-$O4)/5 -> 2960 | T4: 3000 | U4: =T4+($Y4-$T4)/5 -> 3040 | V4: =U4+($Y4-$T4)/5 -> 3080 | W4: =V4+($Y4-$T4)/5 -> 3120 | X4: =W4+($Y4-$T4)/5 -> 3160 | Y4: 3200 | Z4: =Y4+($AD4-$Y4)/5 -> 3220 | AA4: =Z4+($AD4-$Y4)/5 -> 3240 | AB4: =AA4+($AD4-$Y4)/5 -> 3260 | AC4: =AB4+($AD4-$Y4)/5 -> 3280 | AD4: 3300 | AE4: =AD4+($AI4-$AD4)/5 -> 3320 | AF4: =AE4+($AI4-$AD4)/5 -> 3340 | AG4: =AF4+($AI4-$AD4)/5 -> 3360 | AH4: =AG4+($AI4-$AD4)/5 -> 3380 | AI4: 3400 | AJ4: =AI4+($AN4-$AI4)/5 -> 3420 | AK4: =AJ4+($AN4-$AI4)/5 -> 3440 | AL4: =AK4+($AN4-$AI4)/5 -> 3460 | AM4: =AL4+($AN4-$AI4)/5 -> 3480 | AN4: 3500 | AO4: =AN4+($AS4-$AN4)/5 -> 3500 | AP4: =AO4+($AS4-$AN4)/5 -> 3500 | AQ4: =AP4+($AS4-$AN4)/5 -> 3500 | AR4: =AQ4+($AS4-$AN4)/5 -> 3500 | AS4: 3500
A5: 黑色金属矿采选业 | B5: 铁矿石原矿 | C5: 亿吨 | D5: 产品产量与粗钢产量挂钩 | E5: 8.6672 | F5: 9.8053 | G5: 9.6787 | H5: =G5+($J5-$G5)/3 -> 9.7168617 | I5: =H5+($J5-$G5)/3 -> 9.7550235 | J5: =J18/G18*G5 -> 9.7931852 | K5: =J5+($O5-$J5)/5 -> 9.7361375 | L5: =K5+($O5-$J5)/5 -> 9.6790898 | M5: =L5+($O5-$J5)/5 -> 9.6220421 | N5: =M5+($O5-$J5)/5 -> 9.5649945 | O5: =O18/J18*J5 -> 9.5079468 | P5: =O5+($T5-$O5)/5 -> 9.3748355 | Q5: =P5+($T5-$O5)/5 -> 9.2417243 | R5: =Q5+($T5-$O5)/5 -> 9.108613 | S5: =R5+($T5-$O5)/5 -> 8.9755018 | T5: =T18/O18*O5 -> 8.8423905 | U5: =T5+($Y5-$T5)/5 -> 8.6141998 | V5: =U5+($Y5-$T5)/5 -> 8.3860091 | W5: =V5+($Y5-$T5)/5 -> 8.1578183 | X5: =W5+($Y5-$T5)/5 -> 7.9296276 | Y5: =Y18/T18*T5 -> 7.7014369 | Z5: =Y5+($AD5-$Y5)/5 -> 7.5302939 | AA5: =Z5+($AD5-$Y5)/5 -> 7.3591508 | AB5: =AA5+($AD5-$Y5)/5 -> 7.1880078 | AC5: =AB5+($AD5-$Y5)/5 -> 7.0168647 | AD5: =AD18/Y18*Y5 -> 6.8457217 | AE5: =AD5+($AI5-$AD5)/5 -> 6.6745786 | AF5: =AE5+($AI5-$AD5)/5 -> 6.5034356 | AG5: =AF5+($AI5-$AD5)/5 -> 6.3322926 | AH5: =AG5+($AI5-$AD5)/5 -> 6.1611495 | AI5: =AI18/AD18*AD5 -> 5.9900065 | AJ5: =AI5+($AN5-$AI5)/5 -> 5.894927 | AK5: =AJ5+($AN5-$AI5)/5 -> 5.7998475 | AL5: =AK5+($AN5-$AI5)/5 -> 5.7047681 | AM5: =AL5+($AN5-$AI5)/5 -> 5.6096886 | AN5: =AN18/AI18*AI5 -> 5.5146091 | AO5: =AN5+($AS5-$AN5)/5 -> 5.4765773 | AP5: =AO5+($AS5-$AN5)/5 -> 5.4385456 | AQ5: =AP5+($AS5-$AN5)/5 -> 5.4005138 | AR5: =AQ5+($AS5-$AN5)/5 -> 5.362482 | AS5: =AS18/AN18*AN5 -> 5.3244502
A6: 有色金属矿采选业 | B6: 铜矿 | C6: 万吨 | D6: 产量与精炼铜产量挂钩；https://www.wkqh.cn/ueditor/jsp/upload/file/20240603/1717376096015027949.pdf | E6: 172 | F6: 191 | G6: 194 | H6: =G6+($J6-$G6)/3 -> 219.50934 | I6: =H6+($J6-$G6)/3 -> 245.01867 | J6: =J20/G20*G6 -> 270.52801 | K6: =J6+($O6-$J6)/5 -> 279.25472 | L6: =K6+($O6-$J6)/5 -> 287.98143 | M6: =L6+($O6-$J6)/5 -> 296.70814 | N6: =M6+($O6-$J6)/5 -> 305.43485 | O6: =O20/J20*J6 -> 314.16156 | P6: =O6+($T6-$O6)/5 -> 319.39759 | Q6: =P6+($T6-$O6)/5 -> 324.63361 | R6: =Q6+($T6-$O6)/5 -> 329.86964 | S6: =R6+($T6-$O6)/5 -> 335.10567 | T6: =T20/O20*O6 -> 340.34169 | U6: =T6+($Y6-$T6)/5 -> 344.87958 | V6: =U6+($Y6-$T6)/5 -> 349.41747 | W6: =V6+($Y6-$T6)/5 -> 353.95536 | X6: =W6+($Y6-$T6)/5 -> 358.49325 | Y6: =Y20/T20*T6 -> 363.03114 | Z6: =Y6+($AD6-$Y6)/5 -> 365.47462 | AA6: =Z6+($AD6-$Y6)/5 -> 367.91809 | AB6: =AA6+($AD6-$Y6)/5 -> 370.36157 | AC6: =AB6+($AD6-$Y6)/5 -> 372.80505 | AD6: =AD20/Y20*Y6 -> 375.24853 | AE6: =AD6+($AI6-$AD6)/5 -> 376.99387 | AF6: =AE6+($AI6-$AD6)/5 -> 378.73922 | AG6: =AF6+($AI6-$AD6)/5 -> 380.48456 | AH6: =AG6+($AI6-$AD6)/5 -> 382.2299 | AI6: =AI20/AD20*AD6 -> 383.97524 | AJ6: =AI6+($AN6-$AI6)/5 -> 385.72058 | AK6: =AJ6+($AN6-$AI6)/5 -> 387.46593 | AL6: =AK6+($AN6-$AI6)/5 -> 389.21127 | AM6: =AL6+($AN6-$AI6)/5 -> 390.95661 | AN6: =AN20/AI20*AI6 -> 392.70195 | AO6: =AN6+($AS6-$AN6)/5 -> 393.40009 | AP6: =AO6+($AS6-$AN6)/5 -> 394.09822 | AQ6: =AP6+($AS6-$AN6)/5 -> 394.79636 | AR6: =AQ6+($AS6-$AN6)/5 -> 395.4945 | AS6: =AS20/AN20*AN6 -> 396.19264
A7: 有色金属矿采选业 | B7: 铝土矿 | C7: 万吨 | D7: 产量与电解铝产量挂钩 | E7: 9269 | F7: 8500 | G7: 9000 | H7: =G7+($J7-$G7)/3 -> 9213.4076 | I7: =H7+($J7-$G7)/3 -> 9426.8153 | J7: =J19/G19*G7 -> 9640.2229 | K7: =J7+($O7-$J7)/5 -> 9729.8994 | L7: =K7+($O7-$J7)/5 -> 9819.5759 | M7: =L7+($O7-$J7)/5 -> 9909.2524 | N7: =M7+($O7-$J7)/5 -> 9998.9289 | O7: =O19/J19*J7 -> 10088.605 | P7: =O7+($T7-$O7)/5 -> 10021.348 | Q7: =P7+($T7-$O7)/5 -> 9954.0906 | R7: =Q7+($T7-$O7)/5 -> 9886.8332 | S7: =R7+($T7-$O7)/5 -> 9819.5759 | T7: =T19/O19*O7 -> 9752.3185 | U7: =T7+($Y7-$T7)/5 -> 9550.5464 | V7: =U7+($Y7-$T7)/5 -> 9348.7743 | W7: =V7+($Y7-$T7)/5 -> 9147.0022 | X7: =W7+($Y7-$T7)/5 -> 8945.2301 | Y7: =Y19/T19*T7 -> 8743.458 | Z7: =Y7+($AD7-$Y7)/5 -> 8608.9432 | AA7: =Z7+($AD7-$Y7)/5 -> 8474.4285 | AB7: =AA7+($AD7-$Y7)/5 -> 8339.9138 | AC7: =AB7+($AD7-$Y7)/5 -> 8205.399 | AD7: =AD19/Y19*Y7 -> 8070.8843 | AE7: =AD7+($AI7-$AD7)/5 -> 7981.2078 | AF7: =AE7+($AI7-$AD7)/5 -> 7891.5313 | AG7: =AF7+($AI7-$AD7)/5 -> 7801.8548 | AH7: =AG7+($AI7-$AD7)/5 -> 7712.1783 | AI7: =AI19/AD19*AD7 -> 7622.5018 | AJ7: =AI7+($AN7-$AI7)/5 -> 7532.8253 | AK7: =AJ7+($AN7-$AI7)/5 -> 7443.1488 | AL7: =AK7+($AN7-$AI7)/5 -> 7353.4723 | AM7: =AL7+($AN7-$AI7)/5 -> 7263.7959 | AN7: =AN19/AI19*AI7 -> 7174.1194 | AO7: =AN7+($AS7-$AN7)/5 -> 7129.2811 | AP7: =AO7+($AS7-$AN7)/5 -> 7084.4429 | AQ7: =AP7+($AS7-$AN7)/5 -> 7039.6046 | AR7: =AQ7+($AS7-$AN7)/5 -> 6994.7664 | AS7: =AS19/AN19*AN7 -> 6949.9281
A8: 非金属矿采选业 | B8: 石灰石 | C8: 亿吨 | D8: 产品产量与水泥产量挂钩;https://www.sohu.com/a/716515038_121388092 | E8: 31.55 | F8: 31.4 | G8: 28.79 | H8: =G8+($J8-$G8)/3 -> 27.976588 | I8: =H8+($J8-$G8)/3 -> 27.163176 | J8: =J16/E16*E8 -> 26.349765 | K8: =J8+($O8-$J8)/5 -> 26.218016 | L8: =K8+($O8-$J8)/5 -> 26.086267 | M8: =L8+($O8-$J8)/5 -> 25.954518 | N8: =M8+($O8-$J8)/5 -> 25.822769 | O8: =O16/J16*J8 -> 25.69102 | P8: =O8+($T8-$O8)/5 -> 25.295774 | Q8: =P8+($T8-$O8)/5 -> 24.900528 | R8: =Q8+($T8-$O8)/5 -> 24.505281 | S8: =R8+($T8-$O8)/5 -> 24.110035 | T8: =T16/O16*O8 -> 23.714788 | U8: =T8+($Y8-$T8)/5 -> 23.187793 | V8: =U8+($Y8-$T8)/5 -> 22.660798 | W8: =V8+($Y8-$T8)/5 -> 22.133802 | X8: =W8+($Y8-$T8)/5 -> 21.606807 | Y8: =Y16/T16*T8 -> 21.079812 | Z8: =Y8+($AD8-$Y8)/5 -> 20.552816 | AA8: =Z8+($AD8-$Y8)/5 -> 20.025821 | AB8: =AA8+($AD8-$Y8)/5 -> 19.498826 | AC8: =AB8+($AD8-$Y8)/5 -> 18.971831 | AD8: =AD16/Y16*Y8 -> 18.444835 | AE8: =AD8+($AI8-$AD8)/5 -> 18.049589 | AF8: =AE8+($AI8-$AD8)/5 -> 17.654342 | AG8: =AF8+($AI8-$AD8)/5 -> 17.259096 | AH8: =AG8+($AI8-$AD8)/5 -> 16.863849 | AI8: =AI16/AD16*AD8 -> 16.468603 | AJ8: =AI8+($AN8-$AI8)/5 -> 16.073356 | AK8: =AJ8+($AN8-$AI8)/5 -> 15.67811 | AL8: =AK8+($AN8-$AI8)/5 -> 15.282863 | AM8: =AL8+($AN8-$AI8)/5 -> 14.887617 | AN8: =AN16/AI16*AI8 -> 14.492371 | AO8: =AN8+($AS8-$AN8)/5 -> 14.228873 | AP8: =AO8+($AS8-$AN8)/5 -> 13.965375 | AQ8: =AP8+($AS8-$AN8)/5 -> 13.701878 | AR8: =AQ8+($AS8-$AN8)/5 -> 13.43838 | AS8: =AS16/AN16*AN8 -> 13.174882
A9: 造纸和纸制品业 | B9: 纸和纸板 | C9: 万吨 | D9: 中国能源研究会-内部报告 | E9: 12700.63 | F9: 13583.87 | G9: 13691.4 | H9: =G9+($J9-$G9)/3 -> 13960.933 | I9: =H9+($J9-$G9)/3 -> 14230.467 | J9: 14500 | K9: =J9+($O9-$J9)/5 -> 14800 | L9: =K9+($O9-$J9)/5 -> 15100 | M9: =L9+($O9-$J9)/5 -> 15400 | N9: =M9+($O9-$J9)/5 -> 15700 | O9: 16000 | P9: =O9+($T9-$O9)/5 -> 16200 | Q9: =P9+($T9-$O9)/5 -> 16400 | R9: =Q9+($T9-$O9)/5 -> 16600 | S9: =R9+($T9-$O9)/5 -> 16800 | T9: 17000 | U9: =T9+($Y9-$T9)/5 -> 17020 | V9: =U9+($Y9-$T9)/5 -> 17040 | W9: =V9+($Y9-$T9)/5 -> 17060 | X9: =W9+($Y9-$T9)/5 -> 17080 | Y9: 17100 | Z9: =Y9+($AD9-$Y9)/5 -> 16980 | AA9: =Z9+($AD9-$Y9)/5 -> 16860 | AB9: =AA9+($AD9-$Y9)/5 -> 16740 | AC9: =AB9+($AD9-$Y9)/5 -> 16620 | AD9: 16500 | AE9: =AD9+($AI9-$AD9)/5 -> 16200 | AF9: =AE9+($AI9-$AD9)/5 -> 15900 | AG9: =AF9+($AI9-$AD9)/5 -> 15600 | AH9: =AG9+($AI9-$AD9)/5 -> 15300 | AI9: 15000 | AJ9: =AI9+($AN9-$AI9)/5 -> 14700 | AK9: =AJ9+($AN9-$AI9)/5 -> 14400 | AL9: =AK9+($AN9-$AI9)/5 -> 14100 | AM9: =AL9+($AN9-$AI9)/5 -> 13800 | AN9: 13500 | AO9: =AN9+($AS9-$AN9)/5 -> 13200 | AP9: =AO9+($AS9-$AN9)/5 -> 12900 | AQ9: =AP9+($AS9-$AN9)/5 -> 12600 | AR9: =AQ9+($AS9-$AN9)/5 -> 12300 | AS9: 12000
A10: 石油、煤炭及其他燃料加工业 | B10: 原油加工量 | C10: 亿吨 | D10: 加工量与原油产量挂钩 | E10: 6.7441 | F10: 7 | G10: 6.759 | H10: =G10+($J10-$G10)/3 -> 6.861129 | I10: =H10+($J10-$G10)/3 -> 6.9632579 | J10: =J3/G3*G10 -> 7.0653869 | K10: =J10+($O10-$J10)/5 -> 7.0851964 | L10: =K10+($O10-$J10)/5 -> 7.1050059 | M10: =L10+($O10-$J10)/5 -> 7.1248154 | N10: =M10+($O10-$J10)/5 -> 7.1446249 | O10: =O3/J3*J10 -> 7.1644343 | P10: =O10+($T10-$O10)/5 -> 7.1182122 | Q10: =P10+($T10-$O10)/5 -> 7.07199 | R10: =Q10+($T10-$O10)/5 -> 7.0257679 | S10: =R10+($T10-$O10)/5 -> 6.9795457 | T10: =T3/O3*O10 -> 6.9333236 | U10: =T10+($Y10-$T10)/5 -> 6.8672919 | V10: =U10+($Y10-$T10)/5 -> 6.8012603 | W10: =V10+($Y10-$T10)/5 -> 6.7352286 | X10: =W10+($Y10-$T10)/5 -> 6.669197 | Y10: =Y3/T3*T10 -> 6.6031653 | Z10: =Y10+($AD10-$Y10)/5 -> 6.5371336 | AA10: =Z10+($AD10-$Y10)/5 -> 6.471102 | AB10: =AA10+($AD10-$Y10)/5 -> 6.4050703 | AC10: =AB10+($AD10-$Y10)/5 -> 6.3390387 | AD10: =AD3/Y3*Y10 -> 6.273007 | AE10: =AD10+($AI10-$AD10)/5 -> 6.2201817 | AF10: =AE10+($AI10-$AD10)/5 -> 6.1673564 | AG10: =AF10+($AI10-$AD10)/5 -> 6.1145311 | AH10: =AG10+($AI10-$AD10)/5 -> 6.0617057 | AI10: =AI3/AD3*AD10 -> 6.0088804 | AJ10: =AI10+($AN10-$AI10)/5 -> 5.9626583 | AK10: =AJ10+($AN10-$AI10)/5 -> 5.9164361 | AL10: =AK10+($AN10-$AI10)/5 -> 5.870214 | AM10: =AL10+($AN10-$AI10)/5 -> 5.8239918 | AN10: =AN3/AI3*AI10 -> 5.7777696 | AO10: =AN10+($AS10-$AN10)/5 -> 5.7447538 | AP10: =AO10+($AS10-$AN10)/5 -> 5.711738 | AQ10: =AP10+($AS10-$AN10)/5 -> 5.6787222 | AR10: =AQ10+($AS10-$AN10)/5 -> 5.6457063 | AS10: =AS3/AN3*AN10 -> 5.6126905
A11: 石油、煤炭及其他燃料加工业 | B11: 焦炭 | C11: 万吨 | D11: 焦炭产量与钢铁产量挂钩 | E11: 47116 | F11: 46400 | G11: 47300 | H11: =G11+($J11-$G11)/3 -> 47486.497 | I11: =H11+($J11-$G11)/3 -> 47672.994 | J11: =J18/G18*G11 -> 47859.491 | K11: =J11+($O11-$J11)/5 -> 47580.698 | L11: =K11+($O11-$J11)/5 -> 47301.905 | M11: =L11+($O11-$J11)/5 -> 47023.112 | N11: =M11+($O11-$J11)/5 -> 46744.319 | O11: =O18/J18*J11 -> 46465.526 | P11: =O11+($T11-$O11)/5 -> 45815.008 | Q11: =P11+($T11-$O11)/5 -> 45164.491 | R11: =Q11+($T11-$O11)/5 -> 44513.974 | S11: =R11+($T11-$O11)/5 -> 43863.456 | T11: =T18/O18*O11 -> 43212.939 | U11: =T11+($Y11-$T11)/5 -> 42097.766 | V11: =U11+($Y11-$T11)/5 -> 40982.594 | W11: =V11+($Y11-$T11)/5 -> 39867.421 | X11: =W11+($Y11-$T11)/5 -> 38752.248 | Y11: =Y18/T18*T11 -> 37637.076 | Z11: =Y11+($AD11-$Y11)/5 -> 36800.696 | AA11: =Z11+($AD11-$Y11)/5 -> 35964.317 | AB11: =AA11+($AD11-$Y11)/5 -> 35127.937 | AC11: =AB11+($AD11-$Y11)/5 -> 34291.558 | AD11: =AD18/Y18*Y11 -> 33455.178 | AE11: =AD11+($AI11-$AD11)/5 -> 32618.799 | AF11: =AE11+($AI11-$AD11)/5 -> 31782.42 | AG11: =AF11+($AI11-$AD11)/5 -> 30946.04 | AH11: =AG11+($AI11-$AD11)/5 -> 30109.661 | AI11: =AI18/AD18*AD11 -> 29273.281 | AJ11: =AI11+($AN11-$AI11)/5 -> 28808.626 | AK11: =AJ11+($AN11-$AI11)/5 -> 28343.971 | AL11: =AK11+($AN11-$AI11)/5 -> 27879.315 | AM11: =AL11+($AN11-$AI11)/5 -> 27414.66 | AN11: =AN18/AI18*AI11 -> 26950.005 | AO11: =AN11+($AS11-$AN11)/5 -> 26764.143 | AP11: =AO11+($AS11-$AN11)/5 -> 26578.281 | AQ11: =AP11+($AS11-$AN11)/5 -> 26392.419 | AR11: =AQ11+($AS11-$AN11)/5 -> 26206.556 | AS11: =AS18/AN18*AN11 -> 26020.694
A12: 化学原料和化学制品制造业 | B12: 烧碱 | C12: 万吨 | D12: 中国能源研究会-内部报告 | E12: 3673.87 | F12: 3891.31 | G12: 3463.08 | H12: =G12+($J12-$G12)/3 -> 3708.72 | I12: =H12+($J12-$G12)/3 -> 3954.36 | J12: 4200 | K12: =J12+($O12-$J12)/5 -> 4220 | L12: =K12+($O12-$J12)/5 -> 4240 | M12: =L12+($O12-$J12)/5 -> 4260 | N12: =M12+($O12-$J12)/5 -> 4280 | O12: 4300 | P12: =O12+($T12-$O12)/5 -> 4260 | Q12: =P12+($T12-$O12)/5 -> 4220 | R12: =Q12+($T12-$O12)/5 -> 4180 | S12: =R12+($T12-$O12)/5 -> 4140 | T12: 4100 | U12: =T12+($Y12-$T12)/5 -> 4040 | V12: =U12+($Y12-$T12)/5 -> 3980 | W12: =V12+($Y12-$T12)/5 -> 3920 | X12: =W12+($Y12-$T12)/5 -> 3860 | Y12: 3800 | Z12: =Y12+($AD12-$Y12)/5 -> 3720 | AA12: =Z12+($AD12-$Y12)/5 -> 3640 | AB12: =AA12+($AD12-$Y12)/5 -> 3560 | AC12: =AB12+($AD12-$Y12)/5 -> 3480 | AD12: 3400 | AE12: =AD12+($AI12-$AD12)/5 -> 3340 | AF12: =AE12+($AI12-$AD12)/5 -> 3280 | AG12: =AF12+($AI12-$AD12)/5 -> 3220 | AH12: =AG12+($AI12-$AD12)/5 -> 3160 | AI12: 3100 | AJ12: =AI12+($AN12-$AI12)/5 -> 3040 | AK12: =AJ12+($AN12-$AI12)/5 -> 2980 | AL12: =AK12+($AN12-$AI12)/5 -> 2920 | AM12: =AL12+($AN12-$AI12)/5 -> 2860 | AN12: 2800 | AO12: =AN12+($AS12-$AN12)/5 -> 2780 | AP12: =AO12+($AS12-$AN12)/5 -> 2760 | AQ12: =AP12+($AS12-$AN12)/5 -> 2740 | AR12: =AQ12+($AS12-$AN12)/5 -> 2720 | AS12: 2700
A13: 化学原料和化学制品制造业 | B13: 纯碱 | C13: 万吨 | D13: 中国能源研究会-内部报告 | E13: 2812.37 | F13: 2913.25 | G13: 2920.2 | H13: =G13+($J13-$G13)/3 -> 3013.4667 | I13: =H13+($J13-$G13)/3 -> 3106.7333 | J13: 3200 | K13: =J13+($O13-$J13)/5 -> 3210 | L13: =K13+($O13-$J13)/5 -> 3220 | M13: =L13+($O13-$J13)/5 -> 3230 | N13: =M13+($O13-$J13)/5 -> 3240 | O13: 3250 | P13: =O13+($T13-$O13)/5 -> 3220 | Q13: =P13+($T13-$O13)/5 -> 3190 | R13: =Q13+($T13-$O13)/5 -> 3160 | S13: =R13+($T13-$O13)/5 -> 3130 | T13: 3100 | U13: =T13+($Y13-$T13)/5 -> 3040 | V13: =U13+($Y13-$T13)/5 -> 2980 | W13: =V13+($Y13-$T13)/5 -> 2920 | X13: =W13+($Y13-$T13)/5 -> 2860 | Y13: 2800 | Z13: =Y13+($AD13-$Y13)/5 -> 2740 | AA13: =Z13+($AD13-$Y13)/5 -> 2680 | AB13: =AA13+($AD13-$Y13)/5 -> 2620 | AC13: =AB13+($AD13-$Y13)/5 -> 2560 | AD13: 2500 | AE13: =AD13+($AI13-$AD13)/5 -> 2450 | AF13: =AE13+($AI13-$AD13)/5 -> 2400 | AG13: =AF13+($AI13-$AD13)/5 -> 2350 | AH13: =AG13+($AI13-$AD13)/5 -> 2300 | AI13: 2250 | AJ13: =AI13+($AN13-$AI13)/5 -> 2220 | AK13: =AJ13+($AN13-$AI13)/5 -> 2190 | AL13: =AK13+($AN13-$AI13)/5 -> 2160 | AM13: =AL13+($AN13-$AI13)/5 -> 2130 | AN13: 2100 | AO13: =AN13+($AS13-$AN13)/5 -> 2080 | AP13: =AO13+($AS13-$AN13)/5 -> 2060 | AQ13: =AP13+($AS13-$AN13)/5 -> 2040 | AR13: =AQ13+($AS13-$AN13)/5 -> 2020 | AS13: 2000
A14: 化学原料和化学制品制造业 | B14: 乙烯 | C14: 万吨 | D14: 中国能源研究会-内部报告 | E14: 2159.96 | F14: 2825.67 | G14: 2897.51 | H14: =G14+($J14-$G14)/3 -> 3165.0067 | I14: =H14+($J14-$G14)/3 -> 3432.5033 | J14: 3700 | K14: =J14+($O14-$J14)/5 -> 3920 | L14: =K14+($O14-$J14)/5 -> 4140 | M14: =L14+($O14-$J14)/5 -> 4360 | N14: =M14+($O14-$J14)/5 -> 4580 | O14: 4800 | P14: =O14+($T14-$O14)/5 -> 4880 | Q14: =P14+($T14-$O14)/5 -> 4960 | R14: =Q14+($T14-$O14)/5 -> 5040 | S14: =R14+($T14-$O14)/5 -> 5120 | T14: 5200 | U14: =T14+($Y14-$T14)/5 -> 5190 | V14: =U14+($Y14-$T14)/5 -> 5180 | W14: =V14+($Y14-$T14)/5 -> 5170 | X14: =W14+($Y14-$T14)/5 -> 5160 | Y14: 5150 | Z14: =Y14+($AD14-$Y14)/5 -> 5140 | AA14: =Z14+($AD14-$Y14)/5 -> 5130 | AB14: =AA14+($AD14-$Y14)/5 -> 5120 | AC14: =AB14+($AD14-$Y14)/5 -> 5110 | AD14: 5100 | AE14: =AD14+($AI14-$AD14)/5 -> 5040 | AF14: =AE14+($AI14-$AD14)/5 -> 4980 | AG14: =AF14+($AI14-$AD14)/5 -> 4920 | AH14: =AG14+($AI14-$AD14)/5 -> 4860 | AI14: 4800 | AJ14: =AI14+($AN14-$AI14)/5 -> 4710 | AK14: =AJ14+($AN14-$AI14)/5 -> 4620 | AL14: =AK14+($AN14-$AI14)/5 -> 4530 | AM14: =AL14+($AN14-$AI14)/5 -> 4440 | AN14: 4350 | AO14: =AN14+($AS14-$AN14)/5 -> 4280 | AP14: =AO14+($AS14-$AN14)/5 -> 4210 | AQ14: =AP14+($AS14-$AN14)/5 -> 4140 | AR14: =AQ14+($AS14-$AN14)/5 -> 4070 | AS14: 4000
A15: 化学原料和化学制品制造业 | B15: 合成氨 | C15: 万吨 | D15: 中国能源研究会-内部报告 | E15: 5117.13 | F15: 5189.38 | G15: 5321.01 | H15: =G15+($J15-$G15)/3 -> 5480.6733 | I15: =H15+($J15-$G15)/3 -> 5640.3367 | J15: 5800 | K15: =J15+($O15-$J15)/5 -> 5880 | L15: =K15+($O15-$J15)/5 -> 5960 | M15: =L15+($O15-$J15)/5 -> 6040 | N15: =M15+($O15-$J15)/5 -> 6120 | O15: 6200 | P15: =O15+($T15-$O15)/5 -> 6240 | Q15: =P15+($T15-$O15)/5 -> 6280 | R15: =Q15+($T15-$O15)/5 -> 6320 | S15: =R15+($T15-$O15)/5 -> 6360 | T15: 6400 | U15: =T15+($Y15-$T15)/5 -> 6450 | V15: =U15+($Y15-$T15)/5 -> 6500 | W15: =V15+($Y15-$T15)/5 -> 6550 | X15: =W15+($Y15-$T15)/5 -> 6600 | Y15: 6650 | Z15: =Y15+($AD15-$Y15)/5 -> 6710 | AA15: =Z15+($AD15-$Y15)/5 -> 6770 | AB15: =AA15+($AD15-$Y15)/5 -> 6830 | AC15: =AB15+($AD15-$Y15)/5 -> 6890 | AD15: 6950 | AE15: =AD15+($AI15-$AD15)/5 -> 7020 | AF15: =AE15+($AI15-$AD15)/5 -> 7090 | AG15: =AF15+($AI15-$AD15)/5 -> 7160 | AH15: =AG15+($AI15-$AD15)/5 -> 7230 | AI15: 7300 | AJ15: =AI15+($AN15-$AI15)/5 -> 7360 | AK15: =AJ15+($AN15-$AI15)/5 -> 7420 | AL15: =AK15+($AN15-$AI15)/5 -> 7480 | AM15: =AL15+($AN15-$AI15)/5 -> 7540 | AN15: 7600 | AO15: =AN15+($AS15-$AN15)/5 -> 7640 | AP15: =AO15+($AS15-$AN15)/5 -> 7680 | AQ15: =AP15+($AS15-$AN15)/5 -> 7720 | AR15: =AQ15+($AS15-$AN15)/5 -> 7760 | AS15: 7800
A16: 非金属矿物制品业 | B16: 水泥 | C16: 万吨 | D16: 中国能源研究会-内部报告 | E16: 239470.83 | F16: 237724.49 | G16: 212927.18 | H16: =G16+($J16-$G16)/3 -> 208618.12 | I16: =H16+($J16-$G16)/3 -> 204309.06 | J16: 200000 | K16: =J16+($O16-$J16)/5 -> 199000 | L16: =K16+($O16-$J16)/5 -> 198000 | M16: =L16+($O16-$J16)/5 -> 197000 | N16: =M16+($O16-$J16)/5 -> 196000 | O16: 195000 | P16: =O16+($T16-$O16)/5 -> 192000 | Q16: =P16+($T16-$O16)/5 -> 189000 | R16: =Q16+($T16-$O16)/5 -> 186000 | S16: =R16+($T16-$O16)/5 -> 183000 | T16: 180000 | U16: =T16+($Y16-$T16)/5 -> 176000 | V16: =U16+($Y16-$T16)/5 -> 172000 | W16: =V16+($Y16-$T16)/5 -> 168000 | X16: =W16+($Y16-$T16)/5 -> 164000 | Y16: 160000 | Z16: =Y16+($AD16-$Y16)/5 -> 156000 | AA16: =Z16+($AD16-$Y16)/5 -> 152000 | AB16: =AA16+($AD16-$Y16)/5 -> 148000 | AC16: =AB16+($AD16-$Y16)/5 -> 144000 | AD16: 140000 | AE16: =AD16+($AI16-$AD16)/5 -> 137000 | AF16: =AE16+($AI16-$AD16)/5 -> 134000 | AG16: =AF16+($AI16-$AD16)/5 -> 131000 | AH16: =AG16+($AI16-$AD16)/5 -> 128000 | AI16: 125000 | AJ16: =AI16+($AN16-$AI16)/5 -> 122000 | AK16: =AJ16+($AN16-$AI16)/5 -> 119000 | AL16: =AK16+($AN16-$AI16)/5 -> 116000 | AM16: =AL16+($AN16-$AI16)/5 -> 113000 | AN16: 110000 | AO16: =AN16+($AS16-$AN16)/5 -> 108000 | AP16: =AO16+($AS16-$AN16)/5 -> 106000 | AQ16: =AP16+($AS16-$AN16)/5 -> 104000 | AR16: =AQ16+($AS16-$AN16)/5 -> 102000 | AS16: 100000
A17: 非金属矿物制品业 | B17: 平板玻璃 | C17: 万重量厢 | D17: 中国能源研究会-内部报告 | E17: 95227.79 | F17: 101727.37 | G17: 101668.65 | H17: =G17+($J17-$G17)/3 -> 100112.43 | I17: =H17+($J17-$G17)/3 -> 98556.217 | J17: 97000 | K17: =J17+($O17-$J17)/5 -> 96600 | L17: =K17+($O17-$J17)/5 -> 96200 | M17: =L17+($O17-$J17)/5 -> 95800 | N17: =M17+($O17-$J17)/5 -> 95400 | O17: 95000 | P17: =O17+($T17-$O17)/5 -> 94400 | Q17: =P17+($T17-$O17)/5 -> 93800 | R17: =Q17+($T17-$O17)/5 -> 93200 | S17: =R17+($T17-$O17)/5 -> 92600 | T17: 92000 | U17: =T17+($Y17-$T17)/5 -> 91000 | V17: =U17+($Y17-$T17)/5 -> 90000 | W17: =V17+($Y17-$T17)/5 -> 89000 | X17: =W17+($Y17-$T17)/5 -> 88000 | Y17: 87000 | Z17: =Y17+($AD17-$Y17)/5 -> 85900 | AA17: =Z17+($AD17-$Y17)/5 -> 84800 | AB17: =AA17+($AD17-$Y17)/5 -> 83700 | AC17: =AB17+($AD17-$Y17)/5 -> 82600 | AD17: 81500 | AE17: =AD17+($AI17-$AD17)/5 -> 80600 | AF17: =AE17+($AI17-$AD17)/5 -> 79700 | AG17: =AF17+($AI17-$AD17)/5 -> 78800 | AH17: =AG17+($AI17-$AD17)/5 -> 77900 | AI17: 77000 | AJ17: =AI17+($AN17-$AI17)/5 -> 76400 | AK17: =AJ17+($AN17-$AI17)/5 -> 75800 | AL17: =AK17+($AN17-$AI17)/5 -> 75200 | AM17: =AL17+($AN17-$AI17)/5 -> 74600 | AN17: 74000 | AO17: =AN17+($AS17-$AN17)/5 -> 73600 | AP17: =AO17+($AS17-$AN17)/5 -> 73200 | AQ17: =AP17+($AS17-$AN17)/5 -> 72800 | AR17: =AQ17+($AS17-$AN17)/5 -> 72400 | AS17: 72000
A18: 黑色金属冶炼和压延加工业 | B18: 钢铁 | C18: 万吨 | D18: 中国能源研究会-内部报告 | E18: 106476.68 | F18: 103524.26 | G18: 101795.9 | H18: =G18+($J18-$G18)/3 -> 102197.27 | I18: =H18+($J18-$G18)/3 -> 102598.63 | J18: 103000 | K18: =J18+($O18-$J18)/5 -> 102400 | L18: =K18+($O18-$J18)/5 -> 101800 | M18: =L18+($O18-$J18)/5 -> 101200 | N18: =M18+($O18-$J18)/5 -> 100600 | O18: 100000 | P18: =O18+($T18-$O18)/5 -> 98600 | Q18: =P18+($T18-$O18)/5 -> 97200 | R18: =Q18+($T18-$O18)/5 -> 95800 | S18: =R18+($T18-$O18)/5 -> 94400 | T18: 93000 | U18: =T18+($Y18-$T18)/5 -> 90600 | V18: =U18+($Y18-$T18)/5 -> 88200 | W18: =V18+($Y18-$T18)/5 -> 85800 | X18: =W18+($Y18-$T18)/5 -> 83400 | Y18: 81000 | Z18: =Y18+($AD18-$Y18)/5 -> 79200 | AA18: =Z18+($AD18-$Y18)/5 -> 77400 | AB18: =AA18+($AD18-$Y18)/5 -> 75600 | AC18: =AB18+($AD18-$Y18)/5 -> 73800 | AD18: 72000 | AE18: =AD18+($AI18-$AD18)/5 -> 70200 | AF18: =AE18+($AI18-$AD18)/5 -> 68400 | AG18: =AF18+($AI18-$AD18)/5 -> 66600 | AH18: =AG18+($AI18-$AD18)/5 -> 64800 | AI18: 63000 | AJ18: =AI18+($AN18-$AI18)/5 -> 62000 | AK18: =AJ18+($AN18-$AI18)/5 -> 61000 | AL18: =AK18+($AN18-$AI18)/5 -> 60000 | AM18: =AL18+($AN18-$AI18)/5 -> 59000 | AN18: 58000 | AO18: =AN18+($AS18-$AN18)/5 -> 57600 | AP18: =AO18+($AS18-$AN18)/5 -> 57200 | AQ18: =AP18+($AS18-$AN18)/5 -> 56800 | AR18: =AQ18+($AS18-$AN18)/5 -> 56400 | AS18: 56000
A19: 有色金属冶炼和压延加工业 | B19: 电解铝 | C19: 万吨 | D19: 中国能源研究会-内部报告 | E19: 3708.04 | F19: 3850.32 | G19: 4014.43 | H19: =G19+($J19-$G19)/3 -> 4109.62 | I19: =H19+($J19-$G19)/3 -> 4204.81 | J19: 4300 | K19: =J19+($O19-$J19)/5 -> 4340 | L19: =K19+($O19-$J19)/5 -> 4380 | M19: =L19+($O19-$J19)/5 -> 4420 | N19: =M19+($O19-$J19)/5 -> 4460 | O19: 4500 | P19: =O19+($T19-$O19)/5 -> 4470 | Q19: =P19+($T19-$O19)/5 -> 4440 | R19: =Q19+($T19-$O19)/5 -> 4410 | S19: =R19+($T19-$O19)/5 -> 4380 | T19: 4350 | U19: =T19+($Y19-$T19)/5 -> 4260 | V19: =U19+($Y19-$T19)/5 -> 4170 | W19: =V19+($Y19-$T19)/5 -> 4080 | X19: =W19+($Y19-$T19)/5 -> 3990 | Y19: 3900 | Z19: =Y19+($AD19-$Y19)/5 -> 3840 | AA19: =Z19+($AD19-$Y19)/5 -> 3780 | AB19: =AA19+($AD19-$Y19)/5 -> 3720 | AC19: =AB19+($AD19-$Y19)/5 -> 3660 | AD19: 3600 | AE19: =AD19+($AI19-$AD19)/5 -> 3560 | AF19: =AE19+($AI19-$AD19)/5 -> 3520 | AG19: =AF19+($AI19-$AD19)/5 -> 3480 | AH19: =AG19+($AI19-$AD19)/5 -> 3440 | AI19: 3400 | AJ19: =AI19+($AN19-$AI19)/5 -> 3360 | AK19: =AJ19+($AN19-$AI19)/5 -> 3320 | AL19: =AK19+($AN19-$AI19)/5 -> 3280 | AM19: =AL19+($AN19-$AI19)/5 -> 3240 | AN19: 3200 | AO19: =AN19+($AS19-$AN19)/5 -> 3180 | AP19: =AO19+($AS19-$AN19)/5 -> 3160 | AQ19: =AP19+($AS19-$AN19)/5 -> 3140 | AR19: =AQ19+($AS19-$AN19)/5 -> 3120 | AS19: 3100
A20: 有色金属冶炼和压延加工业 | B20: 精炼铜 | C20: 万吨 | D20: 拍数 | E20: 1002.51 | F20: 1048.67 | G20: 1111.53 | H20: =G20+($J20-$G20)/3 -> 1257.6867 | I20: =H20+($J20-$G20)/3 -> 1403.8433 | J20: 1550 | K20: =J20+($O20-$J20)/5 -> 1600 | L20: =K20+($O20-$J20)/5 -> 1650 | M20: =L20+($O20-$J20)/5 -> 1700 | N20: =M20+($O20-$J20)/5 -> 1750 | O20: 1800 | P20: =O20+($T20-$O20)/5 -> 1830 | Q20: =P20+($T20-$O20)/5 -> 1860 | R20: =Q20+($T20-$O20)/5 -> 1890 | S20: =R20+($T20-$O20)/5 -> 1920 | T20: 1950 | U20: =T20+($Y20-$T20)/5 -> 1976 | V20: =U20+($Y20-$T20)/5 -> 2002 | W20: =V20+($Y20-$T20)/5 -> 2028 | X20: =W20+($Y20-$T20)/5 -> 2054 | Y20: 2080 | Z20: =Y20+($AD20-$Y20)/5 -> 2094 | AA20: =Z20+($AD20-$Y20)/5 -> 2108 | AB20: =AA20+($AD20-$Y20)/5 -> 2122 | AC20: =AB20+($AD20-$Y20)/5 -> 2136 | AD20: 2150 | AE20: =AD20+($AI20-$AD20)/5 -> 2160 | AF20: =AE20+($AI20-$AD20)/5 -> 2170 | AG20: =AF20+($AI20-$AD20)/5 -> 2180 | AH20: =AG20+($AI20-$AD20)/5 -> 2190 | AI20: 2200 | AJ20: =AI20+($AN20-$AI20)/5 -> 2210 | AK20: =AJ20+($AN20-$AI20)/5 -> 2220 | AL20: =AK20+($AN20-$AI20)/5 -> 2230 | AM20: =AL20+($AN20-$AI20)/5 -> 2240 | AN20: 2250 | AO20: =AN20+($AS20-$AN20)/5 -> 2254 | AP20: =AO20+($AS20-$AN20)/5 -> 2258 | AQ20: =AP20+($AS20-$AN20)/5 -> 2262 | AR20: =AQ20+($AS20-$AN20)/5 -> 2266 | AS20: 2270
A21: 汽车制造业 | B21: 汽车 | C21: 万辆 | D21: 2023节能与新能源汽车发展报告-结果微调 | E21: 2532.49 | F21: 2625.7 | G21: 2713.63 | H21: =G21+($J21-$G21)/3 -> 2948.7072 | I21: =H21+($J21-$G21)/3 -> 3183.7843 | J21: =E21*(2700/2000) -> 3418.8615 | K21: =J21+($O21-$J21)/5 -> 3520.1611 | L21: =K21+($O21-$J21)/5 -> 3621.4607 | M21: =L21+($O21-$J21)/5 -> 3722.7603 | N21: =M21+($O21-$J21)/5 -> 3824.0599 | O21: =J21*(3100/2700) -> 3925.3595 | P21: =O21+($T21-$O21)/5 -> 3976.0093 | Q21: =P21+($T21-$O21)/5 -> 4026.6591 | R21: =Q21+($T21-$O21)/5 -> 4077.3089 | S21: =R21+($T21-$O21)/5 -> 4127.9587 | T21: =O21*(3300/3100) -> 4178.6085 | U21: =T21+($Y21-$T21)/5 -> 4165.946 | V21: =U21+($Y21-$T21)/5 -> 4153.2836 | W21: =V21+($Y21-$T21)/5 -> 4140.6211 | X21: =W21+($Y21-$T21)/5 -> 4127.9587 | Y21: =T21*(3250/3300) -> 4115.2962 | Z21: =Y21+($AD21-$Y21)/5 -> 4102.6338 | AA21: =Z21+($AD21-$Y21)/5 -> 4089.9713 | AB21: =AA21+($AD21-$Y21)/5 -> 4077.3089 | AC21: =AB21+($AD21-$Y21)/5 -> 4064.6465 | AD21: =Y21*(3200/3250) -> 4051.984 | AE21: =AD21+($AI21-$AD21)/5 -> 4039.3215 | AF21: =AE21+($AI21-$AD21)/5 -> 4026.6591 | AG21: =AF21+($AI21-$AD21)/5 -> 4013.9967 | AH21: =AG21+($AI21-$AD21)/5 -> 4001.3342 | AI21: =AD21*(3150/3200) -> 3988.6717 | AJ21: =AI21+($AN21-$AI21)/5 -> 3983.6068 | AK21: =AJ21+($AN21-$AI21)/5 -> 3978.5418 | AL21: =AK21+($AN21-$AI21)/5 -> 3973.4768 | AM21: =AL21+($AN21-$AI21)/5 -> 3968.4118 | AN21: =AI21*(3130/3150) -> 3963.3468 | AO21: =AN21+($AS21-$AN21)/5 -> 3955.7494 | AP21: =AO21+($AS21-$AN21)/5 -> 3948.1519 | AQ21: =AP21+($AS21-$AN21)/5 -> 3940.5544 | AR21: =AQ21+($AS21-$AN21)/5 -> 3932.957 | AS21: =AN21*(3100/3130) -> 3925.3595

Sheet 中情景
A1: 行业 | B1: 计量指标 | C1: 计量单位 | D1: 数据来源 | E1: 2020 | F1: 2021 | G1: 2022 | H1: 2023 | I1: 2024 | J1: 2025 | K1: 2026 | L1: 2027 | M1: 2028 | N1: 2029 | O1: 2030 | P1: 2031 | Q1: 2032 | R1: 2033 | S1: 2034 | T1: 2035 | U1: 2036 | V1: 2037 | W1: 2038 | X1: 2039 | Y1: 2040 | Z1: 2041 | AA1: 2042 | AB1: 2043 | AC1: 2044 | AD1: 2045 | AE1: 2046 | AF1: 2047 | AG1: 2048 | AH1: 2049 | AI1: 2050 | AJ1: 2051 | AK1: 2052 | AL1: 2053 | AM1: 2054 | AN1: 2055 | AO1: 2056 | AP1: 2057 | AQ1: 2058 | AR1: 2059 | AS1: 2060
A2: 煤炭开采和洗选业 | B2: 原煤 | C2: 亿吨 | D2: 中石化《中国能源展望2060》 | E2: =高情景!E2*0.5+低情景!E2*0.5 -> 39.02 | F2: =高情景!F2*0.5+低情景!F2*0.5 -> 41.26 | G2: =高情景!G2*0.5+低情景!G2*0.5 -> 45.59 | H2: =高情景!H2*0.5+低情景!H2*0.5 -> 46.393333 | I2: =高情景!I2*0.45+低情景!I2*0.55 -> 47.196667 | J2: =高情景!J2*0.37+低情景!J2*0.63 -> 48 | K2: =高情景!K2*0.7+低情景!K2*0.3 -> 47.24 | L2: =高情景!L2*0.8+低情景!L2*0.2 -> 46.72 | M2: =高情景!M2*0.65+低情景!M2*0.35 -> 45.54 | N2: =高情景!N2*0.55+低情景!N2*0.45 -> 44.24 | O2: =高情景!O2*0.5+低情景!O2*0.5 -> 43 | P2: =(高情景!P2+低情景!P2)/2 -> 41.693137 | Q2: =(高情景!Q2+低情景!Q2)/2 -> 40.386275 | R2: =(高情景!R2+低情景!R2)/2 -> 39.079412 | S2: =(高情景!S2+低情景!S2)/2 -> 37.772549 | T2: =(高情景!T2+低情景!T2)/2 -> 36.465686 | U2: =(高情景!U2+低情景!U2)/2 -> 35.095588 | V2: =(高情景!V2+低情景!V2)/2 -> 33.72549 | W2: =(高情景!W2+低情景!W2)/2 -> 32.355392 | ... AS2: =(高情景!AS2+低情景!AS2)/2 -> 4.004902
A3: 石油和天然气开采业 | B3: 原油 | C3: 亿吨 | D3: 中石油《世界与中国能源展望2021》 | E3: =高情景!E3*0.5+低情景!E3*0.5 -> 1.9477 | F3: =高情景!F3*0.5+低情景!F3*0.5 -> 1.9888 | G3: =高情景!G3*0.5+低情景!G3*0.5 -> 2.0472 | H3: =高情景!H3*0.5+低情景!H3*0.5 -> 2.0781333 | I3: =高情景!I3*0.45+低情景!I3*0.55 -> 2.1090667 | J3: =高情景!J3*0.37+低情景!J3*0.63 -> 2.14 | K3: =高情景!K3*0.7+低情景!K3*0.3 -> 2.146 | L3: =高情景!L3*0.8+低情景!L3*0.2 -> 2.152 | M3: =高情景!M3*0.65+低情景!M3*0.35 -> 2.158 | N3: =高情景!N3*0.55+低情景!N3*0.45 -> 2.164 | O3: =高情景!O3*0.5+低情景!O3*0.5 -> 2.17 | P3: =(高情景!P3+低情景!P3)/2 -> 2.156 | Q3: =(高情景!Q3+低情景!Q3)/2 -> 2.142 | R3: =(高情景!R3+低情景!R3)/2 -> 2.128 | S3: =(高情景!S3+低情景!S3)/2 -> 2.114 | T3: =(高情景!T3+低情景!T3)/2 -> 2.1 | U3: =(高情景!U3+低情景!U3)/2 -> 2.08 | V3: =(高情景!V3+低情景!V3)/2 -> 2.06 | W3: =(高情景!W3+低情景!W3)/2 -> 2.04 | ... AS3: =(高情景!AS3+低情景!AS3)/2 -> 1.7
A4: 石油和天然气开采业 | B4: 天然气 | C4: 亿立方米 | D4: 中石油《世界与中国能源展望2021》 | E4: =高情景!E4*0.5+低情景!E4*0.5 -> 1924.95 | F4: =高情景!F4*0.5+低情景!F4*0.5 -> 2075.84 | G4: =高情景!G4*0.5+低情景!G4*0.5 -> 2201.1 | H4: =高情景!H4*0.5+低情景!H4*0.5 -> 2298.4 | I4: =高情景!I4*0.45+低情景!I4*0.55 -> 2395.7 | J4: =高情景!J4*0.37+低情景!J4*0.63 -> 2493 | K4: =高情景!K4*0.7+低情景!K4*0.3 -> 2554.4 | L4: =高情景!L4*0.8+低情景!L4*0.2 -> 2615.8 | M4: =高情景!M4*0.65+低情景!M4*0.35 -> 2677.2 | N4: =高情景!N4*0.55+低情景!N4*0.45 -> 2738.6 | O4: =高情景!O4*0.5+低情景!O4*0.5 -> 2800 | P4: =(高情景!P4+低情景!P4)/2 -> 2840 | Q4: =(高情景!Q4+低情景!Q4)/2 -> 2880 | R4: =(高情景!R4+低情景!R4)/2 -> 2920 | S4: =(高情景!S4+低情景!S4)/2 -> 2960 | T4: =(高情景!T4+低情景!T4)/2 -> 3000 | U4: =(高情景!U4+低情景!U4)/2 -> 3040 | V4: =(高情景!V4+低情景!V4)/2 -> 3080 | W4: =(高情景!W4+低情景!W4)/2 -> 3120 | ... AS4: =(高情景!AS4+低情景!AS4)/2 -> 3500
A5: 黑色金属矿采选业 | B5: 铁矿石原矿 | C5: 亿吨 | D5: 产品产量与粗钢产量挂钩 | E5: =高情景!E5*0.5+低情景!E5*0.5 -> 8.6672 | F5: =高情景!F5*0.5+低情景!F5*0.5 -> 9.8053 | G5: =高情景!G5*0.5+低情景!G5*0.5 -> 9.6787 | H5: =高情景!H5*0.5+低情景!H5*0.5 -> 9.7027298 | I5: =高情景!I5*0.45+低情景!I5*0.55 -> 9.6191313 | J5: =高情景!J5*0.37+低情景!J5*0.63 -> 9.6733851 | K5: =高情景!K5*0.7+低情景!K5*0.3 -> 9.6448612 | L5: =高情景!L5*0.8+低情景!L5*0.2 -> 9.5954199 | M5: =高情景!M5*0.65+低情景!M5*0.35 -> 9.4356864 | N5: =高情景!N5*0.55+低情景!N5*0.45 -> 9.2740513 | O5: =高情景!O5*0.5+低情景!O5*0.5 -> 9.1276289 | P5: =(高情景!P5+低情景!P5)/2 -> 8.9755018 | Q5: =(高情景!Q5+低情景!Q5)/2 -> 8.8233746 | R5: =(高情景!R5+低情景!R5)/2 -> 8.6712475 | S5: =(高情景!S5+低情景!S5)/2 -> 8.5191203 | T5: =(高情景!T5+低情景!T5)/2 -> 8.3669932 | U5: =(高情景!U5+低情景!U5)/2 -> 8.1673263 | V5: =(高情景!V5+低情景!V5)/2 -> 7.9676594 | W5: =(高情景!W5+低情景!W5)/2 -> 7.7679925 | ... AS5: =(高情景!AS5+低情景!AS5)/2 -> 5.3244502
A6: 有色金属矿采选业 | B6: 铜矿 | C6: 万吨 | D6: 产量与精炼铜产量挂钩；https://www.wkqh.cn/ueditor/jsp/upload/file/20240603/1717376096015027949.pdf | E6: =高情景!E6*0.5+低情景!E6*0.5 -> 172 | F6: =高情景!F6*0.5+低情景!F6*0.5 -> 191 | G6: =高情景!G6*0.5+低情景!G6*0.5 -> 194 | H6: =高情景!H6*0.5+低情景!H6*0.5 -> 218.05489 | I6: =高情景!I6*0.45+低情景!I6*0.55 -> 241.81888 | J6: =高情景!J6*0.37+低情景!J6*0.63 -> 265.03018 | K6: =高情景!K6*0.7+低情景!K6*0.3 -> 276.11311 | L6: =高情景!L6*0.8+低情景!L6*0.2 -> 285.53795 | M6: =高情景!M6*0.65+低情景!M6*0.35 -> 291.82118 | N6: =高情景!N6*0.55+低情景!N6*0.45 -> 298.36622 | O6: =高情景!O6*0.5+低情景!O6*0.5 -> 305.43485 | P6: =(高情景!P6+低情景!P6)/2 -> 309.79821 | Q6: =(高情景!Q6+低情景!Q6)/2 -> 314.16156 | R6: =(高情景!R6+低情景!R6)/2 -> 318.52492 | S6: =(高情景!S6+低情景!S6)/2 -> 322.88827 | T6: =(高情景!T6+低情景!T6)/2 -> 327.25163 | U6: =(高情景!U6+低情景!U6)/2 -> 330.91684 | V6: =(高情景!V6+低情景!V6)/2 -> 334.58206 | W6: =(高情景!W6+低情景!W6)/2 -> 338.24728 | ... AS6: =(高情景!AS6+低情景!AS6)/2 -> 352.55909
A7: 有色金属矿采选业 | B7: 铝土矿 | C7: 万吨 | D7: 产量与电解铝产量挂钩 | E7: =高情景!E7*0.5+低情景!E7*0.5 -> 9269 | F7: =高情景!F7*0.5+低情景!F7*0.5 -> 8500 | G7: =高情景!G7*0.5+低情景!G7*0.5 -> 9000 | H7: =高情景!H7*0.5+低情景!H7*0.5 -> 9213.4076 | I7: =高情景!I7*0.45+低情景!I7*0.55 -> 9426.8153 | J7: =高情景!J7*0.37+低情景!J7*0.63 -> 9640.2229 | K7: =高情景!K7*0.7+低情景!K7*0.3 -> 9689.545 | L7: =高情景!L7*0.8+低情景!L7*0.2 -> 9765.77 | M7: =高情景!M7*0.65+低情景!M7*0.35 -> 9768.0119 | N7: =高情景!N7*0.55+低情景!N7*0.45 -> 9756.8023 | O7: =高情景!O7*0.5+低情景!O7*0.5 -> 9752.3185 | P7: =(高情景!P7+低情景!P7)/2 -> 9662.642 | Q7: =(高情景!Q7+低情景!Q7)/2 -> 9572.9655 | R7: =(高情景!R7+低情景!R7)/2 -> 9483.289 | S7: =(高情景!S7+低情景!S7)/2 -> 9393.6125 | T7: =(高情景!T7+低情景!T7)/2 -> 9303.9361 | U7: =(高情景!U7+低情景!U7)/2 -> 9147.0022 | V7: =(高情景!V7+低情景!V7)/2 -> 8990.0683 | W7: =(高情景!W7+低情景!W7)/2 -> 8833.1345 | ... AS7: =(高情景!AS7+低情景!AS7)/2 -> 6949.9281
A8: 非金属矿采选业 | B8: 石灰石 | C8: 亿吨 | D8: 产品产量与水泥产量挂钩;https://www.sohu.com/a/716515038_121388092 | E8: =高情景!E8*0.5+低情景!E8*0.5 -> 31.55 | F8: =高情景!F8*0.5+低情景!F8*0.5 -> 31.4 | G8: =高情景!G8*0.5+低情景!G8*0.5 -> 28.79 | H8: =高情景!H8*0.5+低情景!H8*0.5 -> 28.046909 | I8: =高情景!I8*0.45+低情景!I8*0.55 -> 27.317882 | J8: =高情景!J8*0.37+低情景!J8*0.63 -> 26.615576 | K8: =高情景!K8*0.7+低情景!K8*0.3 -> 26.197527 | L8: =高情景!L8*0.8+低情景!L8*0.2 -> 25.974564 | M8: =高情景!M8*0.65+低情景!M8*0.35 -> 25.587461 | N8: =高情景!N8*0.55+低情景!N8*0.45 -> 25.130239 | O8: =高情景!O8*0.5+低情景!O8*0.5 -> 24.676433 | P8: =(高情景!P8+低情景!P8)/2 -> 24.275994 | Q8: =(高情景!Q8+低情景!Q8)/2 -> 23.875555 | R8: =(高情景!R8+低情景!R8)/2 -> 23.475116 | S8: =(高情景!S8+低情景!S8)/2 -> 23.074677 | T8: =(高情景!T8+低情景!T8)/2 -> 22.674238 | U8: =(高情景!U8+低情景!U8)/2 -> 22.248487 | V8: =(高情景!V8+低情景!V8)/2 -> 21.822737 | W8: =(高情景!W8+低情景!W8)/2 -> 21.396987 | ... AS8: =(高情景!AS8+低情景!AS8)/2 -> 13.347968
A9: 造纸和纸制品业 | B9: 纸和纸板 | C9: 万吨 | D9: 中国能源研究会-内部报告 | E9: =高情景!E9*0.5+低情景!E9*0.5 -> 12700.63 | F9: =高情景!F9*0.5+低情景!F9*0.5 -> 13583.87 | G9: =高情景!G9*0.5+低情景!G9*0.5 -> 13691.4 | H9: =高情景!H9*0.5+低情景!H9*0.5 -> 13877.6 | I9: =高情景!I9*0.45+低情景!I9*0.55 -> 14047.133 | J9: =高情景!J9*0.37+低情景!J9*0.63 -> 14185 | K9: =高情景!K9*0.7+低情景!K9*0.3 -> 14650 | L9: =高情景!L9*0.8+低情景!L9*0.2 -> 15000 | M9: =高情景!M9*0.65+低情景!M9*0.35 -> 15225 | N9: =高情景!N9*0.55+低情景!N9*0.45 -> 15475 | O9: =高情景!O9*0.5+低情景!O9*0.5 -> 15750 | P9: =(高情景!P9+低情景!P9)/2 -> 15930 | Q9: =(高情景!Q9+低情景!Q9)/2 -> 16110 | R9: =(高情景!R9+低情景!R9)/2 -> 16290 | S9: =(高情景!S9+低情景!S9)/2 -> 16470 | T9: =(高情景!T9+低情景!T9)/2 -> 16650 | U9: =(高情景!U9+低情景!U9)/2 -> 16610 | V9: =(高情景!V9+低情景!V9)/2 -> 16570 | W9: =(高情景!W9+低情景!W9)/2 -> 16530 | ... AS9: =(高情景!AS9+低情景!AS9)/2 -> 10300
A10: 石油、煤炭及其他燃料加工业 | B10: 原油加工量 | C10: 亿吨 | D10: 加工量与原油产量挂钩 | E10: =高情景!E10*0.5+低情景!E10*0.5 -> 6.7441 | F10: =高情景!F10*0.5+低情景!F10*0.5 -> 7 | G10: =高情景!G10*0.5+低情景!G10*0.5 -> 6.759 | H10: =高情景!H10*0.5+低情景!H10*0.5 -> 6.861129 | I10: =高情景!I10*0.45+低情景!I10*0.55 -> 6.9632579 | J10: =高情景!J10*0.37+低情景!J10*0.63 -> 7.0653869 | K10: =高情景!K10*0.7+低情景!K10*0.3 -> 7.0851964 | L10: =高情景!L10*0.8+低情景!L10*0.2 -> 7.1050059 | M10: =高情景!M10*0.65+低情景!M10*0.35 -> 7.1248154 | N10: =高情景!N10*0.55+低情景!N10*0.45 -> 7.1446249 | O10: =高情景!O10*0.5+低情景!O10*0.5 -> 7.1644343 | P10: =(高情景!P10+低情景!P10)/2 -> 7.1182122 | Q10: =(高情景!Q10+低情景!Q10)/2 -> 7.07199 | R10: =(高情景!R10+低情景!R10)/2 -> 7.0257679 | S10: =(高情景!S10+低情景!S10)/2 -> 6.9795457 | T10: =(高情景!T10+低情景!T10)/2 -> 6.9333236 | U10: =(高情景!U10+低情景!U10)/2 -> 6.8672919 | V10: =(高情景!V10+低情景!V10)/2 -> 6.8012603 | W10: =(高情景!W10+低情景!W10)/2 -> 6.7352286 | ... AS10: =(高情景!AS10+低情景!AS10)/2 -> 5.6126905
A11: 石油、煤炭及其他燃料加工业 | B11: 焦炭 | C11: 万吨 | D11: 焦炭产量与钢铁产量挂钩 | E11: =高情景!E11*0.5+低情景!E11*0.5 -> 47116 | F11: =高情景!F11*0.5+低情景!F11*0.5 -> 46400 | G11: =高情景!G11*0.5+低情景!G11*0.5 -> 47300 | H11: =高情景!H11*0.5+低情景!H11*0.5 -> 47331.612 | I11: =高情景!I11*0.45+低情景!I11*0.55 -> 47332.247 | J11: =高情景!J11*0.37+低情景!J11*0.63 -> 47274.026 | K11: =高情景!K11*0.7+低情景!K11*0.3 -> 47134.629 | L11: =高情景!L11*0.8+低情景!L11*0.2 -> 46893.008 | M11: =高情景!M11*0.65+低情景!M11*0.35 -> 46112.388 | N11: =高情景!N11*0.55+低情景!N11*0.45 -> 45322.474 | O11: =高情景!O11*0.5+低情景!O11*0.5 -> 44606.905 | P11: =(高情景!P11+低情景!P11)/2 -> 43863.456 | Q11: =(高情景!Q11+低情景!Q11)/2 -> 43120.008 | R11: =(高情景!R11+低情景!R11)/2 -> 42376.559 | S11: =(高情景!S11+低情景!S11)/2 -> 41633.111 | T11: =(高情景!T11+低情景!T11)/2 -> 40889.663 | U11: =(高情景!U11+低情景!U11)/2 -> 39913.887 | V11: =(高情景!V11+低情景!V11)/2 -> 38938.11 | W11: =(高情景!W11+低情景!W11)/2 -> 37962.334 | ... AS11: =(高情景!AS11+低情景!AS11)/2 -> 26020.694
A12: 化学原料和化学制品制造业 | B12: 烧碱 | C12: 万吨 | D12: 中国能源研究会-内部报告 | E12: =高情景!E12*0.5+低情景!E12*0.5 -> 3673.87 | F12: =高情景!F12*0.5+低情景!F12*0.5 -> 3891.31 | G12: =高情景!G12*0.5+低情景!G12*0.5 -> 3463.08 | H12: =高情景!H12*0.5+低情景!H12*0.5 -> 3692.0533 | I12: =高情景!I12*0.45+低情景!I12*0.55 -> 3917.6933 | J12: =高情景!J12*0.37+低情景!J12*0.63 -> 4137 | K12: =高情景!K12*0.7+低情景!K12*0.3 -> 4178 | L12: =高情景!L12*0.8+低情景!L12*0.2 -> 4204 | M12: =高情景!M12*0.65+低情景!M12*0.35 -> 4183 | N12: =高情景!N12*0.55+低情景!N12*0.45 -> 4163 | O12: =高情景!O12*0.5+低情景!O12*0.5 -> 4150 | P12: =(高情景!P12+低情景!P12)/2 -> 4105 | Q12: =(高情景!Q12+低情景!Q12)/2 -> 4060 | R12: =(高情景!R12+低情景!R12)/2 -> 4015 | S12: =(高情景!S12+低情景!S12)/2 -> 3970 | T12: =(高情景!T12+低情景!T12)/2 -> 3925 | U12: =(高情景!U12+低情景!U12)/2 -> 3865 | V12: =(高情景!V12+低情景!V12)/2 -> 3805 | W12: =(高情景!W12+低情景!W12)/2 -> 3745 | ... AS12: =(高情景!AS12+低情景!AS12)/2 -> 2700
A13: 化学原料和化学制品制造业 | B13: 纯碱 | C13: 万吨 | D13: 中国能源研究会-内部报告 | E13: =高情景!E13*0.5+低情景!E13*0.5 -> 2812.37 | F13: =高情景!F13*0.5+低情景!F13*0.5 -> 2913.25 | G13: =高情景!G13*0.5+低情景!G13*0.5 -> 2920.2 | H13: =高情景!H13*0.5+低情景!H13*0.5 -> 3005.1333 | I13: =高情景!I13*0.45+低情景!I13*0.55 -> 3088.4 | J13: =高情景!J13*0.37+低情景!J13*0.63 -> 3168.5 | K13: =高情景!K13*0.7+低情景!K13*0.3 -> 3186 | L13: =高情景!L13*0.8+低情景!L13*0.2 -> 3198 | M13: =高情景!M13*0.65+低情景!M13*0.35 -> 3181 | N13: =高情景!N13*0.55+低情景!N13*0.45 -> 3163.5 | O13: =高情景!O13*0.5+低情景!O13*0.5 -> 3150 | P13: =(高情景!P13+低情景!P13)/2 -> 3110 | Q13: =(高情景!Q13+低情景!Q13)/2 -> 3070 | R13: =(高情景!R13+低情景!R13)/2 -> 3030 | S13: =(高情景!S13+低情景!S13)/2 -> 2990 | T13: =(高情景!T13+低情景!T13)/2 -> 2950 | U13: =(高情景!U13+低情景!U13)/2 -> 2890 | V13: =(高情景!V13+低情景!V13)/2 -> 2830 | W13: =(高情景!W13+低情景!W13)/2 -> 2770 | ... AS13: =(高情景!AS13+低情景!AS13)/2 -> 2000
... A21: 汽车制造业 | B21: 汽车 | C21: 万辆 | D21: 2023节能与新能源汽车发展报告-结果微调 | E21: =高情景!E21*0.5+低情景!E21*0.5 -> 2532.49 | F21: =高情景!F21*0.5+低情景!F21*0.5 -> 2625.7 | G21: =高情景!G21*0.5+低情景!G21*0.5 -> 2713.63 | H21: =高情景!H21*0.5+低情景!H21*0.5 -> 2969.8112 | I21: =高情景!I21*0.45+低情景!I21*0.55 -> 3230.2133 | J21: =高情景!J21*0.37+低情景!J21*0.63 -> 3498.6349 | K21: =高情景!K21*0.7+低情景!K21*0.3 -> 3559.274 | L21: =高情景!L21*0.8+低情景!L21*0.2 -> 3648.2863 | M21: =高情景!M21*0.65+低情景!M21*0.35 -> 3771.0183 | N21: =高情景!N21*0.55+低情景!N21*0.45 -> 3887.7942 | O21: =高情景!O21*0.5+低情景!O21*0.5 -> 3998.0513 | P21: =(高情景!P21+低情景!P21)/2 -> 4049.6391 | Q21: =(高情景!Q21+低情景!Q21)/2 -> 4101.2269 | R21: =(高情景!R21+低情景!R21)/2 -> 4152.8146 | S21: =(高情景!S21+低情景!S21)/2 -> 4204.4024 | T21: =(高情景!T21+低情景!T21)/2 -> 4255.9901 | U21: =(高情景!U21+低情景!U21)/2 -> 4269.3561 | V21: =(高情景!V21+低情景!V21)/2 -> 4282.722 | W21: =(高情景!W21+低情景!W21)/2 -> 4296.0879 | ... AS21: =(高情景!AS21+低情景!AS21)/2 -> 4190.8245

Sheet 低情景
A1: 行业 | B1: 计量指标 | C1: 计量单位 | D1: 数据来源 | E1: 2020 | F1: 2021 | G1: 2022 | H1: 2023 | I1: 2024 | J1: 2025 | K1: 2026 | L1: 2027 | M1: 2028 | N1: 2029 | O1: 2030 | P1: 2031 | Q1: 2032 | R1: 2033 | S1: 2034 | T1: 2035 | U1: 2036 | V1: 2037 | W1: 2038 | X1: 2039 | Y1: 2040 | Z1: 2041 | AA1: 2042 | AB1: 2043 | AC1: 2044 | AD1: 2045 | AE1: 2046 | AF1: 2047 | AG1: 2048 | AH1: 2049 | AI1: 2050 | AJ1: 2051 | AK1: 2052 | AL1: 2053 | AM1: 2054 | AN1: 2055 | AO1: 2056 | AP1: 2057 | AQ1: 2058 | AR1: 2059 | AS1: 2060
A2: 煤炭开采和洗选业 | B2: 原煤 | C2: 亿吨 | D2: 中石化《中国能源展望2060》 | E2: 39.02 | F2: 41.26 | G2: 45.59 | H2: =G2+($J2-$G2)/3 -> 46.393333 | I2: =H2+($J2-$G2)/3 -> 47.196667 | J2: 48 | K2: =J2+($O2-$J2)/5 -> 46.4 | L2: =K2+($O2-$J2)/5 -> 44.8 | M2: =L2+($O2-$J2)/5 -> 43.2 | N2: =M2+($O2-$J2)/5 -> 41.6 | O2: 40 | P2: =O2+($T2-$O2)/5 -> 38.784314 | Q2: =P2+($T2-$O2)/5 -> 37.568627 | R2: =Q2+($T2-$O2)/5 -> 36.352941 | S2: =R2+($T2-$O2)/5 -> 35.137255 | T2: =O2*(34.6/40.8) -> 33.921569 | U2: =T2+($Y2-$T2)/5 -> 32.647059 | V2: =U2+($Y2-$T2)/5 -> 31.372549 | W2: =V2+($Y2-$T2)/5 -> 30.098039 | X2: =W2+($Y2-$T2)/5 -> 28.823529 | Y2: =T2*(28.1/34.6) -> 27.54902 | Z2: =Y2+($AD2-$Y2)/5 -> 26.215686 | AA2: =Z2+($AD2-$Y2)/5 -> 24.882353 | AB2: =AA2+($AD2-$Y2)/5 -> 23.54902 | AC2: =AB2+($AD2-$Y2)/5 -> 22.215686 | AD2: =Y2*(21.3/28.1) -> 20.882353 | AE2: =AD2+($AI2-$AD2)/5 -> 19.470588 | AF2: =AE2+($AI2-$AD2)/5 -> 18.058824 | AG2: =AF2+($AI2-$AD2)/5 -> 16.647059 | AH2: =AG2+($AI2-$AD2)/5 -> 15.235294 | AI2: =AD2*(14.1/21.3) -> 13.823529 | AJ2: =AI2+($AN2-$AI2)/5 -> 12.72549 | AK2: =AJ2+($AN2-$AI2)/5 -> 11.627451 | AL2: =AK2+($AN2-$AI2)/5 -> 10.529412 | AM2: =AL2+($AN2-$AI2)/5 -> 9.4313725 | AN2: =AI2*(8.5/14.1) -> 8.3333333 | AO2: =AN2+($AS2-$AN2)/5 -> 7.4117647 | AP2: =AO2+($AS2-$AN2)/5 -> 6.4901961 | AQ2: =AP2+($AS2-$AN2)/5 -> 5.5686275 | AR2: =AQ2+($AS2-$AN2)/5 -> 4.6470588 | AS2: =AN2*(3.8/8.5) -> 3.7254902
A3: 石油和天然气开采业 | B3: 原油 | C3: 亿吨 | D3: 中石油《世界与中国能源展望2021》 | E3: 1.9477 | F3: 1.9888 | G3: 2.0472 | H3: =G3+($J3-$G3)/3 -> 2.0781333 | I3: =H3+($J3-$G3)/3 -> 2.1090667 | J3: 2.14 | K3: =J3+($O3-$J3)/5 -> 2.146 | L3: =K3+($O3-$J3)/5 -> 2.152 | M3: =L3+($O3-$J3)/5 -> 2.158 | N3: =M3+($O3-$J3)/5 -> 2.164 | O3: 2.17 | P3: =O3+($T3-$O3)/5 -> 2.156 | Q3: =P3+($T3-$O3)/5 -> 2.142 | R3: =Q3+($T3-$O3)/5 -> 2.128 | S3: =R3+($T3-$O3)/5 -> 2.114 | T3: 2.1 | U3: =T3+($Y3-$T3)/5 -> 2.08 | V3: =U3+($Y3-$T3)/5 -> 2.06 | W3: =V3+($Y3-$T3)/5 -> 2.04 | X3: =W3+($Y3-$T3)/5 -> 2.02 | Y3: 2 | Z3: =Y3+($AD3-$Y3)/5 -> 1.98 | AA3: =Z3+($AD3-$Y3)/5 -> 1.96 | AB3: =AA3+($AD3-$Y3)/5 -> 1.94 | AC3: =AB3+($AD3-$Y3)/5 -> 1.92 | AD3: 1.9 | AE3: =AD3+($AI3-$AD3)/5 -> 1.884 | AF3: =AE3+($AI3-$AD3)/5 -> 1.868 | AG3: =AF3+($AI3-$AD3)/5 -> 1.852 | AH3: =AG3+($AI3-$AD3)/5 -> 1.836 | AI3: 1.82 | AJ3: =AI3+($AN3-$AI3)/5 -> 1.806 | AK3: =AJ3+($AN3-$AI3)/5 -> 1.792 | AL3: =AK3+($AN3-$AI3)/5 -> 1.778 | AM3: =AL3+($AN3-$AI3)/5 -> 1.764 | AN3: 1.75 | AO3: =AN3+($AS3-$AN3)/5 -> 1.74 | AP3: =AO3+($AS3-$AN3)/5 -> 1.73 | AQ3: =AP3+($AS3-$AN3)/5 -> 1.72 | AR3: =AQ3+($AS3-$AN3)/5 -> 1.71 | AS3: 1.7
A4: 石油和天然气开采业 | B4: 天然气 | C4: 亿立方米 | D4: 中石油《世界与中国能源展望2021》 | E4: 1924.95 | F4: 2075.84 | G4: 2201.1 | H4: =G4+($J4-$G4)/3 -> 2298.4 | I4: =H4+($J4-$G4)/3 -> 2395.7 | J4: 2493 | K4: =J4+($O4-$J4)/5 -> 2554.4 | L4: =K4+($O4-$J4)/5 -> 2615.8 | M4: =L4+($O4-$J4)/5 -> 2677.2 | N4: =M4+($O4-$J4)/5 -> 2738.6 | O4: 2800 | P4: =O4+($T4-$O4)/5 -> 2840 | Q4: =P4+($T4-$O4)/5 -> 2880 | R4: =Q4+($T4-$O4)/5 -> 2920 | S4: =R4+($T4-$O4)/5 -> 2960 | T4: 3000 | U4: =T4+($Y4-$T4)/5 -> 3040 | V4: =U4+($Y4-$T4)/5 -> 3080 | W4: =V4+($Y4-$T4)/5 -> 3120 | X4: =W4+($Y4-$T4)/5 -> 3160 | Y4: 3200 | Z4: =Y4+($AD4-$Y4)/5 -> 3220 | AA4: =Z4+($AD4-$Y4)/5 -> 3240 | AB4: =AA4+($AD4-$Y4)/5 -> 3260 | AC4: =AB4+($AD4-$Y4)/5 -> 3280 | AD4: 3300 | AE4: =AD4+($AI4-$AD4)/5 -> 3320 | AF4: =AE4+($AI4-$AD4)/5 -> 3340 | AG4: =AF4+($AI4-$AD4)/5 -> 3360 | AH4: =AG4+($AI4-$AD4)/5 -> 3380 | AI4: 3400 | AJ4: =AI4+($AN4-$AI4)/5 -> 3420 | AK4: =AJ4+($AN4-$AI4)/5 -> 3440 | AL4: =AK4+($AN4-$AI4)/5 -> 3460 | AM4: =AL4+($AN4-$AI4)/5 -> 3480 | AN4: 3500 | AO4: =AN4+($AS4-$AN4)/5 -> 3500 | AP4: =AO4+($AS4-$AN4)/5 -> 3500 | AQ4: =AP4+($AS4-$AN4)/5 -> 3500 | AR4: =AQ4+($AS4-$AN4)/5 -> 3500 | AS4: 3500
A5: 黑色金属矿采选业 | B5: 铁矿石原矿 | C5: 亿吨 | D5: 产品产量与粗钢产量挂钩 | E5: 8.6672 | F5: 9.8053 | G5: 9.6787 | H5: =H18/G18*G5 -> 9.6885978 | I5: =I18/H18*H5 -> 9.5079468 | J5: =J18/G18*G5 -> 9.6030263 | K5: =J5+($O5-$J5)/5 -> 9.4318832 | L5: =K5+($O5-$J5)/5 -> 9.2607402 | M5: =L5+($O5-$J5)/5 -> 9.0895971 | N5: =M5+($O5-$J5)/5 -> 8.9184541 | O5: =O18/J18*J5 -> 8.747311 | P5: =O5+($T5-$O5)/5 -> 8.576168 | Q5: =P5+($T5-$O5)/5 -> 8.405025 | R5: =Q5+($T5-$O5)/5 -> 8.2338819 | S5: =R5+($T5-$O5)/5 -> 8.0627389 | T5: =T18/O18*O5 -> 7.8915958 | U5: =T5+($Y5-$T5)/5 -> 7.7204528 | V5: =U5+($Y5-$T5)/5 -> 7.5493097 | W5: =V5+($Y5-$T5)/5 -> 7.3781667 | X5: =W5+($Y5-$T5)/5 -> 7.2070237 | Y5: =Y18/T18*T5 -> 7.0358806 | Z5: =Y5+($AD5-$Y5)/5 -> 6.8837535 | AA5: =Z5+($AD5-$Y5)/5 -> 6.7316263 | AB5: =AA5+($AD5-$Y5)/5 -> 6.5794992 | AC5: =AB5+($AD5-$Y5)/5 -> 6.427372 | AD5: =AD18/Y18*Y5 -> 6.2752449 | AE5: =AD5+($AI5-$AD5)/5 -> 6.1801654 | AF5: =AE5+($AI5-$AD5)/5 -> 6.0850859 | AG5: =AF5+($AI5-$AD5)/5 -> 5.9900065 | AH5: =AG5+($AI5-$AD5)/5 -> 5.894927 | AI5: =AI18/AD18*AD5 -> 5.7998475 | AJ5: =AI5+($AN5-$AI5)/5 -> 5.7427999 | AK5: =AJ5+($AN5-$AI5)/5 -> 5.6857522 | AL5: =AK5+($AN5-$AI5)/5 -> 5.6287045 | AM5: =AL5+($AN5-$AI5)/5 -> 5.5716568 | AN5: =AN18/AI18*AI5 -> 5.5146091 | AO5: =AN5+($AS5-$AN5)/5 -> 5.4765773 | AP5: =AO5+($AS5-$AN5)/5 -> 5.4385456 | AQ5: =AP5+($AS5-$AN5)/5 -> 5.4005138 | AR5: =AQ5+($AS5-$AN5)/5 -> 5.362482 | AS5: =AS18/AN18*AN5 -> 5.3244502
A6: 有色金属矿采选业 | B6: 铜矿 | C6: 万吨 | D6: 拍数；https://www.wkqh.cn/ueditor/jsp/upload/file/20240603/1717376096015027949.pdf | E6: 172 | F6: 191 | G6: 194 | H6: =G6+($J6-$G6)/3 -> 216.60043 | I6: =H6+($J6-$G6)/3 -> 239.20087 | J6: =J20/G20*G6 -> 261.8013 | K6: =J6+($O6-$J6)/5 -> 268.78267 | L6: =K6+($O6-$J6)/5 -> 275.76404 | M6: =L6+($O6-$J6)/5 -> 282.7454 | N6: =M6+($O6-$J6)/5 -> 289.72677 | O6: =O20/J20*J6 -> 296.70814 | P6: =O6+($T6-$O6)/5 -> 300.19883 | Q6: =P6+($T6-$O6)/5 -> 303.68951 | R6: =Q6+($T6-$O6)/5 -> 307.18019 | S6: =R6+($T6-$O6)/5 -> 310.67088 | T6: =T20/O20*O6 -> 314.16156 | U6: =T6+($Y6-$T6)/5 -> 316.95411 | V6: =U6+($Y6-$T6)/5 -> 319.74666 | W6: =V6+($Y6-$T6)/5 -> 322.5392 | X6: =W6+($Y6-$T6)/5 -> 325.33175 | Y6: =Y20/T20*T6 -> 328.1243 | Z6: =Y6+($AD6-$Y6)/5 -> 327.42616 | AA6: =Z6+($AD6-$Y6)/5 -> 326.72802 | AB6: =AA6+($AD6-$Y6)/5 -> 326.02989 | AC6: =AB6+($AD6-$Y6)/5 -> 325.33175 | AD6: =AD20/Y20*Y6 -> 324.63361 | AE6: =AD6+($AI6-$AD6)/5 -> 322.5392 | AF6: =AE6+($AI6-$AD6)/5 -> 320.44479 | AG6: =AF6+($AI6-$AD6)/5 -> 318.35038 | AH6: =AG6+($AI6-$AD6)/5 -> 316.25597 | AI6: =AI20/AD20*AD6 -> 314.16156 | AJ6: =AI6+($AN6-$AI6)/5 -> 313.46342 | AK6: =AJ6+($AN6-$AI6)/5 -> 312.76529 | AL6: =AK6+($AN6-$AI6)/5 -> 312.06715 | AM6: =AL6+($AN6-$AI6)/5 -> 311.36901 | AN6: =AN20/AI20*AI6 -> 310.67088 | AO6: =AN6+($AS6-$AN6)/5 -> 310.32181 | AP6: =AO6+($AS6-$AN6)/5 -> 309.97274 | AQ6: =AP6+($AS6-$AN6)/5 -> 309.62367 | AR6: =AQ6+($AS6-$AN6)/5 -> 309.2746 | AS6: =AS20/AN20*AN6 -> 308.92554
A7: 有色金属矿采选业 | B7: 铝土矿 | C7: 万吨 | D7: 产量与电解铜产量挂钩 | E7: 9269 | F7: 8500 | G7: 9000 | H7: =G7+($J7-$G7)/3 -> 9213.4076 | I7: =H7+($J7-$G7)/3 -> 9426.8153 | J7: =J19/G19*G7 -> 9640.2229 | K7: =J7+($O7-$J7)/5 -> 9595.3846 | L7: =K7+($O7-$J7)/5 -> 9550.5464 | M7: =L7+($O7-$J7)/5 -> 9505.7082 | N7: =M7+($O7-$J7)/5 -> 9460.8699 | O7: =O19/J19*J7 -> 9416.0317 | P7: =O7+($T7-$O7)/5 -> 9303.9361 | Q7: =P7+($T7-$O7)/5 -> 9191.8404 | R7: =Q7+($T7-$O7)/5 -> 9079.7448 | S7: =R7+($T7-$O7)/5 -> 8967.6492 | T7: =T19/O19*O7 -> 8855.5536 | U7: =T7+($Y7-$T7)/5 -> 8743.458 | V7: =U7+($Y7-$T7)/5 -> 8631.3624 | W7: =V7+($Y7-$T7)/5 -> 8519.2667 | X7: =W7+($Y7-$T7)/5 -> 8407.1711 | Y7: =Y19/T19*T7 -> 8295.0755 | Z7: =Y7+($AD7-$Y7)/5 -> 8227.8181 | AA7: =Z7+($AD7-$Y7)/5 -> 8160.5608 | AB7: =AA7+($AD7-$Y7)/5 -> 8093.3034 | AC7: =AB7+($AD7-$Y7)/5 -> 8026.046 | AD7: =AD19/Y19*Y7 -> 7958.7887 | AE7: =AD7+($AI7-$AD7)/5 -> 7878.0798 | AF7: =AE7+($AI7-$AD7)/5 -> 7797.371 | AG7: =AF7+($AI7-$AD7)/5 -> 7716.6621 | AH7: =AG7+($AI7-$AD7)/5 -> 7635.9533 | AI7: =AI19/AD19*AD7 -> 7555.2445 | AJ7: =AI7+($AN7-$AI7)/5 -> 7479.0194 | AK7: =AJ7+($AN7-$AI7)/5 -> 7402.7944 | AL7: =AK7+($AN7-$AI7)/5 -> 7326.5694 | AM7: =AL7+($AN7-$AI7)/5 -> 7250.3444 | AN7: =AN19/AI19*AI7 -> 7174.1194 | AO7: =AN7+($AS7-$AN7)/5 -> 7129.2811 | AP7: =AO7+($AS7-$AN7)/5 -> 7084.4429 | AQ7: =AP7+($AS7-$AN7)/5 -> 7039.6046 | AR7: =AQ7+($AS7-$AN7)/5 -> 6994.7664 | AS7: =AS19/AN19*AN7 -> 6949.9281
A8: 非金属矿采选业 | B8: 石灰石 | C8: 亿吨 | D8: 产品产量与水泥产量挂钩;https://www.sohu.com/a/716515038_121388092 | E8: 31.55 | F8: 31.4 | G8: 28.79 | H8: =G8+($J8-$G8)/3 -> 28.117229 | I8: =H8+($J8-$G8)/3 -> 27.444459 | J8: =J16/G16*G8 -> 26.771688 | K8: =J8+($O8-$J8)/5 -> 26.149719 | L8: =K8+($O8-$J8)/5 -> 25.527751 | M8: =L8+($O8-$J8)/5 -> 24.905782 | N8: =M8+($O8-$J8)/5 -> 24.283814 | O8: =O16/J16*J8 -> 23.661845 | P8: =O8+($T8-$O8)/5 -> 23.256214 | Q8: =P8+($T8-$O8)/5 -> 22.850582 | R8: =Q8+($T8-$O8)/5 -> 22.44495 | S8: =R8+($T8-$O8)/5 -> 22.039319 | T8: =T16/O16*O8 -> 21.633687 | U8: =T8+($Y8-$T8)/5 -> 21.309182 | V8: =U8+($Y8-$T8)/5 -> 20.984677 | W8: =V8+($Y8-$T8)/5 -> 20.660171 | X8: =W8+($Y8-$T8)/5 -> 20.335666 | Y8: =Y16/T16*T8 -> 20.011161 | Z8: =Y8+($AD8-$Y8)/5 -> 19.659613 | AA8: =Z8+($AD8-$Y8)/5 -> 19.308066 | AB8: =AA8+($AD8-$Y8)/5 -> 18.956518 | AC8: =AB8+($AD8-$Y8)/5 -> 18.604971 | AD8: =AD16/Y16*Y8 -> 18.253424 | AE8: =AD8+($AI8-$AD8)/5 -> 17.847792 | AF8: =AE8+($AI8-$AD8)/5 -> 17.44216 | AG8: =AF8+($AI8-$AD8)/5 -> 17.036529 | AH8: =AG8+($AI8-$AD8)/5 -> 16.630897 | AI8: =AI16/AD16*AD8 -> 16.225265 | AJ8: =AI8+($AN8-$AI8)/5 -> 15.954844 | AK8: =AJ8+($AN8-$AI8)/5 -> 15.684423 | AL8: =AK8+($AN8-$AI8)/5 -> 15.414002 | AM8: =AL8+($AN8-$AI8)/5 -> 15.143581 | AN8: =AN16/AI16*AI8 -> 14.87316 | AO8: =AN8+($AS8-$AN8)/5 -> 14.602739 | AP8: =AO8+($AS8-$AN8)/5 -> 14.332318 | AQ8: =AP8+($AS8-$AN8)/5 -> 14.061897 | AR8: =AQ8+($AS8-$AN8)/5 -> 13.791476 | AS8: =AS16/AN16*AN8 -> 13.521054
A9: 造纸和纸制品业 | B9: 纸和纸板 | C9: 万吨 | D9: 中国能源研究会-内部报告 | E9: 12700.63 | F9: 13583.87 | G9: 13691.4 | H9: =G9+($J9-$G9)/3 -> 13794.267 | I9: =H9+($J9-$G9)/3 -> 13897.133 | J9: 14000 | K9: =J9+($O9-$J9)/5 -> 14300 | L9: =K9+($O9-$J9)/5 -> 14600 | M9: =L9+($O9-$J9)/5 -> 14900 | N9: =M9+($O9-$J9)/5 -> 15200 | O9: 15500 | P9: =O9+($T9-$O9)/5 -> 15660 | Q9: =P9+($T9-$O9)/5 -> 15820 | R9: =Q9+($T9-$O9)/5 -> 15980 | S9: =R9+($T9-$O9)/5 -> 16140 | T9: 16300 | U9: =T9+($Y9-$T9)/5 -> 16200 | V9: =U9+($Y9-$T9)/5 -> 16100 | W9: =V9+($Y9-$T9)/5 -> 16000 | X9: =W9+($Y9-$T9)/5 -> 15900 | Y9: 15800 | Z9: =Y9+($AD9-$Y9)/5 -> 15540 | AA9: =Z9+($AD9-$Y9)/5 -> 15280 | AB9: =AA9+($AD9-$Y9)/5 -> 15020 | AC9: =AB9+($AD9-$Y9)/5 -> 14760 | AD9: 14500 | AE9: =AD9+($AI9-$AD9)/5 -> 14060 | AF9: =AE9+($AI9-$AD9)/5 -> 13620 | AG9: =AF9+($AI9-$AD9)/5 -> 13180 | AH9: =AG9+($AI9-$AD9)/5 -> 12740 | AI9: 12300 | AJ9: =AI9+($AN9-$AI9)/5 -> 11900 | AK9: =AJ9+($AN9-$AI9)/5 -> 11500 | AL9: =AK9+($AN9-$AI9)/5 -> 11100 | AM9: =AL9+($AN9-$AI9)/5 -> 10700 | AN9: 10300 | AO9: =AN9+($AS9-$AN9)/5 -> 9960 | AP9: =AO9+($AS9-$AN9)/5 -> 9620 | AQ9: =AP9+($AS9-$AN9)/5 -> 9280 | AR9: =AQ9+($AS9-$AN9)/5 -> 8940 | AS9: 8600
A10: 石油、煤炭及其他燃料加工业 | B10: 原油加工量 | C10: 亿吨 | D10: 加工量与原油产量挂钩 | E10: 6.7441 | F10: 7 | G10: 6.759 | H10: =G10+($J10-$G10)/3 -> 6.861129 | I10: =H10+($J10-$G10)/3 -> 6.9632579 | J10: =J3/G3*G10 -> 7.0653869 | K10: =J10+($O10-$J10)/5 -> 7.0851964 | L10: =K10+($O10-$J10)/5 -> 7.1050059 | M10: =L10+($O10-$J10)/5 -> 7.1248154 | N10: =M10+($O10-$J10)/5 -> 7.1446249 | O10: =O3/J3*J10 -> 7.1644343 | P10: =O10+($T10-$O10)/5 -> 7.1182122 | Q10: =P10+($T10-$O10)/5 -> 7.07199 | R10: =Q10+($T10-$O10)/5 -> 7.0257679 | S10: =R10+($T10-$O10)/5 -> 6.9795457 | T10: =T3/O3*O10 -> 6.9333236 | U10: =T10+($Y10-$T10)/5 -> 6.8672919 | V10: =U10+($Y10-$T10)/5 -> 6.8012603 | W10: =V10+($Y10-$T10)/5 -> 6.7352286 | X10: =W10+($Y10-$T10)/5 -> 6.669197 | Y10: =Y3/T3*T10 -> 6.6031653 | Z10: =Y10+($AD10-$Y10)/5 -> 6.5371336 | AA10: =Z10+($AD10-$Y10)/5 -> 6.471102 | AB10: =AA10+($AD10-$Y10)/5 -> 6.4050703 | AC10: =AB10+($AD10-$Y10)/5 -> 6.3390387 | AD10: =AD3/Y3*Y10 -> 6.273007 | AE10: =AD10+($AI10-$AD10)/5 -> 6.2201817 | AF10: =AE10+($AI10-$AD10)/5 -> 6.1673564 | AG10: =AF10+($AI10-$AD10)/5 -> 6.1145311 | AH10: =AG10+($AI10-$AD10)/5 -> 6.0617057 | AI10: =AI3/AD3*AD10 -> 6.0088804 | AJ10: =AI10+($AN10-$AI10)/5 -> 5.9626583 | AK10: =AJ10+($AN10-$AI10)/5 -> 5.9164361 | AL10: =AK10+($AN10-$AI10)/5 -> 5.870214 | AM10: =AL10+($AN10-$AI10)/5 -> 5.8239918 | AN10: =AN3/AI3*AI10 -> 5.7777696 | AO10: =AN10+($AS10-$AN10)/5 -> 5.7447538 | AP10: =AO10+($AS10-$AN10)/5 -> 5.711738 | AQ10: =AP10+($AS10-$AN10)/5 -> 5.6787222 | AR10: =AQ10+($AS10-$AN10)/5 -> 5.6457063 | AS10: =AS3/AN3*AN10 -> 5.6126905
A11: 石油、煤炭及其他燃料加工业 | B11: 焦炭 | C11: 万吨 | D11: 焦炭产量与钢铁产量挂钩 | E11: 47116 | F11: 46400 | G11: 47300 | H11: =G11+($J11-$G11)/3 -> 47176.727 | I11: =H11+($J11-$G11)/3 -> 47053.454 | J11: =J18/G18*G11 -> 46930.181 | K11: =J11+($O11-$J11)/5 -> 46093.801 | L11: =K11+($O11-$J11)/5 -> 45257.422 | M11: =L11+($O11-$J11)/5 -> 44421.042 | N11: =M11+($O11-$J11)/5 -> 43584.663 | O11: =O18/J18*J11 -> 42748.284 | P11: =O11+($T11-$O11)/5 -> 41911.904 | Q11: =P11+($T11-$O11)/5 -> 41075.525 | R11: =Q11+($T11-$O11)/5 -> 40239.145 | S11: =R11+($T11-$O11)/5 -> 39402.766 | T11: =T18/O18*O11 -> 38566.386 | U11: =T11+($Y11-$T11)/5 -> 37730.007 | V11: =U11+($Y11-$T11)/5 -> 36893.627 | W11: =V11+($Y11-$T11)/5 -> 36057.248 | X11: =W11+($Y11-$T11)/5 -> 35220.868 | Y11: =Y18/T18*T11 -> 34384.489 | Z11: =Y11+($AD11-$Y11)/5 -> 33641.041 | AA11: =Z11+($AD11-$Y11)/5 -> 32897.592 | AB11: =AA11+($AD11-$Y11)/5 -> 32154.144 | AC11: =AB11+($AD11-$Y11)/5 -> 31410.695 | AD11: =AD18/Y18*Y11 -> 30667.247 | AE11: =AD11+($AI11-$AD11)/5 -> 30202.592 | AF11: =AE11+($AI11-$AD11)/5 -> 29737.936 | AG11: =AF11+($AI11-$AD11)/5 -> 29273.281 | AH11: =AG11+($AI11-$AD11)/5 -> 28808.626 | AI11: =AI18/AD18*AD11 -> 28343.971 | AJ11: =AI11+($AN11-$AI11)/5 -> 28065.177 | AK11: =AJ11+($AN11-$AI11)/5 -> 27786.384 | AL11: =AK11+($AN11-$AI11)/5 -> 27507.591 | AM11: =AL11+($AN11-$AI11)/5 -> 27228.798 | AN11: =AN18/AI18*AI11 -> 26950.005 | AO11: =AN11+($AS11-$AN11)/5 -> 26764.143 | AP11: =AO11+($AS11-$AN11)/5 -> 26578.281 | AQ11: =AP11+($AS11-$AN11)/5 -> 26392.419 | AR11: =AQ11+($AS11-$AN11)/5 -> 26206.556 | AS11: =AS18/AN18*AN11 -> 26020.694
A12: 化学原料和化学制品制造业 | B12: 烧碱 | C12: 万吨 | D12: 中国能源研究会-内部报告 | E12: 3673.87 | F12: 3891.31 | G12: 3463.08 | H12: =G12+($J12-$G12)/3 -> 3675.3867 | I12: =H12+($J12-$G12)/3 -> 3887.6933 | J12: 4100 | K12: =J12+($O12-$J12)/5 -> 4080 | L12: =K12+($O12-$J12)/5 -> 4060 | M12: =L12+($O12-$J12)/5 -> 4040 | N12: =M12+($O12-$J12)/5 -> 4020 | O12: 4000 | P12: =O12+($T12-$O12)/5 -> 3950 | Q12: =P12+($T12-$O12)/5 -> 3900 | R12: =Q12+($T12-$O12)/5 -> 3850 | S12: =R12+($T12-$O12)/5 -> 3800 | T12: 3750 | U12: =T12+($Y12-$T12)/5 -> 3690 | V12: =U12+($Y12-$T12)/5 -> 3630 | W12: =V12+($Y12-$T12)/5 -> 3570 | X12: =W12+($Y12-$T12)/5 -> 3510 | Y12: 3450 | Z12: =Y12+($AD12-$Y12)/5 -> 3390 | AA12: =Z12+($AD12-$Y12)/5 -> 3330 | AB12: =AA12+($AD12-$Y12)/5 -> 3270 | AC12: =AB12+($AD12-$Y12)/5 -> 3210 | AD12: 3150 | AE12: =AD12+($AI12-$AD12)/5 -> 3100 | AF12: =AE12+($AI12-$AD12)/5 -> 3050 | AG12: =AF12+($AI12-$AD12)/5 -> 3000 | AH12: =AG12+($AI12-$AD12)/5 -> 2950 | AI12: 2900 | AJ12: =AI12+($AN12-$AI12)/5 -> 2880 | AK12: =AJ12+($AN12-$AI12)/5 -> 2860 | AL12: =AK12+($AN12-$AI12)/5 -> 2840 | AM12: =AL12+($AN12-$AI12)/5 -> 2820 | AN12: 2800 | AO12: =AN12+($AS12-$AN12)/5 -> 2780 | AP12: =AO12+($AS12-$AN12)/5 -> 2760 | AQ12: =AP12+($AS12-$AN12)/5 -> 2740 | AR12: =AQ12+($AS12-$AN12)/5 -> 2720 | AS12: 2700
A13: 化学原料和化学制品制造业 | B13: 纯碱 | C13: 万吨 | D13: 中国能源研究会-内部报告 | E13: 2812.37 | F13: 2913.25 | G13: 2920.2 | H13: =G13+($J13-$G13)/3 -> 2996.8 | I13: =H13+($J13-$G13)/3 -> 3073.4 | J13: 3150 | K13: =J13+($O13-$J13)/5 -> 3130 | L13: =K13+($O13-$J13)/5 -> 3110 | M13: =L13+($O13-$J13)/5 -> 3090 | N13: =M13+($O13-$J13)/5 -> 3070 | O13: 3050 | P13: =O13+($T13-$O13)/5 -> 3000 | Q13: =P13+($T13-$O13)/5 -> 2950 | R13: =Q13+($T13-$O13)/5 -> 2900 | S13: =R13+($T13-$O13)/5 -> 2850 | T13: 2800 | U13: =T13+($Y13-$T13)/5 -> 2740 | V13: =U13+($Y13-$T13)/5 -> 2680 | W13: =V13+($Y13-$T13)/5 -> 2620 | X13: =W13+($Y13-$T13)/5 -> 2560 | Y13: 2500 | Z13: =Y13+($AD13-$Y13)/5 -> 2456 | AA13: =Z13+($AD13-$Y13)/5 -> 2412 | AB13: =AA13+($AD13-$Y13)/5 -> 2368 | AC13: =AB13+($AD13-$Y13)/5 -> 2324 | AD13: 2280 | AE13: =AD13+($AI13-$AD13)/5 -> 2254 | AF13: =AE13+($AI13-$AD13)/5 -> 2228 | AG13: =AF13+($AI13-$AD13)/5 -> 2202 | AH13: =AG13+($AI13-$AD13)/5 -> 2176 | AI13: 2150 | AJ13: =AI13+($AN13-$AI13)/5 -> 2130 | AK13: =AJ13+($AN13-$AI13)/5 -> 2110 | AL13: =AK13+($AN13-$AI13)/5 -> 2090 | AM13: =AL13+($AN13-$AI13)/5 -> 2070 | AN13: 2050 | AO13: =AN13+($AS13-$AN13)/5 -> 2040 | AP13: =AO13+($AS13-$AN13)/5 -> 2030 | AQ13: =AP13+($AS13-$AN13)/5 -> 2020 | AR13: =AQ13+($AS13-$AN13)/5 -> 2010 | AS13: 2000
A14: 化学原料和化学制品制造业 | B14: 乙烯 | C14: 万吨 | D14: 中国能源研究会-内部报告 | E14: 2159.96 | F14: 2825.67 | G14: 2897.51 | H14: =G14+($J14-$G14)/3 -> 3148.34 | I14: =H14+($J14-$G14)/3 -> 3399.17 | J14: 3650 | K14: =J14+($O14-$J14)/5 -> 3820 | L14: =K14+($O14-$J14)/5 -> 3990 | M14: =L14+($O14-$J14)/5 -> 4160 | N14: =M14+($O14-$J14)/5 -> 4330 | O14: 4500 | P14: =O14+($T14-$O14)/5 -> 4560 | Q14: =P14+($T14-$O14)/5 -> 4620 | R14: =Q14+($T14-$O14)/5 -> 4680 | S14: =R14+($T14-$O14)/5 -> 4740 | T14: 4800 | U14: =T14+($Y14-$T14)/5 -> 4780 | V14: =U14+($Y14-$T14)/5 -> 4760 | W14: =V14+($Y14-$T14)/5 -> 4740 | X14: =W14+($Y14-$T14)/5 -> 4720 | Y14: 4700 | Z14: =Y14+($AD14-$Y14)/5 -> 4660 | AA14: =Z14+($AD14-$Y14)/5 -> 4620 | AB14: =AA14+($AD14-$Y14)/5 -> 4580 | AC14: =AB14+($AD14-$Y14)/5 -> 4540 | AD14: 4500 | AE14: =AD14+($AI14-$AD14)/5 -> 4460 | AF14: =AE14+($AI14-$AD14)/5 -> 4420 | AG14: =AF14+($AI14-$AD14)/5 -> 4380 | AH14: =AG14+($AI14-$AD14)/5 -> 4340 | AI14: 4300 | AJ14: =AI14+($AN14-$AI14)/5 -> 4260 | AK14: =AJ14+($AN14-$AI14)/5 -> 4220 | AL14: =AK14+($AN14-$AI14)/5 -> 4180 | AM14: =AL14+($AN14-$AI14)/5 -> 4140 | AN14: 4100 | AO14: =AN14+($AS14-$AN14)/5 -> 4080 | AP14: =AO14+($AS14-$AN14)/5 -> 4060 | AQ14: =AP14+($AS14-$AN14)/5 -> 4040 | AR14: =AQ14+($AS14-$AN14)/5 -> 4020 | AS14: 4000
A15: 化学原料和化学制品制造业 | B15: 合成氨 | C15: 万吨 | D15: 中国能源研究会-内部报告 | E15: 5117.13 | F15: 5189.38 | G15: 5321.01 | H15: =G15+($J15-$G15)/3 -> 5447.34 | I15: =H15+($J15-$G15)/3 -> 5573.67 | J15: 5700 | K15: =J15+($O15-$J15)/5 -> 5734 | L15: =K15+($O15-$J15)/5 -> 5768 | M15: =L15+($O15-$J15)/5 -> 5802 | N15: =M15+($O15-$J15)/5 -> 5836 | O15: 5870 | P15: =O15+($T15-$O15)/5 -> 5896 | Q15: =P15+($T15-$O15)/5 -> 5922 | R15: =Q15+($T15-$O15)/5 -> 5948 | S15: =R15+($T15-$O15)/5 -> 5974 | T15: 6000 | U15: =T15+($Y15-$T15)/5 -> 6024 | V15: =U15+($Y15-$T15)/5 -> 6048 | W15: =V15+($Y15-$T15)/5 -> 6072 | X15: =W15+($Y15-$T15)/5 -> 6096 | Y15: 6120 | Z15: =Y15+($AD15-$Y15)/5 -> 6140 | AA15: =Z15+($AD15-$Y15)/5 -> 6160 | AB15: =AA15+($AD15-$Y15)/5 -> 6180 | AC15: =AB15+($AD15-$Y15)/5 -> 6200 | AD15: 6220 | AE15: =AD15+($AI15-$AD15)/5 -> 6236 | AF15: =AE15+($AI15-$AD15)/5 -> 6252 | AG15: =AF15+($AI15-$AD15)/5 -> 6268 | AH15: =AG15+($AI15-$AD15)/5 -> 6284 | AI15: 6300 | AJ15: =AI15+($AN15-$AI15)/5 -> 6320 | AK15: =AJ15+($AN15-$AI15)/5 -> 6340 | AL15: =AK15+($AN15-$AI15)/5 -> 6360 | AM15: =AL15+($AN15-$AI15)/5 -> 6380 | AN15: 6400 | AO15: =AN15+($AS15-$AN15)/5 -> 6420 | AP15: =AO15+($AS15-$AN15)/5 -> 6440 | AQ15: =AP15+($AS15-$AN15)/5 -> 6460 | AR15: =AQ15+($AS15-$AN15)/5 -> 6480 | AS15: 6500
