Workbook
Name ab: '[1]1997 Table 1a Modified'!#REF!
Name Eno_TM: '[1]1997 Table 1a Modified'!#REF!
Name Eno_TM: '[1]1997 Table 1a Modified'!#REF!
Name Eno_TM: '[1]1997 Table 1a Modified'!#REF!
Name Eno_TM: '[1]1997 Table 1a Modified'!#REF!
Name Eno_TM: '[1]1997 Table 1a Modified'!#REF!
Name Eno_TM: '[1]1997 Table 1a Modified'!#REF!
Name Eno_TM: '[1]1997 Table 1a Modified'!#REF!
Name Eno_TM: '[1]1997 Table 1a Modified'!#REF!
Name Eno_TM: '[1]1997 Table 1a Modified'!#REF!
Name Eno_TM: '[2]1997 Table 1a Modified'!#REF!
Name Eno_Tons: '[1]1997 Table 1a Modified'!#REF!
Name Eno_Tons: '[1]1997 Table 1a Modified'!#REF!
Name Eno_Tons: '[1]1997 Table 1a Modified'!#REF!
Name Eno_Tons: '[1]1997 Table 1a Modified'!#REF!
Name Eno_Tons: '[1]1997 Table 1a Modified'!#REF!
Name Eno_Tons: '[1]1997 Table 1a Modified'!#REF!
Name Eno_Tons: '[1]1997 Table 1a Modified'!#REF!
Name Eno_Tons: '[1]1997 Table 1a Modified'!#REF!
Name Eno_Tons: '[1]1997 Table 1a Modified'!#REF!
Name Eno_Tons: '[2]1997 Table 1a Modified'!#REF!
Name sd: #REF!
Name sss: '[1]1997 Table 1a Modified'!#REF!
Name Sum_T2: '[1]1997 Table 1a Modified'!#REF!
Name Sum_T2: '[1]1997 Table 1a Modified'!#REF!
Name Sum_T2: '[1]1997 Table 1a Modified'!#REF!
Name Sum_T2: '[1]1997 Table 1a Modified'!#REF!
Name Sum_T2: '[1]1997 Table 1a Modified'!#REF!
Name Sum_T2: '[1]1997 Table 1a Modified'!#REF!
Name Sum_T2: '[1]1997 Table 1a Modified'!#REF!
Name Sum_T2: '[1]1997 Table 1a Modified'!#REF!
Name Sum_T2: '[1]1997 Table 1a Modified'!#REF!
Name Sum_T2: '[2]1997 Table 1a Modified'!#REF!
Name Sum_TTM: '[1]1997 Table 1a Modified'!#REF!
Name Sum_TTM: '[1]1997 Table 1a Modified'!#REF!
Name Sum_TTM: '[1]1997 Table 1a Modified'!#REF!
Name Sum_TTM: '[1]1997 Table 1a Modified'!#REF!
Name Sum_TTM: '[1]1997 Table 1a Modified'!#REF!
Name Sum_TTM: '[1]1997 Table 1a Modified'!#REF!
Name Sum_TTM: '[1]1997 Table 1a Modified'!#REF!
Name Sum_TTM: '[1]1997 Table 1a Modified'!#REF!
Name Sum_TTM: '[1]1997 Table 1a Modified'!#REF!
Name Sum_TTM: '[2]1997 Table 1a Modified'!#REF!
Name ti_tbl_50: #REF!
Name ti_tbl_50: #REF!
Name ti_tbl_50: #REF!
Name ti_tbl_50: #REF!
Name ti_tbl_50: #REF!
Name ti_tbl_50: #REF!
Name ti_tbl_50: #REF!
Name ti_tbl_50: #REF!
Name ti_tbl_50: #REF!
Name ti_tbl_50: #REF!
Name ti_tbl_69: #REF!
Name ti_tbl_69: #REF!
Name ti_tbl_69: #REF!
Name ti_tbl_69: #REF!
Name ti_tbl_69: #REF!
Name ti_tbl_69: #REF!
Name ti_tbl_69: #REF!

Sheet About 
A1: China Average Annual Dist Traveled by Vehicle Type
A3: Source: | B3: LDVs, HDVs and motorbike: Technical Guidance for Emission Inventory of Vehicles (China, 2015)
B4: Ministry of Ecology and Environment of the People's Republic of China
B5: 2015
B6: Technical Guidance for Emission Inventory of Vehicles
B7: https://wenku.baidu.com/view/586194e3b307e87101f696e3.html
B8: Tables 4
B10: China_train
B11: China Railway
B12: China Railway Yearbook 2017
B13: Tables 13-3-3
B15: China_ship
B16: National Data
B17: China Statistical Yearbook 2018
B18: http://data.stats.gov.cn/easyquery.htm?cn=C01&zb=A0G05&sj=2017
B21: China_aircraft
... B24: https://max.book118.com/html/2018/0524/168430691.shtm
A28: Notes:
A29: For ship, we use turnover and total passenger seats(weight of cargos) to calculate.
A31: For train,the China Railway Yearbook provides the travel distance for locomotives, but does not distinguish between freight and passenger. So we use the same data for both.
A33: Aircraft: In average there is 9.49 utilized hours per day for one aircraft(from China Statistic Report of Civil Aviation 2017) ,
A34: so we assume that an aircraft can perform two 2000km flights per day within the 9.49 hours,
A35: and travel distance per year remains the same for passenger and freight transportation.
A37: LDVs, HDVs and motorbike: Technical Guidance for Emission Inventory of Vehicles (China, 2015)

Sheet LDVs HDVs
A1: kilometer | C1: passenger | F1: freight | I1: iCET Report
A2: LDVs | C2: 10000 | E2: 2018 iCET《2018中国乘用车实际道路行驶与油耗分析年度报告》 http://www.icet.org.cn/admin/upload/2019081537990401.pdf 大部分车实际跑不到10000km | F2: 30000 | G2: https://q.qcds.com/view/Yrqol5W
A3: HDVs | C3: 60000 | D3: =C3*50% -> 30000 | F3: 75000 | G3: =F3*80% -> 60000
A4: miles
A5: LDVs | C5: ='LDVs HDVs'!C2/converter!D2 -> 6213.8818 | F5: =F2/converter!D2 -> 18641.645
A6: HDVs | C6: =C3/converter!D2 -> 37283.291 | F6: =F3/converter!D2 -> 46604.114
B15: LDV-psgr | D15: HDV-psgr | E15: LDV-frgt | F15: HDV-frgt
B16: 私家车 | C16: 营运车 | H16: 2019 | I16: 汽油保有量 | J16: 2020新销汽油 | K16: 柴油保有量 | L16: 2020新销柴油 | M16: 天然气保有量 | N16: 2020新销天然气 | O16: 插电保有量 | P16: 2020新销插电 | Q16: 纯电保有量 | R16: 2020新销纯电 | S16: 燃料电池保有量 | T16: 2020新销燃料电池 | U16: 甲醇保有量 | V16: 2020新销甲醇 | W16: LPG保有量 | X16: 2020新销LPG
A17: SYVbT | B17: 2858281 | C17: 219557919 | D17: 2310494 | E17: 18926340 | F17: 8502856 | H17: 出租车 | I17: 1849624.5 | J17: 252202.23 | K17: 37143.237 | L17: 12686.579 | M17: 438244.31 | N17: 101792.34 | O17: 81082.727 | P17: 45907.414 | Q17: 432005.82 | R17: 252409.47 | S17: 0 | T17: 0 | U17: 17170.51 | V17: 15441.343 | W17: 3009.8344 | X17: 214.68451
A18: AVLo | B18: 1.67 | C18: 1.67 | D18: 21.196137 | E18: 1.25 | F18: 10.82 | H18: 私家车 | I18: 2.1502796e+08 | J18: 21292753 | K18: 2160864.4 | L18: 155130.82 | M18: 334141.89 | N18: 11971.319 | O18: 1038136 | P18: 567728.94 | Q18: 994327.86 | R18: 403462.34 | S18: 0 | T18: 0 | U18: 257.26007 | V18: 0 | W18: 534.30937 | X18: 0
A19: 年鉴周转量 | C19: 8857.1 | E19: 59636.4 | H19: 小型公交车 | I19: 674.87458 | J19: 315.65 | K19: 600.47896 | L19: 5.3139731 | M19: 365.60135 | N19: 179.61229 | O19: 0 | P19: 0 | Q19: 60.579293 | R19: 46.762963 | S19: 0 | T19: 0 | U19: 0 | V19: 0 | W19: 0 | X19: 0
A20: 年报公里 | C20: =(44400*1702+96000*2858281)/(1702+2858281) -> 95969.292 | D20: 50000 | E20: 25000 | F20: =(48000*1113343+60000*7389513)/(1113343+7389513) -> 58428.75 | H20: 中型公交车 | I20: 5348.9726 | J20: 159.15772 | K20: 24952.352 | L20: 951.65339 | M20: 6649.6753 | N20: 60.370169 | O20: 0 | P20: 0 | Q20: 1280.9452 | R20: 1212.8916 | S20: 0 | T20: 0 | U20: 0 | V20: 0 | W20: 0 | X20: 0
A21: 计算周转量 | C21: =(C17*C18*C20+D17*D18*D20)/10^8 -> 376369.44 | E21: =(E17*E18*E20+F17*F18*F20)/10^8 -> 59669.458 | H21: 大型公交车 | I21: 11756.384 | J21: 2.5787397 | K21: 221475.25 | L21: 1304.8423 | M21: 242415.37 | N21: 1402.8344 | O21: 13266.326 | P21: 5540.4222 | Q21: 187474.37 | R21: 86426.46 | S21: 1347.3915 | T21: 954.13368 | U21: 0 | V21: 0 | W21: 0 | X21: 0
A22: km | B22: =(11800*B17+44400*1702+96000*2858281)/(B17+1702+2858281) -> 53897.172 | D22: 50000 | E22: =E20 -> 25000 | F22: =F20 -> 58428.75 | H22: 中型客车 | I22: 262101.49 | J22: 11798.526 | K22: 407170.22 | L22: 28998.536 | M22: 6223.9973 | N22: 93.299352 | O22: 0 | P22: 0 | Q22: 246.67251 | R22: 248.06651 | S22: 0 | T22: 0 | U22: 0 | V22: 0 | W22: 0 | X22: 0
A23: mile | B23: =B22/converter!$D$2/2.95 -> 11352.904 | D23: =D22/converter!$D$2 -> 31069.409 | E23: =E22/converter!$D$2 -> 15534.705 | F23: =F22/converter!$D$2 -> 36306.934 | H23: 大型客车 | I23: 75554.38 | J23: 5684.8316 | K23: 758715.49 | L23: 53795.089 | M23: 70979.911 | N23: 1101.1218 | O23: 114.88285 | P23: 5.1574794 | Q23: 12688.173 | R23: 5005.3337 | S23: 725.03845 | T23: 562.16525 | U23: 6.3823807 | V23: 0 | W23: 0 | X23: 0
H24: 微轻型货车 | I24: 7715647.1 | J24: 1163639.3 | K24: 11001245 | L24: 1127332.5 | M24: 146358.69 | N24: 35151.052 | O24: 106.03797 | P24: 104.96688 | Q24: 62983.342 | R24: 19423.157 | S24: 0 | T24: 0 | U24: 0 | V24: 0 | W24: 0 | X24: 0
H25: 中型货车 | I25: 9030.7627 | J25: 29.654264 | K25: 1098475.4 | L25: 83252.369 | M25: 1575.6991 | N25: 215.48765 | O25: 0 | P25: 0 | Q25: 1871.184 | R25: 887.65096 | S25: 2390.1337 | T25: 1990.7896 | U25: 0 | V25: 0 | W25: 0 | X25: 0
H26: 重型货车 | I26: 34095.052 | J26: 0 | K26: 7037095.2 | L26: 1211734.9 | M26: 311949.39 | N26: 132946.24 | O26: 2.2237179 | P26: 0 | Q26: 6356.4977 | R26: 5804.5916 | S26: 0 | T26: 0 | U26: 14.454167 | V26: 0 | W26: 0 | X26: 0

Sheet rail
B1: railway mileage(km)
A2: 2016 | B2: 123991.9 | D2: Calibrate with China Statistics Yearbook data
B3: =B2/converter!D2 -> 77047.101 | E3: Passenger | F3: Freight
D4: AVLo | E4: 715.54 | F4: 4000
D5: SYVbT | E5: 76754 | F5: 877046
D6: Turn-Over | E6: 14706.6 | F6: 30182 | I6: https://www.mot.gov.cn/tongjishuju/tielu/201805/t20180515_3020550.html
D8: Distance per vehicle | E8: =E6/E5/E4*10^8 -> 26777.951 | F8: =F6/F5/F4*10^8 -> 860.33116
D9: mile | E9: =E8/converter!$D$2 -> 16639.502 | F9: =F8/converter!$D$2 -> 534.59961
C18: 机车 | D18: 21700 | E18: 21800 | F18: 22000 | G18: 22100 | H18: 22400 | I18: =7800+14700 -> 22500
C19: 客车 | D19: 76000 | E19: 76000 | F19: 78000 | G19: 77000 | H19: 78000 | I19: 81000
C20: 货车 | D20: 878000 | E20: 912000 | F20: 966000 | G20: 997000 | H20: 1007000 | I20: 1019000
D21: 2019 | E21: 2020 | F21: 2021 | G21: 2022 | H21: 2023 | I21: 2024
B22: 客运 | C22: 客运数量 | D22: =D19+D18*D19/(D19+D20) -> 77728.721 | E22: =E19+E18*E19/(E19+E20) -> 77676.923 | F22: =F19+F18*F19/(F19+F20) -> 79643.678 | G22: =G19+G18*G19/(G19+G20) -> 78584.451 | H22: =H19+H18*H19/(H19+H20) -> 79610.323 | I22: =I19+I18*I19/(I19+I20) -> 82656.818
C23: 周转量 | D23: 14706.6 | E23: 8266.2 | F23: 9567.8 | G23: 6577.5 | H23: 14729.4 | I23: 15799.1
C24: 距离 | D24: =D23*10^8/D22/$E$4 -> 26442.155 | E24: =E23*10^8/E22/$E$4 -> 14872.363 | F24: =F23*10^8/F22/$E$4 -> 16789.079 | G24: =G23*10^8/G22/$E$4 -> 11697.426 | H24: =H23*10^8/H22/$E$4 -> 25857.216 | I24: =I23*10^8/I22/$E$4 -> 26712.821 | J24: =J25*K25 -> 1.6714855
C25: mile | D25: =D24/converter!$D$2 -> 16430.842 | E25: =E24/converter!$D$2*$J$25 -> 16430.86 | F25: =F24/converter!$D$2*$J$25 -> 18548.431 | G25: =G24/converter!$D$2*$J$25 -> 12923.217 | H25: =H24/converter!$D$2*$J$25 -> 28566.832 | I25: =I24/converter!$D$2*$J$25 -> 29512.097 | J25: 1.777941 | K25: 0.94012431
C26: BCD | D26: =D23/$D$23 -> 1 | E26: =E23/$D$23 -> 0.56207417 | F26: =F23/$D$23 -> 0.65057865 | G26: =G23/$D$23 -> 0.44724817 | H26: =H23/$D$23 -> 1.0015503 | I26: =I23/$D$23 -> 1.0742864
B27: 货运 | C27: 货运数量 | D27: =D20+D18*D20/(D19+D20) -> 897971.28 | E27: =E20+E18*E20/(E19+E20) -> 932123.08 | F27: =F20+F18*F20/(F19+F20) -> 986356.32 | G27: =G20+G18*G20/(G19+G20) -> 1017515.5 | H27: =H20+H18*H20/(H19+H20) -> 1027789.7 | I27: =I20+I18*I20/(I19+I20) -> 1039843.2
C28: 周转量 | D28: 30182 | E28: 30514.5 | F28: 33238 | G28: 35945.7 | H28: 36460.4 | I28: 35861.9
C29: 距离 | D29: =D28*10^8/D27/$F$4 -> 840.283 | E29: =E28*10^8/E27/$F$4 -> 818.41392 | F29: =F28*10^8/F27/$F$4 -> 842.44404 | G29: =G28*10^8/G27/$F$4 -> 883.17324 | H29: =H28*10^8/H27/$F$4 -> 886.86433 | I29: =I28*10^8/I27/$F$4 -> 862.19491 | J29: 0.87166617 | K29: =J29*J30 -> 0.895513
C30: mile | D30: =D29/converter!$D$2 -> 522.14193 | E30: =E29/converter!$D$2*$J$30 -> 522.4656 | F30: =F29/converter!$D$2*$J$30 -> 537.80614 | G30: =G29/converter!$D$2*$J$30 -> 563.80717 | H30: =H29/converter!$D$2*$J$30 -> 566.16352 | I30: =I29/converter!$D$2*$J$30 -> 550.41486 | J30: 1.0273578
C31: BCD | D31: =D28/$D$28 -> 1 | E31: =E28/$D$28 -> 1.0110165 | F31: =F28/$D$28 -> 1.1012524 | G31: =G28/$D$28 -> 1.1909648 | H31: =H28/$D$28 -> 1.208018 | I31: =I28/$D$28 -> 1.1881883

Sheet aircraft
F6: depend on other indicators
G7: Passenger | H7: Freight
F8: AVLo | G8: 239.70073 | H8: 29.51167
F9: SYVbT | G9: 3645 | H9: 173
F10: Turn-Over | G10: 11705.3 | H10: 263.2 | I10: 10^8 person/ton miles | M10: https://baijiahao.baidu.com/s?id=1593250628267819387&wfr=spider&for=pc
F12: Distance per vehicle | G12: =G10/G9/G8*10^8 -> 1339725 | H12: =H10/H9/H8*10^8 -> 5155205.6
F13: mile | G13: =G12/converter!$D$2 -> 832489.27 | H13: =H12/converter!$D$2 -> 3203383.8
F22: 1.8912418 | G22: 1.1780618
E23: 2019 | F23: 2020 | G23: 2021 | H23: 2022 | I23: 2023 | J23: 2024
C24: 客运 | D24: 飞机架次 | E24: 3645 | F24: 3717 | G24: 3856 | H24: 3942 | I24: 4013 | J24: 4126 | K24: 民航行业发展统计公报
D25: 周转量 | E25: 11705.3 | F25: 6311.3 | G25: 6529.7 | H25: 3913.9 | I25: 10309 | J25: 12914.7
D26: 距离 | E26: =E25*10^8/E24/$G$8 -> 1339725 | F26: =F25*10^8/F24/$G$8 -> 708364.69 | G26: =G25*10^8/G24/$G$8 -> 706458.81 | H26: =H25*10^8/H24/$G$8 -> 414213.02 | I26: =I25*10^8/I24/$G$8 -> 1071711.8 | J26: =J25*10^8/J24/$G$8 -> 1305827.3
D27: mile | E27: =E26/converter!$D$2 -> 832489.27 | F27: =(F26/converter!$D$2)*1.8912417621456 -> 832466.84 | G27: =(G26/converter!$D$2)*1.8912417621456 -> 830227.05 | H27: =(H26/converter!$D$2)*1.8912417621456 -> 486781.19 | I27: =(I26/converter!$D$2)*1.8912417621456 -> 1259470.7 | J27: =J26/converter!$D$2 -> 811425.64
D28: BCD | E28: =E26/$E$26 -> 1 | F28: =F26/$E$26 -> 0.52873888 | G28: =G26/$E$26 -> 0.52731629 | H28: =H26/$E$26 -> 0.30917765 | I28: =I26/$E$26 -> 0.79994912 | J28: =J26/$E$26 -> 0.97469802
C29: 货运 | D29: 飞机架次 | E29: 173 | F29: 186 | G29: 198 | H29: 223 | I29: 257 | J29: 268
D30: 周转量 | E30: 263.2 | F30: 240.2 | G30: 278.16 | H30: 254.1 | I30: 283.62 | J30: 353.89
D31: 距离 | E31: =E30*10^8/E29/$H$8 -> 5155205.6 | F31: =F30*10^8/F29/$H$8 -> 4375888.7 | G31: =G30*10^8/G29/$H$8 -> 4760315.1 | H31: =H30*10^8/H29/$H$8 -> 3861055.2 | I31: =I30*10^8/I29/$H$8 -> 3739469 | J31: =J30*10^8/J29/$H$8 -> 4474450.5
D32: mile | E32: =E31/converter!$D$2 -> 3203383.8 | F32: =(F31/converter!$D$2)*1.17806178963019 -> 3203297.9 | G32: =(G31/converter!$D$2)*1.17806178963019 -> 3484710.9 | H32: =(H31/converter!$D$2)*1.17806178963019 -> 2826422.4 | I32: =(I31/converter!$D$2)*1.17806178963019 -> 2737417.2 | J32: =(J31/converter!$D$2)*1.17806178963019 -> 3275448.4
D33: BCD | E33: =E30/$E$30 -> 1 | F33: =F30/$E$30 -> 0.91261398 | G33: =G30/$E$30 -> 1.0568389 | H33: =H30/$E$30 -> 0.96542553 | I33: =I30/$E$30 -> 1.0775836 | J33: =J30/$E$30 -> 1.3445669

Sheet ships
L2: https://data.chinabaogao.com/jiaotong/2018/12133W4362018.html
L3: https://www.chyxx.com/industry/201808/668940.html
A13: ships | B13: turnover | D13: number of vehicles | F13: average loading per vehicle | I13: km | J13: mile
A14: passenger | B14: 80.2 | D14: 5853 | F14: 17.53 | H14: =B14/D14/F14 -> 0.00078165287 | I14: =H14*10^8 -> 78165.287 | J14: =I14/converter!D2 -> 48570.986
A15: freight | B15: 103963 | D15: 120998 | F15: 2258 | H15: =B15/D15/F15 -> 0.00038051929 | I15: =H15*10^8 -> 38051.929 | J15: =I15/converter!D2 -> 23645.019
C20: 船舶总数 | D20: =D22+D27 -> 131528 | E20: =11.5*10^4+10352+1499 -> 126851 | F20: =11.36*10^4+10891+1402 -> 125893 | G20: =10.95*10^4+10997+1387 -> 121884 | H20: =10.66*10^4+10672+972 -> 118244 | I20: =9.87*10^4+10245+1217 -> 110162 | J20: 《交通运输行业发展统计公报》
D21: 2019 | E21: 2020 | F21: 2021 | G21: 2022 | H21: 2023 | I21: 2024
A22: 17.533087 | B22: 客运 | C22: 客运数量 | D22: 5853 | E22: =E20*$D22/$D$20 -> 5644.8734 | F22: =F20*$D22/$D$20 -> 5602.2423 | G22: =G20*$D22/$D$20 -> 5423.8417 | H22: =H20*$D22/$D$20 -> 5261.8616 | I22: =I20*$D22/$D$20 -> 4902.2124
C23: 周转量 | D23: 80.2 | E23: 33 | F23: 33.1 | G23: 22.6 | H23: 53.8 | I23: 54.7
C24: 距离 | D24: =D23*10^8/D22/$A$22 -> 78151.523 | E24: =E23*10^8/E22/$A$22 -> 33342.744 | F24: =F23*10^8/F22/$A$22 -> 33698.278 | G24: =G23*10^8/G22/$A$22 -> 23765.285 | H24: =H23*10^8/H22/$A$22 -> 58315.561 | I24: =I23*10^8/I22/$A$22 -> 63640.973
C25: mile | D25: =D24/converter!$D$2 -> 48562.433 | E25: =E24/converter!$D$2*$J$25 -> 20718.787 | F25: =F24/converter!$D$2*$J$25 -> 20939.712 | G25: =G24/converter!$D$2*$J$25 -> 14767.468 | H25: =H24/converter!$D$2*$J$25 -> 36236.6 | I25: =I24/converter!$D$2*$J$25 -> 39545.748 | J25: 1
C26: BCD | D26: =D24/$D$24 -> 1 | E26: =E23/$D$23 -> 0.41147132 | F26: =F23/$D$23 -> 0.4127182 | G26: =G23/$D$23 -> 0.28179551 | H26: =H23/$D$23 -> 0.67082294 | I26: =I23/$D$23 -> 0.68204489
A27: 2257.5223 | B27: 货运 | C27: 货运数量 | D27: 125675 | E27: =E20*$D27/$D$20 -> 121206.13 | F27: =F20*$D27/$D$20 -> 120290.76 | G27: =G20*$D27/$D$20 -> 116460.16 | H27: =H20*$D27/$D$20 -> 112982.14 | I27: =I20*$D27/$D$20 -> 105259.79
C28: 周转量 | D28: 103963 | E28: 105834.4 | F28: 115577.5 | G28: 121003.1 | H28: 129951.5 | I28: 141422.9
C29: 距离 | D29: =D28*10^8/D27/$A$27 -> 36643.578 | E29: =E28*10^8/E27/$A$27 -> 38678.555 | F29: =F28*10^8/F27/$A$27 -> 42560.723 | G29: =G28*10^8/G27/$A$27 -> 46024.288 | H29: =H28*10^8/H27/$A$27 -> 50949.446 | I29: =I28*10^8/I27/$A$27 -> 59514.831
C30: mile | D30: =D29/converter!$D$2 -> 22769.886 | E30: =E29/converter!$D$2*$J$30 -> 22769.631 | F30: =F29/converter!$D$2*$J$30 -> 25055.019 | G30: =G29/converter!$D$2*$J$30 -> 27093.981 | H30: =H29/converter!$D$2*$J$30 -> 29993.367 | I30: =I29/converter!$D$2*$J$30 -> 35035.713 | J30: 0.94737684
C31: BCD | D31: =D28/$D$28 -> 1 | E31: =E28/$D$28 -> 1.0180006 | F31: =F28/$D$28 -> 1.1117176 | G31: =G28/$D$28 -> 1.1639054 | H31: =H28/$D$28 -> 1.2499784 | I31: =I28/$D$28 -> 1.3603195

Sheet motorbikes
B1: (Unit:km/vehicle/year）
A2: motorbikes | B2: 6000
B3: =B2/converter!D2 -> 3728.3291

Sheet China Vehicle Fleet Model Data
A1: Fleet Average VKT per Vehicle
A2: Unit: 1000 km
C4: Highway Vehicle | O4: Total
C5: Light-Duty Passenger Vehicle | G5: Bus | J5: Truck
C6: Private LDPV | D6: Taxi LDPV | E6: Business LDPV | F6: LDPV Total | G6: Urban Bus | H6: Intercity Bus | I6: Bus Total | J6: Mini Truck | K6: LD Truck | L6: MD Truck | M6: HD Truck | N6: Truck Total
B8: 2005 | C8: 18.0405 | D8: 85.327273 | E8: 23.45265 | F8: 23.344015 | G8: 59.7 | H8: 37 | I8: 40.274381 | J8: 30 | K8: 30 | L8: 30 | M8: 30 | N8: 30 | O8: 26.575748
B9: 2006 | C9: 17.8695 | D9: 88.781818 | E9: 23.23035 | F9: 22.369999 | G9: 60.5 | H9: 37 | I9: 40.250821 | J9: 30.9 | K9: 30.9 | L9: 30 | M9: 30 | N9: 30.526416 | O9: 25.713417
B10: 2007 | C10: 17.5275 | D10: 92.322727 | E10: 22.78575 | F10: 21.522169 | G10: 61.398205 | H10: 37 | I10: 40.561442 | J10: 22.3 | K10: 22.3 | L10: 30 | M10: 30 | N10: 25.442665 | O10: 23.544302
B11: 2008 | C11: 17.1855 | D11: 95 | E11: 22.34115 | F11: 20.697244 | G11: 62.177006 | H11: 37 | I11: 40.942381 | J11: 17 | K11: 17 | L11: 30 | M11: 30 | N11: 22.201619 | O11: 22.031667
B12: 2009 | C12: 16.929 | D12: 99.231686 | E12: 22.0077 | F12: 19.877828 | G12: 62.972469 | H12: 37 | I12: 41.215988 | J12: 14.7 | K12: 14.7 | L12: 30 | M12: 30 | N12: 21.153737 | O12: 21.030245
B13: 2010 | C13: 16.31 | D13: 99.227707 | E13: 21.203 | F13: 18.728314 | G13: 61.296411 | H13: 37 | I13: 40.891814 | J13: 12 | K13: 12 | L13: 30 | M13: 30 | N13: 19.487633 | O13: 19.638909
B14: 2011 | C14: 15.428 | D14: 98.218899 | E14: 19.509 | F14: 17.397418 | G14: 59.266166 | H14: 37 | I14: 40.684331 | J14: 13 | K14: 13 | L14: 32 | M14: 32 | N14: 20.740095 | O14: 18.730858
B15: 2012 | C15: 14.546 | D15: 98.396832 | E15: 17.815 | F15: 16.169627 | G15: 59.028457 | H15: 37 | I15: 41.025051 | J15: 14 | K15: 14 | L15: 34 | M15: 34 | N15: 21.406818 | O15: 17.681306
B16: 2013 | C16: 13.664 | D16: 97.064686 | E16: 16.121 | F16: 14.994198 | G16: 55.272494 | H16: 37 | I16: 40.747985 | J16: 15 | K16: 15 | L16: 36 | M16: 36 | N16: 22.294217 | O16: 16.670565
B17: 2014 | C17: 12.782 | D17: 96.341108 | E17: 14.427 | F17: 13.872127 | G17: 52.431291 | H17: 37 | I17: 40.242415 | J17: 16 | K17: 16 | L17: 38 | M17: 38 | N17: 23.470771 | O17: 15.742995
B18: 2015 | C18: 11.9 | D18: 93.778257 | E18: 12.733 | F18: 12.783955 | G18: 47.262794 | H18: 37 | I18: 39.50962 | J18: 17 | K18: 17 | L18: 40 | M18: 40 | N18: 24.559602 | O18: 14.66893
B19: 2016 | C19: 11.632 | D19: 90.052613 | E19: 12.2984 | F19: 12.361315 | G19: 40.684655 | H19: 37 | I19: 37.975635 | J19: 17 | K19: 17 | L19: 40 | M19: 40 | N19: 24.499453 | O19: 14.109279
... B53: 2050 | C53: 14.02 | D53: 46.486 | E53: 14.02 | F53: 14.179227 | G53: 23.814 | H53: 37 | I53: 33.632412 | J53: 17 | K53: 17 | L53: 40 | M53: 40 | N53: 24.36 | O53: 16.289994

Sheet converter
A2: 1 | B2: mile | C2: = | D2: 1.6093 | E2: km

Sheet raw data
A1: 旅客周转量（1978-2021年） | H1: 货物周转量（1978-2021年）
A2: Year | B2: Total | C2: Railways | D2: Highways | E2: Waterways | F2: Civial Aviation | H2: Year | I2: Total | J2: Railways | K2: Highways | L2: Waterways | N2: Civial Aviation
M3: Ocean | P3: 年报数据
A4: 1978 | B4: 1743.1 | C4: 1093.22 | D4: 521.3 | E4: 100.63 | F4: 27.91 | H4: 1978 | I4: 9928 | J4: 5345.19 | K4: 350.3 | L4: 3801.8 | M4: 2487 | N4: 0.97 | P4: 2019 | Q4: 2020 | R4: 2021 | S4: 2022 | T4: 2023
A5: 1980 | B5: 2281.3 | C5: 1383.16 | D5: 729.5 | E5: 129.12 | F5: 39.56 | H5: 1980 | I5: 11629 | J5: 5717.5 | K5: 342.9 | L5: 5076.5 | M5: 3532 | N5: 1.41 | P5: 13100.627 | Q5: 11397.277 | R5: 11800 | S5: 10327.242 | T5: 10503.775
A6: 1985 | B6: 4435.3863 | C6: 2416.14 | D6: 1724.88 | E6: 178.65 | F6: 115.7163 | H6: 1985 | I6: 18365 | J6: 8125.66 | K6: 1903 | L6: 7729.3 | M6: 5329 | N6: 4.15
A7: 1990 | B7: 5628.4 | C7: 2612.63 | D7: 2620.32 | E7: 164.91 | F7: 230.48 | H7: 1990 | I7: 26208 | J7: 10622.38 | K7: 3358.1 | L7: 11591.9 | M7: 8140.86 | N7: 8.18 | R7: Railways | S7: Highways | T7: Waterways | U7: Civial Aviation
A8: 1991 | B8: 6178.3 | C8: 2828.1 | D8: 2871.74 | E8: 177.2 | F8: 301.32 | H8: 1991 | I8: 27987 | J8: 10972 | K8: 3428 | L8: 12955.4 | M8: 8990.4 | N8: 10.1
A9: 1992 | B9: 6949.4 | C9: 3152.24 | D9: 3192.64 | E9: 198.35 | F9: 406.12 | H9: 1992 | I9: 29218 | J9: 11575.55 | K9: 3755.39 | L9: 13256.2 | M9: 9034 | N9: 13.42 | P9: Passenger | Q9: 2019 | R9: 1 | S9: 1 | T9: 1 | U9: 1
A10: 1993 | B10: 7858 | C10: 3483.3 | D10: 3700.7 | E10: 196.4 | F10: 477.6 | H10: 1993 | I10: 30646.81 | J10: 12090.9 | K10: 4070.5 | L10: 13860.8 | M10: 9133.9 | N10: 16.61 | Q10: 2020 | R10: =C37/C$36 -> 0.56207349 | S10: =D37/D$36 -> 0.52398754 | T10: =E37/E$36 -> 0.41134663 | U10: =F37/F$36 -> 0.53919061
A11: 1994 | B11: 8591.4 | C11: 3636 | D11: 4220.3 | E11: 183.5 | F11: 551.58 | H11: 1994 | I11: 33435.48 | J11: 12632 | K11: 4486.3 | L11: 15686.6 | M11: 10267.7 | N11: 18.58 | Q11: 2021 | R11: =C38/C$36 -> 0.65057933 | S11: =D38/D$36 -> 0.40956295 | T11: =E38/E$36 -> 0.41284289 | U11: =F38/F$36 -> 0.55784914
A12: 1995 | B12: 9001.9 | C12: 3545.7 | D12: 4603.1 | E12: 171.8 | F12: 681.3 | H12: 1995 | I12: 35908.9 | J12: 13049.48 | K12: 4694.9 | L12: 17552.2 | M12: 11938 | N12: 22.3 | Q12: 2022 | R12: =C39/C$36 -> 0.44725021 | S12: =D39/D$36 -> 0.27182058 | T12: =E39/E$36 -> 0.28182419 | U12: =F39/F$36 -> 0.33435853
A13: 1996 | B13: 9164.8 | C13: 3347.6 | D13: 4908.79 | E13: 160.57 | F13: 747.84 | H13: 1996 | I13: 36589.8 | J13: 13106.2 | K13: 5011.2 | L13: 17862.5 | M13: 11254 | N13: 24.93 | P13: Freight | Q13: 2019 | R13: 1 | S13: 1 | T13: 1 | U13: 1
A14: 1997 | B14: 10055.48 | C14: 3584.86 | D14: 5541.4 | E14: 155.7 | F14: 773.52 | H14: 1997 | I14: 38384.7 | J14: 13269.9 | K14: 5271.5 | L14: 19235 | M14: 14874.7 | N14: 29.1 | Q14: 2020 | R14: =J37/J$36 -> 1.0110168 | S14: =K37/K$36 -> 1.0089787 | T14: =L37/L$36 -> 1.0180006 | U14: =N37/N$36 -> 0.91261398
A15: 1998 | B15: 10636.7 | C15: 3773.42 | D15: 5942.81 | E15: 120.27 | F15: 800.24 | H15: 1998 | I15: 38088.7 | J15: 12560.1 | K15: 5483.38 | L15: 19405.8 | M15: 14920.28 | N15: 33.45 | Q15: 2021 | R15: =J38/J$36 -> 1.1012542 | S15: =K38/K$36 -> 1.1584814 | T15: =L38/L$36 -> 1.1117173 | U15: =N38/N$36 -> 1.0568389
A16: 1999 | B16: 11299.7 | C16: 4135.9 | D16: 6199.24 | E16: 107.28 | F16: 857.3 | H16: 1999 | I16: 40567.8 | J16: 12910.3 | K16: 5724.3 | L16: 21262.8 | M16: 17014.4 | N16: 42.34 | Q16: 2022 | R16: =J39/J$36 -> 1.1909665 | S16: =K39/K$36 -> 1.1579849 | T16: =L39/L$36 -> 1.1639053 | U16: =N39/N$36 -> 0.96542553
A17: 2000 | B17: 12261.1 | C17: 4532.59 | D17: 6657.42 | E17: 100.54 | F17: 970.54 | H17: 2000 | I17: 44320.5 | J17: 13770.49 | K17: 6129.4 | L17: 23734.2 | M17: 17073 | N17: 50.27
A18: 2001 | B18: 13155.13 | C18: 4766.82 | D18: 7207.08 | E18: 89.88 | F18: 1091.35 | H18: 2001 | I18: 47709.9 | J18: 14694.1 | K18: 6330.4 | L18: 25988.9 | M18: 20873 | N18: 43.72
A19: 2002 | B19: 14125.6 | C19: 4969.4 | D19: 7805.8 | E19: 81.8 | F19: 1268.7 | H19: 2002 | I19: 50685.9 | J19: 15658.4 | K19: 6782.5 | L19: 27510.6 | M19: 21733 | N19: 51.55 | Q19: Passenger
A20: 2003 | B20: 13810.5 | C20: 4788.61 | D20: 7695.6 | E20: 63.1 | F20: 1263.19 | H20: 2003 | I20: 53859.2 | J20: 17246.7 | K20: 7099.4756 | L20: 28715.8 | M20: 22304.77 | N20: 57.9 | S20: 2019 | T20: 2020 | U20: 2021 | V20: 2022 | W20: 2023
A21: 2004 | B21: 16309.1 | C21: 5712.2 | D21: 8748.4 | E21: 66.3 | F21: 1782.3 | H21: 2004 | I21: 69445 | J21: 19288.8 | K21: 7840.9 | L21: 41428.7 | M21: 32255 | N21: 71.8 | Q21: Railways | S21: {=TRANSPOSE(R9:R12)} -> 1 | T21: 0.56207349 | U21: 0.65057933 | V21: 0.44725021 | W21: =(1-V21)*0.85+V21 -> 0.91708753
A22: 2005 | B22: 17466.74 | C22: 6061.96 | D22: 9292.08 | E22: 67.77 | F22: 2044.93 | H22: 2005 | I22: 80258.1 | J22: 20726 | K22: 8693.2 | L22: 49672.3 | M22: 38552 | N22: 78.9 | Q22: Highways | S22: 1 | T22: =Q5/$P$5 -> 0.86997953 | U22: =R5/$P$5 -> 0.90072027 | V22: =S5/$P$5 -> 0.78830136 | W22: =T5/$P$5 -> 0.80177652
A23: 2006 | B23: 19197.211 | C23: 6622.1222 | D23: 10130.846 | E23: 73.5825 | F23: 2370.66 | H23: 2006 | I23: 88839.851 | J23: 21954.41 | K23: 9754.2476 | L23: 55485.749 | M23: 42577.3 | N23: 94.27526 | Q23: Waterways | S23: {=TRANSPOSE(T9:U12)} -> 1 | T23: 0.41134663 | U23: 0.41284289 | V23: 0.28182419 | W23: =(1-V23)*0.85+V23 -> 0.89227363
A24: 2007 | B24: 21592.581 | C24: 7216.31 | D24: 11506.767 | E24: 77.7783 | F24: 2791.7258 | H24: 2007 | I24: 101418.81 | J24: 23797 | K24: 11354.687 | L24: 64284.846 | M24: 48685.894 | N24: 116.38667 | Q24: Civial Aviation | S24: 1 | T24: 0.53919061 | U24: 0.55784914 | V24: 0.33435853 | W24: =(1-V24)*0.85+V24 -> 0.90015378
A25: 2008 | B25: 23196.698 | C25: 7778.6046 | D25: 12476.115 | E25: 59.1796 | F25: 2882.7993 | H25: 2008 | I25: 110300 | J25: 25106.282 | K25: 32868.186 | L25: 50262.704 | M25: 32851 | N25: 119.60227 | Q25: Freight
A26: 2009 | B26: 24834.942 | C26: 7878.8885 | D26: 13511.438 | E26: 69.3802 | F26: 3375.2354 | H26: 2009 | I26: 122133.31 | J26: 25239.169 | K26: 37188.821 | L26: 57556.672 | M26: 39524 | N26: 126.2307 | S26: 2019 | T26: 2020 | U26: 2021 | V26: 2022
A27: 2010 | B27: 27894.257 | C27: 8762.1783 | D27: 15020.812 | E27: 72.2701 | F27: 4038.996 | H27: 2010 | I27: 141837.42 | J27: 27644.133 | K27: 43389.672 | L27: 68427.526 | M27: 45999 | N27: 178.89816 | Q27: Railways | S27: {=TRANSPOSE(R13:U16)} -> 1 | T27: 1.0110168 | U27: 1.1012542 | V27: 1.1909665
A28: 2011 | B28: 30984.03 | C28: 9612.2936 | D28: 16760.247 | E28: 74.5285 | F28: 4536.9629 | H28: 2011 | I28: 159323.6 | J28: 29465.785 | K28: 51374.741 | L28: 75423.836 | M28: 49355 | N28: 173.91 | Q28: Highways | S28: 1 | T28: 1.0089787 | U28: 1.1584814 | V28: 1.1579849
A29: 2012 | B29: 33383.089 | C29: 9812.3272 | D29: 18467.546 | E29: 77.4791 | F29: 5025.7366 | H29: 2012 | I29: 173804.46 | J29: 29187.086 | K29: 59534.865 | L29: 81707.579 | M29: 53412.101 | N29: 163.88936 | Q29: Waterways | S29: 1 | T29: 1.0180006 | U29: 1.1117173 | V29: 1.1639053
A30: 2013 | B30: 27571.654 | C30: 10595.619 | D30: 11250.943 | E30: 68.3326 | F30: 5656.7596 | H30: 2013 | I30: 168013.8 | J30: 29173.891 | K30: 55738.077 | L30: 79435.651 | M30: 48705.368 | N30: 170.29181 | Q30: Civial Aviation | S30: 1 | T30: 0.91261398 | U30: 1.0568389 | V30: 0.96542553
A31: 2014 | B31: 28647.132 | C31: 11241.85 | D31: 10996.75 | E31: 74.341293 | F31: 6334.1903 | H31: 2014 | I31: 181667.69 | J31: 27530.19 | K31: 56846.9 | L31: 92774.556 | M31: 55935.062 | N31: 187.77149
A32: 2015 | B32: 30058.898 | C32: 11960.604 | D32: 10742.658 | E32: 73.084 | F32: 7282.5513 | H32: 2015 | I32: 178355.9 | J32: 23754.308 | K32: 57955.724 | L32: 91772.451 | M32: 54236.094 | N32: 208.0683
A33: 2016 | B33: 31258.462 | C33: 12579.293 | D33: 10228.708 | E33: 72.326542 | F33: 8378.1348 | H33: 2016 | I33: 186629.48 | J33: 23792.262 | K33: 61080.097 | L33: 97338.802 | M33: 58074.6 | N33: 222.44934
A34: 2017 | B34: 32812.8 | C34: 13456.92 | D34: 9765.1794 | E34: 77.664137 | F34: 9513.0358 | H34: 2017 | I34: 197372.65 | J34: 26962.204 | K34: 66771.516 | L34: 98611.246 | M34: 55083.857 | N34: 243.55229
A35: 2018 | B35: 34218.152 | C35: 14146.582 | D35: 9279.6786 | E35: 79.574191 | F35: 10712.317 | H35: 2018 | I35: 204686.24 | J35: 28820.986 | K35: 71249.212 | L35: 99052.815 | M35: 51926.58 | N35: 262.49911
A36: 2019 | B36: =SUM(C36:F36) -> 35349 | C36: 14706.6 | D36: 8857.1 | E36: 80.2 | F36: 11705.1 | H36: 2019 | I36: =SUM(J36:N36)-M36 -> 194044.58 | J36: 30181.95 | K36: 59636.39 | L36: 103963.04 | M36: 54057 | N36: 263.2
A37: 2020 | B37: =SUM(C37:F37) -> 19251.47 | C37: 8266.19 | D37: 4641.01 | E37: 32.99 | F37: 6311.28 | H37: 2020 | I37: =SUM(J37:N37)-M37 -> 196760.95 | J37: 30514.46 | K37: 60171.85 | L37: 105834.44 | M37: 89897 | N37: 240.2
A38: 2021 | B38: =SUM(C38:F38) -> 19758.14 | C38: 9567.81 | D38: 3627.54 | E38: 33.11 | F38: 6529.68 | H38: 2021 | I38: =SUM(J38:N38)-M38 -> 218181.32 | J38: 33238 | K38: 69087.65 | L38: 115577.51 | M38: 97842 | N38: 278.16
A39: 2022 | B39: =C39+D39+E39+F39 -> 12921.374 | C39: 6577.53 | D39: 2407.5421 | E39: 22.6023 | F39: 3913.7 | H39: 2022 | I39: =SUM(J39:N39)-M39 -> 226260.96 | J39: 35945.69 | K39: 69058.038 | L39: 121003.14 | N39: 254.1
B43: passenger | C43: from SVYbT | D43: average loading from AVLo | E43: freight | F43: from SVYbT | G43: average loading from AVLo
...

Sheet BAADTbVT-passengers
A1: Annual Distance (miles/vehicle) | B1: 2019 | C1: 2020 | D1: 2021 | E1: 2022 | F1: 2023 | G1: 2024 | H1: 2025 | I1: 2026 | J1: 2027 | K1: 2028 | L1: 2029 | M1: 2030 | N1: 2031 | O1: 2032 | P1: 2033 | Q1: 2034 | R1: 2035 | S1: 2036 | T1: 2037 | U1: 2038 | V1: 2039 | W1: 2040 | X1: 2041 | Y1: 2042 | Z1: 2043 | AA1: 2044 | AB1: 2045 | AC1: 2046 | AD1: 2047 | AE1: 2048 | AF1: 2049 | AG1: 2050 | AH1: 2051 | AI1: 2052 | AJ1: 2053 | AK1: 2054 | AL1: 2055 | AM1: 2056 | AN1: 2057 | AO1: 2058 | AP1: 2059 | AQ1: 2060
A2: LDVs | B2: ='LDVs HDVs'!B23 -> 11352.904 | C2: =$B2*'raw data'!T$22*0.98 -> 9679.2579 | D2: =$B2*'raw data'!U$22*0.98 -> 10021.275 | E2: =$B2*'raw data'!V$22 -> 8949.5094 | F2: =$B2*'raw data'!C52 -> 10084.243 | G2: =F2*0.98 -> 9882.5586 | H2: =F2*0.98 -> 9882.5586 | I2: =H2 -> 9882.5586 | J2: =I2 -> 9882.5586 | K2: =J2 -> 9882.5586 | L2: =K2 -> 9882.5586 | M2: =L2 -> 9882.5586 | N2: =M2 -> 9882.5586 | O2: =N2 -> 9882.5586 | P2: =O2 -> 9882.5586 | ... AQ2: =AP2 -> 9882.5586
A3: HDVs | B3: ='LDVs HDVs'!D23 -> 31069.409 | C3: =$B3*'raw data'!T$22 -> 27029.75 | D3: =$B3*'raw data'!U$22 -> 27984.847 | E3: =$B3*'raw data'!V$22 -> 24492.057 | F3: =$B3*'raw data'!W$22 -> 24910.723 | G3: =F3 -> 24910.723 | H3: =G3 -> 24910.723 | I3: =H3 -> 24910.723 | J3: =I3 -> 24910.723 | K3: =J3 -> 24910.723 | L3: =K3 -> 24910.723 | M3: =L3 -> 24910.723 | N3: =M3 -> 24910.723 | ... AQ3: =AP3 -> 24910.723
A4: aircraft | B4: =aircraft!E27 -> 832489.27 | C4: =aircraft!F27 -> 832466.84 | D4: =aircraft!G27 -> 830227.05 | E4: =aircraft!H27 -> 486781.19 | F4: =aircraft!I27 -> 1259470.7 | G4: =B4 -> 832489.27 | H4: =$B4 -> 832489.27 | I4: =$B4 -> 832489.27 | J4: =$B4 -> 832489.27 | K4: =$B4 -> 832489.27 | L4: =$B4 -> 832489.27 | M4: =$B4 -> 832489.27 | N4: =$B4 -> 832489.27 | O4: =$B4 -> 832489.27 | ... AQ4: =$B4 -> 832489.27
A5: rail | B5: =rail!D25 -> 16430.842 | C5: =rail!E25 -> 16430.86 | D5: =rail!F25 -> 18548.431 | E5: =rail!G25 -> 12923.217 | F5: =rail!H25 -> 28566.832 | G5: =rail!I25 -> 29512.097 | H5: =G5 -> 29512.097 | I5: =H5 -> 29512.097 | J5: =I5 -> 29512.097 | K5: =J5 -> 29512.097 | L5: =K5 -> 29512.097 | M5: =L5 -> 29512.097 | N5: =M5 -> 29512.097 | O5: =N5 -> 29512.097 | ... AQ5: =AP5 -> 29512.097
A6: ships | B6: =ships!D25 -> 48562.433 | C6: =ships!E25 -> 20718.787 | D6: =ships!F25 -> 20939.712 | E6: =ships!G25 -> 14767.468 | F6: =ships!H25 -> 36236.6 | G6: =ships!I25 -> 39545.748 | H6: =$G6 -> 39545.748 | I6: =$G6 -> 39545.748 | J6: =$G6 -> 39545.748 | K6: =$G6 -> 39545.748 | L6: =$G6 -> 39545.748 | M6: =$G6 -> 39545.748 | N6: =$G6 -> 39545.748 | O6: =$G6 -> 39545.748 | ... AQ6: =$G6 -> 39545.748
A7: motorbikes | B7: =motorbikes!$B$3 -> 3728.3291 | C7: =motorbikes!$B$3*'raw data'!T$21 -> 2095.5949 | D7: =motorbikes!$B$3*'raw data'!U$21 -> 2425.5738 | E7: =motorbikes!$B$3*'raw data'!V$21 -> 1667.496 | F7: =motorbikes!$B$3*'raw data'!W$21 -> 3419.2041 | G7: =motorbikes!$B$3 -> 3728.3291 | H7: =motorbikes!$B$3 -> 3728.3291 | I7: =motorbikes!$B$3 -> 3728.3291 | J7: =motorbikes!$B$3 -> 3728.3291 | K7: =motorbikes!$B$3 -> 3728.3291 | L7: =motorbikes!$B$3 -> 3728.3291 | M7: =motorbikes!$B$3 -> 3728.3291 | N7: =motorbikes!$B$3 -> 3728.3291 | ... AQ7: =motorbikes!$B$3 -> 3728.3291

Sheet BAADTbVT-freight
B1: 2019 | C1: 2020 | D1: 2021 | E1: 2022 | F1: 2023 | G1: 2024 | H1: 2025 | I1: 2026 | J1: 2027 | K1: 2028 | L1: 2029 | M1: 2030 | N1: 2031 | O1: 2032 | P1: 2033 | Q1: 2034 | R1: 2035 | S1: 2036 | T1: 2037 | U1: 2038 | V1: 2039 | W1: 2040 | X1: 2041 | Y1: 2042 | Z1: 2043 | AA1: 2044 | AB1: 2045 | AC1: 2046 | AD1: 2047 | AE1: 2048 | AF1: 2049 | AG1: 2050 | AH1: 2051 | AI1: 2052 | AJ1: 2053 | AK1: 2054 | AL1: 2055 | AM1: 2056 | AN1: 2057 | AO1: 2058 | AP1: 2059 | AQ1: 2060
A2: LDVs | B2: ='LDVs HDVs'!E23 -> 15534.705 | C2: =B2 -> 15534.705 | D2: =C2 -> 15534.705 | E2: =D2 -> 15534.705 | F2: =E2 -> 15534.705 | G2: =F2 -> 15534.705 | H2: =G2 -> 15534.705 | I2: =H2 -> 15534.705 | J2: =I2 -> 15534.705 | ... AQ2: =AP2 -> 15534.705
A3: HDVs | B3: ='LDVs HDVs'!F23 -> 36306.934 | C3: =B3 -> 36306.934 | D3: =B3 -> 36306.934 | E3: =B3 -> 36306.934 | F3: =B3 -> 36306.934 | G3: =B3 -> 36306.934 | H3: =G3 -> 36306.934 | I3: =H3 -> 36306.934 | J3: =I3 -> 36306.934 | K3: =J3 -> 36306.934 | L3: =K3 -> 36306.934 | M3: =L3 -> 36306.934 | N3: =M3 -> 36306.934 | O3: =N3 -> 36306.934 | ... AQ3: =AP3 -> 36306.934
A4: aircraft | B4: =aircraft!E32 -> 3203383.8 | C4: =aircraft!F32 -> 3203297.9 | D4: =aircraft!G32 -> 3484710.9 | E4: =aircraft!H32 -> 2826422.4 | F4: =aircraft!I32 -> 2737417.2 | G4: =aircraft!J32 -> 3275448.4 | H4: =$B4 -> 3203383.8 | I4: =$B4 -> 3203383.8 | J4: =$B4 -> 3203383.8 | K4: =$B4 -> 3203383.8 | L4: =$B4 -> 3203383.8 | M4: =$B4 -> 3203383.8 | N4: =$B4 -> 3203383.8 | O4: =$B4 -> 3203383.8 | ... AQ4: =$B4 -> 3203383.8
A5: rail | B5: =rail!D30 -> 522.14193 | C5: =rail!E30 -> 522.4656 | D5: =rail!F30 -> 537.80614 | E5: =rail!G30 -> 563.80717 | F5: =rail!H30 -> 566.16352 | G5: =rail!I30 -> 550.41486 | H5: =G5 -> 550.41486 | I5: =H5 -> 550.41486 | J5: =I5 -> 550.41486 | K5: =J5 -> 550.41486 | L5: =K5 -> 550.41486 | M5: =L5 -> 550.41486 | N5: =M5 -> 550.41486 | O5: =N5 -> 550.41486 | ... AQ5: =AP5 -> 550.41486
A6: ships | B6: =ships!D30 -> 22769.886 | C6: =ships!E30 -> 22769.631 | D6: =ships!F30 -> 25055.019 | E6: =ships!G30 -> 27093.981 | F6: =ships!H30 -> 29993.367 | G6: =ships!I30 -> 35035.713 | H6: =$G6 -> 35035.713 | I6: =$G6 -> 35035.713 | J6: =$G6 -> 35035.713 | K6: =$G6 -> 35035.713 | L6: =$G6 -> 35035.713 | M6: =$G6 -> 35035.713 | N6: =$G6 -> 35035.713 | O6: =$G6 -> 35035.713 | ... AQ6: =$G6 -> 35035.713
A7: motorbikes | B7: =motorbikes!B3 -> 3728.3291 | C7: =$B7 -> 3728.3291 | D7: =$B7 -> 3728.3291 | E7: =$B7 -> 3728.3291 | F7: =$B7 -> 3728.3291 | G7: =$B7 -> 3728.3291 | H7: =$B7 -> 3728.3291 | I7: =$B7 -> 3728.3291 | J7: =$B7 -> 3728.3291 | ... AQ7: =$B7 -> 3728.3291
