Workbook

Sheet About
A1: BFoHPbF BAU Frac of Heat Provided by Fuel
A3: source: | B3: BAU Frac of Heat Provided by Fuel
B4: National Bureau of Statistics
B5: 2018-2022
B6: Energy Balance Sheet
B7: 中国统计年鉴 - 国家统计局 (stats.gov.cn)
A8: note | B8: Based on the unit calorific value of the fuel “Heat conversion factor”, we convert the energy mass in the energy balance to total heat
A11: Region Selector
A12: This excel file includes data required for all Chinese provinces (excluding Taiwan, Hong Kong, Macau,
A13: and sometimes Tibet). You can use the selector below to choose which province/region you would
A14: like to calculate for:
B15: Region Selector
B16: 全国 National

Sheet Region Selector
A1: Code | B1: Name | C1: Region | D1: Region (short) | E1: Region (EN)
A2: 00 | B2: 全国 National | C2: 全国 | D2: 全国 | E2: National
A3: 11 | B3: 北京市 Beijing | C3: 北京市 | D3: 北京 | E3: Beijing
A4: 12 | B4: 天津市 Tianjin | C4: 天津市 | D4: 天津 | E4: Tianjin
A5: 13 | B5: 河北省 Hebei | C5: 河北省 | D5: 河北 | E5: Hebei
A6: 14 | B6: 山西省 Shanxi | C6: 山西省 | D6: 山西 | E6: Shanxi
A7: 15 | B7: 内蒙古自治区 Inner Mongolia | C7: 内蒙古自治区 | D7: 内蒙古 | E7: Inner Mongolia
A8: 21 | B8: 辽宁省 Liaoning | C8: 辽宁省 | D8: 辽宁 | E8: Liaoning
A9: 22 | B9: 吉林省 Jilin | C9: 吉林省 | D9: 吉林 | E9: Jilin
A10: 23 | B10: 黑龙江省 Heilongjiang | C10: 黑龙江省 | D10: 黑龙江 | E10: Heilongjiang
A11: 31 | B11: 上海市 Shanghai | C11: 上海市 | D11: 上海 | E11: Shanghai
A12: 32 | B12: 江苏省 Jiangsu | C12: 江苏省 | D12: 江苏 | E12: Jiangsu
A13: 33 | B13: 浙江省 Zhejiang | C13: 浙江省 | D13: 浙江 | E13: Zhejiang
A14: 34 | B14: 安徽省 Anhui | C14: 安徽省 | D14: 安徽 | E14: Anhui
... A33: 65 | B33: 新疆维吾尔自治区 Xijiang | C33: 新疆维吾尔自治区 | D33: 新疆 | E33: Xinjiang

Sheet  Energy Balance
A1: 索引 | B1: 地区 | C1: 年份 | D1: 项目 | E1: 能源品种 | F1: 实物量单位 | G1: 实物消费量 | H1: 折标准煤消费量 | I1: EPS Industry Fuel Type
A2: 12 | B2: 安徽省 | C2: 2022 | D2: 2.2. 供热 | E2: 柴油 | F2: 万吨 | G2: -0.12 | H2: =IFERROR(IF(ABS($G2)>0,VLOOKUP($E2,'Fuel Category and Heat Rate'!$B$1:$G$34,6,FALSE)*($G2),""),"") -> -4.8511555e+10 | I2: =IFERROR(VLOOKUP($E2,'Fuel Category and Heat Rate'!$K$2:$M$36,3,FALSE),"") -> petroleum diesel
A3: 47 | B3: 安徽省 | C3: 2022 | D3: 2.2. 供热 | E3: 电力 | F3: 亿千瓦小时 | H3: =IFERROR(IF(ABS($G3)>0,VLOOKUP($E3,'Fuel Category and Heat Rate'!$B$1:$G$34,6,FALSE)*($G3),""),"") | I3: =IFERROR(VLOOKUP($E3,'Fuel Category and Heat Rate'!$K$2:$M$36,3,FALSE),"") -> electricity
A4: 82 | B4: 安徽省 | C4: 2022 | D4: 2.2. 供热 | E4: 高炉煤气 | F4: 亿立方米 | G4: -5.24 | H4: =IFERROR(IF(ABS($G4)>0,VLOOKUP($E4,'Fuel Category and Heat Rate'!$B$1:$G$34,6,FALSE)*($G4),""),"") -> -1.8689172e+12 | I4: =IFERROR(VLOOKUP($E4,'Fuel Category and Heat Rate'!$K$2:$M$36,3,FALSE),"") -> LPG propane or butane
A5: 117 | B5: 安徽省 | C5: 2022 | D5: 2.2. 供热 | E5: 焦炉煤气 | F5: 亿立方米 | G5: -1.68 | H5: =IFERROR(IF(ABS($G5)>0,VLOOKUP($E5,'Fuel Category and Heat Rate'!$B$1:$G$34,6,FALSE)*($G5),""),"") -> -2.7632547e+12 | I5: =IFERROR(VLOOKUP($E5,'Fuel Category and Heat Rate'!$K$2:$M$36,3,FALSE),"") -> LPG propane or butane
A6: 152 | B6: 安徽省 | C6: 2022 | D6: 2.2. 供热 | E6: 焦炭 | F6: 万吨 | H6: =IFERROR(IF(ABS($G6)>0,VLOOKUP($E6,'Fuel Category and Heat Rate'!$B$1:$G$34,6,FALSE)*($G6),""),"") | I6: =IFERROR(VLOOKUP($E6,'Fuel Category and Heat Rate'!$K$2:$M$36,3,FALSE),"") -> coal
A7: 187 | B7: 安徽省 | C7: 2022 | D7: 2.2. 供热 | E7: 炼厂干气 | F7: 万吨 | G7: -1.12 | H7: =IFERROR(IF(ABS($G7)>0,VLOOKUP($E7,'Fuel Category and Heat Rate'!$B$1:$G$34,6,FALSE)*($G7),""),"") -> -4.8829415e+11 | I7: =IFERROR(VLOOKUP($E7,'Fuel Category and Heat Rate'!$K$2:$M$36,3,FALSE),"") -> LPG propane or butane
A8: 222 | B8: 安徽省 | C8: 2022 | D8: 2.2. 供热 | E8: 煤矸石 | F8: 万吨 | G8: -19.83 | H8: =IFERROR(IF(ABS($G8)>0,VLOOKUP($E8,'Fuel Category and Heat Rate'!$B$1:$G$34,6,FALSE)*($G8),""),"") -> -1.5739112e+12 | I8: =IFERROR(VLOOKUP($E8,'Fuel Category and Heat Rate'!$K$2:$M$36,3,FALSE),"") -> coal
A9: 257 | B9: 安徽省 | C9: 2022 | D9: 2.2. 供热 | E9: 煤合计 | F9: 万吨 | G9: -899.07 | H9: =IFERROR(IF(ABS($G9)>0,VLOOKUP($E9,'Fuel Category and Heat Rate'!$B$1:$G$34,6,FALSE)*($G9),""),"") -> 0 | I9: =IFERROR(VLOOKUP($E9,'Fuel Category and Heat Rate'!$K$2:$M$36,3,FALSE),"")
A10: 292 | B10: 安徽省 | C10: 2022 | D10: 2.2. 供热 | E10: 煤油 | F10: 万吨 | H10: =IFERROR(IF(ABS($G10)>0,VLOOKUP($E10,'Fuel Category and Heat Rate'!$B$1:$G$34,6,FALSE)*($G10),""),"") | I10: =IFERROR(VLOOKUP($E10,'Fuel Category and Heat Rate'!$K$2:$M$36,3,FALSE),"") -> petroleum diesel
A11: 327 | B11: 安徽省 | C11: 2022 | D11: 2.2. 供热 | E11: 其他焦化产品 | F11: 万吨 | H11: =IFERROR(IF(ABS($G11)>0,VLOOKUP($E11,'Fuel Category and Heat Rate'!$B$1:$G$34,6,FALSE)*($G11),""),"") | I11: =IFERROR(VLOOKUP($E11,'Fuel Category and Heat Rate'!$K$2:$M$36,3,FALSE),"") -> petroleum diesel
A12: 362 | B12: 安徽省 | C12: 2022 | D12: 2.2. 供热 | E12: 其他煤气 | F12: 亿立方米 | H12: =IFERROR(IF(ABS($G12)>0,VLOOKUP($E12,'Fuel Category and Heat Rate'!$B$1:$G$34,6,FALSE)*($G12),""),"") | I12: =IFERROR(VLOOKUP($E12,'Fuel Category and Heat Rate'!$K$2:$M$36,3,FALSE),"") -> LPG propane or butane
A13: 397 | B13: 安徽省 | C13: 2022 | D13: 2.2. 供热 | E13: 其他能源 | F13: 万吨标准煤 | G13: -38.37 | H13: =IFERROR(IF(ABS($G13)>0,VLOOKUP($E13,'Fuel Category and Heat Rate'!$B$1:$G$34,6,FALSE)*($G13),""),"") -> -1.0645202e+13 | I13: =IFERROR(VLOOKUP($E13,'Fuel Category and Heat Rate'!$K$2:$M$36,3,FALSE),"") -> biomass
A14: 432 | B14: 安徽省 | C14: 2022 | D14: 2.2. 供热 | E14: 其他石油制品 | F14: 万吨 | H14: =IFERROR(IF(ABS($G14)>0,VLOOKUP($E14,'Fuel Category and Heat Rate'!$B$1:$G$34,6,FALSE)*($G14),""),"") | I14: =IFERROR(VLOOKUP($E14,'Fuel Category and Heat Rate'!$K$2:$M$36,3,FALSE),"") -> heavy or residual fuel oil
A15: 467 | B15: 安徽省 | C15: 2022 | D15: 2.2. 供热 | E15: 其他洗煤 | F15: 万吨 | G15: -20.8 | H15: =IFERROR(IF(ABS($G15)>0,VLOOKUP($E15,'Fuel Category and Heat Rate'!$B$1:$G$34,6,FALSE)*($G15),""),"") -> -1.6487317e+12 | I15: =IFERROR(VLOOKUP($E15,'Fuel Category and Heat Rate'!$K$2:$M$36,3,FALSE),"") -> coal
A16: 502 | B16: 安徽省 | C16: 2022 | D16: 2.2. 供热 | E16: 汽油 | F16: 万吨 | H16: =IFERROR(IF(ABS($G16)>0,VLOOKUP($E16,'Fuel Category and Heat Rate'!$B$1:$G$34,6,FALSE)*($G16),""),"") | I16: =IFERROR(VLOOKUP($E16,'Fuel Category and Heat Rate'!$K$2:$M$36,3,FALSE),"") -> petroleum diesel
A17: 537 | B17: 安徽省 | C17: 2022 | D17: 2.2. 供热 | E17: 燃料油 | F17: 万吨 | H17: =IFERROR(IF(ABS($G17)>0,VLOOKUP($E17,'Fuel Category and Heat Rate'!$B$1:$G$34,6,FALSE)*($G17),""),"") | I17: =IFERROR(VLOOKUP($E17,'Fuel Category and Heat Rate'!$K$2:$M$36,3,FALSE),"") -> heavy or residual fuel oil
A18: 572 | B18: 安徽省 | C18: 2022 | D18: 2.2. 供热 | E18: 热力 | F18: 万百万千焦 | G18: 17230.49 | H18: =IFERROR(IF(ABS($G18)>0,VLOOKUP($E18,'Fuel Category and Heat Rate'!$B$1:$G$34,6,FALSE)*($G18),""),"") -> 1.6331353e+14 | I18: =IFERROR(VLOOKUP($E18,'Fuel Category and Heat Rate'!$K$2:$M$36,3,FALSE),"") -> heat
A19: 607 | B19: 安徽省 | C19: 2022 | D19: 2.2. 供热 | E19: 溶剂油 | F19: 万吨 | H19: =IFERROR(IF(ABS($G19)>0,VLOOKUP($E19,'Fuel Category and Heat Rate'!$B$1:$G$34,6,FALSE)*($G19),""),"") | I19: =IFERROR(VLOOKUP($E19,'Fuel Category and Heat Rate'!$K$2:$M$36,3,FALSE),"") -> heavy or residual fuel oil
A20: 642 | B20: 安徽省 | C20: 2022 | D20: 2.2. 供热 | E20: 润滑油 | F20: 万吨 | H20: =IFERROR(IF(ABS($G20)>0,VLOOKUP($E20,'Fuel Category and Heat Rate'!$B$1:$G$34,6,FALSE)*($G20),""),"") | I20: =IFERROR(VLOOKUP($E20,'Fuel Category and Heat Rate'!$K$2:$M$36,3,FALSE),"") -> LPG propane or butane
A21: 677 | B21: 安徽省 | C21: 2022 | D21: 2.2. 供热 | E21: 石蜡 | F21: 万吨 | H21: =IFERROR(IF(ABS($G21)>0,VLOOKUP($E21,'Fuel Category and Heat Rate'!$B$1:$G$34,6,FALSE)*($G21),""),"") | I21: =IFERROR(VLOOKUP($E21,'Fuel Category and Heat Rate'!$K$2:$M$36,3,FALSE),"") -> heavy fuel oil
A22: 712 | B22: 安徽省 | C22: 2022 | D22: 2.2. 供热 | E22: 石脑油 | F22: 万吨 | H22: =IFERROR(IF(ABS($G22)>0,VLOOKUP($E22,'Fuel Category and Heat Rate'!$B$1:$G$34,6,FALSE)*($G22),""),"") | I22: =IFERROR(VLOOKUP($E22,'Fuel Category and Heat Rate'!$K$2:$M$36,3,FALSE),"") -> LPG propane or butane
A23: 747 | B23: 安徽省 | C23: 2022 | D23: 2.2. 供热 | E23: 石油焦 | F23: 万吨 | H23: =IFERROR(IF(ABS($G23)>0,VLOOKUP($E23,'Fuel Category and Heat Rate'!$B$1:$G$34,6,FALSE)*($G23),""),"") | I23: =IFERROR(VLOOKUP($E23,'Fuel Category and Heat Rate'!$K$2:$M$36,3,FALSE),"") -> heavy fuel oil
A24: 782 | B24: 安徽省 | C24: 2022 | D24: 2.2. 供热 | E24: 石油沥青 | F24: 万吨 | H24: =IFERROR(IF(ABS($G24)>0,VLOOKUP($E24,'Fuel Category and Heat Rate'!$B$1:$G$34,6,FALSE)*($G24),""),"") | I24: =IFERROR(VLOOKUP($E24,'Fuel Category and Heat Rate'!$K$2:$M$36,3,FALSE),"") -> heavy fuel oil
A25: 817 | B25: 安徽省 | C25: 2022 | D25: 2.2. 供热 | E25: 天然气 | F25: 亿立方米 | G25: -0.8 | H25: =IFERROR(IF(ABS($G25)>0,VLOOKUP($E25,'Fuel Category and Heat Rate'!$B$1:$G$34,6,FALSE)*($G25),""),"") -> -2.6982079e+12 | I25: =IFERROR(VLOOKUP($E25,'Fuel Category and Heat Rate'!$K$2:$M$36,3,FALSE),"") -> natural gas
A26: 852 | B26: 安徽省 | C26: 2022 | D26: 2.2. 供热 | E26: 洗精煤 | F26: 万吨 | H26: =IFERROR(IF(ABS($G26)>0,VLOOKUP($E26,'Fuel Category and Heat Rate'!$B$1:$G$34,6,FALSE)*($G26),""),"") | I26: =IFERROR(VLOOKUP($E26,'Fuel Category and Heat Rate'!$K$2:$M$36,3,FALSE),"") -> coal
A27: 887 | B27: 安徽省 | C27: 2022 | D27: 2.2. 供热 | E27: 型煤 | F27: 万吨 | H27: =IFERROR(IF(ABS($G27)>0,VLOOKUP($E27,'Fuel Category and Heat Rate'!$B$1:$G$34,6,FALSE)*($G27),""),"") | I27: =IFERROR(VLOOKUP($E27,'Fuel Category and Heat Rate'!$K$2:$M$36,3,FALSE),"") -> coal
A28: 922 | B28: 安徽省 | C28: 2022 | D28: 2.2. 供热 | E28: 液化石油气 | F28: 万吨 | H28: =IFERROR(IF(ABS($G28)>0,VLOOKUP($E28,'Fuel Category and Heat Rate'!$B$1:$G$34,6,FALSE)*($G28),""),"") | I28: =IFERROR(VLOOKUP($E28,'Fuel Category and Heat Rate'!$K$2:$M$36,3,FALSE),"") -> LPG propane or butane
A29: 957 | B29: 安徽省 | C29: 2022 | D29: 2.2. 供热 | E29: 液化天然气 | F29: 万吨 | G29: -0.35 | H29: =IFERROR(IF(ABS($G29)>0,VLOOKUP($E29,'Fuel Category and Heat Rate'!$B$1:$G$34,6,FALSE)*($G29),""),"") -> -1.7062509e+11 | I29: =IFERROR(VLOOKUP($E29,'Fuel Category and Heat Rate'!$K$2:$M$36,3,FALSE),"") -> natural gas
A30: 992 | B30: 安徽省 | C30: 2022 | D30: 2.2. 供热 | E30: 油品合计 | F30: 万吨 | G30: -1.24 | H30: =IFERROR(IF(ABS($G30)>0,VLOOKUP($E30,'Fuel Category and Heat Rate'!$B$1:$G$34,6,FALSE)*($G30),""),"") -> 0 | I30: =IFERROR(VLOOKUP($E30,'Fuel Category and Heat Rate'!$K$2:$M$36,3,FALSE),"")
A31: 1027 | B31: 安徽省 | C31: 2022 | D31: 2.2. 供热 | E31: 原煤 | F31: 万吨 | G31: -878.27 | H31: =IFERROR(IF(ABS($G31)>0,VLOOKUP($E31,'Fuel Category and Heat Rate'!$B$1:$G$34,6,FALSE)*($G31),""),"") -> -1.7404642e+14 | I31: =IFERROR(VLOOKUP($E31,'Fuel Category and Heat Rate'!$K$2:$M$36,3,FALSE),"") -> coal
A32: 1062 | B32: 安徽省 | C32: 2022 | D32: 2.2. 供热 | E32: 原油 | F32: 万吨 | H32: =IFERROR(IF(ABS($G32)>0,VLOOKUP($E32,'Fuel Category and Heat Rate'!$B$1:$G$34,6,FALSE)*($G32),""),"") | I32: =IFERROR(VLOOKUP($E32,'Fuel Category and Heat Rate'!$K$2:$M$36,3,FALSE),"") -> crude oil
A33: 1097 | B33: 安徽省 | C33: 2022 | D33: 2.2. 供热 | E33: 转炉煤气 | F33: 亿立方米 | G33: -0.81 | H33: =IFERROR(IF(ABS($G33)>0,VLOOKUP($E33,'Fuel Category and Heat Rate'!$B$1:$G$34,6,FALSE)*($G33),""),"") -> -6.0996297e+11 | I33: =IFERROR(VLOOKUP($E33,'Fuel Category and Heat Rate'!$K$2:$M$36,3,FALSE),"") -> LPG propane or butane
A34: 1132 | B34: 安徽省 | C34: 2021 | D34: 2.2. 供热 | E34: 柴油 | F34: 万吨 | G34: -0.06 | H34: =IFERROR(IF(ABS($G34)>0,VLOOKUP($E34,'Fuel Category and Heat Rate'!$B$1:$G$34,6,FALSE)*($G34),""),"") -> -2.4255778e+10 | I34: =IFERROR(VLOOKUP($E34,'Fuel Category and Heat Rate'!$K$2:$M$36,3,FALSE),"") -> petroleum diesel
A35: 1167 | B35: 安徽省 | C35: 2021 | D35: 2.2. 供热 | E35: 电力 | F35: 亿千瓦小时 | H35: =IFERROR(IF(ABS($G35)>0,VLOOKUP($E35,'Fuel Category and Heat Rate'!$B$1:$G$34,6,FALSE)*($G35),""),"") | I35: =IFERROR(VLOOKUP($E35,'Fuel Category and Heat Rate'!$K$2:$M$36,3,FALSE),"") -> electricity
A36: 1202 | B36: 安徽省 | C36: 2021 | D36: 2.2. 供热 | E36: 高炉煤气 | F36: 亿立方米 | G36: -8.17 | H36: =IFERROR(IF(ABS($G36)>0,VLOOKUP($E36,'Fuel Category and Heat Rate'!$B$1:$G$34,6,FALSE)*($G36),""),"") -> -2.9139415e+12 | I36: =IFERROR(VLOOKUP($E36,'Fuel Category and Heat Rate'!$K$2:$M$36,3,FALSE),"") -> LPG propane or butane
A37: 1237 | B37: 安徽省 | C37: 2021 | D37: 2.2. 供热 | E37: 焦炉煤气 | F37: 亿立方米 | G37: -1.33 | H37: =IFERROR(IF(ABS($G37)>0,VLOOKUP($E37,'Fuel Category and Heat Rate'!$B$1:$G$34,6,FALSE)*($G37),""),"") -> -2.1875766e+12 | I37: =IFERROR(VLOOKUP($E37,'Fuel Category and Heat Rate'!$K$2:$M$36,3,FALSE),"") -> LPG propane or butane
A38: 1272 | B38: 安徽省 | C38: 2021 | D38: 2.2. 供热 | E38: 焦炭 | F38: 万吨 | H38: =IFERROR(IF(ABS($G38)>0,VLOOKUP($E38,'Fuel Category and Heat Rate'!$B$1:$G$34,6,FALSE)*($G38),""),"") | I38: =IFERROR(VLOOKUP($E38,'Fuel Category and Heat Rate'!$K$2:$M$36,3,FALSE),"") -> coal
A39: 1307 | B39: 安徽省 | C39: 2021 | D39: 2.2. 供热 | E39: 炼厂干气 | F39: 万吨 | G39: -0.54 | H39: =IFERROR(IF(ABS($G39)>0,VLOOKUP($E39,'Fuel Category and Heat Rate'!$B$1:$G$34,6,FALSE)*($G39),""),"") -> -2.3542754e+11 | I39: =IFERROR(VLOOKUP($E39,'Fuel Category and Heat Rate'!$K$2:$M$36,3,FALSE),"") -> LPG propane or butane
A40: 1342 | B40: 安徽省 | C40: 2021 | D40: 2.2. 供热 | E40: 煤矸石 | F40: 万吨 | G40: -29.42 | H40: =IFERROR(IF(ABS($G40)>0,VLOOKUP($E40,'Fuel Category and Heat Rate'!$B$1:$G$34,6,FALSE)*($G40),""),"") -> -2.3350715e+12 | I40: =IFERROR(VLOOKUP($E40,'Fuel Category and Heat Rate'!$K$2:$M$36,3,FALSE),"") -> coal
...

Sheet Calculation
A1: Selected Region (see about Sheet)
A2: =VLOOKUP(About!$B$16,'Region Selector'!B1:E33,2,FALSE) -> 全国
A4: 项目 | B4: 能源品种 | C4: Fuel Type | D4: 2018 | E4: 2019 | F4: 2020 | G4: 2021 | H4: 2022 | L4: 2018 | M4: 2019 | N4: 2020 | O4: 2021 | P4: 2022
A5: Fuel Intake | K5: electricity | L5: =SUMIFS(D$6:D$34,$C$6:$C$34,$K5) -> 0 | M5: =SUMIFS(E$6:E$34,$C$6:$C$34,$K5) -> 0 | N5: =SUMIFS(F$6:F$34,$C$6:$C$34,$K5) -> 0 | O5: =SUMIFS(G$6:G$34,$C$6:$C$34,$K5) -> 0 | P5: =SUMIFS(H$6:H$34,$C$6:$C$34,$K5) -> 0
A6: 2.2. 供热 | B6: 其他能源 | C6: =VLOOKUP(B6,'Fuel Category and Heat Rate'!K$3:M$36,3,FALSE) -> biomass | D6: =-SUMIFS(' Energy Balance'!$H:$H,' Energy Balance'!$B:$B,$A$2,' Energy Balance'!$C:$C,D$4,' Energy Balance'!$D:$D,$A6,' Energy Balance'!$E:$E,$B6) -> 9.786539e+13 | E6: =-SUMIFS(' Energy Balance'!$H:$H,' Energy Balance'!$B:$B,$A$2,' Energy Balance'!$C:$C,E$4,' Energy Balance'!$D:$D,$A6,' Energy Balance'!$E:$E,$B6) -> 1.0874364e+14 | F6: =-SUMIFS(' Energy Balance'!$H:$H,' Energy Balance'!$B:$B,$A$2,' Energy Balance'!$C:$C,F$4,' Energy Balance'!$D:$D,$A6,' Energy Balance'!$E:$E,$B6) -> 1.9135562e+14 | G6: =-SUMIFS(' Energy Balance'!$H:$H,' Energy Balance'!$B:$B,$A$2,' Energy Balance'!$C:$C,G$4,' Energy Balance'!$D:$D,$A6,' Energy Balance'!$E:$E,$B6) -> 2.5231376e+14 | H6: =-SUMIFS(' Energy Balance'!$H:$H,' Energy Balance'!$B:$B,$A$2,' Energy Balance'!$C:$C,H$4,' Energy Balance'!$D:$D,$A6,' Energy Balance'!$E:$E,$B6) -> 3.3088351e+14 | K6: coal | L6: =SUMIFS(D$6:D$34,$C$6:$C$34,$K6) -> 6.3332445e+15 | M6: =SUMIFS(E$6:E$34,$C$6:$C$34,$K6) -> 6.7213003e+15 | N6: =SUMIFS(F$6:F$34,$C$6:$C$34,$K6) -> 7.2768889e+15 | O6: =SUMIFS(G$6:G$34,$C$6:$C$34,$K6) -> 8.7105205e+15 | P6: =SUMIFS(H$6:H$34,$C$6:$C$34,$K6) -> 9.9335807e+15
A7: 2.2. 供热 | B7: 焦炭 | C7: =VLOOKUP(B7,'Fuel Category and Heat Rate'!K$3:M$36,3,FALSE) -> coal | D7: =-SUMIFS(' Energy Balance'!$H:$H,' Energy Balance'!$B:$B,$A$2,' Energy Balance'!$C:$C,D$4,' Energy Balance'!$D:$D,$A7,' Energy Balance'!$E:$E,$B7) -> 4.0292014e+12 | E7: =-SUMIFS(' Energy Balance'!$H:$H,' Energy Balance'!$B:$B,$A$2,' Energy Balance'!$C:$C,E$4,' Energy Balance'!$D:$D,$A7,' Energy Balance'!$E:$E,$B7) -> 1.2804506e+13 | F7: =-SUMIFS(' Energy Balance'!$H:$H,' Energy Balance'!$B:$B,$A$2,' Energy Balance'!$C:$C,F$4,' Energy Balance'!$D:$D,$A7,' Energy Balance'!$E:$E,$B7) -> 7.5538767e+13 | G7: =-SUMIFS(' Energy Balance'!$H:$H,' Energy Balance'!$B:$B,$A$2,' Energy Balance'!$C:$C,G$4,' Energy Balance'!$D:$D,$A7,' Energy Balance'!$E:$E,$B7) -> 8.9857929e+13 | H7: =-SUMIFS(' Energy Balance'!$H:$H,' Energy Balance'!$B:$B,$A$2,' Energy Balance'!$C:$C,H$4,' Energy Balance'!$D:$D,$A7,' Energy Balance'!$E:$E,$B7) -> 4.4588032e+13 | K7: natural gas | L7: =SUMIFS(D$6:D$34,$C$6:$C$34,$K7) -> 4.4693834e+14 | M7: =SUMIFS(E$6:E$34,$C$6:$C$34,$K7) -> 4.9928162e+14 | N7: =SUMIFS(F$6:F$34,$C$6:$C$34,$K7) -> 5.960027e+14 | O7: =SUMIFS(G$6:G$34,$C$6:$C$34,$K7) -> 7.0396591e+14 | P7: =SUMIFS(H$6:H$34,$C$6:$C$34,$K7) -> 7.7638621e+14
A8: 2.2. 供热 | B8: 煤矸石 | C8: =VLOOKUP(B8,'Fuel Category and Heat Rate'!K$3:M$36,3,FALSE) -> coal | D8: =-SUMIFS(' Energy Balance'!$H:$H,' Energy Balance'!$B:$B,$A$2,' Energy Balance'!$C:$C,D$4,' Energy Balance'!$D:$D,$A8,' Energy Balance'!$E:$E,$B8) -> 5.3648703e+13 | E8: =-SUMIFS(' Energy Balance'!$H:$H,' Energy Balance'!$B:$B,$A$2,' Energy Balance'!$C:$C,E$4,' Energy Balance'!$D:$D,$A8,' Energy Balance'!$E:$E,$B8) -> 5.129617e+13 | F8: =-SUMIFS(' Energy Balance'!$H:$H,' Energy Balance'!$B:$B,$A$2,' Energy Balance'!$C:$C,F$4,' Energy Balance'!$D:$D,$A8,' Energy Balance'!$E:$E,$B8) -> 6.054518e+13 | G8: =-SUMIFS(' Energy Balance'!$H:$H,' Energy Balance'!$B:$B,$A$2,' Energy Balance'!$C:$C,G$4,' Energy Balance'!$D:$D,$A8,' Energy Balance'!$E:$E,$B8) -> 6.4721641e+13 | H8: =-SUMIFS(' Energy Balance'!$H:$H,' Energy Balance'!$B:$B,$A$2,' Energy Balance'!$C:$C,H$4,' Energy Balance'!$D:$D,$A8,' Energy Balance'!$E:$E,$B8) -> 6.1595248e+13 | K8: biomass | L8: =SUMIFS(D$6:D$34,$C$6:$C$34,$K8) -> 9.786539e+13 | M8: =SUMIFS(E$6:E$34,$C$6:$C$34,$K8) -> 1.0874364e+14 | N8: =SUMIFS(F$6:F$34,$C$6:$C$34,$K8) -> 1.9135562e+14 | O8: =SUMIFS(G$6:G$34,$C$6:$C$34,$K8) -> 2.5231376e+14 | P8: =SUMIFS(H$6:H$34,$C$6:$C$34,$K8) -> 3.3088351e+14
A9: 2.2. 供热 | B9: 其他洗煤 | C9: =VLOOKUP(B9,'Fuel Category and Heat Rate'!K$3:M$36,3,FALSE) -> coal | D9: =-SUMIFS(' Energy Balance'!$H:$H,' Energy Balance'!$B:$B,$A$2,' Energy Balance'!$C:$C,D$4,' Energy Balance'!$D:$D,$A9,' Energy Balance'!$E:$E,$B9) -> 9.5169865e+13 | E9: =-SUMIFS(' Energy Balance'!$H:$H,' Energy Balance'!$B:$B,$A$2,' Energy Balance'!$C:$C,E$4,' Energy Balance'!$D:$D,$A9,' Energy Balance'!$E:$E,$B9) -> 1.1207174e+14 | F9: =-SUMIFS(' Energy Balance'!$H:$H,' Energy Balance'!$B:$B,$A$2,' Energy Balance'!$C:$C,F$4,' Energy Balance'!$D:$D,$A9,' Energy Balance'!$E:$E,$B9) -> 1.1882758e+14 | G9: =-SUMIFS(' Energy Balance'!$H:$H,' Energy Balance'!$B:$B,$A$2,' Energy Balance'!$C:$C,G$4,' Energy Balance'!$D:$D,$A9,' Energy Balance'!$E:$E,$B9) -> 1.3341172e+14 | H9: =-SUMIFS(' Energy Balance'!$H:$H,' Energy Balance'!$B:$B,$A$2,' Energy Balance'!$C:$C,H$4,' Energy Balance'!$D:$D,$A9,' Energy Balance'!$E:$E,$B9) -> 1.1901703e+14 | K9: petroleum diesel | L9: =SUMIFS(D$6:D$34,$C$6:$C$34,$K9) -> 2.1267005e+12 | M9: =SUMIFS(E$6:E$34,$C$6:$C$34,$K9) -> 2.1630049e+12 | N9: =SUMIFS(F$6:F$34,$C$6:$C$34,$K9) -> 1.1764052e+12 | O9: =SUMIFS(G$6:G$34,$C$6:$C$34,$K9) -> 1.3866219e+12 | P9: =SUMIFS(H$6:H$34,$C$6:$C$34,$K9) -> 1.3502383e+12
A10: 2.2. 供热 | B10: 洗精煤 | C10: =VLOOKUP(B10,'Fuel Category and Heat Rate'!K$3:M$36,3,FALSE) -> coal | D10: =-SUMIFS(' Energy Balance'!$H:$H,' Energy Balance'!$B:$B,$A$2,' Energy Balance'!$C:$C,D$4,' Energy Balance'!$D:$D,$A10,' Energy Balance'!$E:$E,$B10) -> 0 | E10: =-SUMIFS(' Energy Balance'!$H:$H,' Energy Balance'!$B:$B,$A$2,' Energy Balance'!$C:$C,E$4,' Energy Balance'!$D:$D,$A10,' Energy Balance'!$E:$E,$B10) -> 0 | F10: =-SUMIFS(' Energy Balance'!$H:$H,' Energy Balance'!$B:$B,$A$2,' Energy Balance'!$C:$C,F$4,' Energy Balance'!$D:$D,$A10,' Energy Balance'!$E:$E,$B10) -> 0 | G10: =-SUMIFS(' Energy Balance'!$H:$H,' Energy Balance'!$B:$B,$A$2,' Energy Balance'!$C:$C,G$4,' Energy Balance'!$D:$D,$A10,' Energy Balance'!$E:$E,$B10) -> 0 | H10: =-SUMIFS(' Energy Balance'!$H:$H,' Energy Balance'!$B:$B,$A$2,' Energy Balance'!$C:$C,H$4,' Energy Balance'!$D:$D,$A10,' Energy Balance'!$E:$E,$B10) -> 0 | K10: heat | L10: =SUMIFS(D$6:D$34,$C$6:$C$34,$K10) -> 0 | M10: =SUMIFS(E$6:E$34,$C$6:$C$34,$K10) -> 0 | N10: =SUMIFS(F$6:F$34,$C$6:$C$34,$K10) -> 0 | O10: =SUMIFS(G$6:G$34,$C$6:$C$34,$K10) -> 0 | P10: =SUMIFS(H$6:H$34,$C$6:$C$34,$K10) -> 0
A11: 2.2. 供热 | B11: 型煤 | C11: =VLOOKUP(B11,'Fuel Category and Heat Rate'!K$3:M$36,3,FALSE) -> coal | D11: =-SUMIFS(' Energy Balance'!$H:$H,' Energy Balance'!$B:$B,$A$2,' Energy Balance'!$C:$C,D$4,' Energy Balance'!$D:$D,$A11,' Energy Balance'!$E:$E,$B11) -> 0 | E11: =-SUMIFS(' Energy Balance'!$H:$H,' Energy Balance'!$B:$B,$A$2,' Energy Balance'!$C:$C,E$4,' Energy Balance'!$D:$D,$A11,' Energy Balance'!$E:$E,$B11) -> 0 | F11: =-SUMIFS(' Energy Balance'!$H:$H,' Energy Balance'!$B:$B,$A$2,' Energy Balance'!$C:$C,F$4,' Energy Balance'!$D:$D,$A11,' Energy Balance'!$E:$E,$B11) -> 0 | G11: =-SUMIFS(' Energy Balance'!$H:$H,' Energy Balance'!$B:$B,$A$2,' Energy Balance'!$C:$C,G$4,' Energy Balance'!$D:$D,$A11,' Energy Balance'!$E:$E,$B11) -> 0 | H11: =-SUMIFS(' Energy Balance'!$H:$H,' Energy Balance'!$B:$B,$A$2,' Energy Balance'!$C:$C,H$4,' Energy Balance'!$D:$D,$A11,' Energy Balance'!$E:$E,$B11) -> 0 | K11: crude oil | L11: =SUMIFS(D$6:D$34,$C$6:$C$34,$K11) -> 0 | M11: =SUMIFS(E$6:E$34,$C$6:$C$34,$K11) -> 0 | N11: =SUMIFS(F$6:F$34,$C$6:$C$34,$K11) -> 0 | O11: =SUMIFS(G$6:G$34,$C$6:$C$34,$K11) -> 0 | P11: =SUMIFS(H$6:H$34,$C$6:$C$34,$K11) -> 0
A12: 2.2. 供热 | B12: 原煤 | C12: =VLOOKUP(B12,'Fuel Category and Heat Rate'!K$3:M$36,3,FALSE) -> coal | D12: =-SUMIFS(' Energy Balance'!$H:$H,' Energy Balance'!$B:$B,$A$2,' Energy Balance'!$C:$C,D$4,' Energy Balance'!$D:$D,$A12,' Energy Balance'!$E:$E,$B12) -> 6.1803967e+15 | E12: =-SUMIFS(' Energy Balance'!$H:$H,' Energy Balance'!$B:$B,$A$2,' Energy Balance'!$C:$C,E$4,' Energy Balance'!$D:$D,$A12,' Energy Balance'!$E:$E,$B12) -> 6.5451278e+15 | F12: =-SUMIFS(' Energy Balance'!$H:$H,' Energy Balance'!$B:$B,$A$2,' Energy Balance'!$C:$C,F$4,' Energy Balance'!$D:$D,$A12,' Energy Balance'!$E:$E,$B12) -> 7.0219774e+15 | G12: =-SUMIFS(' Energy Balance'!$H:$H,' Energy Balance'!$B:$B,$A$2,' Energy Balance'!$C:$C,G$4,' Energy Balance'!$D:$D,$A12,' Energy Balance'!$E:$E,$B12) -> 8.4225292e+15 | H12: =-SUMIFS(' Energy Balance'!$H:$H,' Energy Balance'!$B:$B,$A$2,' Energy Balance'!$C:$C,H$4,' Energy Balance'!$D:$D,$A12,' Energy Balance'!$E:$E,$B12) -> 9.7083804e+15 | K12: heavy or residual fuel oil | L12: =SUMIFS(D$6:D$34,$C$6:$C$34,$K12) -> 2.9198908e+13 | M12: =SUMIFS(E$6:E$34,$C$6:$C$34,$K12) -> 3.2758298e+13 | N12: =SUMIFS(F$6:F$34,$C$6:$C$34,$K12) -> 9.7123362e+13 | O12: =SUMIFS(G$6:G$34,$C$6:$C$34,$K12) -> 1.026764e+14 | P12: =SUMIFS(H$6:H$34,$C$6:$C$34,$K12) -> 1.0112148e+14
A13: 2.2. 供热 | B13: 原油 | C13: =VLOOKUP(B13,'Fuel Category and Heat Rate'!K$3:M$36,3,FALSE) -> crude oil | D13: =-SUMIFS(' Energy Balance'!$H:$H,' Energy Balance'!$B:$B,$A$2,' Energy Balance'!$C:$C,D$4,' Energy Balance'!$D:$D,$A13,' Energy Balance'!$E:$E,$B13) -> 0 | E13: =-SUMIFS(' Energy Balance'!$H:$H,' Energy Balance'!$B:$B,$A$2,' Energy Balance'!$C:$C,E$4,' Energy Balance'!$D:$D,$A13,' Energy Balance'!$E:$E,$B13) -> 0 | F13: =-SUMIFS(' Energy Balance'!$H:$H,' Energy Balance'!$B:$B,$A$2,' Energy Balance'!$C:$C,F$4,' Energy Balance'!$D:$D,$A13,' Energy Balance'!$E:$E,$B13) -> 0 | G13: =-SUMIFS(' Energy Balance'!$H:$H,' Energy Balance'!$B:$B,$A$2,' Energy Balance'!$C:$C,G$4,' Energy Balance'!$D:$D,$A13,' Energy Balance'!$E:$E,$B13) -> 0 | H13: =-SUMIFS(' Energy Balance'!$H:$H,' Energy Balance'!$B:$B,$A$2,' Energy Balance'!$C:$C,H$4,' Energy Balance'!$D:$D,$A13,' Energy Balance'!$E:$E,$B13) -> 0 | K13: LPG propane or butane | L13: =SUMIFS(D$6:D$34,$C$6:$C$34,$K13) -> 4.4702709e+14 | M13: =SUMIFS(E$6:E$34,$C$6:$C$34,$K13) -> 4.8791004e+14 | N13: =SUMIFS(F$6:F$34,$C$6:$C$34,$K13) -> 3.8590005e+14 | O13: =SUMIFS(G$6:G$34,$C$6:$C$34,$K13) -> 3.6837429e+14 | P13: =SUMIFS(H$6:H$34,$C$6:$C$34,$K13) -> 3.9351435e+14
A14: 2.2. 供热 | B14: 电力 | C14: =VLOOKUP(B14,'Fuel Category and Heat Rate'!K$3:M$36,3,FALSE) -> electricity | D14: =-SUMIFS(' Energy Balance'!$H:$H,' Energy Balance'!$B:$B,$A$2,' Energy Balance'!$C:$C,D$4,' Energy Balance'!$D:$D,$A14,' Energy Balance'!$E:$E,$B14) -> 0 | E14: =-SUMIFS(' Energy Balance'!$H:$H,' Energy Balance'!$B:$B,$A$2,' Energy Balance'!$C:$C,E$4,' Energy Balance'!$D:$D,$A14,' Energy Balance'!$E:$E,$B14) -> 0 | F14: =-SUMIFS(' Energy Balance'!$H:$H,' Energy Balance'!$B:$B,$A$2,' Energy Balance'!$C:$C,F$4,' Energy Balance'!$D:$D,$A14,' Energy Balance'!$E:$E,$B14) -> 0 | G14: =-SUMIFS(' Energy Balance'!$H:$H,' Energy Balance'!$B:$B,$A$2,' Energy Balance'!$C:$C,G$4,' Energy Balance'!$D:$D,$A14,' Energy Balance'!$E:$E,$B14) -> 0 | H14: =-SUMIFS(' Energy Balance'!$H:$H,' Energy Balance'!$B:$B,$A$2,' Energy Balance'!$C:$C,H$4,' Energy Balance'!$D:$D,$A14,' Energy Balance'!$E:$E,$B14) -> 0 | K14: hydrogen | L14: =SUMIFS(D$6:D$34,$C$6:$C$34,$K14) -> 0 | M14: =SUMIFS(E$6:E$34,$C$6:$C$34,$K14) -> 0 | N14: =SUMIFS(F$6:F$34,$C$6:$C$34,$K14) -> 0 | O14: =SUMIFS(G$6:G$34,$C$6:$C$34,$K14) -> 0 | P14: =SUMIFS(H$6:H$34,$C$6:$C$34,$K14) -> 0
A15: 2.2. 供热 | B15: 其他石油制品 | C15: =VLOOKUP(B15,'Fuel Category and Heat Rate'!K$3:M$36,3,FALSE) -> heavy or residual fuel oil | D15: =-SUMIFS(' Energy Balance'!$H:$H,' Energy Balance'!$B:$B,$A$2,' Energy Balance'!$C:$C,D$4,' Energy Balance'!$D:$D,$A15,' Energy Balance'!$E:$E,$B15) -> 5.604835e+12 | E15: =-SUMIFS(' Energy Balance'!$H:$H,' Energy Balance'!$B:$B,$A$2,' Energy Balance'!$C:$C,E$4,' Energy Balance'!$D:$D,$A15,' Energy Balance'!$E:$E,$B15) -> 8.894714e+12 | F15: =-SUMIFS(' Energy Balance'!$H:$H,' Energy Balance'!$B:$B,$A$2,' Energy Balance'!$C:$C,F$4,' Energy Balance'!$D:$D,$A15,' Energy Balance'!$E:$E,$B15) -> 5.4183956e+12 | G15: =-SUMIFS(' Energy Balance'!$H:$H,' Energy Balance'!$B:$B,$A$2,' Energy Balance'!$C:$C,G$4,' Energy Balance'!$D:$D,$A15,' Energy Balance'!$E:$E,$B15) -> 5.9854822e+12 | H15: =-SUMIFS(' Energy Balance'!$H:$H,' Energy Balance'!$B:$B,$A$2,' Energy Balance'!$C:$C,H$4,' Energy Balance'!$D:$D,$A15,' Energy Balance'!$E:$E,$B15) -> 6.2418364e+12
A16: 2.2. 供热 | B16: 燃料油 | C16: =VLOOKUP(B16,'Fuel Category and Heat Rate'!K$3:M$36,3,FALSE) -> heavy or residual fuel oil | D16: =-SUMIFS(' Energy Balance'!$H:$H,' Energy Balance'!$B:$B,$A$2,' Energy Balance'!$C:$C,D$4,' Energy Balance'!$D:$D,$A16,' Energy Balance'!$E:$E,$B16) -> 2.3594073e+13 | E16: =-SUMIFS(' Energy Balance'!$H:$H,' Energy Balance'!$B:$B,$A$2,' Energy Balance'!$C:$C,E$4,' Energy Balance'!$D:$D,$A16,' Energy Balance'!$E:$E,$B16) -> 2.3863584e+13 | F16: =-SUMIFS(' Energy Balance'!$H:$H,' Energy Balance'!$B:$B,$A$2,' Energy Balance'!$C:$C,F$4,' Energy Balance'!$D:$D,$A16,' Energy Balance'!$E:$E,$B16) -> 9.1704966e+13 | G16: =-SUMIFS(' Energy Balance'!$H:$H,' Energy Balance'!$B:$B,$A$2,' Energy Balance'!$C:$C,G$4,' Energy Balance'!$D:$D,$A16,' Energy Balance'!$E:$E,$B16) -> 9.6690913e+13 | H16: =-SUMIFS(' Energy Balance'!$H:$H,' Energy Balance'!$B:$B,$A$2,' Energy Balance'!$C:$C,H$4,' Energy Balance'!$D:$D,$A16,' Energy Balance'!$E:$E,$B16) -> 9.4879643e+13 | K16: Share of heat generation pathway | L16: 2018 | M16: 2019 | N16: 2020 | O16: 2021 | P16: 2022
A17: 2.2. 供热 | B17: 溶剂油 | C17: =VLOOKUP(B17,'Fuel Category and Heat Rate'!K$3:M$36,3,FALSE) -> heavy or residual fuel oil | D17: =-SUMIFS(' Energy Balance'!$H:$H,' Energy Balance'!$B:$B,$A$2,' Energy Balance'!$C:$C,D$4,' Energy Balance'!$D:$D,$A17,' Energy Balance'!$E:$E,$B17) -> 0 | E17: =-SUMIFS(' Energy Balance'!$H:$H,' Energy Balance'!$B:$B,$A$2,' Energy Balance'!$C:$C,E$4,' Energy Balance'!$D:$D,$A17,' Energy Balance'!$E:$E,$B17) -> 0 | F17: =-SUMIFS(' Energy Balance'!$H:$H,' Energy Balance'!$B:$B,$A$2,' Energy Balance'!$C:$C,F$4,' Energy Balance'!$D:$D,$A17,' Energy Balance'!$E:$E,$B17) -> 0 | G17: =-SUMIFS(' Energy Balance'!$H:$H,' Energy Balance'!$B:$B,$A$2,' Energy Balance'!$C:$C,G$4,' Energy Balance'!$D:$D,$A17,' Energy Balance'!$E:$E,$B17) -> 0 | H17: =-SUMIFS(' Energy Balance'!$H:$H,' Energy Balance'!$B:$B,$A$2,' Energy Balance'!$C:$C,H$4,' Energy Balance'!$D:$D,$A17,' Energy Balance'!$E:$E,$B17) -> 0 | K17: electricity | L17: =L5/SUM(L$5:L$14) -> 0 | M17: =M5/SUM(M$5:M$14) -> 0 | N17: =N5/SUM(N$5:N$14) -> 0 | O17: =O5/SUM(O$5:O$14) -> 0 | P17: =P5/SUM(P$5:P$14) -> 0
A18: 2.2. 供热 | B18: 石蜡 | C18: =VLOOKUP(B18,'Fuel Category and Heat Rate'!K$3:M$36,3,FALSE) -> heavy fuel oil | D18: =-SUMIFS(' Energy Balance'!$H:$H,' Energy Balance'!$B:$B,$A$2,' Energy Balance'!$C:$C,D$4,' Energy Balance'!$D:$D,$A18,' Energy Balance'!$E:$E,$B18) -> 0 | E18: =-SUMIFS(' Energy Balance'!$H:$H,' Energy Balance'!$B:$B,$A$2,' Energy Balance'!$C:$C,E$4,' Energy Balance'!$D:$D,$A18,' Energy Balance'!$E:$E,$B18) -> 0 | F18: =-SUMIFS(' Energy Balance'!$H:$H,' Energy Balance'!$B:$B,$A$2,' Energy Balance'!$C:$C,F$4,' Energy Balance'!$D:$D,$A18,' Energy Balance'!$E:$E,$B18) -> 0 | G18: =-SUMIFS(' Energy Balance'!$H:$H,' Energy Balance'!$B:$B,$A$2,' Energy Balance'!$C:$C,G$4,' Energy Balance'!$D:$D,$A18,' Energy Balance'!$E:$E,$B18) -> 0 | H18: =-SUMIFS(' Energy Balance'!$H:$H,' Energy Balance'!$B:$B,$A$2,' Energy Balance'!$C:$C,H$4,' Energy Balance'!$D:$D,$A18,' Energy Balance'!$E:$E,$B18) -> 0 | K18: coal | L18: =L6/SUM(L$5:L$14) -> 0.86091617 | M18: =M6/SUM(M$5:M$14) -> 0.85598141 | N18: =N6/SUM(N$5:N$14) -> 0.85125273 | O18: =O6/SUM(O$5:O$14) -> 0.85909029 | P18: =P6/SUM(P$5:P$14) -> 0.86103159
A19: 2.2. 供热 | B19: 石油焦 | C19: =VLOOKUP(B19,'Fuel Category and Heat Rate'!K$3:M$36,3,FALSE) -> heavy fuel oil | D19: =-SUMIFS(' Energy Balance'!$H:$H,' Energy Balance'!$B:$B,$A$2,' Energy Balance'!$C:$C,D$4,' Energy Balance'!$D:$D,$A19,' Energy Balance'!$E:$E,$B19) -> 6.0247944e+13 | E19: =-SUMIFS(' Energy Balance'!$H:$H,' Energy Balance'!$B:$B,$A$2,' Energy Balance'!$C:$C,E$4,' Energy Balance'!$D:$D,$A19,' Energy Balance'!$E:$E,$B19) -> 6.788151e+13 | F19: =-SUMIFS(' Energy Balance'!$H:$H,' Energy Balance'!$B:$B,$A$2,' Energy Balance'!$C:$C,F$4,' Energy Balance'!$D:$D,$A19,' Energy Balance'!$E:$E,$B19) -> 7.7683118e+13 | G19: =-SUMIFS(' Energy Balance'!$H:$H,' Energy Balance'!$B:$B,$A$2,' Energy Balance'!$C:$C,G$4,' Energy Balance'!$D:$D,$A19,' Energy Balance'!$E:$E,$B19) -> 6.5440949e+13 | H19: =-SUMIFS(' Energy Balance'!$H:$H,' Energy Balance'!$B:$B,$A$2,' Energy Balance'!$C:$C,H$4,' Energy Balance'!$D:$D,$A19,' Energy Balance'!$E:$E,$B19) -> 6.4523468e+13 | K19: natural gas | L19: =L7/SUM(L$5:L$14) -> 0.060755028 | M19: =M7/SUM(M$5:M$14) -> 0.063585283 | N19: =N7/SUM(N$5:N$14) -> 0.069720581 | O19: =O7/SUM(O$5:O$14) -> 0.069429867 | P19: =P7/SUM(P$5:P$14) -> 0.067296283
A20: 2.2. 供热 | B20: 石油沥青 | C20: =VLOOKUP(B20,'Fuel Category and Heat Rate'!K$3:M$36,3,FALSE) -> heavy fuel oil | D20: =-SUMIFS(' Energy Balance'!$H:$H,' Energy Balance'!$B:$B,$A$2,' Energy Balance'!$C:$C,D$4,' Energy Balance'!$D:$D,$A20,' Energy Balance'!$E:$E,$B20) -> 0 | E20: =-SUMIFS(' Energy Balance'!$H:$H,' Energy Balance'!$B:$B,$A$2,' Energy Balance'!$C:$C,E$4,' Energy Balance'!$D:$D,$A20,' Energy Balance'!$E:$E,$B20) -> 0 | F20: =-SUMIFS(' Energy Balance'!$H:$H,' Energy Balance'!$B:$B,$A$2,' Energy Balance'!$C:$C,F$4,' Energy Balance'!$D:$D,$A20,' Energy Balance'!$E:$E,$B20) -> 0 | G20: =-SUMIFS(' Energy Balance'!$H:$H,' Energy Balance'!$B:$B,$A$2,' Energy Balance'!$C:$C,G$4,' Energy Balance'!$D:$D,$A20,' Energy Balance'!$E:$E,$B20) -> 0 | H20: =-SUMIFS(' Energy Balance'!$H:$H,' Energy Balance'!$B:$B,$A$2,' Energy Balance'!$C:$C,H$4,' Energy Balance'!$D:$D,$A20,' Energy Balance'!$E:$E,$B20) -> 0 | K20: biomass | L20: =L8/SUM(L$5:L$14) -> 0.013303434 | M20: =M8/SUM(M$5:M$14) -> 0.013848888 | N20: =N8/SUM(N$5:N$14) -> 0.02238484 | O20: =O8/SUM(O$5:O$14) -> 0.024884885 | P20: =P8/SUM(P$5:P$14) -> 0.02868061
A21: 2.2. 供热 | B21: 高炉煤气 | C21: =VLOOKUP(B21,'Fuel Category and Heat Rate'!K$3:M$36,3,FALSE) -> LPG propane or butane | D21: =-SUMIFS(' Energy Balance'!$H:$H,' Energy Balance'!$B:$B,$A$2,' Energy Balance'!$C:$C,D$4,' Energy Balance'!$D:$D,$A21,' Energy Balance'!$E:$E,$B21) -> 2.0921172e+14 | E21: =-SUMIFS(' Energy Balance'!$H:$H,' Energy Balance'!$B:$B,$A$2,' Energy Balance'!$C:$C,E$4,' Energy Balance'!$D:$D,$A21,' Energy Balance'!$E:$E,$B21) -> 2.0451447e+14 | F21: =-SUMIFS(' Energy Balance'!$H:$H,' Energy Balance'!$B:$B,$A$2,' Energy Balance'!$C:$C,F$4,' Energy Balance'!$D:$D,$A21,' Energy Balance'!$E:$E,$B21) -> 1.7834962e+14 | G21: =-SUMIFS(' Energy Balance'!$H:$H,' Energy Balance'!$B:$B,$A$2,' Energy Balance'!$C:$C,G$4,' Energy Balance'!$D:$D,$A21,' Energy Balance'!$E:$E,$B21) -> 1.581696e+14 | H21: =-SUMIFS(' Energy Balance'!$H:$H,' Energy Balance'!$B:$B,$A$2,' Energy Balance'!$C:$C,H$4,' Energy Balance'!$D:$D,$A21,' Energy Balance'!$E:$E,$B21) -> 1.3597086e+14 | K21: petroleum diesel | L21: =L9/SUM(L$5:L$14) -> 0.00028909524 | M21: =M9/SUM(M$5:M$14) -> 0.00027546634 | N21: =N9/SUM(N$5:N$14) -> 0.00013761625 | O21: =O9/SUM(O$5:O$14) -> 0.00013675801 | P21: =P9/SUM(P$5:P$14) -> 0.00011703713
A22: 2.2. 供热 | B22: 焦炉煤气 | C22: =VLOOKUP(B22,'Fuel Category and Heat Rate'!K$3:M$36,3,FALSE) -> LPG propane or butane | D22: =-SUMIFS(' Energy Balance'!$H:$H,' Energy Balance'!$B:$B,$A$2,' Energy Balance'!$C:$C,D$4,' Energy Balance'!$D:$D,$A22,' Energy Balance'!$E:$E,$B22) -> 7.3176905e+13 | E22: =-SUMIFS(' Energy Balance'!$H:$H,' Energy Balance'!$B:$B,$A$2,' Energy Balance'!$C:$C,E$4,' Energy Balance'!$D:$D,$A22,' Energy Balance'!$E:$E,$B22) -> 1.0286544e+14 | F22: =-SUMIFS(' Energy Balance'!$H:$H,' Energy Balance'!$B:$B,$A$2,' Energy Balance'!$C:$C,F$4,' Energy Balance'!$D:$D,$A22,' Energy Balance'!$E:$E,$B22) -> 9.4032898e+13 | G22: =-SUMIFS(' Energy Balance'!$H:$H,' Energy Balance'!$B:$B,$A$2,' Energy Balance'!$C:$C,G$4,' Energy Balance'!$D:$D,$A22,' Energy Balance'!$E:$E,$B22) -> 8.3572006e+13 | H22: =-SUMIFS(' Energy Balance'!$H:$H,' Energy Balance'!$B:$B,$A$2,' Energy Balance'!$C:$C,H$4,' Energy Balance'!$D:$D,$A22,' Energy Balance'!$E:$E,$B22) -> 1.1748767e+14 | K22: heat | L22: =L10/SUM(L$5:L$14) -> 0 | M22: =M10/SUM(M$5:M$14) -> 0 | N22: =N10/SUM(N$5:N$14) -> 0 | O22: =O10/SUM(O$5:O$14) -> 0 | P22: =P10/SUM(P$5:P$14) -> 0
A23: 2.2. 供热 | B23: 炼厂干气 | C23: =VLOOKUP(B23,'Fuel Category and Heat Rate'!K$3:M$36,3,FALSE) -> LPG propane or butane | D23: =-SUMIFS(' Energy Balance'!$H:$H,' Energy Balance'!$B:$B,$A$2,' Energy Balance'!$C:$C,D$4,' Energy Balance'!$D:$D,$A23,' Energy Balance'!$E:$E,$B23) -> 7.4386382e+13 | E23: =-SUMIFS(' Energy Balance'!$H:$H,' Energy Balance'!$B:$B,$A$2,' Energy Balance'!$C:$C,E$4,' Energy Balance'!$D:$D,$A23,' Energy Balance'!$E:$E,$B23) -> 7.5855624e+13 | F23: =-SUMIFS(' Energy Balance'!$H:$H,' Energy Balance'!$B:$B,$A$2,' Energy Balance'!$C:$C,F$4,' Energy Balance'!$D:$D,$A23,' Energy Balance'!$E:$E,$B23) -> 7.2023387e+13 | G23: =-SUMIFS(' Energy Balance'!$H:$H,' Energy Balance'!$B:$B,$A$2,' Energy Balance'!$C:$C,G$4,' Energy Balance'!$D:$D,$A23,' Energy Balance'!$E:$E,$B23) -> 8.2674303e+13 | H23: =-SUMIFS(' Energy Balance'!$H:$H,' Energy Balance'!$B:$B,$A$2,' Energy Balance'!$C:$C,H$4,' Energy Balance'!$D:$D,$A23,' Energy Balance'!$E:$E,$B23) -> 8.08432e+13 | K23: crude oil | L23: =L11/SUM(L$5:L$14) -> 0 | M23: =M11/SUM(M$5:M$14) -> 0 | N23: =N11/SUM(N$5:N$14) -> 0 | O23: =O11/SUM(O$5:O$14) -> 0 | P23: =P11/SUM(P$5:P$14) -> 0
A24: 2.2. 供热 | B24: 其他煤气 | C24: =VLOOKUP(B24,'Fuel Category and Heat Rate'!K$3:M$36,3,FALSE) -> LPG propane or butane | D24: =-SUMIFS(' Energy Balance'!$H:$H,' Energy Balance'!$B:$B,$A$2,' Energy Balance'!$C:$C,D$4,' Energy Balance'!$D:$D,$A24,' Energy Balance'!$E:$E,$B24) -> 9.9084802e+09 | E24: =-SUMIFS(' Energy Balance'!$H:$H,' Energy Balance'!$B:$B,$A$2,' Energy Balance'!$C:$C,E$4,' Energy Balance'!$D:$D,$A24,' Energy Balance'!$E:$E,$B24) -> 5.9450881e+11 | F24: =-SUMIFS(' Energy Balance'!$H:$H,' Energy Balance'!$B:$B,$A$2,' Energy Balance'!$C:$C,F$4,' Energy Balance'!$D:$D,$A24,' Energy Balance'!$E:$E,$B24) -> 7.9267842e+11 | G24: =-SUMIFS(' Energy Balance'!$H:$H,' Energy Balance'!$B:$B,$A$2,' Energy Balance'!$C:$C,G$4,' Energy Balance'!$D:$D,$A24,' Energy Balance'!$E:$E,$B24) -> 3.631458e+12 | H24: =-SUMIFS(' Energy Balance'!$H:$H,' Energy Balance'!$B:$B,$A$2,' Energy Balance'!$C:$C,H$4,' Energy Balance'!$D:$D,$A24,' Energy Balance'!$E:$E,$B24) -> 3.9881633e+12 | K24: heavy or residual fuel oil | L24: =L12/SUM(L$5:L$14) -> 0.0039691839 | M24: =M12/SUM(M$5:M$14) -> 0.0041718853 | N24: =N12/SUM(N$5:N$14) -> 0.011361521 | O24: =O12/SUM(O$5:O$14) -> 0.010126639 | P24: =P12/SUM(P$5:P$14) -> 0.008765096
A25: 2.2. 供热 | B25: 润滑油 | C25: =VLOOKUP(B25,'Fuel Category and Heat Rate'!K$3:M$36,3,FALSE) -> LPG propane or butane | D25: =-SUMIFS(' Energy Balance'!$H:$H,' Energy Balance'!$B:$B,$A$2,' Energy Balance'!$C:$C,D$4,' Energy Balance'!$D:$D,$A25,' Energy Balance'!$E:$E,$B25) -> 0 | E25: =-SUMIFS(' Energy Balance'!$H:$H,' Energy Balance'!$B:$B,$A$2,' Energy Balance'!$C:$C,E$4,' Energy Balance'!$D:$D,$A25,' Energy Balance'!$E:$E,$B25) -> 0 | F25: =-SUMIFS(' Energy Balance'!$H:$H,' Energy Balance'!$B:$B,$A$2,' Energy Balance'!$C:$C,F$4,' Energy Balance'!$D:$D,$A25,' Energy Balance'!$E:$E,$B25) -> 0 | G25: =-SUMIFS(' Energy Balance'!$H:$H,' Energy Balance'!$B:$B,$A$2,' Energy Balance'!$C:$C,G$4,' Energy Balance'!$D:$D,$A25,' Energy Balance'!$E:$E,$B25) -> 0 | H25: =-SUMIFS(' Energy Balance'!$H:$H,' Energy Balance'!$B:$B,$A$2,' Energy Balance'!$C:$C,H$4,' Energy Balance'!$D:$D,$A25,' Energy Balance'!$E:$E,$B25) -> 0 | K25: LPG propane or butane | L25: =L13/SUM(L$5:L$14) -> 0.060767093 | M25: =M13/SUM(M$5:M$14) -> 0.062137072 | N25: =N13/SUM(N$5:N$14) -> 0.045142708 | O25: =O13/SUM(O$5:O$14) -> 0.036331557 | P25: =P13/SUM(P$5:P$14) -> 0.034109381
A26: 2.2. 供热 | B26: 石脑油 | C26: =VLOOKUP(B26,'Fuel Category and Heat Rate'!K$3:M$36,3,FALSE) -> LPG propane or butane | D26: =-SUMIFS(' Energy Balance'!$H:$H,' Energy Balance'!$B:$B,$A$2,' Energy Balance'!$C:$C,D$4,' Energy Balance'!$D:$D,$A26,' Energy Balance'!$E:$E,$B26) -> 5.7246703e+13 | E26: =-SUMIFS(' Energy Balance'!$H:$H,' Energy Balance'!$B:$B,$A$2,' Energy Balance'!$C:$C,E$4,' Energy Balance'!$D:$D,$A26,' Energy Balance'!$E:$E,$B26) -> 6.787538e+13 | F26: =-SUMIFS(' Energy Balance'!$H:$H,' Energy Balance'!$B:$B,$A$2,' Energy Balance'!$C:$C,F$4,' Energy Balance'!$D:$D,$A26,' Energy Balance'!$E:$E,$B26) -> 0 | G26: =-SUMIFS(' Energy Balance'!$H:$H,' Energy Balance'!$B:$B,$A$2,' Energy Balance'!$C:$C,G$4,' Energy Balance'!$D:$D,$A26,' Energy Balance'!$E:$E,$B26) -> 0 | H26: =-SUMIFS(' Energy Balance'!$H:$H,' Energy Balance'!$B:$B,$A$2,' Energy Balance'!$C:$C,H$4,' Energy Balance'!$D:$D,$A26,' Energy Balance'!$E:$E,$B26) -> 0 | K26: hydrogen | L26: =L14/SUM(L$5:L$14) -> 0 | M26: =M14/SUM(M$5:M$14) -> 0 | N26: =N14/SUM(N$5:N$14) -> 0 | O26: =O14/SUM(O$5:O$14) -> 0 | P26: =P14/SUM(P$5:P$14) -> 0
A27: 2.2. 供热 | B27: 液化石油气 | C27: =VLOOKUP(B27,'Fuel Category and Heat Rate'!K$3:M$36,3,FALSE) -> LPG propane or butane | D27: =-SUMIFS(' Energy Balance'!$H:$H,' Energy Balance'!$B:$B,$A$2,' Energy Balance'!$C:$C,D$4,' Energy Balance'!$D:$D,$A27,' Energy Balance'!$E:$E,$B27) -> 1.8120556e+12 | E27: =-SUMIFS(' Energy Balance'!$H:$H,' Energy Balance'!$B:$B,$A$2,' Energy Balance'!$C:$C,E$4,' Energy Balance'!$D:$D,$A27,' Energy Balance'!$E:$E,$B27) -> 1.9262009e+12 | F27: =-SUMIFS(' Energy Balance'!$H:$H,' Energy Balance'!$B:$B,$A$2,' Energy Balance'!$C:$C,F$4,' Energy Balance'!$D:$D,$A27,' Energy Balance'!$E:$E,$B27) -> 3.6669157e+12 | G27: =-SUMIFS(' Energy Balance'!$H:$H,' Energy Balance'!$B:$B,$A$2,' Energy Balance'!$C:$C,G$4,' Energy Balance'!$D:$D,$A27,' Energy Balance'!$E:$E,$B27) -> 4.3089827e+12 | H27: =-SUMIFS(' Energy Balance'!$H:$H,' Energy Balance'!$B:$B,$A$2,' Energy Balance'!$C:$C,H$4,' Energy Balance'!$D:$D,$A27,' Energy Balance'!$E:$E,$B27) -> 1.91764e+13
A28: 2.2. 供热 | B28: 转炉煤气 | C28: =VLOOKUP(B28,'Fuel Category and Heat Rate'!K$3:M$36,3,FALSE) -> LPG propane or butane | D28: =-SUMIFS(' Energy Balance'!$H:$H,' Energy Balance'!$B:$B,$A$2,' Energy Balance'!$C:$C,D$4,' Energy Balance'!$D:$D,$A28,' Energy Balance'!$E:$E,$B28) -> 3.1183416e+13 | E28: =-SUMIFS(' Energy Balance'!$H:$H,' Energy Balance'!$B:$B,$A$2,' Energy Balance'!$C:$C,E$4,' Energy Balance'!$D:$D,$A28,' Energy Balance'!$E:$E,$B28) -> 3.4278413e+13 | F28: =-SUMIFS(' Energy Balance'!$H:$H,' Energy Balance'!$B:$B,$A$2,' Energy Balance'!$C:$C,F$4,' Energy Balance'!$D:$D,$A28,' Energy Balance'!$E:$E,$B28) -> 3.7034542e+13 | G28: =-SUMIFS(' Energy Balance'!$H:$H,' Energy Balance'!$B:$B,$A$2,' Energy Balance'!$C:$C,G$4,' Energy Balance'!$D:$D,$A28,' Energy Balance'!$E:$E,$B28) -> 3.6017937e+13 | H28: =-SUMIFS(' Energy Balance'!$H:$H,' Energy Balance'!$B:$B,$A$2,' Energy Balance'!$C:$C,H$4,' Energy Balance'!$D:$D,$A28,' Energy Balance'!$E:$E,$B28) -> 3.6048058e+13 | K28: Share of "free" heat in final supply | L28: 2018 | M28: 2019 | N28: 2020 | O28: 2021 | P28: 2022
A29: 2.2. 供热 | B29: 天然气 | C29: =VLOOKUP(B29,'Fuel Category and Heat Rate'!K$3:M$36,3,FALSE) -> natural gas | D29: =-SUMIFS(' Energy Balance'!$H:$H,' Energy Balance'!$B:$B,$A$2,' Energy Balance'!$C:$C,D$4,' Energy Balance'!$D:$D,$A29,' Energy Balance'!$E:$E,$B29) -> 4.3498484e+14 | E29: =-SUMIFS(' Energy Balance'!$H:$H,' Energy Balance'!$B:$B,$A$2,' Energy Balance'!$C:$C,E$4,' Energy Balance'!$D:$D,$A29,' Energy Balance'!$E:$E,$B29) -> 4.8294548e+14 | F29: =-SUMIFS(' Energy Balance'!$H:$H,' Energy Balance'!$B:$B,$A$2,' Energy Balance'!$C:$C,F$4,' Energy Balance'!$D:$D,$A29,' Energy Balance'!$E:$E,$B29) -> 5.7222243e+14 | G29: =-SUMIFS(' Energy Balance'!$H:$H,' Energy Balance'!$B:$B,$A$2,' Energy Balance'!$C:$C,G$4,' Energy Balance'!$D:$D,$A29,' Energy Balance'!$E:$E,$B29) -> 6.7843064e+14 | H29: =-SUMIFS(' Energy Balance'!$H:$H,' Energy Balance'!$B:$B,$A$2,' Energy Balance'!$C:$C,H$4,' Energy Balance'!$D:$D,$A29,' Energy Balance'!$E:$E,$B29) -> 7.5644258e+14 | K29: Recovered Heat | L29: =D36/(D36+D38) -> 0.15493086 | M29: =E36/(E36+E38) -> 0.14597666 | N29: =F36/(F36+F38) -> 0.15285332 | O29: =G36/(G36+G38) -> 0.14714835 | P29: =H36/(H36+H38) -> 0.14352954
A30: 2.2. 供热 | B30: 液化天然气 | C30: =VLOOKUP(B30,'Fuel Category and Heat Rate'!K$3:M$36,3,FALSE) -> natural gas | D30: =-SUMIFS(' Energy Balance'!$H:$H,' Energy Balance'!$B:$B,$A$2,' Energy Balance'!$C:$C,D$4,' Energy Balance'!$D:$D,$A30,' Energy Balance'!$E:$E,$B30) -> 1.1953506e+13 | E30: =-SUMIFS(' Energy Balance'!$H:$H,' Energy Balance'!$B:$B,$A$2,' Energy Balance'!$C:$C,E$4,' Energy Balance'!$D:$D,$A30,' Energy Balance'!$E:$E,$B30) -> 1.6336134e+13 | F30: =-SUMIFS(' Energy Balance'!$H:$H,' Energy Balance'!$B:$B,$A$2,' Energy Balance'!$C:$C,F$4,' Energy Balance'!$D:$D,$A30,' Energy Balance'!$E:$E,$B30) -> 2.3780263e+13 | G30: =-SUMIFS(' Energy Balance'!$H:$H,' Energy Balance'!$B:$B,$A$2,' Energy Balance'!$C:$C,G$4,' Energy Balance'!$D:$D,$A30,' Energy Balance'!$E:$E,$B30) -> 2.5535264e+13 | H30: =-SUMIFS(' Energy Balance'!$H:$H,' Energy Balance'!$B:$B,$A$2,' Energy Balance'!$C:$C,H$4,' Energy Balance'!$D:$D,$A30,' Energy Balance'!$E:$E,$B30) -> 1.9943636e+13
A31: 2.2. 供热 | B31: 柴油 | C31: =VLOOKUP(B31,'Fuel Category and Heat Rate'!K$3:M$36,3,FALSE) -> petroleum diesel | D31: =-SUMIFS(' Energy Balance'!$H:$H,' Energy Balance'!$B:$B,$A$2,' Energy Balance'!$C:$C,D$4,' Energy Balance'!$D:$D,$A31,' Energy Balance'!$E:$E,$B31) -> 2.0981248e+12 | E31: =-SUMIFS(' Energy Balance'!$H:$H,' Energy Balance'!$B:$B,$A$2,' Energy Balance'!$C:$C,E$4,' Energy Balance'!$D:$D,$A31,' Energy Balance'!$E:$E,$B31) -> 2.1425937e+12 | F31: =-SUMIFS(' Energy Balance'!$H:$H,' Energy Balance'!$B:$B,$A$2,' Energy Balance'!$C:$C,F$4,' Energy Balance'!$D:$D,$A31,' Energy Balance'!$E:$E,$B31) -> 1.1764052e+12 | G31: =-SUMIFS(' Energy Balance'!$H:$H,' Energy Balance'!$B:$B,$A$2,' Energy Balance'!$C:$C,G$4,' Energy Balance'!$D:$D,$A31,' Energy Balance'!$E:$E,$B31) -> 1.3866219e+12 | H31: =-SUMIFS(' Energy Balance'!$H:$H,' Energy Balance'!$B:$B,$A$2,' Energy Balance'!$C:$C,H$4,' Energy Balance'!$D:$D,$A31,' Energy Balance'!$E:$E,$B31) -> 1.3502383e+12 | K31: Average Heat Conversion Efficiency | L31: 2018 | M31: 2019 | N31: 2020 | O31: 2021 | P31: 2022
A32: 2.2. 供热 | B32: 煤油 | C32: =VLOOKUP(B32,'Fuel Category and Heat Rate'!K$3:M$36,3,FALSE) -> petroleum diesel | D32: =-SUMIFS(' Energy Balance'!$H:$H,' Energy Balance'!$B:$B,$A$2,' Energy Balance'!$C:$C,D$4,' Energy Balance'!$D:$D,$A32,' Energy Balance'!$E:$E,$B32) -> 0 | E32: =-SUMIFS(' Energy Balance'!$H:$H,' Energy Balance'!$B:$B,$A$2,' Energy Balance'!$C:$C,E$4,' Energy Balance'!$D:$D,$A32,' Energy Balance'!$E:$E,$B32) -> 0 | F32: =-SUMIFS(' Energy Balance'!$H:$H,' Energy Balance'!$B:$B,$A$2,' Energy Balance'!$C:$C,F$4,' Energy Balance'!$D:$D,$A32,' Energy Balance'!$E:$E,$B32) -> 0 | G32: =-SUMIFS(' Energy Balance'!$H:$H,' Energy Balance'!$B:$B,$A$2,' Energy Balance'!$C:$C,G$4,' Energy Balance'!$D:$D,$A32,' Energy Balance'!$E:$E,$B32) -> 0 | H32: =-SUMIFS(' Energy Balance'!$H:$H,' Energy Balance'!$B:$B,$A$2,' Energy Balance'!$C:$C,H$4,' Energy Balance'!$D:$D,$A32,' Energy Balance'!$E:$E,$B32) -> 0 | K32: Efficiency | L32: =D38/SUM(L5:L14) -> 0.67567284 | M32: =E38/SUM(M5:M14) -> 0.68216686 | N32: =F38/SUM(N5:N14) -> 0.68067471 | O32: =G38/SUM(O5:O14) -> 0.67955571 | P32: =H38/SUM(P5:P14) -> 0.69261699
A33: 2.2. 供热 | B33: 其他焦化产品 | C33: =VLOOKUP(B33,'Fuel Category and Heat Rate'!K$3:M$36,3,FALSE) -> petroleum diesel | D33: =-SUMIFS(' Energy Balance'!$H:$H,' Energy Balance'!$B:$B,$A$2,' Energy Balance'!$C:$C,D$4,' Energy Balance'!$D:$D,$A33,' Energy Balance'!$E:$E,$B33) -> 0 | E33: =-SUMIFS(' Energy Balance'!$H:$H,' Energy Balance'!$B:$B,$A$2,' Energy Balance'!$C:$C,E$4,' Energy Balance'!$D:$D,$A33,' Energy Balance'!$E:$E,$B33) -> 0 | F33: =-SUMIFS(' Energy Balance'!$H:$H,' Energy Balance'!$B:$B,$A$2,' Energy Balance'!$C:$C,F$4,' Energy Balance'!$D:$D,$A33,' Energy Balance'!$E:$E,$B33) -> 0 | G33: =-SUMIFS(' Energy Balance'!$H:$H,' Energy Balance'!$B:$B,$A$2,' Energy Balance'!$C:$C,G$4,' Energy Balance'!$D:$D,$A33,' Energy Balance'!$E:$E,$B33) -> 0 | H33: =-SUMIFS(' Energy Balance'!$H:$H,' Energy Balance'!$B:$B,$A$2,' Energy Balance'!$C:$C,H$4,' Energy Balance'!$D:$D,$A33,' Energy Balance'!$E:$E,$B33) -> 0 | K33: *This data is fairly close to the results calculated from actual heating facilities used in EoCtUH, and will be treated as supporting evidence
A34: 2.2. 供热 | B34: 汽油 | C34: =VLOOKUP(B34,'Fuel Category and Heat Rate'!K$3:M$36,3,FALSE) -> petroleum diesel | D34: =-SUMIFS(' Energy Balance'!$H:$H,' Energy Balance'!$B:$B,$A$2,' Energy Balance'!$C:$C,D$4,' Energy Balance'!$D:$D,$A34,' Energy Balance'!$E:$E,$B34) -> 2.8575738e+10 | E34: =-SUMIFS(' Energy Balance'!$H:$H,' Energy Balance'!$B:$B,$A$2,' Energy Balance'!$C:$C,E$4,' Energy Balance'!$D:$D,$A34,' Energy Balance'!$E:$E,$B34) -> 2.0411242e+10 | F34: =-SUMIFS(' Energy Balance'!$H:$H,' Energy Balance'!$B:$B,$A$2,' Energy Balance'!$C:$C,F$4,' Energy Balance'!$D:$D,$A34,' Energy Balance'!$E:$E,$B34) -> 0 | G34: =-SUMIFS(' Energy Balance'!$H:$H,' Energy Balance'!$B:$B,$A$2,' Energy Balance'!$C:$C,G$4,' Energy Balance'!$D:$D,$A34,' Energy Balance'!$E:$E,$B34) -> 0 | H34: =-SUMIFS(' Energy Balance'!$H:$H,' Energy Balance'!$B:$B,$A$2,' Energy Balance'!$C:$C,H$4,' Energy Balance'!$D:$D,$A34,' Energy Balance'!$E:$E,$B34) -> 0
A35: Recovered Heat
A36: 2.9. 回收能 | B36: 热力 | C36: =VLOOKUP(B36,'Fuel Category and Heat Rate'!K$3:M$36,3,FALSE) -> heat | D36: =SUMIFS(' Energy Balance'!$H:$H,' Energy Balance'!$B:$B,$A$2,' Energy Balance'!$C:$C,D$4,' Energy Balance'!$D:$D,$A36,' Energy Balance'!$E:$E,$B36) -> 911271000487794 | E36: =SUMIFS(' Energy Balance'!$H:$H,' Energy Balance'!$B:$B,$A$2,' Energy Balance'!$C:$C,E$4,' Energy Balance'!$D:$D,$A36,' Energy Balance'!$E:$E,$B36) -> 9.1557362e+14 | F36: =SUMIFS(' Energy Balance'!$H:$H,' Energy Balance'!$B:$B,$A$2,' Energy Balance'!$C:$C,F$4,' Energy Balance'!$D:$D,$A36,' Energy Balance'!$E:$E,$B36) -> 1.0498883e+15 | G36: =SUMIFS(' Energy Balance'!$H:$H,' Energy Balance'!$B:$B,$A$2,' Energy Balance'!$C:$C,G$4,' Energy Balance'!$D:$D,$A36,' Energy Balance'!$E:$E,$B36) -> 1.1888095e+15 | H36: =SUMIFS(' Energy Balance'!$H:$H,' Energy Balance'!$B:$B,$A$2,' Energy Balance'!$C:$C,H$4,' Energy Balance'!$D:$D,$A36,' Energy Balance'!$E:$E,$B36) -> 1.3390869e+15
A37: Heat Generated from Fuel
A38: 2.2. 供热 | B38: 热力 | C38: =VLOOKUP(B38,'Fuel Category and Heat Rate'!K$3:M$36,3,FALSE) -> heat | D38: =SUMIFS(' Energy Balance'!$H:$H,' Energy Balance'!$B:$B,$A$2,' Energy Balance'!$C:$C,D$4,' Energy Balance'!$D:$D,$A38,' Energy Balance'!$E:$E,$B38) -> 4.9705203e+15 | E38: =SUMIFS(' Energy Balance'!$H:$H,' Energy Balance'!$B:$B,$A$2,' Energy Balance'!$C:$C,E$4,' Energy Balance'!$D:$D,$A38,' Energy Balance'!$E:$E,$B38) -> 5.3564812e+15 | F38: =SUMIFS(' Energy Balance'!$H:$H,' Energy Balance'!$B:$B,$A$2,' Energy Balance'!$C:$C,F$4,' Energy Balance'!$D:$D,$A38,' Energy Balance'!$E:$E,$B38) -> 5.8187118e+15 | G38: =SUMIFS(' Energy Balance'!$H:$H,' Energy Balance'!$B:$B,$A$2,' Energy Balance'!$C:$C,G$4,' Energy Balance'!$D:$D,$A38,' Energy Balance'!$E:$E,$B38) -> 6.8901767e+15 | H38: =SUMIFS(' Energy Balance'!$H:$H,' Energy Balance'!$B:$B,$A$2,' Energy Balance'!$C:$C,H$4,' Energy Balance'!$D:$D,$A38,' Energy Balance'!$E:$E,$B38) -> 7.990609e+15

Sheet Fuel Category and Heat Rate
A1: 序号 Index | B1: 能源名称 Fuel Type | C1: 实物量单位 Physical Unit | D1: 能源名称(含单位） Fuel Type | E1: 平均低位发热量 Average Lower Heat Value
E2: TJ/单位 | F2: 万tce/单位 | G2: BTU/单位 | J2: Chinese Model Fuel | K2: 能源品种 | L2: EPS Fuel | M2: EPS Industrial Module Fuel
A3: 1 | B3: 煤合计 | C3: 万吨 | D3: 煤合计(万吨) | J3: Crude Oil | K3: 原油 | L3: crude oil | M3: crude oil
A4: 2 | B4: 原煤 | C4: 万吨 | D4: 原煤(万吨) | E4: 209.08 | F4: 0.71341318 | G4: 1.981696e+11 | J4: Diesel Oil | K4: 柴油 | L4: petroleum diesel | M4: petroleum diesel
A5: 3 | B5: 洗精煤 | C5: 万吨 | D5: 洗精煤(万吨) | E5: 263.44 | F5: 0.89889787 | G5: 2.4969294e+11 | J5: municipal solid waste | K5: 城市生活垃圾 | L5: municipal solid waste | M5: other energy
A6: 4 | B6: 其他洗煤 | C6: 万吨 | D6: 其他洗煤(万吨) | E6: 83.63 | F6: 0.28535845 | G6: 7.9265946e+10 | J6: Electricity | K6: 电力 | L6: electricity | M6: electricity
A7: 5 | B7: 型煤 | C7: 万吨 | D7: 型煤(万吨) | E7: 154.73 | F7: 0.5279626 | G7: 1.4665574e+11 | J7: Blast Furnance Gas | K7: 高炉煤气 | L7: LPG propane or butane | M7: LPG propane or butane
A8: 6 | B8: 煤矸石 | C8: 万吨 | D8: 煤矸石(万吨) | E8: 83.74 | F8: 0.28573378 | G8: 7.9370206e+10 | J8: Coke Oven Gas | K8: 焦炉煤气 | L8: LPG propane or butane | M8: LPG propane or butane
A9: 7 | B9: 焦炭 | C9: 万吨 | D9: 焦炭(万吨) | E9: 284.35 | F9: 0.97024602 | G9: 2.695118e+11 | J9: Coke | K9: 焦炭 | L9: other energy | M9: coal
A10: 8 | B10: 焦炉煤气 | C10: 亿立方米 | D10: 焦炉煤气(亿立方米) | E10: 1735.35 | F10: 5.9212816 | G10: 1.6447944e+12 | J10: Refinery Gas | K10: 炼厂干气 | L10: LPG propane or butane | M10: LPG propane or butane
A11: 9 | B11: 高炉煤气 | C11: 亿立方米 | D11: 高炉煤气(亿立方米) | E11: 376.3 | F11: 1.2839936 | G11: 3.5666358e+11 | J11: Gangue | K11: 煤矸石 | L11: lignite | M11: coal
A12: 10 | B12: 转炉煤气 | C12: 亿立方米 | D12: 转炉煤气(亿立方米) | E12: 794.5 | F12: 2.7109564 | G12: 7.530407e+11 | J12: Kerosene | K12: 煤油 | L12: jet fuel or kerosene | M12: petroleum diesel
A13: 11 | B13: 其他煤气 | C13: 亿立方米 | D13: 其他煤气(亿立方米) | E13: 522.7 | F13: 1.7835329 | G13: 4.9542401e+11 | J13: Briquettes | K13: 型煤 | L13: hard coal | M13: coal
A14: 12 | B14: 其他焦化产品 | C14: 万吨 | D14: 其他焦化产品(万吨) | E14: 334.53 | F14: 1.1414679 | G14: 3.1707326e+11 | J14: Other Coking Products | K14: 其他焦化产品 | L14: petroleum diesel | M14: petroleum diesel
A15: 13 | B15: 油品合计 | C15: 万吨 | D15: 油品合计(万吨) | J15: Other Gas | K15: 其他煤气 | L15: LPG propane or butane | M15: LPG propane or butane
A16: 14 | B16: 原油 | C16: 万吨 | D16: 原油(万吨) | E16: 418.16 | F16: 1.4268264 | G16: 3.9633921e+11 | J16: Other Energy | K16: 其他能源 | L16: biomass | M16: biomass
A17: 15 | B17: 汽油 | C17: 万吨 | D17: 汽油(万吨) | E17: 430.7 | F17: 1.4696148 | G17: 4.0822483e+11 | J17: Other Petroleum Products | K17: 其他石油制品 | L17: heavy or residual fuel oil | M17: heavy or residual fuel oil
A18: 16 | B18: 煤油 | C18: 万吨 | D18: 煤油(万吨) | E18: 430.7 | F18: 1.4696148 | G18: 4.0822483e+11 | J18: Other Washed Coal | K18: 其他洗煤 | L18: lignite | M18: coal
A19: 17 | B19: 柴油 | C19: 万吨 | D19: 柴油(万吨) | E19: 426.52 | F19: 1.455352 | G19: 4.0426296e+11 | J19: Gasoline | K19: 汽油 | L19: petroleum gasoline | M19: petroleum diesel
A20: 18 | B20: 燃料油 | C20: 万吨 | D20: 燃料油(万吨) | E20: 418.16 | F20: 1.4268264 | G20: 3.9633921e+11 | J20: Fuel Oil | K20: 燃料油 | L20: heavy or residual fuel oil | M20: heavy or residual fuel oil
A21: 19 | B21: 石脑油 | C21: 万吨 | D21: 石脑油(万吨) | E21: 439.07 | F21: 1.4981745 | G21: 4.1615806e+11 | J21: Heat | K21: 热力 | L21: heat | M21: heat
A22: 20 | B22: 润滑油 | C22: 万吨 | D22: 润滑油(万吨) | E22: 413.98 | F22: 1.4125636 | G22: 3.9237733e+11 | J22: White Spirit | K22: 溶剂油 | L22: heavy or residual fuel oil | M22: heavy or residual fuel oil
A23: 21 | B23: 石蜡 | C23: 万吨 | D23: 石蜡(万吨) | E23: 399.25 | F23: 1.3623025 | G23: 3.7841599e+11 | J23: Lubricant | K23: 润滑油 | L23: LPG propane or butane | M23: LPG propane or butane
A24: 22 | B24: 溶剂油 | C24: 万吨 | D24: 溶剂油(万吨) | E24: 429.45 | F24: 1.4653496 | G24: 4.0704006e+11 | J24: biomass | K24: 生物质 | L24: biomass | M24: other energy
A25: 23 | B25: 石油沥青 | C25: 万吨 | D25: 石油沥青(万吨) | E25: 389.31 | F25: 1.3283857 | G25: 3.6899468e+11 | J25: biofuel diesel | K25: 生物质柴油 | L25: biofuel diesel | M25: other energy
A26: 24 | B26: 石油焦 | C26: 万吨 | D26: 石油焦(万吨) | E26: 319.47 | F26: 1.0900809 | G26: 3.0279914e+11 | J26: biofuel gasoline | K26: 生物质汽油 | L26: biofuel gasoline | M26: other energy
A27: 25 | B27: 液化石油气 | C27: 万吨 | D27: 液化石油气(万吨) | E27: 501.79 | F27: 1.7121848 | G27: 4.7560515e+11 | J27: Paraffin Waxes | K27: 石蜡 | L27: LPG propane or butane | M27: heavy fuel oil
... A34: 32 | B34: 其他能源 | C34: 万吨标准煤 | D34: 其他能源(万吨标准煤) | E34: 292.71 | F34: 0.99877162 | G34: 2.7743555e+11 | J34: Liquefied Natural Gas | K34: 液化天然气 | L34: natural gas | M34: natural gas
J35: Raw Coal | K35: 原煤 | L35: hard coal | M35: coal
J36: Converter Gas | K36: 转炉煤气 | L36: LPG propane or butane | M36: LPG propane or butane

Sheet BFoHPbF
A1: Fraction of Heat Provided by Fuel (dimensionless) | B1: 2018 | C1: 2019 | D1: 2020 | E1: 2021 | F1: 2022 | G1: 2023 | H1: 2024 | I1: 2025 | J1: 2026 | K1: 2027 | L1: 2028 | M1: 2029 | N1: 2030 | O1: 2031 | P1: 2032 | Q1: 2033 | R1: 2034 | S1: 2035 | T1: 2036 | U1: 2037 | V1: 2038 | W1: 2039 | X1: 2040 | Y1: 2041 | Z1: 2042 | AA1: 2043 | AB1: 2044 | AC1: 2045 | AD1: 2046 | AE1: 2047 | AF1: 2048 | AG1: 2049 | AH1: 2050 | AI1: 2051 | AJ1: 2052 | AK1: 2053 | AL1: 2054 | AM1: 2055 | AN1: 2056 | AO1: 2057 | AP1: 2058 | AQ1: 2059 | AR1: 2060
A2: electricity | B2: =VLOOKUP($A2,Calculation!$K$16:$P$26,COLUMN(B$1),FALSE) -> 0 | C2: =VLOOKUP($A2,Calculation!$K$16:$P$26,COLUMN(C$1),FALSE) -> 0 | D2: =VLOOKUP($A2,Calculation!$K$16:$P$26,COLUMN(D$1),FALSE) -> 0 | E2: =VLOOKUP($A2,Calculation!$K$16:$P$26,COLUMN(E$1),FALSE) -> 0 | F2: =VLOOKUP($A2,Calculation!$K$16:$P$26,COLUMN(F$1),FALSE) -> 0 | G2: =$F2 -> 0 | H2: =$F2 -> 0 | I2: =$F2 -> 0 | J2: =$F2 -> 0 | K2: =$F2 -> 0 | L2: =$F2 -> 0 | M2: =$F2 -> 0 | N2: =$F2 -> 0 | ... AR2: =$F2 -> 0
A3: coal | B3: =VLOOKUP($A3,Calculation!$K$16:$P$26,COLUMN(B$1),FALSE) -> 0.86091617 | C3: =VLOOKUP($A3,Calculation!$K$16:$P$26,COLUMN(C$1),FALSE) -> 0.85598141 | D3: =VLOOKUP($A3,Calculation!$K$16:$P$26,COLUMN(D$1),FALSE) -> 0.85125273 | E3: =VLOOKUP($A3,Calculation!$K$16:$P$26,COLUMN(E$1),FALSE) -> 0.85909029 | F3: =VLOOKUP($A3,Calculation!$K$16:$P$26,COLUMN(F$1),FALSE) -> 0.86103159 | G3: =$F3 -> 0.86103159 | H3: =$F3 -> 0.86103159 | I3: =$F3 -> 0.86103159 | J3: =$F3 -> 0.86103159 | K3: =$F3 -> 0.86103159 | L3: =$F3 -> 0.86103159 | M3: =$F3 -> 0.86103159 | N3: =$F3 -> 0.86103159 | ... AR3: =$F3 -> 0.86103159
A4: natural gas | B4: =VLOOKUP($A4,Calculation!$K$16:$P$26,COLUMN(B$1),FALSE) -> 0.060755028 | C4: =VLOOKUP($A4,Calculation!$K$16:$P$26,COLUMN(C$1),FALSE) -> 0.063585283 | D4: =VLOOKUP($A4,Calculation!$K$16:$P$26,COLUMN(D$1),FALSE) -> 0.069720581 | E4: =VLOOKUP($A4,Calculation!$K$16:$P$26,COLUMN(E$1),FALSE) -> 0.069429867 | F4: =VLOOKUP($A4,Calculation!$K$16:$P$26,COLUMN(F$1),FALSE) -> 0.067296283 | G4: =$F4 -> 0.067296283 | H4: =$F4 -> 0.067296283 | I4: =$F4 -> 0.067296283 | J4: =$F4 -> 0.067296283 | K4: =$F4 -> 0.067296283 | L4: =$F4 -> 0.067296283 | M4: =$F4 -> 0.067296283 | N4: =$F4 -> 0.067296283 | ... AR4: =$F4 -> 0.067296283
A5: biomass | B5: =VLOOKUP($A5,Calculation!$K$16:$P$26,COLUMN(B$1),FALSE) -> 0.013303434 | C5: =VLOOKUP($A5,Calculation!$K$16:$P$26,COLUMN(C$1),FALSE) -> 0.013848888 | D5: =VLOOKUP($A5,Calculation!$K$16:$P$26,COLUMN(D$1),FALSE) -> 0.02238484 | E5: =VLOOKUP($A5,Calculation!$K$16:$P$26,COLUMN(E$1),FALSE) -> 0.024884885 | F5: =VLOOKUP($A5,Calculation!$K$16:$P$26,COLUMN(F$1),FALSE) -> 0.02868061 | G5: =$F5 -> 0.02868061 | H5: =$F5 -> 0.02868061 | I5: =$F5 -> 0.02868061 | J5: =$F5 -> 0.02868061 | K5: =$F5 -> 0.02868061 | L5: =$F5 -> 0.02868061 | M5: =$F5 -> 0.02868061 | N5: =$F5 -> 0.02868061 | ... AR5: =$F5 -> 0.02868061
A6: petroleum diesel | B6: =VLOOKUP($A6,Calculation!$K$16:$P$26,COLUMN(B$1),FALSE) -> 0.00028909524 | C6: =VLOOKUP($A6,Calculation!$K$16:$P$26,COLUMN(C$1),FALSE) -> 0.00027546634 | D6: =VLOOKUP($A6,Calculation!$K$16:$P$26,COLUMN(D$1),FALSE) -> 0.00013761625 | E6: =VLOOKUP($A6,Calculation!$K$16:$P$26,COLUMN(E$1),FALSE) -> 0.00013675801 | F6: =VLOOKUP($A6,Calculation!$K$16:$P$26,COLUMN(F$1),FALSE) -> 0.00011703713 | G6: =$F6 -> 0.00011703713 | H6: =$F6 -> 0.00011703713 | I6: =$F6 -> 0.00011703713 | J6: =$F6 -> 0.00011703713 | K6: =$F6 -> 0.00011703713 | L6: =$F6 -> 0.00011703713 | M6: =$F6 -> 0.00011703713 | N6: =$F6 -> 0.00011703713 | ... AR6: =$F6 -> 0.00011703713
A7: heat | B7: =VLOOKUP($A7,Calculation!$K$16:$P$26,COLUMN(B$1),FALSE) -> 0 | C7: =VLOOKUP($A7,Calculation!$K$16:$P$26,COLUMN(C$1),FALSE) -> 0 | D7: =VLOOKUP($A7,Calculation!$K$16:$P$26,COLUMN(D$1),FALSE) -> 0 | E7: =VLOOKUP($A7,Calculation!$K$16:$P$26,COLUMN(E$1),FALSE) -> 0 | F7: =VLOOKUP($A7,Calculation!$K$16:$P$26,COLUMN(F$1),FALSE) -> 0 | G7: =$F7 -> 0 | H7: =$F7 -> 0 | I7: =$F7 -> 0 | J7: =$F7 -> 0 | K7: =$F7 -> 0 | L7: =$F7 -> 0 | M7: =$F7 -> 0 | N7: =$F7 -> 0 | ... AR7: =$F7 -> 0
A8: crude oil | B8: =VLOOKUP($A8,Calculation!$K$16:$P$26,COLUMN(B$1),FALSE) -> 0 | C8: =VLOOKUP($A8,Calculation!$K$16:$P$26,COLUMN(C$1),FALSE) -> 0 | D8: =VLOOKUP($A8,Calculation!$K$16:$P$26,COLUMN(D$1),FALSE) -> 0 | E8: =VLOOKUP($A8,Calculation!$K$16:$P$26,COLUMN(E$1),FALSE) -> 0 | F8: =VLOOKUP($A8,Calculation!$K$16:$P$26,COLUMN(F$1),FALSE) -> 0 | G8: =$F8 -> 0 | H8: =$F8 -> 0 | I8: =$F8 -> 0 | J8: =$F8 -> 0 | K8: =$F8 -> 0 | L8: =$F8 -> 0 | M8: =$F8 -> 0 | N8: =$F8 -> 0 | ... AR8: =$F8 -> 0
A9: heavy or residual fuel oil | B9: =VLOOKUP($A9,Calculation!$K$16:$P$26,COLUMN(B$1),FALSE) -> 0.0039691839 | C9: =VLOOKUP($A9,Calculation!$K$16:$P$26,COLUMN(C$1),FALSE) -> 0.0041718853 | D9: =VLOOKUP($A9,Calculation!$K$16:$P$26,COLUMN(D$1),FALSE) -> 0.011361521 | E9: =VLOOKUP($A9,Calculation!$K$16:$P$26,COLUMN(E$1),FALSE) -> 0.010126639 | F9: =VLOOKUP($A9,Calculation!$K$16:$P$26,COLUMN(F$1),FALSE) -> 0.008765096 | G9: =$F9 -> 0.008765096 | H9: =$F9 -> 0.008765096 | I9: =$F9 -> 0.008765096 | J9: =$F9 -> 0.008765096 | K9: =$F9 -> 0.008765096 | L9: =$F9 -> 0.008765096 | M9: =$F9 -> 0.008765096 | N9: =$F9 -> 0.008765096 | ... AR9: =$F9 -> 0.008765096
A10: LPG propane or butane | B10: =VLOOKUP($A10,Calculation!$K$16:$P$26,COLUMN(B$1),FALSE) -> 0.060767093 | C10: =VLOOKUP($A10,Calculation!$K$16:$P$26,COLUMN(C$1),FALSE) -> 0.062137072 | D10: =VLOOKUP($A10,Calculation!$K$16:$P$26,COLUMN(D$1),FALSE) -> 0.045142708 | E10: =VLOOKUP($A10,Calculation!$K$16:$P$26,COLUMN(E$1),FALSE) -> 0.036331557 | F10: =VLOOKUP($A10,Calculation!$K$16:$P$26,COLUMN(F$1),FALSE) -> 0.034109381 | G10: =$F10 -> 0.034109381 | H10: =$F10 -> 0.034109381 | I10: =$F10 -> 0.034109381 | J10: =$F10 -> 0.034109381 | K10: =$F10 -> 0.034109381 | L10: =$F10 -> 0.034109381 | M10: =$F10 -> 0.034109381 | N10: =$F10 -> 0.034109381 | ... AR10: =$F10 -> 0.034109381
A11: hydrogen | B11: =VLOOKUP($A11,Calculation!$K$16:$P$26,COLUMN(B$1),FALSE) -> 0 | C11: =VLOOKUP($A11,Calculation!$K$16:$P$26,COLUMN(C$1),FALSE) -> 0 | D11: =VLOOKUP($A11,Calculation!$K$16:$P$26,COLUMN(D$1),FALSE) -> 0 | E11: =VLOOKUP($A11,Calculation!$K$16:$P$26,COLUMN(E$1),FALSE) -> 0 | F11: =VLOOKUP($A11,Calculation!$K$16:$P$26,COLUMN(F$1),FALSE) -> 0 | G11: =$F11 -> 0 | H11: =$F11 -> 0 | I11: =$F11 -> 0 | J11: =$F11 -> 0 | K11: =$F11 -> 0 | L11: =$F11 -> 0 | M11: =$F11 -> 0 | N11: =$F11 -> 0 | ... AR11: =$F11 -> 0
