Workbook
Name billion_kw_to_MW: [1]About!$B$29
Name gigwatt_to_megawatt: [1]About!$B$30
Name OLE_LINK2: 户用光伏安装数据!#REF!
Name Percent_rural: [1]About!$A$27
Name Percent_Urban: [1]About!$A$26

Sheet 能源局光伏并网数据
A1: 省（区、市） | B1: 累计装机容量（万千瓦） | D1: 新增装机容量（万千瓦） | K1: 2017 | L1: 2018 | M1: 2019 | N1: 2020H1 | O1: 2020 | P1: 2021 | R1: 2017 | S1: 2018 | T1: 2019 | U1: 2020H1 | V1: 2020 | W1: 2021 | AA1: 省（区、市） | AB1: 2021年新增并网容量 | AE1: 截至2021年底累计并网容置 | AM1: 地区 | AN1: 装机容量（万千瓦） | AR1: 发电量（亿千瓦时） | AV1: 容量因子 | AZ1: 运行小时数
C2: 其中：光伏电站 | E2: 其中：光伏电站 | K2: 光伏电站 | L2: 光伏电站 | M2: 光伏电站 | N2: 光伏电站 | O2: 光伏电站 | P2: 光伏电站 | R2: 分布式光伏 | S2: 分布式光伏 | T2: 分布式光伏 | U2: 分布式光伏 | V2: 分布式光伏 | W2: 分布式光伏 | AC2: 其中：集中 式光伏电站 | AD2: 其中：分 布式光伏 | AF2: 其中：集中 式光伏电站 | AG2: 其中:分布式 光伏 | AN2: 2020年 | AO2: 2019年 | AP2: 2018年 | AQ2: 2017年 | AR2: 2020年 | AS2: 2019年 | AT2: 2018年 | AU2: 2017年 | AV2: 2020年 | AW2: 2019年 | AX2: 2018年 | AY2: 2017年 | AZ2: 2020年 | BA2: 2019年 | BB2: 2018年 | BC2: 2017年
A3: 总计 | B3: 21582 | C3: 14875 | D3: 1152 | E3: 708 | F3: =B3-C3 -> 6707 | G3: =D3-E3 -> 444 | H3: =B3-D3 -> 20430 | J3: 全国 | K3: =AJ3-R3 -> 9384 | L3: =AK3-S3 -> 12406 | M3: =C3-E3 -> 14167 | N3: =C3 -> 14875 | O3: =AF3-AC3 -> 17287.87 | P3: =AF3 -> 19847.94 | R3: 3658 | S3: 5027 | T3: =F3-G3 -> 6263 | U3: =B3-C3 -> 6707 | V3: =AG3-AD3 -> 7822.9 | W3: =AG3 -> 10750.8 | Z3: 5488 | AA3: 总计 | AB3: 5488 | AC3: 2560.07 | AD3: 2927.9 | AE3: 30598.7 | AF3: 19847.94 | AG3: 10750.8 | AJ3: 13042 | AK3: 17433 | AM3: 全国 | AN3: 7827 | AO3: 6180 | AP3: 5027 | AQ3: 3658 | AR3: 679 | AS3: 538 | AT3: 388 | AU3: 154 | AV3: =AR3*10000/(AN3*8760) -> 0.099030811 | AW3: =AS3*10000/(AO3*8760) -> 0.099377872 | AX3: =AT3*10000/(AP3*8760) -> 0.088108688 | AY3: =AU3*10000/(AQ3*8760) -> 0.048058799 | AZ3: =AR3*10000/AN3 -> 867.5099 | BA3: =AS3*10000/AO3 -> 870.55016 | BB3: =AT3*10000/AP3 -> 771.83211 | BC3: =AU3*10000/AQ3 -> 420.99508
A4: 北京 | B4: 60 | C4: 5 | D4: 9 | E4: 0 | F4: =B4-C4 -> 55 | G4: =D4-E4 -> 9 | H4: =B4-D4 -> 51 | J4: 北京市 | K4: =AJ4-R4 -> 3 | L4: =AK4-S4 -> 5 | M4: =C4-E4 -> 5 | N4: =C4 -> 5 | O4: =AF4-AC4 -> 5.1 | P4: =AF4 -> 5.1 | R4: 22 | S4: 35 | T4: =F4-G4 -> 46 | U4: =B4-C4 -> 55 | V4: =AG4-AD4 -> 56.4 | W4: =AG4 -> 75 | Z4: 18.6 | AA4: 北京 | AB4: 18.6 | AC4: 0 | AD4: 18.6 | AE4: 80.1 | AF4: 5.1 | AG4: 75 | AJ4: 25 | AK4: 40 | AM4: 北京 | AN4: 56 | AO4: 46 | AP4: 35 | AQ4: 22 | AR4: 5 | AS4: 4 | AT4: 2 | AU4: 1 | AV4: =AR4*10000/(AN4*8760) -> 0.10192433 | AW4: =AS4*10000/(AO4*8760) -> 0.099265436 | AX4: =AT4*10000/(AP4*8760) -> 0.065231572 | AY4: =AU4*10000/(AQ4*8760) -> 0.051888751 | AZ4: =AR4*10000/AN4 -> 892.85714 | BA4: =AS4*10000/AO4 -> 869.56522 | BB4: =AT4*10000/AP4 -> 571.42857 | BC4: =AU4*10000/AQ4 -> 454.54545
A5: 天津 | B5: 151 | C5: 110 | D5: 9 | E5: 6 | F5: =B5-C5 -> 41 | G5: =D5-E5 -> 3 | H5: =B5-D5 -> 142 | J5: 天津市 | K5: =AJ5-R5 -> 53 | L5: =AK5-S5 -> 97 | M5: =C5-E5 -> 104 | N5: =C5 -> 110 | O5: =AF5-AC5 -> 118.84 | P5: =AF5 -> 118.85 | R5: 15 | S5: 31 | T5: =F5-G5 -> 38 | U5: =B5-C5 -> 41 | V5: =AG5-AD5 -> 44.7 | W5: =AG5 -> 58.9 | Z5: 14.2 | AA5: 天津 | AB5: 14.2 | AC5: 0.01 | AD5: 14.2 | AE5: 177.8 | AF5: 118.85 | AG5: 58.9 | AJ5: 68 | AK5: 128 | AM5: 天津 | AN5: 45 | AO5: 38 | AP5: 31 | AQ5: 15 | AR5: 4 | AS5: 3 | AT5: 2 | AU5: 1 | AV5: =AR5*10000/(AN5*8760) -> 0.10147133 | AW5: =AS5*10000/(AO5*8760) -> 0.090122567 | AX5: =AT5*10000/(AP5*8760) -> 0.073648549 | AY5: =AU5*10000/(AQ5*8760) -> 0.076103501 | AZ5: =AR5*10000/AN5 -> 888.88889 | BA5: =AS5*10000/AO5 -> 789.47368 | BB5: =AT5*10000/AP5 -> 645.16129 | BC5: =AU5*10000/AQ5 -> 666.66667
A6: 河北 | B6: 1571 | C6: 1018 | D6: 97 | E6: 56 | F6: =B6-C6 -> 553 | G6: =D6-E6 -> 41 | H6: =B6-D6 -> 1474 | J6: 河北省 | K6: =AJ6-R6 -> 517 | L6: =AK6-S6 -> 856 | M6: =C6-E6 -> 962 | N6: =C6 -> 1018 | O6: =AF6-AC6 -> 1445.52 | P6: =AF6 -> 1658.84 | R6: 351 | S6: 378 | T6: =F6-G6 -> 512 | U6: =B6-C6 -> 553 | V6: =AG6-AD6 -> 745.8 | W6: =AG6 -> 1262.5 | Z6: 730 | AA6: 河北 | AB6: 730 | AC6: 213.32 | AD6: 516.7 | AE6: 2921.3 | AF6: 1658.84 | AG6: 1262.5 | AJ6: 868 | AK6: 1234 | AM6: 河北 | AN6: 747 | AO6: 513 | AP6: 378 | AQ6: 351 | AR6: 70 | AS6: 53 | AT6: 32 | AU6: 11 | AV6: =AR6*10000/(AN6*8760) -> 0.10697279 | AW6: =AS6*10000/(AO6*8760) -> 0.11793817 | AX6: =AT6*10000/(AP6*8760) -> 0.096639366 | AY6: =AU6*10000/(AQ6*8760) -> 0.03577515 | AZ6: =AR6*10000/AN6 -> 937.08166 | BA6: =AS6*10000/AO6 -> 1033.1384 | BB6: =AT6*10000/AP6 -> 846.56085 | BC6: =AU6*10000/AQ6 -> 313.39031
A7: 山西 | B7: 1198 | C7: 963 | D7: 110 | E7: 106 | F7: =B7-C7 -> 235 | G7: =D7-E7 -> 4 | H7: =B7-D7 -> 1088 | J7: 山西省 | K7: =AJ7-R7 -> 530 | L7: =AK7-S7 -> 681 | M7: =C7-E7 -> 857 | N7: =C7 -> 963 | O7: =AF7-AC7 -> 1028.32 | P7: =AF7 -> 1101.84 | R7: 60 | S7: 183 | T7: =F7-G7 -> 231 | U7: =B7-C7 -> 235 | V7: =AG7-AD7 -> 280.2 | W7: =AG7 -> 355.9 | AA7: 山西 | AB7: 149.2 | AC7: 73.52 | AD7: 75.7 | AE7: 1457.7 | AF7: 1101.84 | AG7: 355.9 | AJ7: 590 | AK7: 864 | AM7: 山西 | AN7: 280 | AO7: 231 | AP7: 183 | AQ7: 60 | AR7: 31 | AS7: 25 | AT7: 14 | AU7: 5 | AV7: =AR7*10000/(AN7*8760) -> 0.12638617 | AW7: =AS7*10000/(AO7*8760) -> 0.12354464 | AX7: =AT7*10000/(AP7*8760) -> 0.087331886 | AY7: =AU7*10000/(AQ7*8760) -> 0.095129376 | AZ7: =AR7*10000/AN7 -> 1107.1429 | BA7: =AS7*10000/AO7 -> 1082.2511 | BB7: =AT7*10000/AP7 -> 765.02732 | BC7: =AU7*10000/AQ7 -> 833.33333
A8: 内蒙古 | B8: 1131 | C8: 1048 | D8: 50 | E8: 47 | F8: =B8-C8 -> 83 | G8: =D8-E8 -> 3 | H8: =B8-D8 -> 1081 | J8: 内蒙古自治区 | K8: =AJ8-R8 -> 741 | L8: =AK8-S8 -> 933 | M8: =C8-E8 -> 1001 | N8: =C8 -> 1048 | O8: =AF8-AC8 -> 1138 | P8: =AF8 -> 1299.5 | R8: 2 | S8: 13 | T8: =F8-G8 -> 80 | U8: =B8-C8 -> 83 | V8: =AG8-AD8 -> 90.1 | W8: =AG8 -> 102.5 | AA8: 内蒙古 | AB8: 173.9 | AC8: 161.5 | AD8: 12.4 | AE8: 1402 | AF8: 1299.5 | AG8: 102.5 | AJ8: 743 | AK8: 946 | AM8: 内蒙古 | AN8: 88 | AO8: 51 | AP8: 13 | AQ8: 2 | AR8: 13 | AS8: 3 | AT8: 1 | AU8: 0.3 | AV8: =AR8*10000/(AN8*8760) -> 0.16863844 | AW8: =AS8*10000/(AO8*8760) -> 0.067150148 | AX8: =AT8*10000/(AP8*8760) -> 0.087811732 | AY8: =AU8*10000/(AQ8*8760) -> 0.17123288 | AZ8: =AR8*10000/AN8 -> 1477.2727 | BA8: =AS8*10000/AO8 -> 588.23529 | BB8: =AT8*10000/AP8 -> 769.23077 | BC8: =AU8*10000/AQ8 -> 1500
A9: 辽宁 | B9: 369 | C9: 268 | D9: 26 | E9: 22 | F9: =B9-C9 -> 101 | G9: =D9-E9 -> 4 | H9: =B9-D9 -> 343 | J9: 辽宁省 | K9: =AJ9-R9 -> 185 | L9: =AK9-S9 -> 219 | M9: =C9-E9 -> 246 | N9: =C9 -> 268 | O9: =AF9-AC9 -> 281.89 | P9: =AF9 -> 317.5 | R9: 38 | S9: 83 | T9: =F9-G9 -> 97 | U9: =B9-C9 -> 101 | V9: =AG9-AD9 -> 117.9 | W9: =AG9 -> 160 | AA9: 辽宁 | AB9: 77.7 | AC9: 35.61 | AD9: 42.1 | AE9: 477.5 | AF9: 317.5 | AG9: 160 | AJ9: 223 | AK9: 302 | AM9: 辽宁 | AN9: 118 | AO9: 97 | AP9: 83 | AQ9: 38 | AR9: 12 | AS9: 10 | AT9: 7 | AU9: 3 | AV9: =AR9*10000/(AN9*8760) -> 0.11609009 | AW9: =AS9*10000/(AO9*8760) -> 0.11768583 | AX9: =AT9*10000/(AP9*8760) -> 0.096275513 | AY9: =AU9*10000/(AQ9*8760) -> 0.090122567 | AZ9: =AR9*10000/AN9 -> 1016.9492 | BA9: =AS9*10000/AO9 -> 1030.9278 | BB9: =AT9*10000/AP9 -> 843.37349 | BC9: =AU9*10000/AQ9 -> 789.47368
A10: 吉林 | B10: 326 | C10: 255 | D10: 52 | E10: 50 | F10: =B10-C10 -> 71 | G10: =D10-E10 -> 2 | H10: =B10-D10 -> 274 | J10: 吉林省 | K10: =AJ10-R10 -> 107 | L10: =AK10-S10 -> 203 | M10: =C10-E10 -> 205 | N10: =C10 -> 255 | O10: =AF10-AC10 -> 260.91 | P10: =AF10 -> 265.79 | R10: 52 | S10: 62 | T10: =F10-G10 -> 69 | U10: =B10-C10 -> 71 | V10: =AG10-AD10 -> 76 | W10: =AG10 -> 80.1 | AA10: 吉林 | AB10: 9 | AC10: 4.88 | AD10: 4.1 | AE10: 345.9 | AF10: 265.79 | AG10: 80.1 | AJ10: 159 | AK10: 265 | AM10: 吉林 | AN10: 76 | AO10: 69 | AP10: 62 | AQ10: 52 | AR10: 9 | AS10: 9 | AT10: 7 | AU10: 2 | AV10: =AR10*10000/(AN10*8760) -> 0.13518385 | AW10: =AS10*10000/(AO10*8760) -> 0.14889815 | AX10: =AT10*10000/(AP10*8760) -> 0.12888496 | AY10: =AU10*10000/(AQ10*8760) -> 0.043905866 | AZ10: =AR10*10000/AN10 -> 1184.2105 | BA10: =AS10*10000/AO10 -> 1304.3478 | BB10: =AT10*10000/AP10 -> 1129.0323 | BC10: =AU10*10000/AQ10 -> 384.61538
A11: 黑龙江 | B11: 287 | C11: 205 | D11: 12 | E11: 10 | F11: =B11-C11 -> 82 | G11: =D11-E11 -> 2 | H11: =B11-D11 -> 275 | J11: 黑龙江省 | K11: =AJ11-R11 -> 64 | L11: =AK11-S11 -> 141 | M11: =C11-E11 -> 195 | N11: =C11 -> 205 | O11: =AF11-AC11 -> 234.99 | P11: =AF11 -> 329.99 | R11: 30 | S11: 74 | T11: =F11-G11 -> 80 | U11: =B11-C11 -> 82 | V11: =AG11-AD11 -> 82.7 | W11: =AG11 -> 89.8 | AA11: 黑龙江 | AB11: 102.1 | AC11: 95 | AD11: 7.1 | AE11: 419.8 | AF11: 329.99 | AG11: 89.8 | AJ11: 94 | AK11: 215 | AM11: 黑龙江 | AN11: 83 | AO11: 79 | AP11: 74 | AQ11: 30 | AR11: 10 | AS11: 9 | AT11: 5 | AU11: 1 | AV11: =AR11*10000/(AN11*8760) -> 0.13753645 | AW11: =AS11*10000/(AO11*8760) -> 0.13005029 | AX11: =AT11*10000/(AP11*8760) -> 0.077131926 | AY11: =AU11*10000/(AQ11*8760) -> 0.03805175 | AZ11: =AR11*10000/AN11 -> 1204.8193 | BA11: =AS11*10000/AO11 -> 1139.2405 | BB11: =AT11*10000/AP11 -> 675.67568 | BC11: =AU11*10000/AQ11 -> 333.33333
A12: 上海 | B12: 117 | C12: 6 | D12: 8 | E12: 0 | F12: =B12-C12 -> 111 | G12: =D12-E12 -> 8 | H12: =B12-D12 -> 109 | J12: 上海市 | K12: =AJ12-R12 -> -1 | L12: =AK12-S12 -> 7 | M12: =C12-E12 -> 6 | N12: =C12 -> 6 | O12: =AF12-AC12 -> 19.7 | P12: =AF12 -> 24.09 | R12: 59 | S12: 82 | T12: =F12-G12 -> 103 | U12: =B12-C12 -> 111 | V12: =AG12-AD12 -> 116.9 | W12: =AG12 -> 144.2 | AA12: 上海 | AB12: 31.7 | AC12: 4.39 | AD12: 27.3 | AE12: 168.3 | AF12: 24.09 | AG12: 144.2 | AJ12: 58 | AK12: 89 | AM12: 上海 | AN12: 117 | AO12: 102 | AP12: 82 | AQ12: 59 | AR12: 9 | AS12: 7 | AT12: 5 | AU12: 2 | AV12: =AR12*10000/(AN12*8760) -> 0.087811732 | AW12: =AS12*10000/(AO12*8760) -> 0.078341839 | AX12: =AT12*10000/(AP12*8760) -> 0.06960686 | AY12: =AU12*10000/(AQ12*8760) -> 0.038696695 | AZ12: =AR12*10000/AN12 -> 769.23077 | BA12: =AS12*10000/AO12 -> 686.27451 | BB12: =AT12*10000/AP12 -> 609.7561 | BC12: =AU12*10000/AQ12 -> 338.98305
A13: 江苏 | B13: 1599 | C13: 883 | D13: 113 | E13: 62 | F13: =B13-C13 -> 716 | G13: =D13-E13 -> 51 | H13: =B13-D13 -> 1486 | J13: 江苏省 | K13: =AJ13-R13 -> 580 | L13: =AK13-S13 -> 792 | M13: =C13-E13 -> 821 | N13: =C13 -> 883 | O13: =AF13-AC13 -> 895.91 | P13: =AF13 -> 941.08 | R13: 327 | S13: 540 | T13: =F13-G13 -> 665 | U13: =B13-C13 -> 716 | V13: =AG13-AD13 -> 788.1 | W13: =AG13 -> 974.9 | AA13: 江苏 | AB13: 232 | AC13: 45.17 | AD13: 186.8 | AE13: 1916 | AF13: 941.08 | AG13: 974.9 | AJ13: 907 | AK13: 1332 | AM13: 江苏 | AN13: 788 | AO13: 664 | AP13: 540 | AQ13: 327 | AR13: 61 | AS13: 53 | AT13: 40 | AU13: 19 | AV13: =AR13*10000/(AN13*8760) -> 0.088368913 | AW13: =AS13*10000/(AO13*8760) -> 0.091117896 | AX13: =AT13*10000/(AP13*8760) -> 0.084559445 | AY13: =AU13*10000/(AQ13*8760) -> 0.066328739 | AZ13: =AR13*10000/AN13 -> 774.11168 | BA13: =AS13*10000/AO13 -> 798.19277 | BB13: =AT13*10000/AP13 -> 740.74074 | BC13: =AU13*10000/AQ13 -> 581.03976
A14: 浙江 | B14: 1409 | C14: 428 | D14: 70 | E14: 14 | F14: =B14-C14 -> 981 | G14: =D14-E14 -> 56 | H14: =B14-D14 -> 1339 | J14: 浙江省 | K14: =AJ14-R14 -> 315 | L14: =AK14-S14 -> 361 | M14: =C14-E14 -> 414 | N14: =C14 -> 428 | O14: =AF14-AC14 -> 412.17 | P14: =AF14 -> 577.03 | R14: 499 | S14: 777 | T14: =F14-G14 -> 925 | U14: =B14-C14 -> 981 | V14: =AG14-AD14 -> 1067.2 | W14: =AG14 -> 1264.8 | AA14: 浙江 | AB14: 362.5 | AC14: 164.86 | AD14: 197.6 | AE14: 1841.8 | AF14: 577.03 | AG14: 1264.8 | AJ14: 814 | AK14: 1138 | AM14: 浙江 | AN14: 1067 | AO14: 925 | AP14: 777 | AQ14: 499 | AR14: 88 | AS14: 75 | AT14: 63 | AU14: 31 | AV14: =AR14*10000/(AN14*8760) -> 0.094148661 | AW14: =AS14*10000/(AO14*8760) -> 0.092558312 | AX14: =AT14*10000/(AP14*8760) -> 0.092558312 | AY14: =AU14*10000/(AQ14*8760) -> 0.070918092 | AZ14: =AR14*10000/AN14 -> 824.74227 | BA14: =AS14*10000/AO14 -> 810.81081 | BB14: =AT14*10000/AP14 -> 810.81081 | BC14: =AU14*10000/AQ14 -> 621.24248
A15: 安徽 | B15: 1272 | C15: 774 | D15: 19 | E15: 1 | F15: =B15-C15 -> 498 | G15: =D15-E15 -> 18 | H15: =B15-D15 -> 1253 | J15: 安徽省 | K15: =AJ15-R15 -> 565 | L15: =AK15-S15 -> 677 | M15: =C15-E15 -> 773 | N15: =C15 -> 774 | O15: =AF15-AC15 -> 825.56 | P15: =AF15 -> 947.02 | R15: 323 | S15: 441 | T15: =F15-G15 -> 480 | U15: =B15-C15 -> 498 | V15: =AG15-AD15 -> 544.1 | W15: =AG15 -> 759.8 | AA15: 安徽 | AB15: 337.2 | AC15: 121.46 | AD15: 215.7 | AE15: 1706.8 | AF15: 947.02 | AG15: 759.8 | AJ15: 888 | AK15: 1118 | AM15: 安徽 | AN15: 544 | AO15: 480 | AP15: 441 | AQ15: 323 | AR15: 45 | AS15: 46 | AT15: 36 | AU15: 18 | AV15: =AR15*10000/(AN15*8760) -> 0.094429895 | AW15: =AS15*10000/(AO15*8760) -> 0.10939878 | AX15: =AT15*10000/(AP15*8760) -> 0.09318796 | AY15: =AU15*10000/(AQ15*8760) -> 0.063615929 | AZ15: =AR15*10000/AN15 -> 827.20588 | BA15: =AS15*10000/AO15 -> 958.33333 | BB15: =AT15*10000/AP15 -> 816.32653 | BC15: =AU15*10000/AQ15 -> 557.27554
A16: 福建 | B16: 179 | C16: 38 | D16: 10 | E16: 0 | F16: =B16-C16 -> 141 | G16: =D16-E16 -> 10 | H16: =B16-D16 -> 169 | J16: 福建省 | K16: =AJ16-R16 -> -17 | L16: =AK16-S16 -> 37 | M16: =C16-E16 -> 38 | N16: =C16 -> 38 | O16: =AF16-AC16 -> 37.8 | P16: =AF16 -> 39.16 | R16: 109 | S16: 111 | T16: =F16-G16 -> 131 | U16: =B16-C16 -> 141 | V16: =AG16-AD16 -> 164.3 | W16: =AG16 -> 237.9 | AA16: 福建 | AB16: 75 | AC16: 1.36 | AD16: 73.6 | AE16: 277 | AF16: 39.16 | AG16: 237.9 | AJ16: 92 | AK16: 148 | AM16: 福建 | AN16: 164 | AO16: 131 | AP16: 111 | AQ16: 109 | AR16: 15 | AS16: 11 | AT16: 9 | AU16: 3 | AV16: =AR16*10000/(AN16*8760) -> 0.10441029 | AW16: =AS16*10000/(AO16*8760) -> 0.095855554 | AX16: =AT16*10000/(AP16*8760) -> 0.092558312 | AY16: =AU16*10000/(AQ16*8760) -> 0.031418876 | AZ16: =AR16*10000/AN16 -> 914.63415 | BA16: =AS16*10000/AO16 -> 839.69466 | BB16: =AT16*10000/AP16 -> 810.81081 | BC16: =AU16*10000/AQ16 -> 275.22936
A17: 江西 | B17: 678 | C17: 394 | D17: 48 | E17: 27 | F17: =B17-C17 -> 284 | G17: =D17-E17 -> 21 | H17: =B17-D17 -> 630 | J17: 江西省 | K17: =AJ17-R17 -> 277 | L17: =AK17-S17 -> 294 | M17: =C17-E17 -> 367 | N17: =C17 -> 394 | O17: =AF17-AC17 -> 476.66 | P17: =AF17 -> 551.95 | R17: 172 | S17: 242 | T17: =F17-G17 -> 263 | U17: =B17-C17 -> 284 | V17: =AG17-AD17 -> 299.2 | W17: =AG17 -> 359.2 | AA17: 江西 | AB17: 135.3 | AC17: 75.29 | AD17: 60 | AE17: 911.1 | AF17: 551.95 | AG17: 359.2 | AJ17: 449 | AK17: 536 | AM17: 江西 | AN17: 299 | AO17: 262 | AP17: 242 | AQ17: 172 | AR17: 26 | AS17: 24 | AT17: 21 | AU17: 8 | AV17: =AR17*10000/(AN17*8760) -> 0.099265436 | AW17: =AS17*10000/(AO17*8760) -> 0.1045697 | AX17: =AT17*10000/(AP17*8760) -> 0.099060342 | AY17: =AU17*10000/(AQ17*8760) -> 0.053095466 | AZ17: =AR17*10000/AN17 -> 869.56522 | BA17: =AS17*10000/AO17 -> 916.03053 | BB17: =AT17*10000/AP17 -> 867.7686 | BC17: =AU17*10000/AQ17 -> 465.11628
A18: 山东 | B18: 1801 | C18: 739 | D18: 181 | E18: 62 | F18: =B18-C18 -> 1062 | G18: =D18-E18 -> 119 | H18: =B18-D18 -> 1620 | J18: 山东省 | K18: =AJ18-R18 -> 578 | L18: =AK18-S18 -> 648 | M18: =C18-E18 -> 677 | N18: =C18 -> 739 | O18: =AF18-AC18 -> 805.02 | P18: =AF18 -> 1008.97 | R18: 474 | S18: 713 | T18: =F18-G18 -> 943 | U18: =B18-C18 -> 1062 | V18: =AG18-AD18 -> 1467.4 | W18: =AG18 -> 2334.4 | AA18: 山东 | AB18: 1070.9 | AC18: 203.95 | AD18: 867 | AE18: 3343.4 | AF18: 1008.97 | AG18: 2334.4 | AJ18: 1052 | AK18: 1361 | AM18: 山东 | AN18: 1467 | AO18: 942 | AP18: 713 | AQ18: 474 | AR18: 117 | AS18: 80 | AT18: 60 | AU18: 20 | AV18: =AR18*10000/(AN18*8760) -> 0.091044065 | AW18: =AS18*10000/(AO18*8760) -> 0.096947135 | AX18: =AT18*10000/(AP18*8760) -> 0.096063325 | AY18: =AU18*10000/(AQ18*8760) -> 0.048166773 | AZ18: =AR18*10000/AN18 -> 797.54601 | BA18: =AS18*10000/AO18 -> 849.2569 | BB18: =AT18*10000/AP18 -> 841.51473 | BC18: =AU18*10000/AQ18 -> 421.94093
... A26: 四川 | B26: 189 | C26: 169 | D26: 1 | E26: 0 | F26: =B26-C26 -> 20 | G26: =D26-E26 -> 1 | H26: =B26-D26 -> 188 | J26: 四川省 | K26: =AJ26-R26 -> 116 | L26: =AK26-S26 -> 168 | M26: =C26-E26 -> 169 | N26: =C26 -> 169 | O26: =AF26-AC26 -> 169.01 | P26: =AF26 -> 169.01 | R26: 19 | S26: 13 | T26: =F26-G26 -> 19 | U26: =B26-C26 -> 20 | V26: =AG26-AD26 -> 22.1 | W26: =AG26 -> 26.9 | AA26: 四川 | AB26: 4.8 | AC26: 0 | AD26: 4.8 | AE26: 195.9 | AF26: 169.01 | AG26: 26.9 | AJ26: 135 | AK26: 181 | AM26: 四川 | AN26: 22 | AO26: 19 | AP26: 13 | AQ26: 19 | AR26: 2 | AS26: 2 | AT26: 1 | AU26: 1 | AV26: =AR26*10000/(AN26*8760) -> 0.1037775 | AW26: =AS26*10000/(AO26*8760) -> 0.12016342 | AX26: =AT26*10000/(AP26*8760) -> 0.087811732 | AY26: =AU26*10000/(AQ26*8760) -> 0.060081711 | AZ26: =AR26*10000/AN26 -> 909.09091 | BA26: =AS26*10000/AO26 -> 1052.6316 | BB26: =AT26*10000/AP26 -> 769.23077 | BC26: =AU26*10000/AQ26 -> 526.31579
A27: 贵州 | B27: 537 | C27: 518 | D27: 27 | E27: 27 | F27: =B27-C27 -> 19 | G27: =D27-E27 -> 0 | H27: =B27-D27 -> 510 | J27: 贵州省 | K27: =AJ27-R27 -> 135 | L27: =AK27-S27 -> 161 | M27: =C27-E27 -> 491 | N27: =C27 -> 518 | O27: =AF27-AC27 -> 970.67 | P27: =AF27 -> 1117.6 | S27: 17 | T27: =F27-G27 -> 19 | U27: =B27-C27 -> 19 | V27: =AG27-AD27 -> 19 | W27: =AG27 -> 19.4 | AA27: 贵州 | AB27: 147.3 | AC27: 146.93 | AD27: 0.4 | AE27: 1137 | AF27: 1117.6 | AG27: 19.4 | AJ27: 135 | AK27: 178 | AM27: 贵州 | AN27: 19 | AO27: 19 | AP27: 17 | AR27: 1 | AS27: 1 | AT27: 1 | AV27: =AR27*10000/(AN27*8760) -> 0.060081711 | AW27: =AS27*10000/(AO27*8760) -> 0.060081711 | AX27: =AT27*10000/(AP27*8760) -> 0.067150148 | AZ27: =AR27*10000/AN27 -> 526.31579 | BA27: =AS27*10000/AO27 -> 526.31579 | BB27: =AT27*10000/AP27 -> 588.23529
A28: 云南 | B28: 389 | C28: 352 | D28: 14 | E28: 2 | F28: =B28-C28 -> 37 | G28: =D28-E28 -> 12 | H28: =B28-D28 -> 375 | J28: 云南省 | K28: =AJ28-R28 -> 237.5 | L28: =AK28-S28 -> 312 | M28: =C28-E28 -> 350 | N28: =C28 -> 352 | O28: =AF28-AC28 -> 295.43 | P28: =AF28 -> 349.91 | R28: 0.5 | S28: 14 | T28: =F28-G28 -> 25 | U28: =B28-C28 -> 37 | V28: =AG28-AD28 -> 38.4 | W28: =AG28 -> 47.2 | AA28: 云南 | AB28: 63.3 | AC28: 54.48 | AD28: 8.8 | AE28: 397.1 | AF28: 349.91 | AG28: 47.2 | AJ28: 238 | AK28: 326 | AM28: 云南 | AN28: 38 | AO28: 25 | AP28: 14 | AQ28: 0.5 | AR28: 3 | AS28: 2 | AT28: 1 | AU28: 0.3 | AV28: =AR28*10000/(AN28*8760) -> 0.090122567 | AW28: =AS28*10000/(AO28*8760) -> 0.091324201 | AX28: =AT28*10000/(AP28*8760) -> 0.081539465 | AY28: =AU28*10000/(AQ28*8760) -> 0.68493151 | AZ28: =AR28*10000/AN28 -> 789.47368 | BA28: =AS28*10000/AO28 -> 800 | BB28: =AT28*10000/AP28 -> 714.28571 | BC28: =AU28*10000/AQ28 -> 6000
A29: 西藏 | B29: 128 | C29: 128 | D29: 18 | E29: 18 | F29: =B29-C29 -> 0 | G29: =D29-E29 -> 0 | H29: =B29-D29 -> 110 | J29: 西藏自治区 | K29: =AJ29-R29 -> 79 | L29: =AK29-S29 -> 98 | M29: =C29-E29 -> 110 | N29: =C29 -> 128 | O29: =AF29-AC29 -> 136.26 | P29: =AF29 -> 136.51 | T29: =F29-G29 -> 0 | U29: =B29-C29 -> 0 | V29: =AG29-AD29 -> 0 | W29: =AG29 -> 2.2 | AA29: 西藏 | AB29: 2.4 | AC29: 0.25 | AD29: 2.2 | AE29: 138.9 | AF29: 136.51 | AG29: 2.2 | AJ29: 79 | AK29: 98 | AM29: 西藏
A30: 陕西 | B30: 953 | C30: 781 | D30: 13 | E30: 3 | F30: =B30-C30 -> 172 | G30: =D30-E30 -> 10 | H30: =B30-D30 -> 940 | J30: 山西省 | K30: =AJ30-R30 -> 484 | L30: =AK30-S30 -> 640 | M30: =C30-E30 -> 778 | N30: =C30 -> 781 | O30: =AF30-AC30 -> 893.42 | P30: =AF30 -> 1102.82 | R30: 51 | S30: 76 | T30: =F30-G30 -> 162 | U30: =B30-C30 -> 172 | V30: =AG30-AD30 -> 190.7 | W30: =AG30 -> 210.9 | AA30: 陕西 | AB30: 229.6 | AC30: 209.4 | AD30: 20.2 | AE30: 1313.7 | AF30: 1102.82 | AG30: 210.9 | AJ30: 535 | AK30: 716 | AM30: 陕西 | AN30: 194 | AO30: 102 | AP30: 76 | AQ30: 51 | AR30: 16 | AS30: 9 | AT30: 6 | AU30: 2 | AV30: =AR30*10000/(AN30*8760) -> 0.094148661 | AW30: =AS30*10000/(AO30*8760) -> 0.10072522 | AX30: =AT30*10000/(AP30*8760) -> 0.090122567 | AY30: =AU30*10000/(AQ30*8760) -> 0.044766765 | AZ30: =AR30*10000/AN30 -> 824.74227 | BA30: =AS30*10000/AO30 -> 882.35294 | BB30: =AT30*10000/AP30 -> 789.47368 | BC30: =AU30*10000/AQ30 -> 392.15686
A31: 甘肃 | B31: 911 | C31: 838 | D31: 4 | E31: 2 | F31: =B31-C31 -> 73 | G31: =D31-E31 -> 2 | H31: =B31-D31 -> 907 | J31: 甘肃省 | K31: =AJ31-R31 -> 768 | L31: =AK31-S31 -> 790 | M31: =C31-E31 -> 836 | N31: =C31 -> 838 | O31: =AF31-AC31 -> 891.32 | P31: =AF31 -> 1047.65 | R31: 18 | S31: 49 | T31: =F31-G31 -> 71 | U31: =B31-C31 -> 73 | V31: =AG31-AD31 -> 74 | W31: =AG31 -> 77.1 | AA31: 甘肃 | AB31: 159.5 | AC31: 156.33 | AD31: 3.1 | AE31: 1124.8 | AF31: 1047.65 | AG31: 77.1 | AJ31: 786 | AK31: 839 | AM31: 甘肃 | AN31: 74 | AO31: 71 | AP31: 49 | AQ31: 18 | AR31: 9 | AS31: 6 | AT31: 2 | AU31: 1 | AV31: =AR31*10000/(AN31*8760) -> 0.13883747 | AW31: =AS31*10000/(AO31*8760) -> 0.096469226 | AX31: =AT31*10000/(AP31*8760) -> 0.04659398 | AY31: =AU31*10000/(AQ31*8760) -> 0.063419584 | AZ31: =AR31*10000/AN31 -> 1216.2162 | BA31: =AS31*10000/AO31 -> 845.07042 | BB31: =AT31*10000/AP31 -> 408.16327 | BC31: =AU31*10000/AQ31 -> 555.55556
A32: 青海 | B32: 1102 | C32: 1086 | D32: 1 | E32: 0 | F32: =B32-C32 -> 16 | G32: =D32-E32 -> 1 | H32: =B32-D32 -> 1101 | J32: 青海省 | K32: =AJ32-R32 -> 786 | L32: =AK32-S32 -> 952 | M32: =C32-E32 -> 1086 | N32: =C32 -> 1086 | O32: =AF32-AC32 -> 1532.09 | P32: =AF32 -> 1594.77 | R32: 5 | S32: 10 | T32: =F32-G32 -> 15 | U32: =B32-C32 -> 16 | V32: =AG32-AD32 -> 15.7 | W32: =AG32 -> 16 | AA32: 青海 | AB32: 63 | AC32: 62.68 | AD32: 0.3 | AE32: 1610.8 | AF32: 1594.77 | AG32: 16 | AJ32: 791 | AK32: 962 | AM32: 青海 | AN32: 17 | AO32: 15 | AP32: 10 | AQ32: 5 | AR32: 2 | AS32: 2 | AT32: 1 | AU32: 0.3 | AV32: =AR32*10000/(AN32*8760) -> 0.1343003 | AW32: =AS32*10000/(AO32*8760) -> 0.152207 | AX32: =AT32*10000/(AP32*8760) -> 0.11415525 | AY32: =AU32*10000/(AQ32*8760) -> 0.068493151 | AZ32: =AR32*10000/AN32 -> 1176.4706 | BA32: =AS32*10000/AO32 -> 1333.3333 | BB32: =AT32*10000/AP32 -> 1000 | BC32: =AU32*10000/AQ32 -> 600
A33: 宁夏 | B33: 983 | C33: 908 | D33: 65 | E33: 64 | F33: =B33-C33 -> 75 | G33: =D33-E33 -> 1 | H33: =B33-D33 -> 918 | J33: 宁夏回族自治区 | K33: =AJ33-R33 -> 587 | L33: =AK33-S33 -> 761 | M33: =C33-E33 -> 844 | N33: =C33 -> 908 | O33: =AF33-AC33 -> 1121.96 | P33: =AF33 -> 1303.36 | R33: 33 | S33: 55 | T33: =F33-G33 -> 74 | U33: =B33-C33 -> 75 | V33: =AG33-AD33 -> 75.2 | W33: =AG33 -> 80.6 | AA33: 宁夏 | AB33: 186.8 | AC33: 181.4 | AD33: 5.4 | AE33: 1384 | AF33: 1303.36 | AG33: 80.6 | AJ33: 620 | AK33: 816 | AM33: 宁夏 | AN33: 75 | AO33: 74 | AP33: 55 | AQ33: 33 | AR33: 10 | AS33: 8 | AT33: 4 | AU33: 3 | AV33: =AR33*10000/(AN33*8760) -> 0.152207 | AW33: =AS33*10000/(AO33*8760) -> 0.12341108 | AX33: =AT33*10000/(AP33*8760) -> 0.083022001 | AY33: =AU33*10000/(AQ33*8760) -> 0.1037775 | AZ33: =AR33*10000/AN33 -> 1333.3333 | BA33: =AS33*10000/AO33 -> 1081.0811 | BB33: =AT33*10000/AP33 -> 727.27273 | BC33: =AU33*10000/AQ33 -> 909.09091
A34: 新疆自治区 | B34: 1042 | C34: 1027 | D34: 1 | E34: 0 | F34: =B34-C34 -> 15 | G34: =D34-E34 -> 1 | H34: =B34-D34 -> 1041 | J34: 新疆维吾尔自治区 | K34: =AJ34-R34 -> 933 | L34: =AK34-S34 -> 976 | M34: =C34-E34 -> 1027 | N34: =C34 -> 1027 | O34: =AF34-AC34 -> 1205.48 | P34: =AF34 -> 1254.78 | R34: 1 | S34: 2 | T34: =F34-G34 -> 14 | U34: =B34-C34 -> 15 | V34: =AG34-AD34 -> 16.7 | W34: =AG34 -> 17.2 | AA34: 新疆 | AB34: 49.8 | AC34: 49.3 | AD34: 0.5 | AE34: 1272 | AF34: 1254.78 | AG34: 17.2 | AJ34: 934 | AK34: 978 | AM34: 新疆 | AN34: 16 | AO34: 15 | AP34: 2 | AQ34: 1 | AR34: 2 | AS34: 1 | AT34: 0.1 | AU34: 0.01 | AV34: =AR34*10000/(AN34*8760) -> 0.14269406 | AW34: =AS34*10000/(AO34*8760) -> 0.076103501 | AX34: =AT34*10000/(AP34*8760) -> 0.057077626 | AY34: =AU34*10000/(AQ34*8760) -> 0.011415525 | AZ34: =AR34*10000/AN34 -> 1250 | BA34: =AS34*10000/AO34 -> 666.66667 | BB34: =AT34*10000/AP34 -> 500 | BC34: =AU34*10000/AQ34 -> 100
A35: 新疆兵团 | B35: 39 | C35: 39 | D35: 0 | E35: 0 | F35: =B35-C35 -> 0 | G35: =D35-E35 -> 0 | H35: =B35-D35 -> 39 | J35: 新疆建设兵团 | K35: =AJ35-R35 -> 0 | L35: =AK35-S35 -> 0 | M35: =C35-E35 -> 39 | N35: =C35 -> 39 | O35: =AF35-AC35 -> 77.2 | P35: =AF35 -> 77.2 | T35: =F35-G35 -> 0 | U35: =B35-C35 -> 0 | V35: =AG35-AD35 -> 0 | W35: =AG35 -> 0 | AA35: 新疆兵团 | AB35: 0 | AC35: 0 | AD35: 0 | AE35: 77.2 | AF35: 77.2 | AG35: 0
K37: =K3-SUM(K4:K34) -> 0.5 | L37: =L3-SUM(L4:L34) -> 0 | M37: =M3-SUM(M4:M34) -> 38 | N37: =N3-SUM(N4:N34) -> 37 | O37: =O3-SUM(O4:O34) -> 77.25 | P37: =P3-SUM(P4:P34) -> 77.24 | R37: =R3-SUM(R4:R34) -> 1.5 | S37: =S3-SUM(S4:S34) -> 0 | T37: =T3-SUM(T4:T34) -> -1 | U37: =U3-SUM(U4:U34) -> 0 | V37: =V3-SUM(V4:V34) -> -0.3 | W37: =W3-SUM(W4:W34) -> -0.1

Sheet 户用光伏安装数据
B1: 201901 | C1: 201902 | D1: 201903 | E1: 201904 | F1: 201905 | G1: 201906 | H1: 201907 | I1: 201908 | J1: 201909 | K1: 201910 | L1: 201911 | M1: 201912 | N1: 202001 | O1: 202002 | P1: 202003 | Q1: 202004 | R1: 202005 | S1: 202006 | T1: 202007 | U1: 202008 | V1: 202009 | W1: 202010 | X1: 202011 | Y1: 202012 | Z1: 202101 | AA1: 202102 | AB1: 202103 | AC1: 202104 | AD1: 202105 | AE1: 202106 | AF1: 202107 | AG1: 202108 | AH1: 202109 | AI1: 202110 | AJ1: 202111 | AK1: 202112 | AN1: 1 | AO1: 2 | AP1: 3 | AQ1: 4 | AR1: 5 | AS1: 6 | AT1: 7 | AU1: 8 | AV1: 9 | AW1: 10 | AX1: 11 | AY1: 12
A2: 北京 | G2: 0.35 | H2: 0.063897 | I2: 0.2317335 | J2: 0.247972 | K2: 0.888244 | N2: 0.040062 | O2: 0 | P2: 0.003069 | Q2: 0.021942 | R2: 0.058974 | S2: 0.090849 | T2: 0.065412 | U2: =U38-T38 -> 0.138801 | V2: 0.1535 | W2: 0.1281 | X2: 0.2161 | Z2: 0.1786 | AA2: 0.0738 | AB2: 0.1198 | AC2: 0.2117 | AD2: 0.3528 | AE2: 0.3831 | AF2: 0.8349 | AG2: 0.4129 | AH2: 0.9094 | AI2: 0.5307 | AJ2: 1.6774 | AK2: 5.2768 | AS2: 18.5208 | AT2: 19.7179 | AU2: 26.5132 | AV2: 37.5837 | AW2: 44.478115
A3: 天津 | G3: 0.04 | H3: 0.411 | I3: 0.056102 | J3: 0.025725 | K3: 0.150136 | N3: 0.0008 | O3: 0 | P3: 0 | Q3: 0.00338 | R3: 0.0024 | S3: 0.0096 | T3: 0.14733 | U3: =U39-T39 -> 0.155124 | V3: 0.1373 | W3: 0.1514 | X3: 0.4185 | Z3: 0.0438 | AA3: 0.0489 | AB3: 0.0628 | AC3: 0.1516 | AD3: 0.2041 | AE3: 0.2821 | AF3: 0.1881 | AG3: 0.2924 | AH3: 0.3213 | AI3: 0.2483 | AJ3: 0.3474 | AK3: 0.5951 | AN3: 4.7263237 | AO3: 0.4216055 | AP3: 4.610248 | AQ3: 17.147776 | AR3: 25.439407 | AS3: 32.997844 | AT3: 38.548428 | AU3: 45.48621 | AV3: 57.9509 | AW3: 56.7659 | AX3: 173.2052
A4: 河北 | G4: 9.108782 | H4: 7.613066 | I4: 12.893203 | J4: 17.390082 | K4: 12.927215 | N4: 2.6241187 | O4: 0.1307875 | P4: 1.5698509 | Q4: 9.6245205 | R4: 12.905168 | S4: 16.837642 | T4: 17.363186 | U4: =U40-T40 -> 23.966927 | V4: 31.2149 | W4: 35.1162 | X4: 64.0835 | Z4: 5.9675 | AA4: 4.1371 | AB4: 17.1836 | AC4: 37.2244 | AD4: 37.7382 | AE4: 45.6523 | AF4: 44.8371 | AG4: 49.7806 | AH4: 57.8999 | AI4: 46.1181 | AJ4: 64.4772 | AK4: 123.0571 | AN4: 12.035 | AO4: 13.3488 | AP4: 28.1457 | AQ4: 55.8136 | AR4: 63.3849 | AS4: 67.2034 | AT4: 65.5694 | AU4: 67.8232 | AV4: 69.9044 | AW4: 64.3601 | AX4: 88.13 | AY4: 157.9777
A5: 其中：河北南网 | G5: 6.958782 | H5: 7.2 | I5: 10.8374 | J5: 15.113119 | K5: 11.0172 | N5: 2.5451667 | O5: 0.1240625 | P5: 1.3597949 | Q5: 8.960305 | R5: 11.930059 | S5: 15.475212 | T5: 15.895472 | U5: =U41-T41 -> 22.714628 | V5: 28.7508 | W5: 32.0827 | X5: 55.7591 | Z5: 5.4018 | AA5: 3.4495 | AB5: 16.2044 | AC5: 34.4905 | AD5: 33.5382 | AE5: 41.2945 | AF5: 39.2908 | AG5: 43.1765 | AH5: 51.5353 | AI5: 40.9591 | AJ5: 58.0853 | AK5: 109.535
A6: 冀北电网 | G6: 2.15 | H6: 0.413662 | I6: 2.055803 | J6: 2.276963 | K6: 1.910015 | N6: 0.078952 | O6: 0.006725 | P6: 0.210056 | Q6: 0.6642155 | R6: 0.975109 | S6: 1.36243 | T6: 1.4677135 | U6: =U42-T42 -> 1.252199 | V6: 2.4642 | W6: 3.0335 | X6: 8.3245 | Z6: 0.5657 | AA6: 0.6875 | AB6: 0.9792 | AC6: 2.7339 | AD6: 4.2 | AE6: 4.3578 | AF6: 5.5462 | AG6: 6.6041 | AH6: 6.3646 | AI6: 5.159 | AJ6: 6.3918 | AK6: 13.522
A7: 山西 | G7: 1.679881 | H7: 1.289771 | I7: 2.179311 | J7: 4.2711197 | K7: 7.5039975 | N7: 0.097213 | O7: 0.003 | P7: 0.0946615 | Q7: 0.4809445 | R7: 1.506641 | S7: 2.857445 | T7: 3.8275771 | U7: =U43-T43 -> 4.6087179 | V7: 5.8826 | W7: 6.0878 | X7: 20.3292 | Z7: 0.8123 | AA7: 0.3844 | AB7: 1.0245 | AC7: 2.3394 | AD7: 4.2833 | AE7: 5.8873 | AF7: 6.7127 | AG7: 7.0306 | AH7: 7.238 | AI7: 5.9761 | AJ7: 9.9275 | AK7: 22.6447
A8: 内蒙古 | G8: 0.204246 | H8: 0.11902 | I8: 0.044382 | J8: 0.177113 | K8: 1.697067 | N8: 0.065763 | O8: 0 | P8: 0.0008 | Q8: 0.035856 | R8: 0.01832 | S8: 0.128705 | T8: 0.04712 | U8: =U44-T44 -> 0.092936 | V8: 0.3413 | W8: 0.1561 | X8: 1.0987 | Z8: 0.0726 | AA8: 0.106 | AB8: 0.0087 | AC8: 0.1003 | AD8: 0.1175 | AE8: 0.0634 | AF8: 0.2646 | AG8: 0.1491 | AH8: 0.1323 | AI8: 0.552 | AJ8: 0.7906 | AK8: 2.9517
A9: 其中：蒙西 | G9: 0.0016 | H9: 0.003 | I9: 0.0084 | J9: 0.0015 | K9: 0.026671 | N9: 0.0535 | O9: 0 | P9: 0 | Q9: 0.0091 | R9: 0.00105 | S9: 0.05856 | T9: 0.00827 | U9: =U45-T45 -> 0.01592 | V9: 0.0968 | W9: 0.0285 | X9: 0.4838 | Z9: 0.0616 | AA9: 0.0705 | AB9: 0.0065 | AC9: 0.088 | AD9: 0.0163 | AE9: 0.0406 | AF9: 0.2371 | AG9: 0.0325 | AH9: 0.0654 | AI9: 0.1404 | AJ9: 0.1982 | AK9: 0.281
A10: 蒙东 | G10: 0.202646 | H10: 0.11602 | I10: 0.035982 | J10: 0.175613 | K10: 1.670396 | N10: 0.012263 | O10: 0 | P10: 0.0008 | Q10: 0.026756 | R10: 0.01727 | S10: 0.070145 | T10: 0.03885 | U10: =U46-T46 -> 0.077016 | V10: 0.2445 | W10: 0.1276 | X10: 0.6149 | Z10: 0.011 | AA10: 0.0355 | AB10: 0.0022 | AC10: 0.0123 | AD10: 0.1013 | AE10: 0.0228 | AF10: 0.0274 | AG10: 0.1166 | AH10: 0.0669 | AI10: 0.4116 | AJ10: 0.5924 | AK10: 2.6707
A11: 辽宁 | G11: 0.8758 | H11: 0.4055 | I11: 0.701206 | J11: 1.007487 | K11: 1.357455 | N11: 0.011195 | O11: 0.00417 | P11: 0.00749 | Q11: 0.0783 | R11: 0.254865 | S11: 0.7939015 | T11: 1.488858 | U11: =U47-T47 -> 1.3783205 | V11: 1.7548 | W11: 2.3567 | X11: 6.5393 | Z11: 0.101 | AA11: 0.0711 | AB11: 0.0685 | AC11: 0.5611 | AD11: 4.2 | AE11: 2.0447 | AF11: 1.847 | AG11: 2.5361 | AH11: 3.14 | AI11: 1.028 | AJ11: 4.1059 | AK11: 11.6456
A12: 吉林 | G12: 0.413608 | H12: 0.133081 | I12: 0.310494 | J12: 0.617114 | K12: 0.787384 | N12: 0.00364 | O12: 0.145563 | P12: 0.019536 | Q12: 0.073166 | R12: 0.425222 | S12: 0.137029 | T12: 0.3465525 | U12: =U48-T48 -> 0.6061915 | V12: 0.6826 | W12: 0.6614 | X12: 2.9643 | Z12: 0.0559 | AA12: 0.0268 | AB12: 0.0204 | AC12: 0.1176 | AD12: 0.0856 | AE12: 0.2453 | AF12: 0.314 | AG12: 0.4064 | AH12: 0.3774 | AI12: 0.3504 | AJ12: 0.3849 | AK12: 2.6022
A13: 黑龙江 | G13: 0.068 | H13: 0.0384 | I13: 0.1291 | J13: 0.519546 | K13: 0.3276 | N13: 0.012 | O13: 0.0009 | P13: 0.0005 | Q13: 0.05426 | R13: 0.043028 | S13: 0.051908 | T13: 0.068205 | U13: =U49-T49 -> 0.103619 | V13: 0.0601 | W13: 0.2 | X13: 1.0297 | Z13: 0.0278 | AA13: 0 | AB13: 0.045 | AC13: 0.0311 | AD13: 0.0412 | AE13: 0.0694 | AF13: 0.0718 | AG13: 0.131 | AH13: 0.0915 | AI13: 0.2171 | AJ13: 0.2662 | AK13: 1.1844
A14: 上海 | G14: 0.22 | H14: 0.2055 | I14: 0.2272 | J14: 0.1506 | K14: 0.3345 | N14: 0.046544 | O14: 0 | P14: 0.018565 | Q14: 0.0459022 | R14: 0.0726795 | S14: 0.1440565 | T14: 0.1641623 | U14: =U50-T50 -> 0.1490905 | V14: 0.184 | W14: 0.1204 | X14: 0.3435 | Z14: 0.0617 | AA14: 0.0365 | AB14: 0.0453 | AC14: 0.1083 | AD14: 0.1375 | AE14: 0.1329 | AF14: 0.1495 | AG14: 0.1676 | AH14: 0.1876 | AI14: 0.0716 | AJ14: 0.2706 | AK14: 0.4717
A15: 江苏 | G15: 2.07776 | H15: 1.8031639 | I15: 3.427096 | J15: 3.6969945 | K15: 3.6943895 | N15: 0.3323056 | O15: 0.009638 | P15: 0.386241 | Q15: 1.3082675 | R15: 1.754988 | S15: 1.97121 | T15: 2.2841789 | U15: =U51-T51 -> 2.2189055 | V15: 3.0691 | W15: 2.9263 | X15: 6.9188 | Z15: 0.3055 | AA15: 0.6522 | AB15: 1.891 | AC15: 3.0393 | AD15: 2.6704 | AE15: 2.859 | AF15: 4.0384 | AG15: 3.0402 | AH15: 3.608 | AI15: 3.6764 | AJ15: 4.9271 | AK15: 13.0681
A16: 浙江 | G16: 3.82102 | H16: 2.9892 | I16: 3.4746 | J16: 4.1095 | K16: 5.372 | N16: 1.0887465 | O16: 0.0136165 | P16: 0.7763235 | Q16: 1.7573965 | R16: 2.052077 | S16: 2.6506145 | T16: 2.5063612 | U16: =U52-T52 -> 2.7453643 | V16: 2.2441 | W16: 2.2235 | X16: 5.7009 | Z16: 0.8739 | AA16: 0.3364 | AB16: 0.7451 | AC16: 1.7078 | AD16: 1.3473 | AE16: 1.7208 | AF16: 1.6721 | AG16: 1.7316 | AH16: 2.7864 | AI16: 1.1857 | AJ16: 1.5615 | AK16: 2.6349
... A35: 海南 | G35: 0.012713 | H35: 0.387322 | I35: 0.0353345 | J35: 0.125937 | K35: 0.2809755 | N35: 0.016884 | O35: 0.023 | P35: 0.014303 | Q35: 0.00602 | R35: 0.019539 | S35: 0.02977 | T35: 0.038793 | U35: =U71-T71 -> 0.085791 | V35: 0.0409 | W35: 0.1034 | X35: 0.4566 | Z35: 0.0272 | AA35: 0.0863 | AB35: 0.0161 | AC35: 0.0424 | AD35: 0.0668 | AE35: 0.0333 | AF35: 0.0318 | AG35: 0.0749 | AH35: 0.0908 | AI35: 0.1088 | AJ35: 0.1126 | AK35: 0.6128
B37: 201901 | C37: 201902 | D37: 201903 | E37: 201904 | F37: 201905 | G37: 201906 | H37: 201907 | I37: 201908 | J37: 201909 | K37: 201910 | L37: 201911 | M37: 201912 | N37: 202001 | O37: 202002 | P37: 202003 | Q37: 202004 | R37: 202005 | S37: 202006 | T37: 202007 | U37: 202008 | V37: 202009 | W37: 202010 | X37: 202011 | Y37: 202012 | Z37: 202101 | AA37: 202102 | AB37: 202103 | AC37: 202104 | AD37: 202105 | AE37: 202106 | AF37: 202107 | AG37: 202108 | AH37: 202109 | AI37: 202110 | AJ37: 202111 | AK37: 202112
A38: 北京 | F38: 3.15 | G38: =H38-H2 -> 3.500527 | H38: 3.564424 | I38: 4.0771135 | J38: =I38+J2 -> 4.3250855 | K38: =J38+K2 -> 5.2133295 | N38: =M38+N2 -> 0.040062 | O38: =N38+O2 -> 0.040062 | P38: =O38+P2 -> 0.043131 | Q38: 0.065073 | R38: 0.124047 | S38: 0.216487 | T38: 0.284999 | U38: =V38-V2 -> 0.4238 | V38: 0.5773 | W38: 0.7053 | X38: 0.9214 | Z38: =Z2 -> 0.1786 | AA38: =Z38+AA2 -> 0.2524 | AB38: =AA38+AB2 -> 0.3722 | AC38: =AB38+AC2 -> 0.5839 | AD38: =AC38+AD2 -> 0.9367 | AE38: 1.3199 | AF38: 2.1548 | AG38: 2.5677 | AH38: 3.4891 | AI38: 4.0626 | AJ38: 5.8045 | AK38: 11.5264
A39: 天津 | F39: 0.13 | G39: =H39-H3 -> 0.169 | H39: 0.58 | I39: 0.6354775 | J39: =I39+J3 -> 0.6612025 | K39: =J39+K3 -> 0.8113385 | N39: =M39+N3 -> 0.0008 | O39: =N39+O3 -> 0.0008 | P39: =O39+P3 -> 0.0008 | Q39: 0.006275 | R39: 0.008675 | S39: 0.035075 | T39: 0.338776 | U39: =V39-V3 -> 0.4939 | V39: 0.6312 | W39: 0.7826 | X39: 1.2011 | Z39: =Z3 -> 0.0438 | AA39: =Z39+AA3 -> 0.0927 | AB39: =AA39+AB3 -> 0.1555 | AC39: =AB39+AC3 -> 0.3071 | AD39: =AC39+AD3 -> 0.5112 | AE39: 0.7933 | AF39: 0.9815 | AG39: 1.2739 | AH39: 1.5951 | AI39: 1.8435 | AJ39: 2.1909 | AK39: 2.7859
A40: 河北 | F40: 23.74884 | G40: =H40-H4 -> 32.85658 | H40: 40.469646 | I40: 53.362828 | J40: =I40+J4 -> 70.75291 | K40: =J40+K4 -> 83.680125 | N40: =M40+N4 -> 2.6241187 | O40: =N40+O4 -> 2.7549062 | P40: =O40+P4 -> 4.3247571 | Q40: 13.949278 | R40: 26.854446 | S40: 43.692087 | T40: 61.055273 | U40: =V40-V4 -> 85.0222 | V40: 116.2371 | W40: 151.3534 | X40: 215.4475 | Z40: =Z4 -> 5.9675 | AA40: =Z40+AA4 -> 10.1046 | AB40: =AA40+AB4 -> 27.2882 | AC40: =AB40+AC4 -> 64.5126 | AD40: =AC40+AD4 -> 102.2508 | AE40: 147.9031 | AF40: 192.7401 | AG40: 242.5224 | AH40: 300.4223 | AI40: 346.5404 | AJ40: 411.0176 | AK40: 534.0746
A41: 其中：河北南网 | F41: 19.00884 | G41: =H41-H5 -> 25.97 | H41: 33.17 | I41: 44.0044 | J41: =I41+J5 -> 59.117519 | K41: =J41+K5 -> 70.134719 | N41: =M41+N5 -> 2.5451667 | O41: =N41+O5 -> 2.6692292 | P41: =O41+P5 -> 4.0290241 | Q41: 12.989329 | R41: 24.919388 | S41: 40.3946 | T41: 56.290072 | U41: =V41-V5 -> 79.0047 | V41: 107.7555 | W41: 139.8382 | X41: 195.6079 | Z41: =Z5 -> 5.4018 | AA41: =Z41+AA5 -> 8.8513 | AB41: =AA41+AB5 -> 25.0557 | AC41: =AB41+AC5 -> 59.5462 | AD41: =AC41+AD5 -> 93.0844 | AE41: 134.3789 | AF41: 173.6697 | AG41: 216.8479 | AH41: 268.3832 | AI41: 309.3423 | AJ41: 367.4277 | AK41: 476.9627
A42: 冀北电网 | F42: 4.74 | G42: =H42-H6 -> 6.888963 | H42: 7.302625 | I42: 9.358428 | J42: =I42+J6 -> 11.635391 | K42: =J42+K6 -> 13.545406 | N42: =M42+N6 -> 0.078952 | O42: =N42+O6 -> 0.085677 | P42: =O42+P6 -> 0.295733 | Q42: 0.9599485 | R42: 1.9350575 | S42: 3.2974875 | T42: 4.765201 | U42: =V42-V6 -> 6.0174 | V42: 8.4816 | W42: 11.5151 | X42: 19.8396 | Z42: =Z6 -> 0.5657 | AA42: =Z42+AA6 -> 1.2532 | AB42: =AA42+AB6 -> 2.2324 | AC42: =AB42+AC6 -> 4.9663 | AD42: =AC42+AD6 -> 9.1663 | AE42: 13.5242 | AF42: 19.0704 | AG42: 25.6745 | AH42: 32.0391 | AI42: 37.1981 | AJ42: 43.5899 | AK42: 57.1119
A43: 山西 | F43: 10.16097 | G43: =H43-H7 -> 11.840851 | H43: 13.130622 | I43: 15.414288 | J43: =I43+J7 -> 19.685407 | K43: =J43+K7 -> 27.189405 | N43: =M43+N7 -> 0.097213 | O43: =N43+O7 -> 0.100213 | P43: =O43+P7 -> 0.1948745 | Q43: 0.675819 | R43: 2.18246 | S43: 5.039905 | T43: 8.8674821 | U43: =V43-V7 -> 13.4762 | V43: 19.3588 | W43: 25.476 | X43: 45.8052 | Z43: =Z7 -> 0.8123 | AA43: =Z43+AA7 -> 1.1967 | AB43: =AA43+AB7 -> 2.2212 | AC43: =AB43+AC7 -> 4.5606 | AD43: =AC43+AD7 -> 8.8439 | AE43: 14.7313 | AF43: 21.4439 | AG43: 28.4745 | AH43: 35.7125 | AI43: 41.6886 | AJ43: 51.6161 | AK43: 74.2915
A44: 内蒙古 | F44: 1.702584 | G44: =H44-H8 -> 1.90683 | H44: 2.02585 | I44: 2.070232 | J44: =I44+J8 -> 2.247345 | K44: =J44+K8 -> 3.944412 | N44: =M44+N8 -> 0.065763 | O44: =N44+O8 -> 0.065763 | P44: =O44+P8 -> 0.066563 | Q44: 0.102419 | R44: 0.120739 | S44: 0.251244 | T44: 0.298364 | U44: =V44-V8 -> 0.3913 | V44: 0.7326 | W44: 0.8908 | X44: 1.9904 | Z44: =Z8 -> 0.0726 | AA44: =Z44+AA8 -> 0.1786 | AB44: =AA44+AB8 -> 0.1873 | AC44: =AB44+AC8 -> 0.2876 | AD44: =AC44+AD8 -> 0.4051 | AE44: 0.4686 | AF44: 0.7449 | AG44: 0.8953 | AH44: 1.0376 | AI44: 1.6026 | AJ44: 2.3984 | AK44: 5.3501
A45: 其中：蒙西 | F45: 0.129183 | G45: =H45-H9 -> 0.130783 | H45: 0.133783 | I45: 0.142183 | J45: =I45+J9 -> 0.143683 | K45: =J45+K9 -> 0.170354 | N45: =M45+N9 -> 0.0535 | O45: =N45+O9 -> 0.0535 | P45: =O45+P9 -> 0.0535 | Q45: 0.0626 | R45: 0.06365 | S45: 0.12401 | T45: 0.13228 | U45: =V45-V9 -> 0.1482 | V45: 0.245 | W45: 0.2756 | X45: 0.7594 | Z45: =Z9 -> 0.0616 | AA45: =Z45+AA9 -> 0.1321 | AB45: =AA45+AB9 -> 0.1386 | AC45: =AB45+AC9 -> 0.2266 | AD45: =AC45+AD9 -> 0.2429 | AE45: 0.2835 | AF45: 0.5323 | AG45: 0.5661 | AH45: 0.6416 | AI45: 0.795 | AJ45: 0.9962 | AK45: 1.2772
A46: 蒙东 | F46: 1.573401 | G46: =H46-H10 -> 1.776047 | H46: 1.892067 | I46: 1.928049 | J46: =I46+J10 -> 2.103662 | K46: =J46+K10 -> 3.774058 | N46: =M46+N10 -> 0.012263 | O46: =N46+O10 -> 0.012263 | P46: =O46+P10 -> 0.013063 | Q46: 0.039819 | R46: 0.057089 | S46: 0.127234 | T46: 0.166084 | U46: =V46-V10 -> 0.2431 | V46: 0.4876 | W46: 0.6152 | X46: 1.231 | Z46: =Z10 -> 0.011 | AA46: =Z46+AA10 -> 0.0465 | AB46: =AA46+AB10 -> 0.0487 | AC46: =AB46+AC10 -> 0.061 | AD46: =AC46+AD10 -> 0.1623 | AE46: 0.1851 | AF46: 0.2126 | AG46: 0.3291 | AH46: 0.396 | AI46: 0.8076 | AJ46: 1.4022 | AK46: 4.0729
A47: 辽宁 | F47: 2.4835 | G47: =H47-H11 -> 3.3593 | H47: 3.7648 | I47: 4.465963 | J47: =I47+J11 -> 5.47345 | K47: =J47+K11 -> 6.830905 | N47: =M47+N11 -> 0.011195 | O47: =N47+O11 -> 0.015365 | P47: =O47+P11 -> 0.022855 | Q47: 0.101155 | R47: 0.35602 | S47: 1.1499215 | T47: 2.6387795 | U47: =V47-V11 -> 4.0171 | V47: 5.7719 | W47: 8.1286 | X47: 14.6679 | Z47: =Z11 -> 0.101 | AA47: =Z47+AA11 -> 0.1721 | AB47: =AA47+AB11 -> 0.2406 | AC47: =AB47+AC11 -> 0.8017 | AD47: =AC47+AD11 -> 5.0017 | AE47: 3.716 | AF47: 5.563 | AG47: 8.1308 | AH47: 11.2708 | AI47: 12.2988 | AJ47: 16.4047 | AK47: 29.1297
A48: 吉林 | F48: 0.756171 | G48: =H48-H12 -> 1.2282323 | H48: 1.3613133 | I48: 1.592207 | J48: =I48+J12 -> 2.209321 | K48: =J48+K12 -> 2.996705 | N48: =M48+N12 -> 0.00364 | O48: =N48+O12 -> 0.149203 | P48: =O48+P12 -> 0.168739 | Q48: 0.241905 | R48: 0.667127 | S48: 0.804156 | T48: 1.1507085 | U48: =V48-V12 -> 1.7569 | V48: 2.4395 | W48: 3.1039 | X48: 6.0682 | Z48: =Z12 -> 0.0559 | AA48: =Z48+AA12 -> 0.0827 | AB48: =AA48+AB12 -> 0.1031 | AC48: =AB48+AC12 -> 0.2207 | AD48: =AC48+AD12 -> 0.3063 | AE48: 0.5517 | AF48: 0.8657 | AG48: 1.2721 | AH48: 1.6495 | AI48: 1.9998 | AJ48: 2.3878 | AK48: 4.9921
A49: 黑龙江 | F49: 0.8282 | G49: =H49-H13 -> 0.8225 | H49: 0.8609 | I49: 0.9899 | J49: =I49+J13 -> 1.509446 | K49: =J49+K13 -> 1.837046 | N49: =M49+N13 -> 0.012 | O49: =N49+O13 -> 0.0129 | P49: =O49+P13 -> 0.0134 | Q49: 0.06766 | R49: 0.110688 | S49: 0.209576 | T49: 0.277781 | U49: =V49-V13 -> 0.3814 | V49: 0.4415 | W49: 0.6415 | X49: 1.6807 | Z49: =Z13 -> 0.0278 | AA49: =Z49+AA13 -> 0.0278 | AB49: =AA49+AB13 -> 0.0728 | AC49: =AB49+AC13 -> 0.1039 | AD49: =AC49+AD13 -> 0.1451 | AE49: 0.2145 | AF49: 0.2863 | AG49: 0.4173 | AH49: 0.5089 | AI49: 0.726 | AJ49: 1.018 | AK49: 2.2025
... A55: 江西 | F55: 3.86 | G55: =H55-H19 -> 4.7123 | H55: 5.2072 | I55: 6.3192 | J55: =I55+J19 -> 7.672 | K55: =J55+K19 -> 9.8245 | N55: =M55+N19 -> 0.263909 | O55: =N55+O19 -> 0.293789 | P55: =O55+P19 -> 0.442051 | Q55: 0.916109 | R55: 1.766758 | S55: 2.8160965 | T55: 4.3828335 | U55: =V55-V19 -> 5.7842 | V55: 7.4741 | W55: 9.134 | X55: 14.8327 | Z55: =Z19 -> 0.5313 | AA55: =Z55+AA19 -> 1.0215 | AB55: =AA55+AB19 -> 1.9417 | AC55: =AB55+AC19 -> 4.0516 | AD55: =AC55+AD19 -> 6.3833 | AE55: 10.0767 | AF55: 14.265 | AG55: 18.8812 | AH55: 24.4653 | AI55: 29.5102 | AJ55: 35.5597 | AK55: 49.0241
A56: 山东 | F56: 42.9135 | G56: =H56-H20 -> 61.4343 | H56: 81.1522 | I56: 107.665 | J56: =I56+J20 -> 145.2487 | K56: =J56+K20 -> 189.72682 | N56: =M56+N20 -> 4.7263237 | O56: =N56+O20 -> 5.1479292 | P56: =O56+P20 -> 9.7581772 | Q56: 26.905953 | R56: 52.34536 | S56: 85.583762 | T56: 124.13249 | U56: =V56-V20 -> 169.6187 | V56: 227.5696 | W56: 284.3355 | X56: 457.5407 | Y56: 466 | Z56: =Z20 -> 12.035 | AA56: =Z56+AA20 -> 25.3838 | AB56: =AA56+AB20 -> 53.5295 | AC56: =AB56+AC20 -> 109.3431 | AD56: =AC56+AD20 -> 172.728 | AE56: 240.4745 | AF56: 309.919 | AG56: 378.1659 | AH56: 448.2107 | AI56: 512.6124 | AJ56: 600.8018 | AK56: 763.2183
A57: 河南 | F57: 13.63934 | G57: =H57-H21 -> 17.6293 | H57: 23.8286 | I57: 31.0919 | J57: =I57+J21 -> 41.2316 | K57: =J57+K21 -> 48.2795 | N57: =M57+N21 -> 2.0353965 | O57: =N57+O21 -> 2.171565 | P57: =O57+P21 -> 4.4751777 | Q57: 9.5836757 | R57: 17.728381 | S57: 26.990064 | T57: 38.199446 | U57: =V57-V21 -> 48.5735 | V57: 61.9354 | W57: 74.2602 | X57: 105.3314 | Z57: =Z21 -> 5.1144 | AA57: =Z57+AA21 -> 9.97 | AB57: =AA57+AB21 -> 20.8916 | AC57: =AB57+AC21 -> 40.4041 | AD57: =AC57+AD21 -> 64.3464 | AE57: 89.9464 | AF57: 115.7053 | AG57: 139.3703 | AH57: 171.6745 | AI57: 207.8536 | AJ57: 267.9879 | AK57: 343.2272
A58: 湖北 | F58: 2.44 | G58: =H58-H22 -> 2.51 | H58: 2.88 | I58: 3.5501355 | J58: =I58+J22 -> 4.3022161 | K58: =J58+K22 -> 5.0883676 | N58: =M58+N22 -> 0.091982 | O58: =N58+O22 -> 0.091982 | P58: =O58+P22 -> 0.095707 | Q58: 0.1766005 | R58: 0.3544765 | S58: 0.5805865 | T58: 0.839664 | U58: =V58-V22 -> 1.1681 | V58: 1.8213 | W58: 2.0703 | X58: 3.005 | Z58: =Z22 -> 0.3888 | AA58: =Z58+AA22 -> 0.5188 | AB58: =AA58+AB22 -> 0.7337 | AC58: =AB58+AC22 -> 0.9359 | AD58: =AC58+AD22 -> 1.3686 | AE58: 1.543 | AF58: 2.0678 | AG58: 2.5983 | AH58: 3.3159 | AI58: 3.8932 | AJ58: 4.9037 | AK58: 7.3506
A59: 湖南 | F59: 5.851063 | G59: =H59-H23 -> 6.4286 | H59: 7.7331 | I59: 8.2013 | J59: =I59+J23 -> 8.7699 | K59: =J59+K23 -> 9.8826625 | N59: =M59+N23 -> 0.1873 | O59: =N59+O23 -> 0.2202 | P59: =O59+P23 -> 0.3406 | Q59: 0.6375 | R59: 1.17751 | S59: 1.61731 | T59: 2.34871 | U59: =V59-V23 -> 3.0412 | V59: 3.6257 | W59: 4.3898 | X59: 7.2949 | Z59: =Z23 -> 0.395 | AA59: =Z59+AA23 -> 0.6442 | AB59: =AA59+AB23 -> 1.1071 | AC59: =AB59+AC23 -> 1.8924 | AD59: =AC59+AD23 -> 2.7352 | AE59: 4.0384 | AF59: 5.4836 | AG59: 7.0713 | AH59: 9.4154 | AI59: 11.2964 | AJ59: 13.5559 | AK59: 19.0448
A60: 重庆 | F60: 0.218251 | G60: =H60-H24 -> 0.248041 | H60: 0.258285 | I60: 0.324618 | J60: =I60+J24 -> 0.365218 | K60: =J60+K24 -> 0.391229 | N60: =M60+N24 -> 0.001918 | O60: =N60+O24 -> 0.001918 | P60: =O60+P24 -> 0.007544 | Q60: 0.027268 | R60: 0.03539 | S60: 0.063734 | T60: 0.094223 | U60: =V60-V24 -> 0.1267 | V60: 0.1329 | W60: 0.162 | X60: 0.176 | Z60: =Z24 -> 0.0158 | AA60: =Z60+AA24 -> 0.0182 | AB60: =AA60+AB24 -> 0.0278 | AC60: =AB60+AC24 -> 0.0456 | AD60: =AC60+AD24 -> 0.0715 | AE60: 0.0897 | AF60: 0.1231 | AG60: 0.1517 | AH60: 0.1731 | AI60: 0.2097 | AJ60: 0.2585 | AK60: 0.3459
A61: 四川 | F61: 0.4535 | G61: =H61-H25 -> 0.452105 | H61: 0.8447965 | I61: 0.9124495 | J61: =I61+J25 -> 1.0517605 | K61: =J61+K25 -> 1.2946805 | N61: =M61+N25 -> 0.052872 | O61: =N61+O25 -> 0.055672 | P61: =O61+P25 -> 0.072962 | Q61: 0.126537 | R61: 0.219969 | S61: 0.499661 | T61: 0.764531 | U61: =V61-V25 -> 0.946 | V61: 1.0618 | W61: 1.1988 | X61: 1.9801 | Z61: =Z25 -> 0.0411 | AA61: =Z61+AA25 -> 0.1028 | AB61: =AA61+AB25 -> 0.2124 | AC61: =AB61+AC25 -> 0.5283 | AD61: =AC61+AD25 -> 0.7752 | AE61: 0.9662 | AF61: 1.2243 | AG61: 1.7284 | AH61: 2.0112 | AI61: 2.2019 | AJ61: 3.106 | AK61: 3.8123
A62: 陕西 | F62: 2.207777 | G62: =H62-H26 -> 2.584636 | H62: 3.277233 | I62: 4.240469 | J62: =I62+J26 -> 5.3280725 | K62: =J62+K26 -> 6.6805495 | N62: =M62+N26 -> 0.069535 | O62: =N62+O26 -> 0.087301 | P62: =O62+P26 -> 0.110818 | Q62: 0.359284 | R62: 1.277771 | S62: 2.9671331 | T62: 4.2713348 | U62: =V62-V26 -> 6.3381 | V62: 7.8289 | W62: 9.2298 | X62: 13.5018 | Z62: =Z26 -> 0.0447 | AA62: =Z62+AA26 -> 0.0891 | AB62: =AA62+AB26 -> 0.3706 | AC62: =AB62+AC26 -> 1.0755 | AD62: =AC62+AD26 -> 2.1592 | AE62: 4.2139 | AF62: 5.9322 | AG62: 8.3188 | AH62: 10.5095 | AI62: 12.647 | AJ62: 16.0348 | AK62: 21.7042
A63: 甘肃 | F63: 2.117933 | G63: =H63-H27 -> 2.2323855 | H63: 2.2936955 | I63: 2.411596 | J63: =I63+J27 -> 2.573644 | K63: =J63+K27 -> 3.251883 | N63: =M63+N27 -> 0.00536 | O63: =N63+O27 -> 0.00536 | P63: =O63+P27 -> 0.01456 | Q63: 0.027016 | R63: 0.056334 | S63: 0.092884 | T63: 0.145542 | U63: =V63-V27 -> 0.2249 | V63: 0.2793 | W63: 0.4284 | X63: 0.7275 | Z63: =Z27 -> 0.0235 | AA63: =Z63+AA27 -> 0.0265 | AB63: =AA63+AB27 -> 0.0533 | AC63: =AB63+AC27 -> 0.1363 | AD63: =AC63+AD27 -> 0.1744 | AE63: 0.2282 | AF63: 0.3274 | AG63: 0.445 | AH63: 0.5349 | AI63: 0.5915 | AJ63: 0.7526 | AK63: 1.0777
A64: 青海 | F64: 0.221434 | G64: =H64-H28 -> 0.3925335 | H64: 0.4205335 | I64: 0.4220335 | J64: =I64+J28 -> 0.4410335 | K64: =J64+K28 -> 0.5077935 | N64: =M64+N28 -> 0 | O64: =N64+O28 -> 0.0012 | P64: =O64+P28 -> 0.320155 | Q64: 0.333979 | R64: 0.342289 | S64: 0.359355 | T64: 0.368237 | U64: =V64-V28 -> 0.3747 | V64: 0.3964 | W64: 0.4038 | X64: 0.5136 | Z64: =Z28 -> 0.0012 | AA64: =Z64+AA28 -> 0.0017 | AB64: =AA64+AB28 -> 0.0122 | AC64: =AB64+AC28 -> 0.0257 | AD64: =AC64+AD28 -> 0.0392 | AE64: 0.077 | AF64: 0.1195 | AG64: 0.1813 | AH64: 0.213 | AI64: 0.2565 | AJ64: 0.2878 | AK64: 0.3517
...

Sheet 户用光伏上限模拟
A1: 单户光伏 | B1: =911/51.3 -> 17.758285 | C1: 乡村户人口 | D1: 2.78 | E1: 城镇户人口 | F1: 2.74 | G1: 乡村户覆盖率 | H1: 0.2 | I1: 城镇户覆盖率 | J1: 0.05
A3: 年份 | B3: 2016 | C3: 2017 | D3: 2018 | E3: 2019 | F3: 2020 | G3: 2021 | H3: 2022 | I3: 2023 | J3: 2024 | K3: 2025 | L3: 2026 | M3: 2027 | N3: 2028 | O3: 2029 | P3: 2030 | Q3: 2031 | R3: 2032 | S3: 2033 | T3: 2034 | U3: 2035 | V3: 2036 | W3: 2037 | X3: 2038 | Y3: 2039 | Z3: 2040 | AA3: 2041 | AB3: 2042 | AC3: 2043 | AD3: 2044 | AE3: 2045 | AF3: 2046 | AG3: 2047 | AH3: 2048 | AI3: 2049 | AJ3: 2050 | AK3: 2051 | AL3: 2052 | AM3: 2053 | AN3: 2054 | AO3: 2055 | AP3: 2056 | AQ3: 2057 | AR3: 2058 | AS3: 2059 | AT3: 2060
A4: 济南市 | E4: 9124789 | F4: 9201490 | G4: 9266483 | H4: 9320566 | I4: 9364509 | J4: 9399053 | K4: 9424908 | L4: 9442756 | M4: 9453249 | N4: 9457010 | O4: 9454632 | P4: 9446679 | Q4: 9433686 | R4: 9416158 | S4: 9394571 | T4: 9369372 | U4: 9340977 | V4: 9309775 | W4: 9276123 | X4: 9240351 | Y4: 9202758 | Z4: 9163614 | AA4: 9123161 | AB4: 9081609 | AC4: 9039142 | AD4: 8995911 | AE4: 8952040 | AF4: 8907623 | AG4: 8862724 | AH4: 8817379 | AI4: 8771593 | AJ4: 8725344 | AK4: 8678577 | AL4: 8631211 | AM4: 8583134 | AN4: 8534204 | AO4: 8484252 | AP4: 8433078 | AQ4: 8380452 | AR4: 8326116 | AS4: 8269781 | AT4: 8211131
A5: 青岛市 | E5: 10004648 | F5: 10070342 | G5: 10125262 | H5: 10170056 | I5: 10205351 | J5: 10231753 | K5: 10249849 | L5: 10260204 | M5: 10263363 | N5: 10259848 | O5: 10250163 | P5: 10234790 | Q5: 10214192 | R5: 10188808 | S5: 10159060 | T5: 10125346 | U5: 10088046 | V5: 10047517 | W5: 10004098 | X5: 9958105 | Y5: 9909833 | Z5: 9859559 | AA5: 9807537 | AB5: 9754000 | AC5: 9699163 | AD5: 9643217 | AE5: 9586335 | AF5: 9528667 | AG5: 9470344 | AH5: 9411477 | AI5: 9352153 | AJ5: 9292441 | AK5: 9232388 | AL5: 9172023 | AM5: 9111351 | AN5: 9050357 | AO5: 8989006 | AP5: 8927242 | AQ5: 8864990 | AR5: 8802151 | AS5: 8738608 | AT5: 8674222
A6: 淄博市 | E6: 4681060 | F6: 4703603 | G6: 4722676 | H6: 4738360 | I6: 4750739 | J6: 4759897 | K6: 4765924 | L6: 4768912 | M6: 4768955 | N6: 4766151 | O6: 4760600 | P6: 4752406 | Q6: 4741674 | R6: 4728514 | S6: 4713037 | T6: 4695359 | U6: 4675596 | V6: 4653869 | W6: 4630301 | X6: 4605020 | Y6: 4578153 | Z6: 4549833 | AA6: 4520194 | AB6: 4489375 | AC6: 4457515 | AD6: 4424759 | AE6: 4391252 | AF6: 4357143 | AG6: 4322585 | AH6: 4287733 | AI6: 4252744 | AJ6: 4217779 | AK6: 4183001 | AL6: 4148578 | AM6: 4114677 | AN6: 4081471 | AO6: 4049136 | AP6: 4017848 | AQ6: 3987790 | AR6: 3959143 | AS6: 3932096 | AT6: 3906836
A7: 枣庄市 | E7: 3828414 | F7: 3855201 | G7: 3879651 | H7: 3901786 | I7: 3921634 | J7: 3939224 | K7: 3954589 | L7: 3967767 | M7: 3978797 | N7: 3987722 | O7: 3994588 | P7: 3999445 | Q7: 4002346 | R7: 4003348 | S7: 4002509 | T7: 3999893 | U7: 3995565 | V7: 3989596 | W7: 3982057 | X7: 3973024 | Y7: 3962578 | Z7: 3950800 | AA7: 3937776 | AB7: 3923595 | AC7: 3908350 | AD7: 3892136 | AE7: 3875053 | AF7: 3857202 | AG7: 3838689 | AH7: 3819623 | AI7: 3800116 | AJ7: 3780283 | AK7: 3760243 | AL7: 3740118 | AM7: 3720033 | AN7: 3700117 | AO7: 3680501 | AP7: 3661320 | AQ7: 3642714 | AR7: 3624823 | AS7: 3607793 | AT7: 3591771
A8: 东营市 | E8: 2181073 | F8: 2193342 | G8: 2203929 | H8: 2212897 | I8: 2220309 | J8: 2226225 | K8: 2230707 | L8: 2233814 | M8: 2235605 | N8: 2236138 | O8: 2235472 | P8: 2233662 | Q8: 2230764 | R8: 2226835 | S8: 2221927 | T8: 2216095 | U8: 2209392 | V8: 2201870 | W8: 2193579 | X8: 2184571 | Y8: 2174895 | Z8: 2164600 | AA8: 2153734 | AB8: 2142346 | AC8: 2130480 | AD8: 2118184 | AE8: 2105503 | AF8: 2092480 | AG8: 2079160 | AH8: 2065584 | AI8: 2051796 | AJ8: 2037836 | AK8: 2023745 | AL8: 2009563 | AM8: 1995328 | AN8: 1981078 | AO8: 1966852 | AP8: 1952685 | AQ8: 1938613 | AR8: 1924672 | AS8: 1910895 | AT8: 1897317
A9: 烟台市 | E9: 7061298 | F9: 7101116 | G9: 7131386 | H9: 7152720 | I9: 7165713 | J9: 7170939 | K9: 7168958 | L9: 7160307 | M9: 7145508 | N9: 7125064 | O9: 7099459 | P9: 7069158 | Q9: 7034610 | R9: 6996243 | S9: 6954468 | T9: 6909677 | U9: 6862246 | V9: 6812529 | W9: 6760864 | X9: 6707570 | Y9: 6652948 | Z9: 6597281 | AA9: 6540832 | AB9: 6483847 | AC9: 6426553 | AD9: 6369161 | AE9: 6311859 | AF9: 6254821 | AG9: 6198200 | AH9: 6142133 | AI9: 6086736 | AJ9: 6032108 | AK9: 5978331 | AL9: 5925466 | AM9: 5873557 | AN9: 5822630 | AO9: 5772692 | AP9: 5723732 | AQ9: 5675720 | AR9: 5628609 | AS9: 5582333 | AT9: 5536807
A10: 潍坊市 | E10: 9338971 | F10: 9385514 | G10: 9425574 | H10: 9459303 | I10: 9486859 | J10: 9508405 | K10: 9524107 | L10: 9534139 | M10: 9538675 | N10: 9537899 | O10: 9531996 | P10: 9521158 | Q10: 9505580 | R10: 9485464 | S10: 9461014 | T10: 9432441 | U10: 9399961 | V10: 9363792 | W10: 9324161 | X10: 9281295 | Y10: 9235430 | Z10: 9186805 | AA10: 9135663 | AB10: 9082252 | AC10: 9026828 | AD10: 8969646 | AE10: 8910972 | AF10: 8851072 | AG10: 8790219 | AH10: 8728690 | AI10: 8666767 | AJ10: 8604738 | AK10: 8542894 | AL10: 8481532 | AM10: 8420953 | AN10: 8361463 | AO10: 8303373 | AP10: 8246999 | AQ10: 8192661 | AR10: 8140684 | AS10: 8091399 | AT10: 8045140
A11: 济宁市 | E11: 8319940 | F11: 8356958 | G11: 8391066 | H11: 8422171 | I11: 8450190 | J11: 8475052 | K11: 8496696 | L11: 8515074 | M11: 8530148 | N11: 8541892 | O11: 8550288 | P11: 8555335 | Q11: 8557037 | R11: 8555413 | S11: 8550493 | T11: 8542315 | U11: 8530932 | V11: 8516406 | W11: 8498811 | X11: 8478231 | Y11: 8454762 | Z11: 8428512 | AA11: 8399598 | AB11: 8368150 | AC11: 8334309 | AD11: 8298226 | AE11: 8260064 | AF11: 8219996 | AG11: 8178209 | AH11: 8134897 | AI11: 8090269 | AJ11: 8044543 | AK11: 7997949 | AL11: 7950727 | AM11: 7903130 | AN11: 7855420 | AO11: 7807872 | AP11: 7760772 | AQ11: 7714415 | AR11: 7669109 | AS11: 7625174 | AT11: 7582939
A12: 泰安市 | E12: 5450865 | F12: 5471633 | G12: 5488885 | H12: 5502735 | I12: 5513301 | J12: 5520697 | K12: 5525037 | L12: 5526435 | M12: 5525005 | N12: 5520859 | O12: 5514108 | P12: 5504865 | Q12: 5493240 | R12: 5479343 | S12: 5463284 | T12: 5445172 | U12: 5425115 | V12: 5403221 | W12: 5379598 | X12: 5354351 | Y12: 5327587 | Z12: 5299412 | AA12: 5269929 | AB12: 5239244 | AC12: 5207459 | AD12: 5174678 | AE12: 5141003 | AF12: 5106537 | AG12: 5071379 | AH12: 5035631 | AI12: 4999393 | AJ12: 4962765 | AK12: 4925844 | AL12: 4888729 | AM12: 4851518 | AN12: 4814308 | AO12: 4777195 | AP12: 4740275 | AQ12: 4703643 | AR12: 4667394 | AS12: 4631621 | AT12: 4596419
A13: 威海市 | E13: 2888794 | F13: 2906105 | G13: 2919006 | H13: 2927801 | I13: 2932786 | J13: 2934246 | K13: 2932455 | L13: 2927679 | M13: 2920174 | N13: 2910185 | O13: 2897948 | P13: 2883691 | Q13: 2867628 | R13: 2849966 | S13: 2830904 | T13: 2810626 | U13: 2789311 | V13: 2767127 | W13: 2744230 | X13: 2720768 | Y13: 2696880 | Z13: 2672694 | AA13: 2648328 | AB13: 2623891 | AC13: 2599481 | AD13: 2575189 | AE13: 2551092 | AF13: 2527260 | AG13: 2503754 | AH13: 2480622 | AI13: 2457905 | AJ13: 2435634 | AK13: 2413828 | AL13: 2392498 | AM13: 2371646 | AN13: 2351262 | AO13: 2331327 | AP13: 2311814 | AQ13: 2292683 | AR13: 2273886 | AS13: 2255366 | AT13: 2237055
A14: 日照市 | E14: 2957601 | F14: 2967964 | G14: 2977190 | H14: 2985231 | I14: 2992046 | J14: 2997598 | K14: 3001857 | L14: 3004801 | M14: 3006410 | N14: 3006673 | O14: 3005585 | P14: 3003146 | Q14: 2999363 | R14: 2994247 | S14: 2987818 | T14: 2980100 | U14: 2971123 | V14: 2960925 | W14: 2949547 | X14: 2937040 | Y14: 2923457 | Z14: 2908859 | AA14: 2893314 | AB14: 2876893 | AC14: 2859677 | AD14: 2841750 | AE14: 2823203 | AF14: 2804133 | AG14: 2784644 | AH14: 2764844 | AI14: 2744849 | AJ14: 2724780 | AK14: 2704765 | AL14: 2684937 | AM14: 2665434 | AN14: 2646403 | AO14: 2627996 | AP14: 2610369 | AQ14: 2593686 | AR14: 2578118 | AS14: 2563839 | AT14: 2551031
A15: 临沂市 | E15: 10982491 | F15: 11017081 | G15: 11050803 | H15: 11083213 | I15: 11113899 | J15: 11142479 | K15: 11168600 | L15: 11191943 | M15: 11212215 | N15: 11229157 | O15: 11242538 | P15: 11252160 | Q15: 11257852 | R15: 11259476 | S15: 11256924 | T15: 11250118 | U15: 11239010 | V15: 11223583 | W15: 11203851 | X15: 11179857 | Y15: 11151675 | Z15: 11119411 | AA15: 11083198 | AB15: 11043203 | AC15: 10999621 | AD15: 10952678 | AE15: 10902632 | AF15: 10849768 | AG15: 10794406 | AH15: 10736892 | AI15: 10677605 | AJ15: 10616953 | AK15: 10555376 | AL15: 10493344 | AM15: 10431356 | AN15: 10369943 | AO15: 10309665 | AP15: 10251114 | AQ15: 10194912 | AR15: 10141710 | AS15: 10092191 | AT15: 10047068
... A19: 菏泽市 | E19: 8780329 | F19: 8794781 | G19: 8813631 | H19: 8835977 | I19: 8860965 | J19: 8887791 | K19: 8915703 | L19: 8943995 | M19: 8972013 | N19: 8999151 | O19: 9024854 | P19: 9048616 | Q19: 9069980 | R19: 9088538 | S19: 9103935 | T19: 9115861 | U19: 9124059 | V19: 9128320 | W19: 9128484 | X19: 9124443 | Y19: 9116135 | Z19: 9103551 | AA19: 9086729 | AB19: 9065759 | AC19: 9040778 | AD19: 9011975 | AE19: 8979586 | AF19: 8943899 | AG19: 8905249 | AH19: 8864024 | AI19: 8820659 | AJ19: 8775638 | AK19: 8729497 | AL19: 8682820 | AM19: 8636241 | AN19: 8590443 | AO19: 8546160 | AP19: 8504173 | AQ19: 8465315 | AR19: 8430468 | AS19: 8400563 | AT19: 8376580
B20: -6.849497e-05 | C20: 0.283187 | D20: -291.889
A21: 山东人口(万人） | E21: =SUM(E4:E19)/10000 -> 10102.832 | F21: =SUM(F4:F19)/10000 -> 10151.555 | G21: =SUM(G4:G19)/10000 -> 10194.211 | H21: =SUM(H4:H19)/10000 -> 10230.924 | I21: =SUM(I4:I19)/10000 -> 10261.823 | J21: =SUM(J4:J19)/10000 -> 10287.042 | K21: =SUM(K4:K19)/10000 -> 10306.718 | L21: =SUM(L4:L19)/10000 -> 10320.995 | ... AT21: =SUM(AT4:AT19)/10000 -> 8900.7642
A22: 城镇化率 | B22: =$B$20*B$3^2+$C$20*B$3+$D$20 -> 0.63489921 | C22: =$B$20*C$3^2+$C$20*C$3+$D$20 -> 0.64184599 | D22: =$B$20*D$3^2+$C$20*D$3+$D$20 -> 0.64865579 | E22: =$B$20*E$3^2+$C$20*E$3+$D$20 -> 0.6553286 | F22: =$B$20*F$3^2+$C$20*F$3+$D$20 -> 0.66186441 | G22: =$B$20*G$3^2+$C$20*G$3+$D$20 -> 0.66826324 | H22: =$B$20*H$3^2+$C$20*H$3+$D$20 -> 0.67452507 | I22: =$B$20*I$3^2+$C$20*I$3+$D$20 -> 0.68064992 | ... AT22: =$B$20*AT$3^2+$C$20*AT$3+$D$20 -> 0.81096531
A23: 城市人口 | E23: =E21*E22 -> 6620.6745 | F23: =F21*F22 -> 6718.9529 | G23: =G21*G22 -> 6812.4163 | H23: =H21*H22 -> 6901.0146 | I23: =I21*I22 -> 6984.7093 | J23: =J21*J22 -> 7063.4718 | K23: =K21*K22 -> 7137.2854 | L23: =L21*L22 -> 7206.1444 | ... AT23: =AT21*AT22 -> 7218.211
A24: 乡村人口 | E24: =E21-E23 -> 3482.1572 | F24: =F21-F23 -> 3432.602 | G24: =G21-G23 -> 3381.7945 | H24: =H21-H23 -> 3329.9092 | I24: =I21-I23 -> 3277.1141 | J24: =J21-J23 -> 3223.5704 | K24: =K21-K23 -> 3169.4329 | L24: =L21-L23 -> 3114.8501 | ... AT24: =AT21-AT23 -> 1682.5532
A26: 城镇户数 | B26: 万户 | E26: =E23/$F$1 -> 2416.3046 | F26: =F23/$F$1 -> 2452.1726 | G26: =G23/$F$1 -> 2486.2833 | H26: =H23/$F$1 -> 2518.6185 | I26: =I23/$F$1 -> 2549.164 | J26: =J23/$F$1 -> 2577.9094 | K26: =K23/$F$1 -> 2604.8487 | L26: =L23/$F$1 -> 2629.9797 | ... AT26: =AT23/$F$1 -> 2634.3836
A27: 乡村户数 | B27: 万户 | E27: =E24/$D$1 -> 1252.5745 | F27: =F24/$D$1 -> 1234.7489 | G27: =G24/$D$1 -> 1216.4728 | H27: =H24/$D$1 -> 1197.8091 | I27: =I24/$D$1 -> 1178.818 | J27: =J24/$D$1 -> 1159.5577 | K27: =K24/$D$1 -> 1140.0838 | L27: =L24/$D$1 -> 1120.4497 | ... AT27: =AT24/$D$1 -> 605.23497
A29: 城镇光伏 | C29: MW | E29: =E26*$J$1*$B$1*10 -> 21454.712 | F29: =F26*$J$1*$B$1*10 -> 21773.189 | G29: =G26*$J$1*$B$1*10 -> 22076.063 | H29: =H26*$J$1*$B$1*10 -> 22363.172 | I29: =I26*$J$1*$B$1*10 -> 22634.39 | J29: =J26*$J$1*$B$1*10 -> 22889.625 | K29: =K26*$J$1*$B$1*10 -> 23128.822 | L29: =L26*$J$1*$B$1*10 -> 23351.964 | ... AT29: =AT26*$J$1*$B$1*10 -> 23391.067
A30: 乡村光伏 | C30: MW | E30: =E27*$H$1*$B$1*10 -> 44487.15 | F30: =F27*$H$1*$B$1*10 -> 43854.045 | G30: =G27*$H$1*$B$1*10 -> 43204.942 | H30: =H27*$H$1*$B$1*10 -> 42542.068 | I30: =I27*$H$1*$B$1*10 -> 41867.572 | J30: =J27*$H$1*$B$1*10 -> 41183.511 | K30: =K27*$H$1*$B$1*10 -> 40491.865 | L30: =L27*$H$1*$B$1*10 -> 39794.529 | ... AT30: =AT27*$H$1*$B$1*10 -> 21495.87
E32: =E29+E30 -> 65941.862 | F32: =F29+F30 -> 65627.235 | G32: =G29+G30 -> 65281.005 | H32: =H29+H30 -> 64905.24 | I32: =I29+I30 -> 64501.962 | J32: =J29+J30 -> 64073.136 | K32: =K29+K30 -> 63620.687 | L32: =L29+L30 -> 63146.493 | ... AT32: =AT29+AT30 -> 44886.936
E33: =山东光伏数据!O24*10 -> 3356.6 | F33: =山东光伏数据!P24*10 -> 8016.6 | G33: =山东光伏数据!Q24*10 -> 15648.8 | K33: =F33+15000 -> 23016.6

Sheet 世行山东城市化率
A1: 2020 | C1: 2030 | E1: 2040 | G1: 2050 | I1: 2060
A2: 9201490 | B2: 7928794.2 | C2: 9446679 | D2: 8991701.5 | E2: 9163614 | F2: 9163614 | G2: 8725344 | H2: 8725344 | I2: 8211131 | J2: 8211131
A3: 10070342 | B3: 7852632.2 | C3: 10234790 | D3: 8815840.2 | E3: 9859559 | F3: 8926945.4 | G3: 9292441 | H3: 8736401.6 | I3: 8674222 | J3: 8468192
A4: 4703603 | B4: 3545987.5 | C4: 4752406 | D4: 3957617.5 | E4: 4549833 | F4: 3982688.7 | G4: 4217779 | H4: 3833735.2 | I4: 3906836 | J4: 3687405.1
A5: 3855201 | B5: 2343863.9 | C5: 3999445 | D5: 2685955.6 | E5: 3950800 | F5: 2788975.9 | G5: 3780283 | H5: 2771031.2 | I5: 3591771 | J5: 2733903.2
A6: 2193342 | B6: 1596320 | C6: 2233662 | D6: 1795745.5 | E6: 2164600 | F6: 1829218.6 | G6: 2037836 | H6: 1788193.7 | I6: 1897317 | J6: 1728791.5
A7: 7101116 | B7: 4820886.1 | C7: 7069158 | D7: 5301291.5 | E7: 6597281 | F7: 5200434.1 | G7: 6032108 | H7: 4937431.8 | I7: 5536807 | J7: 4705965.9
A8: 9385514 | B8: 5975205.1 | C8: 9521158 | D8: 6695735.2 | E8: 9186805 | F8: 6790998.1 | G8: 8604738 | H8: 6604868.1 | I8: 8045140 | J8: 6412354
A9: 8356958 | B9: 5061104.2 | C9: 8555335 | D9: 5723317.2 | E9: 8428512 | F9: 5926828 | G9: 8044543 | H9: 5873949.1 | I9: 7582939 | J9: 5749416.2
A10: 5471633 | B10: 3536681.6 | C10: 5504865 | D10: 3930424.1 | E10: 5299412 | F10: 3977233.1 | G10: 4962765 | H10: 3867536.8 | I10: 4596419 | J10: 3719527.2
A11: 2906105 | B11: 2063059.2 | C11: 2883691 | D11: 2261324.3 | E11: 2672694 | F11: 2203048.1 | G11: 2435634 | H11: 2084702.8 | I11: 2237055 | J11: 1988228
A12: 2967964 | B12: 1848605.2 | C12: 3003146 | D12: 2066216 | E12: 2908859 | F12: 2103694 | G12: 2724780 | H12: 2046203 | I12: 2551031 | J12: 1989254.7
A13: 11017081 | B13: 6741695.3 | C13: 11252160 | D13: 7605928.1 | E13: 11119411 | F13: 7900575.3 | G13: 10616953 | H13: 7833109.8 | I13: 10047068 | J13: 7697169.5
... A17: 8794781 | B17: 4583957.2 | C17: 9048616 | D17: 5209684.5 | E17: 9103551 | F17: 5509354.4 | G17: 8775638 | H17: 5514751.7 | I17: 8376580 | J17: 5466022.2
