Workbook

Sheet 增加值 (2001-2060, 2012USD)
A1: 全国 | B1: 2001 | C1: 2002 | D1: 2003 | E1: 2004 | F1: 2005 | G1: 2006 | H1: 2007 | I1: 2008 | J1: 2009 | K1: 2010 | L1: 2011 | M1: 2012 | N1: 2013 | O1: 2014 | P1: 2015 | Q1: 2016 | R1: 2017 | S1: 2018 | T1: 2019 | U1: 2020 | V1: 2021 | W1: 2022 | X1: 2023 | Y1: 2024 | Z1: 2025 | AA1: 2026 | AB1: 2027 | AC1: 2028 | AD1: 2029 | AE1: 2030 | AF1: 2031 | AG1: 2032 | AH1: 2033 | AI1: 2034 | AJ1: 2035 | AK1: 2036 | AL1: 2037 | AM1: 2038 | AN1: 2039 | AO1: 2040 | AP1: 2041 | AQ1: 2042 | AR1: 2043 | AS1: 2044 | AT1: 2045 | AU1: 2046 | AV1: 2047 | AW1: 2048 | AX1: 2049 | AY1: 2050 | AZ1: 2051 | BA1: 2052 | BB1: 2053 | BC1: 2054 | BD1: 2055 | BE1: 2056 | BF1: 2057 | BG1: 2058 | BH1: 2059 | BI1: 2060
A2: 地区生产总值 | B2: ='增加值 (2001-2060, 2020RMB)'!B2*$B$73 -> 28718.704 | C2: ='增加值 (2001-2060, 2020RMB)'!C2*$B$73 -> 31332.106 | D2: ='增加值 (2001-2060, 2020RMB)'!D2*$B$73 -> 34465.316 | E2: ='增加值 (2001-2060, 2020RMB)'!E2*$B$73 -> 37946.313 | F2: ='增加值 (2001-2060, 2020RMB)'!F2*$B$73 -> 42272.193 | G2: ='增加值 (2001-2060, 2020RMB)'!G2*$B$73 -> 47640.761 | H2: ='增加值 (2001-2060, 2020RMB)'!H2*$B$73 -> 54405.75 | I2: ='增加值 (2001-2060, 2020RMB)'!I2*$B$73 -> 59683.107 | ... BI2: ='增加值 (2001-2060, 2020RMB)'!BI2*$B$73 -> 485952.6
A3: 农业 | B3: ='增加值 (2001-2060, 2020RMB)'!B3*$B$73 -> 4087.7546 | C3: ='增加值 (2001-2060, 2020RMB)'!C3*$B$73 -> 4256.5673 | D3: ='增加值 (2001-2060, 2020RMB)'!D3*$B$73 -> 4359.0391 | E3: ='增加值 (2001-2060, 2020RMB)'!E3*$B$73 -> 5020.1194 | F3: ='增加值 (2001-2060, 2020RMB)'!F3*$B$73 -> 5058.6563 | G3: ='增加值 (2001-2060, 2020RMB)'!G3*$B$73 -> 5218.3751 | H3: ='增加值 (2001-2060, 2020RMB)'!H3*$B$73 -> 5737.5832 | I3: ='增加值 (2001-2060, 2020RMB)'!I3*$B$73 -> 6249.4178 | ... BI3: ='增加值 (2001-2060, 2020RMB)'!BI3*$B$73 -> 24783.583
A4: 工业 | B4: ='增加值 (2001-2060, 2020RMB)'!B4*$B$73 -> 11360.305 | C4: ='增加值 (2001-2060, 2020RMB)'!C4*$B$73 -> 12298.063 | D4: ='增加值 (2001-2060, 2020RMB)'!D4*$B$73 -> 13884.791 | E4: ='增加值 (2001-2060, 2020RMB)'!E4*$B$73 -> 15422.095 | F4: ='增加值 (2001-2060, 2020RMB)'!F4*$B$73 -> 17592.823 | G4: ='增加值 (2001-2060, 2020RMB)'!G4*$B$73 -> 20024.671 | H4: ='增加值 (2001-2060, 2020RMB)'!H4*$B$73 -> 22498.315 | I4: ='增加值 (2001-2060, 2020RMB)'!I4*$B$73 -> 24625.938 | ... BI4: ='增加值 (2001-2060, 2020RMB)'!BI4*$B$73 -> 92816.947
A5: 建筑业 | B5: ='增加值 (2001-2060, 2020RMB)'!B5*$B$73 -> 1540.1613 | C5: ='增加值 (2001-2060, 2020RMB)'!C5*$B$73 -> 1668.6015 | D5: ='增加值 (2001-2060, 2020RMB)'!D5*$B$73 -> 1883.702 | E5: ='增加值 (2001-2060, 2020RMB)'!E5*$B$73 -> 2044.6763 | F5: ='增加值 (2001-2060, 2020RMB)'!F5*$B$73 -> 2347.0773 | G5: ='增加值 (2001-2060, 2020RMB)'!G5*$B$73 -> 2702.9543 | H5: ='增加值 (2001-2060, 2020RMB)'!H5*$B$73 -> 3091.6077 | I5: ='增加值 (2001-2060, 2020RMB)'!I5*$B$73 -> 3516.1002 | ... BI5: ='增加值 (2001-2060, 2020RMB)'!BI5*$B$73 -> 24297.63
A6: 交运仓邮 | B6: ='增加值 (2001-2060, 2020RMB)'!B6*$B$73 -> 1779.9866 | C6: ='增加值 (2001-2060, 2020RMB)'!C6*$B$73 -> 1929.1589 | D6: ='增加值 (2001-2060, 2020RMB)'!D6*$B$73 -> 1985.0249 | E6: ='增加值 (2001-2060, 2020RMB)'!E6*$B$73 -> 2182.0744 | F6: ='增加值 (2001-2060, 2020RMB)'!F6*$B$73 -> 2407.6245 | G6: ='增加值 (2001-2060, 2020RMB)'!G6*$B$73 -> 2645.6826 | H6: ='增加值 (2001-2060, 2020RMB)'!H6*$B$73 -> 2941.9625 | I6: ='增加值 (2001-2060, 2020RMB)'!I6*$B$73 -> 3059.9397 | ... BI6: ='增加值 (2001-2060, 2020RMB)'!BI6*$B$73 -> 9071.0148
A7: 批发零售 | B7: ='增加值 (2001-2060, 2020RMB)'!B7*$B$73 -> 2362.7118 | C7: ='增加值 (2001-2060, 2020RMB)'!C7*$B$73 -> 2573.3444 | D7: ='增加值 (2001-2060, 2020RMB)'!D7*$B$73 -> 2801.7271 | E7: ='增加值 (2001-2060, 2020RMB)'!E7*$B$73 -> 2920.4838 | F7: ='增加值 (2001-2060, 2020RMB)'!F7*$B$73 -> 3152.2667 | G7: ='增加值 (2001-2060, 2020RMB)'!G7*$B$73 -> 3589.4511 | H7: ='增加值 (2001-2060, 2020RMB)'!H7*$B$73 -> 4218.2478 | I7: ='增加值 (2001-2060, 2020RMB)'!I7*$B$73 -> 4895.5371 | ... BI7: ='增加值 (2001-2060, 2020RMB)'!BI7*$B$73 -> 22177.568
A8: 餐饮住宿 | B8: ='增加值 (2001-2060, 2020RMB)'!B8*$B$73 -> 621.73763 | C8: ='增加值 (2001-2060, 2020RMB)'!C8*$B$73 -> 701.40934 | D8: ='增加值 (2001-2060, 2020RMB)'!D8*$B$73 -> 784.02312 | E8: ='增加值 (2001-2060, 2020RMB)'!E8*$B$73 -> 859.27754 | F8: ='增加值 (2001-2060, 2020RMB)'!F8*$B$73 -> 946.8422 | G8: ='增加值 (2001-2060, 2020RMB)'!G8*$B$73 -> 1040.4879 | H8: ='增加值 (2001-2060, 2020RMB)'!H8*$B$73 -> 1117.5755 | I8: ='增加值 (2001-2060, 2020RMB)'!I8*$B$73 -> 1236.8867 | ... BI8: ='增加值 (2001-2060, 2020RMB)'!BI8*$B$73 -> 3786.9976
A9: 金融业 | B9: ='增加值 (2001-2060, 2020RMB)'!B9*$B$73 -> 1347.7674 | C9: ='增加值 (2001-2060, 2020RMB)'!C9*$B$73 -> 1430.1564 | D9: ='增加值 (2001-2060, 2020RMB)'!D9*$B$73 -> 1516.2562 | E9: ='增加值 (2001-2060, 2020RMB)'!E9*$B$73 -> 1547.5343 | F9: ='增加值 (2001-2060, 2020RMB)'!F9*$B$73 -> 1689.3631 | G9: ='增加值 (2001-2060, 2020RMB)'!G9*$B$73 -> 2165.0165 | H9: ='增加值 (2001-2060, 2020RMB)'!H9*$B$73 -> 3061.7955 | I9: ='增加值 (2001-2060, 2020RMB)'!I9*$B$73 -> 3429.7288 | ... BI9: ='增加值 (2001-2060, 2020RMB)'!BI9*$B$73 -> 21655.802
A10: 房地产 | B10: ='增加值 (2001-2060, 2020RMB)'!B10*$B$73 -> 1219.0213 | C10: ='增加值 (2001-2060, 2020RMB)'!C10*$B$73 -> 1373.19 | D10: ='增加值 (2001-2060, 2020RMB)'!D10*$B$73 -> 1544.1702 | E10: ='增加值 (2001-2060, 2020RMB)'!E10*$B$73 -> 1676.937 | F10: ='增加值 (2001-2060, 2020RMB)'!F10*$B$73 -> 1914.288 | G10: ='增加值 (2001-2060, 2020RMB)'!G10*$B$73 -> 2240.6986 | H10: ='增加值 (2001-2060, 2020RMB)'!H10*$B$73 -> 2762.4647 | I10: ='增加值 (2001-2060, 2020RMB)'!I10*$B$73 -> 2729.5411 | ... BI10: ='增加值 (2001-2060, 2020RMB)'!BI10*$B$73 -> 19597.345
A11: 其他三产 | B11: ='增加值 (2001-2060, 2020RMB)'!B11*$B$73 -> 4399.284 | C11: ='增加值 (2001-2060, 2020RMB)'!C11*$B$73 -> 5101.6409 | D11: ='增加值 (2001-2060, 2020RMB)'!D11*$B$73 -> 5706.6329 | E11: ='增加值 (2001-2060, 2020RMB)'!E11*$B$73 -> 6273.0918 | F11: ='增加值 (2001-2060, 2020RMB)'!F11*$B$73 -> 7163.229 | G11: ='增加值 (2001-2060, 2020RMB)'!G11*$B$73 -> 8013.4462 | H11: ='增加值 (2001-2060, 2020RMB)'!H11*$B$73 -> 8976.1974 | I11: ='增加值 (2001-2060, 2020RMB)'!I11*$B$73 -> 9940.0555 | ... BI11: ='增加值 (2001-2060, 2020RMB)'!BI11*$B$73 -> 267765.71
A13: 工业 | B13: ='增加值 (2001-2060, 2020RMB)'!B13*$B$73 -> 11360.305 | C13: ='增加值 (2001-2060, 2020RMB)'!C13*$B$73 -> 12298.063 | D13: ='增加值 (2001-2060, 2020RMB)'!D13*$B$73 -> 13884.791 | E13: ='增加值 (2001-2060, 2020RMB)'!E13*$B$73 -> 15422.095 | F13: ='增加值 (2001-2060, 2020RMB)'!F13*$B$73 -> 17592.823 | G13: ='增加值 (2001-2060, 2020RMB)'!G13*$B$73 -> 20024.671 | H13: ='增加值 (2001-2060, 2020RMB)'!H13*$B$73 -> 22498.315 | I13: ='增加值 (2001-2060, 2020RMB)'!I13*$B$73 -> 24625.938 | ... BI13: ='增加值 (2001-2060, 2020RMB)'!BI13*$B$73 -> 92816.947
A14: 煤炭开采和洗选业 | I14: ='增加值 (2001-2060, 2020RMB)'!I14*$B$73 -> 1608.2849 | J14: ='增加值 (2001-2060, 2020RMB)'!J14*$B$73 -> 1651.0989 | K14: ='增加值 (2001-2060, 2020RMB)'!K14*$B$73 -> 1879.1923 | L14: ='增加值 (2001-2060, 2020RMB)'!L14*$B$73 -> 2105.4222 | M14: ='增加值 (2001-2060, 2020RMB)'!M14*$B$73 -> 2200.7749 | N14: ='增加值 (2001-2060, 2020RMB)'!N14*$B$73 -> 2209.8175 | O14: ='增加值 (2001-2060, 2020RMB)'!O14*$B$73 -> 2171.5798 | P14: ='增加值 (2001-2060, 2020RMB)'!P14*$B$73 -> 2099.3377 | ... BI14: ='增加值 (2001-2060, 2020RMB)'!BI14*$B$73 -> 1899.2504
A15: 石油和天然气开采业 | I15: ='增加值 (2001-2060, 2020RMB)'!I15*$B$73 -> 1691.9642 | J15: ='增加值 (2001-2060, 2020RMB)'!J15*$B$73 -> 1680.87 | K15: ='增加值 (2001-2060, 2020RMB)'!K15*$B$73 -> 1629.0529 | L15: ='增加值 (2001-2060, 2020RMB)'!L15*$B$73 -> 1645.1569 | M15: ='增加值 (2001-2060, 2020RMB)'!M15*$B$73 -> 1616.2967 | N15: ='增加值 (2001-2060, 2020RMB)'!N15*$B$73 -> 1570.7336 | O15: ='增加值 (2001-2060, 2020RMB)'!O15*$B$73 -> 1558.6134 | P15: ='增加值 (2001-2060, 2020RMB)'!P15*$B$73 -> 1540.7723 | ... BI15: ='增加值 (2001-2060, 2020RMB)'!BI15*$B$73 -> 1148.9919
A16: 黑色金属矿采选业 | I16: ='增加值 (2001-2060, 2020RMB)'!I16*$B$73 -> 281.4176 | J16: ='增加值 (2001-2060, 2020RMB)'!J16*$B$73 -> 334.25968 | K16: ='增加值 (2001-2060, 2020RMB)'!K16*$B$73 -> 391.47301 | L16: ='增加值 (2001-2060, 2020RMB)'!L16*$B$73 -> 451.39058 | M16: ='增加值 (2001-2060, 2020RMB)'!M16*$B$73 -> 518.24352 | N16: ='增加值 (2001-2060, 2020RMB)'!N16*$B$73 -> 566.15783 | O16: ='增加值 (2001-2060, 2020RMB)'!O16*$B$73 -> 600.32741 | P16: ='增加值 (2001-2060, 2020RMB)'!P16*$B$73 -> 583.77348 | ... BI16: ='增加值 (2001-2060, 2020RMB)'!BI16*$B$73 -> 359.34837
A17: 有色金属矿采选业 | I17: ='增加值 (2001-2060, 2020RMB)'!I17*$B$73 -> 180.55744 | J17: ='增加值 (2001-2060, 2020RMB)'!J17*$B$73 -> 205.04722 | K17: ='增加值 (2001-2060, 2020RMB)'!K17*$B$73 -> 221.42629 | L17: ='增加值 (2001-2060, 2020RMB)'!L17*$B$73 -> 245.74268 | M17: ='增加值 (2001-2060, 2020RMB)'!M17*$B$73 -> 269.73915 | N17: ='增加值 (2001-2060, 2020RMB)'!N17*$B$73 -> 280.58464 | O17: ='增加值 (2001-2060, 2020RMB)'!O17*$B$73 -> 288.91076 | P17: ='增加值 (2001-2060, 2020RMB)'!P17*$B$73 -> 285.87774 | ... BI17: ='增加值 (2001-2060, 2020RMB)'!BI17*$B$73 -> 142.41405
A18: 非金属矿采选业 | I18: ='增加值 (2001-2060, 2020RMB)'!I18*$B$73 -> 102.03795 | J18: ='增加值 (2001-2060, 2020RMB)'!J18*$B$73 -> 116.26469 | K18: ='增加值 (2001-2060, 2020RMB)'!K18*$B$73 -> 140.90713 | L18: ='增加值 (2001-2060, 2020RMB)'!L18*$B$73 -> 167.34813 | M18: ='增加值 (2001-2060, 2020RMB)'!M18*$B$73 -> 175.56443 | N18: ='增加值 (2001-2060, 2020RMB)'!N18*$B$73 -> 186.7929 | O18: ='增加值 (2001-2060, 2020RMB)'!O18*$B$73 -> 193.05215 | P18: ='增加值 (2001-2060, 2020RMB)'!P18*$B$73 -> 195.23792 | ... BI18: ='增加值 (2001-2060, 2020RMB)'!BI18*$B$73 -> 105.91022
A19: 开采专业及辅助性活动 | I19: ='增加值 (2001-2060, 2020RMB)'!I19*$B$73 -> 85.717113 | J19: ='增加值 (2001-2060, 2020RMB)'!J19*$B$73 -> 97.654766 | K19: ='增加值 (2001-2060, 2020RMB)'!K19*$B$73 -> 109.73872 | L19: ='增加值 (2001-2060, 2020RMB)'!L19*$B$73 -> 123.65278 | M19: ='增加值 (2001-2060, 2020RMB)'!M19*$B$73 -> 134.43244 | N19: ='增加值 (2001-2060, 2020RMB)'!N19*$B$73 -> 134.21856 | O19: ='增加值 (2001-2060, 2020RMB)'!O19*$B$73 -> 124.43272 | P19: ='增加值 (2001-2060, 2020RMB)'!P19*$B$73 -> 104.00227 | ... BI19: ='增加值 (2001-2060, 2020RMB)'!BI19*$B$73 -> 284.84331
A20: 其他采矿业 | I20: ='增加值 (2001-2060, 2020RMB)'!I20*$B$73 -> 0.57954864 | J20: ='增加值 (2001-2060, 2020RMB)'!J20*$B$73 -> 0.78396292 | K20: ='增加值 (2001-2060, 2020RMB)'!K20*$B$73 -> 0.91891072 | L20: ='增加值 (2001-2060, 2020RMB)'!L20*$B$73 -> 1.0842792 | M20: ='增加值 (2001-2060, 2020RMB)'!M20*$B$73 -> 1.0889994 | N20: ='增加值 (2001-2060, 2020RMB)'!N20*$B$73 -> 1.1648549 | O20: ='增加值 (2001-2060, 2020RMB)'!O20*$B$73 -> 1.083276 | P20: ='增加值 (2001-2060, 2020RMB)'!P20*$B$73 -> 1.0523771 | ... BI20: ='增加值 (2001-2060, 2020RMB)'!BI20*$B$73 -> 1.2042161
A21: 农副食品加工业 | I21: ='增加值 (2001-2060, 2020RMB)'!I21*$B$73 -> 833.39094 | J21: ='增加值 (2001-2060, 2020RMB)'!J21*$B$73 -> 915.61705 | K21: ='增加值 (2001-2060, 2020RMB)'!K21*$B$73 -> 1022.5446 | L21: ='增加值 (2001-2060, 2020RMB)'!L21*$B$73 -> 1121.0818 | M21: ='增加值 (2001-2060, 2020RMB)'!M21*$B$73 -> 1212.4106 | N21: ='增加值 (2001-2060, 2020RMB)'!N21*$B$73 -> 1260.0066 | O21: ='增加值 (2001-2060, 2020RMB)'!O21*$B$73 -> 1301.0203 | P21: ='增加值 (2001-2060, 2020RMB)'!P21*$B$73 -> 1302.1735 | ... BI21: ='增加值 (2001-2060, 2020RMB)'!BI21*$B$73 -> 1123.5909
A22: 食品制造业 | I22: ='增加值 (2001-2060, 2020RMB)'!I22*$B$73 -> 391.28881 | J22: ='增加值 (2001-2060, 2020RMB)'!J22*$B$73 -> 423.21858 | K22: ='增加值 (2001-2060, 2020RMB)'!K22*$B$73 -> 473.46484 | L22: ='增加值 (2001-2060, 2020RMB)'!L22*$B$73 -> 532.73846 | M22: ='增加值 (2001-2060, 2020RMB)'!M22*$B$73 -> 567.00898 | N22: ='增加值 (2001-2060, 2020RMB)'!N22*$B$73 -> 592.50009 | O22: ='增加值 (2001-2060, 2020RMB)'!O22*$B$73 -> 616.89858 | P22: ='增加值 (2001-2060, 2020RMB)'!P22*$B$73 -> 629.15052 | ... BI22: ='增加值 (2001-2060, 2020RMB)'!BI22*$B$73 -> 816.17992
A23: 酒、饮料和精制茶制造业 | I23: ='增加值 (2001-2060, 2020RMB)'!I23*$B$73 -> 416.04114 | J23: ='增加值 (2001-2060, 2020RMB)'!J23*$B$73 -> 451.96266 | K23: ='增加值 (2001-2060, 2020RMB)'!K23*$B$73 -> 502.98809 | L23: ='增加值 (2001-2060, 2020RMB)'!L23*$B$73 -> 574.65737 | M23: ='增加值 (2001-2060, 2020RMB)'!M23*$B$73 -> 615.45397 | N23: ='增加值 (2001-2060, 2020RMB)'!N23*$B$73 -> 644.29235 | O23: ='增加值 (2001-2060, 2020RMB)'!O23*$B$73 -> 657.85187 | P23: ='增加值 (2001-2060, 2020RMB)'!P23*$B$73 -> 672.16537 | ... BI23: ='增加值 (2001-2060, 2020RMB)'!BI23*$B$73 -> 966.81921
A24: 烟草制品业 | I24: ='增加值 (2001-2060, 2020RMB)'!I24*$B$73 -> 814.11627 | J24: ='增加值 (2001-2060, 2020RMB)'!J24*$B$73 -> 835.01708 | K24: ='增加值 (2001-2060, 2020RMB)'!K24*$B$73 -> 907.39414 | L24: ='增加值 (2001-2060, 2020RMB)'!L24*$B$73 -> 981.75649 | M24: ='增加值 (2001-2060, 2020RMB)'!M24*$B$73 -> 1021.5462 | N24: ='增加值 (2001-2060, 2020RMB)'!N24*$B$73 -> 1040.3 | O24: ='增加值 (2001-2060, 2020RMB)'!O24*$B$73 -> 1079.149 | P24: ='增加值 (2001-2060, 2020RMB)'!P24*$B$73 -> 1058.6058 | ... BI24: ='增加值 (2001-2060, 2020RMB)'!BI24*$B$73 -> 1012.4
A25: 纺织业 | I25: ='增加值 (2001-2060, 2020RMB)'!I25*$B$73 -> 777.95992 | J25: ='增加值 (2001-2060, 2020RMB)'!J25*$B$73 -> 800.14486 | K25: ='增加值 (2001-2060, 2020RMB)'!K25*$B$73 -> 867.1682 | L25: ='增加值 (2001-2060, 2020RMB)'!L25*$B$73 -> 902.40443 | M25: ='增加值 (2001-2060, 2020RMB)'!M25*$B$73 -> 963.89151 | N25: ='增加值 (2001-2060, 2020RMB)'!N25*$B$73 -> 995.32176 | O25: ='增加值 (2001-2060, 2020RMB)'!O25*$B$73 -> 1018.1774 | P25: ='增加值 (2001-2060, 2020RMB)'!P25*$B$73 -> 1033.5692 | ... BI25: ='增加值 (2001-2060, 2020RMB)'!BI25*$B$73 -> 554.17911
... A54: 水的生产和供应业 | I54: ='增加值 (2001-2060, 2020RMB)'!I54*$B$73 -> 106.41261 | J54: ='增加值 (2001-2060, 2020RMB)'!J54*$B$73 -> 106.01748 | K54: ='增加值 (2001-2060, 2020RMB)'!K54*$B$73 -> 108.72062 | L54: ='增加值 (2001-2060, 2020RMB)'!L54*$B$73 -> 112.09366 | M54: ='增加值 (2001-2060, 2020RMB)'!M54*$B$73 -> 111.51452 | N54: ='增加值 (2001-2060, 2020RMB)'!N54*$B$73 -> 113.03206 | O54: ='增加值 (2001-2060, 2020RMB)'!O54*$B$73 -> 116.38619 | P54: ='增加值 (2001-2060, 2020RMB)'!P54*$B$73 -> 116.59977 | ... BI54: ='增加值 (2001-2060, 2020RMB)'!BI54*$B$73 -> 390.32718
A56: 第三产业 | B56: ='增加值 (2001-2060, 2020RMB)'!B56*$B$73 -> 11730.483 | C56: ='增加值 (2001-2060, 2020RMB)'!C56*$B$73 -> 13108.874 | D56: ='增加值 (2001-2060, 2020RMB)'!D56*$B$73 -> 14337.784 | E56: ='增加值 (2001-2060, 2020RMB)'!E56*$B$73 -> 15459.422 | F56: ='增加值 (2001-2060, 2020RMB)'!F56*$B$73 -> 17273.636 | G56: ='增加值 (2001-2060, 2020RMB)'!G56*$B$73 -> 19694.761 | H56: ='增加值 (2001-2060, 2020RMB)'!H56*$B$73 -> 23078.243 | I56: ='增加值 (2001-2060, 2020RMB)'!I56*$B$73 -> 25291.652 | ... BI56: ='增加值 (2001-2060, 2020RMB)'!BI56*$B$73 -> 344054.44
A57: 交运仓邮 | B57: ='增加值 (2001-2060, 2020RMB)'!B57*$B$73 -> 1779.9866 | C57: ='增加值 (2001-2060, 2020RMB)'!C57*$B$73 -> 1929.1589 | D57: ='增加值 (2001-2060, 2020RMB)'!D57*$B$73 -> 1985.0249 | E57: ='增加值 (2001-2060, 2020RMB)'!E57*$B$73 -> 2182.0744 | F57: ='增加值 (2001-2060, 2020RMB)'!F57*$B$73 -> 2407.6245 | G57: ='增加值 (2001-2060, 2020RMB)'!G57*$B$73 -> 2645.6826 | H57: ='增加值 (2001-2060, 2020RMB)'!H57*$B$73 -> 2941.9625 | I57: ='增加值 (2001-2060, 2020RMB)'!I57*$B$73 -> 3059.9397 | ... BI57: ='增加值 (2001-2060, 2020RMB)'!BI57*$B$73 -> 9071.0148
A58: 批发零售 | B58: ='增加值 (2001-2060, 2020RMB)'!B58*$B$73 -> 2362.7118 | C58: ='增加值 (2001-2060, 2020RMB)'!C58*$B$73 -> 2573.3444 | D58: ='增加值 (2001-2060, 2020RMB)'!D58*$B$73 -> 2801.7271 | E58: ='增加值 (2001-2060, 2020RMB)'!E58*$B$73 -> 2920.4838 | F58: ='增加值 (2001-2060, 2020RMB)'!F58*$B$73 -> 3152.2667 | G58: ='增加值 (2001-2060, 2020RMB)'!G58*$B$73 -> 3589.4511 | H58: ='增加值 (2001-2060, 2020RMB)'!H58*$B$73 -> 4218.2478 | I58: ='增加值 (2001-2060, 2020RMB)'!I58*$B$73 -> 4895.5371 | ... BI58: ='增加值 (2001-2060, 2020RMB)'!BI58*$B$73 -> 22177.568
A59: 餐饮住宿 | B59: ='增加值 (2001-2060, 2020RMB)'!B59*$B$73 -> 621.73763 | C59: ='增加值 (2001-2060, 2020RMB)'!C59*$B$73 -> 701.40934 | D59: ='增加值 (2001-2060, 2020RMB)'!D59*$B$73 -> 784.02312 | E59: ='增加值 (2001-2060, 2020RMB)'!E59*$B$73 -> 859.27754 | F59: ='增加值 (2001-2060, 2020RMB)'!F59*$B$73 -> 946.8422 | G59: ='增加值 (2001-2060, 2020RMB)'!G59*$B$73 -> 1040.4879 | H59: ='增加值 (2001-2060, 2020RMB)'!H59*$B$73 -> 1117.5755 | I59: ='增加值 (2001-2060, 2020RMB)'!I59*$B$73 -> 1236.8867 | ... BI59: ='增加值 (2001-2060, 2020RMB)'!BI59*$B$73 -> 3786.9976
A60: 金融业 | B60: ='增加值 (2001-2060, 2020RMB)'!B60*$B$73 -> 1347.7674 | C60: ='增加值 (2001-2060, 2020RMB)'!C60*$B$73 -> 1430.1564 | D60: ='增加值 (2001-2060, 2020RMB)'!D60*$B$73 -> 1516.2562 | E60: ='增加值 (2001-2060, 2020RMB)'!E60*$B$73 -> 1547.5343 | F60: ='增加值 (2001-2060, 2020RMB)'!F60*$B$73 -> 1689.3631 | G60: ='增加值 (2001-2060, 2020RMB)'!G60*$B$73 -> 2165.0165 | H60: ='增加值 (2001-2060, 2020RMB)'!H60*$B$73 -> 3061.7955 | I60: ='增加值 (2001-2060, 2020RMB)'!I60*$B$73 -> 3429.7288 | ... BI60: ='增加值 (2001-2060, 2020RMB)'!BI60*$B$73 -> 21655.802
A61: 房地产 | B61: ='增加值 (2001-2060, 2020RMB)'!B61*$B$73 -> 1219.0213 | C61: ='增加值 (2001-2060, 2020RMB)'!C61*$B$73 -> 1373.19 | D61: ='增加值 (2001-2060, 2020RMB)'!D61*$B$73 -> 1544.1702 | E61: ='增加值 (2001-2060, 2020RMB)'!E61*$B$73 -> 1676.937 | F61: ='增加值 (2001-2060, 2020RMB)'!F61*$B$73 -> 1914.288 | G61: ='增加值 (2001-2060, 2020RMB)'!G61*$B$73 -> 2240.6986 | H61: ='增加值 (2001-2060, 2020RMB)'!H61*$B$73 -> 2762.4647 | I61: ='增加值 (2001-2060, 2020RMB)'!I61*$B$73 -> 2729.5411 | ... BI61: ='增加值 (2001-2060, 2020RMB)'!BI61*$B$73 -> 19597.345
A62: 信息传输、软件和信息技术服务 | K62: ='增加值 (2001-2060, 2020RMB)'!K62*$B$73 -> 1585.7514 | L62: ='增加值 (2001-2060, 2020RMB)'!L62*$B$73 -> 1671.5039 | M62: ='增加值 (2001-2060, 2020RMB)'!M62*$B$73 -> 1891.467 | N62: ='增加值 (2001-2060, 2020RMB)'!N62*$B$73 -> 2131.6109 | O62: ='增加值 (2001-2060, 2020RMB)'!O62*$B$73 -> 2376.8126 | P62: ='增加值 (2001-2060, 2020RMB)'!P62*$B$73 -> 2690.219 | Q62: ='增加值 (2001-2060, 2020RMB)'!Q62*$B$73 -> 3046.3629 | R62: ='增加值 (2001-2060, 2020RMB)'!R62*$B$73 -> 3456.28 | ... BI62: ='增加值 (2001-2060, 2020RMB)'!BI62*$B$73 -> 111665.24
A63: 租赁和商务服务 | K63: ='增加值 (2001-2060, 2020RMB)'!K63*$B$73 -> 1272.1127 | L63: ='增加值 (2001-2060, 2020RMB)'!L63*$B$73 -> 1484.2205 | M63: ='增加值 (2001-2060, 2020RMB)'!M63*$B$73 -> 1726.3539 | N63: ='增加值 (2001-2060, 2020RMB)'!N63*$B$73 -> 2003.5562 | O63: ='增加值 (2001-2060, 2020RMB)'!O63*$B$73 -> 2373.8474 | P63: ='增加值 (2001-2060, 2020RMB)'!P63*$B$73 -> 2778.2046 | Q63: ='增加值 (2001-2060, 2020RMB)'!Q63*$B$73 -> 3258.9744 | R63: ='增加值 (2001-2060, 2020RMB)'!R63*$B$73 -> 3668.8634 | ... BI63: ='增加值 (2001-2060, 2020RMB)'!BI63*$B$73 -> 42499.191
A64: 科学研究和技术服务 | K64: ='增加值 (2001-2060, 2020RMB)'!K64*$B$73 -> 1132.7196 | L64: ='增加值 (2001-2060, 2020RMB)'!L64*$B$73 -> 1288.6969 | M64: ='增加值 (2001-2060, 2020RMB)'!M64*$B$73 -> 1499.4007 | N64: ='增加值 (2001-2060, 2020RMB)'!N64*$B$73 -> 1711.412 | O64: ='增加值 (2001-2060, 2020RMB)'!O64*$B$73 -> 1916.7397 | P64: ='增加值 (2001-2060, 2020RMB)'!P64*$B$73 -> 2132.7873 | Q64: ='增加值 (2001-2060, 2020RMB)'!Q64*$B$73 -> 2330.3561 | R64: ='增加值 (2001-2060, 2020RMB)'!R64*$B$73 -> 2532.4046 | ... BI64: ='增加值 (2001-2060, 2020RMB)'!BI64*$B$73 -> 24042.124
A65: 水利、环境和公共设施管理 | K65: ='增加值 (2001-2060, 2020RMB)'!K65*$B$73 -> 356.60438 | L65: ='增加值 (2001-2060, 2020RMB)'!L65*$B$73 -> 405.40231 | M65: ='增加值 (2001-2060, 2020RMB)'!M65*$B$73 -> 479.6097 | N65: ='增加值 (2001-2060, 2020RMB)'!N65*$B$73 -> 569.0268 | O65: ='增加值 (2001-2060, 2020RMB)'!O65*$B$73 -> 605.45685 | P65: ='增加值 (2001-2060, 2020RMB)'!P65*$B$73 -> 634.06776 | Q65: ='增加值 (2001-2060, 2020RMB)'!Q65*$B$73 -> 659.19429 | R65: ='增加值 (2001-2060, 2020RMB)'!R65*$B$73 -> 668.14822 | ... BI65: ='增加值 (2001-2060, 2020RMB)'!BI65*$B$73 -> 2695.2914
A66: 居民服务、修理和其他服务 | K66: ='增加值 (2001-2060, 2020RMB)'!K66*$B$73 -> 1131.6157 | L66: ='增加值 (2001-2060, 2020RMB)'!L66*$B$73 -> 1228.6644 | M66: ='增加值 (2001-2060, 2020RMB)'!M66*$B$73 -> 1304.6361 | N66: ='增加值 (2001-2060, 2020RMB)'!N66*$B$73 -> 1351.918 | O66: ='增加值 (2001-2060, 2020RMB)'!O66*$B$73 -> 1480.0346 | P66: ='增加值 (2001-2060, 2020RMB)'!P66*$B$73 -> 1625.8986 | Q66: ='增加值 (2001-2060, 2020RMB)'!Q66*$B$73 -> 1844.3241 | R66: ='增加值 (2001-2060, 2020RMB)'!R66*$B$73 -> 1992.4829 | ... BI66: ='增加值 (2001-2060, 2020RMB)'!BI66*$B$73 -> 10216.664
A67: 教育 | K67: ='增加值 (2001-2060, 2020RMB)'!K67*$B$73 -> 2167.1895 | L67: ='增加值 (2001-2060, 2020RMB)'!L67*$B$73 -> 2396.5338 | M67: ='增加值 (2001-2060, 2020RMB)'!M67*$B$73 -> 2639.4152 | N67: ='增加值 (2001-2060, 2020RMB)'!N67*$B$73 -> 2942.3084 | O67: ='增加值 (2001-2060, 2020RMB)'!O67*$B$73 -> 3258.7341 | P67: ='增加值 (2001-2060, 2020RMB)'!P67*$B$73 -> 3742.8059 | Q67: ='增加值 (2001-2060, 2020RMB)'!Q67*$B$73 -> 4081.9152 | R67: ='增加值 (2001-2060, 2020RMB)'!R67*$B$73 -> 4385.2798 | ... BI67: ='增加值 (2001-2060, 2020RMB)'!BI67*$B$73 -> 27145.174
A68: 卫生和社会工作 | K68: ='增加值 (2001-2060, 2020RMB)'!K68*$B$73 -> 1031.9816 | L68: ='增加值 (2001-2060, 2020RMB)'!L68*$B$73 -> 1204.9985 | M68: ='增加值 (2001-2060, 2020RMB)'!M68*$B$73 -> 1428.8554 | N68: ='增加值 (2001-2060, 2020RMB)'!N68*$B$73 -> 1713.1509 | O68: ='增加值 (2001-2060, 2020RMB)'!O68*$B$73 -> 1943.9791 | P68: ='增加值 (2001-2060, 2020RMB)'!P68*$B$73 -> 2267.6607 | Q68: ='增加值 (2001-2060, 2020RMB)'!Q68*$B$73 -> 2538.1387 | R68: ='增加值 (2001-2060, 2020RMB)'!R68*$B$73 -> 2692.6841 | ... BI68: ='增加值 (2001-2060, 2020RMB)'!BI68*$B$73 -> 10320.559
A69: 文化、体育和娱乐 | K69: ='增加值 (2001-2060, 2020RMB)'!K69*$B$73 -> 495.48927 | L69: ='增加值 (2001-2060, 2020RMB)'!L69*$B$73 -> 539.48207 | M69: ='增加值 (2001-2060, 2020RMB)'!M69*$B$73 -> 595.91668 | N69: ='增加值 (2001-2060, 2020RMB)'!N69*$B$73 -> 642.43158 | O69: ='增加值 (2001-2060, 2020RMB)'!O69*$B$73 -> 688.38857 | P69: ='增加值 (2001-2060, 2020RMB)'!P69*$B$73 -> 777.69518 | Q69: ='增加值 (2001-2060, 2020RMB)'!Q69*$B$73 -> 844.66364 | R69: ='增加值 (2001-2060, 2020RMB)'!R69*$B$73 -> 961.79317 | ... BI69: ='增加值 (2001-2060, 2020RMB)'!BI69*$B$73 -> 4744.165
A70: 公共管理、社会保障和社会组织 | K70: ='增加值 (2001-2060, 2020RMB)'!K70*$B$73 -> 2856.6725 | L70: ='增加值 (2001-2060, 2020RMB)'!L70*$B$73 -> 2932.5284 | M70: ='增加值 (2001-2060, 2020RMB)'!M70*$B$73 -> 3187.4137 | N70: ='增加值 (2001-2060, 2020RMB)'!N70*$B$73 -> 3367.9568 | O70: ='增加值 (2001-2060, 2020RMB)'!O70*$B$73 -> 3733.4944 | P70: ='增加值 (2001-2060, 2020RMB)'!P70*$B$73 -> 4368.995 | Q70: ='增加值 (2001-2060, 2020RMB)'!Q70*$B$73 -> 5123.8406 | R70: ='增加值 (2001-2060, 2020RMB)'!R70*$B$73 -> 5639.5856 | ... BI70: ='增加值 (2001-2060, 2020RMB)'!BI70*$B$73 -> 34437.311
...

Sheet 增加值 (2001-2060, 2020RMB)
A1: 全国 | B1: 2001 | C1: 2002 | D1: 2003 | E1: 2004 | F1: 2005 | G1: 2006 | H1: 2007 | I1: 2008 | J1: 2009 | K1: 2010 | L1: 2011 | M1: 2012 | N1: 2013 | O1: 2014 | P1: 2015 | Q1: 2016 | R1: 2017 | S1: 2018 | T1: 2019 | U1: 2020 | V1: 2021 | W1: 2022 | X1: 2023 | Y1: 2024 | Z1: 2025 | AA1: 2026 | AB1: 2027 | AC1: 2028 | AD1: 2029 | AE1: 2030 | AF1: 2031 | AG1: 2032 | AH1: 2033 | AI1: 2034 | AJ1: 2035 | AK1: 2036 | AL1: 2037 | AM1: 2038 | AN1: 2039 | AO1: 2040 | AP1: 2041 | AQ1: 2042 | AR1: 2043 | AS1: 2044 | AT1: 2045 | AU1: 2046 | AV1: 2047 | AW1: 2048 | AX1: 2049 | AY1: 2050 | AZ1: 2051 | BA1: 2052 | BB1: 2053 | BC1: 2054 | BD1: 2055 | BE1: 2056 | BF1: 2057 | BG1: 2058 | BH1: 2059 | BI1: 2060
A2: 地区生产总值 | B2: ='增加值 (2001-2022, 当年价) '!B2*B$77 -> 208489.63 | C2: ='增加值 (2001-2022, 当年价) '!C2*C$77 -> 227462.19 | D2: ='增加值 (2001-2022, 当年价) '!D2*D$77 -> 250208.41 | E2: ='增加值 (2001-2022, 当年价) '!E2*E$77 -> 275479.46 | F2: ='增加值 (2001-2022, 当年价) '!F2*F$77 -> 306884.11 | G2: ='增加值 (2001-2022, 当年价) '!G2*G$77 -> 345858.4 | H2: ='增加值 (2001-2022, 当年价) '!H2*H$77 -> 394970.29 | I2: ='增加值 (2001-2022, 当年价) '!I2*I$77 -> 433282.41 | ... W2: ='增加值 (2001-2022, 当年价) '!W2*W$77 -> 1131667.8 | X2: =VLOOKUP($A2,平滑数据导入!$A$1:$AN$61,COLUMN(平滑数据导入!C$1),0) -> 1191674.2 | Y2: =VLOOKUP($A2,平滑数据导入!$A$1:$AN$61,COLUMN(平滑数据导入!D$1),0) -> 1256332.4 | Z2: =W2*(1+情景假设!B3)^3 -> 1325076 | AA2: =VLOOKUP($A2,平滑数据导入!$A$1:$AN$61,COLUMN(平滑数据导入!F$1),0) -> 1397204.6 | AB2: =VLOOKUP($A2,平滑数据导入!$A$1:$AN$61,COLUMN(平滑数据导入!G$1),0) -> 1471850.3 | AC2: =VLOOKUP($A2,平滑数据导入!$A$1:$AN$61,COLUMN(平滑数据导入!H$1),0) -> 1547952.3 | AD2: =VLOOKUP($A2,平滑数据导入!$A$1:$AN$61,COLUMN(平滑数据导入!I$1),0) -> 1624241.1 | AE2: =Z2*(1+情景假设!B4)^5 -> 1699238.7 | AF2: =VLOOKUP($A2,平滑数据导入!$A$1:$AN$61,COLUMN(平滑数据导入!K$1),0) -> 1771676 | AG2: =VLOOKUP($A2,平滑数据导入!$A$1:$AN$61,COLUMN(平滑数据导入!L$1),0) -> 1841829.8 | AH2: =VLOOKUP($A2,平滑数据导入!$A$1:$AN$61,COLUMN(平滑数据导入!M$1),0) -> 1910523.1 | AI2: =VLOOKUP($A2,平滑数据导入!$A$1:$AN$61,COLUMN(平滑数据导入!N$1),0) -> 1978734 | AJ2: =AE2*(1+情景假设!B5)^5 -> 2047581.3 | AK2: =VLOOKUP($A2,平滑数据导入!$A$1:$AN$61,COLUMN(平滑数据导入!P$1),0) -> 2118060.2 | AL2: =VLOOKUP($A2,平滑数据导入!$A$1:$AN$61,COLUMN(平滑数据导入!Q$1),0) -> 2190206.6 | AM2: =VLOOKUP($A2,平滑数据导入!$A$1:$AN$61,COLUMN(平滑数据导入!R$1),0) -> 2263788.7 | AN2: =VLOOKUP($A2,平滑数据导入!$A$1:$AN$61,COLUMN(平滑数据导入!S$1),0) -> 2338554 | AO2: =VLOOKUP($A2,平滑数据导入!$A$1:$AN$61,COLUMN(平滑数据导入!T$1),0) -> 2414227.7 | AP2: =VLOOKUP($A2,平滑数据导入!$A$1:$AN$61,COLUMN(平滑数据导入!U$1),0) -> 2490511.8 | AQ2: =VLOOKUP($A2,平滑数据导入!$A$1:$AN$61,COLUMN(平滑数据导入!V$1),0) -> 2567084.4 | AR2: =VLOOKUP($A2,平滑数据导入!$A$1:$AN$61,COLUMN(平滑数据导入!W$1),0) -> 2643599.3 | ... AX2: =VLOOKUP($A2,平滑数据导入!$A$1:$AN$61,COLUMN(平滑数据导入!AC$1),0) -> 3079285.8 | AY2: =AJ2*(1+情景假设!B6)^15 -> 3143922.1 | AZ2: =VLOOKUP($A2,平滑数据导入!$A$1:$AN$61,COLUMN(平滑数据导入!AE$1),0) -> 3205047.7 | BA2: =VLOOKUP($A2,平滑数据导入!$A$1:$AN$61,COLUMN(平滑数据导入!AF$1),0) -> 3262198.4 | BB2: =VLOOKUP($A2,平滑数据导入!$A$1:$AN$61,COLUMN(平滑数据导入!AG$1),0) -> 3314921.1 | BC2: =VLOOKUP($A2,平滑数据导入!$A$1:$AN$61,COLUMN(平滑数据导入!AH$1),0) -> 3362781.6 | BD2: =VLOOKUP($A2,平滑数据导入!$A$1:$AN$61,COLUMN(平滑数据导入!AI$1),0) -> 3405372.2 | BE2: =VLOOKUP($A2,平滑数据导入!$A$1:$AN$61,COLUMN(平滑数据导入!AJ$1),0) -> 3442319.7 | BF2: =VLOOKUP($A2,平滑数据导入!$A$1:$AN$61,COLUMN(平滑数据导入!AK$1),0) -> 3473293.8 | BG2: =VLOOKUP($A2,平滑数据导入!$A$1:$AN$61,COLUMN(平滑数据导入!AL$1),0) -> 3498015 | BH2: =VLOOKUP($A2,平滑数据导入!$A$1:$AN$61,COLUMN(平滑数据导入!AM$1),0) -> 3516261.8 | BI2: =AJ2*(1+情景假设!B7)^25 -> 3527877.9
A3: 农业 | B3: ='增加值 (2001-2022, 当年价) '!B3*B$77 -> 29675.937 | C3: ='增加值 (2001-2022, 当年价) '!C3*C$77 -> 30901.469 | D3: ='增加值 (2001-2022, 当年价) '!D3*D$77 -> 31645.386 | E3: ='增加值 (2001-2022, 当年价) '!E3*E$77 -> 36444.641 | F3: ='增加值 (2001-2022, 当年价) '!F3*F$77 -> 36724.408 | G3: ='增加值 (2001-2022, 当年价) '!G3*G$77 -> 37883.921 | H3: ='增加值 (2001-2022, 当年价) '!H3*H$77 -> 41653.225 | I3: ='增加值 (2001-2022, 当年价) '!I3*I$77 -> 45368.998 | ... W3: ='增加值 (2001-2022, 当年价) '!W3*W$77 -> 86574.037 | X3: =VLOOKUP($A3,平滑数据导入!$A$1:$AN$61,COLUMN(平滑数据导入!C$1),0) -> 89111.56 | Y3: =VLOOKUP($A3,平滑数据导入!$A$1:$AN$61,COLUMN(平滑数据导入!D$1),0) -> 92551.325 | Z3: =Z2*情景假设!B15 -> 96730.551 | AA3: =VLOOKUP($A3,平滑数据导入!$A$1:$AN$61,COLUMN(平滑数据导入!F$1),0) -> 101462.91 | AB3: =VLOOKUP($A3,平滑数据导入!$A$1:$AN$61,COLUMN(平滑数据导入!G$1),0) -> 106523.11 | AC3: =VLOOKUP($A3,平滑数据导入!$A$1:$AN$61,COLUMN(平滑数据导入!H$1),0) -> 111635.79 | AD3: =VLOOKUP($A3,平滑数据导入!$A$1:$AN$61,COLUMN(平滑数据导入!I$1),0) -> 116470.61 | AE3: =AE2*情景假设!B16 -> 120645.95 | AF3: =VLOOKUP($A3,平滑数据导入!$A$1:$AN$61,COLUMN(平滑数据导入!K$1),0) -> 123851.07 | AG3: =VLOOKUP($A3,平滑数据导入!$A$1:$AN$61,COLUMN(平滑数据导入!L$1),0) -> 126209.58 | AH3: =VLOOKUP($A3,平滑数据导入!$A$1:$AN$61,COLUMN(平滑数据导入!M$1),0) -> 127991.81 | AI3: =VLOOKUP($A3,平滑数据导入!$A$1:$AN$61,COLUMN(平滑数据导入!N$1),0) -> 129497.44 | AJ3: =AJ2*情景假设!B17 -> 131045.2 | AK3: =VLOOKUP($A3,平滑数据导入!$A$1:$AN$61,COLUMN(平滑数据导入!P$1),0) -> 132907.13 | AL3: =VLOOKUP($A3,平滑数据导入!$A$1:$AN$61,COLUMN(平滑数据导入!Q$1),0) -> 135116.02 | AM3: =VLOOKUP($A3,平滑数据导入!$A$1:$AN$61,COLUMN(平滑数据导入!R$1),0) -> 137643.47 | AN3: =VLOOKUP($A3,平滑数据导入!$A$1:$AN$61,COLUMN(平滑数据导入!S$1),0) -> 140460.19 | AO3: =VLOOKUP($A3,平滑数据导入!$A$1:$AN$61,COLUMN(平滑数据导入!T$1),0) -> 143535.22 | AP3: =VLOOKUP($A3,平滑数据导入!$A$1:$AN$61,COLUMN(平滑数据导入!U$1),0) -> 146835.15 | AQ3: =VLOOKUP($A3,平滑数据导入!$A$1:$AN$61,COLUMN(平滑数据导入!V$1),0) -> 150323.41 | AR3: =VLOOKUP($A3,平滑数据导入!$A$1:$AN$61,COLUMN(平滑数据导入!W$1),0) -> 153959.67 | ... AX3: =VLOOKUP($A3,平滑数据导入!$A$1:$AN$61,COLUMN(平滑数据导入!AC$1),0) -> 176049.97 | AY3: =AY2*情景假设!B18 -> 179203.56 | AZ3: =VLOOKUP($A3,平滑数据导入!$A$1:$AN$61,COLUMN(平滑数据导入!AE$1),0) -> 182016.52 | BA3: =VLOOKUP($A3,平滑数据导入!$A$1:$AN$61,COLUMN(平滑数据导入!AF$1),0) -> 184411.15 | BB3: =VLOOKUP($A3,平滑数据导入!$A$1:$AN$61,COLUMN(平滑数据导入!AG$1),0) -> 186309.28 | BC3: =VLOOKUP($A3,平滑数据导入!$A$1:$AN$61,COLUMN(平滑数据导入!AH$1),0) -> 187633.95 | BD3: =VLOOKUP($A3,平滑数据导入!$A$1:$AN$61,COLUMN(平滑数据导入!AI$1),0) -> 188311.45 | BE3: =VLOOKUP($A3,平滑数据导入!$A$1:$AN$61,COLUMN(平滑数据导入!AJ$1),0) -> 188273.46 | BF3: =VLOOKUP($A3,平滑数据导入!$A$1:$AN$61,COLUMN(平滑数据导入!AK$1),0) -> 187459.42 | BG3: =VLOOKUP($A3,平滑数据导入!$A$1:$AN$61,COLUMN(平滑数据导入!AL$1),0) -> 185818.93 | BH3: =VLOOKUP($A3,平滑数据导入!$A$1:$AN$61,COLUMN(平滑数据导入!AM$1),0) -> 183314.1 | BI3: =BI2*情景假设!B19 -> 179921.77
A4: 工业 | B4: ='增加值 (2001-2022, 当年价) '!B4*B$77 -> 82472.589 | C4: ='增加值 (2001-2022, 当年价) '!C4*C$77 -> 89280.442 | D4: ='增加值 (2001-2022, 当年价) '!D4*D$77 -> 100799.64 | E4: ='增加值 (2001-2022, 当年价) '!E4*E$77 -> 111960.03 | F4: ='增加值 (2001-2022, 当年价) '!F4*F$77 -> 127718.9 | G4: ='增加值 (2001-2022, 当年价) '!G4*G$77 -> 145373.42 | H4: ='增加值 (2001-2022, 当年价) '!H4*H$77 -> 163331.38 | I4: ='增加值 (2001-2022, 当年价) '!I4*I$77 -> 178777.31 | ... W4: ='增加值 (2001-2022, 当年价) '!W4*W$77 -> 375578.61 | X4: =VLOOKUP($A4,平滑数据导入!$A$1:$AN$61,COLUMN(平滑数据导入!C$1),0) -> 388611.81 | Y4: =VLOOKUP($A4,平滑数据导入!$A$1:$AN$61,COLUMN(平滑数据导入!D$1),0) -> 402616.52 | Z4: =Z2*情景假设!D15 -> 417398.95 | AA4: =VLOOKUP($A4,平滑数据导入!$A$1:$AN$61,COLUMN(平滑数据导入!F$1),0) -> 432743.74 | AB4: =VLOOKUP($A4,平滑数据导入!$A$1:$AN$61,COLUMN(平滑数据导入!G$1),0) -> 448409.44 | AC4: =VLOOKUP($A4,平滑数据导入!$A$1:$AN$61,COLUMN(平滑数据导入!H$1),0) -> 464125.57 | AD4: =VLOOKUP($A4,平滑数据导入!$A$1:$AN$61,COLUMN(平滑数据导入!I$1),0) -> 479591.6 | AE4: =AE2*情景假设!D16 -> 494478.45 | AF4: =VLOOKUP($A4,平滑数据导入!$A$1:$AN$61,COLUMN(平滑数据导入!K$1),0) -> 508505.38 | AG4: =VLOOKUP($A4,平滑数据导入!$A$1:$AN$61,COLUMN(平滑数据导入!L$1),0) -> 521674.06 | AH4: =VLOOKUP($A4,平滑数据导入!$A$1:$AN$61,COLUMN(平滑数据导入!M$1),0) -> 534070.3 | AI4: =VLOOKUP($A4,平滑数据导入!$A$1:$AN$61,COLUMN(平滑数据导入!N$1),0) -> 545791.14 | AJ4: =AJ2*情景假设!D17 -> 556942.11 | AK4: =VLOOKUP($A4,平滑数据导入!$A$1:$AN$61,COLUMN(平滑数据导入!P$1),0) -> 567610.38 | AL4: =VLOOKUP($A4,平滑数据导入!$A$1:$AN$61,COLUMN(平滑数据导入!Q$1),0) -> 577789.79 | AM4: =VLOOKUP($A4,平滑数据导入!$A$1:$AN$61,COLUMN(平滑数据导入!R$1),0) -> 587454.19 | AN4: =VLOOKUP($A4,平滑数据导入!$A$1:$AN$61,COLUMN(平滑数据导入!S$1),0) -> 596582.23 | AO4: =VLOOKUP($A4,平滑数据导入!$A$1:$AN$61,COLUMN(平滑数据导入!T$1),0) -> 605157.37 | AP4: =VLOOKUP($A4,平滑数据导入!$A$1:$AN$61,COLUMN(平滑数据导入!U$1),0) -> 613167.94 | AQ4: =VLOOKUP($A4,平滑数据导入!$A$1:$AN$61,COLUMN(平滑数据导入!V$1),0) -> 620607.1 | AR4: =VLOOKUP($A4,平滑数据导入!$A$1:$AN$61,COLUMN(平滑数据导入!W$1),0) -> 627472.76 | ... AX4: =VLOOKUP($A4,平滑数据导入!$A$1:$AN$61,COLUMN(平滑数据导入!AC$1),0) -> 657065.9 | AY4: =AY2*情景假设!D18 -> 660223.63 | AZ4: =VLOOKUP($A4,平滑数据导入!$A$1:$AN$61,COLUMN(平滑数据导入!AE$1),0) -> 662941.57 | BA4: =VLOOKUP($A4,平滑数据导入!$A$1:$AN$61,COLUMN(平滑数据导入!AF$1),0) -> 665252.11 | BB4: =VLOOKUP($A4,平滑数据导入!$A$1:$AN$61,COLUMN(平滑数据导入!AG$1),0) -> 667190.43 | BC4: =VLOOKUP($A4,平滑数据导入!$A$1:$AN$61,COLUMN(平滑数据导入!AH$1),0) -> 668794.37 | BD4: =VLOOKUP($A4,平滑数据导入!$A$1:$AN$61,COLUMN(平滑数据导入!AI$1),0) -> 670104.31 | BE4: =VLOOKUP($A4,平滑数据导入!$A$1:$AN$61,COLUMN(平滑数据导入!AJ$1),0) -> 671163.02 | BF4: =VLOOKUP($A4,平滑数据导入!$A$1:$AN$61,COLUMN(平滑数据导入!AK$1),0) -> 672015.66 | BG4: =VLOOKUP($A4,平滑数据导入!$A$1:$AN$61,COLUMN(平滑数据导入!AL$1),0) -> 672709.76 | BH4: =VLOOKUP($A4,平滑数据导入!$A$1:$AN$61,COLUMN(平滑数据导入!AM$1),0) -> 673295.28 | BI4: =BI2*情景假设!D19 -> 673824.68
A5: 建筑业 | B5: ='增加值 (2001-2022, 当年价) '!B5*B$77 -> 11181.133 | C5: ='增加值 (2001-2022, 当年价) '!C5*C$77 -> 12113.573 | D5: ='增加值 (2001-2022, 当年价) '!D5*D$77 -> 13675.142 | E5: ='增加值 (2001-2022, 当年价) '!E5*E$77 -> 14843.769 | F5: ='增加值 (2001-2022, 当年价) '!F5*F$77 -> 17039.115 | G5: ='增加值 (2001-2022, 当年价) '!G5*G$77 -> 19622.681 | H5: ='增加值 (2001-2022, 当年价) '!H5*H$77 -> 22444.194 | I5: ='增加值 (2001-2022, 当年价) '!I5*I$77 -> 25525.889 | ... W5: ='增加值 (2001-2022, 当年价) '!W5*W$77 -> 77971.749 | X5: =VLOOKUP($A5,平滑数据导入!$A$1:$AN$61,COLUMN(平滑数据导入!C$1),0) -> 81807.142 | Y5: =VLOOKUP($A5,平滑数据导入!$A$1:$AN$61,COLUMN(平滑数据导入!D$1),0) -> 85873.041 | Z5: =Z2*情景假设!E15 -> 90105.171 | AA5: =VLOOKUP($A5,平滑数据导入!$A$1:$AN$61,COLUMN(平滑数据导入!F$1),0) -> 94424.654 | AB5: =VLOOKUP($A5,平滑数据导入!$A$1:$AN$61,COLUMN(平滑数据导入!G$1),0) -> 98736.898 | AC5: =VLOOKUP($A5,平滑数据导入!$A$1:$AN$61,COLUMN(平滑数据导入!H$1),0) -> 102931.31 | AD5: =VLOOKUP($A5,平滑数据导入!$A$1:$AN$61,COLUMN(平滑数据导入!I$1),0) -> 106882.12 | AE5: =AE2*情景假设!E16 -> 110450.51 | AF5: =VLOOKUP($A5,平滑数据导入!$A$1:$AN$61,COLUMN(平滑数据导入!K$1),0) -> 113529.67 | AG5: =VLOOKUP($A5,平滑数据导入!$A$1:$AN$61,COLUMN(平滑数据导入!L$1),0) -> 116181.56 | AH5: =VLOOKUP($A5,平滑数据导入!$A$1:$AN$61,COLUMN(平滑数据导入!M$1),0) -> 118526.82 | AI5: =VLOOKUP($A5,平滑数据导入!$A$1:$AN$61,COLUMN(平滑数据导入!N$1),0) -> 120701.65 | AJ5: =AJ2*情景假设!E17 -> 122854.88 | AK5: =VLOOKUP($A5,平滑数据导入!$A$1:$AN$61,COLUMN(平滑数据导入!P$1),0) -> 125116.94 | AL5: =VLOOKUP($A5,平滑数据导入!$A$1:$AN$61,COLUMN(平滑数据导入!Q$1),0) -> 127506.41 | AM5: =VLOOKUP($A5,平滑数据导入!$A$1:$AN$61,COLUMN(平滑数据导入!R$1),0) -> 130012.21 | AN5: =VLOOKUP($A5,平滑数据导入!$A$1:$AN$61,COLUMN(平滑数据导入!S$1),0) -> 132622.3 | AO5: =VLOOKUP($A5,平滑数据导入!$A$1:$AN$61,COLUMN(平滑数据导入!T$1),0) -> 135323.54 | AP5: =VLOOKUP($A5,平滑数据导入!$A$1:$AN$61,COLUMN(平滑数据导入!U$1),0) -> 138101.55 | AQ5: =VLOOKUP($A5,平滑数据导入!$A$1:$AN$61,COLUMN(平滑数据导入!V$1),0) -> 140940.64 | AR5: =VLOOKUP($A5,平滑数据导入!$A$1:$AN$61,COLUMN(平滑数据导入!W$1),0) -> 143823.71 | ... AX5: =VLOOKUP($A5,平滑数据导入!$A$1:$AN$61,COLUMN(平滑数据导入!AC$1),0) -> 160898.2 | AY5: =AY2*情景假设!E18 -> 163483.95 | AZ5: =VLOOKUP($A5,平滑数据导入!$A$1:$AN$61,COLUMN(平滑数据导入!AE$1),0) -> 165923.58 | BA5: =VLOOKUP($A5,平滑数据导入!$A$1:$AN$61,COLUMN(平滑数据导入!AF$1),0) -> 168187.69 | BB5: =VLOOKUP($A5,平滑数据导入!$A$1:$AN$61,COLUMN(平滑数据导入!AG$1),0) -> 170246.24 | BC5: =VLOOKUP($A5,平滑数据导入!$A$1:$AN$61,COLUMN(平滑数据导入!AH$1),0) -> 172068.79 | BD5: =VLOOKUP($A5,平滑数据导入!$A$1:$AN$61,COLUMN(平滑数据导入!AI$1),0) -> 173624.89 | BE5: =VLOOKUP($A5,平滑数据导入!$A$1:$AN$61,COLUMN(平滑数据导入!AJ$1),0) -> 174884.48 | BF5: =VLOOKUP($A5,平滑数据导入!$A$1:$AN$61,COLUMN(平滑数据导入!AK$1),0) -> 175818.27 | BG5: =VLOOKUP($A5,平滑数据导入!$A$1:$AN$61,COLUMN(平滑数据导入!AL$1),0) -> 176398.24 | BH5: =VLOOKUP($A5,平滑数据导入!$A$1:$AN$61,COLUMN(平滑数据导入!AM$1),0) -> 176598.12 | BI5: =BI2*情景假设!E19 -> 176393.89
A6: 交运仓邮 | B6: ='增加值 (2001-2022, 当年价) '!B6*B$77 -> 12922.197 | C6: ='增加值 (2001-2022, 当年价) '!C6*C$77 -> 14005.145 | D6: ='增加值 (2001-2022, 当年价) '!D6*D$77 -> 14410.717 | E6: ='增加值 (2001-2022, 当年价) '!E6*E$77 -> 15841.241 | F6: ='增加值 (2001-2022, 当年价) '!F6*F$77 -> 17478.67 | G6: ='增加值 (2001-2022, 当年价) '!G6*G$77 -> 19206.904 | H6: ='增加值 (2001-2022, 当年价) '!H6*H$77 -> 21357.812 | I6: ='增加值 (2001-2022, 当年价) '!I6*I$77 -> 22214.293 | ... W6: ='增加值 (2001-2022, 当年价) '!W6*W$77 -> 46450.003 | X6: =VLOOKUP($A6,平滑数据导入!$A$1:$AN$61,COLUMN(平滑数据导入!C$1),0) -> 48503.015 | Y6: =VLOOKUP($A6,平滑数据导入!$A$1:$AN$61,COLUMN(平滑数据导入!D$1),0) -> 50559.101 | Z6: =Z57 -> 52600.681 | AA6: =VLOOKUP($A6,平滑数据导入!$A$1:$AN$61,COLUMN(平滑数据导入!F$1),0) -> 54608.297 | AB6: =VLOOKUP($A6,平滑数据导入!$A$1:$AN$61,COLUMN(平滑数据导入!G$1),0) -> 56560.723 | AC6: =VLOOKUP($A6,平滑数据导入!$A$1:$AN$61,COLUMN(平滑数据导入!H$1),0) -> 58435.148 | AD6: =VLOOKUP($A6,平滑数据导入!$A$1:$AN$61,COLUMN(平滑数据导入!I$1),0) -> 60207.423 | AE6: =AE57 -> 61852.383 | AF6: =VLOOKUP($A6,平滑数据导入!$A$1:$AN$61,COLUMN(平滑数据导入!K$1),0) -> 63352.732 | AG6: =VLOOKUP($A6,平滑数据导入!$A$1:$AN$61,COLUMN(平滑数据导入!L$1),0) -> 64726.421 | AH6: =VLOOKUP($A6,平滑数据导入!$A$1:$AN$61,COLUMN(平滑数据导入!M$1),0) -> 66003.682 | AI6: =VLOOKUP($A6,平滑数据导入!$A$1:$AN$61,COLUMN(平滑数据导入!N$1),0) -> 67218.384 | AJ6: =AJ57 -> 68407.593 | AK6: =VLOOKUP($A6,平滑数据导入!$A$1:$AN$61,COLUMN(平滑数据导入!P$1),0) -> 69602.322 | AL6: =VLOOKUP($A6,平滑数据导入!$A$1:$AN$61,COLUMN(平滑数据导入!Q$1),0) -> 70799.227 | AM6: =VLOOKUP($A6,平滑数据导入!$A$1:$AN$61,COLUMN(平滑数据导入!R$1),0) -> 71985.447 | AN6: =VLOOKUP($A6,平滑数据导入!$A$1:$AN$61,COLUMN(平滑数据导入!S$1),0) -> 73147.306 | AO6: =VLOOKUP($A6,平滑数据导入!$A$1:$AN$61,COLUMN(平滑数据导入!T$1),0) -> 74270.343 | AP6: =VLOOKUP($A6,平滑数据导入!$A$1:$AN$61,COLUMN(平滑数据导入!U$1),0) -> 75339.377 | AQ6: =VLOOKUP($A6,平滑数据导入!$A$1:$AN$61,COLUMN(平滑数据导入!V$1),0) -> 76338.594 | AR6: =VLOOKUP($A6,平滑数据导入!$A$1:$AN$61,COLUMN(平滑数据导入!W$1),0) -> 77251.665 | ... AX6: =VLOOKUP($A6,平滑数据导入!$A$1:$AN$61,COLUMN(平滑数据导入!AC$1),0) -> 79987.238 | AY6: =AY57 -> 79837.009 | AZ6: =VLOOKUP($A6,平滑数据导入!$A$1:$AN$61,COLUMN(平滑数据导入!AE$1),0) -> 79476.3 | BA6: =VLOOKUP($A6,平滑数据导入!$A$1:$AN$61,COLUMN(平滑数据导入!AF$1),0) -> 78894.528 | BB6: =VLOOKUP($A6,平滑数据导入!$A$1:$AN$61,COLUMN(平滑数据导入!AG$1),0) -> 78083.273 | BC6: =VLOOKUP($A6,平滑数据导入!$A$1:$AN$61,COLUMN(平滑数据导入!AH$1),0) -> 77036.591 | BD6: =VLOOKUP($A6,平滑数据导入!$A$1:$AN$61,COLUMN(平滑数据导入!AI$1),0) -> 75751.295 | BE6: =VLOOKUP($A6,平滑数据导入!$A$1:$AN$61,COLUMN(平滑数据导入!AJ$1),0) -> 74227.195 | BF6: =VLOOKUP($A6,平滑数据导入!$A$1:$AN$61,COLUMN(平滑数据导入!AK$1),0) -> 72467.296 | BG6: =VLOOKUP($A6,平滑数据导入!$A$1:$AN$61,COLUMN(平滑数据导入!AL$1),0) -> 70477.925 | BH6: =VLOOKUP($A6,平滑数据导入!$A$1:$AN$61,COLUMN(平滑数据导入!AM$1),0) -> 68268.797 | BI6: =BI57 -> 65852.991
A7: 批发零售 | B7: ='增加值 (2001-2022, 当年价) '!B7*B$77 -> 17152.616 | C7: ='增加值 (2001-2022, 当年价) '!C7*C$77 -> 18681.75 | D7: ='增加值 (2001-2022, 当年价) '!D7*D$77 -> 20339.743 | E7: ='增加值 (2001-2022, 当年价) '!E7*E$77 -> 21201.883 | F7: ='增加值 (2001-2022, 当年价) '!F7*F$77 -> 22884.561 | G7: ='增加值 (2001-2022, 当年价) '!G7*G$77 -> 26058.396 | H7: ='增加值 (2001-2022, 当年价) '!H7*H$77 -> 30623.281 | I7: ='增加值 (2001-2022, 当年价) '!I7*I$77 -> 35540.209 | ... W7: ='增加值 (2001-2022, 当年价) '!W7*W$77 -> 107085.79 | X7: =VLOOKUP($A7,平滑数据导入!$A$1:$AN$61,COLUMN(平滑数据导入!C$1),0) -> 112084.11 | Y7: =VLOOKUP($A7,平滑数据导入!$A$1:$AN$61,COLUMN(平滑数据导入!D$1),0) -> 117103.2 | Z7: =Z58 -> 122101.5 | AA7: =VLOOKUP($A7,平滑数据导入!$A$1:$AN$61,COLUMN(平滑数据导入!F$1),0) -> 127032.77 | AB7: =VLOOKUP($A7,平滑数据导入!$A$1:$AN$61,COLUMN(平滑数据导入!G$1),0) -> 131846.32 | AC7: =VLOOKUP($A7,平滑数据导入!$A$1:$AN$61,COLUMN(平滑数据导入!H$1),0) -> 136487.44 | AD7: =VLOOKUP($A7,平滑数据导入!$A$1:$AN$61,COLUMN(平滑数据导入!I$1),0) -> 140898 | AE7: =AE58 -> 145017.16 | AF7: =VLOOKUP($A7,平滑数据导入!$A$1:$AN$61,COLUMN(平滑数据导入!K$1),0) -> 148802.35 | AG7: =VLOOKUP($A7,平滑数据导入!$A$1:$AN$61,COLUMN(平滑数据导入!L$1),0) -> 152294.08 | AH7: =VLOOKUP($A7,平滑数据导入!$A$1:$AN$61,COLUMN(平滑数据导入!M$1),0) -> 155562.36 | AI7: =VLOOKUP($A7,平滑数据导入!$A$1:$AN$61,COLUMN(平滑数据导入!N$1),0) -> 158686.43 | AJ7: =AJ58 -> 161753.71 | AK7: =VLOOKUP($A7,平滑数据导入!$A$1:$AN$61,COLUMN(平滑数据导入!P$1),0) -> 164837.83 | AL7: =VLOOKUP($A7,平滑数据导入!$A$1:$AN$61,COLUMN(平滑数据导入!Q$1),0) -> 167931.01 | AM7: =VLOOKUP($A7,平滑数据导入!$A$1:$AN$61,COLUMN(平滑数据导入!R$1),0) -> 171002.71 | AN7: =VLOOKUP($A7,平滑数据导入!$A$1:$AN$61,COLUMN(平滑数据导入!S$1),0) -> 174020.32 | AO7: =VLOOKUP($A7,平滑数据导入!$A$1:$AN$61,COLUMN(平滑数据导入!T$1),0) -> 176949.17 | AP7: =VLOOKUP($A7,平滑数据导入!$A$1:$AN$61,COLUMN(平滑数据导入!U$1),0) -> 179752.7 | AQ7: =VLOOKUP($A7,平滑数据导入!$A$1:$AN$61,COLUMN(平滑数据导入!V$1),0) -> 182392.67 | AR7: =VLOOKUP($A7,平滑数据导入!$A$1:$AN$61,COLUMN(平滑数据导入!W$1),0) -> 184829.45 | ... AX7: =VLOOKUP($A7,平滑数据导入!$A$1:$AN$61,COLUMN(平滑数据导入!AC$1),0) -> 192894.26 | AY7: =AY58 -> 192776.67 | AZ7: =VLOOKUP($A7,平滑数据导入!$A$1:$AN$61,COLUMN(平滑数据导入!AE$1),0) -> 192147.79 | BA7: =VLOOKUP($A7,平滑数据导入!$A$1:$AN$61,COLUMN(平滑数据导入!AF$1),0) -> 190980.39 | BB7: =VLOOKUP($A7,平滑数据导入!$A$1:$AN$61,COLUMN(平滑数据导入!AG$1),0) -> 189252.38 | BC7: =VLOOKUP($A7,平滑数据导入!$A$1:$AN$61,COLUMN(平滑数据导入!AH$1),0) -> 186947.6 | BD7: =VLOOKUP($A7,平滑数据导入!$A$1:$AN$61,COLUMN(平滑数据导入!AI$1),0) -> 184056.49 | BE7: =VLOOKUP($A7,平滑数据导入!$A$1:$AN$61,COLUMN(平滑数据导入!AJ$1),0) -> 180576.74 | BF7: =VLOOKUP($A7,平滑数据导入!$A$1:$AN$61,COLUMN(平滑数据导入!AK$1),0) -> 176513.79 | BG7: =VLOOKUP($A7,平滑数据导入!$A$1:$AN$61,COLUMN(平滑数据导入!AL$1),0) -> 171881.2 | BH7: =VLOOKUP($A7,平滑数据导入!$A$1:$AN$61,COLUMN(平滑数据导入!AM$1),0) -> 166700.83 | BI7: =BI58 -> 161002.85
A8: 餐饮住宿 | B8: ='增加值 (2001-2022, 当年价) '!B8*B$77 -> 4513.6386 | C8: ='增加值 (2001-2022, 当年价) '!C8*C$77 -> 5092.0326 | D8: ='增加值 (2001-2022, 当年价) '!D8*D$77 -> 5691.7852 | E8: ='增加值 (2001-2022, 当年价) '!E8*E$77 -> 6238.1109 | F8: ='增加值 (2001-2022, 当年价) '!F8*F$77 -> 6873.8055 | G8: ='增加值 (2001-2022, 当年价) '!G8*G$77 -> 7553.6469 | H8: ='增加值 (2001-2022, 当年价) '!H8*H$77 -> 8113.2808 | I8: ='增加值 (2001-2022, 当年价) '!I8*I$77 -> 8979.4463 | ... W8: ='增加值 (2001-2022, 当年价) '!W8*W$77 -> 16696.536 | X8: =VLOOKUP($A8,平滑数据导入!$A$1:$AN$61,COLUMN(平滑数据导入!C$1),0) -> 17540.017 | Y8: =VLOOKUP($A8,平滑数据导入!$A$1:$AN$61,COLUMN(平滑数据导入!D$1),0) -> 18390.439 | Z8: =Z59 -> 19241.079 | AA8: =VLOOKUP($A8,平滑数据导入!$A$1:$AN$61,COLUMN(平滑数据导入!F$1),0) -> 20084.395 | AB8: =VLOOKUP($A8,平滑数据导入!$A$1:$AN$61,COLUMN(平滑数据导入!G$1),0) -> 20912.062 | AC8: =VLOOKUP($A8,平滑数据导入!$A$1:$AN$61,COLUMN(平滑数据导入!H$1),0) -> 21715.034 | AD8: =VLOOKUP($A8,平滑数据导入!$A$1:$AN$61,COLUMN(平滑数据导入!I$1),0) -> 22483.633 | AE8: =AE59 -> 23207.669 | AF8: =VLOOKUP($A8,平滑数据导入!$A$1:$AN$61,COLUMN(平滑数据导入!K$1),0) -> 23879.825 | AG8: =VLOOKUP($A8,平滑数据导入!$A$1:$AN$61,COLUMN(平滑数据导入!L$1),0) -> 24506.191 | AH8: =VLOOKUP($A8,平滑数据导入!$A$1:$AN$61,COLUMN(平滑数据导入!M$1),0) -> 25097.749 | AI8: =VLOOKUP($A8,平滑数据导入!$A$1:$AN$61,COLUMN(平滑数据导入!N$1),0) -> 25667.124 | AJ8: =AJ59 -> 26228.433 | AK8: =VLOOKUP($A8,平滑数据导入!$A$1:$AN$61,COLUMN(平滑数据导入!P$1),0) -> 26793.687 | AL8: =VLOOKUP($A8,平滑数据导入!$A$1:$AN$61,COLUMN(平滑数据导入!Q$1),0) -> 27361.656 | AM8: =VLOOKUP($A8,平滑数据导入!$A$1:$AN$61,COLUMN(平滑数据导入!R$1),0) -> 27927.358 | AN8: =VLOOKUP($A8,平滑数据导入!$A$1:$AN$61,COLUMN(平滑数据导入!S$1),0) -> 28485.426 | AO8: =VLOOKUP($A8,平滑数据导入!$A$1:$AN$61,COLUMN(平滑数据导入!T$1),0) -> 29030.121 | AP8: =VLOOKUP($A8,平滑数据导入!$A$1:$AN$61,COLUMN(平滑数据导入!U$1),0) -> 29555.345 | AQ8: =VLOOKUP($A8,平滑数据导入!$A$1:$AN$61,COLUMN(平滑数据导入!V$1),0) -> 30054.682 | AR8: =VLOOKUP($A8,平滑数据导入!$A$1:$AN$61,COLUMN(平滑数据导入!W$1),0) -> 30521.438 | ... AX8: =VLOOKUP($A8,平滑数据导入!$A$1:$AN$61,COLUMN(平滑数据导入!AC$1),0) -> 32245.732 | AY8: =AY59 -> 32289.52 | AZ8: =VLOOKUP($A8,平滑数据导入!$A$1:$AN$61,COLUMN(平滑数据导入!AE$1),0) -> 32247.076 | BA8: =VLOOKUP($A8,平滑数据导入!$A$1:$AN$61,COLUMN(平滑数据导入!AF$1),0) -> 32113.403 | BB8: =VLOOKUP($A8,平滑数据导入!$A$1:$AN$61,COLUMN(平滑数据导入!AG$1),0) -> 31884.337 | BC8: =VLOOKUP($A8,平滑数据导入!$A$1:$AN$61,COLUMN(平滑数据导入!AH$1),0) -> 31556.683 | BD8: =VLOOKUP($A8,平滑数据导入!$A$1:$AN$61,COLUMN(平滑数据导入!AI$1),0) -> 31128.345 | BE8: =VLOOKUP($A8,平滑数据导入!$A$1:$AN$61,COLUMN(平滑数据导入!AJ$1),0) -> 30598.441 | BF8: =VLOOKUP($A8,平滑数据导入!$A$1:$AN$61,COLUMN(平滑数据导入!AK$1),0) -> 29967.393 | BG8: =VLOOKUP($A8,平滑数据导入!$A$1:$AN$61,COLUMN(平滑数据导入!AL$1),0) -> 29237.003 | BH8: =VLOOKUP($A8,平滑数据导入!$A$1:$AN$61,COLUMN(平滑数据导入!AM$1),0) -> 28410.495 | BI8: =BI59 -> 27492.527
A9: 金融业 | B9: ='增加值 (2001-2022, 当年价) '!B9*B$77 -> 9784.4085 | C9: ='增加值 (2001-2022, 当年价) '!C9*C$77 -> 10382.529 | D9: ='增加值 (2001-2022, 当年价) '!D9*D$77 -> 11007.59 | E9: ='增加值 (2001-2022, 当年价) '!E9*E$77 -> 11234.659 | F9: ='增加值 (2001-2022, 当年价) '!F9*F$77 -> 12264.296 | G9: ='增加值 (2001-2022, 当年价) '!G9*G$77 -> 15717.405 | H9: ='增加值 (2001-2022, 当年价) '!H9*H$77 -> 22227.766 | I9: ='增加值 (2001-2022, 当年价) '!I9*I$77 -> 24898.857 | ... W9: ='增加值 (2001-2022, 当年价) '!W9*W$77 -> 90528.212 | X9: =VLOOKUP($A9,平滑数据导入!$A$1:$AN$61,COLUMN(平滑数据导入!C$1),0) -> 95168.114 | Y9: =VLOOKUP($A9,平滑数据导入!$A$1:$AN$61,COLUMN(平滑数据导入!D$1),0) -> 100177.18 | Z9: =Z60 -> 105499.82 | AA9: =VLOOKUP($A9,平滑数据导入!$A$1:$AN$61,COLUMN(平滑数据导入!F$1),0) -> 111064.69 | AB9: =VLOOKUP($A9,平滑数据导入!$A$1:$AN$61,COLUMN(平滑数据导入!G$1),0) -> 116782.43 | AC9: =VLOOKUP($A9,平滑数据导入!$A$1:$AN$61,COLUMN(平滑数据导入!H$1),0) -> 122543.97 | AD9: =VLOOKUP($A9,平滑数据导入!$A$1:$AN$61,COLUMN(平滑数据导入!I$1),0) -> 128219.81 | AE9: =AE60 -> 133660.44 | AF9: =VLOOKUP($A9,平滑数据导入!$A$1:$AN$61,COLUMN(平滑数据导入!K$1),0) -> 138731.73 | AG9: =VLOOKUP($A9,平滑数据导入!$A$1:$AN$61,COLUMN(平滑数据导入!L$1),0) -> 143427.91 | AH9: =VLOOKUP($A9,平滑数据导入!$A$1:$AN$61,COLUMN(平滑数据导入!M$1),0) -> 147788.68 | AI9: =VLOOKUP($A9,平滑数据导入!$A$1:$AN$61,COLUMN(平滑数据导入!N$1),0) -> 151866.82 | AJ9: =AJ60 -> 155726.85 | AK9: =VLOOKUP($A9,平滑数据导入!$A$1:$AN$61,COLUMN(平滑数据导入!P$1),0) -> 159426.34 | AL9: =VLOOKUP($A9,平滑数据导入!$A$1:$AN$61,COLUMN(平滑数据导入!Q$1),0) -> 162959.42 | AM9: =VLOOKUP($A9,平滑数据导入!$A$1:$AN$61,COLUMN(平滑数据导入!R$1),0) -> 166303.34 | AN9: =VLOOKUP($A9,平滑数据导入!$A$1:$AN$61,COLUMN(平滑数据导入!S$1),0) -> 169435.29 | AO9: =VLOOKUP($A9,平滑数据导入!$A$1:$AN$61,COLUMN(平滑数据导入!T$1),0) -> 172332.6 | AP9: =VLOOKUP($A9,平滑数据导入!$A$1:$AN$61,COLUMN(平滑数据导入!U$1),0) -> 174972.98 | AQ9: =VLOOKUP($A9,平滑数据导入!$A$1:$AN$61,COLUMN(平滑数据导入!V$1),0) -> 177334.74 | AR9: =VLOOKUP($A9,平滑数据导入!$A$1:$AN$61,COLUMN(平滑数据导入!W$1),0) -> 179397.02 | ... AX9: =VLOOKUP($A9,平滑数据导入!$A$1:$AN$61,COLUMN(平滑数据导入!AC$1),0) -> 184481.95 | AY9: =AY60 -> 183986.27 | AZ9: =VLOOKUP($A9,平滑数据导入!$A$1:$AN$61,COLUMN(平滑数据导入!AE$1),0) -> 183083.78 | BA9: =VLOOKUP($A9,平滑数据导入!$A$1:$AN$61,COLUMN(平滑数据导入!AF$1),0) -> 181771.8 | BB9: =VLOOKUP($A9,平滑数据导入!$A$1:$AN$61,COLUMN(平滑数据导入!AG$1),0) -> 180050.63 | BC9: =VLOOKUP($A9,平滑数据导入!$A$1:$AN$61,COLUMN(平滑数据导入!AH$1),0) -> 177923.61 | BD9: =VLOOKUP($A9,平滑数据导入!$A$1:$AN$61,COLUMN(平滑数据导入!AI$1),0) -> 175397.17 | BE9: =VLOOKUP($A9,平滑数据导入!$A$1:$AN$61,COLUMN(平滑数据导入!AJ$1),0) -> 172480.87 | BF9: =VLOOKUP($A9,平滑数据导入!$A$1:$AN$61,COLUMN(平滑数据导入!AK$1),0) -> 169187.38 | BG9: =VLOOKUP($A9,平滑数据导入!$A$1:$AN$61,COLUMN(平滑数据导入!AL$1),0) -> 165532.37 | BH9: =VLOOKUP($A9,平滑数据导入!$A$1:$AN$61,COLUMN(平滑数据导入!AM$1),0) -> 161534.45 | BI9: =BI60 -> 157214.98
A10: 房地产 | B10: ='增加值 (2001-2022, 当年价) '!B10*B$77 -> 8849.7481 | C10: ='增加值 (2001-2022, 当年价) '!C10*C$77 -> 9968.9695 | D10: ='增加值 (2001-2022, 当年价) '!D10*D$77 -> 11210.237 | E10: ='增加值 (2001-2022, 当年价) '!E10*E$77 -> 12174.087 | F10: ='增加值 (2001-2022, 当年价) '!F10*F$77 -> 13897.188 | G10: ='增加值 (2001-2022, 当年价) '!G10*G$77 -> 16266.835 | H10: ='增加值 (2001-2022, 当年价) '!H10*H$77 -> 20054.709 | I10: ='增加值 (2001-2022, 当年价) '!I10*I$77 -> 19815.693 | ... W10: ='增加值 (2001-2022, 当年价) '!W10*W$77 -> 69030.485 | X10: =VLOOKUP($A10,平滑数据导入!$A$1:$AN$61,COLUMN(平滑数据导入!C$1),0) -> 72919.08 | Y10: =VLOOKUP($A10,平滑数据导入!$A$1:$AN$61,COLUMN(平滑数据导入!D$1),0) -> 76843.649 | Z10: =Z61 -> 80767.16 | AA10: =VLOOKUP($A10,平滑数据导入!$A$1:$AN$61,COLUMN(平滑数据导入!F$1),0) -> 84647.702 | AB10: =VLOOKUP($A10,平滑数据导入!$A$1:$AN$61,COLUMN(平滑数据导入!G$1),0) -> 88438.741 | AC10: =VLOOKUP($A10,平滑数据导入!$A$1:$AN$61,COLUMN(平滑数据导入!H$1),0) -> 92089.571 | AD10: =VLOOKUP($A10,平滑数据导入!$A$1:$AN$61,COLUMN(平滑数据导入!I$1),0) -> 95545.966 | AE10: =AE61 -> 98751.059 | AF10: =VLOOKUP($A10,平滑数据导入!$A$1:$AN$61,COLUMN(平滑数据导入!K$1),0) -> 101667.15 | AG10: =VLOOKUP($A10,平滑数据导入!$A$1:$AN$61,COLUMN(平滑数据导入!L$1),0) -> 104343.37 | AH10: =VLOOKUP($A10,平滑数据导入!$A$1:$AN$61,COLUMN(平滑数据导入!M$1),0) -> 106860.88 | AI10: =VLOOKUP($A10,平滑数据导入!$A$1:$AN$61,COLUMN(平滑数据导入!N$1),0) -> 109311.69 | AJ10: =AJ61 -> 111797.7 | AK10: =VLOOKUP($A10,平滑数据导入!$A$1:$AN$61,COLUMN(平滑数据导入!P$1),0) -> 114407.66 | AL10: =VLOOKUP($A10,平滑数据导入!$A$1:$AN$61,COLUMN(平滑数据导入!Q$1),0) -> 117145.17 | AM10: =VLOOKUP($A10,平滑数据导入!$A$1:$AN$61,COLUMN(平滑数据导入!R$1),0) -> 119990 | AN10: =VLOOKUP($A10,平滑数据导入!$A$1:$AN$61,COLUMN(平滑数据导入!S$1),0) -> 122919.7 | AO10: =VLOOKUP($A10,平滑数据导入!$A$1:$AN$61,COLUMN(平滑数据导入!T$1),0) -> 125909.36 | AP10: =VLOOKUP($A10,平滑数据导入!$A$1:$AN$61,COLUMN(平滑数据导入!U$1),0) -> 128931.48 | AQ10: =VLOOKUP($A10,平滑数据导入!$A$1:$AN$61,COLUMN(平滑数据导入!V$1),0) -> 131955.89 | AR10: =VLOOKUP($A10,平滑数据导入!$A$1:$AN$61,COLUMN(平滑数据导入!W$1),0) -> 134949.64 | ... AX10: =VLOOKUP($A10,平滑数据导入!$A$1:$AN$61,COLUMN(平滑数据导入!AC$1),0) -> 150110.08 | AY10: =AY61 -> 151770.35 | AZ10: =VLOOKUP($A10,平滑数据导入!$A$1:$AN$61,COLUMN(平滑数据导入!AE$1),0) -> 153063.64 | BA10: =VLOOKUP($A10,平滑数据导入!$A$1:$AN$61,COLUMN(平滑数据导入!AF$1),0) -> 153946.38 | BB10: =VLOOKUP($A10,平滑数据导入!$A$1:$AN$61,COLUMN(平滑数据导入!AG$1),0) -> 154377.37 | BC10: =VLOOKUP($A10,平滑数据导入!$A$1:$AN$61,COLUMN(平滑数据导入!AH$1),0) -> 154318.82 | BD10: =VLOOKUP($A10,平滑数据导入!$A$1:$AN$61,COLUMN(平滑数据导入!AI$1),0) -> 153737.41 | BE10: =VLOOKUP($A10,平滑数据导入!$A$1:$AN$61,COLUMN(平滑数据导入!AJ$1),0) -> 152605.45 | BF10: =VLOOKUP($A10,平滑数据导入!$A$1:$AN$61,COLUMN(平滑数据导入!AK$1),0) -> 150901.88 | BG10: =VLOOKUP($A10,平滑数据导入!$A$1:$AN$61,COLUMN(平滑数据导入!AL$1),0) -> 148613.33 | BH10: =VLOOKUP($A10,平滑数据导入!$A$1:$AN$61,COLUMN(平滑数据导入!AM$1),0) -> 145734.95 | BI10: =BI61 -> 142271.16
A11: 其他三产 | B11: ='增加值 (2001-2022, 当年价) '!B11*B$77 -> 31937.552 | C11: ='增加值 (2001-2022, 当年价) '!C11*C$77 -> 37036.464 | D11: ='增加值 (2001-2022, 当年价) '!D11*D$77 -> 41428.534 | E11: ='增加值 (2001-2022, 当年价) '!E11*E$77 -> 45540.865 | F11: ='增加值 (2001-2022, 当年价) '!F11*F$77 -> 52003.008 | G11: ='增加值 (2001-2022, 当年价) '!G11*G$77 -> 58175.344 | H11: ='增加值 (2001-2022, 当年价) '!H11*H$77 -> 65164.644 | I11: ='增加值 (2001-2022, 当年价) '!I11*I$77 -> 72161.98 | ... W11: ='增加值 (2001-2022, 当年价) '!W11*W$77 -> 261752.41 | X11: =VLOOKUP($A11,平滑数据导入!$A$1:$AN$61,COLUMN(平滑数据导入!C$1),0) -> 285929.33 | Y11: =VLOOKUP($A11,平滑数据导入!$A$1:$AN$61,COLUMN(平滑数据导入!D$1),0) -> 312217.97 | Z11: =SUM(Z62:Z70) -> 340631.13 | AA11: =VLOOKUP($A11,平滑数据导入!$A$1:$AN$61,COLUMN(平滑数据导入!F$1),0) -> 371135.42 | AB11: =VLOOKUP($A11,平滑数据导入!$A$1:$AN$61,COLUMN(平滑数据导入!G$1),0) -> 403640.62 | AC11: =VLOOKUP($A11,平滑数据导入!$A$1:$AN$61,COLUMN(平滑数据导入!H$1),0) -> 437988.47 | AD11: =VLOOKUP($A11,平滑数据导入!$A$1:$AN$61,COLUMN(平滑数据导入!I$1),0) -> 473941.89 | AE11: =SUM(AE62:AE70) -> 511175.04 | AF11: =VLOOKUP($A11,平滑数据导入!$A$1:$AN$61,COLUMN(平滑数据导入!K$1),0) -> 549356.11 | AG11: =VLOOKUP($A11,平滑数据导入!$A$1:$AN$61,COLUMN(平滑数据导入!L$1),0) -> 588466.61 | AH11: =VLOOKUP($A11,平滑数据导入!$A$1:$AN$61,COLUMN(平滑数据导入!M$1),0) -> 628620.83 | AI11: =VLOOKUP($A11,平滑数据导入!$A$1:$AN$61,COLUMN(平滑数据导入!N$1),0) -> 669993.32 | AJ11: =SUM(AJ62:AJ70) -> 712824.8 | AK11: =VLOOKUP($A11,平滑数据导入!$A$1:$AN$61,COLUMN(平滑数据导入!P$1),0) -> 757357.89 | AL11: =VLOOKUP($A11,平滑数据导入!$A$1:$AN$61,COLUMN(平滑数据导入!Q$1),0) -> 803597.88 | AM11: =VLOOKUP($A11,平滑数据导入!$A$1:$AN$61,COLUMN(平滑数据导入!R$1),0) -> 851469.95 | AN11: =VLOOKUP($A11,平滑数据导入!$A$1:$AN$61,COLUMN(平滑数据导入!S$1),0) -> 900881.21 | AO11: =VLOOKUP($A11,平滑数据导入!$A$1:$AN$61,COLUMN(平滑数据导入!T$1),0) -> 951719.98 | AP11: =VLOOKUP($A11,平滑数据导入!$A$1:$AN$61,COLUMN(平滑数据导入!U$1),0) -> 1003855.3 | AQ11: =VLOOKUP($A11,平滑数据导入!$A$1:$AN$61,COLUMN(平滑数据导入!V$1),0) -> 1057136.7 | AR11: =VLOOKUP($A11,平滑数据导入!$A$1:$AN$61,COLUMN(平滑数据导入!W$1),0) -> 1111394 | ... AX11: =VLOOKUP($A11,平滑数据导入!$A$1:$AN$61,COLUMN(平滑数据导入!AC$1),0) -> 1445552.5 | AY11: =SUM(AY62:AY70) -> 1500351.1 | AZ11: =VLOOKUP($A11,平滑数据导入!$A$1:$AN$61,COLUMN(平滑数据导入!AE$1),0) -> 1554147.5 | BA11: =VLOOKUP($A11,平滑数据导入!$A$1:$AN$61,COLUMN(平滑数据导入!AF$1),0) -> 1606641 | BB11: =VLOOKUP($A11,平滑数据导入!$A$1:$AN$61,COLUMN(平滑数据导入!AG$1),0) -> 1657527.2 | BC11: =VLOOKUP($A11,平滑数据导入!$A$1:$AN$61,COLUMN(平滑数据导入!AH$1),0) -> 1706501.2 | BD11: =VLOOKUP($A11,平滑数据导入!$A$1:$AN$61,COLUMN(平滑数据导入!AI$1),0) -> 1753260.8 | BE11: =VLOOKUP($A11,平滑数据导入!$A$1:$AN$61,COLUMN(平滑数据导入!AJ$1),0) -> 1797510 | BF11: =VLOOKUP($A11,平滑数据导入!$A$1:$AN$61,COLUMN(平滑数据导入!AK$1),0) -> 1838962.7 | BG11: =VLOOKUP($A11,平滑数据导入!$A$1:$AN$61,COLUMN(平滑数据导入!AL$1),0) -> 1877346.3 | BH11: =VLOOKUP($A11,平滑数据导入!$A$1:$AN$61,COLUMN(平滑数据导入!AM$1),0) -> 1912404.8 | BI11: =SUM(BI62:BI70) -> 1943903
A13: 工业 | B13: =B4 -> 82472.589 | C13: =C4 -> 89280.442 | D13: =D4 -> 100799.64 | E13: =E4 -> 111960.03 | F13: =F4 -> 127718.9 | G13: =G4 -> 145373.42 | H13: =H4 -> 163331.38 | I13: =I4 -> 178777.31 | ... W13: =W4 -> 375578.61 | X13: =VLOOKUP($A13,平滑数据导入!$A$1:$AN$61,COLUMN(平滑数据导入!C$1),0) -> 388611.81 | Y13: =VLOOKUP($A13,平滑数据导入!$A$1:$AN$61,COLUMN(平滑数据导入!D$1),0) -> 402616.52 | Z13: =Z4 -> 417398.95 | AA13: =VLOOKUP($A13,平滑数据导入!$A$1:$AN$61,COLUMN(平滑数据导入!F$1),0) -> 432743.74 | AB13: =VLOOKUP($A13,平滑数据导入!$A$1:$AN$61,COLUMN(平滑数据导入!G$1),0) -> 448409.44 | AC13: =VLOOKUP($A13,平滑数据导入!$A$1:$AN$61,COLUMN(平滑数据导入!H$1),0) -> 464125.57 | AD13: =VLOOKUP($A13,平滑数据导入!$A$1:$AN$61,COLUMN(平滑数据导入!I$1),0) -> 479591.6 | AE13: =AE4 -> 494478.45 | AF13: =VLOOKUP($A13,平滑数据导入!$A$1:$AN$61,COLUMN(平滑数据导入!K$1),0) -> 508505.38 | AG13: =VLOOKUP($A13,平滑数据导入!$A$1:$AN$61,COLUMN(平滑数据导入!L$1),0) -> 521674.06 | AH13: =VLOOKUP($A13,平滑数据导入!$A$1:$AN$61,COLUMN(平滑数据导入!M$1),0) -> 534070.3 | AI13: =VLOOKUP($A13,平滑数据导入!$A$1:$AN$61,COLUMN(平滑数据导入!N$1),0) -> 545791.14 | AJ13: =AJ4 -> 556942.11 | AK13: =VLOOKUP($A13,平滑数据导入!$A$1:$AN$61,COLUMN(平滑数据导入!P$1),0) -> 567610.38 | AL13: =VLOOKUP($A13,平滑数据导入!$A$1:$AN$61,COLUMN(平滑数据导入!Q$1),0) -> 577789.79 | AM13: =VLOOKUP($A13,平滑数据导入!$A$1:$AN$61,COLUMN(平滑数据导入!R$1),0) -> 587454.19 | AN13: =VLOOKUP($A13,平滑数据导入!$A$1:$AN$61,COLUMN(平滑数据导入!S$1),0) -> 596582.23 | AO13: =VLOOKUP($A13,平滑数据导入!$A$1:$AN$61,COLUMN(平滑数据导入!T$1),0) -> 605157.37 | AP13: =VLOOKUP($A13,平滑数据导入!$A$1:$AN$61,COLUMN(平滑数据导入!U$1),0) -> 613167.94 | AQ13: =VLOOKUP($A13,平滑数据导入!$A$1:$AN$61,COLUMN(平滑数据导入!V$1),0) -> 620607.1 | AR13: =VLOOKUP($A13,平滑数据导入!$A$1:$AN$61,COLUMN(平滑数据导入!W$1),0) -> 627472.76 | ... AX13: =VLOOKUP($A13,平滑数据导入!$A$1:$AN$61,COLUMN(平滑数据导入!AC$1),0) -> 657065.9 | AY13: =AY4 -> 660223.63 | AZ13: =VLOOKUP($A13,平滑数据导入!$A$1:$AN$61,COLUMN(平滑数据导入!AE$1),0) -> 662941.57 | BA13: =VLOOKUP($A13,平滑数据导入!$A$1:$AN$61,COLUMN(平滑数据导入!AF$1),0) -> 665252.11 | BB13: =VLOOKUP($A13,平滑数据导入!$A$1:$AN$61,COLUMN(平滑数据导入!AG$1),0) -> 667190.43 | BC13: =VLOOKUP($A13,平滑数据导入!$A$1:$AN$61,COLUMN(平滑数据导入!AH$1),0) -> 668794.37 | BD13: =VLOOKUP($A13,平滑数据导入!$A$1:$AN$61,COLUMN(平滑数据导入!AI$1),0) -> 670104.31 | BE13: =VLOOKUP($A13,平滑数据导入!$A$1:$AN$61,COLUMN(平滑数据导入!AJ$1),0) -> 671163.02 | BF13: =VLOOKUP($A13,平滑数据导入!$A$1:$AN$61,COLUMN(平滑数据导入!AK$1),0) -> 672015.66 | BG13: =VLOOKUP($A13,平滑数据导入!$A$1:$AN$61,COLUMN(平滑数据导入!AL$1),0) -> 672709.76 | BH13: =VLOOKUP($A13,平滑数据导入!$A$1:$AN$61,COLUMN(平滑数据导入!AM$1),0) -> 673295.28 | BI13: =BI4 -> 673824.68
A14: 煤炭开采和洗选业 | I14: ='增加值 (2001-2022, 当年价) '!I14*I$77 -> 11675.691 | J14: ='增加值 (2001-2022, 当年价) '!J14*J$77 -> 11986.509 | K14: ='增加值 (2001-2022, 当年价) '!K14*K$77 -> 13642.403 | L14: ='增加值 (2001-2022, 当年价) '!L14*L$77 -> 15284.767 | M14: ='增加值 (2001-2022, 当年价) '!M14*M$77 -> 15977.001 | N14: ='增加值 (2001-2022, 当年价) '!N14*N$77 -> 16042.647 | O14: ='增加值 (2001-2022, 当年价) '!O14*O$77 -> 15765.053 | P14: ='增加值 (2001-2022, 当年价) '!P14*P$77 -> 15240.596 | ... W14: ='增加值 (2001-2022, 当年价) '!W14*W$77 -> 18002.061 | X14: =VLOOKUP($A14,平滑数据导入!$A$1:$AN$61,COLUMN(平滑数据导入!C$1),0) -> 18184.611 | Y14: =VLOOKUP($A14,平滑数据导入!$A$1:$AN$61,COLUMN(平滑数据导入!D$1),0) -> 18449.3 | Z14: =VLOOKUP(A14,情景假设!$B$48:$S$88,14,0)/情景假设!O$47*Z$13 -> 18773.814 | AA14: =VLOOKUP($A14,平滑数据导入!$A$1:$AN$61,COLUMN(平滑数据导入!F$1),0) -> 19134.821 | AB14: =VLOOKUP($A14,平滑数据导入!$A$1:$AN$61,COLUMN(平滑数据导入!G$1),0) -> 19507.346 | AC14: =VLOOKUP($A14,平滑数据导入!$A$1:$AN$61,COLUMN(平滑数据导入!H$1),0) -> 19864.444 | AD14: =VLOOKUP($A14,平滑数据导入!$A$1:$AN$61,COLUMN(平滑数据导入!I$1),0) -> 20177.235 | AE14: =VLOOKUP(A14,情景假设!$B$48:$S$88,15,0)/情景假设!P$47*AE$13 -> 20415.335 | AF14: =VLOOKUP($A14,平滑数据导入!$A$1:$AN$61,COLUMN(平滑数据导入!K$1),0) -> 20555.494 | AG14: =VLOOKUP($A14,平滑数据导入!$A$1:$AN$61,COLUMN(平滑数据导入!L$1),0) -> 20606.307 | AH14: =VLOOKUP($A14,平滑数据导入!$A$1:$AN$61,COLUMN(平滑数据导入!M$1),0) -> 20585.523 | AI14: =VLOOKUP($A14,平滑数据导入!$A$1:$AN$61,COLUMN(平滑数据导入!N$1),0) -> 20511.709 | AJ14: =VLOOKUP(A14,情景假设!$B$48:$S$88,16,0)/情景假设!Q$47*AJ$13 -> 20403.684 | AK14: =VLOOKUP($A14,平滑数据导入!$A$1:$AN$61,COLUMN(平滑数据导入!P$1),0) -> 20277.112 | AL14: =VLOOKUP($A14,平滑数据导入!$A$1:$AN$61,COLUMN(平滑数据导入!Q$1),0) -> 20135.358 | AM14: =VLOOKUP($A14,平滑数据导入!$A$1:$AN$61,COLUMN(平滑数据导入!R$1),0) -> 19978.766 | AN14: =VLOOKUP($A14,平滑数据导入!$A$1:$AN$61,COLUMN(平滑数据导入!S$1),0) -> 19807.71 | AO14: =VLOOKUP($A14,平滑数据导入!$A$1:$AN$61,COLUMN(平滑数据导入!T$1),0) -> 19622.596 | AP14: =VLOOKUP($A14,平滑数据导入!$A$1:$AN$61,COLUMN(平滑数据导入!U$1),0) -> 19423.858 | AQ14: =VLOOKUP($A14,平滑数据导入!$A$1:$AN$61,COLUMN(平滑数据导入!V$1),0) -> 19211.959 | AR14: =VLOOKUP($A14,平滑数据导入!$A$1:$AN$61,COLUMN(平滑数据导入!W$1),0) -> 18987.387 | ... AX14: =VLOOKUP($A14,平滑数据导入!$A$1:$AN$61,COLUMN(平滑数据导入!AC$1),0) -> 17403.924 | AY14: =VLOOKUP(A14,情景假设!$B$48:$S$88,17,0)/情景假设!R$47*AY$13 -> 17106.066 | AZ14: =VLOOKUP($A14,平滑数据导入!$A$1:$AN$61,COLUMN(平滑数据导入!AE$1),0) -> 16800.133 | BA14: =VLOOKUP($A14,平滑数据导入!$A$1:$AN$61,COLUMN(平滑数据导入!AF$1),0) -> 16486.753 | BB14: =VLOOKUP($A14,平滑数据导入!$A$1:$AN$61,COLUMN(平滑数据导入!AG$1),0) -> 16166.562 | BC14: =VLOOKUP($A14,平滑数据导入!$A$1:$AN$61,COLUMN(平滑数据导入!AH$1),0) -> 15840.198 | BD14: =VLOOKUP($A14,平滑数据导入!$A$1:$AN$61,COLUMN(平滑数据导入!AI$1),0) -> 15508.3 | BE14: =VLOOKUP($A14,平滑数据导入!$A$1:$AN$61,COLUMN(平滑数据导入!AJ$1),0) -> 15171.508 | BF14: =VLOOKUP($A14,平滑数据导入!$A$1:$AN$61,COLUMN(平滑数据导入!AK$1),0) -> 14830.457 | BG14: =VLOOKUP($A14,平滑数据导入!$A$1:$AN$61,COLUMN(平滑数据导入!AL$1),0) -> 14485.777 | BH14: =VLOOKUP($A14,平滑数据导入!$A$1:$AN$61,COLUMN(平滑数据导入!AM$1),0) -> 14138.092 | BI14: =VLOOKUP(A14,情景假设!$B$48:$S$88,18,0)/情景假设!S$47*BI$13 -> 13788.019
A15: 石油和天然气开采业 | I15: ='增加值 (2001-2022, 当年价) '!I15*I$77 -> 12283.18 | J15: ='增加值 (2001-2022, 当年价) '!J15*J$77 -> 12202.638 | K15: ='增加值 (2001-2022, 当年价) '!K15*K$77 -> 11826.461 | L15: ='增加值 (2001-2022, 当年价) '!L15*L$77 -> 11943.372 | M15: ='增加值 (2001-2022, 当年价) '!M15*M$77 -> 11733.855 | N15: ='增加值 (2001-2022, 当年价) '!N15*N$77 -> 11403.08 | O15: ='增加值 (2001-2022, 当年价) '!O15*O$77 -> 11315.091 | P15: ='增加值 (2001-2022, 当年价) '!P15*P$77 -> 11185.569 | ... W15: ='增加值 (2001-2022, 当年价) '!W15*W$77 -> 12304.163 | X15: =VLOOKUP($A15,平滑数据导入!$A$1:$AN$61,COLUMN(平滑数据导入!C$1),0) -> 12293.53 | Y15: =VLOOKUP($A15,平滑数据导入!$A$1:$AN$61,COLUMN(平滑数据导入!D$1),0) -> 12328.258 | Z15: =VLOOKUP(A15,情景假设!$B$48:$S$88,14,0)/情景假设!O$47*Z$13 -> 12394.815 | AA15: =VLOOKUP($A15,平滑数据导入!$A$1:$AN$61,COLUMN(平滑数据导入!F$1),0) -> 12479.705 | AB15: =VLOOKUP($A15,平滑数据导入!$A$1:$AN$61,COLUMN(平滑数据导入!G$1),0) -> 12569.185 | AC15: =VLOOKUP($A15,平滑数据导入!$A$1:$AN$61,COLUMN(平滑数据导入!H$1),0) -> 12649.145 | AD15: =VLOOKUP($A15,平滑数据导入!$A$1:$AN$61,COLUMN(平滑数据导入!I$1),0) -> 12705.129 | AE15: =VLOOKUP(A15,情景假设!$B$48:$S$88,15,0)/情景假设!P$47*AE$13 -> 12722.533 | AF15: =VLOOKUP($A15,平滑数据导入!$A$1:$AN$61,COLUMN(平滑数据导入!K$1),0) -> 12691.135 | AG15: =VLOOKUP($A15,平滑数据导入!$A$1:$AN$61,COLUMN(平滑数据导入!L$1),0) -> 12617.924 | AH15: =VLOOKUP($A15,平滑数据导入!$A$1:$AN$61,COLUMN(平滑数据导入!M$1),0) -> 12514.321 | AI15: =VLOOKUP($A15,平滑数据导入!$A$1:$AN$61,COLUMN(平滑数据导入!N$1),0) -> 12391.674 | AJ15: =VLOOKUP(A15,情景假设!$B$48:$S$88,16,0)/情景假设!Q$47*AJ$13 -> 12261.041 | AK15: =VLOOKUP($A15,平滑数据导入!$A$1:$AN$61,COLUMN(平滑数据导入!P$1),0) -> 12131.225 | AL15: =VLOOKUP($A15,平滑数据导入!$A$1:$AN$61,COLUMN(平滑数据导入!Q$1),0) -> 12003.359 | AM15: =VLOOKUP($A15,平滑数据导入!$A$1:$AN$61,COLUMN(平滑数据导入!R$1),0) -> 11876.721 | AN15: =VLOOKUP($A15,平滑数据导入!$A$1:$AN$61,COLUMN(平滑数据导入!S$1),0) -> 11750.618 | AO15: =VLOOKUP($A15,平滑数据导入!$A$1:$AN$61,COLUMN(平滑数据导入!T$1),0) -> 11624.388 | AP15: =VLOOKUP($A15,平滑数据导入!$A$1:$AN$61,COLUMN(平滑数据导入!U$1),0) -> 11497.396 | AQ15: =VLOOKUP($A15,平滑数据导入!$A$1:$AN$61,COLUMN(平滑数据导入!V$1),0) -> 11369.037 | AR15: =VLOOKUP($A15,平滑数据导入!$A$1:$AN$61,COLUMN(平滑数据导入!W$1),0) -> 11238.736 | ... AX15: =VLOOKUP($A15,平滑数据导入!$A$1:$AN$61,COLUMN(平滑数据导入!AC$1),0) -> 10387.959 | AY15: =VLOOKUP(A15,情景假设!$B$48:$S$88,17,0)/情景假设!R$47*AY$13 -> 10230.702 | AZ15: =VLOOKUP($A15,平滑数据导入!$A$1:$AN$61,COLUMN(平滑数据导入!AE$1),0) -> 10068.126 | BA15: =VLOOKUP($A15,平滑数据导入!$A$1:$AN$61,COLUMN(平滑数据导入!AF$1),0) -> 9899.9856 | BB15: =VLOOKUP($A15,平滑数据导入!$A$1:$AN$61,COLUMN(平滑数据导入!AG$1),0) -> 9726.0847 | BC15: =VLOOKUP($A15,平滑数据导入!$A$1:$AN$61,COLUMN(平滑数据导入!AH$1),0) -> 9546.2736 | BD15: =VLOOKUP($A15,平滑数据导入!$A$1:$AN$61,COLUMN(平滑数据导入!AI$1),0) -> 9360.4526 | BE15: =VLOOKUP($A15,平滑数据导入!$A$1:$AN$61,COLUMN(平滑数据导入!AJ$1),0) -> 9168.5731 | BF15: =VLOOKUP($A15,平滑数据导入!$A$1:$AN$61,COLUMN(平滑数据导入!AK$1),0) -> 8970.6391 | BG15: =VLOOKUP($A15,平滑数据导入!$A$1:$AN$61,COLUMN(平滑数据导入!AL$1),0) -> 8766.708 | BH15: =VLOOKUP($A15,平滑数据导入!$A$1:$AN$61,COLUMN(平滑数据导入!AM$1),0) -> 8556.8914 | BI15: =VLOOKUP(A15,情景假设!$B$48:$S$88,18,0)/情景假设!S$47*BI$13 -> 8341.3552
