Workbook

Sheet Vehicle Sales Database
A1: Index | B1: Year | C1: FuelType | D1: Fuel Type Adjusted | E1: Class | F1: UseType | G1: Class2 | H1: Database Class | I1: EPS Class | J1: Sales | M1: Fuel Adjustment | P1: Class Adjustment
A2: 1 | B2: 2015 | C2: 插电式混合动力 | D2: =VLOOKUP(C2,M$3:N$16,2,FALSE) -> plugin hybrid vehicle | E2: 大型客车 | F2: 城市公交 | G2: 商用车 | H2: =VLOOKUP(E2&F2&G2,$S$3:$U$68,2,FALSE) -> 公交车 | I2: =VLOOKUP(E2&F2&G2,$S$3:$U$68,3,FALSE) -> Passenger HDV | J2: 16295 | M2: FuelType | N2: Fuel Type Adjusted | P2: Class | Q2: UseType | R2: Class2 | S2: Key | T2: Database | U2: EPS | V2: 数量
A3: 2 | B3: 2016 | C3: 插电式混合动力 | D3: =VLOOKUP(C3,M$3:N$16,2,FALSE) -> plugin hybrid vehicle | E3: 大型客车 | F3: 城市公交 | G3: 商用车 | H3: =VLOOKUP(E3&F3&G3,$S$3:$U$68,2,FALSE) -> 公交车 | I3: =VLOOKUP(E3&F3&G3,$S$3:$U$68,3,FALSE) -> Passenger HDV | J3: 4474 | M3: 插电式混合动力 | N3: plugin hybrid vehicle | P3: 小型客车 | Q3: 非营运 | R3: 乘用车 | S3: =P3&Q3&R3 -> 小型客车非营运乘用车 | T3: 乘用车 | U3: Passenger LDV | V3: =SUMIFS(J:J,E:E,P3,F:F,Q3,G:G,R3) -> 150944896
A4: 3 | B4: 2017 | C4: 插电式混合动力 | D4: =VLOOKUP(C4,M$3:N$16,2,FALSE) -> plugin hybrid vehicle | E4: 大型客车 | F4: 城市公交 | G4: 商用车 | H4: =VLOOKUP(E4&F4&G4,$S$3:$U$68,2,FALSE) -> 公交车 | I4: =VLOOKUP(E4&F4&G4,$S$3:$U$68,3,FALSE) -> Passenger HDV | J4: 12043 | M4: 柴油 | N4: diesel vehicle | P4: 轻型货车 | Q4: 非营运 | R4: 商用车 | S4: =P4&Q4&R4 -> 轻型货车非营运商用车 | T4: 轻型货车 | U4: Freight LDV | V4: =SUMIFS(J:J,E:E,P4,F:F,Q4,G:G,R4) -> 10907801
A5: 4 | B5: 2018 | C5: 插电式混合动力 | D5: =VLOOKUP(C5,M$3:N$16,2,FALSE) -> plugin hybrid vehicle | E5: 大型客车 | F5: 城市公交 | G5: 商用车 | H5: =VLOOKUP(E5&F5&G5,$S$3:$U$68,2,FALSE) -> 公交车 | I5: =VLOOKUP(E5&F5&G5,$S$3:$U$68,3,FALSE) -> Passenger HDV | J5: 5764 | M5: 纯电动 | N5: battery electric vehicle | P5: 重型货车 | Q5: 营运 | R5: 商用车 | S5: =P5&Q5&R5 -> 重型货车营运商用车 | T5: 中重型货车 | U5: Freight HDV | V5: =SUMIFS(J:J,E:E,P5,F:F,Q5,G:G,R5) -> 6273983
A6: 5 | B6: 2019 | C6: 插电式混合动力 | D6: =VLOOKUP(C6,M$3:N$16,2,FALSE) -> plugin hybrid vehicle | E6: 大型客车 | F6: 城市公交 | G6: 商用车 | H6: =VLOOKUP(E6&F6&G6,$S$3:$U$68,2,FALSE) -> 公交车 | I6: =VLOOKUP(E6&F6&G6,$S$3:$U$68,3,FALSE) -> Passenger HDV | J6: 4294 | M6: 混合动力 | N6: hybrid fuel vehicle | P6: 轻型货车 | Q6: 营运 | R6: 商用车 | S6: =P6&Q6&R6 -> 轻型货车营运商用车 | T6: 轻型货车 | U6: Freight LDV | V6: =SUMIFS(J:J,E:E,P6,F:F,Q6,G:G,R6) -> 3069497
A7: 6 | B7: 2020 | C7: 插电式混合动力 | D7: =VLOOKUP(C7,M$3:N$16,2,FALSE) -> plugin hybrid vehicle | E7: 大型客车 | F7: 城市公交 | G7: 商用车 | H7: =VLOOKUP(E7&F7&G7,$S$3:$U$68,2,FALSE) -> 公交车 | I7: =VLOOKUP(E7&F7&G7,$S$3:$U$68,3,FALSE) -> Passenger HDV | J7: 5040 | M7: 汽油 | N7: gasoline vehicle | P7: 小型客车 | Q7: 出租租赁 | R7: 乘用车 | S7: =P7&Q7&R7 -> 小型客车出租租赁乘用车 | T7: 出租车 | U7: Passenger LDV | V7: =SUMIFS(J:J,E:E,P7,F:F,Q7,G:G,R7) -> 2976234
A8: 7 | B8: 2021 | C8: 插电式混合动力 | D8: =VLOOKUP(C8,M$3:N$16,2,FALSE) -> plugin hybrid vehicle | E8: 大型客车 | F8: 城市公交 | G8: 商用车 | H8: =VLOOKUP(E8&F8&G8,$S$3:$U$68,2,FALSE) -> 公交车 | I8: =VLOOKUP(E8&F8&G8,$S$3:$U$68,3,FALSE) -> Passenger HDV | J8: 1224 | M8: 汽油-天然气 | N8: natural gas vehicle | P8: 未知 | Q8: 非营运 | R8: 商用车 | S8: =P8&Q8&R8 -> 未知非营运商用车 | T8: Unknown | U8: Unknown | V8: =SUMIFS(J:J,E:E,P8,F:F,Q8,G:G,R8) -> 2193211
A9: 8 | B9: 2015 | C9: 柴油 | D9: =VLOOKUP(C9,M$3:N$16,2,FALSE) -> diesel vehicle | E9: 大型客车 | F9: 城市公交 | G9: 商用车 | H9: =VLOOKUP(E9&F9&G9,$S$3:$U$68,2,FALSE) -> 公交车 | I9: =VLOOKUP(E9&F9&G9,$S$3:$U$68,3,FALSE) -> Passenger HDV | J9: 21733 | M9: 燃料电池 | N9: hydrogen vehicle | P9: 微型客车 | Q9: 非营运 | R9: 乘用车 | S9: =P9&Q9&R9 -> 微型客车非营运乘用车 | T9: 乘用车 | U9: Passenger LDV | V9: =SUMIFS(J:J,E:E,P9,F:F,Q9,G:G,R9) -> 1396360
A10: 9 | B10: 2016 | C10: 柴油 | D10: =VLOOKUP(C10,M$3:N$16,2,FALSE) -> diesel vehicle | E10: 大型客车 | F10: 城市公交 | G10: 商用车 | H10: =VLOOKUP(E10&F10&G10,$S$3:$U$68,2,FALSE) -> 公交车 | I10: =VLOOKUP(E10&F10&G10,$S$3:$U$68,3,FALSE) -> Passenger HDV | J10: 7308 | M10: 天然气 | N10: natural gas vehicle | P10: 小型客车 | Q10: 非营运 | R10: 商用车 | S10: =P10&Q10&R10 -> 小型客车非营运商用车 | T10: 乘用车 | U10: Passenger LDV | V10: =SUMIFS(J:J,E:E,P10,F:F,Q10,G:G,R10) -> 1152779
A11: 10 | B11: 2017 | C11: 柴油 | D11: =VLOOKUP(C11,M$3:N$16,2,FALSE) -> diesel vehicle | E11: 大型客车 | F11: 城市公交 | G11: 商用车 | H11: =VLOOKUP(E11&F11&G11,$S$3:$U$68,2,FALSE) -> 公交车 | I11: =VLOOKUP(E11&F11&G11,$S$3:$U$68,3,FALSE) -> Passenger HDV | J11: 4681 | M11: 无 | N11: unknown | P11: 重型货车 | Q11: 未知 | R11: 商用车 | S11: =P11&Q11&R11 -> 重型货车未知商用车 | T11: 中重型货车 | U11: Freight HDV | V11: =SUMIFS(J:J,E:E,P11,F:F,Q11,G:G,R11) -> 683717
A12: 11 | B12: 2018 | C12: 柴油 | D12: =VLOOKUP(C12,M$3:N$16,2,FALSE) -> diesel vehicle | E12: 大型客车 | F12: 城市公交 | G12: 商用车 | H12: =VLOOKUP(E12&F12&G12,$S$3:$U$68,2,FALSE) -> 公交车 | I12: =VLOOKUP(E12&F12&G12,$S$3:$U$68,3,FALSE) -> Passenger HDV | J12: 2329 | M12: 甲醇 | N12: other fuel vehicle | P12: 大型客车 | Q12: 城市公交 | R12: 商用车 | S12: =P12&Q12&R12 -> 大型客车城市公交商用车 | T12: 公交车 | U12: Passenger HDV | V12: =SUMIFS(J:J,E:E,P12,F:F,Q12,G:G,R12) -> 551293
A13: 12 | B13: 2019 | C13: 柴油 | D13: =VLOOKUP(C13,M$3:N$16,2,FALSE) -> diesel vehicle | E13: 大型客车 | F13: 城市公交 | G13: 商用车 | H13: =VLOOKUP(E13&F13&G13,$S$3:$U$68,2,FALSE) -> 公交车 | I13: =VLOOKUP(E13&F13&G13,$S$3:$U$68,3,FALSE) -> Passenger HDV | J13: 1012 | M13: 柴油-天然气 | N13: natural gas vehicle | P13: 重型货车 | Q13: 非营运 | R13: 商用车 | S13: =P13&Q13&R13 -> 重型货车非营运商用车 | T13: 中重型货车 | U13: Freight HDV | V13: =SUMIFS(J:J,E:E,P13,F:F,Q13,G:G,R13) -> 500202
A14: 13 | B14: 2020 | C14: 柴油 | D14: =VLOOKUP(C14,M$3:N$16,2,FALSE) -> diesel vehicle | E14: 大型客车 | F14: 城市公交 | G14: 商用车 | H14: =VLOOKUP(E14&F14&G14,$S$3:$U$68,2,FALSE) -> 公交车 | I14: =VLOOKUP(E14&F14&G14,$S$3:$U$68,3,FALSE) -> Passenger HDV | J14: 662 | M14: 柴油-甲醇 | N14: hybrid fuel vehicle | P14: 中型货车 | Q14: 营运 | R14: 商用车 | S14: =P14&Q14&R14 -> 中型货车营运商用车 | T14: 中重型货车 | U14: Freight HDV | V14: =SUMIFS(J:J,E:E,P14,F:F,Q14,G:G,R14) -> 285237
... A16: 15 | B16: 2015 | C16: 纯电动 | D16: =VLOOKUP(C16,M$3:N$16,2,FALSE) -> battery electric vehicle | E16: 大型客车 | F16: 城市公交 | G16: 商用车 | H16: =VLOOKUP(E16&F16&G16,$S$3:$U$68,2,FALSE) -> 公交车 | I16: =VLOOKUP(E16&F16&G16,$S$3:$U$68,3,FALSE) -> Passenger HDV | J16: 44539 | M16: 增程式混合动力 | N16: hybrid fuel vehicle | P16: 大型客车 | Q16: 非营运 | R16: 商用车 | S16: =P16&Q16&R16 -> 大型客车非营运商用车 | T16: 道路客车 | U16: Passenger HDV | V16: =SUMIFS(J:J,E:E,P16,F:F,Q16,G:G,R16) -> 232628
A17: 16 | B17: 2016 | C17: 纯电动 | D17: =VLOOKUP(C17,M$3:N$16,2,FALSE) -> battery electric vehicle | E17: 大型客车 | F17: 城市公交 | G17: 商用车 | H17: =VLOOKUP(E17&F17&G17,$S$3:$U$68,2,FALSE) -> 公交车 | I17: =VLOOKUP(E17&F17&G17,$S$3:$U$68,3,FALSE) -> Passenger HDV | J17: 60979 | P17: 大型客车 | Q17: 公路客运 | R17: 商用车 | S17: =P17&Q17&R17 -> 大型客车公路客运商用车 | T17: 道路客车 | U17: Passenger HDV | V17: =SUMIFS(J:J,E:E,P17,F:F,Q17,G:G,R17) -> 201564
A18: 17 | B18: 2017 | C18: 纯电动 | D18: =VLOOKUP(C18,M$3:N$16,2,FALSE) -> battery electric vehicle | E18: 大型客车 | F18: 城市公交 | G18: 商用车 | H18: =VLOOKUP(E18&F18&G18,$S$3:$U$68,2,FALSE) -> 公交车 | I18: =VLOOKUP(E18&F18&G18,$S$3:$U$68,3,FALSE) -> Passenger HDV | J18: 56938 | P18: NULL | Q18: 非营运 | R18: 乘用车 | S18: =P18&Q18&R18 -> NULL非营运乘用车 | T18: 乘用车 | U18: Unknown | V18: =SUMIFS(J:J,E:E,P18,F:F,Q18,G:G,R18) -> 198660
A19: 18 | B19: 2018 | C19: 纯电动 | D19: =VLOOKUP(C19,M$3:N$16,2,FALSE) -> battery electric vehicle | E19: 大型客车 | F19: 城市公交 | G19: 商用车 | H19: =VLOOKUP(E19&F19&G19,$S$3:$U$68,2,FALSE) -> 公交车 | I19: =VLOOKUP(E19&F19&G19,$S$3:$U$68,3,FALSE) -> Passenger HDV | J19: 79727 | P19: 中型货车 | Q19: 非营运 | R19: 商用车 | S19: =P19&Q19&R19 -> 中型货车非营运商用车 | T19: 中重型货车 | U19: Freight HDV | V19: =SUMIFS(J:J,E:E,P19,F:F,Q19,G:G,R19) -> 193197
A20: 19 | B20: 2019 | C20: 纯电动 | D20: =VLOOKUP(C20,M$3:N$16,2,FALSE) -> battery electric vehicle | E20: 大型客车 | F20: 城市公交 | G20: 商用车 | H20: =VLOOKUP(E20&F20&G20,$S$3:$U$68,2,FALSE) -> 公交车 | I20: =VLOOKUP(E20&F20&G20,$S$3:$U$68,3,FALSE) -> Passenger HDV | J20: 67030 | P20: 未知 | Q20: 营运 | R20: 商用车 | S20: =P20&Q20&R20 -> 未知营运商用车 | T20: Unknown | U20: Unknown | V20: =SUMIFS(J:J,E:E,P20,F:F,Q20,G:G,R20) -> 191372
A21: 20 | B21: 2020 | C21: 纯电动 | D21: =VLOOKUP(C21,M$3:N$16,2,FALSE) -> battery electric vehicle | E21: 大型客车 | F21: 城市公交 | G21: 商用车 | H21: =VLOOKUP(E21&F21&G21,$S$3:$U$68,2,FALSE) -> 公交车 | I21: =VLOOKUP(E21&F21&G21,$S$3:$U$68,3,FALSE) -> Passenger HDV | J21: 51600 | P21: 中型客车 | Q21: 非营运 | R21: 商用车 | S21: =P21&Q21&R21 -> 中型客车非营运商用车 | T21: 道路客车 | U21: Passenger HDV | V21: =SUMIFS(J:J,E:E,P21,F:F,Q21,G:G,R21) -> 161822
A22: 21 | B22: 2021 | C22: 纯电动 | D22: =VLOOKUP(C22,M$3:N$16,2,FALSE) -> battery electric vehicle | E22: 大型客车 | F22: 城市公交 | G22: 商用车 | H22: =VLOOKUP(E22&F22&G22,$S$3:$U$68,2,FALSE) -> 公交车 | I22: =VLOOKUP(E22&F22&G22,$S$3:$U$68,3,FALSE) -> Passenger HDV | J22: 39634 | P22: 中型货车 | Q22: 未知 | R22: 商用车 | S22: =P22&Q22&R22 -> 中型货车未知商用车 | T22: 中重型货车 | U22: Freight HDV | V22: =SUMIFS(J:J,E:E,P22,F:F,Q22,G:G,R22) -> 159848
A23: 22 | B23: 2015 | C23: 混合动力 | D23: =VLOOKUP(C23,M$3:N$16,2,FALSE) -> hybrid fuel vehicle | E23: 大型客车 | F23: 城市公交 | G23: 商用车 | H23: =VLOOKUP(E23&F23&G23,$S$3:$U$68,2,FALSE) -> 公交车 | I23: =VLOOKUP(E23&F23&G23,$S$3:$U$68,3,FALSE) -> Passenger HDV | J23: 7940 | P23: 小型客车 | Q23: 营运 | R23: 商用车 | S23: =P23&Q23&R23 -> 小型客车营运商用车 | T23: 出租车 | U23: Passenger LDV | V23: =SUMIFS(J:J,E:E,P23,F:F,Q23,G:G,R23) -> 144693
A24: 23 | B24: 2016 | C24: 混合动力 | D24: =VLOOKUP(C24,M$3:N$16,2,FALSE) -> hybrid fuel vehicle | E24: 大型客车 | F24: 城市公交 | G24: 商用车 | H24: =VLOOKUP(E24&F24&G24,$S$3:$U$68,2,FALSE) -> 公交车 | I24: =VLOOKUP(E24&F24&G24,$S$3:$U$68,3,FALSE) -> Passenger HDV | J24: 12742 | P24: 小型客车 | Q24: 营运 | R24: 乘用车 | S24: =P24&Q24&R24 -> 小型客车营运乘用车 | T24: 出租车 | U24: Passenger LDV | V24: =SUMIFS(J:J,E:E,P24,F:F,Q24,G:G,R24) -> 121818
A25: 24 | B25: 2017 | C25: 混合动力 | D25: =VLOOKUP(C25,M$3:N$16,2,FALSE) -> hybrid fuel vehicle | E25: 大型客车 | F25: 城市公交 | G25: 商用车 | H25: =VLOOKUP(E25&F25&G25,$S$3:$U$68,2,FALSE) -> 公交车 | I25: =VLOOKUP(E25&F25&G25,$S$3:$U$68,3,FALSE) -> Passenger HDV | J25: 2171 | P25: 小型客车 | Q25: 公路客运 | R25: 乘用车 | S25: =P25&Q25&R25 -> 小型客车公路客运乘用车 | T25: 道路客车 | U25: Passenger LDV | V25: =SUMIFS(J:J,E:E,P25,F:F,Q25,G:G,R25) -> 93633
A26: 25 | B26: 2018 | C26: 混合动力 | D26: =VLOOKUP(C26,M$3:N$16,2,FALSE) -> hybrid fuel vehicle | E26: 大型客车 | F26: 城市公交 | G26: 商用车 | H26: =VLOOKUP(E26&F26&G26,$S$3:$U$68,2,FALSE) -> 公交车 | I26: =VLOOKUP(E26&F26&G26,$S$3:$U$68,3,FALSE) -> Passenger HDV | J26: 228 | P26: 小型客车 | Q26: 未知 | R26: 商用车 | S26: =P26&Q26&R26 -> 小型客车未知商用车 | T26: 出租车 | U26: Passenger LDV | V26: =SUMIFS(J:J,E:E,P26,F:F,Q26,G:G,R26) -> 81321
A27: 26 | B27: 2019 | C27: 混合动力 | D27: =VLOOKUP(C27,M$3:N$16,2,FALSE) -> hybrid fuel vehicle | E27: 大型客车 | F27: 城市公交 | G27: 商用车 | H27: =VLOOKUP(E27&F27&G27,$S$3:$U$68,2,FALSE) -> 公交车 | I27: =VLOOKUP(E27&F27&G27,$S$3:$U$68,3,FALSE) -> Passenger HDV | J27: 3 | P27: 中型客车 | Q27: 公路客运 | R27: 商用车 | S27: =P27&Q27&R27 -> 中型客车公路客运商用车 | T27: 道路客车 | U27: Passenger HDV | V27: =SUMIFS(J:J,E:E,P27,F:F,Q27,G:G,R27) -> 69510
A28: 27 | B28: 2021 | C28: 混合动力 | D28: =VLOOKUP(C28,M$3:N$16,2,FALSE) -> hybrid fuel vehicle | E28: 大型客车 | F28: 城市公交 | G28: 商用车 | H28: =VLOOKUP(E28&F28&G28,$S$3:$U$68,2,FALSE) -> 公交车 | I28: =VLOOKUP(E28&F28&G28,$S$3:$U$68,3,FALSE) -> Passenger HDV | J28: 2 | P28: 中型客车 | Q28: 城市公交 | R28: 商用车 | S28: =P28&Q28&R28 -> 中型客车城市公交商用车 | T28: 公交车 | U28: Passenger HDV | V28: =SUMIFS(J:J,E:E,P28,F:F,Q28,G:G,R28) -> 30427
... A68: 67 | B68: 2020 | C68: 汽油 | D68: =VLOOKUP(C68,M$3:N$16,2,FALSE) -> gasoline vehicle | E68: 小型客车 | F68: 城市公交 | G68: 商用车 | H68: =VLOOKUP(E68&F68&G68,$S$3:$U$68,2,FALSE) -> 公交车 | I68: =VLOOKUP(E68&F68&G68,$S$3:$U$68,3,FALSE) -> Passenger LDV | J68: 106 | P68: NULL | Q68: 公路客运 | R68: 乘用车 | S68: =P68&Q68&R68 -> NULL公路客运乘用车 | T68: Unknown | U68: Unknown | V68: =SUMIFS(J:J,E:E,P68,F:F,Q68,G:G,R68) -> 1
A69: 68 | B69: 2021 | C69: 汽油 | D69: =VLOOKUP(C69,M$3:N$16,2,FALSE) -> gasoline vehicle | E69: 小型客车 | F69: 城市公交 | G69: 商用车 | H69: =VLOOKUP(E69&F69&G69,$S$3:$U$68,2,FALSE) -> 公交车 | I69: =VLOOKUP(E69&F69&G69,$S$3:$U$68,3,FALSE) -> Passenger LDV | J69: 34
A70: 69 | B70: 2016 | C70: 汽油-天然气 | D70: =VLOOKUP(C70,M$3:N$16,2,FALSE) -> natural gas vehicle | E70: 小型客车 | F70: 城市公交 | G70: 商用车 | H70: =VLOOKUP(E70&F70&G70,$S$3:$U$68,2,FALSE) -> 公交车 | I70: =VLOOKUP(E70&F70&G70,$S$3:$U$68,3,FALSE) -> Passenger LDV | J70: 88
A71: 70 | B71: 2017 | C71: 汽油-天然气 | D71: =VLOOKUP(C71,M$3:N$16,2,FALSE) -> natural gas vehicle | E71: 小型客车 | F71: 城市公交 | G71: 商用车 | H71: =VLOOKUP(E71&F71&G71,$S$3:$U$68,2,FALSE) -> 公交车 | I71: =VLOOKUP(E71&F71&G71,$S$3:$U$68,3,FALSE) -> Passenger LDV | J71: 11
A72: 71 | B72: 2018 | C72: 汽油-天然气 | D72: =VLOOKUP(C72,M$3:N$16,2,FALSE) -> natural gas vehicle | E72: 小型客车 | F72: 城市公交 | G72: 商用车 | H72: =VLOOKUP(E72&F72&G72,$S$3:$U$68,2,FALSE) -> 公交车 | I72: =VLOOKUP(E72&F72&G72,$S$3:$U$68,3,FALSE) -> Passenger LDV | J72: 60
A73: 72 | B73: 2019 | C73: 汽油-天然气 | D73: =VLOOKUP(C73,M$3:N$16,2,FALSE) -> natural gas vehicle | E73: 小型客车 | F73: 城市公交 | G73: 商用车 | H73: =VLOOKUP(E73&F73&G73,$S$3:$U$68,2,FALSE) -> 公交车 | I73: =VLOOKUP(E73&F73&G73,$S$3:$U$68,3,FALSE) -> Passenger LDV | J73: 129
A74: 73 | B74: 2020 | C74: 汽油-天然气 | D74: =VLOOKUP(C74,M$3:N$16,2,FALSE) -> natural gas vehicle | E74: 小型客车 | F74: 城市公交 | G74: 商用车 | H74: =VLOOKUP(E74&F74&G74,$S$3:$U$68,2,FALSE) -> 公交车 | I74: =VLOOKUP(E74&F74&G74,$S$3:$U$68,3,FALSE) -> Passenger LDV | J74: 82
A75: 74 | B75: 2016 | C75: 天然气 | D75: =VLOOKUP(C75,M$3:N$16,2,FALSE) -> natural gas vehicle | E75: 小型客车 | F75: 城市公交 | G75: 商用车 | H75: =VLOOKUP(E75&F75&G75,$S$3:$U$68,2,FALSE) -> 公交车 | I75: =VLOOKUP(E75&F75&G75,$S$3:$U$68,3,FALSE) -> Passenger LDV | J75: 5
A76: 75 | B76: 2017 | C76: 天然气 | D76: =VLOOKUP(C76,M$3:N$16,2,FALSE) -> natural gas vehicle | E76: 小型客车 | F76: 城市公交 | G76: 商用车 | H76: =VLOOKUP(E76&F76&G76,$S$3:$U$68,2,FALSE) -> 公交车 | I76: =VLOOKUP(E76&F76&G76,$S$3:$U$68,3,FALSE) -> Passenger LDV | J76: 256
A77: 76 | B77: 2018 | C77: 天然气 | D77: =VLOOKUP(C77,M$3:N$16,2,FALSE) -> natural gas vehicle | E77: 小型客车 | F77: 城市公交 | G77: 商用车 | H77: =VLOOKUP(E77&F77&G77,$S$3:$U$68,2,FALSE) -> 公交车 | I77: =VLOOKUP(E77&F77&G77,$S$3:$U$68,3,FALSE) -> Passenger LDV | J77: 115
A78: 77 | B78: 2019 | C78: 天然气 | D78: =VLOOKUP(C78,M$3:N$16,2,FALSE) -> natural gas vehicle | E78: 小型客车 | F78: 城市公交 | G78: 商用车 | H78: =VLOOKUP(E78&F78&G78,$S$3:$U$68,2,FALSE) -> 公交车 | I78: =VLOOKUP(E78&F78&G78,$S$3:$U$68,3,FALSE) -> Passenger LDV | J78: 40
A79: 78 | B79: 2020 | C79: 天然气 | D79: =VLOOKUP(C79,M$3:N$16,2,FALSE) -> natural gas vehicle | E79: 小型客车 | F79: 城市公交 | G79: 商用车 | H79: =VLOOKUP(E79&F79&G79,$S$3:$U$68,2,FALSE) -> 公交车 | I79: =VLOOKUP(E79&F79&G79,$S$3:$U$68,3,FALSE) -> Passenger LDV | J79: 1
A80: 79 | B80: 2017 | C80: 柴油 | D80: =VLOOKUP(C80,M$3:N$16,2,FALSE) -> diesel vehicle | E80: 中型货车 | F80: 城市公交 | G80: 商用车 | H80: =VLOOKUP(E80&F80&G80,$S$3:$U$68,2,FALSE) -> 公交车 | I80: =VLOOKUP(E80&F80&G80,$S$3:$U$68,3,FALSE) -> Passenger HDV | J80: 51
...

Sheet Pivot Table
A1: 求和项:Sales | B1: 列标签
A2: 行标签 | B2: battery electric vehicle | C2: diesel vehicle | D2: gasoline vehicle | E2: hybrid fuel vehicle | F2: hydrogen vehicle | G2: LPG vehicle | H2: natural gas vehicle | I2: other fuel vehicle | J2: plugin hybrid vehicle | K2: unknown | L2: 总计 | N2: Fuel Type | O2: battery electric vehicle | P2: natural gas vehicle | Q2: gasoline vehicle | R2: diesel vehicle | S2: plugin hybrid vehicle | T2: LPG vehicle | U2: hydrogen vehicle | V2: hybrid fuel vehicle | W2: other fuel vehicle
A3: Freight HDV | B3: 49887 | C3: 7556854 | D3: 402 | E3: 106 | F3: 4322 | H3: 484270 | I3: 117 | J3: 1156 | K3: 4 | L3: 8097118 | N3: Freight HDV
A4: 2015 | B4: 5722 | C4: 543387 | D4: 213 | H4: 14079 | L4: 563401 | N4: 2015 | O4: =B4/($L4-$K4) -> 0.010156177 | P4: =H4/($L4-$K4) -> 0.024989306 | Q4: =D4/($L4-$K4) -> 0.0003780611 | R4: =C4/($L4-$K4) -> 0.96447646 | S4: =J4/($L4-$K4) -> 0 | T4: =G4/($L4-$K4) -> 0 | U4: =F4/($L4-$K4) -> 0 | V4: =E4/($L4-$K4) -> 0 | W4: =I4/($L4-$K4) -> 0
A5: 2016 | B5: 4529 | C5: 761880 | D5: 25 | E5: 6 | H5: 15344 | K5: 4 | L5: 781788 | N5: 2016 | O5: =B5/($L5-$K5) -> 0.0057931603 | P5: =H5/($L5-$K5) -> 0.019626905 | Q5: =D5/($L5-$K5) -> 3.1978142e-05 | R5: =C5/($L5-$K5) -> 0.97454028 | S5: =J5/($L5-$K5) -> 0 | T5: =G5/($L5-$K5) -> 0 | U5: =F5/($L5-$K5) -> 0 | V5: =E5/($L5-$K5) -> 7.6747542e-06 | W5: =I5/($L5-$K5) -> 0
A6: 2017 | B6: 16933 | C6: 1061952 | D6: 46 | E6: 56 | F6: 933 | H6: 70507 | J6: 1120 | L6: 1151547 | N6: 2017 | O6: =B6/($L6-$K6) -> 0.014704567 | P6: =H6/($L6-$K6) -> 0.06122807 | Q6: =D6/($L6-$K6) -> 3.9946264e-05 | R6: =C6/($L6-$K6) -> 0.92219597 | S6: =J6/($L6-$K6) -> 0.00097260468 | T6: =G6/($L6-$K6) -> 0 | U6: =F6/($L6-$K6) -> 0.00081021443 | V6: =E6/($L6-$K6) -> 4.8630234e-05 | W6: =I6/($L6-$K6) -> 0
A7: 2018 | B7: 1648 | C7: 1070295 | D7: 40 | E7: 2 | F7: 404 | H7: 65710 | L7: 1138099 | N7: 2018 | O7: =B7/($L7-$K7) -> 0.0014480287 | P7: =H7/($L7-$K7) -> 0.057736629 | Q7: =D7/($L7-$K7) -> 3.5146327e-05 | R7: =C7/($L7-$K7) -> 0.94042346 | S7: =J7/($L7-$K7) -> 0 | T7: =G7/($L7-$K7) -> 0 | U7: =F7/($L7-$K7) -> 0.00035497791 | V7: =E7/($L7-$K7) -> 1.7573164e-06 | W7: =I7/($L7-$K7) -> 0
A8: 2019 | B8: 5962 | C8: 1141356 | D8: 30 | F8: 2014 | H8: 116202 | I8: 13 | L8: 1265577 | N8: 2019 | O8: =B8/($L8-$K8) -> 0.0047108947 | P8: =H8/($L8-$K8) -> 0.091817408 | Q8: =D8/($L8-$K8) -> 2.3704603e-05 | R8: =C8/($L8-$K8) -> 0.90184635 | S8: =J8/($L8-$K8) -> 0 | T8: =G8/($L8-$K8) -> 0 | U8: =F8/($L8-$K8) -> 0.001591369 | V8: =E8/($L8-$K8) -> 0 | W8: =I8/($L8-$K8) -> 1.0271995e-05
A9: 2020 | B9: 4111 | C9: 1530088 | D9: 44 | E9: 24 | F9: 146 | H9: 142829 | I9: 14 | J9: 11 | L9: 1677267 | N9: 2020 | O9: =B9/($L9-$K9) -> 0.0024510111 | P9: =H9/($L9-$K9) -> 0.085155792 | Q9: =D9/($L9-$K9) -> 2.6233152e-05 | R9: =C9/($L9-$K9) -> 0.9122507 | S9: =J9/($L9-$K9) -> 6.558288e-06 | T9: =G9/($L9-$K9) -> 0 | U9: =F9/($L9-$K9) -> 8.7046368e-05 | V9: =E9/($L9-$K9) -> 1.4308992e-05 | W9: =I9/($L9-$K9) -> 8.346912e-06
A10: 2021 | B10: 10982 | C10: 1447896 | D10: 4 | E10: 18 | F10: 825 | H10: 59599 | I10: 90 | J10: 25 | L10: 1519439 | N10: 2021 | O10: =B10/($L10-$K10) -> 0.0072276676 | P10: =H10/($L10-$K10) -> 0.039224345 | Q10: =D10/($L10-$K10) -> 2.6325506e-06 | R10: =C10/($L10-$K10) -> 0.95291486 | S10: =J10/($L10-$K10) -> 1.6453441e-05 | T10: =G10/($L10-$K10) -> 0 | U10: =F10/($L10-$K10) -> 0.00054296355 | V10: =E10/($L10-$K10) -> 1.1846478e-05 | W10: =I10/($L10-$K10) -> 5.9232388e-05
A11: Freight LDV | B11: 217086 | C11: 7283616 | D11: 6562410 | E11: 12 | F11: 3 | H11: 176564 | J11: 1667 | L11: 14241358 | N11: Freight LDV
A12: 2015 | B12: 24785 | C12: 763006 | D12: 706406 | E12: 4 | H12: 36040 | L12: 1530241 | N12: 2015 | O12: =B12/($L12-$K12) -> 0.016196795 | P12: =H12/($L12-$K12) -> 0.023551846 | Q12: =D12/($L12-$K12) -> 0.46163055 | R12: =C12/($L12-$K12) -> 0.49861819 | S12: =J12/($L12-$K12) -> 0 | T12: =G12/($L12-$K12) -> 0 | U12: =F12/($L12-$K12) -> 0 | V12: =E12/($L12-$K12) -> 2.6139673e-06 | W12: =I12/($L12-$K12) -> 0
A13: 2016 | B13: 17755 | C13: 876597 | D13: 756679 | H13: 16696 | L13: 1667727 | N13: 2016 | O13: =B13/($L13-$K13) -> 0.010646227 | P13: =H13/($L13-$K13) -> 0.010011231 | Q13: =D13/($L13-$K13) -> 0.45371874 | R13: =C13/($L13-$K13) -> 0.5256238 | S13: =J13/($L13-$K13) -> 0 | T13: =G13/($L13-$K13) -> 0 | U13: =F13/($L13-$K13) -> 0 | V13: =E13/($L13-$K13) -> 0 | W13: =I13/($L13-$K13) -> 0
A14: 2017 | B14: 61786 | C14: 1024613 | D14: 838364 | H14: 20278 | L14: 1945041 | N14: 2017 | O14: =B14/($L14-$K14) -> 0.031765911 | P14: =H14/($L14-$K14) -> 0.010425487 | Q14: =D14/($L14-$K14) -> 0.43102639 | R14: =C14/($L14-$K14) -> 0.52678221 | S14: =J14/($L14-$K14) -> 0 | T14: =G14/($L14-$K14) -> 0 | U14: =F14/($L14-$K14) -> 0 | V14: =E14/($L14-$K14) -> 0 | W14: =I14/($L14-$K14) -> 0
A15: 2018 | B15: 40792 | C15: 1036146 | D15: 940137 | H15: 27190 | J15: 1 | L15: 2044266 | N15: 2018 | O15: =B15/($L15-$K15) -> 0.01995435 | P15: =H15/($L15-$K15) -> 0.013300617 | Q15: =D15/($L15-$K15) -> 0.45988976 | R15: =C15/($L15-$K15) -> 0.50685478 | S15: =J15/($L15-$K15) -> 4.8917313e-07 | T15: =G15/($L15-$K15) -> 0 | U15: =F15/($L15-$K15) -> 0 | V15: =E15/($L15-$K15) -> 0 | W15: =I15/($L15-$K15) -> 0
A16: 2019 | B16: 18134 | C16: 1052509 | D16: 1086406 | H16: 32818 | J16: 98 | L16: 2189965 | N16: 2019 | O16: =B16/($L16-$K16) -> 0.0082804976 | P16: =H16/($L16-$K16) -> 0.014985628 | Q16: =D16/($L16-$K16) -> 0.49608373 | R16: =C16/($L16-$K16) -> 0.4806054 | S16: =J16/($L16-$K16) -> 4.4749574e-05 | T16: =G16/($L16-$K16) -> 0 | U16: =F16/($L16-$K16) -> 0 | V16: =E16/($L16-$K16) -> 0 | W16: =I16/($L16-$K16) -> 0
A17: 2020 | B17: 15349 | C17: 1319180 | D17: 1157774 | H17: 21626 | J17: 318 | L17: 2514247 | N17: 2020 | O17: =B17/($L17-$K17) -> 0.0061048099 | P17: =H17/($L17-$K17) -> 0.0086013824 | Q17: =D17/($L17-$K17) -> 0.46048539 | R17: =C17/($L17-$K17) -> 0.52468194 | S17: =J17/($L17-$K17) -> 0.00012647922 | T17: =G17/($L17-$K17) -> 0 | U17: =F17/($L17-$K17) -> 0 | V17: =E17/($L17-$K17) -> 0 | W17: =I17/($L17-$K17) -> 0
A18: 2021 | B18: 38485 | C18: 1211565 | D18: 1076644 | E18: 8 | F18: 3 | H18: 21916 | J18: 1250 | L18: 2349871 | N18: 2021 | O18: =B18/($L18-$K18) -> 0.016377495 | P18: =H18/($L18-$K18) -> 0.0093264694 | Q18: =D18/($L18-$K18) -> 0.45817153 | R18: =C18/($L18-$K18) -> 0.51558788 | S18: =J18/($L18-$K18) -> 0.00053194409 | T18: =G18/($L18-$K18) -> 0 | U18: =F18/($L18-$K18) -> 1.2766658e-06 | V18: =E18/($L18-$K18) -> 3.4044422e-06 | W18: =I18/($L18-$K18) -> 0
A19: Passenger HDV | B19: 512915 | C19: 547268 | D19: 102586 | E19: 24163 | F19: 4155 | H19: 53334 | I19: 5 | J19: 51218 | K19: 38 | L19: 1295682 | N19: Passenger HDV
A20: 2015 | B20: 85938 | C20: 123176 | D20: 18249 | E20: 8354 | H20: 25597 | J20: 16901 | K20: 38 | L20: 278253 | N20: 2015 | O20: =B20/($L20-$K20) -> 0.30889061 | P20: =H20/($L20-$K20) -> 0.092004385 | Q20: =D20/($L20-$K20) -> 0.065593156 | R20: =C20/($L20-$K20) -> 0.44273673 | S20: =J20/($L20-$K20) -> 0.060747983 | T20: =G20/($L20-$K20) -> 0 | U20: =F20/($L20-$K20) -> 0 | V20: =E20/($L20-$K20) -> 0.030027137 | W20: =I20/($L20-$K20) -> 0
A21: 2016 | B21: 91058 | C21: 113793 | D21: 19181 | E21: 13270 | F21: 29 | H21: 11598 | J21: 5344 | L21: 254273 | N21: 2016 | O21: =B21/($L21-$K21) -> 0.35811116 | P21: =H21/($L21-$K21) -> 0.045612393 | Q21: =D21/($L21-$K21) -> 0.075434671 | R21: =C21/($L21-$K21) -> 0.44752294 | S21: =J21/($L21-$K21) -> 0.021016781 | T21: =G21/($L21-$K21) -> 0 | U21: =F21/($L21-$K21) -> 0.00011405065 | V21: =E21/($L21-$K21) -> 0.052188003 | W21: =I21/($L21-$K21) -> 0
A22: 2017 | B22: 76566 | C22: 85307 | D22: 16807 | E22: 2295 | F22: 115 | H22: 8781 | J22: 12561 | L22: 202432 | N22: 2017 | O22: =B22/($L22-$K22) -> 0.37823071 | P22: =H22/($L22-$K22) -> 0.043377529 | Q22: =D22/($L22-$K22) -> 0.083025411 | R22: =C22/($L22-$K22) -> 0.42141065 | S22: =J22/($L22-$K22) -> 0.062050466 | T22: =G22/($L22-$K22) -> 0 | U22: =F22/($L22-$K22) -> 0.000568092 | V22: =E22/($L22-$K22) -> 0.01133714 | W22: =I22/($L22-$K22) -> 0
A23: 2018 | B23: 85927 | C23: 72442 | D23: 12754 | E23: 239 | F23: 437 | H23: 3832 | I23: 5 | J23: 5839 | L23: 181475 | N23: 2018 | O23: =B23/($L23-$K23) -> 0.47349222 | P23: =H23/($L23-$K23) -> 0.021115856 | Q23: =D23/($L23-$K23) -> 0.070279653 | R23: =C23/($L23-$K23) -> 0.39918446 | S23: =J23/($L23-$K23) -> 0.032175231 | T23: =G23/($L23-$K23) -> 0 | U23: =F23/($L23-$K23) -> 0.0024080452 | V23: =E23/($L23-$K23) -> 0.0013169858 | W23: =I23/($L23-$K23) -> 2.7552004e-05
A24: 2019 | B24: 72243 | C24: 70020 | D24: 15305 | E24: 3 | F24: 1176 | H24: 2082 | J24: 4298 | L24: 165127 | N24: 2019 | O24: =B24/($L24-$K24) -> 0.43749962 | P24: =H24/($L24-$K24) -> 0.012608477 | Q24: =D24/($L24-$K24) -> 0.092686235 | R24: =C24/($L24-$K24) -> 0.42403726 | S24: =J24/($L24-$K24) -> 0.026028451 | T24: =G24/($L24-$K24) -> 0 | U24: =F24/($L24-$K24) -> 0.0071217911 | V24: =E24/($L24-$K24) -> 1.8167834e-05 | W24: =I24/($L24-$K24) -> 0
A25: 2020 | B25: 55145 | C25: 35741 | D25: 7949 | F25: 1351 | H25: 915 | J25: 5049 | L25: 106150 | N25: 2020 | O25: =B25/($L25-$K25) -> 0.51950071 | P25: =H25/($L25-$K25) -> 0.0086198775 | Q25: =D25/($L25-$K25) -> 0.074884597 | R25: =C25/($L25-$K25) -> 0.33670278 | S25: =J25/($L25-$K25) -> 0.047564767 | T25: =G25/($L25-$K25) -> 0 | U25: =F25/($L25-$K25) -> 0.012727273 | V25: =E25/($L25-$K25) -> 0 | W25: =I25/($L25-$K25) -> 0
A26: 2021 | B26: 46038 | C26: 46789 | D26: 12341 | E26: 2 | F26: 1047 | H26: 529 | J26: 1226 | L26: 107972 | N26: 2021 | O26: =B26/($L26-$K26) -> 0.42638832 | P26: =H26/($L26-$K26) -> 0.0048994184 | Q26: =D26/($L26-$K26) -> 0.11429815 | R26: =C26/($L26-$K26) -> 0.43334383 | S26: =J26/($L26-$K26) -> 0.011354796 | T26: =G26/($L26-$K26) -> 0 | U26: =F26/($L26-$K26) -> 0.0096969585 | V26: =E26/($L26-$K26) -> 1.8523321e-05 | W26: =I26/($L26-$K26) -> 0
A27: Passenger LDV | B27: 5711717 | C27: 1203924 | D27: 144403802 | E27: 2485070 | F27: 77 | G27: 10354 | H27: 2028005 | I27: 26020 | J27: 1106569 | L27: 156975538 | N27: Passenger LDV
A28: 2015 | B28: 135782 | C28: 163367 | D28: 19291074 | E28: 69444 | H28: 1495689 | I28: 578 | J28: 12662 | L28: 21168596 | N28: 2015 | O28: =B28/($L28-$K28) -> 0.006414313 | P28: =H28/($L28-$K28) -> 0.070656032 | Q28: =D28/($L28-$K28) -> 0.91130626 | R28: =C28/($L28-$K28) -> 0.0077174225 | S28: =J28/($L28-$K28) -> 0.0005981502 | T28: =G28/($L28-$K28) -> 0 | U28: =F28/($L28-$K28) -> 0 | V28: =E28/($L28-$K28) -> 0.0032805199 | W28: =I28/($L28-$K28) -> 2.7304598e-05
A29: 2016 | B29: 246143 | C29: 154701 | D29: 24058794 | E29: 157772 | F29: 8 | G29: 1722 | H29: 110827 | I29: 205 | J29: 24705 | L29: 24754877 | N29: 2016 | O29: =B29/($L29-$K29) -> 0.0099432124 | P29: =H29/($L29-$K29) -> 0.0044769764 | Q29: =D29/($L29-$K29) -> 0.97188098 | R29: =C29/($L29-$K29) -> 0.006249314 | S29: =J29/($L29-$K29) -> 0.00099798516 | T29: =G29/($L29-$K29) -> 6.956205e-05 | U29: =F29/($L29-$K29) -> 3.2316864e-07 | V29: =E29/($L29-$K29) -> 0.0063733704 | W29: =I29/($L29-$K29) -> 8.2811965e-06
A30: 2017 | B30: 508748 | C30: 160842 | D30: 23725630 | E30: 222304 | F30: 50 | G30: 5287 | H30: 99873 | I30: 2309 | J30: 58890 | L30: 24783933 | N30: 2017 | O30: =B30/($L30-$K30) -> 0.020527331 | P30: =H30/($L30-$K30) -> 0.0040297478 | Q30: =D30/($L30-$K30) -> 0.95729883 | R30: =C30/($L30-$K30) -> 0.006489769 | S30: =J30/($L30-$K30) -> 0.0023761362 | T30: =G30/($L30-$K30) -> 0.00021332369 | U30: =F30/($L30-$K30) -> 2.0174361e-06 | V30: =E30/($L30-$K30) -> 0.0089696821 | W30: =I30/($L30-$K30) -> 9.3165197e-05
A31: 2018 | B31: 744374 | C31: 188491 | D31: 21161732 | E31: 308721 | G31: 3142 | H31: 127403 | I31: 1842 | J31: 187801 | L31: 22723506 | N31: 2018 | O31: =B31/($L31-$K31) -> 0.032757885 | P31: =H31/($L31-$K31) -> 0.0056066612 | Q31: =D31/($L31-$K31) -> 0.93127055 | R31: =C31/($L31-$K31) -> 0.0082949788 | S31: =J31/($L31-$K31) -> 0.0082646137 | T31: =G31/($L31-$K31) -> 0.00013827092 | U31: =F31/($L31-$K31) -> 0 | V31: =E31/($L31-$K31) -> 0.013585976 | W31: =I31/($L31-$K31) -> 8.1061435e-05
A32: 2019 | B32: 724626 | C32: 157907 | D32: 20272632 | E32: 376905 | G32: 203 | H32: 107211 | I32: 14561 | J32: 200475 | L32: 21854520 | N32: 2019 | O32: =B32/($L32-$K32) -> 0.033156802 | P32: =H32/($L32-$K32) -> 0.0049056671 | Q32: =D32/($L32-$K32) -> 0.92761735 | R32: =C32/($L32-$K32) -> 0.0072253703 | S32: =J32/($L32-$K32) -> 0.0091731596 | T32: =G32/($L32-$K32) -> 9.2886963e-06 | U32: =F32/($L32-$K32) -> 0 | V32: =E32/($L32-$K32) -> 0.017246089 | W32: =I32/($L32-$K32) -> 0.00066626949
A33: 2020 | B33: 939086 | C33: 187404 | D33: 18373144 | E33: 552189 | H33: 41878 | I33: 5688 | J33: 207790 | L33: 20307179 | N33: 2020 | O33: =B33/($L33-$K33) -> 0.04624404 | P33: =H33/($L33-$K33) -> 0.0020622264 | Q33: =D33/($L33-$K33) -> 0.90476102 | R33: =C33/($L33-$K33) -> 0.0092284605 | S33: =J33/($L33-$K33) -> 0.010232342 | T33: =G33/($L33-$K33) -> 0 | U33: =F33/($L33-$K33) -> 0 | V33: =E33/($L33-$K33) -> 0.027191812 | W33: =I33/($L33-$K33) -> 0.00028009799
A34: 2021 | B34: 2412958 | C34: 191212 | D34: 17520796 | E34: 797735 | F34: 19 | H34: 45124 | I34: 837 | J34: 414246 | L34: 21382927 | N34: 2021 | O34: =B34/($L34-$K34) -> 0.11284507 | P34: =H34/($L34-$K34) -> 0.0021102817 | Q34: =D34/($L34-$K34) -> 0.81938249 | R34: =C34/($L34-$K34) -> 0.0089422744 | S34: =J34/($L34-$K34) -> 0.019372745 | T34: =G34/($L34-$K34) -> 0 | U34: =F34/($L34-$K34) -> 8.8855936e-07 | V34: =E34/($L34-$K34) -> 0.0373071 | W34: =I34/($L34-$K34) -> 3.9143378e-05
A35: Unknown | B35: 3058 | C35: 16503 | D35: 2339472 | E35: 22971 | H35: 10200 | J35: 6003 | K35: 192895 | L35: 2591102
A36: 2015 | B36: 261 | C36: 16431 | D36: 2172590 | H36: 10200 | K36: 192895 | L36: 2392377
A37: 2021 | B37: 2797 | C37: 72 | D37: 166882 | E37: 22971 | J37: 6003 | L37: 198725
A38: 总计 | B38: 6494663 | C38: 16608165 | D38: 153408672 | E38: 2532322 | F38: 8557 | G38: 10354 | H38: 2752373 | I38: 26142 | J38: 1166613 | K38: 192937 | L38: 183200798

Sheet Electric Ratio
A1: 求和项:Sales | B1: 列标签
A2: 行标签 | B2: battery electric vehicle | C2: diesel vehicle | D2: gasoline vehicle | E2: hybrid fuel vehicle | F2: hydrogen vehicle | G2: LPG vehicle | H2: natural gas vehicle | I2: other fuel vehicle | J2: plugin hybrid vehicle | K2: unknown | L2: 总计 | O2: 车型占比 | P2: 电动化率 | Q2: 混动占比 | R2: 纯电占比 | S2: 车型占比 | T2: 电动化率 | U2: 混动占比 | V2: 纯电占比 | W2: 车型占比 | X2: 电动化率 | Y2: 混动占比 | Z2: 纯电占比 | AA2: 车型占比 | AB2: 电动化率 | AC2: 混动占比 | AD2: 纯电占比 | AE2: 车型占比 | AF2: 电动化率 | AG2: 混动占比 | AH2: 纯电占比 | AI2: 车型占比 | AJ2: 电动化率 | AK2: 混动占比 | AL2: 纯电占比 | AM2: 车型占比 | AN2: 电动化率 | AO2: 混动占比 | AP2: 纯电占比 | AQ2: 车型占比 | AR2: 电动化率 | AS2: 混动占比 | AT2: 纯电占比 | AU2: 车型占比 | AV2: 电动化率 | AW2: 混动占比 | AX2: 纯电占比 | AY2: 车型占比 | AZ2: 电动化率 | BA2: 混动占比 | BB2: 纯电占比
A3: Freight HDV | B3: 49887 | C3: 7556854 | D3: 402 | E3: 106 | F3: 4322 | H3: 484270 | I3: 117 | J3: 1156 | K3: 4 | L3: 8097118 | N3: EPS Type | O3: Freight HDV | S3: Freight LDV | W3: Passenger HDV | AI3: Passenger LDV
A4: 中重型货车 | B4: 49887 | C4: 7556854 | D4: 402 | E4: 106 | F4: 4322 | H4: 484270 | I4: 117 | J4: 1156 | K4: 4 | L4: 8097118 | N4: Database Type | O4: 中重型货车 | S4: 轻型货车 | W4: 合并 | AA4: 道路客车 | AE4: 公交车 | AI4: 合并 | AM4: 乘用车 | AQ4: 出租车 | AU4: 道路客车 | AY4: 公交车
A5: 2015 | B5: 5722 | C5: 543387 | D5: 213 | H5: 14079 | L5: 563401 | N5: 2015-2021 | O5: =L4/L4 -> 1 | P5: =(J4+B4)/L4 -> 0.0063038479 | Q5: =J4/(J4+B4) -> 0.022647572 | R5: =B4/(B4+J4) -> 0.97735243 | S5: =L13/L13 -> 1 | T5: =(J13+B13)/L13 -> 0.015360403 | U5: =J13/(J13+B13) -> 0.0076204669 | V5: =B13/(B13+J13) -> 0.99237953 | W5: =AA5+AE5 -> 1 | X5: =AB5*AA5+AF5*AE5 -> 0.43539464 | Y5: =(AA5*AB5*AC5+AE5*AF5*AG5)/(AA5*AB5+AE5*AF5) -> 0.01205722 | Z5: =(AA5*AB5*AD5+AE5*AF5*AH5)/(AA5*AB5+AE5*AF5) -> 0.90920935 | AA5: =L22/(L22+L30) -> 0.54903055 | AB5: =(J22+B22)/L22 -> 0.15372753 | AC5: =J22/(J22+B22) -> 0.018581344 | AD5: =B22/(B22+J22) -> 0.98141866 | AE5: =L30/(L22+L30) -> 0.45096945 | AF5: =(B30+J30)/L30 -> 0.77830889 | AG5: =J30/(J30+B39) -> 0.010488406 | AH5: =B30/(B30+J30) -> 0.89184566 | AI5: =AM5+AQ5+AU5+AY5 -> 1 | AJ5: =(AM5*AN5+AQ5*AR5+AU5*AV5+AY5*AZ5) -> 0.043435341 | AK5: =(AM5*AN5*AO5+AQ5*AR5*AS5+AU5*AV5*AW5+AY5*AZ5*BA5)/(AM5*AN5+AQ5*AR5+AU5*AV5+AY5*AZ5) -> 0.16229431 | AL5: =(AM5*AN5*AP5+AQ5*AR5*AT5+AU5*AV5*AX5+AY5*AZ5*BB5)/(AM5*AN5+AQ5*AR5+AU5*AV5+AY5*AZ5) -> 0.83770569 | AM5: =L39/(L39+L47+L55+L63) -> 0.97785901 | AN5: =(J39+B39)/L39 -> 0.037040691 | AO5: =J39/(J39+B39) -> 0.18385826 | AP5: =B39/(B39+J39) -> 0.81614174 | AQ5: =L47/(L39+L47+L55+L63) -> 0.021366482 | AR5: =(B47+J47)/L47 -> 0.33657423 | AS5: =J47/(J47+B47) -> 0.054196435 | AT5: =B47/(B47+J47) -> 0.94580357 | AU5: =L55/(L39+L47+L55+L63) -> 0.00073858005 | AV5: =(B55+J55)/L55 -> 0.023374361 | AW5: =J55/(J55+B55) -> 0.0062730627 | AX5: =B55/(B55+J55) -> 0.99372694 | AY5: =L63/(L39+L47+L55+L63) -> 3.5929165e-05 | AZ5: =(B63+J63)/L63 -> 0.16968085 | BA5: =J63/(J63+B63) -> 0 | BB5: =B63/(B63+J63) -> 1
A6: 2016 | B6: 4529 | C6: 761880 | D6: 25 | E6: 6 | H6: 15344 | K6: 4 | L6: 781788 | N6: 2015 | O6: =L5/L5 -> 1 | P6: =(J5+B5)/L5 -> 0.010156177 | Q6: =J5/(J5+B5) -> 0 | R6: =B5/(B5+J5) -> 1 | S6: =L14/L14 -> 1 | T6: =(J14+B14)/L14 -> 0.016196795 | U6: =J14/(J14+B14) -> 0 | V6: =B14/(B14+J14) -> 1 | W6: =AA6+AE6 -> 1 | X6: =AB6*AA6+AF6*AE6 -> 0.36958811 | Y6: =(AA6*AB6*AC6+AE6*AF6*AG6)/(AA6*AB6+AE6*AF6) -> 0.078797614 | Z6: =(AA6*AB6*AD6+AE6*AF6*AH6)/(AA6*AB6+AE6*AF6) -> 0.83565573 | AA6: =L23/(L23+L31) -> 0.53563484 | AB6: =(J23+B23)/L23 -> 0.28081346 | AC6: =J23/(J23+B23) -> 0.014479249 | AD6: =B23/(B23+J23) -> 0.98552075 | AE6: =L31/(L23+L31) -> 0.46436516 | AF6: =(B31+J31)/L31 -> 0.47198768 | AG6: =J31/(J31+B40) -> 0.12293752 | AH6: =B31/(B31+J31) -> 0.73280753 | AI6: =AM6+AQ6+AU6+AY6 -> 1 | AJ6: =(AM6*AN6+AQ6*AR6+AU6*AV6+AY6*AZ6) -> 0.0070124632 | AK6: =(AM6*AN6*AO6+AQ6*AR6*AS6+AU6*AV6*AW6+AY6*AZ6*BA6)/(AM6*AN6+AQ6*AR6+AU6*AV6+AY6*AZ6) -> 0.08529816 | AL6: =(AM6*AN6*AP6+AQ6*AR6*AT6+AU6*AV6*AX6+AY6*AZ6*BB6)/(AM6*AN6+AQ6*AR6+AU6*AV6+AY6*AZ6) -> 0.91470184 | AM6: =L40/(L40+L48+L56+L64) -> 0.98191226 | AN6: =(J40+B40)/L40 -> 0.00607557 | AO6: =J40/(J40+B40) -> 0.079447282 | AP6: =B40/(B40+J40) -> 0.92055272 | AQ6: =L48/(L40+L48+L56+L64) -> 0.017548731 | AR6: =(B48+J48)/L48 -> 0.059238402 | AS6: =J48/(J48+B48) -> 0.11946742 | AT6: =B48/(B48+J48) -> 0.88053258 | AU6: =L56/(L40+L48+L56+L64) -> 0.00050683569 | AV6: =(B56+J56)/L56 -> 0.00027961599 | AW6: =J56/(J56+B56) -> 0 | AX6: =B56/(B56+J56) -> 1 | AY6: =L64/(L40+L48+L56+L64) -> 3.2170296e-05 | AZ6: =(B64+J64)/L64 -> 0.22026432 | BA6: =J64/(J64+B64) -> 0 | BB6: =B64/(B64+J64) -> 1
A7: 2017 | B7: 16933 | C7: 1061952 | D7: 46 | E7: 56 | F7: 933 | H7: 70507 | J7: 1120 | L7: 1151547 | N7: 2016 | O7: =L5/L5 -> 1 | P7: =(J6+B6)/L6 -> 0.0057931306 | Q7: =J6/(J6+B6) -> 0 | R7: =B6/(B6+J6) -> 1 | S7: =L14/L14 -> 1 | T7: =(J15+B15)/L15 -> 0.010646227 | U7: =J15/(J15+B15) -> 0 | V7: =B15/(B15+J15) -> 1 | W7: =AA7+AE7 -> 1 | X7: =AB7*AA7+AF7*AE7 -> 0.37912795 | Y7: =(AA7*AB7*AC7+AE7*AF7*AG7)/(AA7*AB7+AE7*AF7) -> 0.022941066 | Z7: =(AA7*AB7*AD7+AE7*AF7*AH7)/(AA7*AB7+AE7*AF7) -> 0.94456547 | AA7: =L24/(L24+L32) -> 0.62035293 | AB7: =(J24+B24)/L24 -> 0.19620386 | AC7: =J24/(J24+B24) -> 0.028110763 | AD7: =B24/(B24+J24) -> 0.97188924 | AE7: =L32/(L24+L32) -> 0.37964707 | AF7: =(B32+J32)/L32 -> 0.67803054 | AG7: =J32/(J32+B41) -> 0.02049661 | AH7: =B32/(B32+J32) -> 0.93164561 | AI7: =AM7+AQ7+AU7+AY7 -> 1 | AJ7: =(AM7*AN7+AQ7*AR7+AU7*AV7+AY7*AZ7) -> 0.010941198 | AK7: =(AM7*AN7*AO7+AQ7*AR7*AS7+AU7*AV7*AW7+AY7*AZ7*BA7)/(AM7*AN7+AQ7*AR7+AU7*AV7+AY7*AZ7) -> 0.091213522 | AL7: =(AM7*AN7*AP7+AQ7*AR7*AT7+AU7*AV7*AX7+AY7*AZ7*BB7)/(AM7*AN7+AQ7*AR7+AU7*AV7+AY7*AZ7) -> 0.90878648 | AM7: =L41/(L41+L49+L57+L65) -> 0.9861319 | AN7: =(J41+B41)/L41 -> 0.0096563212 | AO7: =J41/(J41+B41) -> 0.092989318 | AP7: =B41/(B41+J41) -> 0.90701068 | AQ7: =L49/(L41+L49+L57+L65) -> 0.013550219 | AR7: =(B49+J49)/L49 -> 0.1046644 | AS7: =J49/(J49+B49) -> 0.079326649 | AT7: =B49/(B49+J49) -> 0.92067335 | AU7: =L57/(L41+L49+L57+L65) -> 0.00030272823 | AV7: =(B57+J57)/L57 -> 0.0018681612 | AW7: =J57/(J57+B57) -> 0 | AX7: =B57/(B57+J57) -> 1 | AY7: =L65/(L41+L49+L57+L65) -> 1.514853e-05 | AZ7: =(B65+J65)/L65 -> 0 | BA7: =IFERROR(J65/(J65+B65),BA5) -> 0 | BB7: =IFERROR(B65/(B65+J65),BB5) -> 1
A8: 2018 | B8: 1648 | C8: 1070295 | D8: 40 | E8: 2 | F8: 404 | H8: 65710 | L8: 1138099 | N8: 2017 | O8: =L6/L6 -> 1 | P8: =(J7+B7)/L7 -> 0.015677172 | Q8: =J7/(J7+B7) -> 0.06203955 | R8: =B7/(B7+J7) -> 0.93796045 | S8: =L15/L15 -> 1 | T8: =(J16+B16)/L16 -> 0.031765911 | U8: =J16/(J16+B16) -> 0 | V8: =B16/(B16+J16) -> 1 | W8: =AA8+AE8 -> 1 | X8: =AB8*AA8+AF8*AE8 -> 0.44028118 | Y8: =(AA8*AB8*AC8+AE8*AF8*AG8)/(AA8*AB8+AE8*AF8) -> 0.02675972 | Z8: =(AA8*AB8*AD8+AE8*AF8*AH8)/(AA8*AB8+AE8*AF8) -> 0.85906628 | AA8: =L25/(L25+L33) -> 0.57428173 | AB8: =(J25+B25)/L25 -> 0.16203453 | AC8: =J25/(J25+B25) -> 0.024738546 | AD8: =B25/(B25+J25) -> 0.97526145 | AE8: =L33/(L25+L33) -> 0.42571827 | AF8: =(B33+J33)/L33 -> 0.81562794 | AG8: =J33/(J33+B42) -> 0.027301374 | AH8: =B33/(B33+J33) -> 0.82792716 | AI8: =AM8+AQ8+AU8+AY8 -> 1 | AJ8: =(AM8*AN8+AQ8*AR8+AU8*AV8+AY8*AZ8) -> 0.022903467 | AK8: =(AM8*AN8*AO8+AQ8*AR8*AS8+AU8*AV8*AW8+AY8*AZ8*BA8)/(AM8*AN8+AQ8*AR8+AU8*AV8+AY8*AZ8) -> 0.1037457 | AL8: =(AM8*AN8*AP8+AQ8*AR8*AT8+AU8*AV8*AX8+AY8*AZ8*BB8)/(AM8*AN8+AQ8*AR8+AU8*AV8+AY8*AZ8) -> 0.8962543 | AM8: =L42/(L42+L50+L58+L66) -> 0.97716545 | AN8: =(J42+B42)/L42 -> 0.020046409 | AO8: =J42/(J42+B42) -> 0.11238475 | AP8: =B42/(B42+J42) -> 0.88761525 | AQ8: =L50/(L42+L50+L58+L66) -> 0.021733193 | AR8: =(B50+J50)/L50 -> 0.15131611 | AS8: =J50/(J50+B50) -> 0.053113958 | AT8: =B50/(B50+J50) -> 0.94688604 | AU8: =L58/(L42+L50+L58+L66) -> 0.0010505597 | AV8: =(B58+J58)/L58 -> 0.023812267 | AW8: =J58/(J58+B58) -> 0 | AX8: =B58/(B58+J58) -> 1 | AY8: =L66/(L42+L50+L58+L66) -> 5.079904e-05 | AZ8: =(B66+J66)/L66 -> 0.023828435 | BA8: =J66/(J66+B66) -> 0 | BB8: =B66/(B66+J66) -> 1
A9: 2019 | B9: 5962 | C9: 1141356 | D9: 30 | F9: 2014 | H9: 116202 | I9: 13 | L9: 1265577 | N9: 2018 | O9: =L7/L7 -> 1 | P9: =(J8+B8)/L8 -> 0.0014480287 | Q9: =J8/(J8+B8) -> 0 | R9: =B8/(B8+J8) -> 1 | S9: =L16/L16 -> 1 | T9: =(J17+B17)/L17 -> 0.01995484 | U9: =J17/(J17+B17) -> 2.451401e-05 | V9: =B17/(B17+J17) -> 0.99997549 | W9: =AA9+AE9 -> 1 | X9: =AB9*AA9+AF9*AE9 -> 0.50566745 | Y9: =(AA9*AB9*AC9+AE9*AF9*AG9)/(AA9*AB9+AE9*AF9) -> 0.010064986 | Z9: =(AA9*AB9*AD9+AE9*AF9*AH9)/(AA9*AB9+AE9*AF9) -> 0.93637077 | AA9: =L26/(L26+L34) -> 0.49390274 | AB9: =(J26+B26)/L26 -> 0.069317535 | AC9: =J26/(J26+B26) -> 0.012071463 | AD9: =B26/(B26+J26) -> 0.98792854 | AE9: =L34/(L26+L34) -> 0.50609726 | AF9: =(B34+J34)/L34 -> 0.93150342 | AG9: =J34/(J34+B43) -> 0.0099192725 | AH9: =B34/(B34+J34) -> 0.93262656 | AI9: =AM9+AQ9+AU9+AY9 -> 1 | AJ9: =(AM9*AN9+AQ9*AR9+AU9*AV9+AY9*AZ9) -> 0.041022499 | AK9: =(AM9*AN9*AO9+AQ9*AR9*AS9+AU9*AV9*AW9+AY9*AZ9*BA9)/(AM9*AN9+AQ9*AR9+AU9*AV9+AY9*AZ9) -> 0.20146539 | AL9: =(AM9*AN9*AP9+AQ9*AR9*AT9+AU9*AV9*AX9+AY9*AZ9*BB9)/(AM9*AN9+AQ9*AR9+AU9*AV9+AY9*AZ9) -> 0.79853461 | AM9: =L43/(L43+L51+L59+L67) -> 0.97463142 | AN9: =(J43+B43)/L43 -> 0.033992077 | AO9: =J43/(J43+B43) -> 0.2357749 | AP9: =B43/(B43+J43) -> 0.7642251 | AQ9: =L51/(L43+L51+L59+L67) -> 0.024276227 | AR9: =(B51+J51)/L51 -> 0.32499035 | AS9: =J51/(J51+B51) -> 0.057474983 | AT9: =B51/(B51+J51) -> 0.94252502 | AU9: =L59/(L43+L51+L59+L67) -> 0.0010431929 | AV9: =(B59+J59)/L59 -> 0.0025311116 | AW9: =J59/(J59+B59) -> 0 | AX9: =B59/(B59+J59) -> 1 | AY9: =L67/(L43+L51+L59+L67) -> 4.9156147e-05 | AZ9: =(B67+J67)/L67 -> 0.011638317 | BA9: =J67/(J67+B67) -> 0 | BB9: =B67/(B67+J67) -> 1
A10: 2020 | B10: 4111 | C10: 1530088 | D10: 44 | E10: 24 | F10: 146 | H10: 142829 | I10: 14 | J10: 11 | L10: 1677267 | N10: 2019 | O10: =L8/L8 -> 1 | P10: =(J9+B9)/L9 -> 0.0047108947 | Q10: =J9/(J9+B9) -> 0 | R10: =B9/(B9+J9) -> 1 | S10: =L17/L17 -> 1 | T10: =(J18+B18)/L18 -> 0.0083252472 | U10: =J18/(J18+B18) -> 0.0053751645 | V10: =B18/(B18+J18) -> 0.99462484 | W10: =AA10+AE10 -> 1 | X10: =AB10*AA10+AF10*AE10 -> 0.46352807 | Y10: =(AA10*AB10*AC10+AE10*AF10*AG10)/(AA10*AB10+AE10*AF10) -> 0.008355345 | Z10: =(AA10*AB10*AD10+AE10*AF10*AH10)/(AA10*AB10+AE10*AF10) -> 0.94384709 | AA10: =L27/(L27+L35) -> 0.53768312 | AB10: =(J27+B27)/L27 -> 0.046313608 | AC10: =J27/(J27+B27) -> 0.00097276265 | AD10: =B27/(B27+J27) -> 0.99902724 | AE10: =L35/(L27+L35) -> 0.46231688 | AF10: =(B35+J35)/L35 -> 0.94875624 | AG10: =J35/(J35+B44) -> 0.0087744751 | AH10: =B35/(B35+J35) -> 0.94071435 | AI10: =AM10+AQ10+AU10+AY10 -> 1 | AJ10: =(AM10*AN10+AQ10*AR10+AU10*AV10+AY10*AZ10) -> 0.042329962 | AK10: =(AM10*AN10*AO10+AQ10*AR10*AS10+AU10*AV10*AW10+AY10*AZ10*BA10)/(AM10*AN10+AQ10*AR10+AU10*AV10+AY10*AZ10) -> 0.21670607 | AL10: =(AM10*AN10*AP10+AQ10*AR10*AT10+AU10*AV10*AX10+AY10*AZ10*BB10)/(AM10*AN10+AQ10*AR10+AU10*AV10+AY10*AZ10) -> 0.78329393 | AM10: =L44/(L44+L52+L60+L68) -> 0.97004954 | AN10: =(J44+B44)/L44 -> 0.031539625 | AO10: =J44/(J44+B44) -> 0.27452631 | AP10: =B44/(B44+J44) -> 0.72547369 | AQ10: =L52/(L44+L52+L60+L68) -> 0.029315995 | AR10: =(B52+J52)/L52 -> 0.40004245 | AS10: =J52/(J52+B52) -> 0.065953446 | AT10: =B52/(B52+J52) -> 0.93404655 | AU10: =L60/(L44+L52+L60+L68) -> 0.00061090337 | AV10: =(B60+J60)/L60 -> 0.0086884878 | AW10: =J60/(J60+B60) -> 0.10344828 | AX10: =B60/(B60+J60) -> 0.89655172 | AY10: =L68/(L44+L52+L60+L68) -> 2.3564919e-05 | AZ10: =(B68+J68)/L68 -> 0.085436893 | BA10: =J68/(J68+B68) -> 0 | BB10: =B68/(B68+J68) -> 1
A11: 2021 | B11: 10982 | C11: 1447896 | D11: 4 | E11: 18 | F11: 825 | H11: 59599 | I11: 90 | J11: 25 | L11: 1519439 | N11: 2020 | O11: =L9/L9 -> 1 | P11: =(J10+B10)/L10 -> 0.0024575694 | Q11: =J10/(J10+B10) -> 0.0026686075 | R11: =B10/(B10+J10) -> 0.99733139 | S11: =L18/L18 -> 1 | T11: =(J19+B19)/L19 -> 0.0062312891 | U11: =J19/(J19+B19) -> 0.02029744 | V11: =B19/(B19+J19) -> 0.97970256 | W11: =AA11+AE11 -> 1 | X11: =AB11*AA11+AF11*AE11 -> 0.56706547 | Y11: =(AA11*AB11*AC11+AE11*AF11*AG11)/(AA11*AB11+AE11*AF11) -> 0.0064132174 | Z11: =(AA11*AB11*AD11+AE11*AF11*AH11)/(AA11*AB11+AE11*AF11) -> 0.91612121 | AA11: =L28/(L28+L36) -> 0.43130476 | AB11: =(J28+B28)/L28 -> 0.053753577 | AC11: =J28/(J28+B28) -> 0.00365705 | AD11: =B28/(B28+J28) -> 0.99634295 | AE11: =L36/(L28+L36) -> 0.56869524 | AF11: =(B36+J36)/L36 -> 0.95636689 | AG11: =J36/(J36+B45) -> 0.0065307053 | AH11: =B36/(B36+J36) -> 0.91270157 | AI11: =AM11+AQ11+AU11+AY11 -> 1 | AJ11: =(AM11*AN11+AQ11*AR11+AU11*AV11+AY11*AZ11) -> 0.056476382 | AK11: =(AM11*AN11*AO11+AQ11*AR11*AS11+AU11*AV11*AW11+AY11*AZ11*BA11)/(AM11*AN11+AQ11*AR11+AU11*AV11+AY11*AZ11) -> 0.18117913 | AL11: =(AM11*AN11*AP11+AQ11*AR11*AT11+AU11*AV11*AX11+AY11*AZ11*BB11)/(AM11*AN11+AQ11*AR11+AU11*AV11+AY11*AZ11) -> 0.81882087 | AM11: =L45/(L45+L53+L61+L69) -> 0.98018573 | AN11: =(J45+B45)/L45 -> 0.048318529 | AO11: =J45/(J45+B45) -> 0.20282583 | AP11: =B45/(B45+J45) -> 0.79717417 | AQ11: =L53/(L45+L53+L61+L69) -> 0.018810441 | AR11: =(B53+J53)/L53 -> 0.48163419 | AS11: =J53/(J53+B53) -> 0.069127831 | AT11: =B53/(B53+J53) -> 0.93087217 | AU11: =L61/(L45+L53+L61+L69) -> 0.00093114854 | AV11: =(B61+J61)/L61 -> 0.025331853 | AW11: =J61/(J61+B61) -> 0 | AX11: =B61/(B61+J61) -> 1 | AY11: =L69/(L45+L53+L61+L69) -> 7.2683655e-05 | AZ11: =(B69+J69)/L69 -> 0.43902439 | BA11: =J69/(J69+B69) -> 0 | BB11: =B69/(B69+J69) -> 1
A12: Freight LDV | B12: 217086 | C12: 7283616 | D12: 6562410 | E12: 12 | F12: 3 | H12: 176564 | J12: 1667 | L12: 14241358 | N12: 2021 | O12: =L10/L10 -> 1 | P12: =(J11+B11)/L11 -> 0.007244121 | Q12: =J11/(J11+B11) -> 0.0022712819 | R12: =B11/(B11+J11) -> 0.99772872 | S12: =L19/L19 -> 1 | T12: =(J20+B20)/L20 -> 0.016909439 | U12: =J20/(J20+B20) -> 0.031458412 | V12: =B20/(B20+J20) -> 0.96854159 | W12: =AA12+AE12 -> 1 | X12: =AB12*AA12+AF12*AE12 -> 0.43774312 | Y12: =(AA12*AB12*AC12+AE12*AF12*AG12)/(AA12*AB12+AE12*AF12) -> 0.00057617001 | Z12: =(AA12*AB12*AD12+AE12*AF12*AH12)/(AA12*AB12+AE12*AF12) -> 0.9740606 | AA12: =L29/(L29+L37) -> 0.59399659 | AB12: =(J29+B29)/L29 -> 0.076900288 | AC12: =J29/(J29+B29) -> 0.000405515 | AD12: =B29/(B29+J29) -> 0.99959448 | AE12: =L37/(L29+L37) -> 0.40600341 | AF12: =(B37+J37)/L37 -> 0.96566827 | AG12: =J37/(J37+B46) -> 0.00059605261 | AH12: =B37/(B37+J37) -> 0.9710857 | AI12: =AM12+AQ12+AU12+AY12 -> 1 | AJ12: =(AM12*AN12+AQ12*AR12+AU12*AV12+AY12*AZ12) -> 0.13221782 | AK12: =(AM12*AN12*AO12+AQ12*AR12*AS12+AU12*AV12*AW12+AY12*AZ12*BA12)/(AM12*AN12+AQ12*AR12+AU12*AV12+AY12*AZ12) -> 0.14652144 | AL12: =(AM12*AN12*AP12+AQ12*AR12*AT12+AU12*AV12*AX12+AY12*AZ12*BB12)/(AM12*AN12+AQ12*AR12+AU12*AV12+AY12*AZ12) -> 0.85347856 | AM12: =L46/(L46+L54+L62+L70) -> 0.97427476 | AN12: =(J46+B46)/L46 -> 0.11784348 | AO12: =J46/(J46+B46) -> 0.1640434 | AP12: =B46/(B46+J46) -> 0.8359566 | AQ12: =L54/(L46+L54+L62+L70) -> 0.02498021 | AR12: =(B54+J54)/L54 -> 0.69399794 | AS12: =J54/(J54+B54) -> 0.031054845 | AT12: =B54/(B54+J54) -> 0.96894515 | AU12: =L62/(L46+L54+L62+L70) -> 0.00073488536 | AV12: =(B62+J62)/L62 -> 0.090238004 | AW12: =J62/(J62+B62) -> 0.0035260931 | AX12: =B62/(B62+J62) -> 0.99647391 | AY12: =L70/(L46+L54+L62+L70) -> 1.0148283e-05 | AZ12: =(B70+J70)/L70 -> 0.33179724 | BA12: =J70/(J70+B70) -> 0 | BB12: =B70/(B70+J70) -> 1
A13: 轻型货车 | B13: 217086 | C13: 7283616 | D13: 6562410 | E13: 12 | F13: 3 | H13: 176564 | J13: 1667 | L13: 14241358 | N13: 2025 | O13: 1 | P13: =HLOOKUP(O$4,$O$24:$U$33,ROW(P13)-10,FALSE) -> 0.026420039 | Q13: =Q5 -> 0.022647572 | R13: =R5 -> 0.97735243 | S13: =100% -> 1 | T13: =HLOOKUP(S$4,$O$24:$U$33,ROW(T13)-10,FALSE) -> 0.089203147 | U13: =U5 -> 0.0076204669 | V13: =V5 -> 0.99237953 | W13: =AA13+AE13 -> 1 | X13: =AB13*AA13+AF13*AE13 -> 0.34046608 | Y13: =(AA13*AB13*AC13+AE13*AF13*AG13)/(AA13*AB13+AE13*AF13) -> 0.013194562 | Z13: =(AA13*AB13*AD13+AE13*AF13*AH13)/(AA13*AB13+AE13*AF13) -> 0.92179751 | AA13: =S36/(R36+S36) -> 0.75096772 | AB13: =HLOOKUP(AA$4,$O$24:$U$33,ROW(AB13)-10,FALSE) -> 0.1516 | AC13: =AC5 -> 0.018581344 | AD13: =AD5 -> 0.98141866 | AE13: =R36/(R36+S36) -> 0.24903228 | AF13: =HLOOKUP(AE$4,$O$24:$U$33,ROW(AF13)-10,FALSE) -> 0.91 | AG13: =AG5 -> 0.010488406 | AH13: =AH5 -> 0.89184566 | AI13: =AM13+AQ13+AU13+AY13 -> 1 | AJ13: =(AM13*AN13+AQ13*AR13+AU13*AV13+AY13*AZ13) -> 0.10622057 | AK13: =(AM13*AN13*AO13+AQ13*AR13*AS13+AU13*AV13*AW13+AY13*AZ13*BA13)/(AM13*AN13+AQ13*AR13+AU13*AV13+AY13*AZ13) -> 0.17368893 | AL13: =(AM13*AN13*AP13+AQ13*AR13*AT13+AU13*AV13*AX13+AY13*AZ13*BB13)/(AM13*AN13+AQ13*AR13+AU13*AV13+AY13*AZ13) -> 0.82631107 | AM13: =O36/(O36+P36+R36+S36) -> 0.98776333 | AN13: =HLOOKUP(AM$4,$O$24:$U$33,ROW(AN13)-10,FALSE) -> 0.1 | AO13: =AO5 -> 0.18385826 | AP13: =AP5 -> 0.81614174 | AQ13: =P36/(O36+P36+R36+S36) -> 0.0057557062 | AR13: =HLOOKUP(AQ$4,$O$24:$U$33,ROW(AR13)-10,FALSE) -> 0.91 | AS13: =AS5 -> 0.054196435 | AT13: =AT5 -> 0.94580357 | AU13: =S36/(O36+P36+R36+S36) -> 0.0048669938 | AV13: =HLOOKUP(AU$4,$O$24:$U$33,ROW(AV13)-10,FALSE) -> 0.1516 | AW13: =AW5 -> 0.0062730627 | AX13: =AX5 -> 0.99372694 | AY13: =R36/(O36+P36+R36+S36) -> 0.0016139689 | AZ13: =HLOOKUP(AY$4,$O$24:$U$33,ROW(AZ13)-10,FALSE) -> 0.91 | BA13: =BA5 -> 0 | BB13: =BB5 -> 1
A14: 2015 | B14: 24785 | C14: 763006 | D14: 706406 | E14: 4 | H14: 36040 | L14: 1530241 | N14: 2030 | O14: 1 | P14: =HLOOKUP(O$4,$O$24:$U$33,ROW(P14)-10,FALSE) -> 0.059427603 | Q14: =Q13 -> 0.022647572 | R14: =R13 -> 0.97735243 | S14: =100% -> 1 | T14: =HLOOKUP(S$4,$O$24:$U$33,ROW(T14)-10,FALSE) -> 0.18086855 | U14: =U13 -> 0.0076204669 | V14: =V13 -> 0.99237953 | W14: =AA14+AE14 -> 1 | X14: =AB14*AA14+AF14*AE14 -> 0.52305415 | Y14: =(AA14*AB14*AC14+AE14*AF14*AG14)/(AA14*AB14+AE14*AF14) -> 0.013646501 | Z14: =(AA14*AB14*AD14+AE14*AF14*AH14)/(AA14*AB14+AE14*AF14) -> 0.9267996 | AA14: =S37/(R37+S37) -> 0.67119227 | AB14: =HLOOKUP(AA$4,$O$24:$U$33,ROW(AB14)-10,FALSE) -> 0.30410161 | AC14: =AC13 -> 0.018581344 | AD14: =AD13 -> 0.98141866 | AE14: =R37/(R37+S37) -> 0.32880773 | AF14: =HLOOKUP(AE$4,$O$24:$U$33,ROW(AF14)-10,FALSE) -> 0.97 | AG14: =AG13 -> 0.010488406 | AH14: =AH13 -> 0.89184566 | AI14: =AM14+AQ14+AU14+AY14 -> 1 | AJ14: =(AM14*AN14+AQ14*AR14+AU14*AV14+AY14*AZ14) -> 0.15655173 | AK14: =(AM14*AN14*AO14+AQ14*AR14*AS14+AU14*AV14*AW14+AY14*AZ14*BA14)/(AM14*AN14+AQ14*AR14+AU14*AV14+AY14*AZ14) -> 0.17581857 | AL14: =(AM14*AN14*AP14+AQ14*AR14*AT14+AU14*AV14*AX14+AY14*AZ14*BB14)/(AM14*AN14+AQ14*AR14+AU14*AV14+AY14*AZ14) -> 0.82418143 | AM14: =O37/(O37+P37+R37+S37) -> 0.98833879 | AN14: =HLOOKUP(AM$4,$O$24:$U$33,ROW(AN14)-10,FALSE) -> 0.15 | AO14: =AO13 -> 0.18385826 | AP14: =AP13 -> 0.81614174 | AQ14: =P37/(O37+P37+R37+S37) -> 0.0049255857 | AR14: =HLOOKUP(AQ$4,$O$24:$U$33,ROW(AR14)-10,FALSE) -> 0.97 | AS14: =AS13 -> 0.054196435 | AT14: =AT13 -> 0.94580357 | AU14: =S37/(O37+P37+R37+S37) -> 0.0045208998 | AV14: =HLOOKUP(AU$4,$O$24:$U$33,ROW(AV14)-10,FALSE) -> 0.30410161 | AW14: =AW13 -> 0.0062730627 | AX14: =AX13 -> 0.99372694 | AY14: =R37/(O37+P37+R37+S37) -> 0.0022147258 | AZ14: =HLOOKUP(AY$4,$O$24:$U$33,ROW(AZ14)-10,FALSE) -> 0.97 | BA14: =BA13 -> 0 | BB14: =BB13 -> 1
A15: 2016 | B15: 17755 | C15: 876597 | D15: 756679 | H15: 16696 | L15: 1667727 | N15: 2035 | O15: 1 | P15: =HLOOKUP(O$4,$O$24:$U$33,ROW(P15)-10,FALSE) -> 0.10442111 | Q15: =Q14 -> 0.022647572 | R15: =R14 -> 0.97735243 | S15: =100% -> 1 | T15: =HLOOKUP(S$4,$O$24:$U$33,ROW(T15)-10,FALSE) -> 0.29922705 | U15: =U14 -> 0.0076204669 | V15: =V14 -> 0.99237953 | W15: =AA15+AE15 -> 1 | X15: =AB15*AA15+AF15*AE15 -> 0.60054664 | Y15: =(AA15*AB15*AC15+AE15*AF15*AG15)/(AA15*AB15+AE15*AF15) -> 0.015441441 | Z15: =(AA15*AB15*AD15+AE15*AF15*AH15)/(AA15*AB15+AE15*AF15) -> 0.94666607 | AA15: =S38/(R38+S38) -> 0.76699955 | AB15: =HLOOKUP(AA$4,$O$24:$U$33,ROW(AB15)-10,FALSE) -> 0.4792 | AC15: =AC14 -> 0.018581344 | AD15: =AD14 -> 0.98141866 | AE15: =R38/(R38+S38) -> 0.23300045 | AF15: =HLOOKUP(AE$4,$O$24:$U$33,ROW(AF15)-10,FALSE) -> 1 | AG15: =AG14 -> 0.010488406 | AH15: =AH14 -> 0.89184566 | AI15: =AM15+AQ15+AU15+AY15 -> 1 | AJ15: =(AM15*AN15+AQ15*AR15+AU15*AV15+AY15*AZ15) -> 0.20655035 | AK15: =(AM15*AN15*AO15+AQ15*AR15*AS15+AU15*AV15*AW15+AY15*AZ15*BA15)/(AM15*AN15+AQ15*AR15+AU15*AV15+AY15*AZ15) -> 0.17727154 | AL15: =(AM15*AN15*AP15+AQ15*AR15*AT15+AU15*AV15*AX15+AY15*AZ15*BB15)/(AM15*AN15+AQ15*AR15+AU15*AV15+AY15*AZ15) -> 0.82272846 | AM15: =O38/(O38+P38+R38+S38) -> 0.98835738 | AN15: =HLOOKUP(AM$4,$O$24:$U$33,ROW(AN15)-10,FALSE) -> 0.2 | AO15: =AO14 -> 0.18385826 | AP15: =AP14 -> 0.81614174 | AQ15: =P38/(O38+P38+R38+S38) -> 0.0047238013 | AR15: =HLOOKUP(AQ$4,$O$24:$U$33,ROW(AR15)-10,FALSE) -> 1 | AS15: =AS14 -> 0.054196435 | AT15: =AT14 -> 0.94580357 | AU15: =S38/(O38+P38+R38+S38) -> 0.0053067339 | AV15: =HLOOKUP(AU$4,$O$24:$U$33,ROW(AV15)-10,FALSE) -> 0.4792 | AW15: =AW14 -> 0.0062730627 | AX15: =AX14 -> 0.99372694 | AY15: =R38/(O38+P38+R38+S38) -> 0.0016120889 | AZ15: =HLOOKUP(AY$4,$O$24:$U$33,ROW(AZ15)-10,FALSE) -> 1 | BA15: =BA14 -> 0 | BB15: =BB14 -> 1
A16: 2017 | B16: 61786 | C16: 1024613 | D16: 838364 | H16: 20278 | L16: 1945041 | N16: 2040 | O16: 1 | P16: =HLOOKUP(O$4,$O$24:$U$33,ROW(P16)-10,FALSE) -> 0.17782076 | Q16: =Q15 -> 0.022647572 | R16: =R15 -> 0.97735243 | S16: =100% -> 1 | T16: =HLOOKUP(S$4,$O$24:$U$33,ROW(T16)-10,FALSE) -> 0.45018795 | U16: =U15 -> 0.0076204669 | V16: =V15 -> 0.99237953 | W16: =AA16+AE16 -> 1 | X16: =AB16*AA16+AF16*AE16 -> 0.75772861 | Y16: =(AA16*AB16*AC16+AE16*AF16*AG16)/(AA16*AB16+AE16*AF16) -> 0.015066662 | Z16: =(AA16*AB16*AD16+AE16*AF16*AH16)/(AA16*AB16+AE16*AF16) -> 0.942518 | AA16: =S39/(R39+S39) -> 0.67092604 | AB16: =HLOOKUP(AA$4,$O$24:$U$33,ROW(AB16)-10,FALSE) -> 0.6389 | AC16: =AC15 -> 0.018581344 | AD16: =AD15 -> 0.98141866 | AE16: =R39/(R39+S39) -> 0.32907396 | AF16: =HLOOKUP(AE$4,$O$24:$U$33,ROW(AF16)-10,FALSE) -> 1 | AG16: =AG15 -> 0.010488406 | AH16: =AH15 -> 0.89184566 | AI16: =AM16+AQ16+AU16+AY16 -> 1 | AJ16: =(AM16*AN16+AQ16*AR16+AU16*AV16+AY16*AZ16) -> 0.28653448 | AK16: =(AM16*AN16*AO16+AQ16*AR16*AS16+AU16*AV16*AW16+AY16*AZ16*BA16)/(AM16*AN16+AQ16*AR16+AU16*AV16+AY16*AZ16) -> 0.17855992 | AL16: =(AM16*AN16*AP16+AQ16*AR16*AT16+AU16*AV16*AX16+AY16*AZ16*BB16)/(AM16*AN16+AQ16*AR16+AU16*AV16+AY16*AZ16) -> 0.82144008 | AM16: =O39/(O39+P39+R39+S39) -> 0.98865382 | AN16: =HLOOKUP(AM$4,$O$24:$U$33,ROW(AN16)-10,FALSE) -> 0.28 | AO16: =AO15 -> 0.18385826 | AP16: =AP15 -> 0.81614174 | AQ16: =P39/(O39+P39+R39+S39) -> 0.0045984979 | AR16: =HLOOKUP(AQ$4,$O$24:$U$33,ROW(AR16)-10,FALSE) -> 1 | AS16: =AS15 -> 0.054196435 | AT16: =AT15 -> 0.94580357 | AU16: =S39/(O39+P39+R39+S39) -> 0.0045271937 | AV16: =HLOOKUP(AU$4,$O$24:$U$33,ROW(AV16)-10,FALSE) -> 0.6389 | AW16: =AW15 -> 0.0062730627 | AX16: =AX15 -> 0.99372694 | AY16: =R39/(O39+P39+R39+S39) -> 0.0022204856 | AZ16: =HLOOKUP(AY$4,$O$24:$U$33,ROW(AZ16)-10,FALSE) -> 1 | BA16: =BA15 -> 0 | BB16: =BB15 -> 1
A17: 2018 | B17: 40792 | C17: 1036146 | D17: 940137 | H17: 27190 | J17: 1 | L17: 2044266 | N17: 2045 | O17: 1 | P17: =HLOOKUP(O$4,$O$24:$U$33,ROW(P17)-10,FALSE) -> 0.27339725 | Q17: =Q16 -> 0.022647572 | R17: =R16 -> 0.97735243 | S17: =100% -> 1 | T17: =HLOOKUP(S$4,$O$24:$U$33,ROW(T17)-10,FALSE) -> 0.61094922 | U17: =U16 -> 0.0076204669 | V17: =V16 -> 0.99237953 | W17: =AA17+AE17 -> 1 | X17: =AB17*AA17+AF17*AE17 -> 0.85030307 | Y17: =(AA17*AB17*AC17+AE17*AF17*AG17)/(AA17*AB17+AE17*AF17) -> 0.016248565 | Z17: =(AA17*AB17*AD17+AE17*AF17*AH17)/(AA17*AB17+AE17*AF17) -> 0.95559936 | AA17: =S40/(R40+S40) -> 0.75490129 | AB17: =HLOOKUP(AA$4,$O$24:$U$33,ROW(AB17)-10,FALSE) -> 0.8017 | AC17: =AC16 -> 0.018581344 | AD17: =AD16 -> 0.98141866 | AE17: =R40/(R40+S40) -> 0.24509871 | AF17: =HLOOKUP(AE$4,$O$24:$U$33,ROW(AF17)-10,FALSE) -> 1 | AG17: =AG16 -> 0.010488406 | AH17: =AH16 -> 0.89184566 | AI17: =AM17+AQ17+AU17+AY17 -> 1 | AJ17: =(AM17*AN17+AQ17*AR17+AU17*AV17+AY17*AZ17) -> 0.40680742 | AK17: =(AM17*AN17*AO17+AQ17*AR17*AS17+AU17*AV17*AW17+AY17*AZ17*BA17)/(AM17*AN17+AQ17*AR17+AU17*AV17+AY17*AZ17) -> 0.17928344 | AL17: =(AM17*AN17*AP17+AQ17*AR17*AT17+AU17*AV17*AX17+AY17*AZ17*BB17)/(AM17*AN17+AQ17*AR17+AU17*AV17+AY17*AZ17) -> 0.82071656 | AM17: =O40/(O40+P40+R40+S40) -> 0.98689258 | AN17: =HLOOKUP(AM$4,$O$24:$U$33,ROW(AN17)-10,FALSE) -> 0.4 | AO17: =AO16 -> 0.18385826 | AP17: =AP16 -> 0.81614174 | AQ17: =P40/(O40+P40+R40+S40) -> 0.0060462861 | AR17: =HLOOKUP(AQ$4,$O$24:$U$33,ROW(AR17)-10,FALSE) -> 1 | AS17: =AS16 -> 0.054196435 | AT17: =AT16 -> 0.94580357 | AU17: =S40/(O40+P40+R40+S40) -> 0.0053304578 | AV17: =HLOOKUP(AU$4,$O$24:$U$33,ROW(AV17)-10,FALSE) -> 0.8017 | AW17: =AW16 -> 0.0062730627 | AX17: =AX16 -> 0.99372694 | AY17: =R40/(O40+P40+R40+S40) -> 0.0017306743 | AZ17: =HLOOKUP(AY$4,$O$24:$U$33,ROW(AZ17)-10,FALSE) -> 1 | BA17: =BA16 -> 0 | BB17: =BB16 -> 1
A18: 2019 | B18: 18134 | C18: 1052509 | D18: 1086406 | H18: 32818 | J18: 98 | L18: 2189965 | N18: 2050 | O18: 1 | P18: =HLOOKUP(O$4,$O$24:$U$33,ROW(P18)-10,FALSE) -> 0.38 | Q18: =Q17 -> 0.022647572 | R18: =R17 -> 0.97735243 | S18: =100% -> 1 | T18: =HLOOKUP(S$4,$O$24:$U$33,ROW(T18)-10,FALSE) -> 0.79601574 | U18: =U17 -> 0.0076204669 | V18: =V17 -> 0.99237953 | W18: =AA18+AE18 -> 1 | X18: =AB18*AA18+AF18*AE18 -> 1 | Y18: =(AA18*AB18*AC18+AE18*AF18*AG18)/(AA18*AB18+AE18*AF18) -> 0.016021876 | Z18: =(AA18*AB18*AD18+AE18*AF18*AH18)/(AA18*AB18+AE18*AF18) -> 0.95309035 | AA18: =S41/(R41+S41) -> 0.68374053 | AB18: =HLOOKUP(AA$4,$O$24:$U$33,ROW(AB18)-10,FALSE) -> 1 | AC18: =AC17 -> 0.018581344 | AD18: =AD17 -> 0.98141866 | AE18: =R41/(R41+S41) -> 0.31625947 | AF18: =HLOOKUP(AE$4,$O$24:$U$33,ROW(AF18)-10,FALSE) -> 1 | AG18: =AG17 -> 0.010488406 | AH18: =AH17 -> 0.89184566 | AI18: =AM18+AQ18+AU18+AY18 -> 1 | AJ18: =(AM18*AN18+AQ18*AR18+AU18*AV18+AY18*AZ18) -> 0.50634653 | AK18: =(AM18*AN18*AO18+AQ18*AR18*AS18+AU18*AV18*AW18+AY18*AZ18*BA18)/(AM18*AN18+AQ18*AR18+AU18*AV18+AY18*AZ18) -> 0.17986652 | AL18: =(AM18*AN18*AP18+AQ18*AR18*AT18+AU18*AV18*AX18+AY18*AZ18*BB18)/(AM18*AN18+AQ18*AR18+AU18*AV18+AY18*AZ18) -> 0.82013348 | AM18: =O41/(O41+P41+R41+S41) -> 0.98730694 | AN18: =HLOOKUP(AM$4,$O$24:$U$33,ROW(AN18)-10,FALSE) -> 0.5 | AO18: =AO17 -> 0.18385826 | AP18: =AP17 -> 0.81614174 | AQ18: =P41/(O41+P41+R41+S41) -> 0.0051710904 | AR18: =HLOOKUP(AQ$4,$O$24:$U$33,ROW(AR18)-10,FALSE) -> 1 | AS18: =AS17 -> 0.054196435 | AT18: =AT17 -> 0.94580357 | AU18: =S41/(O41+P41+R41+S41) -> 0.0051430736 | AV18: =HLOOKUP(AU$4,$O$24:$U$33,ROW(AV18)-10,FALSE) -> 1 | AW18: =AW17 -> 0.0062730627 | AX18: =AX17 -> 0.99372694 | AY18: =R41/(O41+P41+R41+S41) -> 0.0023788933 | AZ18: =HLOOKUP(AY$4,$O$24:$U$33,ROW(AZ18)-10,FALSE) -> 1 | BA18: =BA17 -> 0 | BB18: =BB17 -> 1
A19: 2020 | B19: 15349 | C19: 1319180 | D19: 1157774 | H19: 21626 | J19: 318 | L19: 2514247 | N19: 2055 | O19: 1 | P19: =HLOOKUP(O$4,$O$24:$U$33,ROW(P19)-10,FALSE) -> 0.48312408 | Q19: =Q18 -> 0.022647572 | R19: =R18 -> 0.97735243 | S19: =100% -> 1 | T19: =HLOOKUP(S$4,$O$24:$U$33,ROW(T19)-10,FALSE) -> 0.9 | U19: =U18 -> 0.0076204669 | V19: =V18 -> 0.99237953 | W19: =AA19+AE19 -> 1 | X19: =AB19*AA19+AF19*AE19 -> 1 | Y19: =(AA19*AB19*AC19+AE19*AF19*AG19)/(AA19*AB19+AE19*AF19) -> 0.016507815 | Z19: =(AA19*AB19*AD19+AE19*AF19*AH19)/(AA19*AB19+AE19*AF19) -> 0.95846874 | AA19: =S42/(R42+S42) -> 0.74378536 | AB19: =HLOOKUP(AA$4,$O$24:$U$33,ROW(AB19)-10,FALSE) -> 1 | AC19: =AC18 -> 0.018581344 | AD19: =AD18 -> 0.98141866 | AE19: =R42/(R42+S42) -> 0.25621464 | AF19: =HLOOKUP(AE$4,$O$24:$U$33,ROW(AF19)-10,FALSE) -> 1 | AG19: =AG18 -> 0.010488406 | AH19: =AH18 -> 0.89184566 | AI19: =AM19+AQ19+AU19+AY19 -> 1 | AJ19: =(AM19*AN19+AQ19*AR19+AU19*AV19+AY19*AZ19) -> 0.65423161 | AK19: =(AM19*AN19*AO19+AQ19*AR19*AS19+AU19*AV19*AW19+AY19*AZ19*BA19)/(AM19*AN19+AQ19*AR19+AU19*AV19+AY19*AZ19) -> 0.18092211 | AL19: =(AM19*AN19*AP19+AQ19*AR19*AT19+AU19*AV19*AX19+AY19*AZ19*BB19)/(AM19*AN19+AQ19*AR19+AU19*AV19+AY19*AZ19) -> 0.81907789 | AM19: =O42/(O42+P42+R42+S42) -> 0.98790968 | AN19: =HLOOKUP(AM$4,$O$24:$U$33,ROW(AN19)-10,FALSE) -> 0.65 | AO19: =AO18 -> 0.18385826 | AP19: =AP18 -> 0.81614174 | AQ19: =P42/(O42+P42+R42+S42) -> 0.0049579078 | AR19: =HLOOKUP(AQ$4,$O$24:$U$33,ROW(AR19)-10,FALSE) -> 1 | AS19: =AS18 -> 0.054196435 | AT19: =AT18 -> 0.94580357 | AU19: =S42/(O42+P42+R42+S42) -> 0.0053049805 | AV19: =HLOOKUP(AU$4,$O$24:$U$33,ROW(AV19)-10,FALSE) -> 1 | AW19: =AW18 -> 0.0062730627 | AX19: =AX18 -> 0.99372694 | AY19: =R42/(O42+P42+R42+S42) -> 0.0018274273 | AZ19: =HLOOKUP(AY$4,$O$24:$U$33,ROW(AZ19)-10,FALSE) -> 1 | BA19: =BA18 -> 0 | BB19: =BB18 -> 1
A20: 2021 | B20: 38485 | C20: 1211565 | D20: 1076644 | E20: 8 | F20: 3 | H20: 21916 | J20: 1250 | L20: 2349871 | N20: 2060 | O20: 1 | P20: =HLOOKUP(O$4,$O$24:$U$33,ROW(P20)-10,FALSE) -> 0.58094619 | Q20: =Q19 -> 0.022647572 | R20: =R19 -> 0.97735243 | S20: =100% -> 1 | T20: =HLOOKUP(S$4,$O$24:$U$33,ROW(T20)-10,FALSE) -> 1 | U20: =U19 -> 0.0076204669 | V20: =V19 -> 0.99237953 | W20: =AA20+AE20 -> 1 | X20: =AB20*AA20+AF20*AE20 -> 1 | Y20: =(AA20*AB20*AC20+AE20*AF20*AG20)/(AA20*AB20+AE20*AF20) -> 0.016051969 | Z20: =(AA20*AB20*AD20+AE20*AF20*AH20)/(AA20*AB20+AE20*AF20) -> 0.95342343 | AA20: =S43/(R43+S43) -> 0.68745907 | AB20: =HLOOKUP(AA$4,$O$24:$U$33,ROW(AB20)-10,FALSE) -> 1 | AC20: =AC19 -> 0.018581344 | AD20: =AD19 -> 0.98141866 | AE20: =R43/(R43+S43) -> 0.31254093 | AF20: =HLOOKUP(AE$4,$O$24:$U$33,ROW(AF20)-10,FALSE) -> 1 | AG20: =AG19 -> 0.010488406 | AH20: =AH19 -> 0.89184566 | AI20: =AM20+AQ20+AU20+AY20 -> 1 | AJ20: =(AM20*AN20+AQ20*AR20+AU20*AV20+AY20*AZ20) -> 0.80289881 | AK20: =(AM20*AN20*AO20+AQ20*AR20*AS20+AU20*AV20*AW20+AY20*AZ20*BA20)/(AM20*AN20+AQ20*AR20+AU20*AV20+AY20*AZ20) -> 0.18101569 | AL20: =(AM20*AN20*AP20+AQ20*AR20*AT20+AU20*AV20*AX20+AY20*AZ20*BB20)/(AM20*AN20+AQ20*AR20+AU20*AV20+AY20*AZ20) -> 0.81898431 | AM20: =O43/(O43+P43+R43+S43) -> 0.98550596 | AN20: =HLOOKUP(AM$4,$O$24:$U$33,ROW(AN20)-10,FALSE) -> 0.8 | AO20: =AO19 -> 0.18385826 | AP20: =AP19 -> 0.81614174 | AQ20: =P43/(O43+P43+R43+S43) -> 0.0064158482 | AR20: =HLOOKUP(AQ$4,$O$24:$U$33,ROW(AR20)-10,FALSE) -> 1 | AS20: =AS19 -> 0.054196435 | AT20: =AT19 -> 0.94580357 | AU20: =S43/(O43+P43+R43+S43) -> 0.0055534245 | AV20: =HLOOKUP(AU$4,$O$24:$U$33,ROW(AV20)-10,FALSE) -> 1 | AW20: =AW19 -> 0.0062730627 | AX20: =AX19 -> 0.99372694 | AY20: =R43/(O43+P43+R43+S43) -> 0.0025247648 | AZ20: =HLOOKUP(AY$4,$O$24:$U$33,ROW(AZ20)-10,FALSE) -> 1 | BA20: =BA19 -> 0 | BB20: =BB19 -> 1
A21: Passenger HDV | B21: 512915 | C21: 547268 | D21: 102586 | E21: 24163 | F21: 4155 | H21: 53334 | I21: 5 | J21: 51218 | K21: 38 | L21: 1295682
A22: 道路客车 | B22: 107325 | C22: 488708 | D22: 98628 | E22: 957 | F22: 936 | H22: 12740 | I22: 5 | J22: 2032 | K22: 38 | L22: 711369
A23: 2015 | B23: 41247 | C23: 87105 | D23: 14744 | E23: 414 | H23: 4888 | J23: 606 | K23: 38 | L23: 149042
A24: 2016 | B24: 30079 | C24: 104312 | D24: 19137 | E24: 528 | F24: 5 | H24: 2808 | J24: 870 | L24: 157739 | N24: Electric Ratio | O24: 乘用车 | P24: 出租车 | Q24: 轻型货车 | R24: 公交车 | S24: 道路客车 | T24: 专用重型货车 | U24: 中重型货车
A25: 2017 | B25: 18371 | C25: 78701 | D25: 16714 | E25: 4 | F25: 112 | H25: 1885 | J25: 466 | L25: 116253 | N25: 2020 | O25: 0.075 | P25: 0.8 | Q25: 0.0088393183 | R25: 0.8 | S25: 0.06 | T25: 0.026466098 | U25: 0.0013456519
