Workbook

Sheet Summary
Q20: Extraction of Petroleum and Natural Gas | S20: =VLOOKUP(Q20,'图11-工业强度'!$B$195:$C$219,2,FALSE) -> 石油、天然气开采
R21: Energy CONS for | S21: 能源消费及碳排放
R22: =R21&Q20 -> Energy CONS for Extraction of Petroleum and Natural Gas | S22: =S20&S21 -> 石油、天然气开采能源消费及碳排放
Q38: freight
Q39: LDVs
Q56: LDVs

Sheet 汇总
Q20: Rubber and Plastics Products | S20: =VLOOKUP(Q20,'图11-工业强度'!$B$195:$C$219,2,FALSE) -> 橡胶和塑料制品业
R21: Energy CONS for | S21: 能源消费及碳排放
R22: =R21&Q20 -> Energy CONS for Rubber and Plastics Products | S22: =S20&S21 -> 橡胶和塑料制品业能源消费及碳排放
Q38: passenger
Q39: LDVs
Q56: LDVs

Sheet 图1-二氧化碳排放
C1: conversion | D1: gram | E1: 亿吨 | F1: 100 mt | G1: Scope 1 CO2 Emission by Sector
C2: 单位转换 | D2: 1 | E2: =10^-14 -> 1e-14 | G2: 分部门二氧化碳直接排放（范围1）
B3: 2023 | I3: 2030 | N3: 2035 | S3: 2040 | X3: 2045 | AC3: 2050 | AH3: 2055 | AM3: 2060
A4: Transportation | B4: =二氧化碳排放!B2*$E$2 -> 15.6359 | C4: =二氧化碳排放!C2*$E$2 -> 15.5767 | D4: =二氧化碳排放!D2*$E$2 -> 15.5182 | E4: =二氧化碳排放!E2*$E$2 -> 15.4621 | F4: =二氧化碳排放!F2*$E$2 -> 15.3937 | G4: =二氧化碳排放!G2*$E$2 -> 15.3141 | H4: =二氧化碳排放!H2*$E$2 -> 15.2196 | I4: =二氧化碳排放!I2*$E$2 -> 15.1044 | ... AM4: =二氧化碳排放!AM2*$E$2 -> 11.3117
A5: Electricity | B5: =二氧化碳排放!B3*$E$2 -> 41.2478 | C5: =二氧化碳排放!C3*$E$2 -> 41.1613 | D5: =二氧化碳排放!D3*$E$2 -> 43.7224 | E5: =二氧化碳排放!E3*$E$2 -> 45.8054 | F5: =二氧化碳排放!F3*$E$2 -> 47.7911 | G5: =二氧化碳排放!G3*$E$2 -> 49.5862 | H5: =二氧化碳排放!H3*$E$2 -> 51.1375 | I5: =二氧化碳排放!I3*$E$2 -> 52.8159 | ... AM5: =二氧化碳排放!AM3*$E$2 -> 13.5208
A6: Residential bldg | B6: =二氧化碳排放!B4*$E$2 -> 3.2022 | C6: =二氧化碳排放!C4*$E$2 -> 3.20086 | D6: =二氧化碳排放!D4*$E$2 -> 3.19575 | E6: =二氧化碳排放!E4*$E$2 -> 3.18393 | F6: =二氧化碳排放!F4*$E$2 -> 3.17364 | G6: =二氧化碳排放!G4*$E$2 -> 3.16948 | H6: =二氧化碳排放!H4*$E$2 -> 3.16077 | I6: =二氧化碳排放!I4*$E$2 -> 3.15547 | ... AM6: =二氧化碳排放!AM4*$E$2 -> 2.63523
A7: Commercial bldg | B7: =二氧化碳排放!B5*$E$2 -> 1.28319 | C7: =二氧化碳排放!C5*$E$2 -> 1.3106 | D7: =二氧化碳排放!D5*$E$2 -> 1.33418 | E7: =二氧化碳排放!E5*$E$2 -> 1.35142 | F7: =二氧化碳排放!F5*$E$2 -> 1.36808 | G7: =二氧化碳排放!G5*$E$2 -> 1.3861 | H7: =二氧化碳排放!H5*$E$2 -> 1.40341 | I7: =二氧化碳排放!I5*$E$2 -> 1.41925 | ... AM7: =二氧化碳排放!AM5*$E$2 -> 1.58751
A8: Industrial Fuel | B8: =二氧化碳排放!B6*$E$2-B9 -> 28.11798 | C8: =二氧化碳排放!C6*$E$2-C9 -> 28.197062 | D8: =二氧化碳排放!D6*$E$2-D9 -> 29.450875 | E8: =二氧化碳排放!E6*$E$2-E9 -> 29.794727 | F8: =二氧化碳排放!F6*$E$2-F9 -> 30.151667 | G8: =二氧化碳排放!G6*$E$2-G9 -> 30.499537 | H8: =二氧化碳排放!H6*$E$2-H9 -> 30.798146 | I8: =二氧化碳排放!I6*$E$2-I9 -> 31.168946 | ... AM8: =二氧化碳排放!AM6*$E$2-AM9 -> 22.672217
A9: Industrial Process | B9: =SUM(二氧化碳排放!B32:B56)*$E2 -> 14.51112 | C9: =SUM(二氧化碳排放!C32:C56)*$E2 -> 14.450738 | D9: =SUM(二氧化碳排放!D32:D56)*$E2 -> 14.566725 | E9: =SUM(二氧化碳排放!E32:E56)*$E2 -> 14.522373 | F9: =SUM(二氧化碳排放!F32:F56)*$E2 -> 14.436133 | G9: =SUM(二氧化碳排放!G32:G56)*$E2 -> 14.294263 | H9: =SUM(二氧化碳排放!H32:H56)*$E2 -> 14.158554 | I9: =SUM(二氧化碳排放!I32:I56)*$E2 -> 14.024754 | ... AM9: =SUM(二氧化碳排放!AM32:AM56)*$E2 -> 8.1439834
A10: Heating and H2 | B10: =二氧化碳排放!B7*$E$2 -> 6.00222 | C10: =二氧化碳排放!C7*$E$2 -> 6.16358 | D10: =二氧化碳排放!D7*$E$2 -> 6.33633 | E10: =二氧化碳排放!E7*$E$2 -> 6.47841 | F10: =二氧化碳排放!F7*$E$2 -> 6.62564 | G10: =二氧化碳排放!G7*$E$2 -> 6.77144 | H10: =二氧化碳排放!H7*$E$2 -> 6.93463 | I10: =二氧化碳排放!I7*$E$2 -> 7.09303 | ... AM10: =二氧化碳排放!AM7*$E$2 -> 7.8598
A11: LULUCF | B11: =二氧化碳排放!B8*$E$2 -> -4.34 | C11: =二氧化碳排放!C8*$E$2 -> -4.34 | D11: =二氧化碳排放!D8*$E$2 -> -4.34 | E11: =二氧化碳排放!E8*$E$2 -> -4.34 | F11: =二氧化碳排放!F8*$E$2 -> -4.34 | G11: =二氧化碳排放!G8*$E$2 -> -4.34 | H11: =二氧化碳排放!H8*$E$2 -> -4.34 | I11: =二氧化碳排放!I8*$E$2 -> -4.34 | ... AM11: =二氧化碳排放!AM8*$E$2 -> -4.34
A12: Geo-engineering | B12: =二氧化碳排放!B9*$E$2 -> 0 | C12: =二氧化碳排放!C9*$E$2 -> 0 | D12: =二氧化碳排放!D9*$E$2 -> 0 | E12: =二氧化碳排放!E9*$E$2 -> 0 | F12: =二氧化碳排放!F9*$E$2 -> 0 | G12: =二氧化碳排放!G9*$E$2 -> 0 | H12: =二氧化碳排放!H9*$E$2 -> 0 | I12: =二氧化碳排放!I9*$E$2 -> 0 | ... AM12: =二氧化碳排放!AM9*$E$2 -> 0
A13: District Heating | B13: =二氧化碳排放!B12*$E$2 -> 5.97593 | C13: =二氧化碳排放!C12*$E$2 -> 6.12539 | D13: =二氧化碳排放!D12*$E$2 -> 6.28023 | E13: =二氧化碳排放!E12*$E$2 -> 6.40035 | F13: =二氧化碳排放!F12*$E$2 -> 6.52058 | G13: =二氧化碳排放!G12*$E$2 -> 6.63311 | H13: =二氧化碳排放!H12*$E$2 -> 6.75534 | I13: =二氧化碳排放!I12*$E$2 -> 6.863 | ... AM13: =二氧化碳排放!AM12*$E$2 -> 6.53262
A14: Hydrogen | B14: =SUM(二氧化碳排放!B15:B24)*$E$2 -> 0.02628675 | C14: =SUM(二氧化碳排放!C15:C24)*$E$2 -> 0.03819311 | D14: =SUM(二氧化碳排放!D15:D24)*$E$2 -> 0.05609264 | E14: =SUM(二氧化碳排放!E15:E24)*$E$2 -> 0.0780509 | F14: =SUM(二氧化碳排放!F15:F24)*$E$2 -> 0.1050646 | G14: =SUM(二氧化碳排放!G15:G24)*$E$2 -> 0.1383316 | H14: =SUM(二氧化碳排放!H15:H24)*$E$2 -> 0.1792863 | I14: =SUM(二氧化碳排放!I15:I24)*$E$2 -> 0.2300271 | ... AM14: =SUM(二氧化碳排放!AM15:AM24)*$E$2 -> 1.327186
A15: Non CO2 | B15: =二氧化碳排放!B27*$E$2-SUM(B4:B14) -> 23.073373 | C15: =二氧化碳排放!C27*$E$2-SUM(C4:C14) -> 23.413577 | D15: =二氧化碳排放!D27*$E$2-SUM(D4:D14) -> 23.746217 | E15: =二氧化碳排放!E27*$E$2-SUM(E4:E14) -> 23.756239 | F15: =二氧化碳排放!F27*$E$2-SUM(F4:F14) -> 23.755395 | G15: =二氧化碳排放!G27*$E$2-SUM(G4:G14) -> 23.755438 | H15: =二氧化碳排放!H27*$E$2-SUM(H4:H14) -> 23.731764 | I15: =二氧化碳排放!I27*$E$2-SUM(I4:I14) -> 23.696223 | ... AM15: =二氧化碳排放!AM27*$E$2-SUM(AM4:AM14) -> 18.345354
A16: CO2 emission | B16: =SUM(B4:B12) -> 105.66041 | C16: =SUM(C4:C12) -> 105.72084 | D16: =SUM(D4:D12) -> 109.78446 | E16: =SUM(E4:E12) -> 112.25836 | F16: =SUM(F4:F12) -> 114.59996 | G16: =SUM(G4:G12) -> 116.68112 | H16: =SUM(H4:H12) -> 118.47261 | I16: =SUM(I4:I12) -> 120.44175 | ... AM16: =SUM(AM4:AM12) -> 63.39124
A17: CO2e emission | B17: =B15+B16 -> 128.73378 | C17: =C15+C16 -> 129.13442 | D17: =D15+D16 -> 133.53068 | E17: =E15+E16 -> 136.0146 | F17: =F15+F16 -> 138.35536 | G17: =G15+G16 -> 140.43656 | H17: =H15+H16 -> 142.20437 | I17: =I15+I16 -> 144.13797 | ... AM17: =AM15+AM16 -> 81.736594
Q19: Max Value
O20: Transportation | P20: 交通部门 | Q20: =MAX(4:4) -> 15.6359
O21: Electricity | P21: 电力部门 | Q21: =MAX(5:5) -> 54.1082
O22: Residential bldg | P22: 居民建筑 | Q22: =MAX(6:6) -> 3.2022
O23: Commercial bldg | P23: 公共建筑 | Q23: =MAX(7:7) -> 1.58751
O24: Industrial Fuel | P24: 工业燃料 | Q24: =MAX(8:8) -> 31.168946
O25: Industrial Process | P25: 工业过程 | Q25: =MAX(9:9) -> 14.566725
O26: Heating and H2 | P26: 供热与氢能 | Q26: =MAX(10:10) -> 7.8598
O27: LULUCF | P27: 土地利用 | Q27: =MAX(11:11) -> -4.34
O28: Geo-engineering | P28: 碳捕集 | Q28: =MAX(12:12) -> 0
O29: District Heating | P29: 集中供热 | Q29: =MAX(13:13) -> 7.19303
O30: Hydrogen | P30: 氢气生产 | Q30: =MAX(14:14) -> 1.327186
O31: Non CO2 | P31: 非二温室气体 | Q31: =MAX(15:15) -> 23.756239
O32: CO2 emission | P32: 二氧化碳排放 | Q32: =MAX(16:16) -> 120.53266
O33: CO2e emission | P33: 温室气体排放 | Q33: =MAX(17:17) -> 144.13797
B38: 2023 | I38: 2030 | N38: 2035 | S38: 2040 | X38: 2045 | AC38: 2050 | AH38: 2055 | AM38: 2060
A39: BAU Transportation | B39: =BAU二氧化碳排放!B2*'图1-二氧化碳排放'!$E$2 -> 15.6359 | C39: =BAU二氧化碳排放!C2*'图1-二氧化碳排放'!$E$2 -> 15.5767 | D39: =BAU二氧化碳排放!D2*'图1-二氧化碳排放'!$E$2 -> 15.5182 | E39: =BAU二氧化碳排放!E2*'图1-二氧化碳排放'!$E$2 -> 15.4621 | F39: =BAU二氧化碳排放!F2*'图1-二氧化碳排放'!$E$2 -> 15.3937 | G39: =BAU二氧化碳排放!G2*'图1-二氧化碳排放'!$E$2 -> 15.3141 | H39: =BAU二氧化碳排放!H2*'图1-二氧化碳排放'!$E$2 -> 15.2196 | I39: =BAU二氧化碳排放!I2*'图1-二氧化碳排放'!$E$2 -> 15.1044 | ... AM39: =BAU二氧化碳排放!AM2*'图1-二氧化碳排放'!$E$2 -> 11.3107
A40: BAU Electricity | B40: =BAU二氧化碳排放!B3*'图1-二氧化碳排放'!$E$2 -> 41.2478 | C40: =BAU二氧化碳排放!C3*'图1-二氧化碳排放'!$E$2 -> 41.1613 | D40: =BAU二氧化碳排放!D3*'图1-二氧化碳排放'!$E$2 -> 43.7221 | E40: =BAU二氧化碳排放!E3*'图1-二氧化碳排放'!$E$2 -> 45.8051 | F40: =BAU二氧化碳排放!F3*'图1-二氧化碳排放'!$E$2 -> 47.7903 | G40: =BAU二氧化碳排放!G3*'图1-二氧化碳排放'!$E$2 -> 49.5852 | H40: =BAU二氧化碳排放!H3*'图1-二氧化碳排放'!$E$2 -> 51.1363 | I40: =BAU二氧化碳排放!I3*'图1-二氧化碳排放'!$E$2 -> 52.8148 | ... AM40: =BAU二氧化碳排放!AM3*'图1-二氧化碳排放'!$E$2 -> 13.5207
A41: BAU Residential bldg | B41: =BAU二氧化碳排放!B4*'图1-二氧化碳排放'!$E$2 -> 3.2022 | C41: =BAU二氧化碳排放!C4*'图1-二氧化碳排放'!$E$2 -> 3.20086 | D41: =BAU二氧化碳排放!D4*'图1-二氧化碳排放'!$E$2 -> 3.19575 | E41: =BAU二氧化碳排放!E4*'图1-二氧化碳排放'!$E$2 -> 3.18393 | F41: =BAU二氧化碳排放!F4*'图1-二氧化碳排放'!$E$2 -> 3.17364 | G41: =BAU二氧化碳排放!G4*'图1-二氧化碳排放'!$E$2 -> 3.16948 | H41: =BAU二氧化碳排放!H4*'图1-二氧化碳排放'!$E$2 -> 3.16077 | I41: =BAU二氧化碳排放!I4*'图1-二氧化碳排放'!$E$2 -> 3.15547 | ... AM41: =BAU二氧化碳排放!AM4*'图1-二氧化碳排放'!$E$2 -> 2.63523
A42: BAU Commercial bldg | B42: =BAU二氧化碳排放!B5*'图1-二氧化碳排放'!$E$2 -> 1.28319 | C42: =BAU二氧化碳排放!C5*'图1-二氧化碳排放'!$E$2 -> 1.3106 | D42: =BAU二氧化碳排放!D5*'图1-二氧化碳排放'!$E$2 -> 1.33418 | E42: =BAU二氧化碳排放!E5*'图1-二氧化碳排放'!$E$2 -> 1.35142 | F42: =BAU二氧化碳排放!F5*'图1-二氧化碳排放'!$E$2 -> 1.36808 | G42: =BAU二氧化碳排放!G5*'图1-二氧化碳排放'!$E$2 -> 1.3861 | H42: =BAU二氧化碳排放!H5*'图1-二氧化碳排放'!$E$2 -> 1.40341 | I42: =BAU二氧化碳排放!I5*'图1-二氧化碳排放'!$E$2 -> 1.41925 | ... AM42: =BAU二氧化碳排放!AM5*'图1-二氧化碳排放'!$E$2 -> 1.58751
A43: BAU Industrial Fuel | B43: =BAU二氧化碳排放!B6*'图1-二氧化碳排放'!$E$2-B44 -> 28.24292 | C43: =BAU二氧化碳排放!C6*'图1-二氧化碳排放'!$E$2-C44 -> 28.404782 | D43: =BAU二氧化碳排放!D6*'图1-二氧化碳排放'!$E$2-D44 -> 29.917035 | E43: =BAU二氧化碳排放!E6*'图1-二氧化碳排放'!$E$2-E44 -> 30.243637 | F43: =BAU二氧化碳排放!F6*'图1-二氧化碳排放'!$E$2-F44 -> 30.585297 | G43: =BAU二氧化碳排放!G6*'图1-二氧化碳排放'!$E$2-G44 -> 30.912027 | H43: =BAU二氧化碳排放!H6*'图1-二氧化碳排放'!$E$2-H44 -> 31.192957 | I43: =BAU二氧化碳排放!I6*'图1-二氧化碳排放'!$E$2-I44 -> 31.544538 | ... AM43: =BAU二氧化碳排放!AM6*'图1-二氧化碳排放'!$E$2-AM44 -> 22.598458
A44: BAU Industrial Process | B44: =SUM(BAU二氧化碳排放!B32:B56)*'图1-二氧化碳排放'!$E2 -> 14.38618 | C44: =SUM(BAU二氧化碳排放!C32:C56)*'图1-二氧化碳排放'!$E2 -> 14.243018 | D44: =SUM(BAU二氧化碳排放!D32:D56)*'图1-二氧化碳排放'!$E2 -> 14.100565 | E44: =SUM(BAU二氧化碳排放!E32:E56)*'图1-二氧化碳排放'!$E2 -> 14.073463 | F44: =SUM(BAU二氧化碳排放!F32:F56)*'图1-二氧化碳排放'!$E2 -> 14.002503 | G44: =SUM(BAU二氧化碳排放!G32:G56)*'图1-二氧化碳排放'!$E2 -> 13.881673 | H44: =SUM(BAU二氧化碳排放!H32:H56)*'图1-二氧化碳排放'!$E2 -> 13.763643 | I44: =SUM(BAU二氧化碳排放!I32:I56)*'图1-二氧化碳排放'!$E2 -> 13.648962 | ... AM44: =SUM(BAU二氧化碳排放!AM32:AM56)*'图1-二氧化碳排放'!$E2 -> 8.2176421
A45: BAU Heating and H2 | B45: =BAU二氧化碳排放!B7*'图1-二氧化碳排放'!$E$2 -> 6.00222 | C45: =BAU二氧化碳排放!C7*'图1-二氧化碳排放'!$E$2 -> 6.16358 | D45: =BAU二氧化碳排放!D7*'图1-二氧化碳排放'!$E$2 -> 6.33633 | E45: =BAU二氧化碳排放!E7*'图1-二氧化碳排放'!$E$2 -> 6.47841 | F45: =BAU二氧化碳排放!F7*'图1-二氧化碳排放'!$E$2 -> 6.62564 | G45: =BAU二氧化碳排放!G7*'图1-二氧化碳排放'!$E$2 -> 6.77144 | H45: =BAU二氧化碳排放!H7*'图1-二氧化碳排放'!$E$2 -> 6.93462 | I45: =BAU二氧化碳排放!I7*'图1-二氧化碳排放'!$E$2 -> 7.09302 | ... AM45: =BAU二氧化碳排放!AM7*'图1-二氧化碳排放'!$E$2 -> 7.84891
...

Sheet 图2-二氧化碳排放范围二
C1: conversion | D1: gram | E1: 亿吨 | F1: 100 mt | G1: Scope 1+2 CO2 Emission by Sector
C2: 单位转换 | D2: 1 | E2: =10^-14 -> 1e-14 | G2: 分部门二氧化碳间接排放（范围1+2）
A3: Indirect Emission | B3: 2023 | I3: 2030 | N3: 2035 | S3: 2040 | X3: 2045 | AC3: 2050 | AH3: 2055 | AM3: 2060
A4: Transportation | B4: =B35+B47+B59+B70 -> 16.722929 | C4: =C35+C47+C59+C70 -> 16.695871 | D4: =D35+D47+D59+D70 -> 16.724729 | E4: =E35+E47+E59+E70 -> 16.772094 | F4: =F35+F47+F59+F70 -> 16.834251 | G4: =G35+G47+G59+G70 -> 16.907994 | H4: =H35+H47+H59+H70 -> 16.987694 | I4: =I35+I47+I59+I70 -> 17.077587 | ... AM4: =AM35+AM47+AM59+AM70 -> 13.411888
A5: Residential bldg | B5: =B37+B49+B61+B72 -> 11.227515 | C5: =C37+C49+C61+C72 -> 10.998304 | D5: =D37+D49+D61+D72 -> 11.482977 | E5: =E37+E49+E61+E72 -> 11.905614 | F5: =F37+F49+F61+F72 -> 12.31193 | G5: =G37+G49+G61+G72 -> 12.678764 | H5: =H37+H49+H61+H72 -> 12.974492 | I5: =I37+I49+I61+I72 -> 13.302627 | ... AM5: =AM37+AM49+AM61+AM72 -> 7.2876192
A6: Commercial bldg | B6: =B38+B50+B62+B73 -> 7.9160094 | C6: =C38+C50+C62+C73 -> 7.8114384 | D6: =D38+D50+D62+D73 -> 8.5604878 | E6: =E38+E50+E62+E73 -> 9.2285628 | F6: =F38+F50+F62+F73 -> 9.8417466 | G6: =G38+G50+G62+G73 -> 10.41153 | H6: =H38+H50+H62+H73 -> 10.894194 | I6: =I38+I50+I62+I73 -> 11.392622 | ... AM6: =AM38+AM50+AM62+AM73 -> 6.051884
A7: Industry | B7: =B39+B51+B63+B74 -> 59.533007 | C7: =C39+C51+C63+C74 -> 60.016593 | D7: =D39+D51+D63+D74 -> 62.700795 | E7: =E39+E51+E63+E74 -> 64.080462 | F7: =F39+F51+F63+F74 -> 65.42575 | G7: =G39+G51+G63+G74 -> 66.637489 | H7: =H39+H51+H63+H74 -> 67.705822 | I7: =I39+I51+I63+I74 -> 68.891211 | ... AM7: =AM39+AM51+AM63+AM74 -> 32.818496
A8: Industrial Process | B8: =SUM(二氧化碳排放!B32:B56)*$E2 -> 14.51112 | C8: =SUM(二氧化碳排放!C32:C56)*$E2 -> 14.450738 | D8: =SUM(二氧化碳排放!D32:D56)*$E2 -> 14.566725 | E8: =SUM(二氧化碳排放!E32:E56)*$E2 -> 14.522373 | F8: =SUM(二氧化碳排放!F32:F56)*$E2 -> 14.436133 | G8: =SUM(二氧化碳排放!G32:G56)*$E2 -> 14.294263 | H8: =SUM(二氧化碳排放!H32:H56)*$E2 -> 14.158554 | I8: =SUM(二氧化碳排放!I32:I56)*$E2 -> 14.024754 | ... AM8: =SUM(二氧化碳排放!AM32:AM56)*$E2 -> 8.1439834
A9: Electricity Export | B9: =B52 -> 0.089335182 | C9: =C52 -> 0.087205541 | D9: =D52 -> 0.087720242 | E9: =E52 -> 0.087833787 | F9: =F52 -> 0.088256289 | G9: =G52 -> 0.088590419 | H9: =H52 -> 0.08863832 | I9: =I52 -> 0.088837401 | ... AM9: =AM52 -> 0.013927456
A10: LULUCF | B10: ='图1-二氧化碳排放'!B11 -> -4.34 | C10: ='图1-二氧化碳排放'!C11 -> -4.34 | D10: ='图1-二氧化碳排放'!D11 -> -4.34 | E10: ='图1-二氧化碳排放'!E11 -> -4.34 | F10: ='图1-二氧化碳排放'!F11 -> -4.34 | G10: ='图1-二氧化碳排放'!G11 -> -4.34 | H10: ='图1-二氧化碳排放'!H11 -> -4.34 | I10: ='图1-二氧化碳排放'!I11 -> -4.34 | ... AM10: ='图1-二氧化碳排放'!AM11 -> -4.34
A11: Geo-engineering | B11: ='图1-二氧化碳排放'!B12 -> 0 | C11: ='图1-二氧化碳排放'!C12 -> 0 | D11: ='图1-二氧化碳排放'!D12 -> 0 | E11: ='图1-二氧化碳排放'!E12 -> 0 | F11: ='图1-二氧化碳排放'!F12 -> 0 | G11: ='图1-二氧化碳排放'!G12 -> 0 | H11: ='图1-二氧化碳排放'!H12 -> 0 | I11: ='图1-二氧化碳排放'!I12 -> 0 | ... AM11: ='图1-二氧化碳排放'!AM12 -> 0
A12: subtotal | B12: =SUM(B4:B11) -> 105.65991 | C12: =SUM(C4:C11) -> 105.72015 | D12: =SUM(D4:D11) -> 109.78343 | E12: =SUM(E4:E11) -> 112.25694 | F12: =SUM(F4:F11) -> 114.59807 | G12: =SUM(G4:G11) -> 116.67863 | H12: =SUM(H4:H11) -> 118.46939 | I12: =SUM(I4:I11) -> 120.43764 | ... AM12: =SUM(AM4:AM11) -> 63.387798
A13: diff. | B13: =B12-SUM('图1-二氧化碳排放'!B4:B12) -> -0.00049504461 | C13: =C12-SUM('图1-二氧化碳排放'!C4:C12) -> -0.00069040903 | D13: =D12-SUM('图1-二氧化碳排放'!D4:D12) -> -0.0010260765 | E13: =E12-SUM('图1-二氧化碳排放'!E4:E12) -> -0.0014204006 | F13: =F12-SUM('图1-二氧化碳排放'!F4:F12) -> -0.0018935367 | G13: =G12-SUM('图1-二氧化碳排放'!G4:G12) -> -0.002489694 | H13: =H12-SUM('图1-二氧化碳排放'!H4:H12) -> -0.0032159562 | I13: =I12-SUM('图1-二氧化碳排放'!I4:I12) -> -0.0041108074 | ... AM13: =AM12-SUM('图1-二氧化碳排放'!AM4:AM12) -> -0.0034424122
R16: Max Value
P17: Transportation | Q17: 交通部门 | R17: =MAX(4:4) -> 17.077587
P18: Residential bldg | Q18: 居民建筑 | R18: =MAX(5:5) -> 13.670541
P19: Commercial bldg | Q19: 公共建筑 | R19: =MAX(6:6) -> 12.974668
P20: Industrial Fuel | Q20: 工业燃料 | R20: =MAX(7:7) -> 68.891211
P21: Industrial Process | Q21: 工业过程 | R21: =MAX(8:8) -> 14.566725
P22: Electricity Export | Q22: 外送电力 | R22: =MAX(9:9) -> 0.089335182
P23: LULUCF | Q23: 土地利用 | R23: =MAX(10:10) -> -4.34
P24: Geo-engineering | Q24: 碳捕集 | R24: =MAX(11:11) -> 0
A34: Direct Emission | B34: 2023 | C34: 2024 | D34: 2025 | E34: 2026 | F34: 2027 | G34: 2028 | H34: 2029 | I34: 2030 | J34: 2031 | K34: 2032 | L34: 2033 | M34: 2034 | N34: 2035 | O34: 2036 | P34: 2037 | Q34: 2038 | R34: 2039 | S34: 2040 | T34: 2041 | U34: 2042 | V34: 2043 | W34: 2044 | X34: 2045 | Y34: 2046 | Z34: 2047 | AA34: 2048 | AB34: 2049 | AC34: 2050 | AD34: 2051 | AE34: 2052 | AF34: 2053 | AG34: 2054 | AH34: 2055 | AI34: 2056 | AJ34: 2057 | AK34: 2058 | AL34: 2059 | AM34: 2060
A35: Transportation | B35: ='图1-二氧化碳排放'!B4 -> 15.6359 | C35: ='图1-二氧化碳排放'!C4 -> 15.5767 | D35: ='图1-二氧化碳排放'!D4 -> 15.5182 | E35: ='图1-二氧化碳排放'!E4 -> 15.4621 | F35: ='图1-二氧化碳排放'!F4 -> 15.3937 | G35: ='图1-二氧化碳排放'!G4 -> 15.3141 | H35: ='图1-二氧化碳排放'!H4 -> 15.2196 | I35: ='图1-二氧化碳排放'!I4 -> 15.1044 | ... AM35: ='图1-二氧化碳排放'!AM4 -> 11.3117
A36: Electricity | B36: ='图1-二氧化碳排放'!B5 -> 41.2478 | C36: ='图1-二氧化碳排放'!C5 -> 41.1613 | D36: ='图1-二氧化碳排放'!D5 -> 43.7224 | E36: ='图1-二氧化碳排放'!E5 -> 45.8054 | F36: ='图1-二氧化碳排放'!F5 -> 47.7911 | G36: ='图1-二氧化碳排放'!G5 -> 49.5862 | H36: ='图1-二氧化碳排放'!H5 -> 51.1375 | I36: ='图1-二氧化碳排放'!I5 -> 52.8159 | ... AM36: ='图1-二氧化碳排放'!AM5 -> 13.5208
A37: Residential bldg | B37: ='图1-二氧化碳排放'!B6 -> 3.2022 | C37: ='图1-二氧化碳排放'!C6 -> 3.20086 | D37: ='图1-二氧化碳排放'!D6 -> 3.19575 | E37: ='图1-二氧化碳排放'!E6 -> 3.18393 | F37: ='图1-二氧化碳排放'!F6 -> 3.17364 | G37: ='图1-二氧化碳排放'!G6 -> 3.16948 | H37: ='图1-二氧化碳排放'!H6 -> 3.16077 | I37: ='图1-二氧化碳排放'!I6 -> 3.15547 | ... AM37: ='图1-二氧化碳排放'!AM6 -> 2.63523
A38: Commercial bldg | B38: ='图1-二氧化碳排放'!B7 -> 1.28319 | C38: ='图1-二氧化碳排放'!C7 -> 1.3106 | D38: ='图1-二氧化碳排放'!D7 -> 1.33418 | E38: ='图1-二氧化碳排放'!E7 -> 1.35142 | F38: ='图1-二氧化碳排放'!F7 -> 1.36808 | G38: ='图1-二氧化碳排放'!G7 -> 1.3861 | H38: ='图1-二氧化碳排放'!H7 -> 1.40341 | I38: ='图1-二氧化碳排放'!I7 -> 1.41925 | ... AM38: ='图1-二氧化碳排放'!AM7 -> 1.58751
A39: Industry | B39: ='图1-二氧化碳排放'!B8 -> 28.11798 | C39: ='图1-二氧化碳排放'!C8 -> 28.197062 | D39: ='图1-二氧化碳排放'!D8 -> 29.450875 | E39: ='图1-二氧化碳排放'!E8 -> 29.794727 | F39: ='图1-二氧化碳排放'!F8 -> 30.151667 | G39: ='图1-二氧化碳排放'!G8 -> 30.499537 | H39: ='图1-二氧化碳排放'!H8 -> 30.798146 | I39: ='图1-二氧化碳排放'!I8 -> 31.168946 | ... AM39: ='图1-二氧化碳排放'!AM8 -> 22.672217
A40: Heating and hydrogen | B40: ='图1-二氧化碳排放'!B10 -> 6.00222 | C40: ='图1-二氧化碳排放'!C10 -> 6.16358 | D40: ='图1-二氧化碳排放'!D10 -> 6.33633 | E40: ='图1-二氧化碳排放'!E10 -> 6.47841 | F40: ='图1-二氧化碳排放'!F10 -> 6.62564 | G40: ='图1-二氧化碳排放'!G10 -> 6.77144 | H40: ='图1-二氧化碳排放'!H10 -> 6.93463 | I40: ='图1-二氧化碳排放'!I10 -> 7.09303 | ... AM40: ='图1-二氧化碳排放'!AM10 -> 7.8598
A41: sub: District Heating | B41: ='图1-二氧化碳排放'!B13 -> 5.97593 | C41: ='图1-二氧化碳排放'!C13 -> 6.12539 | D41: ='图1-二氧化碳排放'!D13 -> 6.28023 | E41: ='图1-二氧化碳排放'!E13 -> 6.40035 | F41: ='图1-二氧化碳排放'!F13 -> 6.52058 | G41: ='图1-二氧化碳排放'!G13 -> 6.63311 | H41: ='图1-二氧化碳排放'!H13 -> 6.75534 | I41: ='图1-二氧化碳排放'!I13 -> 6.863 | ... AM41: ='图1-二氧化碳排放'!AM13 -> 6.53262
A42: sub: Hydrogen Supply | B42: ='图1-二氧化碳排放'!B14 -> 0.02628675 | C42: ='图1-二氧化碳排放'!C14 -> 0.03819311 | D42: ='图1-二氧化碳排放'!D14 -> 0.05609264 | E42: ='图1-二氧化碳排放'!E14 -> 0.0780509 | F42: ='图1-二氧化碳排放'!F14 -> 0.1050646 | G42: ='图1-二氧化碳排放'!G14 -> 0.1383316 | H42: ='图1-二氧化碳排放'!H14 -> 0.1792863 | I42: ='图1-二氧化碳排放'!I14 -> 0.2300271 | ... AM42: ='图1-二氧化碳排放'!AM14 -> 1.327186
A46: From Electricity | B46: 2023 | C46: 2024 | D46: 2025 | E46: 2026 | F46: 2027 | G46: 2028 | H46: 2029 | I46: 2030 | J46: 2031 | K46: 2032 | L46: 2033 | M46: 2034 | N46: 2035 | O46: 2036 | P46: 2037 | Q46: 2038 | R46: 2039 | S46: 2040 | T46: 2041 | U46: 2042 | V46: 2043 | W46: 2044 | X46: 2045 | Y46: 2046 | Z46: 2047 | AA46: 2048 | AB46: 2049 | AC46: 2050 | AD46: 2051 | AE46: 2052 | AF46: 2053 | AG46: 2054 | AH46: 2055 | AI46: 2056 | AJ46: 2057 | AK46: 2058 | AL46: 2059 | AM46: 2060
A47: Transportation | B47: =B$36*'图7-用电量'!C$4/SUM('图7-用电量'!C$4:C$9) -> 1.0607427 | C47: =C$36*'图7-用电量'!D$4/SUM('图7-用电量'!D$4:D$9) -> 1.0809782 | D47: =D$36*'图7-用电量'!E$4/SUM('图7-用电量'!E$4:E$9) -> 1.150436 | E47: =E$36*'图7-用电量'!F$4/SUM('图7-用电量'!F$4:F$9) -> 1.2319427 | F47: =F$36*'图7-用电量'!G$4/SUM('图7-用电量'!G$4:G$9) -> 1.3354867 | G47: =G$36*'图7-用电量'!H$4/SUM('图7-用电量'!H$4:H$9) -> 1.4555626 | H47: =H$36*'图7-用电量'!I$4/SUM('图7-用电量'!I$4:I$9) -> 1.5888077 | I47: =I$36*'图7-用电量'!J$4/SUM('图7-用电量'!J$4:J$9) -> 1.7431598 | ... AM47: =AM$36*'图7-用电量'!AN$4/SUM('图7-用电量'!AN$4:AN$9) -> 0.77300175
A48: Electricity | B48: 0 | C48: 0 | D48: 0 | E48: 0 | F48: 0 | G48: 0 | H48: 0 | I48: 0 | J48: 0 | K48: 0 | L48: 0 | M48: 0 | N48: 0 | O48: 0 | P48: 0 | Q48: 0 | R48: 0 | S48: 0 | T48: 0 | U48: 0 | V48: 0 | W48: 0 | X48: 0 | Y48: 0 | Z48: 0 | AA48: 0 | AB48: 0 | AC48: 0 | AD48: 0 | AE48: 0 | AF48: 0 | AG48: 0 | AH48: 0 | AI48: 0 | AJ48: 0 | AK48: 0 | AL48: 0 | AM48: 0
A49: Residential bldg | B49: =B$36*'图7-用电量'!C11/SUM('图7-用电量'!C$4:C$9) -> 6.8190247 | C49: =C$36*'图7-用电量'!D11/SUM('图7-用电量'!D$4:D$9) -> 6.5782146 | D49: =D$36*'图7-用电量'!E11/SUM('图7-用电量'!E$4:E$9) -> 7.0551197 | E49: =E$36*'图7-用电量'!F11/SUM('图7-用电量'!F$4:F$9) -> 7.4784989 | F49: =F$36*'图7-用电量'!G11/SUM('图7-用电量'!G$4:G$9) -> 7.8812269 | G49: =G$36*'图7-用电量'!H11/SUM('图7-用电量'!H$4:H$9) -> 8.2364855 | H49: =H$36*'图7-用电量'!I11/SUM('图7-用电量'!I$4:I$9) -> 8.5237794 | I49: =I$36*'图7-用电量'!J11/SUM('图7-用电量'!J$4:J$9) -> 8.8492196 | ... AM49: =AM$36*'图7-用电量'!AN11/SUM('图7-用电量'!AN$4:AN$9) -> 3.2410387
A50: Commercial bldg | B50: =B$36*'图7-用电量'!C10/SUM('图7-用电量'!C$4:C$9) -> 6.3365912 | C50: =C$36*'图7-用电量'!D10/SUM('图7-用电量'!D$4:D$9) -> 6.2009534 | D50: =D$36*'图7-用电量'!E10/SUM('图7-用电量'!E$4:E$9) -> 6.9227887 | E50: =E$36*'图7-用电量'!F10/SUM('图7-用电量'!F$4:F$9) -> 7.57084 | F50: =F$36*'图7-用电量'!G10/SUM('图7-用电量'!G$4:G$9) -> 8.1631422 | G50: =G$36*'图7-用电量'!H10/SUM('图7-用电量'!H$4:H$9) -> 8.7109737 | H50: =H$36*'图7-用电量'!I10/SUM('图7-用电量'!I$4:I$9) -> 9.1720487 | I50: =I$36*'图7-用电量'!J10/SUM('图7-用电量'!J$4:J$9) -> 9.6500131 | ... AM50: =AM$36*'图7-用电量'!AN10/SUM('图7-用电量'!AN$4:AN$9) -> 4.0968191
A51: Industry | B51: =B$36*'图7-用电量'!C5/SUM('图7-用电量'!C$4:C$9) -> 26.941614 | C51: =C$36*'图7-用电量'!D5/SUM('图7-用电量'!D$4:D$9) -> 27.213255 | D51: =D$36*'图7-用电量'!E5/SUM('图7-用电量'!E$4:E$9) -> 28.505317 | E51: =E$36*'图7-用电量'!F5/SUM('图7-用电量'!F$4:F$9) -> 29.434873 | F51: =F$36*'图7-用电量'!G5/SUM('图7-用电量'!G$4:G$9) -> 30.32109 | G51: =G$36*'图7-用电量'!H5/SUM('图7-用电量'!H$4:H$9) -> 31.092097 | H51: =H$36*'图7-用电量'!I5/SUM('图7-用电量'!I$4:I$9) -> 31.761014 | I51: =I$36*'图7-用电量'!J5/SUM('图7-用电量'!J$4:J$9) -> 32.480562 | ... AM51: =AM$36*'图7-用电量'!AN5/SUM('图7-用电量'!AN$4:AN$9) -> 5.3925646
A52: Electricity Export | B52: =MAX(B$36*'图7-用电量'!C9/SUM('图7-用电量'!C$4:C$9),0) -> 0.089335182 | C52: =MAX(C$36*'图7-用电量'!D9/SUM('图7-用电量'!D$4:D$9),0) -> 0.087205541 | D52: =MAX(D$36*'图7-用电量'!E9/SUM('图7-用电量'!E$4:E$9),0) -> 0.087720242 | E52: =MAX(E$36*'图7-用电量'!F9/SUM('图7-用电量'!F$4:F$9),0) -> 0.087833787 | F52: =MAX(F$36*'图7-用电量'!G9/SUM('图7-用电量'!G$4:G$9),0) -> 0.088256289 | G52: =MAX(G$36*'图7-用电量'!H9/SUM('图7-用电量'!H$4:H$9),0) -> 0.088590419 | H52: =MAX(H$36*'图7-用电量'!I9/SUM('图7-用电量'!I$4:I$9),0) -> 0.08863832 | I52: =MAX(I$36*'图7-用电量'!J9/SUM('图7-用电量'!J$4:J$9),0) -> 0.088837401 | ... AM52: =MAX(AM$36*'图7-用电量'!AN9/SUM('图7-用电量'!AN$4:AN$9),0) -> 0.013927456
A53: Heating and hydrogen | B53: =B54+B55 -> 0.00049179461 | C53: =C54+C55 -> 0.00069351903 | D53: =D54+D55 -> 0.0010187165 | E53: =E54+E55 -> 0.0014113006 | F53: =F54+F55 -> 0.0018981367 | G53: =G54+G55 -> 0.002491294 | H53: =H54+H55 -> 0.0032122562 | I53: =I54+I55 -> 0.0041079074 | ... AM53: =AM54+AM55 -> 0.0034484122
A54: sub: District Heating | B54: =B$36*'图7-用电量'!C7/SUM('图7-用电量'!C$4:C$9) -> 0 | C54: =C$36*'图7-用电量'!D7/SUM('图7-用电量'!D$4:D$9) -> 0 | D54: =D$36*'图7-用电量'!E7/SUM('图7-用电量'!E$4:E$9) -> 0 | E54: =E$36*'图7-用电量'!F7/SUM('图7-用电量'!F$4:F$9) -> 0 | F54: =F$36*'图7-用电量'!G7/SUM('图7-用电量'!G$4:G$9) -> 0 | G54: =G$36*'图7-用电量'!H7/SUM('图7-用电量'!H$4:H$9) -> 0 | H54: =H$36*'图7-用电量'!I7/SUM('图7-用电量'!I$4:I$9) -> 0 | I54: =I$36*'图7-用电量'!J7/SUM('图7-用电量'!J$4:J$9) -> 0 | ... AM54: =AM$36*'图7-用电量'!AN7/SUM('图7-用电量'!AN$4:AN$9) -> 0
...

Sheet BAU二氧化碳排放
A1: Time (Year) | B1: 2023 | C1: 2024 | D1: 2025 | E1: 2026 | F1: 2027 | G1: 2028 | H1: 2029 | I1: 2030 | J1: 2031 | K1: 2032 | L1: 2033 | M1: 2034 | N1: 2035 | O1: 2036 | P1: 2037 | Q1: 2038 | R1: 2039 | S1: 2040 | T1: 2041 | U1: 2042 | V1: 2043 | W1: 2044 | X1: 2045 | Y1: 2046 | Z1: 2047 | AA1: 2048 | AB1: 2049 | AC1: 2050 | AD1: 2051 | AE1: 2052 | AF1: 2053 | AG1: 2054 | AH1: 2055 | AI1: 2056 | AJ1: 2057 | AK1: 2058 | AL1: 2059 | AM1: 2060
A2: BAU Total Pollutant Emissions by Sector[transportation sector,CO2] : MostRecentRun | B2: 1.56359e+15 | C2: 1.55767e+15 | D2: 1.55182e+15 | E2: 1.54621e+15 | F2: 1.53937e+15 | G2: 1.53141e+15 | H2: 1.52196e+15 | I2: 1.51044e+15 | J2: 1.4872e+15 | K2: 1.46233e+15 | L2: 1.44024e+15 | M2: 1.41812e+15 | N2: 1.39541e+15 | O2: 1.37744e+15 | P2: 1.35706e+15 | Q2: 1.33216e+15 | R2: 1.31018e+15 | S2: 1.2908e+15 | T2: 1.2679e+15 | U2: 1.24707e+15 | V2: 1.22855e+15 | W2: 1.21227e+15 | X2: 1.19837e+15 | Y2: 1.19008e+15 | Z2: 1.18408e+15 | AA2: 1.18026e+15 | AB2: 1.1775e+15 | AC2: 1.17607e+15 | AD2: 1.17005e+15 | AE2: 1.16487e+15 | AF2: 1.16016e+15 | AG2: 1.15567e+15 | AH2: 1.15136e+15 | AI2: 1.14736e+15 | AJ2: 1.14341e+15 | AK2: 1.13935e+15 | AL2: 1.13531e+15 | AM2: 1.13107e+15
A3: BAU Total Pollutant Emissions by Sector[electricity sector,CO2] : MostRecentRun | B3: 4.12478e+15 | C3: 4.11613e+15 | D3: 4.37221e+15 | E3: 4.58051e+15 | F3: 4.77903e+15 | G3: 4.95852e+15 | H3: 5.11363e+15 | I3: 5.28148e+15 | J3: 5.32857e+15 | K3: 5.36378e+15 | L3: 5.38991e+15 | M3: 5.41081e+15 | N3: 5.30724e+15 | O3: 5.20366e+15 | P3: 5.08351e+15 | Q3: 4.96016e+15 | R3: 4.82869e+15 | S3: 4.68984e+15 | T3: 4.54309e+15 | U3: 4.39025e+15 | V3: 4.23343e+15 | W3: 4.073e+15 | X3: 3.90865e+15 | Y3: 3.74036e+15 | Z3: 3.56864e+15 | AA3: 3.39268e+15 | AB3: 3.2145e+15 | AC3: 3.03485e+15 | AD3: 2.85814e+15 | AE3: 2.67708e+15 | AF3: 2.49737e+15 | AG3: 2.31996e+15 | AH3: 2.14294e+15 | AI3: 1.97071e+15 | AJ3: 1.80155e+15 | AK3: 1.63731e+15 | AL3: 1.48488e+15 | AM3: 1.35207e+15
A4: BAU Total Pollutant Emissions by Sector[residential buildings sector,CO2] : MostRecentRun | B4: 320220000000000 | C4: 320086000000000 | D4: 319575000000000 | E4: 318393000000000 | F4: 317364000000000 | G4: 316948000000000 | H4: 316077000000000 | I4: 315547000000000 | J4: 314655000000000 | K4: 312747000000000 | L4: 312025000000000 | M4: 310026000000000 | N4: 307479000000000 | O4: 304607000000000 | P4: 302808000000000 | Q4: 300963000000000 | R4: 300345000000000 | S4: 297842000000000 | T4: 295276000000000 | U4: 293127000000000 | V4: 290985000000000 | W4: 289517000000000 | X4: 287299000000000 | Y4: 284571000000000 | Z4: 280852000000000 | AA4: 278447000000000 | AB4: 275899000000000 | AC4: 272326000000000 | AD4: 269124000000000 | AE4: 265234000000000 | AF4: 260605000000000 | AG4: 256636000000000 | AH4: 253255000000000 | AI4: 248454000000000 | AJ4: 243623000000000 | AK4: 238871000000000 | AL4: 234056000000000 | AM4: 263523000000000
A5: BAU Total Pollutant Emissions by Sector[commercial buildings sector,CO2] : MostRecentRun | B5: 128319000000000 | C5: 131060000000000 | D5: 133418000000000 | E5: 135142000000000 | F5: 136808000000000 | G5: 138610000000000 | H5: 140341000000000 | I5: 141925000000000 | J5: 143650000000000 | K5: 145194000000000 | L5: 146737000000000 | M5: 148339000000000 | N5: 149636000000000 | O5: 150053000000000 | P5: 150620000000000 | Q5: 151111000000000 | R5: 151755000000000 | S5: 152087000000000 | T5: 152087000000000 | U5: 152087000000000 | V5: 152113000000000 | W5: 152113000000000 | X5: 151961000000000 | Y5: 151714000000000 | Z5: 151176000000000 | AA5: 150920000000000 | AB5: 150512000000000 | AC5: 149979000000000 | AD5: 149072000000000 | AE5: 148192000000000 | AF5: 147396000000000 | AG5: 146428000000000 | AH5: 145463000000000 | AI5: 144182000000000 | AJ5: 142913000000000 | AK5: 141614000000000 | AL5: 140342000000000 | AM5: 158751000000000
A6: BAU Total Pollutant Emissions by Sector[industry sector,CO2] : MostRecentRun | B6: 4.26291e+15 | C6: 4.26478e+15 | D6: 4.40176e+15 | E6: 4.43171e+15 | F6: 4.45878e+15 | G6: 4.47937e+15 | H6: 4.49566e+15 | I6: 4.51935e+15 | J6: 4.4912e+15 | K6: 4.46503e+15 | L6: 4.43891e+15 | M6: 4.42273e+15 | N6: 4.39809e+15 | O6: 4.36052e+15 | P6: 4.31101e+15 | Q6: 4.26965e+15 | R6: 4.22902e+15 | S6: 4.18747e+15 | T6: 4.12722e+15 | U6: 4.06865e+15 | V6: 4.00771e+15 | W6: 3.94801e+15 | X6: 3.88752e+15 | Y6: 3.83607e+15 | Z6: 3.77492e+15 | AA6: 3.72291e+15 | AB6: 3.66459e+15 | AC6: 3.6062e+15 | AD6: 3.55176e+15 | AE6: 3.49628e+15 | AF6: 3.43837e+15 | AG6: 3.38213e+15 | AH6: 3.3237e+15 | AI6: 3.27666e+15 | AJ6: 3.23109e+15 | AK6: 3.18295e+15 | AL6: 3.13373e+15 | AM6: 3.08161e+15
A7: BAU Total Pollutant Emissions by Sector[district heat and hydrogen sector,CO2] : MostRecentRun | B7: 600222000000000 | C7: 616358000000000 | D7: 633633000000000 | E7: 647841000000000 | F7: 662564000000000 | G7: 677144000000000 | H7: 693462000000000 | I7: 709302000000000 | J7: 721879000000000 | K7: 735863000000000 | L7: 744552000000000 | M7: 752828000000000 | N7: 761290000000000 | O7: 763774000000000 | P7: 766685000000000 | Q7: 769942000000000 | R7: 772370000000000 | S7: 775623000000000 | T7: 776438000000000 | U7: 775766000000000 | V7: 776644000000000 | W7: 777723000000000 | X7: 778102000000000 | Y7: 777035000000000 | Z7: 777592000000000 | AA7: 776772000000000 | AB7: 776016000000000 | AC7: 776710000000000 | AD7: 774519000000000 | AE7: 773040000000000 | AF7: 771675000000000 | AG7: 770594000000000 | AH7: 768535000000000 | AI7: 767628000000000 | AJ7: 766836000000000 | AK7: 765412000000000 | AL7: 764118000000000 | AM7: 784891000000000
A8: BAU Total Pollutant Emissions by Sector[LULUCF sector,CO2] : MostRecentRun | B8: -434000000000000 | C8: -434000000000000 | D8: -434000000000000 | E8: -434000000000000 | F8: -434000000000000 | G8: -434000000000000 | H8: -434000000000000 | I8: -434000000000000 | J8: -434000000000000 | K8: -434000000000000 | L8: -434000000000000 | M8: -434000000000000 | N8: -434000000000000 | O8: -434000000000000 | P8: -434000000000000 | Q8: -434000000000000 | R8: -434000000000000 | S8: -434000000000000 | T8: -434000000000000 | U8: -434000000000000 | V8: -434000000000000 | W8: -434000000000000 | X8: -434000000000000 | Y8: -434000000000000 | Z8: -434000000000000 | AA8: -434000000000000 | AB8: -434000000000000 | AC8: -434000000000000 | AD8: -434000000000000 | AE8: -434000000000000 | AF8: -434000000000000 | AG8: -434000000000000 | AH8: -434000000000000 | AI8: -434000000000000 | AJ8: -434000000000000 | AK8: -434000000000000 | AL8: -434000000000000 | AM8: -434000000000000
A9: BAU Total Pollutant Emissions by Sector[geoengineering sector,CO2] : MostRecentRun | B9: 0 | C9: 0 | D9: 0 | E9: 0 | F9: 0 | G9: 0 | H9: 0 | I9: 0 | J9: 0 | K9: 0 | L9: 0 | M9: 0 | N9: 0 | O9: 0 | P9: 0 | Q9: 0 | R9: 0 | S9: 0 | T9: 0 | U9: 0 | V9: 0 | W9: 0 | X9: 0 | Y9: 0 | Z9: 0 | AA9: 0 | AB9: 0 | AC9: 0 | AD9: 0 | AE9: 0 | AF9: 0 | AG9: 0 | AH9: 0 | AI9: 0 | AJ9: 0 | AK9: 0 | AL9: 0 | AM9: 0
A11: Time (Year) | B11: 2023 | C11: 2024 | D11: 2025 | E11: 2026 | F11: 2027 | G11: 2028 | H11: 2029 | I11: 2030 | J11: 2031 | K11: 2032 | L11: 2033 | M11: 2034 | N11: 2035 | O11: 2036 | P11: 2037 | Q11: 2038 | R11: 2039 | S11: 2040 | T11: 2041 | U11: 2042 | V11: 2043 | W11: 2044 | X11: 2045 | Y11: 2046 | Z11: 2047 | AA11: 2048 | AB11: 2049 | AC11: 2050 | AD11: 2051 | AE11: 2052 | AF11: 2053 | AG11: 2054 | AH11: 2055 | AI11: 2056 | AJ11: 2057 | AK11: 2058 | AL11: 2059 | AM11: 2060
A12: BAU District Heating Pollutant Emissions Summed Across Fuels[CO2] : MostRecentRun | B12: 597593000000000 | C12: 612539000000000 | D12: 628023000000000 | E12: 640035000000000 | F12: 652058000000000 | G12: 663311000000000 | H12: 675533000000000 | I12: 686299000000000 | J12: 693027000000000 | K12: 699820000000000 | L12: 705671000000000 | M12: 711419000000000 | N12: 717784000000000 | O12: 718042000000000 | P12: 718609000000000 | Q12: 719268000000000 | R12: 718940000000000 | S12: 719300000000000 | T12: 717424000000000 | U12: 713956000000000 | V12: 711913000000000 | W12: 709937000000000 | X12: 707142000000000 | Y12: 702765000000000 | Z12: 699922000000000 | AA12: 695555000000000 | AB12: 691164000000000 | AC12: 688098000000000 | AD12: 682347000000000 | AE12: 677197000000000 | AF12: 672022000000000 | AG12: 666981000000000 | AH12: 660769000000000 | AI12: 655551000000000 | AJ12: 650225000000000 | AK12: 644050000000000 | AL12: 637762000000000 | AM12: 653261000000000
A14: Time (Year) | B14: 2023 | C14: 2024 | D14: 2025 | E14: 2026 | F14: 2027 | G14: 2028 | H14: 2029 | I14: 2030 | J14: 2031 | K14: 2032 | L14: 2033 | M14: 2034 | N14: 2035 | O14: 2036 | P14: 2037 | Q14: 2038 | R14: 2039 | S14: 2040 | T14: 2041 | U14: 2042 | V14: 2043 | W14: 2044 | X14: 2045 | Y14: 2046 | Z14: 2047 | AA14: 2048 | AB14: 2049 | AC14: 2050 | AD14: 2051 | AE14: 2052 | AF14: 2053 | AG14: 2054 | AH14: 2055 | AI14: 2056 | AJ14: 2057 | AK14: 2058 | AL14: 2059 | AM14: 2060
... A56: BAU Process Emissions after CCS[construction 41T43,CO2] : MostRecentRun | B56: 0 | C56: 0 | D56: 0 | E56: 0 | F56: 0 | G56: 0 | H56: 0 | I56: 0 | J56: 0 | K56: 0 | L56: 0 | M56: 0 | N56: 0 | O56: 0 | P56: 0 | Q56: 0 | R56: 0 | S56: 0 | T56: 0 | U56: 0 | V56: 0 | W56: 0 | X56: 0 | Y56: 0 | Z56: 0 | AA56: 0 | AB56: 0 | AC56: 0 | AD56: 0 | AE56: 0 | AF56: 0 | AG56: 0 | AH56: 0 | AI56: 0 | AJ56: 0 | AK56: 0 | AL56: 0 | AM56: 0

Sheet 二氧化碳排放
A1: Time (Year) | B1: 2023 | C1: 2024 | D1: 2025 | E1: 2026 | F1: 2027 | G1: 2028 | H1: 2029 | I1: 2030 | J1: 2031 | K1: 2032 | L1: 2033 | M1: 2034 | N1: 2035 | O1: 2036 | P1: 2037 | Q1: 2038 | R1: 2039 | S1: 2040 | T1: 2041 | U1: 2042 | V1: 2043 | W1: 2044 | X1: 2045 | Y1: 2046 | Z1: 2047 | AA1: 2048 | AB1: 2049 | AC1: 2050 | AD1: 2051 | AE1: 2052 | AF1: 2053 | AG1: 2054 | AH1: 2055 | AI1: 2056 | AJ1: 2057 | AK1: 2058 | AL1: 2059 | AM1: 2060
A2: Total Pollutant Emissions by Sector[transportation sector,CO2] : MostRecentRun | B2: 1.56359e+15 | C2: 1.55767e+15 | D2: 1.55182e+15 | E2: 1.54621e+15 | F2: 1.53937e+15 | G2: 1.53141e+15 | H2: 1.52196e+15 | I2: 1.51044e+15 | J2: 1.4872e+15 | K2: 1.46233e+15 | L2: 1.44024e+15 | M2: 1.41813e+15 | N2: 1.39541e+15 | O2: 1.37745e+15 | P2: 1.35706e+15 | Q2: 1.33217e+15 | R2: 1.31018e+15 | S2: 1.29081e+15 | T2: 1.2679e+15 | U2: 1.24707e+15 | V2: 1.22855e+15 | W2: 1.21227e+15 | X2: 1.19837e+15 | Y2: 1.19008e+15 | Z2: 1.18407e+15 | AA2: 1.18026e+15 | AB2: 1.1775e+15 | AC2: 1.17606e+15 | AD2: 1.17004e+15 | AE2: 1.16487e+15 | AF2: 1.16016e+15 | AG2: 1.15566e+15 | AH2: 1.15135e+15 | AI2: 1.14736e+15 | AJ2: 1.14339e+15 | AK2: 1.13937e+15 | AL2: 1.13524e+15 | AM2: 1.13117e+15
A3: Total Pollutant Emissions by Sector[electricity sector,CO2] : MostRecentRun | B3: 4.12478e+15 | C3: 4.11613e+15 | D3: 4.37224e+15 | E3: 4.58054e+15 | F3: 4.77911e+15 | G3: 4.95862e+15 | H3: 5.11375e+15 | I3: 5.28159e+15 | J3: 5.32866e+15 | K3: 5.36389e+15 | L3: 5.39001e+15 | M3: 5.41082e+15 | N3: 5.30724e+15 | O3: 5.20366e+15 | P3: 5.08351e+15 | Q3: 4.96016e+15 | R3: 4.8287e+15 | S3: 4.68984e+15 | T3: 4.5431e+15 | U3: 4.39018e+15 | V3: 4.23343e+15 | W3: 4.073e+15 | X3: 3.90865e+15 | Y3: 3.74036e+15 | Z3: 3.56865e+15 | AA3: 3.39269e+15 | AB3: 3.21451e+15 | AC3: 3.03485e+15 | AD3: 2.85814e+15 | AE3: 2.67708e+15 | AF3: 2.49737e+15 | AG3: 2.31997e+15 | AH3: 2.14294e+15 | AI3: 1.97072e+15 | AJ3: 1.80155e+15 | AK3: 1.63731e+15 | AL3: 1.48493e+15 | AM3: 1.35208e+15
A4: Total Pollutant Emissions by Sector[residential buildings sector,CO2] : MostRecentRun | B4: 320220000000000 | C4: 320086000000000 | D4: 319575000000000 | E4: 318393000000000 | F4: 317364000000000 | G4: 316948000000000 | H4: 316077000000000 | I4: 315547000000000 | J4: 314655000000000 | K4: 312747000000000 | L4: 312025000000000 | M4: 310026000000000 | N4: 307479000000000 | O4: 304607000000000 | P4: 302808000000000 | Q4: 300963000000000 | R4: 300345000000000 | S4: 297842000000000 | T4: 295276000000000 | U4: 293127000000000 | V4: 290985000000000 | W4: 289517000000000 | X4: 287299000000000 | Y4: 284571000000000 | Z4: 280852000000000 | AA4: 278447000000000 | AB4: 275899000000000 | AC4: 272326000000000 | AD4: 269124000000000 | AE4: 265234000000000 | AF4: 260605000000000 | AG4: 256636000000000 | AH4: 253255000000000 | AI4: 248454000000000 | AJ4: 243623000000000 | AK4: 238871000000000 | AL4: 234056000000000 | AM4: 263523000000000
A5: Total Pollutant Emissions by Sector[commercial buildings sector,CO2] : MostRecentRun | B5: 128319000000000 | C5: 131060000000000 | D5: 133418000000000 | E5: 135142000000000 | F5: 136808000000000 | G5: 138610000000000 | H5: 140341000000000 | I5: 141925000000000 | J5: 143650000000000 | K5: 145194000000000 | L5: 146737000000000 | M5: 148339000000000 | N5: 149636000000000 | O5: 150053000000000 | P5: 150620000000000 | Q5: 151111000000000 | R5: 151755000000000 | S5: 152087000000000 | T5: 152087000000000 | U5: 152087000000000 | V5: 152113000000000 | W5: 152113000000000 | X5: 151961000000000 | Y5: 151714000000000 | Z5: 151176000000000 | AA5: 150920000000000 | AB5: 150512000000000 | AC5: 149979000000000 | AD5: 149072000000000 | AE5: 148192000000000 | AF5: 147396000000000 | AG5: 146428000000000 | AH5: 145463000000000 | AI5: 144182000000000 | AJ5: 142913000000000 | AK5: 141614000000000 | AL5: 140342000000000 | AM5: 158751000000000
A6: Total Pollutant Emissions by Sector[industry sector,CO2] : MostRecentRun | B6: 4.26291e+15 | C6: 4.26478e+15 | D6: 4.40176e+15 | E6: 4.43171e+15 | F6: 4.45878e+15 | G6: 4.47938e+15 | H6: 4.49567e+15 | I6: 4.51937e+15 | J6: 4.49122e+15 | K6: 4.46505e+15 | L6: 4.43893e+15 | M6: 4.42276e+15 | N6: 4.39811e+15 | O6: 4.36055e+15 | P6: 4.31104e+15 | Q6: 4.26967e+15 | R6: 4.22904e+15 | S6: 4.1875e+15 | T6: 4.12725e+15 | U6: 4.06868e+15 | V6: 4.00774e+15 | W6: 3.94804e+15 | X6: 3.88754e+15 | Y6: 3.8361e+15 | Z6: 3.77495e+15 | AA6: 3.72294e+15 | AB6: 3.66462e+15 | AC6: 3.60623e+15 | AD6: 3.55179e+15 | AE6: 3.4963e+15 | AF6: 3.43839e+15 | AG6: 3.38215e+15 | AH6: 3.32372e+15 | AI6: 3.27668e+15 | AJ6: 3.23111e+15 | AK6: 3.18297e+15 | AL6: 3.13375e+15 | AM6: 3.08162e+15
A7: Total Pollutant Emissions by Sector[district heat and hydrogen sector,CO2] : MostRecentRun | B7: 600222000000000 | C7: 616358000000000 | D7: 633633000000000 | E7: 647841000000000 | F7: 662564000000000 | G7: 677144000000000 | H7: 693463000000000 | I7: 709303000000000 | J7: 721881000000000 | K7: 735865000000000 | L7: 744554000000000 | M7: 752830000000000 | N7: 761292000000000 | O7: 763776000000000 | P7: 766688000000000 | Q7: 769945000000000 | R7: 772373000000000 | S7: 775626000000000 | T7: 776440000000000 | U7: 775769000000000 | V7: 776647000000000 | W7: 777727000000000 | X7: 778104000000000 | Y7: 777039000000000 | Z7: 777593000000000 | AA7: 776778000000000 | AB7: 776016000000000 | AC7: 776717000000000 | AD7: 774516000000000 | AE7: 773053000000000 | AF7: 771663000000000 | AG7: 770624000000000 | AH7: 768493000000000 | AI7: 767711000000000 | AJ7: 766694000000000 | AK7: 765690000000000 | AL7: 763611000000000 | AM7: 785980000000000
A8: Total Pollutant Emissions by Sector[LULUCF sector,CO2] : MostRecentRun | B8: -434000000000000 | C8: -434000000000000 | D8: -434000000000000 | E8: -434000000000000 | F8: -434000000000000 | G8: -434000000000000 | H8: -434000000000000 | I8: -434000000000000 | J8: -434000000000000 | K8: -434000000000000 | L8: -434000000000000 | M8: -434000000000000 | N8: -434000000000000 | O8: -434000000000000 | P8: -434000000000000 | Q8: -434000000000000 | R8: -434000000000000 | S8: -434000000000000 | T8: -434000000000000 | U8: -434000000000000 | V8: -434000000000000 | W8: -434000000000000 | X8: -434000000000000 | Y8: -434000000000000 | Z8: -434000000000000 | AA8: -434000000000000 | AB8: -434000000000000 | AC8: -434000000000000 | AD8: -434000000000000 | AE8: -434000000000000 | AF8: -434000000000000 | AG8: -434000000000000 | AH8: -434000000000000 | AI8: -434000000000000 | AJ8: -434000000000000 | AK8: -434000000000000 | AL8: -434000000000000 | AM8: -434000000000000
A9: Total Pollutant Emissions by Sector[geoengineering sector,CO2] : MostRecentRun | B9: 0 | C9: 0 | D9: 0 | E9: 0 | F9: 0 | G9: 0 | H9: 0 | I9: 0 | J9: 0 | K9: 0 | L9: 0 | M9: 0 | N9: 0 | O9: 0 | P9: 0 | Q9: 0 | R9: 0 | S9: 0 | T9: 0 | U9: 0 | V9: 0 | W9: 0 | X9: 0 | Y9: 0 | Z9: 0 | AA9: 0 | AB9: 0 | AC9: 0 | AD9: 0 | AE9: 0 | AF9: 0 | AG9: 0 | AH9: 0 | AI9: 0 | AJ9: 0 | AK9: 0 | AL9: 0 | AM9: 0
A11: Time (Year) | B11: 2023 | C11: 2024 | D11: 2025 | E11: 2026 | F11: 2027 | G11: 2028 | H11: 2029 | I11: 2030 | J11: 2031 | K11: 2032 | L11: 2033 | M11: 2034 | N11: 2035 | O11: 2036 | P11: 2037 | Q11: 2038 | R11: 2039 | S11: 2040 | T11: 2041 | U11: 2042 | V11: 2043 | W11: 2044 | X11: 2045 | Y11: 2046 | Z11: 2047 | AA11: 2048 | AB11: 2049 | AC11: 2050 | AD11: 2051 | AE11: 2052 | AF11: 2053 | AG11: 2054 | AH11: 2055 | AI11: 2056 | AJ11: 2057 | AK11: 2058 | AL11: 2059 | AM11: 2060
A12: District Heating Pollutant Emissions Summed Across Fuels[CO2] : MostRecentRun | B12: 597593000000000 | C12: 612539000000000 | D12: 628023000000000 | E12: 640035000000000 | F12: 652058000000000 | G12: 663311000000000 | H12: 675534000000000 | I12: 686300000000000 | J12: 693028000000000 | K12: 699822000000000 | L12: 705673000000000 | M12: 711421000000000 | N12: 717786000000000 | O12: 718044000000000 | P12: 718612000000000 | Q12: 719271000000000 | R12: 718943000000000 | S12: 719303000000000 | T12: 717427000000000 | U12: 713959000000000 | V12: 711917000000000 | W12: 709941000000000 | X12: 707145000000000 | Y12: 702769000000000 | Z12: 699925000000000 | AA12: 695558000000000 | AB12: 691167000000000 | AC12: 688101000000000 | AD12: 682351000000000 | AE12: 677200000000000 | AF12: 672025000000000 | AG12: 666984000000000 | AH12: 660772000000000 | AI12: 655554000000000 | AJ12: 650228000000000 | AK12: 644053000000000 | AL12: 637766000000000 | AM12: 653262000000000
A14: Time (Year) | B14: 2023 | C14: 2024 | D14: 2025 | E14: 2026 | F14: 2027 | G14: 2028 | H14: 2029 | I14: 2030 | J14: 2031 | K14: 2032 | L14: 2033 | M14: 2034 | N14: 2035 | O14: 2036 | P14: 2037 | Q14: 2038 | R14: 2039 | S14: 2040 | T14: 2041 | U14: 2042 | V14: 2043 | W14: 2044 | X14: 2045 | Y14: 2046 | Z14: 2047 | AA14: 2048 | AB14: 2049 | AC14: 2050 | AD14: 2051 | AE14: 2052 | AF14: 2053 | AG14: 2054 | AH14: 2055 | AI14: 2056 | AJ14: 2057 | AK14: 2058 | AL14: 2059 | AM14: 2060
... A56: Process Emissions after CCS[construction 41T43,CO2] : MostRecentRun | B56: 0 | C56: 0 | D56: 0 | E56: 0 | F56: 0 | G56: 0 | H56: 0 | I56: 0 | J56: 0 | K56: 0 | L56: 0 | M56: 0 | N56: 0 | O56: 0 | P56: 0 | Q56: 0 | R56: 0 | S56: 0 | T56: 0 | U56: 0 | V56: 0 | W56: 0 | X56: 0 | Y56: 0 | Z56: 0 | AA56: 0 | AB56: 0 | AC56: 0 | AD56: 0 | AE56: 0 | AF56: 0 | AG56: 0 | AH56: 0 | AI56: 0 | AJ56: 0 | AK56: 0 | AL56: 0 | AM56: 0

Sheet 图3，4-一次能源消费量
A1: vehicle type | C1: display unit | D1: btu | E1: 万吨标煤 | G1: Primary Energy Use by Sector | K1: Total Primary Energy Use by Fuel
A2: passenger | D2: 1 | E2: 3.6008786e-12 | G2: 分部门一次能源消费量 | K2: 分品种一次能源消费量
C3: 2023 | D3: =C3+1 -> 2024 | E3: =D3+1 -> 2025 | F3: =E3+1 -> 2026 | G3: =F3+1 -> 2027 | H3: =G3+1 -> 2028 | I3: =H3+1 -> 2029 | J3: =I3+1 -> 2030 | K3: =J3+1 -> 2031 | ... AN3: =AM3+1 -> 2060
A4: Transportation | B4: =VLOOKUP(A4,$J$30:$K$38,2,FALSE) -> 交通部门 | C4: =SUMIFS(一次燃料消费!D:D,一次燃料消费!$A:$A,$A4)*$E$2 -> 75662.667 | D4: =SUMIFS(一次燃料消费!E:E,一次燃料消费!$A:$A,'图3，4-一次能源消费量'!$A4)*$E$2 -> 75376.362 | E4: =SUMIFS(一次燃料消费!F:F,一次燃料消费!$A:$A,'图3，4-一次能源消费量'!$A4)*$E$2 -> 75091.574 | F4: =SUMIFS(一次燃料消费!G:G,一次燃料消费!$A:$A,'图3，4-一次能源消费量'!$A4)*$E$2 -> 74820.203 | G4: =SUMIFS(一次燃料消费!H:H,一次燃料消费!$A:$A,'图3，4-一次能源消费量'!$A4)*$E$2 -> 74490.94 | H4: =SUMIFS(一次燃料消费!I:I,一次燃料消费!$A:$A,'图3，4-一次能源消费量'!$A4)*$E$2 -> 74109.376 | I4: =SUMIFS(一次燃料消费!J:J,一次燃料消费!$A:$A,'图3，4-一次能源消费量'!$A4)*$E$2 -> 73658.309 | J4: =SUMIFS(一次燃料消费!K:K,一次燃料消费!$A:$A,'图3，4-一次能源消费量'!$A4)*$E$2 -> 73109.321 | K4: =SUMIFS(一次燃料消费!L:L,一次燃料消费!$A:$A,'图3，4-一次能源消费量'!$A4)*$E$2 -> 71986.918 | L4: =SUMIFS(一次燃料消费!M:M,一次燃料消费!$A:$A,'图3，4-一次能源消费量'!$A4)*$E$2 -> 70790.02 | M4: =SUMIFS(一次燃料消费!N:N,一次燃料消费!$A:$A,'图3，4-一次能源消费量'!$A4)*$E$2 -> 69719.303 | N4: =SUMIFS(一次燃料消费!O:O,一次燃料消费!$A:$A,'图3，4-一次能源消费量'!$A4)*$E$2 -> 68656.192 | O4: =SUMIFS(一次燃料消费!P:P,一次燃料消费!$A:$A,'图3，4-一次能源消费量'!$A4)*$E$2 -> 67572.44 | P4: =SUMIFS(一次燃料消费!Q:Q,一次燃料消费!$A:$A,'图3，4-一次能源消费量'!$A4)*$E$2 -> 66720.993 | Q4: =SUMIFS(一次燃料消费!R:R,一次燃料消费!$A:$A,'图3，4-一次能源消费量'!$A4)*$E$2 -> 65754.543 | R4: =SUMIFS(一次燃料消费!S:S,一次燃料消费!$A:$A,'图3，4-一次能源消费量'!$A4)*$E$2 -> 64575.215 | S4: =SUMIFS(一次燃料消费!T:T,一次燃料消费!$A:$A,'图3，4-一次能源消费量'!$A4)*$E$2 -> 63540.135 | T4: =SUMIFS(一次燃料消费!U:U,一次燃料消费!$A:$A,'图3，4-一次能源消费量'!$A4)*$E$2 -> 62634.079 | U4: =SUMIFS(一次燃料消费!V:V,一次燃料消费!$A:$A,'图3，4-一次能源消费量'!$A4)*$E$2 -> 61561.82 | V4: =SUMIFS(一次燃料消费!W:W,一次燃料消费!$A:$A,'图3，4-一次能源消费量'!$A4)*$E$2 -> 60593.126 | W4: =SUMIFS(一次燃料消费!X:X,一次燃料消费!$A:$A,'图3，4-一次能源消费量'!$A4)*$E$2 -> 59738.353 | X4: =SUMIFS(一次燃料消费!Y:Y,一次燃料消费!$A:$A,'图3，4-一次能源消费量'!$A4)*$E$2 -> 58995.466 | Y4: =SUMIFS(一次燃料消费!Z:Z,一次燃料消费!$A:$A,'图3，4-一次能源消费量'!$A4)*$E$2 -> 58368.741 | Z4: =SUMIFS(一次燃料消费!AA:AA,一次燃料消费!$A:$A,'图3，4-一次能源消费量'!$A4)*$E$2 -> 58011.663 | AA4: =SUMIFS(一次燃料消费!AB:AB,一次燃料消费!$A:$A,'图3，4-一次能源消费量'!$A4)*$E$2 -> 57766.13 | AB4: =SUMIFS(一次燃料消费!AC:AC,一次燃料消费!$A:$A,'图3，4-一次能源消费量'!$A4)*$E$2 -> 57626.193 | AC4: =SUMIFS(一次燃料消费!AD:AD,一次燃料消费!$A:$A,'图3，4-一次能源消费量'!$A4)*$E$2 -> 57537.809 | AD4: =SUMIFS(一次燃料消费!AE:AE,一次燃料消费!$A:$A,'图3，4-一次能源消费量'!$A4)*$E$2 -> 57512.164 | AE4: =SUMIFS(一次燃料消费!AF:AF,一次燃料消费!$A:$A,'图3，4-一次能源消费量'!$A4)*$E$2 -> 57262.504 | AF4: =SUMIFS(一次燃料消费!AG:AG,一次燃料消费!$A:$A,'图3，4-一次能源消费量'!$A4)*$E$2 -> 57052.238 | AG4: =SUMIFS(一次燃料消费!AH:AH,一次燃料消费!$A:$A,'图3，4-一次能源消费量'!$A4)*$E$2 -> 56862.533 | AH4: =SUMIFS(一次燃料消费!AI:AI,一次燃料消费!$A:$A,'图3，4-一次能源消费量'!$A4)*$E$2 -> 56682.237 | AI4: =SUMIFS(一次燃料消费!AJ:AJ,一次燃料消费!$A:$A,'图3，4-一次能源消费量'!$A4)*$E$2 -> 56511.494 | AJ4: =SUMIFS(一次燃料消费!AK:AK,一次燃料消费!$A:$A,'图3，4-一次能源消费量'!$A4)*$E$2 -> 56353.311 | AK4: =SUMIFS(一次燃料消费!AL:AL,一次燃料消费!$A:$A,'图3，4-一次能源消费量'!$A4)*$E$2 -> 56195.956 | AL4: =SUMIFS(一次燃料消费!AM:AM,一次燃料消费!$A:$A,'图3，4-一次能源消费量'!$A4)*$E$2 -> 56036.016 | AM4: =SUMIFS(一次燃料消费!AN:AN,一次燃料消费!$A:$A,'图3，4-一次能源消费量'!$A4)*$E$2 -> 55869.907 | AN4: =SUMIFS(一次燃料消费!AO:AO,一次燃料消费!$A:$A,'图3，4-一次能源消费量'!$A4)*$E$2 -> 55706.672
A5: electricity | B5: =VLOOKUP(A5,$J$30:$K$38,2,FALSE) -> 电力部门 | C5: =SUMIFS(一次燃料消费!D:D,一次燃料消费!$A:$A,$A5)*$E$2+C47+C49+C53+C59+C66 -> 271862.85 | D5: =SUMIFS(一次燃料消费!E:E,一次燃料消费!$A:$A,$A5)*$E$2+D47+D49+D53+D59+D66 -> 275883.01 | E5: =SUMIFS(一次燃料消费!F:F,一次燃料消费!$A:$A,$A5)*$E$2+E47+E49+E53+E59+E66 -> 291278.95 | F5: =SUMIFS(一次燃料消费!G:G,一次燃料消费!$A:$A,$A5)*$E$2+F47+F49+F53+F59+F66 -> 305068.76 | G5: =SUMIFS(一次燃料消费!H:H,一次燃料消费!$A:$A,$A5)*$E$2+G47+G49+G53+G59+G66 -> 318752.43 | H5: =SUMIFS(一次燃料消费!I:I,一次燃料消费!$A:$A,$A5)*$E$2+H47+H49+H53+H59+H66 -> 331138.22 | I5: =SUMIFS(一次燃料消费!J:J,一次燃料消费!$A:$A,$A5)*$E$2+I47+I49+I53+I59+I66 -> 342425.64 | J5: =SUMIFS(一次燃料消费!K:K,一次燃料消费!$A:$A,$A5)*$E$2+J47+J49+J53+J59+J66 -> 354129.85 | K5: =SUMIFS(一次燃料消费!L:L,一次燃料消费!$A:$A,$A5)*$E$2+K47+K49+K53+K59+K66 -> 364158.39 | L5: =SUMIFS(一次燃料消费!M:M,一次燃料消费!$A:$A,$A5)*$E$2+L47+L49+L53+L59+L66 -> 374954.63 | M5: =SUMIFS(一次燃料消费!N:N,一次燃料消费!$A:$A,$A5)*$E$2+M47+M49+M53+M59+M66 -> 386271.1 | N5: =SUMIFS(一次燃料消费!O:O,一次燃料消费!$A:$A,$A5)*$E$2+N47+N49+N53+N59+N66 -> 397398.91 | O5: =SUMIFS(一次燃料消费!P:P,一次燃料消费!$A:$A,$A5)*$E$2+O47+O49+O53+O59+O66 -> 408981.75 | P5: =SUMIFS(一次燃料消费!Q:Q,一次燃料消费!$A:$A,$A5)*$E$2+P47+P49+P53+P59+P66 -> 419249.39 | Q5: =SUMIFS(一次燃料消费!R:R,一次燃料消费!$A:$A,$A5)*$E$2+Q47+Q49+Q53+Q59+Q66 -> 430280.55 | R5: =SUMIFS(一次燃料消费!S:S,一次燃料消费!$A:$A,$A5)*$E$2+R47+R49+R53+R59+R66 -> 442125.66 | S5: =SUMIFS(一次燃料消费!T:T,一次燃料消费!$A:$A,$A5)*$E$2+S47+S49+S53+S59+S66 -> 454367.3 | T5: =SUMIFS(一次燃料消费!U:U,一次燃料消费!$A:$A,$A5)*$E$2+T47+T49+T53+T59+T66 -> 466756.94 | U5: =SUMIFS(一次燃料消费!V:V,一次燃料消费!$A:$A,$A5)*$E$2+U47+U49+U53+U59+U66 -> 478348.03 | V5: =SUMIFS(一次燃料消费!W:W,一次燃料消费!$A:$A,$A5)*$E$2+V47+V49+V53+V59+V66 -> 490206.74 | W5: =SUMIFS(一次燃料消费!X:X,一次燃料消费!$A:$A,$A5)*$E$2+W47+W49+W53+W59+W66 -> 501520.02 | X5: =SUMIFS(一次燃料消费!Y:Y,一次燃料消费!$A:$A,$A5)*$E$2+X47+X49+X53+X59+X66 -> 512867.73 | Y5: =SUMIFS(一次燃料消费!Z:Z,一次燃料消费!$A:$A,$A5)*$E$2+Y47+Y49+Y53+Y59+Y66 -> 523802.81 | Z5: =SUMIFS(一次燃料消费!AA:AA,一次燃料消费!$A:$A,$A5)*$E$2+Z47+Z49+Z53+Z59+Z66 -> 534323.34 | AA5: =SUMIFS(一次燃料消费!AB:AB,一次燃料消费!$A:$A,$A5)*$E$2+AA47+AA49+AA53+AA59+AA66 -> 544423.09 | AB5: =SUMIFS(一次燃料消费!AC:AC,一次燃料消费!$A:$A,$A5)*$E$2+AB47+AB49+AB53+AB59+AB66 -> 554663.94 | AC5: =SUMIFS(一次燃料消费!AD:AD,一次燃料消费!$A:$A,$A5)*$E$2+AC47+AC49+AC53+AC59+AC66 -> 562888.22 | AD5: =SUMIFS(一次燃料消费!AE:AE,一次燃料消费!$A:$A,$A5)*$E$2+AD47+AD49+AD53+AD59+AD66 -> 571679.5 | AE5: =SUMIFS(一次燃料消费!AF:AF,一次燃料消费!$A:$A,$A5)*$E$2+AE47+AE49+AE53+AE59+AE66 -> 578895.9 | AF5: =SUMIFS(一次燃料消费!AG:AG,一次燃料消费!$A:$A,$A5)*$E$2+AF47+AF49+AF53+AF59+AF66 -> 584816.36 | AG5: =SUMIFS(一次燃料消费!AH:AH,一次燃料消费!$A:$A,$A5)*$E$2+AG47+AG49+AG53+AG59+AG66 -> 590909.42 | AH5: =SUMIFS(一次燃料消费!AI:AI,一次燃料消费!$A:$A,$A5)*$E$2+AH47+AH49+AH53+AH59+AH66 -> 595725.62 | AI5: =SUMIFS(一次燃料消费!AJ:AJ,一次燃料消费!$A:$A,$A5)*$E$2+AI47+AI49+AI53+AI59+AI66 -> 600188.8 | AJ5: =SUMIFS(一次燃料消费!AK:AK,一次燃料消费!$A:$A,$A5)*$E$2+AJ47+AJ49+AJ53+AJ59+AJ66 -> 603528.34 | AK5: =SUMIFS(一次燃料消费!AL:AL,一次燃料消费!$A:$A,$A5)*$E$2+AK47+AK49+AK53+AK59+AK66 -> 605967.24 | AL5: =SUMIFS(一次燃料消费!AM:AM,一次燃料消费!$A:$A,$A5)*$E$2+AL47+AL49+AL53+AL59+AL66 -> 606974.15 | AM5: =SUMIFS(一次燃料消费!AN:AN,一次燃料消费!$A:$A,$A5)*$E$2+AM47+AM49+AM53+AM59+AM66 -> 607208.82 | AN5: =SUMIFS(一次燃料消费!AO:AO,一次燃料消费!$A:$A,$A5)*$E$2+AN47+AN49+AN53+AN59+AN66 -> 616390.41
A6: residential | B6: =VLOOKUP(A6,$J$30:$K$38,2,FALSE) -> 居民建筑 | C6: =SUMIFS(一次燃料消费!D:D,一次燃料消费!$A:$A,$A6)*$E$2 -> 18116.157 | D6: =SUMIFS(一次燃料消费!E:E,一次燃料消费!$A:$A,'图3，4-一次能源消费量'!$A6)*$E$2 -> 18139.57 | E6: =SUMIFS(一次燃料消费!F:F,一次燃料消费!$A:$A,'图3，4-一次能源消费量'!$A6)*$E$2 -> 18138.821 | F6: =SUMIFS(一次燃料消费!G:G,一次燃料消费!$A:$A,'图3，4-一次能源消费量'!$A6)*$E$2 -> 18098.606 | G6: =SUMIFS(一次燃料消费!H:H,一次燃料消费!$A:$A,'图3，4-一次能源消费量'!$A6)*$E$2 -> 18060.693 | H6: =SUMIFS(一次燃料消费!I:I,一次燃料消费!$A:$A,'图3，4-一次能源消费量'!$A6)*$E$2 -> 18061.672 | I6: =SUMIFS(一次燃料消费!J:J,一次燃料消费!$A:$A,'图3，4-一次能源消费量'!$A6)*$E$2 -> 18037.802 | J6: =SUMIFS(一次燃料消费!K:K,一次燃料消费!$A:$A,'图3，4-一次能源消费量'!$A6)*$E$2 -> 18032.336 | K6: =SUMIFS(一次燃料消费!L:L,一次燃料消费!$A:$A,'图3，4-一次能源消费量'!$A6)*$E$2 -> 18004.757 | L6: =SUMIFS(一次燃料消费!M:M,一次燃料消费!$A:$A,'图3，4-一次能源消费量'!$A6)*$E$2 -> 17917.407 | M6: =SUMIFS(一次燃料消费!N:N,一次燃料消费!$A:$A,'图3，4-一次能源消费量'!$A6)*$E$2 -> 17902.107 | N6: =SUMIFS(一次燃料消费!O:O,一次燃料消费!$A:$A,'图3，4-一次能源消费量'!$A6)*$E$2 -> 17810.396 | O6: =SUMIFS(一次燃料消费!P:P,一次燃料消费!$A:$A,'图3，4-一次能源消费量'!$A6)*$E$2 -> 17688.369 | P6: =SUMIFS(一次燃料消费!Q:Q,一次燃料消费!$A:$A,'图3，4-一次能源消费量'!$A6)*$E$2 -> 17549.231 | Q6: =SUMIFS(一次燃料消费!R:R,一次燃料消费!$A:$A,'图3，4-一次能源消费量'!$A6)*$E$2 -> 17457.481 | R6: =SUMIFS(一次燃料消费!S:S,一次燃料消费!$A:$A,'图3，4-一次能源消费量'!$A6)*$E$2 -> 17366.49 | S6: =SUMIFS(一次燃料消费!T:T,一次燃料消费!$A:$A,'图3，4-一次能源消费量'!$A6)*$E$2 -> 17347.874 | T6: =SUMIFS(一次燃料消费!U:U,一次燃料消费!$A:$A,'图3，4-一次能源消费量'!$A6)*$E$2 -> 17217.522 | U6: =SUMIFS(一次燃料消费!V:V,一次燃料消费!$A:$A,'图3，4-一次能源消费量'!$A6)*$E$2 -> 17083.569 | V6: =SUMIFS(一次燃料消费!W:W,一次燃料消费!$A:$A,'图3，4-一次能源消费量'!$A6)*$E$2 -> 16971.582 | W6: =SUMIFS(一次燃料消费!X:X,一次燃料消费!$A:$A,'图3，4-一次能源消费量'!$A6)*$E$2 -> 16856.03 | X6: =SUMIFS(一次燃料消费!Y:Y,一次燃料消费!$A:$A,'图3，4-一次能源消费量'!$A6)*$E$2 -> 16784.408 | Y6: =SUMIFS(一次燃料消费!Z:Z,一次燃料消费!$A:$A,'图3，4-一次能源消费量'!$A6)*$E$2 -> 16668.784 | Z6: =SUMIFS(一次燃料消费!AA:AA,一次燃料消费!$A:$A,'图3，4-一次能源消费量'!$A6)*$E$2 -> 16519.668 | AA6: =SUMIFS(一次燃料消费!AB:AB,一次燃料消费!$A:$A,'图3，4-一次能源消费量'!$A6)*$E$2 -> 16318.343 | AB6: =SUMIFS(一次燃料消费!AC:AC,一次燃料消费!$A:$A,'图3，4-一次能源消费量'!$A6)*$E$2 -> 16191.588 | AC6: =SUMIFS(一次燃料消费!AD:AD,一次燃料消费!$A:$A,'图3，4-一次能源消费量'!$A6)*$E$2 -> 16058.68 | AD6: =SUMIFS(一次燃料消费!AE:AE,一次燃料消费!$A:$A,'图3，4-一次能源消费量'!$A6)*$E$2 -> 15859.872 | AE6: =SUMIFS(一次燃料消费!AF:AF,一次燃料消费!$A:$A,'图3，4-一次能源消费量'!$A6)*$E$2 -> 15689.439 | AF6: =SUMIFS(一次燃料消费!AG:AG,一次燃料消费!$A:$A,'图3，4-一次能源消费量'!$A6)*$E$2 -> 15474.427 | AG6: =SUMIFS(一次燃料消费!AH:AH,一次燃料消费!$A:$A,'图3，4-一次能源消费量'!$A6)*$E$2 -> 15218.509 | AH6: =SUMIFS(一次燃料消费!AI:AI,一次燃料消费!$A:$A,'图3，4-一次能源消费量'!$A6)*$E$2 -> 15003.388 | AI6: =SUMIFS(一次燃料消费!AJ:AJ,一次燃料消费!$A:$A,'图3，4-一次能源消费量'!$A6)*$E$2 -> 14820.316 | AJ6: =SUMIFS(一次燃料消费!AK:AK,一次燃料消费!$A:$A,'图3，4-一次能源消费量'!$A6)*$E$2 -> 14554.46 | AK6: =SUMIFS(一次燃料消费!AL:AL,一次燃料消费!$A:$A,'图3，4-一次能源消费量'!$A6)*$E$2 -> 14287.303 | AL6: =SUMIFS(一次燃料消费!AM:AM,一次燃料消费!$A:$A,'图3，4-一次能源消费量'!$A6)*$E$2 -> 14024.94 | AM6: =SUMIFS(一次燃料消费!AN:AN,一次燃料消费!$A:$A,'图3，4-一次能源消费量'!$A6)*$E$2 -> 13759.152 | AN6: =SUMIFS(一次燃料消费!AO:AO,一次燃料消费!$A:$A,'图3，4-一次能源消费量'!$A6)*$E$2 -> 15514.857
A7: commercial | B7: =VLOOKUP(A7,$J$30:$K$38,2,FALSE) -> 公共建筑 | C7: =SUMIFS(一次燃料消费!D:D,一次燃料消费!$A:$A,$A7)*$E$2 -> 6116.4524 | D7: =SUMIFS(一次燃料消费!E:E,一次燃料消费!$A:$A,'图3，4-一次能源消费量'!$A7)*$E$2 -> 6246.4441 | E7: =SUMIFS(一次燃料消费!F:F,一次燃料消费!$A:$A,'图3，4-一次能源消费量'!$A7)*$E$2 -> 6358.4315 | F7: =SUMIFS(一次燃料消费!G:G,一次燃料消费!$A:$A,'图3，4-一次能源消费量'!$A7)*$E$2 -> 6440.1714 | G7: =SUMIFS(一次燃料消费!H:H,一次燃料消费!$A:$A,'图3，4-一次能源消费量'!$A7)*$E$2 -> 6518.3105 | H7: =SUMIFS(一次燃料消费!I:I,一次燃料消费!$A:$A,'图3，4-一次能源消费量'!$A7)*$E$2 -> 6603.6513 | I7: =SUMIFS(一次燃料消费!J:J,一次燃料消费!$A:$A,'图3，4-一次能源消费量'!$A7)*$E$2 -> 6685.7513 | J7: =SUMIFS(一次燃料消费!K:K,一次燃料消费!$A:$A,'图3，4-一次能源消费量'!$A7)*$E$2 -> 6761.0097 | K7: =SUMIFS(一次燃料消费!L:L,一次燃料消费!$A:$A,'图3，4-一次能源消费量'!$A7)*$E$2 -> 6842.7496 | L7: =SUMIFS(一次燃料消费!M:M,一次燃料消费!$A:$A,'图3，4-一次能源消费量'!$A7)*$E$2 -> 6915.8475 | M7: =SUMIFS(一次燃料消费!N:N,一次燃料消费!$A:$A,'图3，4-一次能源消费量'!$A7)*$E$2 -> 6988.5852 | N7: =SUMIFS(一次燃料消费!O:O,一次燃料消费!$A:$A,'图3，4-一次能源消费量'!$A7)*$E$2 -> 7065.2839 | O7: =SUMIFS(一次燃料消费!P:P,一次燃料消费!$A:$A,'图3，4-一次能源消费量'!$A7)*$E$2 -> 7126.1388 | P7: =SUMIFS(一次燃料消费!Q:Q,一次燃料消费!$A:$A,'图3，4-一次能源消费量'!$A7)*$E$2 -> 7145.5835 | Q7: =SUMIFS(一次燃料消费!R:R,一次燃料消费!$A:$A,'图3，4-一次能源消费量'!$A7)*$E$2 -> 7172.23 | R7: =SUMIFS(一次燃料消费!S:S,一次燃料消费!$A:$A,'图3，4-一次能源消费量'!$A7)*$E$2 -> 7195.2756 | S7: =SUMIFS(一次燃料消费!T:T,一次燃料消费!$A:$A,'图3，4-一次能源消费量'!$A7)*$E$2 -> 7225.523 | T7: =SUMIFS(一次燃料消费!U:U,一次燃料消费!$A:$A,'图3，4-一次能源消费量'!$A7)*$E$2 -> 7240.6467 | U7: =SUMIFS(一次燃料消费!V:V,一次燃料消费!$A:$A,'图3，4-一次能源消费量'!$A7)*$E$2 -> 7241.0068 | V7: =SUMIFS(一次燃料消费!W:W,一次燃料消费!$A:$A,'图3，4-一次能源消费量'!$A7)*$E$2 -> 7241.0068 | W7: =SUMIFS(一次燃料消费!X:X,一次燃料消费!$A:$A,'图3，4-一次能源消费量'!$A7)*$E$2 -> 7240.6467 | X7: =SUMIFS(一次燃料消费!Y:Y,一次燃料消费!$A:$A,'图3，4-一次能源消费量'!$A7)*$E$2 -> 7240.6467 | Y7: =SUMIFS(一次燃料消费!Z:Z,一次燃料消费!$A:$A,'图3，4-一次能源消费量'!$A7)*$E$2 -> 7233.445 | Z7: =SUMIFS(一次燃料消费!AA:AA,一次燃料消费!$A:$A,'图3，4-一次能源消费量'!$A7)*$E$2 -> 7221.5621 | AA7: =SUMIFS(一次燃料消费!AB:AB,一次燃料消费!$A:$A,'图3，4-一次能源消费量'!$A7)*$E$2 -> 7194.9156 | AB7: =SUMIFS(一次燃料消费!AC:AC,一次燃料消费!$A:$A,'图3，4-一次能源消费量'!$A7)*$E$2 -> 7183.3927 | AC7: =SUMIFS(一次燃料消费!AD:AD,一次燃料消费!$A:$A,'图3，4-一次能源消费量'!$A7)*$E$2 -> 7163.5879 | AD7: =SUMIFS(一次燃料消费!AE:AE,一次燃料消费!$A:$A,'图3，4-一次能源消费量'!$A7)*$E$2 -> 7137.3015 | AE7: =SUMIFS(一次燃料消费!AF:AF,一次燃料消费!$A:$A,'图3，4-一次能源消费量'!$A7)*$E$2 -> 7095.1712 | AF7: =SUMIFS(一次燃料消费!AG:AG,一次燃料消费!$A:$A,'图3，4-一次能源消费量'!$A7)*$E$2 -> 7052.6809 | AG7: =SUMIFS(一次燃料消费!AH:AH,一次燃料消费!$A:$A,'图3，4-一次能源消费量'!$A7)*$E$2 -> 7014.5115 | AH7: =SUMIFS(一次燃料消费!AI:AI,一次燃料消费!$A:$A,'图3，4-一次能源消费量'!$A7)*$E$2 -> 6968.4203 | AI7: =SUMIFS(一次燃料消费!AJ:AJ,一次燃料消费!$A:$A,'图3，4-一次能源消费量'!$A7)*$E$2 -> 6922.6891 | AJ7: =SUMIFS(一次燃料消费!AK:AK,一次燃料消费!$A:$A,'图3，4-一次能源消费量'!$A7)*$E$2 -> 6861.1141 | AK7: =SUMIFS(一次燃料消费!AL:AL,一次燃料消费!$A:$A,'图3，4-一次能源消费量'!$A7)*$E$2 -> 6799.8992 | AL7: =SUMIFS(一次燃料消费!AM:AM,一次燃料消费!$A:$A,'图3，4-一次能源消费量'!$A7)*$E$2 -> 6739.0447 | AM7: =SUMIFS(一次燃料消费!AN:AN,一次燃料消费!$A:$A,'图3，4-一次能源消费量'!$A7)*$E$2 -> 6677.8298 | AN7: =SUMIFS(一次燃料消费!AO:AO,一次燃料消费!$A:$A,'图3，4-一次能源消费量'!$A7)*$E$2 -> 7545.6411
A8: industry | B8: =VLOOKUP(A8,$J$30:$K$38,2,FALSE) -> 工业燃料 | C8: =(SUMIFS(一次燃料消费!D:D,一次燃料消费!$A:$A,$A8)-SUM(工业非燃料使用!D$2:D$251))*$E$2 -> 129807.78 | D8: =(SUMIFS(一次燃料消费!E:E,一次燃料消费!$A:$A,'图3，4-一次能源消费量'!$A8)-SUM(工业非燃料使用!E$2:E$251))*$E$2 -> 130456.75 | E8: =(SUMIFS(一次燃料消费!F:F,一次燃料消费!$A:$A,'图3，4-一次能源消费量'!$A8)-SUM(工业非燃料使用!F$2:F$251))*$E$2 -> 136202.03 | F8: =(SUMIFS(一次燃料消费!G:G,一次燃料消费!$A:$A,'图3，4-一次能源消费量'!$A8)-SUM(工业非燃料使用!G$2:G$251))*$E$2 -> 137979.67 | G8: =(SUMIFS(一次燃料消费!H:H,一次燃料消费!$A:$A,'图3，4-一次能源消费量'!$A8)-SUM(工业非燃料使用!H$2:H$251))*$E$2 -> 139923.71 | H8: =(SUMIFS(一次燃料消费!I:I,一次燃料消费!$A:$A,'图3，4-一次能源消费量'!$A8)-SUM(工业非燃料使用!I$2:I$251))*$E$2 -> 141849.25 | I8: =(SUMIFS(一次燃料消费!J:J,一次燃料消费!$A:$A,'图3，4-一次能源消费量'!$A8)-SUM(工业非燃料使用!J$2:J$251))*$E$2 -> 143590.97 | J8: =(SUMIFS(一次燃料消费!K:K,一次燃料消费!$A:$A,'图3，4-一次能源消费量'!$A8)-SUM(工业非燃料使用!K$2:K$251))*$E$2 -> 145617.24 | K8: =(SUMIFS(一次燃料消费!L:L,一次燃料消费!$A:$A,'图3，4-一次能源消费量'!$A8)-SUM(工业非燃料使用!L$2:L$251))*$E$2 -> 145754.55 | L8: =(SUMIFS(一次燃料消费!M:M,一次燃料消费!$A:$A,'图3，4-一次能源消费量'!$A8)-SUM(工业非燃料使用!M$2:M$251))*$E$2 -> 145956.55 | M8: =(SUMIFS(一次燃料消费!N:N,一次燃料消费!$A:$A,'图3，4-一次能源消费量'!$A8)-SUM(工业非燃料使用!N$2:N$251))*$E$2 -> 146151.43 | N8: =(SUMIFS(一次燃料消费!O:O,一次燃料消费!$A:$A,'图3，4-一次能源消费量'!$A8)-SUM(工业非燃料使用!O$2:O$251))*$E$2 -> 146712.77 | O8: =(SUMIFS(一次燃料消费!P:P,一次燃料消费!$A:$A,'图3，4-一次能源消费量'!$A8)-SUM(工业非燃料使用!P$2:P$251))*$E$2 -> 146870.22 | P8: =(SUMIFS(一次燃料消费!Q:Q,一次燃料消费!$A:$A,'图3，4-一次能源消费量'!$A8)-SUM(工业非燃料使用!Q$2:Q$251))*$E$2 -> 146078.14 | Q8: =(SUMIFS(一次燃料消费!R:R,一次燃料消费!$A:$A,'图3，4-一次能源消费量'!$A8)-SUM(工业非燃料使用!R$2:R$251))*$E$2 -> 144799.45 | R8: =(SUMIFS(一次燃料消费!S:S,一次燃料消费!$A:$A,'图3，4-一次能源消费量'!$A8)-SUM(工业非燃料使用!S$2:S$251))*$E$2 -> 143868.22 | S8: =(SUMIFS(一次燃料消费!T:T,一次燃料消费!$A:$A,'图3，4-一次能源消费量'!$A8)-SUM(工业非燃料使用!T$2:T$251))*$E$2 -> 142955.74 | T8: =(SUMIFS(一次燃料消费!U:U,一次燃料消费!$A:$A,'图3，4-一次能源消费量'!$A8)-SUM(工业非燃料使用!U$2:U$251))*$E$2 -> 142017.01 | U8: =(SUMIFS(一次燃料消费!V:V,一次燃料消费!$A:$A,'图3，4-一次能源消费量'!$A8)-SUM(工业非燃料使用!V$2:V$251))*$E$2 -> 140351.57 | V8: =(SUMIFS(一次燃料消费!W:W,一次燃料消费!$A:$A,'图3，4-一次能源消费量'!$A8)-SUM(工业非燃料使用!W$2:W$251))*$E$2 -> 138780.36 | W8: =(SUMIFS(一次燃料消费!X:X,一次燃料消费!$A:$A,'图3，4-一次能源消费量'!$A8)-SUM(工业非燃料使用!X$2:X$251))*$E$2 -> 137082.96 | X8: =(SUMIFS(一次燃料消费!Y:Y,一次燃料消费!$A:$A,'图3，4-一次能源消费量'!$A8)-SUM(工业非燃料使用!Y$2:Y$251))*$E$2 -> 135456.97 | Y8: =(SUMIFS(一次燃料消费!Z:Z,一次燃料消费!$A:$A,'图3，4-一次能源消费量'!$A8)-SUM(工业非燃料使用!Z$2:Z$251))*$E$2 -> 133799.71 | Z8: =(SUMIFS(一次燃料消费!AA:AA,一次燃料消费!$A:$A,'图3，4-一次能源消费量'!$A8)-SUM(工业非燃料使用!AA$2:AA$251))*$E$2 -> 132466.86 | AA8: =(SUMIFS(一次燃料消费!AB:AB,一次燃料消费!$A:$A,'图3，4-一次能源消费量'!$A8)-SUM(工业非燃料使用!AB$2:AB$251))*$E$2 -> 130758.8 | AB8: =(SUMIFS(一次燃料消费!AC:AC,一次燃料消费!$A:$A,'图3，4-一次能源消费量'!$A8)-SUM(工业非燃料使用!AC$2:AC$251))*$E$2 -> 129406.62 | AC8: =(SUMIFS(一次燃料消费!AD:AD,一次燃料消费!$A:$A,'图3，4-一次能源消费量'!$A8)-SUM(工业非燃料使用!AD$2:AD$251))*$E$2 -> 127797.22 | AD8: =(SUMIFS(一次燃料消费!AE:AE,一次燃料消费!$A:$A,'图3，4-一次能源消费量'!$A8)-SUM(工业非燃料使用!AE$2:AE$251))*$E$2 -> 126176.74 | AE8: =(SUMIFS(一次燃料消费!AF:AF,一次燃料消费!$A:$A,'图3，4-一次能源消费量'!$A8)-SUM(工业非燃料使用!AF$2:AF$251))*$E$2 -> 124548.4 | AF8: =(SUMIFS(一次燃料消费!AG:AG,一次燃料消费!$A:$A,'图3，4-一次能源消费量'!$A8)-SUM(工业非燃料使用!AG$2:AG$251))*$E$2 -> 122909.63 | AG8: =(SUMIFS(一次燃料消费!AH:AH,一次燃料消费!$A:$A,'图3，4-一次能源消费量'!$A8)-SUM(工业非燃料使用!AH$2:AH$251))*$E$2 -> 121131.31 | AH8: =(SUMIFS(一次燃料消费!AI:AI,一次燃料消费!$A:$A,'图3，4-一次能源消费量'!$A8)-SUM(工业非燃料使用!AI$2:AI$251))*$E$2 -> 119429.05 | AI8: =(SUMIFS(一次燃料消费!AJ:AJ,一次燃料消费!$A:$A,'图3，4-一次能源消费量'!$A8)-SUM(工业非燃料使用!AJ$2:AJ$251))*$E$2 -> 117617.37 | AJ8: =(SUMIFS(一次燃料消费!AK:AK,一次燃料消费!$A:$A,'图3，4-一次能源消费量'!$A8)-SUM(工业非燃料使用!AK$2:AK$251))*$E$2 -> 116131.62 | AK8: =(SUMIFS(一次燃料消费!AL:AL,一次燃料消费!$A:$A,'图3，4-一次能源消费量'!$A8)-SUM(工业非燃料使用!AL$2:AL$251))*$E$2 -> 114717.93 | AL8: =(SUMIFS(一次燃料消费!AM:AM,一次燃料消费!$A:$A,'图3，4-一次能源消费量'!$A8)-SUM(工业非燃料使用!AM$2:AM$251))*$E$2 -> 113173.89 | AM8: =(SUMIFS(一次燃料消费!AN:AN,一次燃料消费!$A:$A,'图3，4-一次能源消费量'!$A8)-SUM(工业非燃料使用!AN$2:AN$251))*$E$2 -> 111581.16 | AN8: =(SUMIFS(一次燃料消费!AO:AO,一次燃料消费!$A:$A,'图3，4-一次能源消费量'!$A8)-SUM(工业非燃料使用!AO$2:AO$251))*$E$2 -> 109840.13
