Workbook

Sheet About
A1: BCpUC Battery Cost per Unit Capacity
A2: BCpUC Battery Balance of System Cost per Unit Capacity
A4: Sources: | B4: Battery cost projections per kWh | E4: China Historical Battery Cost
B5: Rocky Mountain Institute | E5: 2021 Data
B6: 2014 | E6: 北极星储能网
B7: The Economics of Grid Defection | E7: 2021储能中标均价1.476元/Wh
B8: http://www.rmi.org/electricity_grid_defection
B9: Page 61, First Table, "Li-ion Battery Capital Cost" | E9: 2022 Data
E10: 储能与电力市场
B11: 2010 Battery Costs per kW | E11: https://mp.weixin.qq.com/s/2dLCmA_6qSvE5v-GP6WXLg
B12: Sandia National Laboratory
B13: 2013 | E13: 2023H1 Data
B14: DOE/EPRI 2013 Electricity Storage Handbook in Collaboration with NRECA | E14: 储能与电力市场
B15: http://www.sandia.gov/ess/publications/SAND2013-5131.pdf | E15: 2023上半年储能盘点：储能系统和EPC价格全景分析
B16: Page B-45, Table B-28
B18: Capital Costs | E18: China Battery Cost Breakdown
B19: National Renewable Energy Laboratory | E19: ESCN 2022
B20: 2021 | E20: 大储 ~ P2：成本测算
B21: Annual Technology Baseline
B22: https://atb.nrel.gov/ | E22: BNEF 2020
B23: Utility-Scale Battery Storage tab, CAPEX, Moderate scenario | E23: 新型储能系统成本分析
B25: Balance of System Costs | E25: Wind & Weibo 2022
B26: National Renewable Energy Laboratory | E26: 韦伯咨询：2023年中国储能行业专题调研与深度分析报告
B27: 2018
B28: 2018 U.S. Utility-Scale Photovoltaics Plus-Energy Storage System Costs Benchmark
B29: https://www.nrel.gov/docs/fy19osti/71714.pdf | E29: Capital Cost Price Projections
B30: Page 12, Table 3 | E30: BNEF 2020
E31: 韦伯咨询：2023年中国储能行业专题调研与深度分析报告
A32: Note:
A33: Used to calculate battery storage deployment. Only the first year of this time series | E33: BNEF 2022
A34: input variable is used, and the remaining years are handled via endogenous | E34: 2022年储能系统成本调查_电力网 (chinapower.com.cn)
A35: learning.
E36: MIT Energy Storage for the Future
A37: Balance of System | E37: 2022
A38: The "balance of system" should include all costs the utility must pay to purchase and | E38: Chapoter 2, Page 19 (44), Table 2.1
A39: install the battery system, apart from the batteries themselves (and apart from sales | E39: The-Future-of-Energy-Storage.pdf (mit.edu)
A40: tax on the batteries). This includes the inverter, labor, etc.
A42: Only the battery cost is affected by endogenous learning. The "Balance of System"
A43: costs are read directly from this variable and are not modified via endogenous learning
A44: inside the simulator.
...

Sheet Exchange Rate
A1: Year | B1: Current RMB / 2012 USD | C1: 2012 USD / Current RMB | D1: Current USD / 2012 USD
A2: 2000 | B2: 0.26402732 | C2: 3.7874869 | D2: 1.3332985
A3: 2001 | B3: 0.25873097 | C3: 3.8650186 | D3: 1.2964088
A4: 2002 | B4: 0.25718247 | C4: 3.8882898 | D4: 1.2762312
A5: 2003 | B5: 0.25065742 | C5: 3.9895089 | D5: 1.2477935
A6: 2004 | B6: 0.23436442 | C6: 4.2668593 | D6: 1.2154262
A7: 2005 | B7: 0.22555917 | C7: 4.4334266 | D7: 1.1755965
A8: 2006 | B8: 0.2170371 | C8: 4.6075073 | D8: 1.1388591
A9: 2007 | B9: 0.20142713 | C9: 4.9645746 | D9: 1.1073203
A10: 2008 | B10: 0.18686069 | C10: 5.3515804 | D10: 1.0663762
A11: 2009 | B11: 0.18725305 | C11: 5.340367 | D11: 1.0701837
A12: 2010 | B12: 0.17519707 | C12: 5.707858 | D12: 1.052913
A13: 2011 | B13: 0.16210591 | C13: 6.1688066 | D13: 1.0206945
... A23: 2021 | B23: 0.13187297 | C23: 7.5830552 | D23: 0.84730413
A24: 2022 | B24: 0.12836129 | C24: 7.7905106 | D24: =D23*0.93 -> 0.78799284

Sheet NREL ATB
D1: For 15-year life (values in 2019$):
F2: 2019 | G2: 2020 | H2: 2021 | I2: 2022 | J2: 2023 | K2: 2024 | L2: 2025 | M2: 2026 | N2: 2027 | O2: 2028 | P2: 2029 | Q2: 2030 | R2: 2031 | S2: 2032 | T2: 2033 | U2: 2034 | V2: 2035 | W2: 2036 | X2: 2037 | Y2: 2038 | Z2: 2039 | AA2: 2040 | AB2: 2041 | AC2: 2042 | AD2: 2043 | AE2: 2044 | AF2: 2045 | AG2: 2046 | AH2: 2047 | AI2: 2048 | AJ2: 2049 | AK2: 2050
B3: Techno-Economic Cost and Performance Parameters | D3: CAPEX ($/kW) | E3: 2Hr Battery Storage - Advanced | F3: 853.4592 | G3: 810.03484 | H3: 743.8134 | I3: 682.5698 | J3: 621.3262 | K3: 560.0826 | L3: 498.839 | M3: 467.2294 | N3: 432.6564 | O3: 401.0468 | P3: 369.4372 | Q3: 336.8398 | R3: 330.913 | S3: 324.9862 | T3: 317.0838 | U3: 311.157 | V3: 304.2424 | W3: 296.34 | X3: 290.4132 | Y3: 284.4864 | Z3: 278.5596 | AA3: 270.6572 | AB3: 264.7304 | AC3: 257.8158 | AD3: 251.889 | AE3: 243.9866 | AF3: 238.0598 | AG3: 232.133 | AH3: 226.2062 | AI3: 218.3038 | AJ3: 212.377 | AK3: 205.4624
E4: 2Hr Battery Storage - Moderate | F4: 853.4592 | G4: 810.03484 | H4: 763.39637 | I4: 716.75789 | J4: 670.11941 | K4: 623.48093 | L4: 576.84245 | M4: 559.57645 | N4: 542.31045 | O4: 525.04445 | P4: 507.77845 | Q4: 490.51245 | R4: 485.22556 | S4: 479.93868 | T4: 474.65179 | U4: 469.36491 | V4: 464.07803 | W4: 458.79114 | X4: 453.50426 | Y4: 448.21738 | Z4: 442.93049 | AA4: 437.64361 | AB4: 432.35672 | AC4: 427.06984 | AD4: 421.78296 | AE4: 416.49607 | AF4: 411.20919 | AG4: 405.92231 | AH4: 400.63542 | AI4: 395.34854 | AJ4: 390.06166 | AK4: 384.77477
E5: 2Hr Battery Storage - Conservative | F5: 853.4592 | G5: 810.03484 | H5: 784.3132 | I5: 760.606 | J5: 739.8622 | K5: 717.1428 | L5: 694.4234 | M5: 674.37106 | N5: 654.31872 | O5: 634.26638 | P5: 614.21404 | Q5: 594.1617 | R5: 594.1617 | S5: 594.1617 | T5: 594.1617 | U5: 594.1617 | V5: 594.1617 | W5: 594.1617 | X5: 594.1617 | Y5: 594.1617 | Z5: 594.1617 | AA5: 594.1617 | AB5: 594.1617 | AC5: 594.1617 | AD5: 594.1617 | AE5: 594.1617 | AF5: 594.1617 | AG5: 594.1617 | AH5: 594.1617 | AI5: 594.1617 | AJ5: 594.1617 | AK5: 594.1617
E6: 4Hr Battery Storage - Advanced | F6: 1434.2856 | G6: 1363.2842 | H6: 1249.567 | I6: 1146.8358 | J6: 1044.1046 | K6: 941.3734 | L6: 838.6422 | M6: 785.301 | N6: 727.0208 | O6: 673.6796 | P6: 620.3384 | Q6: 566.0094 | R6: 556.1314 | S6: 546.2534 | T6: 532.4242 | U6: 522.5462 | V6: 511.6804 | W6: 497.8512 | X6: 487.9732 | Y6: 478.0952 | Z6: 468.2172 | AA6: 454.388 | AB6: 444.51 | AC6: 433.6442 | AD6: 423.7662 | AE6: 409.937 | AF6: 400.059 | AG6: 390.181 | AH6: 380.303 | AI6: 366.4738 | AJ6: 356.5958 | AK6: 345.73
E7: 4Hr Battery Storage - Moderate | F7: 1434.2856 | G7: 1363.2842 | H7: 1281.8131 | I7: 1200.3419 | J7: 1118.8707 | K7: 1037.3996 | L7: 955.92839 | M7: 921.56147 | N7: 887.19456 | O7: 852.82765 | P7: 818.46073 | Q7: 784.09382 | R7: 774.29265 | S7: 764.49148 | T7: 754.6903 | U7: 744.88913 | V7: 735.08796 | W7: 725.28679 | X7: 715.48561 | Y7: 705.68444 | Z7: 695.88327 | AA7: 686.08209 | AB7: 676.28092 | AC7: 666.47975 | AD7: 656.67858 | AE7: 646.8774 | AF7: 637.07623 | AG7: 627.27506 | AH7: 617.47388 | AI7: 607.67271 | AJ7: 597.87154 | AK7: 588.07037
E8: 4Hr Battery Storage - Conservative | F8: 1434.2856 | G8: 1363.2842 | H8: 1317.7252 | I8: 1278.2132 | J8: 1243.6402 | K8: 1205.116 | L8: 1166.5918 | M8: 1129.4505 | N8: 1092.3092 | O8: 1055.168 | P8: 1018.0267 | Q8: 980.8854 | R8: 980.8854 | S8: 980.8854 | T8: 980.8854 | U8: 980.8854 | V8: 980.8854 | W8: 980.8854 | X8: 980.8854 | Y8: 980.8854 | Z8: 980.8854 | AA8: 980.8854 | AB8: 980.8854 | AC8: 980.8854 | AD8: 980.8854 | AE8: 980.8854 | AF8: 980.8854 | AG8: 980.8854 | AH8: 980.8854 | AI8: 980.8854 | AJ8: 980.8854 | AK8: 980.8854
E9: 6Hr Battery Storage - Advanced | F9: 2015.112 | G9: 1916.5336 | H9: 1755.3206 | I9: 1611.1018 | J9: 1466.883 | K9: 1322.6642 | L9: 1178.4454 | M9: 1103.3726 | N9: 1021.3852 | O9: 946.3124 | P9: 871.2396 | Q9: 795.179 | R9: 781.3498 | S9: 767.5206 | T9: 747.7646 | U9: 733.9354 | V9: 719.1184 | W9: 699.3624 | X9: 685.5332 | Y9: 671.704 | Z9: 657.8748 | AA9: 638.1188 | AB9: 624.2896 | AC9: 609.4726 | AD9: 595.6434 | AE9: 575.8874 | AF9: 562.0582 | AG9: 548.229 | AH9: 534.3998 | AI9: 514.6438 | AJ9: 500.8146 | AK9: 485.9976
E10: 6Hr Battery Storage - Moderate | F10: 2015.112 | G10: 1916.5336 | H10: 1800.2298 | I10: 1683.9259 | J10: 1567.622 | K10: 1451.3182 | L10: 1335.0143 | M10: 1283.5465 | N10: 1232.0787 | O10: 1180.6108 | P10: 1129.143 | Q10: 1077.6752 | R10: 1063.3597 | S10: 1049.0443 | T10: 1034.7288 | U10: 1020.4134 | V10: 1006.0979 | W10: 991.78243 | X10: 977.46696 | Y10: 963.1515 | Z10: 948.83604 | AA10: 934.52058 | AB10: 920.20512 | AC10: 905.88966 | AD10: 891.57419 | AE10: 877.25873 | AF10: 862.94327 | AG10: 848.62781 | AH10: 834.31235 | AI10: 819.99688 | AJ10: 805.68142 | AK10: 791.36596
E11: 6Hr Battery Storage - Conservative | F11: 2015.112 | G11: 1916.5336 | H11: 1851.1372 | I11: 1795.8204 | J11: 1747.4182 | K11: 1693.0892 | L11: 1638.7602 | M11: 1584.53 | N11: 1530.2998 | O11: 1476.0695 | P11: 1421.8393 | Q11: 1367.6091 | R11: 1367.6091 | S11: 1367.6091 | T11: 1367.6091 | U11: 1367.6091 | V11: 1367.6091 | W11: 1367.6091 | X11: 1367.6091 | Y11: 1367.6091 | Z11: 1367.6091 | AA11: 1367.6091 | AB11: 1367.6091 | AC11: 1367.6091 | AD11: 1367.6091 | AE11: 1367.6091 | AF11: 1367.6091 | AG11: 1367.6091 | AH11: 1367.6091 | AI11: 1367.6091 | AJ11: 1367.6091 | AK11: 1367.6091
E12: 8Hr Battery Storage - Advanced | F12: 2595.9384 | G12: 2469.783 | H12: 2261.0742 | I12: 2075.3678 | J12: 1889.6614 | K12: 1703.955 | L12: 1518.2486 | M12: 1421.4442 | N12: 1315.7496 | O12: 1218.9452 | P12: 1122.1408 | Q12: 1024.3486 | R12: 1006.5682 | S12: 988.7878 | T12: 963.105 | U12: 945.3246 | V12: 926.5564 | W12: 900.8736 | X12: 883.0932 | Y12: 865.3128 | Z12: 847.5324 | AA12: 821.8496 | AB12: 804.0692 | AC12: 785.301 | AD12: 767.5206 | AE12: 741.8378 | AF12: 724.0574 | AG12: 706.277 | AH12: 688.4966 | AI12: 662.8138 | AJ12: 645.0334 | AK12: 626.2652
E13: 8Hr Battery Storage - Moderate | F13: 2595.9384 | G13: 2469.783 | H13: 2318.6465 | I13: 2167.5099 | J13: 2016.3734 | K13: 1865.2368 | L13: 1714.1003 | M13: 1645.5315 | N13: 1576.9628 | O13: 1508.394 | P13: 1439.8253 | Q13: 1371.2566 | R13: 1352.4268 | S13: 1333.5971 | T13: 1314.7673 | U13: 1295.9376 | V13: 1277.1078 | W13: 1258.2781 | X13: 1239.4483 | Y13: 1220.6186 | Z13: 1201.7888 | AA13: 1182.9591 | AB13: 1164.1293 | AC13: 1145.2996 | AD13: 1126.4698 | AE13: 1107.6401 | AF13: 1088.8103 | AG13: 1069.9806 | AH13: 1051.1508 | AI13: 1032.3211 | AJ13: 1013.4913 | AK13: 994.66156
E14: 8Hr Battery Storage - Conservative | F14: 2595.9384 | G14: 2469.783 | H14: 2384.5492 | I14: 2313.4276 | J14: 2251.1962 | K14: 2181.0624 | L14: 2110.9286 | M14: 2039.6094 | N14: 1968.2903 | O14: 1896.9711 | P14: 1825.652 | Q14: 1754.3328 | R14: 1754.3328 | S14: 1754.3328 | T14: 1754.3328 | U14: 1754.3328 | V14: 1754.3328 | W14: 1754.3328 | X14: 1754.3328 | Y14: 1754.3328 | Z14: 1754.3328 | AA14: 1754.3328 | AB14: 1754.3328 | AC14: 1754.3328 | AD14: 1754.3328 | AE14: 1754.3328 | AF14: 1754.3328 | AG14: 1754.3328 | AH14: 1754.3328 | AI14: 1754.3328 | AJ14: 1754.3328 | AK14: 1754.3328
E15: 10Hr Battery Storage - Advanced | F15: 3176.7648 | G15: 3023.0324 | H15: 2766.8278 | I15: 2539.6338 | J15: 2312.4398 | K15: 2085.2458 | L15: 1858.0518 | M15: 1739.5158 | N15: 1610.114 | O15: 1491.578 | P15: 1373.042 | Q15: 1253.5182 | R15: 1231.7866 | S15: 1210.055 | T15: 1178.4454 | U15: 1156.7138 | V15: 1133.9944 | W15: 1102.3848 | X15: 1080.6532 | Y15: 1058.9216 | Z15: 1037.19 | AA15: 1005.5804 | AB15: 983.8488 | AC15: 961.1294 | AD15: 939.3978 | AE15: 907.7882 | AF15: 886.0566 | AG15: 864.325 | AH15: 842.5934 | AI15: 810.9838 | AJ15: 789.2522 | AK15: 766.5328
... E17: 10Hr Battery Storage - Conservative | F17: 3176.7648 | G17: 3023.0324 | H17: 2917.9612 | I17: 2831.0348 | J17: 2754.9742 | K17: 2669.0356 | L17: 2583.097 | M17: 2494.6889 | N17: 2406.2808 | O17: 2317.8727 | P17: 2229.4646 | Q17: 2141.0565 | R17: 2141.0565 | S17: 2141.0565 | T17: 2141.0565 | U17: 2141.0565 | V17: 2141.0565 | W17: 2141.0565 | X17: 2141.0565 | Y17: 2141.0565 | Z17: 2141.0565 | AA17: 2141.0565 | AB17: 2141.0565 | AC17: 2141.0565 | AD17: 2141.0565 | AE17: 2141.0565 | AF17: 2141.0565 | AG17: 2141.0565 | AH17: 2141.0565 | AI17: 2141.0565 | AJ17: 2141.0565 | AK17: 2141.0565

Sheet China Historical Battery Cost
B1: 2021 | C1: LiFePO4 Battery System (2022) | I1: LiFePO4 Battery System (2023H1) | O1: system vs EPC price differnce | R1: Average EPC Price excluding Battery System
B2: EPC Price | D2: system cost (rmb/Wh) | G2: EPC price | J2: system cost (rmb/Wh) | M2: EPC price | R2: =AVERAGE(P4:P6) -> 0.30333333 | S2: 2022RMB/Wh
R3: Average EPC Price excluding Battery Only
A4: 1hr system | C4: 1.38 | D4: 1.82 | E4: 2.11 | F4: 1.71 | G4: 2.65 | H4: 3.47 | J4: 1.54 | M4: 1.92 | O4: =G4-D4 -> 0.83 | P4: =M4-J4 -> 0.38 | R4: =R2/SUM('China Battery Cost Breakdown'!E6:E8)*SUM('China Battery Cost Breakdown'!E4:E8) -> 0.53925926 | S4: 2022RMB/Wh
A5: 2hr system | C5: 1.3 | D5: 1.57 | E5: 2.26 | F5: 1.47 | G5: 1.81 | H5: 2.59 | J5: 1.24 | M5: 1.61 | O5: =G5-D5 -> 0.24 | P5: =M5-J5 -> 0.37 | R5: =R4*2*10^6*'Exchange Rate'!B24 -> 138440.03 | S5: 2012USD/MW
A6: 4hr system | C6: 1.32 | D6: 1.48 | E6: 1.85 | F6: 1.39 | G6: 1.69 | H6: 2.25 | J6: 1.18 | M6: 1.34 | O6: =G6-D6 -> 0.21 | P6: =M6-J6 -> 0.16
A7: average | B7: 1.475 | R7: Average Battery System Cost
R8: 2021 | S8: 2022 | T8: 2023
A9: Difference from 2hr system | B9: =AVERAGE(C9:M9) -> 1.1945008 | C9: =C4/C5 -> 1.0615385 | D9: =D4/D5 -> 1.1592357 | E9: =E4/E5 -> 0.93362832 | F9: =F4/F5 -> 1.1632653 | G9: =G4/G5 -> 1.4640884 | H9: =H4/H5 -> 1.3397683 | J9: =J4/J5 -> 1.2419355 | M9: =M4/M5 -> 1.1925466 | Q9: 2022RMB/Wh | R9: =B7 -> 1.475 | S9: =D5 -> 1.57 | T9: =J5 -> 1.24
B10: =AVERAGE(C10:M10) -> 1 | C10: =1 -> 1 | D10: =1 -> 1 | E10: =1 -> 1 | F10: =1 -> 1 | G10: =1 -> 1 | H10: =1 -> 1 | J10: =1 -> 1 | M10: =1 -> 1 | Q10: 2012USD/MW | R10: =R9*2*10^6*'Exchange Rate'!$B$23 -> 389025.26 | S10: =S9*2*10^6*'Exchange Rate'!$B$24 -> 403054.45 | T10: =T9*2*10^6*'Exchange Rate'!$B$24*0.978 -> 311332.61
B11: =AVERAGE(C11:M11) -> 0.91357008 | C11: =C6/C5 -> 1.0153846 | D11: =D6/D5 -> 0.94267516 | E11: =E6/E5 -> 0.81858407 | F11: =F6/F5 -> 0.94557823 | G11: =G6/G5 -> 0.93370166 | H11: =H6/H5 -> 0.86872587 | J11: =J6/J5 -> 0.9516129 | M11: =M6/M5 -> 0.83229814

Sheet MIT Cost Projection
B1: Tech | D1: Discharging capital cost ($/kW) | E1: Storage capital cost ($/kWh) | F1: FOM ($/kW-year) | G1: FOM ($/kWh-year) | H1: Efficiency- charge (%) | I1: Efficiency- discharge (%) | J1: Self- discharge rate (%/month)
B2: Li-ion | C2: 2020 | D2: 257 | E2: 277 | F2: 1.4 | G2: 6.8 | H2: 0.92 | I2: 0.92 | J2: 1.5
B3: Li-ion | C3: 2050 Low | D3: 32 | E3: 70.9 | F3: 0.3 | G3: 1.4 | H3: 0.92 | I3: 0.92 | J3: 1.5
B4: Li-ion | C4: 2050 Mid | D4: 110 | E4: 125.8 | F4: 0.8 | G4: 2.2 | H4: 0.92 | I4: 0.92 | J4: 1.5
B5: Li-ion | C5: 2050 High | D5: 154 | E5: 177 | F5: 1.4 | G5: 3.2 | H5: 0.92 | I5: 0.92 | J5: 1.5
B6: RFB | C6: 2020 | D6: 583–650 | E6: 171 | F6: 4.1 | G6: 0 | H6: 0.92 | I6: 0.88 | J6: 0
B7: RFB | C7: 2050 Low | D7: 297 | E7: 15.5 | F7: 4.1 | G7: 0 | H7: 0.92 | I7: 0.88 | J7: 0
B8: RFB | C8: 2050 Mid | D8: 396 | E8: 48 | F8: 4.1 | G8: 0 | H8: 0.92 | I8: 0.88 | J8: 0
B9: RFB | C9: 2050 High | D9: 530 | E9: 102.2 | F9: 4.1 | G9: 0 | H9: 0.92 | I9: 0.88 | J9: 0
B10: Metal-air | C10: 2020 | D10: 1,068–1,135 | E10: 3.7 | F10: 26.7–28.4 | G10: 0.1 | H10: 0.72 | I10: 0.6 | J10: 7.3
B11: Metal-air | C11: 2050 Low | D11: 595 | E11: 0.1 | F11: 14.9 | G11: 0 | H11: 0.7 | I11: 0.59 | J11: 1.5
B12: Metal-air | C12: 2050 Mid | D12: 643 | E12: 2.4 | F12: 16.1 | G12: 0.1 | H12: 0.73 | I12: 0.63 | J12: 1.5
B13: Metal-air | C13: 2050 High | D13: 950 | E13: 3.6 | F13: 23.7 | G13: 0.1 | H13: 0.72 | I13: 0.6 | J13: 1.5
B15: all costs are in 2021 USD, when converted to 2012 USD
B16: Tech | D16: Discharging capital cost ($/kW) | E16: Storage capital cost ($/kWh) | F16: FOM ($/kW-year)
B17: Li-ion | C17: 2020 | D17: =D2*'Exchange Rate'!$D$23 -> 217.75716 | E17: =E2*'Exchange Rate'!$D$23 -> 234.70324 | F17: =F2*'Exchange Rate'!$D$23 -> 1.1862258
B18: Li-ion | C18: 2050 Low | D18: =D3*'Exchange Rate'!$D$23 -> 27.113732 | E18: =E3*'Exchange Rate'!$D$23 -> 60.073863 | F18: =F3*'Exchange Rate'!$D$23 -> 0.25419124
B19: Li-ion | C19: 2050 Mid | D19: =D4*'Exchange Rate'!$D$23 -> 93.203454 | E19: =E4*'Exchange Rate'!$D$23 -> 106.59086 | F19: =F4*'Exchange Rate'!$D$23 -> 0.6778433
B20: Li-ion | C20: 2050 High | D20: =D5*'Exchange Rate'!$D$23 -> 130.48484 | E20: =E5*'Exchange Rate'!$D$23 -> 149.97283 | F20: =F5*'Exchange Rate'!$D$23 -> 1.1862258

Sheet China Battery Cost Breakdown
C1: ESCN 2022 | D1: Wind & Weibo 2022 | H1: BNEF 2020
A2: 电池模组 | B2: Battery | C2: 0.7 | D2: 0.67 | E2: =AVERAGE(C2:D2) -> 0.685 | F2: CAPEX | G2: Battety | H2: 0.5
A3: 电池管理系统 | B3: Battery Management System (BMS) | C3: 0.06 | D3: 0.09 | E3: =AVERAGE(C3:D3) -> 0.075 | G3: Battery System | H3: 0.16
A4: 储能逆变器 | B4: Power Conversion System (PCS) | C4: 0.06 | D4: 0.1 | E4: =AVERAGE(C4:D4) -> 0.08 | G4: Installation | H4: 0.17
A5: 能量管理系统 | B5: Energy Management System (EMS) | C5: 0.03 | D5: 0.02 | E5: =AVERAGE(C5:D5) -> 0.025 | G5: OM Cost | H5: 0.05
A6: 集装箱 | B6: Container | C6: 0.08 | D6: 0.03 | E6: =AVERAGE(C6:D6) -> 0.055 | G6: Financing Cost | H6: 0.12
A7: 变压器 | B7: Transfomer | C7: 0.03 | D7: 0.06 | E7: =AVERAGE(C7:D7) -> 0.045
A8: 安装等 | B8: Installation | C8: 0.04 | D8: 0.03 | E8: =AVERAGE(C8:D8) -> 0.035
A11: ESCN 2022 | B11: 大储 ~ P2：成本测算
A12: BNEF 2020 | B12: 新型储能系统成本分析
A13: Wind & Weibo 2022 | B13: 韦伯咨询：2023年中国储能行业专题调研与深度分析报告

Sheet BNEF Outlook
B1: China 2hr storage system | C1: Global 4hr storage systen | D1: Global 4hr storage system | E1: China 2hr storage system | F1: China 4hr storage system inferred | G1: Global 4hr storage systen | H1: Global 4hr storage system
A2: Year | B2: 2020RMB/Wh | C2: 2020USD/KWh | D2: 2022USD/KWh | E2: 2012USD/KWh | F2: 2012USD/KWh | G2: 2012USD/KWh | H2: 2012USD/KWh
A3: 2017 | D3: 558 | H3: =D3*'Exchange Rate'!D$24 -> 439.70001
A4: 2018 | D4: 387 | H4: =D4*'Exchange Rate'!D$24 -> 304.95323
A5: 2019 | B5: =(1.6+2.3)/2 -> 1.95 | C5: 333.70871 | D5: 341 | E5: ='BNEF Outlook'!B5*1000*'Exchange Rate'!B$22 -> 268.41882 | G5: =C5*'Exchange Rate'!D$22 -> 296.03656 | H5: =D5*'Exchange Rate'!D$24 -> 268.70556
A6: 2020 | B6: 1.5 | C6: 299.23901 | D6: 267 | E6: ='BNEF Outlook'!B6*1000*'Exchange Rate'!B$22 -> 206.47602 | F6: =E6*'China Historical Battery Cost'!$B$11 -> 188.63031 | G6: =C6*'Exchange Rate'!D$22 -> 265.45812 | H6: =D6*'Exchange Rate'!D$24 -> 210.39409
A7: 2021 | B7: 1.3 | C7: 278.91073 | D7: 256 | E7: ='BNEF Outlook'!B7*1000*'Exchange Rate'!B$22 -> 178.94588 | F7: =E7*'China Historical Battery Cost'!$B$11 -> 163.4796 | G7: =C7*'Exchange Rate'!D$22 -> 247.42468 | H7: =D7*'Exchange Rate'!D$24 -> 201.72617
A8: 2022 | B8: 1.2 | C8: 259.46628 | D8: 324 | E8: ='BNEF Outlook'!B8*1000*'Exchange Rate'!B$22 -> 165.18081 | F8: =E8*'China Historical Battery Cost'!$B$11 -> 150.90425 | G8: =C8*'Exchange Rate'!D$22 -> 230.17531 | H8: =D8*'Exchange Rate'!D$24 -> 255.30968
A9: 2023 | B9: 1.1 | C9: 239.138 | E9: ='BNEF Outlook'!B9*1000*'Exchange Rate'!B$22 -> 151.41575 | F9: =E9*'China Historical Battery Cost'!$B$11 -> 138.3289 | G9: =C9*'Exchange Rate'!D$22 -> 212.14187
A10: 2024 | B10: 1 | C10: 221.46123 | E10: ='BNEF Outlook'!B10*1000*'Exchange Rate'!B$22 -> 137.65068 | F10: =E10*'China Historical Battery Cost'!$B$11 -> 125.75354 | G10: =C10*'Exchange Rate'!D$22 -> 196.46062
A11: 2025 | B11: 0.9 | C11: 209.0875 | E11: ='BNEF Outlook'!B11*1000*'Exchange Rate'!B$22 -> 123.88561 | F11: =E11*'China Historical Battery Cost'!$B$11 -> 113.17819 | G11: =C11*'Exchange Rate'!D$22 -> 185.48375
A12: 2026 | C12: 199.36527 | G12: =C12*'Exchange Rate'!D$22 -> 176.85906
A13: 2027 | C13: 188.75921 | G13: =C13*'Exchange Rate'!D$22 -> 167.45031
A14: 2028 | C14: 180.80467 | G14: =C14*'Exchange Rate'!D$22 -> 160.39375
A15: 2029 | C15: 174.6178 | G15: =C15*'Exchange Rate'!D$22 -> 154.90531
A16: 2030 | C16: 167.54709 | G16: =C16*'Exchange Rate'!D$22 -> 148.63281
B18: BNEF 2020 | C18: 韦伯咨询：2023年中国储能行业专题调研与深度分析报告
B19: BNEF 2022 | C19: 2022年储能系统成本调查_电力网 (chinapower.com.cn)

Sheet Balance of System Calculations
A1: Table 3. Detailed Cost Breakdown for a 60-MW U.S. Li-ion Standalone Storage System with Durations of 0.5–4 Hours
B2: 60-MW, 4-hour Duration, 240-MWh | E2: 60-MW, 2-hour Duration, 120-MWh | H2: 60-MW, 1-hour Duration, 60-MWh | K2: 60-MW, 0.5-hour Duration, 30-MWh
A3: Model Component | B3: Total Cost ($) | C3: $/kWh | D3: $/W | E3: Total Cost | F3: $/kWh | G3: $/W | H3: Total Cost | I3: $/kWh | J3: $/W | K3: Total Cost | L3: $/kWh | M3: $/W
A4: Li-ion battery | B4: 50160000 | C4: 209 | D4: 0.84 | E4: 25080000 | F4: 209 | G4: 0.42 | H4: 12540000 | I4: 209 | J4: 0.21 | K4: 6270000 | L4: 209 | M4: 0.1
A5: Battery central inverter | B5: 4200000 | C5: 18 | D5: 0.07 | E5: 4200000 | F5: 35 | G5: 0.07 | H5: 4200000 | I5: 70 | J5: 0.07 | K5: 4200000 | L5: 140 | M5: 0.07
A6: Structural BOS | B6: 3121131 | C6: 13 | D6: 0.05 | E6: 1813452 | F6: 15 | G6: 0.03 | H6: 1159612 | I6: 19 | J6: 0.02 | K6: 832692 | L6: 28 | M6: 0.01
A7: Electrical BOS | B7: 8602825 | C7: 36 | D7: 0.14 | E7: 6119167 | F7: 51 | G7: 0.1 | H7: 4877337 | I7: 81 | J7: 0.08 | K7: 4256423 | L7: 142 | M7: 0.07
A8: Installation labor & equipment | B8: 5479149 | C8: 23 | D8: 0.09 | E8: 4322275 | F8: 36 | G8: 0.07 | H8: 3743838 | I8: 62 | J8: 0.06 | K8: 3454619 | L8: 115 | M8: 0.06
A9: EPC overhead | B9: 2775545 | C9: 12 | D9: 0.05 | E9: 1948565 | F9: 16 | G9: 0.03 | H9: 1535075 | I9: 26 | J9: 0.03 | K9: 1328330 | L9: 44 | M9: 0.02
A10: Sales tax | B10: 5293460 | C10: 22 | D10: 0.09 | E10: 3083292 | F10: 26 | G10: 0.05 | H10: 1978209 | I10: 33 | J10: 0.03 | K10: 1425667 | L10: 48 | M10: 0.02
A11: ∑ EPC cost | B11: 79632110 | C11: 332 | D11: 1.33 | E11: 46566751 | F11: 388 | G11: 0.78 | H11: 30034071 | I11: 501 | J11: 0.5 | K11: 21767732 | L11: 726 | M11: 0.36
A12: Land acquisition | B12: 250000 | C12: 1 | D12: 0 | E12: 250000 | F12: 2 | G12: 0 | H12: 250000 | I12: 4 | J12: 0 | K12: 250000 | L12: 8 | M12: 0
A13: Permitting fee | B13: 295289 | C13: 1 | D13: 0 | E13: 295289 | F13: 2 | G13: 0 | H13: 295289 | I13: 5 | J13: 0 | K13: 295289 | L13: 10 | M13: 0
A14: Interconnection fee | B14: 1802363 | C14: 8 | D14: 0.03 | E14: 1802363 | F14: 15 | G14: 0.03 | H14: 1802363 | I14: 30 | J14: 0.03 | K14: 1802363 | L14: 60 | M14: 0.03
A15: Contingency | B15: 2477135 | C15: 10 | D15: 0.04 | E15: 1476303 | F15: 12 | G15: 0.02 | H15: 975887 | I15: 16 | J15: 0.02 | K15: 725679 | L15: 24 | M15: 0.01
... A18: ∑ Developer cost | B18: 11648623 | C18: 49 | D18: 0.19 | E18: 7893608 | F18: 66 | G18: 0.13 | H18: 6016101 | I18: 100 | J18: 0.1 | K18: 5077347 | L18: 169 | M18: 0.08
A20: We use the largest (4-hour duration) for our estimate.
A22: Balance of System (excl. sales tax) | D22: =SUM(D5:D9,D12:D17) -> 0.58 | E22: 2018 $/W | G22: =SUM(G5:G9,G12:G17) -> 0.41 | J22: =SUM(J5:J9,J12:J17) -> 0.36 | M22: =SUM(M5:M9,M12:M17) -> 0.3
A23: Sales tax on balance of system elements | D23: =D10*SUM(D5:D7)/SUM(D4:D7) -> 0.021272727 | E23: 2018 $/W | G23: =G10*SUM(G5:G7)/SUM(G4:G7) -> 0.016129032 | J23: =J10*SUM(J5:J7)/SUM(J4:J7) -> 0.013421053 | M23: =M10*SUM(M5:M7)/SUM(M4:M7) -> 0.012
A24: Balance of System | D24: =SUM(D22:D23) -> 0.60127273 | E24: 2018 $/W | G24: =SUM(G22:G23) -> 0.42612903 | J24: =SUM(J22:J23) -> 0.37342105 | M24: =SUM(M22:M23) -> 0.312
A25: Balance of System | D25: =D24*10^6 -> 601272.73 | E25: 2018 $/MW | G25: =G24*10^6 -> 426129.03 | J25: =J24*10^6 -> 373421.05 | M25: =M24*10^6 -> 312000
A26: Balance of System | D26: =D25*About!$A$49 -> 549760.1 | E26: 2012 $/MW | G26: =G25*About!$A$49 -> 389621.43 | J26: =J25*About!$A$49 -> 341429.08 | M26: =M25*About!$A$49 -> 285270.14
A28: For the U.S. model, we assume the balance of system costs remain constant throughout the model run.
A30: EPC Cost (exclude Battery) | B30: 2018 $/W | D30: =D24-D31 -> 0.41127273 | G30: =G24-G31 -> 0.29612903 | J30: =J24-J31 -> 0.27342105 | M30: =M24-M31 -> 0.232 | O30: =AVERAGE(D30:M30) -> 0.3032057
A31: Non EPC Cost | B31: 2018 $/W | D31: =D18 -> 0.19 | G31: =G18 -> 0.13 | J31: =J18 -> 0.1 | M31: =M18 -> 0.08 | O31: =AVERAGE(D31:M31) -> 0.125
A35: China EPC Cost (exclude Battery) | B35: 2012 $/MW | D35: ='China Historical Battery Cost'!R5 -> 138440.03
A36: China Balance of System Cost | B36: 2012 $/MW | D36: =D35/O30*(O30+O31) -> 195513.51

Sheet Cost per Unit Capacity Calc
B2: 2019 | C2: 2020 | D2: 2021 | E2: 2022 | F2: 2023 | G2: 2024 | H2: 2025 | I2: 2026 | J2: 2027 | K2: 2028 | L2: 2029 | M2: 2030 | N2: 2031 | O2: 2032 | P2: 2033 | Q2: 2034 | R2: 2035 | S2: 2036 | T2: 2037 | U2: 2038 | V2: 2039 | W2: 2040 | X2: 2041 | Y2: 2042 | Z2: 2043 | AA2: 2044 | AB2: 2045 | AC2: 2046 | AD2: 2047 | AE2: 2048 | AF2: 2049 | AG2: 2050 | AH2: 2051 | AI2: 2052 | AJ2: 2053 | AK2: 2054 | AL2: 2055 | AM2: 2056 | AN2: 2057 | AO2: 2058 | AP2: 2059 | AQ2: 2060
A3: BNEF China | B3: {=TRANSPOSE('BNEF Outlook'!E5:E11)} -> 268.41882 | C3: 206.47602 | D3: 178.94588 | E3: 165.18081 | F3: 151.41575 | G3: 137.65068 | H3: 123.88561
A4: MIT Li-Low | AG4: ='MIT Cost Projection'!E18 -> 60.073863
A5: China Capital Cost (2012USD/KWH) | B5: =B3 -> 268.41882 | C5: =C3 -> 206.47602 | D5: =D3 -> 178.94588 | E5: =E3 -> 165.18081 | F5: =F3 -> 151.41575 | G5: =G3 -> 137.65068 | H5: =H3 -> 123.88561 | I5: =($AG$4/$H$3)^(1/25)*H5 -> 120.35038 | J5: =($AG$4/$H$3)^(1/25)*I5 -> 116.91602 | K5: =($AG$4/$H$3)^(1/25)*J5 -> 113.57968 | L5: =($AG$4/$H$3)^(1/25)*K5 -> 110.33854 | M5: =($AG$4/$H$3)^(1/25)*L5 -> 107.18988 | N5: =($AG$4/$H$3)^(1/25)*M5 -> 104.13108 | O5: =($AG$4/$H$3)^(1/25)*N5 -> 101.15957 | P5: =($AG$4/$H$3)^(1/25)*O5 -> 98.272853 | ... AQ5: =($AG$4/$H$3)^(1/25)*AP5 -> 44.972956
A6: China Capital Cost （2012USD/MW) | B6: =B5*1000*2 -> 536837.64 | C6: =C5*1000*2 -> 412952.03 | D6: =D5*1000*2 -> 357891.76 | E6: =E5*1000*2 -> 330361.63 | F6: =F5*1000*2 -> 302831.49 | G6: =G5*1000*2 -> 275301.36 | H6: =H5*1000*2 -> 247771.22 | I6: =I5*1000*2 -> 240700.75 | ... AQ6: =AQ5*1000*2 -> 89945.912

Sheet BCpUC
A1: Year | B1: Battery Cost ($/MW)
A2: 2019 | B2: {=TRANSPOSE('Cost per Unit Capacity Calc'!B6:AQ6)} -> 536837.64
A3: 2020 | B3: 412952.03
A4: 2021 | B4: 357891.76
A5: 2022 | B5: 330361.63
A6: 2023 | B6: 302831.49
A7: 2024 | B7: 275301.36
A8: 2025 | B8: 247771.22
A9: 2026 | B9: 240700.75
A10: 2027 | B10: 233832.05
A11: 2028 | B11: 227159.35
A12: 2029 | B12: 220677.07
A13: 2030 | B13: 214379.77
A14: 2031 | B14: 208262.17
... A43: 2060 | B43: 89945.912

Sheet BBoSCpUC
A1: Unit: $/MW | B1: 2019 | C1: 2020 | D1: 2021 | E1: 2022 | F1: 2023 | G1: 2024 | H1: 2025 | I1: 2026 | J1: 2027 | K1: 2028 | L1: 2029 | M1: 2030 | N1: 2031 | O1: 2032 | P1: 2033 | Q1: 2034 | R1: 2035 | S1: 2036 | T1: 2037 | U1: 2038 | V1: 2039 | W1: 2040 | X1: 2041 | Y1: 2042 | Z1: 2043 | AA1: 2044 | AB1: 2045 | AC1: 2046 | AD1: 2047 | AE1: 2048 | AF1: 2049 | AG1: 2050 | AH1: 2051 | AI1: 2052 | AJ1: 2053 | AK1: 2054 | AL1: 2055 | AM1: 2056 | AN1: 2057 | AO1: 2058 | AP1: 2059 | AQ1: 2060
A2: Balance of System | B2: =$C2 -> 195513.51 | C2: ='Balance of System Calculations'!D36 -> 195513.51 | D2: =$C2 -> 195513.51 | E2: =$C2 -> 195513.51 | F2: =$C2 -> 195513.51 | G2: =$C2 -> 195513.51 | H2: =$C2 -> 195513.51 | I2: =$C2 -> 195513.51 | J2: =$C2 -> 195513.51 | K2: =$C2 -> 195513.51 | ... AQ2: =$C2 -> 195513.51
