Workbook

Sheet About
B1: Source：
B2: 中国统计年鉴2019 China Statistic Yearbook 2019 | C2: http://www.stats.gov.cn/tjsj/ndsj/2019/indexch.htm | I2: LDV, LDH
B4: 2018年民航行业发展统计公报 Development Statistics Bulletin of civil aviation industry in 2018 | C4: http://www.caac.gov.cn/XXGK/XXGK/TZTG/201905/P020190508527175796080.pdf | K4: aircraft
B6: 中国移动源环境管理年报2019 China Mobile Source Environmental Management Annual Report 2019 | C6: http://www.mee.gov.cn/hjzl/sthjzk/ydyhjgl/201909/P020190905586230826402.pdf | K6: gasoline, diesel, natural gas
B8: News | C8: http://www.sohu.com/a/288800709_146550
C9: https://baijiahao.baidu.com/s?id=1622349088177624657&wfr=spider&for=pc | K9: plugin
C10: http://www.sohu.com/a/288908266_99922905
C11: https://www.sohu.com/a/291989396_115312
B13: Note
B14: Start Year is the year prior to the model's first simulated year.
B15: Start Year：2018
B16: some sources are noted in 2018 China National Data directly
B18: Rail
B19: *Rail vehicle stock is measured in cars, instead of trains
B21: Aircraft
B22: We only consider Aero Transport under Civil Aviation, and do not include General Aircraft.
B24: Motorbikes
B25: As for motorbikes, it could refer to two-wheel or three wheel motorbikes. | O25: 2020年摩托车保有量
B26: Two-wheel are basically all for passenger use. | O26: http://www.gov.cn/xinwen/2020-07/18/content_5528056.htm
B27: While three-wheels can be used either for passenger or for freight, and mostly used in rural area. So we just assume no for freight use.
B28: In China, there are emerging electric bicycles, but they are not considered
B29: under the category of Motorbikes in China's statistics system.
B32: Road Transport
B33: HDV in US context includes Medium and Heavy Duty Vehicles in China's context.
B35: Low-speed vehicles are not categorized. The amount of them are small(compare to
B36: other vehicles). Besides, their categories are hard to define.
M37: US HDV
B38: Electric passenger HDV is taken equal to electric city buses
B40: We account fuel oil into diesel in terms of ships
B42: Other notes and assumptions are indicated in 2018 China National Data | J42: 8501 lbs = | L42: about 4000 kg
I45: These errors lead to a total number of road vehicles a little bit larger than the official amount, 240 million

Sheet 2020 China National Data
A1: 2018年机动车保有量 | B1: =3.27*10^8 -> 327000000 | C1: 还有拖拉机、摩托车等 | D1: =B1-F13 -> 86686700 | E1: 拖拉机不纳入本次核算范围
A4: 载客车 | I4: 公安部统计:
A5: 大型 | B5: 中型 | C5: 小型 | D5: 微型 | E5: LDV | F5: HDV | I5: 截至2018年底，全国汽车保有量达2.4亿辆，
A6: 1583300 | B6: 754000 | C6: 201352200 | D6: 1864600 | E6: =C6+D6 -> 203216800 | F6: =A6+B6 -> 2337300 | I6: 比2017年增加2285万辆，增长10.51%。
D7: (LDV和HDV的比例) | E7: =E6/(E6+F6) -> 0.98862927 | F7: =1-E7 -> 0.011370729 | I7: 其中，私家车（私人小微型载客汽车）持续快速增长，2018年保有量达1.89亿辆，
A8: 载货车
A9: 重型 | B9: 中型 | C9: 轻型 | D9: 微型 | E9: LDV | F9: HDV | I9: 汽车总= | J9: 240000000 | K9: LDV载客汽车总= | L9: 189000000
A10: 7095300 | B10: 1243900 | C10: 17285300 | D10: 53700 | E10: =C10+D10 -> 17339000 | F10: =A10+B10 -> 8339200
D11: (LDV和HDV的比例) | E11: =E10/(E10+F10) -> 0.67524203 | F11: =1-E11 -> 0.32475797
A12: 其他汽车 | C12: 民用汽车保有量 | D12: 低速汽车 | F12: 汽车
A13: =108*10000 -> 1080000 | C13: =A13+SUM(A6:D6)+SUM(A10:D10) -> 232312300 | D13: =800.1*10000 -> 8001000 | F13: =C13+D13 -> 240313300 | I13: 2018年纯电动汽车保有量211万辆，新能源
A14: Freight LDV | D14: =D13-D23-H51 -> 3801870.6 | E14: 低速汽车中有一部分新能源5w、CNG4百万，其余为柴油 | I14: 汽车保有量261万辆
E15: 其中4百万CNG中有大部分作为客运，小部分作为货运 | I15: 新能源=纯电动+氢燃料+混合动力
E16: 目前模型中均纳入货运LDV | I16: 纯电动= | J16: 2110000 | K16: 新能源总= | L16: 2610000
A18: =C13 -> 232312300 | B18: 民用汽车 | D18: =SUM(A20:E20) -> 231210000 | F18: 68890000 | G18: 摩托车 | L18: 左表中 | M18: 纯电动 | N18: 插电式混合动力
A19: 柴油车 | B19: 汽油车 | C19: 天然气 | D19: 新能源 | E19: 其他燃料 | Q19: Passenger LDV | R19: Passenger HDV | S19: Freight LDV | T19: Freight HDV
A20: 21030000 | B20: 205070000 | C20: 546000 | D20: =260.1*10000 -> 2601000 | E20: =196.3*10000 -> 1963000 | F20: MEE报告中数据 | L20: 新能源乘用车 | M20: 0.5749 | N20: 0.1771 | P20: Battery | Q20: =M20 -> 0.5749 | R20: =M21 -> 0.1472 | S20: =M22 -> 0.0734
A21: 0.091 | B21: 0.887 | C21: 0.002 | D21: 0.011 | E21: 0.009 | L21: 新能源客车 | M21: 0.1472 | N21: 0.0269 | P21: Plug-in | Q21: =N20 -> 0.1771 | R21: =N21 -> 0.0269
A22: =A21*$A$18 -> 21140419 | B22: =B21*$A$18 -> 2.0606101e+08 | C22: =C21*$A$18 -> 464624.6 | D22: =D21*$A$18 -> 2555435.3 | E22: =E21*$A$18 -> 2090810.7 | F22: 基于统计年鉴民用汽车总量乘以MEE的比例得出 | L22: 新能源货车 | M22: 0.0734 | N22: 0 | P22: Other | S22: =1-SUM(Q20:S21) -> 0.0005
B23: There is seldom HDV gasoline cars, therefore assume 0 for gasoline HDVs. | C23: MEE的统计口径中天然气指LNG | D23: =L16-D22 -> 54564.7 | E23: 其他燃料都假设为CNG
D24: 低速车中有5w辆新能源 | Q24: Passenger LDV | R24: Passenger HDV | S24: Freight LDV | T24: Freight HDV
P25: Battery | Q25: =$L$16*Q20 -> 1500489 | R25: =$L$16*R20 -> 384192 | S25: =$L$16*S20 -> 191574
A26: 柴油车 | P26: Plug-in | Q26: =$L$16*Q21 -> 462231 | R26: =$L$16*R21 -> 70209 | S26: =$L$16*S21 -> 0 | V26: 2018年国内氢燃料电池汽车产量为1619辆，其中专用车909辆，客车710辆
F27: 左图中 | G27: LDV | H27: HDV | P27: Hydrogen | Q27: =INT(U27*710/(710+909)) -> 572 | S27: =U27-Q27 -> 733 | U27: =$L$16*S22 -> 1305 | V27: 高工产研氢电研究所(GGII)数据统计，2018年全年国内各地新增氢燃料电池汽车运行数量为875辆。
F28: 柴油客车 | G28: =0.075 -> 0.075 | H28: =0.06 -> 0.06 | V28: https://www.gg-lb.com/asdisp2-65b095fb-36457-.html
F29: 柴油货车 | G29: 0.48 | H29: =0.326+0.059 -> 0.385
F31: 数量 | G31: LDV | H31: HDV
F32: 柴油客车 | G32: =INT($A$22*G28) -> 1585531 | H32: =INT($A$22*H28) -> 1268425
F33: 柴油货车 | G33: =INT($A$22*G29) -> 10147401 | H33: =INT($A$22*H29) -> 8139061
H34: =A20*H29 -> 8096550 | I34: 为了和HDV Freight总量对上，调整为用MEE的柴油车总量数据
H36: =H33-H34 -> 42511
A40: 天然气车 | B40: https://www.docin.com/p-2146232035.html | F40: 假设产量比例为存量结构比例
G42: LDV | H42: HDV
F43: 客车 | G43: 0.4138 | H43: =5.05%+0.14% -> 0.0519
F44: 货车 | G44: =16.96% -> 0.1696 | H44: =36.47% -> 0.3647
G45: =G44/(G43+G44) -> 0.29070963 | H45: =H55/H47 -> 0.038059701
F47: Total Natural Gas Vehicle | H47: =670*10000 -> 6700000 | I47: uncertain
G48: LNG | H48: =C22 -> 464624.6
G49: CNG | H49: =H47-H48 -> 6235375.4
G50: 汽车（其他燃料） | H50: =E22 -> 2090810.7
...

Sheet table
A1: 载客
A2: Number of Vehicles | B2: battery electric vehicle | C2: natural gas vehicle | D2: gasoline vehicle | E2: diesel vehicle | F2: plugin hybrid vehicle | G2: LPG vehicle | H2: hydrogen vehicle
A3: LDVs | B3: ='2020 China National Data'!C148 -> 2828508 | C3: ='2020 China National Data'!C158 -> 2739356 | D3: =227300000-table!B3-table!C3-table!F3-table!H3-E3 -> 219357580 | E3: ='2020 China National Data'!C139 -> 1500000 | F3: ='2020 China National Data'!C149 -> 871332 | G3: 0 | H3: ='2020 China National Data'!C111 -> 3224
A4: HDVs | B4: ='2020 China National Data'!C109 -> 377460 | C4: ='2020 China National Data'!C159 -> 343578 | D4: =2253000-table!B4-table!C4-table!F4-E4 -> 243422 | E4: ='2020 China National Data'!C140 -> 1200000 | F4: ='2020 China National Data'!C110 -> 88540 | G4: 0 | H4: 0
A5: aircraft | B5: 0 | C5: 0 | D5: 0 | E5: ='2020 China National Data'!A62 -> 3645 | F5: 0 | G5: 0 | H5: 0
A6: rail | B6: ='2020 China National Data'!D81 -> 14000 | C6: 0 | D6: 0 | E6: ='2020 China National Data'!C81 -> 615.38462 | F6: 0 | G6: 0 | H6: 0
A7: ships | B7: ='2020 China National Data'!B75 -> 250 | C7: =INT('2020 China National Data'!A74) -> 1 | D7: 0 | E7: ='2020 China National Data'!B74 -> 5551 | F7: 0 | G7: 0 | H7: 0
A8: motorbikes | B8: 0 | C8: 0 | D8: ='2020 China National Data'!F18 -> 68890000 | E8: 0 | F8: 0 | G8: 0 | H8: 0
J10: =SUM(B13:I14)+SUM(B3:I4) -> 259979400
A11: 载货
A12: Number of Vehicles | B12: battery electric vehicle | C12: natural gas vehicle | D12: gasoline vehicle | E12: diesel vehicle | F12: plugin hybrid vehicle | G12: LPG vehicle | H12: hydrogen vehicle
A13: LDVs | B13: ='2020 China National Data'!C152 -> 361128 | C13: ='2020 China National Data'!C160 -> 1122752 | D13: =20958100-B13-C13-E13-H13+1159927 -> 10993755 | E13: ='2020 China National Data'!C142 -> 9636264.4 | F13: ='2020 China National Data'!S26 -> 0 | G13: 0 | H13: ='2020 China National Data'!C112 -> 4128 | J13: =SUM(B13:H13) -> 22118027
A14: HDVs | B14: ='2020 China National Data'!S21 -> 0 | C14: ='2020 China National Data'!C132 -> 582000 | D14: 0 | E14: ='2020 China National Data'!C141 -> 7726373 | F14: 0 | G14: 0 | H14: 0 | J14: ='2020 China National Data'!E10+'2020 China National Data'!D13+'2020 China National Data'!A13 -> 26420000
A15: aircraft | B15: 0 | C15: 0 | D15: 0 | E15: ='2020 China National Data'!B62 -> 173 | F15: 0 | G15: 0 | H15: 0
A16: rail | B16: 0 | C16: 0 | D16: 0 | E16: ='2020 China National Data'!E81 -> 7384.6154 | F16: 0 | G16: 0 | H16: 0
A17: ships | B17: 0 | C17: ='2020 China National Data'!C74 -> 399 | D17: 0 | E17: ='2020 China National Data'!D74 -> 120599 | F17: 0 | G17: 0 | H17: 0
A18: motorbikes | B18: 0 | C18: 0 | D18: 0 | E18: 0 | F18: 0 | G18: 0 | H18: 0

Sheet SYVbT-passenger
A1: Number of Vehicles | B1: battery electric vehicle | C1: natural gas vehicle | D1: gasoline vehicle | E1: diesel vehicle | F1: plugin hybrid vehicle | G1: LPG vehicle | H1: hydrogen vehicle
A2: LDVs | B2: =table!B3 -> 2828508 | C2: =table!C3 -> 2739356 | D2: =table!D3 -> 219357580 | E2: =table!E3 -> 1500000 | F2: =table!F3 -> 871332 | G2: =table!G3 -> 0 | H2: =table!H3 -> 3224
A3: HDVs | B3: =table!B4 -> 377460 | C3: =table!C4 -> 343578 | D3: =table!D4 -> 243422 | E3: =table!E4 -> 1200000 | F3: =table!F4 -> 88540 | G3: =table!G4 -> 0 | H3: =table!H4 -> 0
A4: aircraft | B4: =table!B5 -> 0 | C4: =table!C5 -> 0 | D4: =table!D5 -> 0 | E4: =table!E5 -> 3645 | F4: =table!F5 -> 0 | G4: =table!G5 -> 0 | H4: =table!H5 -> 0
A5: rail | B5: =table!B6 -> 14000 | C5: =table!C6 -> 0 | D5: =table!D6 -> 0 | E5: =table!E6 -> 615.38462 | F5: =table!F6 -> 0 | G5: =table!G6 -> 0 | H5: =table!H6 -> 0
A6: ships | B6: =table!B7 -> 250 | C6: =table!C7 -> 1 | D6: =table!D7 -> 0 | E6: =table!E7 -> 5551 | F6: =table!F7 -> 0 | G6: =table!G7 -> 0 | H6: =table!H7 -> 0
A7: motorbikes | B7: =table!B8 -> 0 | C7: =table!C8 -> 0 | D7: =table!D8 -> 68890000 | E7: =table!E8 -> 0 | F7: =table!F8 -> 0 | G7: =table!G8 -> 0 | H7: =table!H8 -> 0

Sheet SYVbT-freight
A1: Number of Vehicles | B1: battery electric vehicle | C1: natural gas vehicle | D1: gasoline vehicle | E1: diesel vehicle | F1: plugin hybrid vehicle | G1: LPG vehicle | H1: hydrogen vehicle
A2: LDVs | B2: =table!B13 -> 361128 | C2: =table!C13 -> 1122752 | D2: =table!D13 -> 10993755 | E2: =table!E13 -> 9636264.4 | F2: =table!F13 -> 0 | G2: =table!G13 -> 0 | H2: =table!H13 -> 4128
A3: HDVs | B3: =table!B14 -> 0 | C3: =table!C14 -> 582000 | D3: 0 | E3: =table!E14 -> 7726373 | F3: =table!F14 -> 0 | G3: =table!G14 -> 0 | H3: =table!H14 -> 0
A4: aircraft | B4: =table!B15 -> 0 | C4: =table!C15 -> 0 | D4: =table!D15 -> 0 | E4: =table!E15 -> 173 | F4: =table!F15 -> 0 | G4: =table!G15 -> 0 | H4: =table!H15 -> 0
A5: rail | B5: =table!B16 -> 0 | C5: =table!C16 -> 0 | D5: =table!D16 -> 0 | E5: =table!E16 -> 7384.6154 | F5: =table!F16 -> 0 | G5: =table!G16 -> 0 | H5: =table!H16 -> 0
A6: ships | B6: =table!B17 -> 0 | C6: =table!C17 -> 399 | D6: =table!D17 -> 0 | E6: =table!E17 -> 120599 | F6: =table!F17 -> 0 | G6: =table!G17 -> 0 | H6: =table!H17 -> 0
A7: motorbikes | B7: =table!B18 -> 0 | C7: =table!C18 -> 0 | D7: =table!D18 -> 0 | E7: =table!E18 -> 0 | F7: =table!F18 -> 0 | G7: =table!G18 -> 0 | H7: =table!H18 -> 0
