Workbook

Sheet About
A1: SYDEC Start Year Destributed Electricity Capacity
A3: source: | B3: Distributed photovoltaic installed capacity and power generation in each province
B4: Energy Bureau photovoltaic data
B5: 2019
B6: China Energy Bureau
B7: https://www.nea.gov.cn/2019-08/23/c_138330885.htm
A10: note: | B10: Photovoltaic installed capacity data comes from the National Bureau of Statistics. Multiplied by the annual effective sunshine hours in each province, the annual photovoltaic power generation capacity is obtained. By consulting experts, the upper limit of photovoltaic coverage of each building is obtained, and then the expected changes in photovoltaic power generation are obtained.

Sheet 能源局光伏数据
B1: 2017 | C1: 2018 | D1: 2019 | E1: 2020 | F1: 2021 | H1: 2017 | I1: 2018 | J1: 2019 | K1: 2020 | L1: 2021 | N1: 分布式发电量（亿千瓦时） | S1: 太阳能总发电量 | X1: 规模以上装机容量 | AC1: 规模以上发电量 | AH1: 经济指标小时数 | AM1: 规模以上运行小时数 | AR1: 光伏电站小时数 | AW1: 分布式小时数
B2: 光伏电站 | C2: 光伏电站 | D2: 光伏电站 | E2: 光伏电站 | F2: 光伏电站 | H2: 分布式光伏 | I2: 分布式光伏 | J2: 分布式光伏 | K2: 分布式光伏 | L2: 分布式光伏 | N2: 2017年 | O2: 2018年 | P2: 2019年 | Q2: 2020年 | S2: 2017年 | T2: 2018年 | U2: 2019年 | V2: 2020年 | X2: 2017年 | Y2: 2018年 | Z2: 2019年 | AA2: 2020年 | AC2: 2017年 | AD2: 2018年 | AE2: 2019年 | AF2: 2020年 | AH2: 2017年 | AI2: 2018年 | AJ2: 2019年 | AK2: 2020年 | AM2: 2017年 | AN2: 2018年 | AO2: 2019年 | AP2: 2020年 | AR2: 2017年 | AS2: 2018年 | AT2: 2019年 | AU2: 2020年 | AW2: 2017年 | AX2: 2018年 | AY2: 2019年 | AZ2: 2020年
A3: 全国 | B3: 9384 | C3: 12406 | D3: 14167 | E3: 17287.87 | F3: 19847.94 | H3: 3658 | I3: 5027 | J3: 6263 | K3: 7822.9 | L3: 10750.8 | N3: 154 | O3: 388 | P3: 538 | Q3: 679 | S3: 1178 | T3: 1769 | U3: 2240 | V3: 2611 | X3: 10277 | Y3: 12885 | Z3: 14709 | AA3: 18134 | AC3: 1029 | AD3: 1412 | AE3: 1738 | AF3: 1982 | AH3: 1205 | AI3: 1230 | AJ3: 1281 | AK3: 1291 | AM3: =AC3*10000/X3 -> 1001.265 | AN3: =AD3*10000/Y3 -> 1095.8479 | AO3: =AE3*10000/Z3 -> 1181.5895 | AP3: =AF3*10000/AA3 -> 1092.9745 | AR3: =(S3-N3)*10000/B3 -> 1091.2191 | AS3: =(T3-O3)*10000/C3 -> 1113.171 | AT3: =(U3-P3)*10000/D3 -> 1201.3835 | AU3: =(V3-Q3)*10000/E3 -> 1117.5466 | AW3: =N3*10000/H3 -> 420.99508 | AX3: =O3*10000/I3 -> 771.83211 | AY3: =P3*10000/J3 -> 859.01325 | AZ3: =Q3*10000/K3 -> 867.96457
A4: 北京市 | B4: 3 | C4: 5 | D4: 5 | E4: 5.1 | F4: 5.1 | H4: 22 | I4: 35 | J4: 46 | K4: 56.4 | L4: 75 | N4: 1 | O4: 2 | P4: 4 | Q4: 5 | S4: 2 | T4: 3 | U4: 5 | V4: 6 | X4: 5 | Y4: 8 | Z4: 8 | AA4: 8 | AC4: 1 | AD4: 0.8 | AE4: 1 | AF4: 1 | AH4: 1551 | AI4: 1261 | AJ4: 1242 | AK4: 1323 | AN4: =AD4*10000/Y4 -> 1000 | AO4: =AE4*10000/Z4 -> 1250 | AP4: =AF4*10000/AA4 -> 1250 | AW4: =N4*10000/H4 -> 454.54545 | AX4: =O4*10000/I4 -> 571.42857 | AY4: =P4*10000/J4 -> 869.56522 | AZ4: =Q4*10000/K4 -> 886.52482
A5: 天津市 | B5: 53 | C5: 97 | D5: 104 | E5: 118.84 | F5: 118.85 | H5: 15 | I5: 31 | J5: 38 | K5: 44.7 | L5: 58.9 | N5: 1 | O5: 2 | P5: 3 | Q5: 4 | S5: 6.2 | T5: 8 | U5: 15 | V5: 19 | X5: 55 | Y5: 108 | Z5: 119 | AA5: 134 | AC5: 6 | AD5: 7 | AE5: 13 | AF5: 16 | AH5: 1027 | AI5: 864 | AJ5: 1265 | AK5: 1144 | AM5: =AC5*10000/X5 -> 1090.9091 | AN5: =AD5*10000/Y5 -> 648.14815 | AO5: =AE5*10000/Z5 -> 1092.437 | AP5: =AF5*10000/AA5 -> 1194.0299 | AR5: =(S5-N5)*10000/B5 -> 981.13208 | AS5: =(T5-O5)*10000/C5 -> 618.5567 | AT5: =(U5-P5)*10000/D5 -> 1153.8462 | AU5: =(V5-Q5)*10000/E5 -> 1262.2013 | AW5: =N5*10000/H5 -> 666.66667 | AX5: =O5*10000/I5 -> 645.16129 | AY5: =P5*10000/J5 -> 789.47368 | AZ5: =Q5*10000/K5 -> 894.85459
A6: 河北省 | B6: 517 | C6: 856 | D6: 962 | E6: 1445.52 | F6: 1658.84 | H6: 351 | I6: 378 | J6: 512 | K6: 745.8 | L6: 1262.5 | N6: 11 | O6: 32 | P6: 53 | Q6: 70 | S6: 77 | T6: 126 | U6: 176 | V6: 211 | X6: 662 | Y6: 859 | Z6: 965 | AA6: 1447 | AC6: 67 | AD6: 95 | AE6: 124 | AF6: 141 | AH6: 1303 | AI6: 1275 | AJ6: 1336 | AK6: 1379 | AM6: =AC6*10000/X6 -> 1012.0846 | AN6: =AD6*10000/Y6 -> 1105.9371 | AO6: =AE6*10000/Z6 -> 1284.9741 | AP6: =AF6*10000/AA6 -> 974.42985 | AR6: =(S6-N6)*10000/B6 -> 1276.5957 | AS6: =(T6-O6)*10000/C6 -> 1098.1308 | AT6: =(U6-P6)*10000/D6 -> 1278.5863 | AU6: =(V6-Q6)*10000/E6 -> 975.42753 | AW6: =N6*10000/H6 -> 313.39031 | AX6: =O6*10000/I6 -> 846.56085 | AY6: =P6*10000/J6 -> 1035.1562 | AZ6: =Q6*10000/K6 -> 938.58943
A7: 山西省 | B7: 530 | C7: 681 | D7: 857 | E7: 1028.32 | F7: 1101.84 | H7: 60 | I7: 183 | J7: 231 | K7: 280.2 | L7: 355.9 | N7: 5 | O7: 14 | P7: 25 | Q7: 31 | S7: 56 | T7: 94 | U7: 128 | V7: 159 | X7: 534 | Y7: 686 | Z7: 862 | AA7: 1033 | AC7: 51 | AD7: 80 | AE7: 103 | AF7: 129 | AH7: 1374 | AI7: 1265 | AJ7: 1277 | AK7: 1307 | AM7: =AC7*10000/X7 -> 955.05618 | AN7: =AD7*10000/Y7 -> 1166.1808 | AO7: =AE7*10000/Z7 -> 1194.8956 | AP7: =AF7*10000/AA7 -> 1248.7899 | AR7: =(S7-N7)*10000/B7 -> 962.26415 | AS7: =(T7-O7)*10000/C7 -> 1174.743 | AT7: =(U7-P7)*10000/D7 -> 1201.867 | AU7: =(V7-Q7)*10000/E7 -> 1244.7487 | AW7: =N7*10000/H7 -> 833.33333 | AX7: =O7*10000/I7 -> 765.02732 | AY7: =P7*10000/J7 -> 1082.2511 | AZ7: =Q7*10000/K7 -> 1106.3526
A8: 内蒙古自治区 | B8: 741 | C8: 933 | D8: 1001 | E8: 1138 | F8: 1299.5 | H8: 2 | I8: 13 | J8: 80 | K8: 90.1 | L8: 102.5 | N8: 0.3 | O8: 1 | P8: 3 | Q8: 13 | S8: 113 | T8: 130 | U8: 163 | V8: 188 | X8: 740 | Y8: 933 | Z8: 962 | AA8: 1176 | AC8: 112 | AD8: 129 | AE8: 160 | AF8: 180 | AH8: 1524 | AI8: 1632 | AJ8: 1654 | AK8: 1663 | AM8: =AC8*10000/X8 -> 1513.5135 | AN8: =AD8*10000/Y8 -> 1382.6367 | AO8: =AE8*10000/Z8 -> 1663.2017 | AP8: =AF8*10000/AA8 -> 1530.6122 | AR8: =(S8-N8)*10000/B8 -> 1520.9177 | AS8: =(T8-O8)*10000/C8 -> 1382.6367 | AT8: =(U8-P8)*10000/D8 -> 1598.4016 | AU8: =(V8-Q8)*10000/E8 -> 1537.7856 | AW8: =N8*10000/H8 -> 1500 | AX8: =O8*10000/I8 -> 769.23077 | AY8: =P8*10000/J8 -> 375 | AZ8: =Q8*10000/K8 -> 1442.8413
A9: 辽宁省 | B9: 185 | C9: 219 | D9: 246 | E9: 281.89 | F9: 317.5 | H9: 38 | I9: 83 | J9: 97 | K9: 117.9 | L9: 160 | N9: 3 | O9: 7 | P9: 10 | Q9: 12 | S9: 12 | T9: 32 | U9: 42 | V9: 51 | X9: 200 | Y9: 248 | Z9: 276 | AA9: 313 | AC9: 10 | AD9: 27 | AE9: 35 | AF9: 43 | AH9: 1072 | AI9: 1235 | AJ9: 1453 | AK9: 1396 | AM9: =AC9*10000/X9 -> 500 | AN9: =AD9*10000/Y9 -> 1088.7097 | AO9: =AE9*10000/Z9 -> 1268.1159 | AP9: =AF9*10000/AA9 -> 1373.8019 | AR9: =(S9-N9)*10000/B9 -> 486.48649 | AS9: =(T9-O9)*10000/C9 -> 1141.5525 | AT9: =(U9-P9)*10000/D9 -> 1300.813 | AU9: =(V9-Q9)*10000/E9 -> 1383.5184 | AW9: =N9*10000/H9 -> 789.47368 | AX9: =O9*10000/I9 -> 843.37349 | AY9: =P9*10000/J9 -> 1030.9278 | AZ9: =Q9*10000/K9 -> 1017.8117
A10: 吉林省 | B10: 107 | C10: 203 | D10: 205 | E10: 260.91 | F10: 265.79 | H10: 52 | I10: 62 | J10: 69 | K10: 76 | L10: 80.1 | N10: 2 | O10: 7 | P10: 9 | Q10: 9 | S10: 13 | T10: 24 | U10: 40 | V10: 45 | X10: 130 | Y10: 226 | Z10: 228 | AA10: 285 | AC10: 12 | AD10: 20 | AE10: 34 | AF10: 39 | AH10: 1251 | AI10: 1332 | AJ10: 1531 | AK10: 1504 | AM10: =AC10*10000/X10 -> 923.07692 | AN10: =AD10*10000/Y10 -> 884.95575 | AO10: =AE10*10000/Z10 -> 1491.2281 | AP10: =AF10*10000/AA10 -> 1368.4211 | AR10: =(S10-N10)*10000/B10 -> 1028.0374 | AS10: =(T10-O10)*10000/C10 -> 837.43842 | AT10: =(U10-P10)*10000/D10 -> 1512.1951 | AU10: =(V10-Q10)*10000/E10 -> 1379.7861 | AW10: =N10*10000/H10 -> 384.61538 | AX10: =O10*10000/I10 -> 1129.0323 | AY10: =P10*10000/J10 -> 1304.3478 | AZ10: =Q10*10000/K10 -> 1184.2105
A11: 黑龙江省 | B11: 64 | C11: 141 | D11: 195 | E11: 234.99 | F11: 329.99 | H11: 30 | I11: 74 | J11: 80 | K11: 82.7 | L11: 89.8 | N11: 1 | O11: 5 | P11: 9 | Q11: 10 | S11: 6 | T11: 20 | U11: 32 | V11: 43 | X11: 73 | Y11: 144 | Z11: 198 | AA11: 238 | AC11: 5 | AD11: 16 | AE11: 23 | AF11: 33 | AH11: 1249 | AI11: 1447 | AJ11: 1604 | AK11: 1566 | AM11: =AC11*10000/X11 -> 684.93151 | AN11: =AD11*10000/Y11 -> 1111.1111 | AO11: =AE11*10000/Z11 -> 1161.6162 | AP11: =AF11*10000/AA11 -> 1386.5546 | AR11: =(S11-N11)*10000/B11 -> 781.25 | AS11: =(T11-O11)*10000/C11 -> 1063.8298 | AT11: =(U11-P11)*10000/D11 -> 1179.4872 | AU11: =(V11-Q11)*10000/E11 -> 1404.3151 | AW11: =N11*10000/H11 -> 333.33333 | AX11: =O11*10000/I11 -> 675.67568 | AY11: =P11*10000/J11 -> 1125 | AZ11: =Q11*10000/K11 -> 1209.1898
A12: 上海市 | C12: 7 | D12: 6 | E12: 19.7 | F12: 24.09 | H12: 59 | I12: 82 | J12: 103 | K12: 116.9 | L12: 144.2 | N12: 2 | O12: 5 | P12: 7 | Q12: 9 | S12: 3 | T12: 6 | U12: 8 | V12: 10 | X12: 7 | Y12: 13 | Z12: 15 | AA12: 28 | AC12: 1 | AD12: 1 | AE12: 1 | AF12: 2 | AH12: 893 | AI12: 946 | AJ12: 861 | AK12: 867 | AM12: =AC12*10000/X12 -> 1428.5714 | AN12: =AD12*10000/Y12 -> 769.23077 | AO12: =AE12*10000/Z12 -> 666.66667 | AP12: =AF12*10000/AA12 -> 714.28571 | AS12: =(T12-O12)*10000/C12 -> 1428.5714 | AT12: =(U12-P12)*10000/D12 -> 1666.6667 | AU12: =(V12-Q12)*10000/E12 -> 507.61421 | AW12: =N12*10000/H12 -> 338.98305 | AX12: =O12*10000/I12 -> 609.7561 | AY12: =P12*10000/J12 -> 679.61165 | AZ12: =Q12*10000/K12 -> 769.88879
A13: 江苏省 | B13: 580 | C13: 792 | D13: 821 | E13: 895.91 | F13: 941.08 | H13: 327 | I13: 540 | J13: 665 | K13: 788.1 | L13: 974.9 | N13: 19 | O13: 40 | P13: 53 | Q13: 61 | S13: 81 | T13: 120 | U13: 154 | V13: 167 | X13: 571 | Y13: 776 | Z13: 815 | AA13: 898 | AC13: 60 | AD13: 75 | AE13: 95 | AF13: 100 | AH13: 1188 | AI13: 1059 | AJ13: 1165 | AK13: 1192 | AM13: =AC13*10000/X13 -> 1050.7881 | AN13: =AD13*10000/Y13 -> 966.49485 | AO13: =AE13*10000/Z13 -> 1165.6442 | AP13: =AF13*10000/AA13 -> 1113.5857 | AR13: =(S13-N13)*10000/B13 -> 1068.9655 | AS13: =(T13-O13)*10000/C13 -> 1010.101 | AT13: =(U13-P13)*10000/D13 -> 1230.2071 | AU13: =(V13-Q13)*10000/E13 -> 1183.1546 | AW13: =N13*10000/H13 -> 581.03976 | AX13: =O13*10000/I13 -> 740.74074 | AY13: =P13*10000/J13 -> 796.99248 | AZ13: =Q13*10000/K13 -> 774.01345
A14: 浙江省 | B14: 315 | C14: 361 | D14: 414 | E14: 412.17 | F14: 577.03 | H14: 499 | I14: 777 | J14: 925 | K14: 1067.2 | L14: 1264.8 | N14: 31 | O14: 63 | P14: 75 | Q14: 88 | S14: 56 | T14: 100 | U14: 119 | V14: 131 | X14: 328 | Y14: 376 | Z14: 428 | AA14: 462 | AC14: 27 | AD14: 38 | AE14: 45 | AF14: 44 | AH14: 1044 | AI14: 1085 | AJ14: 998 | AK14: 1104 | AM14: =AC14*10000/X14 -> 823.17073 | AN14: =AD14*10000/Y14 -> 1010.6383 | AO14: =AE14*10000/Z14 -> 1051.4019 | AP14: =AF14*10000/AA14 -> 952.38095 | AR14: =(S14-N14)*10000/B14 -> 793.65079 | AS14: =(T14-O14)*10000/C14 -> 1024.9307 | AT14: =(U14-P14)*10000/D14 -> 1062.8019 | AU14: =(V14-Q14)*10000/E14 -> 1043.2588 | AW14: =N14*10000/H14 -> 621.24248 | AX14: =O14*10000/I14 -> 810.81081 | AY14: =P14*10000/J14 -> 810.81081 | AZ14: =Q14*10000/K14 -> 824.58771
A15: 安徽省 | B15: 565 | C15: 677 | D15: 773 | E15: 825.56 | F15: 947.02 | H15: 323 | I15: 441 | J15: 480 | K15: 544.1 | L15: 759.8 | N15: 18 | O15: 36 | P15: 46 | Q15: 45 | S15: 62 | T15: 104 | U15: 125 | V15: 130 | X15: 608 | Y15: 743 | Z15: 859 | AA15: 887 | AC15: 48 | AD15: 73 | AE15: 86 | AF15: 89 | AH15: 992 | AI15: 1065 | AJ15: 1071 | AK15: 1102 | AM15: =AC15*10000/X15 -> 789.47368 | AN15: =AD15*10000/Y15 -> 982.50336 | AO15: =AE15*10000/Z15 -> 1001.1641 | AP15: =AF15*10000/AA15 -> 1003.3822 | AR15: =(S15-N15)*10000/B15 -> 778.76106 | AS15: =(T15-O15)*10000/C15 -> 1004.4313 | AT15: =(U15-P15)*10000/D15 -> 1021.9922 | AU15: =(V15-Q15)*10000/E15 -> 1029.6041 | AW15: =N15*10000/H15 -> 557.27554 | AX15: =O15*10000/I15 -> 816.32653 | AY15: =P15*10000/J15 -> 958.33333 | AZ15: =Q15*10000/K15 -> 827.05385
A16: 福建省 | C16: 37 | D16: 38 | E16: 37.8 | F16: 39.16 | H16: 109 | I16: 111 | J16: 131 | K16: 164.3 | L16: 237.9 | N16: 3 | O16: 9 | P16: 11 | Q16: 15 | S16: 6 | T16: 14 | U16: 16 | V16: 19 | X16: 60 | Y16: 67 | Z16: 72 | AA16: 72 | AC16: 4 | AD16: 7 | AE16: 7 | AF16: 8 | AH16: 843 | AI16: 1099 | AJ16: 1063 | AK16: 1040 | AM16: =AC16*10000/X16 -> 666.66667 | AN16: =AD16*10000/Y16 -> 1044.7761 | AO16: =AE16*10000/Z16 -> 972.22222 | AP16: =AF16*10000/AA16 -> 1111.1111 | AS16: =(T16-O16)*10000/C16 -> 1351.3514 | AT16: =(U16-P16)*10000/D16 -> 1315.7895 | AU16: =(V16-Q16)*10000/E16 -> 1058.2011 | AW16: =N16*10000/H16 -> 275.22936 | AX16: =O16*10000/I16 -> 810.81081 | AY16: =P16*10000/J16 -> 839.69466 | AZ16: =Q16*10000/K16 -> 912.96409
A17: 江西省 | B17: 277 | C17: 294 | D17: 367 | E17: 476.66 | F17: 551.95 | H17: 172 | I17: 242 | J17: 263 | K17: 299.2 | L17: 359.2 | N17: 8 | O17: 21 | P17: 24 | Q17: 26 | S17: 30 | T17: 52 | U17: 56 | V17: 62 | X17: 287 | Y17: 309 | Z17: 383 | AA17: 500 | AC17: 23 | AD17: 32 | AE17: 33 | AF17: 38 | AH17: 891 | AI17: 1064 | AJ17: 917 | AK17: 1004 | AM17: =AC17*10000/X17 -> 801.39373 | AN17: =AD17*10000/Y17 -> 1035.5987 | AO17: =AE17*10000/Z17 -> 861.6188 | AP17: =AF17*10000/AA17 -> 760 | AR17: =(S17-N17)*10000/B17 -> 794.22383 | AS17: =(T17-O17)*10000/C17 -> 1054.4218 | AT17: =(U17-P17)*10000/D17 -> 871.9346 | AU17: =(V17-Q17)*10000/E17 -> 755.25532 | AW17: =N17*10000/H17 -> 465.11628 | AX17: =O17*10000/I17 -> 867.7686 | AY17: =P17*10000/J17 -> 912.54753 | AZ17: =Q17*10000/K17 -> 868.98396
A18: 山东省 | B18: 578 | C18: 648 | D18: 677 | E18: 805.02 | F18: 1008.97 | H18: 474 | I18: 713 | J18: 943 | K18: 1467.4 | L18: 2334.4 | N18: 20 | O18: 60 | P18: 80 | Q18: 117 | S18: 73 | T18: 137 | U18: 167 | V18: 206 | X18: 640 | Y18: 708 | Z18: 751 | AA18: 905 | AC18: 56 | AD18: 82 | AE18: 93 | AF18: 99 | AH18: 1154 | AI18: 1227 | AJ18: 1225 | AK18: 1284 | AM18: =AC18*10000/X18 -> 875 | AN18: =AD18*10000/Y18 -> 1158.1921 | AO18: =AE18*10000/Z18 -> 1238.3489 | AP18: =AF18*10000/AA18 -> 1093.9227 | AR18: =(S18-N18)*10000/B18 -> 916.95502 | AS18: =(T18-O18)*10000/C18 -> 1188.2716 | AT18: =(U18-P18)*10000/D18 -> 1285.0812 | AU18: =(V18-Q18)*10000/E18 -> 1105.5626 | AW18: =N18*10000/H18 -> 421.94093 | AX18: =O18*10000/I18 -> 841.51473 | AY18: =P18*10000/J18 -> 848.35631 | AZ18: =Q18*10000/K18 -> 797.32861
A19: 河南省 | B19: 492 | C19: 600 | D19: 600 | E19: 603.85 | F19: 625.8 | H19: 211 | I19: 391 | J19: 454 | K19: 570.8 | L19: 929.8 | N19: 4 | O19: 27 | P19: 38 | Q19: 49 | S19: 44 | T19: 84 | U19: 102 | V19: 112 | X19: 532 | Y19: 602 | Z19: 602 | AA19: 604 | AC19: 40 | AD19: 57 | AE19: 64 | AF19: 63 | AH19: 934 | AI19: 998 | AJ19: 1055 | AK19: 1061 | AM19: =AC19*10000/X19 -> 751.8797 | AN19: =AD19*10000/Y19 -> 946.84385 | AO19: =AE19*10000/Z19 -> 1063.1229 | AP19: =AF19*10000/AA19 -> 1043.0464 | AR19: =(S19-N19)*10000/B19 -> 813.00813 | AS19: =(T19-O19)*10000/C19 -> 950 | AT19: =(U19-P19)*10000/D19 -> 1066.6667 | AU19: =(V19-Q19)*10000/E19 -> 1043.3055 | AW19: =N19*10000/H19 -> 189.57346 | AX19: =O19*10000/I19 -> 690.53708 | AY19: =P19*10000/J19 -> 837.00441 | AZ19: =Q19*10000/K19 -> 858.44429
A20: 湖北省 | B20: 236 | C20: 335 | D20: 420 | E20: 485.66 | F20: 713 | H20: 177 | I20: 175 | J20: 201 | K20: 211.9 | L20: 239.6 | N20: 5 | O20: 13 | P20: 17 | Q20: 19 | S20: 28 | T20: 49 | U20: 57 | V20: 65 | X20: 301 | Y20: 338 | Z20: 425 | AA20: 491 | AC20: 23 | AD20: 36 | AE20: 40 | AF20: 46 | AH20: 987 | AI20: 1115 | AJ20: 1013 | AK20: 1103 | AM20: =AC20*10000/X20 -> 764.1196 | AN20: =AD20*10000/Y20 -> 1065.0888 | AO20: =AE20*10000/Z20 -> 941.17647 | AP20: =AF20*10000/AA20 -> 936.86354 | AR20: =(S20-N20)*10000/B20 -> 974.57627 | AS20: =(T20-O20)*10000/C20 -> 1074.6269 | AT20: =(U20-P20)*10000/D20 -> 952.38095 | AU20: =(V20-Q20)*10000/E20 -> 947.16468 | AW20: =N20*10000/H20 -> 282.48588 | AX20: =O20*10000/I20 -> 742.85714 | AY20: =P20*10000/J20 -> 845.77114 | AZ20: =Q20*10000/K20 -> 896.64936
A21: 湖南省 | B21: 86 | C21: 126 | D21: 155 | E21: 190.62 | F21: 220.15 | H21: 90 | I21: 166 | J21: 189 | K21: 200.1 | L21: 231 | N21: 4 | O21: 10 | P21: 13 | Q21: 14 | S21: 6 | T21: 20 | U21: 26 | V21: 30 | X21: 113 | Y21: 160 | Z21: 188 | AA21: 242 | AC21: 3 | AD21: 12 | AE21: 16 | AF21: 20 | AH21: 512 | AI21: 933 | AJ21: 902 | AK21: 905 | AM21: =AC21*10000/X21 -> 265.48673 | AN21: =AD21*10000/Y21 -> 750 | AO21: =AE21*10000/Z21 -> 851.06383 | AP21: =AF21*10000/AA21 -> 826.44628 | AR21: =(S21-N21)*10000/B21 -> 232.55814 | AS21: =(T21-O21)*10000/C21 -> 793.65079 | AT21: =(U21-P21)*10000/D21 -> 838.70968 | AU21: =(V21-Q21)*10000/E21 -> 839.36628 | AW21: =N21*10000/H21 -> 444.44444 | AX21: =O21*10000/I21 -> 602.40964 | AY21: =P21*10000/J21 -> 687.83069 | AZ21: =Q21*10000/K21 -> 699.65017
A22: 广东省 | B22: 210 | C22: 318 | D22: 302 | E22: 408.82 | F22: 508.2 | H22: 122 | I22: 209 | J22: 308 | K22: 384.9 | L22: 511.9 | N22: 8 | O22: 15 | P22: 22 | Q22: 32 | S22: 20 | T22: 38 | U22: 53 | V22: 74 | X22: 229 | Y22: 370 | Z22: 382 | AA22: 495 | AC22: 12 | AD22: 25 | AE22: 34 | AF22: 47 | AH22: 843 | AI22: 884 | AJ22: 1020 | AK22: 915 | AM22: =AC22*10000/X22 -> 524.01747 | AN22: =AD22*10000/Y22 -> 675.67568 | AO22: =AE22*10000/Z22 -> 890.05236 | AP22: =AF22*10000/AA22 -> 949.49495 | AR22: =(S22-N22)*10000/B22 -> 571.42857 | AS22: =(T22-O22)*10000/C22 -> 723.27044 | AT22: =(U22-P22)*10000/D22 -> 1026.4901 | AU22: =(V22-Q22)*10000/E22 -> 1027.347 | AW22: =N22*10000/H22 -> 655.7377 | AX22: =O22*10000/I22 -> 717.70335 | AY22: =P22*10000/J22 -> 714.28571 | AZ22: =Q22*10000/K22 -> 831.38478
A23: 广西壮族自治区 | C23: 95 | D23: 105 | E23: 162.46 | F23: 259.16 | H23: 373 | I23: 29 | J23: 30 | K23: 42.7 | L23: 52.6 | N23: 1 | O23: 1 | P23: 2 | Q23: 3 | S23: 4 | T23: 9 | U23: 14 | V23: 19 | X23: 69 | Y23: 99 | Z23: 110 | AA23: 170 | AC23: 4 | AD23: 8 | AE23: 12 | AF23: 15 | AH23: 919 | AI23: 1006 | AJ23: 1085 | AK23: 1097 | AM23: =AC23*10000/X23 -> 579.71014 | AN23: =AD23*10000/Y23 -> 808.08081 | AO23: =AE23*10000/Z23 -> 1090.9091 | AP23: =AF23*10000/AA23 -> 882.35294 | AS23: =(T23-O23)*10000/C23 -> 842.10526 | AT23: =(U23-P23)*10000/D23 -> 1142.8571 | AU23: =(V23-Q23)*10000/E23 -> 984.85781 | AW23: =N23*10000/H23 -> 26.809651 | AX23: =O23*10000/I23 -> 344.82759 | AY23: =P23*10000/J23 -> 666.66667 | AZ23: =Q23*10000/K23 -> 702.57611
A24: 海南省 | B24: 32 | C24: 123 | D24: 127 | E24: 108.01 | F24: 127.1 | H24: 11 | I24: 13 | J24: 13 | K24: 12.6 | L24: 19.4 | N24: 0.2 | O24: 1 | P24: 1 | Q24: 1 | S24: 3 | T24: 6 | U24: 14 | V24: 15 | X24: 33 | Y24: 125 | Z24: 129 | AA24: 129 | AC24: 3 | AD24: 6 | AE24: 13 | AF24: 14 | AH24: 1113 | AI24: 752 | AJ24: 1061 | AK24: 1023 | AM24: =AC24*10000/X24 -> 909.09091 | AN24: =AD24*10000/Y24 -> 480 | AO24: =AE24*10000/Z24 -> 1007.7519 | AP24: =AF24*10000/AA24 -> 1085.2713 | AR24: =(S24-N24)*10000/B24 -> 875 | AS24: =(T24-O24)*10000/C24 -> 406.50407 | AT24: =(U24-P24)*10000/D24 -> 1023.622 | AU24: =(V24-Q24)*10000/E24 -> 1296.1763 | AW24: =N24*10000/H24 -> 181.81818 | AX24: =O24*10000/I24 -> 769.23077 | AY24: =P24*10000/J24 -> 769.23077 | AZ24: =Q24*10000/K24 -> 793.65079
A25: 重庆市 | D25: 58 | E25: 49.17 | F25: 54.17 | H25: 12 | I25: 43 | J25: 7 | K25: 7.4 | L25: 9.2 | N25: 0.2 | O25: 2 | P25: 3 | Q25: 0.4 | S25: 0.2 | T25: 2 | U25: 3 | V25: 4 | X25: 10 | Y25: 38 | Z25: 58 | AA25: 60 | AC25: 0.2 | AD25: 2 | AE25: 3 | AF25: 4 | AH25: 549 | AI25: 602 | AJ25: 655 | AK25: 606 | AM25: =AC25*10000/X25 -> 200 | AN25: =AD25*10000/Y25 -> 526.31579 | AO25: =AE25*10000/Z25 -> 517.24138 | AP25: =AF25*10000/AA25 -> 666.66667 | AU25: =(V25-Q25)*10000/E25 -> 732.15375 | AW25: =N25*10000/H25 -> 166.66667 | AX25: =O25*10000/I25 -> 465.11628 | AY25: =P25*10000/J25 -> 4285.7143 | AZ25: =Q25*10000/K25 -> 540.54054
A26: 四川省 | B26: 116 | C26: 168 | D26: 169 | E26: 169.01 | F26: 169.01 | H26: 19 | I26: 13 | J26: 19 | K26: 22.1 | L26: 26.9 | N26: 1 | O26: 1 | P26: 2 | Q26: 2 | S26: 16 | T26: 22 | U26: 28 | V26: 27 | X26: 132 | Y26: 175 | Z26: 179 | AA26: 179 | AC26: 16 | AD26: 22 | AE26: 28 | AF26: 26 | AH26: 1492 | AI26: 1461 | AJ26: 1466 | AK26: 1554 | AM26: =AC26*10000/X26 -> 1212.1212 | AN26: =AD26*10000/Y26 -> 1257.1429 | AO26: =AE26*10000/Z26 -> 1564.2458 | AP26: =AF26*10000/AA26 -> 1452.514 | AR26: =(S26-N26)*10000/B26 -> 1293.1034 | AS26: =(T26-O26)*10000/C26 -> 1250 | AT26: =(U26-P26)*10000/D26 -> 1538.4615 | AU26: =(V26-Q26)*10000/E26 -> 1479.2024 | AW26: =N26*10000/H26 -> 526.31579 | AX26: =O26*10000/I26 -> 769.23077 | AY26: =P26*10000/J26 -> 1052.6316 | AZ26: =Q26*10000/K26 -> 904.97738
A27: 贵州省 | B27: 135 | C27: 161 | D27: 491 | E27: 970.67 | F27: 1117.6 | I27: 17 | J27: 19 | K27: 19 | L27: 19.4 | O27: 1 | P27: 1 | Q27: 1 | S27: 6 | T27: 16 | U27: 20 | V27: 45 | X27: 135 | Y27: 178 | Z27: 510 | AA27: 1057 | AC27: 6 | AD27: 16 | AE27: 20 | AF27: 45 | AH27: 793 | AI27: 932 | AJ27: 1032 | AK27: 1092 | AM27: =AC27*10000/X27 -> 444.44444 | AN27: =AD27*10000/Y27 -> 898.8764 | AO27: =AE27*10000/Z27 -> 392.15686 | AP27: =AF27*10000/AA27 -> 425.73321 | AR27: =(S27-N27)*10000/B27 -> 444.44444 | AS27: =(T27-O27)*10000/C27 -> 931.67702 | AT27: =(U27-P27)*10000/D27 -> 386.96538 | AU27: =(V27-Q27)*10000/E27 -> 453.29515 | AX27: =O27*10000/I27 -> 588.23529 | AY27: =P27*10000/J27 -> 526.31579 | AZ27: =Q27*10000/K27 -> 526.31579
A28: 云南省 | B28: 237.5 | C28: 312 | D28: 350 | E28: 295.43 | F28: 349.91 | H28: 0.5 | I28: 14 | J28: 25 | K28: 38.4 | L28: 47.2 | N28: 0.3 | O28: 1 | P28: 2 | Q28: 3 | S28: 28 | T28: 34 | U28: 48 | V28: 50 | X28: 238 | Y28: 326 | Z28: 350 | AA28: 350 | AC28: 28 | AD28: 34 | AE28: 47 | AF28: 47 | AH28: 1282 | AI28: 1182 | AJ28: 1332 | AK28: 1350 | AM28: =AC28*10000/X28 -> 1176.4706 | AN28: =AD28*10000/Y28 -> 1042.9448 | AO28: =AE28*10000/Z28 -> 1342.8571 | AP28: =AF28*10000/AA28 -> 1342.8571 | AR28: =(S28-N28)*10000/B28 -> 1166.3158 | AS28: =(T28-O28)*10000/C28 -> 1057.6923 | AT28: =(U28-P28)*10000/D28 -> 1314.2857 | AU28: =(V28-Q28)*10000/E28 -> 1590.9014 | AX28: =O28*10000/I28 -> 714.28571 | AY28: =P28*10000/J28 -> 800 | AZ28: =Q28*10000/K28 -> 781.25
A29: 西藏自治区 | B29: 79 | C29: 98 | D29: 110 | E29: 136.26 | F29: 136.51 | J29: 0 | K29: 0 | L29: 2.2 | S29: 6 | T29: 8 | U29: 13 | V29: 14 | X29: 79 | Y29: 98 | Z29: 110 | AA29: 137 | AC29: 6 | AD29: 8 | AE29: 13 | AF29: 14 | AH29: 894 | AI29: 900 | AJ29: 1116 | AK29: 1210 | AM29: =AC29*10000/X29 -> 759.49367 | AN29: =AD29*10000/Y29 -> 816.32653 | AO29: =AE29*10000/Z29 -> 1181.8182 | AP29: =AF29*10000/AA29 -> 1021.8978 | AR29: =(S29-N29)*10000/B29 -> 759.49367 | AS29: =(T29-O29)*10000/C29 -> 816.32653 | AT29: =(U29-P29)*10000/D29 -> 1181.8182 | AU29: =(V29-Q29)*10000/E29 -> 1027.4475
A30: 山西省 | B30: 484 | C30: 640 | D30: 778 | E30: 893.42 | F30: 1102.82 | H30: 51 | I30: 76 | J30: 162 | K30: 190.7 | L30: 210.9 | N30: 2 | O30: 6 | P30: 9 | Q30: 16 | S30: 52 | T30: 71 | U30: 94 | V30: 119 | X30: 406 | Y30: 659 | Z30: 806 | AA30: 926 | AC30: 40 | AD30: 65 | AE30: 83 | AF30: 104 | AH30: 1270 | AI30: 1274 | AJ30: 1392 | AK30: 1273 | AM30: =AC30*10000/X30 -> 985.22167 | AN30: =AD30*10000/Y30 -> 986.34294 | AO30: =AE30*10000/Z30 -> 1029.7767 | AP30: =AF30*10000/AA30 -> 1123.1102 | AR30: =(S30-N30)*10000/B30 -> 1033.0579 | AS30: =(T30-O30)*10000/C30 -> 1015.625 | AT30: =(U30-P30)*10000/D30 -> 1092.545 | AU30: =(V30-Q30)*10000/E30 -> 1152.8732 | AW30: =N30*10000/H30 -> 392.15686 | AX30: =O30*10000/I30 -> 789.47368 | AY30: =P30*10000/J30 -> 555.55556 | AZ30: =Q30*10000/K30 -> 839.01416
A31: 甘肃省 | B31: 768 | C31: 790 | D31: 836 | E31: 891.32 | F31: 1047.65 | H31: 18 | I31: 49 | J31: 71 | K31: 74 | L31: 77.1 | N31: 1 | O31: 2 | P31: 6 | Q31: 9 | S31: 73 | T31: 95 | U31: 118 | V31: 133 | X31: 769 | Y31: 790 | Z31: 852 | AA31: 908 | AC31: 73 | AD31: 93 | AE31: 112 | AF31: 125 | AH31: 1123 | AI31: 1336 | AJ31: 1511 | AK31: 1422 | AM31: =AC31*10000/X31 -> 949.28479 | AN31: =AD31*10000/Y31 -> 1177.2152 | AO31: =AE31*10000/Z31 -> 1314.554 | AP31: =AF31*10000/AA31 -> 1376.652 | AR31: =(S31-N31)*10000/B31 -> 937.5 | AS31: =(T31-O31)*10000/C31 -> 1177.2152 | AT31: =(U31-P31)*10000/D31 -> 1339.7129 | AU31: =(V31-Q31)*10000/E31 -> 1391.1951 | AW31: =N31*10000/H31 -> 555.55556 | AX31: =O31*10000/I31 -> 408.16327 | AY31: =P31*10000/J31 -> 845.07042 | AZ31: =Q31*10000/K31 -> 1216.2162
A32: 青海省 | B32: 786 | C32: 952 | D32: 1086 | E32: 1532.09 | F32: 1594.77 | H32: 5 | I32: 10 | J32: 15 | K32: 15.7 | L32: 16 | N32: 0.3 | O32: 1 | P32: 2 | Q32: 2 | S32: 113 | T32: 131 | U32: 158 | V32: 167 | X32: 785 | Y32: 946 | Z32: 1102 | AA32: 1565 | AC32: 113 | AD32: 130 | AE32: 155 | AF32: 162 | AH32: 1518 | AI32: 1464 | AJ32: 1376 | AK32: 1487 | AM32: =AC32*10000/X32 -> 1439.4904 | AN32: =AD32*10000/Y32 -> 1374.2072 | AO32: =AE32*10000/Z32 -> 1406.5336 | AP32: =AF32*10000/AA32 -> 1035.1438 | AR32: =(S32-N32)*10000/B32 -> 1433.8422 | AS32: =(T32-O32)*10000/C32 -> 1365.5462 | AT32: =(U32-P32)*10000/D32 -> 1436.4641 | AU32: =(V32-Q32)*10000/E32 -> 1076.9602 | AW32: =N32*10000/H32 -> 600 | AX32: =O32*10000/I32 -> 1000 | AY32: =P32*10000/J32 -> 1333.3333 | AZ32: =Q32*10000/K32 -> 1273.8854
A33: 宁夏回族自治区 | B33: 587 | C33: 761 | D33: 844 | E33: 1121.96 | F33: 1303.36 | H33: 33 | I33: 55 | J33: 74 | K33: 75.2 | L33: 80.6 | N33: 3 | O33: 4 | P33: 8 | Q33: 10 | S33: 76 | T33: 97 | U33: 115 | V33: 136 | X33: 612 | Y33: 799 | Z33: 895 | AA33: 1173 | AC33: 75 | AD33: 96 | AE33: 112 | AF33: 133 | AH33: 1326 | AI33: 1383 | AJ33: 1393 | AK33: 1371 | AM33: =AC33*10000/X33 -> 1225.4902 | AN33: =AD33*10000/Y33 -> 1201.5019 | AO33: =AE33*10000/Z33 -> 1251.3966 | AP33: =AF33*10000/AA33 -> 1133.8448 | AR33: =(S33-N33)*10000/B33 -> 1243.6116 | AS33: =(T33-O33)*10000/C33 -> 1222.0762 | AT33: =(U33-P33)*10000/D33 -> 1267.7725 | AU33: =(V33-Q33)*10000/E33 -> 1123.0347 | AW33: =N33*10000/H33 -> 909.09091 | AX33: =O33*10000/I33 -> 727.27273 | AY33: =P33*10000/J33 -> 1081.0811 | AZ33: =Q33*10000/K33 -> 1329.7872
A34: 新疆维吾尔自治区 | B34: 933 | C34: 976 | D34: 1027 | E34: 1282.68 | F34: 1331.98 | H34: 1 | I34: 2 | J34: 14 | K34: 16.7 | L34: 17.2 | N34: 0.01 | O34: 0.1 | P34: 1 | Q34: 2 | S34: 107 | T34: 116 | U34: 132 | V34: 157 | X34: 934 | Y34: 978 | Z34: 1072 | AA34: 1266 | AC34: 107 | AD34: 116 | AE34: 132 | AF34: 157 | AH34: 1156 | AI34: 1228 | AJ34: 1396 | AK34: 1284 | AM34: =AC34*10000/X34 -> 1145.6103 | AN34: =AD34*10000/Y34 -> 1186.0941 | AO34: =AE34*10000/Z34 -> 1231.3433 | AP34: =AF34*10000/AA34 -> 1240.1264 | AR34: =(S34-N34)*10000/B34 -> 1146.731 | AS34: =(T34-O34)*10000/C34 -> 1187.5 | AT34: =(U34-P34)*10000/D34 -> 1275.5599 | AU34: =(V34-Q34)*10000/E34 -> 1208.4074 | AW34: =N34*10000/H34 -> 100 | AX34: =O34*10000/I34 -> 500 | AY34: =P34*10000/J34 -> 714.28571 | AZ34: =Q34*10000/K34 -> 1197.6048

Sheet 用户光伏装机数据
B1: 201901 | C1: 201902 | D1: 201903 | E1: 201904 | F1: 201905 | G1: 201906 | H1: 201907 | I1: 201908 | J1: 201909 | K1: 201910 | L1: 201911 | M1: 201912 | N1: 202001 | O1: 202002 | P1: 202003 | Q1: 202004 | R1: 202005 | S1: 202006 | T1: 202007 | U1: 202008 | V1: 202009 | W1: 202010 | X1: 202011 | Y1: 202012 | Z1: 202101 | AA1: 202102 | AB1: 202103 | AC1: 202104 | AD1: 202105 | AE1: 202106 | AF1: 202107 | AG1: 202108 | AH1: 202109 | AI1: 202110 | AJ1: 202111 | AK1: 202112 | AN1: 1 | AO1: 2 | AP1: 3 | AQ1: 4 | AR1: 5 | AS1: 6 | AT1: 7 | AU1: 8 | AV1: 9 | AW1: 10 | AX1: 11 | AY1: 12
A2: 北京 | G2: 0.35 | H2: 0.063897 | I2: 0.2317335 | J2: 0.247972 | K2: 0.888244 | N2: 0.040062 | O2: 0 | P2: 0.003069 | Q2: 0.021942 | R2: 0.058974 | S2: 0.090849 | T2: 0.065412 | U2: =U39-T39 -> 0.138801 | V2: 0.1535 | W2: 0.1281 | X2: 0.2161 | Z2: 0.1786 | AA2: 0.0738 | AB2: 0.1198 | AC2: 0.2117 | AD2: 0.3528 | AE2: 0.3831 | AF2: 0.8349 | AG2: 0.4129 | AH2: 0.9094 | AI2: 0.5307 | AJ2: 1.6774 | AK2: 5.2768 | AS2: 18.5208 | AT2: 19.7179 | AU2: 26.5132 | AV2: 37.5837 | AW2: 44.478115
A3: 天津 | G3: 0.04 | H3: 0.411 | I3: 0.056102 | J3: 0.025725 | K3: 0.150136 | N3: 0.0008 | O3: 0 | P3: 0 | Q3: 0.00338 | R3: 0.0024 | S3: 0.0096 | T3: 0.14733 | U3: =U40-T40 -> 0.155124 | V3: 0.1373 | W3: 0.1514 | X3: 0.4185 | Z3: 0.0438 | AA3: 0.0489 | AB3: 0.0628 | AC3: 0.1516 | AD3: 0.2041 | AE3: 0.2821 | AF3: 0.1881 | AG3: 0.2924 | AH3: 0.3213 | AI3: 0.2483 | AJ3: 0.3474 | AK3: 0.5951 | AN3: 4.7263237 | AO3: 0.4216055 | AP3: 4.610248 | AQ3: 17.147776 | AR3: 25.439407 | AS3: 32.997844 | AT3: 38.548428 | AU3: 45.48621 | AV3: 57.9509 | AW3: 56.7659 | AX3: 173.2052
A4: 河北 | G4: 9.108782 | H4: 7.613066 | I4: 12.893203 | J4: 17.390082 | K4: 12.927215 | N4: 2.6241187 | O4: 0.1307875 | P4: 1.5698509 | Q4: 9.6245205 | R4: 12.905168 | S4: 16.837642 | T4: 17.363186 | U4: =U41-T41 -> 23.966927 | V4: 31.2149 | W4: 35.1162 | X4: 64.0835 | Z4: 5.9675 | AA4: 4.1371 | AB4: 17.1836 | AC4: 37.2244 | AD4: 37.7382 | AE4: 45.6523 | AF4: 44.8371 | AG4: 49.7806 | AH4: 57.8999 | AI4: 46.1181 | AJ4: 64.4772 | AK4: 123.0571 | AN4: 12.035 | AO4: 13.3488 | AP4: 28.1457 | AQ4: 55.8136 | AR4: 63.3849 | AS4: 67.2034 | AT4: 65.5694 | AU4: 67.8232 | AV4: 69.9044 | AW4: 64.3601 | AX4: 88.13 | AY4: 157.9777
A5: 其中：河北南网 | G5: 6.958782 | H5: 7.2 | I5: 10.8374 | J5: 15.113119 | K5: 11.0172 | N5: 2.5451667 | O5: 0.1240625 | P5: 1.3597949 | Q5: 8.960305 | R5: 11.930059 | S5: 15.475212 | T5: 15.895472 | U5: =U42-T42 -> 22.714628 | V5: 28.7508 | W5: 32.0827 | X5: 55.7591 | Z5: 5.4018 | AA5: 3.4495 | AB5: 16.2044 | AC5: 34.4905 | AD5: 33.5382 | AE5: 41.2945 | AF5: 39.2908 | AG5: 43.1765 | AH5: 51.5353 | AI5: 40.9591 | AJ5: 58.0853 | AK5: 109.535
A6: 冀北电网 | G6: 2.15 | H6: 0.413662 | I6: 2.055803 | J6: 2.276963 | K6: 1.910015 | N6: 0.078952 | O6: 0.006725 | P6: 0.210056 | Q6: 0.6642155 | R6: 0.975109 | S6: 1.36243 | T6: 1.4677135 | U6: =U43-T43 -> 1.252199 | V6: 2.4642 | W6: 3.0335 | X6: 8.3245 | Z6: 0.5657 | AA6: 0.6875 | AB6: 0.9792 | AC6: 2.7339 | AD6: 4.2 | AE6: 4.3578 | AF6: 5.5462 | AG6: 6.6041 | AH6: 6.3646 | AI6: 5.159 | AJ6: 6.3918 | AK6: 13.522
A7: 山西 | G7: 1.679881 | H7: 1.289771 | I7: 2.179311 | J7: 4.2711197 | K7: 7.5039975 | N7: 0.097213 | O7: 0.003 | P7: 0.0946615 | Q7: 0.4809445 | R7: 1.506641 | S7: 2.857445 | T7: 3.8275771 | U7: =U44-T44 -> 4.6087179 | V7: 5.8826 | W7: 6.0878 | X7: 20.3292 | Z7: 0.8123 | AA7: 0.3844 | AB7: 1.0245 | AC7: 2.3394 | AD7: 4.2833 | AE7: 5.8873 | AF7: 6.7127 | AG7: 7.0306 | AH7: 7.238 | AI7: 5.9761 | AJ7: 9.9275 | AK7: 22.6447
A8: 内蒙古 | G8: 0.204246 | H8: 0.11902 | I8: 0.044382 | J8: 0.177113 | K8: 1.697067 | N8: 0.065763 | O8: 0 | P8: 0.0008 | Q8: 0.035856 | R8: 0.01832 | S8: 0.128705 | T8: 0.04712 | U8: =U45-T45 -> 0.092936 | V8: 0.3413 | W8: 0.1561 | X8: 1.0987 | Z8: 0.0726 | AA8: 0.106 | AB8: 0.0087 | AC8: 0.1003 | AD8: 0.1175 | AE8: 0.0634 | AF8: 0.2646 | AG8: 0.1491 | AH8: 0.1323 | AI8: 0.552 | AJ8: 0.7906 | AK8: 2.9517
A9: 其中：蒙西 | G9: 0.0016 | H9: 0.003 | I9: 0.0084 | J9: 0.0015 | K9: 0.026671 | N9: 0.0535 | O9: 0 | P9: 0 | Q9: 0.0091 | R9: 0.00105 | S9: 0.05856 | T9: 0.00827 | U9: =U46-T46 -> 0.01592 | V9: 0.0968 | W9: 0.0285 | X9: 0.4838 | Z9: 0.0616 | AA9: 0.0705 | AB9: 0.0065 | AC9: 0.088 | AD9: 0.0163 | AE9: 0.0406 | AF9: 0.2371 | AG9: 0.0325 | AH9: 0.0654 | AI9: 0.1404 | AJ9: 0.1982 | AK9: 0.281
A10: 蒙东 | G10: 0.202646 | H10: 0.11602 | I10: 0.035982 | J10: 0.175613 | K10: 1.670396 | N10: 0.012263 | O10: 0 | P10: 0.0008 | Q10: 0.026756 | R10: 0.01727 | S10: 0.070145 | T10: 0.03885 | U10: =U47-T47 -> 0.077016 | V10: 0.2445 | W10: 0.1276 | X10: 0.6149 | Z10: 0.011 | AA10: 0.0355 | AB10: 0.0022 | AC10: 0.0123 | AD10: 0.1013 | AE10: 0.0228 | AF10: 0.0274 | AG10: 0.1166 | AH10: 0.0669 | AI10: 0.4116 | AJ10: 0.5924 | AK10: 2.6707
A11: 辽宁 | G11: 0.8758 | H11: 0.4055 | I11: 0.701206 | J11: 1.007487 | K11: 1.357455 | N11: 0.011195 | O11: 0.00417 | P11: 0.00749 | Q11: 0.0783 | R11: 0.254865 | S11: 0.7939015 | T11: 1.488858 | U11: =U48-T48 -> 1.3783205 | V11: 1.7548 | W11: 2.3567 | X11: 6.5393 | Z11: 0.101 | AA11: 0.0711 | AB11: 0.0685 | AC11: 0.5611 | AD11: 4.2 | AE11: 2.0447 | AF11: 1.847 | AG11: 2.5361 | AH11: 3.14 | AI11: 1.028 | AJ11: 4.1059 | AK11: 11.6456
A12: 吉林 | G12: 0.413608 | H12: 0.133081 | I12: 0.310494 | J12: 0.617114 | K12: 0.787384 | N12: 0.00364 | O12: 0.145563 | P12: 0.019536 | Q12: 0.073166 | R12: 0.425222 | S12: 0.137029 | T12: 0.3465525 | U12: =U49-T49 -> 0.6061915 | V12: 0.6826 | W12: 0.6614 | X12: 2.9643 | Z12: 0.0559 | AA12: 0.0268 | AB12: 0.0204 | AC12: 0.1176 | AD12: 0.0856 | AE12: 0.2453 | AF12: 0.314 | AG12: 0.4064 | AH12: 0.3774 | AI12: 0.3504 | AJ12: 0.3849 | AK12: 2.6022
A13: 黑龙江 | G13: 0.068 | H13: 0.0384 | I13: 0.1291 | J13: 0.519546 | K13: 0.3276 | N13: 0.012 | O13: 0.0009 | P13: 0.0005 | Q13: 0.05426 | R13: 0.043028 | S13: 0.051908 | T13: 0.068205 | U13: =U50-T50 -> 0.103619 | V13: 0.0601 | W13: 0.2 | X13: 1.0297 | Z13: 0.0278 | AA13: 0 | AB13: 0.045 | AC13: 0.0311 | AD13: 0.0412 | AE13: 0.0694 | AF13: 0.0718 | AG13: 0.131 | AH13: 0.0915 | AI13: 0.2171 | AJ13: 0.2662 | AK13: 1.1844
A14: 上海 | G14: 0.22 | H14: 0.2055 | I14: 0.2272 | J14: 0.1506 | K14: 0.3345 | N14: 0.046544 | O14: 0 | P14: 0.018565 | Q14: 0.0459022 | R14: 0.0726795 | S14: 0.1440565 | T14: 0.1641623 | U14: =U51-T51 -> 0.1490905 | V14: 0.184 | W14: 0.1204 | X14: 0.3435 | Z14: 0.0617 | AA14: 0.0365 | AB14: 0.0453 | AC14: 0.1083 | AD14: 0.1375 | AE14: 0.1329 | AF14: 0.1495 | AG14: 0.1676 | AH14: 0.1876 | AI14: 0.0716 | AJ14: 0.2706 | AK14: 0.4717
A15: 江苏 | G15: 2.07776 | H15: 1.8031639 | I15: 3.427096 | J15: 3.6969945 | K15: 3.6943895 | N15: 0.3323056 | O15: 0.009638 | P15: 0.386241 | Q15: 1.3082675 | R15: 1.754988 | S15: 1.97121 | T15: 2.2841789 | U15: =U52-T52 -> 2.2189055 | V15: 3.0691 | W15: 2.9263 | X15: 6.9188 | Z15: 0.3055 | AA15: 0.6522 | AB15: 1.891 | AC15: 3.0393 | AD15: 2.6704 | AE15: 2.859 | AF15: 4.0384 | AG15: 3.0402 | AH15: 3.608 | AI15: 3.6764 | AJ15: 4.9271 | AK15: 13.0681
A16: 浙江 | G16: 3.82102 | H16: 2.9892 | I16: 3.4746 | J16: 4.1095 | K16: 5.372 | N16: 1.0887465 | O16: 0.0136165 | P16: 0.7763235 | Q16: 1.7573965 | R16: 2.052077 | S16: 2.6506145 | T16: 2.5063612 | U16: =U53-T53 -> 2.7453643 | V16: 2.2441 | W16: 2.2235 | X16: 5.7009 | Z16: 0.8739 | AA16: 0.3364 | AB16: 0.7451 | AC16: 1.7078 | AD16: 1.3473 | AE16: 1.7208 | AF16: 1.6721 | AG16: 1.7316 | AH16: 2.7864 | AI16: 1.1857 | AJ16: 1.5615 | AK16: 2.6349
... A35: 海南 | G35: 0.012713 | H35: 0.387322 | I35: 0.0353345 | J35: 0.125937 | K35: 0.2809755 | N35: 0.016884 | O35: 0.023 | P35: 0.014303 | Q35: 0.00602 | R35: 0.019539 | S35: 0.02977 | T35: 0.038793 | U35: =U72-T72 -> 0.085791 | V35: 0.0409 | W35: 0.1034 | X35: 0.4566 | Z35: 0.0272 | AA35: 0.0863 | AB35: 0.0161 | AC35: 0.0424 | AD35: 0.0668 | AE35: 0.0333 | AF35: 0.0318 | AG35: 0.0749 | AH35: 0.0908 | AI35: 0.1088 | AJ35: 0.1126 | AK35: 0.6128
A36: 合计 | G36: =SUM(G2:G35) -> 56.718605 | H36: =SUM(H2:H35) -> 56.124187 | I36: =SUM(I2:I35) -> 79.216245 | J36: =SUM(J2:J35) -> 109.59405 | K36: =SUM(K2:K35) -> 116.05982 | N36: =SUM(N2:N35) -> 15.681162 | O36: =SUM(O2:O35) -> 1.203917 | P36: =SUM(P2:P35) -> 13.401348 | Q36: =SUM(Q2:Q35) -> 49.920735 | R36: =SUM(R2:R35) -> 72.56354 | S36: =SUM(S2:S35) -> 93.717516 | T36: =SUM(T2:T35) -> 106.08554 | U36: =SUM(U2:U35) -> 127.84704 | ... X36: =SUM(X2:X35) -> 414.9029 | Z36: =SUM(Z2:Z35) -> 36.9024 | AA36: =SUM(AA2:AA35) -> 32.3539 | AB36: =SUM(AB2:AB35) -> 84.678 | AC36: =SUM(AC2:AC35) -> 172.2979 | AD36: =SUM(AD2:AD35) -> 192.2661 | AE36: =SUM(AE2:AE35) -> 218.5723 | AF36: =SUM(AF2:AF35) -> 221.0342 | AG36: =SUM(AG2:AG35) -> 234.5192 | ... AK36: =SUM(AK2:AK35) -> 634.9901
B38: 201901 | C38: 201902 | D38: 201903 | E38: 201904 | F38: 201905 | G38: 201906 | H38: 201907 | I38: 201908 | J38: 201909 | K38: 201910 | L38: 201911 | M38: 201912 | N38: 202001 | O38: 202002 | P38: 202003 | Q38: 202004 | R38: 202005 | S38: 202006 | T38: 202007 | U38: 202008 | V38: 202009 | W38: 202010 | X38: 202011 | Y38: 202012 | Z38: 202101 | AA38: 202102 | AB38: 202103 | AC38: 202104 | AD38: 202105 | AE38: 202106 | AF38: 202107 | AG38: 202108 | AH38: 202109 | AI38: 202110 | AJ38: 202111 | AK38: 202112
A39: 北京 | F39: 3.15 | G39: =H39-H2 -> 3.500527 | H39: 3.564424 | I39: 4.0771135 | J39: =I39+J2 -> 4.3250855 | K39: =J39+K2 -> 5.2133295 | N39: =M39+N2 -> 0.040062 | O39: =N39+O2 -> 0.040062 | P39: =O39+P2 -> 0.043131 | Q39: 0.065073 | R39: 0.124047 | S39: 0.216487 | T39: 0.284999 | U39: =V39-V2 -> 0.4238 | V39: 0.5773 | W39: 0.7053 | X39: 0.9214 | Z39: =Z2 -> 0.1786 | AA39: =Z39+AA2 -> 0.2524 | AB39: =AA39+AB2 -> 0.3722 | AC39: =AB39+AC2 -> 0.5839 | AD39: =AC39+AD2 -> 0.9367 | AE39: 1.3199 | AF39: 2.1548 | AG39: 2.5677 | AH39: 3.4891 | AI39: 4.0626 | AJ39: 5.8045 | AK39: 11.5264
A40: 天津 | F40: 0.13 | G40: =H40-H3 -> 0.169 | H40: 0.58 | I40: 0.6354775 | J40: =I40+J3 -> 0.6612025 | K40: =J40+K3 -> 0.8113385 | N40: =M40+N3 -> 0.0008 | O40: =N40+O3 -> 0.0008 | P40: =O40+P3 -> 0.0008 | Q40: 0.006275 | R40: 0.008675 | S40: 0.035075 | T40: 0.338776 | U40: =V40-V3 -> 0.4939 | V40: 0.6312 | W40: 0.7826 | X40: 1.2011 | Z40: =Z3 -> 0.0438 | AA40: =Z40+AA3 -> 0.0927 | AB40: =AA40+AB3 -> 0.1555 | AC40: =AB40+AC3 -> 0.3071 | AD40: =AC40+AD3 -> 0.5112 | AE40: 0.7933 | AF40: 0.9815 | AG40: 1.2739 | AH40: 1.5951 | AI40: 1.8435 | AJ40: 2.1909 | AK40: 2.7859
A41: 河北 | F41: 23.74884 | G41: =H41-H4 -> 32.85658 | H41: 40.469646 | I41: 53.362828 | J41: =I41+J4 -> 70.75291 | K41: =J41+K4 -> 83.680125 | N41: =M41+N4 -> 2.6241187 | O41: =N41+O4 -> 2.7549062 | P41: =O41+P4 -> 4.3247571 | Q41: 13.949278 | R41: 26.854446 | S41: 43.692087 | T41: 61.055273 | U41: =V41-V4 -> 85.0222 | V41: 116.2371 | W41: 151.3534 | X41: 215.4475 | Z41: =Z4 -> 5.9675 | AA41: =Z41+AA4 -> 10.1046 | AB41: =AA41+AB4 -> 27.2882 | AC41: =AB41+AC4 -> 64.5126 | AD41: =AC41+AD4 -> 102.2508 | AE41: 147.9031 | AF41: 192.7401 | AG41: 242.5224 | AH41: 300.4223 | AI41: 346.5404 | AJ41: 411.0176 | AK41: 534.0746
A42: 其中：河北南网 | F42: 19.00884 | G42: =H42-H5 -> 25.97 | H42: 33.17 | I42: 44.0044 | J42: =I42+J5 -> 59.117519 | K42: =J42+K5 -> 70.134719 | N42: =M42+N5 -> 2.5451667 | O42: =N42+O5 -> 2.6692292 | P42: =O42+P5 -> 4.0290241 | Q42: 12.989329 | R42: 24.919388 | S42: 40.3946 | T42: 56.290072 | U42: =V42-V5 -> 79.0047 | V42: 107.7555 | W42: 139.8382 | X42: 195.6079 | Z42: =Z5 -> 5.4018 | AA42: =Z42+AA5 -> 8.8513 | AB42: =AA42+AB5 -> 25.0557 | AC42: =AB42+AC5 -> 59.5462 | AD42: =AC42+AD5 -> 93.0844 | AE42: 134.3789 | AF42: 173.6697 | AG42: 216.8479 | AH42: 268.3832 | AI42: 309.3423 | AJ42: 367.4277 | AK42: 476.9627
A43: 冀北电网 | F43: 4.74 | G43: =H43-H6 -> 6.888963 | H43: 7.302625 | I43: 9.358428 | J43: =I43+J6 -> 11.635391 | K43: =J43+K6 -> 13.545406 | N43: =M43+N6 -> 0.078952 | O43: =N43+O6 -> 0.085677 | P43: =O43+P6 -> 0.295733 | Q43: 0.9599485 | R43: 1.9350575 | S43: 3.2974875 | T43: 4.765201 | U43: =V43-V6 -> 6.0174 | V43: 8.4816 | W43: 11.5151 | X43: 19.8396 | Z43: =Z6 -> 0.5657 | AA43: =Z43+AA6 -> 1.2532 | AB43: =AA43+AB6 -> 2.2324 | AC43: =AB43+AC6 -> 4.9663 | AD43: =AC43+AD6 -> 9.1663 | AE43: 13.5242 | AF43: 19.0704 | AG43: 25.6745 | AH43: 32.0391 | AI43: 37.1981 | AJ43: 43.5899 | AK43: 57.1119
A44: 山西 | F44: 10.16097 | G44: =H44-H7 -> 11.840851 | H44: 13.130622 | I44: 15.414288 | J44: =I44+J7 -> 19.685407 | K44: =J44+K7 -> 27.189405 | N44: =M44+N7 -> 0.097213 | O44: =N44+O7 -> 0.100213 | P44: =O44+P7 -> 0.1948745 | Q44: 0.675819 | R44: 2.18246 | S44: 5.039905 | T44: 8.8674821 | U44: =V44-V7 -> 13.4762 | V44: 19.3588 | W44: 25.476 | X44: 45.8052 | Z44: =Z7 -> 0.8123 | AA44: =Z44+AA7 -> 1.1967 | AB44: =AA44+AB7 -> 2.2212 | AC44: =AB44+AC7 -> 4.5606 | AD44: =AC44+AD7 -> 8.8439 | AE44: 14.7313 | AF44: 21.4439 | AG44: 28.4745 | AH44: 35.7125 | AI44: 41.6886 | AJ44: 51.6161 | AK44: 74.2915
A45: 内蒙古 | F45: 1.702584 | G45: =H45-H8 -> 1.90683 | H45: 2.02585 | I45: 2.070232 | J45: =I45+J8 -> 2.247345 | K45: =J45+K8 -> 3.944412 | N45: =M45+N8 -> 0.065763 | O45: =N45+O8 -> 0.065763 | P45: =O45+P8 -> 0.066563 | Q45: 0.102419 | R45: 0.120739 | S45: 0.251244 | T45: 0.298364 | U45: =V45-V8 -> 0.3913 | V45: 0.7326 | W45: 0.8908 | X45: 1.9904 | Z45: =Z8 -> 0.0726 | AA45: =Z45+AA8 -> 0.1786 | AB45: =AA45+AB8 -> 0.1873 | AC45: =AB45+AC8 -> 0.2876 | AD45: =AC45+AD8 -> 0.4051 | AE45: 0.4686 | AF45: 0.7449 | AG45: 0.8953 | AH45: 1.0376 | AI45: 1.6026 | AJ45: 2.3984 | AK45: 5.3501
A46: 其中：蒙西 | F46: 0.129183 | G46: =H46-H9 -> 0.130783 | H46: 0.133783 | I46: 0.142183 | J46: =I46+J9 -> 0.143683 | K46: =J46+K9 -> 0.170354 | N46: =M46+N9 -> 0.0535 | O46: =N46+O9 -> 0.0535 | P46: =O46+P9 -> 0.0535 | Q46: 0.0626 | R46: 0.06365 | S46: 0.12401 | T46: 0.13228 | U46: =V46-V9 -> 0.1482 | V46: 0.245 | W46: 0.2756 | X46: 0.7594 | Z46: =Z9 -> 0.0616 | AA46: =Z46+AA9 -> 0.1321 | AB46: =AA46+AB9 -> 0.1386 | AC46: =AB46+AC9 -> 0.2266 | AD46: =AC46+AD9 -> 0.2429 | AE46: 0.2835 | AF46: 0.5323 | AG46: 0.5661 | AH46: 0.6416 | AI46: 0.795 | AJ46: 0.9962 | AK46: 1.2772
A47: 蒙东 | F47: 1.573401 | G47: =H47-H10 -> 1.776047 | H47: 1.892067 | I47: 1.928049 | J47: =I47+J10 -> 2.103662 | K47: =J47+K10 -> 3.774058 | N47: =M47+N10 -> 0.012263 | O47: =N47+O10 -> 0.012263 | P47: =O47+P10 -> 0.013063 | Q47: 0.039819 | R47: 0.057089 | S47: 0.127234 | T47: 0.166084 | U47: =V47-V10 -> 0.2431 | V47: 0.4876 | W47: 0.6152 | X47: 1.231 | Z47: =Z10 -> 0.011 | AA47: =Z47+AA10 -> 0.0465 | AB47: =AA47+AB10 -> 0.0487 | AC47: =AB47+AC10 -> 0.061 | AD47: =AC47+AD10 -> 0.1623 | AE47: 0.1851 | AF47: 0.2126 | AG47: 0.3291 | AH47: 0.396 | AI47: 0.8076 | AJ47: 1.4022 | AK47: 4.0729
A48: 辽宁 | F48: 2.4835 | G48: =H48-H11 -> 3.3593 | H48: 3.7648 | I48: 4.465963 | J48: =I48+J11 -> 5.47345 | K48: =J48+K11 -> 6.830905 | N48: =M48+N11 -> 0.011195 | O48: =N48+O11 -> 0.015365 | P48: =O48+P11 -> 0.022855 | Q48: 0.101155 | R48: 0.35602 | S48: 1.1499215 | T48: 2.6387795 | U48: =V48-V11 -> 4.0171 | V48: 5.7719 | W48: 8.1286 | X48: 14.6679 | Z48: =Z11 -> 0.101 | AA48: =Z48+AA11 -> 0.1721 | AB48: =AA48+AB11 -> 0.2406 | AC48: =AB48+AC11 -> 0.8017 | AD48: =AC48+AD11 -> 5.0017 | AE48: 3.716 | AF48: 5.563 | AG48: 8.1308 | AH48: 11.2708 | AI48: 12.2988 | AJ48: 16.4047 | AK48: 29.1297
A49: 吉林 | F49: 0.756171 | G49: =H49-H12 -> 1.2282323 | H49: 1.3613133 | I49: 1.592207 | J49: =I49+J12 -> 2.209321 | K49: =J49+K12 -> 2.996705 | N49: =M49+N12 -> 0.00364 | O49: =N49+O12 -> 0.149203 | P49: =O49+P12 -> 0.168739 | Q49: 0.241905 | R49: 0.667127 | S49: 0.804156 | T49: 1.1507085 | U49: =V49-V12 -> 1.7569 | V49: 2.4395 | W49: 3.1039 | X49: 6.0682 | Z49: =Z12 -> 0.0559 | AA49: =Z49+AA12 -> 0.0827 | AB49: =AA49+AB12 -> 0.1031 | AC49: =AB49+AC12 -> 0.2207 | AD49: =AC49+AD12 -> 0.3063 | AE49: 0.5517 | AF49: 0.8657 | AG49: 1.2721 | AH49: 1.6495 | AI49: 1.9998 | AJ49: 2.3878 | AK49: 4.9921
A50: 黑龙江 | F50: 0.8282 | G50: =H50-H13 -> 0.8225 | H50: 0.8609 | I50: 0.9899 | J50: =I50+J13 -> 1.509446 | K50: =J50+K13 -> 1.837046 | N50: =M50+N13 -> 0.012 | O50: =N50+O13 -> 0.0129 | P50: =O50+P13 -> 0.0134 | Q50: 0.06766 | R50: 0.110688 | S50: 0.209576 | T50: 0.277781 | U50: =V50-V13 -> 0.3814 | V50: 0.4415 | W50: 0.6415 | X50: 1.6807 | Z50: =Z13 -> 0.0278 | AA50: =Z50+AA13 -> 0.0278 | AB50: =AA50+AB13 -> 0.0728 | AC50: =AB50+AC13 -> 0.1039 | AD50: =AC50+AD13 -> 0.1451 | AE50: 0.2145 | AF50: 0.2863 | AG50: 0.4173 | AH50: 0.5089 | AI50: 0.726 | AJ50: 1.018 | AK50: 2.2025
... A56: 江西 | F56: 3.86 | G56: =H56-H19 -> 4.7123 | H56: 5.2072 | I56: 6.3192 | J56: =I56+J19 -> 7.672 | K56: =J56+K19 -> 9.8245 | N56: =M56+N19 -> 0.263909 | O56: =N56+O19 -> 0.293789 | P56: =O56+P19 -> 0.442051 | Q56: 0.916109 | R56: 1.766758 | S56: 2.8160965 | T56: 4.3828335 | U56: =V56-V19 -> 5.7842 | V56: 7.4741 | W56: 9.134 | X56: 14.8327 | Z56: =Z19 -> 0.5313 | AA56: =Z56+AA19 -> 1.0215 | AB56: =AA56+AB19 -> 1.9417 | AC56: =AB56+AC19 -> 4.0516 | AD56: =AC56+AD19 -> 6.3833 | AE56: 10.0767 | AF56: 14.265 | AG56: 18.8812 | AH56: 24.4653 | AI56: 29.5102 | AJ56: 35.5597 | AK56: 49.0241
A57: 山东 | F57: 42.9135 | G57: =H57-H20 -> 61.4343 | H57: 81.1522 | I57: 107.665 | J57: =I57+J20 -> 145.2487 | K57: =J57+K20 -> 189.72682 | N57: =M57+N20 -> 4.7263237 | O57: =N57+O20 -> 5.1479292 | P57: =O57+P20 -> 9.7581772 | Q57: 26.905953 | R57: 52.34536 | S57: 85.583762 | T57: 124.13249 | U57: =V57-V20 -> 169.6187 | V57: 227.5696 | W57: 284.3355 | X57: 457.5407 | Y57: 466 | Z57: =Z20 -> 12.035 | AA57: =Z57+AA20 -> 25.3838 | AB57: =AA57+AB20 -> 53.5295 | AC57: =AB57+AC20 -> 109.3431 | AD57: =AC57+AD20 -> 172.728 | AE57: 240.4745 | AF57: 309.919 | AG57: 378.1659 | AH57: 448.2107 | AI57: 512.6124 | AJ57: 600.8018 | AK57: 763.2183
A58: 河南 | F58: 13.63934 | G58: =H58-H21 -> 17.6293 | H58: 23.8286 | I58: 31.0919 | J58: =I58+J21 -> 41.2316 | K58: =J58+K21 -> 48.2795 | N58: =M58+N21 -> 2.0353965 | O58: =N58+O21 -> 2.171565 | P58: =O58+P21 -> 4.4751777 | Q58: 9.5836757 | R58: 17.728381 | S58: 26.990064 | T58: 38.199446 | U58: =V58-V21 -> 48.5735 | V58: 61.9354 | W58: 74.2602 | X58: 105.3314 | Z58: =Z21 -> 5.1144 | AA58: =Z58+AA21 -> 9.97 | AB58: =AA58+AB21 -> 20.8916 | AC58: =AB58+AC21 -> 40.4041 | AD58: =AC58+AD21 -> 64.3464 | AE58: 89.9464 | AF58: 115.7053 | AG58: 139.3703 | AH58: 171.6745 | AI58: 207.8536 | AJ58: 267.9879 | AK58: 343.2272
A59: 湖北 | F59: 2.44 | G59: =H59-H22 -> 2.51 | H59: 2.88 | I59: 3.5501355 | J59: =I59+J22 -> 4.3022161 | K59: =J59+K22 -> 5.0883676 | N59: =M59+N22 -> 0.091982 | O59: =N59+O22 -> 0.091982 | P59: =O59+P22 -> 0.095707 | Q59: 0.1766005 | R59: 0.3544765 | S59: 0.5805865 | T59: 0.839664 | U59: =V59-V22 -> 1.1681 | V59: 1.8213 | W59: 2.0703 | X59: 3.005 | Z59: =Z22 -> 0.3888 | AA59: =Z59+AA22 -> 0.5188 | AB59: =AA59+AB22 -> 0.7337 | AC59: =AB59+AC22 -> 0.9359 | AD59: =AC59+AD22 -> 1.3686 | AE59: 1.543 | AF59: 2.0678 | AG59: 2.5983 | AH59: 3.3159 | AI59: 3.8932 | AJ59: 4.9037 | AK59: 7.3506
A60: 湖南 | F60: 5.851063 | G60: =H60-H23 -> 6.4286 | H60: 7.7331 | I60: 8.2013 | J60: =I60+J23 -> 8.7699 | K60: =J60+K23 -> 9.8826625 | N60: =M60+N23 -> 0.1873 | O60: =N60+O23 -> 0.2202 | P60: =O60+P23 -> 0.3406 | Q60: 0.6375 | R60: 1.17751 | S60: 1.61731 | T60: 2.34871 | U60: =V60-V23 -> 3.0412 | V60: 3.6257 | W60: 4.3898 | X60: 7.2949 | Z60: =Z23 -> 0.395 | AA60: =Z60+AA23 -> 0.6442 | AB60: =AA60+AB23 -> 1.1071 | AC60: =AB60+AC23 -> 1.8924 | AD60: =AC60+AD23 -> 2.7352 | AE60: 4.0384 | AF60: 5.4836 | AG60: 7.0713 | AH60: 9.4154 | AI60: 11.2964 | AJ60: 13.5559 | AK60: 19.0448
A61: 重庆 | F61: 0.218251 | G61: =H61-H24 -> 0.248041 | H61: 0.258285 | I61: 0.324618 | J61: =I61+J24 -> 0.365218 | K61: =J61+K24 -> 0.391229 | N61: =M61+N24 -> 0.001918 | O61: =N61+O24 -> 0.001918 | P61: =O61+P24 -> 0.007544 | Q61: 0.027268 | R61: 0.03539 | S61: 0.063734 | T61: 0.094223 | U61: =V61-V24 -> 0.1267 | V61: 0.1329 | W61: 0.162 | X61: 0.176 | Z61: =Z24 -> 0.0158 | AA61: =Z61+AA24 -> 0.0182 | AB61: =AA61+AB24 -> 0.0278 | AC61: =AB61+AC24 -> 0.0456 | AD61: =AC61+AD24 -> 0.0715 | AE61: 0.0897 | AF61: 0.1231 | AG61: 0.1517 | AH61: 0.1731 | AI61: 0.2097 | AJ61: 0.2585 | AK61: 0.3459
A62: 四川 | F62: 0.4535 | G62: =H62-H25 -> 0.452105 | H62: 0.8447965 | I62: 0.9124495 | J62: =I62+J25 -> 1.0517605 | K62: =J62+K25 -> 1.2946805 | N62: =M62+N25 -> 0.052872 | O62: =N62+O25 -> 0.055672 | P62: =O62+P25 -> 0.072962 | Q62: 0.126537 | R62: 0.219969 | S62: 0.499661 | T62: 0.764531 | U62: =V62-V25 -> 0.946 | V62: 1.0618 | W62: 1.1988 | X62: 1.9801 | Z62: =Z25 -> 0.0411 | AA62: =Z62+AA25 -> 0.1028 | AB62: =AA62+AB25 -> 0.2124 | AC62: =AB62+AC25 -> 0.5283 | AD62: =AC62+AD25 -> 0.7752 | AE62: 0.9662 | AF62: 1.2243 | AG62: 1.7284 | AH62: 2.0112 | AI62: 2.2019 | AJ62: 3.106 | AK62: 3.8123
A63: 陕西 | F63: 2.207777 | G63: =H63-H26 -> 2.584636 | H63: 3.277233 | I63: 4.240469 | J63: =I63+J26 -> 5.3280725 | K63: =J63+K26 -> 6.6805495 | N63: =M63+N26 -> 0.069535 | O63: =N63+O26 -> 0.087301 | P63: =O63+P26 -> 0.110818 | Q63: 0.359284 | R63: 1.277771 | S63: 2.9671331 | T63: 4.2713348 | U63: =V63-V26 -> 6.3381 | V63: 7.8289 | W63: 9.2298 | X63: 13.5018 | Z63: =Z26 -> 0.0447 | AA63: =Z63+AA26 -> 0.0891 | AB63: =AA63+AB26 -> 0.3706 | AC63: =AB63+AC26 -> 1.0755 | AD63: =AC63+AD26 -> 2.1592 | AE63: 4.2139 | AF63: 5.9322 | AG63: 8.3188 | AH63: 10.5095 | AI63: 12.647 | AJ63: 16.0348 | AK63: 21.7042
A64: 甘肃 | F64: 2.117933 | G64: =H64-H27 -> 2.2323855 | H64: 2.2936955 | I64: 2.411596 | J64: =I64+J27 -> 2.573644 | K64: =J64+K27 -> 3.251883 | N64: =M64+N27 -> 0.00536 | O64: =N64+O27 -> 0.00536 | P64: =O64+P27 -> 0.01456 | Q64: 0.027016 | R64: 0.056334 | S64: 0.092884 | T64: 0.145542 | U64: =V64-V27 -> 0.2249 | V64: 0.2793 | W64: 0.4284 | X64: 0.7275 | Z64: =Z27 -> 0.0235 | AA64: =Z64+AA27 -> 0.0265 | AB64: =AA64+AB27 -> 0.0533 | AC64: =AB64+AC27 -> 0.1363 | AD64: =AC64+AD27 -> 0.1744 | AE64: 0.2282 | AF64: 0.3274 | AG64: 0.445 | AH64: 0.5349 | AI64: 0.5915 | AJ64: 0.7526 | AK64: 1.0777
...

Sheet 各省城镇化数据
C1: 2005 | D1: 2006 | E1: 2007 | F1: 2008 | G1: 2009 | H1: 2010 | I1: 2011 | J1: 2012 | K1: 2013 | L1: 2014 | M1: 2015 | N1: 2016 | O1: 2017 | P1: 2018 | Q1: 2019 | R1: 2020 | S1: 2021 | T1: 2022 | U1: 2023 | V1: 2024 | W1: 2025 | X1: 2026 | Y1: 2027 | Z1: 2028 | AA1: 2029 | AB1: 2030 | AC1: 2031 | AD1: 2032 | AE1: 2033 | AF1: 2034 | AG1: 2035 | AH1: 2036 | AI1: 2037 | AJ1: 2038 | AK1: 2039 | AL1: 2040 | AM1: 2041 | AN1: 2042 | AO1: 2043 | AP1: 2044 | AQ1: 2045 | AR1: 2046 | AS1: 2047 | AT1: 2048 | AU1: 2049 | AV1: 2050 | AW1: 2051 | AX1: 2052 | AY1: 2053 | AZ1: 2054 | BA1: 2055 | BB1: 2056 | BC1: 2057 | BD1: 2058 | BE1: 2059 | BF1: 2060
A2: 北京市 | B2: 城镇化率 | C2: 0.83615085 | D2: 0.84322299 | E2: 0.84486874 | F2: 0.84923772 | G2: 0.85 | H2: 0.85932722 | I2: 0.86215415 | J2: 0.86284889 | K2: 0.864 | L2: 0.86503915 | M2: 0.86700183 | N2: 0.86742597 | O2: 0.8691887 | P2: 0.87089416 | Q2: 0.87351598 | R2: 0.87528552 | S2: 0.87482869 | T2: 0.88105474 | U2: 0.88732509 | V2: 0.89364007 | W2: 0.9 | X2: 0.90099503 | Y2: 0.90199117 | Z2: 0.90298841 | AA2: 0.90398675 | AB2: 0.90498619 | AC2: 0.90598674 | AD2: 0.90698839 | AE2: 0.90799115 | AF2: 0.90899502 | AG2: 0.91 | AH2: 0.91455 | AI2: 0.91912275 | AJ2: 0.92371836 | AK2: 0.92833696 | AL2: 0.93297864 | AM2: 0.93649926 | AN2: 0.94003317 | AO2: 0.94358041 | AP2: 0.94714104 | AQ2: 0.95071511 | AR2: 0.95430266 | AS2: 0.95790375 | AT2: 0.96151842 | AU2: 0.96514674 | AV2: 0.96878875 | AW2: 0.97 | AX2: 0.97 | AY2: 0.97 | AZ2: 0.97 | BA2: 0.97 | BB2: 0.97 | BC2: 0.97 | BD2: 0.97 | BE2: 0.97 | BF2: 0.97
A3: 天津市 | B3: 城镇化率 | C3: 0.75071908 | D3: 0.7572093 | E3: 0.7632287 | F3: 0.77210884 | G3: 0.78013029 | H3: 0.79599692 | I3: 0.80462342 | J3: 0.81567489 | K3: 0.82269504 | L3: 0.82575227 | M3: 0.82904795 | N3: 0.83298683 | O3: 0.83546099 | P3: 0.83947939 | Q3: 0.8433213 | R3: 0.84715213 | S3: 0.84850692 | T3: 0.85136571 | U3: 0.85423413 | V3: 0.85711222 | W3: 0.86 | X3: 0.86295392 | Y3: 0.86591799 | Z3: 0.86889224 | AA3: 0.8718767 | AB3: 0.87487142 | AC3: 0.87787642 | AD3: 0.88089174 | AE3: 0.88391743 | AF3: 0.8869535 | AG3: 0.89 | AH3: 0.89445 | AI3: 0.89892225 | AJ3: 0.90341686 | AK3: 0.90793395 | AL3: 0.91247362 | AM3: 0.91591686 | AN3: 0.9193731 | AO3: 0.92284238 | AP3: 0.92632475 | AQ3: 0.92982027 | AR3: 0.93332897 | AS3: 0.93685092 | AT3: 0.94038615 | AU3: 0.94393473 | AV3: 0.94749669 | AW3: 0.9510721 | AX3: 0.954661 | AY3: 0.95826344 | AZ3: 0.96187947 | BA3: 0.96550915 | BB3: 0.96915253 | BC3: 0.97 | BD3: 0.97 | BE3: 0.97 | BF3: 0.97
A4: 河北省 | B4: 城镇化率 | C4: 0.37687929 | D4: 0.38764859 | E4: 0.40256373 | F4: 0.41894405 | G4: 0.43744669 | H4: 0.44495413 | I4: 0.45589049 | J4: 0.46598733 | K4: 0.48024149 | L4: 0.49365014 | M4: 0.51667801 | N4: 0.53871186 | O4: 0.55743015 | P4: 0.57325613 | Q4: 0.58775346 | R4: 0.60075027 | S4: 0.61143931 | T4: 0.62085954 | U4: 0.6304249 | V4: 0.64013763 | W4: 0.65 | X4: 0.65483491 | Y4: 0.65970579 | Z4: 0.66461289 | AA4: 0.6695565 | AB4: 0.67453688 | AC4: 0.6795543 | AD4: 0.68460905 | AE4: 0.68970139 | AF4: 0.69483162 | AG4: 0.7 | AH4: 0.7035 | AI4: 0.7070175 | AJ4: 0.71055259 | AK4: 0.71410535 | AL4: 0.71767588 | AM4: 0.72038405 | AN4: 0.72310244 | AO4: 0.72583109 | AP4: 0.72857003 | AQ4: 0.73131931 | AR4: 0.73407897 | AS4: 0.73684904 | AT4: 0.73962956 | AU4: 0.74242057 | AV4: 0.74522212 | AW4: 0.74803423 | AX4: 0.75085696 | AY4: 0.75369034 | AZ4: 0.75653442 | BA4: 0.75938922 | BB4: 0.7622548 | BC4: 0.76513119 | BD4: 0.76801844 | BE4: 0.77091658 | BF4: 0.77382565
A5: 山西省 | B5: 城镇化率 | C5: 0.42116244 | D5: 0.42992593 | E5: 0.4403183 | F5: 0.45118734 | G5: 0.45987744 | H5: 0.4804141 | I5: 0.49803481 | J5: 0.5132469 | K5: 0.52871287 | L5: 0.5430839 | M5: 0.55868144 | N5: 0.57256688 | O5: 0.58603989 | P5: 0.59851513 | Q5: 0.61281098 | R5: 0.6252149 | S5: 0.6341954 | T5: 0.64534886 | U5: 0.65669846 | V5: 0.66824768 | W5: 0.68 | X5: 0.68484187 | Y5: 0.68971823 | Z5: 0.6946293 | AA5: 0.69957534 | AB5: 0.7045566 | AC5: 0.70957333 | AD5: 0.71462577 | AE5: 0.7197142 | AF5: 0.72483885 | AG5: 0.73 | AH5: 0.73365 | AI5: 0.73731825 | AJ5: 0.74100484 | AK5: 0.74470987 | AL5: 0.74843341 | AM5: 0.75125765 | AN5: 0.75409254 | AO5: 0.75693813 | AP5: 0.75979446 | AQ5: 0.76266157 | AR5: 0.76553949 | AS5: 0.76842828 | AT5: 0.77132797 | AU5: 0.7742386 | AV5: 0.77716021 | AW5: 0.78009284 | AX5: 0.78303655 | AY5: 0.78599136 | AZ5: 0.78895732 | BA5: 0.79193447 | BB5: 0.79492286 | BC5: 0.79792253 | BD5: 0.80093351 | BE5: 0.80395586 | BF5: 0.80698961
A6: 内蒙古自治区 | B6: 城镇化率 | C6: 0.47191011 | D6: 0.48654244 | E6: 0.50144092 | F6: 0.51718494 | G6: 0.53417413 | H6: 0.55501618 | I6: 0.57044534 | J6: 0.58400974 | K6: 0.59837067 | L6: 0.60963659 | M6: 0.62090164 | N6: 0.63382594 | O6: 0.64611591 | P6: 0.6552436 | Q6: 0.66459627 | R6: 0.6749896 | S6: 0.68208333 | T6: 0.68405394 | U6: 0.68603025 | V6: 0.68801226 | W6: 0.69 | X6: 0.69294287 | Y6: 0.69589829 | Z6: 0.69886632 | AA6: 0.70184701 | AB6: 0.70484041 | AC6: 0.70784657 | AD6: 0.71086556 | AE6: 0.71389742 | AF6: 0.71694222 | AG6: 0.72 | AH6: 0.7236 | AI6: 0.727218 | AJ6: 0.73085409 | AK6: 0.73450836 | AL6: 0.7381809 | AM6: 0.74096645 | AN6: 0.74376251 | AO6: 0.74656912 | AP6: 0.74938632 | AQ6: 0.75221415 | AR6: 0.75505265 | AS6: 0.75790187 | AT6: 0.76076183 | AU6: 0.76363259 | AV6: 0.76651418 | AW6: 0.76940664 | AX6: 0.77231002 | AY6: 0.77522435 | AZ6: 0.77814969 | BA6: 0.78108606 | BB6: 0.78403351 | BC6: 0.78699208 | BD6: 0.78996182 | BE6: 0.79294276 | BF6: 0.79593496
A7: 辽宁省 | B7: 城镇化率 | C7: 0.58706468 | D7: 0.58979162 | E7: 0.59190321 | F7: 0.6004635 | G7: 0.60354757 | H7: 0.62102857 | I7: 0.6405572 | J7: 0.65645714 | K7: 0.66460481 | L7: 0.67049105 | M7: 0.68049793 | N7: 0.68869887 | O7: 0.69480519 | P7: 0.70263342 | Q7: 0.71218144 | R7: 0.72150411 | S7: 0.7280681 | T7: 0.71835857 | U7: 0.70877852 | V7: 0.69932623 | W7: 0.69 | X7: 0.69294287 | Y7: 0.69589829 | Z7: 0.69886632 | AA7: 0.70184701 | AB7: 0.70484041 | AC7: 0.70784657 | AD7: 0.71086556 | AE7: 0.71389742 | AF7: 0.71694222 | AG7: 0.72 | AH7: 0.7236 | AI7: 0.727218 | AJ7: 0.73085409 | AK7: 0.73450836 | AL7: 0.7381809 | AM7: 0.74096645 | AN7: 0.74376251 | AO7: 0.74656912 | AP7: 0.74938632 | AQ7: 0.75221415 | AR7: 0.75505265 | AS7: 0.75790187 | AT7: 0.76076183 | AU7: 0.76363259 | AV7: 0.76651418 | AW7: 0.76940664 | AX7: 0.77231002 | AY7: 0.77522435 | AZ7: 0.77814969 | BA7: 0.78108606 | BB7: 0.78403351 | BC7: 0.78699208 | BD7: 0.78996182 | BE7: 0.79294276 | BF7: 0.79593496
A8: 吉林省 | B8: 城镇化率 | C8: 0.52503682 | D8: 0.52956298 | E8: 0.53150183 | F8: 0.53218727 | G8: 0.53321168 | H8: 0.53330906 | I8: 0.53394495 | J8: 0.54521868 | K8: 0.55734633 | L8: 0.5681302 | M8: 0.57634902 | N8: 0.58745617 | O8: 0.59699129 | P8: 0.60869565 | Q8: 0.61642157 | R8: 0.62651105 | S8: 0.63368421 | T8: 0.63772436 | U8: 0.64179026 | V8: 0.64588209 | W8: 0.65 | X8: 0.65483491 | Y8: 0.65970579 | Z8: 0.66461289 | AA8: 0.6695565 | AB8: 0.67453688 | AC8: 0.6795543 | AD8: 0.68460905 | AE8: 0.68970139 | AF8: 0.69483162 | AG8: 0.7 | AH8: 0.7035 | AI8: 0.7070175 | AJ8: 0.71055259 | AK8: 0.71410535 | AL8: 0.71767588 | AM8: 0.72038405 | AN8: 0.72310244 | AO8: 0.72583109 | AP8: 0.72857003 | AQ8: 0.73131931 | AR8: 0.73407897 | AS8: 0.73684904 | AT8: 0.73962956 | AU8: 0.74242057 | AV8: 0.74522212 | AW8: 0.74803423 | AX8: 0.75085696 | AY8: 0.75369034 | AZ8: 0.75653442 | BA8: 0.75938922 | BB8: 0.7622548 | BC8: 0.76513119 | BD8: 0.76801844 | BE8: 0.77091658 | BF8: 0.77382565
A9: 黑龙江省 | B9: 城镇化率 | C9: 0.53089005 | D9: 0.53492022 | E9: 0.53896444 | F9: 0.55398693 | G9: 0.55488761 | H9: 0.55674406 | I9: 0.56478054 | J9: 0.56874329 | K9: 0.58046918 | L9: 0.5922949 | M9: 0.60470388 | N9: 0.6110309 | O9: 0.61900559 | P9: 0.63450556 | Q9: 0.64608295 | R9: 0.6559445 | S9: 0.65696 | T9: 0.65521304 | U9: 0.65347073 | V9: 0.65173306 | W9: 0.65 | X9: 0.65483491 | Y9: 0.65970579 | Z9: 0.66461289 | AA9: 0.6695565 | AB9: 0.67453688 | AC9: 0.6795543 | AD9: 0.68460905 | AE9: 0.68970139 | AF9: 0.69483162 | AG9: 0.7 | AH9: 0.7035 | AI9: 0.7070175 | AJ9: 0.71055259 | AK9: 0.71410535 | AL9: 0.71767588 | AM9: 0.72038405 | AN9: 0.72310244 | AO9: 0.72583109 | AP9: 0.72857003 | AQ9: 0.73131931 | AR9: 0.73407897 | AS9: 0.73684904 | AT9: 0.73962956 | AU9: 0.74242057 | AV9: 0.74522212 | AW9: 0.74803423 | AX9: 0.75085696 | AY9: 0.75369034 | AZ9: 0.75653442 | BA9: 0.75938922 | BB9: 0.7622548 | BC9: 0.76513119 | BD9: 0.76801844 | BE9: 0.77091658 | BF9: 0.77382565
A10: 上海市 | B10: 城镇化率 | C10: 0.89100529 | D10: 0.88696538 | E10: 0.88662791 | F10: 0.88603456 | G10: 0.88597285 | H10: 0.89274859 | I10: 0.89303905 | J10: 0.89287203 | K10: 0.89583333 | L10: 0.89298743 | M10: 0.88527258 | N10: 0.89014998 | O10: 0.89091646 | P10: 0.89131313 | Q10: 0.8923821 | R10: 0.89308682 | S10: 0.89312977 | T10: 0.8948424 | U10: 0.8965583 | V10: 0.8982775 | W10: 0.9 | X10: 0.90198028 | Y10: 0.90396491 | Z10: 0.90595391 | AA10: 0.90794729 | AB10: 0.90994505 | AC10: 0.91194721 | AD10: 0.91395378 | AE10: 0.91596476 | AF10: 0.91798016 | AG10: 0.92 | AH10: 0.9246 | AI10: 0.929223 | AJ10: 0.93386912 | AK10: 0.93853846 | AL10: 0.94323115 | AM10: 0.94679046 | AN10: 0.9503632 | AO10: 0.95394943 | AP10: 0.95754918 | AQ10: 0.96116252 | AR10: 0.9647895 | AS10: 0.96843016 | AT10: 0.97 | AU10: 0.97 | AV10: 0.97 | AW10: 0.97 | AX10: 0.97 | AY10: 0.97 | AZ10: 0.97 | BA10: 0.97 | BB10: 0.97 | BC10: 0.97 | BD10: 0.97 | BE10: 0.97 | BF10: 0.97
A11: 江苏省 | B11: 城镇化率 | C11: 0.50500791 | D11: 0.51893939 | E11: 0.53204713 | F11: 0.54303015 | G11: 0.55608195 | H11: 0.60579489 | I11: 0.62009223 | J11: 0.63004926 | K11: 0.6439209 | L11: 0.65704625 | M11: 0.67492483 | N11: 0.68929722 | O11: 0.70176897 | P11: 0.71193464 | Q11: 0.72464281 | R11: 0.73445795 | S11: 0.73944738 | T11: 0.74207154 | U11: 0.744705 | V11: 0.74734781 | W11: 0.75 | X11: 0.75485604 | Y11: 0.75974353 | Z11: 0.76466266 | AA11: 0.76961363 | AB11: 0.77459667 | AC11: 0.77961197 | AD11: 0.78465974 | AE11: 0.78974019 | AF11: 0.79485354 | AG11: 0.8 | AH11: 0.804 | AI11: 0.80802 | AJ11: 0.8120601 | AK11: 0.8161204 | AL11: 0.820201 | AM11: 0.82329606 | AN11: 0.82640279 | AO11: 0.82952124 | AP11: 0.83265146 | AQ11: 0.8357935 | AR11: 0.83894739 | AS11: 0.84211318 | AT11: 0.84529092 | AU11: 0.84848065 | AV11: 0.85168242 | AW11: 0.85489627 | AX11: 0.85812224 | AY11: 0.86136039 | AZ11: 0.86461076 | BA11: 0.8678734 | BB11: 0.87114834 | BC11: 0.87443565 | BD11: 0.87773535 | BE11: 0.88104751 | BF11: 0.88437217
A12: 浙江省 | B12: 城镇化率 | C12: 0.56020838 | D12: 0.56506309 | E12: 0.57206596 | F12: 0.57597851 | G12: 0.57903715 | H12: 0.61611896 | I12: 0.62298025 | J12: 0.62902375 | K12: 0.63934993 | L12: 0.64957555 | M12: 0.66315789 | N12: 0.67720685 | O12: 0.689141 | P12: 0.70014347 | Q12: 0.71576471 | R12: 0.72170686 | S12: 0.7266055 | T12: 0.73238481 | U12: 0.73821008 | V12: 0.74408169 | W12: 0.75 | X12: 0.75485604 | Y12: 0.75974353 | Z12: 0.76466266 | AA12: 0.76961363 | AB12: 0.77459667 | AC12: 0.77961197 | AD12: 0.78465974 | AE12: 0.78974019 | AF12: 0.79485354 | AG12: 0.8 | AH12: 0.804 | AI12: 0.80802 | AJ12: 0.8120601 | AK12: 0.8161204 | AL12: 0.820201 | AM12: 0.82329606 | AN12: 0.82640279 | AO12: 0.82952124 | AP12: 0.83265146 | AQ12: 0.8357935 | AR12: 0.83894739 | AS12: 0.84211318 | AT12: 0.84529092 | AU12: 0.84848065 | AV12: 0.85168242 | AW12: 0.85489627 | AX12: 0.85812224 | AY12: 0.86136039 | AZ12: 0.86461076 | BA12: 0.8678734 | BB12: 0.87114834 | BC12: 0.87443565 | BD12: 0.87773535 | BE12: 0.88104751 | BF12: 0.88437217
