Workbook
Name billion_kw_to_MW: [1]About!$B$29
Name gigwatt_to_megawatt: [1]About!$B$30
Name OLE_LINK2: 户用光伏安装数据!#REF!
Name Percent_rural: [1]About!$A$27
Name Percent_Urban: [1]About!$A$26

Sheet National Workbook
B1: 2017 | C1: 2018 | D1: 2019 | E1: 2020 | F1: 2021 | G1: 2022 | I1: 2017 | J1: 2018 | K1: 2019 | L1: 2020 | M1: 2021 | N1: 2022 | P1: 2019 | Q1: 2020 | R1: 2021 | S1: 2022 | AB1: 户用分布式 | AC1: 户用分布式 | AD1: 户用分布式
B2: 光伏电站 | I2: 分布式光伏 | P2: 户用分布式 | AB2: 201910 | AC2: 202011 | AD2: 202112
A3: 全国 | B3: 9384 | C3: 12406 | D3: 14167 | E3: 17287.87 | F3: 19847.94 | G3: 23442.4 | I3: 3658 | J3: 5027 | K3: 6263 | L3: 7822.9 | M3: 10750.8 | N3: 15761.6 | R3: =SUM(R4:R35) -> 2159.6201 | S3: =SUM(S4:S35) -> 2526.7 | Z3: 北京 | AA3: =VLOOKUP("*"&Z3&"*",A$3:A$35,1,FALSE) -> 北京市 | AB3: 5.2133295 | AC3: 0.9214 | AD3: 11.5264
A4: 北京市 | B4: 3 | C4: 5 | D4: 5 | E4: 5.1 | F4: 5.1 | G4: 5.1 | I4: 22 | J4: 35 | K4: 46 | L4: 56.4 | M4: 75 | N4: 90.2 | R4: =VLOOKUP(A4,AA$3:AD$36,4,FALSE) -> 11.5264 | S4: 3.4 | Z4: 天津 | AA4: =VLOOKUP("*"&Z4&"*",A$3:A$35,1,FALSE) -> 天津市 | AB4: 0.8113385 | AC4: 1.2011 | AD4: 2.7859
A5: 天津市 | B5: 53 | C5: 97 | D5: 104 | E5: 118.84 | F5: 118.85 | G5: 121.7 | I5: 15 | J5: 31 | K5: 38 | L5: 44.7 | M5: 58.9 | N5: 98.9 | R5: =VLOOKUP(A5,AA$3:AD$36,4,FALSE) -> 2.7859 | S5: 10.1 | Z5: 河北 | AA5: =VLOOKUP("*"&Z5&"*",A$3:A$35,1,FALSE) -> 河北省 | AB5: 83.680125 | AC5: 215.4475 | AD5: 534.0746
A6: 河北省 | B6: 517 | C6: 856 | D6: 962 | E6: 1445.52 | F6: 1658.84 | G6: 1994.1 | I6: 351 | J6: 378 | K6: 512 | L6: 745.8 | M6: 1262.5 | N6: 1861.2 | R6: =VLOOKUP(A6,AA$3:AD$36,4,FALSE) -> 534.0746 | S6: 506.2 | Z6: 其中：河北南网 | AA6: =VLOOKUP("*"&Z6&"*",A$3:A$35,1,FALSE) -> #N/A | AB6: 70.134719 | AC6: 195.6079 | AD6: 476.9627
A7: 山西省 | B7: 530 | C7: 681 | D7: 857 | E7: 1028.32 | F7: 1101.84 | G7: 1257 | I7: 60 | J7: 183 | K7: 231 | L7: 280.2 | M7: 355.9 | N7: 438.7 | R7: =VLOOKUP(A7,AA$3:AD$36,4,FALSE) -> 74.2915 | S7: 76 | Z7: 冀北电网 | AA7: =VLOOKUP("*"&Z7&"*",A$3:A$35,1,FALSE) -> #N/A | AB7: 13.545406 | AC7: 19.8396 | AD7: 57.1119
A8: 内蒙古自治区 | B8: 741 | C8: 933 | D8: 1001 | E8: 1138 | F8: 1299.5 | G8: 1429.6 | I8: 2 | J8: 13 | K8: 80 | L8: 90.1 | M8: 102.5 | N8: 121.2 | R8: =VLOOKUP(A8,AA$3:AD$36,4,FALSE) -> 5.3501 | S8: 6.2 | Z8: 山西 | AA8: =VLOOKUP("*"&Z8&"*",A$3:A$35,1,FALSE) -> 山西省 | AB8: 27.189405 | AC8: 45.8052 | AD8: 74.2915
A9: 辽宁省 | B9: 185 | C9: 219 | D9: 246 | E9: 281.89 | F9: 317.5 | G9: 381.3 | I9: 38 | J9: 83 | K9: 97 | L9: 117.9 | M9: 160 | N9: 219.3 | R9: =VLOOKUP(A9,AA$3:AD$36,4,FALSE) -> 29.1297 | S9: 23 | Z9: 内蒙古 | AA9: =VLOOKUP("*"&Z9&"*",A$3:A$35,1,FALSE) -> 内蒙古自治区 | AB9: 3.944412 | AC9: 1.9904 | AD9: 5.3501
A10: 吉林省 | B10: 107 | C10: 203 | D10: 205 | E10: 260.91 | F10: 265.79 | G10: 294.6 | I10: 52 | J10: 62 | K10: 69 | L10: 76 | M10: 80.1 | N10: 92 | R10: =VLOOKUP(A10,AA$3:AD$36,4,FALSE) -> 4.9921 | S10: 2.4 | Z10: 其中：蒙西 | AA10: =VLOOKUP("*"&Z10&"*",A$3:A$35,1,FALSE) -> #N/A | AB10: 0.170354 | AC10: 0.7594 | AD10: 1.2772
A11: 黑龙江省 | B11: 64 | C11: 141 | D11: 195 | E11: 234.99 | F11: 329.99 | G11: 366.9 | I11: 30 | J11: 74 | K11: 80 | L11: 82.7 | M11: 89.8 | N11: 108.4 | R11: =VLOOKUP(A11,AA$3:AD$36,4,FALSE) -> 2.2025 | S11: 3.9 | Z11: 蒙东 | AA11: =VLOOKUP("*"&Z11&"*",A$3:A$35,1,FALSE) -> #N/A | AB11: 3.774058 | AC11: 1.231 | AD11: 4.0729
A12: 上海市 | B12: 0 | C12: 7 | D12: 6 | E12: 19.7 | F12: 24.09 | G12: 24 | I12: 59 | J12: 82 | K12: 103 | L12: 116.9 | M12: 144.2 | N12: 170.9 | R12: =VLOOKUP(A12,AA$3:AD$36,4,FALSE) -> 1.8567 | S12: 1.3 | Z12: 辽宁 | AA12: =VLOOKUP("*"&Z12&"*",A$3:A$35,1,FALSE) -> 辽宁省 | AB12: 6.830905 | AC12: 14.6679 | AD12: 29.1297
A13: 江苏省 | B13: 580 | C13: 792 | D13: 821 | E13: 895.91 | F13: 941.08 | G13: 953.3 | I13: 327 | J13: 540 | K13: 665 | L13: 788.1 | M13: 974.9 | N13: 1555.2 | R13: =VLOOKUP(A13,AA$3:AD$36,4,FALSE) -> 43.9746 | S13: 151.4 | Z13: 吉林 | AA13: =VLOOKUP("*"&Z13&"*",A$3:A$35,1,FALSE) -> 吉林省 | AB13: 2.996705 | AC13: 6.0682 | AD13: 4.9921
A14: 浙江省 | B14: 315 | C14: 361 | D14: 414 | E14: 412.17 | F14: 577.03 | G14: 613.4 | I14: 499 | J14: 777 | K14: 925 | L14: 1067.2 | M14: 1264.8 | N14: 1925.5 | R14: =VLOOKUP(A14,AA$3:AD$36,4,FALSE) -> 17.2588 | S14: 11.2 | Z14: 黑龙江 | AA14: =VLOOKUP("*"&Z14&"*",A$3:A$35,1,FALSE) -> 黑龙江省 | AB14: 1.837046 | AC14: 1.6807 | AD14: 2.2025
A15: 安徽省 | B15: 565 | C15: 677 | D15: 773 | E15: 825.56 | F15: 947.02 | G15: 1063.8 | I15: 323 | J15: 441 | K15: 480 | L15: 544.1 | M15: 759.8 | N15: 1090.3 | R15: =VLOOKUP(A15,AA$3:AD$36,4,FALSE) -> 137.238 | S15: 251 | Z15: 上海 | AA15: =VLOOKUP("*"&Z15&"*",A$3:A$35,1,FALSE) -> 上海市 | AB15: 4.3568 | AC15: 1.2889 | AD15: 1.8567
... A26: 四川省 | B26: 116 | C26: 168 | D26: 169 | E26: 169.01 | F26: 169.01 | G26: 173 | I26: 19 | J26: 13 | K26: 19 | L26: 22.1 | M26: 26.9 | N26: 33.2 | R26: =VLOOKUP(A26,AA$3:AD$36,4,FALSE) -> 3.8123 | S26: 2.4 | Z26: 四川 | AA26: =VLOOKUP("*"&Z26&"*",A$3:A$35,1,FALSE) -> 四川省 | AB26: 1.2946805 | AC26: 1.9801 | AD26: 3.8123
A27: 贵州省 | B27: 135 | C27: 161 | D27: 491 | E27: 970.67 | F27: 1117.6 | G27: 1396.6 | J27: 17 | K27: 19 | L27: 19 | M27: 19.4 | N27: 23.7 | R27: =VLOOKUP(A27,AA$3:AD$36,4,FALSE) -> 0.304 | S27: 0.4 | Z27: 陕西 | AA27: =VLOOKUP("*"&Z27&"*",A$3:A$35,1,FALSE) -> 陕西省 | AB27: 6.6805495 | AC27: 13.5018 | AD27: 21.7042
A28: 云南省 | B28: 237.5 | C28: 312 | D28: 350 | E28: 295.43 | F28: 349.91 | G28: 525.2 | I28: 0.5 | J28: 14 | K28: 25 | L28: 38.4 | M28: 47.2 | N28: 60.1 | R28: =VLOOKUP(A28,AA$3:AD$36,4,FALSE) -> 1.7673 | S28: 2.3 | Z28: 甘肃 | AA28: =VLOOKUP("*"&Z28&"*",A$3:A$35,1,FALSE) -> 甘肃省 | AB28: 3.251883 | AC28: 0.7275 | AD28: 1.0777
A29: 西藏自治区 | B29: 79 | C29: 98 | D29: 110 | E29: 136.26 | F29: 136.51 | G29: 175.9 | K29: 0 | L29: 0 | M29: 2.2 | N29: 2.2 | S29: 0 | Z29: 青海 | AA29: =VLOOKUP("*"&Z29&"*",A$3:A$35,1,FALSE) -> 青海省 | AB29: 0.5077935 | AC29: 0.5136 | AD29: 0.3517
A30: 陕西省 | B30: 484 | C30: 640 | D30: 778 | E30: 893.42 | F30: 1102.82 | G30: 1193.7 | I30: 51 | J30: 76 | K30: 162 | L30: 190.7 | M30: 210.9 | N30: 322.5 | R30: =VLOOKUP(A30,AA$3:AD$36,4,FALSE) -> 21.7042 | S30: 28.9 | Z30: 宁夏 | AA30: =VLOOKUP("*"&Z30&"*",A$3:A$35,1,FALSE) -> 宁夏回族自治区 | AB30: 0.80742 | AC30: 0.3325 | AD30: 0.4052
A31: 甘肃省 | B31: 768 | C31: 790 | D31: 836 | E31: 891.32 | F31: 1047.65 | G31: 1310.9 | I31: 18 | J31: 49 | K31: 71 | L31: 74 | M31: 77.1 | N31: 85.5 | R31: =VLOOKUP(A31,AA$3:AD$36,4,FALSE) -> 1.0777 | S31: 1 | Z31: 新疆自治区（含兵团） | AA31: 新疆维吾尔自治区 | AB31: 0.184156 | AC31: 0.5974 | AD31: 0.4005
A32: 青海省 | B32: 786 | C32: 952 | D32: 1086 | E32: 1532.09 | F32: 1594.77 | G32: 1805.5 | I32: 5 | J32: 10 | K32: 15 | L32: 15.7 | M32: 16 | N32: 15.7 | R32: =VLOOKUP(A32,AA$3:AD$36,4,FALSE) -> 0.3517 | S32: 2.7 | Z32: 广东 | AA32: =VLOOKUP("*"&Z32&"*",A$3:A$35,1,FALSE) -> 广东省 | AB32: 20.9154 | AC32: 12.4418 | AD32: 31.1558
A33: 宁夏回族自治区 | B33: 587 | C33: 761 | D33: 844 | E33: 1121.96 | F33: 1303.36 | G33: 1491.6 | I33: 33 | J33: 55 | K33: 74 | L33: 75.2 | M33: 80.6 | N33: 92.2 | R33: =VLOOKUP(A33,AA$3:AD$36,4,FALSE) -> 0.4052 | S33: 0.3 | Z33: 广西 | AA33: =VLOOKUP("*"&Z33&"*",A$3:A$35,1,FALSE) -> 广西壮族自治区 | AB33: 3.1503365 | AC33: 1.1213 | AD33: 2.8014
A34: 新疆维吾尔自治区 | B34: 933 | C34: 976 | D34: 1027 | E34: 1205.48 | F34: 1254.78 | G34: 1440.3 | I34: 1 | J34: 2 | K34: 14 | L34: 16.7 | M34: 17.2 | N34: 26.9 | R34: =VLOOKUP(A34,AA$3:AD$36,4,FALSE) -> 0.4005 | S34: 0 | Z34: 云南 | AA34: =VLOOKUP("*"&Z34&"*",A$3:A$35,1,FALSE) -> 云南省 | AB34: 1.576 | AC34: 1.1014 | AD34: 1.7673
A35: 新疆建设兵团 | B35: 0 | C35: 0 | D35: 39 | E35: 77.2 | F35: 77.2 | G35: 105.8 | K35: 0 | L35: 0 | M35: 0 | N35: 0 | S35: 0 | Z35: 贵州 | AA35: =VLOOKUP("*"&Z35&"*",A$3:A$35,1,FALSE) -> 贵州省 | AB35: 0.109762 | AC35: 0.0995 | AD35: 0.304
Z36: 海南 | AA36: =VLOOKUP("*"&Z36&"*",A$3:A$35,1,FALSE) -> 海南省 | AB36: 1.103994 | AC36: 0.8751 | AD36: 1.5194
D54: Pre2013 | E54: 2013 | F54: 2014 | G54: 2015 | H54: 2016 | I54: 2017 | J54: 2018 | K54: 2019 | L54: 2020 | M54: 2021 | N54: 2022 | O54: 2023 | P54: 2024 | Q54: 2025 | R54: 2026 | S54: 2027 | T54: 2028 | U54: 2029 | V54: 2030 | W54: 2031 | X54: 2032 | Y54: 2033 | Z54: 2034 | AA54: 2035 | AB54: 2036 | AC54: 2037 | AD54: 2038 | AE54: 2039 | AF54: 2040 | AG54: 2041 | AH54: 2042 | AI54: 2043 | AJ54: 2044 | AK54: 2045 | AL54: 2046 | AM54: 2047 | AN54: 2048 | AO54: 2049 | AP54: 2050 | AQ54: 2051 | AR54: 2052 | AS54: 2053 | AT54: 2054 | AU54: 2055 | AV54: 2056 | AW54: 2057 | AX54: 2058 | AY54: 2059 | AZ54: 2060
B55: 识图叠加 | C55: 光伏电站 | E55: 11.637411 | F55: 7.9701505 | G55: 13.231872 | H55: 29.814267 | I55: 33.162635 | J55: 22.798638 | K55: 17.377471 | L55: 32.205958 | M55: 23.590886
C56: 工商分布式 | E56: 12.414711 | F56: 10.074839 | G56: 14.507441 | H56: 33.640973 | I56: 49.585584 | J56: 41.453832 | K56: 24.393099 | L56: 37.627126 | M56: 30.93039
C57: 户用分布式 | E57: 12.594088 | F57: 10.202396 | G57: 14.666887 | H57: 34.119312 | I57: 52.61506 | J57: 43.845524 | K57: 29.654821 | L57: 47.831677 | M57: 52.61506
B58: 新增 | C58: 光伏电站 | D58: 0 | E58: =E55*100 -> 1163.7411 | F58: =F55*100 -> 797.01505 | G58: =G55*100 -> 1323.1872 | H58: =H55*100 -> 2981.4267 | I58: =I55*100 -> 3316.2635 | J58: =C3-B3 -> 3022 | K58: =D3-C3 -> 1761 | L58: =E3-D3 -> 3120.87 | M58: =F3-E3 -> 2560.07 | N58: =G3-F3 -> 3594.46
C59: 工商分布式 | D59: =I3-SUM(E59:I59) -> 1217.2788 | E59: =(E56-E55)*100 -> 77.729976 | F59: =(F56-F55)*100 -> 210.46886 | G59: =(G56-G55)*100 -> 127.55688 | H59: =(H56-H55)*100 -> 382.67065 | I59: =(I56-I55)*100 -> 1642.2949 | J59: =(J56-J55)*100 -> 1865.5194 | K59: =(K56-K55)*100 -> 701.56286 | L59: =(L56-L55)*100 -> 542.11675 | M59: =(M3-L3)-R3 -> 768.2799 | N59: =(N3-M3)-S3 -> 2484.1
C60: 户用分布式 | D60: 0 | E60: =(E57-E56)*100 -> 17.937687 | F60: =(F57-F56)*100 -> 12.755688 | G60: =(G57-G56)*100 -> 15.94461 | H60: =(H57-H56)*100 -> 47.833831 | I60: =(I57-I56)*100 -> 302.9476 | J60: =(J57-J56)*100 -> 239.16916 | K60: =(K57-K56)*100 -> 526.17214 | L60: =(L57-L56)*100 -> 1020.4551 | M60: =R3 -> 2159.6201 | N60: =S3 -> 2526.7
B61: 累计 | C61: 光伏电站 | D61: =SUM($D58:D58) -> 0 | E61: =SUM($D58:E58) -> 1163.7411 | F61: =SUM($D58:F58) -> 1960.7561 | G61: =SUM($D58:G58) -> 3283.9433 | H61: =SUM($D58:H58) -> 6265.37 | I61: =SUM($D58:I58) -> 9581.6335 | J61: =SUM($D58:J58) -> 12603.634 | K61: =SUM($D58:K58) -> 14364.634 | ... N61: =SUM($D58:N58) -> 23640.034
C62: 工商分布式 | D62: =SUM($D59:D59) -> 1217.2788 | E62: =SUM($D59:E59) -> 1295.0087 | F62: =SUM($D59:F59) -> 1505.4776 | G62: =SUM($D59:G59) -> 1633.0345 | H62: =SUM($D59:H59) -> 2015.7051 | I62: =SUM($D59:I59) -> 3658 | J62: =SUM($D59:J59) -> 5523.5194 | K62: =SUM($D59:K59) -> 6225.0823 | ... N62: =SUM($D59:N59) -> 10019.579 | O62: =MIN(_xlfn.FORECAST.LINEAR(O$54,$H62:$N62,$H$54:$N$54),'Capacity Limit'!F54) -> 10679.26 | P62: =MIN(_xlfn.FORECAST.LINEAR(P$54,$H62:$N62,$H$54:$N$54),'Capacity Limit'!G54) -> 11858.198 | Q62: =MIN(_xlfn.FORECAST.LINEAR(Q$54,$H62:$N62,$H$54:$N$54),'Capacity Limit'!H54) -> 13037.136 | R62: =MIN(_xlfn.FORECAST.LINEAR(R$54,$H62:$N62,$H$54:$N$54),'Capacity Limit'!I54) -> 13826.076 | S62: =MIN(_xlfn.FORECAST.LINEAR(S$54,$H62:$N62,$H$54:$N$54),'Capacity Limit'!J54) -> 14109.298 | T62: =MIN(_xlfn.FORECAST.LINEAR(T$54,$H62:$N62,$H$54:$N$54),'Capacity Limit'!K54) -> 14387.29 | U62: =MIN(_xlfn.FORECAST.LINEAR(U$54,$H62:$N62,$H$54:$N$54),'Capacity Limit'!L54) -> 14660.032 | V62: =MIN(_xlfn.FORECAST.LINEAR(V$54,$H62:$N62,$H$54:$N$54),'Capacity Limit'!M54) -> 14927.511 | ... AZ62: =MIN(_xlfn.FORECAST.LINEAR(AZ$54,$H62:$N62,$H$54:$N$54),'Capacity Limit'!AQ54) -> 19433.348
C63: 户用分布式 | D63: =SUM($D60:D60) -> 0 | E63: =SUM($D60:E60) -> 17.937687 | F63: =SUM($D60:F60) -> 30.693375 | G63: =SUM($D60:G60) -> 46.637986 | H63: =SUM($D60:H60) -> 94.471817 | I63: =SUM($D60:I60) -> 397.41942 | J63: =SUM($D60:J60) -> 636.58857 | K63: =SUM($D60:K60) -> 1162.7607 | ... N63: =SUM($D60:N60) -> 6869.5359
A64: 乡村户用比例 | C64: 乡村户用光伏 | E64: =E63*$A65 -> 14.184001 | F64: =F63*$A65 -> 24.270403 | G64: =G63*$A65 -> 36.878404 | H64: =H63*$A65 -> 74.702408 | I64: =I63*$A65 -> 314.25443 | J64: =J63*$A65 -> 503.37445 | K64: =K63*$A65 -> 919.4385 | L64: =L63*$A65 -> 1726.3506 | ... N64: =N63*$A65 -> 5431.9996 | O64: =MIN(_xlfn.FORECAST.LINEAR(O$54,$L64:$N64,$L$54:$N$54),'Capacity Limit'!F55) -> 7236.4468 | P64: =MIN(_xlfn.FORECAST.LINEAR(P$54,$L64:$N64,$L$54:$N$54),'Capacity Limit'!G55) -> 9089.2713 | Q64: =MIN(_xlfn.FORECAST.LINEAR(Q$54,$L64:$N64,$L$54:$N$54),'Capacity Limit'!H55) -> 10942.096 | R64: =MIN(_xlfn.FORECAST.LINEAR(R$54,$L64:$N64,$L$54:$N$54),'Capacity Limit'!I55) -> 12794.92 | S64: =MIN(_xlfn.FORECAST.LINEAR(S$54,$L64:$N64,$L$54:$N$54),'Capacity Limit'!J55) -> 14647.745 | T64: =MIN(_xlfn.FORECAST.LINEAR(T$54,$L64:$N64,$L$54:$N$54),'Capacity Limit'!K55) -> 16500.569 | U64: =MIN(_xlfn.FORECAST.LINEAR(U$54,$L64:$N64,$L$54:$N$54),'Capacity Limit'!L55) -> 18353.394 | V64: =MIN(_xlfn.FORECAST.LINEAR(V$54,$L64:$N64,$L$54:$N$54),'Capacity Limit'!M55) -> 20206.218 | ... AZ64: =MIN(_xlfn.FORECAST.LINEAR(AZ$54,$L64:$N64,$L$54:$N$54),'Capacity Limit'!AQ55) -> 36703.213
A65: ='Capacity Limit'!D20 -> 0.7907375 | C65: 城镇户用光伏 | E65: =E63*$A67 -> 3.7536852 | F65: =F63*$A67 -> 6.4229725 | G65: =G63*$A67 -> 9.7595816 | H65: =H63*$A67 -> 19.769409 | I65: =I63*$A67 -> 83.164982 | J65: =J63*$A67 -> 133.21412 | K65: =K63*$A67 -> 243.32222 | L65: =L63*$A67 -> 456.8652 | ... N65: =N63*$A67 -> 1437.5363 | O65: =MIN(_xlfn.FORECAST.LINEAR(O$54,$L65:$N65,$L$54:$N$54),'Capacity Limit'!F56) -> 1915.0691 | P65: =MIN(_xlfn.FORECAST.LINEAR(P$54,$L65:$N65,$L$54:$N$54),'Capacity Limit'!G56) -> 2405.4047 | Q65: =MIN(_xlfn.FORECAST.LINEAR(Q$54,$L65:$N65,$L$54:$N$54),'Capacity Limit'!H56) -> 2895.7402 | R65: =MIN(_xlfn.FORECAST.LINEAR(R$54,$L65:$N65,$L$54:$N$54),'Capacity Limit'!I56) -> 3386.0758 | S65: =MIN(_xlfn.FORECAST.LINEAR(S$54,$L65:$N65,$L$54:$N$54),'Capacity Limit'!J56) -> 3876.4113 | T65: =MIN(_xlfn.FORECAST.LINEAR(T$54,$L65:$N65,$L$54:$N$54),'Capacity Limit'!K56) -> 4366.7468 | U65: =MIN(_xlfn.FORECAST.LINEAR(U$54,$L65:$N65,$L$54:$N$54),'Capacity Limit'!L56) -> 4857.0824 | V65: =MIN(_xlfn.FORECAST.LINEAR(V$54,$L65:$N65,$L$54:$N$54),'Capacity Limit'!M56) -> 5347.4179 | ... AZ65: =MIN(_xlfn.FORECAST.LINEAR(AZ$54,$L65:$N65,$L$54:$N$54),'Capacity Limit'!AQ56) -> 10704.877
A66: 城镇户用比例
A67: ='Capacity Limit'!C20 -> 0.2092625

Sheet Capacity Limit
C2: 分布式潜能
C3: 城镇屋顶 | D3: 农村屋顶 | E3: 工矿用地 | F3: 滩涂分布式 | I3: 城市人口 | J3: 乡村人口 | K3: 城镇住宅面积+公共建筑面积 | L3: 乡村住宅面积 | N3: 城乡面积与分布式潜能比
B4: 北京 | C4: 610.8584 | D4: 415.0322 | E4: 185.7993 | F4: 115.96967 | H4: 北京 | I4: =VLOOKUP("*"&B4&"*",Population!A$34:V$64,22,FALSE) -> 1916 | J4: =VLOOKUP("*"&B4&"*",Population!A$66:V$96,22,FALSE) -> 273 | K4: =SUMIFS('Building Area Result'!$F$5:$F$738,'Building Area Result'!$C$5:$C$738,"*"&B4&"*") -> 1.0352656e+09 | L4: =VLOOKUP("*"&B4&"*",'Building Area Result'!$C$739:$F$769,4,FALSE) -> 1.4915488e+08 | N4: =(C4/K4)/(D4/L4) -> 0.21205301
B5: 天津 | C5: 353.87625 | D5: 305.24171 | E5: 246.12375 | F5: 167.09872 | H5: 天津 | I5: =VLOOKUP("*"&B5&"*",Population!A$34:V$64,22,FALSE) -> 1175 | J5: =VLOOKUP("*"&B5&"*",Population!A$66:V$96,22,FALSE) -> 212 | K5: =SUMIFS('Building Area Result'!$F$5:$F$738,'Building Area Result'!$C$5:$C$738,"*"&B5&"*") -> 5.8694661e+08 | L5: =VLOOKUP("*"&B5&"*",'Building Area Result'!$C$739:$F$769,4,FALSE) -> 69415828 | N5: =(C5/K5)/(D5/L5) -> 0.13710947
B6: 河北 | C6: 1197.212 | D6: 5088.3672 | E6: 1384.9488 | F6: 653.41431 | H6: 河北 | I6: =VLOOKUP("*"&B6&"*",Population!A$34:V$64,22,FALSE) -> 4484 | J6: =VLOOKUP("*"&B6&"*",Population!A$66:V$96,22,FALSE) -> 2980 | K6: =SUMIFS('Building Area Result'!$F$5:$F$738,'Building Area Result'!$C$5:$C$738,"*"&B6&"*") -> 1.8773626e+09 | L6: =VLOOKUP("*"&B6&"*",'Building Area Result'!$C$739:$F$769,4,FALSE) -> 1.0967866e+09 | N6: =(C6/K6)/(D6/L6) -> 0.13745691
B7: 上海 | C7: 805.10312 | D7: 594.79905 | E7: 183.07655 | F7: 136.64303 | H7: 上海 | I7: =VLOOKUP("*"&B7&"*",Population!A$34:V$64,22,FALSE) -> 2222 | J7: =VLOOKUP("*"&B7&"*",Population!A$66:V$96,22,FALSE) -> 266 | K7: =SUMIFS('Building Area Result'!$F$5:$F$738,'Building Area Result'!$C$5:$C$738,"*"&B7&"*") -> 1.0911372e+09 | L7: =VLOOKUP("*"&B7&"*",'Building Area Result'!$C$739:$F$769,4,FALSE) -> 1.3930333e+08 | N7: =(C7/K7)/(D7/L7) -> 0.17280781
B8: 江苏 | C8: 1914.9724 | D8: 5575.286 | E8: 1286.1172 | F8: 1430.8959 | H8: 江苏 | I8: =VLOOKUP("*"&B8&"*",Population!A$34:V$64,22,FALSE) -> 6226 | J8: =VLOOKUP("*"&B8&"*",Population!A$66:V$96,22,FALSE) -> 2251 | K8: =SUMIFS('Building Area Result'!$F$5:$F$738,'Building Area Result'!$C$5:$C$738,"*"&B8&"*") -> 3.4942812e+09 | L8: =VLOOKUP("*"&B8&"*",'Building Area Result'!$C$739:$F$769,4,FALSE) -> 1.0178032e+09 | N8: =(C8/K8)/(D8/L8) -> 0.10004637
B9: 浙江 | C9: 1399.9022 | D9: 4693.242 | E9: 554.98492 | F9: 598.41852 | H9: 浙江 | I9: =VLOOKUP("*"&B9&"*",Population!A$34:V$64,22,FALSE) -> 4668 | J9: =VLOOKUP("*"&B9&"*",Population!A$66:V$96,22,FALSE) -> 1800 | K9: =SUMIFS('Building Area Result'!$F$5:$F$738,'Building Area Result'!$C$5:$C$738,"*"&B9&"*") -> 2.697997e+09 | L9: =VLOOKUP("*"&B9&"*",'Building Area Result'!$C$739:$F$769,4,FALSE) -> 1.2223148e+09 | N9: =(C9/K9)/(D9/L9) -> 0.13513453
B10: 安徽 | C10: 1054.8463 | D10: 4227.5373 | E10: 1231.8683 | F10: 619.20747 | H10: 安徽 | I10: =VLOOKUP("*"&B10&"*",Population!A$34:V$64,22,FALSE) -> 3561 | J10: =VLOOKUP("*"&B10&"*",Population!A$66:V$96,22,FALSE) -> 2544 | K10: =SUMIFS('Building Area Result'!$F$5:$F$738,'Building Area Result'!$C$5:$C$738,"*"&B10&"*") -> 1.7210195e+09 | L10: =VLOOKUP("*"&B10&"*",'Building Area Result'!$C$739:$F$769,4,FALSE) -> 9.8327522e+08 | N10: =(C10/K10)/(D10/L10) -> 0.14255783
B11: 福建 | C11: 809.92908 | D11: 2897.0213 | E11: 305.56344 | F11: 506.16233 | H11: 福建 | I11: =VLOOKUP("*"&B11&"*",Population!A$34:V$64,22,FALSE) -> 2861 | J11: =VLOOKUP("*"&B11&"*",Population!A$66:V$96,22,FALSE) -> 1300 | K11: =SUMIFS('Building Area Result'!$F$5:$F$738,'Building Area Result'!$C$5:$C$738,"*"&B11&"*") -> 1.585467e+09 | L11: =VLOOKUP("*"&B11&"*",'Building Area Result'!$C$739:$F$769,4,FALSE) -> 6.8997582e+08 | N11: =(C11/K11)/(D11/L11) -> 0.12166677
B12: 江西 | C12: 980.20489 | D12: 4133.2703 | E12: 553.77843 | F12: 529.68887 | H12: 江西 | I12: =VLOOKUP("*"&B12&"*",Population!A$34:V$64,22,FALSE) -> 2731 | J12: =VLOOKUP("*"&B12&"*",Population!A$66:V$96,22,FALSE) -> 1788 | K12: =SUMIFS('Building Area Result'!$F$5:$F$738,'Building Area Result'!$C$5:$C$738,"*"&B12&"*") -> 1.4194808e+09 | L12: =VLOOKUP("*"&B12&"*",'Building Area Result'!$C$739:$F$769,4,FALSE) -> 9.1828936e+08 | N12: =(C12/K12)/(D12/L12) -> 0.15341686
B13: 山东 | C13: 1823.42 | D13: 6644.0945 | E13: 1693.8008 | F13: 736.87227 | H13: 山东 | I13: =VLOOKUP("*"&B13&"*",Population!A$34:V$64,22,FALSE) -> 6409 | J13: =VLOOKUP("*"&B13&"*",Population!A$66:V$96,22,FALSE) -> 3756 | K13: =SUMIFS('Building Area Result'!$F$5:$F$738,'Building Area Result'!$C$5:$C$738,"*"&B13&"*") -> 3.4361479e+09 | L13: =VLOOKUP("*"&B13&"*",'Building Area Result'!$C$739:$F$769,4,FALSE) -> 1.4062225e+09 | N13: =(C13/K13)/(D13/L13) -> 0.1123138
B14: 河南 | C14: 1471.2057 | D14: 7664.7037 | E14: 1463.2126 | F14: 771.40606 | H14: 河南 | I14: =VLOOKUP("*"&B14&"*",Population!A$34:V$64,22,FALSE) -> 5510 | J14: =VLOOKUP("*"&B14&"*",Population!A$66:V$96,22,FALSE) -> 4431 | K14: =SUMIFS('Building Area Result'!$F$5:$F$738,'Building Area Result'!$C$5:$C$738,"*"&B14&"*") -> 2.6798583e+09 | L14: =VLOOKUP("*"&B14&"*",'Building Area Result'!$C$739:$F$769,4,FALSE) -> 1.7634683e+09 | N14: =(C14/K14)/(D14/L14) -> 0.12630887
B15: 湖北 | C15: 1118.9913 | D15: 4515.8077 | E15: 882.8684 | F15: 835.05122 | H15: 湖北 | I15: =VLOOKUP("*"&B15&"*",Population!A$34:V$64,22,FALSE) -> 3613 | J15: =VLOOKUP("*"&B15&"*",Population!A$66:V$96,22,FALSE) -> 2132 | K15: =SUMIFS('Building Area Result'!$F$5:$F$738,'Building Area Result'!$C$5:$C$738,"*"&B15&"*") -> 2.129533e+09 | L15: =VLOOKUP("*"&B15&"*",'Building Area Result'!$C$739:$F$769,4,FALSE) -> 1.0119981e+09 | N15: =(C15/K15)/(D15/L15) -> 0.11775697
B16: 湖南 | C16: 1369.74 | D16: 6153.0937 | E16: 800.57064 | F16: 568.79433 | H16: 湖南 | I16: =VLOOKUP("*"&B16&"*",Population!A$34:V$64,22,FALSE) -> 3905 | J16: =VLOOKUP("*"&B16&"*",Population!A$66:V$96,22,FALSE) -> 2740 | K16: =SUMIFS('Building Area Result'!$F$5:$F$738,'Building Area Result'!$C$5:$C$738,"*"&B16&"*") -> 2.0808755e+09 | L16: =VLOOKUP("*"&B16&"*",'Building Area Result'!$C$739:$F$769,4,FALSE) -> 1.2601582e+09 | N16: =(C16/K16)/(D16/L16) -> 0.13481045
C17: =SUM(C4:C16)/SUM($C4:$F16) -> 0.17285237 | D17: =SUM(D4:D16)/SUM($C4:$F16) -> 0.61334847 | E17: =SUM(E4:E16)/SUM($C4:$F16) -> 0.12488641 | F17: =SUM(F4:F16)/SUM($C4:$F16) -> 0.088912756
B18: 基于人口推算 | C18: =SUM(C4:C16)/(SUM(I4:I16)/I18) -> 27237.3 | D18: =SUM(D4:D16)/(SUM(J4:J16)/J18) -> 101903.84 | H18: 2020全国 | I18: =SUM(Population!V34:V64) -> 90024 | J18: =SUM(Population!V66:V96) -> 50989 | K18: ='Building Area Result'!F3+'Building Area Result'!F2 -> 4.4232608e+10 | L18: ='Building Area Result'!F4 -> 2.1382914e+10 | N18: =(C19/K18)/(D19/L18) -> 0.12793325
B19: 基于面积推算 | C19: =SUM(C4:C16)/(SUM(K4:K16)/K18) -> 25527.782 | D19: =SUM(D4:D16)/(SUM(L4:L16)/L18) -> 96461.498 | E19: =133000-D19-C19 -> 11010.72 | H19: 省份占比 | I19: =SUM(I4:I16)/I18 -> 0.54742069 | J19: =SUM(J4:J16)/J18 -> 0.51919041 | K19: =SUM(K4:K16)/K18 -> 0.58407979 | L19: =SUM(L4:L16)/L18 -> 0.54848305
C20: =C19/(C19+D19) -> 0.2092625 | D20: =D19/(C19+D19) -> 0.7907375
A22: 分布式光伏技术可开发潜力主要受可安装分布式光伏的场地或者设施面积制约。重点考虑城镇和农村住宅屋顶、工矿用地屋顶、铁路高速公路、滩涂水库坑塘和农业大棚等五大类分布式光伏，
A23: 根据测算，2025年我国分布式光伏技术可开发潜力为14.9亿千瓦，其中主要是农村、城镇住房屋顶光伏和工矿厂房，合计13.3亿千瓦，占到技术可开发总潜力的89%。
A25: 从区域分布来看，国网公司经营区东中部地区 的技术可开发潜力为8.7亿千瓦，约占全国的58%，将成为未来发展重点地区。
A26: 开发潜力最大的省份是河南、山东和江苏，均超过1亿千瓦，主要原因在于数量庞大的农村屋顶。
A27: 考虑项目本体发电成本、电网改造成本、系统平衡成本等，预计全国经济可开发潜力约为4.6亿千瓦左右，其中东中部地区约2.9亿千瓦。
C45: 2020 | D45: 2021 | E45: 2022 | F45: 2023 | G45: 2024 | H45: 2025 | I45: 2026 | J45: 2027 | K45: 2028 | L45: 2029 | M45: 2030 | N45: 2031 | O45: 2032 | P45: 2033 | Q45: 2034 | R45: 2035 | S45: 2036 | T45: 2037 | U45: 2038 | V45: 2039 | W45: 2040 | X45: 2041 | Y45: 2042 | Z45: 2043 | AA45: 2044 | AB45: 2045 | AC45: 2046 | AD45: 2047 | AE45: 2048 | AF45: 2049 | AG45: 2050 | AH45: 2051 | AI45: 2052 | AJ45: 2053 | AK45: 2054 | AL45: 2055 | AM45: 2056 | AN45: 2057 | AO45: 2058 | AP45: 2059 | AQ45: 2060
B46: 城镇住宅面积 | C46: ='Building Area Result'!E3 -> 3.0311727e+10 | D46: ='Building Area Result'!F3 -> 3.1115403e+10 | E46: ='Building Area Result'!G3 -> 3.1727837e+10 | F46: ='Building Area Result'!H3 -> 3.232438e+10 | G46: ='Building Area Result'!I3 -> 3.2904918e+10 | H46: ='Building Area Result'!J3 -> 3.3469355e+10 | I46: ='Building Area Result'!K3 -> 3.4017617e+10 | J46: ='Building Area Result'!L3 -> 3.4549652e+10 | ... AQ46: ='Building Area Result'!AS3 -> 3.9851427e+10
B47: 乡村住宅面积 | C47: ='Building Area Result'!E4 -> 2.1439578e+10 | D47: ='Building Area Result'!F4 -> 2.1382914e+10 | E47: ='Building Area Result'!G4 -> 2.1272869e+10 | F47: ='Building Area Result'!H4 -> 2.1141153e+10 | G47: ='Building Area Result'!I4 -> 2.0988052e+10 | H47: ='Building Area Result'!J4 -> 2.0813933e+10 | I47: ='Building Area Result'!K4 -> 2.0619238e+10 | J47: ='Building Area Result'!L4 -> 2.0404481e+10 | ... AQ47: ='Building Area Result'!AS4 -> 1.3560189e+10
B48: 公共建筑面积 | C48: ='Building Area Result'!E2 -> 1.2718182e+10 | D48: ='Building Area Result'!F2 -> 1.3117204e+10 | E48: ='Building Area Result'!G2 -> 1.3445852e+10 | F48: ='Building Area Result'!H2 -> 1.3769083e+10 | G48: ='Building Area Result'!I2 -> 1.4086864e+10 | H48: ='Building Area Result'!J2 -> 1.4399163e+10 | I48: ='Building Area Result'!K2 -> 1.4705949e+10 | J48: ='Building Area Result'!L2 -> 1.5007196e+10 | ... AQ48: ='Building Area Result'!AS2 -> 2.0670062e+10
B50: 假设住宅与公共建筑单位建筑面积屋顶光伏密度与容积率成反比，容积率之比约为1.68：0.8 | J50: 技术可开发量中城镇住宅与共建之比为： | M50: =(C46/1.68)/(C46/1.68+C48/0.8) -> 0.531599 | N50: =(C48/0.8)/(C46/1.68+C48/0.8) -> 0.468401
A51: 技术可开发量 | B51: 工商分布式光伏上限 | C51: =$C$19*$N$50*C48/$C48 -> 11957.239 | D51: =$C$19*$N$50*D48/$C48 -> 12332.387 | E51: =$C$19*$N$50*E48/$C48 -> 12641.372 | F51: =$C$19*$N$50*F48/$C48 -> 12945.263 | G51: =$C$19*$N$50*G48/$C48 -> 13244.031 | H51: =$C$19*$N$50*H48/$C48 -> 13537.644 | I51: =$C$19*$N$50*I48/$C48 -> 13826.076 | J51: =$C$19*$N$50*J48/$C48 -> 14109.298 | ... AQ51: =$C$19*$N$50*AQ48/$C48 -> 19433.348
B52: 乡村屋顶光伏上限 | C52: =$D$19*(C47/$L$18) -> 96717.118 | D52: =$D$19*(D47/$L$18) -> 96461.498 | E52: =$D$19*(E47/$L$18) -> 95965.068 | F52: =$D$19*(F47/$L$18) -> 95370.878 | G52: =$D$19*(G47/$L$18) -> 94680.216 | H52: =$D$19*(H47/$L$18) -> 93894.737 | I52: =$D$19*(I47/$L$18) -> 93016.439 | J52: =$D$19*(J47/$L$18) -> 92047.642 | ... AQ52: =$D$19*(AQ47/$L$18) -> 61172.022
B53: 城镇住宅光伏上限 | C53: =$C$19*$M$50*C46/$C46 -> 13570.544 | D53: =$C$19*$M$50*D46/$C46 -> 13930.349 | E53: =$C$19*$M$50*E46/$C46 -> 14204.535 | F53: =$C$19*$M$50*F46/$C46 -> 14471.607 | G53: =$C$19*$M$50*G46/$C46 -> 14731.514 | H53: =$C$19*$M$50*H46/$C46 -> 14984.212 | I53: =$C$19*$M$50*I46/$C46 -> 15229.669 | J53: =$C$19*$M$50*J46/$C46 -> 15467.86 | ... AQ53: =$C$19*$M$50*AQ46/$C46 -> 17841.462
A54: 经济可开发量 | B54: 工商分布式光伏上限 | C54: =C51 -> 11957.239 | D54: =D51 -> 12332.387 | E54: =E51 -> 12641.372 | F54: =F51 -> 12945.263 | G54: =G51 -> 13244.031 | H54: =H51 -> 13537.644 | I54: =I51 -> 13826.076 | J54: =J51 -> 14109.298 | ... AQ54: =AQ51 -> 19433.348
B55: 乡村屋顶光伏上限 | C55: =C52*0.6 -> 58030.271 | D55: =D52*0.6 -> 57876.899 | E55: =E52*0.6 -> 57579.041 | F55: =F52*0.6 -> 57222.527 | G55: =G52*0.6 -> 56808.129 | H55: =H52*0.6 -> 56336.842 | I55: =I52*0.6 -> 55809.864 | J55: =J52*0.6 -> 55228.585 | ... AQ55: =AQ52*0.6 -> 36703.213
B56: 城镇住宅光伏上限 | C56: =C53*0.6 -> 8142.3261 | D56: =D53*0.6 -> 8358.2094 | E56: =E53*0.6 -> 8522.7211 | F56: =F53*0.6 -> 8682.9643 | G56: =G53*0.6 -> 8838.9082 | H56: =H53*0.6 -> 8990.5271 | I56: =I53*0.6 -> 9137.8011 | J56: =J53*0.6 -> 9280.7163 | ... AQ56: =AQ53*0.6 -> 10704.877

Sheet Population
A1: 地区 | B1: 2000 | C1: 2001 | D1: 2002 | E1: 2003 | F1: 2004 | G1: 2005 | H1: 2006 | I1: 2007 | J1: 2008 | K1: 2009 | L1: 2010 | M1: 2011 | N1: 2012 | O1: 2013 | P1: 2014 | Q1: 2015 | R1: 2016 | S1: 2017 | T1: 2018 | U1: 2019 | V1: 2020 | W1: 2021 | X1: 2022 | Y1: 2023 | Z1: 2024 | AA1: 2025 | AB1: 2026 | AC1: 2027 | AD1: 2028 | AE1: 2029 | AF1: 2030 | AG1: 2031 | AH1: 2032 | AI1: 2033 | AJ1: 2034 | AK1: 2035 | AL1: 2036 | AM1: 2037 | AN1: 2038 | AO1: 2039 | AP1: 2040 | AQ1: 2041 | AR1: 2042 | AS1: 2043 | AT1: 2044 | AU1: 2045 | AV1: 2046 | AW1: 2047 | AX1: 2048 | AY1: 2049 | AZ1: 2050 | BA1: 2051 | BB1: 2052 | BC1: 2053 | BD1: 2054 | BE1: 2055 | BF1: 2056 | BG1: 2057 | BH1: 2058 | BI1: 2059 | BJ1: 2060
A2: 北京市 | B2: 1364 | C2: 1385 | D2: 1423 | E2: 1456 | F2: 1493 | G2: 1538 | H2: 1601 | I2: 1676 | J2: 1771 | K2: 1860 | L2: 1962 | M2: 2024 | N2: 2078 | O2: 2125 | P2: 2171 | Q2: 2188 | R2: 2195 | S2: 2194 | T2: 2192 | U2: 2190 | V2: 2189 | W2: 2209.2349 | X2: 2224.9167 | Y2: 2236.5919 | Z2: 2244.6671 | AA2: 2249.5287 | AB2: 2251.5425 | AC2: 2251.0539 | AD2: 2248.3879 | AE2: 2243.849 | AF2: 2237.7211 | AG2: 2230.2681 | AH2: 2221.7329 | AI2: 2212.3385 | AJ2: 2202.287 | AK2: 2191.7603 | AL2: 2180.9199 | AM2: 2169.9066 | AN2: 2158.841 | AO2: 2147.8232 | AP2: 2136.9328 | AQ2: 2126.229 | AR2: 2115.7505 | AS2: 2105.5156 | AT2: 2095.5222 | AU2: 2085.7477 | AV2: 2076.149 | AW2: 2066.6628 | AX2: 2057.2049 | AY2: 2047.6712 | AZ2: 2037.9368 | BA2: 2027.8564 | BB2: 2017.2643 | BC2: 2005.9744 | BD2: 1993.7802 | BE2: 1980.4545 | BF2: 1965.75 | BG2: 1949.3987 | BH2: 1931.1122 | BI2: 1910.5817 | BJ2: 1887.4781 | BO2: #REF!
A3: 天津市 | B3: 1001 | C3: 1004 | D3: 1007 | E3: 1011 | F3: 1024 | G3: 1043 | H3: 1075 | I3: 1115 | J3: 1176 | K3: 1228 | L3: 1299 | M3: 1341 | N3: 1378 | O3: 1410 | P3: 1429 | Q3: 1439 | R3: 1443 | S3: 1410 | T3: 1383 | U3: 1385 | V3: 1387 | W3: 1396.5579 | X3: 1404.3199 | Y3: 1409.977 | Z3: 1413.7179 | AA3: 1415.7227 | AB3: 1416.1631 | AC3: 1415.2018 | AD3: 1412.9932 | AE3: 1409.6828 | AF3: 1405.4075 | AG3: 1400.2956 | AH3: 1394.4668 | AI3: 1388.0322 | AJ3: 1381.0939 | AK3: 1373.7458 | AL3: 1366.0729 | AM3: 1358.1517 | AN3: 1350.0498 | AO3: 1341.8265 | AP3: 1333.5323 | AQ3: 1325.2088 | AR3: 1316.8894 | AS3: 1308.5986 | AT3: 1300.3523 | AU3: 1292.1577 | AV3: 1284.0135 | AW3: 1275.9095 | AX3: 1267.8272 | AY3: 1259.7391 | AZ3: 1251.6094 | BA3: 1243.3933 | BB3: 1235.0377 | BC3: 1226.4805 | BD3: 1217.6513 | BE3: 1208.4708 | BF3: 1198.8512 | BG3: 1188.696 | BH3: 1177.9 | BI3: 1166.3494 | BJ3: 1153.9219
A4: 河北省 | B4: 6674 | C4: 6699 | D4: 6735 | E4: 6769 | F4: 6809 | G4: 6851 | H4: 6898 | I4: 6943 | J4: 6989 | K4: 7034 | L4: 7194 | M4: 7232 | N4: 7262 | O4: 7288 | P4: 7323 | Q4: 7345 | R4: 7375 | S4: 7409 | T4: 7426 | U4: 7447 | V4: 7464 | W4: 7502.1028 | X4: 7540.4429 | Y4: 7575.3542 | Z4: 7606.8135 | AA4: 7634.8075 | AB4: 7659.3317 | AC4: 7680.392 | AD4: 7698.0035 | AE4: 7712.1908 | AF4: 7722.9877 | AG4: 7730.439 | AH4: 7734.5975 | AI4: 7735.5261 | AJ4: 7733.2974 | AK4: 7727.9937 | AL4: 7719.7068 | AM4: 7708.5376 | AN4: 7694.5972 | AO4: 7678.0057 | AP4: 7658.8935 | AQ4: 7637.3997 | AR4: 7613.6739 | AS4: 7587.8745 | AT4: 7560.1697 | AU4: 7530.7377 | AV4: 7499.7653 | AW4: 7467.4501 | AX4: 7433.9986 | AY4: 7399.6267 | AZ4: 7364.56 | BA4: 7329.034 | BB4: 7293.2936 | BC4: 7257.5929 | BD4: 7222.1964 | BE4: 7187.3772 | BF4: 7153.4185 | BG4: 7120.6132 | BH4: 7089.2633 | BI4: 7059.6813 | BJ4: 7032.1877
A5: 山西省 | B5: 3247 | C5: 3272 | D5: 3294 | E5: 3314 | F5: 3335 | G5: 3355 | H5: 3375 | I5: 3393 | J5: 3411 | K5: 3427 | L5: 3574 | M5: 3562 | N5: 3548 | O5: 3535 | P5: 3528 | Q5: 3519 | R5: 3514 | S5: 3510 | T5: 3502 | U5: 3497 | V5: 3490 | W5: 3522.7821 | X5: 3551.6126 | Y5: 3577.8317 | Z5: 3601.4691 | AA5: 3622.561 | AB5: 3641.1467 | AC5: 3657.2717 | AD5: 3670.985 | AE5: 3682.3409 | AF5: 3691.3984 | AG5: 3698.2208 | AH5: 3702.8764 | AI5: 3705.4382 | AJ5: 3705.9837 | AK5: 3704.5953 | AL5: 3701.3604 | AM5: 3696.37 | AN5: 3689.7211 | AO5: 3681.5147 | AP5: 3671.856 | AQ5: 3660.8563 | AR5: 3648.6303 | AS5: 3635.2981 | AT5: 3620.9843 | AU5: 3605.8181 | AV5: 3589.9334 | AW5: 3573.4689 | AX5: 3556.5681 | AY5: 3539.3788 | AZ5: 3522.0539 | BA5: 3504.7509 | BB5: 3487.6317 | BC5: 3470.8635 | BD5: 3454.6175 | BE5: 3439.0699 | BF5: 3424.4018 | BG5: 3410.7989 | BH5: 3398.4511 | BI5: 3387.554 | BJ5: 3378.3067
A6: 内蒙古自治区 | B6: 2372 | C6: 2381 | D6: 2384 | E6: 2386 | F6: 2393 | G6: 2403 | H6: 2415 | I6: 2429 | J6: 2444 | K6: 2458 | L6: 2472 | M6: 2470 | N6: 2464 | O6: 2455 | P6: 2449 | Q6: 2440 | R6: 2436 | S6: 2433 | T6: 2422 | U6: 2415 | V6: 2403 | W6: 2420.861 | X6: 2434.6588 | Y6: 2446.2962 | Z6: 2455.8714 | AA6: 2463.4818 | AB6: 2469.2215 | AC6: 2473.1836 | AD6: 2475.4584 | AE6: 2476.1343 | AF6: 2475.2978 | AG6: 2473.0339 | AH6: 2469.4246 | AI6: 2464.5498 | AJ6: 2458.4889 | AK6: 2451.317 | AL6: 2443.1089 | AM6: 2433.9367 | AN6: 2423.8704 | AO6: 2412.9784 | AP6: 2401.326 | AQ6: 2388.9779 | AR6: 2375.9956 | AS6: 2362.4393 | AT6: 2348.3667 | AU6: 2333.8332 | AV6: 2318.8931 | AW6: 2303.5978 | AX6: 2287.9972 | AY6: 2272.1384 | AZ6: 2256.0674 | BA6: 2239.8276 | BB6: 2223.4601 | BC6: 2207.0048 | BD6: 2190.499 | BE6: 2173.9777 | BF6: 2157.4746 | BG6: 2141.02 | BH6: 2124.6444 | BI6: 2108.3744 | BJ6: 2092.2347
A7: 辽宁省 | B7: 4184 | C7: 4194 | D7: 4203 | E7: 4210 | F7: 4217 | G7: 4221 | H7: 4271 | I7: 4298 | J7: 4315 | K7: 4341 | L7: 4375 | M7: 4379 | N7: 4375 | O7: 4365 | P7: 4358 | Q7: 4338 | R7: 4327 | S7: 4312 | T7: 4291 | U7: 4277 | V7: 4255 | W7: 4259.764 | X7: 4272.8546 | Y7: 4281.1622 | Z7: 4285.0087 | AA7: 4284.7045 | AB7: 4280.5505 | AC7: 4272.8369 | AD7: 4261.8441 | AE7: 4247.8422 | AF7: 4231.0902 | AG7: 4211.8376 | AH7: 4190.324 | AI7: 4166.7775 | AJ7: 4141.4172 | AK7: 4114.451 | AL7: 4086.0775 | AM7: 4056.4839 | AN7: 4025.8481 | AO7: 3994.3371 | AP7: 3962.1079 | AQ7: 3929.3074 | AR7: 3896.0722 | AS7: 3862.528 | AT7: 3828.7911 | AU7: 3794.9672 | AV7: 3761.1513 | AW7: 3727.4292 | AX7: 3693.8752 | AY7: 3660.554 | AZ7: 3627.5207 | BA7: 3594.8184 | BB7: 3562.4814 | BC7: 3530.5334 | BD7: 3498.9873 | BE7: 3467.8468 | BF7: 3437.1042 | BG7: 3406.7424 | BH7: 3376.7325 | BI7: 3347.038 | BJ7: 3317.6102
A8: 吉林省 | B8: 2682 | C8: 2691 | D8: 2699 | E8: 2704 | F8: 2709 | G8: 2716 | H8: 2723 | I8: 2730 | J8: 2734 | K8: 2740 | L8: 2747 | M8: 2725 | N8: 2698 | O8: 2668 | P8: 2642 | Q8: 2613 | R8: 2567 | S8: 2526 | T8: 2484 | U8: 2448 | V8: 2399 | W8: 2415.1769 | X8: 2426.4198 | Y8: 2434.9952 | Z8: 2441.0712 | AA8: 2444.8121 | AB8: 2446.3756 | AC8: 2445.9142 | AD8: 2443.5754 | AE8: 2439.5008 | AF8: 2433.8268 | AG8: 2426.6834 | AH8: 2418.1968 | AI8: 2408.4863 | AJ8: 2397.6664 | AK8: 2385.846 | AL8: 2373.1285 | AM8: 2359.6119 | AN8: 2345.3886 | AO8: 2330.5456 | AP8: 2315.1645 | AQ8: 2299.3214 | AR8: 2283.0872 | AS8: 2266.5265 | AT8: 2249.6992 | AU8: 2232.6599 | AV8: 2215.4568 | AW8: 2198.1334 | AX8: 2180.7279 | AY8: 2163.2721 | AZ8: 2145.793 | BA8: 2128.3125 | BB8: 2110.8459 | BC8: 2093.404 | BD8: 2075.9919 | BE8: 2058.6092 | BF8: 2041.2498 | BG8: 2023.9022 | BH8: 2006.55 | BI8: 1989.1705 | BJ8: 1971.7361
A9: 黑龙江省 | B9: 3807 | C9: 3811 | D9: 3813 | E9: 3815 | F9: 3817 | G9: 3820 | H9: 3823 | I9: 3824 | J9: 3825 | K9: 3826 | L9: 3833 | M9: 3782 | N9: 3724 | O9: 3666 | P9: 3608 | Q9: 3529 | R9: 3463 | S9: 3399 | T9: 3327 | U9: 3255 | V9: 3171 | W9: 3204.1673 | X9: 3219.5413 | Y9: 3231.2063 | Z9: 3239.4057 | AA9: 3244.3747 | AB9: 3246.3407 | AC9: 3245.522 | AD9: 3242.1294 | AE9: 3236.3646 | AF9: 3228.4216 | AG9: 3218.4856 | AH9: 3206.7338 | AI9: 3193.335 | AJ9: 3178.4493 | AK9: 3162.2289 | AL9: 3144.8177 | AM9: 3126.3509 | AN9: 3106.9559 | AO9: 3086.7512 | AP9: 3065.8473 | AQ9: 3044.3464 | AR9: 3022.3423 | AS9: 2999.9201 | AT9: 2977.1572 | AU9: 2954.1227 | AV9: 2930.8765 | AW9: 2907.4711 | AX9: 2883.9503 | AY9: 2860.3491 | AZ9: 2836.6953 | BA9: 2813.0073 | BB9: 2789.2962 | BC9: 2765.5632 | BD9: 2741.8031 | BE9: 2718.001 | BF9: 2694.1338 | BG9: 2670.1708 | BH9: 2646.0721 | BI9: 2621.7902 | BJ9: 2597.2691
A10: 上海市 | B10: 1609 | C10: 1668 | D10: 1713 | E10: 1766 | F10: 1835 | G10: 1890 | H10: 1964 | I10: 2064 | J10: 2141 | K10: 2210 | L10: 2303 | M10: 2356 | N10: 2399 | O10: 2448 | P10: 2467 | Q10: 2458 | R10: 2467 | S10: 2466 | T10: 2475 | U10: 2481 | V10: 2488 | W10: 2502.0844 | X10: 2513.1396 | Y10: 2520.2668 | Z10: 2523.8549 | AA10: 2524.274 | AB10: 2521.8753 | AC10: 2516.9909 | AD10: 2509.9342 | AE10: 2500.9995 | AF10: 2490.4622 | AG10: 2478.5789 | AH10: 2465.5873 | AI10: 2451.7059 | AJ10: 2437.1345 | AK10: 2422.054 | AL10: 2406.6263 | AM10: 2390.9945 | AN10: 2375.2824 | AO10: 2359.5954 | AP10: 2344.0196 | AQ10: 2328.6223 | AR10: 2313.452 | AS10: 2298.5381 | AT10: 2283.891 | AU10: 2269.5025 | AV10: 2255.3453 | AW10: 2241.3731 | AX10: 2227.5207 | AY10: 2213.7041 | AZ10: 2199.8203 | BA10: 2185.7473 | BB10: 2171.3444 | BC10: 2156.4518 | BD10: 2140.8908 | BE10: 2124.4638 | BF10: 2106.9542 | BG10: 2088.1266 | BH10: 2067.7267 | BI10: 2045.4811 | BJ10: 2021.0977
A11: 江苏省 | B11: 7327 | C11: 7359 | D11: 7406 | E11: 7458 | F11: 7523 | G11: 7588 | H11: 7656 | I11: 7723 | J11: 7762 | K11: 7810 | L11: 7869 | M11: 8023 | N11: 8120 | O11: 8192 | P11: 8281 | Q11: 8315 | R11: 8381 | S11: 8423 | T11: 8446 | U11: 8469 | V11: 8477 | W11: 8521.1325 | X11: 8559.9624 | Y11: 8590.6422 | Z11: 8613.6598 | AA11: 8629.4899 | AB11: 8638.5921 | AC11: 8641.4123 | AD11: 8638.3824 | AE11: 8629.9195 | AF11: 8616.4274 | AG11: 8598.2949 | AH11: 8575.898 | AI11: 8549.5961 | AJ11: 8519.737 | AK11: 8486.6532 | AL11: 8450.6631 | AM11: 8412.0709 | AN11: 8371.1665 | AO11: 8328.226 | AP11: 8283.5114 | AQ11: 8237.2704 | AR11: 8189.7362 | AS11: 8141.1285 | AT11: 8091.652 | AU11: 8041.4986 | AV11: 7990.8443 | AW11: 7939.8522 | AX11: 7888.671 | AY11: 7837.4346 | AZ11: 7786.2639 | BA11: 7735.2646 | BB11: 7684.5288 | BC11: 7634.1344 | BD11: 7584.145 | BE11: 7534.6097 | BF11: 7485.5642 | BG11: 7437.0297 | BH11: 7389.0133 | BI11: 7341.5075 | BJ11: 7294.4913
A12: 浙江省 | B12: 4680 | C12: 4729 | D12: 4776 | E12: 4857 | F12: 4925 | G12: 4991 | H12: 5072 | I12: 5155 | J12: 5212 | K12: 5276 | L12: 5447 | M12: 5570 | N12: 5685 | O12: 5784 | P12: 5890 | Q12: 5985 | R12: 6072 | S12: 6170 | T12: 6273 | U12: 6375 | V12: 6468 | W12: 6493.3164 | X12: 6524.4278 | Y12: 6549.684 | Z12: 6569.418 | AA12: 6583.953 | AB12: 6593.6011 | AC12: 6598.6649 | AD12: 6599.4362 | AE12: 6596.1967 | AF12: 6589.2173 | AG12: 6578.7591 | AH12: 6565.0725 | AI12: 6548.3974 | AJ12: 6528.9637 | AK12: 6506.991 | AL12: 6482.6881 | AM12: 6456.2538 | AN12: 6427.8765 | AO12: 6397.7341 | AP12: 6365.9942 | AQ12: 6332.8143 | AR12: 6298.3415 | AS12: 6262.7117 | AT12: 6226.0518 | AU12: 6188.4772 | AV12: 6150.0938 | AW12: 6110.9968 | AX12: 6071.2707 | AY12: 6030.9901 | AZ12: 5990.2192 | BA12: 5949.0118 | BB12: 5907.411 | BC12: 5865.4502 | BD12: 5823.1518 | BE12: 5780.5287 | BF12: 5737.5821 | BG12: 5694.3042 | BH12: 5650.6762 | BI12: 5606.669 | BJ12: 5562.2429
A13: 安徽省 | B13: 6093 | C13: 6128 | D13: 6144 | E13: 6163 | F13: 6228 | G13: 6120 | H13: 6110 | I13: 6118 | J13: 6135 | K13: 6131 | L13: 5957 | M13: 5972 | N13: 5978 | O13: 5988 | P13: 5997 | Q13: 6011 | R13: 6033 | S13: 6057 | T13: 6076 | U13: 6092 | V13: 6105 | W13: 6135.401 | X13: 6167.1438 | Y13: 6196.9675 | Z13: 6224.6592 | AA13: 6250.027 | AB13: 6272.8991 | AC13: 6293.1244 | AD13: 6310.573 | AE13: 6325.1349 | AF13: 6336.7213 | AG13: 6345.2638 | AH13: 6350.7146 | AI13: 6353.0472 | AJ13: 6352.2551 | AK13: 6348.3523 | AL13: 6341.3741 | AM13: 6331.3763 | AN13: 6318.4354 | AO13: 6302.6477 | AP13: 6284.1313 | AQ13: 6263.025 | AR13: 6239.4871 | AS13: 6213.6975 | AT13: 6185.8565 | AU13: 6156.185 | AV13: 6124.925 | AW13: 6092.3386 | AX13: 6058.7089 | AY13: 6024.3395 | AZ13: 5989.5542 | BA13: 5954.6992 | BB13: 5920.1392 | BC13: 5886.2603 | BD13: 5853.47 | BE13: 5822.1959 | BF13: 5792.8865 | BG13: 5766.0101 | BH13: 5742.0569 | BI13: 5721.5369 | BJ13: 5704.9811
A14: 福建省 | B14: 3410 | C14: 3445 | D14: 3476 | E14: 3502 | F14: 3529 | G14: 3557 | H14: 3585 | I14: 3612 | J14: 3639 | K14: 3666 | L14: 3693 | M14: 3784 | N14: 3841 | O14: 3885 | P14: 3945 | Q14: 3984 | R14: 4016 | S14: 4065 | T14: 4104 | U14: 4137 | V14: 4161 | W14: 4186.8981 | X14: 4216.8714 | Y14: 4243.6412 | Z14: 4267.3379 | AA14: 4288.0883 | AB14: 4306.0175 | AC14: 4321.2469 | AD14: 4333.896 | AE14: 4344.0813 | AF14: 4351.9166 | AG14: 4357.513 | AH14: 4360.9788 | AI14: 4362.4201 | AJ14: 4361.9396 | AK14: 4359.6379 | AL14: 4355.6123 | AM14: 4349.958 | AN14: 4342.7672 | AO14: 4334.1297 | AP14: 4324.1319 | AQ14: 4312.8585 | AR14: 4300.3905 | AS14: 4286.8069 | AT14: 4272.1839 | AU14: 4256.5949 | AV14: 4240.1107 | AW14: 4222.7988 | AX14: 4204.725 | AY14: 4185.9515 | AZ14: 4166.5388 | BA14: 4146.5438 | BB14: 4126.0209 | BC14: 4105.0223 | BD14: 4083.5966 | BE14: 4061.7911 | BF14: 4039.6489 | BG14: 4017.2111 | BH14: 3994.5164 | BI14: 3971.6001 | BJ14: 3948.4955
... A32: 新疆维吾尔自治区 | B32: 1849 | C32: 1876 | D32: 1905 | E32: 1934 | F32: 1963 | G32: 2010 | H32: 2050 | I32: 2095 | J32: 2131 | K32: 2159 | L32: 2185 | M32: 2225 | N32: 2253 | O32: 2285 | P32: 2325 | Q32: 2385 | R32: 2428 | S32: 2480 | T32: 2520 | U32: 2559 | V32: 2590 | W32: 2762.6777 | X32: 2783.2949 | Y32: 2803.2614 | Z32: 2822.4702 | AA32: 2840.822 | AB32: 2858.2259 | AC32: 2874.5988 | AD32: 2889.8664 | AE32: 2903.962 | AF32: 2916.8277 | AG32: 2928.4132 | AH32: 2938.6764 | AI32: 2947.584 | AJ32: 2955.1107 | AK32: 2961.2391 | AL32: 2965.9597 | AM32: 2969.2727 | AN32: 2971.1845 | AO32: 2971.7109 | AP32: 2970.876 | AQ32: 2968.7115 | AR32: 2965.2573 | AS32: 2960.5621 | AT32: 2954.6827 | AU32: 2947.6834 | AV32: 2939.6372 | AW32: 2930.6254 | AX32: 2920.7372 | AY32: 2910.0706 | AZ32: 2898.7309 | BA32: 2886.8322 | BB32: 2874.4969 | BC32: 2861.8548 | BD32: 2849.0446 | BE32: 2836.2136 | BF32: 2823.5161 | BG32: 2811.1156 | BH32: 2799.1834 | BI32: 2787.8992 | BJ32: 2777.4503
A34: 北京市 | G34: 1286 | H34: 1350 | I34: 1416 | J34: 1504 | K34: 1581 | L34: 1686 | M34: 1745 | N34: 1793 | O34: 1836 | P34: 1878 | Q34: 1897 | R34: 1904 | S34: 1907 | T34: 1909 | U34: 1913 | V34: 1916 | W34: 1932.7021 | X34: 1960.2734 | Y34: 1984.5841 | Z34: 2005.9245 | AA34: 2024.5758 | AB34: 2028.6286 | AC34: 2030.4307 | AD34: 2030.2682 | AE34: 2028.4098 | AF34: 2025.1067 | AG34: 2020.5933 | AH34: 2015.0859 | AI34: 2008.7838 | AJ34: 2001.8679 | AK34: 1994.5019 | AL34: 1994.5603 | AM34: 1994.4105 | AN34: 1994.1611 | AO34: 1993.9037 | AP34: 1993.7127 | AQ34: 1991.2119 | AR34: 1988.8756 | AS34: 1986.7233 | AT34: 1984.7551 | AU34: 1982.9518 | AV34: 1981.2745 | AW34: 1979.664 | AX34: 1978.0404 | AY34: 1976.3032 | AZ34: 1974.3302 | BA34: 1967.0207 | BB34: 1956.7464 | BC34: 1945.7952 | BD34: 1933.9668 | BE34: 1921.0409 | BF34: 1906.7775 | BG34: 1890.9167 | BH34: 1873.1788 | BI34: 1853.2642 | BJ34: 1830.8538
A35: 天津市 | G35: 783 | H35: 814 | I35: 851 | J35: 908 | K35: 958 | L35: 1034 | M35: 1079 | N35: 1124 | O35: 1160 | P35: 1180 | Q35: 1193 | R35: 1202 | S35: 1178 | T35: 1161 | U35: 1168 | V35: 1175 | W35: 1184.989 | X35: 1195.5898 | Y35: 1204.4505 | Z35: 1211.7149 | AA35: 1217.5215 | AB35: 1222.0835 | AC35: 1225.4487 | AD35: 1227.7388 | AE35: 1229.0696 | AF35: 1229.5509 | AG35: 1229.2865 | AH35: 1228.3743 | AI35: 1226.9058 | AJ35: 1224.9661 | AK35: 1222.6338 | AL35: 1221.8839 | AM35: 1220.8728 | AN35: 1219.6578 | AO35: 1218.2898 | AP35: 1216.813 | AQ35: 1213.7811 | AR35: 1210.7127 | AS35: 1207.6302 | AT35: 1204.5485 | AU35: 1201.4744 | AV35: 1198.407 | AW35: 1195.337 | AX35: 1192.2471 | AY35: 1189.1115 | AZ35: 1185.8958 | BA35: 1182.5567 | BB35: 1179.0423 | BC35: 1175.2914 | BD35: 1171.2338 | BE35: 1166.7896 | BF35: 1161.8697 | BG35: 1153.0351 | BH35: 1142.563 | BI35: 1131.3589 | BJ35: 1119.3042
A36: 河北省 | G36: 2582 | H36: 2674 | I36: 2795 | J36: 2928 | K36: 3077 | L36: 3201 | M36: 3297 | N36: 3384 | O36: 3500 | P36: 3615 | Q36: 3795 | R36: 3973 | S36: 4130 | T36: 4257 | U36: 4377 | V36: 4484 | W36: 4587.0806 | X36: 4681.5559 | Y36: 4775.6919 | Z36: 4869.4076 | AA36: 4962.6249 | AB36: 5015.5978 | AC36: 5066.799 | AD36: 5116.1924 | AE36: 5163.7475 | AF36: 5209.44 | AG36: 5253.2531 | AH36: 5295.1754 | AI36: 5335.2031 | AJ36: 5373.3395 | AK36: 5409.5956 | AL36: 5430.8137 | AM36: 5450.071 | AN36: 5467.416 | AO36: 5482.905 | AP36: 5496.6031 | AQ36: 5501.8609 | AR36: 5505.4662 | AS36: 5507.5152 | AT36: 5508.1131 | AU36: 5507.3739 | AV36: 5505.42 | AW36: 5502.3834 | AX36: 5498.4051 | AY36: 5493.6351 | AZ36: 5488.233 | BA36: 5482.3683 | BB36: 5476.2203 | BC36: 5469.9777 | BD36: 5463.8401 | BE36: 5458.0168 | BF36: 5452.7276 | BG36: 5448.2033 | BH36: 5444.6849 | BI36: 5442.4253 | BJ36: 5441.6872
A37: 山西省 | G37: 1413 | H37: 1451 | I37: 1494 | J37: 1539 | K37: 1576 | L37: 1717 | M37: 1774 | N37: 1821 | O37: 1869 | P37: 1916 | Q37: 1966 | R37: 2012 | S37: 2057 | T37: 2096 | U37: 2143 | V37: 2182 | W37: 2234.1322 | X37: 2292.0291 | Y37: 2349.5566 | Z37: 2406.6734 | AA37: 2463.3415 | AB37: 2493.6097 | AC37: 2522.4869 | AD37: 2549.9737 | AE37: 2576.0749 | AF37: 2600.7991 | AG37: 2624.1588 | AH37: 2646.1709 | AI37: 2666.8565 | AJ37: 2686.241 | AK37: 2704.3546 | AL37: 2715.5031 | AM37: 2725.4011 | AN37: 2734.1012 | AO37: 2741.6603 | AP37: 2748.1397 | AQ37: 2750.2463 | AR37: 2751.4049 | AS37: 2751.6958 | AT37: 2751.2038 | AU37: 2750.0189 | AV37: 2748.2358 | AW37: 2745.9546 | AX37: 2743.2804 | AY37: 2740.3237 | AZ37: 2737.2001 | BA37: 2734.0311 | BB37: 2730.9431 | BC37: 2728.0687 | BD37: 2725.5458 | BE37: 2723.518 | BF37: 2722.1353 | BG37: 2721.5533 | BH37: 2721.9334 | BI37: 2723.4439 | BJ37: 2726.2584
A38: 内蒙古自治区 | G38: 1134 | H38: 1175 | I38: 1218 | J38: 1264 | K38: 1313 | L38: 1372 | M38: 1409 | N38: 1439 | O38: 1469 | P38: 1493 | Q38: 1515 | R38: 1544 | S38: 1572 | T38: 1587 | U38: 1605 | V38: 1622 | W38: 1651.2289 | X38: 1665.438 | Y38: 1678.2332 | Z38: 1689.6696 | AA38: 1699.8024 | AB38: 1711.0294 | AC38: 1721.0842 | AD38: 1730.0145 | AE38: 1737.8675 | AF38: 1744.6899 | AG38: 1750.5286 | AH38: 1755.4289 | AI38: 1759.4358 | AJ38: 1762.5945 | AK38: 1764.9482 | AL38: 1767.8336 | AM38: 1770.0026 | AN38: 1771.4956 | AO38: 1772.3528 | AP38: 1772.613 | AQ38: 1770.1525 | AR38: 1767.1764 | AS38: 1763.7242 | AT38: 1759.8339 | AU38: 1755.5424 | AV38: 1750.8864 | AW38: 1745.9011 | AX38: 1740.6209 | AY38: 1735.0789 | AZ38: 1729.3076 | BA38: 1723.3382 | BB38: 1717.2005 | BC38: 1710.9239 | BD38: 1704.5361 | BE38: 1698.0637 | BF38: 1691.5324 | BG38: 1684.9658 | BH38: 1678.388 | BI38: 1671.8202 | BJ38: 1665.2827
A39: 辽宁省 | G39: 2478 | H39: 2519 | I39: 2544 | J39: 2591 | K39: 2620 | L39: 2717 | M39: 2805 | N39: 2872 | O39: 2901 | P39: 2922 | Q39: 2952 | R39: 2980 | S39: 2996 | T39: 3015 | U39: 3046 | V39: 3070 | W39: 3101.3983 | X39: 3069.4417 | Y39: 3034.3958 | Z39: 2996.619 | AA39: 2956.4461 | AB39: 2966.177 | AC39: 2973.4599 | AD39: 2978.4593 | AE39: 2981.3353 | AF39: 2982.2433 | AG39: 2981.3348 | AH39: 2978.757 | AI39: 2974.6517 | AJ39: 2969.1568 | AK39: 2962.4047 | AL39: 2956.6857 | AM39: 2949.9481 | AN39: 2942.3075 | AO39: 2933.874 | AP39: 2924.7524 | AQ39: 2911.485 | AR39: 2897.7524 | AS39: 2883.6441 | AT39: 2869.2437 | AU39: 2854.628 | AV39: 2839.8673 | AW39: 2825.0255 | AX39: 2810.1593 | AY39: 2795.3183 | AZ39: 2780.546 | BA39: 2765.8772 | BB39: 2751.3401 | BC39: 2736.9555 | BD39: 2722.7359 | BE39: 2708.6868 | BF39: 2694.8049 | BG39: 2681.0793 | BH39: 2667.4897 | BI39: 2654.0096 | BJ39: 2640.6019
A40: 吉林省 | G40: 1426 | H40: 1442 | I40: 1451 | J40: 1455 | K40: 1461 | L40: 1465 | M40: 1455 | N40: 1471 | O40: 1487 | P40: 1501 | Q40: 1506 | R40: 1508 | S40: 1508 | T40: 1512 | U40: 1509 | V40: 1503 | W40: 1530.4595 | X40: 1547.387 | Y40: 1562.7562 | Z40: 1576.6442 | AA40: 1589.1279 | AB40: 1601.9721 | AC40: 1613.5838 | AD40: 1624.0317 | AE40: 1633.3836 | AF40: 1641.7059 | AG40: 1649.0631 | AH40: 1655.5194 | AI40: 1661.1364 | AJ40: 1665.9744 | AK40: 1670.0922 | AL40: 1669.4959 | AM40: 1668.2869 | AN40: 1666.5219 | AO40: 1664.2551 | AP40: 1661.5377 | AQ40: 1656.3945 | AR40: 1650.9059 | AS40: 1645.1154 | AT40: 1639.0634 | AU40: 1632.7873 | AV40: 1626.3202 | AW40: 1619.6925 | AX40: 1612.9308 | AY40: 1606.0577 | AZ40: 1599.0924 | BA40: 1592.0506 | BB40: 1584.9433 | BC40: 1577.7784 | BD40: 1570.5593 | BE40: 1563.2856 | BF40: 1555.9525 | BG40: 1548.5507 | BH40: 1541.0674 | BI40: 1533.4845 | BJ40: 1525.78
A41: 黑龙江省 | G41: 2028 | H41: 2045 | I41: 2061 | J41: 2119 | K41: 2123 | L41: 2134 | M41: 2136 | N41: 2118 | O41: 2128 | P41: 2137 | Q41: 2134 | R41: 2116 | S41: 2104 | T41: 2111 | U41: 2103 | V41: 2080 | W41: 2105.0097 | X41: 2109.4855 | Y41: 2111.4988 | Z41: 2111.2278 | AA41: 2108.8436 | AB41: 2125.8172 | AC41: 2141.0896 | AD41: 2154.761 | AE41: 2166.929 | AF41: 2177.6894 | AG41: 2187.1357 | AH41: 2195.359 | AI41: 2202.4476 | AJ41: 2208.4871 | AK41: 2213.5602 | AL41: 2212.3793 | AM41: 2210.3848 | AN41: 2207.6556 | AO41: 2204.2655 | AP41: 2200.2847 | AQ41: 2193.0986 | AR41: 2185.4631 | AS41: 2177.4353 | AT41: 2169.0675 | AU41: 2160.407 | AV41: 2151.4948 | AW41: 2142.3673 | AX41: 2133.0549 | AY41: 2123.582 | AZ41: 2113.9681 | BA41: 2104.2258 | BB41: 2094.3625 | BC41: 2084.3783 | BD41: 2074.2684 | BE41: 2064.0207 | BF41: 2053.6164 | BG41: 2043.031 | BH41: 2032.2322 | BI41: 2021.1815 | BJ41: 2009.8335
A42: 上海市 | G42: 1684 | H42: 1742 | I42: 1830 | J42: 1897 | K42: 1958 | L42: 2056 | M42: 2104 | N42: 2142 | O42: 2193 | P42: 2203 | Q42: 2176 | R42: 2196 | S42: 2197 | T42: 2206 | U42: 2214 | V42: 2222 | W42: 2234.6861 | X42: 2248.8639 | Y42: 2259.5661 | Z42: 2267.1221 | AA42: 2271.8466 | AB42: 2274.6818 | AC42: 2275.2715 | AD42: 2273.8847 | AE42: 2270.7757 | AF42: 2266.1838 | AG42: 2260.3331 | AH42: 2253.4328 | AI42: 2245.6762 | AJ42: 2237.2411 | AK42: 2228.2897 | AL42: 2225.1667 | AM42: 2221.7671 | AN42: 2218.2029 | AO42: 2214.571 | AP42: 2210.9523 | AQ42: 2204.7174 | AR42: 2198.6197 | AS42: 2192.6891 | AT42: 2186.938 | AU42: 2181.3608 | AV42: 2175.9335 | AW42: 2170.6133 | AX42: 2160.6951 | AY42: 2147.293 | AZ42: 2133.8257 | BA42: 2120.1749 | BB42: 2106.2041 | BC42: 2091.7582 | BD42: 2076.6641 | BE42: 2060.7299 | BF42: 2043.7456 | BG42: 2025.4828 | BH42: 2005.6949 | BI42: 1984.1167 | BJ42: 1960.4648
A43: 江苏省 | G43: 3832 | H43: 3973 | I43: 4109 | J43: 4215 | K43: 4343 | L43: 4767 | M43: 4975 | N43: 5116 | O43: 5275 | P43: 5441 | Q43: 5612 | R43: 5777 | S43: 5911 | T43: 6013 | U43: 6137 | V43: 6226 | W43: 6300.9291 | X43: 6352.1044 | Y43: 6397.4942 | Z43: 6437.3998 | AA43: 6472.1174 | AB43: 6520.8934 | AC43: 6565.2571 | AD43: 6605.4484 | AE43: 6641.7037 | AF43: 6674.256 | AG43: 6703.3336 | AH43: 6729.1619 | AI43: 6751.9597 | AJ43: 6771.9431 | AK43: 6789.3226 | AL43: 6794.3331 | AM43: 6797.1215 | AN43: 6797.8903 | AO43: 6796.8351 | AP43: 6794.1444 | AQ43: 6781.7122 | AR43: 6768.0208 | AS43: 6753.239 | AT43: 6737.5259 | AU43: 6721.0323 | AV43: 6703.898 | AW43: 6686.2542 | AX43: 6668.222 | AY43: 6649.9116 | AZ43: 6631.4241 | BA43: 6612.8488 | BB43: 6594.2651 | BC43: 6575.741 | BD43: 6557.3334 | BE43: 6539.0873 | BF43: 6521.0368 | BG43: 6503.2039 | BH43: 6485.5982 | BI43: 6468.2169 | BJ43: 6451.0451
A44: 浙江省 | G44: 2796 | H44: 2866 | I44: 2949 | J44: 3002 | K44: 3055 | L44: 3356 | M44: 3470 | N44: 3576 | O44: 3698 | P44: 3826 | Q44: 3969 | R44: 4112 | S44: 4252 | T44: 4392 | U44: 4563 | V44: 4668 | W44: 4718.0794 | X44: 4778.3918 | Y44: 4835.0428 | Z44: 4888.1837 | AA44: 4937.9648 | AB44: 4977.2196 | AC44: 5013.2929 | AD44: 5046.3424 | AE44: 5076.5229 | AF44: 5103.9858 | AG44: 5128.8793 | AH44: 5151.3481 | AI44: 5171.5326 | AJ44: 5189.5699 | AK44: 5205.5928 | AL44: 5212.0812 | AM44: 5216.7822 | AN44: 5219.822 | AO44: 5221.3213 | AP44: 5221.3948 | AQ44: 5213.781 | AR44: 5204.967 | AS44: 5195.0524 | AT44: 5184.1312 | AU44: 5172.289 | AV44: 5159.6051 | AW44: 5146.151 | AX44: 5131.99 | AY44: 5117.1784 | AZ44: 5101.7644 | BA44: 5085.788 | BB44: 5069.2808 | BC44: 5052.2665 | BD44: 5034.7597 | BE44: 5016.7671 | BF44: 4998.2851 | BG44: 4979.3026 | BH44: 4959.7983 | BI44: 4939.7418 | BJ44: 4919.0928
A45: 安徽省 | G45: 2173 | H45: 2267 | I45: 2368 | J45: 2485 | K45: 2581 | L45: 2562 | M45: 2675 | N45: 2768 | O45: 2866 | P45: 2957 | Q45: 3064 | R45: 3175 | S45: 3288 | T45: 3381 | U45: 3474 | V45: 3561 | W45: 3644.3057 | X45: 3746.6343 | Y45: 3850.5416 | Z45: 3955.8841 | AA45: 4062.5176 | AB45: 4124.9872 | AC45: 4186.601 | AD45: 4247.2224 | AE45: 4306.7231 | AF45: 4364.9846 | AG45: 4421.8982 | AH45: 4477.3661 | AI45: 4531.3024 | AJ45: 4583.633 | AK45: 4634.2972 | AL45: 4652.3491 | AM45: 4668.2393 | AN45: 4681.9912 | AO45: 4693.6439 | AP45: 4703.2538 | AQ45: 4705.1454 | AR45: 4705.1507 | AS45: 4703.3846 | AT45: 4699.9795 | AU45: 4695.0857 | AV45: 4688.872 | AW45: 4681.5253 | AX45: 4673.2516 | AY45: 4664.2762 | AZ45: 4654.8432 | BA45: 4645.2182 | BB45: 4635.6854 | BC45: 4626.5497 | BD45: 4618.138 | BE45: 4610.7976 | BF45: 4604.8979 | BG45: 4600.8294 | BH45: 4599.0058 | BI45: 4599.8631 | BJ45: 4603.8605
... A96: 新疆维吾尔自治区 | G96: 1263 | H96: 1272 | I96: 1275 | J96: 1286 | K96: 1299 | L96: 1245 | M96: 1252 | N96: 1257 | O96: 1258 | P96: 1237 | Q96: 1222 | R96: 1204 | S96: 1193 | T96: 1159 | U96: 1138 | V96: 1126 | W96: 1181.2608 | X96: 1171.224 | Y96: 1160.4137 | Z96: 1148.7925 | AA96: 1136.3288 | AB96: 1129.5085 | AC96: 1122.0065 | AD96: 1113.8063 | AE96: 1104.8963 | AF96: 1095.2694 | AG96: 1084.9228 | AH96: 1073.8582 | AI96: 1062.0814 | AJ96: 1049.6022 | AK96: 1036.4337 | AL96: 1028.4465 | AM96: 1019.8969 | AN96: 1010.8004 | AO96: 1001.1759 | AP96: 991.04468 | AQ96: 982.85712 | AR96: 974.22857 | AS96: 965.18467 | AT96: 955.75324 | AU96: 945.96402 | AV96: 935.84892 | AW96: 925.44179 | AX96: 914.77818 | AY96: 903.89549 | AZ96: 892.83241 | BA96: 881.62926 | BB96: 870.32774 | BC96: 858.97049 | BD96: 847.60147 | BE96: 836.26571 | BF96: 825.00874 | BG96: 813.87711 | BH96: 802.91783 | BI96: 792.17847 | BJ96: 781.70675

Sheet Building Area Result
A1: Type | B1: 行政区划编码 | C1: 省级行政区 | D1: 名称 | E1: 2019 | F1: 2020 | G1: 2021 | H1: 2022 | I1: 2023 | J1: 2024 | K1: 2025 | L1: 2026 | M1: 2027 | N1: 2028 | O1: 2029 | P1: 2030 | Q1: 2031 | R1: 2032 | S1: 2033 | T1: 2034 | U1: 2035 | V1: 2036 | W1: 2037 | X1: 2038 | Y1: 2039 | Z1: 2040 | AA1: 2041 | AB1: 2042 | AC1: 2043 | AD1: 2044 | AE1: 2045 | AF1: 2046 | AG1: 2047 | AH1: 2048 | AI1: 2049 | AJ1: 2050 | AK1: 2051 | AL1: 2052 | AM1: 2053 | AN1: 2054 | AO1: 2055 | AP1: 2056 | AQ1: 2057 | AR1: 2058 | AS1: 2059 | AT1: 2060
A2: 公共建筑面积 | B2: 0 | C2: 全国 | D2: 全国 | E2: =SUMIFS(E$5:E$833,$A$5:$A$833,$A2) -> 1.2718182e+10 | F2: =SUMIFS(F$5:F$833,$A$5:$A$833,$A2) -> 1.3117204e+10 | G2: =SUMIFS(G$5:G$833,$A$5:$A$833,$A2) -> 1.3445852e+10 | H2: =SUMIFS(H$5:H$833,$A$5:$A$833,$A2) -> 1.3769083e+10 | I2: =SUMIFS(I$5:I$833,$A$5:$A$833,$A2) -> 1.4086864e+10 | J2: =SUMIFS(J$5:J$833,$A$5:$A$833,$A2) -> 1.4399163e+10 | K2: =SUMIFS(K$5:K$833,$A$5:$A$833,$A2) -> 1.4705949e+10 | L2: =SUMIFS(L$5:L$833,$A$5:$A$833,$A2) -> 1.5007196e+10 | ... AT2: =SUMIFS(AT$5:AT$833,$A$5:$A$833,$A2) -> 2.0806916e+10
A3: 城镇住宅面积 | B3: 0 | C3: 全国 | D3: 全国 | E3: =SUMIFS(E$5:E$833,$A$5:$A$833,$A3) -> 3.0311727e+10 | F3: =SUMIFS(F$5:F$833,$A$5:$A$833,$A3) -> 3.1115403e+10 | G3: =SUMIFS(G$5:G$833,$A$5:$A$833,$A3) -> 3.1727837e+10 | H3: =SUMIFS(H$5:H$833,$A$5:$A$833,$A3) -> 3.232438e+10 | I3: =SUMIFS(I$5:I$833,$A$5:$A$833,$A3) -> 3.2904918e+10 | J3: =SUMIFS(J$5:J$833,$A$5:$A$833,$A3) -> 3.3469355e+10 | K3: =SUMIFS(K$5:K$833,$A$5:$A$833,$A3) -> 3.4017617e+10 | L3: =SUMIFS(L$5:L$833,$A$5:$A$833,$A3) -> 3.4549652e+10 | ... AT3: =SUMIFS(AT$5:AT$833,$A$5:$A$833,$A3) -> 3.9898968e+10
A4: 乡村住宅面积 | B4: 0 | C4: 全国 | D4: 全国 | E4: =SUMIFS(E$5:E$833,$A$5:$A$833,$A4) -> 2.1439578e+10 | F4: =SUMIFS(F$5:F$833,$A$5:$A$833,$A4) -> 2.1382914e+10 | G4: =SUMIFS(G$5:G$833,$A$5:$A$833,$A4) -> 2.1272869e+10 | H4: =SUMIFS(H$5:H$833,$A$5:$A$833,$A4) -> 2.1141153e+10 | I4: =SUMIFS(I$5:I$833,$A$5:$A$833,$A4) -> 2.0988052e+10 | J4: =SUMIFS(J$5:J$833,$A$5:$A$833,$A4) -> 2.0813933e+10 | K4: =SUMIFS(K$5:K$833,$A$5:$A$833,$A4) -> 2.0619238e+10 | L4: =SUMIFS(L$5:L$833,$A$5:$A$833,$A4) -> 2.0404481e+10 | ... AT4: =SUMIFS(AT$5:AT$833,$A$5:$A$833,$A4) -> 1.3381929e+10
A5: 城镇住宅面积 | B5: 110000 | C5: 北京市 | D5: 北京市 | E5: 6.0288178e+08 | F5: 6.1304299e+08 | G5: 6.2266318e+08 | H5: 6.3111118e+08 | I5: 6.3848514e+08 | J5: 6.4488024e+08 | K5: 6.5038867e+08 | L5: 6.5509931e+08 | M5: 6.5909767e+08 | N5: 6.6246569e+08 | O5: 6.6528155e+08 | P5: 6.6761947e+08 | Q5: 6.6948366e+08 | R5: 6.7100615e+08 | S5: 6.722486e+08 | T5: 6.7326789e+08 | U5: 6.7411613e+08 | V5: 6.7484049e+08 | W5: 6.7548286e+08 | X5: 6.7607985e+08 | Y5: 6.7666253e+08 | Z5: 6.7725619e+08 | AA5: 6.7850728e+08 | AB5: 6.7979965e+08 | AC5: 6.8114048e+08 | AD5: 6.8253046e+08 | AE5: 6.8396357e+08 | AF5: 6.854268e+08 | AG5: 6.8690007e+08 | AH5: 6.8835576e+08 | AI5: 6.8975877e+08 | AJ5: 6.9106603e+08 | AK5: 6.8982502e+08 | AL5: 6.8838825e+08 | AM5: 6.8669039e+08 | AN5: 6.8465825e+08 | AO5: 6.8221064e+08 | AP5: 6.7925846e+08 | AQ5: 6.7570435e+08 | AR5: 6.7144272e+08 | AS5: 6.663596e+08 | AT5: 6.6033259e+08
A6: 城镇住宅面积 | B6: 120000 | C6: 天津市 | D6: 天津市 | E6: 3.6589254e+08 | F6: 3.718983e+08 | G6: 3.7696642e+08 | H6: 3.8145076e+08 | I6: 3.8539371e+08 | J6: 3.8883648e+08 | K6: 3.9181914e+08 | L6: 3.9438059e+08 | M6: 3.9655834e+08 | N6: 3.9838865e+08 | O6: 3.9990627e+08 | P6: 4.0114447e+08 | Q6: 4.0262384e+08 | R6: 4.0388452e+08 | S6: 4.0495428e+08 | T6: 4.0585913e+08 | U6: 4.0662349e+08 | V6: 4.0726995e+08 | W6: 4.078192e+08 | X6: 4.0828993e+08 | Y6: 4.0869884e+08 | Z6: 4.0906046e+08 | AA6: 4.0930837e+08 | AB6: 4.095318e+08 | AC6: 4.0973826e+08 | AD6: 4.0993278e+08 | AE6: 4.1011774e+08 | AF6: 4.1029289e+08 | AG6: 4.1045509e+08 | AH6: 4.1059845e+08 | AI6: 4.1071395e+08 | AJ6: 4.1078965e+08 | AK6: 4.1030617e+08 | AL6: 4.0975302e+08 | AM6: 4.0910861e+08 | AN6: 4.0834813e+08 | AO6: 4.0744326e+08 | AP6: 4.0636221e+08 | AQ6: 4.0506958e+08 | AR6: 4.0352629e+08 | AS6: 4.0168949e+08 | AT6: 3.9951258e+08
A7: 城镇住宅面积 | B7: 130100 | C7: 河北省 | D7: 石家庄市 | E7: 2.0895202e+08 | F7: 2.1494646e+08 | G7: 2.1956855e+08 | H7: 2.2405028e+08 | I7: 2.2839444e+08 | J7: 2.3260402e+08 | K7: 2.3668224e+08 | L7: 2.4063242e+08 | M7: 2.4445813e+08 | N7: 2.4816304e+08 | O7: 2.5175093e+08 | P7: 2.5522574e+08 | Q7: 2.5749838e+08 | R7: 2.5965925e+08 | S7: 2.61714e+08 | T7: 2.6366826e+08 | U7: 2.6552757e+08 | V7: 2.6729741e+08 | W7: 2.6898317e+08 | X7: 2.7059011e+08 | Y7: 2.7212345e+08 | Z7: 2.7358823e+08 | AA7: 2.7473297e+08 | AB7: 2.7581891e+08 | AC7: 2.7685091e+08 | AD7: 2.7783352e+08 | AE7: 2.7877123e+08 | AF7: 2.7966822e+08 | AG7: 2.8052856e+08 | AH7: 2.8135602e+08 | AI7: 2.8215419e+08 | AJ7: 2.829264e+08 | AK7: 2.8374117e+08 | AL7: 2.8453578e+08 | AM7: 2.853127e+08 | AN7: 2.8607422e+08 | AO7: 2.8682225e+08 | AP7: 2.8755845e+08 | AQ7: 2.8828415e+08 | AR7: 2.8900032e+08 | AS7: 2.8970761e+08 | AT7: 2.9040634e+08
A8: 城镇住宅面积 | B8: 130200 | C8: 河北省 | D8: 唐山市 | E8: 1.3751149e+08 | F8: 1.4090772e+08 | G8: 1.4341978e+08 | H8: 1.4585606e+08 | I8: 1.4821609e+08 | J8: 1.504995e+08 | K8: 1.527061e+08 | L8: 1.5483584e+08 | M8: 1.5688887e+08 | N8: 1.5886551e+08 | O8: 1.6076617e+08 | P8: 1.6259151e+08 | Q8: 1.6364762e+08 | R8: 1.6462911e+08 | S8: 1.6553808e+08 | T8: 1.6637675e+08 | U8: 1.6714747e+08 | V8: 1.6785273e+08 | W8: 1.6849509e+08 | X8: 1.6907732e+08 | Y8: 1.6960229e+08 | Z8: 1.7007301e+08 | AA8: 1.703336e+08 | AB8: 1.7054725e+08 | AC8: 1.7071745e+08 | AD8: 1.7084789e+08 | AE8: 1.7094238e+08 | AF8: 1.710048e+08 | AG8: 1.7103925e+08 | AH8: 1.7104987e+08 | AI8: 1.7104102e+08 | AJ8: 1.7101713e+08 | AK8: 1.710223e+08 | AL8: 1.7102146e+08 | AM8: 1.7101953e+08 | AN8: 1.7102155e+08 | AO8: 1.7103263e+08 | AP8: 1.7105815e+08 | AQ8: 1.7110356e+08 | AR8: 1.7117449e+08 | AS8: 1.7127674e+08 | AT8: 1.7141619e+08
A9: 城镇住宅面积 | B9: 130300 | C9: 河北省 | D9: 秦皇岛市 | E9: 55838384 | F9: 57270412 | G9: 58337123 | H9: 59367291 | I9: 60361183 | J9: 61319161 | K9: 62241643 | L9: 63129103 | M9: 63982091 | N9: 64801208 | O9: 65587109 | P9: 66340521 | Q9: 66778730 | R9: 67185564 | S9: 67562310 | T9: 67910247 | U9: 68230759 | V9: 68525139 | W9: 68794801 | X9: 69041110 | Y9: 69265510 | Z9: 69469411 | AA9: 69589345 | AB9: 69692052 | AC9: 69779061 | AD9: 69851901 | AE9: 69912149 | AF9: 69961381 | AG9: 70001105 | AH9: 70032943 | AI9: 70058468 | AJ9: 70079247 | AK9: 70113075 | AL9: 70145228 | AM9: 70177332 | AN9: 70210957 | AO9: 70247716 | AP9: 70289185 | AQ9: 70336986 | AR9: 70392701 | AS9: 70457927 | AT9: 70534222
A10: 城镇住宅面积 | B10: 130400 | C10: 河北省 | D10: 邯郸市 | E10: 1.6773053e+08 | F10: 1.7187863e+08 | G10: 1.7510903e+08 | H10: 1.7839771e+08 | I10: 1.8173392e+08 | J10: 1.8510698e+08 | K10: 1.8850639e+08 | L10: 1.9192182e+08 | M10: 1.9534317e+08 | N10: 1.9876062e+08 | O10: 2.0216468e+08 | P10: 2.0554618e+08 | Q10: 2.0801333e+08 | R10: 2.1042968e+08 | S10: 2.1278831e+08 | T10: 2.15083e+08 | U10: 2.1730811e+08 | V10: 2.1945873e+08 | W10: 2.2153065e+08 | X10: 2.2352046e+08 | Y10: 2.2542546e+08 | Z10: 2.2724383e+08 | AA10: 2.2876102e+08 | AB10: 2.3018954e+08 | AC10: 2.3153043e+08 | AD10: 2.3278572e+08 | AE10: 2.3395837e+08 | AF10: 2.350524e+08 | AG10: 2.3607275e+08 | AH10: 2.3702556e+08 | AI10: 2.3791801e+08 | AJ10: 2.3875837e+08 | AK10: 2.396114e+08 | AL10: 2.4043246e+08 | AM10: 2.4123342e+08 | AN10: 2.4202741e+08 | AO10: 2.4282885e+08 | AP10: 2.4365352e+08 | AQ10: 2.4451862e+08 | AR10: 2.4544265e+08 | AS10: 2.4644567e+08 | AT10: 2.4754914e+08
A11: 城镇住宅面积 | B11: 130500 | C11: 河北省 | D11: 邢台市 | E11: 1.2640857e+08 | F11: 1.298325e+08 | G11: 1.3249494e+08 | H11: 1.3513618e+08 | I11: 1.3775291e+08 | J11: 1.4034192e+08 | K11: 1.4290011e+08 | L11: 1.4542453e+08 | M11: 1.4791232e+08 | N11: 1.5036086e+08 | O11: 1.5276765e+08 | P11: 1.5513038e+08 | Q11: 1.5678137e+08 | R11: 1.5837773e+08 | S11: 1.5991858e+08 | T11: 1.6140328e+08 | U11: 1.6283143e+08 | V11: 1.6420289e+08 | W11: 1.6551777e+08 | X11: 1.6677644e+08 | Y11: 1.6797955e+08 | Z11: 1.6912809e+08 | AA11: 1.700645e+08 | AB11: 1.7094873e+08 | AC11: 1.7178277e+08 | AD11: 1.7256897e+08 | AE11: 1.7330999e+08 | AF11: 1.7400879e+08 | AG11: 1.7466874e+08 | AH11: 1.7529351e+08 | AI11: 1.7588714e+08 | AJ11: 1.7645404e+08 | AK11: 1.7703989e+08 | AL11: 1.7760897e+08 | AM11: 1.7816687e+08 | AN11: 1.7871959e+08 | AO11: 1.7927354e+08 | AP11: 1.7983557e+08 | AQ11: 1.8041298e+08 | AR11: 1.8101352e+08 | AS11: 1.8164541e+08 | AT11: 1.8231731e+08
