Workbook

Sheet About
A1: BLAPE BAU LULUCF Anthropogenic Pollutant Emissions
A4: source: | B4: 6-2 Land Use by Region (2019)
B5: China Environmental Statistical Yearbook 2021
B7: 2009-2016 National land use area
B8: Panel Data on Land Use Types at the National and Provincial Levels 2009-2016
B10: Types of greenhouse gas emission sources and sinks in 2014
B11: The Second Biennial Update Report of the People's Republic of China on Climate Change
B13: Log growth from 2014 to 2020
B14: China Forestry and Grassland Statistical Yearbook
B16: Territorial Ecological Restoration Plan of Shandong Province (2021-2035)
B17: http://zrzyj.dezhou.gov.cn/n54284823/n54284838/c69106044/part/69106048.pdf
A19: note： | B19: Based on data from the 8th National Forest Resource Inventory (2009-13) and 9th National Forest Resource Inventory (2014-18), Shandong's forest resource remains largely stable.
B20: Forest stock increases from 89,197,900 to 91,614,600 cubic meters and forest land area increases from 2,546,000 to 2,665,100 hectares
B21: In the Shandong Land Ecological Restoration Plan 2021-2035, the targeted forestry stock in 90 million cubic meters for both 2025 and 2035, essentially the same as current.
B22: Therefore, we expect the amount of CO2 adsorbtion remains stable in the BAU scenario.

Sheet 2014 National LULUCF Inventory
A1: 年份：2014 | F1: 2014 National GHG Emission Inventory | K1: 2014 National Landuse Area
A2: 温室气体排放源与吸收汇的种类/（万吨） | B2: CO2 | C2: 每千公顷排放的CO2 /(万吨/千公顷） | F2: 温室气体排放源与吸收汇的种类 | G2: CO2 | H2: CH4 | I2: N2O | K2: Forest Land | L2: Land Area (10^4 Hectare) | M2: Other Land | N2: Land Area (10^4 Hectare)
A3: 林地 | B3: -83973 | C3: =B3/(163.72*10^4) -> -0.051290618 | F3: 总量（包括LULUCF） | G3: 912394 | H3: 5529.2 | I3: 196.7 | K3: 乔木林 | L3: 17015 | M3: 农地面积 | N3: 13506
A4: 农地 | B4: -4946 | C4: =B4/'2009-2016 National Land Use'!C25 -> -0.036621484 | F4: 1. 能源活动 | G4: 892492.9 | H4: 2475.7 | I4: 36.7 | K4: 竹林面积 | L4: 632 | M4: 草地面积 | N4: 28656
A5: 草地 | B5: -10916 | C5: =B5/'2009-2016 National Land Use'!F25 -> -0.038094866 | F5: 燃料燃烧 | G5: 892492.9 | H5: 261.4 | I5: 36.7 | K5: 疏林地面积 | L5: 357 | M5: 湿地面积 | N5: 3973
A6: 湿地 | B6: -4454 | C6: =B6/'2009-2016 National Land Use'!G25 -> -0.11210672 | F6: 能源工业 | G6: 399534.4 | H6: 5 | I6: 22.3 | K6: 灌木林地面积 | L6: 7363 | M6: 建设用地面积 | N6: 3723
A7: 建设用地 | B7: 253 | C7: =B7/'2009-2016 National Land Use'!J25 -> 0.0065028307 | F7: 制造业和建筑业 | G7: 342350.6 | H7: 32.4 | I7: 6.5
A8: 其他用地 | B8: 0 | C8: 0 | F8: 交通运输 | G8: 81974 | H8: 7.9 | I8: 2.1 | K8: 2014 National Forest Stock Volume
F9: 其他行业 | G9: 62317.8 | H9: 77.7 | I9: 0.7 | K9: 163.72 | L9: 10^8 Cubic Meter
F10: 其他 | G10: 6316.1 | H10: 138.4 | I10: 5.1
F11: 逃逸排放 | H11: 2214.2
A12: note:2014森林蓄积量 | F12: 固体燃料 | H12: 2101.5
A13: 163.72 亿立方米 | F13: 油气系统 | H13: 112.7
A14: 163.72*10^4 | B14: 万立方米 | F14: 2. 工业生产过程 | G14: 132986.6 | H14: 0.6 | I14: 31.1
F15: 非金属矿物制品 | G15: 91520.2
F16: 化学工业 | G16: 14196.3 | H16: NA | I16: 31.1
F17: 金属冶炼 | G17: 27270.2 | H17: 0.6 | I17: NA
F18: 卤烃和六氟化硫生产
F19: 卤烃和六氟化硫消费
F20: 3. 农业活动 | H20: 2224.5 | I20: 117
F21: 动物肠道发酵 | H21: 985.6
F22: 动物粪便管理 | H22: 315.5 | I22: 23.3
F23: 水稻种植 | H23: 891.1
F24: 农业土壤 | H24: NA | I24: 93
F25: 限定性热带草原烧荒 | H25: NO | I25: NO
F26: 农业废弃物田间焚烧 | H26: 32.3 | I26: 0.7 | M26: CO2 (10^4 Ton) | N26: Land Area (10^4 Hectare) | O26: Forest Stock Volmue (10^4 Cubic Meter) | Q26: Intensity
F27: 4. 土地利用、土地利用变化和林业 | G27: -115091 | H27: 172 | I27: IE,NE | K27: LULUCF Factor | L27: Total | M27: =G27 -> -115091
F28: 林地 | G28: -83973 | L28: Forestry | M28: =G28 -> -83973 | O28: =K9*10^4 -> 1637200 | Q28: =M28/O28 -> -0.051290618
F29: 农地 | G29: -4946 | H29: IE | I29: IE | L29: Farmland | M29: =G29 -> -4946 | N29: =N3 -> 13506 | Q29: =M29/N29 -> -0.36620761
F30: 草地 | G30: -10916 | H30: IE | I30: IE | L30: Grassland | M30: =G30 -> -10916 | N30: =N4 -> 28656 | Q30: =M30/N30 -> -0.38093244
F31: 湿地 | G31: -4454 | H31: 172 | I31: NE | L31: Wetland | M31: =G31 -> -4454 | N31: =N5 -> 3973 | Q31: =M31/N31 -> -1.1210672
F32: 建设用地 | G32: 253 | L32: Construction Land | M32: =G32 -> 253 | N32: =N6 -> 3723 | Q32: =M32/N32 -> 0.06795595
F33: 其他用地 | G33: 0 | L33: Other Landuse | M33: =G33 -> 0 | N33: =('2009-2016 National Land Use'!K25+'2009-2016 National Land Use'!L25)/10 -> 11988.24 | Q33: =M33/N33 -> 0
F34: 林产品 | G34: -11055 | L34: Forest Product | M34: =G34 -> -11055 | P34: ='2021 Forestry Product'!D4 -> 7553.46 | Q34: =M34/P34 -> -1.4635677
F35: 5. 废弃物处理 | G35: 2005.5 | H35: 656.4 | I35: 12
F36: 固体废弃物处理 | G36: 2005.5 | H36: 384.2 | I36: 0.9
F37: 废水处理 | H37: 272.1 | I37: 11
F38: 信息项
F39: 国际航空 | G39: 2933.6 | H39: 0 | I39: 0.1
F40: 国际航海 | G40: 2191.2 | H40: 0.2 | I40: 0.1
...

Sheet 2009-2016 National Land Use
A1: 单位：万亩 | B1: 土地用地面积
A2: 行政 单位 | B2: 年份 | C2: 耕地 | G2: 园地 | K2: 林地 | O2: 草地 | S2: 城镇村及工矿用地 | X2: 交通运输用地 | AE2: 水域及水利设施用地 | AO2: 其他土地
C3: 小计 | D3: 水田 | E3: 水浇地 | F3: 旱地 | G3: 小计 | H3: 果园 | I3: 茶园 | J3: 其它园地 | K3: 小计 | L3: 有林地 | M3: 灌木林地 | N3: 其他林地 | O3: 小计 | P3: 天然 牧草地 | Q3: 人工 牧草地 | R3: 其他草地 | S3: 小计 | T3: 城市 | U3: 建制镇 | V3: 村庄 | W3: 采矿用地 | X3: 小计 | Y3: 铁路用地 | Z3: 公路用地 | AA3: 农村道路 | AB3: 机场用地 | AC3: 港口码头用地 | AD3: 管道运输用地 | AE3: 小计 | AF3: 河流水面 | AG3: 湖泊水面 | AH3: 水库水面 | AI3: 坑塘水面 | AJ3: 沿海滩涂 | AK3: 内陆滩涂 | AL3: 沟渠 | AM3: 水工建筑 用地 | AN3: 冰川及 永久积雪 | AO3: 小计 | AP3: 设施 农用地 | AQ3: 田坎 | AR3: 盐碱地 | AS3: 沼泽地 | AT3: 沙地
A4: 全国 | B4: 2009 | C4: 203076.8 | D4: 49488.7 | E4: 42125.1 | F4: 111463.1 | G4: 22217.7 | H4: 13813.1 | I4: 2195.0 | J4: 6209.6 | K4: 380924.3 | L4: 281596.1 | M4: 65121.5 | N4: 34206.7 | O4: 430970.1 | P4: 326777.0 | Q4: 2804.0 | R4: 101389.2 | S4: =SUM(T4:W4) -> 41966.5 | T4: 5291.4 | U4: 5584.1 | V4: 27709.2 | W4: 3381.8 | X4: 11912.9 | Y4: 590.6 | Z4: 3499.0 | AA4: 7678.1 | AB4: 83.3 | AC4: 49.6 | AD4: 12.3 | AE4: 64035.5 | AF4: 12025.8 | AG4: 11488.0 | AH4: 4007.3 | AI4: 8478.8 | AJ4: 2610.2 | AK4: 9630.0 | AL4: 6354.2 | AM4: 1148.6 | AN4: 8292.6 | AO4: =SUM(AP4:AT4) -> 116470.1 | AP4: 1024 | AQ4: 12328 | AR4: 18221.7 | AS4: 5581.2 | AT4: 79315.2
A5: 全国 | B5: 2010 | C5: =202902.4 -> 202902.4 | D5: 49375.3 | E5: 42048.1 | F5: 111479.1 | G5: 22054.7 | H5: 13699.1 | I5: 2180.0 | J5: 6175.6 | K5: 380649.2 | L5: 281417.5 | M5: 65086.7 | N5: 34145.1 | O5: 430760.6 | P5: 326706.1 | Q5: 2801.9 | R5: 101252.6 | S5: =SUM(T5:W5) -> 42711.5 | T5: 5506.8 | U5: 5879.1 | V5: 27888.7 | W5: 3436.9 | X5: 12166.2 | Y5: 648.6 | Z5: 3674.8 | AA5: 7693.5 | AB5: 85.7 | AC5: 51.1 | AD5: 12.5 | AE5: 63915.0 | AF5: 12023.7 | AG5: 11486.1 | AH5: 4018.0 | AI5: 8405.3 | AJ5: 2592.3 | AK5: 9591.6 | AL5: 6344.1 | AM5: 1161.3 | AN5: 8292.6 | AO5: =SUM(AP5:AT5) -> 116434.3 | AP5: 1069.8 | AQ5: 12292.6 | AR5: 18188.4 | AS5: 5573.1 | AT5: 79310.4
A6: 全国 | B6: 2011 | C6: 202857.8 | D6: 49269.8 | E6: 42041.6 | F6: 111546.5 | G6: 21905.2 | H6: 13585.1 | I6: 2174.0 | J6: 6146.0 | K6: 380340.0 | L6: 281213.3 | M6: 65047.0 | N6: 34079.7 | O6: 430533.5 | P6: 326625.7 | Q6: 2796.7 | R6: 101111.1 | S6: =SUM(T6:W6) -> 43424.6 | T6: 5712.2 | U6: 6190 | V6: 28053.3 | W6: 3469.1 | X6: 12375.3 | Y6: 677.7 | Z6: 3823.1 | AA6: 7714.1 | AB6: 90.4 | AC6: 56.6 | AD6: 13.4 | AE6: 63830.1 | AF6: 12013.2 | AG6: 11484.6 | AH6: 4044.3 | AI6: 8344.5 | AJ6: 2581.5 | AK6: 9555.4 | AL6: 6333.9 | AM6: 1181.7 | AN6: 8291.1 | AO6: =SUM(AP6:AT6) -> 116382.3 | AP6: 1139 | AQ6: 12241 | AR6: 18151.1 | AS6: 5566.6 | AT6: 79284.6
A7: 全国 | B7: 2012 | C7: 202737.7 | D7: 49165.5 | E7: 42000.6 | F7: 111571.6 | G7: 21800.0 | H7: 13510.8 | I7: 2165.4 | J7: 6123.8 | K7: 380095.3 | L7: 281054.8 | M7: 65010.4 | N7: 34030.1 | O7: 430330.1 | P7: 326567.2 | Q7: 2780.8 | R7: 100982.1 | S7: =SUM(T7:W7) -> 44126.5 | T7: 5905.9 | U7: 6516 | V7: 28212 | W7: 3492.6 | X7: 12539.7 | Y7: 696.7 | Z7: 3952.7 | AA7: 7725.4 | AB7: 93.6 | AC7: 57.9 | AD7: 13.5 | AE7: 63719.5 | AF7: 11999.3 | AG7: 11480.1 | AH7: 4057.3 | AI7: 8288.7 | AJ7: 2568.9 | AK7: 9523.6 | AL7: 6320.5 | AM7: 1190.1 | AN7: 8291.1 | AO7: =SUM(AP7:AT7) -> 116328.9 | AP7: 1182.2 | AQ7: 12200.7 | AR7: 18110.8 | AS7: 5566.5 | AT7: 79268.7
A8: 全国 | B8: 2013 | C8: 202747.0 | D8: 50119.7 | E8: 41989.2 | F8: 110638.1 | G8: 21682.0 | H8: 13422.0 | I8: 2154.8 | J8: 6105.2 | K8: 379880.6 | L8: 280917.8 | M8: 64981.1 | N8: 33981.7 | O8: 430063.7 | P8: 326498.1 | Q8: 2772.5 | R8: 100793.0 | S8: =SUM(T8:W8) -> 44731.7 | T8: 6060.5 | U8: 6809.2 | V8: 28355.6 | W8: 3506.4 | X8: 12732.4 | Y8: 720.7 | Z8: 4122.4 | AA8: 7715.5 | AB8: 99.6 | AC8: 60.5 | AD8: 13.8 | AE8: 63598.6 | AF8: 11987.8 | AG8: 11475.6 | AH8: 4062.4 | AI8: 8230.8 | AJ8: 2558.1 | AK8: 9492.0 | AL8: 6306.7 | AM8: 1194.1 | AN8: 8291.1 | AO8: =SUM(AP8:AT8) -> 116295.1 | AP8: 1257.9 | AQ8: 12162.1 | AR8: 18069 | AS8: 5560.1 | AT8: 79246
A9: 全国 | B9: 2014 | C9: 202586.0 | D9: 49985.1 | E9: 41973.0 | F9: 110627.9 | G9: 21567.3 | H9: 13341.0 | I9: 2146.6 | J9: 6079.7 | K9: 379606.9 | L9: 280741.6 | M9: 64948.6 | N9: 33916.7 | O9: 429821.7 | P9: 326448.9 | Q9: 2750.2 | R9: 100622.6 | S9: =SUM(T9:W9) -> 45395.6 | T9: 6243.6 | U9: 7106.8 | V9: 28522.2 | W9: 3523 | X9: 12963.6 | Y9: 755.1 | Z9: 4312.1 | AA9: 7716.9 | AB9: 103.1 | AC9: 62.3 | AD9: 14.2 | AE9: 63541.4 | AF9: 11967.0 | AG9: 11470.5 | AH9: 4134.1 | AI9: 8176.2 | AJ9: 2544.2 | AK9: 9457.9 | AL9: 6294.9 | AM9: 1205.6 | AN9: 8291.1 | AO9: =SUM(AP9:AT9) -> 116282.2 | AP9: 1350.2 | AQ9: 12114.3 | AR9: 18028.8 | AS9: 5557.7 | AT9: 79231.2
A10: 全国 | B10: 2015 | C10: 202498.0 | D10: 49919.1 | E10: 42007.6 | F10: 110571.3 | G10: 21484.9 | H10: 13282.8 | I10: 2140.8 | J10: 6061.3 | K10: 379488.0 | L10: 280671.4 | M10: 64929.8 | N10: 33886.7 | O10: 429602.9 | P10: 326394.8 | Q10: 2736.1 | R10: 100472.0 | S10: =SUM(T10:W10) -> 45949.1 | T10: 6393.1 | U10: 7348.6 | V10: 28673.7 | W10: 3533.7 | X10: 13097.2 | Y10: 771.8 | Z10: 4427.3 | AA10: 7710.1 | AB10: 106.9 | AC10: 66.7 | AD10: 14.4 | AE10: 63452.1 | AF10: 11959.6 | AG10: 11469.1 | AH10: 4143.5 | AI10: 8128.5 | AJ10: 2539.8 | AK10: 9423.5 | AL10: 6282.4 | AM10: 1214.7 | AN10: 8291.1 | AO10: =SUM(AP10:AT10) -> 116233.1 | AP10: 1389.6 | AQ10: 12072.6 | AR10: 18000.1 | AS10: 5554.6 | AT10: 79216.2
A11: 全国 | B11: 2016 | C11: 202381.4 | D11: 49849.4 | E11: 42297.5 | F11: 110234.6 | G11: 21399.4 | H11: 13221.5 | I11: 2134.5 | J11: 6043.4 | K11: 379362.1 | L11: 280604.7 | M11: 64897.5 | N11: 33859.9 | O11: 429423.0 | P11: 326313.9 | Q11: 2724.9 | R11: 100384.3 | S11: =SUM(T11:W11) -> 46489.1 | T11: 6508.7 | U11: 7638.3 | V11: 28800.5 | W11: 3541.6 | X11: 13273.0 | Y11: 805.3 | Z11: 4567.2 | AA11: 7707.7 | AB11: 110.3 | AC11: 68.1 | AD11: 14.5 | AE11: 63365.6 | AF11: 11946.5 | AG11: 11468.5 | AH11: 4157.1 | AI11: 8085.3 | AJ11: 2528.3 | AK11: 9390.2 | AL11: 6270.5 | AM11: 1228.1 | AN11: 8291.1 | AO11: =SUM(AP11:AT11) -> 116141 | AP11: 1427.8 | AQ11: 12017 | AR11: 17950.8 | AS11: 5552.2 | AT11: 79193.2
A14: unit conversion
A15: 1.5万亩=1千公顷
A18: 单位：千公顷
A19: 行政 单位 | B19: 年份 | C19: 耕地 | D19: 园地 | E19: 林地 | F19: 草地 | G19: 湿地 | H19: 城镇及工矿用地 | I19: 交通运输用地 | J19: 建设用地 | K19: 水域及水利设施用地 | L19: 其他土地
A20: 全国 | B20: 2009 | C20: =C4/1.5 -> 135384.53 | D20: =G4/1.5 -> 14811.8 | E20: =K4/1.5 -> 253949.53 | F20: =O4/1.5 -> 287313.4 | H20: =S4/1.5 -> 27977.667 | I20: =X4/1.5 -> 7941.9333 | K20: =AE4/1.5 -> 42690.333 | L20: =AO4/1.5 -> 77646.733
A21: 全国 | B21: 2010 | C21: =C5/1.5 -> 135268.27 | D21: =G5/1.5 -> 14703.133 | E21: =K5/1.5 -> 253766.13 | F21: =O5/1.5 -> 287173.73 | H21: =S5/1.5 -> 28474.333 | I21: =X5/1.5 -> 8110.8 | K21: =AE5/1.5 -> 42610 | L21: =AO5/1.5 -> 77622.867
A22: 全国 | B22: 2011 | C22: =C6/1.5 -> 135238.53 | D22: =G6/1.5 -> 14603.467 | E22: =K6/1.5 -> 253560 | F22: =O6/1.5 -> 287022.33 | H22: =S6/1.5 -> 28949.733 | I22: =X6/1.5 -> 8250.2 | K22: =AE6/1.5 -> 42553.4 | L22: =AO6/1.5 -> 77588.2
A23: 全国 | B23: 2012 | C23: =C7/1.5 -> 135158.47 | D23: =G7/1.5 -> 14533.333 | E23: =K7/1.5 -> 253396.87 | F23: =O7/1.5 -> 286886.73 | H23: =S7/1.5 -> 29417.667 | I23: =X7/1.5 -> 8359.8 | K23: =AE7/1.5 -> 42479.667 | L23: =AO7/1.5 -> 77552.6
A24: 全国 | B24: 2013 | C24: =C8/1.5 -> 135164.67 | D24: =G8/1.5 -> 14454.667 | E24: =K8/1.5 -> 253253.73 | F24: =O8/1.5 -> 286709.13 | H24: =S8/1.5 -> 29821.133 | I24: =X8/1.5 -> 8488.2667 | K24: =AE8/1.5 -> 42399.067 | L24: =AO8/1.5 -> 77530.067
A25: 全国 | B25: 2014 | C25: =C9/1.5 -> 135057.33 | D25: =G9/1.5 -> 14378.2 | E25: =K9/1.5 -> 253071.27 | F25: =O9/1.5 -> 286547.8 | G25: 39730 | H25: =S9/1.5 -> 30263.733 | I25: =X9/1.5 -> 8642.4 | J25: =SUM(H25:I25) -> 38906.133 | K25: =AE9/1.5 -> 42360.933 | L25: =AO9/1.5 -> 77521.467
A26: 全国 | B26: 2015 | C26: =C10/1.5 -> 134998.67 | D26: =G10/1.5 -> 14323.267 | E26: =K10/1.5 -> 252992 | F26: =O10/1.5 -> 286401.93 | H26: =S10/1.5 -> 30632.733 | I26: =X10/1.5 -> 8731.4667 | K26: =AE10/1.5 -> 42301.4 | L26: =AO10/1.5 -> 77488.733
A27: 全国 | B27: 2016 | C27: =C11/1.5 -> 134920.93 | D27: =G11/1.5 -> 14266.267 | E27: =K11/1.5 -> 252908.07 | F27: =O11/1.5 -> 286282 | H27: =S11/1.5 -> 30992.733 | I27: =X11/1.5 -> 8848.6667 | K27: =AE11/1.5 -> 42243.733 | L27: =AO11/1.5 -> 77427.333
A145: 山东省碳汇 | B145: =(SUM('2019 Regional CO2 LAPE'!C18:G18)+'2021 Forestry Product'!#REF!)*10^10 -> #REF! | C145: g

Sheet 2019 Land Use and Emission
A1: 6-2 各地区土地利用情况(2019年)
A2: Land Use by Region(2019)
A3: 单位:千公顷
A4: (1 000 hectares) | M4: CO2 Absorption
A5: 地 区 | B5: Region | C5: 耕 地 Cultivated Land | D5: 园 地 Garden Land | E5: 林地 Forest Land | F5: 草 地 Grassland | G5: 湿 地 Wetland | H5: 城镇村及工矿用地 Land for Urban, Rural,Industrial and Mining Activities | I5: 交通运输用地 Land Used for Transport | J5: 建设用地 | K5: 水域及水利设施用地 Land Used for Water and Water Conservancy Facilities | M5: 地 区 | N5: Region | O5: Farmland | P5: Grassland | Q5: Wetland | R5: Construction Land | S5: Other Land
A6: 全 国 | B6: National Total | C6: 127861.9 | D6: 20171.6 | E6: 284125.9 | F6: 264530.1 | G6: 23469.3 | H6: 35306.4 | I6: 9553.1 | J6: =SUM(H6:I6) -> 44859.5 | K6: 36287.9 | M6: 全 国 | N6: National Total | O6: =C6/10*'2014 National LULUCF Inventory'!$Q$29 -> -4682.4001 | P6: =F6/10*'2014 National LULUCF Inventory'!$Q$30 -> -10076.81 | Q6: =G6/10*'2014 National LULUCF Inventory'!$Q$31 -> -2631.0663 | R6: =J6/10*'2014 National LULUCF Inventory'!$Q$32 -> 304.84699 | S6: 0
A7: 北 京 | B7: Beijing | C7: 93.5 | D7: 126.3 | E7: 967.6 | F7: 14.5 | G7: 3.1 | H7: 313.6 | I7: 49.3 | J7: =SUM(H7:I7) -> 362.9 | K7: 61.7 | M7: 北 京 | N7: Beijing | O7: =C7/10*'2014 National LULUCF Inventory'!$Q$29 -> -3.4240412 | P7: =F7/10*'2014 National LULUCF Inventory'!$Q$30 -> -0.55235204 | Q7: =G7/10*'2014 National LULUCF Inventory'!$Q$31 -> -0.34753083 | R7: =J7/10*'2014 National LULUCF Inventory'!$Q$32 -> 2.4661214 | S7: 0
A8: 天 津 | B8: Tianjin | C8: 329.6 | D8: 36.9 | E8: 148.3 | F8: 15.0 | G8: 32.7 | H8: 332.2 | I8: 45.3 | J8: =SUM(H8:I8) -> 377.5 | K8: 237.3 | M8: 天 津 | N8: Tianjin | O8: =C8/10*'2014 National LULUCF Inventory'!$Q$29 -> -12.070203 | P8: =F8/10*'2014 National LULUCF Inventory'!$Q$30 -> -0.57139866 | Q8: =G8/10*'2014 National LULUCF Inventory'!$Q$31 -> -3.6658898 | R8: =J8/10*'2014 National LULUCF Inventory'!$Q$32 -> 2.5653371 | S8: 0
A9: 河 北 | B9: Hebei | C9: 6034.2 | D9: 1005.9 | E9: 6425.3 | F9: 1947.3 | G9: 142.7 | H9: 2102.9 | I9: 407.1 | J9: =SUM(H9:I9) -> 2510 | K9: 571.1 | M9: 河 北 | N9: Hebei | O9: =C9/10*'2014 National LULUCF Inventory'!$Q$29 -> -220.977 | P9: =F9/10*'2014 National LULUCF Inventory'!$Q$30 -> -74.178974 | Q9: =G9/10*'2014 National LULUCF Inventory'!$Q$31 -> -15.997629 | R9: =J9/10*'2014 National LULUCF Inventory'!$Q$32 -> 17.056943 | S9: 0
A10: 山 西 | B10: Shanxi | C10: 3869.5 | D10: 640.9 | E10: 6095.7 | F10: 3105.1 | G10: 54.4 | H10: 1017.6 | I10: 269.8 | J10: =SUM(H10:I10) -> 1287.4 | K10: 173.1 | M10: 山 西 | N10: Shanxi | O10: =C10/10*'2014 National LULUCF Inventory'!$Q$29 -> -141.70404 | P10: =F10/10*'2014 National LULUCF Inventory'!$Q$30 -> -118.28333 | Q10: =G10/10*'2014 National LULUCF Inventory'!$Q$31 -> -6.0986056 | R10: =J10/10*'2014 National LULUCF Inventory'!$Q$32 -> 8.7486489 | S10: 0
A11: 内蒙古 | B11: Inner Mongolia | C11: 11496.5 | D11: 47.2 | E11: 24360.0 | F11: 54171.9 | G11: 3809.4 | H11: 1493.3 | I11: 799.4 | J11: =SUM(H11:I11) -> 2292.7 | K11: 1061.8 | M11: 内蒙古 | N11: Inner Mongolia | O11: =C11/10*'2014 National LULUCF Inventory'!$Q$29 -> -421.01058 | P11: =F11/10*'2014 National LULUCF Inventory'!$Q$30 -> -2063.5834 | Q11: =G11/10*'2014 National LULUCF Inventory'!$Q$31 -> -427.05934 | R11: =J11/10*'2014 National LULUCF Inventory'!$Q$32 -> 15.580261 | S11: 0
A12: 辽 宁 | B12: Liaoning | C12: 5182.1 | D12: 527.9 | E12: 6015.7 | F12: 487.2 | G12: 286.4 | H12: 1316.2 | I12: 308.9 | J12: =SUM(H12:I12) -> 1625.1 | K12: 691.6 | M12: 辽 宁 | N12: Liaoning | O12: =C12/10*'2014 National LULUCF Inventory'!$Q$29 -> -189.77245 | P12: =F12/10*'2014 National LULUCF Inventory'!$Q$30 -> -18.559028 | Q12: =G12/10*'2014 National LULUCF Inventory'!$Q$31 -> -32.107365 | R12: =J12/10*'2014 National LULUCF Inventory'!$Q$32 -> 11.043521 | S12: 0
A13: 吉 林 | B13: Jilin | C13: 7498.5 | D13: 76.5 | E13: 8759.0 | F13: 674.7 | G13: 230.3 | H13: 850.9 | I13: 264.6 | J13: =SUM(H13:I13) -> 1115.5 | K13: 598.1 | M13: 吉 林 | N13: Jilin | O13: =C13/10*'2014 National LULUCF Inventory'!$Q$29 -> -274.60078 | P13: =F13/10*'2014 National LULUCF Inventory'!$Q$30 -> -25.701512 | Q13: =G13/10*'2014 National LULUCF Inventory'!$Q$31 -> -25.818178 | R13: =J13/10*'2014 National LULUCF Inventory'!$Q$32 -> 7.5804862 | S13: 0
A14: 黑龙江 | B14: Heilongjiang | C14: 17195.4 | D14: 62.4 | E14: 21623.2 | F14: 1185.7 | G14: 3501.0 | H14: 1164.4 | I14: 544.3 | J14: =SUM(H14:I14) -> 1708.7 | K14: 1686.4 | M14: 黑龙江 | N14: Heilongjiang | O14: =C14/10*'2014 National LULUCF Inventory'!$Q$29 -> -629.70864 | P14: =F14/10*'2014 National LULUCF Inventory'!$Q$30 -> -45.167159 | Q14: =G14/10*'2014 National LULUCF Inventory'!$Q$31 -> -392.48563 | R14: =J14/10*'2014 National LULUCF Inventory'!$Q$32 -> 11.611633 | S14: 0
A15: 上 海 | B15: Shanghai | C15: 162.0 | D15: 15.1 | E15: 81.8 | F15: 13.2 | G15: 72.7 | H15: 289.5 | I15: 34.1 | J15: =SUM(H15:I15) -> 323.6 | K15: 191.3 | M15: 上 海 | N15: Shanghai | O15: =C15/10*'2014 National LULUCF Inventory'!$Q$29 -> -5.9325633 | P15: =F15/10*'2014 National LULUCF Inventory'!$Q$30 -> -0.50283082 | Q15: =G15/10*'2014 National LULUCF Inventory'!$Q$31 -> -8.1501586 | R15: =J15/10*'2014 National LULUCF Inventory'!$Q$32 -> 2.1990545 | S15: 0
A16: 江 苏 | B16: Jiangsu | C16: 4089.7 | D16: 230.3 | E16: 787.0 | F16: 93.6 | G16: 416.4 | H16: 2097.3 | I16: 365.1 | J16: =SUM(H16:I16) -> 2462.4 | K16: 2503.4 | M16: 江 苏 | N16: Jiangsu | O16: =C16/10*'2014 National LULUCF Inventory'!$Q$29 -> -149.76793 | P16: =F16/10*'2014 National LULUCF Inventory'!$Q$30 -> -3.5655276 | Q16: =G16/10*'2014 National LULUCF Inventory'!$Q$31 -> -46.681238 | R16: =J16/10*'2014 National LULUCF Inventory'!$Q$32 -> 16.733473 | S16: 0
A17: 浙 江 | B17: Zhejiang | C17: 1290.5 | D17: 760.3 | E17: 6093.6 | F17: 63.5 | G17: 165.2 | H17: 1146.8 | I17: 246.9 | J17: =SUM(H17:I17) -> 1393.7 | K17: 702.5 | M17: 浙 江 | N17: Zhejiang | O17: =C17/10*'2014 National LULUCF Inventory'!$Q$29 -> -47.259092 | P17: =F17/10*'2014 National LULUCF Inventory'!$Q$30 -> -2.418921 | Q17: =G17/10*'2014 National LULUCF Inventory'!$Q$31 -> -18.52003 | R17: =J17/10*'2014 National LULUCF Inventory'!$Q$32 -> 9.4710207 | S17: 0
... A37: 新 疆 | B37: Xinjiang | C37: 7038.6 | D37: 1070.1 | E37: 12212.5 | F37: 51986.0 | G37: 1524.5 | H37: 1410 | I37: 561.9 | J37: =SUM(H37:I37) -> 1971.9 | K37: 5308.5 | M37: 新 疆 | N37: Xinjiang | O37: =C37/10*'2014 National LULUCF Inventory'!$Q$29 -> -257.75889 | P37: =F37/10*'2014 National LULUCF Inventory'!$Q$30 -> -1980.3154 | Q37: =G37/10*'2014 National LULUCF Inventory'!$Q$31 -> -170.9067 | R37: =J37/10*'2014 National LULUCF Inventory'!$Q$32 -> 13.400234 | S37: 0

Sheet 温室气体排放清单
B1: 2005 | E1: 2010 | H1: 2017 | K1: 2018 | N1: 2020b | Q1: 2021
B2: CO2 | C2: CH4 | D2: N2O | E2: CO2 | F2: CH4 | G2: N2O | H2: CO2 | I2: CH4 | J2: N2O | K2: CO2 | L2: CH4 | M2: N2O | N2: CO2 | O2: CH4 | P2: N2O | Q2: CO2 | R2: CH4 | S2: N2O
A3: 3.农业活动 | C3: 2136.5 | D3: 98.3 | F3: 2241.4 | G3: 115.4 | I3: 2470.8 | J3: 98.2 | L3: 2384.6 | M3: 94.3 | O3: 2372 | P3: 94.6 | R3: 2427.9 | S3: 94.9
A4: 3.A动物肠道发酵 | C4: 1120.4 | F4: 1032.9 | I4: 1112.3 | L4: 1084.1 | O4: 1124.2 | R4: 1151.8
A5: 3.B动物粪便管理 | C5: 240.4 | D5: 27.2 | F5: 304.8 | G5: 23.6 | I5: 354.8 | J5: 22 | L5: 346.1 | M5: 21.7 | O5: 344.7 | P5: 22.2 | R5: 375.3 | S5: 22.7
A6: 3.C水稻种植 | C6: 755 | F6: 872.9 | I6: 962.8 | L6: 932.9 | O6: 884.9 | R6: 885.1
A7: 3.D农用地 | D7: 70.6 | G7: 91.1 | J7: 75.2 | M7: 72 | P7: 71.9 | S7: 71.8
A8: 3.F秸秆田间焚烧 | C8: 20.7 | D8: 0.5 | F8: 30.7 | G8: 0.7 | I8: 41 | J8: 1.1 | L8: 21.6 | M8: 0.6 | O8: 18.2 | P8: 0.5 | R8: 15.7 | S8: 0.4
A9: 4.土地利用、土地利用变 化和林业 | B9: -72866.7 | C9: 63.2 | D9: 0 | E9: -102972 | F9: 174 | G9: 0.1 | H9: -134171.4 | K9: -134047.3 | L9: 398.1 | M9: 0.1 | N9: -134262.9 | O9: 139.8 | P9: 0 | Q9: -134649.9 | R9: 111 | S9: 0
A10: 4.A林地 | B10: -55120.5 | C10: 0.2 | D10: 0 | E10: -77923 | F10: 0.1 | G10: 0 | H10: -92842 | K10: -96579.2 | L10: 0.1 | M10: 0 | N10: -89559.2 | O10: 0 | P10: 0 | Q10: -87682.7 | R10: 0 | S10: 0
A11: 4.B农地 | B11: -4107.7 | E11: -6604 | F11: IE | G11: IE | H11: -9643.3 | K11: -7810 | L11: IE | M11: IE | N11: -9801.8 | Q11: -10616.2
A12: 4.C草地 | B12: -4776.9 | C12: 0.1 | D12: 0 | E12: -4513 | F12: 0.1 | G12: 0.1 | H12: -12101.3 | I12: 0.1 | J12: 0.1 | K12: -10175.2 | L12: 0.1 | M12: 0.1 | N12: -7270.7 | O12: 0 | P12: 0 | Q12: -6408.2 | R12: 0 | S12: 0
A13: 4.D湿地 | B13: -1373 | C13: 62.9 | D13: NE | E13: -4508 | F13: 174 | G13: NE | H13: -8586.3 | I13: 398.3 | K13: -8641.7 | L13: 398 | M13: NE | N13: -2978.8 | O13: 139.8 | P13: NE | Q13: -2459.9 | R13: 111 | S13: NE
A14: 4.E建设用地 | B14: 16.3 | E14: 162 | H14: -102.8 | K14: -91.8 | N14: -239.6 | Q14: -63.4
A15: 4.F其他土地 | B15: 543.6 | E15: 0 | H15: 118.3 | K15: 109.5 | N15: 264.1 | Q15: 155.6
A16: 4.G木质林产品 | B16: -6121.5 | E16: -9586 | H16: -11014 | K16: -10859 | N16: -10386.3 | Q16: -10382
A17: 4.H其他生物质 | B17: -1927.1 | N17: -14290.6 | Q17: -17193.1

Sheet 2019 Forestry Stock
A1: 7-2 各地区森林资源情况
A2: Forest Resources by Region
A3: 地 区 | B3: Region | C3: 林业用地 面 积 (万公顷) Area of Afforested Land (10 000 hectares) | D3: 森林面积 (万公顷) Forest Aera (10 000 hectares) | F3: 森 林 覆盖率 (%) Forest Coverage Rate (%) | G3: 活立木 总蓄积量 (万立方米) Total Stock Volume of Living Trees (10 000 cu.m) | H3: 森 林 蓄积量 (万立方米) Stock Volume of Forest (10 000 cu.m)
E4: #人工林 Planted Forest | J4: 地 区 | K4: Region | L4: CO2 Absorption from Forestry
A5: 全 国 | B5: National Total | C5: 32368.55 | D5: 22044.62 | E5: 8003.1 | F5: 22.96 | G5: 1900713.2 | H5: 1756023 | J5: 全 国 | K5: National Total | L5: =H5*'2014 National LULUCF Inventory'!$Q$28 -> -90067.505
A6: 北 京 | B6: Beijing | C6: 107.1 | D6: 71.82 | E6: 43.48 | F6: 43.77 | G6: 3000.81 | H6: 2437.36 | J6: 北 京 | K6: Beijing | L6: =H6*'2014 National LULUCF Inventory'!$Q$28 -> -125.0137
A7: 天 津 | B7: Tianjin | C7: 20.39 | D7: 13.64 | E7: 12.98 | F7: 12.07 | G7: 620.56 | H7: 460.27 | J7: 天 津 | K7: Tianjin | L7: =H7*'2014 National LULUCF Inventory'!$Q$28 -> -23.607533
A8: 河北 | B8: Hebei | C8: 775.64 | D8: 502.69 | E8: 263.54 | F8: 26.78 | G8: 15920.34 | H8: 13737.98 | J8: 河 北 | K8: Hebei | L8: =H8*'2014 National LULUCF Inventory'!$Q$28 -> -704.62949
A9: 山 西 | B9: Shanxi | C9: 787.25 | D9: 321.09 | E9: 167.63 | F9: 20.5 | G9: 14778.65 | H9: 12923.37 | J9: 山 西 | K9: Shanxi | L9: =H9*'2014 National LULUCF Inventory'!$Q$28 -> -662.84764
A10: 内蒙古 | B10: Inner Mongolia | C10: 4499.17 | D10: 2614.85 | E10: 600.01 | F10: 22.1 | G10: 166271.98 | H10: 152704.12 | J10: 内蒙古 | K10: Inner Mongolia | L10: =H10*'2014 National LULUCF Inventory'!$Q$28 -> -7832.2887
A11: 辽 宁 | B11: Liaoning | C11: 735.92 | D11: 571.83 | E11: 315.32 | F11: 39.24 | G11: 30888.53 | H11: 29749.18 | J11: 辽 宁 | K11: Liaoning | L11: =H11*'2014 National LULUCF Inventory'!$Q$28 -> -1525.8538
A12: 吉 林 | B12: Jilin | C12: 904.79 | D12: 784.87 | E12: 175.94 | F12: 41.49 | G12: 105368.45 | H12: 101295.77 | J12: 吉 林 | K12: Jilin | L12: =H12*'2014 National LULUCF Inventory'!$Q$28 -> -5195.5227
A13: 黑龙江 | B13: Heilongjiang | C13: 2453.77 | D13: 1990.46 | E13: 243.26 | F13: 43.78 | G13: 199999.41 | H13: 184704.09 | J13: 黑龙江 | K13: Heilongjiang | L13: =H13*'2014 National LULUCF Inventory'!$Q$28 -> -9473.5869
A14: 上 海 | B14: Shanghai | C14: 10.19 | D14: 8.9 | E14: 8.9 | F14: 14.04 | G14: 664.32 | H14: 449.59 | J14: 上 海 | K14: Shanghai | L14: =H14*'2014 National LULUCF Inventory'!$Q$28 -> -23.059749
A15: 江 苏 | B15: Jiangsu | C15: 174.98 | D15: 155.99 | E15: 150.83 | F15: 15.2 | G15: 9609.62 | H15: 7044.48 | J15: 江 苏 | K15: Jiangsu | L15: =H15*'2014 National LULUCF Inventory'!$Q$28 -> -361.31573
A16: 浙 江 | B16: Zhejiang | C16: 659.77 | D16: 604.99 | E16: 244.65 | F16: 59.43 | G16: 31384.86 | H16: 28114.67 | J16: 浙 江 | K16: Zhejiang | L16: =H16*'2014 National LULUCF Inventory'!$Q$28 -> -1442.0188
... A36: 新 疆 | B36: Xinjiang | C36: 1371.26 | D36: 802.23 | E36: 121.42 | F36: 4.87 | G36: 46490.95 | H36: 39221.5 | J36: 新 疆 | K36: Xinjiang | L36: =H36*'2014 National LULUCF Inventory'!$Q$28 -> -2011.695

Sheet 2021 Forestry Product
A1: 2014 National Forestry Product | G1: 2021 Provincial Forestry Product
A2: 主要指标 | B2: 单位 | C2: 2015 年 | D2: 2014 年 | E2: 2015年比_x000D_ 2014年增减(%) | G2: Region | H2: Woood Product (cubic mieter) | K2: Bamboo Product (unit) | P2: 地 区 | Q2: Region | R2: CO2 Absorption from Forestry Product
A3: 木材产量 | B3: 万立方米 | C3: 7218.21 | D3: 8233.3 | E3: -12.33 | H3: 合计 | I3: 原木 | J3: 薪柴 | K3: Total | L3: 毛竹 | M3: 其他 | N3: 小杂竹（万吨）
A4: 1.原木 | B4: 万立方米 | C4: 6546.35 | D4: 7553.46 | E4: -13.33 | G4: 全国合计 | H4: 11589 | I4: 10331 | J4: 1259 | K4: 325568 | L4: 192710 | M4: 132858 | N4: 3101 | P4: 全 国 | Q4: National Total | R4: =IFERROR(I4*'2014 National LULUCF Inventory'!$Q$34,"") -> -15120.118
A5: 2.薪材 | B5: 万立方米 | C5: 671.86 | D5: 679.84 | E5: -1.17 | G5: 北京 | H5: 17 | I5: 16 | J5: 1 | K5: — | L5: — | M5: — | N5: — | P5: 北 京 | Q5: Beijing | R5: =IFERROR(I5*'2014 National LULUCF Inventory'!$Q$34,"") -> -23.417083
A6: 竹材产量 | B6: 万根 | C6: 235466.04 | D6: 222439.93 | E6: 5.86 | G6: 天津 | H6: 19 | I6: 19 | J6: 一 | K6: 一 | L6: 一 | M6: 一 | N6: 一 | P6: 天 津 | Q6: Tianjin | R6: =IFERROR(I6*'2014 National LULUCF Inventory'!$Q$34,"") -> -27.807786
A7: 锯材产量 | B7: 万立方米 | C7: 7430.38 | D7: 6836.98 | E7: 8.68 | G7: 河北 | H7: 111 | I7: 97 | J7: 13 | K7: — | L7: — | M7: — | N7: — | P7: 河 北 | Q7: Hebei | R7: =IFERROR(I7*'2014 National LULUCF Inventory'!$Q$34,"") -> -141.96607
A8: 人造板产量 | B8: 万立方米 | C8: 28679.52 | D8: 27371.79 | E8: 4.78 | G8: 山西 | H8: 39 | I8: 25 | J8: 14 | K8: — | L8: — | M8: — | N8: — | P8: 山 西 | Q8: Shanxi | R8: =IFERROR(I8*'2014 National LULUCF Inventory'!$Q$34,"") -> -36.589192
A9: 1.胶合板 | B9: 万立方米 | C9: 16546.25 | D9: 14970.03 | E9: 10.53 | G9: 内蒙古 | H9: 109 | I9: 108 | J9: 1 | K9: — | L9: — | M9: — | N9: — | P9: 内蒙古 | Q9: Inner Mongolia | R9: =IFERROR(I9*'2014 National LULUCF Inventory'!$Q$34,"") -> -158.06531
A10: 2.纤维板 | B10: 万立方米 | C10: 6618.53 | D10: 6462.63 | E10: 2.41 | G10: 内蒙古集团 | H10: 2 | I10: 2 | J10: — | K10: — | L10: — | M10: — | N10: — | R10: =IFERROR(I10*'2014 National LULUCF Inventory'!$Q$34,"") -> -2.9271354
A11: 3.刨花板 | B11: 万立方米 | C11: 2030.19 | D11: 2087.53 | E11: -2.75 | G11: 辽宁 | H11: 133 | I11: 113 | J11: 20 | K11: 一 | L11: 一 | M11: 一 | N11: 一 | P11: 辽 宁 | Q11: Liaoning | R11: =IFERROR(I11*'2014 National LULUCF Inventory'!$Q$34,"") -> -165.38315
A12: 4.其他人造板 | B12: 万立方米 | C12: 3484.56 | D12: 3851.59 | E12: -9.53 | G12: 吉林 | H12: 245 | I12: 242 | J12: 3 | K12: — | L12: — | M12: — | N12: — | P12: 吉 林 | Q12: Jilin | R12: =IFERROR(I12*'2014 National LULUCF Inventory'!$Q$34,"") -> -354.18338
A13: 木竹地板产量 | B13: 万平方米 | C13: 77355.85 | D13: 76022.4 | E13: 1.75 | G13: 吉林集团 | H13: 13 | I13: 12 | J13: 1 | K13: — | L13: — | M13: — | N13: — | R13: =IFERROR(I13*'2014 National LULUCF Inventory'!$Q$34,"") -> -17.562812
A14: 松香类产品产量 | B14: 吨 | C14: 1742521 | D14: 1700727 | E14: 2.46 | G14: 长白山集团 | H14: 6 | I14: 6 | J14: 一 | K14: 一 | L14: 一 | M14: 一 | N14: 一 | R14: =IFERROR(I14*'2014 National LULUCF Inventory'!$Q$34,"") -> -8.7814061
A15: 栲胶类产品产量 | B15: 吨 | C15: 7584 | D15: 5013 | E15: 51.29 | G15: 黑龙江 | H15: 174 | I15: 153 | J15: 21 | K15: — | L15: — | M15: — | N15: — | P15: 黑龙江 | Q15: Heilongjiang | R15: =IFERROR(I15*'2014 National LULUCF Inventory'!$Q$34,"") -> -223.92586
A16: 紫胶类产品产量 | B16: 吨 | C16: 3344 | D16: 4645 | E16: -28.01 | G16: 龙江集团 | H16: 5 | I16: 5 | J16: 一 | K16: 一 | L16: 一 | M16: 一 | N16: 一 | R16: =IFERROR(I16*'2014 National LULUCF Inventory'!$Q$34,"") -> -7.3178384
G17: 伊春集团 | H17: 2 | I17: 2 | J17: — | K17: — | L17: — | M17: — | N17: — | R17: =IFERROR(I17*'2014 National LULUCF Inventory'!$Q$34,"") -> -2.9271354
G18: 上海 | H18: — | I18: — | J18: — | K18: — | L18: — | M18: — | N18: 1 | P18: 上 海 | Q18: Shanghai | R18: =IFERROR(I18*'2014 National LULUCF Inventory'!$Q$34,"")
G19: 江苏 | H19: 233 | I19: 210 | J19: 23 | K19: 448 | L19: 445 | M19: 3 | N19: 一 | P19: 江 苏 | Q19: Jiangsu | R19: =IFERROR(I19*'2014 National LULUCF Inventory'!$Q$34,"") -> -307.34921
G20: 浙江 | H20: 100 | I20: 98 | J20: 1 | K20: 21649 | L20: 21205 | M20: 444 | N20: 48 | P20: 浙 江 | Q20: Zhejiang | R20: =IFERROR(I20*'2014 National LULUCF Inventory'!$Q$34,"") -> -143.42963
G21: 安徽 | H21: 612 | I21: 475 | J21: 136 | K21: 19797 | L21: 17099 | M21: 2698 | N21: 259 | P21: 安 徽 | Q21: Anhui | R21: =IFERROR(I21*'2014 National LULUCF Inventory'!$Q$34,"") -> -695.19465
G22: 福建 | H22: 805 | I22: 737 | J22: 68 | K22: 96260 | L22: 63334 | M22: 32926 | N22: 140 | P22: 福 建 | Q22: Fujian | R22: =IFERROR(I22*'2014 National LULUCF Inventory'!$Q$34,"") -> -1078.6494
G23: 江西 | H23: 408 | I23: 386 | J23: 22 | K23: 22083 | L23: 20580 | M23: 1503 | N23: 122 | P23: 江 西 | Q23: Jiangxi | R23: =IFERROR(I23*'2014 National LULUCF Inventory'!$Q$34,"") -> -564.93713
G24: 山东 | H24: 399 | I24: 344 | J24: 55 | K24: 一 | L24: 一 | M24: 一 | N24: 一 | P24: 山 东 | Q24: Shandong | R24: =IFERROR(I24*'2014 National LULUCF Inventory'!$Q$34,"") -> -503.46729
G25: 河南 | H25: 273 | I25: 225 | J25: 48 | K25: 105 | L25: 103 | M25: 2 | N25: 5 | P25: 河 南 | Q25: Henan | R25: =IFERROR(I25*'2014 National LULUCF Inventory'!$Q$34,"") -> -329.30273
G26: 湖北 | H26: 249 | I26: 198 | J26: 51 | K26: 4021 | L26: 3034 | M26: 987 | N26: 12 | P26: 湖 北 | Q26: Hubei | R26: =IFERROR(I26*'2014 National LULUCF Inventory'!$Q$34,"") -> -289.7864
G27: 湖南 | H27: 483 | I27: 427 | J27: 57 | K27: 25829 | L27: 22902 | M27: 2927 | N27: 114 | P27: 湖 南 | Q27: Hunan | R27: =IFERROR(I27*'2014 National LULUCF Inventory'!$Q$34,"") -> -624.9434
G28: 广东 | H28: 1264 | I28: 1123 | J28: 141 | K28: 30907 | L28: 8021 | M28: 22886 | N28: 623 | P28: 广 东 | Q28: Guangdong | R28: =IFERROR(I28*'2014 National LULUCF Inventory'!$Q$34,"") -> -1643.5865
G29: 广西 | H29: 3905 | I29: 3602 | J29: 303 | K29: 60367 | L29: 20138 | M29: 40229 | N29: 50 | P29: 广 西 | Q29: Guangxi | R29: =IFERROR(I29*'2014 National LULUCF Inventory'!$Q$34,"") -> -5271.7708
G30: 海南 | H30: 223 | I30: 219 | J30: 4 | K30: 318 | L30: 198 | M30: 120 | N30: — | P30: 海 南 | Q30: Hainan | R30: =IFERROR(I30*'2014 National LULUCF Inventory'!$Q$34,"") -> -320.52132
G31: 重庆 | H31: 46 | I31: 36 | J31: 10 | K31: 4300 | L31: 2155 | M31: 2145 | N31: 118 | P31: 重 庆 | Q31: Chongqing | R31: =IFERROR(I31*'2014 National LULUCF Inventory'!$Q$34,"") -> -52.688437
G32: 四川 | H32: 303 | I32: 288 | J32: 15 | K32: 23008 | L32: 4056 | M32: 18953 | N32: 618 | P32: 四 川 | Q32: Sichuan | R32: =IFERROR(I32*'2014 National LULUCF Inventory'!$Q$34,"") -> -421.50749
G33: 贵州 | H33: 419 | I33: 394 | J33: 24 | K33: 2159 | L33: 1631 | M33: 528 | N33: 91 | P33: 贵 州 | Q33: Guizhou | R33: =IFERROR(I33*'2014 National LULUCF Inventory'!$Q$34,"") -> -576.64567
G34: 云南 | H34: 903 | I34: 705 | J34: 199 | K34: 13256 | L34: 7113 | M34: 6143 | N34: 898 | P34: 云南 | Q34: Yunnan | R34: =IFERROR(I34*'2014 National LULUCF Inventory'!$Q$34,"") -> -1031.8152
G35: 西藏 | H35: 3 | I35: 1 | J35: 3 | K35: — | L35: — | M35: — | N35: — | P35: 西 藏 | Q35: Tibet | R35: =IFERROR(I35*'2014 National LULUCF Inventory'!$Q$34,"") -> -1.4635677
G36: 陕西 | H36: 30 | I36: 12 | J36: 18 | K36: 1060 | L36: 695 | M36: 365 | N36: 一 | P36: 陕 西 | Q36: Shaanxi | R36: =IFERROR(I36*'2014 National LULUCF Inventory'!$Q$34,"") -> -17.562812
G37: 甘肃 | H37: 6 | I37: 4 | J37: 2 | K37: — | L37: — | M37: — | N37: — | P37: 甘 肃 | Q37: Gansu | R37: =IFERROR(I37*'2014 National LULUCF Inventory'!$Q$34,"") -> -5.8542708
G38: 青海 | H38: — | I38: — | J38: — | K38: — | L38: — | M38: — | N38: — | P38: 青 海 | Q38: Qinghai | R38: =IFERROR(I38*'2014 National LULUCF Inventory'!$Q$34,"")
G39: 宁夏 | H39: — | I39: — | J39: — | K39: — | L39: — | M39: — | N39: — | P39: 宁 夏 | Q39: Ningxia | R39: =IFERROR(I39*'2014 National LULUCF Inventory'!$Q$34,"")
G40: 新疆 | H40: 77 | I40: 73 | J40: 4 | K40: — | L40: — | M40: — | N40: — | P40: 新 疆 | Q40: Xinjiang | R40: =IFERROR(I40*'2014 National LULUCF Inventory'!$Q$34,"") -> -106.84044
...

Sheet 2019 Regional CO2 LAPE
A1: 2019各个地区土地的二氧化碳碳排放量（万吨）
A2: 地 区 | B2: Region | C2: Forestry | D2: Farmland | E2: Grassland | F2: Wetland | G2: Construction Land | H2: Other Landuse | I2: Forest Product | J2: Total
A3: 全 国 | B3: National Total | C3: =VLOOKUP($B3,'2019 Forestry Stock'!$K$5:$L$36,2,FALSE) -> -90067.505 | D3: =VLOOKUP($B3,'2019 Land Use and Emission'!$N$6:$S$37,2,FALSE) -> -4682.4001 | E3: =VLOOKUP($B3,'2019 Land Use and Emission'!$N$6:$S$37,3,FALSE) -> -10076.81 | F3: =VLOOKUP($B3,'2019 Land Use and Emission'!$N$6:$S$37,4,FALSE) -> -2631.0663 | G3: =VLOOKUP($B3,'2019 Land Use and Emission'!$N$6:$S$37,5,FALSE) -> 304.84699 | H3: =VLOOKUP($B3,'2019 Land Use and Emission'!$N$6:$S$37,6,FALSE) -> 0 | I3: =VLOOKUP($B3,'2021 Forestry Product'!$Q$4:$R$40,2,FALSE) -> -15120.118 | J3: =SUM(C3:I3) -> -122273.05
A4: 北 京 | B4: Beijing | C4: =VLOOKUP($B4,'2019 Forestry Stock'!$K$5:$L$36,2,FALSE) -> -125.0137 | D4: =VLOOKUP($B4,'2019 Land Use and Emission'!$N$6:$S$37,2,FALSE) -> -3.4240412 | E4: =VLOOKUP($B4,'2019 Land Use and Emission'!$N$6:$S$37,3,FALSE) -> -0.55235204 | F4: =VLOOKUP($B4,'2019 Land Use and Emission'!$N$6:$S$37,4,FALSE) -> -0.34753083 | G4: =VLOOKUP($B4,'2019 Land Use and Emission'!$N$6:$S$37,5,FALSE) -> 2.4661214 | H4: =VLOOKUP($B4,'2019 Land Use and Emission'!$N$6:$S$37,6,FALSE) -> 0 | I4: =VLOOKUP($B4,'2021 Forestry Product'!$Q$4:$R$40,2,FALSE) -> -23.417083 | J4: =SUM(C4:I4) -> -150.28859
A5: 天 津 | B5: Tianjin | C5: =VLOOKUP($B5,'2019 Forestry Stock'!$K$5:$L$36,2,FALSE) -> -23.607533 | D5: =VLOOKUP($B5,'2019 Land Use and Emission'!$N$6:$S$37,2,FALSE) -> -12.070203 | E5: =VLOOKUP($B5,'2019 Land Use and Emission'!$N$6:$S$37,3,FALSE) -> -0.57139866 | F5: =VLOOKUP($B5,'2019 Land Use and Emission'!$N$6:$S$37,4,FALSE) -> -3.6658898 | G5: =VLOOKUP($B5,'2019 Land Use and Emission'!$N$6:$S$37,5,FALSE) -> 2.5653371 | H5: =VLOOKUP($B5,'2019 Land Use and Emission'!$N$6:$S$37,6,FALSE) -> 0 | I5: =VLOOKUP($B5,'2021 Forestry Product'!$Q$4:$R$40,2,FALSE) -> -27.807786 | J5: =SUM(C5:I5) -> -65.157473
A6: 河 北 | B6: Hebei | C6: =VLOOKUP($B6,'2019 Forestry Stock'!$K$5:$L$36,2,FALSE) -> -704.62949 | D6: =VLOOKUP($B6,'2019 Land Use and Emission'!$N$6:$S$37,2,FALSE) -> -220.977 | E6: =VLOOKUP($B6,'2019 Land Use and Emission'!$N$6:$S$37,3,FALSE) -> -74.178974 | F6: =VLOOKUP($B6,'2019 Land Use and Emission'!$N$6:$S$37,4,FALSE) -> -15.997629 | G6: =VLOOKUP($B6,'2019 Land Use and Emission'!$N$6:$S$37,5,FALSE) -> 17.056943 | H6: =VLOOKUP($B6,'2019 Land Use and Emission'!$N$6:$S$37,6,FALSE) -> 0 | I6: =VLOOKUP($B6,'2021 Forestry Product'!$Q$4:$R$40,2,FALSE) -> -141.96607 | J6: =SUM(C6:I6) -> -1140.6922
A7: 山 西 | B7: Shanxi | C7: =VLOOKUP($B7,'2019 Forestry Stock'!$K$5:$L$36,2,FALSE) -> -662.84764 | D7: =VLOOKUP($B7,'2019 Land Use and Emission'!$N$6:$S$37,2,FALSE) -> -141.70404 | E7: =VLOOKUP($B7,'2019 Land Use and Emission'!$N$6:$S$37,3,FALSE) -> -118.28333 | F7: =VLOOKUP($B7,'2019 Land Use and Emission'!$N$6:$S$37,4,FALSE) -> -6.0986056 | G7: =VLOOKUP($B7,'2019 Land Use and Emission'!$N$6:$S$37,5,FALSE) -> 8.7486489 | H7: =VLOOKUP($B7,'2019 Land Use and Emission'!$N$6:$S$37,6,FALSE) -> 0 | I7: =VLOOKUP($B7,'2021 Forestry Product'!$Q$4:$R$40,2,FALSE) -> -36.589192 | J7: =SUM(C7:I7) -> -956.77415
A8: 内蒙古 | B8: Inner Mongolia | C8: =VLOOKUP($B8,'2019 Forestry Stock'!$K$5:$L$36,2,FALSE) -> -7832.2887 | D8: =VLOOKUP($B8,'2019 Land Use and Emission'!$N$6:$S$37,2,FALSE) -> -421.01058 | E8: =VLOOKUP($B8,'2019 Land Use and Emission'!$N$6:$S$37,3,FALSE) -> -2063.5834 | F8: =VLOOKUP($B8,'2019 Land Use and Emission'!$N$6:$S$37,4,FALSE) -> -427.05934 | G8: =VLOOKUP($B8,'2019 Land Use and Emission'!$N$6:$S$37,5,FALSE) -> 15.580261 | H8: =VLOOKUP($B8,'2019 Land Use and Emission'!$N$6:$S$37,6,FALSE) -> 0 | I8: =VLOOKUP($B8,'2021 Forestry Product'!$Q$4:$R$40,2,FALSE) -> -158.06531 | J8: =SUM(C8:I8) -> -10886.427
A9: 辽 宁 | B9: Liaoning | C9: =VLOOKUP($B9,'2019 Forestry Stock'!$K$5:$L$36,2,FALSE) -> -1525.8538 | D9: =VLOOKUP($B9,'2019 Land Use and Emission'!$N$6:$S$37,2,FALSE) -> -189.77245 | E9: =VLOOKUP($B9,'2019 Land Use and Emission'!$N$6:$S$37,3,FALSE) -> -18.559028 | F9: =VLOOKUP($B9,'2019 Land Use and Emission'!$N$6:$S$37,4,FALSE) -> -32.107365 | G9: =VLOOKUP($B9,'2019 Land Use and Emission'!$N$6:$S$37,5,FALSE) -> 11.043521 | H9: =VLOOKUP($B9,'2019 Land Use and Emission'!$N$6:$S$37,6,FALSE) -> 0 | I9: =VLOOKUP($B9,'2021 Forestry Product'!$Q$4:$R$40,2,FALSE) -> -165.38315 | J9: =SUM(C9:I9) -> -1920.6323
A10: 吉 林 | B10: Jilin | C10: =VLOOKUP($B10,'2019 Forestry Stock'!$K$5:$L$36,2,FALSE) -> -5195.5227 | D10: =VLOOKUP($B10,'2019 Land Use and Emission'!$N$6:$S$37,2,FALSE) -> -274.60078 | E10: =VLOOKUP($B10,'2019 Land Use and Emission'!$N$6:$S$37,3,FALSE) -> -25.701512 | F10: =VLOOKUP($B10,'2019 Land Use and Emission'!$N$6:$S$37,4,FALSE) -> -25.818178 | G10: =VLOOKUP($B10,'2019 Land Use and Emission'!$N$6:$S$37,5,FALSE) -> 7.5804862 | H10: =VLOOKUP($B10,'2019 Land Use and Emission'!$N$6:$S$37,6,FALSE) -> 0 | I10: =VLOOKUP($B10,'2021 Forestry Product'!$Q$4:$R$40,2,FALSE) -> -354.18338 | J10: =SUM(C10:I10) -> -5868.246
A11: 黑龙江 | B11: Heilongjiang | C11: =VLOOKUP($B11,'2019 Forestry Stock'!$K$5:$L$36,2,FALSE) -> -9473.5869 | D11: =VLOOKUP($B11,'2019 Land Use and Emission'!$N$6:$S$37,2,FALSE) -> -629.70864 | E11: =VLOOKUP($B11,'2019 Land Use and Emission'!$N$6:$S$37,3,FALSE) -> -45.167159 | F11: =VLOOKUP($B11,'2019 Land Use and Emission'!$N$6:$S$37,4,FALSE) -> -392.48563 | G11: =VLOOKUP($B11,'2019 Land Use and Emission'!$N$6:$S$37,5,FALSE) -> 11.611633 | H11: =VLOOKUP($B11,'2019 Land Use and Emission'!$N$6:$S$37,6,FALSE) -> 0 | I11: =VLOOKUP($B11,'2021 Forestry Product'!$Q$4:$R$40,2,FALSE) -> -223.92586 | J11: =SUM(C11:I11) -> -10753.263
A12: 上 海 | B12: Shanghai | C12: =VLOOKUP($B12,'2019 Forestry Stock'!$K$5:$L$36,2,FALSE) -> -23.059749 | D12: =VLOOKUP($B12,'2019 Land Use and Emission'!$N$6:$S$37,2,FALSE) -> -5.9325633 | E12: =VLOOKUP($B12,'2019 Land Use and Emission'!$N$6:$S$37,3,FALSE) -> -0.50283082 | F12: =VLOOKUP($B12,'2019 Land Use and Emission'!$N$6:$S$37,4,FALSE) -> -8.1501586 | G12: =VLOOKUP($B12,'2019 Land Use and Emission'!$N$6:$S$37,5,FALSE) -> 2.1990545 | H12: =VLOOKUP($B12,'2019 Land Use and Emission'!$N$6:$S$37,6,FALSE) -> 0 | I12: =VLOOKUP($B12,'2021 Forestry Product'!$Q$4:$R$40,2,FALSE) | J12: =SUM(C12:I12) -> -35.446247
A13: 江 苏 | B13: Jiangsu | C13: =VLOOKUP($B13,'2019 Forestry Stock'!$K$5:$L$36,2,FALSE) -> -361.31573 | D13: =VLOOKUP($B13,'2019 Land Use and Emission'!$N$6:$S$37,2,FALSE) -> -149.76793 | E13: =VLOOKUP($B13,'2019 Land Use and Emission'!$N$6:$S$37,3,FALSE) -> -3.5655276 | F13: =VLOOKUP($B13,'2019 Land Use and Emission'!$N$6:$S$37,4,FALSE) -> -46.681238 | G13: =VLOOKUP($B13,'2019 Land Use and Emission'!$N$6:$S$37,5,FALSE) -> 16.733473 | H13: =VLOOKUP($B13,'2019 Land Use and Emission'!$N$6:$S$37,6,FALSE) -> 0 | I13: =VLOOKUP($B13,'2021 Forestry Product'!$Q$4:$R$40,2,FALSE) -> -307.34921 | J13: =SUM(C13:I13) -> -851.94617
A14: 浙 江 | B14: Zhejiang | C14: =VLOOKUP($B14,'2019 Forestry Stock'!$K$5:$L$36,2,FALSE) -> -1442.0188 | D14: =VLOOKUP($B14,'2019 Land Use and Emission'!$N$6:$S$37,2,FALSE) -> -47.259092 | E14: =VLOOKUP($B14,'2019 Land Use and Emission'!$N$6:$S$37,3,FALSE) -> -2.418921 | F14: =VLOOKUP($B14,'2019 Land Use and Emission'!$N$6:$S$37,4,FALSE) -> -18.52003 | G14: =VLOOKUP($B14,'2019 Land Use and Emission'!$N$6:$S$37,5,FALSE) -> 9.4710207 | H14: =VLOOKUP($B14,'2019 Land Use and Emission'!$N$6:$S$37,6,FALSE) -> 0 | I14: =VLOOKUP($B14,'2021 Forestry Product'!$Q$4:$R$40,2,FALSE) -> -143.42963 | J14: =SUM(C14:I14) -> -1644.1755
... A34: 新 疆 | B34: Xinjiang | C34: =VLOOKUP($B34,'2019 Forestry Stock'!$K$5:$L$36,2,FALSE) -> -2011.695 | D34: =VLOOKUP($B34,'2019 Land Use and Emission'!$N$6:$S$37,2,FALSE) -> -257.75889 | E34: =VLOOKUP($B34,'2019 Land Use and Emission'!$N$6:$S$37,3,FALSE) -> -1980.3154 | F34: =VLOOKUP($B34,'2019 Land Use and Emission'!$N$6:$S$37,4,FALSE) -> -170.9067 | G34: =VLOOKUP($B34,'2019 Land Use and Emission'!$N$6:$S$37,5,FALSE) -> 13.400234 | H34: =VLOOKUP($B34,'2019 Land Use and Emission'!$N$6:$S$37,6,FALSE) -> 0 | I34: =VLOOKUP($B34,'2021 Forestry Product'!$Q$4:$R$40,2,FALSE) -> -106.84044 | J34: =SUM(C34:I34) -> -4514.1162

Sheet data from RPEPUACE
B1: Rebound Emis Factor
A2: CO2 | B2: 0
A3: VOC | B3: 0
A4: CO | B4: 0
A5: NOx | B5: 0
A6: PM10 | B6: 0
A7: PM25 | B7: 0
A8: SOx | B8: 0
A9: BC | B9: 0
A10: OC | B10: 0
A11: CH4 | B11: 0.00066417419
A12: N2O | B12: 3.8529345e-05
A13: F gases | B13: 0

Sheet Policy Action
A1: Time (Year) | B1: 2020 | C1: 2021 | D1: 2022 | E1: 2023 | F1: 2024 | G1: 2025 | H1: 2026 | I1: 2027 | J1: 2028 | K1: 2029 | L1: 2030 | M1: 2031 | N1: 2032 | O1: 2033 | P1: 2034 | Q1: 2035 | R1: 2036 | S1: 2037 | T1: 2038 | U1: 2039 | V1: 2040 | W1: 2041 | X1: 2042 | Y1: 2043 | Z1: 2044 | AA1: 2045 | AB1: 2046 | AC1: 2047 | AD1: 2048 | AE1: 2049 | AF1: 2050 | AG1: 2051 | AH1: 2052 | AI1: 2053 | AJ1: 2054 | AK1: 2055 | AL1: 2056 | AM1: 2057 | AN1: 2058 | AO1: 2059 | AP1: 2060
A2: Change in LULUCF Emissions[CO2] : MostRecentRun | B2: -7077360000000 | C2: -7514470000000 | D2: -9145610000000 | E2: -11647600000000 | F2: -13778800000000 | G2: -15434100000000 | H2: -17089300000000 | I2: -18744500000000 | J2: -20399700000000 | K2: -22055000000000 | L2: -23710200000000 | M2: -25365400000000 | N2: -27020600000000 | O2: -28675900000000 | P2: -30331100000000 | Q2: -31986300000000 | R2: -33641500000000 | S2: -35296700000000 | T2: -36952000000000 | U2: -38607200000000 | V2: -40262400000000 | W2: -41917600000000 | X2: -43572900000000 | Y2: -45228100000000 | Z2: -46883300000000 | AA2: -48538500000000 | AB2: -50193800000000 | AC2: -51849000000000 | AD2: -53504200000000 | AE2: -55159400000000 | AF2: -56814600000000 | AG2: -58469900000000 | AH2: -60125100000000 | AI2: -61780300000000 | AJ2: -63435500000000 | AK2: -65090800000000 | AL2: -66746000000000 | AM2: -68401200000000 | AN2: -70056400000000 | AO2: -71711700000000 | AP2: -73366900000000
A3: Change in LULUCF Emissions[VOC] : MostRecentRun | B3: 0 | C3: 0 | D3: 0 | E3: 0 | F3: 0 | G3: 0 | H3: 0 | I3: 0 | J3: 0 | K3: 0 | L3: 0 | M3: 0 | N3: 0 | O3: 0 | P3: 0 | Q3: 0 | R3: 0 | S3: 0 | T3: 0 | U3: 0 | V3: 0 | W3: 0 | X3: 0 | Y3: 0 | Z3: 0 | AA3: 0 | AB3: 0 | AC3: 0 | AD3: 0 | AE3: 0 | AF3: 0 | AG3: 0 | AH3: 0 | AI3: 0 | AJ3: 0 | AK3: 0 | AL3: 0 | AM3: 0 | AN3: 0 | AO3: 0 | AP3: 0
A4: Change in LULUCF Emissions[CO] : MostRecentRun | B4: 0 | C4: 0 | D4: 0 | E4: 0 | F4: 0 | G4: 0 | H4: 0 | I4: 0 | J4: 0 | K4: 0 | L4: 0 | M4: 0 | N4: 0 | O4: 0 | P4: 0 | Q4: 0 | R4: 0 | S4: 0 | T4: 0 | U4: 0 | V4: 0 | W4: 0 | X4: 0 | Y4: 0 | Z4: 0 | AA4: 0 | AB4: 0 | AC4: 0 | AD4: 0 | AE4: 0 | AF4: 0 | AG4: 0 | AH4: 0 | AI4: 0 | AJ4: 0 | AK4: 0 | AL4: 0 | AM4: 0 | AN4: 0 | AO4: 0 | AP4: 0
A5: Change in LULUCF Emissions[NOx] : MostRecentRun | B5: 0 | C5: 0 | D5: 0 | E5: 0 | F5: 0 | G5: 0 | H5: 0 | I5: 0 | J5: 0 | K5: 0 | L5: 0 | M5: 0 | N5: 0 | O5: 0 | P5: 0 | Q5: 0 | R5: 0 | S5: 0 | T5: 0 | U5: 0 | V5: 0 | W5: 0 | X5: 0 | Y5: 0 | Z5: 0 | AA5: 0 | AB5: 0 | AC5: 0 | AD5: 0 | AE5: 0 | AF5: 0 | AG5: 0 | AH5: 0 | AI5: 0 | AJ5: 0 | AK5: 0 | AL5: 0 | AM5: 0 | AN5: 0 | AO5: 0 | AP5: 0
A6: Change in LULUCF Emissions[PM10] : MostRecentRun | B6: 0 | C6: 0 | D6: 0 | E6: 0 | F6: 0 | G6: 0 | H6: 0 | I6: 0 | J6: 0 | K6: 0 | L6: 0 | M6: 0 | N6: 0 | O6: 0 | P6: 0 | Q6: 0 | R6: 0 | S6: 0 | T6: 0 | U6: 0 | V6: 0 | W6: 0 | X6: 0 | Y6: 0 | Z6: 0 | AA6: 0 | AB6: 0 | AC6: 0 | AD6: 0 | AE6: 0 | AF6: 0 | AG6: 0 | AH6: 0 | AI6: 0 | AJ6: 0 | AK6: 0 | AL6: 0 | AM6: 0 | AN6: 0 | AO6: 0 | AP6: 0
A7: Change in LULUCF Emissions[PM25] : MostRecentRun | B7: 0 | C7: 0 | D7: 0 | E7: 0 | F7: 0 | G7: 0 | H7: 0 | I7: 0 | J7: 0 | K7: 0 | L7: 0 | M7: 0 | N7: 0 | O7: 0 | P7: 0 | Q7: 0 | R7: 0 | S7: 0 | T7: 0 | U7: 0 | V7: 0 | W7: 0 | X7: 0 | Y7: 0 | Z7: 0 | AA7: 0 | AB7: 0 | AC7: 0 | AD7: 0 | AE7: 0 | AF7: 0 | AG7: 0 | AH7: 0 | AI7: 0 | AJ7: 0 | AK7: 0 | AL7: 0 | AM7: 0 | AN7: 0 | AO7: 0 | AP7: 0
A8: Change in LULUCF Emissions[SOx] : MostRecentRun | B8: 0 | C8: 0 | D8: 0 | E8: 0 | F8: 0 | G8: 0 | H8: 0 | I8: 0 | J8: 0 | K8: 0 | L8: 0 | M8: 0 | N8: 0 | O8: 0 | P8: 0 | Q8: 0 | R8: 0 | S8: 0 | T8: 0 | U8: 0 | V8: 0 | W8: 0 | X8: 0 | Y8: 0 | Z8: 0 | AA8: 0 | AB8: 0 | AC8: 0 | AD8: 0 | AE8: 0 | AF8: 0 | AG8: 0 | AH8: 0 | AI8: 0 | AJ8: 0 | AK8: 0 | AL8: 0 | AM8: 0 | AN8: 0 | AO8: 0 | AP8: 0
A9: Change in LULUCF Emissions[BC] : MostRecentRun | B9: 0 | C9: 0 | D9: 0 | E9: 0 | F9: 0 | G9: 0 | H9: 0 | I9: 0 | J9: 0 | K9: 0 | L9: 0 | M9: 0 | N9: 0 | O9: 0 | P9: 0 | Q9: 0 | R9: 0 | S9: 0 | T9: 0 | U9: 0 | V9: 0 | W9: 0 | X9: 0 | Y9: 0 | Z9: 0 | AA9: 0 | AB9: 0 | AC9: 0 | AD9: 0 | AE9: 0 | AF9: 0 | AG9: 0 | AH9: 0 | AI9: 0 | AJ9: 0 | AK9: 0 | AL9: 0 | AM9: 0 | AN9: 0 | AO9: 0 | AP9: 0
A10: Change in LULUCF Emissions[OC] : MostRecentRun | B10: 0 | C10: 0 | D10: 0 | E10: 0 | F10: 0 | G10: 0 | H10: 0 | I10: 0 | J10: 0 | K10: 0 | L10: 0 | M10: 0 | N10: 0 | O10: 0 | P10: 0 | Q10: 0 | R10: 0 | S10: 0 | T10: 0 | U10: 0 | V10: 0 | W10: 0 | X10: 0 | Y10: 0 | Z10: 0 | AA10: 0 | AB10: 0 | AC10: 0 | AD10: 0 | AE10: 0 | AF10: 0 | AG10: 0 | AH10: 0 | AI10: 0 | AJ10: 0 | AK10: 0 | AL10: 0 | AM10: 0 | AN10: 0 | AO10: 0 | AP10: 0
A11: Change in LULUCF Emissions[CH4] : MostRecentRun | B11: 4699360000 | C11: 4989600000 | D11: 6072690000 | E11: 7734000000 | F11: 9149150000 | G11: 10248200000 | H11: 11347300000 | I11: 12446400000 | J11: 13545400000 | K11: 14644500000 | L11: 15743600000 | M11: 16842600000 | N11: 17941700000 | O11: 19040800000 | P11: 20139800000 | Q11: 21238900000 | R11: 22338000000 | S11: 23437000000 | T11: 24536100000 | U11: 25635200000 | V11: 26734200000 | W11: 27833300000 | X11: 28932400000 | Y11: 30031400000 | Z11: 31130500000 | AA11: 32229600000 | AB11: 33328700000 | AC11: 34427700000 | AD11: 35526800000 | AE11: 36625900000 | AF11: 37724900000 | AG11: 38824000000 | AH11: 39923100000 | AI11: 41022100000 | AJ11: 42121200000 | AK11: 43220300000 | AL11: 44319300000 | AM11: 45418400000 | AN11: 46517500000 | AO11: 47616500000 | AP11: 48715600000
A12: Change in LULUCF Emissions[N2O] : MostRecentRun | B12: 272478000 | C12: 289307000 | D12: 352106000 | E12: 448432000 | F12: 530485000 | G12: 594212000 | H12: 657938000 | I12: 721664000 | J12: 785390000 | K12: 849116000 | L12: 912842000 | M12: 976568000 | N12: 1040290000 | O12: 1104020000 | P12: 1167750000 | Q12: 1231470000 | R12: 1295200000 | S12: 1358920000 | T12: 1422650000 | U12: 1486380000 | V12: 1550100000 | W12: 1613830000 | X12: 1677560000 | Y12: 1741280000 | Z12: 1805010000 | AA12: 1868730000 | AB12: 1932460000 | AC12: 1996190000 | AD12: 2059910000 | AE12: 2123640000 | AF12: 2187360000 | AG12: 2251090000 | AH12: 2314820000 | AI12: 2378540000 | AJ12: 2442270000 | AK12: 2505990000 | AL12: 2569720000 | AM12: 2633450000 | AN12: 2697170000 | AO12: 2760900000 | AP12: 2824620000
A13: Change in LULUCF Emissions[F gases] : MostRecentRun | B13: 0 | C13: 0 | D13: 0 | E13: 0 | F13: 0 | G13: 0 | H13: 0 | I13: 0 | J13: 0 | K13: 0 | L13: 0 | M13: 0 | N13: 0 | O13: 0 | P13: 0 | Q13: 0 | R13: 0 | S13: 0 | T13: 0 | U13: 0 | V13: 0 | W13: 0 | X13: 0 | Y13: 0 | Z13: 0 | AA13: 0 | AB13: 0 | AC13: 0 | AD13: 0 | AE13: 0 | AF13: 0 | AG13: 0 | AH13: 0 | AI13: 0 | AJ13: 0 | AK13: 0 | AL13: 0 | AM13: 0 | AN13: 0 | AO13: 0 | AP13: 0
A17: Year | B17: 2020 | C17: 2021
A18: CO2 (g) | B18: =温室气体排放清单!N9*10^10 -> -1.342629e+15 | C18: =温室气体排放清单!Q9*10^10 -> -1.346499e+15
A19: VOCs (g) | B19: 0 | C19: 0
A20: CO (g) | B20: 0 | C20: 0
A21: NOx (g) | B21: 0 | C21: 0
A22: PM10 (g) | B22: 0 | C22: 0
A23: PM25 (g) | B23: 0 | C23: 0
A24: SOx (g) | B24: 0 | C24: 0
A25: BC (g) | B25: 0 | C25: 0
A26: OC (g) | B26: 0 | C26: 0
A27: CH4 (g) | B27: =温室气体排放清单!O9*10^10 -> 1398000000000 | C27: =温室气体排放清单!R9*10^10 -> 1110000000000
A28: N2O (g) | B28: 0 | C28: 0
A29: F gases (g CO2e) | B29: 0 | C29: 0

Sheet BLAPE
A1: Year | B1: 2020 | C1: 2021 | D1: 2022 | E1: 2023 | F1: 2024 | G1: 2025 | H1: 2026 | I1: 2027 | J1: 2028 | K1: 2029 | L1: 2030 | M1: 2031 | N1: 2032 | O1: 2033 | P1: 2034 | Q1: 2035 | R1: 2036 | S1: 2037 | T1: 2038 | U1: 2039 | V1: 2040 | W1: 2041 | X1: 2042 | Y1: 2043 | Z1: 2044 | AA1: 2045 | AB1: 2046 | AC1: 2047 | AD1: 2048 | AE1: 2049 | AF1: 2050 | AG1: 2051 | AH1: 2052 | AI1: 2053 | AJ1: 2054 | AK1: 2055 | AL1: 2056 | AM1: 2057 | AN1: 2058 | AO1: 2059 | AP1: 2060
A2: CO2 (g) | B2: ='Policy Action'!B18-'Policy Action'!B2 -> -1.3355516e+15 | C2: ='Policy Action'!C18-'Policy Action'!C2 -> -1.3389845e+15 | D2: =C2 -> -1.3389845e+15 | E2: =D2 -> -1.3389845e+15 | F2: =E2 -> -1.3389845e+15 | G2: =F2 -> -1.3389845e+15 | H2: =G2 -> -1.3389845e+15 | I2: =H2 -> -1.3389845e+15 | J2: =I2 -> -1.3389845e+15 | K2: =J2 -> -1.3389845e+15 | ... AP2: =AO2 -> -1.3389845e+15
A3: VOCs (g) | B3: 0 | C3: 0 | D3: 0 | E3: 0 | F3: 0 | G3: 0 | H3: 0 | I3: 0 | J3: 0 | K3: 0 | L3: 0 | M3: 0 | N3: 0 | O3: 0 | P3: 0 | Q3: 0 | R3: 0 | S3: 0 | T3: 0 | U3: 0 | V3: 0 | W3: 0 | X3: 0 | Y3: 0 | Z3: 0 | AA3: 0 | AB3: 0 | AC3: 0 | AD3: 0 | AE3: 0 | AF3: 0 | AG3: 0 | AH3: 0 | AI3: 0 | AJ3: 0 | AK3: 0 | AL3: 0 | AM3: 0 | AN3: 0 | AO3: 0 | AP3: 0
A4: CO (g) | B4: 0 | C4: 0 | D4: 0 | E4: 0 | F4: 0 | G4: 0 | H4: 0 | I4: 0 | J4: 0 | K4: 0 | L4: 0 | M4: 0 | N4: 0 | O4: 0 | P4: 0 | Q4: 0 | R4: 0 | S4: 0 | T4: 0 | U4: 0 | V4: 0 | W4: 0 | X4: 0 | Y4: 0 | Z4: 0 | AA4: 0 | AB4: 0 | AC4: 0 | AD4: 0 | AE4: 0 | AF4: 0 | AG4: 0 | AH4: 0 | AI4: 0 | AJ4: 0 | AK4: 0 | AL4: 0 | AM4: 0 | AN4: 0 | AO4: 0 | AP4: 0
A5: NOx (g) | B5: 0 | C5: 0 | D5: 0 | E5: 0 | F5: 0 | G5: 0 | H5: 0 | I5: 0 | J5: 0 | K5: 0 | L5: 0 | M5: 0 | N5: 0 | O5: 0 | P5: 0 | Q5: 0 | R5: 0 | S5: 0 | T5: 0 | U5: 0 | V5: 0 | W5: 0 | X5: 0 | Y5: 0 | Z5: 0 | AA5: 0 | AB5: 0 | AC5: 0 | AD5: 0 | AE5: 0 | AF5: 0 | AG5: 0 | AH5: 0 | AI5: 0 | AJ5: 0 | AK5: 0 | AL5: 0 | AM5: 0 | AN5: 0 | AO5: 0 | AP5: 0
A6: PM10 (g) | B6: 0 | C6: 0 | D6: 0 | E6: 0 | F6: 0 | G6: 0 | H6: 0 | I6: 0 | J6: 0 | K6: 0 | L6: 0 | M6: 0 | N6: 0 | O6: 0 | P6: 0 | Q6: 0 | R6: 0 | S6: 0 | T6: 0 | U6: 0 | V6: 0 | W6: 0 | X6: 0 | Y6: 0 | Z6: 0 | AA6: 0 | AB6: 0 | AC6: 0 | AD6: 0 | AE6: 0 | AF6: 0 | AG6: 0 | AH6: 0 | AI6: 0 | AJ6: 0 | AK6: 0 | AL6: 0 | AM6: 0 | AN6: 0 | AO6: 0 | AP6: 0
A7: PM25 (g) | B7: 0 | C7: 0 | D7: 0 | E7: 0 | F7: 0 | G7: 0 | H7: 0 | I7: 0 | J7: 0 | K7: 0 | L7: 0 | M7: 0 | N7: 0 | O7: 0 | P7: 0 | Q7: 0 | R7: 0 | S7: 0 | T7: 0 | U7: 0 | V7: 0 | W7: 0 | X7: 0 | Y7: 0 | Z7: 0 | AA7: 0 | AB7: 0 | AC7: 0 | AD7: 0 | AE7: 0 | AF7: 0 | AG7: 0 | AH7: 0 | AI7: 0 | AJ7: 0 | AK7: 0 | AL7: 0 | AM7: 0 | AN7: 0 | AO7: 0 | AP7: 0
A8: SOx (g) | B8: 0 | C8: 0 | D8: 0 | E8: 0 | F8: 0 | G8: 0 | H8: 0 | I8: 0 | J8: 0 | K8: 0 | L8: 0 | M8: 0 | N8: 0 | O8: 0 | P8: 0 | Q8: 0 | R8: 0 | S8: 0 | T8: 0 | U8: 0 | V8: 0 | W8: 0 | X8: 0 | Y8: 0 | Z8: 0 | AA8: 0 | AB8: 0 | AC8: 0 | AD8: 0 | AE8: 0 | AF8: 0 | AG8: 0 | AH8: 0 | AI8: 0 | AJ8: 0 | AK8: 0 | AL8: 0 | AM8: 0 | AN8: 0 | AO8: 0 | AP8: 0
A9: BC (g) | B9: 0 | C9: 0 | D9: 0 | E9: 0 | F9: 0 | G9: 0 | H9: 0 | I9: 0 | J9: 0 | K9: 0 | L9: 0 | M9: 0 | N9: 0 | O9: 0 | P9: 0 | Q9: 0 | R9: 0 | S9: 0 | T9: 0 | U9: 0 | V9: 0 | W9: 0 | X9: 0 | Y9: 0 | Z9: 0 | AA9: 0 | AB9: 0 | AC9: 0 | AD9: 0 | AE9: 0 | AF9: 0 | AG9: 0 | AH9: 0 | AI9: 0 | AJ9: 0 | AK9: 0 | AL9: 0 | AM9: 0 | AN9: 0 | AO9: 0 | AP9: 0
A10: OC (g) | B10: 0 | C10: 0 | D10: 0 | E10: 0 | F10: 0 | G10: 0 | H10: 0 | I10: 0 | J10: 0 | K10: 0 | L10: 0 | M10: 0 | N10: 0 | O10: 0 | P10: 0 | Q10: 0 | R10: 0 | S10: 0 | T10: 0 | U10: 0 | V10: 0 | W10: 0 | X10: 0 | Y10: 0 | Z10: 0 | AA10: 0 | AB10: 0 | AC10: 0 | AD10: 0 | AE10: 0 | AF10: 0 | AG10: 0 | AH10: 0 | AI10: 0 | AJ10: 0 | AK10: 0 | AL10: 0 | AM10: 0 | AN10: 0 | AO10: 0 | AP10: 0
A11: CH4 (g) | B11: ='Policy Action'!B27-'Policy Action'!B2 -> 8475360000000 | C11: ='Policy Action'!C27-'Policy Action'!C2 -> 8624470000000 | D11: =C11 -> 8624470000000 | E11: =D11 -> 8624470000000 | F11: =E11 -> 8624470000000 | G11: =F11 -> 8624470000000 | H11: =G11 -> 8624470000000 | I11: =H11 -> 8624470000000 | J11: =I11 -> 8624470000000 | K11: =J11 -> 8624470000000 | ... AP11: =AO11 -> 8624470000000
A12: N2O (g) | B12: 0 | C12: =-'data from RPEPUACE'!B12*(C2-$B2)+B12 -> 1.32267e+08 | D12: =-'data from RPEPUACE'!C12*(D2-$B2)+C12 -> 1.32267e+08 | E12: =-'data from RPEPUACE'!D12*(E2-$B2)+D12 -> 1.32267e+08 | F12: =-'data from RPEPUACE'!E12*(F2-$B2)+E12 -> 1.32267e+08 | G12: =-'data from RPEPUACE'!F12*(G2-$B2)+F12 -> 1.32267e+08 | H12: =-'data from RPEPUACE'!G12*(H2-$B2)+G12 -> 1.32267e+08 | I12: =-'data from RPEPUACE'!H12*(I2-$B2)+H12 -> 1.32267e+08 | J12: =-'data from RPEPUACE'!I12*(J2-$B2)+I12 -> 1.32267e+08 | ... AP12: =-'data from RPEPUACE'!AO12*(AP2-$B2)+AO12 -> 1.32267e+08
A13: F gases (g CO2e) | B13: 0 | C13: 0 | D13: 0 | E13: 0 | F13: 0 | G13: 0 | H13: 0 | I13: 0 | J13: 0 | K13: 0 | L13: 0 | M13: 0 | N13: 0 | O13: 0 | P13: 0 | Q13: 0 | R13: 0 | S13: 0 | T13: 0 | U13: 0 | V13: 0 | W13: 0 | X13: 0 | Y13: 0 | Z13: 0 | AA13: 0 | AB13: 0 | AC13: 0 | AD13: 0 | AE13: 0 | AF13: 0 | AG13: 0 | AH13: 0 | AI13: 0 | AJ13: 0 | AK13: 0 | AL13: 0 | AM13: 0 | AN13: 0 | AO13: 0 | AP13: 0
