Workbook
Name Eno_TM: '[1]1997 Table 1a Modified'!#REF!
Name Eno_Tons: '[1]1997 Table 1a Modified'!#REF!
Name Sum_T2: '[1]1997 Table 1a Modified'!#REF!
Name Sum_TTM: '[1]1997 Table 1a Modified'!#REF!
Name ti_tbl_50: #REF!
Name ti_tbl_69: #REF!

Sheet About
A1: AVLo Average Vehicle Loading
A3: Sources: | B3: passenger LDVs
B4: Article，http://citeseerx.ist.psu.edu/viewdoc/download?doi=10.1.1.396.4005&rep=rep1&type=pdf
B5: Passenger HDVs, freight HDVs， freight ships, passenger motorbikes
B6: Ministry of Public Security http://auto.people.com.cn/n1/2018/0116/c1005-29766686.html
B7: Aircraft
B8: Annual Development Report of Civil Aviation http://www.mot.gov.cn/tongjishuju/minhang/201806/P020180621341239857728.pdf
B9: https://zhidao.baidu.com/question/1500326377840793819.html | C9: 50-60 tons for feight
B10: Rail
B11: Annual Development Report of Rail of 2021: https://www.mot.gov.cn/tongjishuju/tielu/202205/P020220507531780768964.pdf
B12: https://baijiahao.baidu.com/s?id=1687940575408252000&wfr=spider&for=pc
B13: More details on the "rail" tab
B14: HDVs LDVs freight
B15: 能源基金会
B16: 2019
B17: Preliminary investigation and research on freight industry
A18: Notes: | B18: Data for total/average vehicle/vessel travel distace is not available.
B20: No data available for motobikes. Assume an average loading level of 1.15 for passenger motobikes.
B22: Because we notice that the result of passenger HDV is somewhat strange, we use
B23: the U.S figure as the final value.
B25: For aircraft, the date calculated with China data is bit different from US data.
B26: Considering the rationality, we adust the results based on the US data.
B28: Rail here means a whole train with 6-12 cars.

Sheet AVL
A1: Passenger aircraft and freight aircraft | B1: 2017
A2: Aircraft revenue-miles | B2: 65230
A3: Passenger-miles (millions) | B3: =951304/G3 -> 591129.06 | D3: 1 | E3: mile | F3: = | G3: 1.6093 | H3: km
A4: Revenue passenger-miles (millions) | B4: =5.51*B3 -> 3257121.1 | D4: 61174 | E4: 万人
A5: Ton-miles of freight (millions) | B5: =108308/G3 -> 67301.311 | D5: 1108.8万架次
A6: Revenue passenger-miles (millions) | B6: =4.57*B5 -> 307566.99 | D6: =D4/1108.8 -> 55.171356
A7: total aircraft stock | B7: 3296 | C7: Assumes passenger and freight aircraft fly similar numbers of miles per year
A8: Passenger aircraft stock | B8: 3153
A9: cargo aircraft stock | B9: 143
A10: share of aircraft-miles devoted to freight | B10: =B9/B7 -> 0.043385922
A11: Distance-weighted avg. passengers / aircraft | B11: =B4/(B2*(1-B10)) -> 52.197507
A12: Distance-weighted avg. freight tons / aircraft | B12: =B6/(B2*B10) -> 108.67847
A14: Passenger HDVs (buses)
A15: Vehicle-miles, all buses (millions) | B15: =2.32*67.03/G3 -> 96.631828 | C15: Number of Vehicle * Total Mileage
A16: Passenger-miles, all buses (millions) | B16: =14568/G3 -> 9052.383
A17: Distance-weighted avg. passengers/bus | B17: =B16/B15 -> 93.679104 | C17: Commertial passenger road transport
A19: Freight HDVs | B19: 2017
A20: Vehicle-miles, all trucks (millions) | B20: =13.7*181.1/G3 -> 1541.7076 | C20: Number of Vehicle * Total Mileage
A21: Tons-miles, all trucks (millions) | B21: =36869/G3 -> 22909.961
A22: Distance-weighted avg. tons/trucks | B22: =B21/B20 -> 14.860121 | C22: Commertial freight road transport
A24: Passenger LDVs
A25: Passenger LDV use intensity - per vehicle per year | B25: 30
A26: Passenger-miles (millions) | B26: =14568/2/G3 -> 4526.1915
A27: Vehicle stock (millions) | B27: 182.43
A28: Distance-weighted avg. tons/trucks | B28: =B26/(B27*B25) -> 0.82701886 | C28: Private passenger road transport
A30: Freight Ships | B30: 2021
A31: ton-miles (millions), cross ocean | B31: =5508386/G3 -> 3422846
A32: ton-miles (millions), coastwise | B32: =2857871/G3 -> 1775847.3
A33: ton-miles (millions), riverwise/internal | B33: =1494868/G3 -> 928893.31
A34: Total freight tons | B34: 8239730000 | C34: https://xxgk.mot.gov.cn/2020/jigou/zhghs/202201/t20220119_3637300.html | D34: S
A35: number of vessels | B35: 120000 | C35: SYVbT
A36: average tons, cross ocean | B36: 34736 | C36: =0.1402/12.5893 -> 0.011136441
A37: average tons,coastwise | B37: 8158 | C37: =1.0891/12.5893 -> 0.086509973
A38: average tons, riverwise/internal | B38: 1291 | C38: =11.36/12.5893 -> 0.90235359
A39: Avg. freight tons/vessel, riverwise/inland | B39: =B36*C36+B37*C37+B38*C38 -> 2257.5223 | C39: Total Inland navigation mileage:127100km=78978miles
A41: Passenger Ships | B41: 2021
A42: Total passengers | B42: 163370000 | C42: https://xxgk.mot.gov.cn/2020/jigou/zhghs/202201/t20220119_3637301.html
A43: Number of passenger ships | B43: 5900 | C43: total ships:125900 freght ships:120000
A44: annual distance | B44: 20.31
C45: Based on marked loading, assume a 75% of inland shipping in total amount of passenger transported by ship.
...

Sheet aircraft
B1: year：2021
B2: 班次/万次 | C2: 吞吐量/万吨 | D2: 平均载客人数/货吨数
A3: passenger | B3: 378.59 | C3: 90748.3 | D3: =C3/B3 -> 239.70073
A4: freight | B4: =B5-B3 -> 60.41 | C4: 1782.8 | D4: =C4/B4 -> 29.51167
A5: total | B5: 439
B8: https://baijiahao.baidu.com/s?id=1728890865770969590&wfr=spider&for=pc
A9: https://baijiahao.baidu.com/s?id=1721726067943270147&wfr=spider&for=pc
A10: https://baijiahao.baidu.com/s?id=1733239715752982315&wfr=spider&for=pc
B13: year：2019
B14: 班次/万次 | C14: 吞吐量/万人、万吨
A15: passenger | C15: 135162 | D15: 根据《从统计看民航（2020）》来看，上述计算结果可信度较高，因为货运和客运是一起的，客运200人-300人/架左右，货运20吨-30吨/架左右
A16: freight | C16: 1710

Sheet Rail
A1: Passenger Rail | B1: 2021
A2: Average haul distance (mile) | B2: =366.34/D10 -> 227.63935 | C2: source:https://www.mot.gov.cn/tongjishuju/tielu/202205/P020220507531780768964.pdf
A3: Passenger-mile (millions) | B3: =956781/D10 -> 594532.41 | C3: source:https://www.mot.gov.cn/tongjishuju/tielu/202205/P020220507531780768964.pdf
A4: Avg. passenger (per train) | B4: =B3*10^6/(10000*365*B2) -> 715.54234 | C4: During 2021 new year vacation, China's railways run 9,100 passenger trains every day (https://baijiahao.baidu.com/s?id=1687940575408252000&wfr=spider&for=pc)
C5: daily average amount is about 10000, https://www.sohu.com/a/537363985_161795
A6: Freight Rail | B6: 2021
A7: Avg. freight tons (per train) | B7: 4000 | C7: (https://baike.baidu.com/item/%E9%93%81%E8%B7%AF%E8%B4%A7%E8%BD%A6)
A10: 1 | B10: mile | C10: = | D10: 1.6093 | E10: km

Sheet converter
A3: 1 | B3: mile | C3: = | D3: 1.6093 | E3: km
B5: 2017 | C5: 2018 | D5: 2019 | E5: 2020 | F5: 2021 | G5: 2022 | H5: 2023 | I5: 2024 | J5: 2025 | K5: 2026 | L5: 2027 | M5: 2028 | N5: 2029 | O5: 2030 | P5: 2031 | Q5: 2032 | R5: 2033 | S5: 2034 | T5: 2035 | U5: 2036 | V5: 2037 | W5: 2038 | X5: 2039 | Y5: 2040 | Z5: 2041 | AA5: 2042 | AB5: 2043 | AC5: 2044 | AD5: 2045 | AE5: 2046 | AF5: 2047 | AG5: 2048 | AH5: 2049 | AI5: 2050
A6: BAU Cargo Distance Traveled relative to Start Year
A7: HDVs | B7: 1 | C7: 1 | D7: 0.83701136 | E7: 0.88590427 | F7: 0.93765318 | G7: 0.99242494 | H7: 1.0503961 | I7: 1.1117536 | J7: 1.1766952 | K7: 1.2336633 | L7: 1.2933895 | M7: 1.3560072 | N7: 1.4216565 | O7: 1.4904841 | P7: 1.5328343 | Q7: 1.5763877 | R7: 1.6211787 | S7: 1.6672423 | T7: 1.7146147 | U7: 1.7633332 | V7: 1.813436 | W7: 1.8649624 | X7: 1.9179528 | Y7: 1.9724489 | Z7: 2.0284934 | AA7: 2.0861303 | AB7: 2.1454049 | AC7: 2.2063637 | AD7: 2.2690546 | AE7: 2.3335268 | AF7: 2.3998308 | AG7: 2.4680188 | AH7: 2.5381443 | AI7: 2.6102623

Sheet motorbike
C1: average loading
B2: freight | C2: 0.15 | D2: https://www.mybv.cn/mtxw/590050.html
B3: passenger | C3: 1.27 | D3: consistent with Shandong

Sheet AVLo-passengers
B1: 2017 | C1: 2018 | D1: 2019 | E1: 2020 | F1: 2021 | G1: 2022 | H1: 2023 | I1: 2024 | J1: 2025 | K1: 2026 | L1: 2027 | M1: 2028 | N1: 2029 | O1: 2030 | P1: 2031 | Q1: 2032 | R1: 2033 | S1: 2034 | T1: 2035 | U1: 2036 | V1: 2037 | W1: 2038 | X1: 2039 | Y1: 2040 | Z1: 2041 | AA1: 2042 | AB1: 2043 | AC1: 2044 | AD1: 2045 | AE1: 2046 | AF1: 2047 | AG1: 2048 | AH1: 2049 | AI1: 2050 | AJ1: 2051 | AK1: 2052 | AL1: 2053 | AM1: 2054 | AN1: 2055 | AO1: 2056 | AP1: 2057 | AQ1: 2058 | AR1: 2059 | AS1: 2060
A2: LDVs | B2: 1.67 | C2: =B2 -> 1.67 | D2: =C2 -> 1.67 | E2: =D2 -> 1.67 | F2: =E2 -> 1.67 | G2: =F2 -> 1.67 | H2: =G2 -> 1.67 | I2: =H2 -> 1.67 | J2: =I2 -> 1.67 | ... AS2: =AR2 -> 1.67
A3: HDVs | B3: 21.196137 | C3: =B3 -> 21.196137 | D3: =C3 -> 21.196137 | E3: =D3 -> 21.196137 | F3: =E3 -> 21.196137 | G3: =F3 -> 21.196137 | H3: =G3 -> 21.196137 | I3: =H3 -> 21.196137 | J3: =I3 -> 21.196137 | ... AS3: =AR3 -> 21.196137
A4: aircraft | B4: =aircraft!D3 -> 239.70073 | C4: =$B$4 -> 239.70073 | D4: =$B$4 -> 239.70073 | E4: =$B$4 -> 239.70073 | F4: =$B$4 -> 239.70073 | G4: =$B$4 -> 239.70073 | H4: =$B$4 -> 239.70073 | I4: =$B$4 -> 239.70073 | J4: =$B$4 -> 239.70073 | ... AS4: =$B$4 -> 239.70073
A5: rail | B5: =Rail!B4 -> 715.54234 | C5: =B5 -> 715.54234 | D5: =C5 -> 715.54234 | E5: =D5 -> 715.54234 | F5: =E5 -> 715.54234 | G5: =F5 -> 715.54234 | H5: =G5 -> 715.54234 | I5: =H5 -> 715.54234 | J5: =I5 -> 715.54234 | ... AS5: =AR5 -> 715.54234
A6: ships | B6: =AVL!B53 -> 17.533087 | C6: =B6 -> 17.533087 | D6: =C6 -> 17.533087 | E6: =D6 -> 17.533087 | F6: =E6 -> 17.533087 | G6: =F6 -> 17.533087 | H6: =G6 -> 17.533087 | I6: =H6 -> 17.533087 | J6: =I6 -> 17.533087 | ... AS6: =AR6 -> 17.533087
A7: motorbikes | B7: =motorbike!C3 -> 1.27 | C7: =$B$7 -> 1.27 | D7: =$B$7 -> 1.27 | E7: =$B$7 -> 1.27 | F7: =$B$7 -> 1.27 | G7: =$B$7 -> 1.27 | H7: =$B$7 -> 1.27 | I7: =$B$7 -> 1.27 | J7: =$B$7 -> 1.27 | ... AS7: =$B$7 -> 1.27

Sheet AVLo-freight
B1: 2016 | C1: 2017 | D1: 2018 | E1: 2019 | F1: 2020 | G1: 2021 | H1: 2022 | I1: 2023 | J1: 2024 | K1: 2025 | L1: 2026 | M1: 2027 | N1: 2028 | O1: 2029 | P1: 2030 | Q1: 2031 | R1: 2032 | S1: 2033 | T1: 2034 | U1: 2035 | V1: 2036 | W1: 2037 | X1: 2038 | Y1: 2039 | Z1: 2040 | AA1: 2041 | AB1: 2042 | AC1: 2043 | AD1: 2044 | AE1: 2045 | AF1: 2046 | AG1: 2047 | AH1: 2048 | AI1: 2049 | AJ1: 2050 | AK1: 2051 | AL1: 2052 | AM1: 2053 | AN1: 2054 | AO1: 2055 | AP1: 2056 | AQ1: 2057 | AR1: 2058 | AS1: 2059 | AT1: 2060
A2: LDVs | B2: =1.2*0.95 -> 1.14 | C2: =$B2 -> 1.14 | D2: =$B2 -> 1.14 | E2: =$B2 -> 1.14 | F2: =$B2 -> 1.14 | G2: =$B2 -> 1.14 | H2: =$B2 -> 1.14 | I2: =$B2 -> 1.14 | J2: =$B2 -> 1.14 | ... AT2: =$B2 -> 1.14
A3: HDVs | B3: =11.4*0.95 -> 10.83 | C3: =B3 -> 10.83 | D3: =C3 -> 10.83 | E3: =D3 -> 10.83 | F3: =E3 -> 10.83 | G3: =F3 -> 10.83 | H3: =G3 -> 10.83 | I3: =H3 -> 10.83 | J3: =I3 -> 10.83 | ... AT3: =AS3 -> 10.83
A4: aircraft | B4: =aircraft!D4 -> 29.51167 | C4: =$B$4 -> 29.51167 | D4: =$B$4 -> 29.51167 | E4: =$B$4 -> 29.51167 | F4: =$B$4 -> 29.51167 | G4: =$B$4 -> 29.51167 | H4: =$B$4 -> 29.51167 | I4: =$B$4 -> 29.51167 | J4: =$B$4 -> 29.51167 | ... AT4: =$B$4 -> 29.51167
A5: rail | B5: =Rail!B7 -> 4000 | C5: =B5 -> 4000 | D5: =C5 -> 4000 | E5: =D5 -> 4000 | F5: =E5 -> 4000 | G5: =F5 -> 4000 | H5: =G5 -> 4000 | I5: =H5 -> 4000 | J5: =I5 -> 4000 | ... AT5: =AS5 -> 4000
A6: ships | B6: =AVL!B39 -> 2257.5223 | C6: =B6 -> 2257.5223 | D6: =C6 -> 2257.5223 | E6: =D6 -> 2257.5223 | F6: =E6 -> 2257.5223 | G6: =F6 -> 2257.5223 | H6: =G6 -> 2257.5223 | I6: =H6 -> 2257.5223 | J6: =I6 -> 2257.5223 | ... AT6: =AS6 -> 2257.5223
A7: motorbikes | B7: =motorbike!C2 -> 0.15 | C7: =$B$7 -> 0.15 | D7: =$B$7 -> 0.15 | E7: =$B$7 -> 0.15 | F7: =$B$7 -> 0.15 | G7: =$B$7 -> 0.15 | H7: =$B$7 -> 0.15 | I7: =$B$7 -> 0.15 | J7: =$B$7 -> 0.15 | ... AT7: =$B$7 -> 0.15
