Workbook
Name billion: [1]About!$A$93
Name billion: [2]About!$A$109
Name Eno_TM: '[3]1997 Table 1a Modified'!#REF!
Name Eno_TM: '[3]1997 Table 1a Modified'!#REF!
Name Eno_TM: '[3]1997 Table 1a Modified'!#REF!
Name Eno_TM: '[3]1997 Table 1a Modified'!#REF!
Name Eno_TM: '[3]1997 Table 1a Modified'!#REF!
Name Eno_Tons: '[3]1997 Table 1a Modified'!#REF!
Name Eno_Tons: '[3]1997 Table 1a Modified'!#REF!
Name Eno_Tons: '[3]1997 Table 1a Modified'!#REF!
Name Eno_Tons: '[3]1997 Table 1a Modified'!#REF!
Name Eno_Tons: '[3]1997 Table 1a Modified'!#REF!
Name NTS_YR: [4]About!$B$136
Name NTS_YR: About!$B$99
Name Sum_T2: '[3]1997 Table 1a Modified'!#REF!
Name Sum_T2: '[3]1997 Table 1a Modified'!#REF!
Name Sum_T2: '[3]1997 Table 1a Modified'!#REF!
Name Sum_T2: '[3]1997 Table 1a Modified'!#REF!
Name Sum_T2: '[3]1997 Table 1a Modified'!#REF!
Name Sum_TTM: '[3]1997 Table 1a Modified'!#REF!
Name Sum_TTM: '[3]1997 Table 1a Modified'!#REF!
Name Sum_TTM: '[3]1997 Table 1a Modified'!#REF!
Name Sum_TTM: '[3]1997 Table 1a Modified'!#REF!
Name Sum_TTM: '[3]1997 Table 1a Modified'!#REF!
Name ti_tbl_50: #REF!
Name ti_tbl_50: #REF!
Name ti_tbl_50: #REF!
Name ti_tbl_50: #REF!
Name ti_tbl_50: #REF!
Name ti_tbl_69: #REF!
Name ti_tbl_69: #REF!
Name ti_tbl_69: #REF!
Name ti_tbl_69: #REF!
Name ti_tbl_69: #REF!
Name trillion: [1]About!$A$94
Name trillion: [2]About!$A$110

Sheet About
A1: BNVFE BAU New Vehicle Fuel Economy
A3: Sources: | B3: See Notes section for which vehicle types use which sources
B4: EIA
B5: 2021, 2020
B6: Annual Energy Outlook 2021, 2020
B7: https://www.eia.gov/outlooks/aeo/tables_ref.cfm
B8: Tables 7, 35, 36, 38, 40, 47, 48, 49
B10: Bureau of Transportation Statistics
B11: 2017
B12: National Transportation Statistics
B13: https://www.rita.dot.gov/bts/sites/rita.dot.gov.bts/files/publications/national_transportation_statistics/index.html
B14: Table 1-40
B16: U.S. Coast Guard
B17: 2013
B18: National Recreational Boating Survey 2012
B19: http://www.uscgboating.org/library/recreational-boating-servey/2012survey%20report.pdf
B20: Page 63, Table 40
B22: U.S. Department of Energy
B23: 2015
B24: Fuel Cells Fact Sheet
B25: https://www.energy.gov/sites/prod/files/2015/11/f27/fcto_fuel_cells_fact_sheet.pdf
B27: Others as noted on "Calculations Etc" tab
B29: Passenger rail diesel vs. electric efficiency
B30: Environmental and Energy Study Institute
B31: 2018
B32: Electrification of U.S. Railways: Pie in the Sky, or Realistic Goal?
B33: https://www.eesi.org/articles/view/electrification-of-u.s.-railways-pie-in-the-sky-or-realistic-goal
B34: Third paragraph
A36: Notes
A37: This variable gives fuel economy for new vehicles in units of cargo distance per BTU.
A39: passenger LDVs
A40: Sources: AEO 7, AEO 40, others as noted on "Calculations Etc" tab
A41: The AEO provides new vehicle fuel economy in mpge terms. For each of the 7 EPS technologies, we take a weighted average of EIA's listed new vehicle
A42: fuel economy for all vehicles that would fall under the given technology. We then adjust by EIA's ratio of onroad:tested fuel economy from Table 7 and
A43: convert to thing-miles/BTU by multiplying by the passenger loading used in the file trans/AVLo and the BTU content of a gallon of gasoline.
A45: freight LDVs and HDVs
A46: Sources: see file trans/SYFAFE, AEO 7, AEO 49
A47: We classify AEO's light commercial trucks category as well as light-medium and medium duty vehicles
A48: in "freight LDVs" and heavy duty vehicles in "freight HDVs."
A50: The AEO does not contain information on the efficiency of new commercial light trucks broken out by vehicle technology. Therefore, we start with the
...

Sheet AEO 7
B1: highogs.d120120a | C1: 2020 | D1: 2021 | E1: 2022 | F1: 2023 | G1: 2024 | H1: 2025 | I1: 2026 | J1: 2027 | K1: 2028 | L1: 2029 | M1: 2030 | N1: 2031 | O1: 2032 | P1: 2033 | Q1: 2034 | R1: 2035 | S1: 2036 | T1: 2037 | U1: 2038 | V1: 2039 | W1: 2040 | X1: 2041 | Y1: 2042 | Z1: 2043 | AA1: 2044 | AB1: 2045 | AC1: 2046 | AD1: 2047 | AE1: 2048 | AF1: 2049 | AG1: 2050
C3: Report | D3: Annual Energy Outlook 2021
C4: Scenario | D4: ref2021 | G4: Reference case
C5: Datekey | D5: d113020a
C6: Release Date | E6: January 2021
A10: TKI000 | B10: 7. Transportation Sector Key Indicators and Delivered Energy Consumption | AH10: Compound
AH11: Growth
AH12: 2020-2050
B13: Key Indicators and Consumption | C13: 2020 | D13: 2021 | E13: 2022 | F13: 2023 | G13: 2024 | H13: 2025 | I13: 2026 | J13: 2027 | K13: 2028 | L13: 2029 | M13: 2030 | N13: 2031 | O13: 2032 | P13: 2033 | Q13: 2034 | R13: 2035 | S13: 2036 | T13: 2037 | U13: 2038 | V13: 2039 | W13: 2040 | X13: 2041 | Y13: 2042 | Z13: 2043 | AA13: 2044 | AB13: 2045 | AC13: 2046 | AD13: 2047 | AE13: 2048 | AF13: 2049 | AG13: 2050 | AH13: (percent)
B15: Key Indicators
B16: Travel Indicators
B17: (billion vehicle miles traveled)
A18: TKI000:ba_Light-DutyVeh | B18: Light-Duty Vehicles less than 8,501 pounds | C18: 2628.8213 | D18: 2807.2766 | E18: 2862.5334 | F18: 2927.623 | G18: 2985.1787 | H18: 3035.5583 | I18: 3076.646 | J18: 3107.3425 | K18: 3133.9348 | L18: 3153.6963 | M18: 3170.1406 | N18: 3182.3604 | O18: 3194.3308 | P18: 3208.3691 | Q18: 3223.0125 | R18: 3240.585 | S18: 3258.4961 | T18: 3274.8767 | U18: 3290.0166 | V18: 3306.9768 | W18: 3326.3066 | X18: 3344.3862 | Y18: 3362.8257 | Z18: 3380.6958 | AA18: 3396.752 | AB18: 3412.0305 | AC18: 3428.1084 | AD18: 3442.5149 | AE18: 3458.3401 | AF18: 3474.7087 | AG18: 3490.9399 | AH18: 0.009499
A19: TKI000:ba_CommercialLig | B19: Commercial Light Trucks 1/ | C19: 89.884674 | D19: 93.705605 | E19: 96.386086 | F19: 98.338295 | G19: 100.59341 | H19: 102.85941 | I19: 104.50481 | J19: 105.69051 | K19: 106.73648 | L19: 107.65262 | M19: 108.58299 | N19: 109.54169 | O19: 110.61884 | P19: 111.70705 | Q19: 112.95861 | R19: 114.4644 | S19: 115.90713 | T19: 117.2149 | U19: 118.58162 | V19: 120.04366 | W19: 121.52813 | X19: 123.15266 | Y19: 124.79562 | Z19: 126.54729 | AA19: 128.13809 | AB19: 129.78653 | AC19: 131.39938 | AD19: 132.81888 | AE19: 134.41592 | AF19: 136.18376 | AG19: 138.01 | AH19: 0.014396
A20: TKI000:ba_FreightTrucks | B20: Freight Trucks greater than 10,000 pounds | C20: 274.54938 | D20: 282.81525 | E20: 293.31253 | F20: 299.26825 | G20: 306.24057 | H20: 313.39252 | I20: 318.20425 | J20: 321.86676 | K20: 325.49912 | L20: 328.91818 | M20: 332.87759 | N20: 337.04804 | O20: 341.41943 | P20: 345.24298 | Q20: 349.75104 | R20: 355.3486 | S20: 360.47449 | T20: 365.30786 | U20: 370.46982 | V20: 375.98251 | W20: 381.01727 | X20: 386.70856 | Y20: 392.7948 | Z20: 399.70087 | AA20: 405.64847 | AB20: 411.79804 | AC20: 417.07053 | AD20: 422.22894 | AE20: 428.00507 | AF20: 434.11798 | AG20: 440.79153 | AH20: 0.015907
B21: (billion passenger miles traveled)
A22: TKI000:buspassmiles | B22: Bus Transportation | C22: 108.32251 | D22: 134.82925 | E22: 154.71742 | F22: 169.65283 | G22: 180.92081 | H22: 189.4493 | I22: 195.91775 | J22: 200.87158 | K22: 204.4294 | L22: 207.17819 | M22: 209.42627 | N22: 211.01544 | O22: 212.35484 | P22: 213.3685 | Q22: 214.16457 | R22: 214.70816 | S22: 215.16942 | T22: 215.53513 | U22: 215.80548 | V22: 215.98587 | W22: 216.16197 | X22: 216.26544 | Y22: 216.33122 | Z22: 216.37845 | AA22: 216.40999 | AB22: 216.44157 | AC22: 216.45151 | AD22: 216.46837 | AE22: 216.483 | AF22: 216.55254 | AG22: 216.64348 | AH22: 0.023374
A23: TKI000:railpassmiles | B23: Passenger Rail | C23: 24.970692 | D23: 29.653244 | E23: 33.486446 | F23: 36.386101 | G23: 38.577961 | H23: 40.222988 | I23: 41.396164 | J23: 42.264778 | K23: 42.515728 | L23: 42.713291 | M23: 43.137005 | N23: 43.343742 | O23: 43.818241 | P23: 44.274139 | Q23: 44.835865 | R23: 45.310886 | S23: 45.831734 | T23: 46.32793 | U23: 46.816154 | V23: 47.317448 | W23: 47.980492 | X23: 48.58215 | Y23: 49.164021 | Z23: 49.763081 | AA23: 50.334721 | AB23: 50.97802 | AC23: 51.558666 | AD23: 52.079247 | AE23: 52.647175 | AF23: 53.282265 | AG23: 53.912506 | AH23: 0.025987
B24: (billion seat miles available)
A25: TKI000:ba_Air | B25: Air | C25: 738.85895 | D25: 1081.6603 | E25: 1215.7373 | F25: 1284.3009 | G25: 1340.2419 | H25: 1397.254 | I25: 1430.9814 | J25: 1455.4497 | K25: 1476.5328 | L25: 1495.9988 | M25: 1516.3666 | N25: 1539.9563 | O25: 1569.8956 | P25: 1600.4498 | Q25: 1634.8596 | R25: 1672.6685 | S25: 1707.1351 | T25: 1738.4458 | U25: 1770.8867 | V25: 1807.5973 | W25: 1848.892 | X25: 1889.7706 | Y25: 1930.5969 | Z25: 1971.072 | AA25: 2010.4889 | AB25: 2052.9485 | AC25: 2092.6599 | AD25: 2129.1379 | AE25: 2171.0725 | AF25: 2213.2192 | AG25: 2256.3169 | AH25: 0.037914
B26: (billion ton miles traveled)
A27: TKI000:ba_Rail | B27: Rail | C27: 1508.557 | D27: 1600.7733 | E27: 1616.5277 | F27: 1618.1086 | G27: 1617.9658 | H27: 1567.8839 | I27: 1587.1537 | J27: 1586.3214 | K27: 1606.0509 | L27: 1623.5897 | M27: 1641.5112 | N27: 1654.2195 | O27: 1664.4609 | P27: 1678.1671 | Q27: 1686.5093 | R27: 1700.8228 | S27: 1714.3484 | T27: 1725.9465 | U27: 1730.047 | V27: 1747.595 | W27: 1753.4669 | X27: 1765.8125 | Y27: 1783.1677 | Z27: 1804.6465 | AA27: 1808.4172 | AB27: 1822.5868 | AC27: 1832.4125 | AD27: 1846.7275 | AE27: 1860.8992 | AF27: 1876.0131 | AG27: 1898.7479 | AH27: 0.007697
A28: TKI000:ba_DomesticShipp | B28: Domestic Shipping | C28: 347.68133 | D28: 359.32346 | E28: 357.10059 | F28: 354.90668 | G28: 352.6954 | H28: 348.07819 | I28: 341.28058 | J28: 333.10046 | K28: 325.25259 | L28: 316.86505 | M28: 308.73145 | N28: 305.11627 | O28: 301.85187 | P28: 298.30835 | Q28: 295.38019 | R28: 292.62634 | S28: 289.63 | T28: 286.27258 | U28: 282.6651 | V28: 279.71716 | W28: 276.01688 | X28: 275.42545 | Y28: 275.00784 | Z28: 275.36859 | AA28: 274.91849 | AB28: 274.56326 | AC28: 273.54471 | AD28: 272.61859 | AE28: 271.43494 | AF28: 270.55728 | AG28: 270.13117 | AH28: -0.008377
B30: Energy Efficiency Indicators
B31: (miles per gallon)
A32: TKI000:ca_AvgCAFEStand | B32: New Light-Duty Vehicle CAFE Standard 2/ | C32: 34.471165 | D32: 35.386478 | E32: 36.015511 | F32: 36.532135 | G32: 36.999756 | H32: 37.485561 | I32: 38.067947 | J32: 38.072563 | K32: 38.080814 | L32: 38.095245 | M32: 38.18074 | N32: 38.191765 | O32: 38.206318 | P32: 38.220623 | Q32: 38.249493 | R32: 38.23008 | S32: 38.209507 | T32: 38.204479 | U32: 38.204224 | V32: 38.187893 | W32: 38.180141 | X32: 38.173969 | Y32: 38.160957 | Z32: 38.151768 | AA32: 38.148342 | AB32: 38.153297 | AC32: 38.143864 | AD32: 38.134365 | AE32: 38.120548 | AF32: 38.116928 | AG32: 38.114223 | AH32: 0.003354
A33: TKI000:ca_CarCAFEStand | B33: New Car 2/ | C33: 42.096588 | D33: 44.275085 | E33: 44.804096 | F33: 45.431927 | G33: 46.163593 | H33: 46.83271 | I33: 47.617275 | J33: 47.640335 | K33: 47.640335 | L33: 47.644814 | M33: 47.681995 | N33: 47.681995 | O33: 47.681995 | P33: 47.681995 | Q33: 47.681995 | R33: 47.681995 | S33: 47.681995 | T33: 47.681995 | U33: 47.681995 | V33: 47.681995 | W33: 47.681995 | X33: 47.681995 | Y33: 47.681995 | Z33: 47.683205 | AA33: 47.684814 | AB33: 47.687138 | AC33: 47.687138 | AD33: 47.687138 | AE33: 47.687138 | AF33: 47.689449 | AG33: 47.689449 | AH33: 0.004167
A34: TKI000:ca_TwukCAFEStand | B34: New Light Truck 2/ | C34: 30.906752 | D34: 31.515783 | E34: 31.942911 | F34: 32.461285 | G34: 32.91795 | H34: 33.400791 | I34: 33.955074 | J34: 33.955074 | K34: 33.955074 | L34: 33.955074 | M34: 33.955074 | N34: 33.955093 | O34: 33.955093 | P34: 33.955093 | Q34: 33.955093 | R34: 33.955128 | S34: 33.955128 | T34: 33.955128 | U34: 33.955128 | V34: 33.955128 | W34: 33.955128 | X34: 33.955128 | Y34: 33.955128 | Z34: 33.955128 | AA34: 33.955128 | AB34: 33.955128 | AC34: 33.955128 | AD34: 33.955128 | AE34: 33.955128 | AF34: 33.955128 | AG34: 33.955128 | AH34: 0.00314
A35: TKI000:ca_NewVehCred | B35: Compliance New Light-Duty Vehicle 3/ | C35: 35.428043 | D35: 36.588161 | E35: 37.27243 | F35: 37.693687 | G35: 38.000156 | H35: 38.414772 | I35: 38.930225 | J35: 39.067493 | K35: 39.131561 | L35: 39.187084 | M35: 39.367001 | N35: 39.458767 | O35: 39.570412 | P35: 39.688381 | Q35: 39.842903 | R35: 39.925739 | S35: 40.007633 | T35: 40.122059 | U35: 40.263226 | V35: 40.363659 | W35: 40.483315 | X35: 40.567554 | Y35: 40.636898 | Z35: 40.715225 | AA35: 40.813824 | AB35: 40.933929 | AC35: 41.032745 | AD35: 41.136253 | AE35: 41.233734 | AF35: 41.366283 | AG35: 41.510693 | AH35: 0.005296
A36: TKI000:ca_NewCarCred | B36: New Car 3/ | C36: 43.264011 | D36: 45.133469 | E36: 45.638382 | F36: 46.329559 | G36: 46.974045 | H36: 47.544498 | I36: 48.288284 | J36: 48.41925 | K36: 48.519196 | L36: 48.602192 | M36: 48.75803 | N36: 48.944359 | O36: 49.116051 | P36: 49.343533 | Q36: 49.588879 | R36: 49.838387 | S36: 50.062164 | T36: 50.324268 | U36: 50.609341 | V36: 50.887779 | W36: 51.161552 | X36: 51.375084 | Y36: 51.577618 | Z36: 51.784939 | AA36: 52.021469 | AB36: 52.278286 | AC36: 52.554256 | AD36: 52.823685 | AE36: 53.105881 | AF36: 53.415283 | AG36: 53.766708 | AH36: 0.007271
A37: TKI000:ca_NewTwukCred | B37: New Light Truck 3/ | C37: 31.76507 | D37: 32.790131 | E37: 33.304337 | F37: 33.675228 | G37: 33.948895 | H37: 34.370636 | I37: 34.850887 | J37: 34.987331 | K37: 35.027725 | L37: 35.055889 | M37: 35.139996 | N37: 35.184067 | O37: 35.253815 | P37: 35.313755 | Q37: 35.395432 | R37: 35.447819 | S37: 35.509632 | T37: 35.58049 | U37: 35.672146 | V37: 35.736599 | W37: 35.81567 | X37: 35.86631 | Y37: 35.911537 | Z37: 35.962078 | AA37: 36.021683 | AB37: 36.09063 | AC37: 36.147751 | AD37: 36.213341 | AE37: 36.274784 | AF37: 36.358318 | AG37: 36.442936 | AH37: 0.00459
A38: TKI000:ca_TestedNewVeh | B38: Tested New Light-Duty Vehicle 4/ | C38: 35.306622 | D38: 36.467899 | E38: 37.145805 | F38: 37.564754 | G38: 37.869587 | H38: 38.261166 | I38: 38.678329 | J38: 38.78212 | K38: 38.833714 | L38: 38.876083 | M38: 39.031017 | N38: 39.097122 | O38: 39.178814 | P38: 39.263397 | Q38: 39.380604 | R38: 39.428646 | S38: 39.476784 | T38: 39.553841 | U38: 39.655148 | V38: 39.718605 | W38: 39.800255 | X38: 39.857685 | Y38: 39.902508 | Z38: 39.954895 | AA38: 40.024872 | AB38: 40.112934 | AC38: 40.181061 | AD38: 40.254047 | AE38: 40.320404 | AF38: 40.416508 | AG38: 40.5215 | AH38: 0.004603
A39: TKI000:ca_TestedNewCar | B39: New Car 4/ | C39: 42.996372 | D39: 44.88583 | E39: 45.388092 | F39: 46.068283 | G39: 46.702301 | H39: 47.265957 | I39: 47.99147 | J39: 48.105293 | K39: 48.179577 | L39: 48.231701 | M39: 48.343479 | N39: 48.473526 | O39: 48.589264 | P39: 48.747791 | Q39: 48.918312 | R39: 49.08532 | S39: 49.232788 | T39: 49.410698 | U39: 49.605431 | V39: 49.791992 | W39: 49.975594 | X39: 50.118858 | Y39: 50.253036 | Z39: 50.390747 | AA39: 50.551331 | AB39: 50.726044 | AC39: 50.913406 | AD39: 51.097149 | AE39: 51.287189 | AF39: 51.498287 | AG39: 51.738174 | AH39: 0.006188
A40: TKI000:ca_TestedNewTwuk | B40: New Light Truck 4/ | C40: 31.69734 | D40: 32.714512 | E40: 33.224262 | F40: 33.594929 | G40: 33.868374 | H40: 34.261593 | I40: 34.620468 | J40: 34.71925 | K40: 34.751755 | L40: 34.772854 | M40: 34.839573 | N40: 34.86882 | O40: 34.918171 | P40: 34.957504 | Q40: 35.015827 | R40: 35.049236 | S40: 35.091114 | T40: 35.140182 | U40: 35.208858 | V40: 35.253445 | W40: 35.311043 | X40: 35.348305 | Y40: 35.381889 | Z40: 35.41943 | AA40: 35.464706 | AB40: 35.517353 | AC40: 35.560341 | AD40: 35.610996 | AE40: 35.657856 | AF40: 35.722626 | AG40: 35.788242 | AH40: 0.004054
A41: TKI000:ca_OnRoadNewVeh | B41: On-Road New Light-Duty Vehicle 5/ | C41: 28.801699 | D41: 29.748508 | E41: 30.302168 | F41: 30.643736 | G41: 30.892097 | H41: 31.211321 | I41: 31.551422 | J41: 31.636091 | K41: 31.678196 | L41: 31.712803 | M41: 31.839462 | N41: 31.893412 | O41: 31.960094 | P41: 32.029114 | Q41: 32.124813 | R41: 32.16391 | S41: 32.203083 | T41: 32.2659 | U41: 32.348515 | V41: 32.400196 | W41: 32.466755 | X41: 32.513561 | Y41: 32.550056 | Z41: 32.592743 | AA41: 32.649788 | AB41: 32.721619 | AC41: 32.77713 | AD41: 32.836617 | AE41: 32.890667 | AF41: 32.969021 | AG41: 33.054626 | AH41: 0.004601
A42: TKI000:ca_OnRoadNewCar | B42: New Car 5/ | C42: 35.111473 | D42: 36.65443 | E42: 37.064587 | F42: 37.620041 | G42: 38.137787 | H42: 38.598076 | I42: 39.190544 | J42: 39.283493 | K42: 39.344154 | L42: 39.386719 | M42: 39.477997 | N42: 39.584198 | O42: 39.678711 | P42: 39.808167 | Q42: 39.947414 | R42: 40.083797 | S42: 40.20422 | T42: 40.349506 | U42: 40.508526 | V42: 40.660873 | W42: 40.810806 | X42: 40.927799 | Y42: 41.037373 | Z42: 41.149826 | AA42: 41.280964 | AB42: 41.423634 | AC42: 41.576637 | AD42: 41.726685 | AE42: 41.881874 | AF42: 42.05426 | AG42: 42.250156 | AH42: 0.006188
A43: TKI000:ca_OnRoadNewTwuk | B43: New Light Truck 5/ | C43: 25.844681 | D43: 26.67404 | E43: 27.08967 | F43: 27.391895 | G43: 27.614851 | H43: 27.935465 | I43: 28.228077 | J43: 28.30862 | K43: 28.335123 | L43: 28.352325 | M43: 28.406727 | N43: 28.430573 | O43: 28.470812 | P43: 28.502882 | Q43: 28.550436 | R43: 28.577677 | S43: 28.611822 | T43: 28.651831 | U43: 28.707827 | V43: 28.744179 | W43: 28.791143 | X43: 28.821524 | Y43: 28.848907 | Z43: 28.879517 | AA43: 28.916433 | AB43: 28.95936 | AC43: 28.99441 | AD43: 29.035711 | AE43: 29.073919 | AF43: 29.12673 | AG43: 29.180231 | AH43: 0.004054
... A47: TKI000:ca_FreightTruck | B47: Freight Truck | C47: 7.238182 | D47: 7.310616 | E47: 7.389947 | F47: 7.476684 | G47: 7.574702 | H47: 7.686319 | I47: 7.80973 | J47: 7.944551 | K47: 8.083447 | L47: 8.230841 | M47: 8.382581 | N47: 8.536425 | O47: 8.686997 | P47: 8.827357 | Q47: 8.956337 | R47: 9.073474 | S47: 9.178899 | T47: 9.273054 | U47: 9.358724 | V47: 9.437573 | W47: 9.508476 | X47: 9.572987 | Y47: 9.62975 | Z47: 9.67997 | AA47: 9.724974 | AB47: 9.767028 | AC47: 9.806892 | AD47: 9.846315 | AE47: 9.885777 | AF47: 9.92395 | AG47: 9.961658 | AH47: 0.010703
B48: (seat miles per gallon)
A49: TKI000:ca_Aircraft | B49: Aircraft | C49: 71.028343 | D49: 72.22039 | E49: 72.564766 | F49: 73.078918 | G49: 73.855469 | H49: 74.440651 | I49: 74.946922 | J49: 75.432518 | K49: 75.920792 | L49: 76.399239 | M49: 76.903839 | N49: 77.42765 | O49: 77.983635 | P49: 78.569893 | Q49: 79.171509 | R49: 79.79718 | S49: 80.421959 | T49: 81.046387 | U49: 81.662766 | V49: 82.260727 | W49: 82.849083 | X49: 83.43293 | Y49: 84.016846 | Z49: 84.607124 | AA49: 85.178467 | AB49: 85.733246 | AC49: 86.278442 | AD49: 86.813042 | AE49: 87.369904 | AF49: 87.921379 | AG49: 88.469986 | AH49: 0.007346
...

Sheet AEO 7 (2020)
B1: highogs.d112619a | C1: 2019 | D1: 2020 | E1: 2021 | F1: 2022 | G1: 2023 | H1: 2024 | I1: 2025 | J1: 2026 | K1: 2027 | L1: 2028 | M1: 2029 | N1: 2030 | O1: 2031 | P1: 2032 | Q1: 2033 | R1: 2034 | S1: 2035 | T1: 2036 | U1: 2037 | V1: 2038 | W1: 2039 | X1: 2040 | Y1: 2041 | Z1: 2042 | AA1: 2043 | AB1: 2044 | AC1: 2045 | AD1: 2046 | AE1: 2047 | AF1: 2048 | AG1: 2049 | AH1: 2050
C3: Report | D3: Annual Energy Outlook 2020
C4: Scenario | D4: highogs | G4: High oil and gas supply
C5: Datekey | D5: d112619a
C6: Release Date | E6: January 2020
A10: TKI000 | B10: 7. Transportation Sector Key Indicators and Delivered Energy Consumption
AI12: 2019-
B13: Key Indicators and Consumption | C13: 2019 | D13: 2020 | E13: 2021 | F13: 2022 | G13: 2023 | H13: 2024 | I13: 2025 | J13: 2026 | K13: 2027 | L13: 2028 | M13: 2029 | N13: 2030 | O13: 2031 | P13: 2032 | Q13: 2033 | R13: 2034 | S13: 2035 | T13: 2036 | U13: 2037 | V13: 2038 | W13: 2039 | X13: 2040 | Y13: 2041 | Z13: 2042 | AA13: 2043 | AB13: 2044 | AC13: 2045 | AD13: 2046 | AE13: 2047 | AF13: 2048 | AG13: 2049 | AH13: 2050 | AI13: 2050
B15: Key Indicators
B16: Travel Indicators
B17: (billion vehicle miles traveled)
A18: TKI000:ba_Light-DutyVeh | B18: Light-Duty Vehicles less than 8,501 pounds | C18: 2917.2534 | D18: 2975.1255 | E18: 3025.3584 | F18: 3062.7468 | G18: 3083.9775 | H18: 3096.5911 | I18: 3105.9812 | J18: 3125.592 | K18: 3146.8806 | L18: 3167.6331 | M18: 3188.2371 | N18: 3209.8457 | O18: 3233.3459 | P18: 3252.6282 | Q18: 3271.1394 | R18: 3285.1404 | S18: 3295.6909 | T18: 3311.9399 | U18: 3327.9958 | V18: 3344.2627 | W18: 3361.5449 | X18: 3379.7544 | Y18: 3396.2571 | Z18: 3413.8406 | AA18: 3432.0298 | AB18: 3451.1577 | AC18: 3472.0923 | AD18: 3496.9058 | AE18: 3524.3184 | AF18: 3555.4368 | AG18: 3588.8325 | AH18: 3624.4036 | AI18: 0.007026
A19: TKI000:ba_CommercialLig | B19: Commercial Light Trucks 1/ | C19: 99.321114 | D19: 100.61537 | E19: 102.27555 | F19: 103.79449 | G19: 104.99791 | H19: 105.84502 | I19: 106.78965 | J19: 107.83586 | K19: 109.08619 | L19: 110.31479 | M19: 111.61692 | N19: 112.77087 | O19: 114.26243 | P19: 115.52301 | Q19: 116.87927 | R19: 118.14617 | S19: 119.40303 | T19: 120.80527 | U19: 122.15245 | V19: 123.49687 | W19: 124.85643 | X19: 126.2754 | Y19: 127.71654 | Z19: 129.18462 | AA19: 130.707 | AB19: 132.37408 | AC19: 134.19019 | AD19: 136.27534 | AE19: 138.1423 | AF19: 140.20346 | AG19: 142.3405 | AH19: 144.47952 | AI19: 0.012163
A20: TKI000:ba_FreightTrucks | B20: Freight Trucks greater than 10,000 pounds | C20: 299.98956 | D20: 302.9967 | E20: 307.86118 | F20: 312.26749 | G20: 316.85519 | H20: 319.63693 | I20: 322.73798 | J20: 325.80005 | K20: 329.40594 | L20: 332.56686 | M20: 335.87531 | N20: 338.36066 | O20: 342.56183 | P20: 345.99631 | Q20: 349.88959 | R20: 353.1503 | S20: 356.89838 | T20: 360.95453 | U20: 364.40631 | V20: 367.98541 | W20: 371.4613 | X20: 375.17526 | Y20: 378.96576 | Z20: 382.97611 | AA20: 386.86951 | AB20: 391.47946 | AC20: 396.5683 | AD20: 402.70737 | AE20: 407.39862 | AF20: 413.09305 | AG20: 419.04983 | AH20: 425.07648 | AI20: 0.011306
B21: (billion passenger miles traveled)
A22: TKI000:buspassmiles | B22: Bus Transportation | C22: 210.1385 | D22: 211.1262 | E22: 212.11616 | F22: 213.08595 | G22: 214.01353 | H22: 214.96095 | I22: 215.98413 | J22: 216.98978 | K22: 217.98006 | L22: 218.98109 | M22: 219.96805 | N22: 220.90674 | O22: 221.80705 | P22: 222.67883 | Q22: 223.45596 | R22: 224.19052 | S22: 224.88495 | T22: 225.5426 | U22: 226.16771 | V22: 226.76289 | W22: 227.33022 | X22: 227.87238 | Y22: 228.39172 | Z22: 228.89146 | AA22: 229.37672 | AB22: 229.85208 | AC22: 230.32323 | AD22: 230.79691 | AE22: 231.28061 | AF22: 231.78067 | AG22: 232.30583 | AH22: 232.85057 | AI22: 0.003316
A23: TKI000:railpassmiles | B23: Passenger Rail | C23: 41.270718 | D23: 41.874931 | E23: 42.455513 | F23: 42.941441 | G23: 43.403492 | H23: 43.866783 | I23: 44.310471 | J23: 44.75193 | K23: 45.177658 | L23: 45.617382 | M23: 46.05724 | N23: 46.402245 | O23: 46.841446 | P23: 47.267838 | Q23: 47.680485 | R23: 48.055225 | S23: 48.435219 | T23: 48.803921 | U23: 49.166313 | V23: 49.530781 | W23: 49.890511 | X23: 50.244217 | Y23: 50.573273 | Z23: 50.897018 | AA23: 51.222713 | AB23: 51.549355 | AC23: 51.873222 | AD23: 52.227497 | AE23: 52.585468 | AF23: 52.972961 | AG23: 53.355492 | AH23: 53.757782 | AI23: 0.008563
B24: (billion seat miles available)
A25: TKI000:ba_Air | B25: Air | C25: 1222.9934 | D25: 1245.385 | E25: 1270.2579 | F25: 1290.4578 | G25: 1307.1332 | H25: 1325.8835 | I25: 1346.3998 | J25: 1366.3947 | K25: 1386.9773 | L25: 1409.3759 | M25: 1434.0159 | N25: 1459.4762 | O25: 1485.5172 | P25: 1512.3081 | Q25: 1538.871 | R25: 1563.6233 | S25: 1587.829 | T25: 1613.7333 | U25: 1640.1089 | V25: 1667.4398 | W25: 1695.8134 | X25: 1724.8636 | Y25: 1752.9756 | Z25: 1781.3413 | AA25: 1810.3131 | AB25: 1840.631 | AC25: 1874.0067 | AD25: 1909.9596 | AE25: 1947.4512 | AF25: 1987.4026 | AG25: 2028.574 | AH25: 2071.0894 | AI25: 0.017138
B26: (billion ton miles traveled)
A27: TKI000:ba_Rail | B27: Rail | C27: 1807.9623 | D27: 1730.8405 | E27: 1660.0334 | F27: 1651.2594 | G27: 1652.7242 | H27: 1638.4692 | I27: 1604.7769 | J27: 1643.9995 | K27: 1652.7871 | L27: 1662.7437 | M27: 1655.604 | N27: 1648.3021 | O27: 1654.8008 | P27: 1663.8508 | Q27: 1673.921 | R27: 1684.4979 | S27: 1686.808 | T27: 1698.2738 | U27: 1704.6904 | V27: 1701.2555 | W27: 1711.9681 | X27: 1715.1283 | Y27: 1722.2583 | Z27: 1735.2404 | AA27: 1747.2886 | AB27: 1760.9611 | AC27: 1777.2797 | AD27: 1802.0692 | AE27: 1818.0815 | AF27: 1839.249 | AG27: 1861.9969 | AH27: 1888.5421 | AI27: 0.001408
A28: TKI000:ba_DomesticShipp | B28: Domestic Shipping | C28: 416.68076 | D28: 409.15491 | E28: 404.52988 | F28: 396.47797 | G28: 388.98981 | H28: 379.45697 | I28: 370.07324 | J28: 361.44611 | K28: 352.76407 | L28: 343.56067 | M28: 333.81879 | N28: 323.79498 | O28: 320.25205 | P28: 316.14533 | Q28: 312.6521 | R28: 308.38547 | S28: 304.23715 | T28: 300.63773 | U28: 296.55325 | V28: 292.41882 | W28: 288.76395 | X28: 284.95685 | Y28: 283.66168 | Z28: 282.64859 | AA28: 281.33289 | AB28: 280.51184 | AC28: 279.8728 | AD28: 280.18787 | AE28: 279.40164 | AF28: 279.35028 | AG28: 279.69217 | AH28: 280.25092 | AI28: -0.012713
B30: Energy Efficiency Indicators
B31: (miles per gallon)
A32: TKI000:ca_AvgCAFEStand | B32: New Light-Duty Vehicle CAFE Standard 2/ | C32: 34.359936 | D32: 35.284824 | E32: 36.831001 | F32: 38.399506 | G32: 40.110416 | H32: 41.695168 | I32: 43.801582 | J32: 43.785816 | K32: 43.851311 | L32: 43.92421 | M32: 44.014652 | N32: 44.196796 | O32: 44.303349 | P32: 44.390171 | Q32: 44.493732 | R32: 44.60854 | S32: 44.698715 | T32: 44.789574 | U32: 44.882374 | V32: 44.963428 | W32: 45.039089 | X32: 45.11404 | Y32: 45.19231 | Z32: 45.25729 | AA32: 45.303879 | AB32: 45.340485 | AC32: 45.390274 | AD32: 45.422104 | AE32: 45.456978 | AF32: 45.47982 | AG32: 45.506924 | AH32: 45.514236 | AI32: 0.00911
A33: TKI000:ca_CarCAFEStand | B33: New Car 2/ | C33: 40.551155 | D33: 42.338371 | E33: 44.294533 | F33: 46.414017 | G33: 48.711933 | H33: 50.082985 | I33: 52.773457 | J33: 52.773731 | K33: 52.786339 | L33: 52.786339 | M33: 52.798622 | N33: 52.841564 | O33: 52.841564 | P33: 52.841564 | Q33: 52.841564 | R33: 52.841564 | S33: 52.841564 | T33: 52.841564 | U33: 52.841564 | V33: 52.841564 | W33: 52.841564 | X33: 52.842728 | Y33: 52.844788 | Z33: 52.844788 | AA33: 52.844788 | AB33: 52.844788 | AC33: 52.84753 | AD33: 52.84753 | AE33: 52.848724 | AF33: 52.848724 | AG33: 52.84988 | AH33: 52.84988 | AI33: 0.008582
A34: TKI000:ca_TwukCAFEStand | B34: New Light Truck 2/ | C34: 30.2997 | D34: 30.889185 | E34: 32.380001 | F34: 33.7799 | G34: 35.309071 | H34: 36.976479 | I34: 38.765255 | J34: 38.772991 | K34: 38.772991 | L34: 38.772991 | M34: 38.772991 | N34: 38.772991 | O34: 38.772991 | P34: 38.772991 | Q34: 38.772991 | R34: 38.772991 | S34: 38.772991 | T34: 38.772991 | U34: 38.772991 | V34: 38.772991 | W34: 38.772991 | X34: 38.772991 | Y34: 38.772991 | Z34: 38.772991 | AA34: 38.772991 | AB34: 38.772991 | AC34: 38.772991 | AD34: 38.772991 | AE34: 38.772991 | AF34: 38.772991 | AG34: 38.772991 | AH34: 38.773014 | AI34: 0.007986
A35: TKI000:ca_NewVehCred | B35: Compliance New Light-Duty Vehicle 3/ | C35: 35.348213 | D35: 36.238525 | E35: 37.596539 | F35: 39.37933 | G35: 40.901978 | H35: 42.360344 | I35: 44.567291 | J35: 44.831284 | K35: 44.934002 | L35: 45.040806 | M35: 45.183762 | N35: 45.495754 | O35: 45.787571 | P35: 46.034676 | Q35: 46.317448 | R35: 46.60257 | S35: 46.849384 | T35: 47.060444 | U35: 47.280041 | V35: 47.481697 | W35: 47.659729 | X35: 47.83065 | Y35: 47.980515 | Z35: 48.108444 | AA35: 48.197189 | AB35: 48.262737 | AC35: 48.3549 | AD35: 48.425739 | AE35: 48.504185 | AF35: 48.562855 | AG35: 48.634819 | AH35: 48.674248 | AI35: 0.010373
A36: TKI000:ca_NewCarCred | B36: New Car 3/ | C36: 42.356316 | D36: 43.482601 | E36: 45.545635 | F36: 47.835651 | G36: 49.962463 | H36: 51.477432 | I36: 54.131187 | J36: 54.288181 | K36: 54.274036 | L36: 54.345482 | M36: 54.476521 | N36: 54.755726 | O36: 55.19865 | P36: 55.546597 | Q36: 55.91061 | R36: 56.268238 | S36: 56.616009 | T36: 56.875309 | U36: 57.153564 | V36: 57.42186 | W36: 57.643833 | X36: 57.841148 | Y36: 57.984364 | Z36: 58.118862 | AA36: 58.223202 | AB36: 58.303883 | AC36: 58.397022 | AD36: 58.51268 | AE36: 58.621887 | AF36: 58.738182 | AG36: 58.859608 | AH36: 58.987617 | AI36: 0.010741
A37: TKI000:ca_NewTwukCred | B37: New Light Truck 3/ | C37: 30.865908 | D37: 31.724129 | E37: 32.910633 | F37: 34.543072 | G37: 35.889904 | H37: 37.32349 | I37: 39.26572 | J37: 39.595291 | K37: 39.653728 | L37: 39.666462 | M37: 39.683132 | N37: 39.748066 | O37: 39.797894 | P37: 39.852974 | Q37: 39.920296 | R37: 39.970135 | S37: 40.005047 | T37: 40.02647 | U37: 40.043442 | V37: 40.056137 | W37: 40.064693 | X37: 40.075218 | Y37: 40.075615 | Z37: 40.069695 | AA37: 40.055481 | AB37: 40.038029 | AC37: 40.029408 | AD37: 40.008018 | AE37: 39.996075 | AF37: 39.972542 | AG37: 39.958122 | AH37: 39.929474 | AI37: 0.00834
A38: TKI000:ca_TestedNewVeh | B38: Tested New Light-Duty Vehicle 4/ | C38: 34.962322 | D38: 35.991081 | E38: 37.288235 | F38: 39.051094 | G38: 40.553646 | H38: 41.976017 | I38: 44.120575 | J38: 44.336227 | K38: 44.414066 | L38: 44.500385 | M38: 44.615799 | N38: 44.876507 | O38: 45.111603 | P38: 45.306648 | Q38: 45.531082 | R38: 45.75457 | S38: 45.942371 | T38: 46.09964 | U38: 46.263412 | V38: 46.41185 | W38: 46.541386 | X38: 46.666012 | Y38: 46.777721 | Z38: 46.871037 | AA38: 46.931049 | AB38: 46.971848 | AC38: 47.034363 | AD38: 47.077263 | AE38: 47.126358 | AF38: 47.158012 | AG38: 47.200371 | AH38: 47.214767 | AI38: 0.009739
A39: TKI000:ca_TestedNewCar | B39: New Car 4/ | C39: 41.715885 | D39: 42.872379 | E39: 44.733494 | F39: 46.957069 | G39: 49.003487 | H39: 50.41568 | I39: 52.908669 | J39: 53.035347 | K39: 53.002815 | L39: 53.031281 | M39: 53.101597 | N39: 53.283951 | O39: 53.59354 | P39: 53.82737 | Q39: 54.068119 | R39: 54.300163 | S39: 54.521736 | T39: 54.675041 | U39: 54.843937 | V39: 55.006741 | W39: 55.136219 | X39: 55.248566 | Y39: 55.326115 | Z39: 55.397579 | AA39: 55.445976 | AB39: 55.477283 | AC39: 55.516716 | AD39: 55.571735 | AE39: 55.621513 | AF39: 55.67548 | AG39: 55.732971 | AH39: 55.794552 | AI39: 0.009425
A40: TKI000:ca_TestedNewTwuk | B40: New Light Truck 4/ | C40: 30.612513 | D40: 31.651661 | E40: 32.830524 | F40: 34.456524 | G40: 35.799854 | H40: 37.22747 | I40: 39.151051 | J40: 39.426971 | K40: 39.465645 | L40: 39.475208 | M40: 39.488102 | N40: 39.541683 | O40: 39.581787 | P40: 39.624954 | Q40: 39.679688 | R40: 39.716709 | S40: 39.740402 | T40: 39.750675 | U40: 39.756599 | V40: 39.759041 | W40: 39.758137 | X40: 39.759655 | Y40: 39.75499 | Z40: 39.745636 | AA40: 39.729229 | AB40: 39.710049 | AC40: 39.698334 | AD40: 39.675388 | AE40: 39.66048 | AF40: 39.635681 | AG40: 39.61845 | AH40: 39.589142 | AI40: 0.00833
A41: TKI000:ca_OnRoadNewVeh | B41: On-Road New Light-Duty Vehicle 5/ | C41: 28.524006 | D41: 29.363092 | E41: 30.420794 | F41: 31.858644 | G41: 33.084072 | H41: 34.244457 | I41: 35.994076 | J41: 36.169979 | K41: 36.233746 | L41: 36.304462 | M41: 36.398952 | N41: 36.612297 | O41: 36.804462 | P41: 36.963898 | Q41: 37.147385 | R41: 37.330143 | S41: 37.483685 | T41: 37.612339 | U41: 37.7463 | V41: 37.867699 | W41: 37.973671 | X41: 38.075638 | Y41: 38.16708 | Z41: 38.243473 | AA41: 38.292618 | AB41: 38.326035 | AC41: 38.377235 | AD41: 38.412346 | AE41: 38.45253 | AF41: 38.478436 | AG41: 38.513092 | AH41: 38.524834 | AI41: 0.009742
A42: TKI000:ca_OnRoadNewCar | B42: New Car 5/ | C42: 34.065807 | D42: 35.010216 | E42: 36.530029 | F42: 38.345837 | G42: 40.016972 | H42: 41.170189 | I42: 43.205997 | J42: 43.309448 | K42: 43.282879 | L42: 43.306126 | M42: 43.363548 | N42: 43.512459 | O42: 43.765274 | P42: 43.956223 | Q42: 44.152824 | R42: 44.342316 | S42: 44.523254 | T42: 44.648445 | U42: 44.786369 | V42: 44.919315 | W42: 45.025051 | X42: 45.116795 | Y42: 45.180122 | Z42: 45.23848 | AA42: 45.278004 | AB42: 45.303566 | AC42: 45.33577 | AD42: 45.380699 | AE42: 45.421349 | AF42: 45.46542 | AG42: 45.512367 | AH42: 45.562653 | AI42: 0.009425
A43: TKI000:ca_OnRoadNewTwuk | B43: New Light Truck 5/ | C43: 24.960157 | D43: 25.807436 | E43: 26.768633 | F43: 28.094404 | G43: 29.189699 | H43: 30.353718 | I43: 31.922125 | J43: 32.147099 | K43: 32.178631 | L43: 32.186428 | M43: 32.196941 | N43: 32.240631 | O43: 32.273327 | P43: 32.308525 | Q43: 32.353153 | R43: 32.383339 | S43: 32.402657 | T43: 32.411034 | U43: 32.415863 | V43: 32.417854 | W43: 32.417118 | X43: 32.418354 | Y43: 32.414551 | Z43: 32.406925 | AA43: 32.393547 | AB43: 32.377907 | AC43: 32.368355 | AD43: 32.349648 | AE43: 32.33749 | AF43: 32.317272 | AG43: 32.303223 | AH43: 32.279324 | AI43: 0.00833
... A47: TKI000:ca_FreightTruck | B47: Freight Truck | C47: 7.119165 | D47: 7.17094 | E47: 7.235986 | F47: 7.3073 | G47: 7.388516 | H47: 7.48128 | I47: 7.586367 | J47: 7.703835 | K47: 7.834221 | L47: 7.967885 | M47: 8.108215 | N47: 8.251791 | O47: 8.396469 | P47: 8.537745 | Q47: 8.669586 | R47: 8.791187 | S47: 8.902438 | T47: 9.004374 | U47: 9.096915 | V47: 9.181 | W47: 9.258368 | X47: 9.327685 | Y47: 9.391495 | Z47: 9.448672 | AA47: 9.500283 | AB47: 9.547491 | AC47: 9.591628 | AD47: 9.634123 | AE47: 9.675597 | AF47: 9.716289 | AG47: 9.756433 | AH47: 9.797481 | AI47: 0.010354
B48: (seat miles per gallon)
A49: TKI000:ca_Aircraft | B49: Aircraft | C49: 69.061409 | D49: 69.384445 | E49: 69.706734 | F49: 70.035477 | G49: 70.376755 | H49: 70.734436 | I49: 71.082642 | J49: 71.464615 | K49: 71.895363 | L49: 72.350365 | M49: 72.824806 | N49: 73.293343 | O49: 73.757736 | P49: 74.234024 | Q49: 74.700493 | R49: 75.177055 | S49: 75.653641 | T49: 76.137352 | U49: 76.621902 | V49: 77.107964 | W49: 77.601532 | X49: 78.09996 | Y49: 78.56591 | Z49: 79.031158 | AA49: 79.489037 | AB49: 79.918777 | AC49: 80.345123 | AD49: 80.761703 | AE49: 81.17762 | AF49: 81.591446 | AG49: 81.990547 | AH49: 82.372414 | AI49: 0.005702
B50: (ton miles/thousand Btu)
...

Sheet AEO 35
A1: ORIGINAL EIA CODE | F1: 2020 | G1: 2021 | H1: 2022 | I1: 2023 | J1: 2024 | K1: 2025 | L1: 2026 | M1: 2027 | N1: 2028 | O1: 2029 | P1: 2030 | Q1: 2031 | R1: 2032 | S1: 2033 | T1: 2034 | U1: 2035 | V1: 2036 | W1: 2037 | X1: 2038 | Y1: 2039 | Z1: 2040 | AA1: 2041 | AB1: 2042 | AC1: 2043 | AD1: 2044 | AE1: 2045 | AF1: 2046 | AG1: 2047 | AH1: 2048 | AI1: 2049 | AJ1: 2050 | AK1: Growth (2020-2050)
A10: TEU000 | B10: Table 35. Transportation Sector Energy Use by Mode and Type
B11: https://www.eia.gov/outlooks/aeo/data/browser/#/?id=45-AEO2021&region=0-0&cases=highogs&start=2019&end=2050&f=A&sourcekey=0
B12: Tue Mar 09 2021 10:51:32 GMT-0800 (Pacific Standard Time)
B13: Source: U.S. Energy Information Administration
C14: full name | D14: api key | E14: units | F14: 2020 | G14: 2021 | H14: 2022 | I14: 2023 | J14: 2024 | K14: 2025 | L14: 2026 | M14: 2027 | N14: 2028 | O14: 2029 | P14: 2030 | Q14: 2031 | R14: 2032 | S14: 2033 | T14: 2034 | U14: 2035 | V14: 2036 | W14: 2037 | X14: 2038 | Y14: 2039 | Z14: 2040 | AA14: 2041 | AB14: 2042 | AC14: 2043 | AD14: 2044 | AE14: 2045 | AF14: 2046 | AG14: 2047 | AH14: 2048 | AI14: 2049 | AJ14: 2050 | AK14: Growth (2020-2050)
B15: Energy Use by Mode | D15: 45-AEO2021.2.
B16: Highway | D16: 45-AEO2021.3.
A17: TEU000:ba_Light-DutyVeh | B17: Light-Duty Vehicles | C17: Transportation Energy Use: Highway: Light-Duty Vehicles: High oil and gas supply | D17: 45-AEO2021.4.highogs-d120120a | E17: trillion Btu | F17: 13684.959 | G17: 14333.232 | H17: 14327.021 | I17: 14365.353 | J17: 14366.454 | K17: 14341.867 | L17: 14287.134 | M17: 14207.24 | N17: 14125.377 | O17: 14028.782 | P17: 13931.946 | Q17: 13831.038 | R17: 13740.6 | S17: 13671.223 | T17: 13614.178 | U17: 13578.905 | V17: 13555.065 | W17: 13533.014 | X17: 13512.937 | Y17: 13507.699 | Z17: 13519.428 | AA17: 13531.689 | AB17: 13551.022 | AC17: 13573.049 | AD17: 13591.697 | AE17: 13608.703 | AF17: 13631.723 | AG17: 13650.464 | AH17: 13676.699 | AI17: 13706.515 | AJ17: 13736.45 | AK17: 0
A18: TEU000:ba_Automobiles | B18: Automobiles | C18: Transportation Energy Use: Highway: Light-Duty Vehicles: Automobiles: High oil and gas supply | D18: 45-AEO2021.5.highogs-d120120a | E18: trillion Btu | F18: 5675.0977 | G18: 5849.8979 | H18: 5755.2529 | I18: 5674.1973 | J18: 5571.2588 | K18: 5452.5518 | L18: 5322.6035 | M18: 5185.96 | N18: 5050.46 | O18: 4913.0923 | P18: 4785.4287 | Q18: 4662.6523 | R18: 4550.6763 | S18: 4453.6479 | T18: 4370.249 | U18: 4301.7231 | V18: 4245.416 | W18: 4198.5293 | X18: 4159.6685 | Y18: 4129.9312 | Z18: 4109.8428 | AA18: 4093.1614 | AB18: 4081.1697 | AC18: 4071.9587 | AD18: 4063.4624 | AE18: 4055.2773 | AF18: 4048.9263 | AG18: 4041.3586 | AH18: 4035.5654 | AI18: 4031.2227 | AJ18: 4027.0671 | AK18: -0.011
A19: TEU000:ba_LightTrucks | B19: Light Trucks | C19: Transportation Energy Use: Highway: Light-Duty Vehicles: Light Trucks: High oil and gas supply | D19: 45-AEO2021.6.highogs-d120120a | E19: trillion Btu | F19: 7993.563 | G19: 8466.5332 | H19: 8555.2402 | I19: 8674.8594 | J19: 8779.1953 | K19: 8873.6572 | L19: 8949.2451 | M19: 9006.3877 | N19: 9060.4141 | O19: 9101.5811 | P19: 9132.7764 | Q19: 9154.9971 | R19: 9176.8564 | S19: 9204.7871 | T19: 9231.3809 | U19: 9264.832 | V19: 9297.46 | W19: 9322.4297 | X19: 9341.3252 | Y19: 9365.9111 | Z19: 9397.7852 | AA19: 9426.7773 | AB19: 9458.1357 | AC19: 9489.3994 | AD19: 9516.5684 | AE19: 9541.7832 | AF19: 9571.1719 | AG19: 9597.5029 | AH19: 9629.5479 | AI19: 9663.7188 | AJ19: 9697.8213 | AK19: 0.006
A20: TEU000:ba_Motorcycles | B20: Motorcycles | C20: Transportation Energy Use: Highway: Light-Duty Vehicles: Motorcycles: High oil and gas supply | D20: 45-AEO2021.7.highogs-d120120a | E20: trillion Btu | F20: 16.299149 | G20: 16.800869 | H20: 16.528765 | I20: 16.295639 | J20: 15.999691 | K20: 15.658419 | L20: 15.284882 | M20: 14.89215 | N20: 14.502714 | O20: 14.107929 | P20: 13.741054 | Q20: 13.388216 | R20: 13.066401 | S20: 12.787572 | T20: 12.547906 | U20: 12.350933 | V20: 12.189022 | W20: 12.054244 | X20: 11.942542 | Y20: 11.85706 | Z20: 11.799364 | AA20: 11.751442 | AB20: 11.71702 | AC20: 11.690611 | AD20: 11.666224 | AE20: 11.642757 | AF20: 11.624537 | AG20: 11.602818 | AH20: 11.586204 | AI20: 11.573715 | AJ20: 11.561806 | AK20: -0.011
A21: TEU000:ba_CommercialLig | B21: Commercial Light Trucks | C21: Transportation Energy Use: Highway: Commercial Light Trucks: High oil and gas supply | D21: 45-AEO2021.8.highogs-d120120a | E21: trillion Btu | F21: 800.59766 | G21: 824.58264 | H21: 837.18012 | I21: 842.73663 | J21: 851.00818 | K21: 861.96362 | L21: 867.17664 | M21: 868.25635 | N21: 868.72144 | O21: 868.14349 | P21: 868.26971 | Q21: 869.091 | R21: 871.65924 | S21: 875.05597 | T21: 880.52374 | U21: 888.54584 | V21: 896.60486 | W21: 904.57898 | X21: 913.07678 | Y21: 922.39557 | Z21: 932.01129 | AA21: 942.83514 | AB21: 953.38037 | AC21: 965.23499 | AD21: 976.00677 | AE21: 987.21423 | AF21: 999.34717 | AG21: 1008.7945 | AH21: 1019.4604 | AI21: 1031.4871 | AJ21: 1044.0883 | AK21: 0.009
A22: TEU000:ba_Buses | B22: Buses | C22: Transportation Energy Use: Highway: Buses: High oil and gas supply | D22: 45-AEO2021.9.highogs-d120120a | E22: trillion Btu | F22: 123.60058 | G22: 155.22908 | H22: 178.08673 | I22: 194.79402 | J22: 207.08707 | K22: 215.93285 | L22: 222.4467 | M22: 227.38673 | N22: 229.82677 | O22: 231.57542 | P22: 233.38449 | Q22: 233.90918 | R22: 234.57722 | S22: 234.89816 | T22: 235.11737 | U22: 234.73181 | V22: 234.535 | W22: 234.32896 | X22: 233.97902 | Y22: 233.39026 | Z22: 232.92192 | AA22: 232.25186 | AB22: 231.51384 | AC22: 230.76698 | AD22: 230.02493 | AE22: 229.27586 | AF22: 228.442 | AG22: 227.6967 | AH22: 226.85817 | AI22: 226.28667 | AJ22: 225.79506 | AK22: 0.02
A23: TEU000:ba_Transit | B23: Transit | C23: Transportation Energy Use: Highway: Buses: Transit: High oil and gas supply | D23: 45-AEO2021.10.highogs-d120120a | E23: trillion Btu | F23: 65.868385 | G23: 77.343925 | H23: 85.037193 | I23: 90.397377 | J23: 94.148392 | K23: 96.454201 | L23: 98.028534 | M23: 99.228485 | N23: 98.787506 | O23: 98.326218 | P23: 98.456612 | Q23: 97.730179 | R23: 97.429573 | S23: 97.078491 | T23: 96.865768 | U23: 96.19072 | V23: 95.827606 | W23: 95.546768 | X23: 95.188217 | Y23: 94.635986 | Z23: 94.23497 | AA23: 93.65612 | AB23: 93.025208 | AC23: 92.393784 | AD23: 91.770996 | AE23: 91.134651 | AF23: 90.408363 | AG23: 89.765427 | AH23: 89.013596 | AI23: 88.517876 | AJ23: 88.092033 | AK23: 0.01
A24: TEU000:ba_Intercity | B24: Intercity | C24: Transportation Energy Use: Highway: Buses: Intercity: High oil and gas supply | D24: 45-AEO2021.11.highogs-d120120a | E24: trillion Btu | F24: 21.389296 | G24: 24.819853 | H24: 27.510082 | I24: 29.622658 | J24: 31.287823 | K24: 32.605827 | L24: 33.663296 | M24: 34.520813 | N24: 35.224197 | O24: 35.81303 | P24: 36.317593 | Q24: 36.759636 | R24: 37.152344 | S24: 37.510296 | T24: 37.844872 | U24: 38.157986 | V24: 38.449917 | W24: 38.72361 | X24: 38.985104 | Y24: 39.238808 | Z24: 39.486942 | AA24: 39.72662 | AB24: 39.958668 | AC24: 40.184944 | AD24: 40.404293 | AE24: 40.622166 | AF24: 40.834713 | AG24: 41.040451 | AH24: 41.248081 | AI24: 41.453495 | AJ24: 41.657665 | AK24: 0.022
A25: TEU000:ba_School | B25: School | C25: Transportation Energy Use: Highway: Buses: School: High oil and gas supply | D25: 45-AEO2021.12.highogs-d120120a | E25: trillion Btu | F25: 36.342903 | G25: 53.065319 | H25: 65.539474 | I25: 74.77401 | J25: 81.650841 | K25: 86.872803 | L25: 90.754913 | M25: 93.637444 | N25: 95.815033 | O25: 97.436134 | P25: 98.610291 | Q25: 99.419357 | R25: 99.995285 | S25: 100.30936 | T25: 100.40678 | U25: 100.38309 | V25: 100.25748 | W25: 100.05856 | X25: 99.805702 | Y25: 99.51545 | Z25: 99.200005 | AA25: 98.869118 | AB25: 98.529976 | AC25: 98.188255 | AD25: 97.849648 | AE25: 97.519051 | AF25: 97.198906 | AG25: 96.890816 | AH25: 96.596497 | AI25: 96.315292 | AJ25: 96.04538 | AK25: 0.033
A26: TEU000:ba_FreightTrucks | B26: Freight Trucks | C26: Transportation Energy Use: Highway: Freight Trucks: High oil and gas supply | D26: 45-AEO2021.13.highogs-d120120a | E26: trillion Btu | F26: 5217.8584 | G26: 5322.7695 | H26: 5462.249 | I26: 5509.6768 | J26: 5566.189 | K26: 5614.4268 | L26: 5611.2627 | M26: 5579.9849 | N26: 5546.2661 | O26: 5504.2886 | P26: 5469.7124 | Q26: 5438.3926 | R26: 5413.3032 | S26: 5386.6934 | T26: 5378.145 | U26: 5393.2607 | V26: 5407.6289 | W26: 5423.5879 | X26: 5448.6401 | Y26: 5481.9277 | Z26: 5512.1758 | AA26: 5555.085 | AB26: 5607.7852 | AC26: 5675.5957 | AD26: 5732.5215 | AE26: 5793.834 | AF26: 5843.8721 | AG26: 5892.3438 | AH26: 5949.0996 | AI26: 6010.8965 | AJ26: 6080.1992 | AK26: 0.005
A27: TEU000:ba_LightMedium | B27: Light Medium | C27: Transportation Energy Use: Highway: Freight Trucks: Light Medium: High oil and gas supply | D27: 45-AEO2021.14.highogs-d120120a | E27: trillion Btu | F27: 623.06995 | G27: 645.39587 | H27: 666.46094 | I27: 672.76428 | J27: 679.08014 | K27: 685.09302 | L27: 686.81488 | M27: 689.4306 | N27: 695.90314 | O27: 704.39606 | P27: 715.78516 | Q27: 728.40607 | R27: 741.20001 | S27: 752.46381 | T27: 764.91388 | U27: 778.96106 | V27: 790.86975 | W27: 801.79034 | X27: 813.50751 | Y27: 825.59967 | Z27: 835.62042 | AA27: 847.15546 | AB27: 859.51312 | AC27: 873.85864 | AD27: 886.58179 | AE27: 900.4129 | AF27: 912.65735 | AG27: 925.97638 | AH27: 941.71063 | AI27: 957.63281 | AJ27: 974.67029 | AK27: 0.015
A28: TEU000:ba_Medium | B28: Medium | C28: Transportation Energy Use: Highway: Freight Trucks: Medium: High oil and gas supply | D28: 45-AEO2021.15.highogs-d120120a | E28: trillion Btu | F28: 857.06537 | G28: 869.86615 | H28: 890.51807 | I28: 896.80109 | J28: 905.21356 | K28: 912.46588 | L28: 913.59228 | M28: 912.76141 | N28: 914.32025 | O28: 915.86731 | P28: 919.06012 | Q28: 922.55646 | R28: 927.62286 | S28: 931.74396 | T28: 938.57819 | U28: 949.5282 | V28: 960.74689 | W28: 973.51715 | X28: 988.40875 | Y28: 1006.5817 | Z28: 1024.9167 | AA28: 1046.2407 | AB28: 1069.5592 | AC28: 1096.8451 | AD28: 1122.9235 | AE28: 1150.4531 | AF28: 1176.5758 | AG28: 1203.0889 | AH28: 1232.1707 | AI28: 1263.6315 | AJ28: 1297.5896 | AK28: 0.014
A29: TEU000:ba_Large(>26000p | B29: Large (> 26000 pounds) | C29: Transportation Energy Use: Highway: Freight Trucks: Large: High oil and gas supply | D29: 45-AEO2021.16.highogs-d120120a | E29: trillion Btu | F29: 3737.7229 | G29: 3807.5073 | H29: 3905.2695 | I29: 3940.1116 | J29: 3981.8948 | K29: 4016.8679 | L29: 4010.8555 | M29: 3977.7935 | N29: 3936.0427 | O29: 3884.0256 | P29: 3834.8677 | Q29: 3787.4297 | R29: 3744.4802 | S29: 3702.4858 | T29: 3674.6531 | U29: 3664.7715 | V29: 3656.0122 | W29: 3648.28 | X29: 3646.7239 | Y29: 3649.7461 | Z29: 3651.6387 | AA29: 3661.6887 | AB29: 3678.7134 | AC29: 3704.8914 | AD29: 3723.0164 | AE29: 3742.968 | AF29: 3754.6394 | AG29: 3763.2793 | AH29: 3775.218 | AI29: 3789.6326 | AJ29: 3807.9399 | AK29: 0.001
B30: Non-Highway | D30: 45-AEO2021.18.
A31: TEU000:ca_Air | B31: Air | C31: Transportation Energy Use: Non-Highway: Air: High oil and gas supply | D31: 45-AEO2021.19.highogs-d120120a | E31: trillion Btu | F31: 1860.4854 | G31: 2530.9844 | H31: 2826.3455 | I31: 2963.3054 | J31: 3051.7676 | K31: 3120.2192 | L31: 3144.2419 | M31: 3161.6294 | N31: 3182.7922 | O31: 3201.8508 | P31: 3222.4722 | Q31: 3248.7065 | R31: 3287.2988 | S31: 3325.2964 | T31: 3367.7896 | U31: 3416.8149 | V31: 3457.4727 | W31: 3492.2017 | X31: 3528.9043 | Y31: 3570.2961 | Z31: 3622.0222 | AA31: 3669.8469 | AB31: 3718.9998 | AC31: 3765.7593 | AD31: 3814.1929 | AE31: 3866.814 | AF31: 3914.7515 | AG31: 3951.364 | AH31: 3990.6257 | AI31: 4026.4133 | AJ31: 4062.8081 | AK31: 0.026
A32: TEU000:ca_GeneralAviati | B32: General Aviation | C32: Transportation Energy Use: Non-Highway: Air: General Aviation: High oil and gas supply | D32: 45-AEO2021.20.highogs-d120120a | E32: trillion Btu | F32: 109.97633 | G32: 141.88948 | H32: 155.94163 | I32: 162.45311 | J32: 166.65692 | K32: 169.90941 | L32: 171.04748 | M32: 171.87045 | N32: 172.87425 | O32: 173.77844 | P32: 174.75746 | Q32: 176.00456 | R32: 177.84047 | S32: 179.64813 | T32: 181.67046 | U32: 184.0038 | V32: 185.9389 | W32: 187.59193 | X32: 189.3391 | Y32: 191.30975 | Z32: 193.77246 | AA32: 196.04944 | AB32: 198.38971 | AC32: 200.61627 | AD32: 202.92221 | AE32: 205.4279 | AF32: 207.71048 | AG32: 209.45377 | AH32: 211.3233 | AI32: 213.02757 | AJ32: 214.76041 | AK32: 0.023
A33: TEU000:ca_DomesticAirCa | B33: Domestic Passenger | C33: Transportation Energy Use: Non-Highway: Air: Domestic Passenger: High oil and gas supply | D33: 45-AEO2021.21.highogs-d120120a | E33: trillion Btu | F33: 1029.3035 | G33: 1377.4302 | H33: 1491.1099 | I33: 1527.3287 | J33: 1540.603 | K33: 1575.2826 | L33: 1594.6243 | M33: 1603.1229 | N33: 1606.5917 | O33: 1607.7135 | P33: 1610.0349 | Q33: 1616.2908 | R33: 1629.0068 | S33: 1642.5435 | T33: 1659.3156 | U33: 1678.5675 | V33: 1694.2118 | W33: 1706.4603 | X33: 1719.7704 | Y33: 1737.08 | Z33: 1758.8617 | AA33: 1779.666 | AB33: 1799.6539 | AC33: 1818.678 | AD33: 1836.4475 | AE33: 1856.6439 | AF33: 1873.9916 | AG33: 1887.5896 | AH33: 1904.7295 | AI33: 1921.5889 | AJ33: 1938.8723 | AK33: 0.021
A34: TEU000:ca_International | B34: International Passenger | C34: Transportation Energy Use: Non-Highway: Air: International Passenger: High oil and gas supply | D34: 45-AEO2021.22.highogs-d120120a | E34: trillion Btu | F34: 162.01057 | G34: 492.52274 | H34: 669.41522 | I34: 750.97778 | J34: 811.16065 | K34: 837.4071 | L34: 840.55621 | M34: 845.41003 | N34: 854.7381 | O34: 864.04321 | P34: 873.57477 | Q34: 884.18176 | R34: 898.26648 | S34: 911.64954 | T34: 925.93701 | U34: 942.49945 | V34: 956.36585 | W34: 968.7132 | X34: 981.62439 | Y34: 995.19794 | Z34: 1012.1129 | AA34: 1027.5292 | AB34: 1044.0427 | AC34: 1059.8073 | AD34: 1076.9177 | AE34: 1095.1249 | AF34: 1112.1973 | AG34: 1125.2657 | AH34: 1138.3204 | AI34: 1149.8088 | AJ34: 1161.4449 | AK34: 0.068
A35: TEU000:ca_FreightCarrie | B35: Dedicated Freight | C35: Transportation Energy Use: Non-Highway: Air: Dedicated Freight: High oil and gas supply | D35: 45-AEO2021.23.highogs-d120120a | E35: trillion Btu | F35: 559.19495 | G35: 519.14203 | H35: 509.87872 | I35: 522.54559 | J35: 533.34705 | K35: 537.62024 | L35: 538.01386 | M35: 541.22595 | N35: 548.58813 | O35: 556.31574 | P35: 564.1051 | Q35: 572.22961 | R35: 582.18518 | S35: 591.45514 | T35: 600.86682 | U35: 611.74402 | V35: 620.95605 | W35: 629.43628 | X35: 638.17041 | Y35: 646.7085 | Z35: 657.27508 | AA35: 666.6023 | AB35: 676.91339 | AC35: 686.65765 | AD35: 697.90521 | AE35: 709.61707 | AF35: 720.85217 | AG35: 729.05499 | AH35: 736.25275 | AI35: 741.98798 | AJ35: 747.73035 | AK35: 0.01
A36: TEU000:ca_Water | B36: Water | C36: Transportation Energy Use: Non-Highway: Water: High oil and gas supply | D36: 45-AEO2021.24.highogs-d120120a | E36: trillion Btu | F36: 1129.1088 | G36: 1157.2632 | H36: 1251.9425 | I36: 1271.0579 | J36: 1220.1064 | K36: 1222.1813 | L36: 1231.5403 | M36: 1205.2488 | N36: 1202.4742 | O36: 1190.4596 | P36: 1189.082 | Q36: 1203.5217 | R36: 1186.6602 | S36: 1184.9104 | T36: 1180.7228 | U36: 1193.8921 | V36: 1177.7051 | W36: 1175.0314 | X36: 1182.9781 | Y36: 1167.7097 | Z36: 1164.3445 | AA36: 1175.8888 | AB36: 1158.8889 | AC36: 1157.1489 | AD36: 1149.3973 | AE36: 1148.7852 | AF36: 1143.7438 | AG36: 1139.9766 | AH36: 1139.2001 | AI36: 1136.608 | AJ36: 1132.9697 | AK36: 0
A37: TEU000:ca_Freight | B37: Freight | C37: Transportation Energy Use: Non-Highway: Water: Freight: High oil and gas supply | D37: 45-AEO2021.25.highogs-d120120a | E37: trillion Btu | F37: 933.23035 | G37: 960.6062 | H37: 1052.2262 | I37: 1069.5435 | J37: 1017.8489 | K37: 1019.6077 | L37: 1029.6858 | M37: 1004.8707 | N37: 1003.7998 | O37: 993.62921 | P37: 994.01324 | Q37: 1009.9661 | R37: 994.1709 | S37: 993.52716 | T37: 990.23901 | U37: 1004.0739 | V37: 988.7948 | W37: 987.27228 | X37: 996.31964 | Y37: 981.9082 | Z37: 979.12146 | AA37: 991.30054 | AB37: 975.00702 | AC37: 973.97424 | AD37: 967.06848 | AE37: 967.10553 | AF37: 962.83832 | AG37: 960.09705 | AH37: 960.05969 | AI37: 958.24249 | AJ37: 955.39801 | AK37: 0.001
A38: TEU000:ca_DomesticShipp | B38: Domestic Shipping | C38: Transportation Energy Use: Non-Highway: Water: Freight: Domestic Shipping: High oil and gas supply | D38: 45-AEO2021.26.highogs-d120120a | E38: trillion Btu | F38: 77.343407 | G38: 79.141403 | H38: 78.228264 | I38: 77.350044 | J38: 76.446533 | K38: 75.055573 | L38: 73.204681 | M38: 71.058418 | N38: 68.994972 | O38: 66.833633 | P38: 64.753128 | Q38: 63.638058 | R38: 62.605038 | S38: 61.510983 | T38: 60.561947 | U38: 59.665359 | V38: 58.721436 | W38: 57.711258 | X38: 56.658974 | Y38: 55.745102 | Z38: 54.692238 | AA38: 54.265388 | AB38: 53.873783 | AC38: 53.634262 | AD38: 53.239914 | AE38: 52.87286 | AF38: 52.373196 | AG38: 51.890907 | AH38: 51.370388 | AI38: 50.910122 | AJ38: 50.533489 | AK38: -0.014
A39: TEU000:da_International | B39: International Shipping | C39: Transportation Energy Use: Non-Highway: Water: Freight: International Shipping: High oil and gas supply | D39: 45-AEO2021.27.highogs-d120120a | E39: trillion Btu | F39: 855.88696 | G39: 881.46478 | H39: 973.99793 | I39: 992.19336 | J39: 941.40234 | K39: 944.55212 | L39: 956.48108 | M39: 933.81226 | N39: 934.80481 | O39: 926.79559 | P39: 929.26013 | Q39: 946.32806 | R39: 931.56586 | S39: 932.01617 | T39: 929.67706 | U39: 944.40857 | V39: 930.07336 | W39: 929.56103 | X39: 939.66065 | Y39: 926.16309 | Z39: 924.4292 | AA39: 937.03516 | AB39: 921.13324 | AC39: 920.33997 | AD39: 913.82855 | AE39: 914.23267 | AF39: 910.46515 | AG39: 908.20612 | AH39: 908.68933 | AI39: 907.3324 | AJ39: 904.8645 | AK39: 0.002
A40: TEU000:da_RecreationalB | B40: Recreational Boats | C40: Transportation Energy Use: Non-Highway: Water: Recreational Boats: High oil and gas supply | D40: 45-AEO2021.28.highogs-d120120a | E40: trillion Btu | F40: 195.87843 | G40: 196.65694 | H40: 199.71631 | I40: 201.51434 | J40: 202.25748 | K40: 202.57369 | L40: 201.85445 | M40: 200.37804 | N40: 198.67445 | O40: 196.83032 | P40: 195.06877 | Q40: 193.55562 | R40: 192.48926 | S40: 191.38321 | T40: 190.48383 | U40: 189.81821 | V40: 188.91023 | W40: 187.75908 | X40: 186.65848 | Y40: 185.8015 | Z40: 185.22307 | AA40: 184.58832 | AB40: 183.88181 | AC40: 183.17465 | AD40: 182.32883 | AE40: 181.67963 | AF40: 180.9055 | AG40: 179.87953 | AH40: 179.14038 | AI40: 178.36557 | AJ40: 177.57169 | AK40: -0.003
A41: TEU000:da_Rail | B41: Rail | C41: Transportation Energy Use: Non-Highway: Rail: High oil and gas supply | D41: 45-AEO2021.29.highogs-d120120a | E41: trillion Btu | F41: 461.76639 | G41: 491.05136 | H41: 497.25409 | I41: 498.29584 | J41: 498.00287 | K41: 483.20465 | L41: 487.16257 | M41: 485.19531 | N41: 488.07013 | O41: 490.24463 | P41: 492.73157 | Q41: 493.54889 | R41: 493.9744 | S41: 495.27838 | T41: 495.26675 | U41: 496.70953 | V41: 497.9765 | W41: 498.69684 | X41: 497.479 | Y41: 499.69305 | Z41: 499.10703 | AA41: 500.07611 | AB41: 502.25479 | AC41: 505.43637 | AD41: 504.1955 | AE41: 505.57495 | AF41: 505.80637 | AG41: 507.0365 | AH41: 508.25165 | AI41: 509.73273 | AJ41: 512.97174 | AK41: 0.004
A42: TEU000:da_Freight | B42: Freight | C42: Transportation Energy Use: Non-Highway: Rail: Freight: High oil and gas supply | D42: 45-AEO2021.30.highogs-d120120a | E42: trillion Btu | F42: 432.32916 | G42: 455.80057 | H42: 457.32019 | I42: 454.81757 | J42: 451.84665 | K42: 435.03867 | L42: 437.54752 | M42: 434.49982 | N42: 437.06894 | O42: 438.99457 | P42: 440.98004 | Q42: 441.53027 | R42: 441.40082 | S42: 442.16769 | T42: 441.50205 | U42: 442.37979 | V42: 443.02426 | W42: 443.14713 | X42: 441.33752 | Y42: 442.94101 | Z42: 441.56534 | AA42: 441.80859 | AB42: 443.27573 | AC42: 445.72418 | AD42: 443.77713 | AE42: 444.37201 | AF42: 443.88855 | AG42: 444.47339 | AH42: 444.99793 | AI42: 445.72116 | AJ42: 448.21558 | AK42: 0.001
... A53: TEU000:fa_Total | B53: Total | C53: Transportation Energy Use: Total: High oil and gas supply | D53: 45-AEO2021.43.highogs-d120120a | E53: trillion Btu | F53: 24641.816 | G53: 26248.666 | H53: 26805.998 | I53: 27035.342 | J53: 27134.359 | K53: 27234.799 | L53: 27191.32 | M53: 27084.865 | N53: 26996.002 | O53: 26866.41 | P53: 26748.799 | Q53: 26660.07 | R53: 26573.197 | S53: 26520.012 | T53: 26498.09 | U53: 26553.664 | V53: 26586.883 | W53: 26631.479 | X53: 26696.67 | Y53: 26767.367 | Z53: 26871.051 | AA53: 27000.164 | AB53: 27121.412 | AC53: 27278.543 | AD53: 27415.6 | AE53: 27565.312 | AF53: 27701.846 | AG53: 27821.959 | AH53: 27950.746 | AI53: 28088.564 | AJ53: 28244.232 | AK53: 0.005
B54: Energy Use by Type | D54: 45-AEO2021.45.
A55: TEU000:ga_MotorGasoline | B55: Motor Gasoline excluding E85 | C55: Transportation Energy Use: Petroleum: Motor Gasoline: High oil and gas supply | D55: 45-AEO2021.46.highogs-d120120a | E55: trillion Btu | F55: 14809.331 | G55: 15470.562 | H55: 15477.318 | I55: 15509.706 | J55: 15508.433 | K55: 15483.517 | L55: 15421.747 | M55: 15333.079 | N55: 15245.05 | O55: 15143.332 | P55: 15043.969 | Q55: 14940.797 | R55: 14850.533 | S55: 14780.868 | T55: 14725.552 | U55: 14695.301 | V55: 14674.445 | W55: 14655.884 | X55: 14640.091 | Y55: 14640.239 | Z55: 14655.854 | AA55: 14675.101 | AB55: 14702.387 | AC55: 14734.696 | AD55: 14761.429 | AE55: 14788.444 | AF55: 14820.81 | AG55: 14848.021 | AH55: 14885.904 | AI55: 14929.089 | AJ55: 14974.693 | AK55: 0
A56: TEU000:ga_Ethanol | B56: E85 | C56: Transportation Energy Use: E85: High oil and gas supply | D56: 45-AEO2021.47.highogs-d120120a | E56: trillion Btu | F56: 33.666061 | G56: 36.292164 | H56: 35.002701 | I56: 36.768921 | J56: 37.090172 | K56: 37.279301 | L56: 37.273434 | M56: 36.962608 | N56: 36.692116 | O56: 36.407269 | P56: 36.183594 | Q56: 36.116623 | R56: 36.088921 | S56: 36.198486 | T56: 36.388977 | U56: 36.925545 | V56: 37.477287 | W56: 38.130039 | X56: 38.828465 | Y56: 39.735065 | Z56: 40.706123 | AA56: 41.727245 | AB56: 42.842529 | AC56: 43.978745 | AD56: 45.153854 | AE56: 46.265217 | AF56: 47.409328 | AG56: 48.760159 | AH56: 49.995644 | AI56: 51.544422 | AJ56: 53.091187 | AK56: 0.015
A57: TEU000:ga_Distillate(di | B57: Diesel | C57: Transportation Energy Use: Petroleum: Diesel: High oil and gas supply | D57: 45-AEO2021.48.highogs-d120120a | E57: trillion Btu | F57: 6144.374 | G57: 6254.561 | H57: 6296.688 | I57: 6333.9224 | J57: 6469.3887 | K57: 6508.3208 | L57: 6497.1807 | M57: 6493.1206 | N57: 6455.3403 | O57: 6414.4653 | P57: 6368.2964 | Q57: 6301.3911 | R57: 6279.1006 | S57: 6236.5176 | T57: 6213.1655 | U57: 6192.251 | V57: 6207.4717 | W57: 6203.5488 | X57: 6192.0122 | Y57: 6220.2158 | Z57: 6226.5527 | AA57: 6228.9126 | AB57: 6273.5908 | AC57: 6314.6074 | AD57: 6347.5444 | AE57: 6376.3735 | AF57: 6399.9995 | AG57: 6418.7915 | AH57: 6440.9194 | AI57: 6466.8232 | AJ57: 6500.1226 | AK57: 0.002
A58: TEU000:ga_JetFuel(keros | B58: Jet Fuel (kerosene & naphtha) | C58: Transportation Energy Use: Petroleum: Jet Fuel: High oil and gas supply | D58: 45-AEO2021.49.highogs-d120120a | E58: trillion Btu | F58: 2239.7639 | G58: 2917.0544 | H58: 3212.9678 | I58: 3340.0581 | J58: 3422.0215 | K58: 3490.0879 | L58: 3513.1729 | M58: 3530.4417 | N58: 3553.7649 | O58: 3571.9607 | P58: 3591.0972 | Q58: 3617.2712 | R58: 3656.4937 | S58: 3695.1418 | T58: 3738.2942 | U58: 3787.9761 | V58: 3829.3232 | W58: 3864.7639 | X58: 3902.1855 | Y58: 3944.3027 | Z58: 3996.7605 | AA58: 4045.3213 | AB58: 4095.2144 | AC58: 4142.7163 | AD58: 4191.8945 | AE58: 4245.2622 | AF58: 4293.9473 | AG58: 4331.3066 | AH58: 4371.3149 | AI58: 4407.8477 | AJ58: 4444.9878 | AK58: 0.023
...

Sheet AEO 36
B1: ORIGINAL EIA CODE | G1: 2020 | H1: 2021 | I1: 2022 | J1: 2023 | K1: 2024 | L1: 2025 | M1: 2026 | N1: 2027 | O1: 2028 | P1: 2029 | Q1: 2030 | R1: 2031 | S1: 2032 | T1: 2033 | U1: 2034 | V1: 2035 | W1: 2036 | X1: 2037 | Y1: 2038 | Z1: 2039 | AA1: 2040 | AB1: 2041 | AC1: 2042 | AD1: 2043 | AE1: 2044 | AF1: 2045 | AG1: 2046 | AH1: 2047 | AI1: 2048 | AJ1: 2049 | AK1: 2050 | AL1: Growth (2020-2050)
B10: TEF000 | C10: Table 36. Transportation Sector Energy Use by Fuel Type Within a Mode
C11: https://www.eia.gov/outlooks/aeo/data/browser/#/?id=46-AEO2021&region=0-0&cases=highogs&start=2020&end=2050&f=A&linechart=highogs-d120120a.2-46-AEO2021&sourcekey=0
C12: Tue Mar 09 2021 10:55:36 GMT-0800 (Pacific Standard Time)
C13: Source: U.S. Energy Information Administration
D14: full name | E14: api key | F14: units | G14: 2020 | H14: 2021 | I14: 2022 | J14: 2023 | K14: 2024 | L14: 2025 | M14: 2026 | N14: 2027 | O14: 2028 | P14: 2029 | Q14: 2030 | R14: 2031 | S14: 2032 | T14: 2033 | U14: 2034 | V14: 2035 | W14: 2036 | X14: 2037 | Y14: 2038 | Z14: 2039 | AA14: 2040 | AB14: 2041 | AC14: 2042 | AD14: 2043 | AE14: 2044 | AF14: 2045 | AG14: 2046 | AH14: 2047 | AI14: 2048 | AJ14: 2049 | AK14: 2050 | AL14: Growth (2020-2050)
B15: TEF000:ba_Total | C15: Light-Duty Vehicle | D15: Transportation Energy Use: Light-Duty Vehicle: Total: High oil and gas supply | E15: 46-AEO2021.2.highogs-d120120a | F15: trillion Btu | G15: 13684.958 | H15: 14333.23 | I15: 14327.021 | J15: 14365.351 | K15: 14366.454 | L15: 14341.867 | M15: 14287.132 | N15: 14207.238 | O15: 14125.375 | P15: 14028.778 | Q15: 13931.945 | R15: 13831.037 | S15: 13740.597 | T15: 13671.221 | U15: 13614.176 | V15: 13578.902 | W15: 13555.062 | X15: 13533.011 | Y15: 13512.933 | Z15: 13507.697 | AA15: 13519.425 | AB15: 13531.686 | AC15: 13551.019 | AD15: 13573.045 | AE15: 13591.691 | AF15: 13608.698 | AG15: 13631.718 | AH15: 13650.46 | AI15: 13676.694 | AJ15: 13706.509 | AK15: 13736.444 | AL15: 0
B16: TEF000:ba_MotorGasoline | C16: Motor Gasoline excluding E85 | D16: Transportation Energy Use: Light-Duty Vehicle: Motor Gasoline: High oil and gas supply | E16: 46-AEO2021.3.highogs-d120120a | F16: trillion Btu | G16: 13581.067 | H16: 14217.864 | I16: 14204.684 | J16: 14234.458 | K16: 14228.428 | L16: 14196.801 | M16: 14134.474 | N16: 14047.195 | O16: 13957.598 | P16: 13853.153 | Q16: 13748.133 | R16: 13637.929 | S16: 13537.845 | T16: 13457.947 | U16: 13389.198 | V16: 13341.722 | W16: 13304.275 | X16: 13267.979 | Y16: 13232.908 | Z16: 13211.613 | AA16: 13206.084 | AB16: 13201.54 | AC16: 13203.803 | AD16: 13208.375 | AE16: 13209.466 | AF16: 13209.275 | AG16: 13214.956 | AH16: 13216.332 | AI16: 13224.988 | AJ16: 13236.756 | AK16: 13248.583 | AL16: -0.001
