Workbook

Sheet About
A1: MPCbS Max Potential Capacity by Source
A3: Source: | B3: Wind and Solar
B4: Technology Outlook on Wind and Solar Power toward China’s Carbon Neutrality Goal
B5: Institute for Carbon Neutrality, Tsinghua University
B6: https://www.icon.tsinghua.edu.cn/__local/6/95/2F/2E40B08AF86764D6680DC9C7404_3BCB5C27_1CD0BD9.pdf
B8: Hydro
B9: China Society for Hydropower Engineering
B10: Overview of China Hydropower
B11: 2009
B12: 中国水能资源概况
B14: Biomass and MSW
B15: 2020-2024 China Biomass Energy Utilization Industry In-depth Analysis and Development Planning Consultation Report
B16: https://www.163.com/dy/article/FOOLBG0T0538A21J.html
B18: Geothermal
B19: China Energy News
B20: https://paper.people.com.cn/zgnyb/html/2023-07/17/content_26007385.htm
B22: Solar Thermal
B23: China's New Energy Base Development and New Pumped Storage Report
B24: Global Energy Internet Development Cooperation Organization
B25: https://www.iwra.org/proceedings/congress/resource/IWRA2023_Beijing_China_20230912_SS_2_1_ORAL_20230904_%E4%B8%AD%E5%9B%BD%E6%96%B0%E8%83%BD%E6%BA%90%E5%9F%BA%E5%9C%B0%E5%8C%96%E5%BC%80%E5%8F%91%E4%B8%8E%E6%96%B0%E5%9E%8B%E6%8A%BD%E6%B0%B4%E8%93%84%E8%83%BDv3.pdf
A27: Notes:
A28: Though we have a value for thermal resources and nuclear, we assume these actually
A29: have unlimited potential because there is no technical resource limitation for China.
A31: Data are gathered from different sources. Normally the technical potential (技术可开发量）is used here.

Sheet Wind & Solar - Most Updated
P6: 技术可开发量 | U6: 每年理论蕴藏量
N7: 区域电网 | O7: 省份 | P7: 风能(吉瓦) | Q7: 陆上风能(吉瓦) | R7: 海上风能(吉瓦) | S7: 光伏(吉瓦) | T7: 集中式光伏(吉瓦) | U7: 分布式光伏(吉瓦) | V7: 每年理论超载量-风能(万亿千瓦时) | W7: 每年理论超载量-光伏(万亿千瓦时) | X7: 年消耗量(万亿千瓦时)
N8: 东南 | O8: 重庆 | P8: 43 | Q8: 43 | R8: 0 | S8: 22 | T8: 1 | U8: 21 | V8: 0.108 | W8: 0.003 | X8: 0.1187
O9: 贵州 | P9: 109 | Q9: 109 | R9: 0 | S9: 104 | T9: 76 | U9: 28 | V9: 0.296 | W9: 0.105 | X9: 0.1586
O10: 四川 | P10: 223 | Q10: 223 | R10: 0 | S10: 157 | T10: 75 | U10: 82 | V10: 0.621 | W10: 0.182 | X10: 0.2865
O11: 西藏 | P11: 524 | Q11: 524 | R11: 0 | S11: 3332 | T11: 3327 | U11: 4 | V11: 1.375 | W11: 6.177 | X11: 0.0082
N12: 华南 | O12: 广东 | P12: 677 | Q12: 141 | R12: 536 | S12: 202 | T12: 19 | U12: 182 | V12: 1.977 | W12: 0.257 | X12: 0.6926
O13: 广西 | P13: 250 | Q13: 181 | R13: 69 | S13: 187 | T13: 101 | U13: 86 | V13: 0.708 | W13: 0.222 | X13: 0.2025
O14: 海南 | P14: 246 | Q14: 45 | R14: 201 | S14: 29 | T14: 10 | U14: 19 | V14: 0.563 | W14: 0.033 | X14: 0.0362
O15: 台湾 | P15: 10 | Q15: 10 | R15: 0 | S15: 28 | T15: 0 | U15: 28
O16: 香港 | P16: 0 | Q16: 0 | R16: 0 | S16: 3 | T16: 0 | U16: 3
O17: 云南 | P17: 132 | Q17: 132 | R17: 0 | S17: 115 | T17: 60 | U17: 55 | V17: 0.374 | W17: 0.159 | X17: 0.2026
N18: 华中 | O18: 河南 | P18: 291 | Q18: 291 | R18: 0 | S18: 303 | T18: 14 | U18: 289 | V18: 0.869 | W18: 0.377 | X18: 0.3392
O19: 湖北 | P19: 206 | Q19: 206 | R19: 0 | S19: 157 | T19: 33 | U19: 124 | V19: 0.558 | W19: 0.188 | X19: 0.2144
O20: 湖南 | P20: 174 | Q20: 174 | R20: 0 | S20: 91 | T20: 9 | U20: 83 | V20: 0.462 | W20: 0.096 | X20: 0.1929
O21: 江西 | P21: 152 | Q21: 152 | R21: 0 | S21: 97 | T21: 27 | U21: 70 | V21: 0.423 | W21: 0.109 | X21: 0.1627
N22: 华东 | O22: 安徽 | P22: 225 | Q22: 225 | R22: 0 | S22: 233 | T22: 11 | U22: 222 | V22: 0.679 | W22: 0.28 | X22: 0.2428
O23: 福建 | P23: 321 | Q23: 32 | R23: 289 | S23: 91 | T23: 18 | U23: 73 | V23: 0.957 | W23: 0.102 | X23: 0.2483
O24: 江苏 | P24: 441 | Q24: 177 | R24: 264 | S24: 302 | T24: 5 | U24: 297 | V24: 1.2 | W24: 0.372 | X24: 0.6374
O25: 上海 | P25: 55 | Q25: 10 | R25: 45 | S25: 38 | T25: 0 | U25: 37 | V25: 0.15 | W25: 0.051 | X25: 0.1576
O26: 浙江 | P26: 429 | Q26: 50 | R26: 379 | S26: 112 | T26: 4 | U26: 108 | V26: 1.163 | W26: 0.121 | X26: 0.483
N27: 全国 | P27: 10950 | Q27: 8694 | R27: 2254 | S27: 45600 | T27: 41878 | U27: 3726 | V27: 29.31 | W27: 66.53 | X27: 7.511
B38: Source: | C38: 中国碳中和目标下的风光技术展望
C39: Technology Outlook on Wind and Solar Power toward China’s Carbon Neutrality Goal
C40: (by 清华碳中和研究院)

Sheet Wind IEA
A1: Total tech potential in TWh | B1: 8323
A2: Capacity Factor | B2: 0.4
A3: Calculated potential in MW | B3: =B1*1000000/B2/8760 -> 2375285.4
A5: Total capacity potential (GW) | B5: 832.65

Sheet Hydro
B2: 省市区 | C2: 理论蕴藏量 | E2: 技术可开发量 | H2: 经济可开发量
C3: 年电量（亿kWh) | D3: 平均功率（MW) | E3: 电站数（座） | F3: 装机容量（MW） | G3: 年发电量（亿kWh） | H3: 电站数（座） | I3: 装机容量（MW） | J3: 年发电量（亿kWh）
B4: 京津冀 | C4: 199.26 | D4: 2274.6 | E4: 179+12 | F4: 1751.3 | G4: 37.12 | H4: 10441/2 | I4: 1252.5 | J4: 25.27
B5: 山西 | C5: 493.61 | D5: 5634.8 | E5: 169+7/2 | F5: 4020.4 | G5: 120.55 | H5: 149+7/2 | I5: 3973.8 | J5: 118.96
B6: 内蒙古 | C6: 509.14 | D6: 5812.2 | E6: 103+102 | F6: 2624.5 | G6: 73.45 | H6: 82+10/2 | I6: 2567.3 | J6: 71.91
B7: 辽宁 | C7: 177.92 | D7: 2031 | E7: 200+3/2 | F7: 1767.3 | G7: 60.39 | H7: 171+3/2 | I7: 1728.9 | J7: 59.14
B8: 吉林 | C8: 301.3 | D8: 3439.6 | E8: 188+14/2 | F8: 5115.5 | G8: 117.93 | H8: 157+14/2 | I8: 5042.3 | J8: 115.47
B9: 黑龙江 | C9: 664.2 | D9: 7582.2 | E9: 166+11/2 | F9: 8161.9 | G9: 238.31 | H9: 111+11/2 | I9: 7226.9 | J9: 211.79
B10: 上海江苏 | C10: 152.2 | D10: 1738.1 | E10: 22 | F10: 57.9 | G10: 1.73 | H10: 14 | I10: 22.4 | J10: 0.67
B11: 浙江 | C11: 537.59 | D11: 6136.8 | E11: 1070+4/2 | F11: 6643.8 | G11: 161.46 | H11: 1064+4/2 | I11: 6613.2 | J11: 160.72
B12: 安徽 | C12: 273.5 | D12: 3122 | E12: 157 | F12: 1074 | G12: 30 | H12: 144 | I12: 996 | J12: 27.3
B13: 福建 | C13: 941.01 | D13: 10742 | E13: 1031+4/2 | F13: 9979.7 | G13: 353.02 | H13: 1027+4/2 | I13: 9697.7 | J13: 344.97
B14: 江西 | C14: 425.57 | D14: 4858.1 | E14: 533 | F14: 5162.9 | G14: 170.96 | H14: 448 | I14: 4161.9 | J14: 137.74
B15: 山东 | C15: 102.48 | D15: 1170.1 | E15: 50 | F15: 64.2 | G15: 1.59 | H15: 37 | I15: 50.8 | J15: 1.32
B16: 河南 | C16: 412.32 | D16: 4706.6 | E16: 214+32 | F16: 2880.6 | G16: 96.95 | H16: 137+3/2 | I16: 2726.4 | J16: 91.4
B17: 湖北 | C17: 1507.12 | D17: 17204.5 | E17: 704+2/2 | F17: 35540.5 | G17: 1386.31 | H17: 649+2/2 | I17: 35355.9 | J17: 1380.45
B18: 湖南 | C18: 1162.51 | D18: 13270.4 | E18: 967+2/2 | F18: 12020.9 | G18: 486.19 | H18: 769+2/2 | I18: 11349.8 | J18: 457.58
B19: 广东 | C19: 531.6 | D19: 6068.5 | E19: 1051 | F19: 5401.4 | G19: 198.14 | H19: 970 | I19: 4878.8 | J19: 177.79
B20: 海南 | C20: 73.78 | D20: 842.2 | E20: 85 | F20: 760.5 | G20: 21.03 | H20: 82 | I20: 710.5 | J20: 19.94
B21: 广西 | C21: 1545.37 | D21: 17641.2 | E21: 821+5/2 | F21: 18913.8 | G21: 808.84 | H21: 759+52 | I21: 18575 | J21: 794.98
B22: 四川 | C22: 12571.89 | D22: 143514.7 | E22: 1992+27/2 | F22: 120040 | G22: 6121.59 | H22: 1836+19/2 | I22: 103270.7 | J22: 5232.89
B23: 重庆 | C23: 2011.67 | D23: 22964.3 | E23: 421 | F23: 9808.4 | G23: 445.78 | H23: 323 | I23: 8195.9 | J23: 378.04
B24: 贵州 | C24: 1584.37 | D24: 18086.4 | E24: 574+27/2 | F24: 19487.9 | G24: 777.99 | H24: 448+26/2 | I24: 18980.7 | J24: 752.42
B25: 云南 | C25: 9144.21 | D25: 104386 | E25: 769+27/2 | F25: 101939.1 | G25: 4918.81 | H25: 729+25/2 | I25: 97950.4 | J25: 4712.83
B26: 陕西 | C26: 19638.98 | D26: 201358.2 | E26: 333+5/2 | F26: 110004.4 | G26: 5759.69 | H26: 191 | I26: 8350.4 | J26: 376.25
B27: 山西 | C27: 1118.56 | D27: 12768.9 | E27: 343+6/2 | F27: 6623.8 | G27: 222.16 | H27: 312+6/2 | I27: 6501.6 | J27: 217.22
B28: 甘肃 | C28: 1304.16 | D28: 14887.3 | E28: 310+11/2 | F28: 10625.4 | G28: 444.34 | H28: 195+10/2 | I28: 9009 | J28: 370.43
B29: 青海 | C29: 1916.14 | D29: 21873.8 | E29: 229+12/2 | F29: 23140.4 | G29: 913.44 | H29: 170+8/2 | I29: 15479.1 | J29: 554.62
B30: 宁夏 | C30: 184.19 | D30: 2102.6 | E30: 10+1/2 | F30: 1458.4 | G30: 58.94 | H30: 10+1/2 | I30: 1458.4 | J30: 58.94
B31: 新疆 | C31: 3344.46 | D31: 38178.7 | E31: 518 | F31: 16564.9 | G31: 712.59 | H31: 495 | I31: 15670.5 | J31: 682.81
B32: 合计 | C32: 60829 | D32: 694400 | E32: 13286+28/2 | F32: 541640 | G32: 24740 | H32: 11653+27/2 | I32: 401795 | J32: 17534
L40: 流 域 | M40: 理论出力（万kW） | N40: 年发电量（亿kWh） | O40: 占全国（%） | P40: 装机容量（万kW） | Q40: 年发电量（亿kWh） | R40: 占全国（%）
L41: 全国 | M41: 67604.71 | N41: 59221.8 | O41: 100 | P41: 37853.24 | Q41: 19233.04 | R41: 100
L42: 长江 | M42: 26801.77 | N42: 23478.4 | O42: 39.6 | P42: 19724.33 | Q42: 10274.98 | R42: 53.4
L43: 黄河 | M43: 4054.8 | N43: 3552 | O43: 6 | P43: 2800.39 | Q43: 1169.91 | R43: 6.1
L44: 珠江 | M44: 3348.37 | N44: 2933.2 | O44: 5 | P44: 2485.02 | Q44: 1124.78 | R44: 5.8
L45: 海滦河 | M45: 294.4 | N45: 257.9 | O45: 0.4 | P45: 213.48 | Q45: 51.68 | R45: 0.3
L46: 淮河 | M46: 144.96 | N46: 127 | O46: 0.2 | P46: 66.01 | Q46: 18.94 | R46: 0.1
L47: 东北诸河 | M47: 1530.6 | N47: 1340.8 | O47: 2.3 | P47: 1370.75 | Q47: 439.42 | R47: 2.3
L48: 东南沿海诸河 | M48: 2066.78 | N48: 1810.5 | O48: 3.1 | P48: 1389.68 | Q48: 547.41 | R48: 2.9
...

Sheet Biomass and MSW
D19: （顿标准煤） | E19: MWh | F19: MW | H19: https://www.163.com/dy/article/FOOLBG0T0538A21J.html
C20: 农业废弃物资源量 | D20: =2*10^8 -> 200000000 | E20: =D20*$E$25 -> 1628200000 | F20: =E20/$E$27 -> 360620.16
C21: 林业废弃物资源量 | D21: =2*10^8 -> 200000000 | E21: =D21*$E$25 -> 1628200000 | F21: =E21/$E$27 -> 360620.16
C22: 其余相关有机废弃物 | D22: =6000*10000 -> 60000000 | E22: =D22*$E$25 -> 488460000 | F22: =E22/$E$27 -> 108186.05
D25: 1ton of coal equivalent = | E25: 8.141 | F25: MWh
D27: Annual operation hour | E27: 4515 | F27: hr
H30: https://baijiahao.baidu.com/s?id=1773037600839236818&wfr=spider&for=pc

Sheet Geothermal
B1: 2021 Installed Geothermal Capacity by Country
B22: China's geothermal development in the past has mainly been for cooling and heating purpose, for its high temp geothermal resources are located in either south western region or south eastern region
B24: 地热发电亟待政策扶一把 (people.com.cn)
B25: 目前，我国适于发电的高温地热资源发电潜力845.9万千瓦，资源量级虽不大， | V25: Elec | X25: Heat
B26: 但都分布在缺煤少电的西藏川西滇西地热带和东南沿海闽粤琼地热带，地热发电对支撑当地的电力供需十分重要，但现实却是，这些地方的地热发电产业发展较为滞缓。 | U26: China National | V26: 8450 | W26: MW | X26: 12500
U27: South West China | V27: 7120 | W27: MW
B28: 据中国地质调查局评价结果，全国336个地级以上城市浅层地热能年可开采资源量折合7亿吨标准煤,
B29: 全国水热型地热资源量折合1.25万亿吨标准煤，年可开采资源量折合19亿吨标准煤，埋深在3000米至1万米的干热岩资源量折合856万亿吨标准煤。 | U29: 适用于发电的高温地热资源发电潜力 | V29: 8459000 | W29: kW
B30: 中低温水热型地热能资源占比达95%以上，主要分布在华北、松辽、苏北、江汉、鄂尔多斯、四川等平原（盆地）以及东南沿海、胶东半岛和辽东半岛等山地丘陵地区，可用于供暖、工业干燥、旅游和种养植等； | V30: =V29/1000 -> 8459 | W30: MW
B31: 高温水热型地热能资源主要分布于西藏南部、云南西部、四川西部和台湾省，西南地区高温水热型地热能年可采资源量折合1800万吨标准煤，发
B32: 电潜力7120兆瓦，地热能资源的梯级高效开发利用可满足四川西部、西藏南部少数民族地区约50%人口的用电和供暖需求。

Sheet Solar Thermal
B3: 光热技术可开发量 | C3: =200*10^8 -> 20000000000 | D3: kW
B15: Source: | C15: 《中国新能源基地化开发与新型抽水蓄能》
C16: 全球能源互联网发展合作组织
C17: https://www.iwra.org/proceedings/congress/resource/IWRA2023_Beijing_China_20230912_SS_2_1_ORAL_20230904_%E4%B8%AD%E5%9B%BD%E6%96%B0%E8%83%BD%E6%BA%90%E5%9F%BA%E5%9C%B0%E5%8C%96%E5%BC%80%E5%8F%91%E4%B8%8E%E6%96%B0%E5%9E%8B%E6%8A%BD%E6%B0%B4%E8%93%84%E8%83%BDv3.pdf

Sheet MPCbS
A1: Electricity Source | B1: Max Potential Capacity (MW)
A2: hard coal | B2: =9*10^12 -> 9000000000000
A3: natural gas nonpeaker | B3: =9*10^12 -> 9000000000000
A4: nuclear | B4: =9*10^12 -> 9000000000000
A5: hydro | B5: =Hydro!D32 -> 694400
A6: wind | B6: ='Wind & Solar - Most Updated'!Q27*1000 -> 8694000
A7: solar PV | B7: ='Wind & Solar - Most Updated'!S27*1000 -> 45600000
A8: solar thermal | B8: ='Solar Thermal'!C3/1000 -> 20000000
A9: biomass | B9: ='Biomass and MSW'!F20+'Biomass and MSW'!F21 -> 721240.31
A10: geothermal | B10: =Geothermal!V30 -> 8459
A11: petroleum | B11: =9*10^12 -> 9000000000000
A12: natural gas peaker | B12: =9*10^12 -> 9000000000000
A13: lignite | B13: =9*10^12 -> 9000000000000
A14: offshore wind | B14: ='Wind & Solar - Most Updated'!R27*1000 -> 2254000
A15: crude oil | B15: 0
A16: heavy or residual fuel oil | B16: 0
A17: municipal solid waste | B17: ='Biomass and MSW'!F22 -> 108186.05
