Workbook

Sheet 人民币兑美元汇率
A1: 人民币年份 | B1: 当年人民币相对2012美元 | C1: 2012美元相对当年人民币价格
A2: 2000 | B2: 0.26402732 | C2: 3.7874869
A3: 2001 | B3: 0.25873097 | C3: 3.8650186
A4: 2002 | B4: 0.25718247 | C4: 3.8882898
A5: 2003 | B5: 0.25065742 | C5: 3.9895089
A6: 2004 | B6: 0.23436442 | C6: 4.2668593
A7: 2005 | B7: 0.22555917 | C7: 4.4334266
A8: 2006 | B8: 0.2170371 | C8: 4.6075073
A9: 2007 | B9: 0.20142713 | C9: 4.9645746
A10: 2008 | B10: 0.18686069 | C10: 5.3515804
A11: 2009 | B11: 0.18725305 | C11: 5.340367
A12: 2010 | B12: 0.17519707 | C12: 5.707858
A13: 2011 | B13: 0.16210591 | C13: 6.1688066
... A22: 2020 | B22: 0.13765068 | C22: 7.2647663
A23: 2021 | B23: 0.13468755
A24: 2022 | B24: 0.13178821

Sheet 能源品种参考表
A1: ID | B1: Goods | C1: 贸易单位 | D1: 热值参考能源品种 | E1: EPS能源品种 | F1: Heat Value | G1: 热值单位 | H1: 转换比例 | I1: ID | L1: 商品名称 | M1: 商品编码
A2: 38260000 | B2: 生物柴油及其混合物，不含或含有按重量计低于70％的石油或从沥青矿物提取的油类 | C2: =IFERROR(VLOOKUP(A2,Import!A:E,5,FALSE),VLOOKUP(A2,Export!A:E,5,FALSE)) -> 千克 | D2: 生物质柴油 | E2: =VLOOKUP(D2,'Fuel Code Switch'!B$2:C$45,2,FALSE) -> biofuel diesel | F2: =VLOOKUP($D2,'Energy Heat Value Conversion'!$A:$E,5,FALSE) -> 3.6896112e+11 | G2: =VLOOKUP(D2,'Energy Heat Value Conversion'!A:B,2,FALSE) -> 万吨 | H2: =10^-7 -> 1e-07 | I2: =VLOOKUP(B2,L:M,2,FALSE) -> 38260000 | L2: 无烟煤 | M2: 27011100
A3: 27030000 | B3: 泥煤（包括肥料用泥煤），不论是否制成型 | C3: =IFERROR(VLOOKUP(A3,Import!A:E,5,FALSE),VLOOKUP(A3,Export!A:E,5,FALSE)) -> 千克 | D3: 泥煤 | E3: =VLOOKUP(D3,'Fuel Code Switch'!B$2:C$45,2,FALSE) -> hard coal | F3: =VLOOKUP($D3,'Energy Heat Value Conversion'!$A:$E,5,FALSE) -> 1.0302772e+11 | G3: =VLOOKUP(D3,'Energy Heat Value Conversion'!A:B,2,FALSE) -> 万吨 | H3: =10^-7 -> 1e-07 | I3: =VLOOKUP(B3,L:M,2,FALSE) -> 27030000 | L3: 炼焦煤 | M3: 27011210
A4: 68152000 | B4: 泥煤制品 | C4: =IFERROR(VLOOKUP(A4,Import!A:E,5,FALSE),VLOOKUP(A4,Export!A:E,5,FALSE)) -> 千克 | D4: 泥煤 | E4: =VLOOKUP(D4,'Fuel Code Switch'!B$2:C$45,2,FALSE) -> hard coal | F4: =VLOOKUP($D4,'Energy Heat Value Conversion'!$A:$E,5,FALSE) -> 1.0302772e+11 | G4: =VLOOKUP(D4,'Energy Heat Value Conversion'!A:B,2,FALSE) -> 万吨 | H4: =10^-7 -> 1e-07 | I4: =VLOOKUP(B4,L:M,2,FALSE) -> 68152000 | L4: 其他烟煤 | M4: 27011290
A5: 27021000 | B5: 褐煤，不论是否粉化，但未制成型 | C5: =IFERROR(VLOOKUP(A5,Import!A:E,5,FALSE),VLOOKUP(A5,Export!A:E,5,FALSE)) -> 千克 | D5: 褐煤 | E5: =VLOOKUP(D5,'Fuel Code Switch'!B$2:C$45,2,FALSE) -> hard coal | F5: =VLOOKUP($D5,'Energy Heat Value Conversion'!$A:$E,5,FALSE) -> 1.3345265e+11 | G5: =VLOOKUP(D5,'Energy Heat Value Conversion'!A:B,2,FALSE) -> 万吨 | H5: =10^-7 -> 1e-07 | I5: =VLOOKUP(B5,L:M,2,FALSE) -> 27021000 | L5: 其他煤 | M5: 27011900
A6: 27022000 | B6: 制成型的褐煤 | C6: =IFERROR(VLOOKUP(A6,Import!A:E,5,FALSE),VLOOKUP(A6,Export!A:E,5,FALSE)) -> 千克 | D6: 褐煤 | E6: =VLOOKUP(D6,'Fuel Code Switch'!B$2:C$45,2,FALSE) -> hard coal | F6: =VLOOKUP($D6,'Energy Heat Value Conversion'!$A:$E,5,FALSE) -> 1.3345265e+11 | G6: =VLOOKUP(D6,'Energy Heat Value Conversion'!A:B,2,FALSE) -> 万吨 | H6: =10^-7 -> 1e-07 | I6: =VLOOKUP(B6,L:M,2,FALSE) -> 27022000 | L6: 煤砖、煤球及用煤制成的类似固体燃料 | M6: 27012000
A7: 27012000 | B7: 煤砖、煤球及用煤制成的类似固体燃料 | C7: =IFERROR(VLOOKUP(A7,Import!A:E,5,FALSE),VLOOKUP(A7,Export!A:E,5,FALSE)) -> 千克 | D7: 型煤 | E7: =VLOOKUP(D7,'Fuel Code Switch'!B$2:C$45,2,FALSE) -> hard coal | F7: =VLOOKUP($D7,'Energy Heat Value Conversion'!$A:$E,5,FALSE) -> 1.4665574e+11 | G7: =VLOOKUP(D7,'Energy Heat Value Conversion'!A:B,2,FALSE) -> 万吨 | H7: =10^-7 -> 1e-07 | I7: =VLOOKUP(B7,L:M,2,FALSE) -> 27012000 | L7: 褐煤，不论是否粉化，但未制成型 | M7: 27021000
A8: 27011290 | B8: 其他烟煤 | C8: =IFERROR(VLOOKUP(A8,Import!A:E,5,FALSE),VLOOKUP(A8,Export!A:E,5,FALSE)) -> 千克 | D8: 烟煤 | E8: =VLOOKUP(D8,'Fuel Code Switch'!B$2:C$45,2,FALSE) -> hard coal | F8: =VLOOKUP($D8,'Energy Heat Value Conversion'!$A:$E,5,FALSE) -> 1.8548781e+11 | G8: =VLOOKUP(D8,'Energy Heat Value Conversion'!A:B,2,FALSE) -> 万吨 | H8: =10^-7 -> 1e-07 | I8: =VLOOKUP(B8,L:M,2,FALSE) -> 27011290 | L8: 制成型的褐煤 | M8: 27022000
A9: 27011210 | B9: 炼焦煤 | C9: =IFERROR(VLOOKUP(A9,Import!A:E,5,FALSE),VLOOKUP(A9,Export!A:E,5,FALSE)) -> 千克 | D9: 无烟煤 | E9: =VLOOKUP(D9,'Fuel Code Switch'!B$2:C$45,2,FALSE) -> hard coal | F9: =VLOOKUP($D9,'Energy Heat Value Conversion'!$A:$E,5,FALSE) -> 1.9244479e+11 | G9: =VLOOKUP(D9,'Energy Heat Value Conversion'!A:B,2,FALSE) -> 万吨 | H9: =10^-7 -> 1e-07 | I9: =VLOOKUP(B9,L:M,2,FALSE) -> 27011210 | L9: 泥煤（包括肥料用泥煤），不论是否制成型 | M9: 27030000
A10: 27011100 | B10: 无烟煤 | C10: =IFERROR(VLOOKUP(A10,Import!A:E,5,FALSE),VLOOKUP(A10,Export!A:E,5,FALSE)) -> 千克 | D10: 无烟煤 | E10: =VLOOKUP(D10,'Fuel Code Switch'!B$2:C$45,2,FALSE) -> hard coal | F10: =VLOOKUP($D10,'Energy Heat Value Conversion'!$A:$E,5,FALSE) -> 1.9244479e+11 | G10: =VLOOKUP(D10,'Energy Heat Value Conversion'!A:B,2,FALSE) -> 万吨 | H10: =10^-7 -> 1e-07 | I10: =VLOOKUP(B10,L:M,2,FALSE) -> 27011100 | L10: 煤气、水煤气、炉煤气及类似气体 | M10: 27050000
A11: 27011900 | B11: 其他煤 | C11: =IFERROR(VLOOKUP(A11,Import!A:E,5,FALSE),VLOOKUP(A11,Export!A:E,5,FALSE)) -> 千克 | D11: 原煤 | E11: =VLOOKUP(D11,'Fuel Code Switch'!B$2:C$45,2,FALSE) -> hard coal | F11: =VLOOKUP($D11,'Energy Heat Value Conversion'!$A:$E,5,FALSE) -> 1.981696e+11 | G11: =VLOOKUP(D11,'Energy Heat Value Conversion'!A:B,2,FALSE) -> 万吨 | H11: =10^-7 -> 1e-07 | I11: =VLOOKUP(B11,L:M,2,FALSE) -> 27011900 | L11: 其他蒸馏高温煤焦油所得油类等产品及类似品 | M11: 27079990
A12: 27101922 | B12: 5~7号燃料油，不含有生物柴油 | C12: =IFERROR(VLOOKUP(A12,Import!A:E,5,FALSE),VLOOKUP(A12,Export!A:E,5,FALSE)) -> 千克 | D12: 燃料油 | E12: =VLOOKUP(D12,'Fuel Code Switch'!B$2:C$45,2,FALSE) -> heavy fuel oil | F12: =VLOOKUP($D12,'Energy Heat Value Conversion'!$A:$E,5,FALSE) -> 3.9633921e+11 | G12: =VLOOKUP(D12,'Energy Heat Value Conversion'!A:B,2,FALSE) -> 万吨 | H12: =10^-7 -> 1e-07 | I12: 27101922 | L12: 石油原油及从沥青矿物提取的原油 | M12: 27090000
A13: 27101929 | B13: 其他燃料油，不含生物柴油 | C13: =IFERROR(VLOOKUP(A13,Import!A:E,5,FALSE),VLOOKUP(A13,Export!A:E,5,FALSE)) -> 千克 | D13: 燃料油 | E13: =VLOOKUP(D13,'Fuel Code Switch'!B$2:C$45,2,FALSE) -> heavy fuel oil | F13: =VLOOKUP($D13,'Energy Heat Value Conversion'!$A:$E,5,FALSE) -> 3.9633921e+11 | G13: =VLOOKUP(D13,'Energy Heat Value Conversion'!A:B,2,FALSE) -> 万吨 | H13: =10^-7 -> 1e-07 | I13: =VLOOKUP(B13,L:M,2,FALSE) -> 27101929 | L13: 车用汽油和航空汽油，不含有生物柴油 | M13: 27101210
A14: 27101230 | B14: 橡胶溶剂油、油漆溶剂油、抽提溶剂油，不含有生物柴油 | C14: =IFERROR(VLOOKUP(A14,Import!A:E,5,FALSE),VLOOKUP(A14,Export!A:E,5,FALSE)) -> 千克 | D14: 溶剂油 | E14: =VLOOKUP(D14,'Fuel Code Switch'!B$2:C$45,2,FALSE) -> heavy fuel oil | F14: =VLOOKUP($D14,'Energy Heat Value Conversion'!$A:$E,5,FALSE) -> 4.0704006e+11 | G14: =VLOOKUP(D14,'Energy Heat Value Conversion'!A:B,2,FALSE) -> 万吨 | H14: =10^-7 -> 1e-07 | I14: =VLOOKUP(B14,L:M,2,FALSE) -> 27101230 | L14: 石脑油，不含有生物柴油 | M14: 27101220
A15: 27101912 | B15: 灯用煤油，不含生物柴油 | C15: =IFERROR(VLOOKUP(A15,Import!A:E,5,FALSE),VLOOKUP(A15,Export!A:E,5,FALSE)) -> 千克 | D15: 煤油 | E15: =VLOOKUP(D15,'Fuel Code Switch'!B$2:C$45,2,FALSE) -> jet fuel or kerosene | F15: =VLOOKUP($D15,'Energy Heat Value Conversion'!$A:$E,5,FALSE) -> 4.0822483e+11 | G15: =VLOOKUP(D15,'Energy Heat Value Conversion'!A:B,2,FALSE) -> 万吨 | H15: =10^-7 -> 1e-07 | I15: =VLOOKUP(B15,L:M,2,FALSE) -> 27101912 | L15: 橡胶溶剂油、油漆溶剂油、抽提溶剂油，不含有生物柴油 | M15: 27101230
A16: 27101911 | B16: 航空煤油，不含有生物柴油 | C16: =IFERROR(VLOOKUP(A16,Import!A:E,5,FALSE),VLOOKUP(A16,Export!A:E,5,FALSE)) -> 千克 | D16: 煤油 | E16: =VLOOKUP(D16,'Fuel Code Switch'!B$2:C$45,2,FALSE) -> jet fuel or kerosene | F16: =VLOOKUP($D16,'Energy Heat Value Conversion'!$A:$E,5,FALSE) -> 4.0822483e+11 | G16: =VLOOKUP(D16,'Energy Heat Value Conversion'!A:B,2,FALSE) -> 万吨 | H16: =10^-7 -> 1e-07 | I16: =VLOOKUP(B16,L:M,2,FALSE) -> 27101911 | L16: 未列名轻油及其制品，不含有生物柴油 | M16: 27101299
A17: 27129090 | B17: 其他石蜡、矿物蜡及合成方法制得的类似产品 | C17: =IFERROR(VLOOKUP(A17,Import!A:E,5,FALSE),VLOOKUP(A17,Export!A:E,5,FALSE)) -> 千克 | D17: 石蜡 | E17: =VLOOKUP(D17,'Fuel Code Switch'!B$2:C$45,2,FALSE) -> LPG propane or butane | F17: =VLOOKUP($D17,'Energy Heat Value Conversion'!$A:$E,5,FALSE) -> 3.7841599e+11 | G17: =VLOOKUP(D17,'Energy Heat Value Conversion'!A:B,2,FALSE) -> 万吨 | H17: =10^-7 -> 1e-07 | I17: =VLOOKUP(B17,L:M,2,FALSE) -> 27129090 | L17: 航空煤油，不含有生物柴油 | M17: 27101911
A18: 27122000 | B18: 石蜡，按重量计含油量＜0.75％ | C18: =IFERROR(VLOOKUP(A18,Import!A:E,5,FALSE),VLOOKUP(A18,Export!A:E,5,FALSE)) -> 千克 | D18: 石蜡 | E18: =VLOOKUP(D18,'Fuel Code Switch'!B$2:C$45,2,FALSE) -> LPG propane or butane | F18: =VLOOKUP($D18,'Energy Heat Value Conversion'!$A:$E,5,FALSE) -> 3.7841599e+11 | G18: =VLOOKUP(D18,'Energy Heat Value Conversion'!A:B,2,FALSE) -> 万吨 | H18: =10^-7 -> 1e-07 | I18: =VLOOKUP(B18,L:M,2,FALSE) -> 27122000 | L18: 其他煤油馏分，不含有生物柴油 | M18: 27101919
A19: 27129010 | B19: 微晶石蜡 | C19: =IFERROR(VLOOKUP(A19,Import!A:E,5,FALSE),VLOOKUP(A19,Export!A:E,5,FALSE)) -> 千克 | D19: 石蜡 | E19: =VLOOKUP(D19,'Fuel Code Switch'!B$2:C$45,2,FALSE) -> LPG propane or butane | F19: =VLOOKUP($D19,'Energy Heat Value Conversion'!$A:$E,5,FALSE) -> 3.7841599e+11 | G19: =VLOOKUP(D19,'Energy Heat Value Conversion'!A:B,2,FALSE) -> 万吨 | H19: =10^-7 -> 1e-07 | I19: =VLOOKUP(B19,L:M,2,FALSE) -> 27129010 | L19: 5~7号燃料油，不含有生物柴油 | M19: 27101922
A20: 27101994 | B20: 液体石蜡和重质液体石蜡，不含有生物柴油 | C20: =IFERROR(VLOOKUP(A20,Import!A:E,5,FALSE),VLOOKUP(A20,Export!A:E,5,FALSE)) -> 千克 | D20: 石蜡 | E20: =VLOOKUP(D20,'Fuel Code Switch'!B$2:C$45,2,FALSE) -> LPG propane or butane | F20: =VLOOKUP($D20,'Energy Heat Value Conversion'!$A:$E,5,FALSE) -> 3.7841599e+11 | G20: =VLOOKUP(D20,'Energy Heat Value Conversion'!A:B,2,FALSE) -> 万吨 | H20: =10^-7 -> 1e-07 | I20: =VLOOKUP(B20,L:M,2,FALSE) -> 27101994 | L20: 柴油,不含生物柴油 | M20: 27101923
A21: 27101993 | B21: 润滑油基础油，不含有生物柴油 | C21: =IFERROR(VLOOKUP(A21,Import!A:E,5,FALSE),VLOOKUP(A21,Export!A:E,5,FALSE)) -> 千克 | D21: 润滑油 | E21: =VLOOKUP(D21,'Fuel Code Switch'!B$2:C$45,2,FALSE) -> LPG propane or butane | F21: =VLOOKUP($D21,'Energy Heat Value Conversion'!$A:$E,5,FALSE) -> 3.9237733e+11 | G21: =VLOOKUP(D21,'Energy Heat Value Conversion'!A:B,2,FALSE) -> 万吨 | H21: =10^-7 -> 1e-07 | I21: =VLOOKUP(B21,L:M,2,FALSE) -> 27101993 | L21: 其他燃料油，不含生物柴油 | M21: 27101929
A22: 27101991 | B22: 润滑油，不含有生物柴油 | C22: =IFERROR(VLOOKUP(A22,Import!A:E,5,FALSE),VLOOKUP(A22,Export!A:E,5,FALSE)) -> 千克 | D22: 润滑油 | E22: =VLOOKUP(D22,'Fuel Code Switch'!B$2:C$45,2,FALSE) -> LPG propane or butane | F22: =VLOOKUP($D22,'Energy Heat Value Conversion'!$A:$E,5,FALSE) -> 3.9237733e+11 | G22: =VLOOKUP(D22,'Energy Heat Value Conversion'!A:B,2,FALSE) -> 万吨 | H22: =10^-7 -> 1e-07 | I22: =VLOOKUP(B22,L:M,2,FALSE) -> 27101991 | L22: 润滑油，不含有生物柴油 | M22: 27101991
A23: 27101220 | B23: 石脑油，不含有生物柴油 | C23: =IFERROR(VLOOKUP(A23,Import!A:E,5,FALSE),VLOOKUP(A23,Export!A:E,5,FALSE)) -> 千克 | D23: 石脑油 | E23: =VLOOKUP(D23,'Fuel Code Switch'!B$2:C$45,2,FALSE) -> LPG propane or butane | F23: =VLOOKUP($D23,'Energy Heat Value Conversion'!$A:$E,5,FALSE) -> 4.1615806e+11 | G23: =VLOOKUP(D23,'Energy Heat Value Conversion'!A:B,2,FALSE) -> 万吨 | H23: =10^-7 -> 1e-07 | I23: =VLOOKUP(B23,L:M,2,FALSE) -> 27101220 | L23: 润滑油基础油，不含有生物柴油 | M23: 27101993
A24: 27111990 | B24: 未列名液化石油气及其他烃类气 | C24: =IFERROR(VLOOKUP(A24,Import!A:E,5,FALSE),VLOOKUP(A24,Export!A:E,5,FALSE)) -> 千克 | D24: 液化石油气 | E24: =VLOOKUP(D24,'Fuel Code Switch'!B$2:C$45,2,FALSE) -> LPG propane or butane | F24: =VLOOKUP($D24,'Energy Heat Value Conversion'!$A:$E,5,FALSE) -> 4.7560515e+11 | G24: =VLOOKUP(D24,'Energy Heat Value Conversion'!A:B,2,FALSE) -> 万吨 | H24: =10^-7 -> 1e-07 | I24: =VLOOKUP(B24,L:M,2,FALSE) -> 27111990 | L24: 液体石蜡和重质液体石蜡，不含有生物柴油 | M24: 27101994
A25: =VLOOKUP(B25,能源品种参考表!B:I,8,FALSE) -> 27050000 | B25: 煤气、水煤气、炉煤气及类似气体 | C25: =IFERROR(VLOOKUP(A25,Import!A:E,5,FALSE),VLOOKUP(A25,Export!A:E,5,FALSE)) -> 千克 | D25: 其他煤气 | E25: =VLOOKUP(D25,'Fuel Code Switch'!B$2:C$45,2,FALSE) -> LPG propane or butane | F25: =VLOOKUP($D25,'Energy Heat Value Conversion'!$A:$E,5,FALSE) -> 4.9542401e+11 | G25: =VLOOKUP(D25,'Energy Heat Value Conversion'!A:B,2,FALSE) -> 亿立方米 | H25: =1/(0.8795*10^8) -> 1.1370097e-08 | I25: =VLOOKUP(B25,L:M,2,FALSE) -> 27050000 | L25: 其他重油；以石油及从沥青矿物提取的油类为基础成分的未列名制品，不含有生物柴油 | M25: 27101999
A26: 38251000 | B26: 城市生活垃圾 | C26: =IFERROR(VLOOKUP(A26,Import!A:E,5,FALSE),VLOOKUP(A26,Export!A:E,5,FALSE)) -> #N/A | D26: 城市生活垃圾 | E26: =VLOOKUP(D26,'Fuel Code Switch'!B$2:C$45,2,FALSE) -> municipal solid waste | F26: =VLOOKUP($D26,'Energy Heat Value Conversion'!$A:$E,5,FALSE) -> 4.7390856e+10 | G26: =VLOOKUP(D26,'Energy Heat Value Conversion'!A:B,2,FALSE) -> 万吨 | H26: =10^-7 -> 1e-07 | I26: 38251000 | L26: 液化天然气 | M26: 27111100
A27: 27112100 | B27: 天然气 | C27: =IFERROR(VLOOKUP(A27,Import!A:E,5,FALSE),VLOOKUP(A27,Export!A:E,5,FALSE)) -> 千克 | D27: 液化天然气 | E27: =VLOOKUP(D27,'Fuel Code Switch'!B$2:C$45,2,FALSE) -> natural gas | F27: =VLOOKUP($D27,'Energy Heat Value Conversion'!$A:$E,5,FALSE) -> 4.8750026e+11 | G27: =VLOOKUP(D27,'Energy Heat Value Conversion'!A:B,2,FALSE) -> 万吨 | H27: =10^-7 -> 1e-07 | I27: =VLOOKUP(B27,L:M,2,FALSE) -> 27112100 | L27: 未列名液化石油气及其他烃类气 | M27: 27111990
A28: 27111100 | B28: 液化天然气 | C28: =IFERROR(VLOOKUP(A28,Import!A:E,5,FALSE),VLOOKUP(A28,Export!A:E,5,FALSE)) -> 千克 | D28: 液化天然气 | E28: =VLOOKUP(D28,'Fuel Code Switch'!B$2:C$45,2,FALSE) -> natural gas | F28: =VLOOKUP($D28,'Energy Heat Value Conversion'!$A:$E,5,FALSE) -> 4.8750026e+11 | G28: =VLOOKUP(D28,'Energy Heat Value Conversion'!A:B,2,FALSE) -> 万吨 | H28: =10^-7 -> 1e-07 | I28: =VLOOKUP(B28,L:M,2,FALSE) -> 27111100 | L28: 天然气 | M28: 27112100
A29: 27131190 | B29: 其他未煅烧石油焦 | C29: =IFERROR(VLOOKUP(A29,Import!A:E,5,FALSE),VLOOKUP(A29,Export!A:E,5,FALSE)) -> 千克 | D29: 石油焦 | E29: =VLOOKUP(D29,'Fuel Code Switch'!B$2:C$45,2,FALSE) -> petroleum diesel | F29: =VLOOKUP($D29,'Energy Heat Value Conversion'!$A:$E,5,FALSE) -> 3.0279914e+11 | G29: =VLOOKUP(D29,'Energy Heat Value Conversion'!A:B,2,FALSE) -> 万吨 | H29: =10^-7 -> 1e-07 | I29: =VLOOKUP(B29,L:M,2,FALSE) -> 27131190 | L29: 石蜡，按重量计含油量＜0.75％ | M29: 27122000
A30: 27131290 | B30: 其他已煅烧石油焦 | C30: =IFERROR(VLOOKUP(A30,Import!A:E,5,FALSE),VLOOKUP(A30,Export!A:E,5,FALSE)) -> 千克 | D30: 石油焦 | E30: =VLOOKUP(D30,'Fuel Code Switch'!B$2:C$45,2,FALSE) -> petroleum diesel | F30: =VLOOKUP($D30,'Energy Heat Value Conversion'!$A:$E,5,FALSE) -> 3.0279914e+11 | G30: =VLOOKUP(D30,'Energy Heat Value Conversion'!A:B,2,FALSE) -> 万吨 | H30: =10^-7 -> 1e-07 | I30: =VLOOKUP(B30,L:M,2,FALSE) -> 27131290 | L30: 微晶石蜡 | M30: 27129010
A31: 27131110 | B31: 未煅烧石油焦，含硫量＜3% | C31: =IFERROR(VLOOKUP(A31,Import!A:E,5,FALSE),VLOOKUP(A31,Export!A:E,5,FALSE)) -> 千克 | D31: 石油焦 | E31: =VLOOKUP(D31,'Fuel Code Switch'!B$2:C$45,2,FALSE) -> petroleum diesel | F31: =VLOOKUP($D31,'Energy Heat Value Conversion'!$A:$E,5,FALSE) -> 3.0279914e+11 | G31: =VLOOKUP(D31,'Energy Heat Value Conversion'!A:B,2,FALSE) -> 万吨 | H31: =10^-7 -> 1e-07 | I31: =VLOOKUP(B31,L:M,2,FALSE) -> 27131110 | L31: 其他石蜡、矿物蜡及合成方法制得的类似产品 | M31: 27129090
A32: 27131210 | B32: 已煅烧石油焦，含硫量＜0.8% | C32: =IFERROR(VLOOKUP(A32,Import!A:E,5,FALSE),VLOOKUP(A32,Export!A:E,5,FALSE)) -> 千克 | D32: 石油焦 | E32: =VLOOKUP(D32,'Fuel Code Switch'!B$2:C$45,2,FALSE) -> petroleum diesel | F32: =VLOOKUP($D32,'Energy Heat Value Conversion'!$A:$E,5,FALSE) -> 3.0279914e+11 | G32: =VLOOKUP(D32,'Energy Heat Value Conversion'!A:B,2,FALSE) -> 万吨 | H32: =10^-7 -> 1e-07 | I32: =VLOOKUP(B32,L:M,2,FALSE) -> 27131210 | L32: 未煅烧石油焦，含硫量＜3% | M32: 27131110
A33: 27079990 | B33: 其他蒸馏高温煤焦油所得油类等产品及类似品 | C33: =IFERROR(VLOOKUP(A33,Import!A:E,5,FALSE),VLOOKUP(A33,Export!A:E,5,FALSE)) -> 千克 | D33: 煤焦油 | E33: =VLOOKUP(D33,'Fuel Code Switch'!B$2:C$45,2,FALSE) -> petroleum diesel | F33: =VLOOKUP($D33,'Energy Heat Value Conversion'!$A:$E,5,FALSE) -> 3.1707326e+11 | G33: =VLOOKUP(D33,'Energy Heat Value Conversion'!A:B,2,FALSE) -> 万吨 | H33: =10^-7 -> 1e-07 | I33: =VLOOKUP(B33,L:M,2,FALSE) -> 27079990 | L33: 其他未煅烧石油焦 | M33: 27131190
A34: 27132000 | B34: 石油沥青 | C34: =IFERROR(VLOOKUP(A34,Import!A:E,5,FALSE),VLOOKUP(A34,Export!A:E,5,FALSE)) -> 千克 | D34: 石油沥青 | E34: =VLOOKUP(D34,'Fuel Code Switch'!B$2:C$45,2,FALSE) -> petroleum diesel | F34: =VLOOKUP($D34,'Energy Heat Value Conversion'!$A:$E,5,FALSE) -> 3.6899468e+11 | G34: =VLOOKUP(D34,'Energy Heat Value Conversion'!A:B,2,FALSE) -> 万吨 | H34: =10^-7 -> 1e-07 | I34: =VLOOKUP(B34,L:M,2,FALSE) -> 27132000 | L34: 已煅烧石油焦，含硫量＜0.8% | M34: 27131210
A35: 27101923 | B35: 柴油，不含生物柴油 | C35: =IFERROR(VLOOKUP(A35,Import!A:E,5,FALSE),VLOOKUP(A35,Export!A:E,5,FALSE)) -> 千克 | D35: 柴油 | E35: =VLOOKUP(D35,'Fuel Code Switch'!B$2:C$45,2,FALSE) -> petroleum diesel | F35: =VLOOKUP($D35,'Energy Heat Value Conversion'!$A:$E,5,FALSE) -> 4.0426296e+11 | G35: =VLOOKUP(D35,'Energy Heat Value Conversion'!A:B,2,FALSE) -> 万吨 | H35: =10^-7 -> 1e-07 | I35: 27101923 | L35: 其他已煅烧石油焦 | M35: 27131290
A36: 27101210 | B36: 车用汽油和航空汽油，不含有生物柴油 | C36: =IFERROR(VLOOKUP(A36,Import!A:E,5,FALSE),VLOOKUP(A36,Export!A:E,5,FALSE)) -> 千克 | D36: 汽油 | E36: =VLOOKUP(D36,'Fuel Code Switch'!B$2:C$45,2,FALSE) -> petroleum gasoline | F36: =VLOOKUP($D36,'Energy Heat Value Conversion'!$A:$E,5,FALSE) -> 4.0822483e+11 | G36: =VLOOKUP(D36,'Energy Heat Value Conversion'!A:B,2,FALSE) -> 万吨 | H36: =10^-7 -> 1e-07 | I36: =VLOOKUP(B36,L:M,2,FALSE) -> 27101210 | L36: 石油沥青 | M36: 27132000
A37: 28442000 | B37: U235浓缩铀、钚及其化合物、合金、分散体等 | C37: =IFERROR(VLOOKUP(A37,Import!A:E,5,FALSE),VLOOKUP(A37,Export!A:E,5,FALSE)) -> 克 | D37: 核燃料 | E37: =VLOOKUP(D37,'Fuel Code Switch'!B$2:C$45,2,FALSE) -> nuclear | F37: =VLOOKUP($D37,'Energy Heat Value Conversion'!$A:$E,5,FALSE) -> 3939624.9 | G37: =VLOOKUP(D37,'Energy Heat Value Conversion'!A:B,2,FALSE) -> 克 | H37: 1 | I37: 28442000 | L37: 氢 | M37: 28041000
A38: 28041000 | B38: 氢 | C38: =IFERROR(VLOOKUP(A38,Import!A:E,5,FALSE),VLOOKUP(A38,Export!A:E,5,FALSE)) -> 千克 | D38: 氢能源 | E38: hydrogen | F38: =VLOOKUP($D38,'Energy Heat Value Conversion'!$A:$E,5,FALSE) -> 9.1846522e+09 | G38: =VLOOKUP(D38,'Energy Heat Value Conversion'!A:B,2,FALSE) -> 万吨 | H38: =10^-7 -> 1e-07 | I38: =VLOOKUP(B38,L:M,2,FALSE) -> 28041000 | L38: 铀235浓缩铀、钚及其化合物、合金、分散体等 | M38: 28442000
A39: 27101999 | B39: 其他重油；以石油及从沥青矿物提取的油类为基础成分的未列名制品，不含有生物柴油 | C39: =IFERROR(VLOOKUP(A39,Import!A:E,5,FALSE),VLOOKUP(A39,Export!A:E,5,FALSE)) -> 千克 | D39: 石油沥青 | E39: =VLOOKUP(D39,'Fuel Code Switch'!B$2:C$45,2,FALSE) -> petroleum diesel | F39: =VLOOKUP($D39,'Energy Heat Value Conversion'!$A:$E,5,FALSE) -> 3.6899468e+11 | G39: =VLOOKUP(D39,'Energy Heat Value Conversion'!A:B,2,FALSE) -> 万吨 | H39: =10^-7 -> 1e-07 | I39: 27101999 | L39: 城市垃圾 | M39: 38251000
A40: 27101919 | B40: 其他煤油馏分，不含有生物柴油 | C40: =IFERROR(VLOOKUP(A40,Import!A:E,5,FALSE),VLOOKUP(A40,Export!A:E,5,FALSE)) -> 千克 | D40: 煤油 | E40: =VLOOKUP(D40,'Fuel Code Switch'!B$2:C$45,2,FALSE) -> jet fuel or kerosene | F40: =VLOOKUP($D40,'Energy Heat Value Conversion'!$A:$E,5,FALSE) -> 4.0822483e+11 | G40: =VLOOKUP(D40,'Energy Heat Value Conversion'!A:B,2,FALSE) -> 万吨 | H40: =10^-7 -> 1e-07 | I40: =VLOOKUP(B40,L:M,2,FALSE) -> 27101919 | L40: 生物柴油及其混合物，不含或含有按重量计低于70％的石油或从沥青矿物提取的油类 | M40: 38260000
...

Sheet Energy Heat Value Conversion
A1: 能源名称 | B1: 实物量单位 | C1: 平均低位发热量 | D1: 折标准煤系数 | E1: 折EPS BTU 系数 | F1: 单位热值含碳量 | G1: 燃料碳氧化率 | H1: 排放因子1 | I1: 排放因子2 | J1: 数据来源
C2: TJ/单位 | D2: 万吨标煤/单位 | E2: BTU/单位 | F2: 万吨碳/TJ | G2: % | H2: 万tCO2/单位 | I2: 万tCO2/万吨标煤
A3: 原煤 | B3: 万吨 | C3: 209.08 | D3: 0.7143 | E3: =C3*10^12/1055.05585 -> 1.981696e+11 | F3: 0.002749 | G3: 0.94 | H3: =C3*F3*G3*44/12 -> 1.9810093 | I3: =H3/D3 -> 2.7733576 | J3: 能源统计年鉴2020
A4: 洗精煤 | B4: 万吨 | C4: 263.44 | D4: 0.9 | E4: =C4*10^12/1055.05585 -> 2.4969294e+11 | F4: 0.00254 | G4: 0.93 | H4: =C4*F4*G4*44/12 -> 2.2817592 | I4: =H4/D4 -> 2.535288 | J4: 能源统计年鉴2020
A5: 其他洗煤 | B5: 万吨 | C5: 83.63 | D5: 0.2857 | E5: =C5*10^12/1055.05585 -> 7.9265946e+10 | F5: 0.00254 | G5: 0.9 | H5: =C5*F5*G5*44/12 -> 0.70098666 | I5: =H5/D5 -> 2.453576 | J5: 能源统计年鉴2020
A6: 型煤 | B6: 万吨 | C6: 154.73 | D6: =C6/292.7 -> 0.52863 | E6: =C6*10^12/1055.05585 -> 1.4665574e+11 | F6: 0.00266 | G6: 0.9 | H6: =C6*F6*G6*44/12 -> 1.3582199 | I6: =H6/D6 -> 2.5693206 | J6: 2020中国区域电网二氧化碳基准线排放因子
A7: 煤矸石 | B7: 万吨 | C7: 83.74 | D7: =C7/292.7 -> 0.28609498 | E7: =C7*10^12/1055.05585 -> 7.9370206e+10 | F7: 0.00273 | G7: 0.98 | H7: =C7*F7*G7*44/12 -> 0.82147265 | I7: =H7/D7 -> 2.8713285 | J7: 综合能耗计算通则GBT2589-2020
A8: 焦炭 | B8: 万吨 | C8: 284.35 | D8: 0.9714 | E8: =C8*10^12/1055.05585 -> 2.695118e+11 | F8: 0.00294 | G8: 0.93 | H8: =C8*F8*G8*44/12 -> 2.8507225 | I8: =H8/D8 -> 2.9346536 | J8: 能源统计年鉴2020
A9: 焦炉煤气 | B9: 亿立方米 | C9: 1735.35 | D9: 5.9285 | E9: =C9*10^12/1055.05585 -> 1.6447944e+12 | F9: 0.00136 | G9: 0.99 | H9: =C9*F9*G9*44/12 -> 8.5670759 | I9: =H9/D9 -> 1.4450664 | J9: 能源统计年鉴2020
A10: 高炉煤气 | B10: 亿立方米 | C10: 376.3 | D10: =C10/292.7 -> 1.2856167 | E10: =C10*10^12/1055.05585 -> 3.5666358e+11 | F10: 0.00708 | G10: 0.99 | H10: =C10*F10*G10*44/12 -> 9.6710605 | I10: =H10/D10 -> 7.5225071 | J10: 2020中国区域电网二氧化碳基准线排放因子
A11: 转炉煤气 | B11: 亿立方米 | C11: 794.5 | D11: =C11/292.7 -> 2.7143833 | E11: =C11*10^12/1055.05585 -> 7.530407e+11 | F11: 0.00469 | G11: 0.99 | H11: =C11*F11*G11*44/12 -> 13.526124 | I11: =H11/D11 -> 4.9831297 | J11: 2020中国区域电网二氧化碳基准线排放因子
A12: 其他煤气 | B12: 亿立方米 | C12: 522.7 | D12: 1.786 | E12: =C12*10^12/1055.05585 -> 4.9542401e+11 | F12: 0.00122 | G12: 0.99 | H12: =C12*F12*G12*44/12 -> 2.3148292 | I12: =H12/D12 -> 1.296097 | J12: 能源统计年鉴2020
A13: 其他焦化产品 | B13: 万吨 | C13: 334.53 | D13: =C13/292.7 -> 1.1429108 | E13: =C13*10^12/1055.05585 -> 3.1707326e+11 | F13: 0.00258 | G13: 0.93 | H13: =C13*F13*G13*44/12 -> 2.943128 | I13: =H13/D13 -> 2.5751161 | J13: 2020中国区域电网二氧化碳基准线排放因子
A14: 原油 | B14: 万吨 | C14: 418.16 | D14: 1.4286 | E14: =C14*10^12/1055.05585 -> 3.9633921e+11 | F14: 0.00201 | G14: 0.98 | H14: =C14*F14*G14*44/12 -> 3.0202024 | I14: =H14/D14 -> 2.1140994 | J14: 能源统计年鉴2020
A15: 汽油 | B15: 万吨 | C15: 430.7 | D15: 1.4714 | E15: =C15*10^12/1055.05585 -> 4.0822483e+11 | F15: 0.00189 | G15: 0.98 | H15: =C15*F15*G15*44/12 -> 2.925056 | I15: =H15/D15 -> 1.9879407 | J15: 能源统计年鉴2020
A16: 煤油 | B16: 万吨 | C16: 430.7 | D16: 1.4714 | E16: =C16*10^12/1055.05585 -> 4.0822483e+11 | F16: 0.00189 | G16: 0.98 | H16: =C16*F16*G16*44/12 -> 2.925056 | I16: =H16/D16 -> 1.9879407 | J16: 能源统计年鉴2020
A17: 柴油 | B17: 万吨 | C17: 426.52 | D17: 1.4571 | E17: =C17*10^12/1055.05585 -> 4.0426296e+11 | F17: 0.00202 | G17: 0.98 | H17: =C17*F17*G17*44/12 -> 3.0959096 | I17: =H17/D17 -> 2.1247064 | J17: 能源统计年鉴2020
A18: 燃料油 | B18: 万吨 | C18: 418.16 | D18: 1.4286 | E18: =C18*10^12/1055.05585 -> 3.9633921e+11 | F18: 0.00211 | G18: 0.98 | H18: =C18*F18*G18*44/12 -> 3.1704612 | I18: =H18/D18 -> 2.2192785 | J18: 能源统计年鉴2020
A19: 石脑油 | B19: 万吨 | C19: 439.07 | D19: =C19/292.7 -> 1.5000683 | E19: =C19*10^12/1055.05585 -> 4.1615806e+11 | F19: 0.002 | G19: 0.98 | H19: =C19*F19*G19*44/12 -> 3.1554497 | I19: =H19/D19 -> 2.1035373 | J19: 2020中国区域电网二氧化碳基准线排放因子
A20: 润滑油 | B20: 万吨 | C20: 413.98 | D20: =C20/292.7 -> 1.4143492 | E20: =C20*10^12/1055.05585 -> 3.9237733e+11 | F20: 0.002 | G20: 0.98 | H20: =C20*F20*G20*44/12 -> 2.9751363 | I20: =H20/D20 -> 2.1035373 | J20: 2021中国区域电网二氧化碳基准线排放因子
A21: 石蜡 | B21: 万吨 | C21: 399.25 | D21: =C21/292.7 -> 1.3640246 | E21: =C21*10^12/1055.05585 -> 3.7841599e+11 | F21: 0.002 | G21: 0.98 | H21: =C21*F21*G21*44/12 -> 2.8692767 | I21: =H21/D21 -> 2.1035373 | J21: 2022中国区域电网二氧化碳基准线排放因子
A22: 溶剂油 | B22: 万吨 | C22: 429.45 | D22: =C22/292.7 -> 1.4672019 | E22: =C22*10^12/1055.05585 -> 4.0704006e+11 | F22: 0.002 | G22: 0.98 | H22: =C22*F22*G22*44/12 -> 3.086314 | I22: =H22/D22 -> 2.1035373 | J22: 2023中国区域电网二氧化碳基准线排放因子
A23: 石油沥青 | B23: 万吨 | C23: 389.31 | D23: =C23/292.7 -> 1.3300649 | E23: =C23*10^12/1055.05585 -> 3.6899468e+11 | F23: 0.0022 | G23: 0.98 | H23: =C23*F23*G23*44/12 -> 3.0776253 | I23: =H23/D23 -> 2.3138911 | J23: 2024中国区域电网二氧化碳基准线排放因子
A24: 石油焦 | B24: 万吨 | C24: 319.47 | D24: =C24/292.7 -> 1.0914588 | E24: =C24*10^12/1055.05585 -> 3.0279914e+11 | F24: 0.00275 | G24: 0.98 | H24: =C24*F24*G24*44/12 -> 3.156896 | I24: =H24/D24 -> 2.8923638 | J24: 2025中国区域电网二氧化碳基准线排放因子
A25: 液化石油气 | B25: 万吨 | C25: 501.79 | D25: 1.7143 | E25: =C25*10^12/1055.05585 -> 4.7560515e+11 | F25: 0.00172 | G25: 0.99 | H25: =C25*F25*G25*44/12 -> 3.132976 | I25: =H25/D25 -> 1.8275541 | J25: 能源统计年鉴2020
A26: 炼厂干气 | B26: 万吨 | C26: 459.98 | D26: 1.5714 | E26: =C26*10^12/1055.05585 -> 4.3597692e+11 | F26: 0.00182 | G26: 0.99 | H26: =C26*F26*G26*44/12 -> 3.0389039 | I26: =H26/D26 -> 1.9338831 | J26: 能源统计年鉴2020
A27: 其他石油制品 | B27: 万吨 | C27: 409.8 | D27: =C27/292.7 -> 1.4000683 | E27: =C27*10^12/1055.05585 -> 3.8841546e+11 | F27: 0.002 | G27: 0.99 | H27: =C27*F27*G27*44/12 -> 2.975148 | I27: =H27/D27 -> 2.125002 | J27: 2025中国区域电网二氧化碳基准线排放因子
A28: 天然气 | B28: 亿立方米 | C28: 3558.45 | D28: 12.15 | E28: =C28*10^12/1055.05585 -> 3.3727598e+12 | F28: 0.00153 | G28: 0.99 | H28: =C28*F28*G28*44/12 -> 19.763275 | I28: =H28/D28 -> 1.626607 | J28: 能源统计年鉴2020
A29: 液化天然气 | B29: 万吨 | C29: 514.34 | D29: =C29/292.7 -> 1.7572258 | E29: =C29*10^12/1055.05585 -> 4.8750026e+11 | F29: 0.00153 | G29: 1 | H29: =C29*F29*G29*44/12 -> 2.8854474 | I29: =H29/D29 -> 1.642047 | J29: 2025中国区域电网二氧化碳基准线排放因子
A30: 热力 | B30: 万百万千焦 | C30: 10 | D30: =C30/292.7 -> 0.034164674 | E30: =C30*10^12/1055.05585 -> 9.4781712e+09 | G30: 1 | J30: 排放清单缺省值
A31: 电力 | B31: 亿千瓦时 | C31: 360 | D31: =C31/292.7 -> 1.2299283 | E31: =C31*10^12/1055.05585 -> 3.4121416e+11 | G31: 1
A32: 氢能源 | B32: 万吨 | C32: 9.690321 | D32: =C32/292.7 -> 0.033106666 | E32: =C32*10^12/1055.05585 -> 9.1846522e+09
A33: 其他能源 | B33: 万吨标煤 | C33: 292.71 | D33: =C33/292.7 -> 1.0000342 | E33: =C33*10^12/1055.05585 -> 2.7743555e+11 | F33: 0 | G33: 1 | H33: =C33*F33*G33*44/12 -> 0 | I33: =H33/D33 -> 0 | J33: 2025中国区域电网二氧化碳基准线排放因子
A35: 无烟煤 | B35: 万吨 | C35: 203.04 | D35: =C35/292.7 -> 0.69367954 | E35: =C35*10^12/1055.05585 -> 1.9244479e+11
A36: 烟煤 | B36: 万吨 | C36: 195.7 | D36: =C36/292.7 -> 0.66860266 | E36: =C36*10^12/1055.05585 -> 1.8548781e+11
A37: 褐煤 | B37: 万吨 | C37: 140.8 | D37: =C37/292.7 -> 0.48103861 | E37: =C37*10^12/1055.05585 -> 1.3345265e+11
A38: 泥煤 | B38: 万吨 | C38: 108.7 | D38: =C38/292.7 -> 0.37137 | E38: =C38*10^12/1055.05585 -> 1.0302772e+11
A39: 煤焦油 | B39: 万吨 | C39: 334.53 | D39: =C39/292.7 -> 1.1429108 | E39: =C39*10^12/1055.05585 -> 3.1707326e+11
A40: 生物质柴油 | B40: 万吨 | C40: 389.27459 | D40: =C40/292.7 -> 1.3299439 | E40: =C40*10^12/1055.05585 -> 3.6896112e+11
A41: 城市生活垃圾 | B41: 万吨 | C41: 50 | D41: =C41/292.7 -> 0.17082337 | E41: =C41*10^12/1055.05585 -> 4.7390856e+10
...

Sheet Fuel Code Switch
A1: Chinese Model Fuel | C1: EPS Fuel
A2: Crude Oil | B2: 原油 | C2: crude oil
A3: Electricity | B3: 电力 | C3: electricity
A4: Raw Coal | B4: 原煤 | C4: hard coal
A5: Cleaned Coal | B5: 洗精煤 | C5: hard coal
A6: Briquettes | B6: 煤制品 | C6: hard coal
A7: Heat | B7: 热力 | C7: heat
A8: Fuel Oil | B8: 燃料油 | C8: heavy fuel oil
A9: White Spirit | B9: 溶剂油 | C9: heavy fuel oil
A10: Other Petroleum Products | B10: 其他石油制品 | C10: heavy fuel oil
A11: Kerosene | B11: 煤油 | C11: jet fuel or kerosene
A12: Gangue | B12: 煤矸石 | C12: lignite
A13: Other Washed Coal | B13: 其他洗煤 | C13: lignite
... A35: Other Energy | B35: 其他能源 | C35: other energy
B36: 核燃料 | C36: nuclear
B37: 泥煤 | C37: hard coal
B38: 泥煤 | C38: hard coal
B39: 褐煤 | C39: hard coal
B40: 褐煤 | C40: hard coal
B41: 型煤 | C41: hard coal
B42: 烟煤 | C42: hard coal
B43: 无烟煤 | C43: hard coal
B44: 无烟煤 | C44: hard coal
B45: 煤焦油 | C45: petroleum diesel

Sheet Export
A1: 商品编码 | B1: 商品名称 | C1: 年份 | D1: 第一数量 | E1: 第一计量单位 | F1: 第二数量 | G1: 第二计量单位 | H1: 人民币 | I1: EPS Fuel | J1: BTU Value
A2: 23069000 | B2: 未列名植物油渣饼及其他固体残渣 | C2: 2017 | D2: 7632130 | E2: 千克 | F2: 0 | G2: ? | H2: 13262364 | I2: =VLOOKUP($A2,能源品种参考表!$A:$E,5,FALSE) -> #N/A | J2: =D2*VLOOKUP($A2,能源品种参考表!$A:$I,6,FALSE)*VLOOKUP($A2,能源品种参考表!$A:$I,8,FALSE) -> #N/A
A3: 23069000 | B3: 未列名植物油渣饼及其他固体残渣 | C3: 2018 | D3: 110643048 | E3: 千克 | F3: 0 | G3: ? | H3: 274913590 | I3: =VLOOKUP($A3,能源品种参考表!$A:$E,5,FALSE) -> #N/A | J3: =D3*VLOOKUP($A3,能源品种参考表!$A:$I,6,FALSE)*VLOOKUP($A3,能源品种参考表!$A:$I,8,FALSE) -> #N/A
A4: 23069000 | B4: 未列名植物油渣饼及其他固体残渣 | C4: 2019 | D4: 103566150 | E4: 千克 | F4: 0 | G4: ? | H4: 162861788 | I4: =VLOOKUP($A4,能源品种参考表!$A:$E,5,FALSE) -> #N/A | J4: =D4*VLOOKUP($A4,能源品种参考表!$A:$I,6,FALSE)*VLOOKUP($A4,能源品种参考表!$A:$I,8,FALSE) -> #N/A
A5: 23069000 | B5: 未列名植物油渣饼及其他固体残渣 | C5: 2020 | D5: 97911981 | E5: 千克 | F5: 0 | G5: ? | H5: 188579738 | I5: =VLOOKUP($A5,能源品种参考表!$A:$E,5,FALSE) -> #N/A | J5: =D5*VLOOKUP($A5,能源品种参考表!$A:$I,6,FALSE)*VLOOKUP($A5,能源品种参考表!$A:$I,8,FALSE) -> #N/A
A6: 23069000 | B6: 未列名植物油渣饼及其他固体残渣 | C6: 2021 | D6: 110491533 | E6: 千克 | F6: 0 | G6: ? | H6: 212536197 | I6: =VLOOKUP($A6,能源品种参考表!$A:$E,5,FALSE) -> #N/A | J6: =D6*VLOOKUP($A6,能源品种参考表!$A:$I,6,FALSE)*VLOOKUP($A6,能源品种参考表!$A:$I,8,FALSE) -> #N/A
A7: 23069000 | B7: 未列名提炼植物或微生物油脂所得的油渣饼及其他固体残渣 | C7: 2022 | D7: 117881920 | E7: 千克 | F7: 0 | G7: ? | H7: 198019214 | I7: =VLOOKUP($A7,能源品种参考表!$A:$E,5,FALSE) -> #N/A | J7: =D7*VLOOKUP($A7,能源品种参考表!$A:$I,6,FALSE)*VLOOKUP($A7,能源品种参考表!$A:$I,8,FALSE) -> #N/A
A8: =VLOOKUP(B8,能源品种参考表!B:I,8,FALSE) -> 27011100 | B8: 无烟煤 | C8: 2019 | D8: 2003373431 | E8: 千克 | F8: 0 | G8: ? | H8: 2517459471 | I8: =VLOOKUP($A8,能源品种参考表!$A:$E,5,FALSE) -> hard coal | J8: =D8*VLOOKUP($A8,能源品种参考表!$A:$I,6,FALSE)*VLOOKUP($A8,能源品种参考表!$A:$I,8,FALSE) -> 3.8553878e+13
A9: =VLOOKUP(B9,能源品种参考表!B:I,8,FALSE) -> 27011100 | B9: 无烟煤 | C9: 2020 | D9: 1336323420 | E9: 千克 | F9: 0 | G9: ? | H9: 1455920565 | I9: =VLOOKUP($A9,能源品种参考表!$A:$E,5,FALSE) -> hard coal | J9: =D9*VLOOKUP($A9,能源品种参考表!$A:$I,6,FALSE)*VLOOKUP($A9,能源品种参考表!$A:$I,8,FALSE) -> 2.5716848e+13
A10: =VLOOKUP(B10,能源品种参考表!B:I,8,FALSE) -> 27011100 | B10: 无烟煤 | C10: 2021 | D10: 1496653525 | E10: 千克 | F10: 0 | G10: ? | H10: 2295580095 | I10: =VLOOKUP($A10,能源品种参考表!$A:$E,5,FALSE) -> hard coal | J10: =D10*VLOOKUP($A10,能源品种参考表!$A:$I,6,FALSE)*VLOOKUP($A10,能源品种参考表!$A:$I,8,FALSE) -> 2.8802317e+13
A11: =VLOOKUP(B11,能源品种参考表!B:I,8,FALSE) -> 27011100 | B11: 无烟煤 | C11: 2022 | D11: 2110600395 | E11: 千克 | F11: 0 | G11: ? | H11: 15816222100 | I11: =VLOOKUP($A11,能源品种参考表!$A:$E,5,FALSE) -> hard coal | J11: =D11*VLOOKUP($A11,能源品种参考表!$A:$I,6,FALSE)*VLOOKUP($A11,能源品种参考表!$A:$I,8,FALSE) -> 4.0617405e+13
A12: =VLOOKUP(B12,能源品种参考表!B:I,8,FALSE) -> 27011210 | B12: 炼焦煤 | C12: 2019 | D12: 1396550136 | E12: 千克 | F12: 0 | G12: ? | H12: 1906973417 | I12: =VLOOKUP($A12,能源品种参考表!$A:$E,5,FALSE) -> hard coal | J12: =D12*VLOOKUP($A12,能源品种参考表!$A:$I,6,FALSE)*VLOOKUP($A12,能源品种参考表!$A:$I,8,FALSE) -> 2.687588e+13
A13: =VLOOKUP(B13,能源品种参考表!B:I,8,FALSE) -> 27011210 | B13: 炼焦煤 | C13: 2020 | D13: 874468500 | E13: 千克 | F13: 0 | G13: ? | H13: 863715321 | I13: =VLOOKUP($A13,能源品种参考表!$A:$E,5,FALSE) -> hard coal | J13: =D13*VLOOKUP($A13,能源品种参考表!$A:$I,6,FALSE)*VLOOKUP($A13,能源品种参考表!$A:$I,8,FALSE) -> 1.6828691e+13
A14: =VLOOKUP(B14,能源品种参考表!B:I,8,FALSE) -> 27011210 | B14: 炼焦煤 | C14: 2021 | D14: 91532000 | E14: 千克 | F14: 0 | G14: ? | H14: 71811252 | I14: =VLOOKUP($A14,能源品种参考表!$A:$E,5,FALSE) -> hard coal | J14: =D14*VLOOKUP($A14,能源品种参考表!$A:$I,6,FALSE)*VLOOKUP($A14,能源品种参考表!$A:$I,8,FALSE) -> 1.7614856e+12
A15: =VLOOKUP(B15,能源品种参考表!B:I,8,FALSE) -> 27011210 | B15: 炼焦煤 | C15: 2022 | D15: 254956570 | E15: 千克 | F15: 0 | G15: ? | H15: 100824520003 | I15: =VLOOKUP($A15,能源品种参考表!$A:$E,5,FALSE) -> hard coal | J15: =D15*VLOOKUP($A15,能源品种参考表!$A:$I,6,FALSE)*VLOOKUP($A15,能源品种参考表!$A:$I,8,FALSE) -> 4.9065063e+12
A16: =VLOOKUP(B16,能源品种参考表!B:I,8,FALSE) -> 27011290 | B16: 其他烟煤 | C16: 2019 | D16: 2510411233 | E16: 千克 | F16: 0 | G16: ? | H16: 1826131776 | I16: =VLOOKUP($A16,能源品种参考表!$A:$E,5,FALSE) -> hard coal | J16: =D16*VLOOKUP($A16,能源品种参考表!$A:$I,6,FALSE)*VLOOKUP($A16,能源品种参考表!$A:$I,8,FALSE) -> 4.6565068e+13
A17: =VLOOKUP(B17,能源品种参考表!B:I,8,FALSE) -> 27011290 | B17: 其他烟煤 | C17: 2020 | D17: 901973046 | E17: 千克 | F17: 0 | G17: ? | H17: 592298027 | I17: =VLOOKUP($A17,能源品种参考表!$A:$E,5,FALSE) -> hard coal | J17: =D17*VLOOKUP($A17,能源品种参考表!$A:$I,6,FALSE)*VLOOKUP($A17,能源品种参考表!$A:$I,8,FALSE) -> 1.6730501e+13
A18: =VLOOKUP(B18,能源品种参考表!B:I,8,FALSE) -> 27011290 | B18: 其他烟煤 | C18: 2021 | D18: 984265489 | E18: 千克 | F18: 0 | G18: ? | H18: 806705899 | I18: =VLOOKUP($A18,能源品种参考表!$A:$E,5,FALSE) -> hard coal | J18: =D18*VLOOKUP($A18,能源品种参考表!$A:$I,6,FALSE)*VLOOKUP($A18,能源品种参考表!$A:$I,8,FALSE) -> 1.8256925e+13
A19: =VLOOKUP(B19,能源品种参考表!B:I,8,FALSE) -> 27011290 | B19: 其他烟煤 | C19: 2022 | D19: 1602914818 | E19: 千克 | F19: 0 | G19: ? | H19: 54285052466 | I19: =VLOOKUP($A19,能源品种参考表!$A:$E,5,FALSE) -> hard coal | J19: =D19*VLOOKUP($A19,能源品种参考表!$A:$I,6,FALSE)*VLOOKUP($A19,能源品种参考表!$A:$I,8,FALSE) -> 2.9732116e+13
... A34: =VLOOKUP(B34,能源品种参考表!B:I,8,FALSE) -> 27022000 | B34: 制成型的褐煤 | C34: 2022 | D34: 348320 | E34: 千克 | F34: 0 | G34: ? | H34: 213 | I34: =VLOOKUP($A34,能源品种参考表!$A:$E,5,FALSE) -> hard coal | J34: =D34*VLOOKUP($A34,能源品种参考表!$A:$I,6,FALSE)*VLOOKUP($A34,能源品种参考表!$A:$I,8,FALSE) -> 4.6484227e+09
A35: 27030000 | B35: 泥煤（包括肥料用泥煤），不论是否制成型 | C35: 2019 | D35: 3650580 | E35: 千克 | F35: 0 | G35: ? | H35: 3344447 | I35: =VLOOKUP($A35,能源品种参考表!$A:$E,5,FALSE) -> hard coal | J35: =D35*VLOOKUP($A35,能源品种参考表!$A:$I,6,FALSE)*VLOOKUP($A35,能源品种参考表!$A:$I,8,FALSE) -> 3.7611094e+10
A36: 27030000 | B36: 泥煤（包括肥料用泥煤），不论是否制成型 | C36: 2020 | D36: 4095769 | E36: 千克 | F36: 0 | G36: ? | H36: 2720854 | I36: =VLOOKUP($A36,能源品种参考表!$A:$E,5,FALSE) -> hard coal | J36: =D36*VLOOKUP($A36,能源品种参考表!$A:$I,6,FALSE)*VLOOKUP($A36,能源品种参考表!$A:$I,8,FALSE) -> 4.2197775e+10
A37: =VLOOKUP(B37,能源品种参考表!B:I,8,FALSE) -> 27030000 | B37: 泥煤（包括肥料用泥煤），不论是否制成型 | C37: 2021 | D37: 8511800 | E37: 千克 | F37: 0 | G37: ? | H37: 5417881 | I37: =VLOOKUP($A37,能源品种参考表!$A:$E,5,FALSE) -> hard coal | J37: =D37*VLOOKUP($A37,能源品种参考表!$A:$I,6,FALSE)*VLOOKUP($A37,能源品种参考表!$A:$I,8,FALSE) -> 8.7695136e+10
A38: =VLOOKUP(B38,能源品种参考表!B:I,8,FALSE) -> 27030000 | B38: 泥煤（包括肥料用泥煤），不论是否制成型 | C38: 2022 | D38: 5716000 | E38: 千克 | F38: 0 | G38: ? | H38: 871278861 | I38: =VLOOKUP($A38,能源品种参考表!$A:$E,5,FALSE) -> hard coal | J38: =D38*VLOOKUP($A38,能源品种参考表!$A:$I,6,FALSE)*VLOOKUP($A38,能源品种参考表!$A:$I,8,FALSE) -> 5.8890645e+10
A39: =VLOOKUP(B39,能源品种参考表!B:I,8,FALSE) -> 27050000 | B39: 煤气、水煤气、炉煤气及类似气体 | C39: 2022 | D39: 6000 | E39: 千克 | F39: 0 | G39: ? | H39: 99953 | I39: =VLOOKUP($A39,能源品种参考表!$A:$E,5,FALSE) -> LPG propane or butane | J39: =D39*VLOOKUP($A39,能源品种参考表!$A:$I,6,FALSE)*VLOOKUP($A39,能源品种参考表!$A:$I,8,FALSE) -> 33798113
A40: =VLOOKUP(B40,能源品种参考表!B:I,8,FALSE) -> 27079990 | B40: 其他蒸馏高温煤焦油所得油类等产品及类似品 | C40: 2019 | D40: 30704220 | E40: 千克 | F40: 0 | G40: ? | H40: 123342469 | I40: =VLOOKUP($A40,能源品种参考表!$A:$E,5,FALSE) -> petroleum diesel | J40: =D40*VLOOKUP($A40,能源品种参考表!$A:$I,6,FALSE)*VLOOKUP($A40,能源品种参考表!$A:$I,8,FALSE) -> 9.7354872e+11
A41: =VLOOKUP(B41,能源品种参考表!B:I,8,FALSE) -> 27079990 | B41: 其他蒸馏高温煤焦油所得油类等产品及类似品 | C41: 2020 | D41: 6284233 | E41: 千克 | F41: 0 | G41: ? | H41: 68327775 | I41: =VLOOKUP($A41,能源品种参考表!$A:$E,5,FALSE) -> petroleum diesel | J41: =D41*VLOOKUP($A41,能源品种参考表!$A:$I,6,FALSE)*VLOOKUP($A41,能源品种参考表!$A:$I,8,FALSE) -> 1.9925623e+11
A42: =VLOOKUP(B42,能源品种参考表!B:I,8,FALSE) -> 27079990 | B42: 其他蒸馏高温煤焦油所得油类等产品及类似品 | C42: 2021 | D42: 17221792 | E42: 千克 | F42: 790533 | G42: ? | H42: 53047230 | I42: =VLOOKUP($A42,能源品种参考表!$A:$E,5,FALSE) -> petroleum diesel | J42: =D42*VLOOKUP($A42,能源品种参考表!$A:$I,6,FALSE)*VLOOKUP($A42,能源品种参考表!$A:$I,8,FALSE) -> 5.4605698e+11
A43: =VLOOKUP(B43,能源品种参考表!B:I,8,FALSE) -> 27079990 | B43: 其他蒸馏高温煤焦油所得油类等产品及类似品 | C43: 2022 | D43: 39713189 | E43: 千克 | F43: 54918518 | G43: 升 | H43: 267758863 | I43: =VLOOKUP($A43,能源品种参考表!$A:$E,5,FALSE) -> petroleum diesel | J43: =D43*VLOOKUP($A43,能源品种参考表!$A:$I,6,FALSE)*VLOOKUP($A43,能源品种参考表!$A:$I,8,FALSE) -> 1.259199e+12
A44: =VLOOKUP(B44,能源品种参考表!B:I,8,FALSE) -> 27090000 | B44: 石油原油及从沥青矿物提取的原油 | C44: 2017 | D44: 484455385 | E44: 千克 | F44: 0 | G44: ? | H44: 1232246423 | I44: =VLOOKUP($A44,能源品种参考表!$A:$E,5,FALSE) -> crude oil | J44: =D44*VLOOKUP($A44,能源品种参考表!$A:$I,6,FALSE)*VLOOKUP($A44,能源品种参考表!$A:$I,8,FALSE) -> 1.9200866e+13
A45: =VLOOKUP(B45,能源品种参考表!B:I,8,FALSE) -> 27090000 | B45: 石油原油及从沥青矿物提取的原油 | C45: 2018 | D45: 2626588016 | E45: 千克 | F45: 0 | G45: ? | H45: 8414328639 | I45: =VLOOKUP($A45,能源品种参考表!$A:$E,5,FALSE) -> crude oil | J45: =D45*VLOOKUP($A45,能源品种参考表!$A:$I,6,FALSE)*VLOOKUP($A45,能源品种参考表!$A:$I,8,FALSE) -> 1.0410198e+14
A46: =VLOOKUP(B46,能源品种参考表!B:I,8,FALSE) -> 27090000 | B46: 石油原油及从沥青矿物提取的原油 | C46: 2019 | D46: 810025936 | E46: 千克 | F46: 0 | G46: ? | H46: 2458859792 | I46: =VLOOKUP($A46,能源品种参考表!$A:$E,5,FALSE) -> crude oil | J46: =D46*VLOOKUP($A46,能源品种参考表!$A:$I,6,FALSE)*VLOOKUP($A46,能源品种参考表!$A:$I,8,FALSE) -> 3.2104504e+13
A47: =VLOOKUP(B47,能源品种参考表!B:I,8,FALSE) -> 27090000 | B47: 石油原油及从沥青矿物提取的原油 | C47: 2020 | D47: 1638107013 | E47: 千克 | F47: 0 | G47: ? | H47: 3341476728 | I47: =VLOOKUP($A47,能源品种参考表!$A:$E,5,FALSE) -> crude oil | J47: =D47*VLOOKUP($A47,能源品种参考表!$A:$I,6,FALSE)*VLOOKUP($A47,能源品种参考表!$A:$I,8,FALSE) -> 6.4924604e+13
A48: =VLOOKUP(B48,能源品种参考表!B:I,8,FALSE) -> 27090000 | B48: 石油原油及从沥青矿物提取的原油 | C48: 2021 | D48: 2610761502 | E48: 千克 | F48: 0 | G48: ? | H48: 6664195594 | I48: =VLOOKUP($A48,能源品种参考表!$A:$E,5,FALSE) -> crude oil | J48: =D48*VLOOKUP($A48,能源品种参考表!$A:$I,6,FALSE)*VLOOKUP($A48,能源品种参考表!$A:$I,8,FALSE) -> 1.0347471e+14
... A56: =VLOOKUP(B56,能源品种参考表!B:I,8,FALSE) -> 27101220 | B56: 石脑油，不含有生物柴油 | C56: 2022 | D56: 43372169 | E56: 千克 | F56: 60070454 | G56: 升 | H56: 171110499 | I56: =VLOOKUP($A56,能源品种参考表!$A:$E,5,FALSE) -> LPG propane or butane | J56: =D56*VLOOKUP($A56,能源品种参考表!$A:$I,6,FALSE)*VLOOKUP($A56,能源品种参考表!$A:$I,8,FALSE) -> 1.8049678e+12
A57: 27101230 | B57: 橡胶溶剂油、油漆溶剂油、抽提溶剂油，不含有生物柴油 | C57: 2019 | D57: 2599312 | E57: 千克 | F57: 3330690 | G57: 升 | H57: 17758719 | I57: =VLOOKUP($A57,能源品种参考表!$A:$E,5,FALSE) -> heavy fuel oil | J57: =D57*VLOOKUP($A57,能源品种参考表!$A:$I,6,FALSE)*VLOOKUP($A57,能源品种参考表!$A:$I,8,FALSE) -> 1.0580241e+11
A58: 27101230 | B58: 橡胶溶剂油、油漆溶剂油、抽提溶剂油，不含有生物柴油 | C58: 2020 | D58: 3061549 | E58: 千克 | F58: 3921699 | G58: 升 | H58: 17408713 | I58: =VLOOKUP($A58,能源品种参考表!$A:$E,5,FALSE) -> heavy fuel oil | J58: =D58*VLOOKUP($A58,能源品种参考表!$A:$I,6,FALSE)*VLOOKUP($A58,能源品种参考表!$A:$I,8,FALSE) -> 1.2461731e+11
A59: =VLOOKUP(B59,能源品种参考表!B:I,8,FALSE) -> 27101230 | B59: 橡胶溶剂油、油漆溶剂油、抽提溶剂油，不含有生物柴油 | C59: 2021 | D59: 3892526 | E59: 千克 | F59: 4990168 | G59: 升 | H59: 24388292 | I59: =VLOOKUP($A59,能源品种参考表!$A:$E,5,FALSE) -> heavy fuel oil | J59: =D59*VLOOKUP($A59,能源品种参考表!$A:$I,6,FALSE)*VLOOKUP($A59,能源品种参考表!$A:$I,8,FALSE) -> 1.584414e+11
A60: =VLOOKUP(B60,能源品种参考表!B:I,8,FALSE) -> 27101230 | B60: 橡胶溶剂油、油漆溶剂油、抽提溶剂油，不含有生物柴油 | C60: 2022 | D60: 6409595 | E60: 千克 | F60: 8215112 | G60: 升 | H60: 54978404 | I60: =VLOOKUP($A60,能源品种参考表!$A:$E,5,FALSE) -> heavy fuel oil | J60: =D60*VLOOKUP($A60,能源品种参考表!$A:$I,6,FALSE)*VLOOKUP($A60,能源品种参考表!$A:$I,8,FALSE) -> 2.608962e+11
A61: =VLOOKUP(B61,能源品种参考表!B:I,8,FALSE) -> 27101299 | B61: 未列名轻油及其制品，不含有生物柴油 | C61: 2018 | D61: 6346103 | E61: 千克 | F61: 0 | G61: ? | H61: 46405412 | I61: =VLOOKUP($A61,能源品种参考表!$A:$E,5,FALSE) -> petroleum diesel | J61: =D61*VLOOKUP($A61,能源品种参考表!$A:$I,6,FALSE)*VLOOKUP($A61,能源品种参考表!$A:$I,8,FALSE) -> 2.5654944e+11
...

Sheet Import
A1: 商品编码 | B1: 商品名称 | C1: 年份 | D1: 第一数量 | E1: 第一计量单位 | F1: 第二数量 | G1: 第二计量单位 | H1: 人民币 | I1: EPS Fuel | J1: BTU Value
A2: 23069000 | B2: 未列名植物油渣饼及其他固体残渣 | C2: 2017 | D2: 8423467 | E2: 千克 | F2: 0 | G2: ? | H2: 10984314 | I2: =VLOOKUP($A2,能源品种参考表!$A:$E,5,FALSE) -> #N/A | J2: =D2*VLOOKUP($A2,能源品种参考表!$A:$I,6,FALSE)*VLOOKUP($A2,能源品种参考表!$A:$I,8,FALSE) -> #N/A
A3: 23069000 | B3: 未列名植物油渣饼及其他固体残渣 | C3: 2019 | D3: 10663100 | E3: 千克 | F3: 0 | G3: ? | H3: 14269350 | I3: =VLOOKUP($A3,能源品种参考表!$A:$E,5,FALSE) -> #N/A | J3: =D3*VLOOKUP($A3,能源品种参考表!$A:$I,6,FALSE)*VLOOKUP($A3,能源品种参考表!$A:$I,8,FALSE) -> #N/A
A4: 23069000 | B4: 未列名植物油渣饼及其他固体残渣 | C4: 2020 | D4: 24586002 | E4: 千克 | F4: 0 | G4: ? | H4: 35924194 | I4: =VLOOKUP($A4,能源品种参考表!$A:$E,5,FALSE) -> #N/A | J4: =D4*VLOOKUP($A4,能源品种参考表!$A:$I,6,FALSE)*VLOOKUP($A4,能源品种参考表!$A:$I,8,FALSE) -> #N/A
A5: 23069000 | B5: 未列名植物油渣饼及其他固体残渣 | C5: 2021 | D5: 290000 | E5: 千克 | F5: 0 | G5: ? | H5: 281782 | I5: =VLOOKUP($A5,能源品种参考表!$A:$E,5,FALSE) -> #N/A | J5: =D5*VLOOKUP($A5,能源品种参考表!$A:$I,6,FALSE)*VLOOKUP($A5,能源品种参考表!$A:$I,8,FALSE) -> #N/A
A6: 23069000 | B6: 未列名提炼植物或微生物油脂所得的油渣饼及其他固体残渣 | C6: 2022 | D6: 38186653 | E6: 千克 | F6: 0 | G6: ? | H6: 81986145 | I6: =VLOOKUP($A6,能源品种参考表!$A:$E,5,FALSE) -> #N/A | J6: =D6*VLOOKUP($A6,能源品种参考表!$A:$I,6,FALSE)*VLOOKUP($A6,能源品种参考表!$A:$I,8,FALSE) -> #N/A
A7: 26121000 | B7: 铀矿砂及其精矿 | C7: 2018 | D7: 182 | E7: 千克 | F7: 0 | G7: ? | H7: 23356 | I7: =VLOOKUP($A7,能源品种参考表!$A:$E,5,FALSE) -> #N/A | J7: =D7*VLOOKUP($A7,能源品种参考表!$A:$I,6,FALSE)*VLOOKUP($A7,能源品种参考表!$A:$I,8,FALSE) -> #N/A
A8: 26121000 | B8: 铀矿砂及其精矿 | C8: 2020 | D8: 2877 | E8: 千克 | F8: 0 | G8: ? | H8: 384288 | I8: =VLOOKUP($A8,能源品种参考表!$A:$E,5,FALSE) -> #N/A | J8: =D8*VLOOKUP($A8,能源品种参考表!$A:$I,6,FALSE)*VLOOKUP($A8,能源品种参考表!$A:$I,8,FALSE) -> #N/A
A9: 26121000 | B9: 铀矿砂及其精矿 | C9: 2022 | D9: 4006 | E9: 千克 | F9: 0 | G9: ? | H9: 513388 | I9: =VLOOKUP($A9,能源品种参考表!$A:$E,5,FALSE) -> #N/A | J9: =D9*VLOOKUP($A9,能源品种参考表!$A:$I,6,FALSE)*VLOOKUP($A9,能源品种参考表!$A:$I,8,FALSE) -> #N/A
A10: 26122000 | B10: 钍矿砂及其精矿 | C10: 2017 | D10: 6004235 | E10: 千克 | F10: 0 | G10: ? | H10: 110772811 | I10: =VLOOKUP($A10,能源品种参考表!$A:$E,5,FALSE) -> #N/A | J10: =D10*VLOOKUP($A10,能源品种参考表!$A:$I,6,FALSE)*VLOOKUP($A10,能源品种参考表!$A:$I,8,FALSE) -> #N/A
A11: 26122000 | B11: 钍矿砂及其精矿 | C11: 2018 | D11: 13840010 | E11: 千克 | F11: 0 | G11: ? | H11: 138808868 | I11: =VLOOKUP($A11,能源品种参考表!$A:$E,5,FALSE) -> #N/A | J11: =D11*VLOOKUP($A11,能源品种参考表!$A:$I,6,FALSE)*VLOOKUP($A11,能源品种参考表!$A:$I,8,FALSE) -> #N/A
A12: 26122000 | B12: 钍矿砂及其精矿 | C12: 2019 | D12: 284732 | E12: 千克 | F12: 0 | G12: ? | H12: 5589357 | I12: =VLOOKUP($A12,能源品种参考表!$A:$E,5,FALSE) -> #N/A | J12: =D12*VLOOKUP($A12,能源品种参考表!$A:$I,6,FALSE)*VLOOKUP($A12,能源品种参考表!$A:$I,8,FALSE) -> #N/A
A13: 26122000 | B13: 钍矿砂及其精矿 | C13: 2020 | D13: 34220928 | E13: 千克 | F13: 0 | G13: ? | H13: 284012858 | I13: =VLOOKUP($A13,能源品种参考表!$A:$E,5,FALSE) -> #N/A | J13: =D13*VLOOKUP($A13,能源品种参考表!$A:$I,6,FALSE)*VLOOKUP($A13,能源品种参考表!$A:$I,8,FALSE) -> #N/A
... A201: 68152000 | B201: 泥煤制品 | C201: 2022 | D201: 110180 | E201: 千克 | F201: 0 | G201: ? | H201: 318618 | I201: =VLOOKUP($A201,能源品种参考表!$A:$E,5,FALSE) -> hard coal | J201: =D201*VLOOKUP($A201,能源品种参考表!$A:$I,6,FALSE)*VLOOKUP($A201,能源品种参考表!$A:$I,8,FALSE) -> 1.1351594e+09

Sheet BFPIaE-exports
A1: Fuel (BTU) | B1: 2019 | C1: 2020 | D1: 2021 | E1: 2022 | F1: 2023 | G1: 2024 | H1: 2025 | I1: 2026 | J1: 2027 | K1: 2028 | L1: 2029 | M1: 2030 | N1: 2031 | O1: 2032 | P1: 2033 | Q1: 2034 | R1: 2035 | S1: 2036 | T1: 2037 | U1: 2038 | V1: 2039 | W1: 2040 | X1: 2041 | Y1: 2042 | Z1: 2043 | AA1: 2044 | AB1: 2045 | AC1: 2046 | AD1: 2047 | AE1: 2048 | AF1: 2049 | AG1: 2050 | AH1: 2051 | AI1: 2052 | AJ1: 2053 | AK1: 2054 | AL1: 2055 | AM1: 2056 | AN1: 2057 | AO1: 2058 | AP1: 2059 | AQ1: 2060
A2: electricity | B2: 0 | C2: 0 | D2: 0 | E2: 0 | F2: 0 | G2: 0 | H2: 0 | I2: 0 | J2: 0 | K2: 0 | L2: 0 | M2: 0 | N2: 0 | O2: 0 | P2: 0 | Q2: 0 | R2: 0 | S2: 0 | T2: 0 | U2: 0 | V2: 0 | W2: 0 | X2: 0 | Y2: 0 | Z2: 0 | AA2: 0 | AB2: 0 | AC2: 0 | AD2: 0 | AE2: 0 | AF2: 0 | AG2: 0 | AH2: 0 | AI2: 0 | AJ2: 0 | AK2: 0 | AL2: 0 | AM2: 0 | AN2: 0 | AO2: 0 | AP2: 0 | AQ2: 0
A3: hard coal | B3: =SUMIFS(Export!$J:$J,Export!$I:$I,$A3,Export!$C:$C,'BFPIaE-exports'!B$1) -> 1.1406171e+14 | C3: =SUMIFS(Export!$J:$J,Export!$I:$I,$A3,Export!$C:$C,'BFPIaE-exports'!C$1) -> 6.0693251e+13 | D3: =SUMIFS(Export!$J:$J,Export!$I:$I,$A3,Export!$C:$C,'BFPIaE-exports'!D$1) -> 4.9357338e+13 | E3: =SUMIFS(Export!$J:$J,Export!$I:$I,$A3,Export!$C:$C,'BFPIaE-exports'!E$1) -> 7.5802526e+13 | F3: =E3 -> 7.5802526e+13 | G3: =F3 -> 7.5802526e+13 | H3: =G3 -> 7.5802526e+13 | I3: =H3 -> 7.5802526e+13 | J3: =I3 -> 7.5802526e+13 | K3: =J3 -> 7.5802526e+13 | L3: =K3 -> 7.5802526e+13 | M3: =L3 -> 7.5802526e+13 | ... AQ3: =AP3 -> 7.5802526e+13
A4: natural gas | B4: =SUMIFS(Export!$J:$J,Export!$I:$I,$A4,Export!$C:$C,'BFPIaE-exports'!B$1) -> 1.2735418e+14 | C4: =SUMIFS(Export!$J:$J,Export!$I:$I,$A4,Export!$C:$C,'BFPIaE-exports'!C$1) -> 1.8248517e+14 | D4: =SUMIFS(Export!$J:$J,Export!$I:$I,$A4,Export!$C:$C,'BFPIaE-exports'!D$1) -> 1.9510443e+14 | E4: =SUMIFS(Export!$J:$J,Export!$I:$I,$A4,Export!$C:$C,'BFPIaE-exports'!E$1) -> 2.0614353e+14 | F4: =E4 -> 2.0614353e+14 | G4: =F4 -> 2.0614353e+14 | H4: =G4 -> 2.0614353e+14 | I4: =H4 -> 2.0614353e+14 | J4: =I4 -> 2.0614353e+14 | K4: =J4 -> 2.0614353e+14 | L4: =K4 -> 2.0614353e+14 | M4: =L4 -> 2.0614353e+14 | ... AQ4: =AP4 -> 2.0614353e+14
A5: nuclear | B5: =SUMIFS(Export!$J:$J,Export!$I:$I,$A5,Export!$C:$C,'BFPIaE-exports'!B$1) -> 5.225943e+14 | C5: =SUMIFS(Export!$J:$J,Export!$I:$I,$A5,Export!$C:$C,'BFPIaE-exports'!C$1) -> 8.6522563e+14 | D5: =SUMIFS(Export!$J:$J,Export!$I:$I,$A5,Export!$C:$C,'BFPIaE-exports'!D$1) -> 3.7376829e+14 | E5: =SUMIFS(Export!$J:$J,Export!$I:$I,$A5,Export!$C:$C,'BFPIaE-exports'!E$1) -> 3.8039472e+14 | F5: =E5 -> 3.8039472e+14 | G5: =F5 -> 3.8039472e+14 | H5: =G5 -> 3.8039472e+14 | I5: =H5 -> 3.8039472e+14 | J5: =I5 -> 3.8039472e+14 | K5: =J5 -> 3.8039472e+14 | L5: =K5 -> 3.8039472e+14 | M5: =L5 -> 3.8039472e+14 | ... AQ5: =AP5 -> 3.8039472e+14
A6: hydro (is not a fuel) | B6: =SUMIFS(Export!$J:$J,Export!$I:$I,$A6,Export!$C:$C,'BFPIaE-exports'!B$1) -> 0 | C6: =SUMIFS(Export!$J:$J,Export!$I:$I,$A6,Export!$C:$C,'BFPIaE-exports'!C$1) -> 0 | D6: =SUMIFS(Export!$J:$J,Export!$I:$I,$A6,Export!$C:$C,'BFPIaE-exports'!D$1) -> 0 | E6: =SUMIFS(Export!$J:$J,Export!$I:$I,$A6,Export!$C:$C,'BFPIaE-exports'!E$1) -> 0 | F6: =E6 -> 0 | G6: =F6 -> 0 | H6: =G6 -> 0 | I6: =H6 -> 0 | J6: =I6 -> 0 | K6: =J6 -> 0 | L6: =K6 -> 0 | M6: =L6 -> 0 | ... AQ6: =AP6 -> 0
A7: wind (is not a fuel) | B7: =SUMIFS(Export!$J:$J,Export!$I:$I,$A7,Export!$C:$C,'BFPIaE-exports'!B$1) -> 0 | C7: =SUMIFS(Export!$J:$J,Export!$I:$I,$A7,Export!$C:$C,'BFPIaE-exports'!C$1) -> 0 | D7: =SUMIFS(Export!$J:$J,Export!$I:$I,$A7,Export!$C:$C,'BFPIaE-exports'!D$1) -> 0 | E7: =SUMIFS(Export!$J:$J,Export!$I:$I,$A7,Export!$C:$C,'BFPIaE-exports'!E$1) -> 0 | F7: =E7 -> 0 | G7: =F7 -> 0 | H7: =G7 -> 0 | I7: =H7 -> 0 | J7: =I7 -> 0 | K7: =J7 -> 0 | L7: =K7 -> 0 | M7: =L7 -> 0 | ... AQ7: =AP7 -> 0
A8: solar (is not a fuel) | B8: =SUMIFS(Export!$J:$J,Export!$I:$I,$A8,Export!$C:$C,'BFPIaE-exports'!B$1) -> 0 | C8: =SUMIFS(Export!$J:$J,Export!$I:$I,$A8,Export!$C:$C,'BFPIaE-exports'!C$1) -> 0 | D8: =SUMIFS(Export!$J:$J,Export!$I:$I,$A8,Export!$C:$C,'BFPIaE-exports'!D$1) -> 0 | E8: =SUMIFS(Export!$J:$J,Export!$I:$I,$A8,Export!$C:$C,'BFPIaE-exports'!E$1) -> 0 | F8: =E8 -> 0 | G8: =F8 -> 0 | H8: =G8 -> 0 | I8: =H8 -> 0 | J8: =I8 -> 0 | K8: =J8 -> 0 | L8: =K8 -> 0 | M8: =L8 -> 0 | ... AQ8: =AP8 -> 0
A9: biomass | B9: =SUMIFS(Export!$J:$J,Export!$I:$I,$A9,Export!$C:$C,'BFPIaE-exports'!B$1) -> 0 | C9: =SUMIFS(Export!$J:$J,Export!$I:$I,$A9,Export!$C:$C,'BFPIaE-exports'!C$1) -> 0 | D9: =SUMIFS(Export!$J:$J,Export!$I:$I,$A9,Export!$C:$C,'BFPIaE-exports'!D$1) -> 0 | E9: =SUMIFS(Export!$J:$J,Export!$I:$I,$A9,Export!$C:$C,'BFPIaE-exports'!E$1) -> 0 | F9: =E9 -> 0 | G9: =F9 -> 0 | H9: =G9 -> 0 | I9: =H9 -> 0 | J9: =I9 -> 0 | K9: =J9 -> 0 | L9: =K9 -> 0 | M9: =L9 -> 0 | ... AQ9: =AP9 -> 0
A10: petroleum gasoline | B10: =SUMIFS(Export!$J:$J,Export!$I:$I,$A10,Export!$C:$C,'BFPIaE-exports'!B$1) -> 6.6828944e+14 | C10: =SUMIFS(Export!$J:$J,Export!$I:$I,$A10,Export!$C:$C,'BFPIaE-exports'!C$1) -> 6.5315821e+14 | D10: =SUMIFS(Export!$J:$J,Export!$I:$I,$A10,Export!$C:$C,'BFPIaE-exports'!D$1) -> 5.9364892e+14 | E10: =SUMIFS(Export!$J:$J,Export!$I:$I,$A10,Export!$C:$C,'BFPIaE-exports'!E$1) -> 5.1283964e+14 | F10: =E10 -> 5.1283964e+14 | G10: =F10 -> 5.1283964e+14 | H10: =G10 -> 5.1283964e+14 | I10: =H10 -> 5.1283964e+14 | J10: =I10 -> 5.1283964e+14 | K10: =J10 -> 5.1283964e+14 | L10: =K10 -> 5.1283964e+14 | M10: =L10 -> 5.1283964e+14 | ... AQ10: =AP10 -> 5.1283964e+14
A11: petroleum diesel | B11: =SUMIFS(Export!$J:$J,Export!$I:$I,$A11,Export!$C:$C,'BFPIaE-exports'!B$1) -> 962942311498889 | C11: =SUMIFS(Export!$J:$J,Export!$I:$I,$A11,Export!$C:$C,'BFPIaE-exports'!C$1) -> 8.7481273e+14 | D11: =SUMIFS(Export!$J:$J,Export!$I:$I,$A11,Export!$C:$C,'BFPIaE-exports'!D$1) -> 7.7363471e+14 | E11: =SUMIFS(Export!$J:$J,Export!$I:$I,$A11,Export!$C:$C,'BFPIaE-exports'!E$1) -> 5.1685583e+14 | F11: =E11 -> 5.1685583e+14 | G11: =F11 -> 5.1685583e+14 | H11: =G11 -> 5.1685583e+14 | I11: =H11 -> 5.1685583e+14 | J11: =I11 -> 5.1685583e+14 | K11: =J11 -> 5.1685583e+14 | L11: =K11 -> 5.1685583e+14 | M11: =L11 -> 5.1685583e+14 | ... AQ11: =AP11 -> 5.1685583e+14
A12: biofuel gasoline | B12: =SUMIFS(Export!$J:$J,Export!$I:$I,$A12,Export!$C:$C,'BFPIaE-exports'!B$1) -> 0 | C12: =SUMIFS(Export!$J:$J,Export!$I:$I,$A12,Export!$C:$C,'BFPIaE-exports'!C$1) -> 0 | D12: =SUMIFS(Export!$J:$J,Export!$I:$I,$A12,Export!$C:$C,'BFPIaE-exports'!D$1) -> 0 | E12: =SUMIFS(Export!$J:$J,Export!$I:$I,$A12,Export!$C:$C,'BFPIaE-exports'!E$1) -> 0 | F12: =E12 -> 0 | G12: =F12 -> 0 | H12: =G12 -> 0 | I12: =H12 -> 0 | J12: =I12 -> 0 | K12: =J12 -> 0 | L12: =K12 -> 0 | M12: =L12 -> 0 | ... AQ12: =AP12 -> 0
A13: biofuel diesel | B13: =SUMIFS(Export!$J:$J,Export!$I:$I,$A13,Export!$C:$C,'BFPIaE-exports'!B$1) -> 2.4430808e+13 | C13: =SUMIFS(Export!$J:$J,Export!$I:$I,$A13,Export!$C:$C,'BFPIaE-exports'!C$1) -> 3.3624924e+13 | D13: =SUMIFS(Export!$J:$J,Export!$I:$I,$A13,Export!$C:$C,'BFPIaE-exports'!D$1) -> 4.773104e+13 | E13: =SUMIFS(Export!$J:$J,Export!$I:$I,$A13,Export!$C:$C,'BFPIaE-exports'!E$1) -> 6.622014e+13 | F13: =E13 -> 6.622014e+13 | G13: =F13 -> 6.622014e+13 | H13: =G13 -> 6.622014e+13 | I13: =H13 -> 6.622014e+13 | J13: =I13 -> 6.622014e+13 | K13: =J13 -> 6.622014e+13 | L13: =K13 -> 6.622014e+13 | M13: =L13 -> 6.622014e+13 | ... AQ13: =AP13 -> 6.622014e+13
A14: jet fuel or kerosene | B14: =SUMIFS(Export!$J:$J,Export!$I:$I,$A14,Export!$C:$C,'BFPIaE-exports'!B$1) -> 7.1907973e+14 | C14: =SUMIFS(Export!$J:$J,Export!$I:$I,$A14,Export!$C:$C,'BFPIaE-exports'!C$1) -> 4.0719779e+14 | D14: =SUMIFS(Export!$J:$J,Export!$I:$I,$A14,Export!$C:$C,'BFPIaE-exports'!D$1) -> 3.5005285e+14 | E14: =SUMIFS(Export!$J:$J,Export!$I:$I,$A14,Export!$C:$C,'BFPIaE-exports'!E$1) -> 4.4684865e+14 | F14: =E14 -> 4.4684865e+14 | G14: =F14 -> 4.4684865e+14 | H14: =G14 -> 4.4684865e+14 | I14: =H14 -> 4.4684865e+14 | J14: =I14 -> 4.4684865e+14 | K14: =J14 -> 4.4684865e+14 | L14: =K14 -> 4.4684865e+14 | M14: =L14 -> 4.4684865e+14 | ... AQ14: =AP14 -> 4.4684865e+14
... A17: lignite | B17: =SUMIFS(Export!$J:$J,Export!$I:$I,$A17,Export!$C:$C,'BFPIaE-exports'!B$1) -> 0 | C17: =SUMIFS(Export!$J:$J,Export!$I:$I,$A17,Export!$C:$C,'BFPIaE-exports'!C$1) -> 0 | D17: =SUMIFS(Export!$J:$J,Export!$I:$I,$A17,Export!$C:$C,'BFPIaE-exports'!D$1) -> 0 | E17: =SUMIFS(Export!$J:$J,Export!$I:$I,$A17,Export!$C:$C,'BFPIaE-exports'!E$1) -> 0 | F17: =E17 -> 0 | G17: =F17 -> 0 | H17: =G17 -> 0 | I17: =H17 -> 0 | J17: =I17 -> 0 | K17: =J17 -> 0 | L17: =K17 -> 0 | M17: =L17 -> 0 | ... AQ17: =AP17 -> 0
A18: crude oil | B18: 3.2105175e+13 | C18: 6.5003071e+13 | D18: 6.5003071e+13 | E18: 6.5003071e+13 | F18: =E18 -> 6.5003071e+13 | G18: =F18 -> 6.5003071e+13 | H18: =G18 -> 6.5003071e+13 | I18: =H18 -> 6.5003071e+13 | J18: =I18 -> 6.5003071e+13 | K18: =J18 -> 6.5003071e+13 | L18: =K18 -> 6.5003071e+13 | M18: =L18 -> 6.5003071e+13 | ... AQ18: =AP18 -> 6.5003071e+13
A19: heavy fuel oil | B19: =SUMIFS(Export!$J:$J,Export!$I:$I,$A19,Export!$C:$C,'BFPIaE-exports'!B$1) -> 4.4307858e+14 | C19: =SUMIFS(Export!$J:$J,Export!$I:$I,$A19,Export!$C:$C,'BFPIaE-exports'!C$1) -> 6.2765096e+14 | D19: =SUMIFS(Export!$J:$J,Export!$I:$I,$A19,Export!$C:$C,'BFPIaE-exports'!D$1) -> 777500555810999 | E19: =SUMIFS(Export!$J:$J,Export!$I:$I,$A19,Export!$C:$C,'BFPIaE-exports'!E$1) -> 7.3997772e+14 | F19: =E19 -> 7.3997772e+14 | G19: =F19 -> 7.3997772e+14 | H19: =G19 -> 7.3997772e+14 | I19: =H19 -> 7.3997772e+14 | J19: =I19 -> 7.3997772e+14 | K19: =J19 -> 7.3997772e+14 | L19: =K19 -> 7.3997772e+14 | M19: =L19 -> 7.3997772e+14 | ... AQ19: =AP19 -> 7.3997772e+14
A20: LPG propane or butane | B20: =SUMIFS(Export!$J:$J,Export!$I:$I,$A20,Export!$C:$C,'BFPIaE-exports'!B$1) -> 2.9914269e+13 | C20: =SUMIFS(Export!$J:$J,Export!$I:$I,$A20,Export!$C:$C,'BFPIaE-exports'!C$1) -> 3.2680527e+13 | D20: =SUMIFS(Export!$J:$J,Export!$I:$I,$A20,Export!$C:$C,'BFPIaE-exports'!D$1) -> 4.4540454e+13 | E20: =SUMIFS(Export!$J:$J,Export!$I:$I,$A20,Export!$C:$C,'BFPIaE-exports'!E$1) -> 4.7196218e+13 | F20: =E20 -> 4.7196218e+13 | G20: =F20 -> 4.7196218e+13 | H20: =G20 -> 4.7196218e+13 | I20: =H20 -> 4.7196218e+13 | J20: =I20 -> 4.7196218e+13 | K20: =J20 -> 4.7196218e+13 | L20: =K20 -> 4.7196218e+13 | M20: =L20 -> 4.7196218e+13 | ... AQ20: =AP20 -> 4.7196218e+13
A21: municipal solid waste | B21: =SUMIFS(Export!$J:$J,Export!$I:$I,$A21,Export!$C:$C,'BFPIaE-exports'!B$1) -> 0 | C21: =SUMIFS(Export!$J:$J,Export!$I:$I,$A21,Export!$C:$C,'BFPIaE-exports'!C$1) -> 0 | D21: =SUMIFS(Export!$J:$J,Export!$I:$I,$A21,Export!$C:$C,'BFPIaE-exports'!D$1) -> 0 | E21: =SUMIFS(Export!$J:$J,Export!$I:$I,$A21,Export!$C:$C,'BFPIaE-exports'!E$1) -> 0 | F21: =E21 -> 0 | G21: =F21 -> 0 | H21: =G21 -> 0 | I21: =H21 -> 0 | J21: =I21 -> 0 | K21: =J21 -> 0 | L21: =K21 -> 0 | M21: =L21 -> 0 | ... AQ21: =AP21 -> 0
A22: hydrogen | B22: =SUMIFS(Export!$J:$J,Export!$I:$I,$A22,Export!$C:$C,'BFPIaE-exports'!B$1) -> 4925729 | C22: =SUMIFS(Export!$J:$J,Export!$I:$I,$A22,Export!$C:$C,'BFPIaE-exports'!C$1) -> 7862062.3 | D22: =SUMIFS(Export!$J:$J,Export!$I:$I,$A22,Export!$C:$C,'BFPIaE-exports'!D$1) -> 4733769.7 | E22: =SUMIFS(Export!$J:$J,Export!$I:$I,$A22,Export!$C:$C,'BFPIaE-exports'!E$1) -> 5634784.1 | F22: =E22 -> 5634784.1 | G22: =F22 -> 5634784.1 | H22: =G22 -> 5634784.1 | I22: =H22 -> 5634784.1 | J22: =I22 -> 5634784.1 | K22: =J22 -> 5634784.1 | L22: =K22 -> 5634784.1 | M22: =L22 -> 5634784.1 | ... AQ22: =AP22 -> 5634784.1

Sheet BFPIaE-imports
A1: Fuel (BTU) | B1: 2019 | C1: 2020 | D1: 2021 | E1: 2022 | F1: 2023 | G1: 2024 | H1: 2025 | I1: 2026 | J1: 2027 | K1: 2028 | L1: 2029 | M1: 2030 | N1: 2031 | O1: 2032 | P1: 2033 | Q1: 2034 | R1: 2035 | S1: 2036 | T1: 2037 | U1: 2038 | V1: 2039 | W1: 2040 | X1: 2041 | Y1: 2042 | Z1: 2043 | AA1: 2044 | AB1: 2045 | AC1: 2046 | AD1: 2047 | AE1: 2048 | AF1: 2049 | AG1: 2050 | AH1: 2051 | AI1: 2052 | AJ1: 2053 | AK1: 2054 | AL1: 2055 | AM1: 2056 | AN1: 2057 | AO1: 2058 | AP1: 2059 | AQ1: 2060
A2: electricity | B2: 0 | C2: 0 | D2: 0 | E2: 0 | F2: 0 | G2: 0 | H2: 0 | I2: 0 | J2: 0 | K2: 0 | L2: 0 | M2: 0 | N2: 0 | O2: 0 | P2: 0 | Q2: 0 | R2: 0 | S2: 0 | T2: 0 | U2: 0 | V2: 0 | W2: 0 | X2: 0 | Y2: 0 | Z2: 0 | AA2: 0 | AB2: 0 | AC2: 0 | AD2: 0 | AE2: 0 | AF2: 0 | AG2: 0 | AH2: 0 | AI2: 0 | AJ2: 0 | AK2: 0 | AL2: 0 | AM2: 0 | AN2: 0 | AO2: 0 | AP2: 0 | AQ2: 0
A3: hard coal | B3: =SUMIFS(Import!$J:$J,Import!$I:$I,$A3,Import!$C:$C,'BFPIaE-imports'!B$1) -> 5.1271615e+15 | C3: =SUMIFS(Import!$J:$J,Import!$I:$I,$A3,Import!$C:$C,'BFPIaE-imports'!C$1) -> 5.2171731e+15 | D3: =SUMIFS(Import!$J:$J,Import!$I:$I,$A3,Import!$C:$C,'BFPIaE-imports'!D$1) -> 5.4928196e+15 | E3: =SUMIFS(Import!$J:$J,Import!$I:$I,$A3,Import!$C:$C,'BFPIaE-imports'!E$1) -> 4.8636655e+15 | F3: =E3 -> 4.8636655e+15 | G3: =F3 -> 4.8636655e+15 | H3: =G3 -> 4.8636655e+15 | I3: =H3 -> 4.8636655e+15 | J3: =I3 -> 4.8636655e+15 | K3: =J3 -> 4.8636655e+15 | L3: =K3 -> 4.8636655e+15 | M3: =L3 -> 4.8636655e+15 | ... AQ3: =AP3 -> 4.8636655e+15
A4: natural gas | B4: =SUMIFS(Import!$J:$J,Import!$I:$I,$A4,Import!$C:$C,'BFPIaE-imports'!B$1) -> 4.7046363e+15 | C4: =SUMIFS(Import!$J:$J,Import!$I:$I,$A4,Import!$C:$C,'BFPIaE-imports'!C$1) -> 4.9348844e+15 | D4: =SUMIFS(Import!$J:$J,Import!$I:$I,$A4,Import!$C:$C,'BFPIaE-imports'!D$1) -> 5.9118729e+15 | E4: =SUMIFS(Import!$J:$J,Import!$I:$I,$A4,Import!$C:$C,'BFPIaE-imports'!E$1) -> 5.3258281e+15 | F4: =E4 -> 5.3258281e+15 | G4: =F4 -> 5.3258281e+15 | H4: =G4 -> 5.3258281e+15 | I4: =H4 -> 5.3258281e+15 | J4: =I4 -> 5.3258281e+15 | K4: =J4 -> 5.3258281e+15 | L4: =K4 -> 5.3258281e+15 | M4: =L4 -> 5.3258281e+15 | ... AQ4: =AP4 -> 5.3258281e+15
A5: nuclear | B5: =SUMIFS(Import!$J:$J,Import!$I:$I,$A5,Import!$C:$C,'BFPIaE-imports'!B$1) -> 1.0624104e+14 | C5: =SUMIFS(Import!$J:$J,Import!$I:$I,$A5,Import!$C:$C,'BFPIaE-imports'!C$1) -> 757152529921237 | D5: =SUMIFS(Import!$J:$J,Import!$I:$I,$A5,Import!$C:$C,'BFPIaE-imports'!D$1) -> 59094374 | E5: =SUMIFS(Import!$J:$J,Import!$I:$I,$A5,Import!$C:$C,'BFPIaE-imports'!E$1) -> 3.4563032e+15 | F5: =E5 -> 3.4563032e+15 | G5: =F5 -> 3.4563032e+15 | H5: =G5 -> 3.4563032e+15 | I5: =H5 -> 3.4563032e+15 | J5: =I5 -> 3.4563032e+15 | K5: =J5 -> 3.4563032e+15 | L5: =K5 -> 3.4563032e+15 | M5: =L5 -> 3.4563032e+15 | ... AQ5: =AP5 -> 3.4563032e+15
A6: hydro (is not a fuel) | B6: =SUMIFS(Import!$J:$J,Import!$I:$I,$A6,Import!$C:$C,'BFPIaE-imports'!B$1) -> 0 | C6: =SUMIFS(Import!$J:$J,Import!$I:$I,$A6,Import!$C:$C,'BFPIaE-imports'!C$1) -> 0 | D6: =SUMIFS(Import!$J:$J,Import!$I:$I,$A6,Import!$C:$C,'BFPIaE-imports'!D$1) -> 0 | E6: =SUMIFS(Import!$J:$J,Import!$I:$I,$A6,Import!$C:$C,'BFPIaE-imports'!E$1) -> 0 | F6: =E6 -> 0 | G6: =F6 -> 0 | H6: =G6 -> 0 | I6: =H6 -> 0 | J6: =I6 -> 0 | K6: =J6 -> 0 | L6: =K6 -> 0 | M6: =L6 -> 0 | ... AQ6: =AP6 -> 0
A7: wind (is not a fuel) | B7: =SUMIFS(Import!$J:$J,Import!$I:$I,$A7,Import!$C:$C,'BFPIaE-imports'!B$1) -> 0 | C7: =SUMIFS(Import!$J:$J,Import!$I:$I,$A7,Import!$C:$C,'BFPIaE-imports'!C$1) -> 0 | D7: =SUMIFS(Import!$J:$J,Import!$I:$I,$A7,Import!$C:$C,'BFPIaE-imports'!D$1) -> 0 | E7: =SUMIFS(Import!$J:$J,Import!$I:$I,$A7,Import!$C:$C,'BFPIaE-imports'!E$1) -> 0 | F7: =E7 -> 0 | G7: =F7 -> 0 | H7: =G7 -> 0 | I7: =H7 -> 0 | J7: =I7 -> 0 | K7: =J7 -> 0 | L7: =K7 -> 0 | M7: =L7 -> 0 | ... AQ7: =AP7 -> 0
A8: solar (is not a fuel) | B8: =SUMIFS(Import!$J:$J,Import!$I:$I,$A8,Import!$C:$C,'BFPIaE-imports'!B$1) -> 0 | C8: =SUMIFS(Import!$J:$J,Import!$I:$I,$A8,Import!$C:$C,'BFPIaE-imports'!C$1) -> 0 | D8: =SUMIFS(Import!$J:$J,Import!$I:$I,$A8,Import!$C:$C,'BFPIaE-imports'!D$1) -> 0 | E8: =SUMIFS(Import!$J:$J,Import!$I:$I,$A8,Import!$C:$C,'BFPIaE-imports'!E$1) -> 0 | F8: =E8 -> 0 | G8: =F8 -> 0 | H8: =G8 -> 0 | I8: =H8 -> 0 | J8: =I8 -> 0 | K8: =J8 -> 0 | L8: =K8 -> 0 | M8: =L8 -> 0 | ... AQ8: =AP8 -> 0
A9: biomass | B9: =SUMIFS(Import!$J:$J,Import!$I:$I,$A9,Import!$C:$C,'BFPIaE-imports'!B$1) -> 0 | C9: =SUMIFS(Import!$J:$J,Import!$I:$I,$A9,Import!$C:$C,'BFPIaE-imports'!C$1) -> 0 | D9: =SUMIFS(Import!$J:$J,Import!$I:$I,$A9,Import!$C:$C,'BFPIaE-imports'!D$1) -> 0 | E9: =SUMIFS(Import!$J:$J,Import!$I:$I,$A9,Import!$C:$C,'BFPIaE-imports'!E$1) -> 0 | F9: =E9 -> 0 | G9: =F9 -> 0 | H9: =G9 -> 0 | I9: =H9 -> 0 | J9: =I9 -> 0 | K9: =J9 -> 0 | L9: =K9 -> 0 | M9: =L9 -> 0 | ... AQ9: =AP9 -> 0
A10: petroleum gasoline | B10: =SUMIFS(Import!$J:$J,Import!$I:$I,$A10,Import!$C:$C,'BFPIaE-imports'!B$1) -> 1.3609163e+13 | C10: =SUMIFS(Import!$J:$J,Import!$I:$I,$A10,Import!$C:$C,'BFPIaE-imports'!C$1) -> 1.9613419e+13 | D10: =SUMIFS(Import!$J:$J,Import!$I:$I,$A10,Import!$C:$C,'BFPIaE-imports'!D$1) -> 1.4600489e+13 | E10: =SUMIFS(Import!$J:$J,Import!$I:$I,$A10,Import!$C:$C,'BFPIaE-imports'!E$1) -> 8.2037026e+11 | F10: =E10 -> 8.2037026e+11 | G10: =F10 -> 8.2037026e+11 | H10: =G10 -> 8.2037026e+11 | I10: =H10 -> 8.2037026e+11 | J10: =I10 -> 8.2037026e+11 | K10: =J10 -> 8.2037026e+11 | L10: =K10 -> 8.2037026e+11 | M10: =L10 -> 8.2037026e+11 | ... AQ10: =AP10 -> 8.2037026e+11
A11: petroleum diesel | B11: =SUMIFS(Import!$J:$J,Import!$I:$I,$A11,Import!$C:$C,'BFPIaE-imports'!B$1) -> 742046912325828 | C11: =SUMIFS(Import!$J:$J,Import!$I:$I,$A11,Import!$C:$C,'BFPIaE-imports'!C$1) -> 1.051466e+15 | D11: =SUMIFS(Import!$J:$J,Import!$I:$I,$A11,Import!$C:$C,'BFPIaE-imports'!D$1) -> 8.6953115e+14 | E11: =SUMIFS(Import!$J:$J,Import!$I:$I,$A11,Import!$C:$C,'BFPIaE-imports'!E$1) -> 6.0772315e+14 | F11: =E11 -> 6.0772315e+14 | G11: =F11 -> 6.0772315e+14 | H11: =G11 -> 6.0772315e+14 | I11: =H11 -> 6.0772315e+14 | J11: =I11 -> 6.0772315e+14 | K11: =J11 -> 6.0772315e+14 | L11: =K11 -> 6.0772315e+14 | M11: =L11 -> 6.0772315e+14 | ... AQ11: =AP11 -> 6.0772315e+14
