Workbook

Sheet 2015-20线路长度
A1: 地区 | B1: 年份 | C1: 分地区35千伏及以上输电线路杆路长度 | S1: 35千伏及以上输电线路回路长度 | AI1: 电缆
C2: 总计 | D2: 一、直流 工程 | E2: ±1000千伏 | F2: ±800千伏 | G2: ±660千伏 | H2: ±500千伏 | I2: ±400千伏 | J2: 土 400千伏 以下 | K2: 二、交 流工程 | L2: 1000千伏 | M2: 750千伏 | N2: 500千伏 | O2: 330千伏 | P2: 220千伏 | Q2: 110千伏 (含66千伏） | R2: 35千伏 | S2: 总计 | T2: 一、直流 工程 | U2: ±1100千伏 | V2: ±800千伏 | W2: ±660千伏 | X2: 土 500千伏 | Y2: ±400千伏 | Z2: ±400千伏 以下 | AA2: 二、交流工 程 | AB2: 1000千伏 | AC2: 750千伏 | AD2: 500千伏 | AE2: 330千伏 | AF2: 220千伏 | AG2: 110千伏 (含66千伏） | AH2: 35千伏
A3: 全国 | B3: 2015 | C3: 1521011 | D3: =SUM(E3:J3) -> 12947 | F3: 10580 | G3: 1336 | I3: 1031 | K3: =SUM(L3:R3) -> 1508064 | L3: 2297 | M3: 12704 | N3: 140394 | O3: 25314 | P3: 318597 | Q3: 526325 | R3: 482433 | S3: 1696849 | T3: =SUM(U3:Z3) -> 25428 | V3: 10580 | W3: 1336 | X3: 11872 | Y3: 1640 | AA3: =SUM(AB3:AH3) -> 1671419 | AB3: 3114 | AC3: 15665 | AD3: 157973 | AE3: 26811 | AF3: 380121 | AG3: 591637 | AH3: 496098 | AI3: 50063
A4: 北京 | B4: 2015 | C4: 8789 | D4: =SUM(E4:J4) -> 0 | K4: =SUM(L4:R4) -> 8789 | N4: 1460 | P4: 2546 | Q4: 3005 | R4: 1778 | S4: 9953 | T4: =SUM(U4:Z4) -> 0 | X4: 0 | AA4: =SUM(AB4:AH4) -> 9953 | AD4: 1506 | AF4: 2810 | AG4: 3717 | AH4: 1920 | AI4: 1923
A5: 天津 | B5: 2015 | C5: 9945 | D5: =SUM(E5:J5) -> 0 | K5: =SUM(L5:R5) -> 9945 | N5: 804 | P5: 2850 | Q5: 3143 | R5: 3148 | S5: 11806 | T5: =SUM(U5:Z5) -> 0 | X5: 0 | AA5: =SUM(AB5:AH5) -> 11806 | AD5: 804 | AF5: 2850 | AG5: 3747 | AH5: 4405 | AI5: 5796
A6: 河北 | B6: 2015 | C6: 82795 | D6: =SUM(E6:J6) -> 202 | G6: 202 | K6: =SUM(L6:R6) -> 82592 | N6: 10108 | P6: 16443 | Q6: 27228 | R6: 28813 | S6: 92100 | T6: =SUM(U6:Z6) -> 202 | W6: 202 | X6: 0 | AA6: =SUM(AB6:AH6) -> 91899 | AD6: 10561 | AF6: 20342 | AG6: 30729 | AH6: 30267 | AI6: 1508
A7: 山西 | B7: 2015 | C7: 62667 | D7: =SUM(E7:J7) -> 554 | F7: 249 | G7: 305 | K7: =SUM(L7:R7) -> 62113 | L7: 116 | N7: 7329 | P7: 13884 | Q7: 18061 | R7: 22723 | S7: 65881 | T7: =SUM(U7:Z7) -> 554 | V7: 249 | W7: 305 | X7: 0 | AA7: =SUM(AB7:AH7) -> 65326 | AB7: 116 | AD7: 7978 | AF7: 15322 | AG7: 19113 | AH7: 22797 | AI7: 675
A8: 内蒙古 | B8: 2015 | C8: 87396 | D8: =SUM(E8:J8) -> 0 | K8: =SUM(L8:R8) -> 87396 | N8: 7329 | P8: 25276 | Q8: 36459 | R8: 18332 | S8: 89517 | T8: =SUM(U8:Z8) -> 715 | X8: 715 | AA8: =SUM(AB8:AH8) -> 88802 | AD8: 7215 | AF8: 25995 | AG8: 37252 | AH8: 18340 | AI8: 82
A9: 辽宁 | B9: 2015 | C9: 43296 | D9: =SUM(E9:J9) -> 0 | K9: =SUM(L9:R9) -> 43296 | N9: 6360 | P9: 13106 | Q9: 23795 | R9: 35 | S9: 56829 | T9: =SUM(U9:Z9) -> 193 | X9: 193 | AA9: =SUM(AB9:AH9) -> 56636 | AD9: 7569 | AF9: 17094 | AG9: 31935 | AH9: 38 | AI9: 1180
A10: 吉林 | B10: 2015 | C10: 26842 | D10: =SUM(E10:J10) -> 0 | K10: =SUM(L10:R10) -> 26842 | N10: 2342 | P10: 8727 | Q10: 15729 | R10: 44 | S10: 32983 | T10: =SUM(U10:Z10) -> 0 | X10: 0 | AA10: =SUM(AB10:AH10) -> 32982 | AD10: 2865 | AF10: 10614 | AG10: 19459 | AH10: 44 | AI10: 213
A11: 黑龙江 | B11: 2015 | C11: 51614 | D11: =SUM(E11:J11) -> 0 | K11: =SUM(L11:R11) -> 51614 | N11: 4094 | P11: 12207 | Q11: 22427 | R11: 12886 | S11: 55149 | T11: =SUM(U11:Z11) -> 0 | X11: 0 | AA11: =SUM(AB11:AH11) -> 55149 | AD11: 4470 | AF11: 13825 | AG11: 23866 | AH11: 12988 | AI11: 501
A12: 上海 | B12: 2015 | C12: 7065 | D12: =SUM(E12:J12) -> 106 | F12: 106 | K12: =SUM(L12:R12) -> 6958 | L12: 17 | N12: 770 | P12: 1964 | Q12: 841 | R12: 3366 | S12: 9929 | T12: =SUM(U12:Z12) -> 187 | V12: 106 | X12: 81 | AA12: =SUM(AB12:AH12) -> 9741 | AB12: 34 | AD12: 1149 | AF12: 3467 | AG12: 918 | AH12: 4173 | AI12: 10720
A13: 江苏 | B13: 2015 | C13: 67345 | D13: =SUM(E13:J13) -> 65 | F13: 65 | K13: =SUM(L13:R13) -> 67280 | L13: 13 | N13: 8818 | P13: 18158 | Q13: 22598 | R13: 17693 | S13: 87519 | T13: =SUM(U13:Z13) -> 212 | V13: 65 | X13: 147 | AA13: =SUM(AB13:AH13) -> 87307 | AB13: 13 | AD13: 11625 | AF13: 26022 | AG13: 29686 | AH13: 19961 | AI13: 5295
A14: 浙江 | B14: 2015 | C14: 45211 | D14: =SUM(E14:J14) -> 412 | F14: 412 | K14: =SUM(L14:R14) -> 44800 | L14: 833 | N14: 5719 | P14: 10782 | Q14: 14351 | R14: 13115 | S14: 61354 | T14: =SUM(U14:Z14) -> 884 | V14: 412 | X14: 472 | AA14: =SUM(AB14:AH14) -> 60470 | AB14: 1185 | AD14: 7892 | AF14: 15876 | AG14: 20643 | AH14: 14874 | AI14: 4709
A15: 安徽 | B15: 2015 | C15: 55179 | D15: =SUM(E15:J15) -> 771 | F15: 771 | K15: =SUM(L15:R15) -> 54409 | L15: 453 | N15: 4658 | P15: 11052 | Q15: 14832 | R15: 23414 | S15: 63194 | T15: =SUM(U15:Z15) -> 2354 | V15: 771 | X15: 1583 | AA15: =SUM(AB15:AH15) -> 60840 | AB15: 901 | AD15: 4587 | AF15: 14385 | AG15: 17083 | AH15: 23884 | AI15: 1330
A16: 福建 | B16: 2015 | C16: 40836 | D16: =SUM(E16:J16) -> 0 | K16: =SUM(L16:R16) -> 40837 | L16: 342 | N16: 3725 | P16: 9053 | Q16: 14003 | R16: 13714 | S16: 47065 | T16: =SUM(U16:Z16) -> 0 | X16: 0 | AA16: =SUM(AB16:AH16) -> 47065 | AB16: 342 | AD16: 4812 | AF16: 11959 | AG16: 16076 | AH16: 13876 | AI16: 948
A17: 江西 | B17: 2015 | C17: 44557 | D17: =SUM(E17:J17) -> 450 | F17: 450 | K17: =SUM(L17:R17) -> 44107 | N17: 2974 | P17: 10649 | Q17: 13953 | R17: 16531 | S17: 47726 | T17: =SUM(U17:Z17) -> 450 | V17: 450 | X17: 0 | AA17: =SUM(AB17:AH17) -> 47275 | AD17: 4017 | AF17: 11867 | AG17: 14784 | AH17: 16607 | AI17: 470
A18: 山东 | B18: 2015 | C18: 77769 | D18: =SUM(E18:J18) -> 415 | G18: 415 | K18: =SUM(L18:R18) -> 77353 | N18: 5371 | P18: 16714 | Q18: 24557 | R18: 30711 | S18: 92605 | T18: =SUM(U18:Z18) -> 415 | W18: 415 | X18: 0 | AA18: =SUM(AB18:AH18) -> 92190 | AD18: 6931 | AF18: 22473 | AG18: 29343 | AH18: 33443 | AI18: 4465
A19: 河南 | B19: 2015 | C19: 67901 | D19: =SUM(E19:J19) -> 148 | F19: 148 | K19: =SUM(L19:R19) -> 67753 | L19: 343 | N19: 5673 | O19: 95 | P19: 15984 | Q19: 21913 | R19: 23745 | S19: 72381 | T19: =SUM(U19:Z19) -> 148 | V19: 148 | X19: 0 | AA19: =SUM(AB19:AH19) -> 72234 | AB19: 343 | AD19: 7560 | AE19: 140 | AF19: 17212 | AG19: 23005 | AH19: 23974 | AI19: 601
A20: 湖北 | B20: 2015 | C20: 64535 | D20: =SUM(E20:J20) -> 981 | F20: 981 | K20: =SUM(L20:R20) -> 63553 | L20: 180 | N20: 9555 | P20: 12591 | Q20: 20081 | R20: 21146 | S20: 68551 | T20: =SUM(U20:Z20) -> 2779 | V20: 981 | X20: 1798 | AA20: =SUM(AB20:AH20) -> 65771 | AB20: 180 | AD20: 9599 | AF20: 13722 | AG20: 20860 | AH20: 21410 | AI20: 1089
A21: 湖南 | B21: 2015 | C21: 63157 | D21: =SUM(E21:J21) -> 1387 | F21: 1387 | K21: =SUM(L21:R21) -> 61770 | N21: 4769 | P21: 13039 | Q21: 21265 | R21: 22697 | S21: 65414 | T21: =SUM(U21:Z21) -> 2244 | V21: 1387 | X21: 857 | AA21: =SUM(AB21:AH21) -> 63169 | AD21: 4121 | AF21: 13779 | AG21: 22347 | AH21: 22922 | AI21: 489
A22: 广东 | B22: 2015 | C22: 53700 | D22: =SUM(E22:J22) -> 0 | K22: =SUM(L22:R22) -> 53700 | N22: 6443 | P22: 14230 | Q22: 25593 | R22: 7434 | S22: 73140 | T22: =SUM(U22:Z22) -> 0 | X22: 0 | AA22: =SUM(AB22:AH22) -> 73140 | AD22: 9623 | AF22: 21838 | AG22: 34118 | AH22: 7561 | AI22: 3529
A23: 广西 | B23: 2015 | C23: 63359 | D23: =SUM(E23:J23) -> 0 | K23: =SUM(L23:R23) -> 63359 | N23: 1619 | P23: 13489 | Q23: 18069 | R23: 30182 | S23: 67160 | T23: =SUM(U23:Z23) -> 0 | X23: 0 | AA23: =SUM(AB23:AH23) -> 67160 | AD23: 1721 | AF23: 15548 | AG23: 19433 | AH23: 30458 | AI23: 395
A24: 海南 | B24: 2015 | C24: 10127 | D24: =SUM(E24:J24) -> 0 | K24: =SUM(L24:R24) -> 10126 | P24: 3655 | Q24: 3951 | R24: 2520 | S24: 10445 | T24: =SUM(U24:Z24) -> 0 | X24: 0 | AA24: =SUM(AB24:AH24) -> 10445 | AD24: 0 | AF24: 3939 | AG24: 3964 | AH24: 2542 | AI24: 126
A25: 重庆 | B25: 2015 | C25: 29076 | D25: =SUM(E25:J25) -> 575 | F25: 575 | K25: =SUM(L25:R25) -> 28501 | N25: 2543 | P25: 6367 | Q25: 8395 | R25: 11196 | S25: 33312 | T25: =SUM(U25:Z25) -> 575 | V25: 575 | X25: 0 | AA25: =SUM(AB25:AH25) -> 32737 | AD25: 3114 | AF25: 7968 | AG25: 10123 | AH25: 11532 | AI25: 624
A26: 四川 | B26: 2015 | C26: 81375 | D26: =SUM(E26:J26) -> 854 | F26: 854 | K26: =SUM(L26:R26) -> 80521 | N26: 9835 | P26: 16189 | Q26: 26345 | R26: 28152 | S26: 91661 | T26: =SUM(U26:Z26) -> 1094 | V26: 854 | X26: 240 | AA26: =SUM(AB26:AH26) -> 90566 | AD26: 13539 | AF26: 20264 | AG26: 28325 | AH26: 28438 | AI26: 1333
A27: 贵州 | B27: 2015 | C27: 47495 | D27: =SUM(E27:J27) -> 0 | K27: =SUM(L27:R27) -> 47494 | N27: 3419 | P27: 10891 | Q27: 15181 | R27: 18003 | S27: 47575 | T27: =SUM(U27:Z27) -> 0 | X27: 0 | AA27: =SUM(AB27:AH27) -> 47575 | AD27: 3419 | AF27: 10891 | AG27: 15239 | AH27: 18026 | AI27: 194
A28: 云南 | B28: 2015 | C28: 79937 | D28: =SUM(E28:J28) -> 0 | K28: =SUM(L28:R28) -> 79937 | N28: 10376 | P28: 14109 | Q28: 23569 | R28: 31883 | S28: 80750 | T28: =SUM(U28:Z28) -> 0 | X28: 0 | AA28: =SUM(AB28:AH28) -> 80750 | AD28: 10642 | AF28: 14318 | AG28: 23893 | AH28: 31897 | AI28: 362
A29: 西藏 | B29: 2015 | C29: 13114 | D29: =SUM(E29:J29) -> 423 | I29: 423 | K29: =SUM(L29:R29) -> 12691 | P29: 2158 | Q29: 4957 | R29: 5576 | S29: 13423 | T29: =SUM(U29:Z29) -> 423 | X29: 0 | Y29: 423 | AA29: =SUM(AB29:AH29) -> 13000 | AD29: 0 | AF29: 2261 | AG29: 5125 | AH29: 5614 | AI29: 7
A30: 陕西 | B30: 2015 | C30: 51292 | D30: =SUM(E30:J30) -> 476 | F30: 168 | G30: 308 | K30: =SUM(L30:R30) -> 50818 | M30: 1415 | N30: 565 | O30: 7754 | P30: 327 | Q30: 22375 | R30: 18382 | S30: 55024 | T30: =SUM(U30:Z30) -> 770 | V30: 168 | W30: 308 | X30: 294 | AA30: =SUM(AB30:AH30) -> 54255 | AC30: 2323 | AD30: 271 | AE30: 8880 | AF30: 327 | AG30: 24011 | AH30: 18443 | AI30: 982
A31: 甘肃 | B31: 2015 | C31: 58609 | D31: =SUM(E31:J31) -> 1351 | F31: 1351 | K31: =SUM(L31:R31) -> 57258 | M31: 3379 | O31: 9198 | P31: 828 | Q31: 21690 | R31: 22163 | S31: 60684 | T31: =SUM(U31:Z31) -> 1351 | V31: 1351 | X31: 0 | AA31: =SUM(AB31:AH31) -> 59333 | AC31: 5086 | AD31: 0 | AE31: 9323 | AF31: 847 | AG31: 21881 | AH31: 22196 | AI31: 137
A32: 青海 | B32: 2015 | C32: 26978 | D32: =SUM(E32:J32) -> 609 | I32: 609 | K32: =SUM(L32:R32) -> 26370 | M32: 2565 | O32: 5965 | Q32: 10687 | R32: 7153 | S32: 28904 | T32: =SUM(U32:Z32) -> 1217 | X32: 0 | Y32: 1217 | AA32: =SUM(AB32:AH32) -> 27686 | AC32: 2716 | AD32: 0 | AE32: 6123 | AG32: 11643 | AH32: 7204 | AI32: 92
A33: 宁夏 | B33: 2015 | C33: 13667 | D33: =SUM(E33:J33) -> 218 | F33: 112 | G33: 106 | K33: =SUM(L33:R33) -> 13449 | M33: 1128 | O33: 2302 | P33: 1947 | Q33: 4741 | R33: 3331 | S33: 15600 | T33: =SUM(U33:Z33) -> 218 | V33: 112 | W33: 106 | X33: 0 | AA33: =SUM(AB33:AH33) -> 15382 | AC33: 1128 | AD33: 0 | AE33: 2345 | AF33: 2282 | AG33: 6063 | AH33: 3564 | AI33: 93
A34: 新疆 | B34: 2015 | C34: 68856 | D34: =SUM(E34:J34) -> 166 | F34: 166 | K34: =SUM(L34:R34) -> 68691 | M34: 4216 | N34: 186 | P34: 19190 | Q34: 22531 | R34: 22568 | S34: 70537 | T34: =SUM(U34:Z34) -> 166 | V34: 166 | X34: 0 | AA34: =SUM(AB34:AH34) -> 70372 | AC34: 4412 | AD34: 186 | AF34: 19821 | AG34: 23254 | AH34: 22699 | AI34: 166
A35: 跨区 | B35: 2015 | C35: 16529 | D35: =SUM(E35:J35) -> 2787 | F35: 2787 | K35: =SUM(L35:R35) -> 13742 | N35: 13551 | P35: 191 | S35: 18677 | T35: =SUM(U35:Z35) -> 8280 | V35: 2787 | X35: 5493 | AA35: =SUM(AB35:AH35) -> 10398 | AD35: 10198 | AF35: 200 | AI35: 31
A36: 全国 | B36: 2016 | C36: 1581310 | D36: =SUM(E36:J36) -> 14660 | F36: 12295 | G36: 1334 | I36: 1031 | K36: =SUM(L36:R36) -> 1566650 | L36: 5823 | M36: 14957 | N36: 149044 | O36: 26501 | P36: 335210 | Q36: 547826 | R36: 487289 | S36: 1756141 | T36: =SUM(U36:Z36) -> 28808 | V36: 12295 | W36: 1334 | X36: 13539 | Y36: 1640 | AA36: =SUM(AB36:AH36) -> 1727335 | AB36: 7245 | AC36: 17968 | AD36: 165875 | AE36: 28366 | AF36: 397050 | AG36: 611431 | AH36: 499400 | AI36: 57933
A37: 北京 | B37: 2016 | C37: 8916 | D37: =SUM(E37:J37) -> 0 | K37: =SUM(L37:R37) -> 8917 | N37: 1401 | P37: 2664 | Q37: 3094 | R37: 1758 | S37: 10024 | T37: =SUM(U37:Z37) -> 0 | AA37: =SUM(AB37:AH37) -> 10024 | AD37: 1446 | AF37: 2908 | AG37: 3775 | AH37: 1895 | AI37: 2062
A38: 天津 | B38: 2016 | C38: 11149 | D38: =SUM(E38:J38) -> 0 | K38: =SUM(L38:R38) -> 11150 | L38: 579 | N38: 982 | P38: 2856 | Q38: 3322 | R38: 3411 | S38: 11149 | T38: =SUM(U38:Z38) -> 0 | AA38: =SUM(AB38:AH38) -> 11150 | AB38: 579 | AD38: 982 | AF38: 2856 | AG38: 3322 | AH38: 3411 | AI38: 6074
A39: 河北 | B39: 2016 | C39: 87740 | D39: =SUM(E39:J39) -> 200 | G39: 200 | K39: =SUM(L39:R39) -> 87540 | L39: 1167 | N39: 11655 | P39: 17687 | Q39: 27493 | R39: 29538 | S39: 96632 | T39: =SUM(U39:Z39) -> 200 | W39: 200 | AA39: =SUM(AB39:AH39) -> 96432 | AB39: 1419 | AD39: 11698 | AF39: 21554 | AG39: 31024 | AH39: 30737 | AI39: 1747
A40: 山西 | B40: 2016 | C40: 64359 | D40: =SUM(E40:J40) -> 727 | F40: 422 | G40: 305 | K40: =SUM(L40:R40) -> 63632 | L40: 599 | N40: 7526 | P40: 14498 | Q40: 18603 | R40: 22406 | S40: 68293 | T40: =SUM(U40:Z40) -> 727 | V40: 422 | W40: 305 | AA40: =SUM(AB40:AH40) -> 67565 | AB40: 657 | AD40: 8498 | AF40: 16180 | AG40: 19730 | AH40: 22500 | AI40: 727
...

Sheet Capacity by Linetype
A1: Index | B1: Item | C1: Year | D1: 建设规模 | F1: 本年施工规模 | H1: 本年新开工规模 | J1: 累计新增能力 | L1: 本年新增能力 | O1: Item | P1: 电流 | Q1: 电压 | R1: 容量长度比 | S1: 建设规模 | U1: 本年施工规模 | W1: 本年新开工规模 | Y1: 累计新增能力 | AA1: 本年新增能力
D2: 容量 | E2: 长度 | F2: 容量 | G2: 长度 | H2: 容量 | I2: 长度 | J2: 容量 | K2: 长度 | L2: 容量 | M2: 长度 | S2: 容量 | T2: 长度 | U2: 容量 | V2: 长度 | W2: 容量 | X2: 长度 | Y2: 容量 | Z2: 长度 | AA2: 容量 | AB2: 长度
A3: 1 | B3: 全国 | C3: 2020 | E3: 176608 | G3: 150404 | I3: 61102 | K3: 67542 | M3: 62653 | O3: ±400千伏 | P3: 直流 | Q3: 400 | R3: =Y3/Z3 -> 0.58023477 | W3: 30712 | X3: 57829 | Y3: 46019 | Z3: 79311 | AA3: 34585 | AB3: 56679
A4: 2 | B4: 1、直流工程 | C4: 2020 | D4: 12600 | E4: 13148 | F4: 12600 | G4: 13147 | H4: 3800 | I4: 3890 | J4: 5200 | K4: 4444 | L4: 5200 | M4: 4444 | O4: ±500千伏 | P4: 直流 | Q4: 500 | R4: =S4/T4 -> 0.86128544 | S4: 7960 | T4: 9242 | U4: 6180 | V4: 5669 | W4: 2200 | X4: 1738 | Y4: 4920 | Z4: 5733 | AA4: 3040 | AB4: 2726
A5: 3 | B5: ±1100千伏 | C5: 2020 | E5: 1768 | G5: 1768 | O5: ±800千伏 | P5: 直流 | Q5: 800 | R5: =S5/T5 -> 1.0694016 | S5: 58600 | T5: 54797 | U5: 53500 | V5: 45979 | W5: 15800 | X5: 14147 | Y5: 18800 | Z5: 22255 | AA5: 13300 | AB5: 13448
A6: 4 | B6: ±800千伏 | C6: 2020 | D6: 11400 | E6: 10321 | F6: 11400 | G6: 10321 | H6: 3200 | I6: 3224 | J6: 4000 | K6: 3389 | L6: 4000 | M6: 3389 | O6: ±1100千伏 | P6: 直流 | Q6: 1100 | R6: =S6/T6 -> 0.53169734 | S6: 7800 | T6: 14670 | U6: 7800 | V6: 14670 | W6: 2400 | X6: 3325 | Y6: 3000 | Z6: 4882 | AA6: 1200 | AB6: 3325
A7: 5 | B7: ±660千伏 | C7: 2020 | O7: 110千伏（含66千伏） | P7: 交流 | Q7: 110 | R7: =S7/T7 -> 0.40852675 | S7: 162371 | T7: 397455 | U7: 136277 | V7: 349867 | W7: 53565 | X7: 142503 | Y7: 67057 | Z7: 181742 | AA7: 51476 | AB7: 141344
A8: 6 | B8: ±500千伏 | C8: 2020 | D8: 1200 | E8: 1059 | F8: 1200 | G8: 1059 | H8: 600 | I8: 666 | J8: 1200 | K8: 1055 | L8: 1200 | M8: 1055 | O8: 220千伏 | P8: 交流 | Q8: 220 | R8: =S8/T8 -> 0.49348482 | S8: 196896 | T8: 398991 | U8: 158637 | V8: 332070 | W8: 56126 | X8: 116833 | Y8: 80364 | Z8: 159030 | AA8: 55578 | AB8: 116982
A9: 7 | B9: ±400千伏 | C9: 2020 | O9: 330千伏 | P9: 交流 | Q9: 330 | R9: =S9/T9 -> 0.43640528 | S9: 16195 | T9: 37110 | U9: 14658 | V9: 34085 | W9: 6076 | X9: 11740 | Y9: 7089 | Z9: 18263 | AA9: 5238 | AB9: 13840
A10: 8 | B10: 2、交流工程（110千伏及以上） | C10: 2020 | D10: 104095 | E10: 163460 | F10: 87746 | G10: 137257 | H10: 35202 | I10: 57213 | J10: 34042 | K10: 63098 | L10: 31597 | M10: 58208 | O10: 500千伏 | P10: 交流 | Q10: 500 | R10: =S10/T10 -> 1.0290553 | S10: 165717 | T10: 161038 | U10: 150031 | V10: 142497 | W10: 52630 | X10: 52609 | Y10: 64080 | Z10: 63440 | AA10: 52380 | AB10: 49668
A11: 9 | B11: 1000千伏 | C11: 2020 | D11: 6000 | E11: 3411 | F11: 5400 | G11: 2806 | H11: 3300 | I11: 690 | J11: 1800 | K11: 1736 | L11: 1800 | M11: 1736 | O11: 750千伏 | P11: 交流 | Q11: 750 | R11: =S11/T11 -> 1.1160547 | S11: 41640 | T11: 37310 | U11: 39810 | V11: 37106 | W11: 12415 | X11: 11771 | Y11: 17035 | Z11: 13469 | AA11: 14175 | AB11: 12090
A12: 10 | B12: 750千伏 | C12: 2020 | D12: 6850 | E12: 6153 | F12: 6430 | G12: 6051 | H12: 1520 | I12: 2038 | J12: 2620 | K12: 1818 | L12: 2620 | M12: 1760 | O12: 1000千伏 | P12: 交流 | Q12: 1000 | R12: =S12/T12 -> 1.1443442 | S12: 32100 | T12: 28051 | U12: 30300 | V12: 25909 | W12: 13200 | X12: 8149 | Y12: 12900 | Z12: 11693 | AA12: 12300 | AB12: 11063
A13: 11 | B13: 500千伏 | C13: 2020 | D13: 25436 | E13: 22532 | F13: 21568 | G13: 17874 | H13: 8580 | I13: 8676 | J13: 8355 | K13: 8137 | L13: 7705 | M13: 7214 | O13: 35千伏 | P13: 交流 | Q13: 35 | R13: {=FORECAST(Q13,R7:R12,Q7:Q12)} -> 0.3383766
A14: 12 | B14: 330千伏 | C14: 2020 | D14: 4330 | E14: 7010 | F14: 4114 | G14: 6982 | H14: 2008 | I14: 3004 | J14: 1674 | K14: 3014 | L14: 1458 | M14: 2815
A15: 13 | B15: 220千伏 | C15: 2020 | D15: 31777 | E15: 61314 | F15: 25303 | G15: 48944 | H15: 10920 | I15: 20330 | J15: 10576 | K15: 21107 | L15: 9533 | M15: 18511
A16: 14 | B16: 110千伏（含66千伏） | C16: 2020 | D16: 29701 | E16: 63040 | F16: 24931 | G16: 54600 | H16: 8874 | I16: 22474 | J16: 9017 | K16: 27286 | L16: 8481 | M16: 26173
A17: 15 | B17: 全国 | C17: 2019 | E17: 177201 | G17: 160164 | I17: 58731 | K17: 71109 | M17: 57935
A18: 16 | B18: 1、直流工程 | C18: 2019 | D18: 9700 | E18: 11027 | F18: 9000 | G18: 9075 | H18: 1900 | I18: 1295 | J18: 3800 | K18: 3510 | L18: 2200
A19: 17 | B19: ±1100千伏 | C19: 2019 | D19: 1800 | E19: 4010 | F19: 1800 | G19: 4010 | J19: 1800 | K19: 1557 | L19: 1200
A20: 18 | B20: ±800千伏 | C20: 2019 | D20: 6000 | E20: 5945 | F20: 5000 | G20: 3992 | H20: 1600 | I20: 909 | J20: 1000 | K20: 1953
A21: 19 | B21: ±660千伏 | C21: 2019
A22: 20 | B22: ±500千伏 | C22: 2019 | D22: 900 | E22: 1073 | F22: 1200 | G22: 1074 | H22: 300 | I22: 386
A23: 21 | B23: ±400千伏 | C23: 2019 | D23: 1000 | F23: 1000 | J23: 1000 | L23: 1000
A24: 22 | B24: 2、交流工程（110千伏及以上） | C24: 2019 | D24: 95307 | E24: 166174 | F24: 88187 | G24: 151088 | H24: 34390 | I24: 57436 | J24: 37608 | K24: 67599 | L24: 31915 | M24: 57935
A25: 23 | B25: 1000千伏 | C25: 2019 | D25: 4800 | E25: 4316 | F25: 4800 | G25: 4316 | H25: 2100 | I25: 1128 | J25: 1500 | K25: 2100 | L25: 1500 | M25: 2100
A26: 24 | B26: 750千伏 | C26: 2019 | D26: 8840 | E26: 8350 | F26: 8630 | G26: 8350 | H26: 2615 | I26: 1386 | J26: 3455 | K26: 4566 | L26: 3245 | M26: 4406
A27: 25 | B27: 500千伏 | C27: 2019 | D27: 25333 | E27: 22478 | F27: 23603 | G27: 19409 | H27: 9493 | I27: 8563 | J27: 9995 | K27: 8095 | L27: 8645 | M27: 5595
A28: 26 | B28: 330千伏 | C28: 2019 | D28: 3705 | E28: 7328 | F28: 3489 | G28: 7300 | H28: 1188 | I28: 1810 | J28: 1623 | K28: 4245 | L28: 1263 | M28: 3989
A29: 27 | B29: 220千伏 | C29: 2019 | D29: 29630 | E29: 62940 | F29: 26136 | G29: 54343 | H29: 10163 | I29: 18694 | J29: 11775 | K29: 24284 | L29: 9161 | M29: 19822
A30: 28 | B30: 110千伏（含66千伏） | C30: 2019 | D30: 22999 | E30: 60762 | F30: 21528 | G30: 57370 | H30: 8831 | I30: 25855 | J30: 9260 | K30: 24310 | L30: 8100 | M30: 22023
A31: 29 | B31: 全国 | C31: 2018 | E31: 202586 | G31: 162751 | I31: 54031 | K31: 80787 | M31: 60298
A32: 30 | B32: 1、直流工程 | C32: 2018 | D32: 11500 | E32: 13919 | F32: 9400 | G32: 8637 | H32: 2500 | I32: 2253 | J32: 4700 | K32: 7118 | L32: 3200 | M32: 3325
A33: 31 | B33: ±1100千伏 | C33: 2018 | D33: 2400 | E33: 4010 | F33: 2400 | G33: 4010 | J33: 1200 | K33: 3325 | L33: 1200 | M33: 3325
A34: 32 | B34: ±800千伏 | C34: 2018 | D34: 8200 | E34: 8658 | F34: 6100 | G34: 3938 | H34: 1600 | I34: 1604 | J34: 3500 | K34: 3231 | L34: 2000
A35: 33 | B35: ±660千伏 | C35: 2018
A36: 34 | B36: ±500千伏 | C36: 2018 | D36: 900 | E36: 1251 | F36: 900 | G36: 689 | H36: 900 | I36: 649 | K36: 562
A37: 35 | B37: ±400千伏 | C37: 2018
A38: 36 | B38: 2、交流工程（110千伏及以上） | C38: 2018 | D38: 103483 | E38: 188668 | F38: 85931 | G38: 154115 | H38: 30872 | I38: 51778 | J38: 40730 | K38: 73669 | L38: 31024 | M38: 56973
A39: 37 | B39: 1000千伏 | C39: 2018 | D39: 2400 | E39: 2399 | F39: 2100 | G39: 2399 | H39: 1500 | I39: 2169 | J39: 900 | K39: 129 | L39: 900 | M39: 129
A40: 38 | B40: 750千伏 | C40: 2018 | D40: 6570 | E40: 6525 | F40: 5370 | G40: 6423 | H40: 1800 | I40: 2163 | J40: 2340 | K40: 1733 | L40: 1140 | M40: 1573
...

Sheet Calculation
A1: 全国 | B1: 总计 | C1: 一、直流 工程 | D1: ±1100千伏 | E1: ±800千伏 | F1: ±660千伏 | G1: ±500千伏 | H1: ±400千伏 | I1: ±400千伏 以下 | J1: 二、交流工 程 | K1: 1000千伏 | L1: 750千伏 | M1: 500千伏 | N1: 330千伏 | O1: 220千伏 | P1: 110千伏（含66千伏） | Q1: 35千伏 | R1: 电缆 | S1: miles | U1: KV | V1: MW Floor | W1: MW Ceiling | X1: MW Average | Y1: A Floor (factor = 0.8) | Z1: A Ceiling (factor = 0.9 | AA1: A Average | AD1: 直流项目名称 | AE1: 额定电压 | AF1: 传输功率 | AG1: 额定电流 | AH1: 传输距离
A2: 2015 | B2: =SUMIFS('2015-20线路长度'!S$3:S$200,'2015-20线路长度'!$A$3:$A$200,Calculation!$A$1,'2015-20线路长度'!$B$3:$B$200,Calculation!$A2) -> 1696849 | C2: =SUMIFS('2015-20线路长度'!T$3:T$200,'2015-20线路长度'!$A$3:$A$200,Calculation!$A$1,'2015-20线路长度'!$B$3:$B$200,Calculation!$A2) -> 25428 | D2: =SUMIFS('2015-20线路长度'!U$3:U$200,'2015-20线路长度'!$A$3:$A$200,Calculation!$A$1,'2015-20线路长度'!$B$3:$B$200,Calculation!$A2) -> 0 | E2: =SUMIFS('2015-20线路长度'!V$3:V$200,'2015-20线路长度'!$A$3:$A$200,Calculation!$A$1,'2015-20线路长度'!$B$3:$B$200,Calculation!$A2) -> 10580 | F2: =SUMIFS('2015-20线路长度'!W$3:W$200,'2015-20线路长度'!$A$3:$A$200,Calculation!$A$1,'2015-20线路长度'!$B$3:$B$200,Calculation!$A2) -> 1336 | G2: =SUMIFS('2015-20线路长度'!X$3:X$200,'2015-20线路长度'!$A$3:$A$200,Calculation!$A$1,'2015-20线路长度'!$B$3:$B$200,Calculation!$A2) -> 11872 | H2: =SUMIFS('2015-20线路长度'!Y$3:Y$200,'2015-20线路长度'!$A$3:$A$200,Calculation!$A$1,'2015-20线路长度'!$B$3:$B$200,Calculation!$A2) -> 1640 | I2: =SUMIFS('2015-20线路长度'!Z$3:Z$200,'2015-20线路长度'!$A$3:$A$200,Calculation!$A$1,'2015-20线路长度'!$B$3:$B$200,Calculation!$A2) -> 0 | ... R2: =SUMIFS('2015-20线路长度'!AI$3:AI$200,'2015-20线路长度'!$A$3:$A$200,Calculation!$A$1,'2015-20线路长度'!$B$3:$B$200,Calculation!$A2) -> 50063 | S2: =(SUM(E2:I2)+SUM(K2:R2))/1.609344 -> 1085479.5 | U2: 35 | V2: 2.5 | W2: 15 | X2: =U2*AA2*0.85*1.732/1000 -> 8.4114583 | Y2: =V2*1000/0.8/1.732/$U2 -> 51.550643 | Z2: =W2*1000/0.9/1.732/$U2 -> 274.93676 | AA2: =AVERAGE(Y2:Z2) -> 163.2437 | AB2: 400-600 | AD2: 舟山直流 | AE2: 100 | AF2: 100 | AG2: 500 | AH2: 54 | AJ2: 35 | AK2: 163.2437 | AL2: 100 | AM2: 500
A3: 2016 | B3: =SUMIFS('2015-20线路长度'!S$3:S$200,'2015-20线路长度'!$A$3:$A$200,Calculation!$A$1,'2015-20线路长度'!$B$3:$B$200,Calculation!$A3) -> 1756141 | C3: =SUMIFS('2015-20线路长度'!T$3:T$200,'2015-20线路长度'!$A$3:$A$200,Calculation!$A$1,'2015-20线路长度'!$B$3:$B$200,Calculation!$A3) -> 28808 | D3: =SUMIFS('2015-20线路长度'!U$3:U$200,'2015-20线路长度'!$A$3:$A$200,Calculation!$A$1,'2015-20线路长度'!$B$3:$B$200,Calculation!$A3) -> 0 | E3: =SUMIFS('2015-20线路长度'!V$3:V$200,'2015-20线路长度'!$A$3:$A$200,Calculation!$A$1,'2015-20线路长度'!$B$3:$B$200,Calculation!$A3) -> 12295 | F3: =SUMIFS('2015-20线路长度'!W$3:W$200,'2015-20线路长度'!$A$3:$A$200,Calculation!$A$1,'2015-20线路长度'!$B$3:$B$200,Calculation!$A3) -> 1334 | G3: =SUMIFS('2015-20线路长度'!X$3:X$200,'2015-20线路长度'!$A$3:$A$200,Calculation!$A$1,'2015-20线路长度'!$B$3:$B$200,Calculation!$A3) -> 13539 | H3: =SUMIFS('2015-20线路长度'!Y$3:Y$200,'2015-20线路长度'!$A$3:$A$200,Calculation!$A$1,'2015-20线路长度'!$B$3:$B$200,Calculation!$A3) -> 1640 | I3: =SUMIFS('2015-20线路长度'!Z$3:Z$200,'2015-20线路长度'!$A$3:$A$200,Calculation!$A$1,'2015-20线路长度'!$B$3:$B$200,Calculation!$A3) -> 0 | ... R3: =SUMIFS('2015-20线路长度'!AI$3:AI$200,'2015-20线路长度'!$A$3:$A$200,Calculation!$A$1,'2015-20线路长度'!$B$3:$B$200,Calculation!$A3) -> 57933 | S3: =(SUM(E3:I3)+SUM(K3:R3))/1.609344 -> 1127214.6 | U3: 110 | V3: 10 | W3: 50 | X3: =U3*AA3*0.85*1.732/1000 -> 28.923611 | Y3: =V3*1000/0.8/1.732/$U3 -> 65.60991 | Z3: =W3*1000/0.9/1.732/$U3 -> 291.5996 | AA3: =AVERAGE(Y3:Z3) -> 178.60475 | AB3: 600-1200 | AD3: 灵宝直流 | AE3: 125 | AF3: 750 | AG3: 3000 | AJ3: 110 | AK3: 178.60475 | AL3: 125 | AM3: 3000
A4: 2017 | B4: =SUMIFS('2015-20线路长度'!S$3:S$200,'2015-20线路长度'!$A$3:$A$200,Calculation!$A$1,'2015-20线路长度'!$B$3:$B$200,Calculation!$A4) -> 1825611 | C4: =SUMIFS('2015-20线路长度'!T$3:T$200,'2015-20线路长度'!$A$3:$A$200,Calculation!$A$1,'2015-20线路长度'!$B$3:$B$200,Calculation!$A4) -> 37400 | D4: =SUMIFS('2015-20线路长度'!U$3:U$200,'2015-20线路长度'!$A$3:$A$200,Calculation!$A$1,'2015-20线路长度'!$B$3:$B$200,Calculation!$A4) -> 0 | E4: =SUMIFS('2015-20线路长度'!V$3:V$200,'2015-20线路长度'!$A$3:$A$200,Calculation!$A$1,'2015-20线路长度'!$B$3:$B$200,Calculation!$A4) -> 20874 | F4: =SUMIFS('2015-20线路长度'!W$3:W$200,'2015-20线路长度'!$A$3:$A$200,Calculation!$A$1,'2015-20线路长度'!$B$3:$B$200,Calculation!$A4) -> 1334 | G4: =SUMIFS('2015-20线路长度'!X$3:X$200,'2015-20线路长度'!$A$3:$A$200,Calculation!$A$1,'2015-20线路长度'!$B$3:$B$200,Calculation!$A4) -> 13552 | H4: =SUMIFS('2015-20线路长度'!Y$3:Y$200,'2015-20线路长度'!$A$3:$A$200,Calculation!$A$1,'2015-20线路长度'!$B$3:$B$200,Calculation!$A4) -> 1640 | I4: =SUMIFS('2015-20线路长度'!Z$3:Z$200,'2015-20线路长度'!$A$3:$A$200,Calculation!$A$1,'2015-20线路长度'!$B$3:$B$200,Calculation!$A4) -> 0 | ... R4: =SUMIFS('2015-20线路长度'!AI$3:AI$200,'2015-20线路长度'!$A$3:$A$200,Calculation!$A$1,'2015-20线路长度'!$B$3:$B$200,Calculation!$A4) -> 62760 | S4: =(SUM(E4:I4)+SUM(K4:R4))/1.609344 -> 1173379.3 | U4: 220 | V4: 100 | W4: 500 | X4: =U4*AA4*0.85*1.732/1000 -> 289.23611 | Y4: =V4*1000/0.8/1.732/$U4 -> 328.04955 | Z4: =W4*1000/0.9/1.732/$U4 -> 1457.998 | AA4: =AVERAGE(Y4:Z4) -> 893.02377 | AB4: 600-1200 | AE4: 320 | AF4: 1000 | AG4: =AF4/AE4/2*1000 -> 1562.5 | AJ4: 220 | AK4: 893.02377 | AL4: 320 | AM4: 1562.5
A5: 2018 | B5: =SUMIFS('2015-20线路长度'!S$3:S$200,'2015-20线路长度'!$A$3:$A$200,Calculation!$A$1,'2015-20线路长度'!$B$3:$B$200,Calculation!$A5) -> 1892018 | C5: =SUMIFS('2015-20线路长度'!T$3:T$200,'2015-20线路长度'!$A$3:$A$200,Calculation!$A$1,'2015-20线路长度'!$B$3:$B$200,Calculation!$A5) -> 41995 | D5: =SUMIFS('2015-20线路长度'!U$3:U$200,'2015-20线路长度'!$A$3:$A$200,Calculation!$A$1,'2015-20线路长度'!$B$3:$B$200,Calculation!$A5) -> 608 | E5: =SUMIFS('2015-20线路长度'!V$3:V$200,'2015-20线路长度'!$A$3:$A$200,Calculation!$A$1,'2015-20线路长度'!$B$3:$B$200,Calculation!$A5) -> 21723 | F5: =SUMIFS('2015-20线路长度'!W$3:W$200,'2015-20线路长度'!$A$3:$A$200,Calculation!$A$1,'2015-20线路长度'!$B$3:$B$200,Calculation!$A5) -> 2091 | G5: =SUMIFS('2015-20线路长度'!X$3:X$200,'2015-20线路长度'!$A$3:$A$200,Calculation!$A$1,'2015-20线路长度'!$B$3:$B$200,Calculation!$A5) -> 15428 | H5: =SUMIFS('2015-20线路长度'!Y$3:Y$200,'2015-20线路长度'!$A$3:$A$200,Calculation!$A$1,'2015-20线路长度'!$B$3:$B$200,Calculation!$A5) -> 1640 | I5: =SUMIFS('2015-20线路长度'!Z$3:Z$200,'2015-20线路长度'!$A$3:$A$200,Calculation!$A$1,'2015-20线路长度'!$B$3:$B$200,Calculation!$A5) -> 506 | ... R5: =SUMIFS('2015-20线路长度'!AI$3:AI$200,'2015-20线路长度'!$A$3:$A$200,Calculation!$A$1,'2015-20线路长度'!$B$3:$B$200,Calculation!$A5) -> 62760 | S5: =(SUM(E5:I5)+SUM(K5:R5))/1.609344 -> 1214266.2 | U5: 330 | V5: 200 | W5: 800 | X5: =U5*AA5*0.85*1.732/1000 -> 484.02778 | Y5: =V5*1000/0.8/1.732/$U5 -> 437.3994 | Z5: =W5*1000/0.9/1.732/$U5 -> 1555.1979 | AA5: =AVERAGE(Y5:Z5) -> 996.29863 | AD5: 宝鸡-德阳 | AE5: 500 | AF5: 3000 | AG5: 3000 | AH5: 550 | AJ5: 330 | AK5: 996.29863 | AL5: 500 | AM5: 3000
A6: 2019 | B6: =SUMIFS('2015-20线路长度'!S$3:S$200,'2015-20线路长度'!$A$3:$A$200,Calculation!$A$1,'2015-20线路长度'!$B$3:$B$200,Calculation!$A6) -> 1975312 | C6: =SUMIFS('2015-20线路长度'!T$3:T$200,'2015-20线路长度'!$A$3:$A$200,Calculation!$A$1,'2015-20线路长度'!$B$3:$B$200,Calculation!$A6) -> 42364 | D6: =SUMIFS('2015-20线路长度'!U$3:U$200,'2015-20线路长度'!$A$3:$A$200,Calculation!$A$1,'2015-20线路长度'!$B$3:$B$200,Calculation!$A6) -> 3295 | E6: =SUMIFS('2015-20线路长度'!V$3:V$200,'2015-20线路长度'!$A$3:$A$200,Calculation!$A$1,'2015-20线路长度'!$B$3:$B$200,Calculation!$A6) -> 21907 | F6: =SUMIFS('2015-20线路长度'!W$3:W$200,'2015-20线路长度'!$A$3:$A$200,Calculation!$A$1,'2015-20线路长度'!$B$3:$B$200,Calculation!$A6) -> 1334 | G6: =SUMIFS('2015-20线路长度'!X$3:X$200,'2015-20线路长度'!$A$3:$A$200,Calculation!$A$1,'2015-20线路长度'!$B$3:$B$200,Calculation!$A6) -> 13733 | H6: =SUMIFS('2015-20线路长度'!Y$3:Y$200,'2015-20线路长度'!$A$3:$A$200,Calculation!$A$1,'2015-20线路长度'!$B$3:$B$200,Calculation!$A6) -> 1639 | I6: =SUMIFS('2015-20线路长度'!Z$3:Z$200,'2015-20线路长度'!$A$3:$A$200,Calculation!$A$1,'2015-20线路长度'!$B$3:$B$200,Calculation!$A6) -> 457 | ... R6: =SUMIFS('2015-20线路长度'!AI$3:AI$200,'2015-20线路长度'!$A$3:$A$200,Calculation!$A$1,'2015-20线路长度'!$B$3:$B$200,Calculation!$A6) -> 0 | S6: =(SUM(E6:I6)+SUM(K6:R6))/1.609344 -> 1225355.8 | U6: 500 | V6: 1000 | W6: 1500 | X6: =U6*AA6*0.85*1.732/1000 -> 1239.5833 | Y6: =V6*1000/0.8/1.732/$U6 -> 1443.418 | Z6: =W6*1000/0.9/1.732/$U6 -> 1924.5574 | AA6: =AVERAGE(Y6:Z6) -> 1683.9877 | AB6: 3000 | AD6: 葛沪直流 | AE6: 500 | AF6: 3000 | AG6: 3000 | AH6: 976 | AJ6: 500 | AK6: 1683.9877 | AL6: 500 | AM6: 3000
A7: 2020 | B7: =SUMIFS('2015-20线路长度'!S$3:S$200,'2015-20线路长度'!$A$3:$A$200,Calculation!$A$1,'2015-20线路长度'!$B$3:$B$200,Calculation!$A7) -> 2156170 | C7: =SUMIFS('2015-20线路长度'!T$3:T$200,'2015-20线路长度'!$A$3:$A$200,Calculation!$A$1,'2015-20线路长度'!$B$3:$B$200,Calculation!$A7) -> 46324 | D7: =SUMIFS('2015-20线路长度'!U$3:U$200,'2015-20线路长度'!$A$3:$A$200,Calculation!$A$1,'2015-20线路长度'!$B$3:$B$200,Calculation!$A7) -> 3295 | E7: =SUMIFS('2015-20线路长度'!V$3:V$200,'2015-20线路长度'!$A$3:$A$200,Calculation!$A$1,'2015-20线路长度'!$B$3:$B$200,Calculation!$A7) -> 24980 | F7: =SUMIFS('2015-20线路长度'!W$3:W$200,'2015-20线路长度'!$A$3:$A$200,Calculation!$A$1,'2015-20线路长度'!$B$3:$B$200,Calculation!$A7) -> 1334 | G7: =SUMIFS('2015-20线路长度'!X$3:X$200,'2015-20线路长度'!$A$3:$A$200,Calculation!$A$1,'2015-20线路长度'!$B$3:$B$200,Calculation!$A7) -> 14783 | H7: =SUMIFS('2015-20线路长度'!Y$3:Y$200,'2015-20线路长度'!$A$3:$A$200,Calculation!$A$1,'2015-20线路长度'!$B$3:$B$200,Calculation!$A7) -> 1639 | I7: =SUMIFS('2015-20线路长度'!Z$3:Z$200,'2015-20线路长度'!$A$3:$A$200,Calculation!$A$1,'2015-20线路长度'!$B$3:$B$200,Calculation!$A7) -> 293 | ... R7: =SUMIFS('2015-20线路长度'!AI$3:AI$200,'2015-20线路长度'!$A$3:$A$200,Calculation!$A$1,'2015-20线路长度'!$B$3:$B$200,Calculation!$A7) -> 0 | S7: =(SUM(E7:I7)+SUM(K7:R7))/1.609344 -> 1337734.5 | U7: 765 | V7: 2000 | W7: 2500 | X7: =U7*AA7*0.85*1.732/1000 -> 2243.0556 | Y7: =V7*1000/0.8/1.732/$U7 -> 1886.8209 | Z7: =W7*1000/0.9/1.732/$U7 -> 2096.4677 | AA7: =AVERAGE(Y7:Z7) -> 1991.6443 | AD7: 宁东-山东 | AE7: 500 | AF7: 3000 | AG7: 3000 | AH7: 1043 | AJ7: 765 | AK7: 1991.6443 | AL7: 500 | AM7: 3000
S8: MW*miles | U8: 1100 | X8: =1.732*U8*AA8/1000*0.9 -> 4286.7 | AA8: 2500 | AD8: 呼盟-辽宁 | AE8: 500 | AF8: 3000 | AG8: 3000 | AH8: 908 | AJ8: 1100 | AK8: 2500 | AL8: 500 | AM8: 3000
A9: 2015 | B9: =C9+J9 -> 816242.06 | C9: =SUM(D9:I9) -> 23780.734 | D9: =Calculation!D2*VLOOKUP(Calculation!D$1,'Capacity by Linetype'!$O$3:$R$12,4,FALSE) -> 0 | E9: =Calculation!E2*VLOOKUP(Calculation!E$1,'Capacity by Linetype'!$O$3:$R$12,4,FALSE) -> 11314.269 | F9: =Calculation!F2*AVERAGE(I$16,K$16) -> 1289.6989 | G9: =Calculation!G2*VLOOKUP(Calculation!G$1,'Capacity by Linetype'!$O$3:$R$12,4,FALSE) -> 10225.181 | H9: =Calculation!H2*VLOOKUP(Calculation!H$1,'Capacity by Linetype'!$O$3:$R$12,4,FALSE) -> 951.58503 | I9: =Calculation!I2*VLOOKUP(Calculation!H$1,'Capacity by Linetype'!$O$3:$R$12,4,FALSE)*0.5 -> 0 | J9: =SUM(K9:Q9) -> 792461.33 | K9: =Calculation!K2*VLOOKUP(Calculation!K$1,'Capacity by Linetype'!$O$3:$R$12,4,FALSE) -> 3563.4879 | L9: =Calculation!L2*VLOOKUP(Calculation!L$1,'Capacity by Linetype'!$O$3:$R$12,4,FALSE) -> 17482.997 | M9: =Calculation!M2*VLOOKUP(Calculation!M$1,'Capacity by Linetype'!$O$3:$R$12,4,FALSE) -> 162562.95 | N9: =Calculation!N2*VLOOKUP(Calculation!N$1,'Capacity by Linetype'!$O$3:$R$12,4,FALSE) -> 11700.462 | O9: =Calculation!O2*VLOOKUP(Calculation!O$1,'Capacity by Linetype'!$O$3:$R$12,4,FALSE) -> 187583.94 | P9: =Calculation!P2*VLOOKUP(Calculation!P$1,'Capacity by Linetype'!$O$3:$R$12,4,FALSE) -> 241699.54 | Q9: =Calculation!Q2*VLOOKUP(Calculation!Q$1,'Capacity by Linetype'!$O$3:$R$13,4,FALSE) -> 167867.96 | S9: =(SUM(E9:I9)+SUM(K9:R9))*10/1.609344 -> 5071893.1 | AD9: 葛洲坝-上海 | AE9: 500 | AF9: 1200 | AG9: 1200 | AH9: 1064 | AL9: 500 | AM9: 1200
A10: 2016 | B10: =C10+J10 -> 853175.59 | C10: =SUM(D10:I10) -> 27048.59 | D10: =Calculation!D3*VLOOKUP(Calculation!D$1,'Capacity by Linetype'!$O$3:$R$12,4,FALSE) -> 0 | E10: =Calculation!E3*VLOOKUP(Calculation!E$1,'Capacity by Linetype'!$O$3:$R$12,4,FALSE) -> 13148.293 | F10: =Calculation!F3*AVERAGE(I$16,K$16) -> 1287.7683 | G10: =Calculation!G3*VLOOKUP(Calculation!G$1,'Capacity by Linetype'!$O$3:$R$12,4,FALSE) -> 11660.944 | H10: =Calculation!H3*VLOOKUP(Calculation!H$1,'Capacity by Linetype'!$O$3:$R$12,4,FALSE) -> 951.58503 | I10: =Calculation!I3*VLOOKUP(Calculation!H$1,'Capacity by Linetype'!$O$3:$R$12,4,FALSE)*0.5 -> 0 | J10: =SUM(K10:Q10) -> 826127 | K10: =Calculation!K3*VLOOKUP(Calculation!K$1,'Capacity by Linetype'!$O$3:$R$12,4,FALSE) -> 8290.7739 | L10: =Calculation!L3*VLOOKUP(Calculation!L$1,'Capacity by Linetype'!$O$3:$R$12,4,FALSE) -> 20053.27 | M10: =Calculation!M3*VLOOKUP(Calculation!M$1,'Capacity by Linetype'!$O$3:$R$12,4,FALSE) -> 170694.54 | N10: =Calculation!N3*VLOOKUP(Calculation!N$1,'Capacity by Linetype'!$O$3:$R$12,4,FALSE) -> 12379.072 | O10: =Calculation!O3*VLOOKUP(Calculation!O$1,'Capacity by Linetype'!$O$3:$R$12,4,FALSE) -> 195938.15 | P10: =Calculation!P3*VLOOKUP(Calculation!P$1,'Capacity by Linetype'!$O$3:$R$12,4,FALSE) -> 249785.92 | Q10: =Calculation!Q3*VLOOKUP(Calculation!Q$1,'Capacity by Linetype'!$O$3:$R$13,4,FALSE) -> 168985.28 | S10: =(SUM(E10:I10)+SUM(K10:R10))*10/1.609344 -> 5301387.3 | AD10: 三常直流 | AE10: 500 | AF10: 3000 | AG10: 3000 | AH10: 962 | AL10: 500 | AM10: 3000
A11: 2017 | B11: =C11+J11 -> 895772.07 | C11: =SUM(D11:I11) -> 36234.183 | D11: =Calculation!D4*VLOOKUP(Calculation!D$1,'Capacity by Linetype'!$O$3:$R$12,4,FALSE) -> 0 | E11: =Calculation!E4*VLOOKUP(Calculation!E$1,'Capacity by Linetype'!$O$3:$R$12,4,FALSE) -> 22322.689 | F11: =Calculation!F4*AVERAGE(I$16,K$16) -> 1287.7683 | G11: =Calculation!G4*VLOOKUP(Calculation!G$1,'Capacity by Linetype'!$O$3:$R$12,4,FALSE) -> 11672.14 | H11: =Calculation!H4*VLOOKUP(Calculation!H$1,'Capacity by Linetype'!$O$3:$R$12,4,FALSE) -> 951.58503 | I11: =Calculation!I4*VLOOKUP(Calculation!H$1,'Capacity by Linetype'!$O$3:$R$12,4,FALSE)*0.5 -> 0 | J11: =SUM(K11:Q11) -> 859537.89 | K11: =Calculation!K4*VLOOKUP(Calculation!K$1,'Capacity by Linetype'!$O$3:$R$12,4,FALSE) -> 11526.979 | L11: =Calculation!L4*VLOOKUP(Calculation!L$1,'Capacity by Linetype'!$O$3:$R$12,4,FALSE) -> 21015.31 | M11: =Calculation!M4*VLOOKUP(Calculation!M$1,'Capacity by Linetype'!$O$3:$R$12,4,FALSE) -> 178819.96 | N11: =Calculation!N4*VLOOKUP(Calculation!N$1,'Capacity by Linetype'!$O$3:$R$12,4,FALSE) -> 13172.021 | O11: =Calculation!O4*VLOOKUP(Calculation!O$1,'Capacity by Linetype'!$O$3:$R$12,4,FALSE) -> 204949.67 | P11: =Calculation!P4*VLOOKUP(Calculation!P$1,'Capacity by Linetype'!$O$3:$R$12,4,FALSE) -> 257927.86 | Q11: =Calculation!Q4*VLOOKUP(Calculation!Q$1,'Capacity by Linetype'!$O$3:$R$13,4,FALSE) -> 172126.09 | S11: =(SUM(E11:I11)+SUM(K11:R11))*10/1.609344 -> 5566069.6 | AD11: 银东直流 | AE11: 660 | AF11: 4000 | AG11: =AF11/AE11/2*1000 -> 3030.303 | AL11: 660 | AM11: 3030.303
A12: 2018 | B12: =C12+J12 -> 935765.72 | C12: =SUM(D12:I12) -> 39958.713 | D12: =Calculation!D5*VLOOKUP(Calculation!D$1,'Capacity by Linetype'!$O$3:$R$12,4,FALSE) -> 323.27198 | E12: =Calculation!E5*VLOOKUP(Calculation!E$1,'Capacity by Linetype'!$O$3:$R$12,4,FALSE) -> 23230.611 | F12: =Calculation!F5*AVERAGE(I$16,K$16) -> 2018.5333 | G12: =Calculation!G5*VLOOKUP(Calculation!G$1,'Capacity by Linetype'!$O$3:$R$12,4,FALSE) -> 13287.912 | H12: =Calculation!H5*VLOOKUP(Calculation!H$1,'Capacity by Linetype'!$O$3:$R$12,4,FALSE) -> 951.58503 | I12: =Calculation!I5*VLOOKUP(Calculation!H$1,'Capacity by Linetype'!$O$3:$R$12,4,FALSE)*0.5 -> 146.7994 | J12: =SUM(K12:Q12) -> 895807 | K12: =Calculation!K5*VLOOKUP(Calculation!K$1,'Capacity by Linetype'!$O$3:$R$12,4,FALSE) -> 11896.603 | L12: =Calculation!L5*VLOOKUP(Calculation!L$1,'Capacity by Linetype'!$O$3:$R$12,4,FALSE) -> 22927.111 | M12: =Calculation!M5*VLOOKUP(Calculation!M$1,'Capacity by Linetype'!$O$3:$R$12,4,FALSE) -> 192595.92 | N12: =Calculation!N5*VLOOKUP(Calculation!N$1,'Capacity by Linetype'!$O$3:$R$12,4,FALSE) -> 13300.324 | O12: =Calculation!O5*VLOOKUP(Calculation!O$1,'Capacity by Linetype'!$O$3:$R$12,4,FALSE) -> 214415.7 | P12: =Calculation!P5*VLOOKUP(Calculation!P$1,'Capacity by Linetype'!$O$3:$R$12,4,FALSE) -> 266723.44 | Q12: =Calculation!Q5*VLOOKUP(Calculation!Q$1,'Capacity by Linetype'!$O$3:$R$13,4,FALSE) -> 173947.91 | S12: =(SUM(E12:I12)+SUM(K12:R12))*10/1.609344 -> 5812569.9 | AD12: 锦屏-苏南 | AE12: 800 | AF12: 6400 | AG12: 4000 | AH12: 2093 | AL12: 800 | AM12: 4000
A13: 2019 | B13: =C13+J13 -> 977101.95 | C13: =SUM(D13:I13) -> 39378.713 | D13: =Calculation!D6*VLOOKUP(Calculation!D$1,'Capacity by Linetype'!$O$3:$R$12,4,FALSE) -> 1751.9427 | E13: =Calculation!E6*VLOOKUP(Calculation!E$1,'Capacity by Linetype'!$O$3:$R$12,4,FALSE) -> 23427.381 | F13: =Calculation!F6*AVERAGE(I$16,K$16) -> 1287.7683 | G13: =Calculation!G6*VLOOKUP(Calculation!G$1,'Capacity by Linetype'!$O$3:$R$12,4,FALSE) -> 11828.033 | H13: =Calculation!H6*VLOOKUP(Calculation!H$1,'Capacity by Linetype'!$O$3:$R$12,4,FALSE) -> 951.00479 | I13: =Calculation!I6*VLOOKUP(Calculation!H$1,'Capacity by Linetype'!$O$3:$R$12,4,FALSE)*0.5 -> 132.58365 | J13: =SUM(K13:Q13) -> 937723.23 | K13: =Calculation!K6*VLOOKUP(Calculation!K$1,'Capacity by Linetype'!$O$3:$R$12,4,FALSE) -> 12441.31 | L13: =Calculation!L6*VLOOKUP(Calculation!L$1,'Capacity by Linetype'!$O$3:$R$12,4,FALSE) -> 25954.968 | M13: =Calculation!M6*VLOOKUP(Calculation!M$1,'Capacity by Linetype'!$O$3:$R$12,4,FALSE) -> 201320.25 | N13: =Calculation!N6*VLOOKUP(Calculation!N$1,'Capacity by Linetype'!$O$3:$R$12,4,FALSE) -> 14102 | O13: =Calculation!O6*VLOOKUP(Calculation!O$1,'Capacity by Linetype'!$O$3:$R$12,4,FALSE) -> 224330.79 | P13: =Calculation!P6*VLOOKUP(Calculation!P$1,'Capacity by Linetype'!$O$3:$R$12,4,FALSE) -> 279598.16 | Q13: =Calculation!Q6*VLOOKUP(Calculation!Q$1,'Capacity by Linetype'!$O$3:$R$13,4,FALSE) -> 179975.75 | S13: =(SUM(E13:I13)+SUM(K13:R13))*10/1.609344 -> 6060544 | AD13: 云南-广东 | AE13: 800 | AF13: 5000 | AG13: 3200 | AL13: 800 | AM13: 3200
A14: 2020 | B14: =C14+J14 -> 1060095.4 | C14: =SUM(D14:I14) -> 43521.755 | D14: =Calculation!D7*VLOOKUP(Calculation!D$1,'Capacity by Linetype'!$O$3:$R$12,4,FALSE) -> 1751.9427 | E14: =Calculation!E7*VLOOKUP(Calculation!E$1,'Capacity by Linetype'!$O$3:$R$12,4,FALSE) -> 26713.652 | F14: =Calculation!F7*AVERAGE(I$16,K$16) -> 1287.7683 | G14: =Calculation!G7*VLOOKUP(Calculation!G$1,'Capacity by Linetype'!$O$3:$R$12,4,FALSE) -> 12732.383 | H14: =Calculation!H7*VLOOKUP(Calculation!H$1,'Capacity by Linetype'!$O$3:$R$12,4,FALSE) -> 951.00479 | I14: =Calculation!I7*VLOOKUP(Calculation!H$1,'Capacity by Linetype'!$O$3:$R$12,4,FALSE)*0.5 -> 85.004394 | J14: =SUM(K14:Q14) -> 1016573.6 | K14: =Calculation!K7*VLOOKUP(Calculation!K$1,'Capacity by Linetype'!$O$3:$R$12,4,FALSE) -> 15289.583 | L14: =Calculation!L7*VLOOKUP(Calculation!L$1,'Capacity by Linetype'!$O$3:$R$12,4,FALSE) -> 27952.705 | M14: =Calculation!M7*VLOOKUP(Calculation!M$1,'Capacity by Linetype'!$O$3:$R$12,4,FALSE) -> 208957.9 | N14: =Calculation!N7*VLOOKUP(Calculation!N$1,'Capacity by Linetype'!$O$3:$R$12,4,FALSE) -> 15971.124 | O14: =Calculation!O7*VLOOKUP(Calculation!O$1,'Capacity by Linetype'!$O$3:$R$12,4,FALSE) -> 241088.55 | P14: =Calculation!P7*VLOOKUP(Calculation!P$1,'Capacity by Linetype'!$O$3:$R$12,4,FALSE) -> 307442.12 | Q14: =Calculation!Q7*VLOOKUP(Calculation!Q$1,'Capacity by Linetype'!$O$3:$R$13,4,FALSE) -> 199871.62 | S14: =(SUM(E14:I14)+SUM(K14:R14))*10/1.609344 -> 6576241.1 | AD14: 向家坝-上海 | AE14: 800 | AF14: 6400 | AG14: 4000 | AH14: 2000 | AL14: 800 | AM14: 4000
AD15: 滇西北-广东 | AE15: 800 | AF15: =AE15*AG15*2/1000 -> 5000 | AG15: 3125 | AL15: 800 | AM15: 3125
E16: 1 | G16: 1 | I16: =Calculation!E16*VLOOKUP(Calculation!E$1,'Capacity by Linetype'!$O$3:$R$12,4,FALSE) -> 1.0694016 | K16: =Calculation!G16*VLOOKUP(Calculation!G$1,'Capacity by Linetype'!$O$3:$R$12,4,FALSE) -> 0.86128544
A37: Year | B37: 2015 | C37: 2016 | D37: 2017 | E37: 2018 | F37: 2019 | G37: 2020 | H37: 2021 | I37: 2022 | J37: 2023 | K37: 2024 | L37: 2025 | M37: 2026 | N37: 2027 | O37: 2028 | P37: 2029 | Q37: 2030 | R37: 2031 | S37: 2032 | T37: 2033 | U37: 2034 | V37: 2035 | W37: 2036 | X37: 2037 | Y37: 2038 | Z37: 2039 | AA37: 2040 | AB37: 2041 | AC37: 2042 | AD37: 2043 | AE37: 2044 | AF37: 2045 | AG37: 2046 | AH37: 2047 | AI37: 2048 | AJ37: 2049 | AK37: 2050 | AL37: 2051 | AM37: 2052 | AN37: 2053 | AO37: 2054 | AP37: 2055 | AQ37: 2056 | AR37: 2057 | AS37: 2058 | AT37: 2059 | AU37: 2060
A38: Transmission Capacity | B38: {=TRANSPOSE(S9:S14)} -> 5071893.1 | C38: 5301387.3 | D38: 5566069.6 | E38: 5812569.9 | F38: 6060544 | G38: 6576241.1
A39: Power Generation | B39: 57400 | C39: 60228 | D39: 64529 | E39: 69947 | F39: 73269 | G39: 76264
A40: Generation Capacity | B40: 152527 | C40: 165051 | D40: 178451 | E40: 190012 | F40: 201006 | G40: 220204
A41: BAU Power Generation | H41: =SUM('BAU Generation'!B2:B49)/10^5 -> 83927.138 | I41: =SUM('BAU Generation'!C2:C49)/10^5 -> 86271.975 | J41: =SUM('BAU Generation'!D2:D49)/10^5 -> 88548.427 | K41: =SUM('BAU Generation'!E2:E49)/10^5 -> 90708.261 | L41: =SUM('BAU Generation'!F2:F49)/10^5 -> 92785.167 | M41: =SUM('BAU Generation'!G2:G49)/10^5 -> 94890.311 | N41: =SUM('BAU Generation'!H2:H49)/10^5 -> 97245.297 | O41: =SUM('BAU Generation'!I2:I49)/10^5 -> 99523.036 | ... AU41: =SUM('BAU Generation'!AO2:AO49)/10^5 -> 152318.85
A42: BAU Capacity | H42: =SUM('BAU Capacity'!B2:B49)/10 -> 222562 | I42: =SUM('BAU Capacity'!C2:C49)/10 -> 234873.6 | J42: =SUM('BAU Capacity'!D2:D49)/10 -> 239754 | K42: =SUM('BAU Capacity'!E2:E49)/10 -> 245220.7 | L42: =SUM('BAU Capacity'!F2:F49)/10 -> 251474.7 | M42: =SUM('BAU Capacity'!G2:G49)/10 -> 258434.8 | N42: =SUM('BAU Capacity'!H2:H49)/10 -> 266550.6 | O42: =SUM('BAU Capacity'!I2:I49)/10 -> 274809.8 | ... AU42: =SUM('BAU Capacity'!AO2:AO49)/10 -> 790553.6
A43: Forecasted BTC1 | H43: {=FORECAST(H41,$B38:$G38,$B39:$G39)} -> 6940594 | I43: {=FORECAST(I41,$B38:$G38,$B39:$G39)} -> 7107494.3 | J43: {=FORECAST(J41,$B38:$G38,$B39:$G39)} -> 7269527.2 | K43: {=FORECAST(K41,$B38:$G38,$B39:$G39)} -> 7423259.5 | L43: {=FORECAST(L41,$B38:$G38,$B39:$G39)} -> 7571089.2 | M43: {=FORECAST(M41,$B38:$G38,$B39:$G39)} -> 7720928.7 | N43: {=FORECAST(N41,$B38:$G38,$B39:$G39)} -> 7888551.5 | O43: {=FORECAST(O41,$B38:$G38,$B39:$G39)} -> 8050676.1 | ... AU43: {=FORECAST(AU41,$B38:$G38,$B39:$G39)} -> 11808567
A44: Forecasted BTC2 | H44: {=FORECAST(H42,$B38:$G38,$B40:$G40)} -> 6570043.3 | I44: {=FORECAST(I42,$B38:$G38,$B40:$G40)} -> 6841594.3 | J44: {=FORECAST(J42,$B38:$G38,$B40:$G40)} -> 6949238.9 | K44: {=FORECAST(K42,$B38:$G38,$B40:$G40)} -> 7069815.3 | L44: {=FORECAST(L42,$B38:$G38,$B40:$G40)} -> 7207756.7 | M44: {=FORECAST(M42,$B38:$G38,$B40:$G40)} -> 7361272.3 | N44: {=FORECAST(N42,$B38:$G38,$B40:$G40)} -> 7540278.6 | O44: {=FORECAST(O42,$B38:$G38,$B40:$G40)} -> 7722447.7 | ... AU44: {=FORECAST(AU42,$B38:$G38,$B40:$G40)} -> 19097960
A46: Year | B46: 2015 | C46: 2016 | D46: 2017 | E46: 2018 | F46: 2019 | G46: 2020 | H46: 2021 | I46: 2022 | J46: 2023 | K46: 2024 | L46: 2025 | M46: 2026 | N46: 2027 | O46: 2028 | P46: 2029 | Q46: 2030 | R46: 2031 | S46: 2032 | T46: 2033 | U46: 2034 | V46: 2035 | W46: 2036 | X46: 2037 | Y46: 2038 | Z46: 2039 | AA46: 2040 | AB46: 2041 | AC46: 2042 | AD46: 2043 | AE46: 2044 | AF46: 2045 | AG46: 2046 | AH46: 2047 | AI46: 2048 | AJ46: 2049 | AK46: 2050 | AL46: 2051 | AM46: 2052 | AN46: 2053 | AO46: 2054 | AP46: 2055 | AQ46: 2056 | AR46: 2057 | AS46: 2058 | AT46: 2059 | AU46: 2060
A47: Transmission Capacity | B47: =B38 -> 5071893.1 | C47: =C38 -> 5301387.3 | D47: =D38 -> 5566069.6 | E47: =E38 -> 5812569.9 | F47: =F38 -> 6060544 | G47: =G38 -> 6576241.1
A48: Forecasted BTC1 | G48: =MAX($G$38,G43) -> 6576241.1 | H48: =MAX($G$38,H43) -> 6940594 | I48: =MAX($G$38,I43) -> 7107494.3 | J48: =MAX($G$38,J43) -> 7269527.2 | K48: =MAX($G$38,K43) -> 7423259.5 | L48: =MAX($G$38,L43) -> 7571089.2 | M48: =MAX($G$38,M43) -> 7720928.7 | N48: =MAX($G$38,N43) -> 7888551.5 | ... AU48: =MAX($G$38,AU43) -> 11808567
A49: Forecasted BTC2 | G49: =MAX($G$38,G44) -> 6576241.1 | H49: =MAX($G$38,H44) -> 6576241.1 | I49: =MAX($G$38,I44) -> 6841594.3 | J49: =MAX($G$38,J44) -> 6949238.9 | K49: =MAX($G$38,K44) -> 7069815.3 | L49: =MAX($G$38,L44) -> 7207756.7 | M49: =MAX($G$38,M44) -> 7361272.3 | N49: =MAX($G$38,N44) -> 7540278.6 | ... AU49: =MAX($G$38,AU44) -> 19097960

Sheet BAU Capacity
A1: Time (Time) | B1: 2021 | C1: 2022 | D1: 2023 | E1: 2024 | F1: 2025 | G1: 2026 | H1: 2027 | I1: 2028 | J1: 2029 | K1: 2030 | L1: 2031 | M1: 2032 | N1: 2033 | O1: 2034 | P1: 2035 | Q1: 2036 | R1: 2037 | S1: 2038 | T1: 2039 | U1: 2040 | V1: 2041 | W1: 2042 | X1: 2043 | Y1: 2044 | Z1: 2045 | AA1: 2046 | AB1: 2047 | AC1: 2048 | AD1: 2049 | AE1: 2050 | AF1: 2051 | AG1: 2052 | AH1: 2053 | AI1: 2054 | AJ1: 2055 | AK1: 2056 | AL1: 2057 | AM1: 2058 | AN1: 2059 | AO1: 2060
A2: Electricity Generation Capacity[hard coal es,preexisting retiring] : MostRecentRun | B2: 1036580 | C2: 1027810 | D2: 1015160 | E2: 1002520 | F2: 989880 | G2: 977238 | H2: 964596 | I2: 953502 | J2: 942924 | K2: 928734 | L2: 911706 | M2: 898290 | N2: 880746 | O2: 866556 | P2: 851592 | Q2: 835854 | R2: 798960 | S2: 778320 | T2: 752520 | U2: 703500 | V2: 616038 | W2: 551538 | X2: 491166 | Y2: 427956 | Z2: 372486 | AA2: 315984 | AB2: 268254 | AC2: 233940 | AD2: 199110 | AE2: 145188 | AF2: 107004 | AG2: 72174 | AH2: 41730 | AI2: 10770 | AJ2: 0 | AK2: 0 | AL2: 0 | AM2: 0 | AN2: 0 | AO2: 0
A3: Electricity Generation Capacity[hard coal es,preexisting nonretiring] : MostRecentRun | B3: 0 | C3: 0 | D3: 0 | E3: 0 | F3: 0 | G3: 0 | H3: 0 | I3: 0 | J3: 0 | K3: 0 | L3: 0 | M3: 0 | N3: 0 | O3: 0 | P3: 0 | Q3: 0 | R3: 0 | S3: 0 | T3: 0 | U3: 0 | V3: 0 | W3: 0 | X3: 0 | Y3: 0 | Z3: 0 | AA3: 0 | AB3: 0 | AC3: 0 | AD3: 0 | AE3: 0 | AF3: 0 | AG3: 0 | AH3: 0 | AI3: 0 | AJ3: 0 | AK3: 0 | AL3: 0 | AM3: 0 | AN3: 0 | AO3: 0
A4: Electricity Generation Capacity[hard coal es,newly built] : MostRecentRun | B4: 29412 | C4: 55986 | D4: 79722 | E4: 101136 | F4: 120228 | G4: 136998 | H4: 151446 | I4: 163572 | J4: 173376 | K4: 180858 | L4: 186018 | M4: 188598 | N4: 188856 | O4: 189114 | P4: 189372 | Q4: 189630 | R4: 189888 | S4: 190146 | T4: 190404 | U4: 190662 | V4: 191178 | W4: 192210 | X4: 193242 | Y4: 194274 | Z4: 195048 | AA4: 195822 | AB4: 196596 | AC4: 197370 | AD4: 198144 | AE4: 198918 | AF4: 199434 | AG4: 199950 | AH4: 200466 | AI4: 200982 | AJ4: 173826 | AK4: 145188 | AL4: 119130 | AM4: 96684 | AN4: 76560 | AO4: 58500
A5: Electricity Generation Capacity[natural gas nonpeaker es,preexisting retiring] : MostRecentRun | B5: 69804 | C5: 69804 | D5: 69804 | E5: 69804 | F5: 69804 | G5: 69804 | H5: 69804 | I5: 69804 | J5: 69804 | K5: 69804 | L5: 69804 | M5: 69804 | N5: 69804 | O5: 68880 | P5: 68880 | Q5: 68880 | R5: 67956 | S5: 67648 | T5: 66416 | U5: 62104 | V5: 58254 | W5: 54250 | X5: 52094 | Y5: 51324 | Z5: 50554 | AA5: 49014 | AB5: 47320 | AC5: 44240 | AD5: 37772 | AE5: 32998 | AF5: 31612 | AG5: 27762 | AH5: 21602 | AI5: 17290 | AJ5: 11592 | AK5: 6202 | AL5: 1428 | AM5: 0 | AN5: 0 | AO5: 0
A6: Electricity Generation Capacity[natural gas nonpeaker es,preexisting nonretiring] : MostRecentRun | B6: 0 | C6: 0 | D6: 0 | E6: 0 | F6: 0 | G6: 0 | H6: 0 | I6: 0 | J6: 0 | K6: 0 | L6: 0 | M6: 0 | N6: 0 | O6: 0 | P6: 0 | Q6: 0 | R6: 0 | S6: 0 | T6: 0 | U6: 0 | V6: 0 | W6: 0 | X6: 0 | Y6: 0 | Z6: 0 | AA6: 0 | AB6: 0 | AC6: 0 | AD6: 0 | AE6: 0 | AF6: 0 | AG6: 0 | AH6: 0 | AI6: 0 | AJ6: 0 | AK6: 0 | AL6: 0 | AM6: 0 | AN6: 0 | AO6: 0
A7: Electricity Generation Capacity[natural gas nonpeaker es,newly built] : MostRecentRun | B7: 1386 | C7: 2618 | D7: 5852 | E7: 9548 | F7: 10626 | G7: 10780 | H7: 10780 | I7: 10780 | J7: 10780 | K7: 10780 | L7: 10780 | M7: 10780 | N7: 10780 | O7: 10780 | P7: 10780 | Q7: 10780 | R7: 10780 | S7: 10780 | T7: 10780 | U7: 10780 | V7: 10780 | W7: 10780 | X7: 10780 | Y7: 10780 | Z7: 10780 | AA7: 10780 | AB7: 10780 | AC7: 10780 | AD7: 10780 | AE7: 10780 | AF7: 10780 | AG7: 10780 | AH7: 10780 | AI7: 10780 | AJ7: 10780 | AK7: 10780 | AL7: 10780 | AM7: 658 | AN7: 0 | AO7: 0
A8: Electricity Generation Capacity[nuclear es,preexisting retiring] : MostRecentRun | B8: 49890 | C8: 49890 | D8: 49890 | E8: 49890 | F8: 49890 | G8: 49890 | H8: 49890 | I8: 49890 | J8: 49890 | K8: 49890 | L8: 49890 | M8: 49890 | N8: 49890 | O8: 49890 | P8: 49890 | Q8: 49890 | R8: 49890 | S8: 49890 | T8: 49890 | U8: 49890 | V8: 49890 | W8: 49890 | X8: 49890 | Y8: 49890 | Z8: 49890 | AA8: 49890 | AB8: 49890 | AC8: 49890 | AD8: 49890 | AE8: 49890 | AF8: 49890 | AG8: 49890 | AH8: 49890 | AI8: 49890 | AJ8: 49890 | AK8: 49890 | AL8: 49890 | AM8: 49890 | AN8: 49890 | AO8: 49890
A9: Electricity Generation Capacity[nuclear es,preexisting nonretiring] : MostRecentRun | B9: 0 | C9: 0 | D9: 0 | E9: 0 | F9: 0 | G9: 0 | H9: 0 | I9: 0 | J9: 0 | K9: 0 | L9: 0 | M9: 0 | N9: 0 | O9: 0 | P9: 0 | Q9: 0 | R9: 0 | S9: 0 | T9: 0 | U9: 0 | V9: 0 | W9: 0 | X9: 0 | Y9: 0 | Z9: 0 | AA9: 0 | AB9: 0 | AC9: 0 | AD9: 0 | AE9: 0 | AF9: 0 | AG9: 0 | AH9: 0 | AI9: 0 | AJ9: 0 | AK9: 0 | AL9: 0 | AM9: 0 | AN9: 0 | AO9: 0
A10: Electricity Generation Capacity[nuclear es,newly built] : MostRecentRun | B10: 4000 | C10: 5500 | D10: 8500 | E10: 10000 | F10: 12500 | G10: 18500 | H10: 25000 | I10: 30500 | J10: 36000 | K10: 36500 | L10: 37000 | M10: 37500 | N10: 38000 | O10: 38500 | P10: 39000 | Q10: 39500 | R10: 40000 | S10: 40500 | T10: 41000 | U10: 41500 | V10: 42500 | W10: 44500 | X10: 46000 | Y10: 47500 | Z10: 49000 | AA10: 50500 | AB10: 52000 | AC10: 53000 | AD10: 54000 | AE10: 55500 | AF10: 56500 | AG10: 57500 | AH10: 58500 | AI10: 59500 | AJ10: 60500 | AK10: 61000 | AL10: 62000 | AM10: 62500 | AN10: 63000 | AO10: 63500
A11: Electricity Generation Capacity[hydro es,preexisting retiring] : MostRecentRun | B11: 338790 | C11: 338790 | D11: 338790 | E11: 338790 | F11: 338790 | G11: 338790 | H11: 338790 | I11: 338790 | J11: 338790 | K11: 338790 | L11: 338790 | M11: 338790 | N11: 338790 | O11: 338790 | P11: 338790 | Q11: 338790 | R11: 338790 | S11: 338790 | T11: 338790 | U11: 338790 | V11: 338790 | W11: 338790 | X11: 338790 | Y11: 338790 | Z11: 338790 | AA11: 338790 | AB11: 338790 | AC11: 338790 | AD11: 338790 | AE11: 338790 | AF11: 338790 | AG11: 338790 | AH11: 338790 | AI11: 338790 | AJ11: 338790 | AK11: 338790 | AL11: 338790 | AM11: 338790 | AN11: 338790 | AO11: 338790
A12: Electricity Generation Capacity[hydro es,preexisting nonretiring] : MostRecentRun | B12: 0 | C12: 0 | D12: 0 | E12: 0 | F12: 0 | G12: 0 | H12: 0 | I12: 0 | J12: 0 | K12: 0 | L12: 0 | M12: 0 | N12: 0 | O12: 0 | P12: 0 | Q12: 0 | R12: 0 | S12: 0 | T12: 0 | U12: 0 | V12: 0 | W12: 0 | X12: 0 | Y12: 0 | Z12: 0 | AA12: 0 | AB12: 0 | AC12: 0 | AD12: 0 | AE12: 0 | AF12: 0 | AG12: 0 | AH12: 0 | AI12: 0 | AJ12: 0 | AK12: 0 | AL12: 0 | AM12: 0 | AN12: 0 | AO12: 0
... A49: Electricity Generation Capacity[municipal solid waste es,newly built] : MostRecentRun | B49: 6412 | C49: 12194 | D49: 12194 | E49: 12208 | F49: 12236 | G49: 12264 | H49: 12306 | I49: 12334 | J49: 12362 | K49: 12404 | L49: 12446 | M49: 12488 | N49: 12530 | O49: 12572 | P49: 12614 | Q49: 12656 | R49: 12698 | S49: 12726 | T49: 12768 | U49: 12824 | V49: 12894 | W49: 13006 | X49: 13118 | Y49: 13230 | Z49: 13328 | AA49: 13426 | AB49: 13510 | AC49: 13580 | AD49: 13650 | AE49: 13734 | AF49: 13790 | AG49: 13860 | AH49: 13916 | AI49: 13972 | AJ49: 14042 | AK49: 14098 | AL49: 14154 | AM49: 14210 | AN49: 14252 | AO49: 14294

Sheet BAU Generation
A1: Time (Time) | B1: 2021 | C1: 2022 | D1: 2023 | E1: 2024 | F1: 2025 | G1: 2026 | H1: 2027 | I1: 2028 | J1: 2029 | K1: 2030 | L1: 2031 | M1: 2032 | N1: 2033 | O1: 2034 | P1: 2035 | Q1: 2036 | R1: 2037 | S1: 2038 | T1: 2039 | U1: 2040 | V1: 2041 | W1: 2042 | X1: 2043 | Y1: 2044 | Z1: 2045 | AA1: 2046 | AB1: 2047 | AC1: 2048 | AD1: 2049 | AE1: 2050 | AF1: 2051 | AG1: 2052 | AH1: 2053 | AI1: 2054 | AJ1: 2055 | AK1: 2056 | AL1: 2057 | AM1: 2058 | AN1: 2059 | AO1: 2060
A2: Electricity Generation by Type[hard coal es,preexisting retiring] : MostRecentRun | B2: 4757130000 | C2: 4647110000 | D2: 4618110000 | E2: 4591450000 | F2: 4548600000 | G2: 4492000000 | H2: 4435960000 | I2: 4385540000 | J2: 4338070000 | K2: 4275870000 | L2: 4199460000 | M2: 4138840000 | N2: 4060470000 | O2: 3995540000 | P2: 3928490000 | Q2: 3857730000 | R2: 3691930000 | S2: 3598540000 | T2: 3480450000 | U2: 3255310000 | V2: 2857460000 | W2: 2564240000 | X2: 2293640000 | Y2: 2011600000 | Z2: 1763670000 | AA2: 1508110000 | AB2: 1295090000 | AC2: 1133290000 | AD2: 968107000 | AE2: 716398000 | AF2: 561132000 | AG2: 391277000 | AH2: 247571000 | AI2: 71101100 | AJ2: 0 | AK2: 0 | AL2: 0 | AM2: 0 | AN2: 0 | AO2: 0
A3: Electricity Generation by Type[hard coal es,preexisting nonretiring] : MostRecentRun | B3: 0 | C3: 0 | D3: 0 | E3: 0 | F3: 0 | G3: 0 | H3: 0 | I3: 0 | J3: 0 | K3: 0 | L3: 0 | M3: 0 | N3: 0 | O3: 0 | P3: 0 | Q3: 0 | R3: 0 | S3: 0 | T3: 0 | U3: 0 | V3: 0 | W3: 0 | X3: 0 | Y3: 0 | Z3: 0 | AA3: 0 | AB3: 0 | AC3: 0 | AD3: 0 | AE3: 0 | AF3: 0 | AG3: 0 | AH3: 0 | AI3: 0 | AJ3: 0 | AK3: 0 | AL3: 0 | AM3: 0 | AN3: 0 | AO3: 0
A4: Electricity Generation by Type[hard coal es,newly built] : MostRecentRun | B4: 171114000 | C4: 271692000 | D4: 398164000 | E4: 515078000 | F4: 610264000 | G4: 684718000 | H4: 749920000 | I4: 803782000 | J4: 847325000 | K4: 881923000 | L4: 905123000 | M4: 916553000 | N4: 917671000 | O4: 917831000 | P4: 919050000 | Q4: 919966000 | R4: 920982000 | S4: 921685000 | T4: 921613000 | U4: 919494000 | V4: 918590000 | W4: 920960000 | X4: 926005000 | Y4: 931975000 | Z4: 936313000 | AA4: 938637000 | AB4: 943061000 | AC4: 941462000 | AD4: 939067000 | AE4: 936293000 | AF4: 949430000 | AG4: 942871000 | AH4: 940588000 | AI4: 955157000 | AJ4: 830198000 | AK4: 709790000 | AL4: 577414000 | AM4: 466918000 | AN4: 374415000 | AO4: 290823000
A5: Electricity Generation by Type[natural gas nonpeaker es,preexisting retiring] : MostRecentRun | B5: 2154250 | C5: 261408 | D5: 750780 | E5: 1128700 | F5: 1200980 | G5: 1043680 | H5: 1136520 | I5: 1250230 | J5: 1102060 | K5: 1016060 | L5: 948457 | M5: 915212 | N5: 867626 | O5: 804664 | P5: 815222 | Q5: 811409 | R5: 800436 | S5: 808601 | T5: 826275 | U5: 813320 | V5: 786009 | W5: 754454 | X5: 741174 | Y5: 772166 | Z5: 765253 | AA5: 776032 | AB5: 787373 | AC5: 718303 | AD5: 658697 | AE5: 597000 | AF5: 732429 | AG5: 606715 | AH5: 552959 | AI5: 734755 | AJ5: 563143 | AK5: 311539 | AL5: 70279.1 | AM5: 0 | AN5: 0 | AO5: 0
A6: Electricity Generation by Type[natural gas nonpeaker es,preexisting nonretiring] : MostRecentRun | B6: 0 | C6: 0 | D6: 0 | E6: 0 | F6: 0 | G6: 0 | H6: 0 | I6: 0 | J6: 0 | K6: 0 | L6: 0 | M6: 0 | N6: 0 | O6: 0 | P6: 0 | Q6: 0 | R6: 0 | S6: 0 | T6: 0 | U6: 0 | V6: 0 | W6: 0 | X6: 0 | Y6: 0 | Z6: 0 | AA6: 0 | AB6: 0 | AC6: 0 | AD6: 0 | AE6: 0 | AF6: 0 | AG6: 0 | AH6: 0 | AI6: 0 | AJ6: 0 | AK6: 0 | AL6: 0 | AM6: 0 | AN6: 0 | AO6: 0
A7: Electricity Generation by Type[natural gas nonpeaker es,newly built] : MostRecentRun | B7: 513371 | C7: 309809 | D7: 1043610 | E7: 1842050 | F7: 1939070 | G7: 1718270 | H7: 1859190 | I7: 2055630 | J7: 1820240 | K7: 1659710 | L7: 1548480 | M7: 1499280 | N7: 1417660 | O7: 1329310 | P7: 1346410 | Q7: 1342080 | R7: 1323390 | S7: 1344150 | T7: 1395820 | U7: 1431350 | V7: 1439720 | W7: 1425160 | X7: 1393770 | Y7: 1423450 | Z7: 1395440 | AA7: 1434880 | AB7: 1438280 | AC7: 1407740 | AD7: 1407150 | AE7: 1416960 | AF7: 1459800 | AG7: 1390380 | AH7: 1377800 | AI7: 1914130 | AJ7: 2171470 | AK7: 2245290 | AL7: 2199750 | AM7: 138790 | AN7: 0 | AO7: 0
A8: Electricity Generation by Type[nuclear es,preexisting retiring] : MostRecentRun | B8: 372355000 | C8: 372355000 | D8: 372355000 | E8: 372355000 | F8: 372355000 | G8: 372355000 | H8: 372355000 | I8: 372355000 | J8: 372355000 | K8: 372355000 | L8: 372355000 | M8: 372355000 | N8: 372355000 | O8: 372355000 | P8: 372355000 | Q8: 372355000 | R8: 372355000 | S8: 372355000 | T8: 372355000 | U8: 372355000 | V8: 372355000 | W8: 372355000 | X8: 372355000 | Y8: 372355000 | Z8: 372355000 | AA8: 372355000 | AB8: 372355000 | AC8: 372355000 | AD8: 372355000 | AE8: 372355000 | AF8: 372355000 | AG8: 372355000 | AH8: 372355000 | AI8: 372355000 | AJ8: 372355000 | AK8: 372355000 | AL8: 372355000 | AM8: 372355000 | AN8: 372355000 | AO8: 372355000
A9: Electricity Generation by Type[nuclear es,preexisting nonretiring] : MostRecentRun | B9: 0 | C9: 0 | D9: 0 | E9: 0 | F9: 0 | G9: 0 | H9: 0 | I9: 0 | J9: 0 | K9: 0 | L9: 0 | M9: 0 | N9: 0 | O9: 0 | P9: 0 | Q9: 0 | R9: 0 | S9: 0 | T9: 0 | U9: 0 | V9: 0 | W9: 0 | X9: 0 | Y9: 0 | Z9: 0 | AA9: 0 | AB9: 0 | AC9: 0 | AD9: 0 | AE9: 0 | AF9: 0 | AG9: 0 | AH9: 0 | AI9: 0 | AJ9: 0 | AK9: 0 | AL9: 0 | AM9: 0 | AN9: 0 | AO9: 0
A10: Electricity Generation by Type[nuclear es,newly built] : MostRecentRun | B10: 29854100 | C10: 41049400 | D10: 63439900 | E10: 74635200 | F10: 93294000 | G10: 138075000 | H10: 186588000 | I10: 227637000 | J10: 268687000 | K10: 272418000 | L10: 276150000 | M10: 279882000 | N10: 283614000 | O10: 287346000 | P10: 291077000 | Q10: 294809000 | R10: 298541000 | S10: 302273000 | T10: 306004000 | U10: 309736000 | V10: 317200000 | W10: 332127000 | X10: 343322000 | Y10: 354517000 | Z10: 365712000 | AA10: 376908000 | AB10: 388103000 | AC10: 395567000 | AD10: 403030000 | AE10: 414225000 | AF10: 421689000 | AG10: 429152000 | AH10: 436616000 | AI10: 444079000 | AJ10: 451543000 | AK10: 455275000 | AL10: 462738000 | AM10: 466470000 | AN10: 470202000 | AO10: 473934000
A11: Electricity Generation by Type[hydro es,preexisting retiring] : MostRecentRun | B11: 1270220000 | C11: 1270220000 | D11: 1270220000 | E11: 1270220000 | F11: 1270220000 | G11: 1270220000 | H11: 1270220000 | I11: 1270220000 | J11: 1270220000 | K11: 1270220000 | L11: 1270220000 | M11: 1270220000 | N11: 1270220000 | O11: 1270220000 | P11: 1270220000 | Q11: 1270220000 | R11: 1270220000 | S11: 1270220000 | T11: 1270220000 | U11: 1270220000 | V11: 1270220000 | W11: 1270220000 | X11: 1270220000 | Y11: 1270220000 | Z11: 1270220000 | AA11: 1270220000 | AB11: 1270220000 | AC11: 1270220000 | AD11: 1270220000 | AE11: 1270220000 | AF11: 1270220000 | AG11: 1270220000 | AH11: 1270220000 | AI11: 1270220000 | AJ11: 1270220000 | AK11: 1270220000 | AL11: 1270220000 | AM11: 1270220000 | AN11: 1270220000 | AO11: 1270220000
A12: Electricity Generation by Type[hydro es,preexisting nonretiring] : MostRecentRun | B12: 0 | C12: 0 | D12: 0 | E12: 0 | F12: 0 | G12: 0 | H12: 0 | I12: 0 | J12: 0 | K12: 0 | L12: 0 | M12: 0 | N12: 0 | O12: 0 | P12: 0 | Q12: 0 | R12: 0 | S12: 0 | T12: 0 | U12: 0 | V12: 0 | W12: 0 | X12: 0 | Y12: 0 | Z12: 0 | AA12: 0 | AB12: 0 | AC12: 0 | AD12: 0 | AE12: 0 | AF12: 0 | AG12: 0 | AH12: 0 | AI12: 0 | AJ12: 0 | AK12: 0 | AL12: 0 | AM12: 0 | AN12: 0 | AO12: 0
... A49: Electricity Generation by Type[municipal solid waste es,newly built] : MostRecentRun | B49: 53360700 | C49: 101478000 | D49: 101478000 | E49: 101595000 | F49: 101828000 | G49: 102061000 | H49: 102411000 | I49: 102644000 | J49: 102877000 | K49: 103226000 | L49: 103576000 | M49: 103925000 | N49: 104275000 | O49: 104624000 | P49: 104974000 | Q49: 105323000 | R49: 105673000 | S49: 105906000 | T49: 106255000 | U49: 106721000 | V49: 107304000 | W49: 108236000 | X49: 109168000 | Y49: 110100000 | Z49: 110916000 | AA49: 111731000 | AB49: 112430000 | AC49: 113013000 | AD49: 113595000 | AE49: 114294000 | AF49: 114760000 | AG49: 115343000 | AH49: 115809000 | AI49: 116275000 | AJ49: 116858000 | AK49: 117324000 | AL49: 117790000 | AM49: 118256000 | AN49: 118605000 | AO49: 118955000

Sheet BTC
B1: 2015 | C1: 2016 | D1: 2017 | E1: 2018 | F1: 2019 | G1: 2020 | H1: 2021 | I1: 2022 | J1: 2023 | K1: 2024 | L1: 2025 | M1: 2026 | N1: 2027 | O1: 2028 | P1: 2029 | Q1: 2030 | R1: 2031 | S1: 2032 | T1: 2033 | U1: 2034 | V1: 2035 | W1: 2036 | X1: 2037 | Y1: 2038 | Z1: 2039 | AA1: 2040 | AB1: 2041 | AC1: 2042 | AD1: 2043 | AE1: 2044 | AF1: 2045 | AG1: 2046 | AH1: 2047 | AI1: 2048 | AJ1: 2049 | AK1: 2050 | AL1: 2051 | AM1: 2052 | AN1: 2053 | AO1: 2054 | AP1: 2055 | AQ1: 2056 | AR1: 2057 | AS1: 2058 | AT1: 2059 | AU1: 2060
A2: BAU Transmission Capacity (MW*miles) | B2: =Calculation!B$47 -> 5071893.1 | C2: =Calculation!C$47 -> 5301387.3 | D2: =Calculation!D$47 -> 5566069.6 | E2: =Calculation!E$47 -> 5812569.9 | F2: =Calculation!F$47 -> 6060544 | G2: =Calculation!G$47 -> 6576241.1 | H2: =Calculation!H$48 -> 6940594 | I2: =Calculation!I$48 -> 7107494.3 | J2: =Calculation!J$48 -> 7269527.2 | K2: =Calculation!K$48 -> 7423259.5 | L2: =Calculation!L$48 -> 7571089.2 | M2: =Calculation!M$48 -> 7720928.7 | N2: =Calculation!N$48 -> 7888551.5 | O2: =Calculation!O$48 -> 8050676.1 | ... AU2: =Calculation!AU$48 -> 11808567
