Workbook

Sheet 2000
A1: 分地区新增发电装机容量（万KW）
A2: 地区 | B2: 合计 | C2: 水电 | E2: 火电 | S2: 核电 | T2: 风电 | U2: 太阳能发电 | V2: 其他
C3: 合计 | D3: 抽水蓄能 | E3: 合计 | F3: 燃煤 | I3: 燃气 | L3: 燃油 | M3: 其他
F4: 合计 | G4: 常规燃煤 | H4: 煤矸石发电 | I4: 合计 | J4: 常规燃气 | K4: 煤层气发电 | M4: 合计 | N4: 余温、余气、余压发电 | O4: 垃圾焚烧发电 | P4: 秸秆、蔗渣、林木质发电 | Q4: 沼气 | R4: 技改增容
A5: 全国 | X5: =B5-C5-E5-S5-T5-U5-V5 -> 0 | Y5: =E5-F5-I5-L5-M5 -> 0 | Z5: =M5-N5-O5-P5 -> 0
A6: 北京 | X6: =B6-C6-E6-S6-T6-U6-V6 -> 0 | Y6: =E6-F6-I6-L6-M6 -> 0 | Z6: =M6-N6-O6-P6 -> 0
A7: 天津 | X7: =B7-C7-E7-S7-T7-U7-V7 -> 0 | Y7: =E7-F7-I7-L7-M7 -> 0 | Z7: =M7-N7-O7-P7 -> 0
A8: 河北 | X8: =B8-C8-E8-S8-T8-U8-V8 -> 0 | Y8: =E8-F8-I8-L8-M8 -> 0 | Z8: =M8-N8-O8-P8 -> 0
A9: 山西 | X9: =B9-C9-E9-S9-T9-U9-V9 -> 0 | Y9: =E9-F9-I9-L9-M9 -> 0 | Z9: =M9-N9-O9-P9 -> 0
A10: 内蒙古 | X10: =B10-C10-E10-S10-T10-U10-V10 -> 0 | Y10: =E10-F10-I10-L10-M10 -> 0 | Z10: =M10-N10-O10-P10 -> 0
A11: 辽宁 | X11: =B11-C11-E11-S11-T11-U11-V11 -> 0 | Y11: =E11-F11-I11-L11-M11 -> 0 | Z11: =M11-N11-O11-P11 -> 0
A12: 吉林 | X12: =B12-C12-E12-S12-T12-U12-V12 -> 0 | Y12: =E12-F12-I12-L12-M12 -> 0 | Z12: =M12-N12-O12-P12 -> 0
A13: 黑龙江 | X13: =B13-C13-E13-S13-T13-U13-V13 -> 0 | Y13: =E13-F13-I13-L13-M13 -> 0 | Z13: =M13-N13-O13-P13 -> 0
A14: 上海 | X14: =B14-C14-E14-S14-T14-U14-V14 -> 0 | Y14: =E14-F14-I14-L14-M14 -> 0 | Z14: =M14-N14-O14-P14 -> 0
A15: 江苏 | X15: =B15-C15-E15-S15-T15-U15-V15 -> 0 | Y15: =E15-F15-I15-L15-M15 -> 0 | Z15: =M15-N15-O15-P15 -> 0
A16: 浙江 | X16: =B16-C16-E16-S16-T16-U16-V16 -> 0 | Y16: =E16-F16-I16-L16-M16 -> 0 | Z16: =M16-N16-O16-P16 -> 0
... A36: 新疆 | X36: =B36-C36-E36-S36-T36-U36-V36 -> 0 | Y36: =E36-F36-I36-L36-M36 -> 0 | Z36: =M36-N36-O36-P36 -> 0
B38: =B5-SUM(B6:B36) -> 0 | C38: =C5-SUM(C6:C36) -> 0 | D38: =D5-SUM(D6:D36) -> 0 | E38: =E5-SUM(E6:E36) -> 0 | F38: =F5-SUM(F6:F36) -> 0 | H38: =H5-SUM(H6:H36) -> 0 | I38: =I5-SUM(I6:I36) -> 0 | J38: =J5-SUM(J6:J36) -> 0 | K38: =K5-SUM(K6:K36) -> 0 | L38: =L5-SUM(L6:L36) -> 0 | M38: =M5-SUM(M6:M36) -> 0 | N38: =N5-SUM(N6:N36) -> 0 | O38: =O5-SUM(O6:O36) -> 0 | P38: =P5-SUM(P6:P36) -> 0 | S38: =S5-SUM(S6:S36) -> 0 | T38: =T5-SUM(T6:T36) -> 0 | U38: =U5-SUM(U6:U36) -> 0 | V38: =V5-SUM(V6:V36) -> 0

Sheet 2001
A1: 分地区新增发电装机容量（万KW）
A2: 地区 | B2: 合计 | C2: 水电 | E2: 火电 | S2: 核电 | T2: 风电 | U2: 太阳能发电 | V2: 其他
C3: 合计 | D3: 抽水蓄能 | E3: 合计 | F3: 燃煤 | I3: 燃气 | L3: 燃油 | M3: 其他
F4: 合计 | G4: 常规燃煤 | H4: 煤矸石发电 | I4: 合计 | J4: 常规燃气 | K4: 煤层气发电 | M4: 合计 | N4: 余温、余气、余压发电 | O4: 垃圾焚烧发电 | P4: 秸秆、蔗渣、林木质发电 | Q4: 沼气 | R4: 技改增容
A5: 全国 | X5: =B5-C5-E5-S5-T5-U5-V5 -> 0 | Y5: =E5-F5-I5-L5-M5 -> 0 | Z5: =M5-N5-O5-P5 -> 0
A6: 北京 | X6: =B6-C6-E6-S6-T6-U6-V6 -> 0 | Y6: =E6-F6-I6-L6-M6 -> 0 | Z6: =M6-N6-O6-P6 -> 0
A7: 天津 | X7: =B7-C7-E7-S7-T7-U7-V7 -> 0 | Y7: =E7-F7-I7-L7-M7 -> 0 | Z7: =M7-N7-O7-P7 -> 0
A8: 河北 | X8: =B8-C8-E8-S8-T8-U8-V8 -> 0 | Y8: =E8-F8-I8-L8-M8 -> 0 | Z8: =M8-N8-O8-P8 -> 0
A9: 山西 | X9: =B9-C9-E9-S9-T9-U9-V9 -> 0 | Y9: =E9-F9-I9-L9-M9 -> 0 | Z9: =M9-N9-O9-P9 -> 0
A10: 内蒙古 | X10: =B10-C10-E10-S10-T10-U10-V10 -> 0 | Y10: =E10-F10-I10-L10-M10 -> 0 | Z10: =M10-N10-O10-P10 -> 0
A11: 辽宁 | X11: =B11-C11-E11-S11-T11-U11-V11 -> 0 | Y11: =E11-F11-I11-L11-M11 -> 0 | Z11: =M11-N11-O11-P11 -> 0
A12: 吉林 | X12: =B12-C12-E12-S12-T12-U12-V12 -> 0 | Y12: =E12-F12-I12-L12-M12 -> 0 | Z12: =M12-N12-O12-P12 -> 0
A13: 黑龙江 | X13: =B13-C13-E13-S13-T13-U13-V13 -> 0 | Y13: =E13-F13-I13-L13-M13 -> 0 | Z13: =M13-N13-O13-P13 -> 0
A14: 上海 | X14: =B14-C14-E14-S14-T14-U14-V14 -> 0 | Y14: =E14-F14-I14-L14-M14 -> 0 | Z14: =M14-N14-O14-P14 -> 0
A15: 江苏 | X15: =B15-C15-E15-S15-T15-U15-V15 -> 0 | Y15: =E15-F15-I15-L15-M15 -> 0 | Z15: =M15-N15-O15-P15 -> 0
A16: 浙江 | X16: =B16-C16-E16-S16-T16-U16-V16 -> 0 | Y16: =E16-F16-I16-L16-M16 -> 0 | Z16: =M16-N16-O16-P16 -> 0
... A36: 新疆 | X36: =B36-C36-E36-S36-T36-U36-V36 -> 0 | Y36: =E36-F36-I36-L36-M36 -> 0 | Z36: =M36-N36-O36-P36 -> 0
B38: =B5-SUM(B6:B36) -> 0 | C38: =C5-SUM(C6:C36) -> 0 | D38: =D5-SUM(D6:D36) -> 0 | E38: =E5-SUM(E6:E36) -> 0 | F38: =F5-SUM(F6:F36) -> 0 | H38: =H5-SUM(H6:H36) -> 0 | I38: =I5-SUM(I6:I36) -> 0 | J38: =J5-SUM(J6:J36) -> 0 | K38: =K5-SUM(K6:K36) -> 0 | L38: =L5-SUM(L6:L36) -> 0 | M38: =M5-SUM(M6:M36) -> 0 | N38: =N5-SUM(N6:N36) -> 0 | O38: =O5-SUM(O6:O36) -> 0 | P38: =P5-SUM(P6:P36) -> 0 | S38: =S5-SUM(S6:S36) -> 0 | T38: =T5-SUM(T6:T36) -> 0 | U38: =U5-SUM(U6:U36) -> 0 | V38: =V5-SUM(V6:V36) -> 0

Sheet 2002
A1: 分地区新增发电装机容量（万KW）
A2: 地区 | B2: 合计 | C2: 水电 | E2: 火电 | S2: 核电 | T2: 风电 | U2: 太阳能发电 | V2: 其他
C3: 合计 | D3: 抽水蓄能 | E3: 合计 | F3: 燃煤 | I3: 燃气 | L3: 燃油 | M3: 其他
F4: 合计 | G4: 常规燃煤 | H4: 煤矸石发电 | I4: 合计 | J4: 常规燃气 | K4: 煤层气发电 | M4: 合计 | N4: 余温、余气、余压发电 | O4: 垃圾焚烧发电 | P4: 秸秆、蔗渣、林木质发电 | Q4: 沼气 | R4: 技改增容
A5: 全国 | X5: =B5-C5-E5-S5-T5-U5-V5 -> 0 | Y5: =E5-F5-I5-L5-M5 -> 0 | Z5: =M5-N5-O5-P5 -> 0
A6: 北京 | X6: =B6-C6-E6-S6-T6-U6-V6 -> 0 | Y6: =E6-F6-I6-L6-M6 -> 0 | Z6: =M6-N6-O6-P6 -> 0
A7: 天津 | X7: =B7-C7-E7-S7-T7-U7-V7 -> 0 | Y7: =E7-F7-I7-L7-M7 -> 0 | Z7: =M7-N7-O7-P7 -> 0
A8: 河北 | X8: =B8-C8-E8-S8-T8-U8-V8 -> 0 | Y8: =E8-F8-I8-L8-M8 -> 0 | Z8: =M8-N8-O8-P8 -> 0
A9: 山西 | X9: =B9-C9-E9-S9-T9-U9-V9 -> 0 | Y9: =E9-F9-I9-L9-M9 -> 0 | Z9: =M9-N9-O9-P9 -> 0
A10: 内蒙古 | X10: =B10-C10-E10-S10-T10-U10-V10 -> 0 | Y10: =E10-F10-I10-L10-M10 -> 0 | Z10: =M10-N10-O10-P10 -> 0
A11: 辽宁 | X11: =B11-C11-E11-S11-T11-U11-V11 -> 0 | Y11: =E11-F11-I11-L11-M11 -> 0 | Z11: =M11-N11-O11-P11 -> 0
A12: 吉林 | X12: =B12-C12-E12-S12-T12-U12-V12 -> 0 | Y12: =E12-F12-I12-L12-M12 -> 0 | Z12: =M12-N12-O12-P12 -> 0
A13: 黑龙江 | X13: =B13-C13-E13-S13-T13-U13-V13 -> 0 | Y13: =E13-F13-I13-L13-M13 -> 0 | Z13: =M13-N13-O13-P13 -> 0
A14: 上海 | X14: =B14-C14-E14-S14-T14-U14-V14 -> 0 | Y14: =E14-F14-I14-L14-M14 -> 0 | Z14: =M14-N14-O14-P14 -> 0
A15: 江苏 | X15: =B15-C15-E15-S15-T15-U15-V15 -> 0 | Y15: =E15-F15-I15-L15-M15 -> 0 | Z15: =M15-N15-O15-P15 -> 0
A16: 浙江 | X16: =B16-C16-E16-S16-T16-U16-V16 -> 0 | Y16: =E16-F16-I16-L16-M16 -> 0 | Z16: =M16-N16-O16-P16 -> 0
... A36: 新疆 | X36: =B36-C36-E36-S36-T36-U36-V36 -> 0 | Y36: =E36-F36-I36-L36-M36 -> 0 | Z36: =M36-N36-O36-P36 -> 0
B38: =B5-SUM(B6:B36) -> 0 | C38: =C5-SUM(C6:C36) -> 0 | D38: =D5-SUM(D6:D36) -> 0 | E38: =E5-SUM(E6:E36) -> 0 | F38: =F5-SUM(F6:F36) -> 0 | H38: =H5-SUM(H6:H36) -> 0 | I38: =I5-SUM(I6:I36) -> 0 | J38: =J5-SUM(J6:J36) -> 0 | K38: =K5-SUM(K6:K36) -> 0 | L38: =L5-SUM(L6:L36) -> 0 | M38: =M5-SUM(M6:M36) -> 0 | N38: =N5-SUM(N6:N36) -> 0 | O38: =O5-SUM(O6:O36) -> 0 | P38: =P5-SUM(P6:P36) -> 0 | S38: =S5-SUM(S6:S36) -> 0 | T38: =T5-SUM(T6:T36) -> 0 | U38: =U5-SUM(U6:U36) -> 0 | V38: =V5-SUM(V6:V36) -> 0

Sheet 2003
A1: 分地区新增发电装机容量（万KW）
A2: 地区 | B2: 合计 | C2: 水电 | E2: 火电 | S2: 核电 | T2: 风电 | U2: 太阳能发电 | V2: 其他
C3: 合计 | D3: 抽水蓄能 | E3: 合计 | F3: 燃煤 | I3: 燃气 | L3: 燃油 | M3: 其他
F4: 合计 | G4: 常规燃煤 | H4: 煤矸石发电 | I4: 合计 | J4: 常规燃气 | K4: 煤层气发电 | M4: 合计 | N4: 余温、余气、余压发电 | O4: 垃圾焚烧发电 | P4: 秸秆、蔗渣、林木质发电 | Q4: 沼气 | R4: 技改增容
A5: 全国 | X5: =B5-C5-E5-S5-T5-U5-V5 -> 0 | Y5: =E5-F5-I5-L5-M5 -> 0 | Z5: =M5-N5-O5-P5 -> 0
A6: 北京 | X6: =B6-C6-E6-S6-T6-U6-V6 -> 0 | Y6: =E6-F6-I6-L6-M6 -> 0 | Z6: =M6-N6-O6-P6 -> 0
A7: 天津 | X7: =B7-C7-E7-S7-T7-U7-V7 -> 0 | Y7: =E7-F7-I7-L7-M7 -> 0 | Z7: =M7-N7-O7-P7 -> 0
A8: 河北 | X8: =B8-C8-E8-S8-T8-U8-V8 -> 0 | Y8: =E8-F8-I8-L8-M8 -> 0 | Z8: =M8-N8-O8-P8 -> 0
A9: 山西 | X9: =B9-C9-E9-S9-T9-U9-V9 -> 0 | Y9: =E9-F9-I9-L9-M9 -> 0 | Z9: =M9-N9-O9-P9 -> 0
A10: 内蒙古 | X10: =B10-C10-E10-S10-T10-U10-V10 -> 0 | Y10: =E10-F10-I10-L10-M10 -> 0 | Z10: =M10-N10-O10-P10 -> 0
A11: 辽宁 | X11: =B11-C11-E11-S11-T11-U11-V11 -> 0 | Y11: =E11-F11-I11-L11-M11 -> 0 | Z11: =M11-N11-O11-P11 -> 0
A12: 吉林 | X12: =B12-C12-E12-S12-T12-U12-V12 -> 0 | Y12: =E12-F12-I12-L12-M12 -> 0 | Z12: =M12-N12-O12-P12 -> 0
A13: 黑龙江 | X13: =B13-C13-E13-S13-T13-U13-V13 -> 0 | Y13: =E13-F13-I13-L13-M13 -> 0 | Z13: =M13-N13-O13-P13 -> 0
A14: 上海 | X14: =B14-C14-E14-S14-T14-U14-V14 -> 0 | Y14: =E14-F14-I14-L14-M14 -> 0 | Z14: =M14-N14-O14-P14 -> 0
A15: 江苏 | X15: =B15-C15-E15-S15-T15-U15-V15 -> 0 | Y15: =E15-F15-I15-L15-M15 -> 0 | Z15: =M15-N15-O15-P15 -> 0
A16: 浙江 | X16: =B16-C16-E16-S16-T16-U16-V16 -> 0 | Y16: =E16-F16-I16-L16-M16 -> 0 | Z16: =M16-N16-O16-P16 -> 0
... A36: 新疆 | X36: =B36-C36-E36-S36-T36-U36-V36 -> 0 | Y36: =E36-F36-I36-L36-M36 -> 0 | Z36: =M36-N36-O36-P36 -> 0
B38: =B5-SUM(B6:B36) -> 0 | C38: =C5-SUM(C6:C36) -> 0 | D38: =D5-SUM(D6:D36) -> 0 | E38: =E5-SUM(E6:E36) -> 0 | F38: =F5-SUM(F6:F36) -> 0 | H38: =H5-SUM(H6:H36) -> 0 | I38: =I5-SUM(I6:I36) -> 0 | J38: =J5-SUM(J6:J36) -> 0 | K38: =K5-SUM(K6:K36) -> 0 | L38: =L5-SUM(L6:L36) -> 0 | M38: =M5-SUM(M6:M36) -> 0 | N38: =N5-SUM(N6:N36) -> 0 | O38: =O5-SUM(O6:O36) -> 0 | P38: =P5-SUM(P6:P36) -> 0 | S38: =S5-SUM(S6:S36) -> 0 | T38: =T5-SUM(T6:T36) -> 0 | U38: =U5-SUM(U6:U36) -> 0 | V38: =V5-SUM(V6:V36) -> 0

Sheet 2004
A1: 分地区新增发电装机容量（万KW）
A2: 地区 | B2: 合计 | C2: 水电 | E2: 火电 | S2: 核电 | T2: 风电 | U2: 太阳能发电 | V2: 其他
C3: 合计 | D3: 抽水蓄能 | E3: 合计 | F3: 燃煤 | I3: 燃气 | L3: 燃油 | M3: 其他
F4: 合计 | G4: 常规燃煤 | H4: 煤矸石发电 | I4: 合计 | J4: 常规燃气 | K4: 煤层气发电 | M4: 合计 | N4: 余温、余气、余压发电 | O4: 垃圾焚烧发电 | P4: 秸秆、蔗渣、林木质发电 | Q4: 沼气 | R4: 技改增容
A5: 全国 | X5: =B5-C5-E5-S5-T5-U5-V5 -> 0 | Y5: =E5-F5-I5-L5-M5 -> 0 | Z5: =M5-N5-O5-P5 -> 0
A6: 北京 | X6: =B6-C6-E6-S6-T6-U6-V6 -> 0 | Y6: =E6-F6-I6-L6-M6 -> 0 | Z6: =M6-N6-O6-P6 -> 0
A7: 天津 | X7: =B7-C7-E7-S7-T7-U7-V7 -> 0 | Y7: =E7-F7-I7-L7-M7 -> 0 | Z7: =M7-N7-O7-P7 -> 0
A8: 河北 | X8: =B8-C8-E8-S8-T8-U8-V8 -> 0 | Y8: =E8-F8-I8-L8-M8 -> 0 | Z8: =M8-N8-O8-P8 -> 0
A9: 山西 | X9: =B9-C9-E9-S9-T9-U9-V9 -> 0 | Y9: =E9-F9-I9-L9-M9 -> 0 | Z9: =M9-N9-O9-P9 -> 0
A10: 内蒙古 | X10: =B10-C10-E10-S10-T10-U10-V10 -> 0 | Y10: =E10-F10-I10-L10-M10 -> 0 | Z10: =M10-N10-O10-P10 -> 0
A11: 辽宁 | X11: =B11-C11-E11-S11-T11-U11-V11 -> 0 | Y11: =E11-F11-I11-L11-M11 -> 0 | Z11: =M11-N11-O11-P11 -> 0
A12: 吉林 | X12: =B12-C12-E12-S12-T12-U12-V12 -> 0 | Y12: =E12-F12-I12-L12-M12 -> 0 | Z12: =M12-N12-O12-P12 -> 0
A13: 黑龙江 | X13: =B13-C13-E13-S13-T13-U13-V13 -> 0 | Y13: =E13-F13-I13-L13-M13 -> 0 | Z13: =M13-N13-O13-P13 -> 0
A14: 上海 | X14: =B14-C14-E14-S14-T14-U14-V14 -> 0 | Y14: =E14-F14-I14-L14-M14 -> 0 | Z14: =M14-N14-O14-P14 -> 0
A15: 江苏 | X15: =B15-C15-E15-S15-T15-U15-V15 -> 0 | Y15: =E15-F15-I15-L15-M15 -> 0 | Z15: =M15-N15-O15-P15 -> 0
A16: 浙江 | X16: =B16-C16-E16-S16-T16-U16-V16 -> 0 | Y16: =E16-F16-I16-L16-M16 -> 0 | Z16: =M16-N16-O16-P16 -> 0
... A36: 新疆 | X36: =B36-C36-E36-S36-T36-U36-V36 -> 0 | Y36: =E36-F36-I36-L36-M36 -> 0 | Z36: =M36-N36-O36-P36 -> 0
B38: =B5-SUM(B6:B36) -> 0 | C38: =C5-SUM(C6:C36) -> 0 | D38: =D5-SUM(D6:D36) -> 0 | E38: =E5-SUM(E6:E36) -> 0 | F38: =F5-SUM(F6:F36) -> 0 | H38: =H5-SUM(H6:H36) -> 0 | I38: =I5-SUM(I6:I36) -> 0 | J38: =J5-SUM(J6:J36) -> 0 | K38: =K5-SUM(K6:K36) -> 0 | L38: =L5-SUM(L6:L36) -> 0 | M38: =M5-SUM(M6:M36) -> 0 | N38: =N5-SUM(N6:N36) -> 0 | O38: =O5-SUM(O6:O36) -> 0 | P38: =P5-SUM(P6:P36) -> 0 | S38: =S5-SUM(S6:S36) -> 0 | T38: =T5-SUM(T6:T36) -> 0 | U38: =U5-SUM(U6:U36) -> 0 | V38: =V5-SUM(V6:V36) -> 0

Sheet 2005
A1: 分地区新增发电装机容量（万KW）
A2: 地区 | B2: 合计 | C2: 水电 | E2: 火电 | S2: 核电 | T2: 风电 | U2: 太阳能发电 | V2: 其他
C3: 合计 | D3: 抽水蓄能 | E3: 合计 | F3: 燃煤 | I3: 燃气 | L3: 燃油 | M3: 其他
F4: 合计 | G4: 常规燃煤 | H4: 煤矸石发电 | I4: 合计 | J4: 常规燃气 | K4: 煤层气发电 | M4: 合计 | N4: 余温、余气、余压发电 | O4: 垃圾焚烧发电 | P4: 秸秆、蔗渣、林木质发电 | Q4: 沼气 | R4: 技改增容
A5: 全国 | X5: =B5-C5-E5-S5-T5-U5-V5 -> 0 | Y5: =E5-F5-I5-L5-M5 -> 0 | Z5: =M5-N5-O5-P5 -> 0
A6: 北京 | X6: =B6-C6-E6-S6-T6-U6-V6 -> 0 | Y6: =E6-F6-I6-L6-M6 -> 0 | Z6: =M6-N6-O6-P6 -> 0
A7: 天津 | X7: =B7-C7-E7-S7-T7-U7-V7 -> 0 | Y7: =E7-F7-I7-L7-M7 -> 0 | Z7: =M7-N7-O7-P7 -> 0
A8: 河北 | X8: =B8-C8-E8-S8-T8-U8-V8 -> 0 | Y8: =E8-F8-I8-L8-M8 -> 0 | Z8: =M8-N8-O8-P8 -> 0
A9: 山西 | X9: =B9-C9-E9-S9-T9-U9-V9 -> 0 | Y9: =E9-F9-I9-L9-M9 -> 0 | Z9: =M9-N9-O9-P9 -> 0
A10: 内蒙古 | X10: =B10-C10-E10-S10-T10-U10-V10 -> 0 | Y10: =E10-F10-I10-L10-M10 -> 0 | Z10: =M10-N10-O10-P10 -> 0
A11: 辽宁 | X11: =B11-C11-E11-S11-T11-U11-V11 -> 0 | Y11: =E11-F11-I11-L11-M11 -> 0 | Z11: =M11-N11-O11-P11 -> 0
A12: 吉林 | X12: =B12-C12-E12-S12-T12-U12-V12 -> 0 | Y12: =E12-F12-I12-L12-M12 -> 0 | Z12: =M12-N12-O12-P12 -> 0
A13: 黑龙江 | X13: =B13-C13-E13-S13-T13-U13-V13 -> 0 | Y13: =E13-F13-I13-L13-M13 -> 0 | Z13: =M13-N13-O13-P13 -> 0
A14: 上海 | X14: =B14-C14-E14-S14-T14-U14-V14 -> 0 | Y14: =E14-F14-I14-L14-M14 -> 0 | Z14: =M14-N14-O14-P14 -> 0
A15: 江苏 | X15: =B15-C15-E15-S15-T15-U15-V15 -> 0 | Y15: =E15-F15-I15-L15-M15 -> 0 | Z15: =M15-N15-O15-P15 -> 0
A16: 浙江 | X16: =B16-C16-E16-S16-T16-U16-V16 -> 0 | Y16: =E16-F16-I16-L16-M16 -> 0 | Z16: =M16-N16-O16-P16 -> 0
... A36: 新疆 | X36: =B36-C36-E36-S36-T36-U36-V36 -> 0 | Y36: =E36-F36-I36-L36-M36 -> 0 | Z36: =M36-N36-O36-P36 -> 0
B38: =B5-SUM(B6:B36) -> 0 | C38: =C5-SUM(C6:C36) -> 0 | D38: =D5-SUM(D6:D36) -> 0 | E38: =E5-SUM(E6:E36) -> 0 | F38: =F5-SUM(F6:F36) -> 0 | H38: =H5-SUM(H6:H36) -> 0 | I38: =I5-SUM(I6:I36) -> 0 | J38: =J5-SUM(J6:J36) -> 0 | K38: =K5-SUM(K6:K36) -> 0 | L38: =L5-SUM(L6:L36) -> 0 | M38: =M5-SUM(M6:M36) -> 0 | N38: =N5-SUM(N6:N36) -> 0 | O38: =O5-SUM(O6:O36) -> 0 | P38: =P5-SUM(P6:P36) -> 0 | S38: =S5-SUM(S6:S36) -> 0 | T38: =T5-SUM(T6:T36) -> 0 | U38: =U5-SUM(U6:U36) -> 0 | V38: =V5-SUM(V6:V36) -> 0

Sheet 2006
A1: 分地区新增发电装机容量（万KW）
A2: 地区 | B2: 合计 | C2: 水电 | E2: 火电 | S2: 核电 | T2: 风电 | U2: 太阳能发电 | V2: 其他
C3: 合计 | D3: 抽水蓄能 | E3: 合计 | F3: 燃煤 | I3: 燃气 | L3: 燃油 | M3: 其他
F4: 合计 | G4: 常规燃煤 | H4: 煤矸石发电 | I4: 合计 | J4: 常规燃气 | K4: 煤层气发电 | M4: 合计 | N4: 余温、余气、余压发电 | O4: 垃圾焚烧发电 | P4: 秸秆、蔗渣、林木质发电 | Q4: 沼气 | R4: 技改增容
A5: 全国 | B5: 10424 | C5: 1100 | E5: 9207 | T5: 110 | V5: 6 | X5: =B5-C5-E5-S5-T5-U5-V5 -> 1 | Y5: =E5-F5-I5-L5-M5 -> 9207 | Z5: =M5-N5-O5-P5 -> 0
A6: 北京 | X6: =B6-C6-E6-S6-T6-U6-V6 -> 0 | Y6: =E6-F6-I6-L6-M6 -> 0 | Z6: =M6-N6-O6-P6 -> 0
A7: 天津 | B7: 30 | E7: 30 | X7: =B7-C7-E7-S7-T7-U7-V7 -> 0 | Y7: =E7-F7-I7-L7-M7 -> 30 | Z7: =M7-N7-O7-P7 -> 0
A8: 河北 | B8: 386 | C8: 19 | E8: 352 | T8: 14 | V8: 1 | X8: =B8-C8-E8-S8-T8-U8-V8 -> 0 | Y8: =E8-F8-I8-L8-M8 -> 352 | Z8: =M8-N8-O8-P8 -> 0
A9: 山西 | B9: 386 | E9: 386 | X9: =B9-C9-E9-S9-T9-U9-V9 -> 0 | Y9: =E9-F9-I9-L9-M9 -> 386 | Z9: =M9-N9-O9-P9 -> 0
A10: 内蒙古 | B10: 1004 | E10: 971 | T10: 32 | X10: =B10-C10-E10-S10-T10-U10-V10 -> 1 | Y10: =E10-F10-I10-L10-M10 -> 971 | Z10: =M10-N10-O10-P10 -> 0
A11: 辽宁 | B11: 81 | E11: 70 | T11: 11 | X11: =B11-C11-E11-S11-T11-U11-V11 -> 0 | Y11: =E11-F11-I11-L11-M11 -> 70 | Z11: =M11-N11-O11-P11 -> 0
A12: 吉林 | B12: 93 | C12: 15 | E12: 69 | T12: 9 | X12: =B12-C12-E12-S12-T12-U12-V12 -> 0 | Y12: =E12-F12-I12-L12-M12 -> 69 | Z12: =M12-N12-O12-P12 -> 0
A13: 黑龙江 | B13: 114 | E13: 111 | T13: 4 | X13: =B13-C13-E13-S13-T13-U13-V13 -> -1 | Y13: =E13-F13-I13-L13-M13 -> 111 | Z13: =M13-N13-O13-P13 -> 0
A14: 上海 | B14: 138 | E14: 138 | X14: =B14-C14-E14-S14-T14-U14-V14 -> 0 | Y14: =E14-F14-I14-L14-M14 -> 138 | Z14: =M14-N14-O14-P14 -> 0
A15: 江苏 | B15: 868 | E15: 855 | T15: 8 | V15: 5 | X15: =B15-C15-E15-S15-T15-U15-V15 -> 0 | Y15: =E15-F15-I15-L15-M15 -> 855 | Z15: =M15-N15-O15-P15 -> 0
A16: 浙江 | B16: 1010 | C16: 120 | E16: 890 | X16: =B16-C16-E16-S16-T16-U16-V16 -> 0 | Y16: =E16-F16-I16-L16-M16 -> 890 | Z16: =M16-N16-O16-P16 -> 0
A17: 安徽 | B17: 264 | C17: 24 | E17: 240 | X17: =B17-C17-E17-S17-T17-U17-V17 -> 0 | Y17: =E17-F17-I17-L17-M17 -> 240 | Z17: =M17-N17-O17-P17 -> 0
A18: 福建 | B18: 410 | C18: 18 | E18: 383 | T18: 9 | X18: =B18-C18-E18-S18-T18-U18-V18 -> 0 | Y18: =E18-F18-I18-L18-M18 -> 383 | Z18: =M18-N18-O18-P18 -> 0
A19: 江西 | B19: 61 | C19: 5 | E19: 56 | X19: =B19-C19-E19-S19-T19-U19-V19 -> 0 | Y19: =E19-F19-I19-L19-M19 -> 56 | Z19: =M19-N19-O19-P19 -> 0
A20: 山东 | B20: 1207 | C20: 75 | E20: 1128 | T20: 3 | X20: =B20-C20-E20-S20-T20-U20-V20 -> 1 | Y20: =E20-F20-I20-L20-M20 -> 1128 | Z20: =M20-N20-O20-P20 -> 0
A21: 河南 | B21: 580 | E21: 580 | X21: =B21-C21-E21-S21-T21-U21-V21 -> 0 | Y21: =E21-F21-I21-L21-M21 -> 580 | Z21: =M21-N21-O21-P21 -> 0
A22: 湖北 | B22: 237 | C22: 39 | E22: 199 | X22: =B22-C22-E22-S22-T22-U22-V22 -> -1 | Y22: =E22-F22-I22-L22-M22 -> 199 | Z22: =M22-N22-O22-P22 -> 0
A23: 湖南 | B23: 343 | C23: 13 | E23: 330 | X23: =B23-C23-E23-S23-T23-U23-V23 -> 0 | Y23: =E23-F23-I23-L23-M23 -> 330 | Z23: =M23-N23-O23-P23 -> 0
A24: 广东 | B24: 646 | C24: 36 | E24: 604 | T24: 6 | X24: =B24-C24-E24-S24-T24-U24-V24 -> 0 | Y24: =E24-F24-I24-L24-M24 -> 604 | Z24: =M24-N24-O24-P24 -> 0
A25: 广西 | B25: 175 | C25: 145 | E25: 30 | X25: =B25-C25-E25-S25-T25-U25-V25 -> 0 | Y25: =E25-F25-I25-L25-M25 -> 30 | Z25: =M25-N25-O25-P25 -> 0
A26: 海南 | B26: 33 | E26: 33 | X26: =B26-C26-E26-S26-T26-U26-V26 -> 0 | Y26: =E26-F26-I26-L26-M26 -> 33 | Z26: =M26-N26-O26-P26 -> 0
A27: 重庆 | B27: 191 | C27: 2 | E27: 189 | X27: =B27-C27-E27-S27-T27-U27-V27 -> 0 | Y27: =E27-F27-I27-L27-M27 -> 189 | Z27: =M27-N27-O27-P27 -> 0
A28: 四川 | B28: 505 | C28: 262 | E28: 243 | X28: =B28-C28-E28-S28-T28-U28-V28 -> 0 | Y28: =E28-F28-I28-L28-M28 -> 243 | Z28: =M28-N28-O28-P28 -> 0
A29: 贵州 | B29: 594 | C29: 124 | E29: 470 | X29: =B29-C29-E29-S29-T29-U29-V29 -> 0 | Y29: =E29-F29-I29-L29-M29 -> 470 | Z29: =M29-N29-O29-P29 -> 0
A30: 云南 | B30: 433 | C30: 73 | E30: 360 | X30: =B30-C30-E30-S30-T30-U30-V30 -> 0 | Y30: =E30-F30-I30-L30-M30 -> 360 | Z30: =M30-N30-O30-P30 -> 0
A31: 西藏 | B31: 6 | C31: 6 | X31: =B31-C31-E31-S31-T31-U31-V31 -> 0 | Y31: =E31-F31-I31-L31-M31 -> 0 | Z31: =M31-N31-O31-P31 -> 0
A32: 陕西 | B32: 92 | C32: 18 | E32: 74 | X32: =B32-C32-E32-S32-T32-U32-V32 -> 0 | Y32: =E32-F32-I32-L32-M32 -> 74 | Z32: =M32-N32-O32-P32 -> 0
A33: 甘肃 | B33: 106 | C33: 14 | E33: 81 | T33: 11 | X33: =B33-C33-E33-S33-T33-U33-V33 -> 0 | Y33: =E33-F33-I33-L33-M33 -> 81 | Z33: =M33-N33-O33-P33 -> 0
A34: 青海 | B34: 113 | C34: 53 | E34: 60 | X34: =B34-C34-E34-S34-T34-U34-V34 -> 0 | Y34: =E34-F34-I34-L34-M34 -> 60 | Z34: =M34-N34-O34-P34 -> 0
A35: 宁夏 | B35: 189 | E35: 189 | X35: =B35-C35-E35-S35-T35-U35-V35 -> 0 | Y35: =E35-F35-I35-L35-M35 -> 189 | Z35: =M35-N35-O35-P35 -> 0
A36: 新疆 | B36: 132 | C36: 41 | E36: 89 | T36: 2 | X36: =B36-C36-E36-S36-T36-U36-V36 -> 0 | Y36: =E36-F36-I36-L36-M36 -> 89 | Z36: =M36-N36-O36-P36 -> 0
B38: =B5-SUM(B6:B36) -> -3 | C38: =C5-SUM(C6:C36) -> -2 | D38: =D5-SUM(D6:D36) -> 0 | E38: =E5-SUM(E6:E36) -> -3 | F38: =F5-SUM(F6:F36) -> 0 | H38: =H5-SUM(H6:H36) -> 0 | I38: =I5-SUM(I6:I36) -> 0 | J38: =J5-SUM(J6:J36) -> 0 | K38: =K5-SUM(K6:K36) -> 0 | L38: =L5-SUM(L6:L36) -> 0 | M38: =M5-SUM(M6:M36) -> 0 | N38: =N5-SUM(N6:N36) -> 0 | O38: =O5-SUM(O6:O36) -> 0 | P38: =P5-SUM(P6:P36) -> 0 | S38: =S5-SUM(S6:S36) -> 0 | T38: =T5-SUM(T6:T36) -> 1 | U38: =U5-SUM(U6:U36) -> 0 | V38: =V5-SUM(V6:V36) -> 0

Sheet 2007
A1: 分地区新增发电装机容量（万KW）
A2: 地区 | B2: 合计 | C2: 水电 | E2: 火电 | S2: 核电 | T2: 风电 | U2: 太阳能发电 | V2: 其他
C3: 合计 | D3: 抽水蓄能 | E3: 合计 | F3: 燃煤 | I3: 燃气 | L3: 燃油 | M3: 其他
F4: 合计 | G4: 常规燃煤 | H4: 煤矸石发电 | I4: 合计 | J4: 常规燃气 | K4: 煤层气发电 | M4: 合计 | N4: 余温、余气、余压发电 | O4: 垃圾焚烧发电 | P4: 秸秆、蔗渣、林木质发电 | Q4: 沼气 | R4: 技改增容
A5: 全国 | B5: 10190 | C5: 1307 | E5: 8360 | S5: 200 | T5: 303 | V5: 18 | X5: =B5-C5-E5-S5-T5-U5-V5 -> 2 | Y5: =E5-F5-I5-L5-M5 -> 8360 | Z5: =M5-N5-O5-P5 -> 0
A6: 北京 | X6: =B6-C6-E6-S6-T6-U6-V6 -> 0 | Y6: =E6-F6-I6-L6-M6 -> 0 | Z6: =M6-N6-O6-P6 -> 0
A7: 天津 | B7: 30 | E7: 30 | X7: =B7-C7-E7-S7-T7-U7-V7 -> 0 | Y7: =E7-F7-I7-L7-M7 -> 30 | Z7: =M7-N7-O7-P7 -> 0
A8: 河北 | B8: 395 | E8: 382 | T8: 8 | V8: 5 | X8: =B8-C8-E8-S8-T8-U8-V8 -> 0 | Y8: =E8-F8-I8-L8-M8 -> 382 | Z8: =M8-N8-O8-P8 -> 0
A9: 山西 | B9: 376 | E9: 376 | X9: =B9-C9-E9-S9-T9-U9-V9 -> 0 | Y9: =E9-F9-I9-L9-M9 -> 376 | Z9: =M9-N9-O9-P9 -> 0
A10: 内蒙古 | B10: 1055 | E10: 960 | T10: 95 | X10: =B10-C10-E10-S10-T10-U10-V10 -> 0 | Y10: =E10-F10-I10-L10-M10 -> 960 | Z10: =M10-N10-O10-P10 -> 0
A11: 辽宁 | B11: 386 | E11: 364 | T11: 22 | X11: =B11-C11-E11-S11-T11-U11-V11 -> 0 | Y11: =E11-F11-I11-L11-M11 -> 364 | Z11: =M11-N11-O11-P11 -> 0
A12: 吉林 | B12: 179 | C12: 1 | E12: 123 | T12: 55 | X12: =B12-C12-E12-S12-T12-U12-V12 -> 0 | Y12: =E12-F12-I12-L12-M12 -> 123 | Z12: =M12-N12-O12-P12 -> 0
A13: 黑龙江 | B13: 212 | C13: 1 | E13: 186 | T13: 24 | V13: 2 | X13: =B13-C13-E13-S13-T13-U13-V13 -> -1 | Y13: =E13-F13-I13-L13-M13 -> 186 | Z13: =M13-N13-O13-P13 -> 0
A14: 上海 | B14: 2 | E14: 2 | X14: =B14-C14-E14-S14-T14-U14-V14 -> 0 | Y14: =E14-F14-I14-L14-M14 -> 2 | Z14: =M14-N14-O14-P14 -> 0
A15: 江苏 | B15: 551 | E15: 323 | S15: 200 | T15: 21 | V15: 7 | X15: =B15-C15-E15-S15-T15-U15-V15 -> 0 | Y15: =E15-F15-I15-L15-M15 -> 323 | Z15: =M15-N15-O15-P15 -> 0
A16: 浙江 | B16: 297 | E16: 296 | X16: =B16-C16-E16-S16-T16-U16-V16 -> 1 | Y16: =E16-F16-I16-L16-M16 -> 296 | Z16: =M16-N16-O16-P16 -> 0
A17: 安徽 | B17: 618 | C17: 45 | E17: 573 | X17: =B17-C17-E17-S17-T17-U17-V17 -> 0 | Y17: =E17-F17-I17-L17-M17 -> 573 | Z17: =M17-N17-O17-P17 -> 0
A18: 福建 | B18: 162 | C18: 22 | E18: 125 | T18: 15 | X18: =B18-C18-E18-S18-T18-U18-V18 -> 0 | Y18: =E18-F18-I18-L18-M18 -> 125 | Z18: =M18-N18-O18-P18 -> 0
A19: 江西 | B19: 252 | E19: 252 | X19: =B19-C19-E19-S19-T19-U19-V19 -> 0 | Y19: =E19-F19-I19-L19-M19 -> 252 | Z19: =M19-N19-O19-P19 -> 0
A20: 山东 | B20: 586 | C20: 25 | E20: 542 | T20: 14 | V20: 5 | X20: =B20-C20-E20-S20-T20-U20-V20 -> 0 | Y20: =E20-F20-I20-L20-M20 -> 542 | Z20: =M20-N20-O20-P20 -> 0
A21: 河南 | B21: 931 | C21: 4 | E21: 925 | T21: 3 | X21: =B21-C21-E21-S21-T21-U21-V21 -> -1 | Y21: =E21-F21-I21-L21-M21 -> 925 | Z21: =M21-N21-O21-P21 -> 0
A22: 湖北 | B22: 741 | C22: 554 | E22: 186 | T22: 1 | X22: =B22-C22-E22-S22-T22-U22-V22 -> 0 | Y22: =E22-F22-I22-L22-M22 -> 186 | Z22: =M22-N22-O22-P22 -> 0
A23: 湖南 | B23: 345 | C23: 28 | E23: 317 | X23: =B23-C23-E23-S23-T23-U23-V23 -> 0 | Y23: =E23-F23-I23-L23-M23 -> 317 | Z23: =M23-N23-O23-P23 -> 0
A24: 广东 | B24: 705 | E24: 697 | T24: 8 | X24: =B24-C24-E24-S24-T24-U24-V24 -> 0 | Y24: =E24-F24-I24-L24-M24 -> 697 | Z24: =M24-N24-O24-P24 -> 0
A25: 广西 | B25: 566 | C25: 260 | E25: 300 | X25: =B25-C25-E25-S25-T25-U25-V25 -> 6 | Y25: =E25-F25-I25-L25-M25 -> 300 | Z25: =M25-N25-O25-P25 -> 0
A26: 海南 | B26: 35 | C26: 2 | E26: 33 | X26: =B26-C26-E26-S26-T26-U26-V26 -> 0 | Y26: =E26-F26-I26-L26-M26 -> 33 | Z26: =M26-N26-O26-P26 -> 0
A27: 重庆 | B27: 90 | E27: 90 | X27: =B27-C27-E27-S27-T27-U27-V27 -> 0 | Y27: =E27-F27-I27-L27-M27 -> 90 | Z27: =M27-N27-O27-P27 -> 0
A28: 四川 | B28: 443 | C28: 139 | E28: 304 | X28: =B28-C28-E28-S28-T28-U28-V28 -> 0 | Y28: =E28-F28-I28-L28-M28 -> 304 | Z28: =M28-N28-O28-P28 -> 0
A29: 贵州 | B29: 221 | C29: 41 | E29: 180 | X29: =B29-C29-E29-S29-T29-U29-V29 -> 0 | Y29: =E29-F29-I29-L29-M29 -> 180 | Z29: =M29-N29-O29-P29 -> 0
A30: 云南 | B30: 335 | C30: 125 | E30: 210 | X30: =B30-C30-E30-S30-T30-U30-V30 -> 0 | Y30: =E30-F30-I30-L30-M30 -> 210 | Z30: =M30-N30-O30-P30 -> 0
A31: 西藏 | B31: 6 | C31: 6 | X31: =B31-C31-E31-S31-T31-U31-V31 -> 0 | Y31: =E31-F31-I31-L31-M31 -> 0 | Z31: =M31-N31-O31-P31 -> 0
A32: 陕西 | B32: 273 | E32: 273 | X32: =B32-C32-E32-S32-T32-U32-V32 -> 0 | Y32: =E32-F32-I32-L32-M32 -> 273 | Z32: =M32-N32-O32-P32 -> 0
A33: 甘肃 | B33: 157 | C33: 20 | E33: 123 | T33: 15 | X33: =B33-C33-E33-S33-T33-U33-V33 -> -1 | Y33: =E33-F33-I33-L33-M33 -> 123 | Z33: =M33-N33-O33-P33 -> 0
A34: 青海 | B34: 63 | C34: 26 | E34: 38 | X34: =B34-C34-E34-S34-T34-U34-V34 -> -1 | Y34: =E34-F34-I34-L34-M34 -> 38 | Z34: =M34-N34-O34-P34 -> 0
A35: 宁夏 | B35: 135 | E35: 120 | T35: 15 | X35: =B35-C35-E35-S35-T35-U35-V35 -> 0 | Y35: =E35-F35-I35-L35-M35 -> 120 | Z35: =M35-N35-O35-P35 -> 0
A36: 新疆 | B36: 49 | C36: 10 | E36: 30 | T36: 9 | X36: =B36-C36-E36-S36-T36-U36-V36 -> 0 | Y36: =E36-F36-I36-L36-M36 -> 30 | Z36: =M36-N36-O36-P36 -> 0
B38: =B5-SUM(B6:B36) -> -6 | C38: =C5-SUM(C6:C36) -> -2 | D38: =D5-SUM(D6:D36) -> 0 | E38: =E5-SUM(E6:E36) -> 0 | F38: =F5-SUM(F6:F36) -> 0 | H38: =H5-SUM(H6:H36) -> 0 | I38: =I5-SUM(I6:I36) -> 0 | J38: =J5-SUM(J6:J36) -> 0 | K38: =K5-SUM(K6:K36) -> 0 | L38: =L5-SUM(L6:L36) -> 0 | M38: =M5-SUM(M6:M36) -> 0 | N38: =N5-SUM(N6:N36) -> 0 | O38: =O5-SUM(O6:O36) -> 0 | P38: =P5-SUM(P6:P36) -> 0 | S38: =S5-SUM(S6:S36) -> 0 | T38: =T5-SUM(T6:T36) -> -2 | U38: =U5-SUM(U6:U36) -> 0 | V38: =V5-SUM(V6:V36) -> -1

Sheet 2008
A1: 分地区新增发电装机容量（万KW）
A2: 地区 | B2: 合计 | C2: 水电 | E2: 火电 | S2: 核电 | T2: 风电 | U2: 太阳能发电 | V2: 其他
C3: 合计 | D3: 抽水蓄能 | E3: 合计 | F3: 燃煤 | I3: 燃气 | L3: 燃油 | M3: 其他
F4: 合计 | G4: 常规燃煤 | H4: 煤矸石发电 | I4: 合计 | J4: 常规燃气 | K4: 煤层气发电 | M4: 合计 | N4: 余温、余气、余压发电 | O4: 垃圾焚烧发电 | P4: 秸秆、蔗渣、林木质发电 | Q4: 沼气 | R4: 技改增容
A5: 全国 | B5: 9202 | C5: 2148 | D5: 175 | E5: 6555 | F5: 6040 | I5: 321 | L5: 8 | M5: 185 | T5: 499 | X5: =B5-C5-E5-S5-T5-U5-V5 -> 0 | Y5: =E5-F5-I5-L5-M5 -> 1 | Z5: =M5-N5-O5-P5 -> 185
A6: 北京 | B6: 145 | E6: 145 | F6: 16 | I6: 129 | X6: =B6-C6-E6-S6-T6-U6-V6 -> 0 | Y6: =E6-F6-I6-L6-M6 -> 0 | Z6: =M6-N6-O6-P6 -> 0
A7: 天津 | B7: 60 | E7: 60 | F7: 60 | X7: =B7-C7-E7-S7-T7-U7-V7 -> 0 | Y7: =E7-F7-I7-L7-M7 -> 0 | Z7: =M7-N7-O7-P7 -> 0
A8: 河北 | B8: 365 | C8: 75 | D8: 75 | E8: 261 | F8: 257 | I8: 2 | M8: 2 | T8: 30 | X8: =B8-C8-E8-S8-T8-U8-V8 -> -1 | Y8: =E8-F8-I8-L8-M8 -> 0 | Z8: =M8-N8-O8-P8 -> 2
A9: 山西 | B9: 459 | E9: 450 | F9: 418 | M9: 32 | T9: 10 | X9: =B9-C9-E9-S9-T9-U9-V9 -> -1 | Y9: =E9-F9-I9-L9-M9 -> 0 | Z9: =M9-N9-O9-P9 -> 32
A10: 内蒙古 | B10: 773 | E10: 611 | F10: 515 | M10: 96 | T10: 162 | X10: =B10-C10-E10-S10-T10-U10-V10 -> 0 | Y10: =E10-F10-I10-L10-M10 -> 0 | Z10: =M10-N10-O10-P10 -> 96
A11: 辽宁 | B11: 290 | E11: 240 | F11: 240 | T11: 50 | X11: =B11-C11-E11-S11-T11-U11-V11 -> 0 | Y11: =E11-F11-I11-L11-M11 -> 0 | Z11: =M11-N11-O11-P11 -> 0
A12: 吉林 | B12: 112 | E12: 70 | F12: 69 | M12: 1 | T12: 42 | X12: =B12-C12-E12-S12-T12-U12-V12 -> 0 | Y12: =E12-F12-I12-L12-M12 -> 0 | Z12: =M12-N12-O12-P12 -> 1
A13: 黑龙江 | B13: 219 | C13: 1 | E13: 189 | F13: 184 | M13: 6 | T13: 29 | X13: =B13-C13-E13-S13-T13-U13-V13 -> 0 | Y13: =E13-F13-I13-L13-M13 -> -1 | Z13: =M13-N13-O13-P13 -> 6
A14: 上海 | B14: 267 | E14: 266 | F14: 266 | T14: 1 | X14: =B14-C14-E14-S14-T14-U14-V14 -> 0 | Y14: =E14-F14-I14-L14-M14 -> 0 | Z14: =M14-N14-O14-P14 -> 0
A15: 江苏 | B15: 343 | C15: 100 | D15: 100 | E15: 192 | F15: 179 | M15: 13 | T15: 50 | X15: =B15-C15-E15-S15-T15-U15-V15 -> 1 | Y15: =E15-F15-I15-L15-M15 -> 0 | Z15: =M15-N15-O15-P15 -> 13
A16: 浙江 | B16: 417 | C16: 55 | E16: 347 | F16: 269 | I16: 78 | T16: 14 | X16: =B16-C16-E16-S16-T16-U16-V16 -> 1 | Y16: =E16-F16-I16-L16-M16 -> 0 | Z16: =M16-N16-O16-P16 -> 0
A17: 安徽 | B17: 750 | E17: 750 | F17: 744 | M17: 6 | X17: =B17-C17-E17-S17-T17-U17-V17 -> 0 | Y17: =E17-F17-I17-L17-M17 -> 0 | Z17: =M17-N17-O17-P17 -> 6
A18: 福建 | B18: 372 | C18: 41 | E18: 316 | F18: 246 | I18: 70 | T18: 15 | X18: =B18-C18-E18-S18-T18-U18-V18 -> 0 | Y18: =E18-F18-I18-L18-M18 -> 0 | Z18: =M18-N18-O18-P18 -> 0
A19: 江西 | B19: 73 | E19: 70 | F19: 70 | T19: 3 | X19: =B19-C19-E19-S19-T19-U19-V19 -> 0 | Y19: =E19-F19-I19-L19-M19 -> 0 | Z19: =M19-N19-O19-P19 -> 0
A20: 山东 | B20: 326 | E20: 309 | F20: 307 | M20: 2 | T20: 17 | X20: =B20-C20-E20-S20-T20-U20-V20 -> 0 | Y20: =E20-F20-I20-L20-M20 -> 0 | Z20: =M20-N20-O20-P20 -> 2
A21: 河南 | B21: 460 | C21: 4 | E21: 457 | F21: 418 | I21: 39 | X21: =B21-C21-E21-S21-T21-U21-V21 -> -1 | Y21: =E21-F21-I21-L21-M21 -> 0 | Z21: =M21-N21-O21-P21 -> 0
A22: 湖北 | B22: 608 | C22: 488 | E22: 120 | F22: 120 | X22: =B22-C22-E22-S22-T22-U22-V22 -> 0 | Y22: =E22-F22-I22-L22-M22 -> 0 | Z22: =M22-N22-O22-P22 -> 0
A23: 湖南 | B23: 241 | C23: 115 | E23: 126 | F23: 126 | X23: =B23-C23-E23-S23-T23-U23-V23 -> 0 | Y23: =E23-F23-I23-L23-M23 -> 0 | Z23: =M23-N23-O23-P23 -> 0
A24: 广东 | B24: 300 | E24: 300 | F24: 300 | X24: =B24-C24-E24-S24-T24-U24-V24 -> 0 | Y24: =E24-F24-I24-L24-M24 -> 0 | Z24: =M24-N24-O24-P24 -> 0
A25: 广西 | B25: 403 | C25: 342 | E25: 62 | F25: 60 | M25: 2 | X25: =B25-C25-E25-S25-T25-U25-V25 -> -1 | Y25: =E25-F25-I25-L25-M25 -> 0 | Z25: =M25-N25-O25-P25 -> 2
A26: 海南 | B26: 17 | C26: 0 | E26: 12 | L26: 2 | M26: 10 | T26: 5 | X26: =B26-C26-E26-S26-T26-U26-V26 -> 0 | Y26: =E26-F26-I26-L26-M26 -> 0 | Z26: =M26-N26-O26-P26 -> 10
A27: 重庆 | B27: 218 | C27: 185 | E27: 33 | F27: 33 | X27: =B27-C27-E27-S27-T27-U27-V27 -> 0 | Y27: =E27-F27-I27-L27-M27 -> 0 | Z27: =M27-N27-O27-P27 -> 0
A28: 四川 | B28: 292 | C28: 200 | E28: 92 | F28: 92 | X28: =B28-C28-E28-S28-T28-U28-V28 -> 0 | Y28: =E28-F28-I28-L28-M28 -> 0 | Z28: =M28-N28-O28-P28 -> 0
A29: 贵州 | B29: 306 | C29: 126 | E29: 180 | F29: 180 | X29: =B29-C29-E29-S29-T29-U29-V29 -> 0 | Y29: =E29-F29-I29-L29-M29 -> 0 | Z29: =M29-N29-O29-P29 -> 0
A30: 云南 | B30: 316 | C30: 306 | E30: 3 | M30: 3 | T30: 8 | X30: =B30-C30-E30-S30-T30-U30-V30 -> -1 | Y30: =E30-F30-I30-L30-M30 -> 0 | Z30: =M30-N30-O30-P30 -> 3
A31: 西藏 | B31: 11 | C31: 3 | E31: 8 | L31: 7 | M31: 2 | X31: =B31-C31-E31-S31-T31-U31-V31 -> 0 | Y31: =E31-F31-I31-L31-M31 -> -1 | Z31: =M31-N31-O31-P31 -> 2
A32: 陕西 | B32: 535 | E32: 535 | F32: 522 | I32: 3 | M32: 10 | X32: =B32-C32-E32-S32-T32-U32-V32 -> 0 | Y32: =E32-F32-I32-L32-M32 -> 0 | Z32: =M32-N32-O32-P32 -> 10
A33: 甘肃 | B33: 231 | C33: 77 | E33: 120 | F33: 120 | T33: 34 | X33: =B33-C33-E33-S33-T33-U33-V33 -> 0 | Y33: =E33-F33-I33-L33-M33 -> 0 | Z33: =M33-N33-O33-P33 -> 0
A34: 青海 | B34: 22 | C34: 9 | E34: 14 | F34: 14 | X34: =B34-C34-E34-S34-T34-U34-V34 -> -1 | Y34: =E34-F34-I34-L34-M34 -> 0 | Z34: =M34-N34-O34-P34 -> 0
A35: 宁夏 | B35: 57 | E35: 43 | F35: 43 | I35: 0 | T35: 13 | X35: =B35-C35-E35-S35-T35-U35-V35 -> 1 | Y35: =E35-F35-I35-L35-M35 -> 0 | Z35: =M35-N35-O35-P35 -> 0
A36: 新疆 | B36: 214 | C36: 23 | E36: 175 | F36: 174 | M36: 1 | T36: 17 | X36: =B36-C36-E36-S36-T36-U36-V36 -> -1 | Y36: =E36-F36-I36-L36-M36 -> 0 | Z36: =M36-N36-O36-P36 -> 1
B38: =B5-SUM(B6:B36) -> 0 | C38: =C5-SUM(C6:C36) -> -2 | D38: =D5-SUM(D6:D36) -> 0 | E38: =E5-SUM(E6:E36) -> -1 | F38: =F5-SUM(F6:F36) -> -2 | H38: =H5-SUM(H6:H36) -> 0 | I38: =I5-SUM(I6:I36) -> 0 | J38: =J5-SUM(J6:J36) -> 0 | K38: =K5-SUM(K6:K36) -> 0 | L38: =L5-SUM(L6:L36) -> -1 | M38: =M5-SUM(M6:M36) -> -1 | N38: =N5-SUM(N6:N36) -> 0 | O38: =O5-SUM(O6:O36) -> 0 | P38: =P5-SUM(P6:P36) -> 0 | S38: =S5-SUM(S6:S36) -> 0 | T38: =T5-SUM(T6:T36) -> -1 | U38: =U5-SUM(U6:U36) -> 0 | V38: =V5-SUM(V6:V36) -> 0

Sheet 2009
A1: 分地区新增发电装机容量（万KW）
A2: 地区 | B2: 合计 | C2: 水电 | E2: 火电 | S2: 核电 | T2: 风电 | U2: 太阳能发电 | V2: 其他
C3: 合计 | D3: 抽水蓄能 | E3: 合计 | F3: 燃煤 | I3: 燃气 | L3: 燃油 | M3: 其他
F4: 合计 | G4: 常规燃煤 | H4: 煤矸石发电 | I4: 合计 | J4: 常规燃气 | K4: 煤层气发电 | M4: 合计 | N4: 余温、余气、余压发电 | O4: 垃圾焚烧发电 | P4: 秸秆、蔗渣、林木质发电 | Q4: 沼气 | R4: 技改增容
A5: 全国 | B5: 9667.35 | C5: 2105.7 | D5: 385 | E5: 6585.76 | F5: =H5+G5 -> 6341.71 | G5: 6186.71 | H5: 155 | I5: 127.34 | L5: 0.17 | M5: =SUM(N5:R5) -> 116.54 | N5: 68.25 | O5: 11.34 | P5: 23.2 | Q5: 0.05 | R5: 13.7 | T5: 973 | U5: 2.79 | X5: =B5-C5-E5-S5-T5-U5-V5 -> 0.1 | Y5: =E5-F5-I5-L5-M5 -> 1.7053026e-13 | Z5: =M5-SUM(N5:R5) -> 0
A6: 北京 | F6: =H6+G6 -> 0 | M6: =SUM(N6:R6) -> 0 | X6: =B6-C6-E6-S6-T6-U6-V6 -> 0 | Y6: =E6-F6-I6-L6-M6 -> 0 | Z6: =M6-SUM(N6:R6) -> 0
A7: 天津 | B7: 266 | E7: 266 | F7: =H7+G7 -> 266 | G7: 266 | M7: =SUM(N7:R7) -> 0 | X7: =B7-C7-E7-S7-T7-U7-V7 -> 0 | Y7: =E7-F7-I7-L7-M7 -> 0 | Z7: =M7-SUM(N7:R7) -> 0
A8: 河北 | B8: 699.78 | C8: 25 | D8: 25 | E8: 579.6 | F8: =H8+G8 -> 579 | G8: 552 | H8: 27 | M8: =SUM(N8:R8) -> 0.6 | O8: 0.6 | T8: 95.18 | X8: =B8-C8-E8-S8-T8-U8-V8 -> -5.6843419e-14 | Y8: =E8-F8-I8-L8-M8 -> 2.2759572e-14 | Z8: =M8-SUM(N8:R8) -> 0
A9: 山西 | B9: 519.5 | C9: 80 | D9: 60 | E9: 432 | F9: =H9+G9 -> 432 | G9: 372 | H9: 60 | M9: =SUM(N9:R9) -> 0 | T9: 7.5 | X9: =B9-C9-E9-S9-T9-U9-V9 -> 0 | Y9: =E9-F9-I9-L9-M9 -> 0 | Z9: =M9-SUM(N9:R9) -> 0
A10: 内蒙古 | B10: 667.57 | E10: 291.46 | F10: =H10+G10 -> 290.26 | G10: 258.26 | H10: 32 | M10: =SUM(N10:R10) -> 1.2 | P10: 1.2 | T10: 376.11 | X10: =B10-C10-E10-S10-T10-U10-V10 -> 5.6843419e-14 | Y10: =E10-F10-I10-L10-M10 -> -1.1324275e-14 | Z10: =M10-SUM(N10:R10) -> 0
A11: 辽宁 | B11: 394.19 | C11: 1.31 | E11: 271.7 | F11: =H11+G11 -> 242.5 | G11: 212.5 | H11: 30 | M11: =SUM(N11:R11) -> 29.2 | N11: 29.2 | T11: 121.18 | X11: =B11-C11-E11-S11-T11-U11-V11 -> 0 | Y11: =E11-F11-I11-L11-M11 -> 0 | Z11: =M11-SUM(N11:R11) -> 0
A12: 吉林 | B12: 410.73 | C12: 0.3 | E12: 346.7 | F12: =H12+G12 -> 338 | G12: 338 | M12: =SUM(N12:R12) -> 8.7 | O12: 4.2 | P12: 3 | R12: 1.5 | T12: 63.73 | X12: =B12-C12-E12-S12-T12-U12-V12 -> 2.1316282e-14 | Y12: =E12-F12-I12-L12-M12 -> 0 | Z12: =M12-SUM(N12:R12) -> 0
A13: 黑龙江 | B13: 134.14 | C13: 0.24 | E13: 63.24 | F13: =H13+G13 -> 62.85 | G13: 62.85 | M13: =SUM(N13:R13) -> 0.39 | O13: 0.09 | P13: 0.3 | T13: 70.66 | X13: =B13-C13-E13-S13-T13-U13-V13 -> -2.8421709e-14 | Y13: =E13-F13-I13-L13-M13 -> 5.5511151e-16 | Z13: =M13-SUM(N13:R13) -> 0
A14: 上海 | B14: 142.24 | E14: 141.2 | F14: =H14+G14 -> 132 | G14: 132 | M14: =SUM(N14:R14) -> 9.2 | R14: 9.2 | T14: 0.9 | U14: 0.14 | X14: =B14-C14-E14-S14-T14-U14-V14 -> 2.0428104e-14 | Y14: =E14-F14-I14-L14-M14 -> 0 | Z14: =M14-SUM(N14:R14) -> 0
A15: 江苏 | B15: 296.15 | E15: 264.75 | F15: =H15+G15 -> 224.3 | G15: 224.3 | M15: =SUM(N15:R15) -> 40.45 | N15: 26 | O15: 4.55 | P15: 6.9 | R15: 3 | T15: 31.15 | U15: 0.25 | X15: =B15-C15-E15-S15-T15-U15-V15 -> -2.1316282e-14 | Y15: =E15-F15-I15-L15-M15 -> 0 | Z15: =M15-SUM(N15:R15) -> 0
A16: 浙江 | B16: 342.44 | C16: 40 | E16: 300 | F16: =H16+G16 -> 300 | G16: 300 | M16: =SUM(N16:R16) -> 0 | T16: 2.44 | X16: =B16-C16-E16-S16-T16-U16-V16 -> -2.220446e-15 | Y16: =E16-F16-I16-L16-M16 -> 0 | Z16: =M16-SUM(N16:R16) -> 0
A17: 安徽 | B17: 230.9 | C17: 7.8 | E17: 223.1 | F17: =H17+G17 -> 214.5 | G17: 214.5 | M17: =SUM(N17:R17) -> 8.6 | N17: 3.7 | P17: 4.9 | X17: =B17-C17-E17-S17-T17-U17-V17 -> 0 | Y17: =E17-F17-I17-L17-M17 -> 0 | Z17: =M17-SUM(N17:R17) -> 0
A18: 福建 | B18: 272.95 | E18: 266 | F18: =H18+G18 -> 161 | G18: 161 | I18: 105 | M18: =SUM(N18:R18) -> 0 | T18: 6.95 | X18: =B18-C18-E18-S18-T18-U18-V18 -> -1.1546319e-14 | Y18: =E18-F18-I18-L18-M18 -> 0 | Z18: =M18-SUM(N18:R18) -> 0
A19: 江西 | B19: 236.4 | E19: 231 | F19: =H19+G19 -> 231 | G19: 231 | M19: =SUM(N19:R19) -> 0 | T19: 5.4 | X19: =B19-C19-E19-S19-T19-U19-V19 -> 5.3290705e-15 | Y19: =E19-F19-I19-L19-M19 -> 0 | Z19: =M19-SUM(N19:R19) -> 0
A20: 山东 | B20: 504.49 | E20: 447.4 | F20: =H20+G20 -> 442.3 | G20: 442.3 | M20: =SUM(N20:R20) -> 5.1 | O20: 1.8 | P20: 3.3 | T20: 57.09 | X20: =B20-C20-E20-S20-T20-U20-V20 -> 2.8421709e-14 | Y20: =E20-F20-I20-L20-M20 -> -3.375078e-14 | Z20: =M20-SUM(N20:R20) -> 0
A21: 河南 | B21: 493.33 | C21: 90 | D21: 90 | E21: 401 | F21: =H21+G21 -> 401 | G21: 401 | M21: =SUM(N21:R21) -> 5.25 | N21: 1.65 | P21: 3.6 | T21: 2.33 | X21: =B21-C21-E21-S21-T21-U21-V21 -> -1.5987212e-14 | Y21: =E21-F21-I21-L21-M21 -> -5.25 | Z21: =M21-SUM(N21:R21) -> 0
A22: 湖北 | B22: 242.04 | C22: 83.19 | D22: 60 | E22: 158.4 | F22: =H22+G22 -> 153.15 | G22: 153.15 | M22: =SUM(N22:R22) -> 0 | T22: 0.45 | X22: =B22-C22-E22-S22-T22-U22-V22 -> -1.1379786e-14 | Y22: =E22-F22-I22-L22-M22 -> 5.25 | Z22: =M22-SUM(N22:R22) -> 0
A23: 湖南 | B23: 232.25 | C23: 90.7 | D23: 60 | E23: 141.55 | F23: =H23+G23 -> 139.25 | G23: 133.25 | H23: 6 | M23: =SUM(N23:R23) -> 2.3 | N23: 2.2 | O23: 0.1 | X23: =B23-C23-E23-S23-T23-U23-V23 -> 0 | Y23: =E23-F23-I23-L23-M23 -> 1.110223e-14 | Z23: =M23-SUM(N23:R23) -> 0
A24: 广东 | B24: 823.45 | C24: 90 | D24: 90 | E24: 716.8 | F24: =H24+G24 -> 701.2 | G24: 701.2 | I24: 15.6 | M24: =SUM(N24:R24) -> 0 | T24: 16.65 | X24: =B24-C24-E24-S24-T24-U24-V24 -> 9.2370556e-14 | Y24: =E24-F24-I24-L24-M24 -> -9.0594199e-14 | Z24: =M24-SUM(N24:R24) -> 0
A25: 广西 | B25: 73.32 | C25: 72.42 | E25: 0.9 | F25: =H25+G25 -> 0.9 | G25: 0.9 | M25: =SUM(N25:R25) -> 0 | X25: =B25-C25-E25-S25-T25-U25-V25 -> -8.5487173e-15 | Y25: =E25-F25-I25-L25-M25 -> 0 | Z25: =M25-SUM(N25:R25) -> 0
A26: 海南 | B26: 87.32 | C26: 8.2 | E26: 71.37 | F26: =H26+G26 -> 70 | G26: 70 | L26: 0.17 | M26: =SUM(N26:R26) -> 1.2 | N26: 1.2 | T26: 7.75 | X26: =B26-C26-E26-S26-T26-U26-V26 -> -1.4210855e-14 | Y26: =E26-F26-I26-L26-M26 -> 4.6629367e-15 | Z26: =M26-SUM(N26:R26) -> 0
A27: 重庆 | B27: 31.53 | C27: 26.6 | M27: =SUM(N27:R27) -> 0 | T27: 4.93 | X27: =B27-C27-E27-S27-T27-U27-V27 -> 0 | Y27: =E27-F27-I27-L27-M27 -> 0 | Z27: =M27-SUM(N27:R27) -> 0
A28: 四川 | B28: 400 | C28: 398.7 | E28: 1.3 | M28: =SUM(N28:R28) -> 1.3 | N28: 1.3 | X28: =B28-C28-E28-S28-T28-U28-V28 -> 1.1324275e-14 | Y28: =E28-F28-I28-L28-M28 -> 0 | Z28: =M28-SUM(N28:R28) -> 0
A29: 贵州 | B29: 466.05 | C29: 316.05 | E29: 150 | F29: =H29+G29 -> 150 | G29: 150 | M29: =SUM(N29:R29) -> 0 | X29: =B29-C29-E29-S29-T29-U29-V29 -> 0 | Y29: =E29-F29-I29-L29-M29 -> 0 | Z29: =M29-SUM(N29:R29) -> 0
A30: 云南 | B30: 495.53 | C30: 430.33 | E30: 60.05 | F30: =H30+G30 -> 60 | G30: 60 | M30: =SUM(N30:R30) -> 0.05 | Q30: 0.05 | T30: 4.95 | U30: 0.2 | X30: =B30-C30-E30-S30-T30-U30-V30 -> -8.7152507e-15 | Y30: =E30-F30-I30-L30-M30 -> -2.8449465e-15 | Z30: =M30-SUM(N30:R30) -> 0
A31: 西藏 | B31: 0.1 | M31: =SUM(N31:R31) -> 0 | X31: =B31-C31-E31-S31-T31-U31-V31 -> 0.1 | Y31: =E31-F31-I31-L31-M31 -> 0 | Z31: =M31-SUM(N31:R31) -> 0
A32: 陕西 | B32: 257.9 | C32: 5.9 | E32: 252 | F32: =H32+G32 -> 252 | G32: 252 | M32: =SUM(N32:R32) -> 0 | X32: =B32-C32-E32-S32-T32-U32-V32 -> -2.8421709e-14 | Y32: =E32-F32-I32-L32-M32 -> 0 | Z32: =M32-SUM(N32:R32) -> 0
A33: 甘肃 | B33: 348.27 | C33: 45.27 | E33: 258 | F33: =H33+G33 -> 258 | G33: 258 | M33: =SUM(N33:R33) -> 0 | T33: 45 | X33: =B33-C33-E33-S33-T33-U33-V33 -> 0 | Y33: =E33-F33-I33-L33-M33 -> 0 | Z33: =M33-SUM(N33:R33) -> 0
A34: 青海 | B34: 282.42 | C34: 282.42 | M34: =SUM(N34:R34) -> 0 | X34: =B34-C34-E34-S34-T34-U34-V34 -> 0 | Y34: =E34-F34-I34-L34-M34 -> 0 | Z34: =M34-SUM(N34:R34) -> 0
A35: 宁夏 | B35: 144.05 | E35: 126.4 | F35: =H35+G35 -> 120 | G35: 120 | I35: 6.4 | M35: =SUM(N35:R35) -> 0 | T35: 15.45 | U35: 2.2 | X35: =B35-C35-E35-S35-T35-U35-V35 -> 6.2172489e-15 | Y35: =E35-F35-I35-L35-M35 -> 5.3290705e-15 | Z35: =M35-SUM(N35:R35) -> 0
A36: 新疆 | B36: 172.31 | C36: 11.27 | E36: 123.84 | F36: =H36+G36 -> 120.5 | G36: 120.5 | I36: 0.34 | M36: =SUM(N36:R36) -> 3 | N36: 3 | T36: 37.2 | X36: =B36-C36-E36-S36-T36-U36-V36 -> -1.4210855e-14 | Y36: =E36-F36-I36-L36-M36 -> 3.5527137e-15 | Z36: =M36-SUM(N36:R36) -> 0
B38: =B5-SUM(B6:B36) -> 0 | C38: =C5-SUM(C6:C36) -> 0 | D38: =D5-SUM(D6:D36) -> 0 | E38: =E5-SUM(E6:E36) -> 0 | F38: =F5-SUM(F6:F36) -> 0 | H38: =H5-SUM(H6:H36) -> 0 | I38: =I5-SUM(I6:I36) -> 0 | J38: =J5-SUM(J6:J36) -> 0 | K38: =K5-SUM(K6:K36) -> 0 | L38: =L5-SUM(L6:L36) -> 0 | M38: =M5-SUM(M6:M36) -> 0 | N38: =N5-SUM(N6:N36) -> 0 | O38: =O5-SUM(O6:O36) -> 0 | P38: =P5-SUM(P6:P36) -> 0 | S38: =S5-SUM(S6:S36) -> 0 | T38: =T5-SUM(T6:T36) -> 0 | U38: =U5-SUM(U6:U36) -> 0 | V38: =V5-SUM(V6:V36) -> 0

Sheet 2010
A1: 分地区新增发电装机容量（万KW）
A2: 地区 | B2: 合计 | C2: 水电 | E2: 火电 | S2: 核电 | T2: 风电 | U2: 太阳能发电 | V2: 其他
C3: 合计 | D3: 抽水蓄能 | E3: 合计 | F3: 燃煤 | I3: 燃气 | L3: 燃油 | M3: 其他
F4: 合计 | G4: 常规燃煤 | H4: 煤矸石发电 | I4: 合计 | J4: 常规燃气 | K4: 煤层气发电 | M4: 合计 | N4: 余温、余气、余压发电 | O4: 垃圾焚烧发电 | P4: 秸秆、蔗渣、林木质发电 | Q4: 沼气 | R4: 技改增容
A5: 全国 | B5: 9124 | C5: 1642.85 | D5: 240 | E5: 5830.56 | F5: 5555.98 | H5: 130.14 | I5: 123.5 | L5: 2.98 | M5: =SUM(N5:P5) -> 138.91 | N5: 81.77 | O5: 14.03 | P5: 43.11 | Q5: 0.19 | S5: 173.69 | T5: 1457.31 | U5: 19.59 | X5: =B5-C5-E5-S5-T5-U5-V5 -> -7.6383344e-13 | Y5: =E5-F5-I5-L5-M5 -> 9.19 | Z5: =M5-N5-O5-P5 -> 0
A6: 北京 | B6: 8.55 | M6: =SUM(N6:P6) -> 0 | T6: 8.55 | X6: =B6-C6-E6-S6-T6-U6-V6 -> 0 | Y6: =E6-F6-I6-L6-M6 -> 0 | Z6: =M6-N6-O6-P6 -> 0
A7: 天津 | B7: 97.55 | E7: 90 | F7: 90 | M7: =SUM(N7:P7) -> 0 | T7: 7.55 | X7: =B7-C7-E7-S7-T7-U7-V7 -> -2.6645353e-15 | Y7: =E7-F7-I7-L7-M7 -> 0 | Z7: =M7-N7-O7-P7 -> 0
A8: 河北 | B8: 373.51 | E8: 164.8 | F8: 154 | M8: =SUM(N8:P8) -> 10.8 | N8: 3 | O8: 1.8 | P8: 6 | T8: 208.71 | X8: =B8-C8-E8-S8-T8-U8-V8 -> -2.8421709e-14 | Y8: =E8-F8-I8-L8-M8 -> 0 | Z8: =M8-N8-O8-P8 -> 0
A9: 山西 | B9: 214.4 | C9: 22 | E9: 155.5 | F9: 153 | M9: =SUM(N9:P9) -> 2.5 | N9: 1.9 | P9: 0.6 | T9: 36.9 | X9: =B9-C9-E9-S9-T9-U9-V9 -> 7.1054274e-15 | Y9: =E9-F9-I9-L9-M9 -> 0 | Z9: =M9-N9-O9-P9 -> 0
A10: 内蒙古 | B10: 1008.42 | C10: 1.35 | E10: 575.8 | F10: 574 | H10: 60 | M10: =SUM(N10:P10) -> 1.8 | P10: 1.8 | T10: 431.27 | X10: =B10-C10-E10-S10-T10-U10-V10 -> 0 | Y10: =E10-F10-I10-L10-M10 -> -4.5519144e-14 | Z10: =M10-N10-O10-P10 -> 0
A11: 辽宁 | B11: 602.98 | E11: 486.25 | F11: 482.4 | H11: 30 | M11: =SUM(N11:P11) -> 3.85 | N11: 3.85 | T11: 116.73 | X11: =B11-C11-E11-S11-T11-U11-V11 -> 1.4210855e-14 | Y11: =E11-F11-I11-L11-M11 -> 2.264855e-14 | Z11: =M11-N11-O11-P11 -> 0
A12: 吉林 | B12: 449.48 | C12: 9.44 | E12: 359.74 | F12: 349.7 | M12: =SUM(N12:P12) -> 10.04 | N12: 6.05 | O12: 3.1 | P12: 0.89 | T12: 80.3 | X12: =B12-C12-E12-S12-T12-U12-V12 -> 1.4210855e-14 | Y12: =E12-F12-I12-L12-M12 -> 1.9539925e-14 | Z12: =M12-N12-O12-P12 -> 9.9920072e-16
A13: 黑龙江 | B13: 120.73 | E13: 52.5 | F13: 41.1 | H13: 5 | M13: =SUM(N13:P13) -> 11.4 | N13: 2.4 | P13: 9 | T13: 68.23 | X13: =B13-C13-E13-S13-T13-U13-V13 -> 0 | Y13: =E13-F13-I13-L13-M13 -> 0 | Z13: =M13-N13-O13-P13 -> 0
A14: 上海 | B14: 272.61 | E14: 263 | F14: 260 | M14: =SUM(N14:P14) -> 0 | T14: 9.3 | U14: 0.31 | X14: =B14-C14-E14-S14-T14-U14-V14 -> 1.2934098e-14 | Y14: =E14-F14-I14-L14-M14 -> 3 | Z14: =M14-N14-O14-P14 -> 0
A15: 江苏 | B15: 932.21 | E15: 865.08 | F15: 837.1 | H15: 0.14 | M15: =SUM(N15:P15) -> 26.24 | N15: 20.04 | O15: 6.2 | T15: 60.05 | U15: 7.08 | X15: =B15-C15-E15-S15-T15-U15-V15 -> -1.7763568e-15 | Y15: =E15-F15-I15-L15-M15 -> 1.74 | Z15: =M15-N15-O15-P15 -> -8.8817842e-16
A16: 浙江 | B16: 231 | C16: 2.4 | E16: 162 | F16: 162 | M16: =SUM(N16:P16) -> 0 | S16: 65 | T16: 1.6 | X16: =B16-C16-E16-S16-T16-U16-V16 -> -5.7731597e-15 | Y16: =E16-F16-I16-L16-M16 -> 0 | Z16: =M16-N16-O16-P16 -> 0
A17: 安徽 | B17: 98.8 | E17: 79 | F17: 66.9 | M17: =SUM(N17:P17) -> 12.1 | N17: 8.5 | P17: 3.6 | T17: 19.8 | X17: =B17-C17-E17-S17-T17-U17-V17 -> -3.5527137e-15 | Y17: =E17-F17-I17-L17-M17 -> 0 | Z17: =M17-N17-O17-P17 -> 0
A18: 福建 | B18: 348.4 | C18: 3 | E18: 332 | F18: 227 | I18: 105 | M18: =SUM(N18:P18) -> 0 | T18: 13.4 | X18: =B18-C18-E18-S18-T18-U18-V18 -> -2.3092639e-14 | Y18: =E18-F18-I18-L18-M18 -> 0 | Z18: =M18-N18-O18-P18 -> 0
A19: 江西 | B19: 132 | E19: 132 | F19: 132 | M19: =SUM(N19:P19) -> 0 | X19: =B19-C19-E19-S19-T19-U19-V19 -> 0 | Y19: =E19-F19-I19-L19-M19 -> 0 | Z19: =M19-N19-O19-P19 -> 0
A20: 山东 | B20: 271.84 | C20: 0.01 | E20: 183.06 | F20: 166.06 | M20: =SUM(N20:P20) -> 17 | N20: 15.8 | O20: 0.3 | P20: 0.9 | T20: 86.97 | U20: 1.8 | X20: =B20-C20-E20-S20-T20-U20-V20 -> -1.7097435e-14 | Y20: =E20-F20-I20-L20-M20 -> 0 | Z20: =M20-N20-O20-P20 -> 0
A21: 河南 | B21: 356.03 | E21: 353 | F21: 353 | M21: =SUM(N21:P21) -> 0 | T21: 3.03 | X21: =B21-C21-E21-S21-T21-U21-V21 -> -2.7089442e-14 | Y21: =E21-F21-I21-L21-M21 -> 0 | Z21: =M21-N21-O21-P21 -> 0
A22: 湖北 | B22: 304.25 | C22: 72.75 | D22: 60 | E22: 224.14 | F22: 194.6 | I22: 18.5 | M22: =SUM(N22:P22) -> 10.85 | N22: 6.05 | O22: 2.4 | P22: 2.4 | Q22: 0.19 | T22: 7.36 | X22: =B22-C22-E22-S22-T22-U22-V22 -> 1.3322676e-14 | Y22: =E22-F22-I22-L22-M22 -> 0.19 | Z22: =M22-N22-O22-P22 -> 0
A23: 湖南 | B23: 95.56 | C23: 77.03 | D23: 60 | E23: 14.9 | M23: =SUM(N23:P23) -> 14.9 | N23: 10 | O23: 0.1 | P23: 4.8 | T23: 3.63 | X23: =B23-C23-E23-S23-T23-U23-V23 -> 8.8817842e-16 | Y23: =E23-F23-I23-L23-M23 -> 0 | Z23: =M23-N23-O23-P23 -> 0
A24: 广东 | B24: 581.17 | C24: 120 | D24: 120 | E24: 337 | F24: 337 | M24: =SUM(N24:P24) -> 0 | S24: 108.69 | T24: 15.48 | X24: =B24-C24-E24-S24-T24-U24-V24 -> -3.907985e-14 | Y24: =E24-F24-I24-L24-M24 -> 0 | Z24: =M24-N24-O24-P24 -> 0
A25: 广西 | B25: 38.73 | C25: 21.53 | E25: 17.2 | M25: =SUM(N25:P25) -> 14.2 | N25: 1.08 | P25: 13.12 | X25: =B25-C25-E25-S25-T25-U25-V25 -> -3.5527137e-15 | Y25: =E25-F25-I25-L25-M25 -> 3 | Z25: =M25-N25-O25-P25 -> 0
A26: 海南 | B26: 14.73 | C26: 0.6 | E26: 0.48 | L26: 0.48 | M26: =SUM(N26:P26) -> 0 | T26: 13.65 | X26: =B26-C26-E26-S26-T26-U26-V26 -> 0 | Y26: =E26-F26-I26-L26-M26 -> 0 | Z26: =M26-N26-O26-P26 -> 0
A27: 重庆 | B27: 16.9 | C27: 13.5 | M27: =SUM(N27:P27) -> 0 | T27: 3.4 | X27: =B27-C27-E27-S27-T27-U27-V27 -> -1.3322676e-15 | Y27: =E27-F27-I27-L27-M27 -> 0 | Z27: =M27-N27-O27-P27 -> 0
A28: 四川 | B28: 396.66 | C28: 396.66 | M28: =SUM(N28:P28) -> 0 | X28: =B28-C28-E28-S28-T28-U28-V28 -> 0 | Y28: =E28-F28-I28-L28-M28 -> 0 | Z28: =M28-N28-O28-P28 -> 0
A29: 贵州 | B29: 297.95 | C29: 232.95 | E29: 65 | F29: 65 | H29: 5 | M29: =SUM(N29:P29) -> 0 | X29: =B29-C29-E29-S29-T29-U29-V29 -> 0 | Y29: =E29-F29-I29-L29-M29 -> 0 | Z29: =M29-N29-O29-P29 -> 0
A30: 云南 | B30: 445.03 | C30: 363 | E30: 60 | F30: 60 | M30: =SUM(N30:P30) -> 0 | T30: 21.23 | U30: 0.8 | X30: =B30-C30-E30-S30-T30-U30-V30 -> -2.7755576e-14 | Y30: =E30-F30-I30-L30-M30 -> 0 | Z30: =M30-N30-O30-P30 -> 0
A31: 西藏 | B31: 22.48 | E31: 20.88 | F31: 20.88 | M31: =SUM(N31:P31) -> 0 | U31: 1.6 | X31: =B31-C31-E31-S31-T31-U31-V31 -> 1.3322676e-15 | Y31: =E31-F31-I31-L31-M31 -> 0 | Z31: =M31-N31-O31-P31 -> 0
A32: 陕西 | B32: 196.58 | C32: 22.5 | E32: 169.13 | F32: 169 | H32: 30 | M32: =SUM(N32:P32) -> 0.13 | O32: 0.13 | T32: 4.95 | X32: =B32-C32-E32-S32-T32-U32-V32 -> 1.687539e-14 | Y32: =E32-F32-I32-L32-M32 -> -4.5519144e-15 | Z32: =M32-N32-O32-P32 -> 0
A33: 甘肃 | B33: 409.95 | C33: 25.9 | E33: 213 | F33: 213 | M33: =SUM(N33:P33) -> 0 | T33: 170.05 | U33: 1 | X33: =B33-C33-E33-S33-T33-U33-V33 -> 0 | Y33: =E33-F33-I33-L33-M33 -> 0 | Z33: =M33-N33-O33-P33 -> 0
A34: 青海 | B34: 204.7 | C34: 203.5 | M34: =SUM(N34:P34) -> 0 | U34: 1.2 | X34: =B34-C34-E34-S34-T34-U34-V34 -> -1.1324275e-14 | Y34: =E34-F34-I34-L34-M34 -> 0 | Z34: =M34-N34-O34-P34 -> 0
A35: 宁夏 | B35: 408.35 | E35: 370 | F35: 370 | M35: =SUM(N35:P35) -> 0 | T35: 32.55 | U35: 5.8 | X35: =B35-C35-E35-S35-T35-U35-V35 -> 2.5757174e-14 | Y35: =E35-F35-I35-L35-M35 -> 0 | Z35: =M35-N35-O35-P35 -> 0
A36: 新疆 | B36: 172.45 | C36: 54.73 | E36: 85.1 | F36: 79.5 | L36: 2.5 | M36: =SUM(N36:P36) -> 3.1 | N36: 3.1 | T36: 32.62 | X36: =B36-C36-E36-S36-T36-U36-V36 -> 7.1054274e-15 | Y36: =E36-F36-I36-L36-M36 -> -5.7731597e-15 | Z36: =M36-N36-O36-P36 -> 0
B38: =B5-SUM(B6:B36) -> 0 | C38: =C5-SUM(C6:C36) -> 0 | D38: =D5-SUM(D6:D36) -> 0 | E38: =E5-SUM(E6:E36) -> 0 | F38: =F5-SUM(F6:F36) -> -1.26 | H38: =H5-SUM(H6:H36) -> 0 | I38: =I5-SUM(I6:I36) -> 0 | J38: =J5-SUM(J6:J36) -> 0 | K38: =K5-SUM(K6:K36) -> 0 | L38: =L5-SUM(L6:L36) -> 0 | M38: =M5-SUM(M6:M36) -> 0 | N38: =N5-SUM(N6:N36) -> 0 | O38: =O5-SUM(O6:O36) -> 0 | P38: =P5-SUM(P6:P36) -> 0 | S38: =S5-SUM(S6:S36) -> 0 | T38: =T5-SUM(T6:T36) -> 0 | U38: =U5-SUM(U6:U36) -> 0 | V38: =V5-SUM(V6:V36) -> 0

Sheet 2011
A1: 分地区新增发电装机容量（万KW）
A2: 地区 | B2: 合计 | C2: 水电 | E2: 火电 | S2: 核电 | T2: 风电 | U2: 太阳能发电 | V2: 其他
C3: 合计 | D3: 抽水蓄能 | E3: 合计 | F3: 燃煤 | I3: 燃气 | L3: 燃油 | M3: 其他
F4: 合计 | G4: 常规燃煤 | H4: 煤矸石发电 | I4: 合计 | J4: 常规燃气 | K4: 煤层气发电 | M4: 合计 | N4: 余温、余气、余压发电 | O4: 垃圾焚烧发电 | P4: 秸秆、蔗渣、林木质发电 | Q4: 沼气 | R4: 技改增容
A5: 全国 | B5: 9435.65 | C5: 1282.77 | D5: 175 | E5: 6241.34 | F5: 5653.6 | H5: 183 | I5: 236.64 | N5: 77.02 | O5: 25.68 | P5: 65.4 | S5: 174.69 | T5: 1527.77 | V5: 209.08 | X5: =B5-C5-E5-S5-T5-U5-V5 -> -9.9475983e-13 | Y5: =E5-F5-I5-L5-M5 -> 351.1 | Z5: =M5-N5-O5-P5 -> -168.1
A6: 北京 | B6: 92.34 | E6: 92.34 | I6: 92.34 | X6: =B6-C6-E6-S6-T6-U6-V6 -> 0 | Y6: =E6-F6-I6-L6-M6 -> 0 | Z6: =M6-N6-O6-P6 -> 0
A7: 天津 | B7: 65.4 | E7: 60 | F7: 60 | T7: 5.4 | X7: =B7-C7-E7-S7-T7-U7-V7 -> 5.3290705e-15 | Y7: =E7-F7-I7-L7-M7 -> 0 | Z7: =M7-N7-O7-P7 -> 0
A8: 河北 | B8: 234.73 | E8: 132.9 | F8: 126 | N8: 1.5 | P8: 5.4 | T8: 88.78 | V8: 13.05 | X8: =B8-C8-E8-S8-T8-U8-V8 -> -1.7763568e-14 | Y8: =E8-F8-I8-L8-M8 -> 6.9 | Z8: =M8-N8-O8-P8 -> -6.9
A9: 山西 | B9: 677.7 | C9: 60 | D9: 60 | E9: 511.8 | F9: 448.8 | H9: 63 | N9: 0 | T9: 104.4 | V9: 1.5 | X9: =B9-C9-E9-S9-T9-U9-V9 -> 2.8421709e-14 | Y9: =E9-F9-I9-L9-M9 -> 63 | Z9: =M9-N9-O9-P9 -> 0
A10: 内蒙古 | B10: 839.14 | C10: 0.05 | E10: 464.3 | F10: 457.7 | N10: 1.8 | P10: 4.8 | T10: 368.39 | V10: 6.4 | X10: =B10-C10-E10-S10-T10-U10-V10 -> 3.375078e-14 | Y10: =E10-F10-I10-L10-M10 -> 6.6 | Z10: =M10-N10-O10-P10 -> -6.6
A11: 辽宁 | B11: 296.7 | C11: 30 | D11: 30 | E11: 157.9 | F11: 155.2 | N11: 2.7 | T11: 108.8 | X11: =B11-C11-E11-S11-T11-U11-V11 -> -1.4210855e-14 | Y11: =E11-F11-I11-L11-M11 -> 2.7 | Z11: =M11-N11-O11-P11 -> -2.7
A12: 吉林 | B12: 216.43 | C12: 6.33 | E12: 160.6 | F12: 149.4 | N12: 5.7 | P12: 5.5 | T12: 49.5 | X12: =B12-C12-E12-S12-T12-U12-V12 -> 0 | Y12: =E12-F12-I12-L12-M12 -> 11.2 | Z12: =M12-N12-O12-P12 -> -11.2
A13: 黑龙江 | B13: 167.29 | C13: 1.2 | E13: 103.55 | F13: 42.95 | H13: 60 | P13: 0.6 | T13: 62.54 | X13: =B13-C13-E13-S13-T13-U13-V13 -> 7.1054274e-15 | Y13: =E13-F13-I13-L13-M13 -> 60.6 | Z13: =M13-N13-O13-P13 -> -0.6
A14: 上海 | B14: 136.93 | E14: 127.5 | F14: 4 | I14: 122.3 | N14: 1.2 | T14: 9.43 | X14: =B14-C14-E14-S14-T14-U14-V14 -> 7.1054274e-15 | Y14: =E14-F14-I14-L14-M14 -> 1.2 | Z14: =M14-N14-O14-P14 -> -1.2
A15: 江苏 | B15: 567.38 | E15: 525.1 | F15: 479.2 | I15: 22 | N15: 15.45 | O15: 6.85 | P15: 1.6 | T15: 12.15 | V15: 30.13 | X15: =B15-C15-E15-S15-T15-U15-V15 -> 0 | Y15: =E15-F15-I15-L15-M15 -> 23.9 | Z15: =M15-N15-O15-P15 -> -23.9
A16: 浙江 | B16: 336.65 | E16: 260 | F16: 260 | S16: 66 | T16: 10.65 | X16: =B16-C16-E16-S16-T16-U16-V16 -> -2.3092639e-14 | Y16: =E16-F16-I16-L16-M16 -> 0 | Z16: =M16-N16-O16-P16 -> 0
A17: 安徽 | B17: 221.9 | C17: 25 | D17: 25 | E17: 186.8 | F17: 168.5 | N17: 6.3 | P17: 12 | T17: 9.9 | V17: 0.2 | X17: =B17-C17-E17-S17-T17-U17-V17 -> -6.0507155e-15 | Y17: =E17-F17-I17-L17-M17 -> 18.3 | Z17: =M17-N17-O17-P17 -> -18.3
A18: 福建 | B18: 142.4 | E18: 127 | F18: 127 | T18: 15.4 | X18: =B18-C18-E18-S18-T18-U18-V18 -> 5.3290705e-15 | Y18: =E18-F18-I18-L18-M18 -> 0 | Z18: =M18-N18-O18-P18 -> 0
A19: 江西 | B19: 134.95 | E19: 130 | F19: 130 | T19: 4.95 | X19: =B19-C19-E19-S19-T19-U19-V19 -> -1.1546319e-14 | Y19: =E19-F19-I19-L19-M19 -> 0 | Z19: =M19-N19-O19-P19 -> 0
A20: 山东 | B20: 525.28 | C20: 0.21 | E20: 406.18 | F20: 351.45 | N20: 30.32 | O20: 4.91 | P20: 19.5 | T20: 116.76 | V20: 2.13 | X20: =B20-C20-E20-S20-T20-U20-V20 -> -7.5495166e-14 | Y20: =E20-F20-I20-L20-M20 -> 54.73 | Z20: =M20-N20-O20-P20 -> -54.73
A21: 河南 | B21: 385 | C21: 30 | D21: 30 | E21: 347.5 | F21: 346 | P21: 1.5 | T21: 7.5 | X21: =B21-C21-E21-S21-T21-U21-V21 -> 0 | Y21: =E21-F21-I21-L21-M21 -> 1.5 | Z21: =M21-N21-O21-P21 -> -1.5
A22: 湖北 | B22: 387.83 | C22: 294.36 | E22: 87.65 | F22: 81.1 | N22: 6.55 | T22: 5.82 | X22: =B22-C22-E22-S22-T22-U22-V22 -> -3.5527137e-14 | Y22: =E22-F22-I22-L22-M22 -> 6.55 | Z22: =M22-N22-O22-P22 -> -6.55
A23: 湖南 | B23: 219.17 | C23: 16.7 | E23: 192.72 | F23: 188.7 | O23: 2.52 | P23: 1.5 | T23: 9.75 | X23: =B23-C23-E23-S23-T23-U23-V23 -> 0 | Y23: =E23-F23-I23-L23-M23 -> 4.02 | Z23: =M23-N23-O23-P23 -> -4.02
A24: 广东 | B24: 753.48 | C24: 30 | D24: 30 | E24: 591 | F24: 575.6 | O24: 5.4 | P24: 10 | S24: 108.69 | T24: 23.49 | V24: 0.3 | X24: =B24-C24-E24-S24-T24-U24-V24 -> 2.2037927e-14 | Y24: =E24-F24-I24-L24-M24 -> 15.4 | Z24: =M24-N24-O24-P24 -> -15.4
A25: 广西 | B25: 158.1 | C25: 17.15 | E25: 136 | F25: 133 | P25: 3 | T25: 4.95 | X25: =B25-C25-E25-S25-T25-U25-V25 -> -1.1546319e-14 | Y25: =E25-F25-I25-L25-M25 -> 3 | Z25: =M25-N25-O25-P25 -> -3
A26: 海南 | B26: 4.4 | E26: 2.4 | F26: 0 | O26: 2.4 | V26: 2 | X26: =B26-C26-E26-S26-T26-U26-V26 -> 0 | Y26: =E26-F26-I26-L26-M26 -> 2.4 | Z26: =M26-N26-O26-P26 -> -2.4
A27: 重庆 | B27: 123.3 | C27: 123.3 | X27: =B27-C27-E27-S27-T27-U27-V27 -> 0 | Y27: =E27-F27-I27-L27-M27 -> 0 | Z27: =M27-N27-O27-P27 -> 0
A28: 四川 | B28: 396.75 | C28: 206.05 | E28: 189.1 | F28: 180 | N28: 5.5 | O28: 3.6 | T28: 1.6 | X28: =B28-C28-E28-S28-T28-U28-V28 -> -5.7731597e-15 | Y28: =E28-F28-I28-L28-M28 -> 9.1 | Z28: =M28-N28-O28-P28 -> -9.1
A29: 贵州 | B29: 141.64 | C29: 1.19 | E29: 125 | F29: 125 | T29: 15.45 | X29: =B29-C29-E29-S29-T29-U29-V29 -> -1.0658141e-14 | Y29: =E29-F29-I29-L29-M29 -> 0 | Z29: =M29-N29-O29-P29 -> 0
A30: 云南 | B30: 393.34 | C30: 353.36 | T30: 39.98 | X30: =B30-C30-E30-S30-T30-U30-V30 -> -3.5527137e-14 | Y30: =E30-F30-I30-L30-M30 -> 0 | Z30: =M30-N30-O30-P30 -> 0
A31: 西藏 | B31: 12.17 | C31: 10.2 | V31: 1.97 | X31: =B31-C31-E31-S31-T31-U31-V31 -> 0 | Y31: =E31-F31-I31-L31-M31 -> 0 | Z31: =M31-N31-O31-P31 -> 0
A32: 陕西 | B32: 168 | C32: 2 | E32: 137 | F32: 137 | T32: 25.5 | V32: 3.5 | X32: =B32-C32-E32-S32-T32-U32-V32 -> 0 | Y32: =E32-F32-I32-L32-M32 -> 0 | Z32: =M32-N32-O32-P32 -> 0
A33: 甘肃 | B33: 420.09 | C33: 26.74 | E33: 104 | F33: 104 | T33: 281.35 | V33: 8 | X33: =B33-C33-E33-S33-T33-U33-V33 -> -5.6843419e-14 | Y33: =E33-F33-I33-L33-M33 -> 0 | Z33: =M33-N33-O33-P33 -> 0
A34: 青海 | B34: 136.1 | C34: 13 | E34: 27 | F34: 27 | T34: 1.7 | V34: 94.4 | X34: =B34-C34-E34-S34-T34-U34-V34 -> 0 | Y34: =E34-F34-I34-L34-M34 -> 0 | Z34: =M34-N34-O34-P34 -> 0
A35: 宁夏 | B35: 513.18 | E35: 374 | F35: 374 | T35: 99.08 | V35: 40.1 | X35: =B35-C35-E35-S35-T35-U35-V35 -> 0 | Y35: =E35-F35-I35-L35-M35 -> 0 | Z35: =M35-N35-O35-P35 -> 0
A36: 新疆 | B36: 567.88 | C36: 35.93 | E36: 482 | F36: 422 | H36: 60 | T36: 44.55 | V36: 5.4 | X36: =B36-C36-E36-S36-T36-U36-V36 -> 4.7961635e-14 | Y36: =E36-F36-I36-L36-M36 -> 60 | Z36: =M36-N36-O36-P36 -> 0
B38: =B5-SUM(B6:B36) -> 0 | C38: =C5-SUM(C6:C36) -> 0 | D38: =D5-SUM(D6:D36) -> 0 | E38: =E5-SUM(E6:E36) -> 0 | F38: =F5-SUM(F6:F36) -> 0 | H38: =H5-SUM(H6:H36) -> 0 | I38: =I5-SUM(I6:I36) -> 0 | J38: =J5-SUM(J6:J36) -> 0 | K38: =K5-SUM(K6:K36) -> 0 | L38: =L5-SUM(L6:L36) -> 0 | M38: =M5-SUM(M6:M36) -> 0 | N38: =N5-SUM(N6:N36) -> 0 | O38: =O5-SUM(O6:O36) -> 0 | P38: =P5-SUM(P6:P36) -> 0 | S38: =S5-SUM(S6:S36) -> 0 | T38: =T5-SUM(T6:T36) -> 0 | U38: =U5-SUM(U6:U36) -> 0 | V38: =V5-SUM(V6:V36) -> 0

Sheet 2012
A1: 分地区新增发电装机容量（万KW）
A2: 地区 | B2: 合计 | C2: 水电 | E2: 火电 | S2: 核电 | T2: 风电 | U2: 太阳能发电 | V2: 其他
C3: 合计 | D3: 抽水蓄能 | E3: 合计 | F3: 燃煤 | I3: 燃气 | L3: 燃油 | M3: 其他
F4: 合计 | G4: 常规燃煤 | H4: 煤矸石发电 | I4: 合计 | J4: 常规燃气 | K4: 煤层气发电 | M4: 合计 | N4: 余温、余气、余压发电 | O4: 垃圾焚烧发电 | P4: 秸秆、蔗渣、林木质发电 | Q4: 沼气 | R4: 技改增容
A5: 全国 | B5: 8315 | C5: 1676 | D5: 165 | E5: 5236 | F5: 4788 | H5: 156 | I5: 247 | M5: 201 | N5: 105 | O5: 20 | P5: 75 | T5: 1296 | U5: 107 | X5: =B5-C5-E5-S5-T5-U5-V5 -> 0 | Y5: =E5-F5-I5-L5-M5 -> 0 | Z5: =M5-N5-O5-P5 -> 1
A6: 北京 | F6: 0 | I6: 0 | M6: 0 | X6: =B6-C6-E6-S6-T6-U6-V6 -> 0 | Y6: =E6-F6-I6-L6-M6 -> 0 | Z6: =M6-N6-O6-P6 -> 0
A7: 天津 | B7: 31 | E7: 27 | F7: 27 | I7: 0 | M7: 0 | T7: 5 | X7: =B7-C7-E7-S7-T7-U7-V7 -> -1 | Y7: =E7-F7-I7-L7-M7 -> 0 | Z7: =M7-N7-O7-P7 -> 0
A8: 河北 | B8: 334 | E8: 175 | F8: 153 | H8: 60 | I8: 0 | M8: 22 | N8: 0.6 | O8: 4 | P8: 18 | T8: 158 | U8: 0.1 | X8: =B8-C8-E8-S8-T8-U8-V8 -> 0.9 | Y8: =E8-F8-I8-L8-M8 -> 0 | Z8: =M8-N8-O8-P8 -> -0.6
A9: 山西 | B9: 422 | E9: 318 | F9: 317 | H9: 30 | I9: 0.5 | M9: 0 | T9: 103 | U9: 0.8 | X9: =B9-C9-E9-S9-T9-U9-V9 -> 0.2 | Y9: =E9-F9-I9-L9-M9 -> 0.5 | Z9: =M9-N9-O9-P9 -> 0
A10: 内蒙古 | B10: 234 | C10: 1 | E10: 71 | F10: 71 | I10: 0 | M10: 0 | T10: 152 | U10: 11 | X10: =B10-C10-E10-S10-T10-U10-V10 -> -1 | Y10: =E10-F10-I10-L10-M10 -> 0 | Z10: =M10-N10-O10-P10 -> 0
A11: 辽宁 | B11: 421 | C11: 95 | D11: 90 | E11: 257 | F11: 221 | I11: 0 | M11: 36 | N11: 25 | P11: 11 | T11: 69 | U11: 1 | X11: =B11-C11-E11-S11-T11-U11-V11 -> -1 | Y11: =E11-F11-I11-L11-M11 -> 0 | Z11: =M11-N11-O11-P11 -> 0
A12: 吉林 | B12: 159 | C12: 9 | E12: 111 | F12: 104 | H12: 66 | I12: 0 | M12: 8 | N12: 6 | P12: 2 | T12: 39 | X12: =B12-C12-E12-S12-T12-U12-V12 -> 0 | Y12: =E12-F12-I12-L12-M12 -> -1 | Z12: =M12-N12-O12-P12 -> 0
A13: 黑龙江 | B13: 87 | C13: 0.4 | E13: 16 | F13: 0 | I13: 2 | M13: 13 | N13: 8 | P13: 5 | T13: 71 | X13: =B13-C13-E13-S13-T13-U13-V13 -> -0.4 | Y13: =E13-F13-I13-L13-M13 -> 1 | Z13: =M13-N13-O13-P13 -> 0
A14: 上海 | B14: 42 | E14: 42 | F14: 42 | I14: 0 | M14: 0 | X14: =B14-C14-E14-S14-T14-U14-V14 -> 0 | Y14: =E14-F14-I14-L14-M14 -> 0 | Z14: =M14-N14-O14-P14 -> 0
A15: 江苏 | B15: 584 | C15: 0 | E15: 540 | F15: 399 | I15: 117 | M15: 24 | N15: 18 | O15: 0.8 | P15: 5 | T15: 37 | U15: 7 | X15: =B15-C15-E15-S15-T15-U15-V15 -> 0 | Y15: =E15-F15-I15-L15-M15 -> 0 | Z15: =M15-N15-O15-P15 -> 0.2
A16: 浙江 | B16: 139 | E16: 131 | F16: 4 | I16: 127 | M16: 0 | T16: 8 | X16: =B16-C16-E16-S16-T16-U16-V16 -> 0 | Y16: =E16-F16-I16-L16-M16 -> 0 | Z16: =M16-N16-O16-P16 -> 0
A17: 安徽 | B17: 352 | C17: 77 | D17: 75 | E17: 269 | F17: 263 | I17: 0 | M17: 6 | N17: 2 | O17: 0.1 | P17: 3 | T17: 5 | U17: 1.5 | X17: =B17-C17-E17-S17-T17-U17-V17 -> -0.5 | Y17: =E17-F17-I17-L17-M17 -> 0 | Z17: =M17-N17-O17-P17 -> 0.9
A18: 福建 | B18: 137 | E18: 127 | F18: 127 | I18: 0 | M18: 0 | T18: 10 | X18: =B18-C18-E18-S18-T18-U18-V18 -> 0 | Y18: =E18-F18-I18-L18-M18 -> 0 | Z18: =M18-N18-O18-P18 -> 0
A19: 江西 | B19: 138 | C19: 4 | E19: 130 | F19: 130 | I19: 0 | M19: 0 | T19: 3 | X19: =B19-C19-E19-S19-T19-U19-V19 -> 1 | Y19: =E19-F19-I19-L19-M19 -> 0 | Z19: =M19-N19-O19-P19 -> 0
A20: 山东 | B20: 521 | C20: 0.7 | E20: 381 | F20: 337 | I20: 0.4 | M20: 45 | N20: 28 | O20: 5 | P20: 11 | T20: 132 | U20: 7 | X20: =B20-C20-E20-S20-T20-U20-V20 -> 0.3 | Y20: =E20-F20-I20-L20-M20 -> -1.4 | Z20: =M20-N20-O20-P20 -> 1
A21: 河南 | B21: 620 | E21: 615 | F21: 613 | I21: 0 | M21: 2 | P21: 2 | T21: 5 | X21: =B21-C21-E21-S21-T21-U21-V21 -> 0 | Y21: =E21-F21-I21-L21-M21 -> 0 | Z21: =M21-N21-O21-P21 -> 0
A22: 湖北 | B22: 441 | C22: 196 | E22: 239 | F22: 203 | I22: 0.2 | M22: 35 | N22: 17 | O22: 6 | P22: 13 | T22: 5 | U22: 0.9 | X22: =B22-C22-E22-S22-T22-U22-V22 -> 0.1 | Y22: =E22-F22-I22-L22-M22 -> 0.8 | Z22: =M22-N22-O22-P22 -> -1
A23: 湖南 | B23: 95 | C23: 17 | E23: 72 | F23: 66 | I23: 0 | M23: 6 | P23: 6 | T23: 5 | X23: =B23-C23-E23-S23-T23-U23-V23 -> 1 | Y23: =E23-F23-I23-L23-M23 -> 0 | Z23: =M23-N23-O23-P23 -> 0
A24: 广东 | B24: 533 | E24: 496 | F24: 496 | I24: 0 | M24: 0 | T24: 36 | U24: 2 | X24: =B24-C24-E24-S24-T24-U24-V24 -> -1 | Y24: =E24-F24-I24-L24-M24 -> 0 | Z24: =M24-N24-O24-P24 -> 0
A25: 广西 | B25: 275 | C25: 4 | E25: 266 | F25: 266 | I25: 0 | M25: 0 | T25: 5 | X25: =B25-C25-E25-S25-T25-U25-V25 -> 0 | Y25: =E25-F25-I25-L25-M25 -> 0 | Z25: =M25-N25-O25-P25 -> 0
A26: 海南 | B26: 75 | E26: 70 | F26: 70 | I26: 0 | M26: 0 | T26: 5 | X26: =B26-C26-E26-S26-T26-U26-V26 -> 0 | Y26: =E26-F26-I26-L26-M26 -> 0 | Z26: =M26-N26-O26-P26 -> 0
A27: 重庆 | B27: 17 | C27: 17 | F27: 0 | I27: 0 | M27: 0 | X27: =B27-C27-E27-S27-T27-U27-V27 -> 0 | Y27: =E27-F27-I27-L27-M27 -> 0 | Z27: =M27-N27-O27-P27 -> 0
A28: 四川 | B28: 797 | C28: 730 | E28: 67 | F28: 62 | I28: 0 | M28: 5 | N28: 0.2 | O28: 5 | X28: =B28-C28-E28-S28-T28-U28-V28 -> 0 | Y28: =E28-F28-I28-L28-M28 -> 0 | Z28: =M28-N28-O28-P28 -> -0.2
A29: 贵州 | B29: 182 | C29: 11 | E29: 126 | F29: 126 | I29: 0 | M29: 0 | T29: 45 | X29: =B29-C29-E29-S29-T29-U29-V29 -> 0 | Y29: =E29-F29-I29-L29-M29 -> 0 | Z29: =M29-N29-O29-P29 -> 0
A30: 云南 | B30: 708 | C30: 397 | E30: 180 | F30: 180 | I30: 0 | M30: 0 | T30: 130 | U30: 1 | X30: =B30-C30-E30-S30-T30-U30-V30 -> 0 | Y30: =E30-F30-I30-L30-M30 -> 0 | Z30: =M30-N30-O30-P30 -> 0
A31: 西藏 | B31: 4 | F31: 0 | I31: 0 | M31: 0 | U31: 4 | X31: =B31-C31-E31-S31-T31-U31-V31 -> 0 | Y31: =E31-F31-I31-L31-M31 -> 0 | Z31: =M31-N31-O31-P31 -> 0
A32: 陕西 | B32: 90 | E32: 66 | F32: 66 | I32: 0 | M32: 0 | T32: 22 | U32: 3 | X32: =B32-C32-E32-S32-T32-U32-V32 -> -1 | Y32: =E32-F32-I32-L32-M32 -> 0 | Z32: =M32-N32-O32-P32 -> 0
A33: 甘肃 | B33: 156 | C33: 40 | E33: 12 | F33: 12 | I33: 0 | M33: 0 | T33: 75 | U33: 29 | X33: =B33-C33-E33-S33-T33-U33-V33 -> 0 | Y33: =E33-F33-I33-L33-M33 -> 0 | Z33: =M33-N33-O33-P33 -> 0
A34: 青海 | B34: 27 | C34: 4 | F34: 0 | I34: 0 | M34: 0 | T34: 0.2 | U34: 23 | X34: =B34-C34-E34-S34-T34-U34-V34 -> -0.2 | Y34: =E34-F34-I34-L34-M34 -> 0 | Z34: =M34-N34-O34-P34 -> 0
A35: 宁夏 | B35: 95 | F35: 0 | I35: 0 | M35: 0 | T35: 92 | U35: 3 | X35: =B35-C35-E35-S35-T35-U35-V35 -> 0 | Y35: =E35-F35-I35-L35-M35 -> 0 | Z35: =M35-N35-O35-P35 -> 0
A36: 新疆 | B36: 600 | C36: 73 | E36: 433 | F36: 433 | I36: 0 | M36: 0 | T36: 79 | U36: 14 | X36: =B36-C36-E36-S36-T36-U36-V36 -> 1 | Y36: =E36-F36-I36-L36-M36 -> 0 | Z36: =M36-N36-O36-P36 -> 0
B38: =B5-SUM(B6:B36) -> -1 | C38: =C5-SUM(C6:C36) -> -0.1 | D38: =D5-SUM(D6:D36) -> 0 | E38: =E5-SUM(E6:E36) -> -1 | F38: =F5-SUM(F6:F36) -> 0 | H38: =H5-SUM(H6:H36) -> 0 | I38: =I5-SUM(I6:I36) -> -0.1 | J38: =J5-SUM(J6:J36) -> 0 | K38: =K5-SUM(K6:K36) -> 0 | L38: =L5-SUM(L6:L36) -> 0 | M38: =M5-SUM(M6:M36) -> -1 | N38: =N5-SUM(N6:N36) -> 0.2 | O38: =O5-SUM(O6:O36) -> -0.9 | P38: =P5-SUM(P6:P36) -> -1 | S38: =S5-SUM(S6:S36) -> 0 | T38: =T5-SUM(T6:T36) -> -0.2 | U38: =U5-SUM(U6:U36) -> -1.3 | V38: =V5-SUM(V6:V36) -> 0

Sheet 2013
A1: 分地区新增发电装机容量（万KW）
A2: 地区 | B2: 合计 | C2: 水电 | E2: 火电 | S2: 核电 | T2: 风电 | U2: 太阳能发电 | V2: 其他
C3: 合计 | D3: 抽水蓄能 | E3: 合计 | F3: 燃煤 | I3: 燃气 | L3: 燃油 | M3: 其他
F4: 合计 | G4: 常规燃煤 | H4: 煤矸石发电 | I4: 合计 | J4: 常规燃气 | K4: 煤层气发电 | M4: 合计 | N4: 余温、余气、余压发电 | O4: 垃圾焚烧发电 | P4: 秸秆、蔗渣、林木质发电 | Q4: 沼气 | R4: 技改增容
