Workbook

Sheet About
A1: BDCSoCbIC BAU Domestic Content Share of Consumption by ISIC Code
A3: Source: | B3: 2020年全国投入产出表
B4: 国家统计局
B5: 2020
B6: https://data.stats.gov.cn/files/html/quickSearch/trcc/trcc01.html
A8: Notes
A9: “2020年全国投入产出表”是根据我国2020年全年投入产出表中竞争型和非竞争型两张表结合美国EPS模型总结出来42个部门的投入产出表。政府消费支出是根据“2020年全国投入产出表”中各行业政府消费支出数额乘以当年2020年人民币相对2012美元的汇率得出。
A10: 各行业总产出加总进口减去总出口等于国内消费。根据“2020年非竞争型投入产出表”算出进口品占出口的份额，各行业国内消耗的进口品为进口乘以（1-进口品占出口的份额），国内生产消费为国内消费减去国内消费进口的部分。国内消费除以国内生产消费得到Domestic Content Share of Consumption。

Sheet Calculations
B1: ISIC 01T03 | C1: ISIC 05 | D1: ISIC 06 | E1: ISIC 07T08 | F1: ISIC 09 | G1: ISIC 10T12 | H1: ISIC 13T15 | I1: ISIC 16 | J1: ISIC 17T18 | K1: ISIC 19 | L1: ISIC 20 | M1: ISIC 21 | N1: ISIC 22 | O1: ISIC 231 | P1: ISIC 239 | Q1: ISIC 241 | R1: ISIC 242 | S1: ISIC 25 | T1: ISIC 26 | U1: ISIC 27 | V1: ISIC 28 | W1: ISIC 29 | X1: ISIC 30 | Y1: ISIC 31T33 | Z1: ISIC 351 | AA1: ISIC 352T353 | AB1: ISIC 36T39 | AC1: ISIC 41T43 | AD1: ISIC 45T47 | AE1: ISIC 49T53 | AF1: ISIC 55T56 | AG1: ISIC 58T60 | AH1: ISIC 61 | AI1: ISIC 62T63 | AJ1: ISIC 64T66 | AK1: ISIC 68 | AL1: ISIC 69T82 | AM1: ISIC 84 | AN1: ISIC 85 | AO1: ISIC 86T88 | AP1: ISIC 90T96 | AQ1: ISIC 97T98
A2: Domestic Production | B2: ='2020年全国投入产出表'!$BF$7*$B$14 -> 1.833071e+08 | C2: ='2020年全国投入产出表'!$BF$8*$B$14 -> 32357904 | D2: =$B$14*'2020年全国投入产出表'!$BF$9 -> 14823542 | E2: =$B$14*'2020年全国投入产出表'!$BF$10 -> 26640169 | F2: =$B$14*'2020年全国投入产出表'!$BF$11 -> 2785605.7 | G2: =$B$14*'2020年全国投入产出表'!$BF$12 -> 1.7225094e+08 | H2: =$B$14*'2020年全国投入产出表'!$BF$13 -> 1.0425482e+08 | I2: =$B$14*'2020年全国投入产出表'!$BF$14 -> 36534304 | J2: =$B$14*'2020年全国投入产出表'!$BF$15 -> 58968555 | K2: =$B$14*'2020年全国投入产出表'!$BF$16 -> 56345004 | L2: =$B$14*'2020年全国投入产出表'!$BF$17 -> 1.1770463e+08 | M2: =$B$14*'2020年全国投入产出表'!$BF$18 -> 41302931 | N2: =$B$14*'2020年全国投入产出表'!$BF$19 -> 49305314 | O2: =$B$14*'2020年全国投入产出表'!$BF$20 -> 1.0090234e+08 | P2: =$B$14*'2020年全国投入产出表'!$BF$25 -> 53319139 | Q2: =$B$14*'2020年全国投入产出表'!$BF$21 -> 94085607 | R2: =$B$14*'2020年全国投入产出表'!$BF$22 -> 72221184 | S2: =$B$14*'2020年全国投入产出表'!$BF$23 -> 71507005 | T2: =$B$14*'2020年全国投入产出表'!$BF$29 -> 1.6360085e+08 | U2: =$B$14*'2020年全国投入产出表'!$BF$28 -> 96034233 | V2: =$B$14*'2020年全国投入产出表'!$BF$24 -> 73355559 | W2: =$B$14*'2020年全国投入产出表'!$BF$26 -> 97244348 | X2: =$B$14*'2020年全国投入产出表'!$BF$27 -> 21475422 | Y2: =$B$14*'2020年全国投入产出表'!$BF$30 -> 2848964.4 | Z2: =$B$14*'2020年全国投入产出表'!$BF$31 -> 96287002 | AA2: =$B$14*'2020年全国投入产出表'!$BF$32 -> 11187009 | AB2: =$B$14*'2020年全国投入产出表'!$BF$33 -> 5599430.3 | AC2: =$B$14*'2020年全国投入产出表'!$BF$34 -> 3.9372292e+08 | AD2: =$B$14*'2020年全国投入产出表'!$BF$35 -> 2.0627156e+08 | AE2: =$B$14*'2020年全国投入产出表'!$BF$36 -> 1.6506674e+08 | AF2: =$B$14*'2020年全国投入产出表'!$BF$37 -> 59463683 | AG2: =$B$14*'2020年全国投入产出表'!$BF$38 -> 1.3286632e+08 | AH2: =$B$14*'2020年全国投入产出表'!$BF$41 -> 1.3249739e+08 | AI2: =$B$14*'2020年全国投入产出表'!$BF$42 -> 31873919 | AJ2: =$B$14*'2020年全国投入产出表'!$BF$39 -> 1.6922364e+08 | AK2: =$B$14*'2020年全国投入产出表'!$BF$40 -> 1.4682282e+08 | AL2: =$B$14*'2020年全国投入产出表'!$BF$43 -> 71548877 | AM2: =$B$14*'2020年全国投入产出表'!$BF$48 -> 1.2494637e+08 | AN2: =$B$14*'2020年全国投入产出表'!$BF$45 -> 73297274 | AO2: =$B$14*'2020年全国投入产出表'!$BF$46 -> 68835277 | AP2: =$B$14*'2020年全国投入产出表'!$BF$47 -> 21451951 | AQ2: =$B$14*'2020年全国投入产出表'!$BF$44 -> 41341673
A3: Imports | B3: =$B$14*'2020年全国投入产出表'!$BE$7 -> 8845713 | C3: =$B$14*'2020年全国投入产出表'!$BE$8 -> 2055540.1 | D3: =$B$14*'2020年全国投入产出表'!$BE$9 -> 19999809 | E3: =$B$14*'2020年全国投入产出表'!$BE$10 -> 18534353 | F3: =$B$14*'2020年全国投入产出表'!$BE$11 -> 0 | G3: =$B$14*'2020年全国投入产出表'!$BE$12 -> 11174570 | H3: =$B$14*'2020年全国投入产出表'!$BE$13 -> 4137159.6 | I3: =$B$14*'2020年全国投入产出表'!$BE$14 -> 1340286.8 | J3: =$B$14*'2020年全国投入产出表'!$BE$15 -> 3566621.4 | K3: =$B$14*'2020年全国投入产出表'!$BE$16 -> 3117808.3 | L3: =$B$14*'2020年全国投入产出表'!$BE$17 -> 16940664 | M3: =$B$14*'2020年全国投入产出表'!$BE$18 -> 4272575.4 | N3: =$B$14*'2020年全国投入产出表'!$BE$19 -> 2320086.1 | O3: =$B$14*'2020年全国投入产出表'!$BE$20 -> 1711923.1 | P3: =$B$14*'2020年全国投入产出表'!$BE$25 -> 8151482.8 | Q3: =$B$14*'2020年全国投入产出表'!$BE$21 -> 3653415.4 | R3: =$B$14*'2020年全国投入产出表'!$BE$22 -> 7525723.8 | S3: =$B$14*'2020年全国投入产出表'!$BE$23 -> 1127006.8 | T3: =$B$14*'2020年全国投入产出表'!$BE$29 -> 55357030 | U3: =$B$14*'2020年全国投入产出表'!$BE$28 -> 6942578.6 | V3: =$B$14*'2020年全国投入产出表'!$BE$24 -> 7628936.3 | W3: =$B$14*'2020年全国投入产出表'!$BE$26 -> 7093261.1 | X3: =$B$14*'2020年全国投入产出表'!$BE$27 -> 1267414.1 | Y3: =$B$14*'2020年全国投入产出表'!$BE$30 -> 319013.44 | Z3: =$B$14*'2020年全国投入产出表'!$BE$31 -> 16961.102 | AA3: =$B$14*'2020年全国投入产出表'!$BE$32 -> 0 | AB3: =$B$14*'2020年全国投入产出表'!$BE$33 -> 0 | AC3: =$B$14*'2020年全国投入产出表'!$BE$34 -> 763279.6 | AD3: =$B$14*'2020年全国投入产出表'!$BE$35 -> 0 | AE3: =$B$14*'2020年全国投入产出表'!$BE$36 -> 5412723.3 | AF3: =$B$14*'2020年全国投入产出表'!$BE$37 -> 3822200.1 | AG3: =$B$14*'2020年全国投入产出表'!$BE$38 -> 3806254.3 | AH3: =$B$14*'2020年全国投入产出表'!$BE$41 -> 4189699.3 | AI3: =$B$14*'2020年全国投入产出表'!$BE$42 -> 3819424.5 | AJ3: =$B$14*'2020年全国投入产出表'!$BE$39 -> 1454020.6 | AK3: =$B$14*'2020年全国投入产出表'!$BE$40 -> 0 | AL3: =$B$14*'2020年全国投入产出表'!$BE$43 -> 75.239676 | AM3: =$B$14*'2020年全国投入产出表'!$BE$48 -> 708252.11 | AN3: =$B$14*'2020年全国投入产出表'!$BE$45 -> 0 | AO3: =$B$14*'2020年全国投入产出表'!$BE$46 -> 164498.86 | AP3: =$B$14*'2020年全国投入产出表'!$BE$47 -> 1547198.8 | AQ3: =$B$14*'2020年全国投入产出表'!$BE$44 -> 156336.35
A4: Exports | B4: =$B$14*'2020年全国投入产出表'!$BC$7 -> 2501343 | C4: =$B$14*'2020年全国投入产出表'!$BC$8 -> 35898.682 | D4: =$B$14*'2020年全国投入产出表'!$BC$9 -> 149394.68 | E4: =$B$14*'2020年全国投入产出表'!$BC$10 -> 458804.01 | F4: =$B$14*'2020年全国投入产出表'!$BC$11 -> 0 | G4: =$B$14*'2020年全国投入产出表'!$BC$12 -> 4932504.8 | H4: =$B$14*'2020年全国投入产出表'!$BC$13 -> 25713304 | I4: =$B$14*'2020年全国投入产出表'!$BC$14 -> 6161973.5 | J4: =$B$14*'2020年全国投入产出表'!$BC$15 -> 9095204.6 | K4: =$B$14*'2020年全国投入产出表'!$BC$16 -> 2199826.4 | L4: =$B$14*'2020年全国投入产出表'!$BC$17 -> 9113559.2 | M4: =$B$14*'2020年全国投入产出表'!$BC$18 -> 3156482.6 | N4: =$B$14*'2020年全国投入产出表'!$BC$19 -> 7862690.5 | O4: =$B$14*'2020年全国投入产出表'!$BC$20 -> 4756409.6 | P4: =$B$14*'2020年全国投入产出表'!$BC$25 -> 8169609 | Q4: =$B$14*'2020年全国投入产出表'!$BC$21 -> 3822266.4 | R4: =$B$14*'2020年全国投入产出表'!$BC$22 -> 2472995.4 | S4: =$B$14*'2020年全国投入产出表'!$BC$23 -> 8582320.3 | T4: =$B$14*'2020年全国投入产出表'!$BC$29 -> 60479212 | U4: =$B$14*'2020年全国投入产出表'!$BC$28 -> 23476120 | V4: =$B$14*'2020年全国投入产出表'!$BC$24 -> 12742229 | W4: =$B$14*'2020年全国投入产出表'!$BC$26 -> 4339356.7 | X4: =$B$14*'2020年全国投入产出表'!$BC$27 -> 3986971.8 | Y4: =$B$14*'2020年全国投入产出表'!$BC$30 -> 726756.9 | Z4: =$B$14*'2020年全国投入产出表'!$BC$31 -> 143850.43 | AA4: =$B$14*'2020年全国投入产出表'!$BC$32 -> 0 | AB4: =$B$14*'2020年全国投入产出表'!$BC$33 -> 0 | AC4: =$B$14*'2020年全国投入产出表'!$BC$34 -> 1194954 | AD4: =$B$14*'2020年全国投入产出表'!$BC$35 -> 24583246 | AE4: =$B$14*'2020年全国投入产出表'!$BC$36 -> 13092192 | AF4: =$B$14*'2020年全国投入产出表'!$BC$37 -> 372476.47 | AG4: =$B$14*'2020年全国投入产出表'!$BC$38 -> 4232071.4 | AH4: =$B$14*'2020年全国投入产出表'!$BC$41 -> 5578341.8 | AI4: =$B$14*'2020年全国投入产出表'!$BC$42 -> 1332015.2 | AJ4: =$B$14*'2020年全国投入产出表'!$BC$39 -> 949123.63 | AK4: =$B$14*'2020年全国投入产出表'!$BC$40 -> 0 | AL4: =$B$14*'2020年全国投入产出表'!$BC$43 -> 191.02004 | AM4: =$B$14*'2020年全国投入产出表'!$BC$48 -> 279080.96 | AN4: =$B$14*'2020年全国投入产出表'!$BC$45 -> 0 | AO4: =$B$14*'2020年全国投入产出表'!$BC$46 -> 21607.635 | AP4: =$B$14*'2020年全国投入产出表'!$BC$47 -> 391669.04 | AQ4: =$B$14*'2020年全国投入产出表'!$BC$44 -> 13445.129
A5: Domestic Consumption | B5: =B2+B3-B4 -> 1.8965147e+08 | C5: =C2+C3-C4 -> 34377546 | D5: =D2+D3-D4 -> 34673957 | E5: =E2+E3-E4 -> 44715718 | F5: =F2+F3-F4 -> 2785605.7 | G5: =G2+G3-G4 -> 1.78493e+08 | H5: =H2+H3-H4 -> 82678680 | I5: =I2+I3-I4 -> 31712618 | ... AQ5: =AQ2+AQ3-AQ4 -> 41484564
A6: Imported Content Share of Exports | B6: ='2020年非竞争型投入产出表'!$AY$48/('2020年非竞争型投入产出表'!$AY$48+'2020年非竞争型投入产出表'!$AY$6) -> 0.00038435648 | C6: ='2020年非竞争型投入产出表'!$AY$49/('2020年非竞争型投入产出表'!$AY$49+'2020年非竞争型投入产出表'!$AY$7) -> 0.10720738 | D6: ='2020年非竞争型投入产出表'!$AY$50/('2020年非竞争型投入产出表'!$AY$50+'2020年非竞争型投入产出表'!$AY$8) -> 0.75 | E6: ='2020年非竞争型投入产出表'!$AY$51/('2020年非竞争型投入产出表'!$AY$51+'2020年非竞争型投入产出表'!$AY$9) -> 0.73770856 | F6: ='2020年非竞争型投入产出表'!$AY$52/('2020年非竞争型投入产出表'!AY52+'2020年非竞争型投入产出表'!AY10) -> 0.021076701 | G6: ='2020年非竞争型投入产出表'!$AY$53/('2020年非竞争型投入产出表'!$AY$53+'2020年非竞争型投入产出表'!$AY$11) -> 0.0022122425 | H6: =('2020年非竞争型投入产出表'!$AY$54+'2020年非竞争型投入产出表'!$AY$54)/('2020年非竞争型投入产出表'!$AY$54+'2020年非竞争型投入产出表'!$AY$55+'2020年非竞争型投入产出表'!$AY$12+'2020年非竞争型投入产出表'!$AY$13) -> 0 | I6: ='2020年非竞争型投入产出表'!$AY$56/('2020年非竞争型投入产出表'!$AY$56+'2020年非竞争型投入产出表'!$AY$14) -> 0.0010843136 | J6: ='2020年非竞争型投入产出表'!$AY$57/('2020年非竞争型投入产出表'!$AY$57+'2020年非竞争型投入产出表'!$AY$15) -> 0.0064870473 | K6: ='2020年非竞争型投入产出表'!$AY$58/('2020年非竞争型投入产出表'!$AY$58+'2020年非竞争型投入产出表'!$AY$16) -> 0.13374348 | L6: ='2020年非竞争型投入产出表'!$AY$59/('2020年非竞争型投入产出表'!$AY$59+'2020年非竞争型投入产出表'!$AY$17) -> 0.0038132348 | M6: ='2020年非竞争型投入产出表'!$AY$59/('2020年非竞争型投入产出表'!$AY$59+'2020年非竞争型投入产出表'!$AY$17) -> 0.0038132348 | N6: ='2020年非竞争型投入产出表'!$AY$59/('2020年非竞争型投入产出表'!$AY$59+'2020年非竞争型投入产出表'!$AY$17) -> 0.0038132348 | O6: ='2020年非竞争型投入产出表'!$AY$60/('2020年非竞争型投入产出表'!$AY$60+'2020年非竞争型投入产出表'!$AY$18) -> 0.009857735 | P6: ='2020年非竞争型投入产出表'!$AY$64/('2020年非竞争型投入产出表'!$AY$64+'2020年非竞争型投入产出表'!$AY$22) -> 0.0079567378 | Q6: ='2020年非竞争型投入产出表'!$AY$61/('2020年非竞争型投入产出表'!$AY$61+'2020年非竞争型投入产出表'!$AY$19) -> 0.034222771 | R6: ='2020年非竞争型投入产出表'!$AY$61/('2020年非竞争型投入产出表'!$AY$61+'2020年非竞争型投入产出表'!$AY$19) -> 0.034222771 | S6: ='2020年非竞争型投入产出表'!$AY$62/('2020年非竞争型投入产出表'!$AY$62+'2020年非竞争型投入产出表'!$AY$20) -> 0.0016699437 | T6: ='2020年非竞争型投入产出表'!$AY$67/('2020年非竞争型投入产出表'!$AY$67+'2020年非竞争型投入产出表'!$AY$25) -> 0.058971783 | U6: ='2020年非竞争型投入产出表'!$AY$66/('2020年非竞争型投入产出表'!$AY$66+'2020年非竞争型投入产出表'!$AY$24) -> 0.0083592948 | V6: ='2020年非竞争型投入产出表'!$AY$63/('2020年非竞争型投入产出表'!$AY$63+'2020年非竞争型投入产出表'!$AY$21) -> 0.011718285 | W6: ='2020年非竞争型投入产出表'!$AY$65/('2020年非竞争型投入产出表'!$AY$65+'2020年非竞争型投入产出表'!$AY$23) -> 0.0070817422 | X6: ='2020年非竞争型投入产出表'!$AY$65/('2020年非竞争型投入产出表'!$AY$65+'2020年非竞争型投入产出表'!$AY$23) -> 0.0070817422 | Y6: ='2020年非竞争型投入产出表'!$AY$69/('2020年非竞争型投入产出表'!$AY$69+'2020年非竞争型投入产出表'!$AY$27) -> 0 | Z6: ='2020年非竞争型投入产出表'!$AY$71/('2020年非竞争型投入产出表'!$AY$71+'2020年非竞争型投入产出表'!$AY$29) -> 0 | AA6: ='2020年非竞争型投入产出表'!$AY$72/('2020年非竞争型投入产出表'!$AY$72+'2020年非竞争型投入产出表'!$AY$30) -> #DIV/0! | AB6: ='2020年非竞争型投入产出表'!$AY$73/('2020年非竞争型投入产出表'!$AY$73+'2020年非竞争型投入产出表'!$AY$31) -> #DIV/0! | AC6: ='2020年非竞争型投入产出表'!$AY$74/('2020年非竞争型投入产出表'!$AY$74+'2020年非竞争型投入产出表'!$AY$32) -> 0 | AD6: ='2020年非竞争型投入产出表'!$AY$75/('2020年非竞争型投入产出表'!$AY$75+'2020年非竞争型投入产出表'!$AY$33) -> 0 | AE6: ='2020年非竞争型投入产出表'!$AY$76/('2020年非竞争型投入产出表'!$AY$76+'2020年非竞争型投入产出表'!$AY$34) -> 0 | AF6: ='2020年非竞争型投入产出表'!$AY$77/('2020年非竞争型投入产出表'!$AY$77+'2020年非竞争型投入产出表'!$AY$35) -> 0 | AG6: ='2020年非竞争型投入产出表'!$AY$78/('2020年非竞争型投入产出表'!$AY$78+'2020年非竞争型投入产出表'!$AY$34) -> 0 | AH6: ='2020年非竞争型投入产出表'!$AY$81/('2020年非竞争型投入产出表'!$AY$81+'2020年非竞争型投入产出表'!$AY$39) -> 0 | AI6: ='2020年非竞争型投入产出表'!$AY$82/('2020年非竞争型投入产出表'!$AY$82+'2020年非竞争型投入产出表'!$AY$40) -> 0 | AJ6: ='2020年非竞争型投入产出表'!$AY$79/('2020年非竞争型投入产出表'!$AY$79+'2020年非竞争型投入产出表'!$AY$37) -> 0 | AK6: ='2020年非竞争型投入产出表'!$AY$80/('2020年非竞争型投入产出表'!$AY$80+'2020年非竞争型投入产出表'!$AY$38) -> #DIV/0! | AL6: ='2020年非竞争型投入产出表'!$AY$83/('2020年非竞争型投入产出表'!$AY$83+'2020年非竞争型投入产出表'!$AY$41) -> 0 | AM6: ='2020年非竞争型投入产出表'!$AY$84/('2020年非竞争型投入产出表'!$AY$84+'2020年非竞争型投入产出表'!$AY$42) -> 0 | AN6: ='2020年非竞争型投入产出表'!$AY$86/('2020年非竞争型投入产出表'!$AY$86+'2020年非竞争型投入产出表'!$AY$44) -> #DIV/0! | AO6: ='2020年非竞争型投入产出表'!$AY$87/('2020年非竞争型投入产出表'!$AY$87+'2020年非竞争型投入产出表'!$AY$45) -> 0 | AP6: ='2020年非竞争型投入产出表'!$AY$88/('2020年非竞争型投入产出表'!$AY$88+'2020年非竞争型投入产出表'!$AY$46) -> 0 | AQ6: ='2020年非竞争型投入产出表'!$AY$85/('2020年非竞争型投入产出表'!$AY$85+'2020年非竞争型投入产出表'!$AY$43) -> 0
A7: Imports Consumed Domestically | B7: =B3*(1-B6) -> 8842313.1 | C7: =C3*(1-C6) -> 1835171 | D7: =D3*(1-D6) -> 4999952.3 | E7: =E3*(1-E6) -> 4861402.1 | F7: =F3*(1-F6) -> 0 | G7: =G3*(1-G6) -> 11149849 | H7: =H3*(1-H6) -> 4137159.6 | I7: =I3*(1-I6) -> 1338833.6 | ... AQ7: =AQ3*(1-AQ6) -> 156336.35
A8: Domestic Production Consumed Domestically | B8: =B5-B7 -> 1.8080916e+08 | C8: =C5-C7 -> 32542375 | D8: =D5-D7 -> 29674004 | E8: =E5-E7 -> 39854316 | F8: =F5-F7 -> 2785605.7 | G8: =G5-G7 -> 1.6734315e+08 | H8: =H5-H7 -> 78541520 | I8: =I5-I7 -> 30373784 | ... AQ8: =AQ5-AQ7 -> 41328228
A9: Domestic Content Share of Domestic Consumption | B9: =B8/B5 -> 0.95337598 | C9: =C8/C5 -> 0.94661716 | D9: =D8/D5 -> 0.85580093 | E9: =E8/E5 -> 0.89128203 | F9: =F8/F5 -> 1 | G9: =G8/G5 -> 0.93753341 | H9: =H8/H5 -> 0.94996099 | I9: =I8/I5 -> 0.95778231 | ... AQ9: =AQ8/AQ5 -> 0.99623146
B10: 农林牧渔产品和服务 | C10: 煤炭开采和洗选产品 | D10: 石油和天然气开采产品 | E10: 金属矿采选产品&非金属矿 | F10: 开采辅助活动和其他采矿产品 | G10: 食品和烟草 | H10: 纺织品、纺织服装鞋帽皮革羽绒及其制品 | I10: 木材加工品和家具 | J10: 造纸印刷和文教体育用品 | K10: 石油、炼焦产品和核燃料加工品 | L10: 化学原料和化学制品制造业&化学纤维制造业 | M10: 医药制造业 | N10: 橡胶和塑料制品业 | O10: 非金属矿物制品 | P10: 专用设备 | Q10: 黑色金属冶炼和压延加工品 | R10: 有色金属冶炼和压延加工品 | S10: 金属制品 | T10: 通信设备、计算机和其他电子设备&仪器仪表 | U10: 电气机械和器材 | V10: 通用设备 | W10: 汽车制造业 | X10: 铁路、船舶、航空航天和其他运输设备 | Y10: 其他制造产品和废品废料、金属制品、机械和设备修理服务 | Z10: 电力、热力生产和供应 | AA10: 燃气生产和供应 | AB10: 水的生产和供应 | AC10: 建筑 | AD10: 批发和零售 | AE10: 交通运输、仓储和邮政 | AF10: 住宿和餐饮 | AG10: 信息传输、软件和信息技术服务 | AH10: 租赁和商务服务 | AI10: 研究和试验发展 | AJ10: 金融 | AK10: 房地产 | AL10: 综合技术服务 | AM10: 水利、环境和公共设施管理、公共管理、社会保障和社会组织 | AN10: 教育 | AO10: 卫生和社会工作 | AP10: 文化、体育和娱乐 | AQ10: 居民服务、修理和其他服务
B13: 2020年人民币相对2012美元
A14: 2020 | B14: 0.13765068 | AA14: 0 | AB14: 0 | AK14: 0
AA15: =AA3*(1-AA14) -> 0 | AB15: =AB3*(1-AB14) -> 0 | AK15: =AK3*(1-AK14) -> 0
AA16: =AA5-AA15 -> 11187009 | AB16: =AB5-AB15 -> 5599430.3 | AK16: =AK5-AK15 -> 1.4682282e+08
AA17: =AA16/AA5 -> 1 | AB17: =AB16/AB5 -> 1 | AK17: =AK16/AK5 -> 1 | AN17: 1

Sheet 2020年全国投入产出表
A1: 2020年全国投入产出表
A2: (按当年生产者价格计算） （Data are calculated at producers' prices in 2020)
A3: 单位：万元
A4: 投入 产出 | C4: 部门名称 | AU4: 最终使用 | BE4: 进口 | BF4: 总产出
D5: 农林牧渔产品和服务 | E5: 煤炭开采和洗选产品 | F5: 石油和天然气开采产品 | G5: 金属矿采选产品&非金属矿 | H5: 开采辅助活动和其他采矿产品 | I5: 食品和烟草 | J5: 纺织品、纺织服装鞋帽皮革羽绒及其制品 | K5: 木材加工品和家具 | L5: 造纸印刷和文教体育用品 | M5: 石油、炼焦产品和核燃料加工品 | N5: 化学原料和化学制品制造业&化学纤维制造业 | O5: 医药制造业 | P5: 橡胶和塑料制品业 | Q5: 非金属矿物制品 | R5: 黑色金属冶炼和压延加工品 | S5: 有色金属冶炼和压延加工品 | T5: 金属制品 | U5: 通用设备 | V5: 专用设备 | W5: 汽车制造业 | X5: 铁路、船舶、航空航天和其他运输设备 | Y5: 电气机械和器材 | Z5: 通信设备、计算机和其他电子设备&仪器仪表 | AA5: 其他制造产品和废品废料、金属制品、机械和设备修理服务 | AB5: 电力、热力生产和供应 | AC5: 燃气生产和供应 | AD5: 水的生产和供应 | AE5: 建筑 | AF5: 批发和零售 | AG5: 交通运输、仓储和邮政 | AH5: 住宿和餐饮 | AI5: 信息传输、软件和信息技术服务 | AJ5: 金融 | AK5: 房地产 | AL5: 租赁和商务服务 | AM5: 研究和试验发展 | AN5: 综合技术服务 | AO5: 居民服务、修理和其他服务 | AP5: 教育 | AQ5: 卫生和社会工作 | AR5: 文化、体育和娱乐 | AS5: 水利、环境和公共设施管理、公共管理、社会保障和社会组织 | AT5: 中间使用合计 | AU5: 农村居民消费支出 | AV5: 城镇居民消费支出 | AW5: 居民消费支出 | AX5: 政府消费支出 | AY5: 消费支出合计 | AZ5: 固定资本形成总额 | BA5: 存货变动 | BB5: 资本形成总额 | BC5: 出口 | BD5: 最终使用合计
B6: 部门名称 | C6: 代码 | D6: ISIC 01T03 | E6: ISIC 05 | F6: ISIC 06 | G6: ISIC 07T08 | H6: ISIC 09 | I6: ISIC 10T12 | J6: ISIC 13T15 | K6: ISIC 16 | L6: ISIC 17T18 | M6: ISIC 19 | N6: ISIC 20 | O6: ISIC 21 | P6: ISIC 22 | Q6: ISIC 231 | R6: ISIC 241 | S6: ISIC 242 | T6: ISIC 25 | U6: ISIC 28 | V6: ISIC 239 | W6: ISIC 29 | X6: ISIC 30 | Y6: ISIC 27 | Z6: ISIC 26 | AA6: ISIC 31T33 | AB6: ISIC 351 | AC6: ISIC 352T353 | AD6: ISIC 36T39 | AE6: ISIC 41T43 | AF6: ISIC 45T47 | AG6: ISIC 49T53 | AH6: ISIC 55T56 | AI6: ISIC 58T60 | AJ6: ISIC 64T66 | AK6: ISIC 68 | AL6: ISIC 61 | AM6: ISIC 64T66 | AN6: ISIC 69T82 | AO6: ISIC 97T98 | AP6: ISIC 85 | AQ6: ISIC 86T88 | AR6: ISIC 90T96 | AS6: ISIC 84 | AT6: TIU | AU6: FU101 | AV6: FU102 | AW6: THC | AX6: FU103 | AY6: TC | AZ6: FU201 | BA6: FU202 | BB6: GCF | BC6: EX | BD6: TFU | BE6: IM | BF6: GO
B7: 农林牧渔产品和服务 | C7: ISIC 01T03 | D7: 1.8313377e+08 | E7: 203490.68 | F7: 2231.1266 | G7: 30366.118 | H7: 118.5489 | I7: 4.6758672e+08 | J7: 82006169 | K7: 31973463 | L7: 53736067 | M7: 15804.36 | N7: 11513733 | O7: 44821825 | P7: 7680873.6 | Q7: 218881.19 | R7: 20627.162 | S7: 15998.126 | T7: 97311.762 | U7: 27411.881 | V7: 79539.685 | W7: 26629.608 | X7: 12565.824 | Y7: 68073.761 | Z7: 2175.5736 | AA7: 3451035.2 | AB7: 101721.23 | AC7: 1310.7869 | AD7: 0 | AE7: 18834172 | AF7: 13768.593 | AG7: 154389.97 | AH7: 53857079 | AI7: 509534.92 | AJ7: 67279.739 | AK7: 336941.13 | AL7: 7363183.4 | AM7: 4230391.8 | AN7: 1149759.6 | AO7: 2268491.1 | AP7: 612269.39 | AQ7: 605609.6 | AR7: 477755.87 | AS7: 9519615.7 | AT7: 9.5485469e+08 | AU7: 1.0974545e+08 | AV7: 2.21055e+08 | AW7: 3.3080046e+08 | AX7: 19639628 | AY7: 3.5044008e+08 | AZ7: 17577340 | BA7: 54901502 | BB7: 72478841 | BC7: 18171672 | BD7: 4.410906e+08 | BE7: 64262038 | BF7: 1.3316833e+09
B8: 煤炭开采和洗选产品 | C8: ISIC 05 | D8: 601665.54 | E8: 36204794 | F8: 63785.09 | G8: 1725453.9 | H8: 60512.779 | I8: 2167450.2 | J8: 1809485.7 | K8: 280086.13 | L8: 3698845.9 | M8: 22001120 | N8: 21794626 | O8: 436019.62 | P8: 562146.69 | Q8: 34167884 | R8: 21281683 | S8: 3302161.3 | T8: 494727.51 | U8: 360707.78 | V8: 252507.67 | W8: 48318.135 | X8: 49904.046 | Y8: 214230.21 | Z8: 20070.619 | AA8: 178085.14 | AB8: 93800322 | AC8: 2360515.5 | AD8: 0 | AE8: 843243.22 | AF8: 45563.861 | AG8: 128090.52 | AH8: 50429.81 | AI8: 0 | AJ8: 17218.23 | AK8: 63307.69 | AL8: 64.301927 | AM8: 234549.27 | AN8: 170081.94 | AO8: 326757.73 | AP8: 607785.82 | AQ8: 360760.39 | AR8: 41612.685 | AS8: 603682.15 | AT8: 2.5115017e+08 | AU8: 753293.48 | AV8: 468986.1 | AW8: 1222279.6 | AX8: 0 | AY8: 1222279.6 | AZ8: 0 | BA8: -2627614.6 | BB8: -2627614.6 | BC8: 260795.54 | BD8: -1144539.5 | BE8: 14933018 | BF8: 2.3507261e+08
B9: 石油和天然气开采产品 | C9: ISIC 06 | D9: 0 | E9: 44377.409 | F9: 535454.39 | G9: 31524.519 | H9: 15664.728 | I9: 0 | J9: 0 | K9: 0 | L9: 59261.943 | M9: 1.8788629e+08 | N9: 16889360 | O9: 26683.811 | P9: 822898.06 | Q9: 1363725.2 | R9: 372310.78 | S9: 752409.26 | T9: 586961.7 | U9: 564473.99 | V9: 372468.27 | W9: 425241.53 | X9: 143883.1 | Y9: 68067.405 | Z9: 0 | AA9: 0 | AB9: 6735286.1 | AC9: 33825564 | AD9: 0 | AE9: 0 | AF9: 0 | AG9: 487.91953 | AH9: 0 | AI9: 0 | AJ9: 0 | AK9: 0 | AL9: 0 | AM9: 2507.1572 | AN9: 0 | AO9: 0 | AP9: 0 | AQ9: 34579.89 | AR9: 1756.0257 | AS9: 48307.892 | AT9: 2.5160955e+08 | AU9: 0 | AV9: 0 | AW9: 0 | AX9: 0 | AY9: 0 | AZ9: 0 | BA9: 288640.91 | BB9: 288640.91 | BC9: 1085317.4 | BD9: 1373958.3 | BE9: 1.4529394e+08 | BF9: 1.0768957e+08
B10: 金属矿采选产品&非金属矿 | C10: ISIC 07T08 | D10: 2307.8115 | E10: 45270.046 | F10: 20550.068 | G10: 12059565 | H10: 74468.261 | I10: 62486.304 | J10: 20915.922 | K10: 14130.601 | L10: 917816.89 | M10: 351666.07 | N10: 13663939 | O10: 218560.81 | P10: 57763.344 | Q10: 51091549 | R10: 1.3243884e+08 | S10: 78502943 | T10: 6503772.5 | U10: 64839.412 | V10: 122513 | W10: 165447.68 | X10: 51425.009 | Y10: 614877.85 | Z10: 90520.249 | AA10: 56747.979 | AB10: 106588.82 | AC10: 0 | AD10: 0 | AE10: 24113819 | AF10: 60555.457 | AG10: 179268.15 | AH10: 4016.8528 | AI10: 87.113672 | AJ10: 747.23883 | AK10: 376.87524 | AL10: 1678.8514 | AM10: 333550.56 | AN10: 3880.5923 | AO10: 3727.6437 | AP10: 2965.1177 | AQ10: 1023.0554 | AR10: 5435.0281 | AS10: 31541.554 | AT10: 3.2204805e+08 | AU10: 0 | AV10: 0 | AW10: 0 | AX10: 0 | AY10: 0 | AZ10: 0 | BA10: 2801192.3 | BB10: 2801192.3 | BC10: 3333103.9 | BD10: 6134296.2 | BE10: 1.3464774e+08 | BF10: 1.935346e+08
B11: 开采辅助活动和其他采矿产品 | C11: ISIC 09 | D11: 0 | E11: 1372272.6 | F11: 16942467 | G11: 1047957.7 | H11: 177012.62 | I11: 466046.59 | J11: 0 | K11: 0 | L11: 0 | M11: 0 | N11: 0 | O11: 0 | P11: 0 | Q11: 0 | R11: 0 | S11: 0 | T11: 0 | U11: 0 | V11: 0 | W11: 0 | X11: 0 | Y11: 0 | Z11: 12.672237 | AA11: 0 | AB11: 231004.91 | AC11: 0 | AD11: 0 | AE11: 0 | AF11: 0 | AG11: 0 | AH11: 0 | AI11: 0 | AJ11: 0 | AK11: 0 | AL11: 0 | AM11: 0 | AN11: 0 | AO11: 0 | AP11: 0 | AQ11: 0 | AR11: 0 | AS11: 0 | AT11: 20236774 | AU11: 0 | AV11: 0 | AW11: 0 | AX11: 0 | AY11: 0 | AZ11: 0 | BA11: 0 | BB11: 0 | BC11: 0 | BD11: 0 | BE11: 0 | BF11: 20236774
B12: 食品和烟草 | C12: ISIC 10T12 | D12: 1.0818487e+08 | E12: 413271.66 | F12: 79328.127 | G12: 942010.65 | H12: 15471.043 | I12: 2.4937249e+08 | J12: 14128692 | K12: 1247437.6 | L12: 3016090.2 | M12: 3256002.6 | N12: 25114335 | O12: 7560676.1 | P12: 750764.12 | Q12: 1766033.1 | R12: 3822314.4 | S12: 4171930.4 | T12: 2846827.7 | U12: 4402856.9 | V12: 2451141.6 | W12: 2157646.4 | X12: 1244965.2 | Y12: 4524092.6 | Z12: 7303684.3 | AA12: 618269.9 | AB12: 5006459.1 | AC12: 538269.51 | AD12: 432454.55 | AE12: 5743107.4 | AF12: 2301664 | AG12: 7651112.8 | AH12: 1.2774375e+08 | AI12: 5595412.7 | AJ12: 2856239.9 | AK12: 4673588.7 | AL12: 16568941 | AM12: 4782871.6 | AN12: 3289851.4 | AO12: 7513197.7 | AP12: 12503171 | AQ12: 7006157.7 | AR12: 9671567.6 | AS12: 7647553.5 | AT12: 6.7966914e+08 | AU12: 1.5618843e+08 | AV12: 4.5232673e+08 | AW12: 6.0851517e+08 | AX12: 0 | AY12: 6.0851517e+08 | AZ12: 0 | BA12: 8525640.2 | BB12: 8525640.2 | BC12: 35833494 | BD12: 6.528743e+08 | BE12: 81180640 | BF12: 1.2513628e+09
B13: 纺织品、纺织服装鞋帽皮革羽绒及其制品 | C13: ISIC 13T15 | D13: 255022.54 | E13: 1536716.5 | F13: 172891.15 | G13: 431377.15 | H13: 299060.73 | I13: 3696564.2 | J13: 3.1484617e+08 | K13: 8109575.9 | L13: 21141410 | M13: 892568.3 | N13: 3692227 | O13: 4066224.9 | P13: 3366898.1 | Q13: 4050298.9 | R13: 649060.66 | S13: 445858.55 | T13: 2025532.9 | U13: 1951908.6 | V13: 1960493.2 | W13: 5639280.4 | X13: 1374959.5 | Y13: 3039653 | Z13: 3035965.5 | AA13: 4187381.8 | AB13: 864761.17 | AC13: 343622.09 | AD13: 391871.28 | AE13: 4541077.5 | AF13: 3219495.3 | AG13: 5114728.6 | AH13: 3509705.2 | AI13: 999494.99 | AJ13: 4708210.4 | AK13: 2106065.8 | AL13: 16680635 | AM13: 2606793.1 | AN13: 1524598.3 | AO13: 2503390.6 | AP13: 1549810.4 | AQ13: 9533818.8 | AR13: 4734179.3 | AS13: 25315084 | AT13: 4.7300487e+08 | AU13: 23013748 | AV13: 1.0819378e+08 | AW13: 1.3120753e+08 | AX13: 0 | AY13: 1.3120753e+08 | AZ13: 0 | BA13: -3571111.2 | BB13: -3571111.2 | BC13: 1.8680114e+08 | BD13: 3.1443756e+08 | BE13: 30055498 | BF13: 7.5738693e+08
B14: 木材加工品和家具 | C14: ISIC 16 | D14: 336188.95 | E14: 3559037.5 | F14: 156891.3 | G14: 254624.37 | H14: 6327.7151 | I14: 845240.04 | J14: 918481.02 | K14: 81780667 | L14: 90084970 | M14: 186690.2 | N14: 1302287.3 | O14: 114696.06 | P14: 708459.64 | Q14: 1957227.2 | R14: 49068.256 | S14: 185262.26 | T14: 4792477.8 | U14: 931517.23 | V14: 637156.81 | W14: 5926683.2 | X14: 652732.73 | Y14: 1177748.8 | Z14: 1019650 | AA14: 1295524.2 | AB14: 201717.8 | AC14: 4011.8598 | AD14: 3316.5085 | AE14: 57246609 | AF14: 423651.48 | AG14: 934919.87 | AH14: 196032.43 | AI14: 922455.74 | AJ14: 474744.04 | AK14: 546486.36 | AL14: 599781.95 | AM14: 50562.204 | AN14: 401102.15 | AO14: 635895.59 | AP14: 342879.72 | AQ14: 75136.026 | AR14: 319747.38 | AS14: 3983063.1 | AT14: 1.8446106e+08 | AU14: 5007508 | AV14: 17646337 | AW14: 22653845 | AX14: 0 | AY14: 22653845 | AZ14: 21595789 | BA14: 1674063.1 | BB14: 23269852 | BC14: 44765297 | BD14: 90688994 | BE14: 9736870.7 | BF14: 2.6541318e+08
B15: 造纸印刷和文教体育用品 | C15: ISIC 17T18 | D15: 1025682.3 | E15: 31068.882 | F15: 9688.6354 | G15: 315134.03 | H15: 18042.408 | I15: 13214440 | J15: 3599305.4 | K15: 2513515.7 | L15: 1.0517187e+08 | M15: 357515.63 | N15: 4061404.6 | O15: 4907967.4 | P15: 1782237.4 | Q15: 8915729.5 | R15: 89427.25 | S15: 336660.37 | T15: 1916810.8 | U15: 1926288.9 | V15: 1841924.1 | W15: 1597372.5 | X15: 344645.46 | Y15: 5512884.5 | Z15: 5349964.6 | AA15: 807927.26 | AB15: 458088.57 | AC15: 13078.613 | AD15: 21179.986 | AE15: 5313847 | AF15: 8789370.8 | AG15: 4327923.9 | AH15: 1732626.8 | AI15: 27520721 | AJ15: 20038604 | AK15: 5345538.8 | AL15: 69510376 | AM15: 2605460.1 | AN15: 5513422.2 | AO15: 1759661.7 | AP15: 12646201 | AQ15: 288424.63 | AR15: 7453946.6 | AS15: 20046565 | AT15: 3.5651903e+08 | AU15: 6120942 | AV15: 29346782 | AW15: 35467724 | AX15: 0 | AY15: 35467724 | AZ15: 4281134.6 | BA15: -8038986.6 | BB15: -3757852 | BC15: 66074535 | BD15: 97784407 | BE15: 25910671 | BF15: 4.2839277e+08
B16: 石油、炼焦产品和核燃料加工品 | C16: ISIC 19 | D16: 4991926.8 | E16: 700362.55 | F16: 395976.19 | G16: 7776692.3 | H16: 799185.8 | I16: 1015050.6 | J16: 1120310.3 | K16: 1004346.3 | L16: 1858172.8 | M16: 22688076 | N16: 63847205 | O16: 474305.06 | P16: 2190479.3 | Q16: 19987604 | R16: 42144147 | S16: 7221065.2 | T16: 3078282.8 | U16: 2035296.8 | V16: 1035075.2 | W16: 1106854 | X16: 444478.82 | Y16: 1121539.9 | Z16: 1058861.3 | AA16: 836932.65 | AB16: 10310485 | AC16: 1882494.5 | AD16: 38463.432 | AE16: 37120733 | AF16: 3295901.8 | AG16: 96331786 | AH16: 1029117.6 | AI16: 1116149.6 | AJ16: 3729490.6 | AK16: 1528256.1 | AL16: 19256951 | AM16: 1475382.6 | AN16: 12374899 | AO16: 1218116.8 | AP16: 2786127.9 | AQ16: 239725.61 | AR16: 469119.18 | AS16: 5767314 | AT16: 3.8789839e+08 | AU16: 5745628.2 | AV16: 28313585 | AW16: 34059213 | AX16: 0 | AY16: 34059213 | AZ16: 0 | BA16: -5955399.2 | BB16: -5955399.2 | BC16: 15981224 | BD16: 44085038 | BE16: 22650148 | BF16: 4.0933328e+08
B17: 化学原料和化学制品制造业&化学纤维制造业 | C17: ISIC 20 | D17: 75932742 | E17: 2724058.2 | F17: 3946860.5 | G17: 9732267.1 | H17: 1246400.1 | I17: 5072727.7 | J17: 54593583 | K17: 16223100 | L17: 51348513 | M17: 14670765 | N17: 2.9296505e+08 | O17: 11936419 | P17: 1.1027181e+08 | Q17: 31280002 | R17: 3761259 | S17: 9341339.8 | T17: 10641344 | U17: 4653059.2 | V17: 2243331.6 | W17: 6970340.2 | X17: 2118210.8 | Y17: 26478745 | Z17: 15451768 | AA17: 5086887.6 | AB17: 221438.67 | AC17: 31293.166 | AD17: 2463333.3 | AE17: 75178170 | AF17: 101065.7 | AG17: 988410.01 | AH17: 2502380.8 | AI17: 1218070.3 | AJ17: 301378.84 | AK17: 339047.64 | AL17: 4302489.1 | AM17: 14442889 | AN17: 20348720 | AO17: 13522936 | AP17: 7517280.1 | AQ17: 538883.13 | AR17: 1609725.6 | AS17: 8727065.8 | AT17: 9.0682206e+08 | AU17: 2773014.2 | AV17: 19771297 | AW17: 22544311 | AX17: 0 | AY17: 22544311 | AZ17: 0 | BA17: -17407692 | BB17: -17407692 | BC17: 66207878 | BD17: 71344496 | BE17: 1.2306996e+08 | BF17: 8.5509659e+08
B18: 医药制造业 | C18: ISIC 21 | D18: 6070961.4 | E18: 41905.124 | F18: 18810.369 | G18: 6112.285 | H18: 670.13328 | I18: 812022.34 | J18: 88147.315 | K18: 2763.5262 | L18: 656674.07 | M18: 14976.676 | N18: 1196871 | O18: 61912202 | P18: 81220.679 | Q18: 569294.79 | R18: 104789.23 | S18: 14108.632 | T18: 174018.27 | U18: 7811.941 | V18: 424487.47 | W18: 10204.664 | X18: 10869.323 | Y18: 124300.88 | Z18: 501241.91 | AA18: 124963.88 | AB18: 16580.568 | AC18: 375.41193 | AD18: 16573.363 | AE18: 2238386.7 | AF18: 10825.857 | AG18: 152802.04 | AH18: 814.26546 | AI18: 302859.27 | AJ18: 71563.525 | AK18: 15249.379 | AL18: 178518.28 | AM18: 1060731.9 | AN18: 2592341.8 | AO18: 184325.83 | AP18: 710406.22 | AQ18: 1.6382985e+08 | AR18: 24625.037 | AS18: 264315.07 | AT18: 2.4463781e+08 | AU18: 16266751 | AV18: 47595954 | AW18: 63862704 | AX18: 0 | AY18: 63862704 | AZ18: 0 | BA18: -336221.76 | BB18: -336221.76 | BC18: 22931108 | BD18: 86457591 | BE18: 31039262 | BF18: 3.0005614e+08
... B49: 中间投入合计 | C49: TII | D49: 5.0993601e+08 | E49: 1.1507411e+08 | F49: 39965777 | G49: 89225006 | H49: 11697851 | I49: 9.4434911e+08 | J49: 6.1291057e+08 | K49: 2.0981156e+08 | L49: 5.3265536e+08 | M49: 3.0874252e+08 | N49: 6.5708287e+08 | O49: 2.1422011e+08 | P49: 2.7175232e+08 | Q49: 5.0245189e+08 | R49: 5.2721563e+08 | S49: 4.0509258e+08 | T49: 3.9228391e+08 | U49: 4.0882303e+08 | V49: 2.8939979e+08 | W49: 5.6098102e+08 | X49: 1.2377234e+08 | Y49: 5.7633942e+08 | Z49: 9.9720917e+08 | AA49: 67374684 | AB49: 4.8115356e+08 | AC49: 61699159 | AD49: 20179486 | AE49: 2.140212e+09 | AF49: 5.4491128e+08 | AG49: 7.4239633e+08 | AH49: 2.8646918e+08 | AI49: 5.1722835e+08 | AJ49: 3.9319876e+08 | AK49: 2.9696594e+08 | AL49: 6.440355e+08 | AM49: 1.356294e+08 | AN49: 3.3464331e+08 | AO49: 1.4306091e+08 | AP49: 1.591954e+08 | AQ49: 2.9186652e+08 | AR49: 77833015 | AS49: 3.9682481e+08 | AT49: 1.6826058e+10 | AU49: 8.1664287e+08 | AV49: 3.0234403e+09 | AW49: 3.8400831e+09 | AX49: 1.7362538e+09 | AY49: 5.5763369e+09 | AZ49: 4.243704e+09 | BA49: 91509938 | BB49: 4.3352139e+09 | BC49: 1.8792607e+09 | BD49: 1.1790812e+10 | BE49: 1.6265915e+09 | BF49: 2.6990278e+10
A50: 增加值 | B50: 劳动者报酬 | C50: VA001 | D50: 8.2110938e+08 | E50: 49156976 | F50: 10684587 | G50: 34146732 | H50: 9070894.8 | I50: 92288060 | J50: 78070179 | K50: 25339701 | L50: 70607745 | M50: 12815275 | N50: 47509590 | O50: 30588661 | P50: 35944267 | Q50: 74959952 | R50: 39116759 | S50: 35418934 | T50: 57488356 | U50: 46988960 | V50: 51031136 | W50: 36758514 | X50: 17700419 | Y50: 47111754 | Z50: 1.0033013e+08 | AA50: 25541968 | AB50: 61395231 | AC50: 7256304.2 | AD50: 8632889.8 | AE50: 4.6964543e+08 | AF50: 5.197925e+08 | AG50: 2.3052393e+08 | AH50: 85067117 | AI50: 2.0697374e+08 | AJ50: 2.1528198e+08 | AK50: 1.9273312e+08 | AL50: 2.5275721e+08 | AM50: 65841577 | AN50: 1.1541846e+08 | AO50: 1.2768977e+08 | AP50: 2.8165049e+08 | AQ50: 1.7178319e+08 | AR50: 51172540 | AS50: 4.0760071e+08 | AT50: 5.2956554e+09
B51: 生产税净额 | C51: VA002 | D51: -45528241 | E51: 23728884 | F51: 26393586 | G51: 29203561 | H51: 1127941.3 | I51: 82927930 | J51: 1055456.5 | K51: 5439494.6 | L51: 11735860 | M51: 49155196 | N51: 37768625 | O51: 11543782 | P51: 9432919.7 | Q51: 23472867 | R51: 16809804 | S51: 20103753 | T51: 11219547 | U51: 16723538 | V51: 14548977 | W51: 41488606 | X51: 2028722 | Y51: 4541468.5 | Z51: -3678836.3 | AA51: 13432368 | AB51: 20698378 | AC51: 1010550.5 | AD51: 1860447.2 | AE51: 98116386 | AF51: 95383190 | AG51: 8513567.4 | AH51: 1360038.7 | AI51: 13092894 | AJ51: 82718116 | AK51: 1.2344272e+08 | AL51: 27690531 | AM51: 1588413.6 | AN51: 11715875 | AO51: 5023484.2 | AP51: 625840.59 | AQ51: 119102.01 | AR51: 1590021 | AS51: 2016363.5 | AT51: 8.9580223e+08
B52: 固定资产折旧 | C52: VA003 | D52: 23048580 | E52: 11857467 | F52: 23934532 | G52: 14045535 | H52: 881427.49 | I52: 30616039 | J52: 17159912 | K52: 7115541.2 | L52: 23476685 | M52: 11540323 | N52: 37261753 | O52: 7442373.5 | P52: 13681348 | Q52: 36252425 | R52: 31732256 | S52: 20256127 | T52: 17451920 | U52: 16689439 | V52: 12133973 | W52: 15404030 | X52: 3816835 | Y52: 15983410 | Z52: 35286960 | AA52: 6722131.4 | AB52: 97784316 | AC52: 5463404 | AD52: 6900167.1 | AE52: 27714364 | AF52: 1.1846713e+08 | AG52: 2.0022194e+08 | AH52: 46183808 | AI52: 1.2669418e+08 | AJ52: 36197644 | AK52: 70284261 | AL52: 35220354 | AM52: 20894697 | AN52: 47257246 | AO52: 18811001 | AP52: 77784703 | AQ52: 31476065 | AR52: 19443052 | AS52: 92345943 | AT52: 1.5058198e+09
B53: 营业盈余 | C53: VA004 | D53: 23117527 | E53: 35255171 | F53: 6711085 | G53: 26913765 | H53: -2541340.5 | I53: 1.0118166e+08 | J53: 48190809 | K53: 17706882 | L53: 55330297 | M53: 27079971 | N53: 75473751 | O53: 36261214 | P53: 27380722 | Q53: 95894758 | R53: 68635495 | S53: 43798631 | T53: 41037940 | U53: 43686016 | V53: 20237211 | W53: 51825291 | X53: 8695606.9 | Y53: 53690206 | Z53: 59374527 | AA53: 51110402 | AB53: 38471081 | AC53: 5841588 | AD53: 3105561.8 | AE53: 1.2461676e+08 | AF53: 2.1996059e+08 | AG53: 17515502 | AH53: 12909620 | AI53: 1.0125364e+08 | AJ53: 5.0197366e+08 | AK53: 3.8320744e+08 | AL53: 2859006.3 | AM53: 7602478.7 | AN53: 10750979 | AO53: 5752421.8 | AP53: 13231126 | AQ53: 4827324.6 | AR53: 5804782 | AS53: 8918362 | AT53: 2.4669426e+09
B54: 增加值合计 | C54: TVA | D54: 8.2174724e+08 | E54: 1.199985e+08 | F54: 67723790 | G54: 1.0430959e+08 | H54: 8538923.1 | I54: 3.0701369e+08 | J54: 1.4447636e+08 | K54: 55601618 | L54: 1.6115059e+08 | M54: 1.0059076e+08 | N54: 1.9801372e+08 | O54: 85836030 | P54: 86439257 | Q54: 2.3058e+08 | R54: 1.5629431e+08 | S54: 1.1957745e+08 | T54: 1.2719776e+08 | U54: 1.2408795e+08 | V54: 97951296 | W54: 1.4547644e+08 | X54: 32241583 | Y54: 1.2132684e+08 | Z54: 1.9131278e+08 | AA54: 96806870 | AB54: 2.1834901e+08 | AC54: 19571847 | AD54: 20499066 | AE54: 7.2009294e+08 | AF54: 9.5360341e+08 | AG54: 4.5677494e+08 | AH54: 1.4552058e+08 | AI54: 4.4801444e+08 | AJ54: 8.3617139e+08 | AK54: 7.6966754e+08 | AL54: 3.185271e+08 | AM54: 95927166 | AN54: 1.8514256e+08 | AO54: 1.5727667e+08 | AP54: 3.7329216e+08 | AQ54: 2.0820568e+08 | AR54: 78010395 | AS54: 5.1088137e+08 | AT54: 1.016422e+10
A55: 总投入 | C55: TI | D55: 1.3316833e+09 | E55: 2.3507261e+08 | F55: 1.0768957e+08 | G55: 1.935346e+08 | H55: 20236774 | I55: 1.2513628e+09 | J55: 7.5738693e+08 | K55: 2.6541318e+08 | L55: 6.9380595e+08 | M55: 4.0933328e+08 | N55: 8.5509659e+08 | O55: 3.0005614e+08 | P55: 3.5819158e+08 | Q55: 7.3303189e+08 | R55: 6.8350994e+08 | S55: 5.2467002e+08 | T55: 5.1948167e+08 | U55: 5.3291099e+08 | V55: 3.8735108e+08 | W55: 7.0645746e+08 | X55: 1.5601392e+08 | Y55: 6.9766625e+08 | Z55: 1.188522e+09 | AA55: 1.6418155e+08 | AB55: 6.9950257e+08 | AC55: 81271005 | AD55: 40678552 | AE55: 2.860305e+09 | AF55: 1.4985147e+09 | AG55: 1.1991713e+09 | AH55: 4.3198976e+08 | AI55: 9.6524279e+08 | AJ55: 1.2293702e+09 | AK55: 1.0666335e+09 | AL55: 9.625626e+08 | AM55: 2.3155657e+08 | AN55: 5.1978587e+08 | AO55: 3.0033759e+08 | AP55: 5.3248756e+08 | AQ55: 5.000722e+08 | AR55: 1.5584341e+08 | AS55: 9.0770619e+08 | AT55: 2.6990278e+10

Sheet 2020年非竞争型投入产出表
A2: 单位：万元
A3: 投入 产出 | D3: 部门名称 | E3: 中 间 使 用 | AV3: 最终使用 | BA3: 进口 | BB3: 总产出
E4: 农林牧渔产品和服务 | F4: 煤炭采选产品 | G4: 石油和天然气开采产品 | H4: 金属矿采选产品 | I4: 非金属矿和其他矿采选产品 | J4: 食品和烟草 | K4: 纺织品 | L4: 纺织服装鞋帽皮革羽绒及其制品 | M4: 木材加工品和家具 | N4: 造纸印刷和文教体育用品 | O4: 石油、炼焦产品和核燃料加工品 | P4: 化学产品 | Q4: 非金属矿物制品 | R4: 金属冶炼和压延加工品 | S4: 金属制品 | T4: 通用设备 | U4: 专用设备 | V4: 交通运输设备 | W4: 电气机械和器材 | X4: 通信设备、计算机和其他电子设备 | Y4: 仪器仪表 | Z4: 其他制造产品和废品废料 | AA4: 金属制品、机械和设备修理服务 | AB4: 电力、热力的生产和供应 | AC4: 燃气生产和供应 | AD4: 水的生产和供应 | AE4: 建筑 | AF4: 批发和零售 | AG4: 交通运输、仓储和邮政 | AH4: 住宿和餐饮 | AI4: 信息传输、软件和信息技术服务 | AJ4: 金融 | AK4: 房地产 | AL4: 租赁和商务服务 | AM4: 研究和试验发展 | AN4: 综合技术服务 | AO4: 水利、环境和公共设施管理 | AP4: 居民服务、修理和其他服务 | AQ4: 教育 | AR4: 卫生和社会工作 | AS4: 文化、体育和娱乐 | AT4: 公共管理、社会保障和社会组织 | AU4: 中间使用合计 | AV4: 消费支出合计 | AW4: 固定资本形成总额 | AX4: 存货变动 | AY4: 出口 | AZ4: 最终使用合计
A5: 部门名称 | D5: 代码 | E5: 1 | F5: 2 | G5: 3 | H5: 4 | I5: 5 | J5: 6 | K5: 7 | L5: 8 | M5: 9 | N5: 10 | O5: 11 | P5: 12 | Q5: 13 | R5: 14 | S5: 15 | T5: 16 | U5: 17 | V5: 18 | W5: 19 | X5: 20 | Y5: 21 | Z5: 22 | AA5: 23 | AB5: 24 | AC5: 25 | AD5: 26 | AE5: 27 | AF5: 28 | AG5: 29 | AH5: 30 | AI5: 31 | AJ5: 32 | AK5: 33 | AL5: 34 | AM5: 35 | AN5: 36 | AO5: 37 | AP5: 38 | AQ5: 39 | AR5: 40 | AS5: 41 | AT5: 42 | AU5: TIU | AV5: TC | AW5: FU201 | AX5: FU202 | AY5: EX | AZ5: TFU | BA5: M | BB5: GO
A6: 中 间 投 入 | B6: 国 产 品 | C6: 农林牧渔产品和服务 | D6: 1 | E6: 1.7917025e+08 | F6: 203217.62 | G6: 2228.1415 | H6: 16034.349 | I6: 14407.081 | J6: 4.3506509e+08 | K6: 71798944 | L6: 6572302 | M6: 26540751 | N6: 21627437 | O6: 15784.724 | P6: 62113372 | Q6: 218511.12 | R6: 36576.589 | S6: 97183.2 | T6: 26410.047 | U6: 76667.301 | V6: 37652.081 | W6: 67986.203 | X6: 2169.0763 | Y6: 0 | Z6: 3448438.2 | AA6: 0 | AB6: 101651.92 | AC6: 1309.3712 | AD6: 0 | AE6: 18534883 | AF6: 13750.402 | AG6: 154246.35 | AH6: 53819718 | AI6: 509184.06 | AJ6: 67181.716 | AK6: 336728.56 | AL6: 7358379 | AM6: 4228332 | AN6: 1149055.2 | AO6: 9513266.8 | AP6: 2266920.5 | AQ6: 611871.81 | AR6: 605248.45 | AS6: 477452.89 | AT6: 0 | AU6: 9.0690059e+08 | AV6: 3.3755251e+08 | AW6: 17159643 | AX6: 51905816 | AY6: 18164688 | AZ6: 4.2478266e+08 | BA6: 0 | BB6: 1.3316833e+09
C7: 煤炭采选产品 | D7: 2 | E7: 601617.9 | F7: 35226641 | G7: 63780.039 | H7: 391026.44 | I7: 1221705.3 | J7: 2167278.5 | K7: 1388906.4 | L7: 420436.1 | M7: 280063.96 | N7: 3244712 | O7: 18942515 | P7: 22750107 | Q7: 33972639 | R7: 23357619 | S7: 494688.33 | T7: 360679.22 | U7: 252487.68 | V7: 98080.409 | W7: 214213.25 | X7: 567.31485 | Y7: 19501.715 | Z7: 118118.65 | AA7: 59952.382 | AB7: 84805045 | AC7: 2360328.6 | AD7: 0 | AE7: 843176.46 | AF7: 10157.089 | AG7: 128080.38 | AH7: 50425.817 | AI7: 0 | AJ7: 17216.866 | AK7: 63302.677 | AL7: 64.296836 | AM7: 234530.7 | AN7: 170068.47 | AO7: 81789.675 | AP7: 326731.85 | AQ7: 607737.69 | AR7: 360731.83 | AS7: 41609.39 | AT7: 521844.67 | AU7: 2.3627018e+08 | AV7: 1222279.6 | AW7: 0 | AX7: -2652682 | AY7: 232836.33 | AZ7: -1197566.1 | BA7: 0 | BB7: 2.3507261e+08
C8: 石油和天然气开采产品 | D8: 3 | E8: 0 | F8: 33782.504 | G8: 153030.2 | H8: 16517.439 | I8: 19405.589 | J8: 0 | K8: 0 | L8: 0 | M8: 0 | N8: 45113.423 | O8: 80149568 | P8: 13266313 | Q8: 1000297.9 | R8: 856198.23 | S8: 446827.26 | T8: 429708.39 | U8: 283543.16 | V8: 433248.7 | W8: 51816.621 | X8: 0 | Y8: 0 | Z8: 0 | AA8: 0 | AB8: 983410.19 | AC8: 14728549 | AD8: 0 | AE8: 0 | AF8: 0 | AG8: 371.43095 | AH8: 0 | AI8: 0 | AJ8: 0 | AK8: 0 | AL8: 0 | AM8: 1908.5848 | AN8: 0 | AO8: 0 | AP8: 0 | AQ8: 0 | AR8: 26324.098 | AS8: 1336.7825 | AT8: 36774.602 | AU8: 1.1296404e+08 | AV8: 0 | AW8: 0 | AX8: -5545806.2 | AY8: 271329.36 | AZ8: -5274476.8 | BA8: 0 | BB8: 1.0768957e+08
C9: 金属矿采选产品 | D9: 4 | E9: 0 | F9: 0 | G9: 0 | H9: 1202119.5 | I9: 0 | J9: 0 | K9: 0 | L9: 0 | M9: 0 | N9: 0 | O9: 277126.05 | P9: 3552837.4 | Q9: 1409391.8 | R9: 99316334 | S9: 2812170.4 | T9: 0 | U9: 0 | V9: 0 | W9: 0 | X9: 0.38662646 | Y9: 0 | Z9: 10351.315 | AA9: 0 | AB9: 0 | AC9: 0 | AD9: 0 | AE9: 0 | AF9: 0 | AG9: 0 | AH9: 0 | AI9: 0 | AJ9: 0 | AK9: 0 | AL9: 0 | AM9: 234561.95 | AN9: 0 | AO9: 0 | AP9: 0 | AQ9: 0 | AR9: 0 | AS9: 0 | AT9: 0 | AU9: 1.0881489e+08 | AV9: 0 | AW9: 0 | AX9: 967878.65 | AY9: 394270.09 | AZ9: 1362148.7 | BA9: 0 | BB9: 1.1017704e+08
C10: 非金属矿和其他矿采选产品 | D10: 5 | E10: 1787.2345 | F10: 1416291.9 | G10: 16962450 | H10: 368077.9 | I10: 1528725.2 | J10: 526803.28 | K10: 11014.51 | L10: 6510.12 | M10: 12579.386 | N10: 353125.33 | O10: 31032.397 | P10: 7876240.2 | Q10: 46411463 | R10: 495334.58 | S10: 148139.27 | T10: 62466.091 | U10: 118747.37 | V10: 201417.27 | W10: 365564.09 | X10: 81910.467 | Y10: 1447.865 | Z10: 7699.0704 | AA10: 22348.9 | AB10: 334659.36 | AC10: 0 | AD10: 0 | AE10: 22596602 | AF10: 58148.764 | AG10: 174360.59 | AH10: 3905.1298 | AI10: 84.729024 | AJ10: 726.33355 | AK10: 366.49798 | AL10: 1632.6415 | AM10: 20300.344 | AN10: 3773.897 | AO10: 7106.2968 | AP10: 3624.7076 | AQ10: 2883.4311 | AR10: 994.84327 | AS10: 5285.1368 | AT10: 20894.053 | AU10: 1.0024652e+08 | AV10: 0 | AW10: 0 | AX10: 1556447.9 | AY10: 1791359.4 | AZ10: 3347807.3 | BA10: 0 | BB10: 1.0359433e+08
C11: 食品和烟草 | D11: 6 | E11: 1.0776267e+08 | F11: 412630.2 | G11: 79284.894 | H11: 536210.75 | I11: 420250.89 | J11: 2.2690422e+08 | K11: 915942.45 | L11: 12571513 | M11: 1245988.6 | N11: 1765754.5 | O11: 3255066.1 | P11: 32599559 | Q11: 1763518.9 | R11: 7992401 | S11: 2844635.3 | T11: 4400876.3 | U11: 2449313.4 | V11: 3400368.1 | W11: 4521641.8 | X11: 6650685.8 | Y11: 650020.3 | Z11: 586883.37 | AA11: 29779.677 | AB11: 5004111 | AC11: 538052.47 | AD11: 431836.34 | AE11: 5733044.9 | AF11: 2299913.5 | AG11: 7642261.5 | AH11: 1.270192e+08 | AI11: 5591128.7 | AJ11: 2852744.5 | AK11: 4668503.5 | AL11: 16504733 | AM11: 4771848.7 | AN11: 3285314.6 | AO11: 2334103.2 | AP11: 7499178.4 | AQ11: 12475783 | AR11: 6998524.9 | AS11: 9657326.5 | AT11: 5305069 | AU11: 6.543719e+08 | AV11: 5.5560896e+08 | AW11: 0 | AX11: 5627711.1 | AY11: 35754222 | AZ11: 5.969909e+08 | BA11: 0 | BB11: 1.2513628e+09
C12: 纺织品 | D12: 7 | E12: 43488.087 | F12: 87424.207 | G12: 14575.171 | H12: 27494.564 | I12: 196961.07 | J12: 559172.83 | K12: 1.3231286e+08 | L12: 1.2067889e+08 | M12: 3178377.9 | N12: 10030261 | O12: 78510.412 | P12: 6447199 | Q12: 206449.05 | R12: 169682.43 | S12: 977033.03 | T12: 306926.58 | U12: 310475.84 | V12: 974387.14 | W12: 770012.31 | X12: 453207.64 | Y12: 183476.75 | Z12: 3249332.2 | AA12: 55299.188 | AB12: 7118.2066 | AC12: 3052.1557 | AD12: 10030.42 | AE12: 99853.876 | AF12: 388343.62 | AG12: 1753307.8 | AH12: 1422872.2 | AI12: 104287.32 | AJ12: 9621.6707 | AK12: 3644.322 | AL12: 1003000.8 | AM12: 1487777 | AN12: 145816.91 | AO12: 525050.85 | AP12: 1059328.9 | AQ12: 989513.12 | AR12: 5931787.5 | AS12: 180096.12 | AT12: 2377857.1 | AU12: 2.9881386e+08 | AV12: 7886762.7 | AW12: 0 | AX12: -3937756.3 | AY12: 84065465 | AZ12: 88014472 | BA12: 0 | BB12: 3.8682833e+08
C13: 纺织服装鞋帽皮革羽绒及其制品 | D13: 8 | E13: 210633.47 | F13: 1448307.5 | G13: 158164.77 | H13: 184684.32 | I13: 319292.95 | J13: 3133192.3 | K13: 2267846.1 | L13: 51891199 | M13: 4497521 | N13: 2861528.2 | O13: 813538.19 | P13: 4580011.3 | Q13: 3841310.3 | R13: 924068.23 | S13: 1041386.3 | T13: 1575858.4 | U13: 1566622.1 | V13: 5887523.4 | W13: 2217390.1 | X13: 1933974.3 | Y13: 403676.6 | Z13: 661879.45 | AA13: 173353.44 | AB13: 857468.92 | AC13: 340524.53 | AD13: 381727.25 | AE13: 4440887.5 | AF13: 2829126.5 | AG13: 3342867.3 | AH13: 2070923.9 | AI13: 894034.86 | AJ13: 4698326.1 | AK13: 2102069.9 | AL13: 15666105 | AM13: 1109490.3 | AN13: 1377059.6 | AO13: 917893.81 | AP13: 1436099.7 | AQ13: 558356.14 | AR13: 3573065.3 | AS13: 4548449.5 | AT13: 21465210 | AU13: 1.6520265e+08 | AV13: 1.0229009e+08 | AW13: 0 | AX13: 330182.3 | AY13: 1.0273567e+08 | AZ13: 2.0535594e+08 | BA13: 0 | BB13: 3.7055859e+08
C14: 木材加工品和家具 | D14: 9 | E14: 332130.94 | F14: 3550330.9 | G14: 156719.31 | H14: 198051.28 | I14: 62167.204 | J14: 843310.18 | K14: 467472.32 | L14: 448837.7 | M14: 76271556 | N14: 7247944.9 | O14: 186390.63 | P14: 2120037.5 | Q14: 1952322.5 | R14: 233763.18 | S14: 4780108.7 | T14: 926925.34 | U14: 634753.78 | V14: 6342214.9 | W14: 1042253.9 | X14: 836533.28 | Y14: 179508.3 | Z14: 1226495.5 | AA14: 61080.559 | AB14: 201342.02 | AC14: 4006.0181 | AD14: 3311.2823 | AE14: 56675496 | AF14: 423015.44 | AG14: 933685.93 | AH14: 195764.87 | AI14: 921453.45 | AJ14: 474218.71 | AK14: 545892.77 | AL14: 599129.69 | AM14: 50502.959 | AN14: 400653.75 | AO14: 277773.49 | AP14: 614957.76 | AQ14: 342369.87 | AR14: 75000.566 | AS14: 319061.64 | AT14: 3700725.2 | AU14: 1.7685927e+08 | AV14: 20775877 | AW14: 21433220 | AX14: 1628055 | AY14: 44716757 | AZ14: 88553910 | BA14: 0 | BB14: 2.6541318e+08
C15: 造纸印刷和文教体育用品 | D15: 10 | E15: 1022496.5 | F15: 30868.985 | G15: 9609.925 | H15: 125389.01 | I15: 203568.73 | J15: 12906419 | K15: 1361001.5 | L15: 2063602.9 | M15: 2464017.9 | N15: 88553261 | O15: 355036.63 | P15: 10161959 | Q15: 8734267.1 | R15: 417716.71 | S15: 1889707.1 | T15: 1884090.2 | U15: 1781517.1 | V15: 1890921.9 | W15: 5344053.9 | X15: 4608187.4 | Y15: 421461.91 | Z15: 771772.28 | AA15: 13315.011 | AB15: 457287.87 | AC15: 12994.95 | AD15: 21057 | AE15: 5227867.1 | AF15: 8764359.5 | AG15: 4300950.8 | AH15: 1708148.2 | AI15: 27363936 | AJ15: 19939324 | AK15: 5315785.6 | AL15: 68827944 | AM15: 2588639.6 | AN15: 5439646.4 | AO15: 1042583.1 | AP15: 1726186.5 | AQ15: 12542495 | AR15: 286946.12 | AS15: 7224086.1 | AT15: 18858989 | AU15: 3.3866347e+08 | AV15: 28657313 | AW15: 3814474.6 | AX15: -8388396.3 | AY15: 65645907 | AZ15: 89729298 | BA15: 0 | BB15: 4.2839277e+08
C16: 石油、炼焦产品和核燃料加工品 | D16: 11 | E16: 4960667.8 | F16: 699976.68 | G16: 108440.98 | H16: 3644928.5 | I16: 4925874.3 | J16: 1014363.1 | K16: 514658.91 | L16: 591987.1 | M16: 1003761.9 | N16: 691591.53 | O16: 19043682 | P16: 59323183 | Q16: 19288553 | R16: 46663769 | S16: 3073329.5 | T16: 1912452.8 | U16: 924059.07 | V16: 1239212.6 | W16: 1119900.1 | X16: 732962.72 | Y16: 264213.98 | Z16: 551859.2 | AA16: 254526.58 | AB16: 10106707 | AC16: 1260421.3 | AD16: 38446.012 | AE16: 36611751 | AF16: 3294124.4 | AG16: 96255240 | AH16: 1028558 | AI16: 1115623.3 | AJ16: 3727565.8 | AK16: 1527462.9 | AL16: 19247081 | AM16: 1474687.2 | AN16: 12369335 | AO16: 1244053.8 | AP16: 1110772.2 | AQ16: 2784873.9 | AR16: 239595.59 | AS16: 468840.74 | AT16: 4520617.9 | AU16: 3.7097371e+08 | AV16: 31195286 | AW16: 0 | AX16: -6679553 | AY16: 13843840 | AZ16: 38359573 | BA16: 0 | BB16: 4.0933328e+08
C17: 化学产品 | D17: 12 | E17: 89670083 | F17: 3259253.3 | G17: 3451485.9 | H17: 4140765.9 | I17: 8012297 | J17: 16509361 | K17: 40278014 | L17: 21654400 | M17: 19015341 | N17: 48400074 | O17: 13647639 | P17: 4.691546e+08 | Q17: 37002605 | R17: 13476319 | S17: 15681412 | T17: 11722314 | U17: 11204182 | V17: 34388009 | W17: 47326114 | X17: 25815771 | Y17: 1716763.3 | Z17: 7285541.9 | AA17: 363727.1 | AB17: 263731.22 | AC17: 80180.883 | AD17: 3071514.9 | AE17: 1.1054536e+08 | AF17: 2761408.3 | AG17: 12358590 | AH17: 3597338.2 | AI17: 2929183.8 | AJ17: 448289.86 | AK17: 728858.81 | AL17: 7607179.9 | AM17: 15479755 | AN17: 23738608 | AO17: 7991999.9 | AP17: 16180214 | AQ17: 8190649 | AR17: 1.6195067e+08 | AS17: 1755663.9 | AT17: 2790590.1 | AU17: 1.3256459e+09 | AV17: 62694983 | AW17: 0 | AX17: -20698406 | AY17: 1.4570187e+08 | AZ17: 1.8769845e+08 | BA17: 0 | BB17: 1.5133443e+09
C18: 非金属矿物制品 | D18: 13 | E18: 526987.91 | F18: 635523.53 | G18: 37755.329 | H18: 292329.41 | I18: 1918421.1 | J18: 4860795.3 | K18: 389193.28 | L18: 169652.31 | M18: 1826943.9 | N18: 718768.88 | O18: 2701727.6 | P18: 8005894 | Q18: 1.3497831e+08 | R18: 15032339 | S18: 6656897.7 | T18: 2734823.3 | U18: 3800896.9 | V18: 10053978 | W18: 18641450 | X18: 13269343 | Y18: 2556673.8 | Z18: 350345.1 | AA18: 100343.31 | AB18: 1957304.5 | AC18: 7322.509 | AD18: 22818.423 | AE18: 4.5331132e+08 | AF18: 178172.3 | AG18: 460559.45 | AH18: 357391.98 | AI18: 90804.452 | AJ18: 23646.827 | AK18: 32569.89 | AL18: 258306.19 | AM18: 2224772.8 | AN18: 198112.83 | AO18: 808793.48 | AP18: 95123.653 | AQ18: 1123412.4 | AR18: 318440.43 | AS18: 4786.0371 | AT18: 12841.051 | AU18: 6.917459e+08 | AV18: 4940391.9 | AW18: 0 | AX18: 2132017.3 | AY18: 34213578 | AZ18: 41285987 | BA18: 0 | BB18: 7.3303189e+08
... C47: 公共管理、社会保障和社会组织 | D47: 42 | E47: 412974.9 | F47: 65743.863 | G47: 22347.217 | H47: 28375.532 | I47: 36069.178 | J47: 254121.5 | K47: 152277.22 | L47: 124060.4 | M47: 76383.151 | N47: 124585.28 | O47: 62260.665 | P47: 583445.56 | Q47: 417731.79 | R47: 207787.18 | S47: 232464.64 | T47: 223677.46 | U47: 184715.29 | V47: 218431.06 | W47: 149584.82 | X47: 248419.19 | Y47: 21026.199 | Z47: 114116.38 | AA47: 19669.288 | AB47: 225574.63 | AC47: 22478.457 | AD47: 35179.289 | AE47: 429940.98 | AF47: 269257.79 | AG47: 582867.28 | AH47: 129226.2 | AI47: 475134.93 | AJ47: 668175.12 | AK47: 1309922 | AL47: 1300376 | AM47: 184314.69 | AN47: 535713.25 | AO47: 125873.88 | AP47: 165905.71 | AQ47: 910963.87 | AR47: 142966.22 | AS47: 159954.51 | AT47: 18709625 | AU47: 30363717 | AV47: 7.6244424e+08 | AW47: 0 | AX47: 0 | AY47: 1734244.2 | AZ47: 7.6417849e+08 | BA47: 0 | BB47: 7.9454221e+08
B48: 进 口 品 | C48: 农林牧渔产品和服务 | D48: 1 | E48: 3963522.8 | F48: 273.06353 | G48: 2.9851004 | H48: 23.010679 | I48: 20.226381 | J48: 32521630 | K48: 3574299.6 | L48: 60624.047 | M48: 5432711.6 | N48: 135167.14 | O48: 19.636457 | P48: 1903059.7 | Q48: 370.06739 | R48: 48.698973 | S48: 128.56167 | T48: 1001.8343 | U48: 2872.3845 | V48: 1543.3511 | W48: 87.557591 | X48: 6.4973378 | Y48: 0 | Z48: 2596.945 | AA48: 0 | AB48: 69.314798 | AC48: 1.415745 | AD48: 0 | AE48: 299288.82 | AF48: 18.191226 | AG48: 143.61677 | AH48: 37360.976 | AI48: 350.85922 | AJ48: 98.023466 | AK48: 212.57306 | AL48: 4804.3509 | AM48: 2059.8218 | AN48: 704.3809 | AO48: 6348.8407 | AP48: 1570.5706 | AQ48: 397.5743 | AR48: 361.15159 | AS48: 302.97624 | AT48: 0 | AU48: 47954103 | AV48: 12887569 | AW48: 417696.23 | AX48: 2995685.1 | AY48: 6984.3999 | AZ48: 16307934 | BA48: 64262038 | BB48: 0
C49: 煤炭采选产品 | D49: 2 | E49: 47.640725 | F49: 978152.41 | G49: 5.0505932 | H49: 173138.14 | I49: 96.744008 | J49: 171.62176 | K49: 109.98427 | L49: 33.293359 | M49: 22.177615 | N49: 174047.74 | O49: 3058605.1 | P49: 42685.733 | Q49: 195245.64 | R49: 1226225 | S49: 39.17322 | T49: 28.56135 | U49: 19.993913 | V49: 141.77191 | W49: 16.96305 | X49: 0.044924346 | Y49: 1.5442955 | Z49: 9.3535418 | AA49: 4.74749 | AB49: 8995276.9 | AC49: 186.90894 | AD49: 0 | AE49: 66.769186 | AF49: 35406.772 | AG49: 10.142388 | AH49: 3.9931034 | AI49: 0 | AJ49: 1.3633637 | AK49: 5.012792 | AL49: 0.0050915172 | AM49: 18.571941 | AN49: 13.467327 | AO49: 6.4767345 | AP49: 25.873137 | AQ49: 48.125337 | AR49: 28.565516 | AS49: 3.294951 | AT49: 41.323668 | AU49: 14879992 | AV49: 0 | AW49: 0 | AX49: 25067.339 | AY49: 27959.206 | AZ49: 53026.545 | BA49: 14933018 | BB49: 0
C50: 石油和天然气开采产品 | D50: 3 | E50: 0 | F50: 10594.905 | G50: 382424.19 | H50: 5180.217 | I50: 6086.0018 | J50: 0 | K50: 0 | L50: 0 | M50: 0 | N50: 14148.52 | O50: 1.0773673e+08 | P50: 4472628.9 | Q50: 363427.28 | R50: 268521.81 | S50: 140134.44 | T50: 134765.61 | U50: 88925.111 | V50: 135875.92 | W50: 16250.784 | X50: 0 | Y50: 0 | Z50: 0 | AA50: 0 | AB50: 5751876 | AC50: 19097015 | AD50: 0 | AE50: 0 | AF50: 0 | AG50: 116.48857 | AH50: 0 | AI50: 0 | AJ50: 0 | AK50: 0 | AL50: 0 | AM50: 598.5724 | AN50: 0 | AO50: 0 | AP50: 0 | AQ50: 0 | AR50: 8255.792 | AS50: 419.24318 | AT50: 11533.29 | AU50: 1.386455e+08 | AV50: 0 | AW50: 0 | AX50: 5834447.1 | AY50: 813988.07 | AZ50: 6648435.2 | BA50: 1.4529394e+08 | BB50: 0
C51: 金属矿采选产品 | D51: 4 | E51: 0 | F51: 0 | G51: 0 | H51: 9770150.6 | I51: 0 | J51: 0 | K51: 0 | L51: 0 | M51: 0 | N51: 0 | O51: 42630.692 | P51: 1339759.5 | Q51: 450173.09 | R51: 1.1110091e+08 | S51: 3538835.3 | T51: 0 | U51: 0 | V51: 0 | W51: 0 | X51: 0.059566953 | Y51: 0 | Z51: 1594.7175 | AA51: 0 | AB51: 0 | AC51: 0 | AD51: 0 | AE51: 0 | AF51: 0 | AG51: 0 | AH51: 0 | AI51: 0 | AJ51: 0 | AK51: 0 | AL51: 0 | AM51: 78114.008 | AN51: 0 | AO51: 0 | AP51: 0 | AQ51: 0 | AR51: 0 | AS51: 0 | AT51: 0 | AU51: 1.2632217e+08 | AV51: 0 | AW51: 0 | AX51: 276865.75 | AY51: 1108905.5 | AZ51: 1385771.3 | BA51: 1.2770794e+08 | BB51: 0
C52: 非金属矿和其他矿采选产品 | D52: 5 | E52: 520.57704 | F52: 1250.6991 | G52: 567.5633 | H52: 1828.985 | I52: 488101.28 | J52: 1729.6079 | K52: 3131.9981 | L52: 259.29414 | M52: 1551.215 | N52: 550560.96 | O52: 876.93658 | P52: 1171426.5 | Q52: 2820520.5 | R52: 29205.41 | S52: 4627.5523 | T52: 2373.3218 | U52: 3765.6311 | V52: 15455.414 | W52: 249313.76 | X52: 2718.8455 | Y52: 4455.2983 | Z52: 14124.341 | AA52: 629.63532 | AB52: 2934.366 | AC52: 0 | AD52: 0 | AE52: 1517216.4 | AF52: 2406.6932 | AG52: 4907.5541 | AH52: 111.72298 | AI52: 2.3846478 | AJ52: 20.905277 | AK52: 10.377261 | AL52: 46.209888 | AM52: 574.2548 | AN52: 106.69527 | AO52: 2948.1115 | AP52: 102.93615 | AQ52: 81.686659 | AR52: 28.212175 | AS52: 149.89122 | AT52: 593.09246 | AU52: 6901236.8 | AV52: 0 | AW52: 0 | AX52: 0 | AY52: 38568.851 | AZ52: 38568.851 | BA52: 6939805.6 | BB52: 0
C53: 食品和烟草 | D53: 6 | E53: 422192.93 | F53: 641.45671 | G53: 43.2333 | H53: 661.90552 | I53: 358.14448 | J53: 22468274 | K53: 1619.4521 | L53: 639616.69 | M53: 1449.0336 | N53: 2898.0582 | O53: 936.41669 | P53: 826216.08 | Q53: 2514.1979 | R53: 1843.8539 | S53: 2192.3602 | T53: 1980.5838 | U53: 1828.1205 | V53: 2243.4706 | W53: 2450.8529 | X53: 2651.0749 | Y53: 327.14198 | Z53: 1494.4655 | AA53: 112.38585 | AB53: 2348.1209 | AC53: 217.0432 | AD53: 618.203 | AE53: 10062.5 | AF53: 1750.5571 | AG53: 8851.2886 | AH53: 724548.11 | AI53: 4284.0648 | AJ53: 3495.3334 | AK53: 5085.2657 | AL53: 64208.055 | AM53: 11022.898 | AN53: 4536.7829 | AO53: 5394.5518 | AP53: 14019.289 | AQ53: 27388.337 | AR53: 7632.7437 | AS53: 14241.126 | AT53: 2986.7741 | AU53: 25297237 | AV53: 52906201 | AW53: 0 | AX53: 2897929.1 | AY53: 79272.378 | AZ53: 55883402 | BA53: 81180640 | BB53: 0
C54: 纺织品 | D54: 7 | E54: 301.04836 | F54: 840.68622 | G54: 138.24362 | H54: 254.46784 | I54: 1728.7694 | J54: 4053.3998 | K54: 4502513.4 | L54: 1948489.1 | M54: 271326.17 | N54: 121570.77 | O54: 452.93549 | P54: 94786.222 | Q54: 2357.8312 | R54: 1092.5536 | S54: 3318.3197 | T54: 68631.136 | U54: 82292.306 | V54: 97195.263 | W54: 50164.129 | X54: 29887.15 | Y54: 10085.171 | Z54: 44964.413 | AA54: 595.24387 | AB54: 76.352062 | AC54: 30.331622 | AD54: 102.92602 | AE54: 189.75582 | AF54: 1661.1991 | AG54: 18174.622 | AH54: 15657.712 | AI54: 1043.696 | AJ54: 93.671214 | AK54: 28.055076 | AL54: 10793.679 | AM54: 9423.0985 | AN54: 1561.5352 | AO54: 1781.1733 | AP54: 7569.5482 | AQ54: 1893.4248 | AR54: 28783.803 | AS54: 5017.4648 | AT54: 20847.4 | AU54: 7461768.1 | AV54: 2902030.2 | AW54: 0 | AX54: 28840.896 | AY54: 0 | AZ54: 2930871.1 | BA54: 10392639 | BB54: 0
C55: 纺织服装鞋帽皮革羽绒及其制品 | D55: 8 | E55: 599.94129 | F55: 144.04502 | G55: 12.965851 | H55: 8.8228693 | I55: 12.914267 | J55: 145.59966 | K55: 1030.5203 | L55: 1243338.1 | M55: 162350.77 | N55: 18474.494 | O55: 66.763065 | P55: 3353.4975 | Q55: 181.73842 | R55: 75.996887 | S55: 3795.3306 | T55: 492.54691 | U55: 1102.9486 | V55: 55134.106 | W55: 2086.4551 | X55: 861.00264 | Y55: 20796.922 | Z55: 1942.5025 | AA55: 15.396142 | AB55: 97.691077 | AC55: 15.071929 | AD55: 10.691061 | AE55: 146.33082 | AF55: 363.98237 | AG55: 378.86684 | AH55: 251.40637 | AI55: 129.11639 | AJ55: 168.93609 | AK55: 323.54332 | AL55: 734.78484 | AM55: 102.74531 | AN55: 160.23795 | AO55: 145.04343 | AP55: 392.49887 | AQ55: 47.684562 | AR55: 182.22745 | AS55: 616.15815 | AT55: 6298.8779 | AU55: 1526589.2 | AV55: 18128647 | AW55: 0 | AX55: 7621.9601 | AY55: 0 | AZ55: 18136269 | BA55: 19662858 | BB55: 0
C56: 木材加工品和家具 | D56: 9 | E56: 4058.0065 | F56: 8706.6142 | G56: 171.98217 | H56: 570.69277 | I56: 162.913 | J56: 1929.8569 | K56: 1047.1547 | L56: 1123.8405 | M56: 5509110.9 | N56: 1056358.3 | O56: 299.57504 | P56: 5405.5303 | Q56: 4904.7262 | R56: 567.3379 | S56: 12369.104 | T56: 4591.8866 | U56: 2403.0318 | V56: 237201.04 | W56: 135494.93 | X56: 2873.4658 | Y56: 734.96567 | Z56: 7842.1122 | AA56: 106.03255 | AB56: 375.77623 | AC56: 5.841705 | AD56: 5.2262074 | AE56: 571112.98 | AF56: 636.04146 | AG56: 1233.9385 | AH56: 267.56176 | AI56: 1002.2932 | AJ56: 525.3295 | AK56: 593.59045 | AL56: 652.26473 | AM56: 59.244627 | AN56: 448.39508 | AO56: 490.95519 | AP56: 20937.836 | AQ56: 509.84566 | AR56: 135.45991 | AS56: 685.74344 | AT56: 4073.4269 | AU56: 7601785.8 | AV56: 1877967.9 | AW56: 162569.17 | AX56: 46008.128 | AY56: 48539.619 | AZ56: 2135084.8 | BA56: 9736870.7 | BB56: 0
C57: 造纸印刷和文教体育用品 | D57: 10 | E57: 3185.761 | F57: 199.89671 | G57: 78.710415 | H57: 598.84788 | I57: 3619.847 | J57: 308020.46 | K57: 52290.815 | L57: 122410.26 | M57: 49497.778 | N57: 14105095 | O57: 2478.9988 | P57: 589650.34 | Q57: 181462.47 | R57: 8370.9088 | S57: 27103.7 | T57: 42198.739 | U57: 60407.05 | V57: 51096.07 | W57: 168830.56 | X57: 310264.58 | Y57: 10050.692 | Z57: 22682.703 | AA57: 157.27247 | AB57: 800.69321 | AC57: 83.662867 | AD57: 122.98643 | AE57: 85979.886 | AF57: 25011.283 | AG57: 26973.019 | AH57: 24478.577 | AI57: 156784.95 | AJ57: 99280.368 | AK57: 29753.142 | AL57: 682431.79 | AM57: 16820.552 | AN57: 73775.735 | AO57: 2227.1063 | AP57: 33475.139 | AQ57: 103706.1 | AR57: 1478.5158 | AS57: 229860.5 | AT57: 142765.86 | AU57: 17855561 | AV57: 6810411.1 | AW57: 466659.99 | AX57: 349409.72 | AY57: 428628.64 | AZ57: 8055109.5 | BA57: 25910671 | BB57: 0
C58: 石油、炼焦产品和核燃料加工品 | D58: 11 | E58: 31258.977 | F58: 385.87313 | G58: 287535.21 | H58: 2444.2147 | I58: 2631.1348 | J58: 687.50389 | K58: 12584.521 | L58: 1079.7835 | M58: 584.37907 | N58: 162235.04 | O58: 3644393.5 | P58: 7188806.5 | Q58: 699051.08 | R58: 2701443.3 | S58: 4953.273 | T58: 122844.05 | U58: 111016.13 | V58: 312120.28 | W58: 1639.7978 | X58: 42556.363 | Y58: 19128.248 | Z58: 235.62054 | AA58: 30311.256 | AB58: 203778.12 | AC58: 622073.16 | AD58: 17.419778 | AE58: 508982.14 | AF58: 1777.4079 | AG58: 76546.472 | AH58: 559.55312 | AI58: 526.23618 | AJ58: 1924.7415 | AK58: 793.24969 | AL58: 9870.09 | AM58: 695.3819 | AN58: 5563.9924 | AO58: 574.78567 | AP58: 107344.57 | AQ58: 1253.9917 | AR58: 130.01969 | AS58: 278.43703 | AT58: 2067.506 | AU58: 16924683 | AV58: 2863926.6 | AW58: 0 | AX58: 724153.74 | AY58: 2137384.5 | AZ58: 5725464.9 | BA58: 22650148 | BB58: 0
C59: 化学产品 | D59: 12 | E59: 1008187.7 | F59: 61500.326 | G59: 582713.87 | H59: 359091.92 | I59: 212357.68 | J59: 1216603.7 | K59: 2312247 | L59: 1417284 | M59: 1124864.9 | N59: 2112886.2 | O59: 2468486.1 | P59: 95282909 | Q59: 1403722.1 | R59: 618915.31 | S59: 428995.11 | T59: 909727.16 | U59: 1127333.1 | V59: 3659660 | W59: 5595006.8 | X59: 7567523 | Y59: 1239718.9 | Z59: 781525.42 | AA59: 12228.517 | AB59: 7752.5998 | AC59: 1093.6324 | AD59: 107388.4 | AE59: 1570737.8 | AF59: 142547.17 | AG59: 64467.382 | AH59: 10990.613 | AI59: 26961.842 | AJ59: 9064.6421 | AK59: 6566.0785 | AL59: 109355.06 | AM59: 1103217.7 | AN59: 840838.67 | AO59: 268719.57 | AP59: 248456.81 | AQ59: 93447.796 | AR59: 2960069.8 | AS59: 138568.87 | AT59: 11201.423 | AU59: 1.3922493e+08 | AV59: 30132797 | AW59: 0 | AX59: 1048655.7 | AY59: 557722.18 | AZ59: 31739175 | BA59: 1.7096411e+08 | BB59: 0
C60: 非金属矿物制品 | D60: 13 | E60: 684.26297 | F60: 15789.663 | G60: 6836.1544 | H60: 38315.395 | I60: 42665.008 | J60: 27304.625 | K60: 7810.4306 | L60: 4568.9482 | M60: 94232.274 | N60: 191079.81 | O60: 23259.616 | P60: 499938.97 | Q60: 4165319.9 | R60: 318299.44 | S60: 127061.11 | T60: 138920.99 | U60: 265614.04 | V60: 570541.58 | W60: 593564.11 | X60: 2755079.3 | Y60: 130743.58 | Z60: 34843.849 | AA60: 240.55959 | AB60: 34319.921 | AC60: 18.003928 | AD60: 27.973621 | AE60: 1316337.5 | AF60: 63075.661 | AG60: 932.29308 | AH60: 675.31521 | AI60: 491.942 | AJ60: 50.990968 | AK60: 124.14007 | AL60: 2213.2676 | AM60: 43836.98 | AN60: 435.1131 | AO60: 10699.253 | AP60: 676.10346 | AQ60: 7207.8868 | AR60: 7279.5798 | AS60: 3.9433488 | AT60: 32.993866 | AU60: 11541153 | AV60: 546263.3 | AW60: 0 | AX60: 8678.9918 | AY60: 340626.19 | AZ60: 895568.48 | BA60: 12436721 | BB60: 0
... C78: 信息传输、软件和信息技术服务 | D78: 31 | E78: 1063.6626 | F78: 376.89583 | G78: 122.50321 | H78: 430.37762 | I78: 532.17543 | J78: 16407.784 | K78: 5651.1123 | L78: 10464.125 | M78: 2631.1205 | N78: 13478.911 | O78: 1333.5401 | P78: 30954.866 | Q78: 4391.2777 | R78: 8101.5863 | S78: 5176.3181 | T78: 20432.499 | U78: 8494.2743 | V78: 18814.568 | W78: 21752.632 | X78: 208698.58 | Y78: 3108.1902 | Z78: 408.15519 | AA78: 311.30479 | AB78: 880.56714 | AC78: 132.87158 | AD78: 126.02458 | AE78: 1452.6816 | AF78: 118301.24 | AG78: 109431.19 | AH78: 5256.529 | AI78: 3078211.5 | AJ78: 106762.63 | AK78: 1903.8136 | AL78: 205764.19 | AM78: 14148.657 | AN78: 59077.194 | AO78: 322.13628 | AP78: 8060.218 | AQ78: 8052.6143 | AR78: 533.36499 | AS78: 34164.695 | AT78: 79530.487 | AU78: 4215249 | AV78: 512641.74 | AW78: 22923657 | AX78: 0 | AY78: 0 | AZ78: 23436299 | BA78: 27651548 | BB78: 0
C79: 金融 | D79: 32 | E79: 61269.772 | F79: 41413.36 | G79: 12224.98 | H79: 9391.2453 | I79: 9682.6287 | J79: 38041.587 | K79: 25123.417 | L79: 12709.311 | M79: 14397.053 | N79: 39546.132 | O79: 33653.699 | P79: 149485.22 | Q79: 88726.182 | R79: 214795.69 | S79: 60024.883 | T79: 44353.669 | U79: 48270.194 | V79: 44267.045 | W79: 61139.103 | X79: 111265.14 | Y79: 9340.7068 | Z79: 9645.2702 | AA79: 1680.7673 | AB79: 97144.709 | AC79: 9669.1681 | AD79: 7698.3323 | AE79: 513696.62 | AF79: 304523.13 | AG79: 342374.21 | AH79: 11320.898 | AI79: 69849.571 | AJ79: 4524299.6 | AK79: 487168.5 | AL79: 404815.22 | AM79: 8079.7822 | AN79: 85549.356 | AO79: 63175.992 | AP79: 29088.473 | AQ79: 40850.837 | AR79: 13193.046 | AS79: 9231.9784 | AT79: 108142.57 | AU79: 8270319 | AV79: 2292800.9 | AW79: 0 | AX79: 0 | AY79: 0 | AZ79: 2292800.9 | BA79: 10563120 | BB79: 0
C80: 房地产 | D80: 33 | E80: 0 | F80: 0 | G80: 0 | H80: 0 | I80: 0 | J80: 0 | K80: 0 | L80: 0 | M80: 0 | N80: 0 | O80: 0 | P80: 0 | Q80: 0 | R80: 0 | S80: 0 | T80: 0 | U80: 0 | V80: 0 | W80: 0 | X80: 0 | Y80: 0 | Z80: 0 | AA80: 0 | AB80: 0 | AC80: 0 | AD80: 0 | AE80: 0 | AF80: 0 | AG80: 0 | AH80: 0 | AI80: 0 | AJ80: 0 | AK80: 0 | AL80: 0 | AM80: 0 | AN80: 0 | AO80: 0 | AP80: 0 | AQ80: 0 | AR80: 0 | AS80: 0 | AT80: 0 | AU80: 0 | AV80: 0 | AW80: 0 | AX80: 0 | AY80: 0 | AZ80: 0 | BA80: 0 | BB80: 0
C81: 租赁和商务服务 | D81: 34 | E81: 26639.584 | F81: 41568.878 | G81: 7241.7311 | H81: 11600.452 | I81: 11524.021 | J81: 1877914 | K81: 205775.4 | L81: 611908.63 | M81: 198693.35 | N81: 636024.35 | O81: 343881 | P81: 2443298 | Q81: 767030.99 | R81: 467603.17 | S81: 522007.19 | T81: 711948.53 | U81: 641691.51 | V81: 1233154.9 | W81: 822693.79 | X81: 1163113.2 | Y81: 86982.797 | Z81: 63465.629 | AA81: 27102.716 | AB81: 75900.361 | AC81: 29310.094 | AD81: 6824.5289 | AE81: 257287.25 | AF81: 4461164.7 | AG81: 1062823.5 | AH81: 325759.32 | AI81: 1808702.7 | AJ81: 603665.91 | AK81: 390690.31 | AL81: 4457490.2 | AM81: 211700.18 | AN81: 699970.43 | AO81: 17903.377 | AP81: 210033.2 | AQ81: 168075.84 | AR81: 72465.414 | AS81: 485166.59 | AT81: 1076770.9 | AU81: 29344569 | AV81: 1092617.4 | AW81: 0 | AX81: 0 | AY81: 0 | AZ81: 1092617.4 | BA81: 30437186 | BB81: 0
