Workbook
Name CH4_Ar4_to_AR5: #REF!
Name CH4_Ar4_to_AR5: #REF!
Name CH4_Ar4_to_AR5: #REF!
Name CH4_Ar4_to_AR5: [1]Overview!$B$25
Name CH4_to_CO2e: #REF!
Name CH4_to_CO2e: #REF!
Name CH4_to_CO2e: #REF!
Name CH4_to_CO2e: #REF!
Name dollars_2009_2012: #REF!
Name dollars_2009_2012: #REF!
Name dollars_2009_2012: #REF!
Name dollars_2009_2012: About!$B$117
Name gal_per_barrel: #REF!
Name gal_per_barrel: #REF!
Name gal_per_barrel: #REF!
Name gal_per_barrel: [2]About!$A$63
Name Gg_to_grams: #REF!
Name HFC125_AR5: #REF!
Name HFC134a_AR5: #REF!
Name HFC143a_AR5: #REF!
Name HFC152a_AR5: #REF!
Name HFC245fa_AR5: #REF!
Name HFC32_AR5: #REF!
Name HHV_Adjust: #REF!
Name HHV_Adjust: #REF!
Name HHV_Adjust: #REF!
Name HHV_Adjust: [3]About!$A$203
Name IQ_CH: 110000
Name IQ_CQ: 5000
Name IQ_CY: 10000
Name IQ_DAILY: 500000
Name IQ_FH: 100000
Name IQ_FQ: 500
Name IQ_FY: 1000
Name IQ_LTM: 2000
Name IQ_MONTH: 15000
Name IQ_NTM: 6000
Name IQ_WEEK: 50000
Name IQ_YTD: 3000
Name metricton_to_shortton: #REF!
Name metricton_to_shortton: #REF!
Name metricton_to_shortton: #REF!
Name metricton_to_shortton: [4]Overview!$B$19
Name million: #REF!
Name million: #REF!
Name million: #REF!
Name million: [4]Overview!$B$22
Name N2O_AR4_to_AR5: #REF!
Name N2O_AR4_to_AR5: #REF!
Name N2O_AR4_to_AR5: #REF!
Name N2O_AR4_to_AR5: About!$A$88
Name N2O_to_CO2e: #REF!
Name N2O_to_CO2e: #REF!
Name N2O_to_CO2e: #REF!
Name N2O_to_CO2e: '[5]Cross-Page Data'!$C$13
Name unit_conv: #REF!
Name unit_conv: #REF!
Name unit_conv: #REF!
Name unit_conv: [6]About!$A$108

Sheet About
A1: BPE BAU Process Emissions
A2: BPE Share of Agriculture Process Emissions from Animals
A4: Sources: | B4: Greenhouse Gas Inventory 2018 | D4: Non-CO2 Process Emissions for All Countries (Present and Projections)
B5: Ministry of Ecology and Environment, PRC 中华人民共和国生态环境部 | D5: U.S. EPA
B6: 2023 | D6: 2019
B7: The People's Republic of China Third Biennial Update Report on Climate Change | D7: Global Non-CO2 Greenhouse Gas Emission Projections & Mitigation Potential: 2015-2050
B8: 中华人民共和国气候变化第三次两年更新报告 | D8: https://www.epa.gov/global-mitigation-non-co2-greenhouse-gases/global-non-co2-greenhouse-gas-emission-projections
B9: W020231229717236049262.pdf | D9: Non-CO2 Report Data Annex (data vintage 9/30/2019)
B10: Table 1-10, 1-11
D11: CO2 Process Emissions for All Countries (Present)
B12: Greenhouse Gas Inventory 2020 & 2021 | D12: Potsdam Institute for Climate Impact Research
B13: Ministry of Ecology and Environment, PRC 中华人民共和国生态环境部 | D13: 2021
B14: 2024 | D14: The PRIMAP-hist national historical emissions time series (1750-2019) v2.3
B15: The People's Republic of China's First Biennial Transparency Report on Climate Change | D15: https://zenodo.org/record/5175154
B16: 中华人民共和国气候变化第一次双年透明度报告
B17: 中华人民共和国气候变化第一次双年透明度报告.pdf | D17: Cement, Steel, Plastics Production Projections Used to Scale Process CO2 Emissions
D18: Energy Transitions Commission
D19: 2018
B20: The major products production in China for predicting GHGs Process Emissions | D20: Mission Possible: Reachign Net-Zero Carbon Emissions from Harder-to-Abate Sectors by Mid-Century
B21: For Coal：Sinopec 中石化 | D21: http://www.energy-transitions.org/sites/default/files/ETC_MissionPossible_FullReport.pdf
B22: 2024 | D22: Page 56, Exhibits 2.1 and 2.2, and page 57, Exhibit 2.3
B23: China Energy Outlook 2060 (2024 Edition) 中国能源展望2060
B24: https://www.cpnn.com.cn/news/baogao2023/202401/W020240105322424121296.pdf | D24: Population Projection Used to Scale Agriculture and Waste Management Process CO2 Emissions
D25: U.N.
B26: For Crude Oil and Natural Gas：China National Petroleum Corporation 中石油 | D26: 2019
B27: 2024 | D27: World Population Prospects 2019
B28: Energy Outlook for the World and China in 2060 2060年中国与世界能源展望 | D28: https://population.un.org/wpp/Download/Standard/Population/
B29: https://www.sohu.com/a/514937234_121015326 | D29: Total population, Medium case (and historical values for years before 2020)
B31: For Chemcals products and others: CHINA ENERGY RESEARCH SOCIETY 中国能源研究会 | D31: IEA Methane Leakage Multiplier
B32: 2024 | D32: IEA
B33: Analysis of Low-Carbon Development Goals and Pathways for China's Industrial Sector under Carbon Neutrality Targets | D33: 2021
B34: 碳中和目标下中国工业部门低碳发展目标和路径分析 | D34: Methane Tracker 2021
D35: https://www.iea.org/reports/methane-tracker-2020/interactive-country-and-regional-estimates#abstract
D37: Particulates
D38: EPA
D39: 2017
D40: 2017 National Emissions Inventory
D41: https://www.epa.gov/air-emissions-inventories/2017-national-emissions-inventory-nei-data
D43: US Inventory Data
D44: EPA
...

Sheet Sector Match
A1: 农业 | B1: 农、林、牧、渔业 | C1: agriculture and forestry 01T03
A2: 煤炭开采和洗选业 | B2: 煤炭开采和洗选业 | C2: coal mining 05
A3: 石油和天然气开采业 | B3: 石油和天然气开采业 | C3: oil and gas extraction 06
A4: 黑色金属矿采选业 | B4: 黑色金属矿采选业 | C4: other mining and quarrying 07T08
A5: 有色金属矿采选业 | B5: 有色金属矿采选业 | C5: other mining and quarrying 07T08
A6: 非金属矿采选业 | B6: 非金属矿采选业 | C6: other mining and quarrying 07T08
A7: 开采专业及辅助性活动 | B7: 开采专业及辅助性活动 | C7: Mining Support Service Activities 09
A8: 其他采矿业 | B8: 其他采矿业 | C8: Mining Support Service Activities 09
A9: 农副食品加工业 | B9: 农副食品加工业 | C9: food beverage and tobacco 10T12
A10: 食品制造业 | B10: 食品制造业 | C10: food beverage and tobacco 10T12
A11: 酒、饮料和精制茶制造业 | B11: 酒、饮料和精制茶制造业 | C11: food beverage and tobacco 10T12
A12: 烟草制品业 | B12: 烟草制品业 | C12: food beverage and tobacco 10T12
... A22: 化学原料和化学制品制造业 | B22: 化学原料和化学制品制造业 | C22: chemicals 20
A23: 医药制造业 | B23: 医药制造业
A24: 化学纤维制造业 | B24: 化学纤维制造业 | C24: chemicals 20
A25: 橡胶和塑料制品业 | B25: 橡胶和塑料制品业 | C25: rubber and plastic products 22
A26: 非金属矿物制品业 | B26: 非金属矿物制品业 | C26: cement and other nonmetallic minerals 239
A27: 黑色金属冶炼和压延加工业 | B27: 黑色金属冶炼和压延加工业 | C27: iron and steel 241
A28: 有色金属冶炼和压延加工业 | B28: 有色金属冶炼和压延加工业 | C28: other metals 242
A29: 金属制品业 | B29: 金属制品业 | C29: metal products except machinery and vehicles 25
A30: 通用设备制造业 | B30: 通用设备制造业 | C30: other manufacturing 31T33
A31: 专用设备制造业 | B31: 专用设备制造业 | C31: glass and glass products 231
A32: 汽车制造业 | B32: 汽车制造业 | C32: road vehicles 29
A33: 铁路、船舶、航空航天和其他运输设备制造业 | B33: 铁路、船舶、航空航天和其他运输设备制造业 | C33: nonroad vehicles 30
A34: 电气机械和器材制造业 | B34: 电气机械和器材制造业 | C34: appliances and electrical equipment 27
A35: 计算机、通信和其他电子设备制造业 | B35: 计算机、通信和其他电子设备制造业 | C35: computers and electronics 26
... A39: 金属制品、机械和设备修理业 | B39: 金属制品、机械和设备修理业 | C39: other machinery 28
A40: 电力、热力生产和供应业 | B40: 电力、热力生产和供应业
A41: 燃气生产和供应业 | B41: 燃气生产和供应业 | C41: energy pipelines and gas processing 352T353
A42: 水的生产和供应业 | B42: 水的生产和供应业 | C42: water and waste 36T39
A43: 建筑业 | B43: 建筑业 | C43: construction 41T43

Sheet Subnational List
A1: Code | B1: 地区名称 | C1: 地区全称 | D1: 地区简称 | E1: Name | F1: 缩写
A2: 00 | B2: 全国 National | C2: 全国 | D2: 全国 | E2: National | F2: CN
A3: 11 | B3: 北京市 Beijing | C3: 北京市 | D3: 北京 | E3: Beijing | F3: BJ
A4: 12 | B4: 天津市 Tianjin | C4: 天津市 | D4: 天津 | E4: Tianjin | F4: TJ
A5: 13 | B5: 河北省 Hebei | C5: 河北省 | D5: 河北 | E5: Hebei | F5: HE
A6: 14 | B6: 山西省 Shanxi | C6: 山西省 | D6: 山西 | E6: Shanxi | F6: SX
A7: 15 | B7: 内蒙古自治区 Inner Mongolia | C7: 内蒙古自治区 | D7: 内蒙古 | E7: Inner Mongolia | F7: NM
A8: 21 | B8: 辽宁省 Liaoning | C8: 辽宁省 | D8: 辽宁 | E8: Liaoning | F8: LN
A9: 22 | B9: 吉林省 Jilin | C9: 吉林省 | D9: 吉林 | E9: Jilin | F9: JL
A10: 23 | B10: 黑龙江省 Heilongjiang | C10: 黑龙江省 | D10: 黑龙江 | E10: Heilongjiang | F10: HL
A11: 31 | B11: 上海市 Shanghai | C11: 上海市 | D11: 上海 | E11: Shanghai | F11: SH
A12: 32 | B12: 江苏省 Jiangsu | C12: 江苏省 | D12: 江苏 | E12: Jiangsu | F12: JS
A13: 33 | B13: 浙江省 Zhejiang | C13: 浙江省 | D13: 浙江 | E13: Zhejiang | F13: ZJ
A14: 34 | B14: 安徽省 Anhui | C14: 安徽省 | D14: 安徽 | E14: Anhui | F14: AH
... A33: 65 | B33: 新疆维吾尔自治区 Xijiang | C33: 新疆维吾尔自治区 | D33: 新疆 | E33: Xijiang | F33: XJ

Sheet WR-Value Added(19 RMB)
A1: 区域 | B1: 行业 | C1: 2018 | D1: 2019 | E1: 2020 | F1: 2021 | G1: 2022 | H1: 2023 | I1: 2024 | J1: 2025 | K1: 2026 | L1: 2027 | M1: 2028 | N1: 2029 | O1: 2030 | P1: 2031 | Q1: 2032 | R1: 2033 | S1: 2034 | T1: 2035 | U1: 2036 | V1: 2037 | W1: 2038 | X1: 2039 | Y1: 2040 | Z1: 2041 | AA1: 2042 | AB1: 2043 | AC1: 2044 | AD1: 2045 | AE1: 2046 | AF1: 2047 | AG1: 2048 | AH1: 2049 | AI1: 2050 | AJ1: 2051 | AK1: 2052 | AL1: 2053 | AM1: 2054 | AN1: 2055 | AO1: 2056 | AP1: 2057 | AQ1: 2058 | AR1: 2059 | AS1: 2060
A2: 全国 | B2: 煤炭采选产品 | C2: 13128.411 | D2: 12302.691 | E2: 11595.14 | F2: 13119.537 | G2: 13744.853 | H2: 14362.17 | I2: 14972.093 | J2: 15575.441 | K2: 16173.176 | L2: 16766.348 | M2: 17356.048 | N2: 17943.377 | O2: 18529.421 | P2: 19115.235 | Q2: 19701.835 | R2: 20290.19 | S2: 20881.222 | T2: 21475.802 | U2: 22074.757 | V2: 22678.866 | W2: 23288.87 | X2: 23905.469 | Y2: 24529.328 | Z2: 25161.082 | AA2: 25801.338 | AB2: 26450.678 | AC2: 27109.66 | AD2: 27778.826 | AE2: 28458.7 | AF2: 29149.792 | AG2: 29852.601 | AH2: 30567.614 | AI2: 31295.313 | AJ2: 32036.17 | AK2: 32790.655 | AL2: 33559.232 | AM2: 34342.365 | AN2: 35140.514 | AO2: 35954.141 | AP2: 36783.708 | AQ2: 37629.677 | AR2: 38492.515 | AS2: 39372.691
A3: 全国 | B3: 石油和天然气开采产品 | C3: 7594.965 | D3: 8002.4636 | E3: 7731.4547 | F3: 8025.6148 | G3: 8249.1623 | H3: 8466.8246 | I3: 8679.4849 | J3: 8887.9769 | K3: 9093.0939 | L3: 9295.5881 | M3: 9496.1683 | N3: 9695.4969 | O3: 9894.1895 | P3: 10092.815 | Q3: 10291.898 | R3: 10491.918 | S3: 10693.319 | T3: 10896.506 | U3: 11101.851 | V3: 11309.697 | W3: 11520.363 | X3: 11734.141 | Y3: 11951.307 | Z3: 12172.115 | AA3: 12396.806 | AB3: 12625.609 | AC3: 12858.738 | AD3: 13096.401 | AE3: 13338.795 | AF3: 13586.111 | AG3: 13838.535 | AH3: 14096.247 | AI3: 14359.426 | AJ3: 14628.244 | AK3: 14902.874 | AL3: 15183.486 | AM3: 15470.25 | AN3: 15763.335 | AO3: 16062.909 | AP3: 16369.143 | AQ3: 16682.207 | AR3: 17002.271 | AS3: 17329.51
A4: 全国 | B4: 金属矿采选产品 | C4: 5528.1879 | D4: 5185.921 | E4: 7350.7869 | F4: 6452.9258 | G4: 6691.0255 | H4: 6924.7575 | I4: 7154.6434 | J4: 7381.2314 | K4: 7605.0843 | L4: 7826.7666 | M4: 8046.8328 | N4: 8265.8197 | O4: 8484.2401 | P4: 8702.5797 | Q4: 8921.2953 | R4: 9140.8151 | S4: 9361.5389 | T4: 9583.8398 | U4: 9808.0661 | V4: 10034.543 | W4: 10263.576 | X4: 10495.449 | Y4: 10730.433 | Z4: 10968.782 | AA4: 11210.736 | AB4: 11456.527 | AC4: 11706.374 | AD4: 11960.488 | AE4: 12219.074 | AF4: 12482.33 | AG4: 12750.449 | AH4: 13023.62 | AI4: 13302.027 | AJ4: 13585.854 | AK4: 13875.28 | AL4: 14170.485 | AM4: 14471.647 | AN4: 14778.942 | AO4: 15092.549 | AP4: 15412.645 | AQ4: 15739.408 | AR4: 16073.019 | AS4: 16413.658
A5: 全国 | B5: 非金属矿和其他矿采选产品 | C5: 2972.383 | D5: 3396.7183 | E5: 3301.0417 | F5: 3447.3026 | G5: 3540.3757 | H5: 3630.9024 | I5: 3719.2716 | J5: 3805.8477 | K5: 3890.9752 | L5: 3974.9793 | M5: 4058.1651 | N5: 4140.817 | O5: 4223.1985 | P5: 4305.5526 | Q5: 4388.1025 | R5: 4471.0529 | S5: 4554.5913 | T5: 4638.8895 | U5: 4724.1053 | V5: 4810.3836 | W5: 4897.8581 | X5: 4986.6527 | Y5: 5076.8825 | Z5: 5168.655 | AA5: 5262.0711 | AB5: 5357.2263 | AC5: 5454.2108 | AD5: 5553.111 | AE5: 5654.0097 | AF5: 5756.9867 | AG5: 5862.1195 | AH5: 5969.4837 | AI5: 6079.153 | AJ5: 6191.2001 | AK5: 6305.6968 | AL5: 6422.7141 | AM5: 6542.3228 | AN5: 6664.5933 | AO5: 6789.5962 | AP5: 6917.4022 | AQ5: 7048.0824 | AR5: 7181.7082 | AS5: 7318.3521
A6: 全国 | B6: 食品和烟草 | C6: 24778.271 | D6: 26292.024 | E6: 27523.592 | F6: 28195.503 | G6: 28723.214 | H6: 29228.64 | I6: 29715.717 | J6: 30187.914 | K6: 30648.348 | L6: 31099.842 | M6: 31544.95 | N6: 31985.985 | O6: 32425.028 | P6: 32863.955 | Q6: 33304.449 | R6: 33748.02 | S6: 34196.022 | T6: 34649.673 | U6: 35110.068 | V6: 35578.196 | W6: 36054.952 | X6: 36541.152 | Y6: 37037.541 | Z6: 37544.805 | AA6: 38063.576 | AB6: 38594.448 | AC6: 39137.972 | AD6: 39694.673 | AE6: 40265.047 | AF6: 40849.57 | AG6: 41448.7 | AH6: 42062.881 | AI6: 42692.546 | AJ6: 43338.119 | AK6: 44000.019 | AL6: 44678.659 | AM6: 45374.451 | AN6: 46087.805 | AO6: 46819.132 | AP6: 47568.844 | AQ6: 48337.357 | AR6: 49125.089 | AS6: 49932.463
A7: 全国 | B7: 纺织品 | C7: 8366.6518 | D7: 8685.8969 | E7: 8732.6137 | F7: 9044.4533 | G7: 9253.2312 | H7: 9455.1073 | I7: 9651.2163 | J7: 9842.5884 | K7: 10030.173 | L7: 10214.848 | M7: 10397.422 | N7: 10578.64 | O7: 10759.182 | P7: 10939.668 | Q7: 11120.663 | R7: 11302.679 | S7: 11486.18 | T7: 11671.588 | U7: 11859.289 | V7: 12049.632 | W7: 12242.939 | X7: 12439.503 | Y7: 12639.598 | Z7: 12843.476 | AA7: 13051.373 | AB7: 13263.511 | AC7: 13480.098 | AD7: 13701.333 | AE7: 13927.406 | AF7: 14158.5 | AG7: 14394.791 | AH7: 14636.451 | AI7: 14883.648 | AJ7: 15136.547 | AK7: 15395.311 | AL7: 15660.1 | AM7: 15931.074 | AN7: 16208.394 | AO7: 16492.219 | AP7: 16782.71 | AQ7: 17080.028 | AR7: 17384.336 | AS7: 17695.797
A8: 全国 | B8: 纺织服装鞋帽皮革羽绒及其制品 | C8: 8621.613 | D8: 8980.8462 | E8: 8851.2045 | F8: 9355.493 | G8: 9649.6772 | H8: 9937.2107 | I8: 10219.014 | J8: 10495.99 | K8: 10769.019 | L8: 11038.955 | M8: 11306.615 | N8: 11572.775 | O8: 11838.161 | P8: 12103.454 | Q8: 12369.284 | R8: 12636.237 | S8: 12904.853 | T8: 13175.631 | U8: 13449.035 | V8: 13725.494 | W8: 14005.404 | X8: 14289.138 | Y8: 14577.043 | Z8: 14869.445 | AA8: 15166.652 | AB8: 15468.957 | AC8: 15776.638 | AD8: 16089.962 | AE8: 16409.185 | AF8: 16734.557 | AG8: 17066.318 | AH8: 17404.704 | AI8: 17749.946 | AJ8: 18102.272 | AK8: 18461.906 | AL8: 18829.071 | AM8: 19203.989 | AN8: 19586.88 | AO8: 19977.966 | AP8: 20377.468 | AQ8: 20785.609 | AR8: 21202.612 | AS8: 21628.703
A9: 全国 | B9: 木材加工品和家具 | C9: 4575.5303 | D9: 4620.1112 | E9: 4812.4403 | F9: 5296.1892 | G9: 5393.4605 | H9: 5486.5343 | I9: 5576.1559 | J9: 5662.9807 | K9: 5747.5967 | L9: 5830.5353 | M9: 5912.277 | N9: 5993.2558 | O9: 6073.8623 | P9: 6154.4478 | Q9: 6235.3273 | R9: 6316.7832 | S9: 6399.0685 | T9: 6482.4103 | U9: 6567.013 | V9: 6653.0605 | W9: 6740.7197 | X9: 6830.142 | Y9: 6921.4658 | Z9: 7014.8185 | AA9: 7110.3175 | AB9: 7208.0724 | AC9: 7308.1858 | AD9: 7410.7544 | AE9: 7515.8701 | AF9: 7623.6209 | AG9: 7734.0915 | AH9: 7847.3639 | AI9: 7963.518 | AJ9: 8082.6322 | AK9: 8204.7837 | AL9: 8330.0489 | AM9: 8458.5038 | AN9: 8590.2242 | AO9: 8725.2858 | AP9: 8863.7649 | AQ9: 9005.738 | AR9: 9151.2826 | AS9: 9300.4768
A10: 全国 | B10: 造纸印刷和文教体育用品 | C10: 9591.3232 | D10: 9882.2072 | E10: 10131.591 | F10: 10891.094 | G10: 11347.686 | H10: 11797.249 | I10: 12240.485 | J10: 12678.205 | K10: 13111.289 | L10: 13540.651 | M10: 13967.214 | N10: 14391.886 | O10: 14815.55 | P10: 15239.053 | Q10: 15663.199 | R10: 16088.748 | S10: 16516.418 | T10: 16946.883 | U10: 17380.776 | V10: 17818.691 | W10: 18261.191 | X10: 18708.802 | Y10: 19162.027 | Z10: 19621.338 | AA10: 20087.19 | AB10: 20560.013 | AC10: 21040.224 | AD10: 21528.221 | AE10: 22024.392 | AF10: 22529.113 | AG10: 23042.751 | AH10: 23565.664 | AI10: 24098.205 | AJ10: 24640.723 | AK10: 25193.561 | AL10: 25757.06 | AM10: 26331.56 | AN10: 26917.4 | AO10: 27514.916 | AP10: 28124.45 | AQ10: 28746.34 | AR10: 29380.929 | AS10: 30028.562
A11: 全国 | B11: 石油、炼焦产品和核燃料加工品 | C11: 11676.296 | D11: 11830.21 | E11: 11028.798 | F11: 12460.693 | G11: 13191.717 | H11: 13916.001 | I11: 14633.674 | J11: 15345.228 | K11: 16051.402 | L11: 16753.095 | M11: 17451.311 | N11: 18147.103 | O11: 18841.544 | P11: 19535.704 | Q11: 20230.631 | R11: 20927.341 | S11: 21626.816 | T11: 22329.993 | U11: 23037.772 | V11: 23751.008 | W11: 24470.521 | X11: 25197.093 | Y11: 25931.47 | Z11: 26674.369 | AA11: 27426.479 | AB11: 28188.463 | AC11: 28960.962 | AD11: 29744.596 | AE11: 30539.969 | AF11: 31347.671 | AG11: 32168.276 | AH11: 33002.352 | AI11: 33850.454 | AJ11: 34713.133 | AK11: 35590.932 | AL11: 36484.391 | AM11: 37394.049 | AN11: 38320.44 | AO11: 39264.1 | AP11: 40225.566 | AQ11: 41205.374 | AR11: 42204.066 | AS11: 43222.185
A12: 全国 | B12: 化学产品 | C12: 31655.802 | D12: 32966.542 | E12: 33824.234 | F12: 34982.491 | G12: 36397.254 | H12: 37789.112 | I12: 39160.493 | J12: 40514.11 | K12: 41852.854 | L12: 43179.698 | M12: 44497.619 | N12: 45809.533 | O12: 47118.258 | P12: 48426.488 | Q12: 49736.776 | R12: 51051.528 | S12: 52373.008 | T12: 53703.339 | U12: 55044.511 | V12: 56398.393 | W12: 57766.742 | X12: 59151.211 | Y12: 60553.365 | Z12: 61974.685 | AA12: 63416.581 | AB12: 64880.399 | AC12: 66367.433 | AD12: 67878.925 | AE12: 69416.078 | AF12: 70980.062 | AG12: 72572.014 | AH12: 74193.051 | AI12: 75844.266 | AJ12: 77526.739 | AK12: 79241.537 | AL12: 80989.72 | AM12: 82772.341 | AN12: 84590.45 | AO12: 86445.096 | AP12: 88337.333 | AQ12: 90268.215 | AR12: 92238.805 | AS12: 94250.172
... A865: 新疆 | B865: 建筑业 | C865: 987.8 | D865: 1044.6 | E865: 1197 | F865: 1371.6 | G865: 1447.9828 | H865: 1527.7777 | I865: 1611.1797 | J865: 1697.1774 | K865: 1785.568 | L865: 1876.6294 | M865: 1970.3698 | N865: 2067.9346 | O865: 2169.0702 | P865: 2273.3996 | Q865: 2381.1995 | R865: 2491.9803 | S865: 2605.9806 | T865: 2721.4012 | U865: 2840.6661 | V865: 2963.9844 | W865: 3089.7044 | X865: 3219.4127 | Y865: 3352.731 | Z865: 3486.7617 | AA865: 3624.7379 | AB865: 3766.3726 | AC865: 3910.7571 | AD865: 4058.7468 | AE865: 4210.8956 | AF865: 4366.7576 | AG865: 4524.1146 | AH865: 4684.5772 | AI865: 4848.8376 | AJ865: 5017.6388 | AK865: 5190.4535 | AL865: 5366.9763 | AM865: 5546.9208 | AN865: 5731.2378 | AO865: 5921.7814 | AP865: 6118.1837 | AQ865: 6320.8884 | AR865: 6528.3852 | AS865: 6741.9245

Sheet Industrial Asset
B1: 地区 | C1: 行业 | D1: 指标 | E1: 值 | G1: Sources: | H1: China Economic Census Yearbook 2018
A2: 全国 | B2: 全国 | C2: 黑色金属冶炼和压延加工业 | D2: 资产总计（亿元） | E2: 61675.61 | H2: 中国经济普查年鉴2018
A3: 北京 | B3: 北京市 | C3: 黑色金属冶炼和压延加工业 | D3: 资产总计（亿元） | E3: 80.44 | H3: 1-B-38、1-B-39、1-B-48、1-B-49
A4: 天津 | B4: 天津市 | C4: 黑色金属冶炼和压延加工业 | D4: 资产总计（亿元） | E4: 3006.52
A5: 河北 | B5: 河北省 | C5: 黑色金属冶炼和压延加工业 | D5: 资产总计（亿元） | E5: 11205.37 | H5: 中国经济普查年鉴-二产业卷(上)-第一篇 工业企业生产经营及财务状况篇-B.地区部分
A6: 山西 | B6: 山西省 | C6: 黑色金属冶炼和压延加工业 | D6: 资产总计（亿元） | E6: 2752.93 | H6: 非金属矿采选业 | J6: 1-B-16
A7: 内蒙古 | B7: 内蒙古自治区 | C7: 黑色金属冶炼和压延加工业 | D7: 资产总计（亿元） | E7: 2800.51 | H7: 开采专业及辅助性活动 | J7: 1-B-17
A8: 辽宁 | B8: 辽宁省 | C8: 黑色金属冶炼和压延加工业 | D8: 资产总计（亿元） | E8: 5143.83 | H8: 其他采矿业 | J8: 1-B-18
A9: 吉林 | B9: 吉林省 | C9: 黑色金属冶炼和压延加工业 | D9: 资产总计（亿元） | E9: 805.32 | H9: 化学原料和化学制品制造业 | J9: 1-B-33
A10: 黑龙江 | B10: 黑龙江省 | C10: 黑色金属冶炼和压延加工业 | D10: 资产总计（亿元） | E10: 344.26 | H10: 医药制造业 | J10: 1-B-34
A11: 上海 | B11: 上海市 | C11: 黑色金属冶炼和压延加工业 | D11: 资产总计（亿元） | E11: 2745.35 | H11: 化学纤维制造业 | J11: 1-B-35
A12: 江苏 | B12: 江苏省 | C12: 黑色金属冶炼和压延加工业 | D12: 资产总计（亿元） | E12: 6233.66 | H12: 橡胶和塑料制品业 | J12: 1-B-36
A13: 浙江 | B13: 浙江省 | C13: 黑色金属冶炼和压延加工业 | D13: 资产总计（亿元） | E13: 1263.79 | H13: 黑色金属冶炼和压延加工业 | J13: 1-B-38
A14: 安徽 | B14: 安徽省 | C14: 黑色金属冶炼和压延加工业 | D14: 资产总计（亿元） | E14: 1391.1 | H14: 有色金属冶炼和压延加工业 | J14: 1-B-39
A15: 福建 | B15: 福建省 | C15: 黑色金属冶炼和压延加工业 | D15: 资产总计（亿元） | E15: 1117.09 | H15: 汽车制造业 | J15: 1-B-43
A16: 江西 | B16: 江西省 | C16: 黑色金属冶炼和压延加工业 | D16: 资产总计（亿元） | E16: 890.84 | H16: 铁路、船舶、航空航天和其他运输设备制造业 | J16: 1-B-44
A17: 山东 | B17: 山东省 | C17: 黑色金属冶炼和压延加工业 | D17: 资产总计（亿元） | E17: 4363.17 | H17: 其他制造业 | J17: 1-B-48
A18: 河南 | B18: 河南省 | C18: 黑色金属冶炼和压延加工业 | D18: 资产总计（亿元） | E18: 1886.34 | H18: 废弃资源综合利用业 | J18: 1-B-49
A19: 湖北 | B19: 湖北省 | C19: 黑色金属冶炼和压延加工业 | D19: 资产总计（亿元） | E19: 2537.73
A20: 湖南 | B20: 湖南省 | C20: 黑色金属冶炼和压延加工业 | D20: 资产总计（亿元） | E20: 933.32
A21: 广东 | B21: 广东省 | C21: 黑色金属冶炼和压延加工业 | D21: 资产总计（亿元） | E21: 1786.42
A22: 广西 | B22: 广西壮族自治区 | C22: 黑色金属冶炼和压延加工业 | D22: 资产总计（亿元） | E22: 1427.77
A23: 海南 | B23: 海南省 | C23: 黑色金属冶炼和压延加工业 | D23: 资产总计（亿元）
A24: 重庆 | B24: 重庆市 | C24: 黑色金属冶炼和压延加工业 | D24: 资产总计（亿元） | E24: 463.19
A25: 四川 | B25: 四川省 | C25: 黑色金属冶炼和压延加工业 | D25: 资产总计（亿元） | E25: 2152.34
A26: 贵州 | B26: 贵州省 | C26: 黑色金属冶炼和压延加工业 | D26: 资产总计（亿元） | E26: 450.02
A27: 云南 | B27: 云南省 | C27: 黑色金属冶炼和压延加工业 | D27: 资产总计（亿元） | E27: 856.4
A28: 西藏 | B28: 西藏自治区 | C28: 黑色金属冶炼和压延加工业 | D28: 资产总计（亿元）
A29: 陕西 | B29: 陕西省 | C29: 黑色金属冶炼和压延加工业 | D29: 资产总计（亿元） | E29: 476.32
A30: 甘肃 | B30: 甘肃省 | C30: 黑色金属冶炼和压延加工业 | D30: 资产总计（亿元） | E30: 1274.33
A31: 青海 | B31: 青海省 | C31: 黑色金属冶炼和压延加工业 | D31: 资产总计（亿元） | E31: 325.76
A32: 宁夏 | B32: 宁夏回族自治区 | C32: 黑色金属冶炼和压延加工业 | D32: 资产总计（亿元） | E32: 2365
A33: 新疆 | B33: 新疆维吾尔自治区 | C33: 黑色金属冶炼和压延加工业 | D33: 资产总计（亿元） | E33: 596.5
A34: 全国 | B34: 全国 | C34: 黑色金属冶炼和压延加工业 | D34: 营业利润（亿元） | E34: 4432.75
A35: 北京 | B35: 北京市 | C35: 黑色金属冶炼和压延加工业 | D35: 营业利润（亿元） | E35: -0.01
A36: 天津 | B36: 天津市 | C36: 黑色金属冶炼和压延加工业 | D36: 营业利润（亿元） | E36: -18.97
A37: 河北 | B37: 河北省 | C37: 黑色金属冶炼和压延加工业 | D37: 营业利润（亿元） | E37: 925.91
A38: 山西 | B38: 山西省 | C38: 黑色金属冶炼和压延加工业 | D38: 营业利润（亿元） | E38: 206.83
A39: 内蒙古 | B39: 内蒙古自治区 | C39: 黑色金属冶炼和压延加工业 | D39: 营业利润（亿元） | E39: 124.42
A40: 辽宁 | B40: 辽宁省 | C40: 黑色金属冶炼和压延加工业 | D40: 营业利润（亿元） | E40: 245.75
...

Sheet GHGs Inventory 2018
A1: 表 1-10 2018 年中国二氧化碳、甲烷和氧化亚氮清单（万吨） | G1: 表1-9 清单所涉及温室气体的全球增温潜势
A2: 温室气体排放源与吸收汇类别 | B2: CO2 | C2: CH4 | D2: N2O | G2: 温室气体种类 | H2: 全球增温潜势
A3: 总量（不包括LULUCF） | B3: 1089586.6 | C3: 6013.2 | D3: 191.4 | G3: CO2 | H3: 1
A4: 总量（包括LULUCF） | B4: 955539.4 | C4: 6411.3 | D4: 191.5 | G4: CH4 | H4: 21
A5: 能源活动 | B5: 942619.4 | C5: 2865.8 | D5: 41.1 | G5: N2O | H5: 310
A6: 燃料燃烧 | B6: 942619.4 | C6: 165.8 | D6: 41.1 | G6: HFC-23(CHF3) | H6: 11700
A7: 能源工业 | B7: 440332.6 | C7: 10.2 | D7: 29.1 | G7: HFC-32 | H7: 650
A8: 制造业和建筑业 | B8: 334433.6 | C8: 29.2 | D8: 7.5 | G8: HFC-125 | H8: 2800
A9: 交通运输 | B9: 98202.8 | C9: 12.9 | D9: 2.3 | G9: HFC-134a | H9: 1300
A10: 其他行业 | B10: 69650.5 | C10: 113.5 | D10: 2.2 | G10: HFC-143a | H10: 3800
A11: 逃逸排放 | C11: 2700.1 | G11: HFC-152a | H11: 140
A12: 固体燃料 | C12: 2512.2 | G12: HFC-227en | H12: 2900
A13: 油气系统 | C13: 187.9 | G13: HFC-236fa | H13: 6300
A14: 工业生产过程 | B14: 146625.2 | C14: 0.5 | D14: 44.1 | G14: HFC-245fa | H14: 1030
A15: 非金属矿物制品生产 | B15: 99136 | G15: HFC-365mfc | H15: 794
A16: 化学工业生产 | B16: 29057.6 | D16: 44.1 | G16: PFC-14(CF4) | H16: 6500
A17: 金属制品生产 | B17: 18167 | C17: 0.5 | D17: NO | G17: PFC-116(C2F6) | H17: 9200
A18: 源于燃料和溶剂的非能源产品使用 | B18: 264.5 | G18: SF6 | H18: 23900
A19: 卤烃和六氟化硫消费 | G19: 注：HFC-245fa和HFC-365mfc全球增温潜势值采用《IPCC第四次评估报告》中100年时间尺度下的数
A20: 农业活动 | C20: 2384.6 | D20: 94.3
A21: 动物肠道发酵 | C21: 1084.1 | G21: GbPbT/fuels
A22: 动物粪便管理 | C22: 346.1 | D22: 21.7 | G22: Global Warming Potential (g CO2e/g pollutant) | H22: twenty years | I22: one hundred years
A23: 水稻种植 | C23: 932.9 | G23: CO2 | H23: 1 | I23: 1
A24: 农用地 | D24: 72 | G24: VOC | H24: 16.2 | I24: 5
A25: 秸秆田间焚烧 | C25: 21.6 | D25: 0.6 | G25: CO | H25: 5.6 | I25: 1.8
A26: 土地利用、土地利用变化和林业 | B26: -134047.3 | C26: 398.1 | D26: 0.1 | G26: NOx | H26: -2.4 | I26: -8.2
A27: 林地 | B27: -96579.2 | C27: 0.1 | D27: 0 | G27: PM10 | H27: 0 | I27: 0
A28: 农地 | B28: -7810 | C28: IE | D28: IE | G28: PM25 | H28: 0 | I28: 0
A29: 草地 | B29: -10175.2 | C29: 0.1 | D29: 0.1 | G29: SOx | H29: 0 | I29: 0
A30: 湿地 | B30: -8641.7 | C30: 398 | D30: NE | G30: BC | H30: 1200 | I30: 345
A31: 建设用地 | B31: -91.8 | G31: OC | H31: -160 | I31: -46
A32: 其他用地 | B32: 109.5 | G32: CH4 | H32: 84 | I32: 28
A33: 木质林产品 | B33: -10859 | G33: N2O | H33: 264 | I33: 265
A34: 废弃物处理 | B34: 342 | C34: 762.2 | D34: 11.9 | G34: F gases | H34: 1 | I34: 1
A35: 填埋处理 | C35: 468.6
A36: 生物处理 | C36: 2.7 | D36: 0.2
A37: 废水处理 | C37: 290.8 | D37: 11.3
A38: 焚烧处理 | B38: 342 | C38: 0.1 | D38: 0.4
A39: 信息项
A40: 国际航空 | B40: 4683.4 | C40: 0 | D40: 0.1
...

Sheet GHGs Inventory 2020-2021
A1: 表1-4a 中国温室气体排放和吸收 | J1: 表1-23金属矿物生产排放（万吨二氧化碳当量）
A2: 温室气体排放源与吸收汇类别（万吨） | B2: 2020年_CO2 | C2: 2020年_CH4 | D2: 2020年_N2O | E2: 2021年_CO2 | F2: 2021年_CH4 | G2: 2021年_N2O | J2: 年份 | K2: 排放源类别 | L2: CO₂ | M2: CH₄ | N2: PFCs | O2: 合计
A3: 总量（不包括 LULUCF） | B3: 1120166.8 | C3: 5902.8 | D3: 197.9 | E3: 1162800.9 | F3: 5953.5 | G3: 210.2 | J3: 2020年 | K3: 2.C金属制品生产 | L3: 17893.3 | M3: 15 | N3: 2083 | O3: 19991.3
A4: 总量（包括 LULUCF） | B4: 985904 | C4: 6042.6 | D4: 197.9 | E4: 1028151 | F4: 6064.5 | G4: 210.2 | J4: 2020年 | K4: 2.C.1 钢铁生产过程 | L4: 6702.9 | O4: 6702.9
A5: 1.能源活动 | B5: 966087.9 | C5: 2792.2 | D5: 44.2 | E5: 1009504.3 | F5: 2816.5 | G5: 46.4 | J5: 2020年 | K5: 2.C.2 铁合金生产过程 | L5: 5012 | M5: 15 | O5: 5027
A6: 1.A 燃料燃烧 | B6: 966087.9 | C6: 142.9 | D6: 44.2 | E6: 1009504.3 | F6: 138 | G6: 46.4 | J6: 2020年 | K6: 2.C.3 铝冶炼生产过程 | L6: 5302.4 | N6: 2083 | O6: 7385.5
A7: 1.A.1 能源工业 | B7: 478003 | C7: 12.9 | D7: 32.6 | E7: 525862.1 | F7: 14.7 | G7: 34.6 | J7: 2020年 | K7: 2.C.4 镁冶炼生产过程 | L7: 436.5 | O7: 436.5
A8: 1.A.2 制造业和建筑业 | B8: 332293.1 | C8: 29.8 | D8: 8 | E8: 323880.8 | F8: 29 | G8: 8.1 | J8: 2020年 | K8: 2.C.5 铅冶炼生产过程 | L8: 121.8 | O8: 121.8
A9: 1.A.3 交通运输 | B9: 91049.9 | C9: 14 | D9: 2.2 | E9: 99129.3 | F9: 15.6 | G9: 2.3 | J9: 2020年 | K9: 2.C.6 锌冶炼生产过程 | L9: 317.6 | O9: 317.6
A10: 1.A.4 其他部门 | B10: 64741.9 | C10: 86.1 | D10: 1.4 | E10: 60632.1 | F10: 78.7 | G10: 1.4 | J10: 2021年 | K10: 2.C金属制品生产 | L10: 17943.3 | M10: 16 | N10: 2162.8 | O10: 20122.1
A11: 1.B 逸散排放 | C11: 2649.3 | F11: 2678.5 | J11: 2021年 | K11: 2.C.1 钢铁生产过程 | L11: 6549 | O11: 6549
A12: 1.B.1 固体燃料 | C12: 2486.3 | F12: 2503 | J12: 2021年 | K12: 2.C.2 铁合金生产过程 | L12: 5094 | M12: 16 | O12: 5110
A13: 1.B.2 油系统 | C13: 163 | F13: 175.5 | J13: 2021年 | K13: 2.C.3 铝冶炼生产过程 | L13: 5428.5 | N13: 2162.8 | O13: 7591.3
A14: 2.工业生产过程和产品使用 | B14: 153211.8 | C14: 0.5 | D14: 48.9 | E14: 152398.3 | F14: 0.6 | G14: 58 | J14: 2021年 | K14: 2.C.4 镁冶炼生产过程 | L14: 387.3 | O14: 387.3
A15: 2.A 非金属矿物制品生产 | B15: 103494.7 | E15: 101302.7 | J15: 2021年 | K15: 2.C.5 铅冶炼生产过程 | L15: 127.9 | O15: 127.9
A16: 2.B 化学工业生产 | B16: 31576.1 | D16: 48.9 | E16: 32877.5 | G16: 58 | J16: 2021年 | K16: 2.C.6 锌冶炼生产过程 | L16: 356.6 | O16: 356.6
A17: 2.C 金属制品生产 | B17: 17893.3 | C17: 0.5 | D17: NO | E17: 17943.3 | F17: 0.6 | G17: NO
A18: 2.D 非能源产品使用 | B18: 247.7 | E18: 274.8
A19: 2.E 电子工业生产
A20: 2.F 消耗臭氧层物质替代物使用 | J20: 表1-95 国家清单所涉及温室气体的全球增温潜势
A21: 2.G 其他产品制造和使用 | J21: 温室气体种类 | K21: 全球增温潜势
A22: 3.农业活动 | C22: 2372 | D22: 94.6 | F22: 2427.9 | G22: 94.9 | J22: CO2 | K22: 1
A23: 3.A 动物肠道发酵 | C23: 1124.2 | F23: 1151.8 | J23: CH4 | K23: 21
A24: 3.B 动物粪便管理 | C24: 344.7 | D24: 22.2 | F24: 375.3 | G24: 22.7 | J24: N2O | K24: 265
A25: 3.C 水稻种植 | C25: 884.9 | F25: 885.1
A26: 3.D 农用地 | D26: 71.9 | G26: 71.8
A27: 3.F 秸秆田间焚烧 | C27: 18.2 | D27: 0.5 | F27: 15.7 | G27: 0.4
A28: 4.土地利用、土地利用变化和林业 | B28: -134262.9 | C28: 139.8 | D28: 0 | E28: -134649.9 | F28: 111 | G28: 0
A29: 4.A 林地 | B29: -89559.2 | C29: 0 | D29: 0 | E29: -87682.7 | F29: 0 | G29: 0
A30: 4.B 农地 | B30: -9801.8 | C30: 0 | D30: 0 | E30: -10616.2 | F30: 0 | G30: 0
A31: 4.C 草地 | B31: -7270.7 | C31: 0 | D31: 0 | E31: -6408.2 | F31: 0 | G31: 0
A32: 4.D 湿地 | B32: -2978.8 | C32: 139.8 | D32: NE | E32: -2459.9 | F32: 111 | G32: NE
A33: 4.E 建设用地 | B33: -239.6 | E33: -63.4
A34: 4.F 其他土地 | B34: 264.1 | E34: 155.6
A35: 4.G 木质林产品 | B35: -10386.3 | E35: -10382
A36: 4.H 其他生物质 | B36: -14290.6 | E36: -17193.1
A37: 5.废弃物处理 | B37: 867.1 | C37: 738 | D37: 10.3 | E37: 898.3 | F37: 708.5 | G37: 10.9
A38: 5.A 填埋处理 | C38: 505.5 | F38: 472.1
A39: 5.B 生物处理 | C39: 4.3 | D39: 0.3 | F39: 6.4 | G39: 0.5
A40: 5.C 焚烧处理 | B40: 867.1 | C40: 0.2 | D40: 1.1 | E40: 898.3 | F40: 0.2 | G40: 1.6
...

Sheet GHG Emissions 2018-2021
A1: 2018年中国温室气体排放
A2: Sector | B2: 行业 | C2: 对应关系 | D2: CO2 | E2: CH4 | F2: N2O | G2: F-gases
D3: (万吨) | E3: (万吨) | F3: (万吨) | G3: (万吨CO2e）
A4: =VLOOKUP($B4,'Sector Match'!$B$1:$C$43,2,0) -> agriculture and forestry 01T03 | B4: 农、林、牧、渔业 | C4: 动物肠道发酵+动物粪便管理 | E4: ='GHGs Inventory 2018'!C21+'GHGs Inventory 2018'!C22 -> 1430.2 | F4: ='GHGs Inventory 2018'!D22 -> 21.7
A5: =VLOOKUP($B5,'Sector Match'!$B$1:$C$43,2,0) -> agriculture and forestry 01T03 | B5: 农、林、牧、渔业 | C5: 水稻种植+农用地+秸秆田间焚烧 | E5: =SUM('GHGs Inventory 2018'!C23:C25) -> 954.5 | F5: =SUM('GHGs Inventory 2018'!D23:D25) -> 72.6
A6: =VLOOKUP($B6,'Sector Match'!$B$1:$C$43,2,0) -> coal mining 05 | B6: 煤炭开采和洗选业 | C6: 固体燃料逃逸排放 | E6: ='GHGs Inventory 2018'!C12 -> 2512.2
A7: =VLOOKUP($B7,'Sector Match'!$B$1:$C$43,2,0) -> energy pipelines and gas processing 352T353 | B7: 燃气生产和供应业 | C7: 油气系统逃逸排放 | E7: ='GHGs Inventory 2018'!C13 -> 187.9
A8: =VLOOKUP($B8,'Sector Match'!$B$1:$C$43,2,0) -> refined petroleum and coke 19 | B8: 石油、煤炭及其他燃料加工业 | C8: 源于燃料和溶剂的非能源产品使用 | D8: ='GHGs Inventory 2018'!B18 -> 264.5
A9: =VLOOKUP($B9,'Sector Match'!$B$1:$C$43,2,0) -> chemicals 20 | B9: 化学原料和化学制品制造业 | C9: 化学工业生产 | D9: ='GHGs Inventory 2018'!B16 -> 29057.6 | F9: ='GHGs Inventory 2018'!D16 -> 44.1 | G9: {=SUMPRODUCT(TRANSPOSE('GHGs Inventory 2018'!B54:N54),'GHGs Inventory 2018'!H6:H18)} -> 3065.1
A10: =VLOOKUP($B10,'Sector Match'!$B$1:$C$43,2,0) -> cement and other nonmetallic minerals 239 | B10: 非金属矿物制品业 | C10: 非金属矿物制品生产 | D10: ='GHGs Inventory 2018'!B15 -> 99136
A11: =VLOOKUP($B11,'Sector Match'!$B$1:$C$43,2,0) -> iron and steel 241 | B11: 黑色金属冶炼和压延加工业 | C11: 金属制品生产-钢铁&铁合金 | D11: ='GHGs Inventory 2018'!B17*D25/SUM(D25:D26) -> 11894.16 | E11: ='GHGs Inventory 2018'!C17 -> 0.5
A12: =VLOOKUP($B12,'Sector Match'!$B$1:$C$43,2,0) -> other metals 242 | B12: 有色金属冶炼和压延加工业 | C12: 金属制品生产-铝镁铅锌冶炼 | D12: ='GHGs Inventory 2018'!B17*D26/SUM(D25:D26) -> 6272.8397 | G12: ='GHGs Inventory 2018'!L55*'GHGs Inventory 2018'!H16+'GHGs Inventory 2018'!H17*'GHGs Inventory 2018'!M55 -> 1966
A13: =VLOOKUP($B13,'Sector Match'!$B$1:$C$43,2,0) -> glass and glass products 231 | B13: 专用设备制造业 | C13: 卤烃和六氟化硫消费 | G13: {=SUMPRODUCT(TRANSPOSE('GHGs Inventory 2018'!B57:N57),'GHGs Inventory 2018'!H6:H18)} -> 23386.9
A14: =VLOOKUP($B14,'Sector Match'!$B$1:$C$43,2,0) -> water and waste 36T39 | B14: 废弃资源综合利用业 | C14: 废弃物处理 | D14: ='GHGs Inventory 2018'!B34 -> 342 | E14: ='GHGs Inventory 2018'!C34 -> 762.2 | F14: ='GHGs Inventory 2018'!D34 -> 11.9
A15: 备注：2018年没有公布金属制品生产的细分排放源，我们用2020年的比例拆分黑色金属和有色金属的排放。
A16: 2020年中国温室气体排放
A17: Sector | B17: 行业 | C17: 对应关系 | D17: CO2 | E17: CH4 | F17: N2O | G17: F-gases
D18: (万吨) | E18: (万吨) | F18: (万吨) | G18: (万吨CO2e）
A19: =VLOOKUP($B19,'Sector Match'!$B$1:$C$43,2,0) -> agriculture and forestry 01T03 | B19: 农、林、牧、渔业 | C19: 动物肠道发酵+动物粪便管理 | E19: =SUM('GHGs Inventory 2020-2021'!C23:C24) -> 1468.9 | F19: =SUM('GHGs Inventory 2020-2021'!D23:D24) -> 22.2
A20: =VLOOKUP($B20,'Sector Match'!$B$1:$C$43,2,0) -> agriculture and forestry 01T03 | B20: 农、林、牧、渔业 | C20: 水稻种植+农用地+秸秆田间焚烧 | E20: =SUM('GHGs Inventory 2020-2021'!C25:C27) -> 903.1 | F20: =SUM('GHGs Inventory 2020-2021'!D25:D27) -> 72.4
A21: =VLOOKUP($B21,'Sector Match'!$B$1:$C$43,2,0) -> coal mining 05 | B21: 煤炭开采和洗选业 | C21: 固体燃料逃逸排放 | E21: ='GHGs Inventory 2020-2021'!C12 -> 2486.3
A22: =VLOOKUP($B22,'Sector Match'!$B$1:$C$43,2,0) -> energy pipelines and gas processing 352T353 | B22: 燃气生产和供应业 | C22: 油气系统逃逸排放 | E22: ='GHGs Inventory 2020-2021'!C13 -> 163
A23: =VLOOKUP($B23,'Sector Match'!$B$1:$C$43,2,0) -> chemicals 20 | B23: 化学原料和化学制品制造业 | C23: 化学工业生产 | D23: ='GHGs Inventory 2020-2021'!B16 -> 31576.1 | E23: ='GHGs Inventory 2020-2021'!C16 -> 0 | F23: ='GHGs Inventory 2020-2021'!D16 -> 48.9 | G23: =SUM('GHGs Inventory 2020-2021'!B53:D53) -> 1670.5
A24: =VLOOKUP($B24,'Sector Match'!$B$1:$C$43,2,0) -> cement and other nonmetallic minerals 239 | B24: 非金属矿物制品业 | C24: 非金属矿物制品生产 | D24: ='GHGs Inventory 2020-2021'!B15 -> 103494.7
A25: =VLOOKUP($B25,'Sector Match'!$B$1:$C$43,2,0) -> iron and steel 241 | B25: 黑色金属冶炼和压延加工业 | C25: 金属制品生产-钢铁&铁合金 | D25: =SUM('GHGs Inventory 2020-2021'!L4:L5) -> 11714.9 | E25: ='GHGs Inventory 2020-2021'!C17 -> 0.5
A26: =VLOOKUP($B26,'Sector Match'!$B$1:$C$43,2,0) -> other metals 242 | B26: 有色金属冶炼和压延加工业 | C26: 金属制品生产-铝镁铅锌冶炼 | D26: =SUM('GHGs Inventory 2020-2021'!L6:L9) -> 6178.3 | G26: =SUM('GHGs Inventory 2020-2021'!N6:N9) -> 2083
A27: =VLOOKUP($B27,'Sector Match'!$B$1:$C$43,2,0) -> refined petroleum and coke 19 | B27: 石油、煤炭及其他燃料加工业 | C27: 非能源产品使用 | D27: ='GHGs Inventory 2020-2021'!B18 -> 247.7
A28: =VLOOKUP($B28,'Sector Match'!$B$1:$C$43,2,0) -> computers and electronics 26 | B28: 计算机、通信和其他电子设备制造业 | C28: 电子工业生产 | G28: =SUM('GHGs Inventory 2020-2021'!B56:D56) -> 65
A29: =VLOOKUP($B29,'Sector Match'!$B$1:$C$43,2,0) -> glass and glass products 231 | B29: 专用设备制造业 | C29: 消耗臭氧层物质替代物使用 | G29: ='GHGs Inventory 2020-2021'!B57 -> 25834.8
A30: =VLOOKUP($B30,'Sector Match'!$B$1:$C$43,2,0) -> glass and glass products 231 | B30: 专用设备制造业 | C30: 其他产品制造和使用 | G30: ='GHGs Inventory 2020-2021'!D58 -> 9055.6
A31: =VLOOKUP($B31,'Sector Match'!$B$1:$C$43,2,0) -> water and waste 36T39 | B31: 废弃资源综合利用业 | C31: 废弃物处理 | D31: =SUM('GHGs Inventory 2020-2021'!B37) -> 867.1 | E31: =SUM('GHGs Inventory 2020-2021'!C37) -> 738 | F31: =SUM('GHGs Inventory 2020-2021'!D37) -> 10.3
A33: 2021年中国温室气体排放
A34: Sector | B34: 行业 | C34: 对应关系 | D34: CO2 | E34: CH4 | F34: N2O | G34: F-gases
D35: (万吨) | E35: (万吨) | F35: (万吨) | G35: (万吨CO2e）
A36: =VLOOKUP($B36,'Sector Match'!$B$1:$C$43,2,0) -> agriculture and forestry 01T03 | B36: 农、林、牧、渔业 | C36: 动物肠道发酵+动物粪便管理 | E36: =SUM('GHGs Inventory 2020-2021'!F23:F24) -> 1527.1 | F36: =SUM('GHGs Inventory 2020-2021'!G23:G24) -> 22.7
A37: =VLOOKUP($B37,'Sector Match'!$B$1:$C$43,2,0) -> agriculture and forestry 01T03 | B37: 农、林、牧、渔业 | C37: 水稻种植+农用地+秸秆田间焚烧 | E37: =SUM('GHGs Inventory 2020-2021'!F25:F27) -> 900.8 | F37: =SUM('GHGs Inventory 2020-2021'!G25:G27) -> 72.2
A38: =VLOOKUP($B38,'Sector Match'!$B$1:$C$43,2,0) -> coal mining 05 | B38: 煤炭开采和洗选业 | C38: 固体燃料逃逸排放 | E38: ='GHGs Inventory 2020-2021'!F12 -> 2503
A39: =VLOOKUP($B39,'Sector Match'!$B$1:$C$43,2,0) -> energy pipelines and gas processing 352T353 | B39: 燃气生产和供应业 | C39: 油气系统逃逸排放 | E39: ='GHGs Inventory 2020-2021'!F13 -> 175.5
A40: =VLOOKUP($B40,'Sector Match'!$B$1:$C$43,2,0) -> chemicals 20 | B40: 化学原料和化学制品制造业 | C40: 化学工业生产 | D40: ='GHGs Inventory 2020-2021'!E16 -> 32877.5 | F40: ='GHGs Inventory 2020-2021'!G16 -> 58 | G40: =SUM('GHGs Inventory 2020-2021'!E53:G53) -> 2931
A41: =VLOOKUP($B41,'Sector Match'!$B$1:$C$43,2,0) -> cement and other nonmetallic minerals 239 | B41: 非金属矿物制品业 | C41: 非金属矿物制品生产 | D41: ='GHGs Inventory 2020-2021'!E15 -> 101302.7
...

Sheet CN-Med-Growth Rate
A1: 工业产品产量
A2: 行业 | B2: 温室气体 | C2: 产品产量 | D2: 单位 | E2: 数据来源 | F2: 2018 | G2: 2019 | H2: 2020 | I2: 2021 | J2: 2022 | K2: 2023 | L2: 2024 | M2: 2025 | N2: 2026 | O2: 2027 | P2: 2028 | Q2: 2029 | R2: 2030 | S2: 2031 | T2: 2032 | U2: 2033 | V2: 2034 | W2: 2035 | X2: 2036 | Y2: 2037 | Z2: 2038 | AA2: 2039 | AB2: 2040 | AC2: 2041 | AD2: 2042 | AE2: 2043 | AF2: 2044 | AG2: 2045 | AH2: 2046 | AI2: 2047 | AJ2: 2048 | AK2: 2049 | AL2: 2050 | AM2: 2051 | AN2: 2052 | AO2: 2053 | AP2: 2054 | AQ2: 2055 | AR2: 2056 | AS2: 2057 | AT2: 2058 | AU2: 2059 | AV2: 2060
A3: 农、林、牧、渔业 | B3: CH4+N2O | C3: 人口 | D3: 亿人 | E3: WR | F3: 13.9538 | G3: 14.007931 | H3: 14.131352 | I3: 14.16016 | J3: 14.188968 | K3: 14.217777 | L3: 14.246585 | M3: 14.275393 | N3: 14.271093 | O3: 14.266794 | P3: 14.262494 | Q3: 14.258194 | R3: 14.253895 | S3: 14.234383 | T3: 14.214872 | U3: 14.195361 | V3: 14.17585 | W3: 14.156338 | X3: 14.120965 | Y3: 14.085592 | Z3: 14.050219 | AA3: 14.014845 | AB3: 13.979472 | AC3: 13.931014 | AD3: 13.882556 | AE3: 13.834097 | AF3: 13.785639 | AG3: 13.737181 | AH3: 13.667318 | AI3: 13.597456 | AJ3: 13.527593 | AK3: 13.457731 | AL3: 13.387868 | AM3: 13.293637 | AN3: 13.199406 | AO3: 13.105175 | AP3: 13.010944 | AQ3: 12.916713 | AR3: 12.803762 | AS3: 12.690811 | AT3: 12.577859 | AU3: 12.464908 | AV3: 12.351956
A4: 煤炭开采和洗选业 | B4: CH4 | C4: 原煤 | D4: 亿吨 | E4: 中石化《中国能源展望2060》 | F4: 36.98 | G4: 38.46 | H4: 39.02 | I4: 41.26 | J4: 45.59 | K4: 46.826667 | L4: 48.063333 | M4: 49.25 | N4: 50.05 | O4: 50.85 | P4: 51.65 | Q4: 52.48 | R4: 53.3 | S4: 53.45 | T4: 53.6 | U4: 53.725 | V4: 53.8 | W4: 53.825 | X4: 53.19 | Y4: 52.555 | Z4: 51.92 | AA4: 51.285 | AB4: 50.65 | AC4: 49.67 | AD4: 48.69 | AE4: 47.71 | AF4: 46.73 | AG4: 45.75 | AH4: 44.86 | AI4: 43.97 | AJ4: 43.08 | AK4: 42.19 | AL4: 41.3 | AM4: 40.3 | AN4: 39.3 | AO4: 38.3 | AP4: 37.3 | AQ4: 36.3 | AR4: 35.41 | AS4: 34.52 | AT4: 33.63 | AU4: 32.74 | AV4: 31.85
A5: 石油和天然气开采业 | B5: CH4 | C5: 原油 | D5: 亿吨 | E5: 中石油《世界与中国能源展望2021》 | F5: 1.8932 | G5: 1.9101 | H5: 1.9477 | I5: 1.9888 | J5: 2.0472 | K5: 2.0911333 | L5: 2.1350667 | M5: 2.1775 | N5: 2.1895 | O5: 2.2015 | P5: 2.2135 | Q5: 2.22928 | R5: 2.245 | S5: 2.258 | T5: 2.2736 | U5: 2.29 | V5: 2.308 | W5: 2.325 | X5: 2.3254 | Y5: 2.3258 | Z5: 2.3262 | AA5: 2.3266 | AB5: 2.327 | AC5: 2.3088 | AD5: 2.2906 | AE5: 2.2724 | AF5: 2.2542 | AG5: 2.236 | AH5: 2.2088 | AI5: 2.1816 | AJ5: 2.1544 | AK5: 2.1272 | AL5: 2.1 | AM5: 2.061 | AN5: 2.022 | AO5: 1.983 | AP5: 1.944 | AQ5: 1.905 | AR5: 1.8804 | AS5: 1.8558 | AT5: 1.8312 | AU5: 1.8066 | AV5: 1.782
A6: 石油和天然气开采业 | B6: CH4 | C6: 天然气 | D6: 亿立方米 | E6: 中石油《世界与中国能源展望2021》 | F6: 1601.59 | G6: 1761.74 | H6: 1924.95 | I6: 2075.84 | J6: 2201.1 | K6: 2309.1 | L6: 2417.1 | M6: 2519.75 | N6: 2590.8 | O6: 2661.85 | P6: 2732.9 | Q6: 2811.792 | R6: 2890 | S6: 2933 | T6: 2982.4 | U6: 3035.5 | V6: 3096 | W6: 3157.5 | X6: 3197.5 | Y6: 3237.5 | Z6: 3277.5 | AA6: 3317.5 | AB6: 3357.5 | AC6: 3380.2 | AD6: 3402.9 | AE6: 3425.6 | AF6: 3448.3 | AG6: 3471 | AH6: 3488.3 | AI6: 3505.6 | AJ6: 3522.9 | AK6: 3540.2 | AL6: 3557.5 | AM6: 3577.5 | AN6: 3597.5 | AO6: 3617.5 | AP6: 3637.5 | AQ6: 3657.5 | AR6: 3662 | AS6: 3666.5 | AT6: 3671 | AU6: 3675.5 | AV6: 3680
A7: 石油、煤炭及其他燃料加工业 | B7: CO2 | C7: 原油加工 | D7: 亿吨 | E7: 加工量与原油产量挂钩 | F7: 6 | G7: 6.5 | H7: 6.7441 | I7: 7 | J7: 6.759 | K7: 6.9040495 | L7: 7.0490991 | M7: 7.1891962 | N7: 7.2288152 | O7: 7.2684342 | P7: 7.3080532 | Q7: 7.3601522 | R7: 7.412053 | S7: 7.4549736 | T7: 7.5064783 | U7: 7.5606243 | V7: 7.6200528 | W7: 7.6761797 | X7: 7.6775003 | Y7: 7.6788209 | Z7: 7.6801416 | AA7: 7.6814622 | AB7: 7.6827828 | AC7: 7.622694 | AD7: 7.5626052 | AE7: 7.5025164 | AF7: 7.4424276 | AG7: 7.3823388 | AH7: 7.2925358 | AI7: 7.2027327 | AJ7: 7.1129297 | AK7: 7.0231266 | AL7: 6.9333236 | AM7: 6.8045618 | AN7: 6.6758001 | AO7: 6.5470384 | AP7: 6.4182767 | AQ7: 6.2895149 | AR7: 6.208296 | AS7: 6.1270771 | AT7: 6.0458581 | AU7: 5.9646392 | AV7: 5.8834203
A8: 化学原料和化学制品制造业 | B8: CO2 | C8: 电石 | D8: 万吨 | E8: 拍数 | F8: 2688.48 | G8: 2522.49 | H8: 2795 | I8: 2820 | J8: 2850 | K8: 2900 | L8: 2950 | M8: 3000 | N8: 3025 | O8: 3050 | P8: 3075 | Q8: 3100 | R8: 3125 | S8: 3150 | T8: 3175 | U8: 3200 | V8: 3179.1667 | W8: 3158.3333 | X8: 3137.5 | Y8: 3116.6667 | Z8: 3095.8333 | AA8: 3075 | AB8: 3054.1667 | AC8: 3033.3333 | AD8: 3012.5 | AE8: 2991.6667 | AF8: 2970.8333 | AG8: 2950 | AH8: 2932 | AI8: 2914 | AJ8: 2896 | AK8: 2878 | AL8: 2860 | AM8: 2842 | AN8: 2824 | AO8: 2806 | AP8: 2788 | AQ8: 2770 | AR8: 2752 | AS8: 2734 | AT8: 2716 | AU8: 2698 | AV8: 2680
A9: 化学原料和化学制品制造业 | B9: N2O | C9: 己二酸 | D9: 万吨 | E9: 拍数 | F9: 137.54 | G9: 140.04 | H9: 155.71 | I9: 189 | J9: 199.25 | K9: 209.5 | L9: 219.75 | M9: 230 | N9: 232.22222 | O9: 234.44444 | P9: 236.66667 | Q9: 238.88889 | R9: 241.11111 | S9: 243.33333 | T9: 245.55556 | U9: 247.77778 | V9: 250 | W9: 248.18182 | X9: 246.36364 | Y9: 244.54545 | Z9: 242.72727 | AA9: 240.90909 | AB9: 239.09091 | AC9: 237.27273 | AD9: 235.45455 | AE9: 233.63636 | AF9: 231.81818 | AG9: 230 | AH9: 227 | AI9: 224 | AJ9: 221 | AK9: 218 | AL9: 215 | AM9: 212 | AN9: 209 | AO9: 206 | AP9: 203 | AQ9: 200 | AR9: 197 | AS9: 194 | AT9: 191 | AU9: 188 | AV9: 185
A10: 化学原料和化学制品制造业 | B10: N2O | C10: 浓硝酸 | D10: 万吨 | E10: 拍数 | F10: 246.85 | G10: 244.17 | H10: 232.31 | I10: 224.95 | J10: 201.43 | K10: 194.28667 | L10: 187.14333 | M10: 180 | N10: 176.5 | O10: 173 | P10: 169.5 | Q10: 166 | R10: 162.5 | S10: 159 | T10: 155.5 | U10: 152 | V10: 148.5 | W10: 145 | X10: 142.8 | Y10: 140.6 | Z10: 138.4 | AA10: 136.2 | AB10: 134 | AC10: 131.8 | AD10: 129.6 | AE10: 127.4 | AF10: 125.2 | AG10: 123 | AH10: 120.8 | AI10: 118.6 | AJ10: 116.4 | AK10: 114.2 | AL10: 112 | AM10: 109.8 | AN10: 107.6 | AO10: 105.4 | AP10: 103.2 | AQ10: 101 | AR10: 98.8 | AS10: 96.6 | AT10: 94.4 | AU10: 92.2 | AV10: 90
A11: 化学原料和化学制品制造业 | B11: F-gases | C11: HCFCs | D11: 万吨 | E11: 拍数 | F11: 85.17 | G11: 88.95 | H11: 86.69 | I11: 93.16 | J11: 97.37 | K11: 101.58 | L11: 105.79 | M11: 110 | N11: 111.875 | O11: 113.75 | P11: 115.625 | Q11: 117.5 | R11: 119.375 | S11: 121.25 | T11: 123.125 | U11: 125 | V11: 123.75 | W11: 122.5 | X11: 121.25 | Y11: 120 | Z11: 118.75 | AA11: 117.5 | AB11: 116.25 | AC11: 115 | AD11: 113.75 | AE11: 112.5 | AF11: 111.25 | AG11: 110 | AH11: 108.66667 | AI11: 107.33333 | AJ11: 106 | AK11: 104.66667 | AL11: 103.33333 | AM11: 102 | AN11: 100.66667 | AO11: 99.333333 | AP11: 98 | AQ11: 96.666667 | AR11: 95.333333 | AS11: 94 | AT11: 92.666667 | AU11: 91.333333 | AV11: 90
A12: 非金属矿物制品业 | B12: CO2 | C12: 水泥 | D12: 万吨 | E12: 中国能源研究会-内部报告 | F12: 223609.62 | G12: 234430.62 | H12: 239470.83 | I12: 237724.49 | J12: 212927.18 | K12: 219951.45 | L12: 226975.73 | M12: 235000 | N12: 237100 | O12: 239200 | P12: 241300 | Q12: 242368 | R12: 243600 | S12: 240600 | T12: 236840 | U12: 232700 | V12: 227800 | W12: 222900 | X12: 218610 | Y12: 214320 | Z12: 210030 | AA12: 205740 | AB12: 201450 | AC12: 195560 | AD12: 189670 | AE12: 183780 | AF12: 177890 | AG12: 172000 | AH12: 167780 | AI12: 163560 | AJ12: 159340 | AK12: 155120 | AL12: 150900 | AM12: 148120 | AN12: 145340 | AO12: 142560 | AP12: 139780 | AQ12: 137000 | AR12: 135577.12 | AS12: 134154.23 | AT12: 132731.35 | AU12: 131308.46 | AV12: 129885.58
A13: 黑色金属冶炼和压延加工业 | B13: CO2+CH4 | C13: 粗钢 | D13: 万吨 | E13: 中国能源研究会-内部报告 | F13: 92903.84 | G13: 99541.89 | H13: 106476.68 | I13: 103524.26 | J13: 101795.9 | K13: 108463.93 | L13: 115131.97 | M13: 122500 | N13: 124800 | O13: 127100 | P13: 129400 | Q13: 131040 | R13: 132800 | S13: 132520 | T13: 131696 | U13: 130520 | V13: 128640 | W13: 126600 | X13: 124910 | Y13: 123220 | Z13: 121530 | AA13: 119840 | AB13: 118150 | AC13: 115510 | AD13: 112870 | AE13: 110230 | AF13: 107590 | AG13: 104950 | AH13: 102220 | AI13: 99490 | AJ13: 96760 | AK13: 94030 | AL13: 91300 | AM13: 88880 | AN13: 86460 | AO13: 84040 | AP13: 81620 | AQ13: 79200 | AR13: 76797.059 | AS13: 74394.118 | AT13: 71991.176 | AU13: 69588.235 | AV13: 67185.294
... A17: 计算机、通信和其他电子设备制造业 | B17: F-gases | C17: 增加值 | D17: 亿美元 | E17: Smart trans | F17: 3815.9156 | G17: 4021.3432 | H17: 4189.6426 | I17: 5047.0783 | J17: 5516.6343 | K17: 5670.9902 | L17: 6049.7711 | M17: 6517.8327 | N17: 6937.6804 | O17: 7288.3573 | P17: 7588.9287 | Q17: 7864.9854 | R17: 8147.29 | S17: 8463.9122 | T17: 8816.0027 | U17: 9196.6253 | V17: 9597.4332 | W17: 10008.411 | X17: 10419.682 | Y17: 10827.99 | Z17: 11231.875 | AA17: 11629.865 | AB17: 12020.488 | AC17: 12402.28 | AD17: 12773.796 | AE17: 13133.618 | AF17: 13480.368 | AG17: 13812.715 | AH17: 14129.387 | AI17: 14429.175 | AJ17: 14710.947 | AK17: 14973.649 | AL17: 15216.318 | AM17: 15438.083 | AN17: 15638.175 | AO17: 15815.925 | AP17: 15970.776 | AQ17: 16102.275 | AR17: 16210.086 | AS17: 16293.981 | AT17: 16353.846 | AU17: 16389.677 | AV17: 16401.579
A20: 产品过程排放因子
A21: 行业 | B21: 温室气体 | C21: 产品 | D21: 单位 | E21: 工业过程排放因子 | F21: 数据来源
A22: 石油和天然气开采业 | B22: CH4 | C22: 原油 | D22: g CH4/吨 原油 | E22: =2.91/0.9/1000*10^6 -> 3233.3333 | F22: 《中国油气行业甲烷逃逸排放核算与时空特征研究》原油生产，路上低排放技术2.91t/1000m3。原油密度0.9t/m3;
A23: 石油和天然气开采业 | B23: CH4 | C23: 天然气 | D23: g CH4/吨 原油 | E23: =2.54/10^2*10^6 -> 25400 | F23: 《中国油气行业甲烷逃逸排放核算与时空特征研究》天然气生产，路上低排放技术2.54t/百万m3。
A24: 化学原料和化学制品制造业 | B24: N2O | C24: 己二酸 | D24: g N2O/吨己二酸 | E24: =0.293*10^6 -> 293000 | F24: 省级温室气体排放清单
A25: 化学原料和化学制品制造业 | B25: N2O | C25: 浓硝酸 | D25: g N2O/吨硝酸 | E25: =8*10^3 -> 8000 | F25: 省级温室气体排放清单
A29: 指数=产品产量*过程排放因子
A30: Sector | B30: 行业 | C30: 温室气体 | D30: Multiplier | E30: 2018 | F30: 2019 | G30: 2020 | H30: 2021 | I30: 2022 | J30: 2023 | K30: 2024 | L30: 2025 | M30: 2026 | N30: 2027 | O30: 2028 | P30: 2029 | Q30: 2030 | R30: 2031 | S30: 2032 | T30: 2033 | U30: 2034 | V30: 2035 | W30: 2036 | X30: 2037 | Y30: 2038 | Z30: 2039 | AA30: 2040 | AB30: 2041 | AC30: 2042 | AD30: 2043 | AE30: 2044 | AF30: 2045 | AG30: 2046 | AH30: 2047 | AI30: 2048 | AJ30: 2049 | AK30: 2050 | AL30: 2051 | AM30: 2052 | AN30: 2053 | AO30: 2054 | AP30: 2055 | AQ30: 2056 | AR30: 2057 | AS30: 2058 | AT30: 2059 | AU30: 2060
A31: =VLOOKUP($B31,'Sector Match'!$B$1:$C$43,2,0) -> agriculture and forestry 01T03 | B31: 农、林、牧、渔业 | C31: CH4 | D31: 人口增长 | E31: 1 | F31: 1 | G31: 1 | H31: 1 | I31: =J3/$I3 -> 1.0020345 | J31: =K3/$I3 -> 1.0040689 | K31: =L3/$I3 -> 1.0061034 | L31: =M3/$I3 -> 1.0081378 | M31: =N3/$I3 -> 1.0078342 | N31: =O3/$I3 -> 1.0075305 | O31: =P3/$I3 -> 1.0072269 | P31: =Q3/$I3 -> 1.0069233 | ... AU31: =AV3/$I3 -> 0.87230345
A32: =VLOOKUP($B32,'Sector Match'!$B$1:$C$43,2,0) -> agriculture and forestry 01T03 | B32: 农、林、牧、渔业 | C32: N2O | D32: 人口增长 | E32: 1 | F32: 1 | G32: 1 | H32: 1 | I32: =J3/$I3 -> 1.0020345 | J32: =K3/$I3 -> 1.0040689 | K32: =L3/$I3 -> 1.0061034 | L32: =M3/$I3 -> 1.0081378 | M32: =N3/$I3 -> 1.0078342 | N32: =O3/$I3 -> 1.0075305 | O32: =P3/$I3 -> 1.0072269 | P32: =Q3/$I3 -> 1.0069233 | ... AU32: =AV3/$I3 -> 0.87230345
A33: =VLOOKUP($B33,'Sector Match'!$B$1:$C$43,2,0) -> coal mining 05 | B33: 煤炭开采和洗选业 | C33: CH4 | D33: 原煤产量增长 | E33: 1 | F33: 1 | G33: 1 | H33: 1 | I33: =J4/$I4 -> 1.1049443 | J33: =K4/$I4 -> 1.1349168 | K33: =L4/$I4 -> 1.1648893 | L33: =M4/$I4 -> 1.19365 | M33: =N4/$I4 -> 1.2130393 | N33: =O4/$I4 -> 1.2324285 | O33: =P4/$I4 -> 1.2518177 | P33: =Q4/$I4 -> 1.2719341 | ... AU33: =AV4/$I4 -> 0.77193408
A34: =VLOOKUP($B34,'Sector Match'!$B$1:$C$43,2,0) -> energy pipelines and gas processing 352T353 | B34: 燃气生产和供应业 | C34: CH4 | D34: 原油+天然气产量加权增长率 | E34: 1 | F34: 1 | G34: 1 | H34: 1 | I34: =(J5*$E$22+J6*$E$23)/($I5*$E$22+$I6*$E$23) -> 1.0603381 | J34: =(K5*$E$22+K6*$E$23)/($I5*$E$22+$I6*$E$23) -> 1.1123615 | K34: =(L5*$E$22+L6*$E$23)/($I5*$E$22+$I6*$E$23) -> 1.164385 | L34: =(M5*$E$22+M6*$E$23)/($I5*$E$22+$I6*$E$23) -> 1.2138315 | M34: =(N5*$E$22+N6*$E$23)/($I5*$E$22+$I6*$E$23) -> 1.2480551 | N34: =(O5*$E$22+O6*$E$23)/($I5*$E$22+$I6*$E$23) -> 1.2822788 | O34: =(P5*$E$22+P6*$E$23)/($I5*$E$22+$I6*$E$23) -> 1.3165025 | P34: =(Q5*$E$22+Q6*$E$23)/($I5*$E$22+$I6*$E$23) -> 1.3545037 | ... AU34: =(AV5*$E$22+AV6*$E$23)/($I5*$E$22+$I6*$E$23) -> 1.7726694
A35: =VLOOKUP($B35,'Sector Match'!$B$1:$C$43,2,0) -> refined petroleum and coke 19 | B35: 石油、煤炭及其他燃料加工业 | C35: CO2 | D35: 原油加工量增长 | E35: 1 | F35: 1 | G35: 1 | H35: 1 | I35: =J7/$I7 -> 0.96557143 | J35: =K7/$I7 -> 0.98629279 | K35: =L7/$I7 -> 1.0070142 | L35: =M7/$I7 -> 1.027028 | M35: =N7/$I7 -> 1.0326879 | N35: =O7/$I7 -> 1.0383477 | O35: =P7/$I7 -> 1.0440076 | P35: =Q7/$I7 -> 1.0514503 | ... AU35: =AV7/$I7 -> 0.84048861
A36: =VLOOKUP($B36,'Sector Match'!$B$1:$C$43,2,0) -> chemicals 20 | B36: 化学原料和化学制品制造业 | C36: CO2 | D36: 电石产量增长 | E36: 1 | F36: 1 | G36: 1 | H36: 1 | I36: =J8/$I8 -> 1.0106383 | J36: =K8/$I8 -> 1.0283688 | K36: =L8/$I8 -> 1.0460993 | L36: =M8/$I8 -> 1.0638298 | M36: =N8/$I8 -> 1.072695 | N36: =O8/$I8 -> 1.0815603 | O36: =P8/$I8 -> 1.0904255 | P36: =Q8/$I8 -> 1.0992908 | ... AU36: =AV8/$I8 -> 0.95035461
A37: =VLOOKUP($B37,'Sector Match'!$B$1:$C$43,2,0) -> chemicals 20 | B37: 化学原料和化学制品制造业 | C37: N2O | D37: 己二酸+浓硝酸产量加权增长率 | E37: 1 | F37: 1 | G37: 1 | H37: 1 | I37: =(J9*$E$24+J10*$E$25)/($I9*$E$24+$I10*$E$25) -> 1.049235 | J37: =(K9*$E$24+K10*$E$25)/($I9*$E$24+$I10*$E$25) -> 1.1007614 | K37: =(L9*$E$24+L10*$E$25)/($I9*$E$24+$I10*$E$25) -> 1.1522878 | L37: =(M9*$E$24+M10*$E$25)/($I9*$E$24+$I10*$E$25) -> 1.2038141 | M37: =(N9*$E$24+N10*$E$25)/($I9*$E$24+$I10*$E$25) -> 1.2147122 | N37: =(O9*$E$24+O10*$E$25)/($I9*$E$24+$I10*$E$25) -> 1.2256102 | O37: =(P9*$E$24+P10*$E$25)/($I9*$E$24+$I10*$E$25) -> 1.2365082 | P37: =(Q9*$E$24+Q10*$E$25)/($I9*$E$24+$I10*$E$25) -> 1.2474062 | ... AU37: =(AV9*$E$24+AV10*$E$25)/($I9*$E$24+$I10*$E$25) -> 0.96062025
A38: =VLOOKUP($B38,'Sector Match'!$B$1:$C$43,2,0) -> chemicals 20 | B38: 化学原料和化学制品制造业 | C38: F-gases | D38: HCFCs产量增长 | E38: 1 | F38: 1 | G38: 1 | H38: 1 | I38: =J11/$I11 -> 1.0451911 | J38: =K11/$I11 -> 1.0903821 | K38: =L11/$I11 -> 1.1355732 | L38: =M11/$I11 -> 1.1807643 | M38: =N11/$I11 -> 1.2008909 | N38: =O11/$I11 -> 1.2210176 | O38: =P11/$I11 -> 1.2411443 | P38: =Q11/$I11 -> 1.2612709 | ... AU38: =AV11/$I11 -> 0.96607986
A39: =VLOOKUP($B39,'Sector Match'!$B$1:$C$43,2,0) -> cement and other nonmetallic minerals 239 | B39: 非金属矿物制品业 | C39: CO2 | D39: 水泥产量增长 | E39: 1 | F39: 1 | G39: 1 | H39: 1 | I39: =J12/$I12 -> 0.89568887 | J39: =K12/$I12 -> 0.92523683 | K39: =L12/$I12 -> 0.95478479 | L39: =M12/$I12 -> 0.9885393 | M39: =N12/$I12 -> 0.99737305 | N39: =O12/$I12 -> 1.0062068 | O39: =P12/$I12 -> 1.0150406 | P39: =Q12/$I12 -> 1.0195332 | ... AU39: =AV12/$I12 -> 0.54637021
A40: =VLOOKUP($B40,'Sector Match'!$B$1:$C$43,2,0) -> iron and steel 241 | B40: 黑色金属冶炼和压延加工业 | C40: CO2 | D40: 粗钢产量增长 | E40: 1 | F40: 1 | G40: 1 | H40: 1 | I40: =J13/$I13 -> 0.98330478 | J40: =K13/$I13 -> 1.0477151 | K40: =L13/$I13 -> 1.1121255 | L40: =M13/$I13 -> 1.1832975 | M40: =N13/$I13 -> 1.2055145 | N40: =O13/$I13 -> 1.2277315 | O40: =P13/$I13 -> 1.2499486 | P40: =Q13/$I13 -> 1.2657903 | ... AU40: =AV13/$I13 -> 0.64898116
A41: =VLOOKUP($B41,'Sector Match'!$B$1:$C$43,2,0) -> iron and steel 241 | B41: 黑色金属冶炼和压延加工业 | C41: CH4 | D41: 粗钢产量增长 | E41: 1 | F41: 1 | G41: 1 | H41: 1 | I41: =J13/$I13 -> 0.98330478 | J41: =K13/$I13 -> 1.0477151 | K41: =L13/$I13 -> 1.1121255 | L41: =M13/$I13 -> 1.1832975 | M41: =N13/$I13 -> 1.2055145 | N41: =O13/$I13 -> 1.2277315 | O41: =P13/$I13 -> 1.2499486 | P41: =Q13/$I13 -> 1.2657903 | ... AU41: =AV13/$I13 -> 0.64898116
A42: =VLOOKUP($B42,'Sector Match'!$B$1:$C$43,2,0) -> other metals 242 | B42: 有色金属冶炼和压延加工业 | C42: CO2 | D42: 电解铝产量增长 | E42: 1 | F42: 1 | G42: 1 | H42: 1 | I42: =J14/$I14 -> 1.0426224 | J42: =K14/$I14 -> 1.1214531 | K42: =L14/$I14 -> 1.2002838 | L42: =M14/$I14 -> 1.2823609 | M42: =N14/$I14 -> 1.3420962 | N42: =O14/$I14 -> 1.4018315 | O42: =P14/$I14 -> 1.4615668 | P42: =Q14/$I14 -> 1.5156143 | ... AU42: =AV14/$I14 -> 1.1583453
A43: =VLOOKUP($B43,'Sector Match'!$B$1:$C$43,2,0) -> other metals 242 | B43: 有色金属冶炼和压延加工业 | C43: F-gases | D43: 电解铝产量增长 | E43: 1 | F43: 1 | G43: 1 | H43: 1 | I43: =J14/$I14 -> 1.0426224 | J43: =K14/$I14 -> 1.1214531 | K43: =L14/$I14 -> 1.2002838 | L43: =M14/$I14 -> 1.2823609 | M43: =N14/$I14 -> 1.3420962 | N43: =O14/$I14 -> 1.4018315 | O43: =P14/$I14 -> 1.4615668 | P43: =Q14/$I14 -> 1.5156143 | ... AU43: =AV14/$I14 -> 1.1583453
A44: =VLOOKUP($B44,'Sector Match'!$B$1:$C$43,2,0) -> glass and glass products 231 | B44: 专用设备制造业 | C44: F-gases | D44: 用电量增长 | E44: 1 | F44: 1 | G44: 1 | H44: 1 | I44: =J15/$I15 -> 1.0390242 | J44: =K15/$I15 -> 1.1176499 | K44: =L15/$I15 -> 1.1817438 | L44: =M15/$I15 -> 1.2443581 | M44: =N15/$I15 -> 1.3055649 | N44: =O15/$I15 -> 1.3651477 | O44: =P15/$I15 -> 1.4230825 | P44: =Q15/$I15 -> 1.4792128 | ... AU44: =AV15/$I15 -> 1.9299033
A45: =VLOOKUP($B45,'Sector Match'!$B$1:$C$43,2,0) -> water and waste 36T39 | B45: 废弃资源综合利用业 | C45: CO2 | D45: 人口增长 | E45: 1 | F45: 1 | G45: 1 | H45: 1 | I45: =J16/$I16 -> 1.0020345 | J45: =K16/$I16 -> 1.0040689 | K45: =L16/$I16 -> 1.0061034 | L45: =M16/$I16 -> 1.0081378 | M45: =N16/$I16 -> 1.0078342 | N45: =O16/$I16 -> 1.0075305 | O45: =P16/$I16 -> 1.0072269 | P45: =Q16/$I16 -> 1.0069233 | ... AU45: =AV16/$I16 -> 0.87230345
A46: =VLOOKUP($B46,'Sector Match'!$B$1:$C$43,2,0) -> water and waste 36T39 | B46: 废弃资源综合利用业 | C46: CH4 | D46: 人口增长 | E46: 1 | F46: 1 | G46: 1 | H46: 1 | I46: =J16/$I16 -> 1.0020345 | J46: =K16/$I16 -> 1.0040689 | K46: =L16/$I16 -> 1.0061034 | L46: =M16/$I16 -> 1.0081378 | M46: =N16/$I16 -> 1.0078342 | N46: =O16/$I16 -> 1.0075305 | O46: =P16/$I16 -> 1.0072269 | P46: =Q16/$I16 -> 1.0069233 | ... AU46: =AV16/$I16 -> 0.87230345
A47: =VLOOKUP($B47,'Sector Match'!$B$1:$C$43,2,0) -> water and waste 36T39 | B47: 废弃资源综合利用业 | C47: N2O | D47: 人口增长 | E47: 1 | F47: 1 | G47: 1 | H47: 1 | I47: =J16/$I16 -> 1.0020345 | J47: =K16/$I16 -> 1.0040689 | K47: =L16/$I16 -> 1.0061034 | L47: =M16/$I16 -> 1.0081378 | M47: =N16/$I16 -> 1.0078342 | N47: =O16/$I16 -> 1.0075305 | O47: =P16/$I16 -> 1.0072269 | P47: =Q16/$I16 -> 1.0069233 | ... AU47: =AV16/$I16 -> 0.87230345
A48: =VLOOKUP($B48,'Sector Match'!$B$1:$C$43,2,0) -> computers and electronics 26 | B48: 计算机、通信和其他电子设备制造业 | C48: F-gases | D48: 增加值 | E48: 1 | F48: 1 | G48: 1 | H48: 1 | I48: =J17/$I17 -> 1.0930352 | J48: =K17/$I17 -> 1.1236184 | K48: =L17/$I17 -> 1.198668 | L48: =M17/$I17 -> 1.2914071 | M48: =N17/$I17 -> 1.3745934 | N48: =O17/$I17 -> 1.4440746 | O48: =P17/$I17 -> 1.5036281 | P48: =Q17/$I17 -> 1.5583244 | ... AU48: =AV17/$I17 -> 3.2497177

Sheet CN-Med-BPE-CO2
A1: Pollutant: | B1: CO2 | C1: =_xlfn.CONCAT("Unit: grams of ",B1) -> Unit: grams of CO2
B2: 2018 | C2: 2019 | D2: 2020 | E2: 2021 | F2: 2022 | G2: 2023 | H2: 2024 | I2: 2025 | J2: 2026 | K2: 2027 | L2: 2028 | M2: 2029 | N2: 2030 | O2: 2031 | P2: 2032 | Q2: 2033 | R2: 2034 | S2: 2035 | T2: 2036 | U2: 2037 | V2: 2038 | W2: 2039 | X2: 2040 | Y2: 2041 | Z2: 2042 | AA2: 2043 | AB2: 2044 | AC2: 2045 | AD2: 2046 | AE2: 2047 | AF2: 2048 | AG2: 2049 | AH2: 2050 | AI2: 2051 | AJ2: 2052 | AK2: 2053 | AL2: 2054 | AM2: 2055 | AN2: 2056 | AO2: 2057 | AP2: 2058 | AQ2: 2059 | AR2: 2060
A3: agriculture and forestry 01T03 | B3: =SUMIFS('GHG Emissions 2018-2021'!$D$4:$D$14,'GHG Emissions 2018-2021'!$A$4:$A$14,$A3)*10^10 -> 0 | C3: =AVERAGE(B3,D3) -> 0 | D3: =SUMIFS('GHG Emissions 2018-2021'!$D$19:$D$31,'GHG Emissions 2018-2021'!$A$19:$A$31,$A3)*10^10 -> 0 | E3: =SUMIFS('GHG Emissions 2018-2021'!$D$36:$D$48,'GHG Emissions 2018-2021'!$A$36:$A$48,$A3)*10^10 -> 0 | F3: =$E3*SUMIFS('CN-Med-Growth Rate'!I$31:I$47,'CN-Med-Growth Rate'!$A$31:$A$47,$A3,'CN-Med-Growth Rate'!$C$31:$C$47,$B$1) -> 0 | G3: =$E3*SUMIFS('CN-Med-Growth Rate'!J$31:J$47,'CN-Med-Growth Rate'!$A$31:$A$47,$A3,'CN-Med-Growth Rate'!$C$31:$C$47,$B$1) -> 0 | H3: =$E3*SUMIFS('CN-Med-Growth Rate'!K$31:K$47,'CN-Med-Growth Rate'!$A$31:$A$47,$A3,'CN-Med-Growth Rate'!$C$31:$C$47,$B$1) -> 0 | I3: =$E3*SUMIFS('CN-Med-Growth Rate'!L$31:L$47,'CN-Med-Growth Rate'!$A$31:$A$47,$A3,'CN-Med-Growth Rate'!$C$31:$C$47,$B$1) -> 0 | J3: =$E3*SUMIFS('CN-Med-Growth Rate'!M$31:M$47,'CN-Med-Growth Rate'!$A$31:$A$47,$A3,'CN-Med-Growth Rate'!$C$31:$C$47,$B$1) -> 0 | K3: =$E3*SUMIFS('CN-Med-Growth Rate'!N$31:N$47,'CN-Med-Growth Rate'!$A$31:$A$47,$A3,'CN-Med-Growth Rate'!$C$31:$C$47,$B$1) -> 0 | L3: =$E3*SUMIFS('CN-Med-Growth Rate'!O$31:O$47,'CN-Med-Growth Rate'!$A$31:$A$47,$A3,'CN-Med-Growth Rate'!$C$31:$C$47,$B$1) -> 0 | M3: =$E3*SUMIFS('CN-Med-Growth Rate'!P$31:P$47,'CN-Med-Growth Rate'!$A$31:$A$47,$A3,'CN-Med-Growth Rate'!$C$31:$C$47,$B$1) -> 0 | ... AR3: =$E3*SUMIFS('CN-Med-Growth Rate'!AU$31:AU$47,'CN-Med-Growth Rate'!$A$31:$A$47,$A3,'CN-Med-Growth Rate'!$C$31:$C$47,$B$1) -> 0
A4: coal mining 05 | B4: =SUMIFS('GHG Emissions 2018-2021'!$D$4:$D$14,'GHG Emissions 2018-2021'!$A$4:$A$14,$A4)*10^10 -> 0 | C4: =AVERAGE(B4,D4) -> 0 | D4: =SUMIFS('GHG Emissions 2018-2021'!$D$19:$D$31,'GHG Emissions 2018-2021'!$A$19:$A$31,$A4)*10^10 -> 0 | E4: =SUMIFS('GHG Emissions 2018-2021'!$D$36:$D$48,'GHG Emissions 2018-2021'!$A$36:$A$48,$A4)*10^10 -> 0 | F4: =$E4*SUMIFS('CN-Med-Growth Rate'!I$31:I$47,'CN-Med-Growth Rate'!$A$31:$A$47,$A4,'CN-Med-Growth Rate'!$C$31:$C$47,$B$1) -> 0 | G4: =$E4*SUMIFS('CN-Med-Growth Rate'!J$31:J$47,'CN-Med-Growth Rate'!$A$31:$A$47,$A4,'CN-Med-Growth Rate'!$C$31:$C$47,$B$1) -> 0 | H4: =$E4*SUMIFS('CN-Med-Growth Rate'!K$31:K$47,'CN-Med-Growth Rate'!$A$31:$A$47,$A4,'CN-Med-Growth Rate'!$C$31:$C$47,$B$1) -> 0 | I4: =$E4*SUMIFS('CN-Med-Growth Rate'!L$31:L$47,'CN-Med-Growth Rate'!$A$31:$A$47,$A4,'CN-Med-Growth Rate'!$C$31:$C$47,$B$1) -> 0 | J4: =$E4*SUMIFS('CN-Med-Growth Rate'!M$31:M$47,'CN-Med-Growth Rate'!$A$31:$A$47,$A4,'CN-Med-Growth Rate'!$C$31:$C$47,$B$1) -> 0 | K4: =$E4*SUMIFS('CN-Med-Growth Rate'!N$31:N$47,'CN-Med-Growth Rate'!$A$31:$A$47,$A4,'CN-Med-Growth Rate'!$C$31:$C$47,$B$1) -> 0 | L4: =$E4*SUMIFS('CN-Med-Growth Rate'!O$31:O$47,'CN-Med-Growth Rate'!$A$31:$A$47,$A4,'CN-Med-Growth Rate'!$C$31:$C$47,$B$1) -> 0 | M4: =$E4*SUMIFS('CN-Med-Growth Rate'!P$31:P$47,'CN-Med-Growth Rate'!$A$31:$A$47,$A4,'CN-Med-Growth Rate'!$C$31:$C$47,$B$1) -> 0 | ... AR4: =$E4*SUMIFS('CN-Med-Growth Rate'!AU$31:AU$47,'CN-Med-Growth Rate'!$A$31:$A$47,$A4,'CN-Med-Growth Rate'!$C$31:$C$47,$B$1) -> 0
A5: oil and gas extraction 06 | B5: =SUMIFS('GHG Emissions 2018-2021'!$D$4:$D$14,'GHG Emissions 2018-2021'!$A$4:$A$14,$A5)*10^10 -> 0 | C5: =AVERAGE(B5,D5) -> 0 | D5: =SUMIFS('GHG Emissions 2018-2021'!$D$19:$D$31,'GHG Emissions 2018-2021'!$A$19:$A$31,$A5)*10^10 -> 0 | E5: =SUMIFS('GHG Emissions 2018-2021'!$D$36:$D$48,'GHG Emissions 2018-2021'!$A$36:$A$48,$A5)*10^10 -> 0 | F5: =$E5*SUMIFS('CN-Med-Growth Rate'!I$31:I$47,'CN-Med-Growth Rate'!$A$31:$A$47,$A5,'CN-Med-Growth Rate'!$C$31:$C$47,$B$1) -> 0 | G5: =$E5*SUMIFS('CN-Med-Growth Rate'!J$31:J$47,'CN-Med-Growth Rate'!$A$31:$A$47,$A5,'CN-Med-Growth Rate'!$C$31:$C$47,$B$1) -> 0 | H5: =$E5*SUMIFS('CN-Med-Growth Rate'!K$31:K$47,'CN-Med-Growth Rate'!$A$31:$A$47,$A5,'CN-Med-Growth Rate'!$C$31:$C$47,$B$1) -> 0 | I5: =$E5*SUMIFS('CN-Med-Growth Rate'!L$31:L$47,'CN-Med-Growth Rate'!$A$31:$A$47,$A5,'CN-Med-Growth Rate'!$C$31:$C$47,$B$1) -> 0 | J5: =$E5*SUMIFS('CN-Med-Growth Rate'!M$31:M$47,'CN-Med-Growth Rate'!$A$31:$A$47,$A5,'CN-Med-Growth Rate'!$C$31:$C$47,$B$1) -> 0 | K5: =$E5*SUMIFS('CN-Med-Growth Rate'!N$31:N$47,'CN-Med-Growth Rate'!$A$31:$A$47,$A5,'CN-Med-Growth Rate'!$C$31:$C$47,$B$1) -> 0 | L5: =$E5*SUMIFS('CN-Med-Growth Rate'!O$31:O$47,'CN-Med-Growth Rate'!$A$31:$A$47,$A5,'CN-Med-Growth Rate'!$C$31:$C$47,$B$1) -> 0 | M5: =$E5*SUMIFS('CN-Med-Growth Rate'!P$31:P$47,'CN-Med-Growth Rate'!$A$31:$A$47,$A5,'CN-Med-Growth Rate'!$C$31:$C$47,$B$1) -> 0 | ... AR5: =$E5*SUMIFS('CN-Med-Growth Rate'!AU$31:AU$47,'CN-Med-Growth Rate'!$A$31:$A$47,$A5,'CN-Med-Growth Rate'!$C$31:$C$47,$B$1) -> 0
A6: other mining and quarrying 07T08 | B6: =SUMIFS('GHG Emissions 2018-2021'!$D$4:$D$14,'GHG Emissions 2018-2021'!$A$4:$A$14,$A6)*10^10 -> 0 | C6: =AVERAGE(B6,D6) -> 0 | D6: =SUMIFS('GHG Emissions 2018-2021'!$D$19:$D$31,'GHG Emissions 2018-2021'!$A$19:$A$31,$A6)*10^10 -> 0 | E6: =SUMIFS('GHG Emissions 2018-2021'!$D$36:$D$48,'GHG Emissions 2018-2021'!$A$36:$A$48,$A6)*10^10 -> 0 | F6: =$E6*SUMIFS('CN-Med-Growth Rate'!I$31:I$47,'CN-Med-Growth Rate'!$A$31:$A$47,$A6,'CN-Med-Growth Rate'!$C$31:$C$47,$B$1) -> 0 | G6: =$E6*SUMIFS('CN-Med-Growth Rate'!J$31:J$47,'CN-Med-Growth Rate'!$A$31:$A$47,$A6,'CN-Med-Growth Rate'!$C$31:$C$47,$B$1) -> 0 | H6: =$E6*SUMIFS('CN-Med-Growth Rate'!K$31:K$47,'CN-Med-Growth Rate'!$A$31:$A$47,$A6,'CN-Med-Growth Rate'!$C$31:$C$47,$B$1) -> 0 | I6: =$E6*SUMIFS('CN-Med-Growth Rate'!L$31:L$47,'CN-Med-Growth Rate'!$A$31:$A$47,$A6,'CN-Med-Growth Rate'!$C$31:$C$47,$B$1) -> 0 | J6: =$E6*SUMIFS('CN-Med-Growth Rate'!M$31:M$47,'CN-Med-Growth Rate'!$A$31:$A$47,$A6,'CN-Med-Growth Rate'!$C$31:$C$47,$B$1) -> 0 | K6: =$E6*SUMIFS('CN-Med-Growth Rate'!N$31:N$47,'CN-Med-Growth Rate'!$A$31:$A$47,$A6,'CN-Med-Growth Rate'!$C$31:$C$47,$B$1) -> 0 | L6: =$E6*SUMIFS('CN-Med-Growth Rate'!O$31:O$47,'CN-Med-Growth Rate'!$A$31:$A$47,$A6,'CN-Med-Growth Rate'!$C$31:$C$47,$B$1) -> 0 | M6: =$E6*SUMIFS('CN-Med-Growth Rate'!P$31:P$47,'CN-Med-Growth Rate'!$A$31:$A$47,$A6,'CN-Med-Growth Rate'!$C$31:$C$47,$B$1) -> 0 | ... AR6: =$E6*SUMIFS('CN-Med-Growth Rate'!AU$31:AU$47,'CN-Med-Growth Rate'!$A$31:$A$47,$A6,'CN-Med-Growth Rate'!$C$31:$C$47,$B$1) -> 0
