Workbook

Sheet About
A1: BIFUBC
B7: Definition of Energy Product not used as Fuel based on US EPS Model
B8: Coking Coal: Hard coal used in Iron and Steel Industry
B9: Petrochem: Natural Gas, Crude Oil, in refined petroleum and coke
B10: Chemical: Natural as Feedstock, LPG propane or butane as Feedstock
B12: Definition of "Energy Product used as Material"
B13: 4.2.1. #用作原料、材料
B14: “准确界定原料用能范畴”一节是《通知》的重要内容。该节具体指出，对原料用能的基本定义是:
B15: “指用作原材料的能源消费，即能源产品不作为燃料、动力使用，而作为生产非能源产品的原料、材料使用。”
B16: 具体范畴则表述为
B17: “用于生产非能源用途的烯烃、芳烃、炔烃、醇类、合成氨等产品的煤炭、石油、天然气及其制品等，属于原料用能范畴；若用作燃料、动力使用，不属于原料用能范畴”。

Sheet Sector Match
A1: 农、林、牧、渔业 | B1: agriculture and forestry 01T03
A2: 煤炭开采和洗选业 | B2: coal mining 05
A3: 石油和天然气开采业 | B3: oil and gas extraction 06
A4: 黑色金属矿采选业 | B4: other mining and quarrying 07T08
A5: 有色金属矿采选业 | B5: other mining and quarrying 07T08
A6: 非金属矿采选业 | B6: other mining and quarrying 07T08
A7: 开采专业及辅助性活动 | B7: Mining Support Service Activities 09
A8: 其他采矿业 | B8: Mining Support Service Activities 09
A9: 农副食品加工业 | B9: food beverage and tobacco 10T12
A10: 食品制造业 | B10: food beverage and tobacco 10T12
A11: 酒、饮料和精制茶制造业 | B11: food beverage and tobacco 10T12
A12: 烟草制品业 | B12: food beverage and tobacco 10T12
... A22: 化学原料和化学制品制造业 | B22: chemicals 20
A23: 医药制造业
A24: 化学纤维制造业 | B24: chemicals 20
A25: 橡胶和塑料制品业 | B25: rubber and plastic products 22
A26: 非金属矿物制品业 | B26: cement and other nonmetallic minerals 239
A27: 黑色金属冶炼和压延加工业 | B27: iron and steel 241
A28: 有色金属冶炼和压延加工业 | B28: other metals 242
A29: 金属制品业 | B29: metal products except machinery and vehicles 25
A30: 通用设备制造业 | B30: other manufacturing 31T33
A31: 专用设备制造业 | B31: glass and glass products 231
A32: 汽车制造业 | B32: road vehicles 29
A33: 铁路、船舶、航空航天和其他运输设备制造业 | B33: nonroad vehicles 30
A34: 电气机械和器材制造业 | B34: appliances and electrical equipment 27
A35: 计算机、通信和其他电子设备制造业 | B35: computers and electronics 26
... A39: 金属制品、机械和设备修理业 | B39: other machinery 28
A40: 电力、热力生产和供应业
A41: 燃气生产和供应业 | B41: energy pipelines and gas processing 352T353
A42: 水的生产和供应业 | B42: water and waste 36T39
A43: 建筑业 | B43: construction 41T43

Sheet Fuel Match
A1: Chinese Model Fuel | C1: EPS Fuel | D1: EPS Industrial Module Fuel
A2: Crude Oil | B2: 原油 | C2: crude oil | D2: crude oil
A3: Electricity | B3: 电力 | C3: electricity | D3: electricity
A4: Raw Coal | B4: 原煤 | C4: coal | D4: coal
A5: Cleaned Coal | B5: 洗精煤 | C5: coal | D5: coal
A6: Briquettes | B6: 煤制品 | C6: coal | D6: coal
A7: Heat | B7: 热力 | C7: heat | D7: heat
A8: Fuel Oil | B8: 燃料油 | C8: heavy fuel oil | D8: heavy fuel oil
A9: White Spirit | B9: 溶剂油 | C9: heavy fuel oil | D9: heavy fuel oil
A10: Other Petroleum Products | B10: 其他石油制品 | C10: heavy fuel oil | D10: heavy fuel oil
A11: Kerosene | B11: 煤油 | C11: jet fuel or kerosene | D11: petroleum diesel
A12: Gangue | B12: 煤矸石 | C12: lignite | D12: coal
A13: Other Washed Coal | B13: 其他洗煤 | C13: lignite | D13: coal
... A35: Other Energy | B35: 其他能源 | C35: other energy | D35: biomass

Sheet Heat Value
A1: 能源名称 | B1: 实物量单位 | C1: 平均低位发热量 | D1: 折标准煤系数 | E1: 折EPS BTU 系数 | F1: 单位热值含碳量 | G1: 燃料碳氧化率 | H1: 排放因子1 | I1: 排放因子2 | J1: 数据来源
C2: TJ/单位 | D2: 万吨标煤/单位 | E2: BTU/单位 | F2: 万吨碳/TJ | G2: % | H2: 万tCO2/单位 | I2: 万tCO2/万吨标煤
A3: 原煤 | B3: 万吨 | C3: 209.08 | D3: 0.7143 | E3: =C3*10^12/1055.05585 -> 1.981696e+11 | F3: 0.002749 | G3: 0.94 | H3: =C3*F3*G3*44/12 -> 1.9810093 | I3: =H3/D3 -> 2.7733576 | J3: 能源统计年鉴2020
A4: 洗精煤 | B4: 万吨 | C4: 263.44 | D4: 0.9 | E4: =C4*10^12/1055.05585 -> 2.4969294e+11 | F4: 0.00254 | G4: 0.93 | H4: =C4*F4*G4*44/12 -> 2.2817592 | I4: =H4/D4 -> 2.535288 | J4: 能源统计年鉴2020
A5: 其他洗煤 | B5: 万吨 | C5: 83.63 | D5: 0.2857 | E5: =C5*10^12/1055.05585 -> 7.9265946e+10 | F5: 0.00254 | G5: 0.9 | H5: =C5*F5*G5*44/12 -> 0.70098666 | I5: =H5/D5 -> 2.453576 | J5: 能源统计年鉴2020
A6: 型煤 | B6: 万吨 | C6: 154.73 | D6: =C6/292.7 -> 0.52863 | E6: =C6*10^12/1055.05585 -> 1.4665574e+11 | F6: 0.00266 | G6: 0.9 | H6: =C6*F6*G6*44/12 -> 1.3582199 | I6: =H6/D6 -> 2.5693206 | J6: 2020中国区域电网二氧化碳基准线排放因子
A7: 煤矸石 | B7: 万吨 | C7: 83.74 | D7: =C7/292.7 -> 0.28609498 | E7: =C7*10^12/1055.05585 -> 7.9370206e+10 | F7: 0.00273 | G7: 0.98 | H7: =C7*F7*G7*44/12 -> 0.82147265 | I7: =H7/D7 -> 2.8713285 | J7: 综合能耗计算通则GBT2589-2020
A8: 焦炭 | B8: 万吨 | C8: 284.35 | D8: 0.9714 | E8: =C8*10^12/1055.05585 -> 2.695118e+11 | F8: 0.00294 | G8: 0.93 | H8: =C8*F8*G8*44/12 -> 2.8507225 | I8: =H8/D8 -> 2.9346536 | J8: 能源统计年鉴2020
A9: 焦炉煤气 | B9: 亿立方米 | C9: 1735.35 | D9: 5.9285 | E9: =C9*10^12/1055.05585 -> 1.6447944e+12 | F9: 0.00136 | G9: 0.99 | H9: =C9*F9*G9*44/12 -> 8.5670759 | I9: =H9/D9 -> 1.4450664 | J9: 能源统计年鉴2020
A10: 高炉煤气 | B10: 亿立方米 | C10: 376.3 | D10: =C10/292.7 -> 1.2856167 | E10: =C10*10^12/1055.05585 -> 3.5666358e+11 | F10: 0.00708 | G10: 0.99 | H10: =C10*F10*G10*44/12 -> 9.6710605 | I10: =H10/D10 -> 7.5225071 | J10: 2020中国区域电网二氧化碳基准线排放因子
A11: 转炉煤气 | B11: 亿立方米 | C11: 794.5 | D11: =C11/292.7 -> 2.7143833 | E11: =C11*10^12/1055.05585 -> 7.530407e+11 | F11: 0.00469 | G11: 0.99 | H11: =C11*F11*G11*44/12 -> 13.526124 | I11: =H11/D11 -> 4.9831297 | J11: 2020中国区域电网二氧化碳基准线排放因子
A12: 其他煤气 | B12: 亿立方米 | C12: 522.7 | D12: 1.786 | E12: =C12*10^12/1055.05585 -> 4.9542401e+11 | F12: 0.00122 | G12: 0.99 | H12: =C12*F12*G12*44/12 -> 2.3148292 | I12: =H12/D12 -> 1.296097 | J12: 能源统计年鉴2020
A13: 其他焦化产品 | B13: 万吨 | C13: 334.53 | D13: =C13/292.7 -> 1.1429108 | E13: =C13*10^12/1055.05585 -> 3.1707326e+11 | F13: 0.00258 | G13: 0.93 | H13: =C13*F13*G13*44/12 -> 2.943128 | I13: =H13/D13 -> 2.5751161 | J13: 2020中国区域电网二氧化碳基准线排放因子
A14: 原油 | B14: 万吨 | C14: 418.16 | D14: 1.4286 | E14: =C14*10^12/1055.05585 -> 3.9633921e+11 | F14: 0.00201 | G14: 0.98 | H14: =C14*F14*G14*44/12 -> 3.0202024 | I14: =H14/D14 -> 2.1140994 | J14: 能源统计年鉴2020
A15: 汽油 | B15: 万吨 | C15: 430.7 | D15: 1.4714 | E15: =C15*10^12/1055.05585 -> 4.0822483e+11 | F15: 0.00189 | G15: 0.98 | H15: =C15*F15*G15*44/12 -> 2.925056 | I15: =H15/D15 -> 1.9879407 | J15: 能源统计年鉴2020
A16: 煤油 | B16: 万吨 | C16: 430.7 | D16: 1.4714 | E16: =C16*10^12/1055.05585 -> 4.0822483e+11 | F16: 0.00189 | G16: 0.98 | H16: =C16*F16*G16*44/12 -> 2.925056 | I16: =H16/D16 -> 1.9879407 | J16: 能源统计年鉴2020
A17: 柴油 | B17: 万吨 | C17: 426.52 | D17: 1.4571 | E17: =C17*10^12/1055.05585 -> 4.0426296e+11 | F17: 0.00202 | G17: 0.98 | H17: =C17*F17*G17*44/12 -> 3.0959096 | I17: =H17/D17 -> 2.1247064 | J17: 能源统计年鉴2020
A18: 燃料油 | B18: 万吨 | C18: 418.16 | D18: 1.4286 | E18: =C18*10^12/1055.05585 -> 3.9633921e+11 | F18: 0.00211 | G18: 0.98 | H18: =C18*F18*G18*44/12 -> 3.1704612 | I18: =H18/D18 -> 2.2192785 | J18: 能源统计年鉴2020
A19: 石脑油 | B19: 万吨 | C19: 439.07 | D19: =C19/292.7 -> 1.5000683 | E19: =C19*10^12/1055.05585 -> 4.1615806e+11 | F19: 0.002 | G19: 0.98 | H19: =C19*F19*G19*44/12 -> 3.1554497 | I19: =H19/D19 -> 2.1035373 | J19: 2020中国区域电网二氧化碳基准线排放因子
A20: 润滑油 | B20: 万吨 | C20: 413.98 | D20: =C20/292.7 -> 1.4143492 | E20: =C20*10^12/1055.05585 -> 3.9237733e+11 | F20: 0.002 | G20: 0.98 | H20: =C20*F20*G20*44/12 -> 2.9751363 | I20: =H20/D20 -> 2.1035373 | J20: 2021中国区域电网二氧化碳基准线排放因子
A21: 石蜡 | B21: 万吨 | C21: 399.25 | D21: =C21/292.7 -> 1.3640246 | E21: =C21*10^12/1055.05585 -> 3.7841599e+11 | F21: 0.002 | G21: 0.98 | H21: =C21*F21*G21*44/12 -> 2.8692767 | I21: =H21/D21 -> 2.1035373 | J21: 2022中国区域电网二氧化碳基准线排放因子
A22: 溶剂油 | B22: 万吨 | C22: 429.45 | D22: =C22/292.7 -> 1.4672019 | E22: =C22*10^12/1055.05585 -> 4.0704006e+11 | F22: 0.002 | G22: 0.98 | H22: =C22*F22*G22*44/12 -> 3.086314 | I22: =H22/D22 -> 2.1035373 | J22: 2023中国区域电网二氧化碳基准线排放因子
A23: 石油沥青 | B23: 万吨 | C23: 389.31 | D23: =C23/292.7 -> 1.3300649 | E23: =C23*10^12/1055.05585 -> 3.6899468e+11 | F23: 0.0022 | G23: 0.98 | H23: =C23*F23*G23*44/12 -> 3.0776253 | I23: =H23/D23 -> 2.3138911 | J23: 2024中国区域电网二氧化碳基准线排放因子
A24: 石油焦 | B24: 万吨 | C24: 319.47 | D24: =C24/292.7 -> 1.0914588 | E24: =C24*10^12/1055.05585 -> 3.0279914e+11 | F24: 0.00275 | G24: 0.98 | H24: =C24*F24*G24*44/12 -> 3.156896 | I24: =H24/D24 -> 2.8923638 | J24: 2025中国区域电网二氧化碳基准线排放因子
A25: 液化石油气 | B25: 万吨 | C25: 501.79 | D25: 1.7143 | E25: =C25*10^12/1055.05585 -> 4.7560515e+11 | F25: 0.00172 | G25: 0.99 | H25: =C25*F25*G25*44/12 -> 3.132976 | I25: =H25/D25 -> 1.8275541 | J25: 能源统计年鉴2020
A26: 炼厂干气 | B26: 万吨 | C26: 459.98 | D26: 1.5714 | E26: =C26*10^12/1055.05585 -> 4.3597692e+11 | F26: 0.00182 | G26: 0.99 | H26: =C26*F26*G26*44/12 -> 3.0389039 | I26: =H26/D26 -> 1.9338831 | J26: 能源统计年鉴2020
A27: 其他石油制品 | B27: 万吨 | C27: 409.8 | D27: =C27/292.7 -> 1.4000683 | E27: =C27*10^12/1055.05585 -> 3.8841546e+11 | F27: 0.002 | G27: 0.99 | H27: =C27*F27*G27*44/12 -> 2.975148 | I27: =H27/D27 -> 2.125002 | J27: 2025中国区域电网二氧化碳基准线排放因子
A28: 天然气 | B28: 亿立方米 | C28: 3558.45 | D28: 12.15 | E28: =C28*10^12/1055.05585 -> 3.3727598e+12 | F28: 0.00153 | G28: 0.99 | H28: =C28*F28*G28*44/12 -> 19.763275 | I28: =H28/D28 -> 1.626607 | J28: 能源统计年鉴2020
A29: 液化天然气 | B29: 万吨 | C29: 514.34 | D29: =C29/292.7 -> 1.7572258 | E29: =C29*10^12/1055.05585 -> 4.8750026e+11 | F29: 0.00153 | G29: 1 | H29: =C29*F29*G29*44/12 -> 2.8854474 | I29: =H29/D29 -> 1.642047 | J29: 2025中国区域电网二氧化碳基准线排放因子
A30: 热力 | B30: 万百万千焦 | C30: 10 | D30: =C30/292.7 -> 0.034164674 | E30: =C30*10^12/1055.05585 -> 9.4781712e+09 | G30: 1 | J30: 排放清单缺省值
A31: 电力 | B31: 亿千瓦时 | C31: 360 | D31: =C31/292.7 -> 1.2299283 | E31: =C31*10^12/1055.05585 -> 3.4121416e+11 | G31: 1
A32: 氢能源 | B32: 万吨 | C32: 9.690321 | E32: =C32*10^12/1055.05585 -> 9.1846522e+09
A33: 其他能源 | B33: 万吨标煤 | C33: 292.71 | D33: =C33/292.7 -> 1.0000342 | E33: =C33*10^12/1055.05585 -> 2.7743555e+11 | F33: 0 | G33: 1 | H33: =C33*F33*G33*44/12 -> 0 | I33: =H33/D33 -> 0 | J33: 2025中国区域电网二氧化碳基准线排放因子

Sheet Final Energy Consumption-2019
A1: 4-2 工业分行业终端能源消费量(实物量)-2019
A2: 行 业 | B2: 煤合计_x000D_ (万吨)_x000D_ Coal Total_x000D_ (104 tons) | C2: 原煤_x000D_ (万吨)_x000D_ Raw Coal_x000D_ (104 tons) | D2: 洗精煤_x000D_ (万吨)_x000D_ Cleaned_x000D_ Coal_x000D_ (104 tons) | E2: 其他洗煤_x000D_ (万吨)_x000D_ Other_x000D_ Washed Coal_x000D_ (104 tons) | F2: 焦炭_x000D_ (万吨)_x000D_ Coke_x000D_ (104 tons) | G2: 焦炉煤气_x000D_ (亿立方米)_x000D_ Coke Oven_x000D_ Gas_x000D_ (108 cu.m) | H2: 高炉煤气_x000D_ (亿立方米)_x000D_ Blast Furnace_x000D_ Gas_x000D_ (108 cu.m) | I2: 转炉煤气_x000D_ (亿立方米)_x000D_ Converter_x000D_ Gas_x000D_ (108 cu.m) | J2: 其他煤气_x000D_ (亿立方米)_x000D_ Other Gas_x000D_ (108 cu.m) | K2: 其他焦化产品_x000D_ (万吨)_x000D_ Other Coking_x000D_ Products_x000D_ (104 tons) | L2: 油品合计_x000D_ (万吨)_x000D_ Petroleum_x000D_ Products Total_x000D_ (104 tons) | M2: 原油_x000D_ (万吨)_x000D_ Crude Oil_x000D_ (104 tons) | N2: 汽油_x000D_ (万吨)_x000D_ Gasoline_x000D_ (104 tons) | O2: 煤油_x000D_ (万吨)_x000D_ Kerosene_x000D_ (104 tons) | P2: 柴油_x000D_ (万吨)_x000D_ Diesel Oil_x000D_ (104 tons) | Q2: 燃料油_x000D_ (万吨)_x000D_ Fuel Oil_x000D_ (104 tons) | R2: 石脑油_x000D_ (万吨)_x000D_ Naphtha_x000D_ (104 tons) | S2: 润滑油_x000D_ (万吨)_x000D_ Lubricants_x000D_ (104 tons) | T2: 石蜡_x000D_ (万吨)_x000D_ Paraffin_x000D_ Waxes_x000D_ (104 tons) | U2: 溶剂油_x000D_ (万吨)_x000D_ White Spirit_x000D_ (104 tons) | V2: 石油沥青_x000D_ (万吨)_x000D_ Bitumen_x000D_ Asphalt_x000D_ (104 tons) | W2: 石油焦_x000D_ (万吨)_x000D_ Petroleum_x000D_ Coke_x000D_ (104 tons) | X2: 液化石油气_x000D_ (万吨)_x000D_ Liquefied_x000D_ Petroleum Gas_x000D_ (104 tons) | Y2: 炼厂干气_x000D_ (万吨)_x000D_ Refinery_x000D_ Gas_x000D_ (104 tons) | Z2: 其他石油制品_x000D_ (万吨)_x000D_ Other Petroleum_x000D_ Products_x000D_ (104 tons) | AA2: 天然气_x000D_ (亿立方米)_x000D_ Natural Gas_x000D_ (108 cu.m) | AB2: 液化天然气_x000D_ (万吨)_x000D_ Liquefied_x000D_ Natural Gas_x000D_ (104 tons) | AC2: 热力_x000D_ (万百万千焦)_x000D_ Heat_x000D_ (1010 kJ) | AD2: 电力_x000D_ (亿千瓦小时)_x000D_ Electricity_x000D_ (108 kW·h) | AE2: 其他能源_x000D_ (万吨标准煤)_x000D_ Other Energy_x000D_ (104 tce)
A3: 煤炭开采和洗选业 | B3: 2931.16 | C3: 1628.55 | E3: 1297.11 | F3: 48.92 | G3: 1.04 | H3: 25.03 | I3: 0.72 | J3: 1.42 | K3: 6.5 | L3: 351.52 | M3: 0.22 | N3: 4.95 | O3: 0.75 | P3: 152.6 | Q3: 0.27 | R3: 149.36 | S3: 1.01 | V3: 0.1 | X3: 41.75 | Z3: 0.52 | AA3: 14.35 | AB3: 13.45 | AC3: 705.5 | AD3: 1026.76 | AE3: 2.88
A4: 石油和天然气开采业 | B4: 105.6 | C4: 105.6 | L4: 347.07 | M4: 268.2 | N4: 6.99 | P4: 40.56 | Q4: 0.87 | S4: 0.01 | X4: 0.13 | Y4: 12.82 | Z4: 17.51 | AA4: 132.38 | AB4: 4.59 | AC4: 2778.26 | AD4: 434.44
A5: 黑色金属矿采选业 | B5: 175.95 | C5: 167.23 | E5: 5.54 | F5: 147.75 | G5: 3.17 | H5: 18.22 | I5: 0.56 | K5: 0.17 | L5: 43.64 | N5: 0.81 | P5: 42.54 | Q5: 0.05 | S5: 0.23 | AA5: 0.02 | AC5: 162.15 | AD5: 419.28 | AE5: 1.04
A6: 有色金属矿采选业 | B6: 80.3 | C6: 77.93 | E6: 1.84 | F6: 3.57 | L6: 25.06 | N6: 1.64 | O6: 0.46 | P6: 21.82 | Q6: 0.96 | S6: 0.03 | V6: 0.15 | AA6: 0.66 | AC6: 0.09 | AD6: 386.17 | AE6: 2.41
A7: 非金属矿采选业 | B7: 509.68 | C7: 247.69 | E7: 256.97 | F7: 7.74 | G7: 1.1 | I7: 1.39 | L7: 57.14 | N7: 1.05 | O7: 0.02 | P7: 53.79 | Q7: 0.04 | S7: 0.05 | V7: 0.6 | W7: 1.53 | X7: 0.01 | Z7: 0.05 | AA7: 0.62 | AB7: 7.24 | AC7: 2247.71 | AD7: 257.36 | AE7: 0.19
A8: 开采专业及辅助性活动 | B8: 6.95 | C8: 6.95 | L8: 158.72 | M8: 0.1 | N8: 3.82 | P8: 153.85 | Q8: 0.3 | S8: 0.28 | X8: 0.08 | Z8: 0.29 | AA8: 2.38 | AB8: 0.38 | AC8: 277.93 | AD8: 41.3
A9: 其他采矿业 | B9: 0.12 | C9: 0.12 | L9: 0.11 | P9: 0.1 | AD9: 211.62
A10: 农副食品加工业 | B10: 952.96 | C10: 929.67 | E10: 21.32 | F10: 124.44 | G10: 0.03 | H10: 26.33 | I10: 2.1 | J10: 0.16 | K10: 0.01 | L10: 33.01 | N10: 7.09 | O10: 0.09 | P10: 21.51 | Q10: 1.51 | S10: 0.09 | T10: 0.03 | U10: 1.5 | X10: 0.95 | Z10: 0.24 | AA10: 3.86 | AB10: 198.52 | AC10: 7615.31 | AD10: 797.43 | AE10: 221.48
A11: 食品制造业 | B11: 912.52 | C11: 906.34 | E11: 1.13 | F11: 1.57 | L11: 15.51 | N11: 4.21 | P11: 8.26 | Q11: 1.12 | T11: 0.41 | X11: 1.17 | Z11: 0.33 | AA11: 12.87 | AB11: 82.51 | AC11: 7297.6 | AD11: 301.94 | AE11: 39.14
A12: 酒、饮料和精制茶制造业 | B12: 523.51 | C12: 516.79 | E12: 5.74 | F12: 0.08 | G12: 0.03 | K12: 0.01 | L12: 8.81 | N12: 2.89 | O12: 0.06 | P12: 4.77 | Q12: 0.36 | S12: 0.01 | X12: 0.68 | Z12: 0.04 | AA12: 9.92 | AB12: 48.46 | AC12: 5461.59 | AD12: 173.56 | AE12: 13.23
A13: 烟草制品业 | B13: 6.57 | C13: 6.09 | E13: 0.44 | L13: 1.47 | N13: 0.38 | P13: 1.04 | X13: 0.05 | AA13: 1.21 | AC13: 257.7 | AD13: 52.91 | AE13: 2.52
A14: 纺织业 | B14: 417.78 | C14: 374.64 | E14: 6.41 | F14: 1.19 | I14: 0.01 | L14: 19.13 | N14: 5.59 | O14: 0.03 | P14: 5.91 | Q14: 3.45 | S14: 0.1 | V14: 1.56 | X14: 1.54 | Z14: 0.95 | AA14: 14.83 | AB14: 217.53 | AC14: 32377.38 | AD14: 1760.15 | AE14: 65.49
A15: 纺织服装、服饰业 | B15: 36.67 | C15: 35.95 | E15: 0.43 | F15: 0.05 | L15: 11.4 | N15: 4.89 | O15: 0.05 | P15: 5.37 | Q15: 0.49 | S15: 0.01 | X15: 0.37 | Z15: 0.22 | AA15: 1.31 | AB15: 68.93 | AC15: 593.54 | AD15: 231.59 | AE15: 8.27
A16: 皮革、毛皮、羽毛及其制品和制鞋业 | B16: 21.78 | C16: 20.18 | E16: 0.09 | L16: 5.7 | N16: 2.86 | O16: 0.01 | P16: 1.94 | Q16: 0.34 | R16: 0.01 | S16: 0.05 | T16: 0.04 | U16: 0.12 | X16: 0.29 | Z16: 0.04 | AA16: 0.12 | AB16: 14.82 | AC16: 227.8 | AD16: 156.81 | AE16: 9.7
A17: 木材加工和木、竹、藤、棕、草制品业 | B17: 48.66 | C17: 47.78 | E17: 0.88 | F17: 0.05 | L17: 9.07 | N17: 1.7 | P17: 5.21 | Q17: 0.21 | S17: 0.04 | T17: 1.71 | X17: 0.21 | AA17: 2.63 | AB17: 1.84 | AC17: 671.94 | AD17: 279.32 | AE17: 104.92
A18: 家具制造业 | B18: 2.09 | C18: 1.8 | E18: 0.26 | F18: 0.54 | L18: 5.82 | N18: 2.4 | P18: 2.99 | Q18: 0.14 | S18: 0.01 | X18: 0.27 | AA18: 1.35 | AB18: 2.34 | AC18: 60.67 | AD18: 115.36 | AE18: 5.01
A19: 造纸和纸制品业 | B19: 715.5 | C19: 654.92 | E19: 39.31 | F19: 0.23 | G19: 0.09 | L19: 27.98 | M19: 0.03 | N19: 2.51 | O19: 0.01 | P19: 14.99 | Q19: 8.01 | S19: 0.1 | T19: 0.03 | U19: 0.3 | X19: 1.9 | Z19: 0.09 | AA19: 4.86 | AB19: 123.83 | AC19: 21416.18 | AD19: 744.61 | AE19: 90.62
A20: 印刷和记录媒介复制业 | B20: 15.39 | C20: 14.67 | E20: 0.33 | F20: 0.02 | G20: 0.07 | J20: 0.09 | L20: 9.06 | N20: 3.59 | O20: 0.01 | P20: 4.22 | Q20: 0.4 | S20: 0.03 | U20: 0.05 | X20: 0.41 | Z20: 0.35 | AA20: 3.4 | AB20: 11.47 | AC20: 488.67 | AD20: 131.05 | AE20: 9.07
A21: 文教、工美、体育和娱乐用品制造业 | B21: 14.47 | C21: 13.69 | E21: 0.37 | F21: 0.43 | L21: 20.34 | N21: 3.31 | O21: 0.11 | P21: 3.49 | Q21: 0.46 | R21: 0.01 | S21: 0.02 | T21: 0.53 | U21: 0.01 | W21: 11.56 | X21: 0.67 | Z21: 0.18 | AA21: 2.97 | AB21: 80.6 | AC21: 86.85 | AD21: 89.78 | AE21: 5.89
A22: 石油、煤炭及其他燃料加工业 | B22: 2588.48 | C22: 1309.11 | E22: 1151.35 | F22: 52.92 | G22: 208.3 | H22: 97.9 | J22: 11.26 | K22: 143.22 | L22: 9293.13 | M22: 55.95 | N22: 1.42 | O22: 0.18 | P22: 22.54 | Q22: 27.38 | R22: 1390.01 | S22: 219.89 | T22: 0.06 | U22: 6.03 | V22: 4.87 | W22: 230.56 | X22: 1057.39 | Y22: 1739.05 | Z22: 4537.82 | AA22: 26.77 | AB22: 835.63 | AC22: 63440.85 | AD22: 1198.93 | AE22: 6.16
A23: 化学原料和化学制品制造业 | B23: 11986.77 | C23: 11475.78 | E23: 175.06 | F23: 3955.42 | G23: 79.54 | H23: 9 | I23: 10.06 | J23: 22.56 | K23: 624.81 | L23: 7269.24 | M23: 1.35 | N23: 12.09 | O23: 1.9 | P23: 37.97 | Q23: 44.02 | R23: 4207.62 | S23: 5.29 | T23: 252.74 | U23: 82.44 | V23: 1.52 | W23: 51.52 | X23: 1058.99 | Y23: 75.47 | Z23: 1436.3 | AA23: 206.99 | AB23: 1379.26 | AC23: 145178.14 | AD23: 5427.38 | AE23: 90.95
A24: 医药制造业 | B24: 468.86 | C24: 461.02 | E24: 1.92 | F24: 1.95 | G24: 0.37 | K24: 0.08 | L24: 13.7 | M24: 0.03 | N24: 3.92 | O24: 0.01 | P24: 5.73 | Q24: 2.72 | R24: 0.03 | T24: 0.03 | U24: 0.23 | X24: 0.21 | Z24: 0.78 | AA24: 7.46 | AB24: 53.64 | AC24: 10234.32 | AD24: 407.71 | AE24: 25.21
A25: 化学纤维制造业 | B25: 584.87 | C25: 478.34 | E25: 4.74 | F25: 18.57 | L25: 2.87 | N25: 0.61 | O25: 0.02 | P25: 1.64 | Q25: 0.38 | S25: 0.05 | U25: 0.04 | X25: 0.06 | Z25: 0.07 | AA25: 1.71 | AB25: 90.04 | AC25: 11473.54 | AD25: 455.15 | AE25: 12.62
A26: 橡胶和塑料制品业 | B26: 261.77 | C26: 244.32 | E26: 2.53 | F26: 0.03 | G26: 0.62 | K26: 5.33 | L26: 32.62 | M26: 0.01 | N26: 9.45 | O26: 0.06 | P26: 11.9 | Q26: 3.38 | S26: 0.45 | T26: 0.43 | U26: 0.41 | V26: 1.54 | X26: 2.26 | Z26: 2.73 | AA26: 7.95 | AB26: 63.03 | AC26: 3139.12 | AD26: 1426.38 | AE26: 16.28
A27: 非金属矿物制品业 | B27: 22238.05 | C27: 13725.93 | E27: 8413.71 | F27: 1340.43 | G27: 35.94 | H27: 42.5 | I27: 5.62 | J27: 8.56 | K27: 22.25 | L27: 3189.68 | M27: 0.1 | N27: 14.75 | O27: 0.83 | P27: 314.07 | Q27: 96.29 | S27: 0.59 | T27: 0.73 | U27: 0.16 | V27: 241.25 | W27: 2446.51 | X27: 61.41 | Y27: 0.11 | Z27: 12.87 | AA27: 36.98 | AB27: 1024.69 | AC27: 2518.62 | AD27: 3760.64 | AE27: 90.04
A28: 黑色金属冶炼和压延加工业 | B28: 9211.61 | C28: 8451.73 | E28: 669.94 | F28: 39247.4 | G28: 343.31 | H28: 8060.77 | I28: 556.61 | J28: 1.51 | K28: 304.58 | L28: 87.38 | N28: 3.35 | O28: 0.02 | P28: 52.53 | Q28: 0.64 | S28: 0.77 | T28: 0.02 | W28: 18.02 | X28: 9.6 | Y28: 1.58 | Z28: 0.85 | AA28: 46.6 | AB28: 654.5 | AC28: 19472.74 | AD28: 6459.68 | AE28: 101.48
A29: 有色金属冶炼和压延加工业 | B29: 2361.87 | C29: 2098.02 | E29: 256.64 | F29: 406.15 | G29: 19.34 | I29: 0.08 | J29: 89.53 | K29: 20.62 | L29: 332.3 | M29: 0.3 | N29: 3.39 | O29: 0.54 | P29: 33.38 | Q29: 13.82 | S29: 0.42 | U29: 0.1 | V29: 10.01 | W29: 262.09 | X29: 3.24 | Z29: 5.01 | AA29: 20.75 | AB29: 256.51 | AC29: 21858.02 | AD29: 6673.67 | AE29: 5.96
A30: 金属制品业 | B30: 255.08 | C30: 203.46 | E30: 50.46 | F30: 469.08 | G30: 4.55 | H30: 48.79 | I30: 2.22 | J30: 0.53 | K30: 2.61 | L30: 39.75 | N30: 11.6 | O30: 0.45 | P30: 19.52 | Q30: 1.6 | S30: 0.59 | T30: 0.02 | U30: 0.02 | V30: 0.32 | X30: 4.33 | Y30: 0.01 | Z30: 1.28 | AA30: 11.68 | AB30: 372.68 | AC30: 637.35 | AD30: 1672.84 | AE30: 4.88
A31: 通用设备制造业 | B31: 18.99 | C31: 17.21 | E31: 0.8 | F31: 244.56 | G31: 0.15 | H31: 0.08 | I31: 0.05 | L31: 46.46 | N31: 15.29 | O31: 1.62 | P31: 21.25 | Q31: 0.7 | R31: 0.03 | S31: 2.92 | T31: 0.08 | U31: 0.04 | X31: 2.8 | Z31: 1.73 | AA31: 10.36 | AB31: 82.5 | AC31: 343.7 | AD31: 1007.43 | AE31: 5.11
A32: 专用设备制造业 | B32: 20.01 | C32: 17.18 | E32: 1.5 | F32: 6.54 | G32: 1.34 | H32: 2.34 | J32: 3.51 | K32: 0.57 | L32: 37.97 | N32: 11.84 | O32: 0.77 | P32: 14.46 | Q32: 0.64 | S32: 2.89 | T32: 0.04 | U32: 0.08 | X32: 3.62 | Z32: 3.64 | AA32: 4.85 | AB32: 113.88 | AC32: 955.3 | AD32: 499.42 | AE32: 5.42
A33: 汽车制造业 | B33: 21.53 | C33: 20.87 | E33: 0.11 | F33: 14.23 | G33: 0.06 | H33: 0.03 | I33: 0.01 | J33: 0.18 | L33: 65.68 | M33: 0.01 | N33: 24.72 | O33: 0.27 | P33: 26.95 | Q33: 0.32 | R33: 0.01 | S33: 9.25 | T33: 0.01 | U33: 0.13 | V33: 0.01 | X33: 2.07 | Z33: 1.94 | AA33: 7.29 | AB33: 140.31 | AC33: 2982.62 | AD33: 1031.41 | AE33: 3.01
A34: 铁路、船舶、航空航天和其他运输设备制造业 | B34: 41.15 | C34: 20.35 | E34: 20.8 | F34: 0.28 | G34: 0.46 | J34: 0.01 | L34: 19.08 | M34: 0.01 | N34: 3.5 | O34: 0.95 | P34: 11.25 | Q34: 1.39 | S34: 0.23 | X34: 1.34 | Z34: 0.41 | AA34: 4.98 | AB34: 123.53 | AC34: 666.6 | AD34: 166.18 | AE34: 0.3
A35: 电气机械和器材制造业 | B35: 16.17 | C35: 16.05 | E35: 0.07 | F35: 0.56 | G35: 0.02 | L35: 35.46 | N35: 14.94 | O35: 0.42 | P35: 10.72 | Q35: 2.07 | S35: 1.81 | T35: 0.15 | U35: 0.05 | V35: 0.04 | W35: 0.38 | X35: 3.4 | Z35: 1.48 | AA35: 3.42 | AB35: 61.56 | AC35: 1414.4 | AD35: 859.31 | AE35: 6.19
A36: 计算机、通信和其他电子设备制造业 | B36: 17.03 | C36: 15.92 | E36: 1.11 | G36: 0.01 | H36: 0.01 | L36: 19.39 | N36: 9.59 | O36: 0.15 | P36: 6.43 | Q36: 0.41 | S36: 0.66 | T36: 0.02 | U36: 0.02 | X36: 1.96 | Z36: 0.14 | AA36: 11.61 | AB36: 164.44 | AC36: 1558.86 | AD36: 1500.45 | AE36: 2.26
A37: 仪器仪表制造业 | B37: 1.92 | C37: 1.92 | F37: 0.01 | L37: 5.52 | N37: 3.84 | O37: 0.12 | P37: 1.01 | Q37: 0.09 | S37: 0.1 | T37: 0.03 | X37: 0.17 | Z37: 0.15 | AA37: 0.52 | AB37: 3.94 | AC37: 57.44 | AD37: 74.53 | AE37: 1.47
A38: 其他制造业 | B38: 1.98 | C38: 1.45 | E38: 0.17 | G38: 0.01 | K38: 0.75 | L38: 4.94 | N38: 0.68 | O38: 0.08 | P38: 1.13 | X38: 3.04 | AA38: 0.04 | AB38: 31.96 | AC38: 68.84 | AD38: 578.41 | AE38: 1.04
A39: 废弃资源综合利用业 | B39: 132.4 | C39: 105.97 | E39: 19.47 | F39: 97.06 | G39: 0.51 | H39: 5.3 | I39: 2.1 | K39: 1.17 | L39: 6.81 | N39: 0.31 | O39: 0.02 | P39: 4.83 | Q39: 1.32 | S39: 0.02 | X39: 0.31 | AA39: 2.19 | AB39: 123.44 | AC39: 19.73 | AD39: 57.94 | AE39: 5.87
A40: 金属制品、机械和设备修理业 | B40: 0.5 | C40: 0.5 | G40: 0.07 | H40: 0.14 | L40: 6.17 | M40: 0.01 | N40: 0.44 | O40: 0.93 | P40: 4.4 | Q40: 0.31 | S40: 0.05 | X40: 0.02 | AA40: 0.21 | AB40: 2.98 | AC40: 14.9 | AD40: 16.56
...

Sheet Feedstock Split-2019
B1: 煤合计_x000D_ (万吨)_x000D_ Coal Total_x000D_ (104 tons) | C1: 原煤_x000D_ (万吨)_x000D_ Raw Coal_x000D_ (104 tons) | D1: 洗精煤_x000D_ (万吨)_x000D_ Cleaned_x000D_ Coal_x000D_ (104 tons) | E1: 其他洗煤_x000D_ (万吨)_x000D_ Other_x000D_ Washed_x000D_ Coal_x000D_ (104 tons) | F1: 煤制品_x000D_ (万吨)_x000D_ Briquettes_x000D_ (104 tons) | G1: 煤矸石_x000D_ (万吨)_x000D_ Gangue_x000D_ (104 tons) | H1: 焦炭_x000D_ (万吨)_x000D_ Coke_x000D_ (104 tons) | I1: 焦炉煤气_x000D_ (亿立方米)_x000D_ Coke Oven_x000D_ Gas_x000D_ (108 cu.m) | J1: 高炉煤气_x000D_ (亿立方米)_x000D_ Blast Furnace_x000D_ Gas_x000D_ (108 cu.m) | K1: 转炉煤气_x000D_ (亿立方米)_x000D_ Converter_x000D_ Gas_x000D_ (108 cu.m) | L1: 其他煤气_x000D_ (亿立方米)_x000D_ Other Gas_x000D_ (108 cu.m) | M1: 其他焦化产品_x000D_ (万吨)_x000D_ Other_x000D_ Coking_x000D_ Products_x000D_ (104 tons) | N1: 油品合计_x000D_ (万吨)_x000D_ Petroleum_x000D_ Products_x000D_ Total_x000D_ (104 tons) | O1: 原油_x000D_ (万吨)_x000D_ Crude Oil_x000D_ (104 tons) | P1: 汽油_x000D_ (万吨)_x000D_ Gasoline_x000D_ (104 tons) | Q1: 煤油_x000D_ (万吨)_x000D_ Kerosene_x000D_ (104 tons) | R1: 柴油_x000D_ (万吨)_x000D_ Diesel Oil_x000D_ (104 tons) | S1: 燃料油_x000D_ (万吨)_x000D_ Fuel Oil_x000D_ (104 tons) | T1: 石脑油_x000D_ (万吨)_x000D_ Naphtha_x000D_ (104 tons) | U1: 润滑油_x000D_ (万吨)_x000D_ Lubricants_x000D_ (104 tons) | V1: 石蜡_x000D_ (万吨)_x000D_ Paraffin_x000D_ Waxes_x000D_ (104 tons) | W1: 溶剂油_x000D_ (万吨)_x000D_ White Spirit_x000D_ (104 tons) | X1: 石油沥青_x000D_ (万吨)_x000D_ Bitumen_x000D_ Asphalt_x000D_ (104 tons) | Y1: 石油焦_x000D_ (万吨)_x000D_ Petroleum_x000D_ Coke_x000D_ (104 tons) | Z1: 液化石油气_x000D_ (万吨)_x000D_ Liquefied_x000D_ Petroleum Gas_x000D_ (104 tons) | AA1: 炼厂干气_x000D_ (万吨)_x000D_ Refinery_x000D_ Gas_x000D_ (104 tons) | AB1: 其他石油制品_x000D_ (万吨)_x000D_ Other_x000D_ Petroleum_x000D_ Products_x000D_ (104 tons) | AC1: 天然气_x000D_ (亿立方米)_x000D_ Natural Gas_x000D_ (108 cu.m) | AD1: 液化天然气_x000D_ (万吨)_x000D_ Liquefied_x000D_ Natural Gas_x000D_ (104 tons) | AE1: 热力_x000D_ (万百万千焦)_x000D_ Heat_x000D_ (1010 kJ) | AF1: 电力_x000D_ (亿千瓦小时)_x000D_ Electricity_x000D_ (108 kW·h) | AG1: 其他能源_x000D_ (万吨标准煤)_x000D_ Other_x000D_ Energy_x000D_ (104 tce)
A2: 工业 | B2: =SUM(B3:B43) -> 0 | C2: =SUM(C3:C43) -> 1 | D2: =SUM(D3:D43) -> 1 | E2: =SUM(E3:E43) -> 1 | F2: =SUM(F3:F43) -> 1 | G2: =SUM(G3:G43) -> 1 | H2: =SUM(H3:H43) -> 1 | I2: =SUM(I3:I43) -> 1 | ... AG2: =SUM(AG3:AG43) -> 1
A3: 煤炭开采和洗选业 | C3: 0 | D3: 0 | E3: 0 | F3: 0 | G3: 0 | H3: 0 | I3: 0 | J3: 0 | K3: 0 | L3: 0 | M3: 0 | O3: 0 | P3: 0 | Q3: 0 | R3: 0 | S3: 0 | T3: 0 | U3: 0 | V3: 0 | W3: 0 | X3: 0 | Y3: 0 | Z3: 0 | AA3: 0 | AB3: 0 | AC3: 0 | AD3: 0 | AE3: 0 | AF3: 0 | AG3: 0
A4: 石油和天然气开采业 | C4: 0 | D4: 0 | E4: 0 | F4: 0 | G4: 0 | H4: 0 | I4: 0 | J4: 0 | K4: 0 | L4: 0 | M4: 0 | O4: 0 | P4: 0 | Q4: 0 | R4: 0 | S4: 0 | T4: 0 | U4: 0 | V4: 0 | W4: 0 | X4: 0 | Y4: 0 | Z4: 0 | AA4: 0 | AB4: 0 | AC4: 0 | AD4: 0 | AE4: 0 | AF4: 0 | AG4: 0
A5: 黑色金属矿采选业 | C5: 0 | D5: 0 | E5: 0 | F5: 0 | G5: 0 | H5: 0 | I5: 0 | J5: 0 | K5: 0 | L5: 0 | M5: 0 | O5: 0 | P5: 0 | Q5: 0 | R5: 0 | S5: 0 | T5: 0 | U5: 0 | V5: 0 | W5: 0 | X5: 0 | Y5: 0 | Z5: 0 | AA5: 0 | AB5: 0 | AC5: 0 | AD5: 0 | AE5: 0 | AF5: 0 | AG5: 0
A6: 有色金属矿采选业 | C6: 0 | D6: 0 | E6: 0 | F6: 0 | G6: 0 | H6: 0 | I6: 0 | J6: 0 | K6: 0 | L6: 0 | M6: 0 | O6: 0 | P6: 0 | Q6: 0 | R6: 0 | S6: 0 | T6: 0 | U6: 0 | V6: 0 | W6: 0 | X6: 0 | Y6: 0 | Z6: 0 | AA6: 0 | AB6: 0 | AC6: 0 | AD6: 0 | AE6: 0 | AF6: 0 | AG6: 0
A7: 非金属矿采选业 | C7: 0 | D7: 0 | E7: 0 | F7: 0 | G7: 0 | H7: 0 | I7: 0 | J7: 0 | K7: 0 | L7: 0 | M7: 0 | O7: 0 | P7: 0 | Q7: 0 | R7: 0 | S7: 0 | T7: 0 | U7: 0 | V7: 0 | W7: 0 | X7: 0 | Y7: 0 | Z7: 0 | AA7: 0 | AB7: 0 | AC7: 0 | AD7: 0 | AE7: 0 | AF7: 0 | AG7: 0
A8: 开采专业及辅助性活动 | C8: 0 | D8: 0 | E8: 0 | F8: 0 | G8: 0 | H8: 0 | I8: 0 | J8: 0 | K8: 0 | L8: 0 | M8: 0 | O8: 0 | P8: 0 | Q8: 0 | R8: 0 | S8: 0 | T8: 0 | U8: 0 | V8: 0 | W8: 0 | X8: 0 | Y8: 0 | Z8: 0 | AA8: 0 | AB8: 0 | AC8: 0 | AD8: 0 | AE8: 0 | AF8: 0 | AG8: 0
A9: 其他采矿业 | C9: 0 | D9: 0 | E9: 0 | F9: 0 | G9: 0 | H9: 0 | I9: 0 | J9: 0 | K9: 0 | L9: 0 | M9: 0 | O9: 0 | P9: 0 | Q9: 0 | R9: 0 | S9: 0 | T9: 0 | U9: 0 | V9: 0 | W9: 0 | X9: 0 | Y9: 0 | Z9: 0 | AA9: 0 | AB9: 0 | AC9: 0 | AD9: 0 | AE9: 0 | AF9: 0 | AG9: 0
A10: 农副食品加工业 | C10: 0 | D10: 0 | E10: 0 | F10: 0 | G10: 0 | H10: 0 | I10: 0 | J10: 0 | K10: 0 | L10: 0 | M10: 0 | O10: 0 | P10: 0 | Q10: 0 | R10: 0 | S10: 0 | T10: 0 | U10: 0 | V10: 0 | W10: 0 | X10: 0 | Y10: 0 | Z10: 0 | AA10: 0 | AB10: 0 | AC10: 0 | AD10: 0 | AE10: 0 | AF10: 0 | AG10: =AE65 -> 0.54200622
A11: 食品制造业 | C11: 0 | D11: 0 | E11: 0 | F11: 0 | G11: 0 | H11: 0 | I11: 0 | J11: 0 | K11: 0 | L11: 0 | M11: 0 | O11: 0 | P11: 0 | Q11: 0 | R11: 0 | S11: 0 | T11: 0 | U11: 0 | V11: =V55 -> 0.0016051993 | W11: 0 | X11: 0 | Y11: 0 | Z11: 0 | AA11: 0 | AB11: 0 | AC11: 0 | AD11: 0 | AE11: 0 | AF11: 0 | AG11: 0
A12: 酒、饮料和精制茶制造业 | C12: 0 | D12: 0 | E12: 0 | F12: 0 | G12: 0 | H12: 0 | I12: 0 | J12: 0 | K12: 0 | L12: 0 | M12: 0 | O12: 0 | P12: 0 | Q12: 0 | R12: 0 | S12: 0 | T12: 0 | U12: 0 | V12: 0 | W12: 0 | X12: 0 | Y12: 0 | Z12: 0 | AA12: 0 | AB12: 0 | AC12: 0 | AD12: 0 | AE12: 0 | AF12: 0 | AG12: 0
A13: 烟草制品业 | C13: 0 | D13: 0 | E13: 0 | F13: 0 | G13: 0 | H13: 0 | I13: 0 | J13: 0 | K13: 0 | L13: 0 | M13: 0 | O13: 0 | P13: 0 | Q13: 0 | R13: 0 | S13: 0 | T13: 0 | U13: 0 | V13: 0 | W13: 0 | X13: 0 | Y13: 0 | Z13: 0 | AA13: 0 | AB13: 0 | AC13: 0 | AD13: 0 | AE13: 0 | AF13: 0 | AG13: 0
A14: 纺织业 | C14: 0 | D14: 0 | E14: 0 | F14: 0 | G14: 0 | H14: 0 | I14: 0 | J14: 0 | K14: 0 | L14: 0 | M14: 0 | O14: 0 | P14: 0 | Q14: 0 | R14: 0 | S14: 0 | T14: 0 | U14: 0 | V14: 0 | W14: 0 | X14: 0 | Y14: 0 | Z14: 0 | AA14: 0 | AB14: 0 | AC14: 0 | AD14: 0 | AE14: 0 | AF14: 0 | AG14: 0
A15: 纺织服装、服饰业 | C15: 0 | D15: 0 | E15: 0 | F15: 0 | G15: 0 | H15: 0 | I15: 0 | J15: 0 | K15: 0 | L15: 0 | M15: 0 | O15: 0 | P15: 0 | Q15: 0 | R15: 0 | S15: 0 | T15: 0 | U15: 0 | V15: 0 | W15: 0 | X15: 0 | Y15: 0 | Z15: 0 | AA15: 0 | AB15: 0 | AC15: 0 | AD15: 0 | AE15: 0 | AF15: 0 | AG15: 0
A16: 皮革、毛皮、羽毛及其制品和制鞋业 | C16: 0 | D16: 0 | E16: 0 | F16: 0 | G16: 0 | H16: 0 | I16: 0 | J16: 0 | K16: 0 | L16: 0 | M16: 0 | O16: 0 | P16: 0 | Q16: 0 | R16: 0 | S16: 0 | T16: 0 | U16: 0 | V16: 0 | W16: 0 | X16: 0 | Y16: 0 | Z16: 0 | AA16: 0 | AB16: 0 | AC16: 0 | AD16: 0 | AE16: 0 | AF16: 0 | AG16: 0
A17: 木材加工和木、竹、藤、棕、草制品业 | C17: 0 | D17: 0 | E17: 0 | F17: 0 | G17: 0 | H17: 0 | I17: 0 | J17: 0 | K17: 0 | L17: 0 | M17: 0 | O17: 0 | P17: 0 | Q17: 0 | R17: 0 | S17: 0 | T17: 0 | U17: 0 | V17: =V56 -> 0.0066948555 | W17: 0 | X17: 0 | Y17: 0 | Z17: 0 | AA17: 0 | AB17: 0 | AC17: 0 | AD17: 0 | AE17: 0 | AF17: 0 | AG17: 0
A18: 家具制造业 | C18: 0 | D18: 0 | E18: 0 | F18: 0 | G18: 0 | H18: 0 | I18: 0 | J18: 0 | K18: 0 | L18: 0 | M18: 0 | O18: 0 | P18: 0 | Q18: 0 | R18: 0 | S18: 0 | T18: 0 | U18: 0 | V18: 0 | W18: 0 | X18: 0 | Y18: 0 | Z18: 0 | AA18: 0 | AB18: 0 | AC18: 0 | AD18: 0 | AE18: 0 | AF18: 0 | AG18: 0
A19: 造纸和纸制品业 | C19: 0 | D19: 0 | E19: 0 | F19: 0 | G19: 0 | H19: 0 | I19: 0 | J19: 0 | K19: 0 | L19: 0 | M19: 0 | O19: 0 | P19: 0 | Q19: 0 | R19: 0 | S19: 0 | T19: 0 | U19: 0 | V19: 0 | W19: 0 | X19: 0 | Y19: 0 | Z19: 0 | AA19: 0 | AB19: 0 | AC19: 0 | AD19: 0 | AE19: 0 | AF19: 0 | AG19: 0
A20: 印刷和记录媒介复制业 | C20: 0 | D20: 0 | E20: 0 | F20: 0 | G20: 0 | H20: 0 | I20: 0 | J20: 0 | K20: 0 | L20: 0 | M20: 0 | O20: 0 | P20: 0 | Q20: 0 | R20: 0 | S20: 0 | T20: 0 | U20: 0 | V20: 0 | W20: 0 | X20: 0 | Y20: 0 | Z20: 0 | AA20: 0 | AB20: 0 | AC20: 0 | AD20: 0 | AE20: 0 | AF20: 0 | AG20: 0
A21: 文教、工美、体育和娱乐用品制造业 | C21: 0 | D21: 0 | E21: 0 | F21: 0 | G21: 0 | H21: 0 | I21: 0 | J21: 0 | K21: 0 | L21: 0 | M21: 0 | O21: 0 | P21: 0 | Q21: 0 | R21: 0 | S21: 0 | T21: 0 | U21: 0 | V21: =V57 -> 0.0020750137 | W21: 0 | X21: 0 | Y21: 0 | Z21: 0 | AA21: 0 | AB21: 0 | AC21: 0 | AD21: 0 | AE21: 0 | AF21: 0 | AG21: 0
A22: 石油、煤炭及其他燃料加工业 | C22: =C59 -> 0.06164399 | D22: =B65 -> 1 | E22: =C69 -> 0.11249145 | F22: =C69 -> 0.11249145 | G22: =C69 -> 0.11249145 | H22: 0 | I22: 0 | J22: 0 | K22: 0 | L22: 0 | M22: =C88 -> 0.13081125 | O22: 0 | P22: =L60 -> 0.06184669 | Q22: 0 | R22: =L71 -> 0 | S22: =L75 -> 0.38347339 | T22: =L78 -> 0.24832116 | U22: =L83 -> 0.93498597 | V22: 0 | W22: =V63 -> 0.068035654 | X22: =V70 -> 0.019665644 | Y22: 0 | Z22: =V79 -> 0.499622 | AA22: =U84 -> 1 | AB22: =V88 -> 0.75957965 | AC22: 0 | AD22: 0 | AE22: 0 | AF22: 0 | AG22: =AE62 -> 0.015074762
A23: 化学原料和化学制品制造业 | C23: =C60 -> 0.54037695 | D23: 0 | E23: 0 | F23: 0 | G23: 0 | H23: =C77 -> 0.091554672 | I23: =B83 -> 1 | J23: =B83 -> 1 | K23: =B83 -> 1 | L23: =B83 -> 1 | M23: =C89 -> 0.5706757 | O23: =K54 -> 1 | P23: =L59 -> 0.52656794 | Q23: =L64 -> 0.37109375 | R23: =K70 -> 1 | S23: =L74 -> 0.61652661 | T23: =L79 -> 0.75167884 | U23: 0 | V23: =V58 -> 0.98950748 | W23: =V64 -> 0.93015909 | X23: =V68 -> 0.0061379422 | Y23: =W68 -> 0 | Z23: =V80 -> 0.500378 | AA23: 0 | AB23: =V89 -> 0.24042035 | AC23: =AD53 -> 1 | AD23: =AD57 -> 1 | AE23: 0 | AF23: 0 | AG23: =AE63 -> 0.22257299
A24: 医药制造业 | C24: 0 | D24: 0 | E24: 0 | F24: 0 | G24: 0 | H24: 0 | I24: 0 | J24: 0 | K24: 0 | L24: 0 | M24: 0 | O24: 0 | P24: 0 | Q24: 0 | R24: 0 | S24: 0 | T24: 0 | U24: 0 | V24: =V59 -> 0.00011745361 | W24: =W59 -> 0 | X24: 0 | Y24: 0 | Z24: 0 | AA24: 0 | AB24: 0 | AC24: 0 | AD24: 0 | AE24: 0 | AF24: 0 | AG24: 0
A25: 化学纤维制造业 | C25: 0 | D25: 0 | E25: 0 | F25: 0 | G25: 0 | H25: 0 | I25: 0 | J25: 0 | K25: 0 | L25: 0 | M25: 0 | O25: 0 | P25: 0 | Q25: 0 | R25: 0 | S25: 0 | T25: 0 | U25: 0 | V25: 0 | W25: 0 | X25: 0 | Y25: 0 | Z25: 0 | AA25: 0 | AB25: 0 | AC25: 0 | AD25: 0 | AE25: 0 | AF25: 0 | AG25: 0
A26: 橡胶和塑料制品业 | C26: 0 | D26: 0 | E26: 0 | F26: 0 | G26: 0 | H26: 0 | I26: 0 | J26: 0 | K26: 0 | L26: 0 | M26: 0 | O26: 0 | P26: =L58 -> 0.41158537 | Q26: =L63 -> 0.16210938 | R26: 0 | S26: 0 | T26: 0 | U26: 0 | V26: 0 | W26: 0 | X26: 0 | Y26: 0 | Z26: 0 | AA26: 0 | AB26: 0 | AC26: 0 | AD26: 0 | AE26: 0 | AF26: 0 | AG26: 0
A27: 非金属矿物制品业 | C27: 0 | D27: 0 | E27: =C70 -> 0.82205276 | F27: =C70 -> 0.82205276 | G27: =C70 -> 0.82205276 | H27: 0 | I27: 0 | J27: 0 | K27: 0 | L27: 0 | M27: =C90 -> 0.020322233 | O27: 0 | P27: 0 | Q27: 0 | R27: 0 | S27: 0 | T27: 0 | U27: 0 | V27: 0 | W27: =V65 -> 0.0018052578 | X27: =V69 -> 0.97419641 | Y27: =V74 -> 0.90323784 | Z27: 0 | AA27: 0 | AB27: 0 | AC27: 0 | AD27: 0 | AE27: 0 | AF27: 0 | AG27: =AE64 -> 0.22034603
A28: 黑色金属冶炼和压延加工业 | C28: =C61 -> 0.39797906 | D28: 0 | E28: =C71 -> 0.065455789 | F28: =C71 -> 0.065455789 | G28: =C71 -> 0.065455789 | H28: =C78 -> 0.90844533 | I28: 0 | J28: 0 | K28: 0 | L28: 0 | M28: =C91 -> 0.27819082 | O28: 0 | P28: 0 | Q28: 0 | R28: 0 | S28: 0 | T28: 0 | U28: 0 | V28: 0 | W28: 0 | X28: 0 | Y28: 0 | Z28: 0 | AA28: 0 | AB28: 0 | AC28: 0 | AD28: 0 | AE28: 0 | AF28: 0 | AG28: 0
A29: 有色金属冶炼和压延加工业 | C29: 0 | D29: 0 | E29: 0 | F29: 0 | G29: 0 | H29: 0 | I29: 0 | J29: 0 | K29: 0 | L29: 0 | M29: 0 | O29: 0 | P29: 0 | Q29: 0 | R29: 0 | S29: 0 | T29: 0 | U29: 0 | V29: 0 | W29: 0 | X29: 0 | Y29: =V73 -> 0.096762165 | Z29: 0 | AA29: 0 | AB29: 0 | AC29: 0 | AD29: 0 | AE29: 0 | AF29: 0 | AG29: 0
A30: 金属制品业 | C30: 0 | D30: 0 | E30: 0 | F30: 0 | G30: 0 | H30: 0 | I30: 0 | J30: 0 | K30: 0 | L30: 0 | M30: 0 | O30: 0 | P30: 0 | Q30: 0 | R30: 0 | S30: 0 | T30: 0 | U30: 0 | V30: 0 | W30: 0 | X30: 0 | Y30: 0 | Z30: 0 | AA30: 0 | AB30: 0 | AC30: 0 | AD30: 0 | AE30: 0 | AF30: 0 | AG30: 0
A31: 通用设备制造业 | C31: 0 | D31: 0 | E31: 0 | F31: 0 | G31: 0 | H31: 0 | I31: 0 | J31: 0 | K31: 0 | L31: 0 | M31: 0 | O31: 0 | P31: 0 | Q31: =L65 -> 0.31640625 | R31: 0 | S31: 0 | T31: 0 | U31: =L84 -> 0.012416022 | V31: 0 | W31: 0 | X31: 0 | Y31: 0 | Z31: 0 | AA31: 0 | AB31: 0 | AC31: 0 | AD31: 0 | AE31: 0 | AF31: 0 | AG31: 0
A32: 专用设备制造业 | C32: 0 | D32: 0 | E32: 0 | F32: 0 | G32: 0 | H32: 0 | I32: 0 | J32: 0 | K32: 0 | L32: 0 | M32: 0 | O32: 0 | P32: 0 | Q32: =L66 -> 0.15039063 | R32: 0 | S32: 0 | T32: 0 | U32: =L85 -> 0.01228846 | V32: 0 | W32: 0 | X32: 0 | Y32: 0 | Z32: 0 | AA32: 0 | AB32: 0 | AC32: 0 | AD32: 0 | AE32: 0 | AF32: 0 | AG32: 0
A33: 汽车制造业 | C33: 0 | D33: 0 | E33: 0 | F33: 0 | G33: 0 | H33: 0 | I33: 0 | J33: 0 | K33: 0 | L33: 0 | M33: 0 | O33: 0 | P33: 0 | Q33: 0 | R33: 0 | S33: 0 | T33: 0 | U33: =L86 -> 0.039331576 | V33: 0 | W33: 0 | X33: 0 | Y33: 0 | Z33: 0 | AA33: 0 | AB33: 0 | AC33: 0 | AD33: 0 | AE33: 0 | AF33: 0 | AG33: 0
A34: 铁路、船舶、航空航天和其他运输设备制造业 | C34: 0 | D34: 0 | E34: 0 | F34: 0 | G34: 0 | H34: 0 | I34: 0 | J34: 0 | K34: 0 | L34: 0 | M34: 0 | O34: 0 | P34: 0 | Q34: 0 | R34: 0 | S34: 0 | T34: 0 | U34: =L87 -> 0.00097797432 | V34: 0 | W34: 0 | X34: 0 | Y34: 0 | Z34: 0 | AA34: 0 | AB34: 0 | AC34: 0 | AD34: 0 | AE34: 0 | AF34: 0 | AG34: 0
A35: 电气机械和器材制造业 | C35: 0 | D35: 0 | E35: 0 | F35: 0 | G35: 0 | H35: 0 | I35: 0 | J35: 0 | K35: 0 | L35: 0 | M35: 0 | O35: 0 | P35: 0 | Q35: 0 | R35: 0 | S35: 0 | T35: 0 | U35: 0 | V35: 0 | W35: 0 | X35: 0 | Y35: 0 | Z35: 0 | AA35: 0 | AB35: 0 | AC35: 0 | AD35: 0 | AE35: 0 | AF35: 0 | AG35: 0
A36: 计算机、通信和其他电子设备制造业 | C36: 0 | D36: 0 | E36: 0 | F36: 0 | G36: 0 | H36: 0 | I36: 0 | J36: 0 | K36: 0 | L36: 0 | M36: 0 | O36: 0 | P36: 0 | Q36: 0 | R36: 0 | S36: 0 | T36: 0 | U36: 0 | V36: 0 | W36: 0 | X36: 0 | Y36: 0 | Z36: 0 | AA36: 0 | AB36: 0 | AC36: 0 | AD36: 0 | AE36: 0 | AF36: 0 | AG36: 0
A37: 仪器仪表制造业 | C37: 0 | D37: 0 | E37: 0 | F37: 0 | G37: 0 | H37: 0 | I37: 0 | J37: 0 | K37: 0 | L37: 0 | M37: 0 | O37: 0 | P37: 0 | Q37: 0 | R37: 0 | S37: 0 | T37: 0 | U37: 0 | V37: 0 | W37: 0 | X37: 0 | Y37: 0 | Z37: 0 | AA37: 0 | AB37: 0 | AC37: 0 | AD37: 0 | AE37: 0 | AF37: 0 | AG37: 0
A38: 其他制造业 | C38: 0 | D38: 0 | E38: 0 | F38: 0 | G38: 0 | H38: 0 | I38: 0 | J38: 0 | K38: 0 | L38: 0 | M38: 0 | O38: 0 | P38: 0 | Q38: 0 | R38: 0 | S38: 0 | T38: 0 | U38: 0 | V38: 0 | W38: 0 | X38: 0 | Y38: 0 | Z38: 0 | AA38: 0 | AB38: 0 | AC38: 0 | AD38: 0 | AE38: 0 | AF38: 0 | AG38: 0
A39: 废弃资源综合利用业 | C39: 0 | D39: 0 | E39: 0 | F39: 0 | G39: 0 | H39: 0 | I39: 0 | J39: 0 | K39: 0 | L39: 0 | M39: 0 | O39: 0 | P39: 0 | Q39: 0 | R39: 0 | S39: 0 | T39: 0 | U39: 0 | V39: 0 | W39: 0 | X39: 0 | Y39: 0 | Z39: 0 | AA39: 0 | AB39: 0 | AC39: 0 | AD39: 0 | AE39: 0 | AF39: 0 | AG39: 0
A40: 金属制品、机械和设备修理业 | C40: 0 | D40: 0 | E40: 0 | F40: 0 | G40: 0 | H40: 0 | I40: 0 | J40: 0 | K40: 0 | L40: 0 | M40: 0 | O40: 0 | P40: 0 | Q40: 0 | R40: 0 | S40: 0 | T40: 0 | U40: 0 | V40: 0 | W40: 0 | X40: 0 | Y40: 0 | Z40: 0 | AA40: 0 | AB40: 0 | AC40: 0 | AD40: 0 | AE40: 0 | AF40: 0 | AG40: 0
...

Sheet Final Energy Consumption-2020
A1: 4-2 工业分行业终端能源消费量(实物量)-2020
A2: 行 业 | B2: 煤合计_x000D_ (万吨)_x000D_ Coal Total_x000D_ (104 tons) | C2: 原煤_x000D_ (万吨)_x000D_ Raw Coal_x000D_ (104 tons) | D2: 洗精煤_x000D_ (万吨)_x000D_ Cleaned_x000D_ Coal_x000D_ (104 tons) | E2: 其他洗煤_x000D_ (万吨)_x000D_ Other_x000D_ Washed Coal_x000D_ (104 tons) | F2: 焦炭_x000D_ (万吨)_x000D_ Coke_x000D_ (104 tons) | G2: 焦炉煤气_x000D_ (亿立方米)_x000D_ Coke Oven_x000D_ Gas_x000D_ (108 cu.m) | H2: 高炉煤气_x000D_ (亿立方米)_x000D_ Blast Furnace_x000D_ Gas_x000D_ (108 cu.m) | I2: 转炉煤气_x000D_ (亿立方米)_x000D_ Converter_x000D_ Gas_x000D_ (108 cu.m) | J2: 其他煤气_x000D_ (亿立方米)_x000D_ Other Gas_x000D_ (108 cu.m) | K2: 其他焦化产品_x000D_ (万吨)_x000D_ Other Coking_x000D_ Products_x000D_ (104 tons) | L2: 油品合计_x000D_ (万吨)_x000D_ Petroleum_x000D_ Products Total_x000D_ (104 tons) | M2: 原油_x000D_ (万吨)_x000D_ Crude Oil_x000D_ (104 tons) | N2: 汽油_x000D_ (万吨)_x000D_ Gasoline_x000D_ (104 tons) | O2: 煤油_x000D_ (万吨)_x000D_ Kerosene_x000D_ (104 tons) | P2: 柴油_x000D_ (万吨)_x000D_ Diesel Oil_x000D_ (104 tons) | Q2: 燃料油_x000D_ (万吨)_x000D_ Fuel Oil_x000D_ (104 tons) | R2: 石脑油_x000D_ (万吨)_x000D_ Naphtha_x000D_ (104 tons) | S2: 润滑油_x000D_ (万吨)_x000D_ Lubricants_x000D_ (104 tons) | T2: 石蜡_x000D_ (万吨)_x000D_ Paraffin_x000D_ Waxes_x000D_ (104 tons) | U2: 溶剂油_x000D_ (万吨)_x000D_ White Spirit_x000D_ (104 tons) | V2: 石油沥青_x000D_ (万吨)_x000D_ Bitumen_x000D_ Asphalt_x000D_ (104 tons) | W2: 石油焦_x000D_ (万吨)_x000D_ Petroleum_x000D_ Coke_x000D_ (104 tons) | X2: 液化石油气_x000D_ (万吨)_x000D_ Liquefied_x000D_ Petroleum Gas_x000D_ (104 tons) | Y2: 炼厂干气_x000D_ (万吨)_x000D_ Refinery_x000D_ Gas_x000D_ (104 tons) | Z2: 其他石油制品_x000D_ (万吨)_x000D_ Other Petroleum_x000D_ Products_x000D_ (104 tons) | AA2: 天然气_x000D_ (亿立方米)_x000D_ Natural Gas_x000D_ (108 cu.m) | AB2: 液化天然气_x000D_ (万吨)_x000D_ Liquefied_x000D_ Natural Gas_x000D_ (104 tons) | AC2: 热力_x000D_ (万百万千焦)_x000D_ Heat_x000D_ (1010 kJ) | AD2: 电力_x000D_ (亿千瓦小时)_x000D_ Electricity_x000D_ (108 kW·h) | AE2: 其他能源_x000D_ (万吨标准煤)_x000D_ Other Energy_x000D_ (104 tce)
A3: 煤炭开采和洗选业 | B3: 1987.31 | C3: 1115.16 | E3: 867.99 | F3: 4.91 | G3: 0.95 | H3: 0.39 | J3: 1.13 | K3: 0.57 | L3: 332.66 | M3: 0.08 | N3: 3.22 | O3: 0.61 | P3: 147.42 | Q3: 0.2 | R3: 142.6 | S3: 1.22 | V3: 0.36 | X3: 36.44 | Z3: 0.5 | AA3: 8.66 | AB3: 15.21 | AC3: 627.63 | AD3: 908.81 | AE3: 1.13
A4: 石油和天然气开采业 | B4: 65.59 | C4: 65.59 | L4: 305.5 | M4: 247.51 | N4: 5.65 | P4: 25 | Q4: 0.3 | S4: 0.01 | X4: 0.1 | Y4: 10.63 | Z4: 16.31 | AA4: 126.49 | AB4: 11.65 | AC4: 2685.32 | AD4: 463.32
A5: 黑色金属矿采选业 | B5: 163.66 | C5: 150.61 | E5: 5.14 | F5: 169.63 | G5: 2.77 | H5: 19.7 | I5: 0.1 | L5: 35.8 | N5: 0.6 | O5: 0.01 | P5: 34.89 | Q5: 0.01 | S5: 0.29 | AA5: 0.05 | AC5: 130.58 | AD5: 447.44 | AE5: 2.39
A6: 有色金属矿采选业 | B6: 76.01 | C6: 74.75 | E6: 1.25 | F6: 3.65 | G6: 1.01 | L6: 19.3 | N6: 1.07 | O6: 0.4 | P6: 16.57 | Q6: 0.52 | S6: 0.04 | V6: 0.4 | W6: 0.31 | AA6: 0.83 | AC6: 0.34 | AD6: 329.47 | AE6: 6.01
A7: 非金属矿采选业 | B7: 285.91 | C7: 246.51 | E7: 33.63 | F7: 14.73 | G7: 1.66 | I7: 1.22 | L7: 50.26 | N7: 0.77 | O7: 0.01 | P7: 47.82 | Q7: 0.04 | S7: 0.16 | V7: 0.59 | W7: 0.73 | X7: 0.06 | Z7: 0.07 | AA7: 0.84 | AB7: 17.34 | AC7: 2289.53 | AD7: 225.7 | AE7: 0.33
A8: 开采专业及辅助性活动 | B8: 3.33 | C8: 3.33 | L8: 108.59 | M8: 0.09 | N8: 2.59 | P8: 105.17 | Q8: 0.07 | S8: 0.44 | X8: 0.06 | Z8: 0.17 | AA8: 2.97 | AB8: 0.5 | AC8: 251.17 | AD8: 29.53
A9: 其他采矿业 | B9: 8.29 | C9: 8.29 | L9: 0.23 | P9: 0.23 | AD9: 161.71
A10: 农副食品加工业 | B10: 772.08 | C10: 700.34 | E10: 67.55 | F10: 14 | G10: 0.03 | J10: 0.14 | L10: 20.7 | N10: 4.85 | O10: 0.04 | P10: 12.33 | Q10: 0.93 | S10: 0.03 | T10: 0.02 | U10: 1.34 | X10: 0.97 | Z10: 0.18 | AA10: 4.2 | AB10: 187.09 | AC10: 8733.15 | AD10: 842.42 | AE10: 186.82
A11: 食品制造业 | B11: 846.89 | C11: 837.51 | E11: 2.91 | F11: 1.84 | L11: 11.33 | N11: 3.69 | O11: 0.01 | P11: 5.01 | Q11: 0.43 | S11: 0.01 | X11: 1.21 | Z11: 0.97 | AA11: 13.87 | AB11: 89.28 | AC11: 8795.58 | AD11: 334.09 | AE11: 38.62
A12: 酒、饮料和精制茶制造业 | B12: 404.07 | C12: 397.26 | E12: 4.98 | F12: 0.01 | G12: 0.02 | J12: 0.02 | K12: 0.01 | L12: 5.81 | N12: 1.82 | P12: 2.89 | Q12: 0.39 | S12: 0.01 | X12: 0.7 | Z12: 0.01 | AA12: 9.97 | AB12: 34.71 | AC12: 5889.74 | AD12: 176.06 | AE12: 15.13
A13: 烟草制品业 | B13: 4.07 | C13: 4.07 | L13: 0.68 | N13: 0.08 | P13: 0.55 | X13: 0.04 | AA13: 1.14 | AC13: 214.86 | AD13: 50.87 | AE13: 2.23
A14: 纺织业 | B14: 285.95 | C14: 231.19 | E14: 7.28 | F14: 3.93 | L14: 11.87 | N14: 3.27 | O14: 0.01 | P14: 3.8 | Q14: 1.17 | S14: 0.1 | V14: 1.58 | X14: 1.36 | Z14: 0.57 | AA14: 15.9 | AB14: 252.62 | AC14: 32049.84 | AD14: 1650.38 | AE14: 52.08
A15: 纺织服装、服饰业 | B15: 28.66 | C15: 28.28 | E15: 0.3 | F15: 0.04 | L15: 5.57 | N15: 2.89 | P15: 2.16 | Q15: 0.25 | S15: 0.02 | X15: 0.2 | Z15: 0.03 | AA15: 1.01 | AB15: 76.67 | AC15: 321.44 | AD15: 220.24 | AE15: 6.26
A16: 皮革、毛皮、羽毛及其制品和制鞋业 | B16: 17.8 | C16: 15.69 | E16: 0.03 | H16: 0.07 | L16: 3.13 | N16: 1.56 | P16: 1 | Q16: 0.14 | S16: 0.04 | U16: 0.1 | X16: 0.2 | Z16: 0.07 | AA16: 0.11 | AB16: 20.42 | AC16: 184.79 | AD16: 140.96 | AE16: 7.75
A17: 木材加工和木、竹、藤、棕、草制品业 | B17: 34 | C17: 33.47 | E17: 0.52 | F17: 0.01 | L17: 7.27 | N17: 1.27 | P17: 3.88 | Q17: 0.13 | S17: 0.07 | T17: 1.69 | X17: 0.24 | AA17: 2.81 | AB17: 2.29 | AC17: 694.28 | AD17: 283.98 | AE17: 81.03
A18: 家具制造业 | B18: 1.85 | C18: 1.66 | E18: 0.19 | F18: 0.06 | L18: 3.85 | N18: 1.63 | O18: 0.02 | P18: 1.88 | Q18: 0.06 | S18: 0.08 | X18: 0.18 | AA18: 1.37 | AB18: 2.23 | AC18: 76.15 | AD18: 120.74 | AE18: 3.13
A19: 造纸和纸制品业 | B19: 583.73 | C19: 512.11 | E19: 43.34 | F19: 7.93 | G19: 0.07 | L19: 15.49 | M19: 0.03 | N19: 1.63 | P19: 9.23 | Q19: 2.72 | S19: 0.09 | T19: 0.03 | U19: 0.26 | X19: 1.42 | Z19: 0.09 | AA19: 5.11 | AB19: 116.91 | AC19: 22715.18 | AD19: 798.25 | AE19: 62.84
A20: 印刷和记录媒介复制业 | B20: 13 | C20: 12.14 | E20: 0.32 | F20: 0.02 | G20: 0.4 | L20: 6.8 | N20: 2.83 | O20: 0.01 | P20: 3.12 | Q20: 0.16 | S20: 0.06 | U20: 0.02 | X20: 0.42 | Z20: 0.19 | AA20: 3.57 | AB20: 8.23 | AC20: 501.06 | AD20: 132.53 | AE20: 7.32
A21: 文教、工美、体育和娱乐用品制造业 | B21: 10.38 | C21: 9.91 | F21: 0.44 | L21: 16.83 | N21: 2.06 | P21: 1.98 | Q21: 0.27 | S21: 0.02 | T21: 0.51 | U21: 0.06 | W21: 11.07 | X21: 0.71 | Z21: 0.14 | AA21: 3.24 | AB21: 95.96 | AC21: 107.72 | AD21: 85.05 | AE21: 5.31
A22: 石油、煤炭及其他燃料加工业 | B22: 1902.55 | C22: 1138.29 | E22: 724.96 | F22: 56.52 | G22: 196.79 | H22: 100.16 | I22: 2.88 | J22: 2.57 | K22: 91.14 | L22: 11424.97 | M22: 52.25 | N22: 1.19 | O22: 0.03 | P22: 11.72 | Q22: 116.66 | R22: 1295.31 | S22: 241.32 | T22: 0.02 | U22: 1.05 | V22: 7.88 | W22: 219.55 | X22: 1519.62 | Y22: 1660.34 | Z22: 6298.03 | AA22: 27.44 | AB22: 573.8 | AC22: 66461.36 | AD22: 1283.3 | AE22: 52.1
A23: 化学原料和化学制品制造业 | B23: 12283.92 | C23: 11855.34 | E23: 229.71 | F23: 4059.94 | G23: 90.42 | H23: 9.42 | I23: 8.58 | J23: 13.37 | K23: 545.66 | L23: 8128.36 | M23: 118.23 | N23: 8.79 | O23: 2 | P23: 25.49 | Q23: 29.78 | R23: 4740.74 | S23: 1.19 | T23: 193.02 | U23: 39.65 | V23: 39.06 | W23: 84.9 | X23: 840.3 | Y23: 190.42 | Z23: 1814.8 | AA23: 186.67 | AB23: 1715.36 | AC23: 166792.84 | AD23: 5781.14 | AE23: 232.29
A24: 医药制造业 | B24: 412.05 | C24: 398.55 | E24: 3.33 | F24: 3.46 | G24: 0.15 | J24: 0.02 | K24: 0.01 | L24: 9.84 | N24: 2.98 | O24: 0.01 | P24: 3.76 | Q24: 1.5 | S24: 0.01 | T24: 0.03 | U24: 0.34 | X24: 0.46 | Z24: 0.76 | AA24: 7.99 | AB24: 81.89 | AC24: 11051.26 | AD24: 430.45 | AE24: 19.9
A25: 化学纤维制造业 | B25: 538.66 | C25: 358.56 | E25: 4.27 | F25: 0.07 | L25: 2.4 | N25: 0.37 | O25: 0.02 | P25: 1.11 | Q25: 0.63 | S25: 0.04 | U25: 0.09 | X25: 0.09 | Z25: 0.05 | AA25: 2.27 | AB25: 115.9 | AC25: 11070.11 | AD25: 450.37 | AE25: 14.79
A26: 橡胶和塑料制品业 | B26: 221.87 | C26: 199.29 | E26: 1.89 | F26: 1.98 | G26: 0.71 | K26: 2.56 | L26: 26.63 | M26: 0.05 | N26: 5.92 | O26: 0.05 | P26: 7.69 | Q26: 2.21 | S26: 0.54 | T26: 1.26 | U26: 0.5 | V26: 2.89 | X26: 2.55 | Y26: 0.01 | Z26: 2.98 | AA26: 8.28 | AB26: 76.83 | AC26: 3125.94 | AD26: 1480.76 | AE26: 13.85
A27: 非金属矿物制品业 | B27: 24112.5 | C27: 14089.42 | E27: 9828.51 | F27: 1463.15 | G27: 38.27 | H27: 46.12 | I27: 9.44 | J27: 8.48 | K27: 16.56 | L27: 3221.74 | M27: 0.37 | N27: 12.92 | O27: 0.53 | P27: 232.27 | Q27: 58.29 | S27: 0.79 | T27: 0.89 | U27: 0.26 | V27: 280.82 | W27: 2564.62 | X27: 54.47 | Y27: 0.08 | Z27: 15.45 | AA27: 42.44 | AB27: 1332.74 | AC27: 4785.73 | AD27: 3929.53 | AE27: 83.03
A28: 黑色金属冶炼和压延加工业 | B28: 9801.55 | C28: 8804.84 | E28: 884.1 | F28: 40335.4 | G28: 353.69 | H28: 8350.98 | I28: 622.16 | J28: 1.57 | K28: 329.03 | L28: 76.53 | N28: 2.5 | O28: 0.02 | P28: 40.95 | Q28: 0.27 | S28: 1.29 | T28: 0.01 | W28: 21.3 | X28: 8.85 | Y28: 0.92 | Z28: 0.4 | AA28: 48.3 | AB28: 691.75 | AC28: 18749.02 | AD28: 6785.56 | AE28: 47.29
A29: 有色金属冶炼和压延加工业 | B29: 2309.03 | C29: 2019.58 | E29: 280.49 | F29: 399.66 | G29: 23.62 | I29: 1.85 | J29: 68.75 | K29: 9.79 | L29: 318.82 | M29: 0.21 | N29: 2.48 | O29: 0.37 | P29: 24.24 | Q29: 7.72 | S29: 0.48 | T29: 0.01 | U29: 0.1 | V29: 15.7 | W29: 257.88 | X29: 2.77 | Z29: 6.86 | AA29: 21.89 | AB29: 219.18 | AC29: 21665.46 | AD29: 7132.92 | AE29: 7.08
A30: 金属制品业 | B30: 242.3 | C30: 189.96 | E30: 51.18 | F30: 589.1 | G30: 3.21 | H30: 94.58 | I30: 3.04 | J30: 0.63 | K30: 3.01 | L30: 29.43 | N30: 8.24 | O30: 0.3 | P30: 13.11 | Q30: 0.75 | S30: 0.66 | T30: 0.03 | U30: 0.02 | V30: 0.19 | X30: 5.59 | Z30: 0.53 | AA30: 13.52 | AB30: 439.91 | AC30: 629.6 | AD30: 1551.86 | AE30: 4.64
A31: 通用设备制造业 | B31: 14.31 | C31: 12.55 | E31: 0.47 | F31: 412.08 | G31: 1.17 | H31: 0.24 | I31: 0.37 | L31: 35.56 | N31: 10.88 | O31: 1.44 | P31: 14.68 | Q31: 0.45 | R31: 0.03 | S31: 3.6 | T31: 0.14 | U31: 0.04 | X31: 2.77 | Z31: 1.53 | AA31: 10.43 | AB31: 84.84 | AC31: 351.42 | AD31: 1077.47 | AE31: 5.06
A32: 专用设备制造业 | B32: 10.65 | C32: 4.08 | G32: 0.33 | H32: 3.73 | J32: 0.5 | K32: 2.77 | L32: 35.42 | M32: 0.01 | N32: 8.3 | O32: 0.88 | P32: 15.01 | Q32: 0.38 | S32: 3.69 | T32: 0.03 | U32: 0.04 | X32: 3.92 | Z32: 3.16 | AA32: 5.28 | AB32: 93.55 | AC32: 833.26 | AD32: 498.54 | AE32: 4.35
A33: 汽车制造业 | B33: 16.78 | C33: 15.73 | E33: 0.06 | F33: 11.23 | G33: 0.06 | H33: 0.01 | I33: 0.01 | J33: 0.16 | L33: 41.86 | M33: 0.01 | N33: 13.62 | O33: 0.24 | P33: 16.33 | Q33: 0.17 | R33: 0.01 | S33: 8.36 | T33: 0.01 | U33: 0.12 | V33: 0.01 | X33: 1.6 | Z33: 1.38 | AA33: 6.88 | AB33: 159.38 | AC33: 2612.21 | AD33: 1182.79 | AE33: 2.32
A34: 铁路、船舶、航空航天和其他运输设备制造业 | B34: 35.24 | C34: 14.97 | E34: 20.27 | F34: 0.4 | G34: 0.24 | L34: 14.83 | N34: 2.71 | O34: 1.3 | P34: 7.59 | Q34: 0.98 | S34: 0.34 | T34: 0.22 | U34: 0.03 | X34: 1.31 | Z34: 0.33 | AA34: 4.99 | AB34: 127.43 | AC34: 592.46 | AD34: 159.76 | AE34: 0.24
A35: 电气机械和器材制造业 | B35: 10.44 | C35: 10.44 | F35: 0.7 | J35: 0.01 | L35: 24.36 | N35: 10.26 | O35: 0.12 | P35: 6.49 | Q35: 1.19 | S35: 1.89 | T35: 0.14 | U35: 0.09 | V35: 0.04 | W35: 0.31 | X35: 2.66 | Z35: 1.16 | AA35: 3.44 | AB35: 87.73 | AC35: 1397.41 | AD35: 942.86 | AE35: 4.76
A36: 计算机、通信和其他电子设备制造业 | B36: 15.82 | C36: 14.94 | E36: 0.87 | F36: 0.02 | G36: 0.05 | H36: 0.01 | L36: 12.54 | N36: 6.29 | O36: 0.02 | P36: 3.52 | Q36: 0.26 | S36: 0.32 | T36: 0.01 | U36: 0.03 | X36: 1.54 | Z36: 0.54 | AA36: 12.48 | AB36: 113.38 | AC36: 1255.34 | AD36: 1570.61 | AE36: 2.87
A37: 仪器仪表制造业 | B37: 2.06 | C37: 2.06 | L37: 3.83 | N37: 2.65 | O37: 0.04 | P37: 0.7 | Q37: 0.07 | S37: 0.08 | T37: 0.06 | X37: 0.09 | Z37: 0.13 | AA37: 0.52 | AB37: 2.71 | AC37: 68.26 | AD37: 77.23 | AE37: 1.21
A38: 其他制造业 | B38: 2.89 | C38: 2.84 | F38: 0.06 | H38: 0.69 | L38: 4.39 | N38: 0.45 | O38: 0.09 | P38: 0.83 | S38: 0.01 | T38: 0.07 | X38: 2.94 | AA38: 0.05 | AB38: 29.85 | AC38: 82.84 | AD38: 600.7 | AE38: 0.76
A39: 废弃资源综合利用业 | B39: 316.37 | C39: 77.46 | E39: 234.19 | F39: 68.85 | G39: 1.14 | H39: 10.96 | I39: 1.7 | K39: 0.6 | L39: 8.02 | N39: 0.24 | O39: 0.01 | P39: 4.09 | Q39: 0.65 | S39: 0.02 | W39: 2.73 | X39: 0.26 | Z39: 0.03 | AA39: 2.91 | AB39: 95.12 | AC39: 39.84 | AD39: 67.1 | AE39: 6
A40: 金属制品、机械和设备修理业 | B40: 1.18 | C40: 1.18 | G40: 0.06 | J40: 0.01 | L40: 6.09 | N40: 0.42 | O40: 0.79 | P40: 4.59 | Q40: 0.17 | S40: 0.1 | X40: 0.02 | AA40: 0.23 | AB40: 2.91 | AC40: 28.9 | AD40: 14.84
...

Sheet Feedstock Split-2020
B1: 煤合计_x000D_ (万吨)_x000D_ Coal Total_x000D_ (104 tons) | C1: 原煤_x000D_ (万吨)_x000D_ Raw Coal_x000D_ (104 tons) | D1: 洗精煤_x000D_ (万吨)_x000D_ Cleaned_x000D_ Coal_x000D_ (104 tons) | E1: 其他洗煤_x000D_ (万吨)_x000D_ Other_x000D_ Washed_x000D_ Coal_x000D_ (104 tons) | F1: 煤制品_x000D_ (万吨)_x000D_ Briquettes_x000D_ (104 tons) | G1: 煤矸石_x000D_ (万吨)_x000D_ Gangue_x000D_ (104 tons) | H1: 焦炭_x000D_ (万吨)_x000D_ Coke_x000D_ (104 tons) | I1: 焦炉煤气_x000D_ (亿立方米)_x000D_ Coke Oven_x000D_ Gas_x000D_ (108 cu.m) | J1: 高炉煤气_x000D_ (亿立方米)_x000D_ Blast Furnace_x000D_ Gas_x000D_ (108 cu.m) | K1: 转炉煤气_x000D_ (亿立方米)_x000D_ Converter_x000D_ Gas_x000D_ (108 cu.m) | L1: 其他煤气_x000D_ (亿立方米)_x000D_ Other Gas_x000D_ (108 cu.m) | M1: 其他焦化产品_x000D_ (万吨)_x000D_ Other_x000D_ Coking_x000D_ Products_x000D_ (104 tons) | N1: 油品合计_x000D_ (万吨)_x000D_ Petroleum_x000D_ Products_x000D_ Total_x000D_ (104 tons) | O1: 原油_x000D_ (万吨)_x000D_ Crude Oil_x000D_ (104 tons) | P1: 汽油_x000D_ (万吨)_x000D_ Gasoline_x000D_ (104 tons) | Q1: 煤油_x000D_ (万吨)_x000D_ Kerosene_x000D_ (104 tons) | R1: 柴油_x000D_ (万吨)_x000D_ Diesel Oil_x000D_ (104 tons) | S1: 燃料油_x000D_ (万吨)_x000D_ Fuel Oil_x000D_ (104 tons) | T1: 石脑油_x000D_ (万吨)_x000D_ Naphtha_x000D_ (104 tons) | U1: 润滑油_x000D_ (万吨)_x000D_ Lubricants_x000D_ (104 tons) | V1: 石蜡_x000D_ (万吨)_x000D_ Paraffin_x000D_ Waxes_x000D_ (104 tons) | W1: 溶剂油_x000D_ (万吨)_x000D_ White Spirit_x000D_ (104 tons) | X1: 石油沥青_x000D_ (万吨)_x000D_ Bitumen_x000D_ Asphalt_x000D_ (104 tons) | Y1: 石油焦_x000D_ (万吨)_x000D_ Petroleum_x000D_ Coke_x000D_ (104 tons) | Z1: 液化石油气_x000D_ (万吨)_x000D_ Liquefied_x000D_ Petroleum Gas_x000D_ (104 tons) | AA1: 炼厂干气_x000D_ (万吨)_x000D_ Refinery_x000D_ Gas_x000D_ (104 tons) | AB1: 其他石油制品_x000D_ (万吨)_x000D_ Other_x000D_ Petroleum_x000D_ Products_x000D_ (104 tons) | AC1: 天然气_x000D_ (亿立方米)_x000D_ Natural Gas_x000D_ (108 cu.m) | AD1: 液化天然气_x000D_ (万吨)_x000D_ Liquefied_x000D_ Natural Gas_x000D_ (104 tons) | AE1: 热力_x000D_ (万百万千焦)_x000D_ Heat_x000D_ (1010 kJ) | AF1: 电力_x000D_ (亿千瓦小时)_x000D_ Electricity_x000D_ (108 kW·h) | AG1: 其他能源_x000D_ (万吨标准煤)_x000D_ Other_x000D_ Energy_x000D_ (104 tce)
A2: 工业 | B2: =SUM(B3:B43) -> 0 | C2: =SUM(C3:C43) -> 1 | D2: =SUM(D3:D43) -> 1 | E2: =SUM(E3:E43) -> 1 | F2: =SUM(F3:F43) -> 1 | G2: =SUM(G3:G43) -> 1 | H2: =SUM(H3:H43) -> 1 | I2: =SUM(I3:I43) -> 1 | ... AG2: =SUM(AG3:AG43) -> 1
A3: 煤炭开采和洗选业 | C3: 0 | D3: 0 | E3: 0 | F3: 0 | G3: 0 | H3: 0 | I3: 0 | J3: 0 | K3: 0 | L3: 0 | M3: 0 | O3: 0 | P3: 0 | Q3: 0 | R3: 0 | S3: 0 | T3: 0 | U3: 0 | V3: 0 | W3: 0 | X3: 0 | Y3: 0 | Z3: 0 | AA3: 0 | AB3: 0 | AC3: 0 | AD3: 0 | AE3: 0 | AF3: 0 | AG3: 0
A4: 石油和天然气开采业 | C4: 0 | D4: 0 | E4: 0 | F4: 0 | G4: 0 | H4: 0 | I4: 0 | J4: 0 | K4: 0 | L4: 0 | M4: 0 | O4: 0 | P4: 0 | Q4: 0 | R4: 0 | S4: 0 | T4: 0 | U4: 0 | V4: 0 | W4: 0 | X4: 0 | Y4: 0 | Z4: 0 | AA4: 0 | AB4: 0 | AC4: 0 | AD4: 0 | AE4: 0 | AF4: 0 | AG4: 0
A5: 黑色金属矿采选业 | C5: 0 | D5: 0 | E5: 0 | F5: 0 | G5: 0 | H5: 0 | I5: 0 | J5: 0 | K5: 0 | L5: 0 | M5: 0 | O5: 0 | P5: 0 | Q5: 0 | R5: 0 | S5: 0 | T5: 0 | U5: 0 | V5: 0 | W5: 0 | X5: 0 | Y5: 0 | Z5: 0 | AA5: 0 | AB5: 0 | AC5: 0 | AD5: 0 | AE5: 0 | AF5: 0 | AG5: 0
A6: 有色金属矿采选业 | C6: 0 | D6: 0 | E6: 0 | F6: 0 | G6: 0 | H6: 0 | I6: 0 | J6: 0 | K6: 0 | L6: 0 | M6: 0 | O6: 0 | P6: 0 | Q6: 0 | R6: 0 | S6: 0 | T6: 0 | U6: 0 | V6: 0 | W6: 0 | X6: 0 | Y6: 0 | Z6: 0 | AA6: 0 | AB6: 0 | AC6: 0 | AD6: 0 | AE6: 0 | AF6: 0 | AG6: 0
A7: 非金属矿采选业 | C7: 0 | D7: 0 | E7: 0 | F7: 0 | G7: 0 | H7: 0 | I7: 0 | J7: 0 | K7: 0 | L7: 0 | M7: 0 | O7: 0 | P7: 0 | Q7: 0 | R7: 0 | S7: 0 | T7: 0 | U7: 0 | V7: 0 | W7: 0 | X7: 0 | Y7: 0 | Z7: 0 | AA7: 0 | AB7: 0 | AC7: 0 | AD7: 0 | AE7: 0 | AF7: 0 | AG7: 0
A8: 开采专业及辅助性活动 | C8: 0 | D8: 0 | E8: 0 | F8: 0 | G8: 0 | H8: 0 | I8: 0 | J8: 0 | K8: 0 | L8: 0 | M8: 0 | O8: 0 | P8: 0 | Q8: 0 | R8: 0 | S8: 0 | T8: 0 | U8: 0 | V8: 0 | W8: 0 | X8: 0 | Y8: 0 | Z8: 0 | AA8: 0 | AB8: 0 | AC8: 0 | AD8: 0 | AE8: 0 | AF8: 0 | AG8: 0
A9: 其他采矿业 | C9: 0 | D9: 0 | E9: 0 | F9: 0 | G9: 0 | H9: 0 | I9: 0 | J9: 0 | K9: 0 | L9: 0 | M9: 0 | O9: 0 | P9: 0 | Q9: 0 | R9: 0 | S9: 0 | T9: 0 | U9: 0 | V9: 0 | W9: 0 | X9: 0 | Y9: 0 | Z9: 0 | AA9: 0 | AB9: 0 | AC9: 0 | AD9: 0 | AE9: 0 | AF9: 0 | AG9: 0
A10: 农副食品加工业 | C10: 0 | D10: 0 | E10: 0 | F10: 0 | G10: 0 | H10: 0 | I10: 0 | J10: 0 | K10: 0 | L10: 0 | M10: 0 | O10: 0 | P10: 0 | Q10: 0 | R10: 0 | S10: 0 | T10: 0 | U10: 0 | V10: 0 | W10: 0 | X10: 0 | Y10: 0 | Z10: 0 | AA10: 0 | AB10: 0 | AC10: 0 | AD10: 0 | AE10: 0 | AF10: 0 | AG10: =AE65 -> 0.33707419
A11: 食品制造业 | C11: 0 | D11: 0 | E11: 0 | F11: 0 | G11: 0 | H11: 0 | I11: 0 | J11: 0 | K11: 0 | L11: 0 | M11: 0 | O11: 0 | P11: 0 | Q11: 0 | R11: 0 | S11: 0 | T11: 0 | U11: 0 | V11: =V55 -> 0 | W11: 0 | X11: 0 | Y11: 0 | Z11: 0 | AA11: 0 | AB11: 0 | AC11: 0 | AD11: 0 | AE11: 0 | AF11: 0 | AG11: 0
A12: 酒、饮料和精制茶制造业 | C12: 0 | D12: 0 | E12: 0 | F12: 0 | G12: 0 | H12: 0 | I12: 0 | J12: 0 | K12: 0 | L12: 0 | M12: 0 | O12: 0 | P12: 0 | Q12: 0 | R12: 0 | S12: 0 | T12: 0 | U12: 0 | V12: 0 | W12: 0 | X12: 0 | Y12: 0 | Z12: 0 | AA12: 0 | AB12: 0 | AC12: 0 | AD12: 0 | AE12: 0 | AF12: 0 | AG12: 0
A13: 烟草制品业 | C13: 0 | D13: 0 | E13: 0 | F13: 0 | G13: 0 | H13: 0 | I13: 0 | J13: 0 | K13: 0 | L13: 0 | M13: 0 | O13: 0 | P13: 0 | Q13: 0 | R13: 0 | S13: 0 | T13: 0 | U13: 0 | V13: 0 | W13: 0 | X13: 0 | Y13: 0 | Z13: 0 | AA13: 0 | AB13: 0 | AC13: 0 | AD13: 0 | AE13: 0 | AF13: 0 | AG13: 0
A14: 纺织业 | C14: 0 | D14: 0 | E14: 0 | F14: 0 | G14: 0 | H14: 0 | I14: 0 | J14: 0 | K14: 0 | L14: 0 | M14: 0 | O14: 0 | P14: 0 | Q14: 0 | R14: 0 | S14: 0 | T14: 0 | U14: 0 | V14: 0 | W14: 0 | X14: 0 | Y14: 0 | Z14: 0 | AA14: 0 | AB14: 0 | AC14: 0 | AD14: 0 | AE14: 0 | AF14: 0 | AG14: 0
A15: 纺织服装、服饰业 | C15: 0 | D15: 0 | E15: 0 | F15: 0 | G15: 0 | H15: 0 | I15: 0 | J15: 0 | K15: 0 | L15: 0 | M15: 0 | O15: 0 | P15: 0 | Q15: 0 | R15: 0 | S15: 0 | T15: 0 | U15: 0 | V15: 0 | W15: 0 | X15: 0 | Y15: 0 | Z15: 0 | AA15: 0 | AB15: 0 | AC15: 0 | AD15: 0 | AE15: 0 | AF15: 0 | AG15: 0
A16: 皮革、毛皮、羽毛及其制品和制鞋业 | C16: 0 | D16: 0 | E16: 0 | F16: 0 | G16: 0 | H16: 0 | I16: 0 | J16: 0 | K16: 0 | L16: 0 | M16: 0 | O16: 0 | P16: 0 | Q16: 0 | R16: 0 | S16: 0 | T16: 0 | U16: 0 | V16: 0 | W16: 0 | X16: 0 | Y16: 0 | Z16: 0 | AA16: 0 | AB16: 0 | AC16: 0 | AD16: 0 | AE16: 0 | AF16: 0 | AG16: 0
A17: 木材加工和木、竹、藤、棕、草制品业 | C17: 0 | D17: 0 | E17: 0 | F17: 0 | G17: 0 | H17: 0 | I17: 0 | J17: 0 | K17: 0 | L17: 0 | M17: 0 | O17: 0 | P17: 0 | Q17: 0 | R17: 0 | S17: 0 | T17: 0 | U17: 0 | V17: =V56 -> 0.0086555698 | W17: 0 | X17: 0 | Y17: 0 | Z17: 0 | AA17: 0 | AB17: 0 | AC17: 0 | AD17: 0 | AE17: 0 | AF17: 0 | AG17: 0
A18: 家具制造业 | C18: 0 | D18: 0 | E18: 0 | F18: 0 | G18: 0 | H18: 0 | I18: 0 | J18: 0 | K18: 0 | L18: 0 | M18: 0 | O18: 0 | P18: 0 | Q18: 0 | R18: 0 | S18: 0 | T18: 0 | U18: 0 | V18: 0 | W18: 0 | X18: 0 | Y18: 0 | Z18: 0 | AA18: 0 | AB18: 0 | AC18: 0 | AD18: 0 | AE18: 0 | AF18: 0 | AG18: 0
A19: 造纸和纸制品业 | C19: 0 | D19: 0 | E19: 0 | F19: 0 | G19: 0 | H19: 0 | I19: 0 | J19: 0 | K19: 0 | L19: 0 | M19: 0 | O19: 0 | P19: 0 | Q19: 0 | R19: 0 | S19: 0 | T19: 0 | U19: 0 | V19: 0 | W19: 0 | X19: 0 | Y19: 0 | Z19: 0 | AA19: 0 | AB19: 0 | AC19: 0 | AD19: 0 | AE19: 0 | AF19: 0 | AG19: 0
A20: 印刷和记录媒介复制业 | C20: 0 | D20: 0 | E20: 0 | F20: 0 | G20: 0 | H20: 0 | I20: 0 | J20: 0 | K20: 0 | L20: 0 | M20: 0 | O20: 0 | P20: 0 | Q20: 0 | R20: 0 | S20: 0 | T20: 0 | U20: 0 | V20: 0 | W20: 0 | X20: 0 | Y20: 0 | Z20: 0 | AA20: 0 | AB20: 0 | AC20: 0 | AD20: 0 | AE20: 0 | AF20: 0 | AG20: 0
A21: 文教、工美、体育和娱乐用品制造业 | C21: 0 | D21: 0 | E21: 0 | F21: 0 | G21: 0 | H21: 0 | I21: 0 | J21: 0 | K21: 0 | L21: 0 | M21: 0 | O21: 0 | P21: 0 | Q21: 0 | R21: 0 | S21: 0 | T21: 0 | U21: 0 | V21: =V57 -> 0.0026120359 | W21: 0 | X21: 0 | Y21: 0 | Z21: 0 | AA21: 0 | AB21: 0 | AC21: 0 | AD21: 0 | AE21: 0 | AF21: 0 | AG21: 0
A22: 石油、煤炭及其他燃料加工业 | C22: =C59 -> 0.052218803 | D22: =B65 -> 1 | E22: =C69 -> 0.063384093 | F22: =C69 -> 0.063384093 | G22: =C69 -> 0.063384093 | H22: 0 | I22: 0 | J22: 0 | K22: 0 | L22: 0 | M22: =C88 -> 0.092773746 | O22: 0 | P22: =L60 -> 0.074842767 | Q22: 0 | R22: =L71 -> 0 | S22: =L75 -> 0.79664026 | T22: =L78 -> 0.21459564 | U22: =L83 -> 0.93785706 | V22: 0 | W22: =V63 -> 0.025634766 | X22: =V70 -> 0.024041982 | Y22: 0 | Z22: =V79 -> 0.64392861 | AA22: =U84 -> 1 | AB22: =V88 -> 0.77630494 | AC22: 0 | AD22: 0 | AE22: 0 | AF22: 0 | AG22: =AE62 -> 0.094002598
A23: 化学原料和化学制品制造业 | C23: =C60 -> 0.54386111 | D23: 0 | E23: 0 | F23: 0 | G23: 0 | H23: =C77 -> 0.091449688 | I23: =B83 -> 1 | J23: =B83 -> 1 | K23: =B83 -> 1 | L23: =B83 -> 1 | M23: =C89 -> 0.55544132 | O23: =K54 -> 1 | P23: =L59 -> 0.55283019 | Q23: =L64 -> 0.41237113 | R23: =K70 -> 1 | S23: =L74 -> 0.20335974 | T23: =L79 -> 0.78540436 | U23: 0 | V23: =V58 -> 0.98857875 | W23: =V64 -> 0.96801758 | X23: =V68 -> 0.11917257 | Y23: =W68 -> 0 | Z23: =V80 -> 0.35607139 | AA23: 0 | AB23: =V89 -> 0.22369506 | AC23: =AD53 -> 1 | AD23: =AD57 -> 1 | AE23: 0 | AF23: 0 | AG23: =AE63 -> 0.41911446
A24: 医药制造业 | C24: 0 | D24: 0 | E24: 0 | F24: 0 | G24: 0 | H24: 0 | I24: 0 | J24: 0 | K24: 0 | L24: 0 | M24: 0 | O24: 0 | P24: 0 | Q24: 0 | R24: 0 | S24: 0 | T24: 0 | U24: 0 | V24: =V59 -> 0.00015364917 | W24: =W59 -> 0 | X24: 0 | Y24: 0 | Z24: 0 | AA24: 0 | AB24: 0 | AC24: 0 | AD24: 0 | AE24: 0 | AF24: 0 | AG24: 0
A25: 化学纤维制造业 | C25: 0 | D25: 0 | E25: 0 | F25: 0 | G25: 0 | H25: 0 | I25: 0 | J25: 0 | K25: 0 | L25: 0 | M25: 0 | O25: 0 | P25: 0 | Q25: 0 | R25: 0 | S25: 0 | T25: 0 | U25: 0 | V25: 0 | W25: 0 | X25: 0 | Y25: 0 | Z25: 0 | AA25: 0 | AB25: 0 | AC25: 0 | AD25: 0 | AE25: 0 | AF25: 0 | AG25: 0
A26: 橡胶和塑料制品业 | C26: 0 | D26: 0 | E26: 0 | F26: 0 | G26: 0 | H26: 0 | I26: 0 | J26: 0 | K26: 0 | L26: 0 | M26: 0 | O26: 0 | P26: =L58 -> 0.37232704 | Q26: =L63 -> 0.10927835 | R26: 0 | S26: 0 | T26: 0 | U26: 0 | V26: 0 | W26: 0 | X26: 0 | Y26: 0 | Z26: 0 | AA26: 0 | AB26: 0 | AC26: 0 | AD26: 0 | AE26: 0 | AF26: 0 | AG26: 0
A27: 非金属矿物制品业 | C27: 0 | D27: 0 | E27: =C70 -> 0.85931802 | F27: =C70 -> 0.85931802 | G27: =C70 -> 0.85931802 | H27: 0 | I27: 0 | J27: 0 | K27: 0 | L27: 0 | M27: =C90 -> 0.016856849 | O27: 0 | P27: 0 | Q27: 0 | R27: 0 | S27: 0 | T27: 0 | U27: 0 | V27: 0 | W27: =V65 -> 0.0063476563 | X27: =V69 -> 0.85678545 | Y27: =V74 -> 0.90863419 | Z27: 0 | AA27: 0 | AB27: 0 | AC27: 0 | AD27: 0 | AE27: 0 | AF27: 0 | AG27: =AE64 -> 0.14980875
A28: 黑色金属冶炼和压延加工业 | C28: =C61 -> 0.40392009 | D28: 0 | E28: =C71 -> 0.077297888 | F28: =C71 -> 0.077297888 | G28: =C71 -> 0.077297888 | H28: =C78 -> 0.90855031 | I28: 0 | J28: 0 | K28: 0 | L28: 0 | M28: =C91 -> 0.33492808 | O28: 0 | P28: 0 | Q28: 0 | R28: 0 | S28: 0 | T28: 0 | U28: 0 | V28: 0 | W28: 0 | X28: 0 | Y28: 0 | Z28: 0 | AA28: 0 | AB28: 0 | AC28: 0 | AD28: 0 | AE28: 0 | AF28: 0 | AG28: 0
A29: 有色金属冶炼和压延加工业 | C29: 0 | D29: 0 | E29: 0 | F29: 0 | G29: 0 | H29: 0 | I29: 0 | J29: 0 | K29: 0 | L29: 0 | M29: 0 | O29: 0 | P29: 0 | Q29: 0 | R29: 0 | S29: 0 | T29: 0 | U29: 0 | V29: 0 | W29: 0 | X29: 0 | Y29: =V73 -> 0.09136581 | Z29: 0 | AA29: 0 | AB29: 0 | AC29: 0 | AD29: 0 | AE29: 0 | AF29: 0 | AG29: 0
A30: 金属制品业 | C30: 0 | D30: 0 | E30: 0 | F30: 0 | G30: 0 | H30: 0 | I30: 0 | J30: 0 | K30: 0 | L30: 0 | M30: 0 | O30: 0 | P30: 0 | Q30: 0 | R30: 0 | S30: 0 | T30: 0 | U30: 0 | V30: 0 | W30: 0 | X30: 0 | Y30: 0 | Z30: 0 | AA30: 0 | AB30: 0 | AC30: 0 | AD30: 0 | AE30: 0 | AF30: 0 | AG30: 0
A31: 通用设备制造业 | C31: 0 | D31: 0 | E31: 0 | F31: 0 | G31: 0 | H31: 0 | I31: 0 | J31: 0 | K31: 0 | L31: 0 | M31: 0 | O31: 0 | P31: 0 | Q31: =L65 -> 0.29690722 | R31: 0 | S31: 0 | T31: 0 | U31: =L84 -> 0.013990906 | V31: 0 | W31: 0 | X31: 0 | Y31: 0 | Z31: 0 | AA31: 0 | AB31: 0 | AC31: 0 | AD31: 0 | AE31: 0 | AF31: 0 | AG31: 0
