Workbook
Name billion_kw_to_MW: #REF!
Name billion_kw_to_MW: #REF!
Name billion_kw_to_MW: [1]About!$B$29
Name gigwatt_to_megawatt: #REF!
Name gigwatt_to_megawatt: #REF!
Name gigwatt_to_megawatt: [1]About!$B$30
Name IQ_CH: 110000
Name IQ_CQ: 5000
Name IQ_CY: 10000
Name IQ_DAILY: 500000
Name IQ_FH: 100000
Name IQ_FQ: 500
Name IQ_FY: 1000
Name IQ_LTM: 2000
Name IQ_MONTH: 15000
Name IQ_NTM: 6000
Name IQ_WEEK: 50000
Name IQ_YTD: 3000
Name Percent_rural: #REF!
Name Percent_rural: #REF!
Name Percent_rural: [1]About!$A$27
Name Percent_Urban: #REF!
Name Percent_Urban: #REF!
Name Percent_Urban: [1]About!$A$26
Name billion_kw_to_MW: #REF!
Name gigwatt_to_megawatt: #REF!
Name Percent_rural: #REF!
Name Percent_Urban: #REF!
Name cpi_2016_to_2012: [3]About!$A$109
Name cpi_2019_to_2012: [3]About!$A$115
Name cpi_2020_to_2012: [3]About!$A$117
Name lifetime_hydro: [4]Lifetime!$C$5
Name lifetime_natural_gas_nonpeaker: [4]Lifetime!$C$3
Name lifetime_nuclear: [4]Lifetime!$C$4

Sheet About
A1: MPPC Minimum Power Plant Capacity
A3: Source: | B3: Thermal, Hydro, Nuclear, Onshore Wind, Solar, Biomass, MSW
B4: China Electricity Council
B5: 中国电力工业统计资料汇编 （Compilation of China Power Sector Statistics)
B6: 2012-2021
B7: Chapter 6 (Power Generation Construction in Detailed List)
B9: Solar Thermal
B10: China Solar Thermal Allaince (CNSTE)
B11: 中国太阳能热发电行业蓝皮书
B12: Blue Book of Concentrating Solar Power Industry (Chinese)
B13: 2021-2022
B14: http://www.cnste.org/uploads/soft/230131/1_0841264311.pdf
B15: http://mediacdn.mengliaoba.cn/download/2021%E4%B8%AD%E5%9B%BD%E5%A4%AA%E9%98%B3%E8%83%BD%E7%83%AD%E5%8F%91%E7%94%B5%E8%A1%8C%E4%B8%9A%E8%93%9D%E7%9A%AE%E4%B9%A6.pdf
B17: Offshore Wind
... B19: Tracker for Global Wind Proejcts
B20: 2023
B21: https://globalenergymonitor.org/projects/global-wind-power-tracker/
A23: Notes
A24: We compiled a list of projects that become operational each year from 2012-2021, and used 1 or 5 percentile installed capacity
A25: from the project list as the value for MPPC (after rounding to the closest integer). The project list has been desensitized, with only
A26: capacity, generation type and year of operation included.
A27: For solar thermal and geothermal, since the number of (planned) project is very small. The minimal value were used.
A28: For geothermal, the existing projects are very old and were built in 1970-80s, these values were disregarded, and we focuses on the planned target for addition.

Sheet Project List
A1: Order | B1: Project.ID | C1: Year | D1: Gen.Type1 | E1: Unit | F1: Capacity
A2: 1 | B2: 112013221 | C2: 2013 | D2: 火电-燃气-常规燃气 | E2: 1 | F2: 83.8
A3: 2 | B3: 112014221 | C3: 2014 | D3: 火电-燃气-常规燃气 | E3: 3 | F3: 138
A4: 3 | B4: 112014221 | C4: 2014 | D4: 火电-燃气-常规燃气 | E4: 1 | F4: 84.5
A5: 5 | B5: 112014221 | C5: 2014 | D5: 火电-燃气-常规燃气 | E5: 1 | F5: 25.5
A6: 4 | B6: 112014221 | C6: 2014 | D6: 火电-燃气-常规燃气 | E6: 2 | F6: 130.7
A7: 6 | B7: 112015221 | C7: 2015 | D7: 火电-燃气-常规燃气 | E7: 1 | F7: 95
A8: 9 | B8: 112015270 | C8: 2015 | D8: 太阳能 | F8: 0.15
A9: 7 | B9: 112015270 | C9: 2015 | D9: 太阳能 | F9: 2
A10: 8 | B10: 112015270 | C10: 2015 | D10: 太阳能 | F10: 0.37
A11: 10 | B11: 112015270 | C11: 2015 | D11: 太阳能 | F11: 0.05
A12: 11 | B12: 112015270 | C12: 2015 | D12: 太阳能 | F12: 2
A13: 12 | B13: 112016221 | C13: 2016 | D13: 火电-燃气-常规燃气 | F13: 1.33
A14: 13 | B14: 112016241 | C14: 2016 | D14: 火电-其他火电-余温、余压、余气发电 | F14: 0.75
A15: 14 | B15: 112016241 | C15: 2016 | D15: 火电-其他火电-余温、余压、余气发电 | F15: 4
A16: 16 | B16: 112016260 | C16: 2016 | D16: 风电 | E16: 24 | F16: 3.6
A17: 15 | B17: 112016260 | C17: 2016 | D17: 风电 | F17: 3.6
A18: 18 | B18: 112016270 | C18: 2016 | D18: 太阳能 | F18: 0.3
A19: 17 | B19: 112016270 | C19: 2016 | D19: 太阳能 | F19: 3.1
A20: 20 | B20: 112016270 | C20: 2016 | D20: 太阳能 | F20: 0
A21: 19 | B21: 112016270 | C21: 2016 | D21: 太阳能 | F21: 3.1
A22: 22 | B22: 112017221 | C22: 2017 | D22: 火电-燃气-常规燃气 | E22: 3 | F22: 99.8
A23: 23 | B23: 112017242 | C23: 2017 | D23: 火电-其他火电-垃圾焚烧发电 | F23: 4
A24: 24 | B24: 112017242 | C24: 2017 | D24: 火电-其他火电-垃圾焚烧发电 | F24: 2.5
A25: 27 | B25: 112017270 | C25: 2017 | D25: 太阳能 | F25: 0.5
A26: 26 | B26: 112017270 | C26: 2017 | D26: 太阳能 | F26: 0.05
A27: 30 | B27: 112018221 | C27: 2018 | D27: 火电-燃气-常规燃气 | E27: 1 | F27: 7.5
A28: 29 | B28: 112018221 | C28: 2018 | D28: 火电-燃气-常规燃气 | E28: 1 | F28: 26.6
A29: 33 | B29: 112018242 | C29: 2018 | D29: 火电-其他火电-垃圾焚烧发电 | F29: 0.2
A30: 32 | B30: 112018242 | C30: 2018 | D30: 火电-其他火电-垃圾焚烧发电 | F30: 5
A31: 31 | B31: 112018242 | C31: 2018 | D31: 火电-其他火电-垃圾焚烧发电 | F31: 1.2
A32: 34 | B32: 112018242 | C32: 2018 | D32: 火电-其他火电-垃圾焚烧发电 | F32: 0.6
A33: 37 | B33: 112018270 | C33: 2018 | D33: 太阳能 | F33: 1.8
A34: 35 | B34: 112018270 | C34: 2018 | D34: 太阳能 | F34: 0.6
A35: 38 | B35: 112019221 | C35: 2019 | D35: 火电-燃气-常规燃气 | E35: 1 | F35: 7.5
A36: 39 | B36: 112019221 | C36: 2019 | D36: 火电-燃气-常规燃气 | F36: 8
A37: 40 | B37: 112019242 | C37: 2019 | D37: 火电-其他火电-垃圾焚烧发电 | F37: 9
A38: 41 | B38: 112019242 | C38: 2019 | D38: 火电-其他火电-垃圾焚烧发电 | F38: 1.5
A39: 43 | B39: 112020221 | C39: 2020 | D39: 火电-燃气-常规燃气 | E39: 1 | F39: 6.7
A40: 44 | B40: 112020242 | C40: 2020 | D40: 火电-其他火电-垃圾焚烧发电 | F40: 2
...

Sheet Solar Thermal
A1: 项目名称 | B1: 项目状态 | C1: 建成时间 | D1: 省份 | E1: 地区 | F1: 装机容量（MW） | G1: 年设计发电量（亿千瓦时） | H1: 塔/线/槽式 | I1: 建成时间（预计） | J1: 建设状态 | K1: 开工时间
A2: 中广核太阳能德令哈有限公司导热油槽式5万千瓦光热发电项目 | B2: 投运 | C2: 2021 | D2: 青海省 | E2: 青海省德令哈市西出口光伏（热）产业园区 | F2: 50 | G2: 1.975 | H2: 槽式 | I2: 2018年6月30日并网 | J2: 建成投运
A3: 首航高科能源技术股份有限公司（原北京首航艾启威节能技术股份有限公司）敦煌熔盐塔式10万千瓦光热发电示范项目 | B3: 投运 | C3: 2019 | D3: 甘肃省 | E3: 甘肃省敦煌市七 里镇西光电产业园 | F3: 100 | G3: 3.9 | H3: 塔式 | I3: 2019 年 6 月 | J3: 建成投运
A4: 青海中控太阳能发电有限公司德令哈熔盐塔式5万千万光热发电项目 | B4: 投运 | C4: 2018 | D4: 青海省 | E4: 青海省德令哈 市西出口光伏（热）产业园区 | F4: 50 | G4: 1.46 | H4: 塔式 | I4: 2018 年 12 月 30 日并网发电，2019 年 4 月 17 日实现了满 负荷运行 | J4: 建成投运
A5: 中国电建西北勘测设计研究院有限公司共和熔盐塔式5万千瓦光热发电项目（中电建青海共和 50MW 塔式项目） | B5: 投运 | C5: 2019 | D5: 青海省 | E5: 青海省海南州共和县生态太阳能发电园区 | F5: 50 | G5: 1.569 | H5: 塔式 | I5: 2020 年 11 月 6 日实现满负荷运行 2021 年 4 月通过国家光热 发电项目示范性验收 | J5: 建成投运
A6: 中国电力工程顾问集团西北电力设计院有限公司哈密熔盐塔式5万千瓦光热发电项目（中能建哈密 50MW 塔式项目） | B6: 投运 | C6: 2019 | D6: 新疆维吾尔自治区 | E6: 新疆哈密市伊吾县 | F6: 50 | G6: 1.983 | H6: 塔式 | I6: 2019 年 12 月 29 日实现首次并网。2021 年 6 月 18 日凌 晨 01 时 26 分并网发电，9 月 6 日实现全容量发电。 | J6: 建成投运 | K6: 2017 年 10 月 19 日
A7: 兰州大成科技股份有限公司敦煌熔盐线性菲涅尔式5万千瓦光热发电示范项目（兰州大成敦煌 50MW 线菲项目） | B7: 投运 | C7: 2020 | D7: 甘肃省 | E7: 甘肃省敦煌市七里镇光电产业园区 | F7: 50 | G7: 2.14 | H7: 线性 菲涅耳式 | I7: 2019 年 12 月 31 日实现并网发电。2020年 6 月 18 日太阳能集热场系统整体并网发电投运 [17 | J7: 建成投运
A8: 内蒙古中核龙腾新能源有限公司乌拉特中旗导热油槽式10万千瓦光热发电项目（中船新能乌拉特中旗 100MW 槽式项目） | B8: 投运 | C8: 2022 | D8: 内蒙古自治区 | E8: 内蒙古巴彦淖尔市乌拉特中旗 | F8: 100 | G8: 3.92 | H8: 槽式 | I8: 2020 年 1 月 8 日首次 实现并网发电，2020 年 12 月 16 日实现满负荷发电，2021 年 10 月 20 日通过国家示范性验收。 | J8: 建成投运 | K8: 2018 年 6 月
A9: 鲁能格尔木多能互补 50MW 塔式项目 | B9: 投运 | C9: 2020 | D9: 青海省 | E9: 青海省海西州多能互补基地 | F9: 50 | G9: 1.6 | H9: 塔式 | I9: 2019年 9 月 19 日成功一次并网， 2020 年 8 月 27 日完成了 120 小时可靠性运行， 2021 年 5 月 14 日，光热电站完成涉网联合试验。 | J9: 建成投运
A10: 玉门鑫能光热第一电力有限公司熔盐塔式5万千瓦光热发电项目 | B10: 投运 | C10: 2022 | D10: 甘肃省 | E10: 玉门市 | F10: 50 | G10: 2.16 | H10: 塔式 | I10: 44560 | J10: 建成投运 | K10: 2017年8月31 日，常规动力岛正式开工建设
A11: 深圳市金钒能源科技有限公司阿克塞5万千瓦熔盐槽式光热发电项目 | D11: 甘肃省 | F11: 50 | G11: 2.56 | H11: 槽式 | J11: 在建 | K11: 主体工程2017年6月份开工建设
A12: 国电投黄河上游水电开发有限责任公司德令哈水工质塔式13.5万千瓦光热发电项目（现由中控太阳能接续开发） | D12: 青海省 | F12: 135 | H12: 塔式 | J12: 在建 | K12: 2021年3月25日项目正式开建。
A13: 中国三峡新能源有限公司金塔熔盐塔式10万千瓦光热发电项目（现由中控太阳能接续开发） | F13: 100 | G13: 13.7 | H13: 塔式 | I13: 计划于2023年底实现全容量并网发电 | K13: 44645
A14: 达华工程管理（集团）有限公司尚义水工质塔式5万千瓦光热发电项目 | F14: 50 | G14: 1.21 | H14: 塔式
A15: 北京国华电力有限责任公司玉门熔盐塔式10万千瓦光热发电项目（现由首航高科接续开发） | F15: 100 | H15: 塔式 | J15: 退出首批
A16: 常州龙腾太阳能热电设备有限公司玉门东镇导热油槽式5万千瓦光热发电项目 | D16: 甘肃省 | F16: 50 | H16: 槽式 | K16: 2018年6月19日奠基
A17: 中海阳能源集团股份有限公司玉门东镇导热油槽式5万千瓦光热发电项目 | F17: 50 | H17: 槽式 | K17: 2017年8月12日，前期场平工程正式启动，项目正式进入全面建设阶段。
A18: 中节能甘肃武威太阳能发电有限公司古浪导热油槽式10万千瓦光热发电项目 | F18: 100 | H18: 槽式
A19: 中阳张家口察北能源有限公司熔盐槽式6.4万千瓦光热发电项目 | F19: 64 | G19: 3.5 | H19: 槽式 | K19: 2017年4月17日（2014年7月举行开工仪式。）
A20: 北方联合电力有限责任公司乌拉特旗导热油菲涅尔式5万千瓦光热发电项目 | F20: 50 | H20: 线性 菲涅耳式 | J20: 退出首批
A21: 中信张北新能源开发有限公司水工质类菲涅尔式5万千瓦光热发电项目 | F21: 50 | H21: 线性 菲涅耳式 | J21: 退出首批
A22: 张北华强兆阳能源有限公司张家口水工质类菲涅尔式5万千瓦太阳能热发电项目 | F22: 50 | H22: 线性 菲涅耳式 | K22: 42842

Sheet Geothermal
A1: 表 3 我国地热能开发目标 | I1: (三)发展目标 在“十三五”时期，新增地热能供暖(制冷)面积 11亿平方米， 其中： 新增浅层地热能供暖(制冷) 面积 7 亿平方米； 新增水热型地热供暖面积 4 亿平方米。新增地热发电装机容量 500MW。到 2020 年， 地热供暖(制冷) 面积累计达到 16 亿平方米，地热发电装机容量约 530MW。2020 年地热能年利用量 7000 万吨标准煤，地热能供暖年利用量4000 万吨标准煤。京津冀地区地热能年利用量达到约 2000万吨标准煤。
B3: “十三五”新增 | E3: 2020 年累计
B4: 浅层地热能 供暖/制冷 面积 (104m2 ) | C4: 水热型地热 能供暖面积 (104m2) | D4: 发电装 机容量 (MW) | E4: 浅层地热能 供暖/制冷 面积 (104m2 ) | F4: 水热型地热 能供暖面积 (104m2) | G4: 发电装 机容量 (MW)
A5: 北京市 | B5: 4000 | C5: 2500 | E5: 8000 | F5: 3000
A6: 天津市 | B6: 4000 | C6: 2500 | D6: 10 | E6: 5000 | F6: 4600 | G6: 10
A7: 河北省 | B7: 7000 | C7: 11000 | D7: 10 | E7: 9800 | F7: 13600 | G7: 10.4
A8: 山西省 | B8: 500 | C8: 5500 | E8: 1000 | F8: 5700
A9: 内蒙古自治区 | B9: 450 | C9: 1850 | E9: 950 | F9: 1950
A10: 山东省 | B10: 5000 | C10: 5000 | D10: 10 | E10: 8000 | F10: 6000 | G10: 10
A11: 河南省 | B11: 5700 | C11: 2500 | E11: 8600 | F11: 3100
A12: 陕西省 | B12: 500 | C12: 4500 | D12: 10 | E12: 1500 | F12: 6000 | G12: 10
A13: 甘肃省 | B13: 500 | C13: 100 | E13: 900 | F13: 100
A14: 宁夏回族自治区 | B14: 500 | E14: 750
A15: 青海省 | C15: 200 | D15: 30 | F15: 250 | G15: 30
A16: 新疆维吾尔自治区 | B16: 500 | C16: 250 | D16: 5 | E16: 800 | F16: 350 | G16: 5
A17: 四川省 | B17: 3000 | D17: 15 | E17: 4000 | G17: 15
A18: 重庆市 | B18: 3700 | E18: 4400
A19: 湖北省 | B19: 6200 | E19: 7400
A20: 湖南省 | B20: 4000 | E20: 4200
A21: 江西省 | B21: 3000 | E21: 3600
A22: 安徽省 | B22: 3000 | E22: 4800 | F22: 50
A23: 江苏省 | B23: 6000 | C23: 200 | D23: 20 | E23: 8500 | F23: 250 | G23: 20
A24: 上海市 | B24: 2700 | E24: 3700
A25: 浙江省 | B25: 3000 | E25: 5200
A26: 辽宁省 | B26: 1000 | C26: 1000 | E26: 8000 | F26: 1200
A27: 吉林省 | B27: 1000 | C27: 1000 | E27: 1200 | F27: 1500
A28: 黑龙江省 | B28: 1000 | C28: 1600 | E28: 1300 | F28: 2250
A29: 广东省 | B29: 2000 | D29: 10 | E29: 2500 | G29: 10.3
A30: 福建省 | B30: 400 | D30: 10 | E30: 500 | G30: 10
A31: 海南省 | B31: 500 | D31: 10 | E31: 600 | G31: 10
A32: 云南省 | B32: 100 | D32: 10 | E32: 250 | G32: 10
A33: 贵州省 | B33: 2000 | C33: 50 | E33: 2800 | F33: 60
A34: 广西壮族自治区 | B34: 1400 | E34: 3600
A35: 西藏自治区 | B35: 0 | C35: 250 | D35: 350 | F35: 250 | G35: 376.58
A36: 全国 | B36: 72650 | C36: 40000 | D36: 500 | E36: 111850 | F36: 50210 | G36: 527.28

Sheet OffshoreProject
A1: Country | B1: Project Name | C1: Project Name in Local Language / Script | D1: Capacity (MW) | E1: Installation Type | F1: Status | G1: Start year | H1: State/Province
A2: China | B2: Fujian Ningde Xiapu Offshore wind farm | C2: 福建宁德霞浦海上风电D区 | D2: 400 | E2: offshore hard mount | F2: announced | G2: 2026 | H2: Fujian
A3: China | B3: Hainan Wanning Offshore Floating wind farm | C3: 海南万宁漂浮式海上风电项目一期 | D3: 200 | E3: offshore floating | F3: construction | G3: 2025 | H3: Hainan
A4: China | B4: Hainan Wanning Offshore Floating wind farm | C4: 海南万宁漂浮式海上风电项目二期 | D4: 800 | E4: offshore floating | F4: construction | G4: 2027 | H4: Hainan
A5: China | B5: Fujian Pingtan Changjiang'Ao Offshore wind farm | C5: 福建平潭长江澳185MW 海上风电场 | D5: 185 | E5: offshore hard mount | F5: construction | H5: Fujian
A6: China | B6: Fujian Zhangpu Liu'ao offshore wind farm | C6: 三峡福建漳浦六鳌海上风电场二期项目 | D6: 400 | E6: offshore hard mount | F6: construction | G6: 2024 | H6: Fujian
A7: China | B7: Fujian Zhangpu Liu'Ao Offshore wind farm | C7: 福建漳浦六鳌海上风电场D区 | D7: 402 | E7: offshore hard mount | F7: construction | G7: 2023 | H7: Fujian
A8: China | B8: Fujian Zhangpu Liu'Ao Offshore wind farm | C8: 福建漳浦六鳌海上风电场E区 | D8: 404 | E8: offshore hard mount | F8: construction | G8: 2024 | H8: Fujian
A9: China | B9: Guangdong Huizhou Gangkou 2 Offshore wind farm | C9: 广东惠州港口二 PA 海上风电场 | D9: 450 | E9: offshore hard mount | F9: construction | G9: 2023 | H9: Guangdong
A10: China | B10: Guangdong Huizhou Gangkou 2 Offshore wind farm | C10: 广东惠州港口二 PB 海上风电场 | D10: 300 | E10: offshore hard mount | F10: construction | G10: 2023 | H10: Guangdong
A11: China | B11: Guangdong Nan'ao Lemen 2 Offshore wind farm | C11: 广东汕头勒门（二）海上风电场 | D11: 406 | E11: offshore hard mount | F11: construction | G11: 2023 | H11: Guangdong
A12: China | B12: Guangdong Shantou Nan'Ao Yangdong Offshore wind farm | C12: 广东汕头市南澳洋东海上风电项目 | D12: 301 | E12: offshore hard mount | F12: construction | G12: 2024 | H12: Guangdong
A13: China | B13: Guangdong Shantou Zhongpeng Offshore Area 2 wind farm | C13: 广东汕头中澎二海上风电场 | D13: 1001 | E13: offshore hard mount | F13: construction | G13: 2024 | H13: Guangdong
A14: China | B14: Guangdong Yangjiang Fanshi Offshore wind farm | C14: 广东阳江帆石一海上风电场 | D14: 1000 | E14: offshore hard mount | F14: construction | G14: 2024 | H14: Guangdong
A15: China | B15: Guangdong Yangjiang Fanshi Offshore wind farm | C15: 广东阳江帆石二海上风电场 | D15: 1000 | E15: offshore hard mount | F15: construction | G15: 2024 | H15: Guangdong
A16: China | B16: Guangdong Yangjiang Qingzhou I Offshore wind farm | C16: 广东阳江青洲一海上风电场项目 | D16: 400 | E16: offshore hard mount | F16: construction | G16: 2023 | H16: Guangdong
A17: China | B17: Guangdong Yangjiang Qingzhou Ii Offshore wind farm | C17: 广东阳江青洲二海上风电场项目 | D17: 600 | E17: offshore hard mount | F17: construction | G17: 2024 | H17: Guangdong
... A21: China | B21: Guangdong Yangjiang Qingzhou Vii Offshore wind farm | C21: 广东阳江青洲七海上风电场项目 | D21: 1000 | E21: offshore hard mount | F21: construction | G21: 2024 | H21: Guangdong
A22: China | B22: Hainan CZ2 Demonstration Offshore wind farm | C22: 海南CZ2海上示范风电场 | D22: 1200 | E22: offshore hard mount | F22: construction | H22: Hainan
A23: China | B23: Hainan CZ9 Demonstration Offshore wind farm | C23: 海南CZ9海上示范风电场 | D23: 1500 | E23: offshore hard mount | F23: construction | G23: 2026 | H23: Hainan
A24: China | B24: Liaoning Zhuanghe (Taopingwan) wind farm | C24: 大连市庄河海上风电场址V项目 | D24: 250 | E24: offshore hard mount | F24: construction | H24: Liaoning
A25: China | B25: Shandong Bandaobei 6 Offshore wind farm | C25: 山东牟平半岛北6#海上风电场一期 | D25: 301 | E25: offshore hard mount | F25: construction | G25: 2023 | H25: Shandong
A26: China | B26: Shandong Bandaobei BW Offshore wind farm | C26: 华能山东半岛北BW场址海上风电项目 | D26: 510 | E26: offshore hard mount | F26: construction | G26: 2024 | H26: Shandong
A27: China | B27: Shandong Bandaonan (Guohua) Offshore wind farm | C27: 国华半岛南地区600mw海上风电项目 | D27: 306 | E27: offshore hard mount | F27: construction | H27: Shandong
A28: China | B28: Shandong Bandaonan (Guohua) Offshore wind farm | C28: 国华半岛南地区600MW海上风电项 | D28: 297.5 | E28: offshore hard mount | F28: construction | H28: Shandong
A29: China | B29: Shandong Bandaonan U Offshore wind farm | C29: 山东半岛南海上风电基地U场 | D29: 450 | E29: offshore hard mount | F29: construction | H29: Shandong
A30: China | B30: Shandong Bandaonan U2 Offshore wind farm | C30: 山东半岛南海上风电U2场址项目（一期） | D30: 300 | E30: offshore hard mount | F30: construction | H30: Shandong
A31: China | B31: Zhejiang Cangnan 2 wind farm | C31: 浙江苍南2号海上风电场 | D31: 301 | E31: offshore hard mount | F31: construction | G31: 2023 | H31: Zhejiang
A32: China | B32: Zhejiang Daishan 1 Offshore wind farm | C32: 浙江岱山1#海上风电场 | D32: 304 | E32: offshore hard mount | F32: construction | H32: Zhejiang
A33: China | B33: Zhejiang Rui'An 1 Offshore wind farm | C33: 浙江瑞安1号海上风电场 | D33: 300 | E33: offshore hard mount | F33: construction | H33: Zhejiang
A34: China | B34: Zhejiang Taizhou 1 Offshore wind farm | C34: 浙江台州1#海上风电场 | D34: 300 | E34: offshore hard mount | F34: construction | G34: 2024 | H34: Zhejiang
A35: China | B35: Zhejiang Xiangshan 1 Offshore wind farm | C35: 浙江象山1#海上风电场二期 | D35: 504 | E35: offshore hard mount | F35: construction | G35: 2023 | H35: Zhejiang
A36: China | B36: Zhejiang Yuhuan No.2 offshore wind farm | C36: 华能玉环2号海上风电项目 | D36: 504 | E36: offshore hard mount | F36: construction | G36: 2025 | H36: Zhejiang
A37: China | B37: Guangxi Fangchenggang Pilot Offshore wind farm | C37: 广西防城港海上风电示范项目A场址工程项目 | D37: 700 | E37: offshore mount unknown | F37: construction | H37: Guangxi
A38: China | B38: Liaoning Dalian Zhuanghe 5 Offshore wind farm | C38: 三峡能源大连市庄河V(250MW)海上风电场项目 | D38: 250 | E38: offshore mount unknown | F38: construction | H38: Liaoning
A39: China | B39: Shandong Muping (Three Gorges) Offshore wind farm | C39: 三峡山东牟平BDB6#一期（300MW）海上风电项目 | D39: 300 | E39: offshore mount unknown | F39: construction | G39: 2023 | H39: Shandong
A40: China | B40: Shandong Weihai Bandaonan offshore wind farm | C40: 国华半岛南U2场址600MW海上风电项目 | D40: 600 | E40: offshore mount unknown | F40: construction | H40: Shandong
A41: China | B41: Zhejiang Yuhuan (Huaneng) wind farm | C41: 华能玉环2号海上风电项目 | D41: 504 | E41: offshore mount unknown | F41: construction | G41: 2024 | H41: Zhejiang
A42: China | B42: Fujian Changle 'Outer Ocean' Area A Offshore wind farm | C42: 福建长乐外海海上风电场A区 | D42: 300 | E42: offshore hard mount | F42: operating | G42: 2021 | H42: Fujian
A43: China | B43: Fujian Changle 'Outer Ocean' Area C Offshore wind farm | C43: 福建长乐外海海上风电场C区 | D43: 496 | E43: offshore hard mount | F43: operating | G43: 2021 | H43: Fujian
...

Sheet Nuclear
A1: 序号 | B1: 机组名称 | C1: 电厂名称 | D1: 电厂期数 | E1: 机组编号 | F1: 堆型 | G1: 状态 | H1: 省份 | I1: 城市 | J1: 县 | K1: 经度 | L1: 纬度 | M1: 装机容量(MW) | N1: 业主单位 | O1: 开工日期 | P1: 首次并网 | Q1: 商业运行 | R1: 预计投运 | S1: 退役日期 | T1: Year
A2: 1 | B2: 福清1号 | C2: 福清核电厂 | D2: 1期 | E2: 1号机组 | F2: M310 / CNP1000 | G2: 在运 | H2: 福建省 | I2: 福州市 | J2: 福清市 | K2: 119.44924 | L2: 25.440775 | M2: 1089 | N2: 中核集团 | O2: 39773 | P2: 41871 | Q2: 41962 | R2: 2014
A3: 2 | B3: 福清2号 | C3: 福清核电厂 | D3: 1期 | E3: 2号机组 | F3: M310 / CNP1000 | G3: 在运 | H3: 福建省 | I3: 福州市 | J3: 福清市 | K3: 119.44924 | L3: 25.440775 | M3: 1089 | N3: 中核集团 | O3: 39981 | P3: 42222 | Q3: 42293 | R3: 2015
A4: 3 | B4: 福清3号 | C4: 福清核电厂 | D4: 1期 | E4: 3号机组 | F4: M310 / CNP1000 | G4: 在运 | H4: 福建省 | I4: 福州市 | J4: 福清市 | K4: 119.44924 | L4: 25.440775 | M4: 1089 | N4: 中核集团 | O4: 40543 | P4: 42620 | Q4: 42667 | R4: 2016
A5: 4 | B5: 福清4号 | C5: 福清核电厂 | D5: 1期 | E5: 4号机组 | F5: M310 / CNP1000 | G5: 在运 | H5: 福建省 | I5: 福州市 | J5: 福清市 | K5: 119.44924 | L5: 25.440775 | M5: 1089 | N5: 中核集团 | O5: 41230 | P5: 42945 | Q5: 42995 | R5: 2017
A6: 5 | B6: 福清5号 | C6: 福清核电厂 | D6: 1期 | E6: 5号机组 | F6: 华龙一号 | G6: 在运 | H6: 福建省 | I6: 福州市 | J6: 福清市 | K6: 119.44924 | L6: 25.440775 | M6: 1161 | N6: 中核集团 | O6: 42131 | P6: 44162 | Q6: 44225 | R6: 2020
A7: 6 | B7: 福清6号 | C7: 福清核电厂 | D7: 1期 | E7: 6号机组 | F7: 华龙一号 | G7: 在运 | H7: 福建省 | I7: 福州市 | J7: 福清市 | K7: 119.44924 | L7: 25.440775 | M7: 1161 | N7: 中核集团 | O7: 42360 | P7: 44562 | Q7: 44562 | R7: 2022
A8: 7 | B8: 宁德1号 | C8: 宁德核电厂 | D8: 1期 | E8: 1号机组 | F8: CPR1000 | G8: 在运 | H8: 福建省 | I8: 宁德市 | J8: 福鼎市 | K8: 120.2846 | L8: 27.042584 | M8: 1089 | N8: 中国广核集团 | O8: 39496 | P8: 41271 | Q8: 41379 | R8: 2012
A9: 8 | B9: 宁德2号 | C9: 宁德核电厂 | D9: 1期 | E9: 2号机组 | F9: CPR1000 | G9: 在运 | H9: 福建省 | I9: 宁德市 | J9: 福鼎市 | K9: 120.2846 | L9: 27.042584 | M9: 1089 | N9: 中国广核集团 | O9: 39764 | P9: 41643 | Q9: 41763 | R9: 2014
A10: 9 | B10: 宁德3号 | C10: 宁德核电厂 | D10: 1期 | E10: 3号机组 | F10: CPR1000 | G10: 在运 | H10: 福建省 | I10: 宁德市 | J10: 福鼎市 | K10: 120.2846 | L10: 27.042584 | M10: 1089 | N10: 中国广核集团 | O10: 40186 | P10: 42084 | Q10: 42165 | R10: 2015
A11: 10 | B11: 宁德4号 | C11: 宁德核电厂 | D11: 1期 | E11: 4号机组 | F11: CPR1000 | G11: 在运 | H11: 福建省 | I11: 宁德市 | J11: 福鼎市 | K11: 120.2846 | L11: 27.042584 | M11: 1089 | N11: 中国广核集团 | O11: 40450 | P11: 42458 | Q11: 42572 | R11: 2016
A12: 11 | B12: 霞浦示范快堆1号 | C12: 霞浦示范快堆 | D12: 1期 | E12: 1号机组 | F12: CFR600 | G12: 在建 | H12: 福建省 | I12: 宁德市 | J12: 霞浦县 | K12: 120.15269 | L12: 26.80127 | M12: 600 | N12: 中核集团 | O12: 43098 | R12: 2023
A13: 12 | B13: 霞浦示范快堆2号 | C13: 霞浦示范快堆 | D13: 1期 | E13: 2号机组 | F13: CFR600 | G13: 在建 | H13: 福建省 | I13: 宁德市 | J13: 霞浦县 | K13: 120.15269 | L13: 26.80127 | M13: 600 | N13: 中核集团 | O13: 44192 | R13: 2026
A14: 13 | B14: 漳州1号 | C14: 漳州核电厂 | D14: 1期 | E14: 1号机组 | F14: 华龙一号 | G14: 在建 | H14: 福建省 | I14: 漳州市 | J14: 东山县 | K14: 117.4914 | L14: 23.830723 | M14: 1212 | N14: 中核集团 | O14: 43754 | R14: 2024
A15: 14 | B15: 漳州2号 | C15: 漳州核电厂 | D15: 1期 | E15: 2号机组 | F15: 华龙一号 | G15: 在建 | H15: 福建省 | I15: 漳州市 | J15: 东山县 | K15: 117.4914 | L15: 23.830723 | M15: 1212 | N15: 中核集团 | O15: 44078 | R15: 2025
A16: 15 | B16: 漳州3号 | C16: 漳州核电厂 | D16: 2期 | E16: 3号机组 | F16: 华龙一号 | G16: 核准 | H16: 福建省 | I16: 漳州市 | J16: 东山县 | K16: 117.4914 | L16: 23.830723 | M16: 1212 | N16: 中核集团 | O16: 2022-09-13 核准
A17: 16 | B17: 漳州4号 | C17: 漳州核电厂 | D17: 2期 | E17: 4号机组 | F17: 华龙一号 | G17: 核准 | H17: 福建省 | I17: 漳州市 | J17: 东山县 | K17: 117.4914 | L17: 23.830723 | M17: 1212 | N17: 中核集团 | O17: 2022-09-13 核准 | R17: 2028
A18: 17 | B18: 大亚湾1号 | C18: 大亚湾核电厂 | D18: 1期 | E18: 1号机组 | F18: M310 | G18: 在运 | H18: 广东省 | I18: 深圳市 | J18: 宝安区 | K18: 114.54467 | L18: 22.596773 | M18: 984 | N18: 中国广核集团 | O18: 31996 | P18: 34212 | Q18: 34366 | R18: 1993
A19: 18 | B19: 大亚湾2号 | C19: 大亚湾核电厂 | D19: 1期 | E19: 2号机组 | F19: M310 | G19: 在运 | H19: 广东省 | I19: 深圳市 | J19: 宝安区 | K19: 114.54467 | L19: 22.596773 | M19: 984 | N19: 中国广核集团 | O19: 32240 | P19: 34372 | Q19: 34460 | R19: 1994
A20: 19 | B20: 岭澳1号 | C20: 岭澳核电厂 | D20: 1期 | E20: 1号机组 | F20: M310 | G20: 在运 | H20: 广东省 | I20: 深圳市 | J20: 宝安区 | K20: 114.55306 | L20: 22.606138 | M20: 990 | N20: 中国广核集团 | O20: 35565 | P20: 37313 | Q20: 37404 | R20: 2002
A21: 20 | B21: 岭澳2号 | C21: 岭澳核电厂 | D21: 1期 | E21: 2号机组 | F21: M310 | G21: 在运 | H21: 广东省 | I21: 深圳市 | J21: 宝安区 | K21: 114.55306 | L21: 22.606138 | M21: 990 | N21: 中国广核集团 | O21: 35762 | P21: 37513 | Q21: 37629 | R21: 2002
A22: 21 | B22: 岭澳3号 | C22: 岭澳核电厂 | D22: 2期 | E22: 3号机组 | F22: CPR1000 | G22: 在运 | H22: 广东省 | I22: 深圳市 | J22: 宝安区 | K22: 114.55306 | L22: 22.606138 | M22: 1086 | N22: 中国广核集团 | O22: 38701 | P22: 40374 | Q22: 40436 | R22: 2010
A23: 22 | B23: 岭澳4号 | C23: 岭澳核电厂 | D23: 2期 | E23: 4号机组 | F23: CPR1000 | G23: 在运 | H23: 广东省 | I23: 深圳市 | J23: 宝安区 | K23: 114.55306 | L23: 22.606138 | M23: 1086 | N23: 中国广核集团 | O23: 38883 | P23: 40666 | Q23: 40762 | R23: 2011
A24: 23 | B24: 台山1号 | C24: 台山核电厂 | D24: 1期 | E24: 1号机组 | F24: EPR | G24: 在运 | H24: 广东省 | I24: 江门市 | J24: 台山市 | K24: 112.98205 | L24: 21.917883 | M24: 1750 | N24: 中国广核集团 | O24: 40135 | P24: 43280 | Q24: 43447 | R24: 2018
A25: 24 | B25: 台山2号 | C25: 台山核电厂 | D25: 1期 | E25: 2号机组 | F25: EPR | G25: 在运 | H25: 广东省 | I25: 江门市 | J25: 台山市 | K25: 112.98205 | L25: 21.917883 | M25: 1750 | N25: 中国广核集团 | O25: 40283 | P25: 43639 | Q25: 43715 | R25: 2019
A26: 25 | B26: 太平岭1号 | C26: 太平岭核电厂 | D26: 1期 | E26: 1号机组 | F26: 华龙一号 | G26: 在建 | H26: 广东省 | I26: 惠州市 | J26: 惠东县 | K26: 114.98445 | L26: 22.692977 | M26: 1202 | N26: 中国广核集团 | O26: 43825 | R26: 2025
A27: 26 | B27: 太平岭2号 | C27: 太平岭核电厂 | D27: 1期 | E27: 2号机组 | F27: 华龙一号 | G27: 在建 | H27: 广东省 | I27: 惠州市 | J27: 惠东县 | K27: 114.98445 | L27: 22.692977 | M27: 1202 | N27: 中国广核集团 | O27: 44119 | R27: 2026
A28: 27 | B28: 阳江1号 | C28: 阳江核电厂 | D28: 1期 | E28: 1号机组 | F28: CPR1000 | G28: 在运 | H28: =VLOOKUP($C28,[2]电厂名单!$A$2:$G$26,2,FALSE) -> #N/A | I28: =VLOOKUP($C28,[2]电厂名单!$A$2:$G$26,3,FALSE) -> #N/A | J28: =VLOOKUP($C28,[2]电厂名单!$A$2:$G$26,4,FALSE) -> #N/A | K28: =VLOOKUP($C28,[2]电厂名单!$A$2:$G$26,6,FALSE) -> #N/A | L28: =VLOOKUP($C28,[2]电厂名单!$A$2:$G$26,7,FALSE) -> #N/A | M28: 1086 | N28: 中国广核集团 | O28: 2008/12/16 | P28: 2013/12/31 | Q28: 2014/03/25 | R28: 2013
A29: 28 | B29: 阳江2号 | C29: 阳江核电厂 | D29: 1期 | E29: 2号机组 | F29: CPR1000 | G29: 在运 | H29: =VLOOKUP($C29,[2]电厂名单!$A$2:$G$26,2,FALSE) -> #N/A | I29: =VLOOKUP($C29,[2]电厂名单!$A$2:$G$26,3,FALSE) -> #N/A | J29: =VLOOKUP($C29,[2]电厂名单!$A$2:$G$26,4,FALSE) -> #N/A | K29: =VLOOKUP($C29,[2]电厂名单!$A$2:$G$26,6,FALSE) -> #N/A | L29: =VLOOKUP($C29,[2]电厂名单!$A$2:$G$26,7,FALSE) -> #N/A | M29: 1086 | N29: 中国广核集团 | O29: 2009/06/04 | P29: 2015/03/10 | Q29: 2015/06/05 | R29: 2015
A30: 29 | B30: 阳江3号 | C30: 阳江核电厂 | D30: 1期 | E30: 3号机组 | F30: CPR1000 | G30: 在运 | H30: =VLOOKUP($C30,[2]电厂名单!$A$2:$G$26,2,FALSE) -> #N/A | I30: =VLOOKUP($C30,[2]电厂名单!$A$2:$G$26,3,FALSE) -> #N/A | J30: =VLOOKUP($C30,[2]电厂名单!$A$2:$G$26,4,FALSE) -> #N/A | K30: =VLOOKUP($C30,[2]电厂名单!$A$2:$G$26,6,FALSE) -> #N/A | L30: =VLOOKUP($C30,[2]电厂名单!$A$2:$G$26,7,FALSE) -> #N/A | M30: 1086 | N30: 中国广核集团 | O30: 2010/11/15 | P30: 2015/10/18 | Q30: 2016/01/01 | R30: 2015
A31: 30 | B31: 阳江4号 | C31: 阳江核电厂 | D31: 1期 | E31: 4号机组 | F31: CPR1000 | G31: 在运 | H31: =VLOOKUP($C31,[2]电厂名单!$A$2:$G$26,2,FALSE) -> #N/A | I31: =VLOOKUP($C31,[2]电厂名单!$A$2:$G$26,3,FALSE) -> #N/A | J31: =VLOOKUP($C31,[2]电厂名单!$A$2:$G$26,4,FALSE) -> #N/A | K31: =VLOOKUP($C31,[2]电厂名单!$A$2:$G$26,6,FALSE) -> #N/A | L31: =VLOOKUP($C31,[2]电厂名单!$A$2:$G$26,7,FALSE) -> #N/A | M31: 1086 | N31: 中国广核集团 | O31: 2012/11/17 | P31: 2017/01/08 | Q31: 2017/03/15 | R31: 2017
A32: 31 | B32: 阳江5号 | C32: 阳江核电厂 | D32: 1期 | E32: 5号机组 | F32: ACPR1000 | G32: 在运 | H32: =VLOOKUP($C32,[2]电厂名单!$A$2:$G$26,2,FALSE) -> #N/A | I32: =VLOOKUP($C32,[2]电厂名单!$A$2:$G$26,3,FALSE) -> #N/A | J32: =VLOOKUP($C32,[2]电厂名单!$A$2:$G$26,4,FALSE) -> #N/A | K32: =VLOOKUP($C32,[2]电厂名单!$A$2:$G$26,6,FALSE) -> #N/A | L32: =VLOOKUP($C32,[2]电厂名单!$A$2:$G$26,7,FALSE) -> #N/A | M32: 1086 | N32: 中国广核集团 | O32: 2013/09/27 | P32: 2018/05/23 | Q32: 2018/07/12 | R32: 2018
A33: 32 | B33: 阳江6号 | C33: 阳江核电厂 | D33: 1期 | E33: 6号机组 | F33: ACPR1000 | G33: 在运 | H33: =VLOOKUP($C33,[2]电厂名单!$A$2:$G$26,2,FALSE) -> #N/A | I33: =VLOOKUP($C33,[2]电厂名单!$A$2:$G$26,3,FALSE) -> #N/A | J33: =VLOOKUP($C33,[2]电厂名单!$A$2:$G$26,4,FALSE) -> #N/A | K33: =VLOOKUP($C33,[2]电厂名单!$A$2:$G$26,6,FALSE) -> #N/A | L33: =VLOOKUP($C33,[2]电厂名单!$A$2:$G$26,7,FALSE) -> #N/A | M33: 1086 | N33: 中国广核集团 | O33: 2013/12/23 | P33: 2019/06/29 | Q33: 2019/07/24 | R33: 2019
A34: 33 | B34: 漳州1号 | C34: 漳州核电厂 | D34: 1期 | E34: 1号机组 | F34: 华龙一号 | G34: 在建 | H34: =VLOOKUP($C34,[2]电厂名单!$A$2:$G$26,2,FALSE) -> #N/A | I34: =VLOOKUP($C34,[2]电厂名单!$A$2:$G$26,3,FALSE) -> #N/A | J34: =VLOOKUP($C34,[2]电厂名单!$A$2:$G$26,4,FALSE) -> #N/A | K34: =VLOOKUP($C34,[2]电厂名单!$A$2:$G$26,6,FALSE) -> #N/A | L34: =VLOOKUP($C34,[2]电厂名单!$A$2:$G$26,7,FALSE) -> #N/A | M34: 1212 | N34: 中核集团 | O34: 2019/10/16 | R34: 2026
A35: 34 | B35: 漳州2号 | C35: 漳州核电厂 | D35: 1期 | E35: 2号机组 | F35: 华龙一号 | G35: 在建 | H35: =VLOOKUP($C35,[2]电厂名单!$A$2:$G$26,2,FALSE) -> #N/A | I35: =VLOOKUP($C35,[2]电厂名单!$A$2:$G$26,3,FALSE) -> #N/A | J35: =VLOOKUP($C35,[2]电厂名单!$A$2:$G$26,4,FALSE) -> #N/A | K35: =VLOOKUP($C35,[2]电厂名单!$A$2:$G$26,6,FALSE) -> #N/A | L35: =VLOOKUP($C35,[2]电厂名单!$A$2:$G$26,7,FALSE) -> #N/A | M35: 1212 | N35: 中核集团 | O35: 2020/09/04 | R35: 2027
A36: 35 | B36: 漳州3号 | C36: 漳州核电厂 | D36: 2期 | E36: 3号机组 | F36: 华龙一号 | G36: 核准 | H36: =VLOOKUP($C36,[2]电厂名单!$A$2:$G$26,2,FALSE) -> #N/A | I36: =VLOOKUP($C36,[2]电厂名单!$A$2:$G$26,3,FALSE) -> #N/A | J36: =VLOOKUP($C36,[2]电厂名单!$A$2:$G$26,4,FALSE) -> #N/A | K36: =VLOOKUP($C36,[2]电厂名单!$A$2:$G$26,6,FALSE) -> #N/A | L36: =VLOOKUP($C36,[2]电厂名单!$A$2:$G$26,7,FALSE) -> #N/A | M36: 1212 | N36: 中核集团 | O36: 2022/09/13 核准 | R36: 2029
A37: 36 | B37: 漳州4号 | C37: 漳州核电厂 | D37: 2期 | E37: 4号机组 | F37: 华龙一号 | G37: 核准 | H37: =VLOOKUP($C37,[2]电厂名单!$A$2:$G$26,2,FALSE) -> #N/A | I37: =VLOOKUP($C37,[2]电厂名单!$A$2:$G$26,3,FALSE) -> #N/A | J37: =VLOOKUP($C37,[2]电厂名单!$A$2:$G$26,4,FALSE) -> #N/A | K37: =VLOOKUP($C37,[2]电厂名单!$A$2:$G$26,6,FALSE) -> #N/A | L37: =VLOOKUP($C37,[2]电厂名单!$A$2:$G$26,7,FALSE) -> #N/A | M37: 1212 | N37: 中核集团 | O37: 2022/09/13 核准 | R37: 2029
A38: 37 | B38: 防城港1号 | C38: 防城港核电厂 | D38: 1期 | E38: 1号机组 | F38: CPR1000 | G38: 在运 | H38: 广西壮族自治区 | I38: 防城港市 | J38: 防城区 | K38: 108.563 | L38: 21.666747 | M38: 1086 | N38: 中国广核集团 | O38: 40389 | P38: 42302 | Q38: 42370 | R38: 2015
A39: 38 | B39: 防城港2号 | C39: 防城港核电厂 | D39: 1期 | E39: 2号机组 | F39: CPR1000 | G39: 在运 | H39: 广西壮族自治区 | I39: 防城港市 | J39: 防城区 | K39: 108.563 | L39: 21.666747 | M39: 1086 | N39: 中国广核集团 | O39: 40535 | P39: 42566 | Q39: 42644 | R39: 2016
A40: 39 | B40: 防城港3号 | C40: 防城港核电厂 | D40: 2期 | E40: 3号机组 | F40: 华龙一号 | G40: 在建 | H40: 广西壮族自治区 | I40: 防城港市 | J40: 防城区 | K40: 108.563 | L40: 21.666747 | M40: 1180 | N40: 中国广核集团 | O40: 42362 | P40: 44939 | R40: 2023
...

Sheet Calculation
A1: Generation Type EN | B1: Generation Type CN | C1: Project Count | D1: Percentile
D2: 0.99 | E2: 0.98 | F2: 0.95 | G2: 0.9 | H2: 0.75 | I2: 0.5 | J2: 0.25 | K2: 0.1 | L2: 0.05 | M2: 0.02 | N2: 0.01
A3: Wind | B3: 风电 | C3: =COUNTIF('Project List'!D:D,Calculation!B3) -> 4771 | D3: {=_xlfn.PERCENTILE.INC(IF('Project List'!$D$2:$D$14396=$B3,'Project List'!$F$2:$F$14396),D$2)*10} -> 301.132 | E3: {=_xlfn.PERCENTILE.INC(IF('Project List'!$D$2:$D$14396=$B3,'Project List'!$F$2:$F$14396),E$2)*10} -> 250 | F3: {=_xlfn.PERCENTILE.INC(IF('Project List'!$D$2:$D$14396=$B3,'Project List'!$F$2:$F$14396),F$2)*10} -> 182.15 | G3: {=_xlfn.PERCENTILE.INC(IF('Project List'!$D$2:$D$14396=$B3,'Project List'!$F$2:$F$14396),G$2)*10} -> 100 | H3: {=_xlfn.PERCENTILE.INC(IF('Project List'!$D$2:$D$14396=$B3,'Project List'!$F$2:$F$14396),H$2)*10} -> 50 | I3: {=_xlfn.PERCENTILE.INC(IF('Project List'!$D$2:$D$14396=$B3,'Project List'!$F$2:$F$14396),I$2)*10} -> 49.5 | J3: {=_xlfn.PERCENTILE.INC(IF('Project List'!$D$2:$D$14396=$B3,'Project List'!$F$2:$F$14396),J$2)*10} -> 32 | K3: {=_xlfn.PERCENTILE.INC(IF('Project List'!$D$2:$D$14396=$B3,'Project List'!$F$2:$F$14396),K$2)*10} -> 12 | ... N3: {=_xlfn.PERCENTILE.INC(IF('Project List'!$D$2:$D$14396=$B3,'Project List'!$F$2:$F$14396),N$2)*10} -> 2
A4: Nuclear | B4: 核电 | C4: =COUNTIF('Project List'!D:D,Calculation!B4) -> 33 | D4: {=_xlfn.PERCENTILE.INC(IF('Project List'!$D$2:$D$14396=$B4,'Project List'!$F$2:$F$14396),D$2)*10} -> 2422 | E4: {=_xlfn.PERCENTILE.INC(IF('Project List'!$D$2:$D$14396=$B4,'Project List'!$F$2:$F$14396),E$2)*10} -> 2342 | F4: {=_xlfn.PERCENTILE.INC(IF('Project List'!$D$2:$D$14396=$B4,'Project List'!$F$2:$F$14396),F$2)*10} -> 2204 | G4: {=_xlfn.PERCENTILE.INC(IF('Project List'!$D$2:$D$14396=$B4,'Project List'!$F$2:$F$14396),G$2)*10} -> 1750 | H4: {=_xlfn.PERCENTILE.INC(IF('Project List'!$D$2:$D$14396=$B4,'Project List'!$F$2:$F$14396),H$2)*10} -> 1118.8 | I4: {=_xlfn.PERCENTILE.INC(IF('Project List'!$D$2:$D$14396=$B4,'Project List'!$F$2:$F$14396),I$2)*10} -> 1089 | J4: {=_xlfn.PERCENTILE.INC(IF('Project List'!$D$2:$D$14396=$B4,'Project List'!$F$2:$F$14396),J$2)*10} -> 1089 | K4: {=_xlfn.PERCENTILE.INC(IF('Project List'!$D$2:$D$14396=$B4,'Project List'!$F$2:$F$14396),K$2)*10} -> 1086 | ... N4: {=_xlfn.PERCENTILE.INC(IF('Project List'!$D$2:$D$14396=$B4,'Project List'!$F$2:$F$14396),N$2)*10} -> 650
A5: Biomass | B5: 火电-其他火电-秸杆、蔗渣、林木质发电 | C5: =COUNTIF('Project List'!D:D,Calculation!B5) -> 371 | D5: {=_xlfn.PERCENTILE.INC(IF('Project List'!$D$2:$D$14396=$B5,'Project List'!$F$2:$F$14396),D$2)*10} -> 80 | E5: {=_xlfn.PERCENTILE.INC(IF('Project List'!$D$2:$D$14396=$B5,'Project List'!$F$2:$F$14396),E$2)*10} -> 80 | F5: {=_xlfn.PERCENTILE.INC(IF('Project List'!$D$2:$D$14396=$B5,'Project List'!$F$2:$F$14396),F$2)*10} -> 52.75 | G5: {=_xlfn.PERCENTILE.INC(IF('Project List'!$D$2:$D$14396=$B5,'Project List'!$F$2:$F$14396),G$2)*10} -> 37.65 | H5: {=_xlfn.PERCENTILE.INC(IF('Project List'!$D$2:$D$14396=$B5,'Project List'!$F$2:$F$14396),H$2)*10} -> 30 | I5: {=_xlfn.PERCENTILE.INC(IF('Project List'!$D$2:$D$14396=$B5,'Project List'!$F$2:$F$14396),I$2)*10} -> 30 | J5: {=_xlfn.PERCENTILE.INC(IF('Project List'!$D$2:$D$14396=$B5,'Project List'!$F$2:$F$14396),J$2)*10} -> 18 | K5: {=_xlfn.PERCENTILE.INC(IF('Project List'!$D$2:$D$14396=$B5,'Project List'!$F$2:$F$14396),K$2)*10} -> 10.45 | ... N5: {=_xlfn.PERCENTILE.INC(IF('Project List'!$D$2:$D$14396=$B5,'Project List'!$F$2:$F$14396),N$2)*10} -> 1.138
A6: Municial Solid Waste | B6: 火电-其他火电-垃圾焚烧发电 | C6: =COUNTIF('Project List'!D:D,Calculation!B6) -> 684 | D6: {=_xlfn.PERCENTILE.INC(IF('Project List'!$D$2:$D$14396=$B6,'Project List'!$F$2:$F$14396),D$2)*10} -> 150 | E6: {=_xlfn.PERCENTILE.INC(IF('Project List'!$D$2:$D$14396=$B6,'Project List'!$F$2:$F$14396),E$2)*10} -> 90 | F6: {=_xlfn.PERCENTILE.INC(IF('Project List'!$D$2:$D$14396=$B6,'Project List'!$F$2:$F$14396),F$2)*10} -> 60 | G6: {=_xlfn.PERCENTILE.INC(IF('Project List'!$D$2:$D$14396=$B6,'Project List'!$F$2:$F$14396),G$2)*10} -> 45 | H6: {=_xlfn.PERCENTILE.INC(IF('Project List'!$D$2:$D$14396=$B6,'Project List'!$F$2:$F$14396),H$2)*10} -> 25 | I6: {=_xlfn.PERCENTILE.INC(IF('Project List'!$D$2:$D$14396=$B6,'Project List'!$F$2:$F$14396),I$2)*10} -> 15 | J6: {=_xlfn.PERCENTILE.INC(IF('Project List'!$D$2:$D$14396=$B6,'Project List'!$F$2:$F$14396),J$2)*10} -> 12 | K6: {=_xlfn.PERCENTILE.INC(IF('Project List'!$D$2:$D$14396=$B6,'Project List'!$F$2:$F$14396),K$2)*10} -> 7.5 | ... N6: {=_xlfn.PERCENTILE.INC(IF('Project List'!$D$2:$D$14396=$B6,'Project List'!$F$2:$F$14396),N$2)*10} -> 1.943
A7: Waste Heat | B7: 火电-其他火电-余温、余压、余气发电 | C7: =COUNTIF('Project List'!D:D,Calculation!B7) -> 925 | D7: {=_xlfn.PERCENTILE.INC(IF('Project List'!$D$2:$D$14396=$B7,'Project List'!$F$2:$F$14396),D$2)*10} -> 270 | E7: {=_xlfn.PERCENTILE.INC(IF('Project List'!$D$2:$D$14396=$B7,'Project List'!$F$2:$F$14396),E$2)*10} -> 175.428 | F7: {=_xlfn.PERCENTILE.INC(IF('Project List'!$D$2:$D$14396=$B7,'Project List'!$F$2:$F$14396),F$2)*10} -> 100.17 | G7: {=_xlfn.PERCENTILE.INC(IF('Project List'!$D$2:$D$14396=$B7,'Project List'!$F$2:$F$14396),G$2)*10} -> 60 | H7: {=_xlfn.PERCENTILE.INC(IF('Project List'!$D$2:$D$14396=$B7,'Project List'!$F$2:$F$14396),H$2)*10} -> 30 | I7: {=_xlfn.PERCENTILE.INC(IF('Project List'!$D$2:$D$14396=$B7,'Project List'!$F$2:$F$14396),I$2)*10} -> 13.35 | J7: {=_xlfn.PERCENTILE.INC(IF('Project List'!$D$2:$D$14396=$B7,'Project List'!$F$2:$F$14396),J$2)*10} -> 7.5 | K7: {=_xlfn.PERCENTILE.INC(IF('Project List'!$D$2:$D$14396=$B7,'Project List'!$F$2:$F$14396),K$2)*10} -> 6 | ... N7: {=_xlfn.PERCENTILE.INC(IF('Project List'!$D$2:$D$14396=$B7,'Project List'!$F$2:$F$14396),N$2)*10} -> 1.846
A8: Coal | B8: 火电-燃煤-常规燃煤 | C8: =COUNTIF('Project List'!D:D,Calculation!B8) -> 917 | D8: {=_xlfn.PERCENTILE.INC(IF('Project List'!$D$2:$D$14396=$B8,'Project List'!$F$2:$F$14396),D$2)*10} -> 2000 | E8: {=_xlfn.PERCENTILE.INC(IF('Project List'!$D$2:$D$14396=$B8,'Project List'!$F$2:$F$14396),E$2)*10} -> 2000 | F8: {=_xlfn.PERCENTILE.INC(IF('Project List'!$D$2:$D$14396=$B8,'Project List'!$F$2:$F$14396),F$2)*10} -> 1320 | G8: {=_xlfn.PERCENTILE.INC(IF('Project List'!$D$2:$D$14396=$B8,'Project List'!$F$2:$F$14396),G$2)*10} -> 1200 | H8: {=_xlfn.PERCENTILE.INC(IF('Project List'!$D$2:$D$14396=$B8,'Project List'!$F$2:$F$14396),H$2)*10} -> 660 | I8: {=_xlfn.PERCENTILE.INC(IF('Project List'!$D$2:$D$14396=$B8,'Project List'!$F$2:$F$14396),I$2)*10} -> 158 | J8: {=_xlfn.PERCENTILE.INC(IF('Project List'!$D$2:$D$14396=$B8,'Project List'!$F$2:$F$14396),J$2)*10} -> 25 | K8: {=_xlfn.PERCENTILE.INC(IF('Project List'!$D$2:$D$14396=$B8,'Project List'!$F$2:$F$14396),K$2)*10} -> 10 | ... N8: {=_xlfn.PERCENTILE.INC(IF('Project List'!$D$2:$D$14396=$B8,'Project List'!$F$2:$F$14396),N$2)*10} -> 3
A9: Gangue | B9: 火电-燃煤-煤矸石发电 | C9: =COUNTIF('Project List'!D:D,Calculation!B9) -> 15 | D9: {=_xlfn.PERCENTILE.INC(IF('Project List'!$D$2:$D$14396=$B9,'Project List'!$F$2:$F$14396),D$2)*10} -> 1233.2 | E9: {=_xlfn.PERCENTILE.INC(IF('Project List'!$D$2:$D$14396=$B9,'Project List'!$F$2:$F$14396),E$2)*10} -> 1146.4 | F9: {=_xlfn.PERCENTILE.INC(IF('Project List'!$D$2:$D$14396=$B9,'Project List'!$F$2:$F$14396),F$2)*10} -> 886 | G9: {=_xlfn.PERCENTILE.INC(IF('Project List'!$D$2:$D$14396=$B9,'Project List'!$F$2:$F$14396),G$2)*10} -> 700 | H9: {=_xlfn.PERCENTILE.INC(IF('Project List'!$D$2:$D$14396=$B9,'Project List'!$F$2:$F$14396),H$2)*10} -> 630 | I9: {=_xlfn.PERCENTILE.INC(IF('Project List'!$D$2:$D$14396=$B9,'Project List'!$F$2:$F$14396),I$2)*10} -> 300 | J9: {=_xlfn.PERCENTILE.INC(IF('Project List'!$D$2:$D$14396=$B9,'Project List'!$F$2:$F$14396),J$2)*10} -> 159 | K9: {=_xlfn.PERCENTILE.INC(IF('Project List'!$D$2:$D$14396=$B9,'Project List'!$F$2:$F$14396),K$2)*10} -> 10.8 | ... N9: {=_xlfn.PERCENTILE.INC(IF('Project List'!$D$2:$D$14396=$B9,'Project List'!$F$2:$F$14396),N$2)*10} -> 2.56
A10: Natural Gas | B10: 火电-燃气-常规燃气 | C10: =COUNTIF('Project List'!D:D,Calculation!B10) -> 178 | D10: {=_xlfn.PERCENTILE.INC(IF('Project List'!$D$2:$D$14396=$B10,'Project List'!$F$2:$F$14396),D$2)*10} -> 1314.9 | E10: {=_xlfn.PERCENTILE.INC(IF('Project List'!$D$2:$D$14396=$B10,'Project List'!$F$2:$F$14396),E$2)*10} -> 1091.6 | F10: {=_xlfn.PERCENTILE.INC(IF('Project List'!$D$2:$D$14396=$B10,'Project List'!$F$2:$F$14396),F$2)*10} -> 950 | G10: {=_xlfn.PERCENTILE.INC(IF('Project List'!$D$2:$D$14396=$B10,'Project List'!$F$2:$F$14396),G$2)*10} -> 921.85 | H10: {=_xlfn.PERCENTILE.INC(IF('Project List'!$D$2:$D$14396=$B10,'Project List'!$F$2:$F$14396),H$2)*10} -> 472.775 | I10: {=_xlfn.PERCENTILE.INC(IF('Project List'!$D$2:$D$14396=$B10,'Project List'!$F$2:$F$14396),I$2)*10} -> 199.5 | J10: {=_xlfn.PERCENTILE.INC(IF('Project List'!$D$2:$D$14396=$B10,'Project List'!$F$2:$F$14396),J$2)*10} -> 25 | K10: {=_xlfn.PERCENTILE.INC(IF('Project List'!$D$2:$D$14396=$B10,'Project List'!$F$2:$F$14396),K$2)*10} -> 6 | ... N10: {=_xlfn.PERCENTILE.INC(IF('Project List'!$D$2:$D$14396=$B10,'Project List'!$F$2:$F$14396),N$2)*10} -> 0.475
A11: Coalbed Gas | B11: 火电-燃气-煤层气发电 | C11: =COUNTIF('Project List'!D:D,Calculation!B11) -> 17 | D11: {=_xlfn.PERCENTILE.INC(IF('Project List'!$D$2:$D$14396=$B11,'Project List'!$F$2:$F$14396),D$2)*10} -> 61.896 | E11: {=_xlfn.PERCENTILE.INC(IF('Project List'!$D$2:$D$14396=$B11,'Project List'!$F$2:$F$14396),E$2)*10} -> 56.392 | F11: {=_xlfn.PERCENTILE.INC(IF('Project List'!$D$2:$D$14396=$B11,'Project List'!$F$2:$F$14396),F$2)*10} -> 39.88 | G11: {=_xlfn.PERCENTILE.INC(IF('Project List'!$D$2:$D$14396=$B11,'Project List'!$F$2:$F$14396),G$2)*10} -> 30 | H11: {=_xlfn.PERCENTILE.INC(IF('Project List'!$D$2:$D$14396=$B11,'Project List'!$F$2:$F$14396),H$2)*10} -> 19.8 | I11: {=_xlfn.PERCENTILE.INC(IF('Project List'!$D$2:$D$14396=$B11,'Project List'!$F$2:$F$14396),I$2)*10} -> 9.6 | J11: {=_xlfn.PERCENTILE.INC(IF('Project List'!$D$2:$D$14396=$B11,'Project List'!$F$2:$F$14396),J$2)*10} -> 7.2 | K11: {=_xlfn.PERCENTILE.INC(IF('Project List'!$D$2:$D$14396=$B11,'Project List'!$F$2:$F$14396),K$2)*10} -> 4.96 | ... N11: {=_xlfn.PERCENTILE.INC(IF('Project List'!$D$2:$D$14396=$B11,'Project List'!$F$2:$F$14396),N$2)*10} -> 2.548
A12: Biogas | B12: 火电-燃气-沼气发电 | C12: =COUNTIF('Project List'!D:D,Calculation!B12) -> 16 | D12: {=_xlfn.PERCENTILE.INC(IF('Project List'!$D$2:$D$14396=$B12,'Project List'!$F$2:$F$14396),D$2)*10} -> 81.425 | E12: {=_xlfn.PERCENTILE.INC(IF('Project List'!$D$2:$D$14396=$B12,'Project List'!$F$2:$F$14396),E$2)*10} -> 72.35 | F12: {=_xlfn.PERCENTILE.INC(IF('Project List'!$D$2:$D$14396=$B12,'Project List'!$F$2:$F$14396),F$2)*10} -> 45.125 | G12: {=_xlfn.PERCENTILE.INC(IF('Project List'!$D$2:$D$14396=$B12,'Project List'!$F$2:$F$14396),G$2)*10} -> 27 | H12: {=_xlfn.PERCENTILE.INC(IF('Project List'!$D$2:$D$14396=$B12,'Project List'!$F$2:$F$14396),H$2)*10} -> 10.35 | I12: {=_xlfn.PERCENTILE.INC(IF('Project List'!$D$2:$D$14396=$B12,'Project List'!$F$2:$F$14396),I$2)*10} -> 6.1 | J12: {=_xlfn.PERCENTILE.INC(IF('Project List'!$D$2:$D$14396=$B12,'Project List'!$F$2:$F$14396),J$2)*10} -> 3.45 | K12: {=_xlfn.PERCENTILE.INC(IF('Project List'!$D$2:$D$14396=$B12,'Project List'!$F$2:$F$14396),K$2)*10} -> 1.1 | ... N12: {=_xlfn.PERCENTILE.INC(IF('Project List'!$D$2:$D$14396=$B12,'Project List'!$F$2:$F$14396),N$2)*10} -> 1
A13: Diesel | B13: 火电-燃油 | C13: =COUNTIF('Project List'!D:D,Calculation!B13) -> 1 | D13: {=_xlfn.PERCENTILE.INC(IF('Project List'!$D$2:$D$14396=$B13,'Project List'!$F$2:$F$14396),D$2)*10} -> 150 | E13: {=_xlfn.PERCENTILE.INC(IF('Project List'!$D$2:$D$14396=$B13,'Project List'!$F$2:$F$14396),E$2)*10} -> 150 | F13: {=_xlfn.PERCENTILE.INC(IF('Project List'!$D$2:$D$14396=$B13,'Project List'!$F$2:$F$14396),F$2)*10} -> 150 | G13: {=_xlfn.PERCENTILE.INC(IF('Project List'!$D$2:$D$14396=$B13,'Project List'!$F$2:$F$14396),G$2)*10} -> 150 | H13: {=_xlfn.PERCENTILE.INC(IF('Project List'!$D$2:$D$14396=$B13,'Project List'!$F$2:$F$14396),H$2)*10} -> 150 | I13: {=_xlfn.PERCENTILE.INC(IF('Project List'!$D$2:$D$14396=$B13,'Project List'!$F$2:$F$14396),I$2)*10} -> 150 | J13: {=_xlfn.PERCENTILE.INC(IF('Project List'!$D$2:$D$14396=$B13,'Project List'!$F$2:$F$14396),J$2)*10} -> 150 | K13: {=_xlfn.PERCENTILE.INC(IF('Project List'!$D$2:$D$14396=$B13,'Project List'!$F$2:$F$14396),K$2)*10} -> 150 | ... N13: {=_xlfn.PERCENTILE.INC(IF('Project List'!$D$2:$D$14396=$B13,'Project List'!$F$2:$F$14396),N$2)*10} -> 150
A14: Other | B14: 其他-其他 | C14: =COUNTIF('Project List'!D:D,Calculation!B14) -> 34 | D14: {=_xlfn.PERCENTILE.INC(IF('Project List'!$D$2:$D$14396=$B14,'Project List'!$F$2:$F$14396),D$2)*10} -> 108.425 | E14: {=_xlfn.PERCENTILE.INC(IF('Project List'!$D$2:$D$14396=$B14,'Project List'!$F$2:$F$14396),E$2)*10} -> 105.95 | F14: {=_xlfn.PERCENTILE.INC(IF('Project List'!$D$2:$D$14396=$B14,'Project List'!$F$2:$F$14396),F$2)*10} -> 100.75 | G14: {=_xlfn.PERCENTILE.INC(IF('Project List'!$D$2:$D$14396=$B14,'Project List'!$F$2:$F$14396),G$2)*10} -> 100 | H14: {=_xlfn.PERCENTILE.INC(IF('Project List'!$D$2:$D$14396=$B14,'Project List'!$F$2:$F$14396),H$2)*10} -> 52.5 | I14: {=_xlfn.PERCENTILE.INC(IF('Project List'!$D$2:$D$14396=$B14,'Project List'!$F$2:$F$14396),I$2)*10} -> 15.55 | J14: {=_xlfn.PERCENTILE.INC(IF('Project List'!$D$2:$D$14396=$B14,'Project List'!$F$2:$F$14396),J$2)*10} -> 8.5 | K14: {=_xlfn.PERCENTILE.INC(IF('Project List'!$D$2:$D$14396=$B14,'Project List'!$F$2:$F$14396),K$2)*10} -> 5 | ... N14: {=_xlfn.PERCENTILE.INC(IF('Project List'!$D$2:$D$14396=$B14,'Project List'!$F$2:$F$14396),N$2)*10} -> 1.7
... A17: Solar | B17: 太阳能 | C17: =COUNTIF('Project List'!D:D,Calculation!B17) -> 5346 | D17: {=_xlfn.PERCENTILE.INC(IF('Project List'!$D$2:$D$14396=$B17,'Project List'!$F$2:$F$14396),D$2)*10} -> 232.185 | E17: {=_xlfn.PERCENTILE.INC(IF('Project List'!$D$2:$D$14396=$B17,'Project List'!$F$2:$F$14396),E$2)*10} -> 189.8 | F17: {=_xlfn.PERCENTILE.INC(IF('Project List'!$D$2:$D$14396=$B17,'Project List'!$F$2:$F$14396),F$2)*10} -> 100 | G17: {=_xlfn.PERCENTILE.INC(IF('Project List'!$D$2:$D$14396=$B17,'Project List'!$F$2:$F$14396),G$2)*10} -> 92.5 | H17: {=_xlfn.PERCENTILE.INC(IF('Project List'!$D$2:$D$14396=$B17,'Project List'!$F$2:$F$14396),H$2)*10} -> 40 | I17: {=_xlfn.PERCENTILE.INC(IF('Project List'!$D$2:$D$14396=$B17,'Project List'!$F$2:$F$14396),I$2)*10} -> 20 | J17: {=_xlfn.PERCENTILE.INC(IF('Project List'!$D$2:$D$14396=$B17,'Project List'!$F$2:$F$14396),J$2)*10} -> 10 | K17: {=_xlfn.PERCENTILE.INC(IF('Project List'!$D$2:$D$14396=$B17,'Project List'!$F$2:$F$14396),K$2)*10} -> 4.8 | ... N17: {=_xlfn.PERCENTILE.INC(IF('Project List'!$D$2:$D$14396=$B17,'Project List'!$F$2:$F$14396),N$2)*10} -> 0.1
C21: Selected Value | D21: rounded | E21: Critiria
B22: hard coal | C22: =L8 -> 6 | D22: =ROUND(C22,0) -> 6 | E22: 0.05
B23: natural gas nonpeaker | C23: =L9 -> 4.8 | D23: =ROUND(C23,0) -> 5 | E23: 0.05
B24: nuclear | C24: =N4 -> 650 | D24: =ROUND(C24,0) -> 650 | E24: 0.01
B25: hydro | C25: =L15 -> 0.8 | D25: =ROUND(C25,0) -> 1 | E25: 0.05
B26: onshore wind | C26: =N3 -> 2 | D26: =ROUND(C26,0) -> 2 | E26: 0.01
B27: solar PV | C27: =L17 -> 1.4 | D27: =ROUND(C27,0) -> 1 | E27: 0.05
B28: solar thermal | C28: =MIN('Solar Thermal'!F:F) -> 50 | D28: =ROUND(C28,0) -> 50 | E28: Smallest Pilot Project Listed in the Solar Thermal Worksheet
B29: biomass | C29: =L5 -> 5.89 | D29: =ROUND(C29,0) -> 6 | E29: 0.05
B30: geothermal | C30: =MIN(Geothermal!D4:D35) -> 5 | D30: =ROUND(C30,0) -> 5 | E30: Smallest Provincial Increment based on China's Geothermal Development 13FYP
B31: petroleum | C31: =C23 -> 4.8 | D31: =ROUND(C31,0) -> 5 | E31: Equals to Natural Gas
B32: natural gas peaker | C32: =C23 -> 4.8 | D32: =ROUND(C32,0) -> 5 | E32: 0.05
B33: lignite | C33: =L9 -> 4.8 | D33: =ROUND(C33,0) -> 5 | E33: 0.05
B34: offshore wind | C34: =_xlfn.PERCENTILE.INC(OffshoreProject!D:D,0.01) -> 32.62 | D34: =ROUND(C34,0) -> 33 | E34: 1% based on Offshore Wind Project List from Global Energy Monitor (China's Project)
B35: crude oil | C35: =C31 -> 4.8 | D35: =ROUND(C35,0) -> 5 | E35: Equals to Natural Gas
B36: heavy or residual fuel oil | C36: =C31 -> 4.8 | D36: =ROUND(C36,0) -> 5 | E36: Equals to Natural Gas
B37: municipal solid waste | C37: =L6 -> 6 | D37: =ROUND(C37,0) -> 6 | E37: 0.05

Sheet MPPC
B1: Minimum Capacity (MW)
A2: hard coal | B2: =Calculation!D22 -> 6
A3: natural gas nonpeaker | B3: =Calculation!D23 -> 5
A4: nuclear | B4: =MIN(Nuclear!M:M) -> 125
A5: hydro | B5: =Calculation!D25 -> 1
A6: onshore wind | B6: =Calculation!D26 -> 2
A7: solar PV | B7: =Calculation!D27 -> 1
A8: solar thermal | B8: =Calculation!D28 -> 50
A9: biomass | B9: =Calculation!D29 -> 6
A10: geothermal | B10: =Calculation!D30 -> 5
A11: petroleum | B11: =Calculation!D31 -> 5
A12: natural gas peaker | B12: =Calculation!M10 -> 0.95
A13: lignite | B13: =Calculation!D33 -> 5
A14: offshore wind | B14: =Calculation!D34 -> 33
A15: crude oil | B15: =Calculation!D35 -> 5
A16: heavy or residual fuel oil | B16: =Calculation!D36 -> 5
A17: municipal solid waste | B17: =Calculation!D37 -> 6
