Workbook

Sheet About
A1: BFoHfC BAU Fraction of Heat from CHP
A4: Source: | B4: Heat Generation and Consumption Data | D4: Cogeneration Heat Production Data
B5: National Bureau of Statistics | D5: China Electricity Council
B6: 中国能源统计年鉴 | D6: 中国电力工业统计资料汇编
B7: China Energy Yearbook | D7: Compilation of China Power Sector Statistics
B8: 2011-2021 | D8: 2011-2021
B9: Chapter 5,6 National and Provincial Energy Balance Sheet | D9: Table 2-11
B11: District Heat Consumption Data | D11: 2020 Municipal Heating System
B12: National Bureau of Statistics | D12: Tsinghua University Building Energy Research Center
B13: 中国统计年鉴 | D13: 中国建筑节能年度发展研究报告2023（城市能源系统专题）
B14: China Statistical Yearbook | D14: China Building Energy Conservation Report 2023 (City Energy System)
B15: 2011-2021 | D15: 2023
B16: https://www.stats.gov.cn/sj/ndsj/2022/indexch.htm. | D16: Chapter 2 China City Heating Demand and System Status
B17: Table 25-7 District Heating Energy Consumption by Province
A19: Notes
A20: The CHP Management Guidelines set up a target to have 60% CHP in district heating for big and middle cities in North,
A21: but does not provide specific time and quantified target in smaller cities and counties.
A22: We assume nationally China will achieve 60% CHP in heating by 2025, and remain constant afterwards.
A24: Heat generation and consumption data are generally underestimated by China's National Bureau of Statistics. Although we can calculate the fraction
A25: of heat that comes from CHP, the percentage is used when no other data is available.
A26: Coal and Natural Gas are the pre-dominant type of heat source in China. For Shandong Province, there are no natural gas cogeneration thus the
A27: fraction is assigned zero.
A29: Notes from July 2025
A30: Although data for Cogeneration Heat Plants are provided here. We discovered from the National Buearu of Statistics that China artificial divides CHP fuel consumption data into fuel used for heat and power generation. And fuel used for heat is embedded in the total heating sector fuel use. Therefore, it would be inappropriate to count heat from CHP as "emission free' heat as EPS does.
A31: We concluded that until a better methodology is developed. This variable is most suited to represent the portion of recovered heat, which has no inherent emission. The calculation is don’t in BFoHPbF and pasted as a sheet in the file.

Sheet Energy Yearbook Data
A1: 索引 | B1: 地区 | C1: 年份 | D1: 项目 | E1: 能源品种 | F1: 实物消费量 | I1: 求和项:实物消费量 | J1: 列标签
A2: 55172 | B2: 上海市 | C2: 2021 | D2: 2.2. 供热 | E2: 热力(万百万千焦) | F2: 6535.28 | J2: 2.2. 供热 | U2: 2.9. 回收能 | AF2: 4. 终端消费量 | AQ2: 4.1. 农、林、牧、渔业 | BB2: 4.2. 工业 | BM2: 4.3. 建筑业 | BX2: 4.4. 交通运输、仓储和邮政业 | CI2: 4.5. 批发、零售业和住宿、餐饮业 | CT2: 4.6. 其他 | DE2: 4.7. 生活消费 | DP2: 6. 消费量合计 | EA2: 总计
A3: 55181 | B3: 上海市 | C3: 2021 | D3: 2.9. 回收能 | E3: 热力(万百万千焦) | F3: 4467.97 | I3: 行标签 | J3: 2011 | K3: 2012 | L3: 2013 | M3: 2014 | N3: 2015 | O3: 2016 | P3: 2017 | Q3: 2018 | R3: 2019 | S3: 2020 | T3: 2021 | U3: 2011 | V3: 2012 | W3: 2013 | X3: 2014 | Y3: 2015 | Z3: 2016 | AA3: 2017 | AB3: 2018 | AC3: 2019 | AD3: 2020 | AE3: 2021 | AF3: 2011 | AG3: 2012 | AH3: 2013 | AI3: 2014 | AJ3: 2015 | AK3: 2016 | AL3: 2017 | AM3: 2018 | AN3: 2019 | AO3: 2020 | AP3: 2021 | AQ3: 2011 | AR3: 2012 | AS3: 2013 | AT3: 2014 | AU3: 2015 | AV3: 2016 | AW3: 2017 | AX3: 2018 | AY3: 2019 | AZ3: 2020 | BA3: 2021 | BB3: 2011 | BC3: 2012 | BD3: 2013 | BE3: 2014 | BF3: 2015 | BG3: 2016 | BH3: 2017 | BI3: 2018 | BJ3: 2019 | BK3: 2020 | BL3: 2021 | BM3: 2011 | BN3: 2012 | BO3: 2013 | BP3: 2014 | BQ3: 2015 | BR3: 2016 | BS3: 2017 | BT3: 2018 | BU3: 2019 | BV3: 2020 | BW3: 2021 | BX3: 2011 | BY3: 2012 | BZ3: 2013 | CA3: 2014 | CB3: 2015 | CC3: 2016 | CD3: 2017 | CE3: 2018 | CF3: 2019 | CG3: 2020 | CH3: 2021 | CI3: 2011 | CJ3: 2012 | CK3: 2013 | CL3: 2014 | CM3: 2015 | CN3: 2016 | CO3: 2017 | CP3: 2018 | CQ3: 2019 | CR3: 2020 | CS3: 2021 | CT3: 2011 | CU3: 2012 | CV3: 2013 | CW3: 2014 | CX3: 2015 | CY3: 2016 | CZ3: 2017 | DA3: 2018 | DB3: 2019 | DC3: 2020 | DD3: 2021 | DE3: 2011 | DF3: 2012 | DG3: 2013 | DH3: 2014 | DI3: 2015 | DJ3: 2016 | DK3: 2017 | DL3: 2018 | DM3: 2019 | DN3: 2020 | DO3: 2021 | DP3: 2011 | DQ3: 2012 | DR3: 2013 | DS3: 2014 | DT3: 2015 | DU3: 2016 | DV3: 2017 | DW3: 2018 | DX3: 2019 | DY3: 2020 | DZ3: 2021
A4: 55183 | B4: 上海市 | C4: 2021 | D4: 4. 终端消费量 | E4: 热力(万百万千焦) | F4: 9799.78 | I4: 安徽省 | J4: 6848.63 | K4: 6873.65 | L4: 8589.87 | M4: 7629.85 | N4: 7986.03 | O4: 8366.79 | P4: 8431.7 | Q4: 9927.29 | R4: 9426.07 | S4: 13049.6 | T4: 14244.01 | U4: 1590 | V4: 2030 | W4: 4986.47 | X4: 5828.44 | Y4: 6685.82 | Z4: 6988.96 | AA4: 7646.8 | AB4: 8493.27 | AC4: 8893.78 | AD4: 9305.27 | AE4: 10426.57 | AF4: 7884.0966 | AG4: 7742.29 | AH4: 9002.1929 | AI4: 8089.03 | AJ4: 8574.17 | AK4: 8889.08 | AL4: 9325.52 | AM4: 11033.11 | AN4: 9892.56 | AO4: 14034.67 | AP4: 16033.26 | BB4: 5799.5366 | BC4: 5760.25 | BD4: 7857.84 | BE4: 6809.1 | BF4: 7416.76 | BG4: 7433.29 | BH4: 7759.52 | BI4: 8704.27 | BJ4: 8383.1 | BK4: 11424.44 | BL4: 13712.06 | BX4: 2.56 | BY4: 5.04 | BZ4: 5.40288 | CA4: 5.13 | CC4: 3.9788 | CD4: 3.7 | CE4: 3.67 | CF4: 3.14 | CG4: 2.48 | CH4: 2.56 | CR4: 544.29 | CS4: 603.07 | DE4: 2082 | DF4: 1977 | DG4: 1138.95 | DH4: 1274.8 | DI4: 1157.41 | DJ4: 1451.8112 | DK4: 1562.3 | DL4: 2325.17 | DM4: 1506.32 | DN4: 2063.45 | DO4: 1715.57 | DP4: 8647.0966 | DQ4: 8908.49 | DR4: 13576.343 | DS4: 13458.29 | DT4: 14671.85 | DU4: 15355.75 | DV4: 16078.5 | DW4: 18420.56 | DX4: 18319.85 | DY4: 22354.87 | DZ4: 24670.58 | EA4: 569711
A5: 55184 | B5: 上海市 | C5: 2021 | D5: 4.1. 农、林、牧、渔业 | E5: 热力(万百万千焦) | F5: 55.51 | I5: 北京市 | J5: 15127.73 | K5: 15632.37 | L5: 14893.567 | M5: 15055.436 | N5: 15819.74 | O5: 16091.903 | P5: 16473.27 | Q5: 18380 | R5: 18195.17 | S5: 19774.02 | T5: 19178.12 | AD5: 264.64 | AE5: 362.66 | AF5: 17539.088 | AG5: 17065.92 | AH5: 15408.218 | AI5: 16577.786 | AJ5: 16803.4 | AK5: 16659.828 | AL5: 17090.34 | AM5: 18921.33 | AN5: 18755.63 | AO5: 20601.16 | AP5: 20064.83 | AX5: 0.45 | BB5: 5101.3794 | BC5: 4890.54 | BD5: 3913.0728 | BE5: 3849.3904 | BF5: 3764.09 | BG5: 3808.8435 | BH5: 3878.57 | BI5: 4437.59 | BJ5: 4370.82 | BK5: 4734.59 | BL5: 4366.32 | BM5: 133.8132 | BN5: 125.62 | BO5: 112.33563 | BP5: 132.3629 | BQ5: 134.57 | BR5: 109.2777 | BS5: 112.53 | BT5: 124.19 | BU5: 121.36 | BV5: 132.09 | BW5: 127.72 | BX5: 689.7027 | BY5: 663.38 | BZ5: 603.86118 | CA5: 615.3251 | CB5: 594.2 | CC5: 538.5972 | CD5: 537.18 | CE5: 582.03 | CF5: 617.55 | CG5: 661.17 | CH5: 600.49 | CI5: 1400.4626 | CJ5: 1344.17 | CK5: 1248.4832 | CL5: 1383.987 | CM5: 1353.88 | CN5: 1248.4084 | CO5: 1245.77 | CP5: 1274.02 | CQ5: 1206.89 | CR5: 1333.06 | CS5: 1248.91 | CT5: 7303.7304 | CU5: 6641.2 | CV5: 5788.465 | CW5: 6574.7204 | CX5: 6733.66 | CY5: 6478.2212 | CZ5: 6674.18 | DA5: 7675.05 | DB5: 7504.01 | DC5: 8283.26 | DD5: 8131.4 | DE5: 2910 | DF5: 3401 | DG5: 3742 | DH5: 4022 | DI5: 4223 | DJ5: 4476.48 | DK5: 4642.11 | DL5: 4828 | DM5: 4935 | DN5: 5457 | DO5: 5590 | DP5: 17539.088 | DQ5: 17065.92 | DR5: 15408.218 | DS5: 16577.786 | DT5: 16803.4 | DU5: 16659.828 | DV5: 17090.34 | DW5: 18921.33 | DX5: 18755.63 | DY5: 20923.03 | DZ5: 20393.36 | EA5: 772361.63
A6: 55185 | B6: 上海市 | C6: 2021 | D6: 4.2. 工业 | E6: 热力(万百万千焦) | F6: 9344.2 | I6: 福建省 | J6: 4468 | K6: 5265.02 | L6: 5177.02 | M6: 8024.19 | N6: 7338 | O6: 7035.75 | P6: 7086.06 | Q6: 9203.25 | R6: 13090.78 | S6: 15367.52 | T6: 20912.01 | W6: 1829.71 | X6: 1852.89 | Y6: 2495.61 | Z6: 2520.28 | AA6: 2719.08 | AB6: 3595.73 | AC6: 3940.58 | AD6: 4013.65 | AE6: 4895.03 | AF6: 4862.43 | AG6: 5601.45 | AH6: 5736.92 | AI6: 8489.26 | AJ6: 7893.67 | AK6: 7630.46 | AL6: 7689.4 | AM6: 9766.48 | AN6: 13129.96 | AO6: 14908.91 | AP6: 20699.55 | BB6: 4862.43 | BC6: 5601.45 | BD6: 5736.92 | BE6: 8489.26 | BF6: 7893.67 | BG6: 7630.46 | BH6: 7689.4 | BI6: 9766.48 | BJ6: 13129.96 | BK6: 14908.91 | BL6: 20699.55 | DP6: 5757.92 | DQ6: 6728.66 | DR6: 7006.73 | DS6: 9877.08 | DT6: 9833.61 | DU6: 9556.03 | DV6: 9805.14 | DW6: 12798.98 | DX6: 17031.36 | DY6: 19381.17 | DZ6: 25807.04 | EA6: 477230.86
A7: 55187 | B7: 上海市 | C7: 2021 | D7: 4.3. 建筑业 | E7: 热力(万百万千焦) | F7: 8.82 | I7: 甘肃省 | J7: 9209.59 | K7: 8042.36 | L7: 9424.69 | M7: 9555.29 | N7: 9945.24 | O7: 10210.1 | P7: 10982.47 | Q7: 13315.17 | R7: 14534.57 | S7: 15493.11 | T7: 16506.84 | V7: 1769.49 | W7: 1800 | X7: 1907.03 | Y7: 2062.88 | Z7: 1652.94 | AA7: 1801.04 | AB7: 2286.26 | AC7: 2319.23 | AD7: 2771.89 | AE7: 3173.45 | AF7: 9128.06 | AG7: 9635.75 | AH7: 10964.24 | AI7: 11057.82 | AJ7: 11484.48 | AK7: 11308.68 | AL7: 12271.25 | AM7: 15081.67 | AN7: 16231.24 | AO7: 17197.44 | AP7: 18421.82 | BB7: 7108.06 | BC7: 7742.11 | BD7: 8788.24 | BE7: 8659.82 | BF7: 8754.48 | BG7: 8226.68 | BH7: 8558.25 | BI7: 8521.67 | BJ7: 9168 | BK7: 9379.9 | BL7: 10055.25 | BO7: 35 | BP7: 40 | BQ7: 60 | BR7: 60 | BS7: 70 | BT7: 80 | BU7: 86 | BV7: 90.3 | BW7: 100.3 | BY7: 12.03 | BZ7: 51 | CA7: 208 | CB7: 250 | CC7: 255 | CD7: 290 | CE7: 310 | CF7: 338 | CG7: 398 | CH7: 441.78 | CK7: 72 | CL7: 75 | CM7: 90 | CN7: 94 | CO7: 115 | CP7: 850 | CQ7: 915 | CR7: 930 | CS7: 1030 | CV7: 38 | CW7: 45 | CX7: 70 | CY7: 73 | CZ7: 105 | DA7: 835 | DB7: 898 | DC7: 943 | DD7: 1043 | DE7: 2020 | DF7: 1881.61 | DG7: 1980 | DH7: 2030 | DI7: 2260 | DJ7: 2600 | DK7: 3133 | DL7: 4485 | DM7: 4826.24 | DN7: 5456.24 | DO7: 5751.49 | DP7: 9209.59 | DQ7: 9811.85 | DR7: 11224.69 | DS7: 11462.32 | DT7: 12008.12 | DU7: 11863.04 | DV7: 12783.51 | DW7: 15601.43 | DX7: 16853.8 | DY7: 18265 | DZ7: 19680.29 | EA7: 583092.18
A8: 55188 | B8: 上海市 | C8: 2021 | D8: 4.4. 交通运输、仓储和邮政业 | E8: 热力(万百万千焦) | F8: 1.52 | I8: 广东省 | J8: 12976.67 | K8: 14778.46 | L8: 17137.1 | M8: 17352.67 | N8: 19788.22 | O8: 21702.9 | P8: 23954.23 | Q8: 25487.71 | R8: 28080.73 | S8: 29880.26 | T8: 36045.11 | U8: 2092.06 | V8: 2170.72 | W8: 2749.03 | X8: 2955.08 | Y8: 2933.22 | Z8: 4094.32 | AA8: 5176.08 | AB8: 4661.72 | AC8: 5234.14 | AD8: 6155.93 | AE8: 7912.9 | AF8: 12981.41 | AG8: 14802.35 | AH8: 17114.55 | AI8: 17463.56 | AJ8: 19784.1 | AK8: 22543.81 | AL8: 21330.72 | AM8: 27004.85 | AN8: 29534.88 | AO8: 28579.55 | AP8: 32675.28 | BB8: 12864.22 | BC8: 14264.95 | BD8: 17093.64 | BE8: 17444.71 | BF8: 19763.51 | BG8: 22528.87 | BH8: 21326.84 | BI8: 27000.95 | BJ8: 29530.94 | BK8: 28575.82 | BL8: 32671.35 | BO8: 8.1 | BP8: 8.3 | BQ8: 0.85 | BR8: 0.91 | BS8: 0.93 | BT8: 0.95 | BU8: 0.97 | BV8: 1 | BW8: 1.04 | BZ8: 2.54 | CB8: 2.61 | CC8: 2.68 | CD8: 2.95 | CE8: 2.95 | CF8: 2.97 | CG8: 2.73 | CH8: 2.89 | CI8: 117.19 | CJ8: 537.4 | CV8: 10.27 | CW8: 10.55 | CX8: 17.13 | CY8: 11.35 | DP8: 15068.73 | DQ8: 16949.18 | DR8: 19886.13 | DS8: 20307.75 | DT8: 22721.44 | DU8: 25797.22 | DV8: 25112.95 | DW8: 30149.43 | DX8: 33314.87 | DY8: 32804.55 | DZ8: 38085.28 | EA8: 1061146.9
A9: 55189 | B9: 上海市 | C9: 2021 | D9: 4.5. 批发、零售业和住宿、餐饮业 | E9: 热力(万百万千焦) | F9: 63.91 | I9: 广西壮族自治区 | J9: 5783.35 | K9: 6608.39 | L9: 7043.62 | M9: 7742.49 | N9: 8114.36 | O9: 8355.94 | P9: 8775.87 | Q9: 8650.15 | R9: 8809.47 | S9: 8761.41 | T9: 10535.11 | U9: 2724.55 | V9: 2777.79 | W9: 3238.53 | X9: 4040.37 | Y9: 4545.65 | Z9: 4955.94 | AA9: 6636.78 | AB9: 4808.09 | AC9: 6672.1 | AD9: 8365.62 | AE9: 8091.18 | AF9: 5634.95 | AG9: 6504.1 | AH9: 6964.62 | AI9: 7712.24 | AJ9: 8121.49 | AK9: 8506.05 | AL9: 10861.66 | AM9: 8366.72 | AN9: 9930.84 | AO9: 9564.84 | AP9: 11383.41 | BB9: 5634.95 | BC9: 6504.1 | BD9: 6964.62 | BE9: 7712.24 | BF9: 8121.49 | BG9: 8506.05 | BH9: 10861.66 | BI9: 8366.72 | BJ9: 9930.84 | BK9: 9564.84 | BL9: 11383.41 | DP9: 8507.9 | DQ9: 9386.18 | DR9: 10282.15 | DS9: 11782.86 | DT9: 12660.01 | DU9: 13311.88 | DV9: 15412.65 | DW9: 13458.24 | DX9: 15481.57 | DY9: 17127.03 | DZ9: 18626.29 | EA9: 479175.36
A10: 55190 | B10: 上海市 | C10: 2021 | D10: 4.6. 其他 | E10: 热力(万百万千焦) | F10: 260.82 | I10: 贵州省 | J10: 82.57 | K10: 181.67 | L10: 259.97 | M10: 70.31 | N10: 47.9 | O10: 25.3 | P10: 31.78 | Q10: 61.25 | R10: 241.39 | S10: 570.49 | T10: 980.92 | U10: 1852.21 | V10: 2176.82 | W10: 2850.06 | X10: 2977.64 | Y10: 3294.71 | Z10: 3998.8 | AA10: 4168.75 | AB10: 4563.93 | AC10: 5192.46 | AD10: 5337.85 | AE10: 5056.11 | AF10: 526.13 | AG10: 617.92 | AH10: 700.38 | AI10: 539.37 | AJ10: 912.86 | AK10: 929.41 | AL10: 971.34 | AM10: 1017.4 | AN10: 1096.79 | AO10: 1411.07 | AP10: 1932.21 | BB10: 526.13 | BC10: 617.92 | BD10: 700.38 | BE10: 539.37 | BF10: 894.47 | BG10: 630.41 | BH10: 583.51 | BI10: 564.09 | BJ10: 824.53 | BK10: 1072.66 | BL10: 1669.69 | DI10: 18.39 | DJ10: 299 | DK10: 387.83 | DL10: 453.31 | DM10: 272.26 | DN10: 338.41 | DO10: 262.52 | DP10: 1934.78 | DQ10: 2358.49 | DR10: 3110.03 | DS10: 3047.95 | DT10: 3342.61 | DU10: 4024.1 | DV10: 4200.54 | DW10: 4625.18 | DX10: 5433.85 | DY10: 5908.34 | DZ10: 6037.03 | EA10: 109355.55
A11: 55191 | B11: 上海市 | C11: 2021 | D11: 4.7. 生活消费 | E11: 热力(万百万千焦) | F11: 65 | I11: 海南省 | J11: 260.56 | K11: 278.28 | L11: 284.32 | M11: 757.61 | N11: 966.14 | O11: 1024.46 | P11: 1020.39 | Q11: 1094.33 | R11: 1484.96 | S11: 2647.04 | T11: 2992.08 | V11: 221.46 | W11: 323.88 | X11: 216.67 | Y11: 131.47 | Z11: 331.84 | AA11: 351.67 | AB11: 806.33 | AC11: 1139.55 | AD11: 1080.66 | AE11: 1362.11 | AF11: 263.98 | AG11: 267.74 | AH11: 234.47 | AI11: 440.27 | AJ11: 608.93 | AK11: 787.14 | AL11: 810.46 | AM11: 1002.52 | AN11: 1484.96 | AO11: 2647.04 | AP11: 2992.08 | BB11: 263.98 | BC11: 267.74 | BD11: 234.47 | BE11: 440.27 | BF11: 608.93 | BG11: 787.14 | BH11: 810.46 | BI11: 1002.52 | BJ11: 1484.96 | BK11: 2647.04 | BL11: 2992.08 | DP11: 263.98 | DQ11: 499.74 | DR11: 608.2 | DS11: 974.28 | DT11: 1097.61 | DU11: 1356.3 | DV11: 1372.06 | DW11: 1808.85 | DX11: 2624.51 | DY11: 3727.7 | DZ11: 4354.19 | EA11: 60542.41
A12: 55195 | B12: 上海市 | C12: 2021 | D12: 6. 消费量合计 | E12: 热力(万百万千焦) | F12: 10992.96 | I12: 河北省 | J12: 26374.23 | K12: 29576.07 | L12: 32536.45 | M12: 30464.964 | N12: 33725.73 | O12: 33923.49 | P12: 35203.27 | Q12: 42229.22 | R12: 48758.28 | S12: 53110.78 | T12: 59721.52 | U12: 2884.88 | V12: 3546.12 | W12: 7755.46 | X12: 8962.79 | Y12: 8516.82 | Z12: 9226.66 | AA12: 9883.84 | AB12: 45834.35 | AC12: 17863.92 | AD12: 22083.53 | AE12: 21071.06 | AF12: 26937.02 | AG12: 30297.29 | AH12: 38925.11 | AI12: 33918.251 | AJ12: 37793.96 | AK12: 38481.91 | AL12: 40029.05 | AM12: 75993.28 | AN12: 53557.14 | AO12: 58799.61 | AP12: 64163.1 | AU12: 94.8 | AV12: 104.8 | AW12: 206.84 | BB12: 19889.05 | BC12: 22816.68 | BD12: 30009.69 | BE12: 21962.791 | BF12: 22930.22 | BG12: 22247 | BH12: 24406.3 | BI12: 53740.69 | BJ12: 30641.77 | BK12: 25823.25 | BL12: 24525.72 | BM12: 63.7 | BN12: 64.34 | BO12: 69.4 | BP12: 79.4 | BQ12: 68.19 | BR12: 78.19 | BS12: 82.31 | BT12: 2664.35 | BU12: 2664.35 | BV12: 56.9 | BW12: 121.73 | BX12: 92.51 | BY12: 95.75 | BZ12: 72.04 | CA12: 102.08 | CB12: 551.74 | CC12: 551.74 | CD12: 587.6 | CE12: 694.97 | CF12: 717.5 | CG12: 970.23 | CH12: 905.61 | CI12: 396.01 | CJ12: 419.77 | CK12: 1263.38 | CL12: 1863.38 | CM12: 2127.18 | CN12: 2187.18 | CO12: 2959.66 | CP12: 2679.4 | CQ12: 2766.26 | CR12: 3227.58 | CS12: 5659.44 | CT12: 1500.05 | CU12: 1605.05 | CV12: 1685.3 | CW12: 2885.3 | CX12: 4160.32 | CY12: 4360.32 | DA12: 5240.36 | DB12: 5410.23 | DC12: 6499 | DD12: 7077 | DE12: 4995.7 | DF12: 5295.7 | DG12: 5825.3 | DH12: 7025.3 | DI12: 7861.51 | DJ12: 8952.68 | DK12: 11786.34 | DL12: 10973.5 | DM12: 11357.02 | DN12: 22222.65 | DO12: 25873.6 | DP12: 29259.11 | DQ12: 33122.19 | DR12: 40291.91 | DS12: 39427.751 | DT12: 42242.55 | DU12: 43150.15 | DV12: 45087.1 | DW12: 88078.31 | DX12: 65779.12 | DY12: 73600.84 | DZ12: 80539.3 | EA12: 2161623.2
A13: 55207 | B13: 云南省 | C13: 2021 | D13: 2.2. 供热 | E13: 热力(万百万千焦) | F13: 1599.32 | I13: 河南省 | J13: 15946.48 | K13: 16786.43 | L13: 19020.87 | M13: 23882.26 | N13: 20974.43 | O13: 22195.471 | P13: 23387.46 | Q13: 27581.47 | R13: 31088.44 | S13: 35388.59 | T13: 40048.79 | U13: 290 | V13: 2331.4 | W13: 2384.18 | Z13: 3850.1083 | AA13: 3504.73 | AB13: 4369.56 | AC13: 5904.75 | AD13: 5489.92 | AE13: 5219.23 | AF13: 15747.232 | AG13: 17885.94 | AH13: 19643.399 | AI13: 21629.03 | AJ13: 18668.31 | AK13: 23621.864 | AL13: 24282.03 | AM13: 28591.16 | AN13: 33393.17 | AO13: 36307.29 | AP13: 41258.15 | AQ13: 490 | AR13: 622.84 | AS13: 685.124 | BB13: 12261.092 | BC13: 12992.44 | BD13: 14257.15 | BE13: 15690.41 | BF13: 12438.17 | BG13: 14372.535 | BH13: 15035.45 | BI13: 17011.11 | BJ13: 19281.46 | BK13: 19462.61 | BL13: 24121.96 | BM13: 2.4 | BN13: 0.31 | BO13: 3.74 | BP13: 44.47 | BQ13: 19.28 | BR13: 23.5969 | BS13: 4.52 | BT13: 5.6 | BU13: 26.47 | BV13: 26.48 | BW13: 26.5 | BX13: 0.8 | BY13: 440.82 | BZ13: 484.902 | CC13: 35.788665 | CD13: 39.53 | CE13: 37.96 | CF13: 31.29 | CG13: 32.22 | CH13: 36.22 | CI13: 204.64 | CJ13: 204.06 | CK13: 224.466 | CL13: 933.03 | CM13: 744.57 | CN13: 797.5078 | CO13: 112.7 | CP13: 2150.47 | CQ13: 2878.78 | CR13: 4229.84 | CS13: 4243.23 | CT13: 150.3 | CU13: 169.23 | CV13: 186.153 | CW13: 130.95 | CX13: 145.62 | CY13: 176.72 | CZ13: 0.29 | DA13: 2904.21 | DB13: 2721.63 | DC13: 3857.71 | DD13: 3904.64 | DE13: 2638 | DF13: 3456.24 | DG13: 3801.864 | DH13: 4830.17 | DI13: 5320.67 | DJ13: 8215.716 | DK13: 9089.53 | DL13: 6481.81 | DM13: 8453.53 | DN13: 8698.44 | DO13: 8925.6 | DP13: 17107.582 | DQ13: 19117.83 | DR13: 21405.049 | DS13: 23882.26 | DT13: 20974.43 | DU13: 26072.569 | DV13: 26892.19 | DW13: 31964.37 | DX13: 36993.76 | DY13: 40508.89 | DZ13: 45268.67 | EA13: 1181887.3
A14: 55216 | B14: 云南省 | C14: 2021 | D14: 2.9. 回收能 | E14: 热力(万百万千焦) | F14: 6462.48 | I14: 黑龙江省 | J14: 25737.2 | K14: 27745.57 | L14: 34270.25 | M14: 34799.4 | N14: 34948.55 | O14: 38178.07 | P14: 41108.29 | Q14: 48640.45 | R14: 49223.85 | S14: 55357.99 | T14: 60022.4 | Z14: 292.87 | AA14: 366.14 | AB14: 455.84 | AD14: 55.93 | AE14: 1531.51 | AF14: 25737.2 | AG14: 27745.57 | AH14: 34270.25 | AI14: 34799.4 | AJ14: 34888.46 | AK14: 38399.87 | AL14: 41324.18 | AM14: 48924.11 | AN14: 49223.85 | AO14: 55325.6 | AP14: 60722.31 | BB14: 4788.2 | BC14: 2783.64 | BD14: 8382.88 | BE14: 7625.91 | BF14: 7274.22 | BG14: 10078.47 | BH14: 10536.42 | BI14: 8527.23 | BJ14: 10024.78 | BK14: 9254.33 | BL14: 14679.81 | BM14: 85.43 | BN14: 75.5 | BO14: 90.81 | BP14: 80 | BQ14: 83.66 | BR14: 86.6 | BS14: 80.66 | BT14: 75 | BU14: 80 | BV14: 180 | BW14: 185 | BX14: 371.08 | BY14: 817.8 | BZ14: 890 | CA14: 899.65 | CB14: 830.48 | CC14: 846.76 | CD14: 746.76 | CE14: 996.1 | CF14: 996.1 | CG14: 3296.1 | CH14: 3569.67 | CI14: 1795.96 | CJ14: 2100.98 | CK14: 2056 | CL14: 2196 | CM14: 2027.15 | CN14: 1827.15 | CO14: 2027.15 | CP14: 3878.22 | CQ14: 4108.22 | CR14: 5843.22 | CS14: 6275.62 | CT14: 1801.64 | CU14: 2201 | CV14: 2165.9 | CW14: 2011.84 | CX14: 1857.16 | CY14: 2498.69 | CZ14: 3198.69 | DA14: 5552.96 | DB14: 4552.96 | DC14: 5382.94 | DD14: 4204.03 | DE14: 16894.89 | DF14: 19766.65 | DG14: 20684.66 | DH14: 21986 | DI14: 22815.79 | DJ14: 23062.2 | DK14: 24734.5 | DL14: 29894.6 | DM14: 29461.79 | DN14: 31369.01 | DO14: 31808.18 | DP14: 25737.2 | DQ14: 27745.57 | DR14: 34270.25 | DS14: 34799.4 | DT14: 34948.55 | DU14: 38470.94 | DV14: 41474.43 | DW14: 49096.29 | DX14: 49223.85 | DY14: 55413.92 | DZ14: 61553.91 | EA14: 1808190.2
A15: 55218 | B15: 云南省 | C15: 2021 | D15: 4. 终端消费量 | E15: 热力(万百万千焦) | F15: 2557.8 | I15: 湖北省 | J15: 8681.06 | K15: 8239.76 | L15: 8390.3227 | M15: 8419.452 | N15: 8953.01 | O15: 8275.5458 | P15: 10086.58 | Q15: 10934.9 | R15: 12406.48 | S15: 11809.16 | T15: 11809.16 | V15: 592.29 | W15: 557.3255 | X15: 930.05562 | Y15: 1022.45 | Z15: 899.42031 | AA15: 1259.94 | AB15: 1559.56 | AC15: 3169.3 | AD15: 3739.53 | AE15: 3739.53 | AF15: 8681.06 | AG15: 8224.32 | AH15: 8344.5005 | AI15: 8174.4368 | AJ15: 8689.48 | AK15: 8292.6283 | AL15: 10395.29 | AM15: 11368.46 | AN15: 12856.7 | AO15: 11836.96 | AP15: 11836.96 | BB15: 7388.78 | BC15: 7862.66 | BD15: 7939.756 | BE15: 7818.7568 | BF15: 8313.78 | BG15: 7861.073 | BH15: 9903.18 | BI15: 10272.39 | BJ15: 11692.76 | BK15: 11511.23 | BL15: 11511.23 | BR15: 33.48 | BS15: 38.89 | BT15: 86.61 | BU15: 90.25 | BZ15: 4.75 | CA15: 4.75 | CB15: 5.02 | CC15: 5.1910185 | CD15: 6.11 | CE15: 13.61 | CF15: 14.3 | CG15: 5.27 | CH15: 5.27 | CI15: 514.03 | CJ15: 361.66 | CK15: 399.99451 | CL15: 350.93 | CM15: 370.68 | CN15: 392.88422 | CO15: 447.11 | CP15: 995.86 | CQ15: 1059.4 | CR15: 1.17 | CS15: 1.17 | DE15: 778.25 | DN15: 319.29 | DO15: 319.29 | DP15: 8681.06 | DQ15: 8832.05 | DR15: 8947.6501 | DS15: 9349.5123 | DT15: 9975.45 | DU15: 9417.1531 | DV15: 11346.52 | DW15: 12494.46 | DX15: 15575.78 | DY15: 15548.69 | DZ15: 15548.69 | EA15: 468593.46
A16: 55219 | B16: 云南省 | C16: 2021 | D16: 4.1. 农、林、牧、渔业 | E16: 热力(万百万千焦) | I16: 湖南省 | J16: 12380.71 | K16: 12345.99 | L16: 12330.37 | M16: 11888.54 | N16: 9755.65 | O16: 4707.73 | P16: 4647.03 | Q16: 4979.79 | R16: 5026.82 | S16: 5029.42 | T16: 5347.18 | U16: 1072.47 | V16: 3348.43 | W16: 2812.53 | X16: 3245.96 | Y16: 3225.43 | Z16: 3461.22 | AA16: 3288.91 | AB16: 3312.16 | AC16: 3520.36 | AD16: 3784.33 | AE16: 3780.8 | AF16: 11576.02 | AG16: 11916.1 | AH16: 11245.39 | AI16: 11889.27 | AJ16: 10696.31 | AK16: 7793.5 | AL16: 7870.2 | AM16: 8291.95 | AN16: 8547.18 | AO16: 8570.34 | AP16: 6952.88 | BB16: 11568.93 | BC16: 11913.32 | BD16: 11242.27 | BE16: 11885.91 | BF16: 10692.61 | BG16: 7789.5217 | BH16: 7866 | BI16: 8287.43 | BJ16: 8542.4 | BK16: 8565.54 | BL16: 6835.52 | BM16: 4.58964 | CS16: 27.31 | CT16: 2.5 | CU16: 2.78 | CV16: 3.12 | CW16: 3.36 | CX16: 3.7 | CY16: 3.9783141 | CZ16: 4.21 | DA16: 4.52 | DB16: 4.78 | DC16: 4.8 | DD16: 39.34 | DO16: 50.71 | DP16: 13453.18 | DQ16: 15694.42 | DR16: 15142.9 | DS16: 15134.5 | DT16: 12981.08 | DU16: 8168.95 | DV16: 7935.95 | DW16: 8291.95 | DX16: 8547.18 | DY16: 8813.76 | DZ16: 9134.89 | EA16: 457288.88
A17: 55220 | B17: 云南省 | C17: 2021 | D17: 4.2. 工业 | E17: 热力(万百万千焦) | F17: 2555.8 | I17: 吉林省 | J17: 25041.94 | K17: 25173.9 | L17: 23804.91 | M17: 22519.33 | N17: 23665.46 | O17: 24835.62 | P17: 26925.72 | Q17: 30016.13 | R17: 29646.81 | S17: 32502.44 | T17: 35537.2 | U17: 736.85 | V17: 866.3 | W17: 616.29 | X17: 937.47 | Y17: 950.47 | Z17: 569.25 | AA17: 640.74 | AB17: 1412.1 | AC17: 1323.68 | AD17: 1358.4 | AE17: 1323.23 | AF17: 23595.97 | AG17: 23433.1 | AH17: 22827.62 | AI17: 20438.77 | AJ17: 21493.96 | AK17: 22226.14 | AL17: 24256.83 | AM17: 27238.21 | AN17: 26963.95 | AO17: 29417.23 | AP17: 32996.85 | BB17: 14235.75 | BC17: 14267.18 | BD17: 16407.2 | BE17: 13839.85 | BF17: 14404.91 | BG17: 14614.12 | BH17: 14642.62 | BI17: 13063.39 | BJ17: 11910.62 | BK17: 13004.2 | BL17: 13113.53 | BM17: 70.12 | BN17: 97.12 | BO17: 130.46 | BP17: 118.86 | BQ17: 130.86 | BR17: 110.86 | BS17: 490.77 | BT17: 1006.53 | BU17: 906.4 | BV17: 1160.5 | BW17: 1240 | BX17: 497.63 | BY17: 589.23 | BZ17: 181.72 | CA17: 241.82 | CB17: 357.51 | CC17: 357.51 | CD17: 388.5 | CE17: 1056.17 | CF17: 997.98 | CG17: 1366.56 | CH17: 1699.73 | CI17: 125.46 | CJ17: 136.46 | CK17: 366.18 | CL17: 356.18 | CM17: 428.17 | CN17: 518.14 | CO17: 721.19 | CP17: 1458.37 | CQ17: 1548.59 | CR17: 1598.59 | CS17: 1545.66 | CT17: 636.21 | CU17: 679 | CV17: 721.01 | CW17: 851.01 | CX17: 915.06 | CY17: 1415.06 | CZ17: 2543.3 | DA17: 3351.04 | DB17: 3426.29 | DC17: 3660.46 | DD17: 6066.68 | DE17: 8030.8 | DF17: 7664.11 | DG17: 5021.05 | DH17: 5031.05 | DI17: 5257.45 | DJ17: 5210.45 | DK17: 5470.45 | DL17: 7302.71 | DM17: 8174.07 | DN17: 8626.92 | DO17: 9331.25 | DP17: 25778.79 | DQ17: 26040.2 | DR17: 25821.2 | DS17: 23456.8 | DT17: 24615.93 | DU17: 25404.87 | DV17: 27566.46 | DW17: 31428.23 | DX17: 30970.49 | DY17: 33795.85 | DZ17: 36860.43 | EA17: 1171920.8
A18: 55222 | B18: 云南省 | C18: 2021 | D18: 4.3. 建筑业 | E18: 热力(万百万千焦) | I18: 江苏省 | J18: 51758.15 | K18: 53118.29 | L18: 54704.85 | M18: 55831.63 | N18: 56970.4 | O18: 57030.01 | P18: 61231.29 | Q18: 62180.38 | R18: 61945.05 | S18: 61459.09 | T18: 62034.62 | U18: 957.38 | V18: 819.2 | W18: 6805.43 | X18: 6872.76 | Y18: 6855.75 | Z18: 7463.39 | AA18: 7524.5 | AB18: 12501.27 | AC18: 13159.85 | AD18: 13097.6 | AE18: 14638.41 | AF18: 50666.56 | AG18: 51740.49 | AH18: 55216.68 | AI18: 53504.19 | AJ18: 54718.24 | AK18: 58355.29 | AL18: 62310.04 | AM18: 66154.82 | AN18: 66294.18 | AO18: 65821.43 | AP18: 67779.51 | BB18: 49884.12 | BC18: 51238.85 | BD18: 54445.17 | BE18: 52845.61 | BF18: 54145.45 | BG18: 58149.76 | BH18: 62117.73 | BI18: 65925.28 | BJ18: 66044.05 | BK18: 65520.52 | BL18: 67529.4 | BO18: 10.66 | BP18: 12.66 | BX18: 79.38 | BY18: 23.4 | BZ18: 48.42 | CA18: 35.42 | CB18: 20.11 | CC18: 10.46 | CD18: 8.94 | CE18: 9.57 | CF18: 5.62 | CG18: 8.74 | CH18: 5.11 | CI18: 63.3 | CJ18: 50 | CK18: 108.26 | CL18: 90.68 | CM18: 76.12 | CP18: 15.58 | CQ18: 13.91 | CR18: 12.1 | CT18: 132 | CU18: 90 | CV18: 90.68 | CW18: 64.4 | CX18: 28.82 | CY18: 12.83 | CZ18: 12.27 | DA18: 13.02 | DB18: 12.44 | DC18: 7.34 | DE18: 507.76 | DF18: 338.24 | DG18: 513.49 | DH18: 455.42 | DI18: 447.74 | DJ18: 182.24 | DK18: 171.1 | DL18: 191.37 | DM18: 218.16 | DN18: 272.73 | DO18: 245 | DP18: 52715.53 | DQ18: 53937.49 | DR18: 61510.28 | DS18: 62704.39 | DT18: 63826.15 | DU18: 64493.4 | DV18: 68755.79 | DW18: 74681.65 | DX18: 75104.9 | DY18: 74556.69 | DZ18: 76673.03 | EA18: 2763041.5
A19: 55223 | B19: 云南省 | C19: 2021 | D19: 4.4. 交通运输、仓储和邮政业 | E19: 热力(万百万千焦) | I19: 江西省 | J19: 789.82 | K19: 867.39 | L19: 1210.49 | M19: 1430.98 | N19: 1491.45 | O19: 1951.58 | P19: 2010.62 | Q19: 2344.2 | R19: 2902.07 | S19: 5827.29 | T19: 6730.54 | U19: 610.13 | V19: 715.5 | W19: 2952.0961 | X19: 3078.12 | Y19: 3238.18 | Z19: 3378.24 | AA19: 4472.05 | AB19: 3969.09 | AC19: 4218.2 | AD19: 4228.88 | AE19: 4536.98 | AF19: 724.66 | AG19: 1038.89 | AH19: 3282.59 | AI19: 3159.1 | AJ19: 1523.17 | AK19: 1935.78 | AL19: 1969.6 | AM19: 2272.11 | AN19: 2976.81 | AO19: 5008.64 | AP19: 6442.08 | BB19: 724.66 | BC19: 1038.89 | BD19: 3276.79 | BE19: 3143.1 | BF19: 1523.17 | BG19: 1935.78 | BH19: 1969.6 | BI19: 2272.11 | BJ19: 2976.81 | BK19: 5008.64 | BL19: 6442.08 | CK19: 5.8 | CL19: 16 | DP19: 1399.95 | DQ19: 1582.89 | DR19: 4162.59 | DS19: 4509.1 | DT19: 4729.63 | DU19: 5329.82 | DV19: 6482.67 | DW19: 6313.29 | DX19: 7120.27 | DY19: 10056.17 | DZ19: 11267.52 | EA19: 186574.66
A20: 55224 | B20: 云南省 | C20: 2021 | D20: 4.5. 批发、零售业和住宿、餐饮业 | E20: 热力(万百万千焦) | F20: 1 | I20: 辽宁省 | J20: 40015.03 | K20: 41464.18 | L20: 44718.4 | M20: 44113.22 | N20: 46594.26 | O20: 49187.88 | P20: 53303.69 | Q20: 58480.4 | R20: 64402.19 | S20: 70493.03 | T20: 72972.2 | U20: 1396.2 | V20: 1820.23 | W20: 2186.33 | X20: 5667.11 | Y20: 6020.02 | Z20: 6595.9 | AA20: 7438.34 | AB20: 8556.41 | AC20: 9673.15 | AD20: 11154.06 | AE20: 11838.83 | AF20: 40970.92 | AG20: 42193.68 | AH20: 45168.34 | AI20: 46658.6 | AJ20: 49423.47 | AK20: 52821.82 | AL20: 56441.8 | AM20: 62626.9 | AN20: 68182.86 | AO20: 74473.07 | AP20: 77444.86 | AT20: 11.25 | AU20: 12 | AV20: 11 | AW20: 11.59 | AX20: 12.05 | AY20: 12.45 | AZ20: 12.46 | BA20: 12.87 | BB20: 21035.09 | BC20: 20892.76 | BD20: 22489.58 | BE20: 23752.16 | BF20: 23973.03 | BG20: 26273.22 | BH20: 29863.63 | BI20: 35314.03 | BJ20: 39198.57 | BK20: 44849.82 | BL20: 47200.18 | BM20: 40.75 | BN20: 41.46 | BO20: 41.15 | BP20: 40.3 | BQ20: 50.25 | BR20: 49.21 | BS20: 50.01 | BT20: 55.08 | BU20: 57.68 | BV20: 57.84 | BW20: 58.88 | BX20: 200.32 | BY20: 201.01 | BZ20: 139.23 | CA20: 161.37 | CB20: 208.67 | CC20: 275.59 | CD20: 279.05 | CE20: 758.29 | CF20: 794.66 | CG20: 727.85 | CH20: 744.65 | CI20: 108.42 | CJ20: 119 | CK20: 120 | CL20: 152.32 | CM20: 165.24 | CN20: 166.33 | CO20: 170.33 | CP20: 175.98 | CQ20: 194.32 | CR20: 184.6 | CS20: 203.06 | CT20: 870.33 | CU20: 902.5 | CV20: 937.37 | CW20: 900.54 | CX20: 1798.23 | CY20: 1799.67 | CZ20: 1801.32 | DA20: 1813.93 | DB20: 1877.43 | DC20: 1875.36 | DD20: 2032.9 | DE20: 18716.01 | DF20: 20036.95 | DG20: 21441.01 | DH20: 21640.66 | DI20: 23216.05 | DJ20: 24246.8 | DK20: 24265.87 | DL20: 24497.54 | DM20: 26047.75 | DN20: 26765.13 | DO20: 27192.31 | DP20: 41411.23 | DQ20: 43284.41 | DR20: 46904.73 | DS20: 49780.33 | DT20: 52614.28 | DU20: 55783.78 | DV20: 60742.03 | DW20: 67036.81 | DX20: 74075.34 | DY20: 81647.09 | DZ20: 84811.03 | EA20: 2548994.7
A21: 55225 | B21: 云南省 | C21: 2021 | D21: 4.6. 其他 | E21: 热力(万百万千焦) | F21: 1 | I21: 内蒙古自治区 | J21: 21780.66 | K21: 26978.95 | L21: 27629.94 | M21: 29157.56 | N21: 32736.17 | O21: 35994.79 | P21: 39490.43 | Q21: 46208.75 | R21: 51000.08 | S21: 57750.26 | T21: 66287.7 | U21: 766.92 | V21: 1046.56 | W21: 1249.33 | X21: 1267.99 | Y21: 2060.07 | Z21: 2568.41 | AA21: 2779.84 | AB21: 5989.24 | AC21: 7853.82 | AD21: 9520.18 | AE21: 11435.51 | AF21: 21567.884 | AG21: 26842.66 | AH21: 27589.25 | AI21: 29234.175 | AJ21: 32781.96 | AK21: 36310.39 | AL21: 39938 | AM21: 47589.81 | AN21: 52908.93 | AO21: 60418.94 | AP21: 71320.28 | AQ21: 195.26 | AR21: 218.65 | AS21: 26.743548 | AT21: 28.55112 | AU21: 32.56 | AV21: 33.79 | AW21: 35.68 | AX21: 35.89 | AY21: 37.43 | AZ21: 38.14 | BA21: 49.97 | BB21: 4315.05 | BC21: 5178.54 | BD21: 5358.93 | BE21: 5498.17 | BF21: 6661.94 | BG21: 6615.83 | BH21: 7644.48 | BI21: 10004.83 | BJ21: 14450.33 | BK21: 21467.29 | BL21: 28046.87 | BM21: 352 | BN21: 430.05 | BO21: 162.13748 | BP21: 173.1219 | BQ21: 172.68 | BR21: 195.43 | BS21: 210.56 | BT21: 210.55 | BU21: 220.02 | BV21: 229.92 | BW21: 270.08 | BX21: 1070.8217 | BY21: 1393.97 | BZ21: 534.07885 | CA21: 570.2537 | CB21: 698.09 | CC21: 208.4201 | CD21: 215.69 | CE21: 228.63 | CF21: 338.69 | CG21: 373.55 | CH21: 423.64 | CI21: 1519.4709 | CJ21: 1938.8 | CK21: 1121.9678 | CL21: 1197.962 | CM21: 1408.11 | CN21: 1887.64 | CO21: 2125.36 | CP21: 2547.67 | CQ21: 2659.77 | CR21: 2526.78 | CS21: 4550.59 | CT21: 1577.2813 | CU21: 1984.86 | CV21: 2089.3774 | CW21: 2230.896 | CX21: 2621.14 | CY21: 3346.75 | CZ21: 3712.69 | DA21: 4450.4 | DB21: 4646.22 | DC21: 4646.22 | DD21: 5957.52 | DE21: 12538 | DF21: 15697.79 | DG21: 18296.015 | DH21: 19535.22 | DI21: 21187.44 | DJ21: 24022.53 | DK21: 25993.54 | DL21: 30111.84 | DM21: 30556.47 | DN21: 31137.04 | DO21: 32021.61 | DP21: 22547.575 | DQ21: 28025.51 | DR21: 28879.27 | DS21: 30425.555 | DT21: 34796.24 | DU21: 38563.2 | DV21: 42270.27 | DW21: 52197.99 | DX21: 58853.9 | DY21: 67192.19 | DZ21: 77487.53 | EA21: 1855796.9
A22: 55226 | B22: 云南省 | C22: 2021 | D22: 4.7. 生活消费 | E22: 热力(万百万千焦) | I22: 宁夏回族自治区 | J22: 4462.0707 | K22: 5394.35 | L22: 5416.6342 | M22: 4979.9655 | N22: 5808.29 | O22: 7999.6832 | P22: 8578.87 | Q22: 8296.54 | R22: 10008.43 | S22: 15401.75 | T22: 16011.02 | U22: 51.213354 | V22: 98.63 | W22: 49.359593 | X22: 74.289747 | Y22: 406.59 | Z22: 668.93878 | AA22: 661.78 | AB22: 1969.85 | AC22: 2082.98 | AD22: 2207.31 | AE22: 2674.97 | AF22: 4364.4076 | AG22: 5321.16 | AH22: 5231.604 | AI22: 5003.7319 | AJ22: 5941.7 | AK22: 8350.7664 | AL22: 8791.57 | AM22: 9736.72 | AN22: 11480.2 | AO22: 16996.32 | AP22: 17989.02 | BB22: 2299.0876 | BC22: 2777.63 | BD22: 2743.004 | BE22: 3079.8216 | BF22: 3304.81 | BG22: 5597.338 | BH22: 5886.57 | BI22: 6706.2 | BJ22: 8187.23 | BK22: 13697.41 | BL22: 14538.43 | BM22: 95 | BN22: 61.84 | BO22: 95.7 | BP22: 10.091932 | BQ22: 15.09 | BR22: 30.060438 | BS22: 80 | BT22: 99.69 | BU22: 95.73 | BV22: 97.73 | BW22: 103.44 | BX22: 38 | BY22: 41.4 | BZ22: 51.4 | CA22: 20.741907 | CB22: 28.74 | CC22: 28.353664 | CD22: 35 | CE22: 45.31 | CF22: 18.07 | CG22: 17.02 | CH22: 25.01 | CI22: 170 | CJ22: 317.95 | CK22: 343.5 | CL22: 293.10047 | CM22: 393.1 | CN22: 407.54609 | CO22: 475 | CP22: 484.89 | CQ22: 507 | CR22: 491 | CS22: 511.68 | CT22: 420 | CU22: 499.66 | CV22: 585 | CW22: 395.34697 | CX22: 895.34 | CY22: 951.37994 | CZ22: 865 | DA22: 859.74 | DB22: 823.1 | DC22: 802.1 | DD22: 808.95 | DE22: 1342.32 | DF22: 1622.68 | DG22: 1413 | DH22: 1204.629 | DI22: 1304.62 | DJ22: 1336.0883 | DK22: 1450 | DL22: 1540.89 | DM22: 1849.06 | DN22: 1891.06 | DO22: 2001.51 | DP22: 4513.2875 | DQ22: 5492.99 | DR22: 5465.9912 | DS22: 5054.2504 | DT22: 6214.88 | DU22: 8668.6208 | DV22: 9240.65 | DW22: 10266.39 | DX22: 12091.41 | DY22: 17609.06 | DZ22: 18685.99 | EA22: 405021.42
A23: 55230 | B23: 云南省 | C23: 2021 | D23: 6. 消费量合计 | E23: 热力(万百万千焦) | F23: 8061.8 | I23: 青海省 | J23: 510.6309 | K23: 519.8 | L23: 472.7974 | M23: 539.0925 | N23: 2479.03 | O23: 3329.8133 | P23: 3821.83 | Q23: 4539.16 | R23: 4291.23 | S23: 3521.84 | T23: 4282.52 | X23: 110.6863 | Y23: 553.03 | Z23: 471.61 | AA23: 650.93 | AB23: 734.12 | AC23: 758.93 | AD23: 633.67 | AE23: 696.88 | AF23: 510.62754 | AG23: 519.79 | AH23: 472.7974 | AI23: 618.9653 | AJ23: 2537.67 | AK23: 3765.0362 | AL23: 3842.99 | AM23: 4604.01 | AN23: 4307.7 | AO23: 3553.06 | AP23: 4354.02 | BB23: 90.0564 | BC23: 115.62 | BD23: 172.7974 | BE23: 240.829 | BF23: 1780.5 | BG23: 3004.7161 | BH23: 3273.51 | BI23: 4024.81 | BJ23: 3898.5 | BK23: 2822.5 | BL23: 3485.59 | BM23: 0.24989364 | BN23: 0.3 | BO23: 0.33 | BP23: 0.5 | BX23: 4.6554259 | BY23: 10 | BZ23: 10.5 | CA23: 12.5 | CB23: 91.4 | CC23: 92 | CI23: 22.203513 | CJ23: 30 | CK23: 31.5 | CL23: 41.5 | CM23: 107.43 | CN23: 107.52 | CO23: 102.57 | CP23: 118.08 | CQ23: 118.08 | CR23: 224.66 | CS23: 297.61 | CT23: 82.816603 | CU23: 85 | CV23: 65.6 | CW23: 76.6 | CX23: 233.67 | CY23: 233.76 | CZ23: 112.36 | DA23: 123.15 | DB23: 53.15 | DC23: 95.26 | DD23: 103.56 | DE23: 310.6457 | DF23: 278.87 | DG23: 192.07 | DH23: 247.0363 | DI23: 324.67 | DJ23: 327.04009 | DK23: 354.56 | DL23: 337.96 | DM23: 237.96 | DN23: 410.65 | DO23: 467.26 | DP23: 510.62754 | DQ23: 519.79 | DR23: 472.7974 | DS23: 649.7788 | DT23: 3032.06 | DU23: 3801.4277 | DV23: 4472.76 | DW23: 5273.28 | DX23: 5050.17 | DY23: 4155.51 | DZ23: 4979.39 | EA23: 124008.52
A24: 55242 | B24: 全国 | C24: 2021 | D24: 2.2. 供热 | E24: 热力(万百万千焦) | F24: 726952.12 | I24: 全国 | J24: 317759.06 | K24: 339684.73 | L24: 362112.66 | M24: 374249.96 | N24: 399029.66 | O24: 430506.88 | P24: 464086.42 | Q24: 524417.65 | R24: 565138.68 | S24: 613906.59 | T24: 726952.12 | U24: 36094.7 | V24: 44046.29 | W24: 51008 | X24: 59161.25 | Y24: 62027.49 | Z24: 66195.28 | AA24: 65921.71 | AB24: 96144.18 | AC24: 96598.13 | AD24: 110769.08 | AE24: 125426.04 | AF24: 318574.49 | AG24: 342687.26 | AH24: 360409.21 | AI24: 373319.42 | AJ24: 396778.72 | AK24: 426530.36 | AL24: 453921.46 | AM24: 518100.81 | AN24: 544808.39 | AO24: 591129.64 | AP24: 710502.01 | AQ24: 90.69 | AR24: 113.44 | AS24: 118.56 | AT24: 88.92 | AU24: 106.7 | AV24: 128.04 | AW24: 133.29 | AX24: 68.39 | AY24: 69.88 | AZ24: 111.89 | BA24: 140.9 | BB24: 233393.14 | BC24: 248391.34 | BD24: 261608.62 | BE24: 267494.7 | BF24: 280611.96 | BG24: 301888.68 | BH24: 319820.87 | BI24: 362133.17 | BJ24: 380696.5 | BK24: 412216.71 | BL24: 512220.94 | BM24: 622.57 | BN24: 687.75 | BO24: 779.36 | BP24: 814.12 | BQ24: 903.67 | BR24: 948.86 | BS24: 1060.35 | BT24: 2302.85 | BU24: 2300.23 | BV24: 1933.11 | BW24: 2017.1 | BX24: 1988.8 | BY24: 2265.44 | BZ24: 2289.81 | CA24: 2408.1 | CB24: 2809.72 | CC24: 2641.04 | CD24: 3064.4 | CE24: 3819 | CF24: 4152.02 | CG24: 3904.98 | CH24: 4145.52 | CI24: 4304.56 | CJ24: 4759.13 | CK24: 5065 | CL24: 5730.54 | CM24: 6113.91 | CN24: 7031 | CO24: 7436.19 | CP24: 8962.17 | CQ24: 9533.06 | CR24: 10405.72 | CS24: 11845.87 | CT24: 8130.8 | CU24: 8862.66 | CV24: 9075.92 | CW24: 10300.66 | CX24: 12391.77 | CY24: 15270.13 | CZ24: 16076.39 | DA24: 19130.9 | DB24: 19224.64 | DC24: 21207.86 | DD24: 22113.43 | DE24: 70043.94 | DF24: 77607.5 | DG24: 81471.95 | DH24: 86482.38 | DI24: 93840.97 | DJ24: 98622.61 | DK24: 106329.97 | DL24: 121684.32 | DM24: 128832.05 | DN24: 141349.38 | DO24: 158018.24 | DP24: 353848.91 | DQ24: 383721.84 | DR24: 413102.56 | DS24: 433440.34 | DT24: 461106.64 | DU24: 496544.52 | DV24: 530006.6 | DW24: 620543.22 | DX24: 661736.52 | DY24: 724168.35 | DZ24: 852046.06 | EA24: 21935026
A25: 55251 | B25: 全国 | C25: 2021 | D25: 2.9. 回收能 | E25: 热力(万百万千焦) | F25: 125426.04 | I25: 山东省 | J25: 74049.074 | K25: 76435.85 | L25: 81725.15 | M25: 80254.736 | N25: 89193.7 | O25: 98313.382 | P25: 99226.99 | Q25: 133092.95 | R25: 149885.24 | S25: 161494.34 | T25: 172492.35 | U25: 1078.5965 | V25: 3263.17 | W25: 5909.3259 | X25: 6382.6245 | Y25: 5649.19 | Z25: 6182.1611 | AA25: 6638.4 | AB25: 9804.76 | AC25: 13069.37 | AD25: 9419.89 | AE25: 16257.21 | AF25: 74049.174 | AG25: 77272.39 | AH25: 84168.572 | AI25: 82322.942 | AJ25: 91092.99 | AK25: 100079.96 | AL25: 101030.91 | AM25: 136713.54 | AN25: 155064.31 | AO25: 161527.25 | AP25: 176934.82 | BB25: 60328.989 | BC25: 62096.6 | BD25: 70706.929 | BE25: 67841.523 | BF25: 76097.17 | BG25: 83990.884 | BH25: 82767.15 | BI25: 104441.97 | BJ25: 118819.88 | BK25: 124246.56 | BL25: 142255.73 | BM25: 712.834 | BN25: 819.03 | BO25: 526.13 | BP25: 565.98655 | BQ25: 549.49 | BR25: 565.73 | BS25: 599.75 | BT25: 799.75 | BU25: 840.57 | BV25: 798.54 | BW25: 718.2 | BX25: 464.8283 | BY25: 476 | BZ25: 476 | CA25: 512.05899 | CB25: 529.76 | CC25: 542.75899 | CD25: 569.9 | CE25: 969.9 | CF25: 1099.53 | CG25: 1044.55 | CH25: 835.64 | CI25: 2712.3 | CJ25: 2912 | CK25: 1390.7606 | CL25: 1496.1165 | CM25: 1683.12 | CN25: 1734.5865 | CO25: 2362.95 | CP25: 3323.87 | CQ25: 3732.87 | CR25: 3359.58 | CS25: 3426.77 | CT25: 2984.92 | CU25: 3504 | CV25: 3604 | CW25: 3877.0181 | CX25: 4017.32 | CY25: 4049.43 | CZ25: 4797.68 | DA25: 4597 | DB25: 5150.9 | DC25: 5408.45 | DD25: 3516.61 | DE25: 6845.3025 | DF25: 7464.75 | DG25: 7464.7525 | DH25: 8030.2387 | DI25: 8216.14 | DJ25: 9196.57 | DK25: 9933.48 | DL25: 22581.05 | DM25: 25420.56 | DN25: 26669.57 | DO25: 26181.86 | DP25: 75127.673 | DQ25: 79699.01 | DR25: 87634.476 | DS25: 86637.36 | DT25: 94842.89 | DU25: 104495.54 | DV25: 105865.39 | DW25: 142897.71 | DX25: 162954.61 | DY25: 170914.24 | DZ25: 188749.56 | EA25: 5080150.6
A26: 55253 | B26: 全国 | C26: 2021 | D26: 4. 终端消费量 | E26: 热力(万百万千焦) | F26: 710502.01 | I26: 山西省 | J26: 14472.47 | K26: 16014.55 | L26: 17916.84 | M26: 19810.62 | N26: 23630.29 | O26: 27215.9 | P26: 31548.05 | Q26: 30699.78 | R26: 30981.34 | S26: 31312.23 | T26: 32785.77 | W26: 5653.96 | X26: 6879.54 | Y26: 6282.75 | Z26: 4151.64 | AA26: 2482.85 | AB26: 4497.35 | AC26: 7448.29 | AD26: 8194.99 | AE26: 8328.37 | AF26: 14472.47 | AG26: 16014.55 | AH26: 20872.93 | AI26: 23610.24 | AJ26: 27044 | AK26: 28042.38 | AL26: 30564.89 | AM26: 28897.67 | AN26: 31639.05 | AO26: 30989.68 | AP26: 32192.17 | BB26: 6314.78 | BC26: 6707.58 | BD26: 11619.86 | BE26: 13383.09 | BF26: 14624.26 | BG26: 15318.32 | BH26: 17461.23 | BI26: 16203.5 | BJ26: 16555.23 | BK26: 16417.32 | BL26: 17538.78 | BO26: 17.68 | BP26: 55.36 | BQ26: 255.92 | BR26: 269.18 | BS26: 14.41 | BT26: 52.74 | BU26: 52.95 | BV26: 31.49 | BW26: 28.57 | CC26: 35.54 | CD26: 674.72 | CE26: 707.53 | CF26: 760.28 | CG26: 560.28 | CH26: 537.24 | CI26: 1385 | CJ26: 1935.55 | CK26: 1725 | CL26: 1920.27 | CM26: 2127.12 | CN26: 2174 | CO26: 1443.3 | CP26: 889.98 | CQ26: 926.79 | CR26: 726.79 | CS26: 784.53 | CT26: 1015 | CU26: 1258 | CV26: 986.71 | CW26: 1216.07 | CX26: 1714.7 | CY26: 1880 | CZ26: 2005.89 | DA26: 1443.92 | DB26: 1573.8 | DC26: 1373.8 | DD26: 1403.25 | DE26: 5757.69 | DF26: 6113.42 | DG26: 6523.68 | DH26: 7035.45 | DI26: 8322 | DJ26: 8365.34 | DK26: 8965.34 | DL26: 9600 | DM26: 11770 | DN26: 11880 | DO26: 11899.8 | DP26: 14472.47 | DQ26: 16014.55 | DR26: 23570.8 | DS26: 26690.16 | DT26: 29913.04 | DU26: 31367.54 | DV26: 34030.9 | DW26: 35197.13 | DX26: 38429.63 | DY26: 39507.22 | DZ26: 41114.14 | EA26: 1229295.2
A27: 55254 | B27: 全国 | C27: 2021 | D27: 4.1. 农、林、牧、渔业 | E27: 热力(万百万千焦) | F27: 140.9 | I27: 陕西省 | J27: 6157.4563 | K27: 6996.99 | L27: 7380.8679 | M27: 8113.6386 | N27: 9439.1 | O27: 11135.417 | P27: 12637.69 | Q27: 14510.64 | R27: 15869.36 | S27: 17767.46 | T27: 21476.05 | V27: 1647.32 | W27: 1941.1582 | X27: 2160.8835 | Y27: 2288.76 | Z27: 2595.1452 | AA27: 3919.91 | AB27: 4314.08 | AC27: 6277.91 | AD27: 9220.31 | AE27: 9532.33 | AF27: 5676.1265 | AG27: 7767.36 | AH27: 8240.28 | AI27: 9129.6222 | AJ27: 10385.71 | AK27: 12372.061 | AL27: 14471.94 | AM27: 16374.45 | AN27: 19332.63 | AO27: 22117.37 | AP27: 25812.02 | BB27: 2571.0565 | BC27: 3979.08 | BD27: 4206.36 | BE27: 4506.6614 | BF27: 5397.46 | BG27: 5881.2319 | BH27: 7118.99 | BI27: 8120.28 | BJ27: 10201.33 | BK27: 11471.34 | BL27: 13140.3 | BO27: 40.22 | BP27: 50.56 | BQ27: 46.76 | BR27: 55.54 | BS27: 58.63 | BT27: 63.99 | BU27: 75.53 | BV27: 89.14 | BW27: 96 | BX27: 0.17 | BY27: 0.18 | BZ27: 40.18 | CA27: 42.06 | CB27: 54.91 | CC27: 93.10098 | CD27: 96.1 | CE27: 105.98 | CF27: 134.26 | CG27: 145.12 | CH27: 166.15 | CI27: 97.3 | CJ27: 113.4 | CK27: 128.34 | CL27: 248.22 | CM27: 274.28 | CN27: 527.698 | CO27: 649.76 | CP27: 745.06 | CQ27: 890.58 | CR27: 913.4 | CS27: 1095.89 | CT27: 307.6 | CU27: 352.7 | CV27: 375.92 | CW27: 655.68 | CX27: 712.4 | CY27: 1012.4 | CZ27: 1324.59 | DA27: 1498.3 | DB27: 1833.19 | DC27: 2152.6 | DD27: 2568.41 | DE27: 2700 | DF27: 3322 | DG27: 3449.26 | DH27: 3626.4408 | DI27: 3899.9 | DJ27: 4802.09 | DK27: 5223.88 | DL27: 5840.84 | DM27: 6197.74 | DN27: 7345.76 | DO27: 8745.27 | DP27: 5963.6093 | DQ27: 8417.4 | DR27: 9322.0261 | DS27: 10274.522 | DT27: 11727.86 | DU27: 13730.562 | DV27: 16557.6 | DW27: 18824.72 | DX27: 22147.27 | DY27: 26915.38 | DZ27: 31008.38 | EA27: 653630.95
A28: 55255 | B28: 全国 | C28: 2021 | D28: 4.2. 工业 | E28: 热力(万百万千焦) | F28: 512220.94 | I28: 上海市 | J28: 7375.14 | K28: 7295.16 | L28: 6980.93 | M28: 6674.9857 | N28: 6908.33 | O28: 7046.39 | P28: 6833.75 | Q28: 6303.86 | R28: 6762.38 | S28: 6683.27 | T28: 6535.28 | U28: 339.16 | V28: 405.72 | W28: 4271.57 | X28: 4337.87 | Y28: 4395.28 | Z28: 4006.5 | AA28: 3913.83 | AB28: 3986.69 | AC28: 3986.69 | AD28: 4080.87 | AE28: 4467.97 | AF28: 7665.2933 | AG28: 7661.82 | AH28: 11244.981 | AI28: 10199.545 | AJ28: 10439.19 | AK28: 10159.64 | AL28: 9834.33 | AM28: 9189.22 | AN28: 9599.7 | AO28: 9612.32 | AP28: 9799.78 | AV28: 12.79 | AW28: 12.43 | AZ28: 40.39 | BA28: 55.51 | BB28: 7454.331 | BC28: 7471.54 | BD28: 11078.56 | BE28: 10045.077 | BF28: 10248.84 | BG28: 9962.5 | BH28: 9730.99 | BI28: 9075.6 | BJ28: 9544.06 | BK28: 9449.54 | BL28: 9344.2 | BM28: 3.72896 | BN28: 21.12 | BO28: 19.55 | BP28: 15.64 | BQ28: 17.86 | BR28: 17.86 | BS28: 3.44 | BT28: 3.62 | BU28: 5.4 | BV28: 6.46 | BW28: 8.82 | BX28: 69.69 | BY28: 65.69 | BZ28: 59.74 | CA28: 60.135718 | CB28: 55.65 | CC28: 25 | CD28: 3.86 | CE28: 3.93 | CF28: 1.49 | CG28: 1.24 | CH28: 1.52 | CI28: 48.07 | CJ28: 43.21 | CK28: 38.24 | CL28: 33.19232 | CM28: 32.56 | CN28: 16.87 | CO28: 24.92 | CP28: 23.25 | CQ28: 11.82 | CR28: 14.27 | CS28: 63.91 | CT28: 69.11 | CU28: 60.26 | CV28: 48.75 | CW28: 45.322875 | CX28: 83.95 | CY28: 124.62 | CZ28: 58.69 | DA28: 82.82 | DB28: 36.93 | DC28: 30.94 | DD28: 260.82 | DE28: 20.3633 | DG28: 0.1408 | DH28: 0.1765 | DI28: 0.33 | DN28: 69.48 | DO28: 65 | DP28: 7714.2977 | DQ28: 7700.88 | DR28: 11252.5 | DS28: 11012.858 | DT28: 11303.61 | DU28: 11049.56 | DV28: 10747.73 | DW28: 10290.56 | DX28: 10751.52 | DY28: 10764.14 | DZ28: 10992.96 | EA28: 437983.88
A29: 55257 | B29: 全国 | C29: 2021 | D29: 4.3. 建筑业 | E29: 热力(万百万千焦) | F29: 2017.1 | I29: 四川省 | J29: 3779.14 | K29: 3672.75 | L29: 3530.64 | M29: 6213.89 | N29: 4202.57 | O29: 4140.88 | P29: 4660.62 | Q29: 4815.81 | R29: 5744.29 | S29: 7652.13 | T29: 7546.37 | AB29: 4726.28 | AC29: 6521.76 | AD29: 6522.71 | AE29: 6651.31 | AF29: 3776.14 | AG29: 3668.78 | AH29: 3527.84 | AI29: 6208.49 | AJ29: 4187.62 | AK29: 4124.34 | AL29: 4638.77 | AM29: 5998.12 | AN29: 8293.08 | AO29: 10109.4 | AP29: 10041.5 | BB29: 3776.14 | BC29: 3668.78 | BD29: 3527.84 | BE29: 6208.49 | BF29: 4187.62 | BG29: 4124.34 | BH29: 4638.77 | BI29: 5998.12 | BJ29: 8293.08 | BK29: 10109.4 | BL29: 10041.5 | DP29: 3779.14 | DQ29: 3672.75 | DR29: 3530.64 | DS29: 6213.89 | DT29: 4202.57 | DU29: 4140.88 | DV29: 4660.62 | DW29: 9542.08 | DX29: 12266.05 | DY29: 14174.84 | DZ29: 14197.68 | EA29: 289910.45
A30: 55258 | B30: 全国 | C30: 2021 | D30: 4.4. 交通运输、仓储和邮政业 | E30: 热力(万百万千焦) | F30: 4145.52 | I30: 天津市 | J30: 16999.62 | K30: 18958 | L30: 19059 | M30: 19459.8 | N30: 19877.26 | O30: 19820.07 | P30: 20425.22 | Q30: 21414.33 | R30: 22270.9 | S30: 21711.67 | T30: 21158.49 | U30: 210.06 | V30: 302 | W30: 541.81 | X30: 550.69 | Y30: 553.69 | Z30: 497.9 | AA30: 909.7 | AB30: 1178.15 | AC30: 1525.68 | AD30: 2444.78 | AE30: 2024.22 | AF30: 17166.81 | AG30: 19212.29 | AH30: 19360.75 | AI30: 19701.73 | AJ30: 20092.72 | AK30: 20059.73 | AL30: 20818.01 | AM30: 21884.55 | AN30: 23014.01 | AO30: 22738.85 | AP30: 21988.95 | BB30: 8579.47 | BC30: 9697.15 | BD30: 9322.85 | BE30: 9053.27 | BF30: 8600.61 | BG30: 8251.21 | BH30: 8172.49 | BI30: 8442.11 | BJ30: 9534.61 | BK30: 9907.55 | BL30: 9109.08 | BM30: 79.4 | BN30: 75.83 | BO30: 76.97 | BP30: 78.22 | BQ30: 77.87 | BR30: 75.69 | BS30: 77.27 | BT30: 71.16 | BU30: 69.96 | BV30: 72.43 | BW30: 75.76 | BX30: 144.86 | BY30: 146.31 | BZ30: 132.62 | CA30: 151.49 | CB30: 187.95 | CC30: 210.73 | CD30: 299.92 | CE30: 312.42 | CF30: 316.98 | CG30: 336.22 | CH30: 365.47 | CI30: 508.25 | CJ30: 502 | CK30: 347.14 | CL30: 390.31 | CM30: 442.09 | CN30: 363.04 | CO30: 386.46 | CP30: 407.92 | CQ30: 370.47 | CR30: 432.41 | CS30: 422.38 | CT30: 943 | CU30: 1056 | CV30: 1119.36 | CW30: 1301.81 | CX30: 1471.8 | CY30: 1546.3 | CZ30: 1663.51 | DA30: 1784.04 | DB30: 1930.49 | DC30: 2176.82 | DD30: 2309.61 | DE30: 6911.83 | DF30: 7735 | DG30: 8361.81 | DH30: 8726.63 | DI30: 9312.4 | DJ30: 9612.76 | DK30: 10218.36 | DL30: 10866.9 | DM30: 10791.5 | DN30: 9813.42 | DO30: 9706.65 | DP30: 17208.81 | DQ30: 19260.29 | DR30: 19600.81 | DS30: 20010.49 | DT30: 20430.95 | DU30: 20317.97 | DV30: 21334.92 | DW30: 22592.48 | DX30: 23796.58 | DY30: 24156.45 | DZ30: 23182.71 | EA30: 915862.3
A31: 55259 | B31: 全国 | C31: 2021 | D31: 4.5. 批发、零售业和住宿、餐饮业 | E31: 热力(万百万千焦) | F31: 11845.87 | I31: 新疆维吾尔自治区 | J31: 21898.57 | K31: 22044.69 | L31: 28331.56 | M31: 28294.93 | N31: 32556.61 | O31: 35741.06 | P31: 40042.11 | Q31: 48728.67 | R31: 52961.83 | S31: 57507.43 | T31: 68616.68 | V31: 651.89 | Z31: 862.24 | AA31: 1025.15 | AB31: 2029.88 | AC31: 4205.91 | AD31: 4732.5 | AE31: 7180.93 | AF31: 21898.57 | AG31: 22696.58 | AH31: 27428.51 | AI31: 27411.01 | AJ31: 31648.67 | AK31: 35749.27 | AL31: 39949.6 | AM31: 49677.03 | AN31: 53870.01 | AO31: 58393.2 | AP31: 71125.33 | AQ31: 10 | AV31: 108 | AW31: 110 | AX31: 20 | AY31: 20 | AZ31: 20.9 | BA31: 22.55 | BB31: 9513 | BC31: 9627.77 | BD31: 11354.88 | BE31: 11162.03 | BF31: 13036.12 | BG31: 13534.53 | BH31: 16732.19 | BI31: 23632.13 | BJ31: 26432.97 | BK31: 29674.07 | BL31: 38622.04 | BM31: 30 | BN31: 30 | BO31: 28 | BP31: 28 | BQ31: 28.7 | BR31: 34.3 | BS31: 32.3 | BT31: 32.3 | BU31: 32.3 | BV31: 33.31 | BW31: 35.24 | BX31: 39 | BY31: 39 | BZ31: 80 | CA31: 70.01 | CB31: 89 | CC31: 90 | CD31: 100 | CE31: 110 | CF31: 110 | CG31: 127.49 | CH31: 145.98 | CI31: 123.3 | CJ31: 120 | CK31: 320 | CL31: 300.2 | CM31: 400.33 | CN31: 3743.2 | CO31: 3843.2 | CP31: 3843.2 | CQ31: 3843.2 | CR31: 4063.11 | CS31: 4473.48 | CT31: 80 | CU31: 84 | CV31: 134 | CW31: 134.4 | CX31: 177 | CY31: 3415 | CZ31: 3515 | DA31: 4448.68 | DB31: 4448.68 | DC31: 4687.49 | DD31: 4940.6 | DE31: 12103.27 | DF31: 12795.81 | DG31: 15511.63 | DH31: 15716.37 | DI31: 17917.52 | DJ31: 14824.24 | DK31: 15616.91 | DL31: 17590.72 | DM31: 18982.86 | DN31: 19786.83 | DO31: 22885.44 | DP31: 21898.57 | DQ31: 22696.58 | DR31: 28331.56 | DS31: 28294.93 | DT31: 32556.61 | DU31: 36603.3 | DV31: 41067.26 | DW31: 50758.55 | DX31: 57167.74 | DY31: 62239.93 | DZ31: 75797.61 | EA31: 1794520.8
A32: 55260 | B32: 全国 | C32: 2021 | D32: 4.6. 其他 | E32: 热力(万百万千焦) | F32: 22113.43 | I32: 云南省 | J32: 507.07 | K32: 485.41 | L32: 441.9213 | M32: 421.97 | N32: 304.12 | O32: 380.15 | P32: 856.9 | Q32: 1167.86 | R32: 1264.02 | S32: 1393.61 | T32: 1599.32 | U32: 1924.78 | V32: 1942.62 | W32: 1436.75 | X32: 1682.7077 | Y32: 2286.44 | Z32: 3439.76 | AA32: 3483.49 | AB32: 4353.88 | AC32: 4961.03 | AD32: 5609.13 | AE32: 6462.48 | AF32: 1167.61 | AG32: 1197.38 | AH32: 614.0739 | AI32: 598.55774 | AJ32: 543.12 | AK32: 426.2079 | AL32: 876.36 | AM32: 1134.06 | AN32: 1470.31 | AO32: 1899.09 | AP32: 2557.8 | BB32: 1166.11 | BC32: 1195.47 | BD32: 611.9729 | BE32: 595.88655 | BF32: 540.4 | BG32: 423.38 | BH32: 873.4 | BI32: 1131.02 | BJ32: 1467.18 | BK32: 1897.02 | BL32: 2555.8 | CJ32: 1.91 | CK32: 2.101 | CL32: 2.6711886 | CM32: 2.73 | CN32: 2.8279005 | CO32: 2.96 | CP32: 3.04 | CQ32: 3.13 | CR32: 1.01 | CS32: 1 | CT32: 1.5 | DC32: 1.06 | DD32: 1 | DP32: 2431.84 | DQ32: 2428.03 | DR32: 1878.6739 | DS32: 2104.6777 | DT32: 2604.41 | DU32: 3832.9679 | DV32: 4353.78 | DW32: 5536.24 | DX32: 6232.61 | DY32: 7002.74 | DZ32: 8061.8 | EA32: 117842.34
A33: 55261 | B33: 全国 | C33: 2021 | D33: 4.7. 生活消费 | E33: 热力(万百万千焦) | F33: 158018.24 | I33: 浙江省 | J33: 43278.4 | K33: 44157.65 | L33: 38851.968 | M33: 39043.813 | N33: 43645.78 | O33: 48084.091 | P33: 51964.95 | Q33: 57042.25 | R33: 58537.79 | S33: 56658.85 | T33: 61189.37 | U33: 3547.7927 | V33: 4150.73 | W33: 4066.7713 | X33: 5045.2945 | Y33: 5399.68 | Z33: 5242.5958 | AA33: 5411.13 | AB33: 6470.19 | AC33: 7843.28 | AD33: 8511.99 | AE33: 10538.04 | AF33: 41965.776 | AG33: 43327.95 | AH33: 38291.768 | AI33: 39044.162 | AJ33: 43687.75 | AK33: 47393.253 | AL33: 51404.21 | AM33: 56501.24 | AN33: 58549.17 | AO33: 56977.39 | AP33: 62271.79 | BB33: 34665.776 | BC33: 36271.18 | BD33: 33808.276 | BE33: 34585.595 | BF33: 38926.75 | BG33: 42481.245 | BH33: 46105.31 | BI33: 50903.11 | BJ33: 52925.9 | BK33: 51329.65 | BL33: 57824.04 | BX33: 7 | BY33: 4.77 | BZ33: 4.4921 | CA33: 8.5671 | CB33: 11 | CC33: 4.6679 | CD33: 3.9 | CE33: 3.13 | CF33: 3.27 | CG33: 2.74 | CH33: 2.74 | CI33: 5593 | CJ33: 5534 | CK33: 3395 | CL33: 3300 | CM33: 3500 | CN33: 3607.34 | CO33: 3845 | CP33: 4045 | CQ33: 4060 | CR33: 4070 | CS33: 3070.01 | CT33: 1700 | CU33: 1518 | CV33: 1084 | CW33: 1150 | CX33: 1250 | CY33: 1300 | CZ33: 1450 | DA33: 1550 | DB33: 1560 | DC33: 1575 | DD33: 1375 | DP33: 46826.161 | DQ33: 48308.39 | DR33: 42918.74 | DS33: 44089.106 | DT33: 49045.46 | DU33: 53326.691 | DV33: 57376.08 | DW33: 63512.43 | DX33: 66381.07 | DY33: 65170.84 | DZ33: 71727.41 | EA33: 2296193.7
A34: 55265 | B34: 全国 | C34: 2021 | D34: 6. 消费量合计 | E34: 热力(万百万千焦) | F34: 852046.06 | I34: 重庆市 | J34: 2651.1007 | K34: 4101.96 | L34: 4225.95 | M34: 4447.59 | N34: 4325.1 | O34: 4596.73 | P34: 4979.8 | Q34: 5109.17 | R34: 5255.99 | S34: 5366.22 | T34: 7549.11 | U34: 533.36 | V34: 1509.46 | W34: 1947.16 | X34: 1858.53 | Y34: 1390.2 | Z34: 1281.96 | AB34: 2168.67 | AC34: 2798.64 | AD34: 2708.9 | AE34: 3711.19 | AF34: 2608.779 | AG34: 5487.84 | AH34: 3601.83 | AI34: 4167.53 | AJ34: 3726.62 | AK34: 4034.53 | AL34: 3082.86 | AM34: 4951.35 | AN34: 5350.3 | AO34: 5366.22 | AP34: 7655.09 | BB34: 2608.779 | BC34: 5487.84 | BD34: 3601.83 | BE34: 4167.53 | BF34: 3726.62 | BG34: 4034.53 | BH34: 3082.86 | BI34: 4951.35 | BJ34: 5350.3 | BK34: 5366.22 | BL34: 7655.09 | DP34: 3184.4602 | DQ34: 5611.42 | DR34: 6173.11 | DS34: 6306.12 | DT34: 5715.3 | DU34: 5878.69 | DV34: 4979.8 | DW34: 7277.83 | DX34: 8054.63 | DY34: 8075.12 | DZ34: 11260.3 | EA34: 245099.47
A35: 55277 | B35: 内蒙古自治区 | C35: 2021 | D35: 2.2. 供热 | E35: 热力(万百万千焦) | F35: 66287.7 | I35: 总计 | J35: 797162.18 | K35: 845718.62 | L35: 897873.93 | M35: 921200.17 | N35: 981220.58 | O35: 1047403.8 | P35: 1123813.3 | Q35: 1279853.5 | R35: 1379234.7 | S35: 1494648.9 | T35: 1690100 | U35: 60753.312 | V35: 84250.14 | W35: 121922.52 | X35: 138984.74 | Y35: 145271.65 | Z35: 158444.28 | AA35: 164678.11 | AB35: 259552.99 | AC35: 258157.47 | AD35: 286864 | AE35: 324347.04 | AF35: 798920.94 | AG35: 856390.71 | AH35: 916103.87 | AI35: 935110.5 | AJ35: 992966.9 | AK35: 1066581.2 | AL35: 1132395.6 | AM35: 1335007.7 | AN35: 1401740.5 | AO35: 1506333.6 | AP35: 1718343.7 | AQ35: 785.95 | AR35: 954.93 | AS35: 830.42755 | AT35: 128.72112 | AU35: 246.06 | AV35: 398.42 | AW35: 509.83 | AX35: 136.78 | AY35: 139.76 | AZ35: 223.78 | BA35: 281.8 | BB35: 561012.12 | BC35: 594121.6 | BD35: 649462.38 | BE35: 650371.33 | BF35: 680658.02 | BG35: 727981.96 | BH35: 771117.95 | BI35: 898546.15 | BJ35: 943493.47 | BK35: 1005380.9 | BL35: 1179887.5 | BM35: 2296.5857 | BN35: 2530.27 | BO35: 2247.7331 | BP35: 2347.9533 | BQ35: 2615.7 | BR35: 2744.775 | BS35: 3067.33 | BT35: 7734.96 | BU35: 7726.17 | BV35: 4997.24 | BW35: 5214.38 | BX35: 5761.8082 | BY35: 7291.22 | BZ35: 6162.687 | CA35: 6129.4625 | CB35: 7376.56 | CC35: 6854.9073 | CD35: 7953.81 | CE35: 10771.15 | CF35: 11453.7 | CG35: 13984.54 | CH35: 14662.89 | CI35: 21208.927 | CJ35: 23481.45 | CK35: 19773.113 | CL35: 22371.59 | CM35: 23867.77 | CN35: 28834.869 | CO35: 30496.58 | CP35: 38872.03 | CQ35: 41348.14 | CR35: 45133.18 | CS35: 51381.19 | CT35: 29708.788 | CU35: 31555.9 | CV35: 30794.905 | CW35: 34861.474 | CX35: 41298.79 | CY35: 49959.609 | CZ35: 49921.06 | DA35: 67359.04 | DB35: 67688.87 | DC35: 74671.47 | DD35: 77857.75 | DE35: 178146.77 | DF35: 196455.32 | DG35: 206832.63 | DH35: 218899.97 | DI35: 236904 | DJ35: 249806.65 | DK35: 269329.07 | DL35: 311587.53 | DM35: 329890.34 | DN35: 361942.46 | DO35: 389058.16 | DP35: 862500.15 | DQ35: 932634.99 | DR35: 1021693 | DS35: 1061736.4 | DT35: 1127539.2 | DU35: 1206537.3 | DV35: 1285103.2 | DW35: 1539880 | DX35: 1637119.8 | DY35: 1776479.6 | DZ35: 2008603.1 | EA35: 54241073
A36: 55286 | B36: 内蒙古自治区 | C36: 2021 | D36: 2.9. 回收能 | E36: 热力(万百万千焦) | F36: 11435.51
A37: 55288 | B37: 内蒙古自治区 | C37: 2021 | D37: 4. 终端消费量 | E37: 热力(万百万千焦) | F37: 71320.28
A38: 55289 | B38: 内蒙古自治区 | C38: 2021 | D38: 4.1. 农、林、牧、渔业 | E38: 热力(万百万千焦) | F38: 49.97
A39: 55290 | B39: 内蒙古自治区 | C39: 2021 | D39: 4.2. 工业 | E39: 热力(万百万千焦) | F39: 28046.87
A40: 55292 | B40: 内蒙古自治区 | C40: 2021 | D40: 4.3. 建筑业 | E40: 热力(万百万千焦) | F40: 270.08
...

Sheet Statistical Yearbook Data
A1: 地区 | B1: 年份 | C1: 热值/万吉焦 | F1: 求和项:热值/万吉焦 | G1: 列标签
A2: 北京市 | B2: 2020 | C2: 19189 | F2: 行标签 | G2: 2011 | H2: 2012 | I2: 2013 | J2: 2014 | K2: 2015 | L2: 2016 | M2: 2017 | N2: 2018 | O2: 2019 | P2: 2020 | Q2: 2021 | R2: 总计
A3: 天津市 | B3: 2020 | C3: 18139 | F3: 安徽省 | G3: 2602 | H3: 2911 | I3: 3111 | J3: 2916 | K3: 2987 | L3: 1526 | M3: 1592 | N3: 1311 | O3: 3280 | P3: 3466 | Q3: 3892 | R3: 29594
A4: 河北省 | B4: 2020 | C4: 35097 | F4: 北京市 | G4: 36028 | H4: 35511 | I4: 34128 | J4: 35466 | K4: 36023 | L4: 37734 | M4: 25043 | N4: 20350 | O4: 18995 | P4: 19189 | Q4: 19614 | R4: 318081
A5: 山西省 | B5: 2020 | C5: 26754 | F5: 福建省 | G5: 0 | H5: 0 | I5: 0 | J5: 0 | K5: 0 | L5: 0 | M5: 0 | N5: 0 | O5: 0 | P5: 0 | Q5: 0 | R5: 0
A6: 内蒙古自治区 | B6: 2020 | C6: 35659 | F6: 甘肃省 | G6: 0 | H6: 7874 | I6: 12450 | J6: 9263 | K6: 9160 | L6: 10259 | M6: 10787 | N6: 11101 | O6: 12498 | P6: 12967 | Q6: 12783 | R6: 109142
A7: 辽宁省 | B7: 2020 | C7: 63191 | F7: 广东省 | G7: 0 | H7: 0 | I7: 0 | J7: 0 | K7: 0 | L7: 0 | M7: 0 | N7: 0 | O7: 0 | P7: 0 | Q7: 0 | R7: 0
A8: 吉林省 | B8: 2020 | C8: 28554 | F8: 广西壮族自治区 | G8: 0 | H8: 0 | I8: 0 | J8: 0 | K8: 0 | L8: 0 | M8: 0 | N8: 0 | O8: 0 | P8: 0 | Q8: 0 | R8: 0
A9: 黑龙江省 | B9: 2020 | C9: 45385 | F9: 贵州省 | G9: 0 | H9: 0 | I9: 0 | J9: 0 | K9: 0 | L9: 0 | M9: 0 | N9: 0 | O9: 0 | P9: 0 | Q9: 57 | R9: 57
A10: 上海市 | B10: 2020 | C10: 0 | F10: 海南省 | G10: 0 | H10: 0 | I10: 0 | J10: 0 | K10: 0 | L10: 0 | M10: 0 | N10: 0 | O10: 0 | P10: 0 | Q10: 0 | R10: 0
A11: 江苏省 | B11: 2020 | C11: 0 | F11: 河北省 | G11: 22806 | H11: 22687 | I11: 23329 | J11: 24828 | K11: 26334 | L11: 28143 | M11: 29607 | N11: 34218 | O11: 35022 | P11: 35097 | Q11: 35372 | R11: 317443
A12: 浙江省 | B12: 2020 | C12: 0 | F12: 河南省 | G12: 6091 | H12: 6192 | I12: 6853 | J12: 8722 | K12: 9373 | L12: 10511 | M12: 12647 | N12: 14956 | O12: 16620 | P12: 19524 | Q12: 18722 | R12: 130211
A13: 安徽省 | B13: 2020 | C13: 3466 | F13: 黑龙江省 | G13: 29118 | H13: 30269 | I13: 35411 | J13: 37979 | K13: 39182 | L13: 40467 | M13: 42496 | N13: 43182 | O13: 43680 | P13: 45385 | Q13: 46218 | R13: 433387
A14: 福建省 | B14: 2020 | C14: 0 | F14: 湖北省 | G14: 784 | H14: 934 | I14: 1012 | J14: 1323 | K14: 1785 | L14: 0 | M14: 749 | N14: 696 | O14: 756 | P14: 1036 | Q14: 1637 | R14: 10712
... A34: 天津市 | B34: 2019 | C34: 17688 | F34: 总计 | G34: 269452 | H34: 289514 | I34: 319284 | J34: 320749 | K34: 345913 | L34: 357840 | M34: 363029 | N34: 375840 | O34: 387281 | P34: 404398 | Q34: 425878 | R34: 3859178
A35: 河北省 | B35: 2019 | C35: 35022
A36: 山西省 | B36: 2019 | C36: 24935
A37: 内蒙古自治区 | B37: 2019 | C37: 33943
A38: 辽宁省 | B38: 2019 | C38: 57475
A39: 吉林省 | B39: 2019 | C39: 27466
A40: 黑龙江省 | B40: 2019 | C40: 43680
A41: 上海市 | B41: 2019 | C41: 0
A42: 江苏省 | B42: 2019 | C42: 0
A43: 浙江省 | B43: 2019 | C43: 0
A44: 安徽省 | B44: 2019 | C44: 3280
A45: 福建省 | B45: 2019 | C45: 0
A46: 江西省 | B46: 2019 | C46: 0
... A652: 新疆维吾尔自治区 | B652: 2021 | C652: 24458

Sheet CHP Data
C1: CHP Capacity | N1: CHP Heat Generation | Y1: Electricity self-consumed by CHP | AJ1: Electricity consumed internally per unit heat generated | AU1: standard coal equivalent energy use per unit heat generated | BF1: coal consumption | BQ1: standard coal equivalent consumption
C2: (10 MW) | N2: (Giga Joule) | Y2: (10MWh) | AJ2: (KWh/GJ) | AU2: (kgce/GJ) | BF2: (10000ton) | BQ2: (10000tce)
C3: 2011 | D3: 2012 | E3: 2013 | F3: 2014 | G3: 2015 | H3: 2016 | I3: 2017 | J3: 2018 | K3: 2019 | L3: 2020 | M3: 2021 | N3: 2011 | O3: 2012 | P3: 2013 | Q3: 2014 | R3: 2015 | S3: 2016 | T3: 2017 | U3: 2018 | V3: 2019 | W3: 2020 | X3: 2021 | Y3: 2011 | Z3: 2012 | AA3: 2013 | AB3: 2014 | AC3: 2015 | AD3: 2016 | AE3: 2017 | AF3: 2018 | AG3: 2019 | AH3: 2020 | AI3: 2021 | AJ3: 2011 | AK3: 2012 | AL3: 2013 | AM3: 2014 | AN3: 2015 | AO3: 2016 | AP3: 2017 | AQ3: 2018 | AR3: 2019 | AS3: 2020 | AT3: 2021 | AU3: 2011 | AV3: 2012 | AW3: 2013 | AX3: 2014 | AY3: 2015 | AZ3: 2016 | BA3: 2017 | BB3: 2018 | BC3: 2019 | BD3: 2020 | BE3: 2021 | BF3: 2011 | BG3: 2012 | BH3: 2013 | BI3: 2014 | BJ3: 2015 | BK3: 2016 | BL3: 2017 | BM3: 2018 | BN3: 2019 | BO3: 2020 | BP3: 2021 | BQ3: 2011 | BR3: 2012 | BS3: 2013 | BT3: 2014 | BU3: 2015 | BV3: 2016 | BW3: 2017 | BX3: 2018 | BY3: 2019 | BZ3: 2020 | CA3: 2021
B4: 地区 | C4: 供热容量（万千瓦） | D4: 供热容量（万千瓦） | E4: 供热容量（万千瓦） | F4: 供热容量（万千瓦） | G4: 供热容量（万千瓦） | H4: 供热容量（万千瓦） | I4: 供热容量（万千瓦） | J4: 供热容量（万千瓦） | K4: 供热容量（万千瓦） | L4: 供热容量（万千瓦） | M4: 供热容量（万千瓦） | N4: 供热量（吉焦） | O4: 供热量（吉焦） | P4: 供热量（吉焦） | Q4: 供热量（吉焦） | R4: 供热量（吉焦） | S4: 供热量（吉焦） | T4: 供热量（吉焦） | U4: 供热量（吉焦） | V4: 供热量（吉焦） | W4: 供热量（吉焦） | X4: 供热量（吉焦） | Y4: 厂用电量（万千瓦时） | Z4: 厂用电量（万千瓦时） | AA4: 厂用电量（万千瓦时） | AB4: 厂用电量（万千瓦时） | AC4: 厂用电量（万千瓦时） | AD4: 厂用电量（万千瓦时） | AE4: 厂用电量（万千瓦时） | AF4: 厂用电量（万千瓦时） | AG4: 厂用电量（万千瓦时） | AH4: 厂用电量（万千瓦时） | AI4: 厂用电量（万千瓦时） | AJ4: 厂用电率（千瓦时/吉焦） | AK4: 厂用电率（千瓦时/吉焦） | AL4: 厂用电率（千瓦时/吉焦） | AM4: 厂用电率（千瓦时/吉焦） | AN4: 厂用电率（千瓦时/吉焦） | AO4: 厂用电率（千瓦时/吉焦） | AP4: 厂用电率（千瓦时/吉焦） | AQ4: 厂用电率（千瓦时/吉焦） | AR4: 厂用电率（千瓦时/吉焦） | AS4: 厂用电率（千瓦时/吉焦） | AT4: 厂用电率（千瓦时/吉焦） | AU4: 供热标准煤耗（千克/吉焦） | AV4: 供热标准煤耗（千克/吉焦） | AW4: 供热标准煤耗（千克/吉焦） | AX4: 供热标准煤耗（千克/吉焦） | AY4: 供热标准煤耗（千克/吉焦） | AZ4: 供热标准煤耗（千克/吉焦） | BA4: 供热标准煤耗（千克/吉焦） | BB4: 供热标准煤耗（千克/吉焦） | BC4: 供热标准煤耗（千克/吉焦） | BD4: 供热标准煤耗（千克/吉焦） | BE4: 供热标准煤耗（千克/吉焦） | BF4: 供热消耗原煤量（万吨） | BG4: 供热消耗原煤量（万吨） | BH4: 供热消耗原煤量（万吨） | BI4: 供热消耗原煤量（万吨） | BJ4: 供热消耗原煤量（万吨） | BK4: 供热消耗原煤量（万吨） | BL4: 供热消耗原煤量（万吨） | BM4: 供热消耗原煤量（万吨） | BN4: 供热消耗原煤量（万吨） | BO4: 供热消耗原煤量（万吨） | BP4: 供热消耗原煤量（万吨） | BQ4: 供热消耗标煤量（万吨） | BR4: 供热消耗标煤量（万吨） | BS4: 供热消耗标煤量（万吨） | BT4: 供热消耗标煤量（万吨） | BU4: 供热消耗标煤量（万吨） | BV4: 供热消耗标煤量（万吨） | BW4: 供热消耗标煤量（万吨） | BX4: 供热消耗标煤量（万吨） | BY4: 供热消耗标煤量（万吨） | BZ4: 供热消耗标煤量（万吨） | CA4: 供热消耗标煤量（万吨）
