Workbook

Sheet About
A1: AVL Avg Vehicle Lifetime 交通工具平均报废车龄
C2: 问题：规定标准的报废寿命？还是平均实际使用寿命？
A3: Sources: | B3: Passenger LDV
B4: 中国汽车技术研究中心有限公司、中汽研（天津）汽车信息咨询有限公司
B5: 2020
B6: 中国汽车产业2019年总结及2020年展望
B7: http://pdf.dfcfw.com/pdf/H3_AP202001141374061121_1.pdf
B8: Page 12
B10: Freight LDVs
B11: 商务部条约法律司
B12: 2013
B13: 机动车强制报废标准规定
B14: http://www.rita.dot.gov/bts/sites/rita.dot.gov.bts/files/publications/national_transportation_statistics/index.html
B15: https://baike.baidu.com/reference/6068667/84ectqzrlqbfO3_-cGZWnJy4qkolxFAkrN6EjaVPtrmESKiWGHz2RHHcZgiv9E0-WMV7PplY0BCYBoARtiis7N-GIfJppDA1sBFe7CClLl42BZUQ_UG3ZcBmJJmG
B17: Freight HDVs
B18: Industrial Securities兴业证券
B19: 2020
B20: 商用载货车行业：从更新和新增角度定量研判重卡的短中长期趋势，景气持续，中枢提升，波动下降
B21: http://m.hibor.com.cn/wap_detail.aspx?id=cb60fbe320b08ccfb8c6548810333d0f
B22: Table 3-14, Row 43
B24: 机动车强制报废标准规定
B25: https://baike.baidu.com/reference/6068667/84ectqzrlqbfO3_-cGZWnJy4qkolxFAkrN6EjaVPtrmESKiWGHz2RHHcZgiv9E0-WMV7PplY0BCYBoARtiis7N-GIfJppDA1sBFe7CClLl42BZUQ_UG3ZcBmJJmG
B27: 东兴证券
B28: 2020
B29: 汽车行业：乘风破浪的重卡市场，高景气度未完待续
B30: http://pdf.dfcfw.com/pdf/H3_AP202006231386758550_1.pdf
B32: Passenger HDVs (Buses)
B33: 中国汽车技术研究中心有限公司、中汽研（天津）汽车信息咨询有限公司
B34: 2020
B35: 中国汽车产业2019年总结及2020年展望
B36: http://pdf.dfcfw.com/pdf/H3_AP202001141374061121_1.pdf
B37: Page 12
B39: aircraft
B40: Jiang, Helen. Boeing.
B41: 2013
B42: Key Findings on Airplane Economic Life
B43: http://www.boeing.com/assets/pdf/commercial/aircraft_economic_life_whitepaper.pdf
B44: Exhibits 1-3
B45: 阜阳市人民政府网站
B46: https://www.fy.gov.cn/openness/detail/content/5de779607f8b9aab4b8b4568.html
...

Sheet China
A2: Passenger LDVs and HDVs
I27: 2004-2018年我国汽车销量和汽车保有量，数据来源：中汽协和公安部网站
A30: Freight LDVs and HDVs
A56: 营运类的汽车一般8年或者60万公里就要强制报废 原文網址：https://kknews.cc/news/gppjk58.html
A57: 通过预测重卡保有量的增量以及报废周期（估计为平均8年） | E57: http://m.hibor.com.cn/wap_detail.aspx?id=cb60fbe320b08ccfb8c6548810333d0f
A81: 2019年11月26日，由商务部市场建设司授权中国汽车技术研究中心有限公司组织的《机动车强制报废标准规定》（以下简称《规定》）修订研究工作正式开启，这也意味着未来机动车强制报废管理会发生变化。
A82: 随着商用车技术的进步，现在的卡车质量远强于十几年前，因此，国家规定15年的强制报废年限，对于车来说完全可以跑15年。
A83: 随着国三、国四、国五、国六切换速度的加快，并且受环保因素影响，卡车强制报废年限缩短，可能跑7-8年就被强制报废
A84: 皮卡车型政策放宽报废执行乘用车的标准在我国，皮卡属于轻型货车，在对皮卡车型的报废标准方面，规定使用年限15年或者行驶里程达到60万公里就要强制报废。目前，随着多地区解禁皮卡，政策逐渐放宽，但是在强制报废规定中皮卡依然归属于普通货车范围。
A88: Rail
A99: 船舶

Sheet NTS 1-20
A1: Table 1-20: Productions, Production Shares, and Production-Weighted Fuel Economies of New Domestic and Imported Automobiles (Thousands of vehicles)
B2: 1980 | C2: 1985 | D2: 1990 | E2: 1991 | F2: 1992 | G2: 1993 | H2: 1994 | I2: 1995 | J2: 1996 | K2: 1997 | L2: 1998 | M2: 1999 | N2: 2000 | O2: 2001 | P2: 2002 | Q2: 2003 | R2: 2004 | S2: 2005 | T2: 2006 | U2: 2007 | V2: 2008 | W2: 2009 | X2: 2010 | Y2: 2011 | Z2: 2012 | AA2: 2013 | AB2: 2014
A3: TOTAL productions | B3: 11306 | C3: 14460 | D3: 12615 | E3: 12573 | F3: 12172 | G3: 13211 | H3: 14125 | I3: 15145 | J3: 13144 | K3: 14458 | L3: 14456 | M3: 15215 | N3: 16571 | O3: 15605 | P3: 16115 | Q3: 15773 | R3: 15709 | S3: 15892 | T3: 15104 | U3: 15276 | V3: 13898 | W3: 9316 | X3: 11110 | Y3: 12003 | Z3: 13438 | AA3: 14846 | AB3: N
A4: Car | B4: 9443 | C4: 10791 | D4: 8810 | E4: 8524 | F4: 8108 | G4: 8456 | H4: 8415 | I4: 9396 | J4: 7890 | K4: 8334 | L4: 7971 | M4: 8376 | N4: 9125 | O4: 8405 | P4: 8301 | Q4: 7921 | R4: 7537 | S4: 8027 | T4: 7993 | U4: 8082 | V4: 7319 | W4: 5636 | X4: 6055 | Y4: 5728 | Z4: 7379 | AA4: 7907 | AB4: N
A5: Car SUV | B5: 0 | C5: 88 | D5: 65 | E5: 224 | F5: 243 | G5: 473 | H5: 332 | I5: 220 | J5: 287 | K5: 361 | L5: 454 | M5: 488 | N5: 617 | O5: 743 | P5: 603 | Q5: 575 | R5: 639 | S5: 813 | T5: 751 | U5: 919 | V5: 924 | W5: 608 | X5: 915 | Y5: 1207 | Z5: 1269 | AA5: 1470 | AB5: N
A6: Pickup | B6: 1437 | C6: 2078 | D6: 1835 | E6: 1920 | F6: 1840 | G6: 2002 | H6: 2669 | I6: 2271 | J6: 1955 | K6: 2408 | L6: 2415 | M6: 2544 | N6: 2612 | O6: 2519 | P6: 2380 | Q6: 2474 | R6: 2505 | S6: 2300 | T6: 2188 | U6: 2113 | V6: 1794 | W6: 989 | X6: 1276 | Y6: 1479 | Z6: 1357 | AA6: 1577 | AB6: N
A7: Van | B7: 242 | C7: 855 | D7: 1262 | E7: 1034 | F7: 1221 | G7: 1441 | H7: 1418 | I7: 1662 | J7: 1409 | K7: 1265 | L7: 1489 | M7: 1463 | N7: 1691 | O7: 1232 | P7: 1243 | Q7: 1232 | R7: 953 | S7: 1481 | T7: 1166 | U7: 847 | V7: 790 | W7: 368 | X7: 559 | Y7: 521 | Z7: 661 | AA7: 571 | AB7: N
A8: Truck SUV | B8: 184 | C8: 648 | D8: 643 | E8: 871 | F8: 761 | G8: 838 | H8: 1291 | I8: 1596 | J8: 1603 | K8: 2089 | L8: 2127 | M8: 2342 | N8: 2526 | O8: 2707 | P8: 3588 | Q8: 3571 | R8: 4075 | S8: 3272 | T8: 3006 | U8: 3314 | V8: 3072 | W8: 1713 | X8: 2305 | Y8: 3069 | Z8: 2773 | AA8: 3321 | AB8: N
A9: Market share, percent
A10: Car | B10: =B4/B$3*100 -> 83.522024 | C10: =C4/C$3*100 -> 74.626556 | D10: 69.8 | E10: 67.8 | F10: 66.6 | G10: 64 | H10: 59.6 | I10: 62 | J10: 60 | K10: 57.6 | L10: 55.1 | M10: 55.1 | N10: 55.1 | O10: 53.9 | P10: 51.5 | Q10: 50.2 | R10: 48 | S10: 50.5 | T10: 52.9 | U10: 52.9 | V10: 52.7 | W10: 60.5 | X10: 54.5 | Y10: 47.7 | Z10: 54.9 | AA10: 53.3 | AB10: 51.3
A11: Car SUV | B11: 0 | C11: 0.6 | D11: 0.5 | E11: 1.8 | F11: 2 | G11: 3.6 | H11: 2.3 | I11: 1.5 | J11: 2.2 | K11: 2.5 | L11: 3.1 | M11: 3.2 | N11: 3.7 | O11: 4.8 | P11: 3.7 | Q11: 3.6 | R11: 4.1 | S11: 5.1 | T11: 5 | U11: 6 | V11: 6.6 | W11: 6.5 | X11: 8.2 | Y11: 10.1 | Z11: 9.4 | AA11: 9.9 | AB11: 10
A12: Pickup | B12: 12.7 | C12: 14.4 | D12: 14.5 | E12: 15.3 | F12: 15.1 | G12: 15.2 | H12: 18.9 | I12: 15 | J12: 14.9 | K12: 16.7 | L12: 16.7 | M12: 16.7 | N12: 15.8 | O12: 16.1 | P12: 14.8 | Q12: 15.7 | R12: 15.9 | S12: 14.5 | T12: 14.5 | U12: 13.8 | V12: 12.9 | W12: 10.6 | X12: 11.5 | Y12: 12.3 | Z12: 10.1 | AA12: 10.6 | AB12: 11.5
A13: Van | B13: 2.1 | C13: 5.9 | D13: 10 | E13: 8.2 | F13: 10 | G13: 10.9 | H13: 10 | I13: 11 | J13: 10.7 | K13: 8.8 | L13: 10.3 | M13: 9.6 | N13: 10.2 | O13: 7.9 | P13: 7.7 | Q13: 7.8 | R13: 6.1 | S13: 9.3 | T13: 7.7 | U13: 5.5 | V13: 5.7 | W13: 4 | X13: 5 | Y13: 4.3 | Z13: 4.9 | AA13: 3.8 | AB13: 3.9
A14: Truck SUV | B14: 1.6 | C14: 4.5 | D14: 5.1 | E14: 6.9 | F14: 6.2 | G14: 6.3 | H14: 9.1 | I14: 10.5 | J14: 12.2 | K14: 14.5 | L14: 14.7 | M14: 15.4 | N14: 15.2 | O14: 17.3 | P14: 22.3 | Q14: 22.6 | R14: 25.9 | S14: 20.6 | T14: 19.9 | U14: 21.7 | V14: 22.1 | W14: 18.4 | X14: 20.8 | Y14: 25.6 | Z14: 20.6 | AA14: 22.4 | AB14: 23.3
A15: Fuel economy, mpg
A16: Car | B16: 20 | C16: 23 | D16: 23.3 | E16: 23.4 | F16: 23.1 | G16: 23.5 | H16: 23.3 | I16: 23.4 | J16: 23.3 | K16: 23.4 | L16: 23.4 | M16: 23 | N16: 22.9 | O16: 23 | P16: 23.1 | Q16: 23.3 | R16: 23.1 | S16: 23.5 | T16: 23.3 | U16: 24.1 | V16: 24.3 | W16: 25.3 | X16: 26.2 | Y16: 26 | Z16: 27.8 | AA16: 28.3 | AB16: 28.7
A17: Car SUV | B17: 14.6 | C17: 20.1 | D17: 18.8 | E17: 18.2 | F17: 17.8 | G17: 17 | H17: 18 | I17: 17.8 | J17: 18.4 | K17: 19.2 | L17: 18.2 | M17: 18.5 | N17: 17.9 | O17: 18.8 | P17: 19.3 | Q17: 19.9 | R17: 20 | S17: 20.2 | T17: 20.5 | U17: 20.6 | V17: 21.2 | W17: 22 | X17: 23 | Y17: 23.6 | Z17: 23.4 | AA17: 24.5 | AB17: 24.3
A18: Pickup | B18: 16.5 | C18: 18.2 | D18: 17.4 | E18: 18.2 | F18: 17.5 | G18: 17.6 | H18: 17.4 | I18: 16.9 | J18: 17.1 | K18: 16.8 | L18: 17 | M18: 16.3 | N18: 16.7 | O18: 16 | P18: 15.8 | Q18: 16.1 | R18: 15.7 | S18: 15.8 | T18: 16.1 | U18: 16.2 | V18: 16.5 | W18: 16.9 | X18: 16.9 | Y18: 17.2 | Z18: 17.2 | AA18: 17.4 | AB18: 18
A19: Van | B19: 14.1 | C19: 16.5 | D19: 17.8 | E19: 17.9 | F19: 17.9 | G19: 18.2 | H19: 17.8 | I19: 18.1 | J19: 18.3 | K19: 18.2 | L19: 18.7 | M19: 18.3 | N19: 18.6 | O19: 18 | P19: 18.7 | Q19: 19 | R19: 19.2 | S19: 19.3 | T19: 19.5 | U19: 19.5 | V19: 19.8 | W19: 20.1 | X19: 20.1 | Y19: 21 | Z19: 21.4 | AA19: 21.1 | AB19: 21.2
A20: Truck SUV | B20: 13.2 | C20: 16.5 | D20: 16.4 | E20: 16.7 | F20: 16.2 | G20: 16.3 | H20: 16 | I20: 16 | J20: 16.2 | K20: 16.1 | L20: 16.2 | M20: 16.1 | N20: 16 | O20: 16.4 | P20: 16.3 | Q20: 16.4 | R20: 16.5 | S20: 16.7 | T20: 17.2 | U20: 17.7 | V20: 18.2 | W20: 19.3 | X20: 19.7 | Y20: 19.8 | Z20: 20 | AA20: 20.9 | AB20: 21.2
A21: KEY: mpg = miles per gallon; N = data are not available; R = revised; SUV = sport utility vehicle.
A23: NOTES
A24: Numbers may not add to totals due to rounding.
A25: This table is not comparable to previous publication's tables due to changes in the source data.
A26: The Environmental Protection Agency changed the vehicle classifications, combining wagons with the rest of the cars and dropping the small, medium, large categories of cars, pickups, sport-utilities, and vans. The fuel economy displayed in those tables has been adjusted to provide the best estimate of real-world performance.
A28: SOURCE
A29: U.S. Department of Energy, Office of Energy Efficiency and Renewable Energy, Transportation Energy Data Book, Edition 33, tables 4.7, table 4.9 and table 4.11 (Oak Ridge, TN), available at http://cta.ornl.gov/data/index.shtml as of Dec. 8, 2015.

Sheet China-Data
A2: Ship
A4: ruled by law | B4: Type | C4: lifetime (year)
A5: Ocean boat | B5: 客船Passenger (recreation) | C5: 30
B6: 高速客船High-express Passenger | C6: 25
B7: 液体货船Tankership | C7: 31
B8: 散货货船Bulk Cargo Ship | C8: 33
B9: 杂货货船General Cargo Ship | C9: 34
A11: River boat | B11: 客船Passenger (recreation) | C11: 30
B12: 高速客船High-express Passenger | C12: 31
B13: 液体货船Tankership | C13: 31
B14: 散货货船Bulk Cargo Ship | C14: 33
B15: 杂货货船General Cargo Ship | C15: 35
A17: Value selected for usein Model | B17: Passenger ship | C17: =AVERAGE(C5,C11) -> 30
B18: Freight ship | C18: =INT(AVERAGE(C13:C15,C7:C9)) -> 32
A20: Rail
B21: Type | C21: lifetime (year) | D21: 旅客发送量占比 | E21: 营业里程占比 | F21: 占铁路客车总量
B22: 地铁 | C22: 30
A23: 动车
A24: 和谐号 | B24: 高铁列车High-speed train | C24: 20 | D24: 0.6415 | E24: =3/15 -> 0.2 | F24: =3256*C29/(46000/63.8%) -> 0.36127443
A25: 复兴号 | B25: 磁悬浮列车 | C25: 30 | F25: =1-F24-F26 -> 0.00072556522
B26: 普通轮轨列车 | C26: 25 | F26: 0.638
A28: 动车： | B28: 标准组与辆的转换
B29: 一个标准组等于 | C29: =26048/3256 -> 8 | D29: 辆
A32: Value selected for usein Model | B32: Passenger Rail | C32: =INT((C22+(C24*F24+C25*F25+C26*F26))/2) -> 26
B33: Freight Rail | C33: =INT(C24*F24+C25*F25+C26*F26) -> 23
A35: HDVs\LDVs\Motorbikes
A37: Passenger | B37: 出租客运-小、微型 | C37: 8
B38: 出租客运-中型 | C38: 10
B39: 出租客运-大型 | C39: 12
B40: 公交客运 | C40: 13
B41: 大型客运 | C41: 15
B42: 专用校车 | C42: 15
B43: 小、微型客运 | C43: 10
B44: 大中型营运汽车 | C44: 15
B45: 摩托车 | C45: 13
B46: 正三轮摩托车 | C46: 12
A47: Freight
B48: 重型 | C48: 15
B49: 轻、中型 | C49: 15
B52: Passenger LDV | C52: =(C37+C43)/2 -> 9
...

Sheet Data
A1: LDVs
A2: Car Avg Lifetime, years (Page 22, Table 7) | B2: Light Truck Avg Lifetime, years (Page 25, Table 8) | C2: Avg Car Sales from 2010-2013, thousands of vehicles (Table 1-20, Rows 4-5) | D2: Avg Light Truck Sales from 2010-2013, thousands of vehicles (Table 1-20, Rows 6-8) | E2: Market Share-Weighted Average LDV Lifetime
A3: 13 | B3: 14 | C3: =AVERAGE(SUM('NTS 1-20'!X4:X5),SUM('NTS 1-20'!Y4:Y5),SUM('NTS 1-20'!Z4:Z5),SUM('NTS 1-20'!AA4:AA5)) -> 7982.5 | D3: =AVERAGE(SUM('NTS 1-20'!X6:X8),SUM('NTS 1-20'!Y6:Y8),SUM('NTS 1-20'!Z6:Z8),SUM('NTS 1-20'!AA6:AA8)) -> 4867.25 | E3: =(A3*C3+B3*D3)/(C3+D3) -> 13.378782
A5: HDVs
A6: Heavy Truck Avg Lifetime, years (Table 3-14, Row 43) | B6: Heavy Truck Start Year Vehicles | C6: Bus Lifetime | D6: Bus Start Year Vehicle
A7: 28 | B7: 11932239 | C7: 23 | D7: 1007829.3
A10: aircraft
A11: Exhibits 1-3 illustrate roughly the same results.
A12: Exhibit 1: | B12: Non-dotted lines (aircraft in service) have been constant at 23-24 years for the last 15 years.
A13: Exhibit 2: | B13: Non-dashed lines (aircraft age when they leave service) has been 22-26 for Pax (passengers) and 31-36 for freighters over the last 15 years.
A14: Exhibit 3: | B14: The curves for all aircraft except the 707 Pax and the 737-100/200 Pax cross or are on track to cross 50% survival around age 23-24.
A15: Value selected for use in model
A16: 24
A18: rail
A19: Table | B19: CA Asset Type | C19: Lifetime (years)
A20: 2000 - Water Utility | B20: railroads | C20: 33
A21: 5000 - Transit | B21: locomotives, electric | C21: 35
B22: Value selected for use in model | C22: 34
A23: Neither of these asset types is exactly what I'd prefer (which would be something like "locomotives, diesel"
A24: or "locomotives, freight"), but they seem like reasonable values and are close to each other.
A26: ships
A27: Table | B27: CA Asset Type | C27: Lifetime (years)
A28: 3000 - Harbor & Port | B28: Motor vessels - diesel, ocean | C28: 33
A30: motorbikes
A31: Year | B31: Registered Motorcycles | C31: Motorcycles sold (new) | D31: Retiring Motorcycles | E31: Percentage of Fleet That Retired This Year
A32: 1997 | B32: 3826373 | C32: 260000
A33: 1998 | B33: 3879450 | C33: 311000 | D33: =C33-(B33-B32) -> 257923 | E33: =D33/B33 -> 0.066484424
A34: 1999 | B34: 4152433 | C34: 394000 | D34: =C34-(B34-B33) -> 121017 | E34: =D34/B34 -> 0.029143637
A35: 2000 | B35: 4346068 | C35: 490000 | D35: =C35-(B35-B34) -> 296365 | E35: =D35/B35 -> 0.068191524
A36: 2001 | B36: 4903056 | C36: 577000 | D36: =C36-(B36-B35) -> 20012 | E36: =D36/B36 -> 0.0040815361
A37: 2002 | B37: 5004156 | C37: 640000 | D37: =C37-(B37-B36) -> 538900 | E37: =D37/B37 -> 0.10769049
A38: 2003 | B38: 5370035 | C38: 683000 | D38: =C38-(B38-B37) -> 317121 | E38: =D38/B38 -> 0.059053805
A39: 2004 | B39: 5780870 | C39: 750000 | D39: =C39-(B39-B38) -> 339165 | E39: =D39/B39 -> 0.058670235
A40: 2005 | B40: 6227146 | C40: 831000 | D40: =C40-(B40-B39) -> 384724 | E40: =D40/B40 -> 0.061781754
A41: 2006 | B41: 6678958 | C41: 892000 | D41: =C41-(B41-B40) -> 440188 | E41: =D41/B41 -> 0.065906688
A42: 2007 | B42: 7138476 | C42: 885000 | D42: =C42-(B42-B41) -> 425482 | E42: =D42/B42 -> 0.059604039
A44: Average Percent Fleet Retirement per Year
A45: =AVERAGE(E33:E42) -> 0.058060813
A47: Estimated Lifetime of Motorcycle (years)
A48: =1/A45 -> 17.223321

Sheet AVL
A1: Vehicle Lifetime (years) | B1: Passenger | C1: Freight
A2: LDVs | B2: ='China-Data'!C52 -> 9 | C2: ='China-Data'!C54 -> 15
A3: HDVs | B3: ='China-Data'!C53 -> 15 | C3: ='China-Data'!C55 -> 15
A4: aircraft | B4: ='China-Data'!C60 -> 27 | C4: =B4 -> 27
A5: rail | B5: ='China-Data'!C32 -> 26 | C5: ='China-Data'!C33 -> 23
A6: ships | B6: ='China-Data'!C17 -> 30 | C6: ='China-Data'!C18 -> 32
A7: motorbikes | B7: =INT('China-Data'!C56) -> 12 | C7: =B7 -> 12
