Workbook

Sheet About
A1: OCCF Dollars per Large Output Currency Unit
A2: OCCF Dollars per Medium Output Currency Unit
A3: OCCF Dollars per Small Output Currency Unit
A5: Source: | B5: Exchange rate and deflator
B6: World bank open data
B7: https://data.worldbank.org/
B9: Official statistics on nominal and real growth
B10: National Bureau of Statistics
B11: https://data.stats.gov.cn/dg/website/page.html#/pc/national/yearData
A12: Notes
A13: This is a conversion factor that converts dollars (the unit used for
A14: internal calculations in the model) to whatever currency output
A15: unit is desired (for a given country/region).
A16: This both allows for currency localization by country and allows
A17: the outputs to be scaled so the Y-axis values on graphs in the
A18: web application interface do not get too large.
A20: For China Regional EPS Models
A21: Large Output Currency Unit
A22: yi (10^8) 2020 RMB
A24: Medium Output Currency Unit
A25: wan (10^4) 2020 RMB
... A28: 2020 RMB
A30: ='Exchange Rate'!B23 -> 0.1387318 | B30: 2020 RMB per 2012 dollar
B32: Recall, this variable is "dollars per large/medium/small currency output unit"
B33: which in this case is "2012 dollars per 2020 dollar."
B34: 2012 dollars are worth more than 2020 dollars, so we need a
B35: value less than 1 in this variable.
B36: This is why we multiply, not divide, by the conversion
B37: factor above.

Sheet Exchange Rate
A1: 人民币年份 | B1: 当年人民币相对2012美元 | C1: 2012美元相对当年人民币价格 | E1: 人民币年份 | F1: 当年人民币相对2012美元 | G1: 2012美元相对当年人民币价格
A2: RMB Year | B2: Current RMB vs 2012 USD | C2: 2012 USD vs Current RMB | E2: RMB Year | F2: Current RMB vs 2012 USD | G2: 2012 USD vs Current RMB | I2: 横纵转换 | J2: Transposed Data
A3: 2000 | B3: ='Worldbank Data'!G45 -> 0.2683276 | C3: ='Worldbank Data'!H45 -> 3.7267877 | E3: 2020 | F3: =B23 -> 0.1387318 | G3: =1/F3 -> 7.2081527 | I3: {=TRANSPOSE(A1:C28)} -> 人民币年份 | J3: RMB Year | K3: 2000 | L3: 2001 | M3: 2002 | N3: 2003 | O3: 2004 | P3: 2005 | Q3: 2006 | R3: 2007 | S3: 2008 | T3: 2009 | U3: 2010 | V3: 2011 | W3: 2012 | X3: 2013 | Y3: 2014 | Z3: 2015 | AA3: 2016 | AB3: 2017 | AC3: 2018 | AD3: 2019 | AE3: 2020 | AF3: 2021 | AG3: 2022 | AH3: 2023 | AI3: 2024 | AJ3: 2025
A4: 2001 | B4: ='Worldbank Data'!G46 -> 0.26252052 | C4: ='Worldbank Data'!H46 -> 3.8092261 | E4: 2021 | F4: =F3*0.978 -> 0.1356797 | G4: =1/F4 -> 7.3702993 | I4: 当年人民币相对2012美元 | J4: Current RMB vs 2012 USD | K4: 0.2683276 | L4: 0.26252052 | M4: 0.26084408 | N4: 0.25412828 | O4: 0.23752484 | P4: 0.22894244 | Q4: 0.22009578 | R4: 0.20395544 | S4: 0.18909873 | T4: 0.18925386 | U4: 0.17699111 | V4: 0.16385628 | W4: 0.1600078 | X4: 0.15641343 | Y4: 0.15472524 | Z4: 0.15451315 | AA4: 0.15226355 | AB4: 0.14620198 | AC4: 0.14130178 | AD4: 0.13946708 | AE4: 0.1387318 | AF4: 0.13279092 | AG4: 0.13027112 | AH4: 0.13093325 | AI4: 0.13186581 | AJ4: 0.13314416
A5: 2002 | B5: ='Worldbank Data'!G47 -> 0.26084408 | C5: ='Worldbank Data'!H47 -> 3.8337078 | E5: 2022 | F5: =F4*0.978 -> 0.13269475 | G5: =1/F5 -> 7.5360933 | I5: 2012美元相对当年人民币价格 | J5: 2012 USD vs Current RMB | K5: 3.7267877 | L5: 3.8092261 | M5: 3.8337078 | N5: 3.9350205 | O5: 4.210086 | P5: 4.3679102 | Q5: 4.5434765 | R5: 4.9030318 | S5: 5.2882427 | T5: 5.2839081 | U5: 5.6500014 | V5: 6.1029091 | W5: 6.2496953 | X5: 6.3933129 | Y5: 6.4630698 | Z5: 6.471941 | AA5: 6.5675602 | AB5: 6.8398527 | AC5: 7.0770518 | AD5: 7.1701509 | AE5: 7.2081527 | AF5: 7.5306355 | AG5: 7.6762986 | AH5: 7.6374792 | AI5: 7.583467 | AJ5: 7.510656
A6: 2003 | B6: ='Worldbank Data'!G48 -> 0.25412828 | C6: ='Worldbank Data'!H48 -> 3.9350205 | E6: 2023 | F6: =F5*0.978 -> 0.12977546 | G6: =1/F6 -> 7.7056169
A7: 2004 | B7: ='Worldbank Data'!G49 -> 0.23752484 | C7: ='Worldbank Data'!H49 -> 4.210086 | E7: 2024 | F7: =F6*0.978 -> 0.1269204 | G7: =1/F7 -> 7.8789539 | I7: {=TRANSPOSE(E1:G43)} -> 人民币年份 | J7: RMB Year | K7: 2020 | L7: 2021 | M7: 2022 | N7: 2023 | O7: 2024 | P7: 2025 | Q7: 2026 | R7: 2027 | S7: 2028 | T7: 2029 | U7: 2030 | V7: 2031 | W7: 2032 | X7: 2033 | Y7: 2034 | Z7: 2035 | AA7: 2036 | AB7: 2037 | AC7: 2038 | AD7: 2039 | AE7: 2040 | AF7: 2041 | AG7: 2042 | AH7: 2043 | AI7: 2044 | AJ7: 2045 | AK7: 2046 | AL7: 2047 | AM7: 2048 | AN7: 2049 | AO7: 2050 | AP7: 2051 | AQ7: 2052 | AR7: 2053 | AS7: 2054 | AT7: 2055 | AU7: 2056 | AV7: 2057 | AW7: 2058 | AX7: 2059 | AY7: 2060
A8: 2005 | B8: ='Worldbank Data'!G50 -> 0.22894244 | C8: ='Worldbank Data'!H50 -> 4.3679102 | E8: 2025 | F8: =F7*0.978 -> 0.12412815 | G8: =1/F8 -> 8.0561901 | I8: 当年人民币相对2012美元 | J8: Current RMB vs 2012 USD | K8: 0.1387318 | L8: 0.1356797 | M8: 0.13269475 | N8: 0.12977546 | O8: 0.1269204 | P8: 0.12412815 | Q8: 0.12139733 | R8: 0.11872659 | S8: 0.11611461 | T8: 0.11356009 | U8: 0.11106176 | V8: 0.10861841 | W8: 0.1062288 | X8: 0.10389177 | Y8: 0.10160615 | Z8: 0.099370813 | AA8: 0.097184655 | AB8: 0.095046593 | AC8: 0.092955568 | AD8: 0.090910545 | AE8: 0.088910513 | AF8: 0.086954482 | AG8: 0.085041483 | AH8: 0.083170571 | AI8: 0.081340818 | AJ8: 0.07955132 | AK8: 0.077801191 | AL8: 0.076089565 | AM8: 0.074415594 | AN8: 0.072778451 | AO8: 0.071177325 | AP8: 0.069611424 | AQ8: 0.068079973 | AR8: 0.066582214 | AS8: 0.065117405 | AT8: 0.063684822 | AU8: 0.062283756 | AV8: 0.060913513 | AW8: 0.059573416 | AX8: 0.058262801 | AY8: 0.056981019
A9: 2006 | B9: ='Worldbank Data'!G51 -> 0.22009578 | C9: ='Worldbank Data'!H51 -> 4.5434765 | E9: 2026 | F9: =F8*0.978 -> 0.12139733 | G9: =1/F9 -> 8.2374132 | I9: 2012美元相对当年人民币价格 | J9: 2012 USD vs Current RMB | K9: 7.2081527 | L9: 7.3702993 | M9: 7.5360933 | N9: 7.7056169 | O9: 7.8789539 | P9: 8.0561901 | Q9: 8.2374132 | R9: 8.4227129 | S9: 8.6121808 | T9: 8.8059109 | U9: 9.0039989 | V9: 9.2065428 | W9: 9.4136429 | X9: 9.6254018 | Y9: 9.8419241 | Z9: 10.063317 | AA9: 10.28969 | AB9: 10.521156 | AC9: 10.757828 | AD9: 10.999824 | AE9: 11.247264 | AF9: 11.50027 | AG9: 11.758967 | AH9: 12.023484 | AI9: 12.293951 | AJ9: 12.570502 | AK9: 12.853274 | AL9: 13.142407 | AM9: 13.438044 | AN9: 13.740331 | AO9: 14.049418 | AP9: 14.365458 | AQ9: 14.688607 | AR9: 15.019026 | AS9: 15.356877 | AT9: 15.702329 | AU9: 16.055551 | AV9: 16.416719 | AW9: 16.786011 | AX9: 17.16361 | AY9: 17.549704
A10: 2007 | B10: ='Worldbank Data'!G52 -> 0.20395544 | C10: ='Worldbank Data'!H52 -> 4.9030318 | E10: 2027 | F10: =F9*0.978 -> 0.11872659 | G10: =1/F10 -> 8.4227129
A11: 2008 | B11: ='Worldbank Data'!G53 -> 0.18909873 | C11: ='Worldbank Data'!H53 -> 5.2882427 | E11: 2028 | F11: =F10*0.978 -> 0.11611461 | G11: =1/F11 -> 8.6121808
A12: 2009 | B12: ='Worldbank Data'!G54 -> 0.18925386 | C12: ='Worldbank Data'!H54 -> 5.2839081 | E12: 2029 | F12: =F11*0.978 -> 0.11356009 | G12: =1/F12 -> 8.8059109
A13: 2010 | B13: ='Worldbank Data'!G55 -> 0.17699111 | C13: ='Worldbank Data'!H55 -> 5.6500014 | E13: 2030 | F13: =F12*0.978 -> 0.11106176 | G13: =1/F13 -> 9.0039989
A14: 2011 | B14: ='Worldbank Data'!G56 -> 0.16385628 | C14: ='Worldbank Data'!H56 -> 6.1029091 | E14: 2031 | F14: =F13*0.978 -> 0.10861841 | G14: =1/F14 -> 9.2065428
A15: 2012 | B15: ='Worldbank Data'!G57 -> 0.1600078 | C15: ='Worldbank Data'!H57 -> 6.2496953 | E15: 2032 | F15: =F14*0.978 -> 0.1062288 | G15: =1/F15 -> 9.4136429
A16: 2013 | B16: ='Worldbank Data'!G58 -> 0.15641343 | C16: ='Worldbank Data'!H58 -> 6.3933129 | E16: 2033 | F16: =F15*0.978 -> 0.10389177 | G16: =1/F16 -> 9.6254018
A17: 2014 | B17: ='Worldbank Data'!G59 -> 0.15472524 | C17: ='Worldbank Data'!H59 -> 6.4630698 | E17: 2034 | F17: =F16*0.978 -> 0.10160615 | G17: =1/F17 -> 9.8419241
A18: 2015 | B18: ='Worldbank Data'!G60 -> 0.15451315 | C18: ='Worldbank Data'!H60 -> 6.471941 | E18: 2035 | F18: =F17*0.978 -> 0.099370813 | G18: =1/F18 -> 10.063317
A19: 2016 | B19: ='Worldbank Data'!G61 -> 0.15226355 | C19: ='Worldbank Data'!H61 -> 6.5675602 | E19: 2036 | F19: =F18*0.978 -> 0.097184655 | G19: =1/F19 -> 10.28969
A20: 2017 | B20: ='Worldbank Data'!G62 -> 0.14620198 | C20: ='Worldbank Data'!H62 -> 6.8398527 | E20: 2037 | F20: =F19*0.978 -> 0.095046593 | G20: =1/F20 -> 10.521156
A21: 2018 | B21: ='Worldbank Data'!G63 -> 0.14130178 | C21: ='Worldbank Data'!H63 -> 7.0770518 | E21: 2038 | F21: =F20*0.978 -> 0.092955568 | G21: =1/F21 -> 10.757828
... A28: 2025 | B28: ='Worldbank Data'!G70 -> 0.13314416 | C28: ='Worldbank Data'!H70 -> 7.510656 | E28: 2045 | F28: =F27*0.978 -> 0.07955132 | G28: =1/F28 -> 12.570502
E29: 2046 | F29: =F28*0.978 -> 0.077801191 | G29: =1/F29 -> 12.853274
A30: *2020-2025年实际数据参考上方数据 | E30: 2047 | F30: =F29*0.978 -> 0.076089565 | G30: =1/F30 -> 13.142407
A31: *When using actual data from 2020-2022, refer to | E31: 2048 | F31: =F30*0.978 -> 0.074415594 | G31: =1/F31 -> 13.438044
A32: values from table above | E32: 2049 | F32: =F31*0.978 -> 0.072778451 | G32: =1/F32 -> 13.740331
E33: 2050 | F33: =F32*0.978 -> 0.071177325 | G33: =1/F33 -> 14.049418
A34: *使用基于2020年为基年的人口经济模型推测时可 | E34: 2051 | F34: =F33*0.978 -> 0.069611424 | G34: =1/F34 -> 14.365458
A35: 参考右侧数据 | E35: 2052 | F35: =F34*0.978 -> 0.068079973 | G35: =1/F35 -> 14.688607
A36: *When using data projected from population | E36: 2053 | F36: =F35*0.978 -> 0.066582214 | G36: =1/F36 -> 15.019026
A37: and ecnomic model refer to values from the table | E37: 2054 | F37: =F36*0.978 -> 0.065117405 | G37: =1/F37 -> 15.356877
A38: on the right | E38: 2055 | F38: =F37*0.978 -> 0.063684822 | G38: =1/F38 -> 15.702329
E39: 2056 | F39: =F38*0.978 -> 0.062283756 | G39: =1/F39 -> 16.055551
E40: 2057 | F40: =F39*0.978 -> 0.060913513 | G40: =1/F40 -> 16.416719
E41: 2058 | F41: =F40*0.978 -> 0.059573416 | G41: =1/F41 -> 16.786011
E42: 2059 | F42: =F41*0.978 -> 0.058262801 | G42: =1/F42 -> 17.16361
E43: 2060 | F43: =F42*0.978 -> 0.056981019 | G43: =1/F43 -> 17.549704

Sheet Worldbank Data
A1: Country Name | B1: 基于统计局数据的通货膨胀系数 | C1: 基于世行数据的通货膨胀系数 | D1: 当年人民币相对2020人民币 | E1: 当年人民币相对2015美元 | F1: 当年美元相对2015美元 | G1: 当年人民币相对2012美元 | H1: 2012美元相对当年人民币价格 | I1: 当年美元相对2012美元 | J1: 2012美元相对当年美元价格 | K1: 平价购买力下当年人民币比2021美元 | M1: Data Source: | R1: China | S1: China | T1: China | U1: United States | V1: United States | W1: United States | X1: China
A2: Country Code | M2: The World Bank Data | R2: CHN | S2: CHN | T2: CHN | U2: USA | V2: USA | W2: USA | X2: CHN
A3: Indicator Name | B3: Inflation Factor based on NBS Data | C3: Inflation Factor based on Worldbank Data | D3: Current RMB vs 2020 RMB | E3: Current RMB vs 2015 USD | F3: Current USD vs 2015 RMB | G3: Current RMB vs 2012 USD | H3: 2012 USD vs Current RMB | I3: Current USD vs 2012 USD | J3: 2012 USD vs Current USD | K3: Current RMB vs 2021 USD,PPP method | M3: GDP (constant 2015 US$) | Data (worldbank.org) | R3: GDP (current LCU) | S3: GDP (constant LCU) | T3: GDP (constant 2015 US$) | U3: GDP (current LCU) | V3: GDP (constant LCU) | W3: GDP (constant 2015 US$) | X3: GDP, PPP (constant 2021 international $)
A4: Indicator Code | R4: NY.GDP.MKTP.CN | S4: NY.GDP.MKTP.KN | T4: NY.GDP.MKTP.KD | U4: NY.GDP.MKTP.CN | V4: NY.GDP.MKTP.KN | W4: NY.GDP.MKTP.KD | X4: NY.GDP.MKTP.PP.KD
A5: 1960 | D5: =S5/R5 -> 7.5805283 | E5: =T5/R5 -> 1.0929419 | F5: =V5/U5 -> 6.8541597 | G5: =E5/$F$57 -> 1.0516603 | H5: =1/G5 -> 0.95087735 | I5: =F5/F$57 -> 6.5952708 | J5: =1/I5 -> 0.1516238 | K5: =R5/X5 -> #DIV/0! | R5: 147330000000 | S5: 1.1168392e+12 | T5: 1.6102313e+11 | U5: 5.4198859e+11 | V5: 3.7148763e+12 | W5: 3.4145298e+12
A6: 1961 | C6: =R6/R5/(S6/S5) -> 1.1524631 | D6: =S6/R6 -> 6.5776757 | E6: =T6/R6 -> 0.94835309 | F6: =V6/U6 -> 6.7628508 | G6: =E6/$F$57 -> 0.91253279 | H6: =1/G6 -> 1.095851 | I6: =F6/F$57 -> 6.5074108 | J6: =1/I6 -> 0.15367095 | K6: =R6/X6 -> #DIV/0! | R6: 123490000000 | S6: 8.1227718e+11 | T6: 1.1711212e+11 | U6: 5.6194031e+11 | V6: 3.8003185e+12 | W6: 3.493064e+12
A7: 1962 | C7: =R7/R6/(S7/S6) -> 0.99889143 | D7: =S7/R7 -> 6.5849756 | E7: =T7/R7 -> 0.94940557 | F7: =V7/U7 -> 6.6797128 | G7: =E7/$F$57 -> 0.91354552 | H7: =1/G7 -> 1.0946362 | I7: =F7/F$57 -> 6.427413 | J7: =1/I7 -> 0.15558359 | K7: =R7/X7 -> #DIV/0! | R7: 116470000000 | S7: 7.6695211e+11 | T7: 1.1057727e+11 | U7: 6.0363941e+11 | V7: 4.0321379e+12 | W7: 3.7061409e+12
A8: 1963 | C8: =R8/R7/(S8/S7) -> 0.97371757 | D8: =S8/R8 -> 6.7627163 | E8: =T8/R8 -> 0.97503178 | F8: =V8/U8 -> 6.6077945 | G8: =E8/$F$57 -> 0.9382038 | H8: =1/G8 -> 1.0658665 | I8: =F8/F$57 -> 6.3582111 | J8: =1/I8 -> 0.15727694 | K8: =R8/X8 -> #DIV/0! | R8: 125090000000 | S8: 8.4594818e+11 | T8: 1.2196673e+11 | U8: 6.3705855e+11 | V8: 4.209552e+12 | W8: 3.8692111e+12
A9: 1964 | C9: =R9/R8/(S9/S8) -> 0.99620269 | D9: =S9/R9 -> 6.7884943 | E9: =T9/R9 -> 0.97874839 | F9: =V9/U9 -> 6.5098896 | G9: =E9/$F$57 -> 0.94178003 | H9: =1/G9 -> 1.0618191 | I9: =F9/F$57 -> 6.2640042 | J9: =1/I9 -> 0.15964229 | K9: =R9/X9 -> #DIV/0! | R9: 147270000000 | S9: 9.9974156e+11 | T9: 1.4414028e+11 | U9: 6.8414462e+11 | V9: 4.453706e+12 | W9: 4.0936253e+12
A10: 1965 | C10: =R10/R9/(S10/S9) -> 1.008638 | D10: =S10/R10 -> 6.7303578 | E10: =T10/R10 -> 0.97036641 | F10: =V10/U10 -> 6.3872653 | G10: =E10/$F$57 -> 0.93371465 | H10: =1/G10 -> 1.070991 | I10: =F10/F$57 -> 6.1460115 | J10: =1/I10 -> 0.16270715 | K10: =R10/X10 -> #DIV/0! | R10: 173720000000 | S10: 1.1691977e+12 | T10: 1.6857205e+11 | U10: 7.4190486e+11 | V10: 4.7387432e+12 | W10: 4.3556173e+12
A11: 1966 | C11: =R11/R10/(S11/S10) -> 0.98428279 | D11: =S11/R11 -> 6.8378293 | E11: =T11/R11 -> 0.9858614 | F11: =V11/U11 -> 6.2073286 | G11: =E11/$F$57 -> 0.94862437 | H11: =1/G11 -> 1.054158 | I11: =F11/F$57 -> 5.9728712 | J11: =1/I11 -> 0.16742367 | K11: =R11/X11 -> #DIV/0! | R11: 189200000000 | S11: 1.2937173e+12 | T11: 1.8652498e+11 | U11: 8.1303276e+11 | V11: 5.0467615e+12 | W11: 4.6387324e+12
A12: 1967 | C12: =R12/R11/(S12/S11) -> 1.0081715 | D12: =S12/R12 -> 6.7824069 | E12: =T12/R12 -> 0.97787073 | F12: =V12/U12 -> 6.0176942 | G12: =E12/$F$57 -> 0.94093552 | H12: =1/G12 -> 1.0627721 | I12: =F12/F$57 -> 5.7903996 | J12: =1/I12 -> 0.17269965 | K12: =R12/X12 -> #DIV/0! | R12: 179740000000 | S12: 1.2190698e+12 | T12: 1.7576249e+11 | U12: 8.5962003e+11 | V12: 5.1729305e+12 | W12: 4.7547008e+12
A13: 1968 | C13: =R13/R12/(S13/S12) -> 1.0137456 | D13: =S13/R13 -> 6.6904427 | E13: =T13/R13 -> 0.96461156 | F13: =V13/U13 -> 5.7658871 | G13: =E13/$F$57 -> 0.92817716 | H13: =1/G13 -> 1.0773805 | I13: =F13/F$57 -> 5.5481034 | J13: =1/I13 -> 0.18024177 | K13: =R13/X13 -> #DIV/0! | R13: 174740000000 | S13: 1.169088e+12 | T13: 1.6855622e+11 | U13: 940225000000 | V13: 5.4212312e+12 | W13: 4.9829264e+12
A14: 1969 | C14: =R14/R13/(S14/S13) -> 0.96197064 | D14: =S14/R14 -> 6.9549344 | E14: =T14/R14 -> 1.0027453 | F14: =V14/U14 -> 5.4934929 | G14: =E14/$F$57 -> 0.96487057 | H14: =1/G14 -> 1.0364084 | I14: =F14/F$57 -> 5.2859978 | J14: =1/I14 -> 0.18917904 | K14: =R14/X14 -> #DIV/0! | R14: 196570000000 | S14: 1.3671315e+12 | T14: 1.9710965e+11 | U14: 1.0174382e+12 | V14: 5.5892893e+12 | W14: 5.1373971e+12
A15: 1970 | C15: =R15/R14/(S15/S14) -> 0.97369808 | D15: =S15/R15 -> 7.1428038 | E15: =T15/R15 -> 1.0298319 | F15: =V15/U15 -> 5.2188395 | G15: =E15/$F$57 -> 0.99093403 | H15: =1/G15 -> 1.0091489 | I15: =F15/F$57 -> 5.0217184 | J15: =1/I15 -> 0.19913502 | K15: =R15/X15 -> #DIV/0! | R15: 228340000000 | S15: 1.6309878e+12 | T15: 2.3515181e+11 | U15: 1073303000000 | V15: 5601396103000 | W15: 5.1485251e+12
A16: 1971 | C16: =R16/R15/(S16/S15) -> 1.0066235 | D16: =S16/R16 -> 7.0958045 | E16: =T16/R16 -> 1.0230556 | F16: =V16/U16 -> 4.9670211 | G16: =E16/$F$57 -> 0.98441373 | H16: =1/G16 -> 1.015833 | I16: =F16/F$57 -> 4.7794115 | J16: =1/I16 -> 0.20923078 | K16: =R16/X16 -> #DIV/0! | R16: 246080000000 | S16: 1.7461356e+12 | T16: 2.5175353e+11 | U16: 1164850000000 | V16: 5785834530000 | W16: 5.3180517e+12
A17: 1972 | C17: =R17/R16/(S17/S16) -> 1.0007608 | D17: =S17/R17 -> 7.0904101 | E17: =T17/R17 -> 1.0222779 | F17: =V17/U17 -> 4.761052 | G17: =E17/$F$57 -> 0.98366535 | H17: =1/G17 -> 1.0166059 | I17: =F17/F$57 -> 4.581222 | J17: =1/I17 -> 0.21828237 | K17: =R17/X17 -> #DIV/0! | R17: 255650000000 | S17: 1.8126633e+12 | T17: 2.6134534e+11 | U17: 1279110000000 | V17: 6089909177000 | W17: 5.597542e+12
... A34: 1989 | C34: =R34/R33/(S34/S33) -> 1.0860763 | D34: =S34/R34 -> 4.0373476 | E34: =T34/R34 -> 0.58209484 | F34: =V34/U34 -> 1.8431127 | G34: =E34/$F$57 -> 0.56010851 | H34: =1/G34 -> 1.7853684 | I34: =F34/F$57 -> 1.7734964 | J34: =1/I34 -> 0.56385792 | K34: =R34/X34 -> #DIV/0! | R34: 1721000000000 | S34: 6.9482753e+12 | T34: 1.0017852e+12 | U34: 5641580000000 | V34: 10398067965000 | W34: 9.5573876e+12
A35: 1990 | C35: =R35/R34/(S35/S34) -> 1.05709 | D35: =S35/R35 -> 3.8193038 | E35: =T35/R35 -> 0.55065781 | F35: =W35/U35 -> 1.6329702 | G35: =E35/$F$57 -> 0.52985889 | H35: =1/G35 -> 1.887295 | I35: =F35/F$57 -> 1.5712912 | J35: =1/I35 -> 0.63641926 | K35: =R35/X35 -> 0.99930699 | R35: 1890960000000 | S35: 7.2221506e+12 | T35: 1.0412719e+12 | U35: 5963144000000 | V35: 10594171948000 | W35: 9.7376366e+12 | X35: 1.8922714e+12
A36: 1991 | B36: =HLOOKUP($A36&"*",'NBS Data'!$B$3:$AJ$25,23,FALSE) -> 1.0668918 | C36: =R36/R35/(S36/S35) -> 1.0672654 | D36: =S36/R36 -> 3.5785885 | E36: =T36/R36 -> 0.51595208 | F36: =W36/U36 -> 1.5795527 | G36: =E36/$F$57 -> 0.49646402 | H36: =1/G36 -> 2.0142446 | I36: =F36/F$57 -> 1.5198914 | J36: =1/I36 -> 0.65794176 | K36: =R36/X36 -> 1.0665258 | R36: 2207090000000 | S36: 7898266873900 | T36: 1.1387527e+12 | U36: 6158129000000 | V36: 10582697095000 | W36: 9.7270895e+12 | X36: 2.0694202e+12
A37: 1992 | B37: =HLOOKUP($A37&"*",'NBS Data'!$B$3:$AJ$25,23,FALSE) -> 1.0819978 | C37: =R37/R36/(S37/S36) -> 1.0820015 | D37: =S37/R37 -> 3.3073786 | E37: =T37/R37 -> 0.4768497 | F37: =W37/U37 -> 1.544359 | G37: =E37/$F$57 -> 0.45883858 | H37: =1/G37 -> 2.1794157 | I37: =F37/F$57 -> 1.486027 | J37: =1/I37 -> 0.6729353 | K37: =R37/X37 -> 1.1539825 | R37: 2729560000000 | S37: 9027688304300 | T37: 1.3015899e+12 | U37: 6520327000000 | V37: 10955472301000 | W37: 1.0069726e+13 | X37: 2.3653392e+12
A38: 1993 | B38: =HLOOKUP($A38&"*",'NBS Data'!$B$3:$AJ$25,23,FALSE) -> 1.1521408 | C38: =R38/R37/(S38/S37) -> 1.1518468 | D38: =S38/R38 -> 2.8713702 | E38: =T38/R38 -> 0.41398709 | F38: =W38/U38 -> 1.5086003 | G38: =E38/$F$57 -> 0.39835036 | H38: =1/G38 -> 2.5103529 | I38: =F38/F$57 -> 1.4516189 | J38: =1/I38 -> 0.68888605 | K38: =R38/X38 -> 1.329211 | R38: 3581970000000 | S38: 10285162051100 | T38: 1.4828893e+12 | U38: 6858559000000 | V38: 11256944535000 | W38: 1.0346824e+13 | X38: 2.6948092e+12
A39: 1994 | B39: =HLOOKUP($A39&"*",'NBS Data'!$B$3:$AJ$25,23,FALSE) -> 1.2061143 | C39: =R39/R38/(S39/S38) -> 1.2064054 | D39: =S39/R39 -> 2.3801039 | E39: =T39/R39 -> 0.34315752 | F39: =W39/U39 -> 1.4770621 | G39: =E39/$F$57 -> 0.3301961 | H39: =1/G39 -> 3.0285034 | I39: =F39/F$57 -> 1.4212719 | J39: =1/I39 -> 0.70359513 | K39: =R39/X39 -> 1.6035674 | R39: 4886220000000 | S39: 11629711373000 | T39: 1.6767431e+12 | U39: 7287236000000 | V39: 11710489389000 | W39: 1.07637e+13 | X39: 3.0470937e+12
A40: 1995 | B40: =HLOOKUP($A40&"*",'NBS Data'!$B$3:$AJ$25,23,FALSE) -> 1.136666 | C40: =R40/R39/(S40/S39) -> 1.1363301 | D40: =S40/R40 -> 2.0945533 | E40: =T40/R40 -> 0.30198754 | F40: =W40/U40 -> 1.4467287 | G40: =E40/$F$57 -> 0.29058115 | H40: =1/G40 -> 3.4413794 | I40: =F40/F$57 -> 1.3920842 | J40: =1/I40 -> 0.71834733 | K40: =R40/X40 -> 1.8221818 | R40: 6164940000000 | S40: 12912795583100 | T40: 1.8617351e+12 | U40: 7639749000000 | V40: 12024849365000 | W40: 1.1052644e+13 | X40: 3.3832738e+12
A41: 1996 | B41: =HLOOKUP($A41&"*",'NBS Data'!$B$3:$AJ$25,23,FALSE) -> 1.0648279 | C41: =R41/R40/(S41/S40) -> 1.0650583 | D41: =S41/R41 -> 1.966609 | E41: =T41/R41 -> 0.28354085 | F41: =W41/U41 -> 1.4207187 | G41: =E41/$F$57 -> 0.27283121 | H41: =1/G41 -> 3.6652698 | I41: =F41/F$57 -> 1.3670567 | J41: =1/I41 -> 0.73149858 | K41: =R41/X41 -> 1.9407299 | R41: 7221060000000 | S41: 14201001885800 | T41: 2.0474655e+12 | U41: 8073122000000 | V41: 12478519598000 | W41: 1.1469635e+13 | X41: 3.720796e+12
A42: 1997 | B42: =HLOOKUP($A42&"*",'NBS Data'!$B$3:$AJ$25,23,FALSE) -> 1.0164561 | C42: =R42/R41/(S42/S41) -> 1.016571 | D42: =S42/R42 -> 1.9345517 | E42: =T42/R42 -> 0.2789189 | F42: =W42/U42 -> 1.3966341 | G42: =E42/$F$57 -> 0.26838383 | H42: =1/G42 -> 3.7260068 | I42: =F42/F$57 -> 1.3438817 | J42: =1/I42 -> 0.74411311 | K42: =R42/X42 -> 1.9728896 | R42: 8022500000000 | S42: 15519940744400 | T42: 2.2376268e+12 | U42: 8577554457000 | V42: 13033455329000 | W42: 1.1979705e+13 | X42: 4.0663704e+12
A43: 1998 | B43: =HLOOKUP($A43&"*",'NBS Data'!$B$3:$AJ$25,23,FALSE) -> 0.99192638 | C43: =R43/R42/(S43/S42) -> 0.99173527 | D43: =S43/R43 -> 1.9506734 | E43: =T43/R43 -> 0.28124329 | F43: =W43/U43 -> 1.3811124 | G43: =E43/$F$57 -> 0.27062044 | H43: =1/G43 -> 3.6952124 | I43: =F43/F$57 -> 1.3289464 | J43: =1/I43 -> 0.75247582 | K43: =R43/X43 -> 1.9565842 | R43: 8586390000000 | S43: 16749242981600 | T43: 2.4148646e+12 | U43: 9062818202000 | V43: 13617762512000 | W43: 1.2516771e+13 | X43: 4.3884591e+12
A44: 1999 | B44: =HLOOKUP($A44&"*",'NBS Data'!$B$3:$AJ$25,23,FALSE) -> 0.98814258 | C44: =R44/R43/(S44/S43) -> 0.98780319 | D44: =S44/R44 -> 1.9747592 | E44: =T44/R44 -> 0.28471592 | F44: =W44/U44 -> 1.3618409 | G44: =E44/$F$57 -> 0.2739619 | H44: =1/G44 -> 3.6501426 | I44: =F44/F$57 -> 1.3104027 | J44: =1/I44 -> 0.76312419 | K44: =R44/X44 -> 1.9327202 | R44: 9137890000000 | S44: 18045132423300 | T44: 2.6017028e+12 | U44: 9631174489000 | V44: 14269838863000 | W44: 1.3116127e+13 | X44: 4.7279943e+12
A45: 2000 | B45: =HLOOKUP($A45&"*",'NBS Data'!$B$3:$AJ$25,23,FALSE) -> 1.0208703 | C45: =R45/R44/(S45/S44) -> 1.0209978 | D45: =S45/R45 -> 1.9341463 | E45: =T45/R45 -> 0.27886045 | F45: =W45/U45 -> 1.3316767 | G45: =E45/$F$57 -> 0.2683276 | H45: =1/G45 -> 3.7267877 | I45: =F45/F$57 -> 1.2813778 | J45: =1/I45 -> 0.78040993 | K45: =R45/X45 -> 1.9733031 | R45: 10130860000000 | S45: 19594565451400 | T45: 2.8250962e+12 | U45: 10250947997000 | V45: 14851703780000 | W45: 1.3650948e+13 | X45: 5.1339604e+12
A46: 2001 | B46: =HLOOKUP($A46&"*",'NBS Data'!$B$3:$AJ$25,23,FALSE) -> 1.0222398 | C46: =R46/R45/(S46/S45) -> 1.0221205 | D46: =S46/R46 -> 1.892288 | E46: =T46/R46 -> 0.27282542 | F46: =W46/U46 -> 1.3023511 | G46: =E46/$F$57 -> 0.26252052 | H46: =1/G46 -> 3.8092261 | I46: =F46/F$57 -> 1.25316 | J46: =1/I46 -> 0.79798272 | K46: =R46/X46 -> 2.0169536 | R46: 11215730000000 | S46: 21223390915700 | T46: 3.0599362e+12 | U46: 10581929774000 | V46: 14993617505000 | W46: 1.3781388e+13 | X46: 5.560728e+12
A47: 2002 | B47: =HLOOKUP($A47&"*",'NBS Data'!$B$3:$AJ$25,23,FALSE) -> 1.0068269 | C47: =R47/R46/(S47/S46) -> 1.006427 | D47: =S47/R47 -> 1.880204 | E47: =T47/R47 -> 0.27108318 | F47: =W47/U47 -> 1.2824219 | G47: =E47/$F$57 -> 0.26084408 | H47: =1/G47 -> 3.8337078 | I47: =F47/F$57 -> 1.2339835 | J47: =1/I47 -> 0.81038363 | K47: =R47/X47 -> 2.0299164 | R47: 12331190000000 | S47: 23185152402500 | T47: 3.3427782e+12 | U47: 10929112955000 | V47: 15248576073000 | W47: 1.4015734e+13 | X47: 6.0747279e+12
... A69: 2024 | B69: =HLOOKUP($A69&"*",'NBS Data'!$B$3:$AJ$25,23,FALSE) -> 0.99196527 | C69: =R69/R68/(S69/S68) -> 0.992928 | D69: =S69/R69 -> 0.95050888 | E69: =T69/R69 -> 0.13704203 | F69: =W69/U69 -> 0.7849639 | G69: =E69/$F$57 -> 0.13186581 | H69: =1/G69 -> 7.583467 | I69: =F69/F$57 -> 0.75531499 | J69: =1/I69 -> 1.323951 | K69: =R69/X69 -> 4.0153827 | R69: 134908354627800 | S69: 128231589615900 | T69: 1.8488115e+13 | U69: 2.8750956e+13 | V69: 24553614511000 | W69: 2.2568463e+13 | X69: 3.3597882e+13
A70: 2025 | B70: =HLOOKUP($A70&"*",'NBS Data'!$B$3:$AJ$25,23,FALSE) -> 0.99039873 | D70: =D69/B70 -> 0.95972345 | E70: =E69*(D70/D69) -> 0.13837056 | G70: =E70/$F$57 -> 0.13314416 | H70: =1/G70 -> 7.510656 | R70: ='NBS Data'!B5*10^8 -> 140187920000000 | S70: =R70*D70 -> 134541634445771 | T70: =R70*E70 -> 19397881563703
S76: =S71/R71 -> #DIV/0!
T16385: China | U16385: United States
T16386: CHN | U16386: USA
T16387: GDP (constant 2015 US$) | U16387: GDP (current LCU)
T16388: NY.GDP.MKTP.KD | U16388: NY.GDP.MKTP.CN
T16389: 1.5890746e+11 | U16389: 543300000000
T16390: 1.1557339e+11 | U16390: 563300000000
...

Sheet NBS Data
A1: 数据库：年度数据
A2: 时间：1990年-2025年
A3: 指标 | B3: 2025年 | C3: 2024年 | D3: 2023年 | E3: 2022年 | F3: 2021年 | G3: 2020年 | H3: 2019年 | I3: 2018年 | J3: 2017年 | K3: 2016年 | L3: 2015年 | M3: 2014年 | N3: 2013年 | O3: 2012年 | P3: 2011年 | Q3: 2010年 | R3: 2009年 | S3: 2008年 | T3: 2007年 | U3: 2006年 | V3: 2005年 | W3: 2004年 | X3: 2003年 | Y3: 2002年 | Z3: 2001年 | AA3: 2000年 | AB3: 1999年 | AC3: 1998年 | AD3: 1997年 | AE3: 1996年 | AF3: 1995年 | AG3: 1994年 | AH3: 1993年 | AI3: 1992年 | AJ3: 1991年 | AK3: 1990年
A4: 国民总收入 (亿元) | B4: 1394052.9 | C4: 1340429 | D4: 1284773.9 | E4: 1223706.8 | F4: 1165816.8 | G4: 1026751.9 | H4: 1003108.4 | I4: 931972.5 | J4: 846292.7 | K4: 757492 | L4: 699224.5 | M4: 656600 | N4: 598838.4 | O4: 546259.7 | P4: 491160.2 | Q4: 417488.1 | R4: 353938.8 | S4: 326302.7 | T4: 274791.4 | U4: 222168.4 | V4: 188587.6 | W4: 163803.2 | X4: 138531.5 | Y4: 122074.9 | Z4: 110570.3 | AA4: 100094.6 | AB4: 90181 | AC4: 84486 | AD4: 79312.8 | AE4: 71176.5 | AF4: 60666.2 | AG4: 48773 | AH4: 35745.8 | AI4: 27309.2 | AJ4: 22115.6 | AK4: 18960
A5: 国内生产总值 (亿元) | B5: 1401879.2 | C5: 1348066.2 | D5: 1294271.7 | E5: 1234029.4 | F5: 1173823 | G5: 1034867.6 | H5: 1005872.4 | I5: 936010.1 | J5: 847382.9 | K5: 761193 | L5: 702511.5 | M5: 655782.9 | N5: 603660.4 | O5: 547510.6 | P5: 495707.6 | Q5: 419253.3 | R5: 354521.6 | S5: 324317.8 | T5: 274179.7 | U5: 222578.4 | V5: 189907.5 | W5: 164228 | X5: 139377.3 | Y5: 123311.9 | Z5: 112157.3 | AA5: 101308.6 | AB5: 91378.9 | AC5: 85863.9 | AD5: 80225 | AE5: 72210.6 | AF5: 61649.4 | AG5: 48862.2 | AH5: 35819.7 | AI5: 27295.6 | AJ5: 22070.9 | AK5: 18909.6
A6: 第一产业增加值 (亿元) | B6: 93346.8 | C6: 91635.8 | D6: 89169.1 | E6: 88207 | F6: 83216.5 | G6: 78030.9 | H6: 70473.6 | I6: 64745.2 | J6: 62099.5 | K6: 60139.2 | L6: 57774.6 | M6: 55626.3 | N6: 53028.1 | O6: 49084.6 | P6: 44781.5 | Q6: 38430.8 | R6: 33583.8 | S6: 32464.1 | T6: 27674.1 | U6: 23317 | V6: 21806.7 | W6: 20904.3 | X6: 16970.2 | Y6: 16190.2 | Z6: 15502.5 | AA6: 14717.4 | AB6: 14549 | AC6: 14618.7 | AD6: 14265.2 | AE6: 13878.3 | AF6: 12020.5 | AG6: 9471.8 | AH6: 6887.6 | AI6: 5800.3 | AJ6: 5288.8 | AK6: 5017.2
A7: 第二产业增加值 (亿元) | B7: 499653 | C7: 490305.4 | D7: 475936.1 | E7: 467629.6 | F7: 447138.2 | G7: 381985.8 | H7: 379860 | I7: 364835.2 | J7: 331580.5 | K7: 295427.8 | L7: 281338.9 | M7: 277282.8 | N7: 261951.6 | O7: 244639.1 | P7: 227035.1 | Q7: 191626.5 | R7: 160168.8 | S7: 149952.9 | T7: 126630.5 | U7: 104359.2 | V7: 88082.2 | W7: 74285 | X7: 62695.8 | Y7: 54104.1 | Z7: 49659.4 | AA7: 45663.7 | AB7: 41079.9 | AC7: 39017.5 | AD7: 37545 | AE7: 33827.3 | AF7: 28676.7 | AG7: 22452.5 | AH7: 16472.7 | AI7: 11725 | AJ7: 9129.6 | AK7: 7744.1
A8: 第三产业增加值 (亿元) | B8: 808879.3 | C8: 766124.9 | D8: 729166.5 | E8: 678192.7 | F8: 643468.4 | G8: 574850.9 | H8: 555538.9 | I8: 506429.8 | J8: 453702.9 | K8: 405626 | L8: 363397.9 | M8: 322873.8 | N8: 288680.7 | O8: 253786.9 | P8: 223891 | Q8: 189195.9 | R8: 160769 | S8: 141900.7 | T8: 119875 | U8: 94902.2 | V8: 80018.6 | W8: 69038.7 | X8: 59711.3 | Y8: 53017.6 | Z8: 46995.4 | AA8: 40927.6 | AB8: 35750 | AC8: 32227.7 | AD8: 28414.8 | AE8: 24505 | AF8: 20952.2 | AG8: 16937.9 | AH8: 12459.5 | AI8: 9770.3 | AJ8: 7652.5 | AK8: 6148.3
A9: 人均国内生产总值 (元) | B9: 99665 | C9: 95677 | D9: 91746 | E9: 87385 | F9: 83111 | G9: 73338 | H9: 71453 | I9: 66726 | J9: 60691 | K9: 54849 | L9: 50912 | M9: 47802 | N9: 44281 | O9: 40431 | P9: 36855 | Q9: 31341 | R9: 26631 | S9: 24483 | T9: 20805 | U9: 16977 | V9: 14567 | W9: 12671 | X9: 10818 | Y9: 9631 | Z9: 8818 | AA9: 8024 | AB9: 7294 | AC9: 6914 | AD9: 6522 | AE9: 5931 | AF9: 5117 | AG9: 4100 | AH9: 3040 | AI9: 2343 | AJ9: 1918 | AK9: 1666
A10: 国民总收入指数 (上年=100) | B10: 105 | C10: 105.1 | D10: 105.5 | E10: 103 | F10: 108.7 | G10: 101.8 | H10: 106.2 | I10: 106.4 | J10: 107.3 | K10: 106.8 | L10: 106.3 | M10: 108.5 | N10: 107.2 | O10: 108.6 | P10: 108.9 | Q10: 110.3 | R10: 108.6 | S10: 110.1 | T10: 114.6 | U10: 113.3 | V10: 111 | W10: 110.5 | X10: 110.6 | Y10: 109.7 | Z10: 108.1 | AA10: 108.7 | AB10: 108.1 | AC10: 107.4 | AD10: 109.6 | AE10: 110.2 | AF10: 109.4 | AG10: 113.1 | AH10: 113.6 | AI10: 114.1 | AJ10: 109.3 | AK10: 104.1
A11: 国内生产总值指数 (上年=100) | B11: 105 | C11: 105 | D11: 105.4 | E11: 103.1 | F11: 108.6 | G11: 102.3 | H11: 106.1 | I11: 106.8 | J11: 106.9 | K11: 106.8 | L11: 107 | M11: 107.5 | N11: 107.8 | O11: 107.9 | P11: 109.5 | Q11: 110.6 | R11: 109.4 | S11: 109.7 | T11: 114.2 | U11: 112.7 | V11: 111.5 | W11: 110.1 | X11: 110.1 | Y11: 109.2 | Z11: 108.3 | AA11: 108.6 | AB11: 107.7 | AC11: 107.9 | AD11: 109.3 | AE11: 110 | AF11: 111 | AG11: 113.1 | AH11: 113.9 | AI11: 114.3 | AJ11: 109.4 | AK11: 103.9
A12: 第一产业增加值指数 (上年=100) | B12: 103.9 | C12: 103.7 | D12: 104.1 | E12: 104.2 | F12: 107.1 | G12: 103.1 | H12: 103.1 | I12: 103.5 | J12: 104 | K12: 103.3 | L12: 103.9 | M12: 104.1 | N12: 103.8 | O12: 104.5 | P12: 104.2 | Q12: 104.3 | R12: 104 | S12: 105.2 | T12: 103.5 | U12: 104.8 | V12: 105.1 | W12: 106.1 | X12: 102.4 | Y12: 102.7 | Z12: 102.6 | AA12: 102.3 | AB12: 102.7 | AC12: 103.4 | AD12: 103.4 | AE12: 105 | AF12: 104.9 | AG12: 103.9 | AH12: 104.6 | AI12: 104.7 | AJ12: 102.4 | AK12: 107.3
A13: 第二产业增加值指数 (上年=100) | B13: 104.5 | C13: 105 | D13: 104.4 | E13: 102.3 | F13: 108.2 | G13: 102.1 | H13: 104.6 | I13: 105.8 | J13: 105.9 | K13: 106 | L13: 105.9 | M13: 107.2 | N13: 108 | O13: 108.4 | P13: 110.7 | Q13: 112.7 | R13: 110.3 | S13: 109.8 | T13: 115.1 | U13: 113.5 | V13: 112.1 | W13: 111.1 | X13: 112.7 | Y13: 109.9 | Z13: 108.5 | AA13: 109.5 | AB13: 108.2 | AC13: 108.9 | AD13: 110.5 | AE13: 112.1 | AF13: 113.8 | AG13: 118.1 | AH13: 119.7 | AI13: 121 | AJ13: 113.8 | AK13: 103.2
A14: 第三产业增加值指数 (上年=100) | B14: 105.4 | C14: 105.1 | D14: 106.3 | E14: 103.5 | F14: 109 | G14: 102.4 | H14: 107.6 | I14: 108 | J14: 108.1 | K14: 107.9 | L14: 108.6 | M14: 108.4 | N14: 108.3 | O14: 108 | P14: 109.3 | Q14: 109.6 | R14: 109.6 | S14: 110.5 | T14: 115.8 | U14: 114 | V14: 112.5 | W14: 110.2 | X14: 109.7 | Y14: 110.7 | Z14: 110.2 | AA14: 110 | AB14: 109.5 | AC14: 108.6 | AD14: 110.6 | AE14: 109.4 | AF14: 110.3 | AG14: 111.5 | AH14: 112.3 | AI14: 112.8 | AJ14: 109.6 | AK14: 102.7
A15: 人均国内生产总值指数 (上年=100) | B15: 105.1 | C15: 105.1 | D15: 105.5 | E15: 103.1 | F15: 108.5 | G15: 102.1 | H15: 105.7 | I15: 106.3 | J15: 106.2 | K15: 106.2 | L15: 106.4 | M15: 106.8 | N15: 107.1 | O15: 107.1 | P15: 108.9 | Q15: 110.1 | R15: 108.9 | S15: 109.1 | T15: 113.6 | U15: 112 | V15: 110.8 | W15: 109.5 | X15: 109.4 | Y15: 108.5 | Z15: 107.5 | AA15: 107.7 | AB15: 106.8 | AC15: 106.9 | AD15: 108.2 | AE15: 108.8 | AF15: 109.8 | AG15: 111.8 | AH15: 112.6 | AI15: 112.9 | AJ15: 107.9 | AK15: 102.4
... A21: 人均国内生产总值指数 (1978年=100) | B21: 3571.8 | C21: 3397.3 | D21: 3232.8 | E21: 3063.5 | F21: 2970 | G21: 2738 | H21: 2681.8 | I21: 2537.4 | J21: 2387.9 | K21: 2247.5 | L21: 2117 | M21: 1990.4 | N21: 1863.9 | O21: 1741 | P21: 1625.1 | Q21: 1492.8 | R21: 1356.4 | S21: 1245.9 | T21: 1141.9 | U21: 1005.6 | V21: 897.5 | W21: 810 | X21: 739.8 | Y21: 676 | Z21: 623 | AA21: 579.4 | AB21: 537.8 | AC21: 503.5 | AD21: 471.1 | AE21: 435.4 | AF21: 400.1 | AG21: 364.3 | AH21: 325.9 | AI21: 289.3 | AJ21: 256.3 | AK21: 237.5
A22: 数据来源：国家统计局
A25: Inflation Index | B25: =B5/C5/B11*100 -> 0.99039873 | C25: =C5/D5/C11*100 -> 0.99196527 | D25: =D5/E5/D11*100 -> 0.99508307 | E25: =E5/F5/E11*100 -> 1.0196808 | F25: =F5/G5/F11*100 -> 1.0444508 | G25: =G5/H5/G11*100 -> 1.0056949 | H25: =H5/I5/H11*100 -> 1.0128543 | I25: =I5/J5/I11*100 -> 1.0342597 | ... AJ25: =AJ5/AK5/AJ11*100 -> 1.0668918

Sheet OCCF-DpLOCU
B1: One Large Output Currency Unit
A2: Dollars | B2: =10^8*About!$A$30 -> 13873180

Sheet OCCF-DpMOCU
B1: One Small Output Currency Unit
A2: Dollars | B2: =10^4*About!$A$30 -> 1387.318

Sheet OCCF-DpSOCU
B1: One Small Output Currency Unit
A2: Dollars | B2: =1*About!A30 -> 0.1387318
