Workbook
Name BTU_per_GJ: #REF!
Name BTU_per_kcal: #REF!
Name BTU_per_kwh: #REF!
Name dollars_per_yuan: #REF!
Name gal_per_barrel: [1]About!$A$63
Name lignite_multiplier: '[2]Hard Coal and Lig Multipliers'!$N$16
Name nonlignite_multiplier: '[2]Hard Coal and Lig Multipliers'!$N$17
Name usd_per_yuan: '[3]Conv Factor'!$A$1
Name usd_per_yuan: '[3]Conv Factor'!$A$1
Name usd_per_yuan: 'Conv Factor'!$A$1

Sheet About
A1: BS BAU Subsidy for Thermal Fuels per Energy Unit Produced
A2: BS BAU Subsidy per Unit Electricity Output
A3: BS BAU Subsidy per Unit Electricity Capacity Built
A4: Source: | B4: Subsidies for Electricity Production from Renewables
B5: See tab for details.
B14: Total Fossil Fuel Subsidies Paid in 2013
B15: International Monetary Fund, Fiscal Affairs Department
B16: 2015
B17: How Large are Global Energy Subsidies?
B18: Detailed country-level data Excel files
B20: Total fossil fuel consuption by fuel in 2013
B21: China Statistics Press
B22: 2016
B23: China Energy Statistical Yearbook 2016
B25: Fossil fuel subsidy breakdown by fuel type in 2012
B26: International Energy Agency
B27: 2013
B28: World Energy Outlook 2013: Energy Subsidies
B29: http://www.iea.org/subsidy/index.html
B30: Via online data viewer
A32: Notes
A33: We use the elements of the "All Fuels" subscript on the "ForCSV-ThermalFuels" tab and
A34: elements of the "Electricity Source" subscript on the "ForCSV-NonThermalElec" tab.
A35: We fill out the rows for unused elements of these subscripts with zeroes, which prevents Vensim
A36: from generating a warning about missing data.
A38: Subsidy is calculated by subtracting the annualized cost of electricity output before subsidy from the average national price for that type of electricity in 2019. Most subsidies will be phased down based on latested projection of policy development.
A39: Note on Inclusion / Non-Inclusion of Subsidy Types for China
A40: In China, there is no power generation subsidy for nuclear, hydro, or fossil fuel generation.
A41: Although there are subsidies for wind, solar, biomass, and geothermal, using them to adjust
A42: the prices causes our BAU case capacity results to be quite different from the results of NCSC's model's
A43: BAU case (because they don't use electricity subsidies). NCSC has requested we not use
A44: these subsidies in the EPS, so that it is possible to more closely match their BAU scenario.
... A49: in the EPS.

Sheet Fossil Fuels
A1: Subsidy for Fossil Fuels in 2013
A2: Total | B2: 7.2147002e+09 | C2: 2013 USD | F2: =19*10^9 -> 19000000000 | G2: =F2-B2 -> 1.17853e+10 | I2: 12是油，7是电
A4: We allocate according to the way fossil fuel subsidies were divided in 2012 according to the IEA:
A6: 2012 Subsidy for Fossil Fuels by Fuel Type:
A7: coal | B7: 3300000000 | C7: 2012 USD
A8: natural gas | B8: 500000000 | C8: 2012 USD
A9: oil | B9: 12900000000 | C9: 2012 USD
A11: Subsidy for Fossil Fuels in 2013
A12: coal | B12: =B$2*(B7/SUM(B$7:B$9)) -> 1.4256593e+09 | C12: 2013 USD
A13: natural gas | B13: =B$2*(B8/SUM(B$7:B$9)) -> 2.1600899e+08 | C13: 2013 USD
A14: oil | B14: =B$2*(B9/SUM(B$7:B$9)) -> 5.5730319e+09 | C14: 2013 USD
A16: Consumption of Fossil Fuels in 2013 (from China Energy Statistical Yearbook 2016)
A17: total | B17: 400299 | C17: 10^4 tce
A18: coal | B18: 0.698 | C18: percentage of total
A19: natural gas | B19: 0.185 | C19: percentage of total
A20: oil | B20: 0.06 | C20: percentage of total
A22: coal | B22: =B$17*B18 -> 279408.7 | C22: 10^4 tce
A23: natural gas | B23: =B$17*B19 -> 74055.315 | C23: 10^4 tce
A24: oil | B24: =B$17*B20 -> 24017.94 | C24: 10^4 tce
A26: Conversion Factor | B26: 27778245 | C26: BTU / tce
A28: coal | B28: =B22*B$26*10^4 -> 7.7614834e+16 | C28: BTU
A29: natural gas | B29: =B23*B$26*10^4 -> 2.0571267e+16 | C29: BTU
A30: oil | B30: =B24*B$26*10^4 -> 6.6717622e+15 | C30: BTU
A32: Subsidy Rate in 2013
A33: coal | B33: =B12/B28 -> 1.8368387e-08 | C33: $ / BTU | E33: 2427094.2 | F33: 万tce
A34: natural gas | B34: =B13/B29 -> 1.050052e-08 | C34: $ / BTU | E34: =17.3*17.2%*10^9*7 -> 20829200000 | F34: yuan | G34: =17.3*10*6.8*17.2%/24 -> 8.4308667
A35: oil | B35: =B14/B30 -> 8.3531633e-07 | C35: $ / BTU | E35: =E34/E33 -> 8581.9496 | F35: yuan/万tce
E36: =E35/10000 -> 0.85819496

Sheet Conv Factor
A1: 0.14538 | B1: $/yuan

Sheet Capacity Price Peaker 
A1: It seems on natural gas has a capacity price. There are various pricing policies across the country. Use Zhejiang Province as a proxy and make adjustment based on the average national price for natural gas and Zhejiang's natural gas power price. https://zhuanlan.zhihu.com/p/42577257
A2: "浙江天然气发电，9F、6F机组电量电价为每千瓦时0.507元，9E、6B机组为每千瓦时0.567元;容量电价分成470、360和680元每千瓦每年三档。"
A3: National Natural Gas Power Price Average (RMB/MWh) | E3: 584.1
A4: Zhejiang Natural Gas Power Price (RMB/MWh) | E4: 507
A5: Assume natural gas peaker operating hours | E5: 900
A6: Zhejiang natural gas peaker capacity price (RMB/MWh) | E6: =SUM(470,360,680)/3*1000 -> 503333.33
A7: Calculated national natural gas peaker capacity price (RMB/MWh) | E7: =E6-(E3-E4)*E5 -> 433943.33 | I7: RMB/USD Exchange Rate 2018 | K7: We adjust 2018 dollars to 2012 dollars using the following conversion factor:
A8: Calculated national natural gas peaker capacity price ($/MWh in 2012 price) | E8: =E7/I8*K8 -> 59956.235 | I8: 6.6174 | K8: 0.9143

Sheet Solar 2019
A1: NEA. 2019. 2019年光伏发电项目国家补贴竞价工作总体情况.http://www.nea.gov.cn/2019-07/11/c_138217905.htm
B2: 2019 Rate
B3: RMB/KWh | C3: $/MWh
A4: Resources Region 1 | B4: 0.0663
A5: Resources Region 2 | B5: 0.0381
A6: Resources Region 3 | B6: 0.0749
A9: Average 2019 Price | B9: =AVERAGE(B4:B7) -> 0.059766667 | C9: =B9*1000/B12 -> 8.6493005
A10: Average 2012 Price | C10: =C9*B14*(1-B15) -> 7.7663246
A12: RMB - USD Exchange Rate 2019 | B12: 6.91
A14: We adjust 2018 dollars to 2012 dollars using the following conversion factor: | B14: 0.914
A15: 2019 inflation rate ($) | B15: 0.0176
A17: 2020 subsidy is assumed to declined by 11.5% based on the percentage of gudiance price change.
A18: Source: NDRC. 2020. 关于2020年光伏发电上网电价政策有关事项的通知
A19: Assume solar subsidy will end on 2023. This assumption is sourced from https://www.ne21.com/news/show-115169.html; Assume 2021 and 2022 will decrease by the same percentage as 2020.
B20: 2020 | C20: 2021 | D20: 2022
A21: Solar PV sub rate $/MWh in 2012 price | B21: =C10*(1-11.5%) -> 6.8731973 | C21: =B21*(1-11.5%) -> 6.0827796 | D21: =C21*(1-11.5%) -> 5.3832599
A23: Assume solar subsidy will end on 2023. This assumption is sourced from https://www.ne21.com/news/show-115169.html

Sheet Wind 2019
A1: Source: 上海证券报. 2019. 2021年我国陆上风电将全面进入平价时代.http://www.xinhuanet.com/2019-05/25/c_1124539698.htm
B3: 2019 | C3: 2020 | D3: 2020 decrease compare to 2019
A4: Average Grid purchase guidance price | B4: =AVERAGE(B6:B8) -> 0.44666667 | C4: =AVERAGE(C6:C8) -> 0.39666667 | D4: =1-C4/B4 -> 0.1119403
A5: Exclude resources region 1 from subsidy average as it is already lower than coal price
A6: Resources Region 2 | B6: 0.39 | C6: 0.34
A7: Resources Region 3 | B7: 0.43 | C7: 0.38
A8: Resources Region 4 | B8: 0.52 | C8: 0.47
A10: Difference from coal price (RMB/MWh 2019 price) | B10: =B4*1000-'Sub by Power Price'!B26 -> 76.146667 | C10: =C4*1000-'Sub by Power Price'!B26 -> 26.146667
A11: Subsidy ($/MWh 2012) | B11: =B10/'Solar 2019'!$B$12*'Solar 2019'!$B$14*(1-'Solar 2019'!$B$15) -> 9.8948086 | C11: =C10/'Solar 2019'!$B$12*'Solar 2019'!$B$14*(1-'Solar 2019'!$B$15) -> 3.3976046 | D11: =C11 -> 3.3976046
A13: Onshore wind subsidy will end on 2022;https://baijiahao.baidu.com/s?id=1634482543833385999&wfr=spider&for=pc

Sheet Sub by Power Price
A1: Unsubsidize Cost of Power Output ($/MWh) in 2012 price (2019 value); Source: Earlier EPS model run when subsidy is set as zero
A3: Time (Year) | B3: in 2012 price | G3: Subsidy needed
A4: BAU Cost per Unit New Elec Output Before Subsidies[hard coal es] : MostRecentRun | B4: 38.977
A5: BAU Cost per Unit New Elec Output Before Subsidies[natural gas nonpeaker es] : MostRecentRun | B5: 91.7269 | G5: =B5-$B$4 -> 52.7499
A6: BAU Cost per Unit New Elec Output Before Subsidies[nuclear es] : MostRecentRun | B6: 36.9543
A7: BAU Cost per Unit New Elec Output Before Subsidies[hydro es] : MostRecentRun | B7: 18.6402
A8: BAU Cost per Unit New Elec Output Before Subsidies[onshore wind es] : MostRecentRun | B8: 37.9143
A9: BAU Cost per Unit New Elec Output Before Subsidies[solar PV es] : MostRecentRun | B9: 41.7894 | G9: =B9-$B$4 -> 2.8124
A10: BAU Cost per Unit New Elec Output Before Subsidies[solar thermal es] : MostRecentRun | B10: 69.2681
A11: BAU Cost per Unit New Elec Output Before Subsidies[biomass es] : MostRecentRun | B11: 94.406 | G11: =B11-$B$4 -> 55.429
A12: BAU Cost per Unit New Elec Output Before Subsidies[geothermal es] : MostRecentRun | B12: 33.9714 | G12: =B12-$B$4 -> -5.0056
A13: BAU Cost per Unit New Elec Output Before Subsidies[petroleum es] : MostRecentRun | B13: 277.353 | G13: =B13-$B$4 -> 238.376
A14: BAU Cost per Unit New Elec Output Before Subsidies[natural gas peaker es] : MostRecentRun | B14: 152.164 | G14: =B14-$B$4 -> 113.187
A15: BAU Cost per Unit New Elec Output Before Subsidies[lignite es] : MostRecentRun | B15: 53.7762 | G15: =B15-$B$4 -> 14.7992
A16: BAU Cost per Unit New Elec Output Before Subsidies[offshore wind es] : MostRecentRun | B16: 69.8089 | G16: =B16-$B$4 -> 30.8319
A17: BAU Cost per Unit New Elec Output Before Subsidies[crude oil es] : MostRecentRun | B17: 78.71 | G17: =B17-$B$4 -> 39.733
A18: BAU Cost per Unit New Elec Output Before Subsidies[heavy or residual fuel oil es] : MostRecentRun | B18: 63.11 | G18: =B18-$B$4 -> 24.133
A19: BAU Cost per Unit New Elec Output Before Subsidies[municipal solid waste es] : MostRecentRun | B19: 30.5655
A22: Source: for all power except for MSW: NEA. 2019. National Power Price Regulation Report for 2018. 能源局.2019.2018年度全国电力价格情况监管通报 http://shoudian.bjx.com.cn/html/20191105/1018668.shtml
A23: Source for MSW: 中国产业信息网. 2019. 中国垃圾焚烧发电行业发展：多重政策支持发展及大气环保标准分析. https://www.cenews.com.cn/pollution_ctr/201906/t20190613_900356.html
B25: Coal | C25: Hydro | D25: Onshore Wind | F25: Natural Gas non-peaker | G25: Nuclear | H25: Biomass | I25: Natural Gas peaker | J25: municipal solid waste | N25: RMB/USD Exchange Rate 2018 | P25: We adjust 2018 dollars to 2012 dollars using the following conversion factor:
A26: Total National Average (RMB/MWh) 2018 Price | B26: 370.52 | C26: 267.19 | D26: 529.01 | F26: 584.1 | G26: 395.02 | H26: 677.99 | I26: =F26 -> 584.1 | J26: 650 | N26: 6.6174 | P26: 0.9143
A27: In 2012 Price (USD/MWh) | B27: =B26/$N$26*$P$26 -> 51.193284 | C27: =C26/$N$26*$P$26 -> 36.916586 | D27: =D26/$N$26*$P$26 -> 73.091221 | F27: =F26/$N$26*$P$26 -> 80.702788 | G27: =G26/$N$26*$P$26 -> 54.578352 | H27: =H26/$N$26*$P$26 -> 93.675198 | I27: =I26/$N$26*$P$26 -> 80.702788 | J27: =J26/$N$26*$P$26 -> 89.807931
A28: Subsidy (Difference of grid paid price and coal benchmark price, if the grid paid price is higher) | B28: =B27-$B$27 -> 0 | D28: =D27-$B$27 -> 21.897937 | F28: =F27-$B$27 -> 29.509504 | G28: =G27-$B$27 -> 3.3850682 | H28: =H27-$B$27 -> 42.481914 | I28: =I27-$B$27 -> 29.509504 | J28: =J27-$B$27 -> 38.614647
B31: 2019 | C31: 2020 | D31: 2021 | E31: 2022 | F31: 2023 | W31: 0.34 | X31: 0.29
A32: Onshore wind | B32: =D28 -> 21.897937 | C32: =B32-$B$32/3 -> 14.598625 | D32: =C32-$B$32/3 -> 7.2993123 | E32: 0 | F32: =0 -> 0 | W32: 0.39 | X32: 0.34
W33: 0.43 | X33: 0.38
W34: 0.52 | X34: 0.47
A35: Offshore Wind | B35: Source: https://finance.huanqiu.com/article/3wVEyZ7gvub | G35: Although national subsidy for off shore wind will end of 2020, subsidy still exist at the provicne level. We assume the subsidy will be 0.2 RMB/KWh in 2022 and reduce 0.05 per year until 2025. Assumption is sourced from https://www.reuters.com/article/中国经济：海上风电国家补贴2022年或取消，鼓励地方政府自行补贴-报载-idCNL4S29C047
B36: 2017 | C36: 2018 | D36: 2019 | E36: 2020 | F36: 2021 | G36: 2022 | H36: 2023 | I36: 2024 | J36: 2025 | K36: 2026 | L36: 2027 | M36: 2028 | N36: 2029 | O36: 2030
A37: Price price of current year | B37: 800 | C37: 800 | D37: 800 | E37: 750 | F37: 700
A38: In 2012 Price (USD/MWh) | B38: =B37/$N$26*$P$26 -> 110.53284 | C38: =C37/$N$26*$P$26 -> 110.53284 | D38: =D37/$N$26*$P$26 -> 110.53284 | E38: =E37/$N$26*$P$26 -> 103.62454 | F38: =F37/$N$26*$P$26 -> 96.716233
A39: Subsidy (Difference of grid paid price and coal benchmark price, if the grid paid price is higher) | B39: =D39 -> 59.339554 | C39: =D39 -> 59.339554 | D39: =D38-$B$27 -> 59.339554 | E39: =E38-$B$27 -> 52.431252 | F39: =F38-$B$27 -> 45.522949 | G39: =200/N26*P26 -> 27.633209 | H39: =150/N26*P26 -> 20.724907 | I39: =100/N26*P26 -> 13.816605 | J39: =50/N26*P26 -> 6.9083024 | K39: 0 | L39: 0 | M39: 0 | N39: 0 | O39: 0
I41: 1/1.3
A42: Solar Thermal | B42: Assume subsidy will end of the end of 2021. Source: http://www.cspplaza.com/article-15533-1.html; ,
B45: 2019 | C45: 2020 | D45: 2021 | E45: 2022 | F45: 2023 | G45: 2024 | H45: 2025 | I45: 2026 | J45: 2027 | K45: 2028 | L45: 2029 | M45: 2030
A46: Price | B46: 1140 | C46: 1100 | D46: 1100
A47: In 2012 Price (USD/MWh) | B47: =B46/$N$26*$P$26 -> 157.50929 | C47: =C46/$N$26*$P$26 -> 151.98265 | D47: =C47 -> 151.98265
A48: Subsidy comparied to Cost ($/MWh) 2012Price minus coal benchmark | B48: =B47-$B$27 -> 106.31601 | C48: =C47-$B$27 -> 100.78937 | D48: =D47-$B$27 -> 100.78937
A52: Additional subsidy for MSW
...

Sheet BS-BSfTFpEUP
A1: Year | B1: 2015 | C1: 2016 | D1: 2017 | E1: 2018 | F1: 2019 | G1: 2020 | H1: 2021 | I1: 2022 | J1: 2023 | K1: 2024 | L1: 2025 | M1: 2026 | N1: 2027 | O1: 2028 | P1: 2029 | Q1: 2030 | R1: 2031 | S1: 2032 | T1: 2033 | U1: 2034 | V1: 2035 | W1: 2036 | X1: 2037 | Y1: 2038 | Z1: 2039 | AA1: 2040 | AB1: 2041 | AC1: 2042 | AD1: 2043 | AE1: 2044 | AF1: 2045 | AG1: 2046 | AH1: 2047 | AI1: 2048 | AJ1: 2049 | AK1: 2050 | AL1: 2051 | AM1: 2052 | AN1: 2053 | AO1: 2054 | AP1: 2055 | AQ1: 2056 | AR1: 2057 | AS1: 2058 | AT1: 2059 | AU1: 2060
A2: electricity | B2: 0 | C2: =$B2 -> 0 | D2: =$B2 -> 0 | E2: =$B2 -> 0 | F2: =$B2 -> 0 | G2: =$B2 -> 0 | H2: =$B2 -> 0 | I2: =$B2 -> 0 | J2: =$B2 -> 0 | ... AU2: =$B2 -> 0
A3: hard coal ($/BTU) | B3: ='Fossil Fuels'!B33 -> 1.8368387e-08 | C3: =$B3 -> 1.8368387e-08 | D3: =$B3 -> 1.8368387e-08 | E3: =$B3 -> 1.8368387e-08 | F3: =$B3 -> 1.8368387e-08 | G3: =$B3 -> 1.8368387e-08 | H3: =$B3 -> 1.8368387e-08 | I3: =$B3 -> 1.8368387e-08 | J3: =$B3 -> 1.8368387e-08 | ... AU3: =$B3 -> 1.8368387e-08
A4: natural gas ($/BTU) | B4: ='Fossil Fuels'!B34 -> 1.050052e-08 | C4: =$B4 -> 1.050052e-08 | D4: =$B4 -> 1.050052e-08 | E4: =$B4 -> 1.050052e-08 | F4: =$B4 -> 1.050052e-08 | G4: =$B4 -> 1.050052e-08 | H4: =$B4 -> 1.050052e-08 | I4: =$B4 -> 1.050052e-08 | J4: =$B4 -> 1.050052e-08 | ... AU4: =$B4 -> 1.050052e-08
A5: nuclear | B5: 0 | C5: =$B5 -> 0 | D5: =$B5 -> 0 | E5: =$B5 -> 0 | F5: =$B5 -> 0 | G5: =$B5 -> 0 | H5: =$B5 -> 0 | I5: =$B5 -> 0 | J5: =$B5 -> 0 | ... AU5: =$B5 -> 0
A6: hydro | B6: 0 | C6: =$B6 -> 0 | D6: =$B6 -> 0 | E6: =$B6 -> 0 | F6: =$B6 -> 0 | G6: =$B6 -> 0 | H6: =$B6 -> 0 | I6: =$B6 -> 0 | J6: =$B6 -> 0 | ... AU6: =$B6 -> 0
A7: wind | B7: 0 | C7: =$B7 -> 0 | D7: =$B7 -> 0 | E7: =$B7 -> 0 | F7: =$B7 -> 0 | G7: =$B7 -> 0 | H7: =$B7 -> 0 | I7: =$B7 -> 0 | J7: =$B7 -> 0 | ... AU7: =$B7 -> 0
A8: solar | B8: 0 | C8: =$B8 -> 0 | D8: =$B8 -> 0 | E8: =$B8 -> 0 | F8: =$B8 -> 0 | G8: =$B8 -> 0 | H8: =$B8 -> 0 | I8: =$B8 -> 0 | J8: =$B8 -> 0 | ... AU8: =$B8 -> 0
A9: biomass ($/BTU) | B9: 0 | C9: =$B9 -> 0 | D9: =$B9 -> 0 | E9: =$B9 -> 0 | F9: =$B9 -> 0 | G9: =$B9 -> 0 | H9: =$B9 -> 0 | I9: =$B9 -> 0 | J9: =$B9 -> 0 | ... AU9: =$B9 -> 0
A10: petroleum gasoline ($/BTU) | B10: ='Fossil Fuels'!B35 -> 8.3531633e-07 | C10: =$B10 -> 8.3531633e-07 | D10: =$B10 -> 8.3531633e-07 | E10: =$B10 -> 8.3531633e-07 | F10: =$B10 -> 8.3531633e-07 | G10: =$B10 -> 8.3531633e-07 | H10: =$B10 -> 8.3531633e-07 | I10: =$B10 -> 8.3531633e-07 | J10: =$B10 -> 8.3531633e-07 | ... AU10: =$B10 -> 8.3531633e-07
A11: petroleum diesel ($/BTU) | B11: ='Fossil Fuels'!B35 -> 8.3531633e-07 | C11: =$B11 -> 8.3531633e-07 | D11: =$B11 -> 8.3531633e-07 | E11: =$B11 -> 8.3531633e-07 | F11: =$B11 -> 8.3531633e-07 | G11: =$B11 -> 8.3531633e-07 | H11: =$B11 -> 8.3531633e-07 | I11: =$B11 -> 8.3531633e-07 | J11: =$B11 -> 8.3531633e-07 | ... AU11: =$B11 -> 8.3531633e-07
A12: biofuel gasoline | B12: 0 | C12: =$B12 -> 0 | D12: =$B12 -> 0 | E12: =$B12 -> 0 | F12: =$B12 -> 0 | G12: =$B12 -> 0 | H12: =$B12 -> 0 | I12: =$B12 -> 0 | J12: =$B12 -> 0 | ... AU12: =$B12 -> 0
A13: biofuel diesel | B13: 0 | C13: =$B13 -> 0 | D13: =$B13 -> 0 | E13: =$B13 -> 0 | F13: =$B13 -> 0 | G13: =$B13 -> 0 | H13: =$B13 -> 0 | I13: =$B13 -> 0 | J13: =$B13 -> 0 | ... AU13: =$B13 -> 0
A14: jet fuel ($/BTU) | B14: ='Fossil Fuels'!B35 -> 8.3531633e-07 | C14: =$B14 -> 8.3531633e-07 | D14: =$B14 -> 8.3531633e-07 | E14: =$B14 -> 8.3531633e-07 | F14: =$B14 -> 8.3531633e-07 | G14: =$B14 -> 8.3531633e-07 | H14: =$B14 -> 8.3531633e-07 | I14: =$B14 -> 8.3531633e-07 | J14: =$B14 -> 8.3531633e-07 | ... AU14: =$B14 -> 8.3531633e-07
A15: heat | B15: 0 | C15: =$B15 -> 0 | D15: =$B15 -> 0 | E15: =$B15 -> 0 | F15: =$B15 -> 0 | G15: =$B15 -> 0 | H15: =$B15 -> 0 | I15: =$B15 -> 0 | J15: =$B15 -> 0 | ... AU15: =$B15 -> 0
A16: geothermal | B16: 0 | C16: =$B16 -> 0 | D16: =$B16 -> 0 | E16: =$B16 -> 0 | F16: =$B16 -> 0 | G16: =$B16 -> 0 | H16: =$B16 -> 0 | I16: =$B16 -> 0 | J16: =$B16 -> 0 | ... AU16: =$B16 -> 0
A17: lignite | B17: 0 | C17: =$B17 -> 0 | D17: =$B17 -> 0 | E17: =$B17 -> 0 | F17: =$B17 -> 0 | G17: =$B17 -> 0 | H17: =$B17 -> 0 | I17: =$B17 -> 0 | J17: =$B17 -> 0 | ... AU17: =$B17 -> 0
A18: crude oil | B18: 0 | C18: 0 | D18: 0 | E18: 0 | F18: 0 | G18: 0 | H18: 0 | I18: 0 | J18: 0 | K18: 0 | L18: 0 | M18: 0 | N18: 0 | O18: 0 | P18: 0 | Q18: 0 | R18: 0 | S18: 0 | T18: 0 | U18: 0 | V18: 0 | W18: 0 | X18: 0 | Y18: 0 | Z18: 0 | AA18: 0 | AB18: 0 | AC18: 0 | AD18: 0 | AE18: 0 | AF18: 0 | AG18: 0 | AH18: 0 | AI18: 0 | AJ18: 0 | AK18: 0 | AL18: 0 | AM18: 0 | AN18: 0 | AO18: 0 | AP18: 0 | AQ18: 0 | AR18: 0 | AS18: 0 | AT18: 0 | AU18: 0
A19: heavy fuel oil | B19: 0 | C19: 0 | D19: 0 | E19: 0 | F19: 0 | G19: 0 | H19: 0 | I19: 0 | J19: 0 | K19: 0 | L19: 0 | M19: 0 | N19: 0 | O19: 0 | P19: 0 | Q19: 0 | R19: 0 | S19: 0 | T19: 0 | U19: 0 | V19: 0 | W19: 0 | X19: 0 | Y19: 0 | Z19: 0 | AA19: 0 | AB19: 0 | AC19: 0 | AD19: 0 | AE19: 0 | AF19: 0 | AG19: 0 | AH19: 0 | AI19: 0 | AJ19: 0 | AK19: 0 | AL19: 0 | AM19: 0 | AN19: 0 | AO19: 0 | AP19: 0 | AQ19: 0 | AR19: 0 | AS19: 0 | AT19: 0 | AU19: 0
A20: LPG propane or butane | B20: 0 | C20: 0 | D20: 0 | E20: 0 | F20: 0 | G20: 0 | H20: 0 | I20: 0 | J20: 0 | K20: 0 | L20: 0 | M20: 0 | N20: 0 | O20: 0 | P20: 0 | Q20: 0 | R20: 0 | S20: 0 | T20: 0 | U20: 0 | V20: 0 | W20: 0 | X20: 0 | Y20: 0 | Z20: 0 | AA20: 0 | AB20: 0 | AC20: 0 | AD20: 0 | AE20: 0 | AF20: 0 | AG20: 0 | AH20: 0 | AI20: 0 | AJ20: 0 | AK20: 0 | AL20: 0 | AM20: 0 | AN20: 0 | AO20: 0 | AP20: 0 | AQ20: 0 | AR20: 0 | AS20: 0 | AT20: 0 | AU20: 0
A21: municipal solid waste | B21: 0 | C21: 0 | D21: 0 | E21: 0 | F21: 0 | G21: 0 | H21: 0 | I21: 0 | J21: 0 | K21: 0 | L21: 0 | M21: 0 | N21: 0 | O21: 0 | P21: 0 | Q21: 0 | R21: 0 | S21: 0 | T21: 0 | U21: 0 | V21: 0 | W21: 0 | X21: 0 | Y21: 0 | Z21: 0 | AA21: 0 | AB21: 0 | AC21: 0 | AD21: 0 | AE21: 0 | AF21: 0 | AG21: 0 | AH21: 0 | AI21: 0 | AJ21: 0 | AK21: 0 | AL21: 0 | AM21: 0 | AN21: 0 | AO21: 0 | AP21: 0 | AQ21: 0 | AR21: 0 | AS21: 0 | AT21: 0 | AU21: 0
A22: hydrogen | B22: 0 | C22: 0 | D22: 0 | E22: 0 | F22: 0 | G22: 0 | H22: 0 | I22: 0 | J22: 0 | K22: 0 | L22: 0 | M22: 0 | N22: 0 | O22: 0 | P22: 0 | Q22: 0 | R22: 0 | S22: 0 | T22: 0 | U22: 0 | V22: 0 | W22: 0 | X22: 0 | Y22: 0 | Z22: 0 | AA22: 0 | AB22: 0 | AC22: 0 | AD22: 0 | AE22: 0 | AF22: 0 | AG22: 0 | AH22: 0 | AI22: 0 | AJ22: 0 | AK22: 0 | AL22: 0 | AM22: 0 | AN22: 0 | AO22: 0 | AP22: 0 | AQ22: 0 | AR22: 0 | AS22: 0 | AT22: 0 | AU22: 0

Sheet BS-BSpUEO-PreRet
A1: Year | B1: 2019 | C1: 2020 | D1: 2021 | E1: 2022 | F1: 2023 | G1: 2024 | H1: 2025 | I1: 2026 | J1: 2027 | K1: 2028 | L1: 2029 | M1: 2030 | N1: 2031 | O1: 2032 | P1: 2033 | Q1: 2034 | R1: 2035 | S1: 2036 | T1: 2037 | U1: 2038 | V1: 2039 | W1: 2040 | X1: 2041 | Y1: 2042 | Z1: 2043 | AA1: 2044 | AB1: 2045 | AC1: 2046 | AD1: 2047 | AE1: 2048 | AF1: 2049 | AG1: 2050 | AH1: 2051 | AI1: 2052 | AJ1: 2053 | AK1: 2054 | AL1: 2055 | AM1: 2056 | AN1: 2057 | AO1: 2058 | AP1: 2059 | AQ1: 2060
A2: hard coal ($/MWh) | B2: 0 | C2: 0 | D2: 0 | E2: 0 | F2: 0 | G2: 0 | H2: 0 | I2: 0 | J2: 0 | K2: 0 | L2: 0 | M2: 0 | N2: 0 | O2: 0 | P2: 0 | Q2: 0 | R2: 0 | S2: 0 | T2: 0 | U2: 0 | V2: 0 | W2: 0 | X2: 0 | Y2: 0 | Z2: 0 | AA2: 0 | AB2: 0 | AC2: 0 | AD2: 0 | AE2: 0 | AF2: 0 | AG2: 0 | AH2: 0 | AI2: 0 | AJ2: 0 | AK2: 0 | AL2: 0 | AM2: 0 | AN2: 0 | AO2: 0 | AP2: 0 | AQ2: 0
A3: natural gas nonpeaker ($/MWh) | B3: 0 | C3: 0 | D3: 0 | E3: 0 | F3: 0 | G3: 0 | H3: 0 | I3: 0 | J3: 0 | K3: 0 | L3: 0 | M3: 0 | N3: 0 | O3: 0 | P3: 0 | Q3: 0 | R3: 0 | S3: 0 | T3: 0 | U3: 0 | V3: 0 | W3: 0 | X3: 0 | Y3: 0 | Z3: 0 | AA3: 0 | AB3: 0 | AC3: 0 | AD3: 0 | AE3: 0 | AF3: 0 | AG3: 0 | AH3: 0 | AI3: 0 | AJ3: 0 | AK3: 0 | AL3: 0 | AM3: 0 | AN3: 0 | AO3: 0 | AP3: 0 | AQ3: 0
A4: nuclear ($/MWh) | B4: 0 | C4: 0 | D4: 0 | E4: 0 | F4: 0 | G4: 0 | H4: 0 | I4: 0 | J4: 0 | K4: 0 | L4: 0 | M4: 0 | N4: 0 | O4: 0 | P4: 0 | Q4: 0 | R4: 0 | S4: 0 | T4: 0 | U4: 0 | V4: 0 | W4: 0 | X4: 0 | Y4: 0 | Z4: 0 | AA4: 0 | AB4: 0 | AC4: 0 | AD4: 0 | AE4: 0 | AF4: 0 | AG4: 0 | AH4: 0 | AI4: 0 | AJ4: 0 | AK4: 0 | AL4: 0 | AM4: 0 | AN4: 0 | AO4: 0 | AP4: 0 | AQ4: 0
A5: hydro ($/MWh) | B5: 0 | C5: 0 | D5: 0 | E5: 0 | F5: 0 | G5: 0 | H5: 0 | I5: 0 | J5: 0 | K5: 0 | L5: 0 | M5: 0 | N5: 0 | O5: 0 | P5: 0 | Q5: 0 | R5: 0 | S5: 0 | T5: 0 | U5: 0 | V5: 0 | W5: 0 | X5: 0 | Y5: 0 | Z5: 0 | AA5: 0 | AB5: 0 | AC5: 0 | AD5: 0 | AE5: 0 | AF5: 0 | AG5: 0 | AH5: 0 | AI5: 0 | AJ5: 0 | AK5: 0 | AL5: 0 | AM5: 0 | AN5: 0 | AO5: 0 | AP5: 0 | AQ5: 0
A6: onshore wind ($/MWh) | B6: 0 | C6: 0 | D6: 0 | E6: 0 | F6: 0 | G6: 0 | H6: 0 | I6: 0 | J6: 0 | K6: 0 | L6: 0 | M6: 0 | N6: 0 | O6: 0 | P6: 0 | Q6: 0 | R6: 0 | S6: 0 | T6: 0 | U6: 0 | V6: 0 | W6: 0 | X6: 0 | Y6: 0 | Z6: 0 | AA6: 0 | AB6: 0 | AC6: 0 | AD6: 0 | AE6: 0 | AF6: 0 | AG6: 0 | AH6: 0 | AI6: 0 | AJ6: 0 | AK6: 0 | AL6: 0 | AM6: 0 | AN6: 0 | AO6: 0 | AP6: 0 | AQ6: 0
A7: solar PV ($/MWh) | B7: 0 | C7: 0 | D7: 0 | E7: 0 | F7: 0 | G7: 0 | H7: 0 | I7: 0 | J7: 0 | K7: 0 | L7: 0 | M7: 0 | N7: 0 | O7: 0 | P7: 0 | Q7: 0 | R7: 0 | S7: 0 | T7: 0 | U7: 0 | V7: 0 | W7: 0 | X7: 0 | Y7: 0 | Z7: 0 | AA7: 0 | AB7: 0 | AC7: 0 | AD7: 0 | AE7: 0 | AF7: 0 | AG7: 0 | AH7: 0 | AI7: 0 | AJ7: 0 | AK7: 0 | AL7: 0 | AM7: 0 | AN7: 0 | AO7: 0 | AP7: 0 | AQ7: 0
A8: solar thermal ($/MWh) | B8: 0 | C8: 0 | D8: 0 | E8: 0 | F8: 0 | G8: 0 | H8: 0 | I8: 0 | J8: 0 | K8: 0 | L8: 0 | M8: 0 | N8: 0 | O8: 0 | P8: 0 | Q8: 0 | R8: 0 | S8: 0 | T8: 0 | U8: 0 | V8: 0 | W8: 0 | X8: 0 | Y8: 0 | Z8: 0 | AA8: 0 | AB8: 0 | AC8: 0 | AD8: 0 | AE8: 0 | AF8: 0 | AG8: 0 | AH8: 0 | AI8: 0 | AJ8: 0 | AK8: 0 | AL8: 0 | AM8: 0 | AN8: 0 | AO8: 0 | AP8: 0 | AQ8: 0
A9: biomass ($/MWh) | B9: 0 | C9: 0 | D9: 0 | E9: 0 | F9: 0 | G9: 0 | H9: 0 | I9: 0 | J9: 0 | K9: 0 | L9: 0 | M9: 0 | N9: 0 | O9: 0 | P9: 0 | Q9: 0 | R9: 0 | S9: 0 | T9: 0 | U9: 0 | V9: 0 | W9: 0 | X9: 0 | Y9: 0 | Z9: 0 | AA9: 0 | AB9: 0 | AC9: 0 | AD9: 0 | AE9: 0 | AF9: 0 | AG9: 0 | AH9: 0 | AI9: 0 | AJ9: 0 | AK9: 0 | AL9: 0 | AM9: 0 | AN9: 0 | AO9: 0 | AP9: 0 | AQ9: 0
A10: geothermal ($/MWh) | B10: 0 | C10: 0 | D10: 0 | E10: 0 | F10: 0 | G10: 0 | H10: 0 | I10: 0 | J10: 0 | K10: 0 | L10: 0 | M10: 0 | N10: 0 | O10: 0 | P10: 0 | Q10: 0 | R10: 0 | S10: 0 | T10: 0 | U10: 0 | V10: 0 | W10: 0 | X10: 0 | Y10: 0 | Z10: 0 | AA10: 0 | AB10: 0 | AC10: 0 | AD10: 0 | AE10: 0 | AF10: 0 | AG10: 0 | AH10: 0 | AI10: 0 | AJ10: 0 | AK10: 0 | AL10: 0 | AM10: 0 | AN10: 0 | AO10: 0 | AP10: 0 | AQ10: 0
A11: petroleum ($/MWh) | B11: 0 | C11: 0 | D11: 0 | E11: 0 | F11: 0 | G11: 0 | H11: 0 | I11: 0 | J11: 0 | K11: 0 | L11: 0 | M11: 0 | N11: 0 | O11: 0 | P11: 0 | Q11: 0 | R11: 0 | S11: 0 | T11: 0 | U11: 0 | V11: 0 | W11: 0 | X11: 0 | Y11: 0 | Z11: 0 | AA11: 0 | AB11: 0 | AC11: 0 | AD11: 0 | AE11: 0 | AF11: 0 | AG11: 0 | AH11: 0 | AI11: 0 | AJ11: 0 | AK11: 0 | AL11: 0 | AM11: 0 | AN11: 0 | AO11: 0 | AP11: 0 | AQ11: 0
A12: natural gas peaker ($/MWh) | B12: 0 | C12: 0 | D12: 0 | E12: 0 | F12: 0 | G12: 0 | H12: 0 | I12: 0 | J12: 0 | K12: 0 | L12: 0 | M12: 0 | N12: 0 | O12: 0 | P12: 0 | Q12: 0 | R12: 0 | S12: 0 | T12: 0 | U12: 0 | V12: 0 | W12: 0 | X12: 0 | Y12: 0 | Z12: 0 | AA12: 0 | AB12: 0 | AC12: 0 | AD12: 0 | AE12: 0 | AF12: 0 | AG12: 0 | AH12: 0 | AI12: 0 | AJ12: 0 | AK12: 0 | AL12: 0 | AM12: 0 | AN12: 0 | AO12: 0 | AP12: 0 | AQ12: 0
... A17: municipal solid waste ($/MWh) | B17: 0 | C17: 0 | D17: 0 | E17: 0 | F17: 0 | G17: 0 | H17: 0 | I17: 0 | J17: 0 | K17: 0 | L17: 0 | M17: 0 | N17: 0 | O17: 0 | P17: 0 | Q17: 0 | R17: 0 | S17: 0 | T17: 0 | U17: 0 | V17: 0 | W17: 0 | X17: 0 | Y17: 0 | Z17: 0 | AA17: 0 | AB17: 0 | AC17: 0 | AD17: 0 | AE17: 0 | AF17: 0 | AG17: 0 | AH17: 0 | AI17: 0 | AJ17: 0 | AK17: 0 | AL17: 0 | AM17: 0 | AN17: 0 | AO17: 0 | AP17: 0 | AQ17: 0

Sheet BS-BSpUEO-PreNonRet
A1: Year | B1: 2019 | C1: 2020 | D1: 2021 | E1: 2022 | F1: 2023 | G1: 2024 | H1: 2025 | I1: 2026 | J1: 2027 | K1: 2028 | L1: 2029 | M1: 2030 | N1: 2031 | O1: 2032 | P1: 2033 | Q1: 2034 | R1: 2035 | S1: 2036 | T1: 2037 | U1: 2038 | V1: 2039 | W1: 2040 | X1: 2041 | Y1: 2042 | Z1: 2043 | AA1: 2044 | AB1: 2045 | AC1: 2046 | AD1: 2047 | AE1: 2048 | AF1: 2049 | AG1: 2050 | AH1: 2051 | AI1: 2052 | AJ1: 2053 | AK1: 2054 | AL1: 2055 | AM1: 2056 | AN1: 2057 | AO1: 2058 | AP1: 2059 | AQ1: 2060
A2: hard coal ($/MWh) | B2: 0 | C2: 0 | D2: 0 | E2: 0 | F2: 0 | G2: 0 | H2: 0 | I2: 0 | J2: 0 | K2: 0 | L2: 0 | M2: 0 | N2: 0 | O2: 0 | P2: 0 | Q2: 0 | R2: 0 | S2: 0 | T2: 0 | U2: 0 | V2: 0 | W2: 0 | X2: 0 | Y2: 0 | Z2: 0 | AA2: 0 | AB2: 0 | AC2: 0 | AD2: 0 | AE2: 0 | AF2: 0 | AG2: 0 | AH2: 0 | AI2: 0 | AJ2: 0 | AK2: 0 | AL2: 0 | AM2: 0 | AN2: 0 | AO2: 0 | AP2: 0 | AQ2: 0
A3: natural gas nonpeaker ($/MWh) | B3: 0 | C3: 0 | D3: 0 | E3: 0 | F3: 0 | G3: 0 | H3: 0 | I3: 0 | J3: 0 | K3: 0 | L3: 0 | M3: 0 | N3: 0 | O3: 0 | P3: 0 | Q3: 0 | R3: 0 | S3: 0 | T3: 0 | U3: 0 | V3: 0 | W3: 0 | X3: 0 | Y3: 0 | Z3: 0 | AA3: 0 | AB3: 0 | AC3: 0 | AD3: 0 | AE3: 0 | AF3: 0 | AG3: 0 | AH3: 0 | AI3: 0 | AJ3: 0 | AK3: 0 | AL3: 0 | AM3: 0 | AN3: 0 | AO3: 0 | AP3: 0 | AQ3: 0
A4: nuclear ($/MWh) | B4: 0 | C4: 0 | D4: 0 | E4: 0 | F4: 0 | G4: 0 | H4: 0 | I4: 0 | J4: 0 | K4: 0 | L4: 0 | M4: 0 | N4: 0 | O4: 0 | P4: 0 | Q4: 0 | R4: 0 | S4: 0 | T4: 0 | U4: 0 | V4: 0 | W4: 0 | X4: 0 | Y4: 0 | Z4: 0 | AA4: 0 | AB4: 0 | AC4: 0 | AD4: 0 | AE4: 0 | AF4: 0 | AG4: 0 | AH4: 0 | AI4: 0 | AJ4: 0 | AK4: 0 | AL4: 0 | AM4: 0 | AN4: 0 | AO4: 0 | AP4: 0 | AQ4: 0
A5: hydro ($/MWh) | B5: 0 | C5: 0 | D5: 0 | E5: 0 | F5: 0 | G5: 0 | H5: 0 | I5: 0 | J5: 0 | K5: 0 | L5: 0 | M5: 0 | N5: 0 | O5: 0 | P5: 0 | Q5: 0 | R5: 0 | S5: 0 | T5: 0 | U5: 0 | V5: 0 | W5: 0 | X5: 0 | Y5: 0 | Z5: 0 | AA5: 0 | AB5: 0 | AC5: 0 | AD5: 0 | AE5: 0 | AF5: 0 | AG5: 0 | AH5: 0 | AI5: 0 | AJ5: 0 | AK5: 0 | AL5: 0 | AM5: 0 | AN5: 0 | AO5: 0 | AP5: 0 | AQ5: 0
A6: onshore wind ($/MWh) | B6: 0 | C6: 0 | D6: 0 | E6: 0 | F6: 0 | G6: 0 | H6: 0 | I6: 0 | J6: 0 | K6: 0 | L6: 0 | M6: 0 | N6: 0 | O6: 0 | P6: 0 | Q6: 0 | R6: 0 | S6: 0 | T6: 0 | U6: 0 | V6: 0 | W6: 0 | X6: 0 | Y6: 0 | Z6: 0 | AA6: 0 | AB6: 0 | AC6: 0 | AD6: 0 | AE6: 0 | AF6: 0 | AG6: 0 | AH6: 0 | AI6: 0 | AJ6: 0 | AK6: 0 | AL6: 0 | AM6: 0 | AN6: 0 | AO6: 0 | AP6: 0 | AQ6: 0
A7: solar PV ($/MWh) | B7: 0 | C7: 0 | D7: 0 | E7: 0 | F7: 0 | G7: 0 | H7: 0 | I7: 0 | J7: 0 | K7: 0 | L7: 0 | M7: 0 | N7: 0 | O7: 0 | P7: 0 | Q7: 0 | R7: 0 | S7: 0 | T7: 0 | U7: 0 | V7: 0 | W7: 0 | X7: 0 | Y7: 0 | Z7: 0 | AA7: 0 | AB7: 0 | AC7: 0 | AD7: 0 | AE7: 0 | AF7: 0 | AG7: 0 | AH7: 0 | AI7: 0 | AJ7: 0 | AK7: 0 | AL7: 0 | AM7: 0 | AN7: 0 | AO7: 0 | AP7: 0 | AQ7: 0
A8: solar thermal ($/MWh) | B8: 0 | C8: 0 | D8: 0 | E8: 0 | F8: 0 | G8: 0 | H8: 0 | I8: 0 | J8: 0 | K8: 0 | L8: 0 | M8: 0 | N8: 0 | O8: 0 | P8: 0 | Q8: 0 | R8: 0 | S8: 0 | T8: 0 | U8: 0 | V8: 0 | W8: 0 | X8: 0 | Y8: 0 | Z8: 0 | AA8: 0 | AB8: 0 | AC8: 0 | AD8: 0 | AE8: 0 | AF8: 0 | AG8: 0 | AH8: 0 | AI8: 0 | AJ8: 0 | AK8: 0 | AL8: 0 | AM8: 0 | AN8: 0 | AO8: 0 | AP8: 0 | AQ8: 0
A9: biomass ($/MWh) | B9: 0 | C9: 0 | D9: 0 | E9: 0 | F9: 0 | G9: 0 | H9: 0 | I9: 0 | J9: 0 | K9: 0 | L9: 0 | M9: 0 | N9: 0 | O9: 0 | P9: 0 | Q9: 0 | R9: 0 | S9: 0 | T9: 0 | U9: 0 | V9: 0 | W9: 0 | X9: 0 | Y9: 0 | Z9: 0 | AA9: 0 | AB9: 0 | AC9: 0 | AD9: 0 | AE9: 0 | AF9: 0 | AG9: 0 | AH9: 0 | AI9: 0 | AJ9: 0 | AK9: 0 | AL9: 0 | AM9: 0 | AN9: 0 | AO9: 0 | AP9: 0 | AQ9: 0
A10: geothermal ($/MWh) | B10: 0 | C10: 0 | D10: 0 | E10: 0 | F10: 0 | G10: 0 | H10: 0 | I10: 0 | J10: 0 | K10: 0 | L10: 0 | M10: 0 | N10: 0 | O10: 0 | P10: 0 | Q10: 0 | R10: 0 | S10: 0 | T10: 0 | U10: 0 | V10: 0 | W10: 0 | X10: 0 | Y10: 0 | Z10: 0 | AA10: 0 | AB10: 0 | AC10: 0 | AD10: 0 | AE10: 0 | AF10: 0 | AG10: 0 | AH10: 0 | AI10: 0 | AJ10: 0 | AK10: 0 | AL10: 0 | AM10: 0 | AN10: 0 | AO10: 0 | AP10: 0 | AQ10: 0
A11: petroleum ($/MWh) | B11: 0 | C11: 0 | D11: 0 | E11: 0 | F11: 0 | G11: 0 | H11: 0 | I11: 0 | J11: 0 | K11: 0 | L11: 0 | M11: 0 | N11: 0 | O11: 0 | P11: 0 | Q11: 0 | R11: 0 | S11: 0 | T11: 0 | U11: 0 | V11: 0 | W11: 0 | X11: 0 | Y11: 0 | Z11: 0 | AA11: 0 | AB11: 0 | AC11: 0 | AD11: 0 | AE11: 0 | AF11: 0 | AG11: 0 | AH11: 0 | AI11: 0 | AJ11: 0 | AK11: 0 | AL11: 0 | AM11: 0 | AN11: 0 | AO11: 0 | AP11: 0 | AQ11: 0
A12: natural gas peaker ($/MWh) | B12: 0 | C12: 0 | D12: 0 | E12: 0 | F12: 0 | G12: 0 | H12: 0 | I12: 0 | J12: 0 | K12: 0 | L12: 0 | M12: 0 | N12: 0 | O12: 0 | P12: 0 | Q12: 0 | R12: 0 | S12: 0 | T12: 0 | U12: 0 | V12: 0 | W12: 0 | X12: 0 | Y12: 0 | Z12: 0 | AA12: 0 | AB12: 0 | AC12: 0 | AD12: 0 | AE12: 0 | AF12: 0 | AG12: 0 | AH12: 0 | AI12: 0 | AJ12: 0 | AK12: 0 | AL12: 0 | AM12: 0 | AN12: 0 | AO12: 0 | AP12: 0 | AQ12: 0
... A17: municipal solid waste ($/MWh) | B17: 0 | C17: 0 | D17: 0 | E17: 0 | F17: 0 | G17: 0 | H17: 0 | I17: 0 | J17: 0 | K17: 0 | L17: 0 | M17: 0 | N17: 0 | O17: 0 | P17: 0 | Q17: 0 | R17: 0 | S17: 0 | T17: 0 | U17: 0 | V17: 0 | W17: 0 | X17: 0 | Y17: 0 | Z17: 0 | AA17: 0 | AB17: 0 | AC17: 0 | AD17: 0 | AE17: 0 | AF17: 0 | AG17: 0 | AH17: 0 | AI17: 0 | AJ17: 0 | AK17: 0 | AL17: 0 | AM17: 0 | AN17: 0 | AO17: 0 | AP17: 0 | AQ17: 0

Sheet BS-BSpUEO-NewBlt
A1: Year | B1: 2019 | C1: 2020 | D1: 2021 | E1: 2022 | F1: 2023 | G1: 2024 | H1: 2025 | I1: 2026 | J1: 2027 | K1: 2028 | L1: 2029 | M1: 2030 | N1: 2031 | O1: 2032 | P1: 2033 | Q1: 2034 | R1: 2035 | S1: 2036 | T1: 2037 | U1: 2038 | V1: 2039 | W1: 2040 | X1: 2041 | Y1: 2042 | Z1: 2043 | AA1: 2044 | AB1: 2045 | AC1: 2046 | AD1: 2047 | AE1: 2048 | AF1: 2049 | AG1: 2050 | AH1: 2051 | AI1: 2052 | AJ1: 2053 | AK1: 2054 | AL1: 2055 | AM1: 2056 | AN1: 2057 | AO1: 2058 | AP1: 2059 | AQ1: 2060
A2: hard coal ($/MWh) | B2: 0 | C2: 0 | D2: 0 | E2: 0 | F2: 0 | G2: 0 | H2: 0 | I2: 0 | J2: 0 | K2: 0 | L2: 0 | M2: 0 | N2: 0 | O2: 0 | P2: 0 | Q2: 0 | R2: 0 | S2: 0 | T2: 0 | U2: 0 | V2: 0 | W2: 0 | X2: 0 | Y2: 0 | Z2: 0 | AA2: 0 | AB2: 0 | AC2: 0 | AD2: 0 | AE2: 0 | AF2: 0 | AG2: 0 | AH2: 0 | AI2: 0 | AJ2: 0 | AK2: 0 | AL2: 0 | AM2: 0 | AN2: 0 | AO2: 0 | AP2: 0 | AQ2: 0
A3: natural gas nonpeaker ($/MWh) | B3: 0 | C3: 0 | D3: 0 | E3: 0 | F3: 0 | G3: 0 | H3: 0 | I3: 0 | J3: 0 | K3: 0 | L3: 0 | M3: 0 | N3: 0 | O3: 0 | P3: 0 | Q3: 0 | R3: 0 | S3: 0 | T3: 0 | U3: 0 | V3: 0 | W3: 0 | X3: 0 | Y3: 0 | Z3: 0 | AA3: 0 | AB3: 0 | AC3: 0 | AD3: 0 | AE3: 0 | AF3: 0 | AG3: 0 | AH3: 0 | AI3: 0 | AJ3: 0 | AK3: 0 | AL3: 0 | AM3: 0 | AN3: 0 | AO3: 0 | AP3: 0 | AQ3: 0
A4: nuclear ($/MWh) | B4: 0 | C4: 0 | D4: 0 | E4: 0 | F4: 0 | G4: 0 | H4: 0 | I4: 0 | J4: 0 | K4: 0 | L4: 0 | M4: 0 | N4: 0 | O4: 0 | P4: 0 | Q4: 0 | R4: 0 | S4: 0 | T4: 0 | U4: 0 | V4: 0 | W4: 0 | X4: 0 | Y4: 0 | Z4: 0 | AA4: 0 | AB4: 0 | AC4: 0 | AD4: 0 | AE4: 0 | AF4: 0 | AG4: 0 | AH4: 0 | AI4: 0 | AJ4: 0 | AK4: 0 | AL4: 0 | AM4: 0 | AN4: 0 | AO4: 0 | AP4: 0 | AQ4: 0
A5: hydro ($/MWh) | B5: 0 | C5: 0 | D5: 0 | E5: 0 | F5: 0 | G5: 0 | H5: 0 | I5: 0 | J5: 0 | K5: 0 | L5: 0 | M5: 0 | N5: 0 | O5: 0 | P5: 0 | Q5: 0 | R5: 0 | S5: 0 | T5: 0 | U5: 0 | V5: 0 | W5: 0 | X5: 0 | Y5: 0 | Z5: 0 | AA5: 0 | AB5: 0 | AC5: 0 | AD5: 0 | AE5: 0 | AF5: 0 | AG5: 0 | AH5: 0 | AI5: 0 | AJ5: 0 | AK5: 0 | AL5: 0 | AM5: 0 | AN5: 0 | AO5: 0 | AP5: 0 | AQ5: 0
A6: onshore wind ($/MWh) | B6: 0 | C6: 0 | D6: 0 | E6: 0 | F6: 0 | G6: 0 | H6: 0 | I6: 0 | J6: 0 | K6: 0 | L6: 0 | M6: 0 | N6: 0 | O6: 0 | P6: 0 | Q6: 0 | R6: 0 | S6: 0 | T6: 0 | U6: 0 | V6: 0 | W6: 0 | X6: 0 | Y6: 0 | Z6: 0 | AA6: 0 | AB6: 0 | AC6: 0 | AD6: 0 | AE6: 0 | AF6: 0 | AG6: 0 | AH6: 0 | AI6: 0 | AJ6: 0 | AK6: 0 | AL6: 0 | AM6: 0 | AN6: 0 | AO6: 0 | AP6: 0 | AQ6: 0
A7: solar PV ($/MWh) | B7: 0 | C7: 0 | D7: 0 | E7: 0 | F7: 0 | G7: 0 | H7: 0 | I7: 0 | J7: 0 | K7: 0 | L7: 0 | M7: 0 | N7: 0 | O7: 0 | P7: 0 | Q7: 0 | R7: 0 | S7: 0 | T7: 0 | U7: 0 | V7: 0 | W7: 0 | X7: 0 | Y7: 0 | Z7: 0 | AA7: 0 | AB7: 0 | AC7: 0 | AD7: 0 | AE7: 0 | AF7: 0 | AG7: 0 | AH7: 0 | AI7: 0 | AJ7: 0 | AK7: 0 | AL7: 0 | AM7: 0 | AN7: 0 | AO7: 0 | AP7: 0 | AQ7: 0
A8: solar thermal ($/MWh) | B8: 0 | C8: 0 | D8: 0 | E8: 0 | F8: 0 | G8: 0 | H8: 0 | I8: 0 | J8: 0 | K8: 0 | L8: 0 | M8: 0 | N8: 0 | O8: 0 | P8: 0 | Q8: 0 | R8: 0 | S8: 0 | T8: 0 | U8: 0 | V8: 0 | W8: 0 | X8: 0 | Y8: 0 | Z8: 0 | AA8: 0 | AB8: 0 | AC8: 0 | AD8: 0 | AE8: 0 | AF8: 0 | AG8: 0 | AH8: 0 | AI8: 0 | AJ8: 0 | AK8: 0 | AL8: 0 | AM8: 0 | AN8: 0 | AO8: 0 | AP8: 0 | AQ8: 0
A9: biomass ($/MWh) | B9: 0 | C9: 0 | D9: 0 | E9: 0 | F9: 0 | G9: 0 | H9: 0 | I9: 0 | J9: 0 | K9: 0 | L9: 0 | M9: 0 | N9: 0 | O9: 0 | P9: 0 | Q9: 0 | R9: 0 | S9: 0 | T9: 0 | U9: 0 | V9: 0 | W9: 0 | X9: 0 | Y9: 0 | Z9: 0 | AA9: 0 | AB9: 0 | AC9: 0 | AD9: 0 | AE9: 0 | AF9: 0 | AG9: 0 | AH9: 0 | AI9: 0 | AJ9: 0 | AK9: 0 | AL9: 0 | AM9: 0 | AN9: 0 | AO9: 0 | AP9: 0 | AQ9: 0
A10: geothermal ($/MWh) | B10: 0 | C10: 0 | D10: 0 | E10: 0 | F10: 0 | G10: 0 | H10: 0 | I10: 0 | J10: 0 | K10: 0 | L10: 0 | M10: 0 | N10: 0 | O10: 0 | P10: 0 | Q10: 0 | R10: 0 | S10: 0 | T10: 0 | U10: 0 | V10: 0 | W10: 0 | X10: 0 | Y10: 0 | Z10: 0 | AA10: 0 | AB10: 0 | AC10: 0 | AD10: 0 | AE10: 0 | AF10: 0 | AG10: 0 | AH10: 0 | AI10: 0 | AJ10: 0 | AK10: 0 | AL10: 0 | AM10: 0 | AN10: 0 | AO10: 0 | AP10: 0 | AQ10: 0
A11: petroleum ($/MWh) | B11: 0 | C11: 0 | D11: 0 | E11: 0 | F11: 0 | G11: 0 | H11: 0 | I11: 0 | J11: 0 | K11: 0 | L11: 0 | M11: 0 | N11: 0 | O11: 0 | P11: 0 | Q11: 0 | R11: 0 | S11: 0 | T11: 0 | U11: 0 | V11: 0 | W11: 0 | X11: 0 | Y11: 0 | Z11: 0 | AA11: 0 | AB11: 0 | AC11: 0 | AD11: 0 | AE11: 0 | AF11: 0 | AG11: 0 | AH11: 0 | AI11: 0 | AJ11: 0 | AK11: 0 | AL11: 0 | AM11: 0 | AN11: 0 | AO11: 0 | AP11: 0 | AQ11: 0
A12: natural gas peaker ($/MWh) | B12: 0 | C12: 0 | D12: 0 | E12: 0 | F12: 0 | G12: 0 | H12: 0 | I12: 0 | J12: 0 | K12: 0 | L12: 0 | M12: 0 | N12: 0 | O12: 0 | P12: 0 | Q12: 0 | R12: 0 | S12: 0 | T12: 0 | U12: 0 | V12: 0 | W12: 0 | X12: 0 | Y12: 0 | Z12: 0 | AA12: 0 | AB12: 0 | AC12: 0 | AD12: 0 | AE12: 0 | AF12: 0 | AG12: 0 | AH12: 0 | AI12: 0 | AJ12: 0 | AK12: 0 | AL12: 0 | AM12: 0 | AN12: 0 | AO12: 0 | AP12: 0 | AQ12: 0
... A17: municipal solid waste ($/MWh) | B17: 0 | C17: 0 | D17: 0 | E17: 0 | F17: 0 | G17: 0 | H17: 0 | I17: 0 | J17: 0 | K17: 0 | L17: 0 | M17: 0 | N17: 0 | O17: 0 | P17: 0 | Q17: 0 | R17: 0 | S17: 0 | T17: 0 | U17: 0 | V17: 0 | W17: 0 | X17: 0 | Y17: 0 | Z17: 0 | AA17: 0 | AB17: 0 | AC17: 0 | AD17: 0 | AE17: 0 | AF17: 0 | AG17: 0 | AH17: 0 | AI17: 0 | AJ17: 0 | AK17: 0 | AL17: 0 | AM17: 0 | AN17: 0 | AO17: 0 | AP17: 0 | AQ17: 0

Sheet BS-BSpUECB
A1: Year | B1: 2017 | C1: 2018 | D1: 2019 | E1: 2020 | F1: 2021 | G1: 2022 | H1: 2023 | I1: 2024 | J1: 2025 | K1: 2026 | L1: 2027 | M1: 2028 | N1: 2029 | O1: 2030 | P1: 2031 | Q1: 2032 | R1: 2033 | S1: 2034 | T1: 2035 | U1: 2036 | V1: 2037 | W1: 2038 | X1: 2039 | Y1: 2040 | Z1: 2041 | AA1: 2042 | AB1: 2043 | AC1: 2044 | AD1: 2045 | AE1: 2046 | AF1: 2047 | AG1: 2048 | AH1: 2049 | AI1: 2050 | AJ1: 2051 | AK1: 2052 | AL1: 2053 | AM1: 2054 | AN1: 2055 | AO1: 2056 | AP1: 2057 | AQ1: 2058 | AR1: 2059 | AS1: 2060
A2: hard coal ($/MW) | B2: 0 | C2: 0 | D2: 0 | E2: 0 | F2: 0 | G2: 0 | H2: 0 | I2: 0 | J2: 0 | K2: 0 | L2: 0 | M2: 0 | N2: 0 | O2: 0 | P2: 0 | Q2: 0 | R2: 0 | S2: 0 | T2: 0 | U2: 0 | V2: 0 | W2: 0 | X2: 0 | Y2: 0 | Z2: 0 | AA2: 0 | AB2: 0 | AC2: 0 | AD2: 0 | AE2: 0 | AF2: 0 | AG2: 0 | AH2: 0 | AI2: 0 | AJ2: 0 | AK2: 0 | AL2: 0 | AM2: 0 | AN2: 0 | AO2: 0 | AP2: 0 | AQ2: 0 | AR2: 0 | AS2: 0
A3: natural gas nonpeaker ($/MW) | B3: 0 | C3: 0 | D3: 0 | E3: 0 | F3: 0 | G3: 0 | H3: 0 | I3: 0 | J3: 0 | K3: 0 | L3: 0 | M3: 0 | N3: 0 | O3: 0 | P3: 0 | Q3: 0 | R3: 0 | S3: 0 | T3: 0 | U3: 0 | V3: 0 | W3: 0 | X3: 0 | Y3: 0 | Z3: 0 | AA3: 0 | AB3: 0 | AC3: 0 | AD3: 0 | AE3: 0 | AF3: 0 | AG3: 0 | AH3: 0 | AI3: 0 | AJ3: 0 | AK3: 0 | AL3: 0 | AM3: 0 | AN3: 0 | AO3: 0 | AP3: 0 | AQ3: 0 | AR3: 0 | AS3: 0
A4: nuclear ($/MW) | B4: 0 | C4: 0 | D4: 0 | E4: 0 | F4: 0 | G4: 0 | H4: 0 | I4: 0 | J4: 0 | K4: 0 | L4: 0 | M4: 0 | N4: 0 | O4: 0 | P4: 0 | Q4: 0 | R4: 0 | S4: 0 | T4: 0 | U4: 0 | V4: 0 | W4: 0 | X4: 0 | Y4: 0 | Z4: 0 | AA4: 0 | AB4: 0 | AC4: 0 | AD4: 0 | AE4: 0 | AF4: 0 | AG4: 0 | AH4: 0 | AI4: 0 | AJ4: 0 | AK4: 0 | AL4: 0 | AM4: 0 | AN4: 0 | AO4: 0 | AP4: 0 | AQ4: 0 | AR4: 0 | AS4: 0
A5: hydro ($/MW) | B5: 0 | C5: 0 | D5: 0 | E5: 0 | F5: 0 | G5: 0 | H5: 0 | I5: 0 | J5: 0 | K5: 0 | L5: 0 | M5: 0 | N5: 0 | O5: 0 | P5: 0 | Q5: 0 | R5: 0 | S5: 0 | T5: 0 | U5: 0 | V5: 0 | W5: 0 | X5: 0 | Y5: 0 | Z5: 0 | AA5: 0 | AB5: 0 | AC5: 0 | AD5: 0 | AE5: 0 | AF5: 0 | AG5: 0 | AH5: 0 | AI5: 0 | AJ5: 0 | AK5: 0 | AL5: 0 | AM5: 0 | AN5: 0 | AO5: 0 | AP5: 0 | AQ5: 0 | AR5: 0 | AS5: 0
A6: onshore wind ($/MW) | B6: 0 | C6: 0 | D6: 0 | E6: 0 | F6: 0 | G6: 0 | H6: 0 | I6: 0 | J6: 0 | K6: 0 | L6: 0 | M6: 0 | N6: 0 | O6: 0 | P6: 0 | Q6: 0 | R6: 0 | S6: 0 | T6: 0 | U6: 0 | V6: 0 | W6: 0 | X6: 0 | Y6: 0 | Z6: 0 | AA6: 0 | AB6: 0 | AC6: 0 | AD6: 0 | AE6: 0 | AF6: 0 | AG6: 0 | AH6: 0 | AI6: 0 | AJ6: 0 | AK6: 0 | AL6: 0 | AM6: 0 | AN6: 0 | AO6: 0 | AP6: 0 | AQ6: 0 | AR6: 0 | AS6: 0
A7: solar PV ($/MW) | B7: 0 | C7: 0 | D7: 0 | E7: 0 | F7: 0 | G7: 0 | H7: 0 | I7: 0 | J7: 0 | K7: 0 | L7: 0 | M7: 0 | N7: 0 | O7: 0 | P7: 0 | Q7: 0 | R7: 0 | S7: 0 | T7: 0 | U7: 0 | V7: 0 | W7: 0 | X7: 0 | Y7: 0 | Z7: 0 | AA7: 0 | AB7: 0 | AC7: 0 | AD7: 0 | AE7: 0 | AF7: 0 | AG7: 0 | AH7: 0 | AI7: 0 | AJ7: 0 | AK7: 0 | AL7: 0 | AM7: 0 | AN7: 0 | AO7: 0 | AP7: 0 | AQ7: 0 | AR7: 0 | AS7: 0
A8: solar thermal ($/MW) | B8: 0 | C8: 0 | D8: 0 | E8: 0 | F8: 0 | G8: 0 | H8: 0 | I8: 0 | J8: 0 | K8: 0 | L8: 0 | M8: 0 | N8: 0 | O8: 0 | P8: 0 | Q8: 0 | R8: 0 | S8: 0 | T8: 0 | U8: 0 | V8: 0 | W8: 0 | X8: 0 | Y8: 0 | Z8: 0 | AA8: 0 | AB8: 0 | AC8: 0 | AD8: 0 | AE8: 0 | AF8: 0 | AG8: 0 | AH8: 0 | AI8: 0 | AJ8: 0 | AK8: 0 | AL8: 0 | AM8: 0 | AN8: 0 | AO8: 0 | AP8: 0 | AQ8: 0 | AR8: 0 | AS8: 0
A9: biomass ($/MW) | B9: 0 | C9: 0 | D9: 0 | E9: 0 | F9: 0 | G9: 0 | H9: 0 | I9: 0 | J9: 0 | K9: 0 | L9: 0 | M9: 0 | N9: 0 | O9: 0 | P9: 0 | Q9: 0 | R9: 0 | S9: 0 | T9: 0 | U9: 0 | V9: 0 | W9: 0 | X9: 0 | Y9: 0 | Z9: 0 | AA9: 0 | AB9: 0 | AC9: 0 | AD9: 0 | AE9: 0 | AF9: 0 | AG9: 0 | AH9: 0 | AI9: 0 | AJ9: 0 | AK9: 0 | AL9: 0 | AM9: 0 | AN9: 0 | AO9: 0 | AP9: 0 | AQ9: 0 | AR9: 0 | AS9: 0
A10: geothermal ($/MW) | B10: 0 | C10: 0 | D10: 0 | E10: 0 | F10: 0 | G10: 0 | H10: 0 | I10: 0 | J10: 0 | K10: 0 | L10: 0 | M10: 0 | N10: 0 | O10: 0 | P10: 0 | Q10: 0 | R10: 0 | S10: 0 | T10: 0 | U10: 0 | V10: 0 | W10: 0 | X10: 0 | Y10: 0 | Z10: 0 | AA10: 0 | AB10: 0 | AC10: 0 | AD10: 0 | AE10: 0 | AF10: 0 | AG10: 0 | AH10: 0 | AI10: 0 | AJ10: 0 | AK10: 0 | AL10: 0 | AM10: 0 | AN10: 0 | AO10: 0 | AP10: 0 | AQ10: 0 | AR10: 0 | AS10: 0
A11: petroleum ($/MW) | B11: 0 | C11: 0 | D11: 0 | E11: 0 | F11: 0 | G11: 0 | H11: 0 | I11: 0 | J11: 0 | K11: 0 | L11: 0 | M11: 0 | N11: 0 | O11: 0 | P11: 0 | Q11: 0 | R11: 0 | S11: 0 | T11: 0 | U11: 0 | V11: 0 | W11: 0 | X11: 0 | Y11: 0 | Z11: 0 | AA11: 0 | AB11: 0 | AC11: 0 | AD11: 0 | AE11: 0 | AF11: 0 | AG11: 0 | AH11: 0 | AI11: 0 | AJ11: 0 | AK11: 0 | AL11: 0 | AM11: 0 | AN11: 0 | AO11: 0 | AP11: 0 | AQ11: 0 | AR11: 0 | AS11: 0
A12: natural gas peaker ($/MW) | B12: ='Capacity Price Peaker '!E8 -> 59956.235 | C12: =B12 -> 59956.235 | D12: =C12 -> 59956.235 | E12: =D12 -> 59956.235 | F12: =E12 -> 59956.235 | G12: =F12 -> 59956.235 | H12: =G12 -> 59956.235 | I12: =H12 -> 59956.235 | J12: =I12 -> 59956.235 | ... AS12: =AR12 -> 59956.235
A13: lignite ($/MW) | B13: 0 | C13: 0 | D13: 0 | E13: 0 | F13: 0 | G13: 0 | H13: 0 | I13: 0 | J13: 0 | K13: 0 | L13: 0 | M13: 0 | N13: 0 | O13: 0 | P13: 0 | Q13: 0 | R13: 0 | S13: 0 | T13: 0 | U13: 0 | V13: 0 | W13: 0 | X13: 0 | Y13: 0 | Z13: 0 | AA13: 0 | AB13: 0 | AC13: 0 | AD13: 0 | AE13: 0 | AF13: 0 | AG13: 0 | AH13: 0 | AI13: 0 | AJ13: 0 | AK13: 0 | AL13: 0 | AM13: 0 | AN13: 0 | AO13: 0 | AP13: 0 | AQ13: 0 | AR13: 0 | AS13: 0
A14: offshore wind ($/MW) | B14: 0 | C14: 0 | D14: 0 | E14: 0 | F14: 0 | G14: 0 | H14: 0 | I14: 0 | J14: 0 | K14: 0 | L14: 0 | M14: 0 | N14: 0 | O14: 0 | P14: 0 | Q14: 0 | R14: 0 | S14: 0 | T14: 0 | U14: 0 | V14: 0 | W14: 0 | X14: 0 | Y14: 0 | Z14: 0 | AA14: 0 | AB14: 0 | AC14: 0 | AD14: 0 | AE14: 0 | AF14: 0 | AG14: 0 | AH14: 0 | AI14: 0 | AJ14: 0 | AK14: 0 | AL14: 0 | AM14: 0 | AN14: 0 | AO14: 0 | AP14: 0 | AQ14: 0 | AR14: 0 | AS14: 0
A15: crude oil ($/MWh) | B15: 0 | C15: 0 | D15: 0 | E15: 0 | F15: 0 | G15: 0 | H15: 0 | I15: 0 | J15: 0 | K15: 0 | L15: 0 | M15: 0 | N15: 0 | O15: 0 | P15: 0 | Q15: 0 | R15: 0 | S15: 0 | T15: 0 | U15: 0 | V15: 0 | W15: 0 | X15: 0 | Y15: 0 | Z15: 0 | AA15: 0 | AB15: 0 | AC15: 0 | AD15: 0 | AE15: 0 | AF15: 0 | AG15: 0 | AH15: 0 | AI15: 0 | AJ15: 0 | AK15: 0 | AL15: 0 | AM15: 0 | AN15: 0 | AO15: 0 | AP15: 0 | AQ15: 0 | AR15: 0 | AS15: 0
A16: heavy or residual fuel oil ($/MWh) | B16: 0 | C16: 0 | D16: 0 | E16: 0 | F16: 0 | G16: 0 | H16: 0 | I16: 0 | J16: 0 | K16: 0 | L16: 0 | M16: 0 | N16: 0 | O16: 0 | P16: 0 | Q16: 0 | R16: 0 | S16: 0 | T16: 0 | U16: 0 | V16: 0 | W16: 0 | X16: 0 | Y16: 0 | Z16: 0 | AA16: 0 | AB16: 0 | AC16: 0 | AD16: 0 | AE16: 0 | AF16: 0 | AG16: 0 | AH16: 0 | AI16: 0 | AJ16: 0 | AK16: 0 | AL16: 0 | AM16: 0 | AN16: 0 | AO16: 0 | AP16: 0 | AQ16: 0 | AR16: 0 | AS16: 0
A17: municipal solid waste ($/MWh) | B17: 0 | C17: 0 | D17: 0 | E17: 0 | F17: 0 | G17: 0 | H17: 0 | I17: 0 | J17: 0 | K17: 0 | L17: 0 | M17: 0 | N17: 0 | O17: 0 | P17: 0 | Q17: 0 | R17: 0 | S17: 0 | T17: 0 | U17: 0 | V17: 0 | W17: 0 | X17: 0 | Y17: 0 | Z17: 0 | AA17: 0 | AB17: 0 | AC17: 0 | AD17: 0 | AE17: 0 | AF17: 0 | AG17: 0 | AH17: 0 | AI17: 0 | AJ17: 0 | AK17: 0 | AL17: 0 | AM17: 0 | AN17: 0 | AO17: 0 | AP17: 0 | AQ17: 0 | AR17: 0 | AS17: 0

Sheet biomass & geothermal -not used
A1: source | B1: http://www.gov.cn/ztzl/2006-01/20/content_165910.htm
B2: 国家发展改革委关于印发《可再生能源发电价格和费用分摊管理试行办法》的通知
A5: Biomass and Geothermal
B6: 2015 | C6: 2016 | D6: 2017 | E6: 2018 | F6: 2019 | G6: 2020 | H6: 2021 | I6: 2022 | J6: 2023 | K6: 2024 | L6: 2025 | M6: 2026 | N6: 2027 | O6: 2028 | P6: 2029 | Q6: 2030 | R6: 2031 | S6: 2032 | T6: 2033 | U6: 2034 | V6: 2035 | W6: 2036 | X6: 2037 | Y6: 2038 | Z6: 2039 | AA6: 2040 | AB6: 2041 | AC6: 2042 | AD6: 2043 | AE6: 2044 | AF6: 2045 | AG6: 2046 | AH6: 2047 | AI6: 2048 | AJ6: 2049 | AK6: 2050
A7: yuan/kwh | B7: =B22 -> 0.18862911 | C7: =B7*(1-2%) -> 0.18485653 | D7: =C7+$I$9 -> 0.17172392 | E7: =D7+$I$9 -> 0.15859131 | F7: =E7+$I$9 -> 0.1454587 | G7: =F7+$I$9 -> 0.13232609 | H7: =G7+$I$9 -> 0.11919348 | I7: =H7+$I$9 -> 0.10606087 | J7: =I7+$I$9 -> 0.092928264 | K7: =J7+$I$9 -> 0.079795655 | ... P7: =O7+$I$9 -> 0.014132609 | Q7: 0.001 | R7: 0 | S7: 0 | T7: 0 | U7: 0 | V7: 0 | W7: 0 | X7: 0 | Y7: 0 | Z7: 0 | AA7: 0 | AB7: 0 | AC7: 0 | AD7: 0 | AE7: 0 | AF7: 0 | AG7: 0 | AH7: 0 | AI7: 0 | AJ7: 0 | AK7: 0
A8: $/MWh | B8: =B7*usd_per_yuan*10^3 -> 27.4229 | C8: =C7*usd_per_yuan*10^3 -> 26.874442 | D8: =D7*usd_per_yuan*10^3 -> 24.965223 | E8: =E7*usd_per_yuan*10^3 -> 23.056005 | F8: =F7*usd_per_yuan*10^3 -> 21.146786 | G8: =G7*usd_per_yuan*10^3 -> 19.237567 | H8: =H7*usd_per_yuan*10^3 -> 17.328348 | I8: =I7*usd_per_yuan*10^3 -> 15.41913 | ... AK8: =AK7*usd_per_yuan*10^3 -> 0
I9: =(Q7-C7)/14 -> -0.013132609
A11: Geothermal (not used)
B12: 2015 | C12: 2016 | D12: 2017 | E12: 2018 | F12: 2019 | G12: 2020 | H12: 2021 | I12: 2022 | J12: 2023 | K12: 2024 | L12: 2025 | M12: 2026 | N12: 2027 | O12: 2028 | P12: 2029 | Q12: 2030 | R12: 2031 | S12: 2032 | T12: 2033 | U12: 2034 | V12: 2035 | W12: 2036 | X12: 2037 | Y12: 2038 | Z12: 2039 | AA12: 2040 | AB12: 2041 | AC12: 2042 | AD12: 2043 | AE12: 2044 | AF12: 2045 | AG12: 2046 | AH12: 2047 | AI12: 2048 | AJ12: 2049 | AK12: 2050
A13: yuan/kwh | B13: =C22 -> 0.32737584 | C13: =B13*(1-2%) -> 0.32082833 | D13: =C13+$I$9 -> 0.30769572 | E13: =D13+$I$9 -> 0.29456311 | F13: =E13+$I$9 -> 0.2814305 | G13: =F13+$I$9 -> 0.26829789 | H13: =G13+$I$9 -> 0.25516528 | I13: =H13+$I$9 -> 0.24203267 | J13: =I13+$I$9 -> 0.22890006 | K13: =J13+$I$9 -> 0.21576745 | ... P13: =O13+$I$9 -> 0.15010441 | Q13: 0.001 | R13: 0 | S13: 0 | T13: 0 | U13: 0 | V13: 0 | W13: 0 | X13: 0 | Y13: 0 | Z13: 0 | AA13: 0 | AB13: 0 | AC13: 0 | AD13: 0 | AE13: 0 | AF13: 0 | AG13: 0 | AH13: 0 | AI13: 0 | AJ13: 0 | AK13: 0
A14: $/MWh | B14: =B13*usd_per_yuan*10^3 -> 47.5939 | C14: =C13*usd_per_yuan*10^3 -> 46.642022 | D14: =D13*usd_per_yuan*10^3 -> 44.732803 | E14: =E13*usd_per_yuan*10^3 -> 42.823585 | F14: =F13*usd_per_yuan*10^3 -> 40.914366 | G14: =G13*usd_per_yuan*10^3 -> 39.005147 | H14: =H13*usd_per_yuan*10^3 -> 37.095928 | I14: =I13*usd_per_yuan*10^3 -> 35.18671 | ... AK14: =AK13*usd_per_yuan*10^3 -> 0
D15: =(Q13-C13)/14 -> -0.02284488
A16: We assume geothermal to have the same subsidy schedule as biomass.
B18: Biomass | C18: Geothermal
A19: LCOE ($/MWh) | B19: 68.5279 | C19: 48.3569
A20: LCOE (RMB/kWh) | B20: =B19/usd_per_yuan/1000 -> 0.47137089 | C20: =C19/usd_per_yuan/1000 -> 0.33262416
A21: FiT | B21: =0.41+0.25 -> 0.66 | C21: =0.41+0.25 -> 0.66
A22: Subsidy | B22: =B21-B20 -> 0.18862911 | C22: =C21-C20 -> 0.32737584
A25: Though we calculate a separte subsidy for geothermal, the subsidy is actually unknown and assumed to be the same amount as the biomass subsidy.

Sheet solar - not used
A1: source | C1: http://www.sdpc.gov.cn/zcfb/zcfbtz/201308/W020130830538568620813.pdf
C2: 2014 | E2: 2016
A3: 一类 | B3: Region 1 | C3: 0.9 | E3: 0.8 | J3: 一类 | K3: 宁夏，青海海西，甘肃嘉峪关、武威、张掖、酒泉、敦煌、金
A4: 二类 | B4: Region 2 | C4: 0.95 | E4: 0.88 | K4: 昌，新疆哈密、塔城、阿勒泰、克拉玛依，内蒙古除赤峰、通
A5: 三类 | B5: Region 3 | C5: 1 | E5: 0.98 | K5: 辽、兴安盟、呼伦贝尔以外地区
C6: =AVERAGE(C3:C5) -> 0.95
J7: 二类 | K7: 北京，天津，黑龙江，吉林，辽宁，四川，云南，内蒙古赤峰
C8: 0.5364631 | K8: 、通辽、兴安盟、呼伦贝尔，河北承德、张家口、唐山、秦皇
C9: 89.4937 | D9: $/MWh | K9: 岛，山西大同、朔州、忻州，陕西榆林、延安，青海、甘肃、
B10: LCOE | C10: =C9/[0]!usd_per_yuan/1000 -> 0.61558467 | D10: RMB/kWh | K10: 新疆除Ⅰ类外其他地区
B11: Subsidy | C11: =C6-C10 -> 0.33441533
J12: 三类 | K12: 除Ⅰ类、Ⅱ类资源区以外的其他地区
A15: Solar
B16: 2014 | C16: 2015 | D16: 2016 | E16: 2017 | F16: 2018 | G16: 2019 | H16: 2020 | I16: 2021 | J16: 2022 | K16: 2023 | L16: 2024 | M16: 2025 | N16: 2026 | O16: 2027 | P16: 2028 | Q16: 2029 | R16: 2030 | S16: 2031 | T16: 2032 | U16: 2033 | V16: 2034 | W16: 2035 | X16: 2036 | Y16: 2037 | Z16: 2038 | AA16: 2039 | AB16: 2040 | AC16: 2041 | AD16: 2042 | AE16: 2043 | AF16: 2044 | AG16: 2045 | AH16: 2046 | AI16: 2047 | AJ16: 2048 | AK16: 2049 | AL16: 2050
A17: yuan/kwh | B17: =C11 -> 0.33441533 | C17: =B17+$C$20 -> 0.31357687 | D17: =C17+$C$20 -> 0.29273841 | E17: =D17+$C$20 -> 0.27189995 | F17: =E17+$C$20 -> 0.25106149 | G17: =F17+$C$20 -> 0.23022304 | H17: =G17+$C$20 -> 0.20938458 | I17: =H17+$C$20 -> 0.18854612 | J17: =I17+$C$20 -> 0.16770766 | ... Q17: =P17+$C$20 -> 0.021838458 | R17: 0.001 | S17: 0 | T17: 0 | U17: 0 | V17: 0 | W17: 0 | X17: 0 | Y17: 0 | Z17: 0 | AA17: 0 | AB17: 0 | AC17: 0 | AD17: 0 | AE17: 0 | AF17: 0 | AG17: 0 | AH17: 0 | AI17: 0 | AJ17: 0 | AK17: 0 | AL17: 0
A18: $/MWh | B18: =B17*usd_per_yuan*10^3 -> 48.6173 | C18: =C17*usd_per_yuan*10^3 -> 45.587805 | D18: =D17*usd_per_yuan*10^3 -> 42.55831 | E18: =E17*usd_per_yuan*10^3 -> 39.528815 | F18: =F17*usd_per_yuan*10^3 -> 36.49932 | G18: =G17*usd_per_yuan*10^3 -> 33.469825 | H18: =H17*usd_per_yuan*10^3 -> 30.44033 | I18: =I17*usd_per_yuan*10^3 -> 27.410835 | ... AL18: =AL17*usd_per_yuan*10^3 -> 0
C20: =(R17-B17)/16 -> -0.020838458
B23: Assume no more subsidy after 2030

Sheet subsidy for gen- not usd
A1: type | B1: data | C1: unit | D1: source | K1: Electricity subsidy（yuan/Mwh) | L1: 2017
A2: natural gas | B2: 0 | C2: yuan/kwh | D2: https://www.xianjichina.com/news/details_93212.html | K2: natural gas | L2: =B2*1000 -> 0
A3: wind | B3: 0.2 | C3: yuan/kwh | D3: http://news.bjx.com.cn/html/20190416/974996.shtml | K3: wind | L3: =B3*1000 -> 200
A4: solar-residential | B4: 0.32 | C4: yuan/kwh | D4: http://guangfu.bjx.com.cn/news/20180918/928845.shtml | K4: solar | L4: =B4*1000 -> 320
A5: solar-commercial | B5: 0.1 | C5: yuan/kwh | D5: http://guangfu.bjx.com.cn/news/20180918/928846.shtml
A6: solar | B6: =AVERAGE(B4:B5) -> 0.21 | C6: yuan/kwh
A7: municipal solid waste 1 | B7: 0.008 | C7: yuan/ton | D7: http://news.bjx.com.cn/html/20151231/697146.shtml
A8: municipal solid waste 2 | B8: 0.064 | C8: yuan/ton | D8: http://news.bjx.com.cn/html/20151231/697147.shtml
A9: municipal solid waste | B9: =AVERAGE(B7:B8) -> 0.036 | C9: yuan/ton | K9: https://www.sohu.com/a/306834225_788193
A10: municipal solid waste 电价 | B10: 0.65 | C10: yuan/kwh | D10: http://news.bjx.com.cn/html/20190603/983959.shtml
D11: http://www.nea.gov.cn/2014-09/29/c_133682178.htm
A12: subsidy | B12: 0.25 | C12: yuan/kwh | D12: https://wenku.baidu.com/view/bb454668b7360b4c2f3f642d.html
D13: 0.008 | E13: yuan/kwh
A14: Electricity subsidy（$/Mwh) | B14: 2017
A15: natural gas | B15: 0
A16: wind | B16: 29.076 | D16: No more subsidy after 2021 | I16: https://baijiahao.baidu.com/s?id=1634482543833385999&wfr=spider&for=pc
A17: solar | B17: 46.5216 | M17: http://news.bjx.com.cn/html/20190416/974996.shtml
A18: biomass/municial solid waste | B18: 36.345 | K18: 0.2 | L18: yuan/kwh

Sheet wind - not used
A1: source | B1: http://www.sdpc.gov.cn/gzdt/201501/t20150109_659879.html
A2: 一类 | B2: 0.49 | C2: 元/度 | D2: http://www.chinairn.com/news/20130910/101802663.html | H2: 一类 | I2: 内蒙古自治区除赤峰市、通辽市、兴安盟、呼伦贝尔市以外其
A3: 二类 | B3: 0.52 | I3: 他地区；新疆维吾尔自治区乌鲁木齐市、伊犁哈萨克族自治州
A4: 三类 | B4: 0.56 | I4: 、克拉玛依市、石河子市
A5: 四类 | B5: 0.61
A6: 平均补贴 | B6: =AVERAGE(B2:B5) -> 0.545 | D6: 0.1314631 | H6: 二类 | I6: 河北省张家口市、承德市；内蒙古自治区赤峰市、通辽市、兴
A7: 发电量 | B7: 376.5 | C7: 亿度 | I7: 安盟、呼伦贝尔市；甘肃省嘉峪关市、酒泉市
B8: =B6*B7 -> 205.1925 | C8: 亿元
H9: 三类 | I9: 吉林省白城市、松原市；黑龙江省鸡西市、双鸭山市、七台河
B10: 60.7787 | C10: $/MWh | I10: 市、绥化市、伊春市，大兴安岭地区；甘肃省除嘉峪关市、酒
B11: =B10/usd_per_yuan/1000 -> 0.41806782 | C11: RMB/kWh | I11: 泉市以外其他地区；新疆维吾尔自治区除乌鲁木齐市、伊犁哈
I12: 萨克族自治州、克拉玛依市、石河子市以外其他地区；宁夏回
I13: 族自治区
H15: 四类 | I15: 除Ⅰ类、Ⅱ类、Ⅲ类资源区以外的其他地区
A17: Wind
B18: 2014 | C18: 2015 | D18: 2016 | E18: 2017 | F18: 2018 | G18: 2019 | H18: 2020 | I18: 2021 | J18: 2022 | K18: 2023 | L18: 2024 | M18: 2025 | N18: 2026 | O18: 2027 | P18: 2028 | Q18: 2029 | R18: 2030 | S18: 2031 | T18: 2032 | U18: 2033 | V18: 2034 | W18: 2035 | X18: 2036 | Y18: 2037 | Z18: 2038 | AA18: 2039 | AB18: 2040 | AC18: 2041 | AD18: 2042 | AE18: 2043 | AF18: 2044 | AG18: 2045 | AH18: 2046 | AI18: 2047 | AJ18: 2048 | AK18: 2049 | AL18: 2050
A19: yuan/kwh | B19: =B6-B11 -> 0.12693218 | C19: =B19+$C$22 -> 0.11906142 | D19: =C19+$C$22 -> 0.11119066 | E19: =D19+$C$22 -> 0.10331989 | F19: =E19+$C$22 -> 0.095449133 | G19: =F19+$C$22 -> 0.087578372 | H19: =G19+$C$22 -> 0.079707611 | I19: =H19+$C$22 -> 0.07183685 | J19: =I19+$C$22 -> 0.063966089 | ... Q19: =P19+$C$22 -> 0.0088707611 | R19: 0.001 | S19: 0 | T19: 0 | U19: 0 | V19: 0 | W19: 0 | X19: 0 | Y19: 0 | Z19: 0 | AA19: 0 | AB19: 0 | AC19: 0 | AD19: 0 | AE19: 0 | AF19: 0 | AG19: 0 | AH19: 0 | AI19: 0 | AJ19: 0 | AK19: 0 | AL19: 0
A20: $/MWh | B20: =B19*usd_per_yuan*10^3 -> 18.4534 | C20: =C19*usd_per_yuan*10^3 -> 17.309149 | D20: =D19*usd_per_yuan*10^3 -> 16.164898 | E20: =E19*usd_per_yuan*10^3 -> 15.020646 | F20: =F19*usd_per_yuan*10^3 -> 13.876395 | G20: =G19*usd_per_yuan*10^3 -> 12.732144 | H20: =H19*usd_per_yuan*10^3 -> 11.587893 | I20: =I19*usd_per_yuan*10^3 -> 10.443641 | ... AL20: =AL19*usd_per_yuan*10^3 -> 0
C22: =(R19-B19)/16 -> -0.0078707611
B23: No more subsidy after 2021 | G23: https://baijiahao.baidu.com/s?id=1634482543833385999&wfr=spider&for=pc
