Workbook
Name IQ_CH: 110000
Name IQ_CQ: 5000
Name IQ_CY: 10000
Name IQ_DAILY: 500000
Name IQ_FH: 100000
Name IQ_FQ: 500
Name IQ_FY: 1000
Name IQ_LTM: 2000
Name IQ_MONTH: 15000
Name IQ_NTM: 6000
Name IQ_WEEK: 50000
Name IQ_YTD: 3000

Sheet About
A1: BRPSPTY BAU Renewable Portfolio Std Percentage This Year
A3: Sources: | B3: Historic Renewable Consumption Data | E3: Historic Electricity Generation Data
B4: National Energy Agency | E4: China Electricity Council
B5: 全国可再生能源电力发展检测评价报告 | E5: 中国电力工业统计资料汇编 （Compilation of China Power Sector Statistics)
B6: Annual Rnewable Power Development Monitoring Report | E6: 2015-2021
B7: 2015-2022 | E7: Chapter 2 (Power Generation)
B8: 2015 | C8: http://cn.chinagate.cn/economics/2016-08/24/content_39157136.htm
B9: 2016 | C9: http://zfxxgk.nea.gov.cn/auto87/201704/t20170418_2773.htm | E9: Historic Electricity Import and Export Data
B10: 2017 | C10: https://www.gov.cn/zhengce/zhengceku/2018-12/31/content_5433577.htm | E10: China National Bureau of Statistics
B11: 2018 | C11: https://www.gov.cn/zhengce/zhengceku/2019-09/29/content_5434697.htm | E11: 中国能源统计年鉴（Statistical Yearbook of China Energy)
B12: 2019 | C12: http://zfxxgk.nea.gov.cn/2020-05/06/c_139059627.htm | E12: 2015-2021
B13: 2020 | C13: http://zfxxgk.nea.gov.cn/2021-06/20/c_1310039970.htm | E13: Chappter 6 Provincial Energy Balance Sheet
B14: 2021 | C14: https://www.gov.cn/zhengce/zhengceku/2022-09/23/content_5711253.htm
B15: 2022 | C15: http://zfxxgk.nea.gov.cn/2023-09/07/c_1310741874.htm
B17: Annually Announced Renewable Consumption Target | E17: Pre 14FYP Announced Renewable Consumption Target till 2030
B18: National Energy Agency | E18: National Energy Agency
B19: 可再生能源消纳责任权重 | E19: 可再生能源消纳责任权重2021-2030(征求意见）
B20: Renewable Consumption Quota (released annually / biannually) | E20: renewable consumption quota 2021-2030 (Draft for opinion)
B21: 2021-22 | C21: https://www.gov.cn/zhengce/zhengceku/2021-05/26/content_5612441.htm | E21: 2021-30
B22: 2023-24 | C22: https://www.ndrc.gov.cn/xwdt/tzgg/202308/t20230804_1359103.html | E22: http://nyj.yq.gov.cn/zxdt/202102/t20210218_1128635.html
A26: Note:
A27: The purpose of this variable is to specify the renewable portfolio standard requirement that must be met
A28: in the BAU case (which the user may increase via a policy lever, affecting the policy case).
A30: For China, instead of production based RPS, the national government announces provincial renewable
A31: consumption quota annually. Since EPS calculated the RPS after deducting electricty import and export,
A32: it is necessary to converted the consumption based target to production based RPS standard.
A33: The annouced consumption target are listed as well as historic electricity import / export are listed.
A35: Since China's latest mid/long-term renewable development plan was 2007-2020, this is no long term
A36: provincial target prior to the anouncement of the 14th FYP. However, in 2021, there was draft for opinion
A37: released by the NEA that contains province specific consumption quota up to 2030. This is before the
A38: release of 14 FYP or the ambitous national target of 1.2 TW wind and solar target, and that historically
A39: the country overshoots its renewable target. We decided to the the quota announced in this draft as the
... A54: like to calculate for:
C55: Province Selector
C56: 全国 National

Sheet Province Selector
A1: Code | B1: 地区名称 | C1: 地区全称 | D1: 地区简称 | E1: Name | F1: 缩写
A2: 00 | B2: 全国 National | C2: 全国 | D2: 全国 | E2: National | F2: CN
A3: 11 | B3: 北京市 Beijing | C3: 北京市 | D3: 北京 | E3: Beijing | F3: BJ
A4: 12 | B4: 天津市 Tianjin | C4: 天津市 | D4: 天津 | E4: Tianjin | F4: TJ
A5: 13 | B5: 河北省 Hebei | C5: 河北省 | D5: 河北 | E5: Hebei | F5: HE
A6: 14 | B6: 山西省 Shanxi | C6: 山西省 | D6: 山西 | E6: Shanxi | F6: SX
A7: 15 | B7: 内蒙古自治区 Inner Mongolia | C7: 内蒙古自治区 | D7: 内蒙古 | E7: Inner Mongolia | F7: NM
A8: 21 | B8: 辽宁省 Liaoning | C8: 辽宁省 | D8: 辽宁 | E8: Liaoning | F8: LN
A9: 22 | B9: 吉林省 Jilin | C9: 吉林省 | D9: 吉林 | E9: Jilin | F9: JL
A10: 23 | B10: 黑龙江省 Heilongjiang | C10: 黑龙江省 | D10: 黑龙江 | E10: Heilongjiang | F10: HL
A11: 31 | B11: 上海市 Shanghai | C11: 上海市 | D11: 上海 | E11: Shanghai | F11: SH
A12: 32 | B12: 江苏省 Jiangsu | C12: 江苏省 | D12: 江苏 | E12: Jiangsu | F12: JS
A13: 33 | B13: 浙江省 Zhejiang | C13: 浙江省 | D13: 浙江 | E13: Zhejiang | F13: ZJ
A14: 34 | B14: 安徽省 Anhui | C14: 安徽省 | D14: 安徽 | E14: Anhui | F14: AH
... A33: 65 | B33: 新疆维吾尔自治区 Xijiang | C33: 新疆维吾尔自治区 | D33: 新疆 | E33: Xijiang | F33: XJ

Sheet historic consumption
A1: Year | B1: 2015 | C1: 2016 | D1: 2017 | E1: 2018 | F1: 2019 | G1: 2020 | H1: 2021 | I1: 2022 | J1: 2015 | K1: 2016 | L1: 2017 | M1: 2018 | N1: 2019 | O1: 2020 | P1: 2021 | Q1: 2022 | R1: 2015 | S1: 2016 | T1: 2017 | U1: 2018 | V1: 2019 | W1: 2020 | X1: 2021 | Y1: 2022 | Z1: 2015 | AA1: 2016 | AB1: 2017 | AC1: 2018 | AD1: 2019 | AE1: 2020 | AF1: 2021 | AG1: 2022
A2: 地区 | B2: 可再生能源电力消纳量（亿千瓦时） | J2: 可再生能源电力消纳比重 | R2: 非水电可再生能源电力消纳量（亿千瓦时） | Z2: Renewable Consumed (100 GWh)
A3: Region | B3: Renewable Consumed (100 GWh) | J3: Renewable Consumed Ratio | R3: Non-hydro Renewable Consumed (100 GWh) | Z3: Non-hydro Renewable Consumed Ratio
A4: 北京 | B4: 81 | C4: 107 | D4: 130 | E4: 150.75 | F4: 148 | G4: 187 | H4: 244 | I4: 292 | J4: 0.085 | K4: 0.105 | L4: 0.121 | M4: 0.132 | N4: 0.127 | O4: 0.164 | P4: 0.198 | Q4: 0.228 | R4: 72 | S4: 91 | T4: 111 | U4: 133.42 | V4: 141 | W4: 183 | X4: 239 | Y4: 283 | Z4: 0.076 | AA4: 0.09 | AB4: 0.104 | AC4: 0.117 | AD4: 0.12 | AE4: 0.161 | AF4: 0.194 | AG4: 0.221
A5: 天津 | B5: 63 | C5: 75 | D5: 89 | E5: 98.2 | F5: 112 | G5: 141 | H5: 191 | I5: 209 | J5: 0.078 | K5: 0.093 | L5: 0.11 | M5: 0.114 | N5: 0.126 | O5: 0.161 | P5: 0.195 | Q5: 0.211 | R5: 61 | S5: 72 | T5: 84 | U5: 94.47 | V5: 106 | W5: 132 | X5: 181 | Y5: 192 | Z5: 0.076 | AA5: 0.09 | AB5: 0.104 | AC5: 0.11 | AD5: 0.12 | AE5: 0.151 | AF5: 0.184 | AG5: 0.194
A6: 河北 | B6: 260 | C6: 335 | D6: 401 | E6: 448.38 | F6: 530 | G6: 559 | H6: 756 | I6: 930 | J6: 0.082 | K6: 0.103 | L6: 0.116 | M6: 0.122 | N6: 0.137 | O6: 0.142 | P6: 0.176 | Q6: 0.214 | R6: 241 | S6: 293 | T6: 357 | U6: 415.31 | V6: 505 | W6: 530 | X6: 721 | Y6: 904 | Z6: 0.076 | AA6: 0.09 | AB6: 0.104 | AC6: 0.113 | AD6: 0.13 | AE6: 0.135 | AF6: 0.168 | AG6: 0.208
A7: 山西 | B7: 152 | C7: 218 | D7: 280 | E7: 355.25 | F7: 417 | G7: 440 | H7: 649 | I7: 675 | J7: 0.088 | K7: 0.121 | L7: 0.141 | M7: 0.164 | N7: 0.184 | O7: 0.188 | P7: 0.249 | Q7: 0.248 | R7: 121 | S7: 179 | T7: 238 | U7: 312.35 | V7: 368 | W7: 393 | X7: 610 | Y7: 637 | Z7: 0.07 | AA7: 0.1 | AB7: 0.12 | AC7: 0.145 | AD7: 0.162 | AE7: 0.168 | AF7: 0.234 | AG7: 0.234
A8: 内蒙古 | B8: 354 | C8: 428 | D8: 554 | E8: 624.34 | F8: 672 | G8: 821 | H8: 954 | I8: 1075 | J8: 0.139 | K8: 0.164 | L8: 0.192 | M8: 0.186 | N8: 0.183 | O8: 0.211 | P8: 0.241 | Q8: 0.256 | R8: 306 | S8: 398 | T8: 528 | U8: 579.28 | V8: 611 | W8: 760 | X8: 890 | Y8: 1029 | Z8: 0.12 | AA8: 0.153 | AB8: 0.183 | AC8: 0.173 | AD8: 0.167 | AE8: 0.195 | AF8: 0.225 | AG8: 0.245
A9: 辽宁 | B9: 197 | C9: 259 | D9: 260 | E9: 326.37 | F9: 371 | G9: 418 | H9: 492 | I9: 551 | J9: 0.099 | K9: 0.127 | L9: 0.122 | M9: 0.142 | N9: 0.154 | O9: 0.172 | P9: 0.191 | Q9: 0.216 | R9: 152 | S9: 175 | T9: 197 | U9: 269.82 | V9: 302 | W9: 331 | X9: 361 | Y9: 421 | Z9: 0.077 | AA9: 0.086 | AB9: 0.092 | AC9: 0.117 | AD9: 0.125 | AE9: 0.136 | AF9: 0.14 | AG9: 0.165
A10: 吉林 | B10: 105 | C10: 138 | D10: 156 | E10: 186.53 | F10: 196 | G10: 244 | H10: 252 | I10: 294 | J10: 0.16 | K10: 0.207 | L10: 0.222 | M10: 0.249 | N10: 0.25 | O10: 0.303 | P10: 0.299 | Q10: 0.345 | R10: 79 | S10: 91 | T10: 115 | U10: 127.59 | V10: 147 | W10: 172 | X10: 177 | Y10: 218 | Z10: 0.122 | AA10: 0.137 | AB10: 0.164 | AC10: 0.17 | AD10: 0.188 | AE10: 0.213 | AF10: 0.21 | AG10: 0.256
A11: 黑龙江 | B11: 119 | C11: 141 | D11: 188 | E11: 188.7 | F11: 219 | G11: 238 | H11: 254 | I11: 372 | J11: 0.137 | K11: 0.157 | L11: 0.202 | M11: 0.194 | N11: 0.22 | O11: 0.234 | P11: 0.233 | Q11: 0.327 | R11: 97 | S11: 111 | T11: 146 | U11: 157.51 | V11: 202 | W11: 218 | X11: 253 | Y11: 347 | Z11: 0.111 | AA11: 0.124 | AB11: 0.158 | AC11: 0.162 | AD11: 0.202 | AE11: 0.215 | AF11: 0.232 | AG11: 0.305
A12: 上海 | B12: 419 | C12: 484 | D12: 509 | E12: 503.23 | F12: 542 | G12: 561 | H12: 558 | I12: 520 | J12: 0.298 | K12: 0.326 | L12: 0.333 | M12: 0.321 | N12: 0.345 | O12: 0.356 | P12: 0.319 | Q12: 0.298 | R12: 23 | S12: 30 | T12: 41 | U12: 51.93 | V12: 66 | W12: 76 | X12: 91 | Y12: 105 | Z12: 0.016 | AA12: 0.02 | AB12: 0.027 | AC12: 0.033 | AD12: 0.042 | AE12: 0.048 | AF12: 0.052 | AG12: 0.06
A13: 江苏 | B13: 599 | C13: 699 | D13: 856 | E13: 902.91 | F13: 941 | G13: 1072 | H13: 1321 | I13: 1650 | J13: 0.117 | K13: 0.128 | L13: 0.147 | M13: 0.147 | N13: 0.15 | O13: 0.168 | P13: 0.186 | Q13: 0.223 | R13: 169 | S13: 227 | T13: 316 | U13: 427.43 | V13: 467 | W13: 574 | X13: 859 | Y13: 1080 | Z13: 0.033 | AA13: 0.042 | AB13: 0.054 | AC13: 0.07 | AD13: 0.074 | AE13: 0.09 | AF13: 0.121 | AG13: 0.146
A14: 浙江 | B14: 658 | C14: 772 | D14: 809 | E14: 826.98 | F14: 946 | G14: 946 | H14: 1042 | I14: 1154 | J14: 0.185 | K14: 0.199 | L14: 0.193 | M14: 0.178 | N14: 0.2 | O14: 0.196 | P14: 0.189 | Q14: 0.199 | R14: 84 | S14: 138 | T14: 176 | U14: 259.56 | V14: 319 | W14: 362 | X14: 474 | Y14: 609 | Z14: 0.024 | AA14: 0.036 | AB14: 0.042 | AC14: 0.053 | AD14: 0.067 | AE14: 0.075 | AF14: 0.086 | AG14: 0.105
A15: 安徽 | B15: 157 | C15: 221 | D15: 274 | E15: 317.06 | F15: 363 | G15: 427 | H15: 524 | I15: 614 | J15: 0.096 | K15: 0.123 | L15: 0.143 | M15: 0.149 | N15: 0.157 | O15: 0.176 | P15: 0.193 | Q15: 0.205 | R15: 64 | S15: 110 | T15: 169 | U15: 235.82 | V15: 284 | W15: 330 | X15: 434 | Y15: 530 | Z15: 0.039 | AA15: 0.061 | AB15: 0.088 | AC15: 0.11 | AD15: 0.123 | AE15: 0.136 | AF15: 0.16 | AG15: 0.177
... A35: 全国 | B35: 13625 | C35: 15058 | D35: 16686 | E35: 18158.97 | F35: 19938 | G35: 21613 | H35: 24446 | I35: 26810 | J35: 0.245 | K35: 0.254 | L35: 0.265 | M35: 0.265 | N35: 0.275 | O35: 0.288 | P35: 0.294 | Q35: 0.316 | R35: 2778 | S35: 3717 | T35: 5025 | U35: 6314.2 | V35: 7388 | W35: 8562 | X35: 11398 | Y35: 13676 | Z35: 0.05 | AA35: 0.063 | AB35: 0.08 | AC35: 0.092 | AD35: 0.102 | AE35: 0.114 | AF35: 0.137 | AG35: 0.159

Sheet historic generation
A1: 地区 | B1: 指标 | C1: 年份 | D1: 值
A2: 安徽省 | B2: 分布式太阳能发电量(亿千瓦小时) | C2: 2015
A3: 北京市 | B3: 分布式太阳能发电量(亿千瓦小时) | C3: 2015
A4: 福建省 | B4: 分布式太阳能发电量(亿千瓦小时) | C4: 2015
A5: 甘肃省 | B5: 分布式太阳能发电量(亿千瓦小时) | C5: 2015
A6: 广东省 | B6: 分布式太阳能发电量(亿千瓦小时) | C6: 2015
A7: 广西壮族自治区 | B7: 分布式太阳能发电量(亿千瓦小时) | C7: 2015
A8: 贵州省 | B8: 分布式太阳能发电量(亿千瓦小时) | C8: 2015
A9: 海南省 | B9: 分布式太阳能发电量(亿千瓦小时) | C9: 2015
A10: 河北省 | B10: 分布式太阳能发电量(亿千瓦小时) | C10: 2015
A11: 河南省 | B11: 分布式太阳能发电量(亿千瓦小时) | C11: 2015
A12: 黑龙江省 | B12: 分布式太阳能发电量(亿千瓦小时) | C12: 2015
A13: 湖北省 | B13: 分布式太阳能发电量(亿千瓦小时) | C13: 2015
... A65: 重庆市 | B65: 分布式太阳能发电量(亿千瓦小时) | C65: 2016
A66: 安徽省 | B66: 分布式太阳能发电量(亿千瓦小时) | C66: 2017 | D66: 18
A67: 北京市 | B67: 分布式太阳能发电量(亿千瓦小时) | C67: 2017 | D67: 1
A68: 福建省 | B68: 分布式太阳能发电量(亿千瓦小时) | C68: 2017 | D68: 3
A69: 甘肃省 | B69: 分布式太阳能发电量(亿千瓦小时) | C69: 2017 | D69: 1
A70: 广东省 | B70: 分布式太阳能发电量(亿千瓦小时) | C70: 2017 | D70: 8
A71: 广西壮族自治区 | B71: 分布式太阳能发电量(亿千瓦小时) | C71: 2017 | D71: 1
A72: 贵州省 | B72: 分布式太阳能发电量(亿千瓦小时) | C72: 2017
A73: 海南省 | B73: 分布式太阳能发电量(亿千瓦小时) | C73: 2017 | D73: 0.2
A74: 河北省 | B74: 分布式太阳能发电量(亿千瓦小时) | C74: 2017 | D74: 11
A75: 河南省 | B75: 分布式太阳能发电量(亿千瓦小时) | C75: 2017 | D75: 4
A76: 黑龙江省 | B76: 分布式太阳能发电量(亿千瓦小时) | C76: 2017 | D76: 1
A77: 湖北省 | B77: 分布式太阳能发电量(亿千瓦小时) | C77: 2017 | D77: 5
A78: 湖南省 | B78: 分布式太阳能发电量(亿千瓦小时) | C78: 2017 | D78: 4
A79: 吉林省 | B79: 分布式太阳能发电量(亿千瓦小时) | C79: 2017 | D79: 2
A80: 江苏省 | B80: 分布式太阳能发电量(亿千瓦小时) | C80: 2017 | D80: 19
A81: 江西省 | B81: 分布式太阳能发电量(亿千瓦小时) | C81: 2017 | D81: 8
A82: 辽宁省 | B82: 分布式太阳能发电量(亿千瓦小时) | C82: 2017 | D82: 3
A83: 内蒙古自治区 | B83: 分布式太阳能发电量(亿千瓦小时) | C83: 2017 | D83: 0.3
A84: 宁夏回族自治区 | B84: 分布式太阳能发电量(亿千瓦小时) | C84: 2017 | D84: 3
... A92: 天津市 | B92: 分布式太阳能发电量(亿千瓦小时) | C92: 2017 | D92: 1
A93: 西藏自治区 | B93: 分布式太阳能发电量(亿千瓦小时) | C93: 2017
A94: 新疆维吾尔自治区 | B94: 分布式太阳能发电量(亿千瓦小时) | C94: 2017 | D94: 0.01
A95: 云南省 | B95: 分布式太阳能发电量(亿千瓦小时) | C95: 2017 | D95: 0.3
A96: 浙江省 | B96: 分布式太阳能发电量(亿千瓦小时) | C96: 2017 | D96: 31
A97: 重庆市 | B97: 分布式太阳能发电量(亿千瓦小时) | C97: 2017 | D97: 0.2
A98: 安徽省 | B98: 分布式太阳能发电量(亿千瓦小时) | C98: 2018 | D98: 36
...

Sheet historic exchange
A1: 索引 | B1: 地区 | C1: 年份 | D1: 项目 | E1: 能源品种 | F1: 实物消费量 | I1: 求和项:实物消费量 | J1: 列标签
A2: 50297 | B2: 全国 | C2: 2015 | D2: 1.1. 一次能源生产量 | E2: 电力(亿千瓦小时) | F2: 15303.85 | I2: 行标签 | J2: 2015 | K2: 2016 | L2: 2017 | M2: 2018 | N2: 2019 | O2: 2020 | P2: 2021 | Q2: (空白) | R2: 总计
A3: 50298 | B3: 全国 | C3: 2015 | D3: 1.2. 外省(区、市)调入量 | E3: 电力(亿千瓦小时) | I3: 安徽省 | J3: -349.12 | K3: -339.70335 | L3: -389.16 | M3: -398.63 | N3: -363.29 | O3: -128.35 | P3: -25.62 | R3: -1993.8734
A4: 50299 | B4: 全国 | C4: 2015 | D4: 1.3. 进口量 | E4: 电力(亿千瓦小时) | F4: 62.1 | I4: 1.1. 一次能源生产量 | J4: 72.98 | K4: 118.00735 | L4: 159.62 | M4: 207.52 | N4: 222.7 | O4: 253.13 | P4: 342.13 | R4: 1376.0874
A5: 50301 | B5: 全国 | C5: 2015 | D5: 1.5. 本省(区、市)调出量(-) | E5: 电力(亿千瓦小时) | I5: 1.2. 外省(区、市)调入量 | J5: 4.51 | K5: 42.4222 | L5: 35.67 | M5: 83.71 | N5: 177.84 | O5: 425.1 | P5: 537.24 | R5: 1306.4922
A6: 50302 | B6: 全国 | C6: 2015 | D6: 1.6. 出口量(-) | E6: 电力(亿千瓦小时) | F6: -186.54 | I6: 1.3. 进口量
A7: 51527 | B7: 安徽省 | C7: 2015 | D7: 1.5. 本省(区、市)调出量(-) | E7: 电力(亿千瓦小时) | F7: -426.61 | I7: 1.5. 本省(区、市)调出量(-) | J7: -426.61 | K7: -500.1329 | L7: -584.45 | M7: -689.86 | N7: -763.83 | O7: -806.58 | P7: -904.99 | R7: -4676.4529
A8: 51627 | B8: 安徽省 | C8: 2015 | D8: 1.1. 一次能源生产量 | E8: 电力(亿千瓦小时) | F8: 72.98 | I8: 1.6. 出口量(-)
A9: 51628 | B9: 安徽省 | C9: 2015 | D9: 1.2. 外省(区、市)调入量 | E9: 电力(亿千瓦小时) | F9: 4.51 | I9: 北京市 | J9: 541.44 | K9: 601.2465 | L9: 689.85 | M9: 709.91 | N9: 723.38 | O9: 705.65 | P9: 786.1 | R9: 4757.5765
A10: 51629 | B10: 安徽省 | C10: 2015 | D10: 1.3. 进口量 | E10: 电力(亿千瓦小时) | I10: 1.1. 一次能源生产量 | J10: 9.72 | K10: 16.5978 | L10: 16.67 | M10: 16.46 | N10: 18.37 | O10: 21.38 | P10: 23.9 | R10: 123.0978
A11: 51807 | B11: 北京市 | C11: 2015 | D11: 1.5. 本省(区、市)调出量(-) | E11: 电力(亿千瓦小时) | F11: -5.26 | I11: 1.2. 外省(区、市)调入量 | J11: 536.98 | K11: 594.908 | L11: 678.53 | M11: 700.29 | N11: 708.87 | O11: 689.02 | P11: 764.84 | R11: 4673.438
A12: 67697 | B12: 福建省 | C12: 2015 | D12: 1.5. 本省(区、市)调出量(-) | E12: 电力(亿千瓦小时) | F12: -32.87 | I12: 1.3. 进口量
A13: 67797 | B13: 北京市 | C13: 2015 | D13: 1.1. 一次能源生产量 | E13: 电力(亿千瓦小时) | F13: 9.72 | I13: 1.5. 本省(区、市)调出量(-) | J13: -5.26 | K13: -10.2593 | L13: -5.35 | M13: -6.84 | N13: -3.86 | O13: -4.75 | P13: -2.64 | R13: -38.9593
A14: 67798 | B14: 北京市 | C14: 2015 | D14: 1.2. 外省(区、市)调入量 | E14: 电力(亿千瓦小时) | F14: 536.98 | I14: 1.6. 出口量(-)
A15: 67799 | B15: 北京市 | C15: 2015 | D15: 1.3. 进口量 | E15: 电力(亿千瓦小时) | I15: 福建省 | J15: 769.91 | K15: 1081.92 | L15: 1012.22 | M15: 908.69 | N15: 996.21 | O15: 932.26 | P15: 1133.85 | R15: 6835.06
A16: 67977 | B16: 甘肃省 | C16: 2015 | D16: 1.5. 本省(区、市)调出量(-) | E16: 电力(亿千瓦小时) | F16: -244.06 | I16: 1.1. 一次能源生产量 | J16: 800.85 | K16: 1117.95 | L16: 1085.07 | M16: 1056.75 | N16: 1166.82 | O16: 1085.74 | P16: 1228.39 | R16: 7541.57
A17: 83967 | B17: 福建省 | C17: 2015 | D17: 1.1. 一次能源生产量 | E17: 电力(亿千瓦小时) | F17: 800.85 | I17: 1.2. 外省(区、市)调入量 | J17: 1.93 | K17: 6.33 | L17: 2.49 | M17: 1.3 | N17: 1.25 | O17: 1.5 | P17: 6.15 | R17: 20.95
A18: 83968 | B18: 福建省 | C18: 2015 | D18: 1.2. 外省(区、市)调入量 | E18: 电力(亿千瓦小时) | F18: 1.93 | I18: 1.3. 进口量
A19: 83969 | B19: 福建省 | C19: 2015 | D19: 1.3. 进口量 | E19: 电力(亿千瓦小时) | I19: 1.5. 本省(区、市)调出量(-) | J19: -32.87 | K19: -42.36 | L19: -75.34 | M19: -149.36 | N19: -171.86 | O19: -154.98 | P19: -100.69 | R19: -727.46
A20: 83971 | B20: 广东省 | C20: 2015 | D20: 1.5. 本省(区、市)调出量(-) | E20: 电力(亿千瓦小时) | I20: 1.6. 出口量(-)
A21: 84147 | B21: 广西壮族自治区 | C21: 2015 | D21: 1.5. 本省(区、市)调出量(-) | E21: 电力(亿千瓦小时) | F21: -120.75 | I21: 甘肃省 | J21: 392.58 | K21: 366.89 | L21: 457.77 | M21: 459.91 | N21: 471.33 | O21: 474.67 | P21: 452.33 | R21: 3075.48
A22: 100037 | B22: 贵州省 | C22: 2015 | D22: 1.5. 本省(区、市)调出量(-) | E22: 电力(亿千瓦小时) | F22: -756.41 | I22: 1.1. 一次能源生产量 | J22: 521.79 | K22: 510.15 | L22: 635.23 | M22: 769.02 | N22: 842.66 | O22: 886.4 | P22: 890.04 | R22: 5055.29
A23: 100137 | B23: 甘肃省 | C23: 2015 | D23: 1.1. 一次能源生产量 | E23: 电力(亿千瓦小时) | F23: 521.79 | I23: 1.2. 外省(区、市)调入量 | J23: 114.85 | K23: 119.2 | L23: 186.77 | M23: 301.16 | N23: 367.93 | O23: 375.59 | P23: 354.96 | R23: 1820.46
A24: 100138 | B24: 甘肃省 | C24: 2015 | D24: 1.2. 外省(区、市)调入量 | E24: 电力(亿千瓦小时) | F24: 114.85 | I24: 1.3. 进口量
A25: 100139 | B25: 甘肃省 | C25: 2015 | D25: 1.3. 进口量 | E25: 电力(亿千瓦小时) | I25: 1.5. 本省(区、市)调出量(-) | J25: -244.06 | K25: -262.46 | L25: -364.23 | M25: -610.27 | N25: -739.26 | O25: -787.32 | P25: -792.67 | R25: -3800.27
A26: 100317 | B26: 海南省 | C26: 2015 | D26: 1.5. 本省(区、市)调出量(-) | E26: 电力(亿千瓦小时) | F26: -0.42 | I26: 1.6. 出口量(-)
A27: 116172 | B27: 广东省 | C27: 2015 | D27: 1.2. 外省(区、市)调入量 | E27: 电力(亿千瓦小时) | F27: 1426.27 | I27: 广东省 | J27: 2377.03 | K27: 2639.1 | L27: 2626.16 | M27: 2859.86 | N27: 3261.96 | O27: 3323 | P27: 3228.06 | R27: 20315.17
A28: 116307 | B28: 广东省 | C28: 2015 | D28: 1.1. 一次能源生产量 | E28: 电力(亿千瓦小时) | F28: 1101.12 | I28: 1.1. 一次能源生产量 | J28: 1101.12 | K28: 1291.98 | L28: 1204 | M28: 1276.12 | N28: 1617.14 | O28: 1622.79 | P28: 1667.66 | R28: 9780.81
A29: 116309 | B29: 广东省 | C29: 2015 | D29: 1.3. 进口量 | E29: 电力(亿千瓦小时) | F29: 11.73 | I29: 1.2. 外省(区、市)调入量 | J29: 1426.27 | K29: 1493.69 | L29: 3060.44 | M29: 1748.47 | N29: 1822.08 | O29: 1880.19 | P29: 1741.26 | R29: 13172.4
A30: 116378 | B30: 河北省 | C30: 2015 | D30: 1.5. 本省(区、市)调出量(-) | E30: 电力(亿千瓦小时) | I30: 1.3. 进口量 | J30: 11.73 | K30: 12.37 | M30: 6.02 | R30: 30.12
A31: 116556 | B31: 河南省 | C31: 2015 | D31: 1.5. 本省(区、市)调出量(-) | E31: 电力(亿千瓦小时) | F31: -57.74 | I31: 1.5. 本省(区、市)调出量(-) | L31: -1638.28 | N31: -0.29 | O31: -0.67 | P31: -180.86 | R31: -1820.1
A32: 132377 | B32: 黑龙江省 | C32: 2015 | D32: 1.5. 本省(区、市)调出量(-) | E32: 电力(亿千瓦小时) | F32: -139.78 | I32: 1.6. 出口量(-) | J32: -162.09 | K32: -158.94 | M32: -170.75 | N32: -176.97 | O32: -179.31 | R32: -848.06
A33: 132477 | B33: 广西壮族自治区 | C33: 2015 | D33: 1.1. 一次能源生产量 | E33: 电力(亿千瓦小时) | F33: 774.74 | I33: 广西壮族自治区 | J33: 790.07 | K33: 785.14 | L33: 825 | M33: 916.55 | N33: 900.66 | O33: 960.36 | P33: 1114.49 | R33: 6292.27
A34: 132478 | B34: 广西壮族自治区 | C34: 2015 | D34: 1.2. 外省(区、市)调入量 | E34: 电力(亿千瓦小时) | F34: 136.08 | I34: 1.1. 一次能源生产量 | J34: 774.74 | K34: 772 | L34: 783.76 | M34: 920.87 | N34: 839.76 | O34: 905.99 | P34: 887.32 | R34: 5884.44
A35: 132479 | B35: 广西壮族自治区 | C35: 2015 | D35: 1.3. 进口量 | E35: 电力(亿千瓦小时) | I35: 1.2. 外省(区、市)调入量 | J35: 136.08 | K35: 103.13 | L35: 144.14 | M35: 205.99 | N35: 171.5 | O35: 204.24 | P35: 321.77 | R35: 1286.85
A36: 132657 | B36: 湖北省 | C36: 2015 | D36: 1.5. 本省(区、市)调出量(-) | E36: 电力(亿千瓦小时) | F36: -775.03 | I36: 1.3. 进口量
A37: 148547 | B37: 湖南省 | C37: 2015 | D37: 1.5. 本省(区、市)调出量(-) | E37: 电力(亿千瓦小时) | F37: -87.12 | I37: 1.5. 本省(区、市)调出量(-) | J37: -120.75 | K37: -89.99 | L37: -102.9 | M37: -210.31 | N37: -110.6 | O37: -149.87 | P37: -94.6 | R37: -879.02
A38: 148647 | B38: 贵州省 | C38: 2015 | D38: 1.1. 一次能源生产量 | E38: 电力(亿千瓦小时) | F38: 859.47 | I38: 1.6. 出口量(-)
A39: 148648 | B39: 贵州省 | C39: 2015 | D39: 1.2. 外省(区、市)调入量 | E39: 电力(亿千瓦小时) | I39: 贵州省 | J39: 103.06 | K39: 76.5136 | L39: 175.18 | M39: 219.39 | N39: 151.06 | O39: 253.96 | P39: 296.17 | R39: 1275.3336
A40: 148649 | B40: 贵州省 | C40: 2015 | D40: 1.3. 进口量 | E40: 电力(亿千瓦小时) | I40: 1.1. 一次能源生产量 | J40: 859.47 | K40: 789.8 | L40: 802.52 | M40: 854.31 | N40: 867 | O40: 973.34 | P40: 921.82 | R40: 6068.26
...

Sheet pre145 21-30 targets
B1: Expected 2021-2030 Provincial Renewabe Consumption Target | N1: Expected 2021-2030 Provincial non-Hydro Renewabe Consumption Target
B2: 2021-2030年各省（区、市）可再生能源电力总量消纳责任权重预期目标建议 | N2: 2021-2030年各省（区、市）可再生能源电力非水消纳责任权重预期目标建议
A3: Hydo % | B3: 年度 | C3: 2021 | D3: 2022 | E3: 2023 | F3: 2024 | G3: 2025 | H3: 2026 | I3: 2027 | J3: 2028 | K3: 2029 | L3: 2030 | N3: 年度 | O3: 2021 | P3: 2022 | Q3: 2023 | R3: 2024 | S3: 2025 | T3: 2026 | U3: 2027 | V3: 2028 | W3: 2029 | X3: 2030
A4: =C4-O4 -> 0.16 | B4: 全国 | C4: 0.287 | D4: 0.299 | E4: 0.311 | F4: 0.324 | G4: 0.336 | H4: 0.349 | I4: 0.361 | J4: 0.374 | K4: 0.386 | L4: 0.4 | N4: 全国 | O4: 0.127 | P4: 0.142 | Q4: 0.156 | R4: 0.171 | S4: 0.186 | T4: 0.2 | U4: 0.215 | V4: 0.23 | W4: 0.244 | X4: 0.259
A5: =C5-O5 -> 0.005 | B5: 北京 | C5: 0.18 | D5: 0.204 | E5: 0.229 | F5: 0.253 | G5: 0.278 | H5: 0.302 | I5: 0.327 | J5: 0.351 | K5: 0.376 | L5: 0.4 | N5: 北京 | O5: 0.175 | P5: 0.19 | Q5: 0.204 | R5: 0.219 | S5: 0.234 | T5: 0.248 | U5: 0.263 | V5: 0.278 | W5: 0.292 | X5: 0.307
A6: =C6-O6 -> 0.01 | B6: 天津 | C6: 0.18 | D6: 0.204 | E6: 0.229 | F6: 0.253 | G6: 0.278 | H6: 0.302 | I6: 0.327 | J6: 0.351 | K6: 0.376 | L6: 0.4 | N6: 天津 | O6: 0.17 | P6: 0.185 | Q6: 0.199 | R6: 0.214 | S6: 0.229 | T6: 0.243 | U6: 0.258 | V6: 0.273 | W6: 0.287 | X6: 0.302
A7: =C7-O7 -> 0.005 | B7: 河北 | C7: 0.165 | D7: 0.191 | E7: 0.217 | F7: 0.243 | G7: 0.269 | H7: 0.296 | I7: 0.322 | J7: 0.348 | K7: 0.374 | L7: 0.4 | N7: 河北 | O7: 0.16 | P7: 0.175 | Q7: 0.189 | R7: 0.204 | S7: 0.219 | T7: 0.233 | U7: 0.248 | V7: 0.263 | W7: 0.277 | X7: 0.292
A8: =C8-O8 -> 0.005 | B8: 山西 | C8: 0.205 | D8: 0.227 | E8: 0.248 | F8: 0.27 | G8: 0.292 | H8: 0.313 | I8: 0.335 | J8: 0.357 | K8: 0.378 | L8: 0.4 | N8: 山西 | O8: 0.2 | P8: 0.215 | Q8: 0.229 | R8: 0.244 | S8: 0.259 | T8: 0.273 | U8: 0.288 | V8: 0.303 | W8: 0.317 | X8: 0.332
A9: =C9-O9 -> 0.005 | B9: 山东 | C9: 0.13 | D9: 0.16 | E9: 0.19 | F9: 0.22 | G9: 0.25 | H9: 0.28 | I9: 0.31 | J9: 0.34 | K9: 0.37 | L9: 0.4 | N9: 山东 | O9: 0.125 | P9: 0.14 | Q9: 0.154 | R9: 0.169 | S9: 0.184 | T9: 0.198 | U9: 0.213 | V9: 0.228 | W9: 0.242 | X9: 0.257
A10: =C10-O10 -> 0.005 | B10: 内蒙古 | C10: 0.21 | D10: 0.231 | E10: 0.252 | F10: 0.273 | G10: 0.294 | H10: 0.316 | I10: 0.337 | J10: 0.358 | K10: 0.379 | L10: 0.4 | N10: 内蒙古 | O10: 0.205 | P10: 0.22 | Q10: 0.234 | R10: 0.249 | S10: 0.264 | T10: 0.278 | U10: 0.293 | V10: 0.308 | W10: 0.322 | X10: 0.337
A11: =C11-O11 -> 0.02 | B11: 辽宁 | C11: 0.155 | D11: 0.182 | E11: 0.209 | F11: 0.237 | G11: 0.264 | H11: 0.291 | I11: 0.318 | J11: 0.346 | K11: 0.373 | L11: 0.4 | N11: 辽宁 | O11: 0.135 | P11: 0.15 | Q11: 0.164 | R11: 0.179 | S11: 0.194 | T11: 0.208 | U11: 0.223 | V11: 0.238 | W11: 0.252 | X11: 0.267
A12: =C12-O12 -> 0.07 | B12: 吉林 | C12: 0.28 | D12: 0.293 | E12: 0.307 | F12: 0.32 | G12: 0.333 | H12: 0.347 | I12: 0.36 | J12: 0.373 | K12: 0.387 | L12: 0.4 | N12: 吉林 | O12: 0.21 | P12: 0.225 | Q12: 0.239 | R12: 0.254 | S12: 0.269 | T12: 0.283 | U12: 0.298 | V12: 0.313 | W12: 0.327 | X12: 0.342
A13: =C13-O13 -> 0.015 | B13: 黑龙江 | C13: 0.225 | D13: 0.244 | E13: 0.264 | F13: 0.283 | G13: 0.303 | H13: 0.322 | I13: 0.342 | J13: 0.361 | K13: 0.381 | L13: 0.4 | N13: 黑龙江 | O13: 0.21 | P13: 0.225 | Q13: 0.239 | R13: 0.254 | S13: 0.269 | T13: 0.283 | U13: 0.298 | V13: 0.313 | W13: 0.327 | X13: 0.342
A14: =C14-O14 -> 0.285 | B14: 上海 | C14: 0.33 | D14: 0.338 | E14: 0.346 | F14: 0.353 | G14: 0.361 | H14: 0.369 | I14: 0.377 | J14: 0.384 | K14: 0.392 | L14: 0.4 | N14: 上海 | O14: 0.045 | P14: 0.06 | Q14: 0.074 | R14: 0.089 | S14: 0.104 | T14: 0.118 | U14: 0.133 | V14: 0.148 | W14: 0.162 | X14: 0.177
A15: =C15-O15 -> 0.075 | B15: 江苏 | C15: 0.185 | D15: 0.209 | E15: 0.233 | F15: 0.257 | G15: 0.281 | H15: 0.304 | I15: 0.328 | J15: 0.352 | K15: 0.376 | L15: 0.4 | N15: 江苏 | O15: 0.11 | P15: 0.125 | Q15: 0.139 | R15: 0.154 | S15: 0.169 | T15: 0.183 | U15: 0.198 | V15: 0.213 | W15: 0.227 | X15: 0.242
... A20: =C20-O20 -> 0.06 | B20: 河南 | C20: 0.26 | D20: 0.276 | E20: 0.291 | F20: 0.307 | G20: 0.322 | H20: 0.338 | I20: 0.353 | J20: 0.369 | K20: 0.384 | L20: 0.4 | N20: 河南 | O20: 0.2 | P20: 0.215 | Q20: 0.229 | R20: 0.244 | S20: 0.259 | T20: 0.273 | U20: 0.288 | V20: 0.303 | W20: 0.317 | X20: 0.332
A21: =C21-O21 -> 0.305 | B21: 河北 | C21: 0.405 | D21: =C21 -> 0.405 | E21: =D21 -> 0.405 | F21: =E21 -> 0.405 | G21: =F21 -> 0.405 | H21: =G21 -> 0.405 | I21: =H21 -> 0.405 | J21: =I21 -> 0.405 | K21: =J21 -> 0.405 | L21: =K21 -> 0.405 | N21: 河北 | O21: 0.1 | P21: 0.115 | Q21: 0.129 | R21: 0.144 | S21: 0.159 | T21: 0.173 | U21: 0.188 | V21: 0.203 | W21: 0.217 | X21: 0.232
A22: =C22-O22 -> 0.325 | B22: 湖南 | C22: 0.47 | D22: =C22 -> 0.47 | E22: =D22 -> 0.47 | F22: =E22 -> 0.47 | G22: =F22 -> 0.47 | H22: =G22 -> 0.47 | I22: =H22 -> 0.47 | J22: =I22 -> 0.47 | K22: =J22 -> 0.47 | L22: =K22 -> 0.47 | N22: 湖南 | O22: 0.145 | P22: 0.16 | Q22: 0.174 | R22: 0.189 | S22: 0.204 | T22: 0.218 | U22: 0.233 | V22: 0.248 | W22: 0.262 | X22: 0.277
A23: =C23-O23 -> 0.445 | B23: 重庆 | C23: 0.485 | D23: =C23 -> 0.485 | E23: =D23 -> 0.485 | F23: =E23 -> 0.485 | G23: =F23 -> 0.485 | H23: =G23 -> 0.485 | I23: =H23 -> 0.485 | J23: =I23 -> 0.485 | K23: =J23 -> 0.485 | L23: =K23 -> 0.485 | N23: 重庆 | O23: 0.04 | P23: 0.055 | Q23: 0.069 | R23: 0.084 | S23: 0.099 | T23: 0.113 | U23: 0.128 | V23: 0.143 | W23: 0.157 | X23: 0.172
A24: =C24-O24 -> 0.73 | B24: 四川 | C24: 0.79 | D24: =C24 -> 0.79 | E24: =D24 -> 0.79 | F24: =E24 -> 0.79 | G24: =F24 -> 0.79 | H24: =G24 -> 0.79 | I24: =H24 -> 0.79 | J24: =I24 -> 0.79 | K24: =J24 -> 0.79 | L24: =K24 -> 0.79 | N24: 四川 | O24: 0.06 | P24: 0.075 | Q24: 0.089 | R24: 0.104 | S24: 0.119 | T24: 0.133 | U24: 0.148 | V24: 0.163 | W24: 0.177 | X24: 0.192
A25: =C25-O25 -> 0.11 | B25: 陕西 | C25: 0.26 | D25: 0.276 | E25: 0.291 | F25: 0.307 | G25: 0.322 | H25: 0.338 | I25: 0.353 | J25: 0.369 | K25: 0.384 | L25: 0.4 | N25: 陕西 | O25: 0.15 | P25: 0.165 | Q25: 0.179 | R25: 0.194 | S25: 0.209 | T25: 0.223 | U25: 0.238 | V25: 0.253 | W25: 0.267 | X25: 0.282
A26: =C26-O26 -> 0.295 | B26: 甘肃 | C26: 0.495 | D26: =C26 -> 0.495 | E26: =D26 -> 0.495 | F26: =E26 -> 0.495 | G26: =F26 -> 0.495 | H26: =G26 -> 0.495 | I26: =H26 -> 0.495 | J26: =I26 -> 0.495 | K26: =J26 -> 0.495 | L26: =K26 -> 0.495 | N26: 甘肃 | O26: 0.2 | P26: 0.215 | Q26: 0.229 | R26: 0.244 | S26: 0.259 | T26: 0.273 | U26: 0.288 | V26: 0.303 | W26: 0.317 | X26: 0.332
A27: =C27-O27 -> 0.44 | B27: 青海 | C27: 0.7 | D27: =C27 -> 0.7 | E27: =D27 -> 0.7 | F27: =E27 -> 0.7 | G27: =F27 -> 0.7 | H27: =G27 -> 0.7 | I27: =H27 -> 0.7 | J27: =I27 -> 0.7 | K27: =J27 -> 0.7 | L27: =K27 -> 0.7 | N27: 青海 | O27: 0.26 | P27: 0.275 | Q27: 0.289 | R27: 0.304 | S27: 0.319 | T27: 0.333 | U27: 0.348 | V27: 0.363 | W27: 0.377 | X27: 0.392
A28: =C28-O28 -> 0.045 | B28: 宁夏 | C28: 0.265 | D28: 0.28 | E28: 0.295 | F28: 0.31 | G28: 0.325 | H28: 0.34 | I28: 0.355 | J28: 0.37 | K28: 0.385 | L28: 0.4 | N28: 宁夏 | O28: 0.22 | P28: 0.235 | Q28: 0.249 | R28: 0.264 | S28: 0.279 | T28: 0.293 | U28: 0.308 | V28: 0.323 | W28: 0.337 | X28: 0.352
A29: =C29-O29 -> 0.09 | B29: 新疆 | C29: 0.23 | D29: 0.249 | E29: 0.268 | F29: 0.287 | G29: 0.306 | H29: 0.324 | I29: 0.343 | J29: 0.362 | K29: 0.381 | L29: 0.4 | N29: 新疆 | O29: 0.14 | P29: 0.155 | Q29: 0.169 | R29: 0.184 | S29: 0.199 | T29: 0.213 | U29: 0.228 | V29: 0.243 | W29: 0.257 | X29: 0.272
A30: =C30-O30 -> 0.245 | B30: 广东 | C30: 0.3 | D30: 0.311 | E30: 0.322 | F30: 0.333 | G30: 0.344 | H30: 0.356 | I30: 0.367 | J30: 0.378 | K30: 0.389 | L30: 0.4 | N30: 广东 | O30: 0.055 | P30: 0.07 | Q30: 0.084 | R30: 0.099 | S30: 0.114 | T30: 0.128 | U30: 0.143 | V30: 0.158 | W30: 0.172 | X30: 0.187
A31: =C31-O31 -> 0.335 | B31: 广西 | C31: 0.435 | D31: =C31 -> 0.435 | E31: =D31 -> 0.435 | F31: =E31 -> 0.435 | G31: =F31 -> 0.435 | H31: =G31 -> 0.435 | I31: =H31 -> 0.435 | J31: =I31 -> 0.435 | K31: =J31 -> 0.435 | L31: =K31 -> 0.435 | N31: 广西 | O31: 0.1 | P31: 0.115 | Q31: 0.129 | R31: 0.144 | S31: 0.159 | T31: 0.173 | U31: 0.188 | V31: 0.203 | W31: 0.217 | X31: 0.232
A32: =C32-O32 -> 0.08 | B32: 海南 | C32: 0.16 | D32: 0.187 | E32: 0.213 | F32: 0.24 | G32: 0.267 | H32: 0.293 | I32: 0.32 | J32: 0.347 | K32: 0.373 | L32: 0.4 | N32: 海南 | O32: 0.08 | P32: 0.095 | Q32: 0.109 | R32: 0.124 | S32: 0.139 | T32: 0.153 | U32: 0.168 | V32: 0.183 | W32: 0.197 | X32: 0.212
A33: =C33-O33 -> 0.285 | B33: 贵州 | C33: 0.38 | D33: 0.382 | E33: 0.384 | F33: 0.387 | G33: 0.389 | H33: 0.391 | I33: 0.393 | J33: 0.396 | K33: 0.398 | L33: 0.4 | N33: 贵州 | O33: 0.095 | P33: 0.11 | Q33: 0.124 | R33: 0.139 | S33: 0.154 | T33: 0.168 | U33: 0.183 | V33: 0.198 | W33: 0.212 | X33: 0.227
A34: =C34-O34 -> 0.6 | B34: 云南 | C34: 0.75 | D34: =C34 -> 0.75 | E34: =D34 -> 0.75 | F34: =E34 -> 0.75 | G34: =F34 -> 0.75 | H34: =G34 -> 0.75 | I34: =H34 -> 0.75 | J34: =I34 -> 0.75 | K34: =J34 -> 0.75 | L34: =K34 -> 0.75 | N34: 云南 | O34: 0.15 | P34: 0.165 | Q34: 0.179 | R34: 0.194 | S34: 0.209 | T34: 0.223 | U34: 0.238 | V34: 0.253 | W34: 0.267 | X34: 0.282
C36: * Values highlighed in Red and filled with started year values to avoild calculation errors.

Sheet annual consumption target
A1: 省（区、市） | B1: Minimum Renewable Consumption Ratio | I1: Minimum non-Hydro Renewable Consumption Ratio | P1: Encouraged Renewable Consumption Ratio | T1: Encouraged non-Hydro Renewable Consumption Ratio
B2: 可再生能源最低消纳权重 | I2: 非水可再生能源最低消纳权重 | P2: 可再生能源激励性消纳权重 | T2: 非水可再生能源激励性消纳权重
B3: 2018 | C3: 2019 | D3: 2020 | E3: 2021 | F3: 2022 | G3: 2023 | H3: 2024 | I3: 2018 | J3: 2019 | K3: 2020 | L3: 2021 | M3: 2022 | N3: 2023 | O3: 2024 | P3: 2018 | Q3: 2019 | R3: 2020 | S3: 2021 | T3: 2018 | U3: 2019 | V3: 2020 | W3: 2021
A4: 北京 | B4: 0.11 | C4: 0.135 | D4: 0.155 | E4: 0.18 | F4: 0.1944 | G4: 0.201 | H4: 0.217 | I4: 0.105 | J4: 0.135 | K4: 0.15 | L4: 0.175 | M4: 0.1875 | N4: 0.2 | O4: 0.217 | P4: 0.121 | Q4: 0.149 | R4: 0.169 | S4: 0.198 | T4: 0.116 | U4: 0.149 | V4: 0.165 | W4: 0.193
A5: 天津 | B5: 0.11 | C5: 0.135 | D5: 0.145 | E5: 0.17 | F5: 0.1842 | G5: 0.195 | H5: 0.205 | I5: 0.105 | J5: 0.135 | K5: 0.14 | L5: 0.16 | M5: 0.1725 | N5: 0.187 | O5: 0.204 | P5: 0.121 | Q5: 0.149 | R5: 0.159 | S5: 0.187 | T5: 0.116 | U5: 0.149 | V5: 0.154 | W5: 0.176
A6: 河北 | B6: 0.11 | C6: 0.135 | D6: 0.13 | E6: 0.165 | F6: 0.1793 | G6: 0.191 | H6: 0.207 | I6: 0.105 | J6: 0.135 | K6: 0.125 | L6: 0.16 | M6: 0.1725 | N6: 0.19 | O6: 0.207 | P6: 0.121 | Q6: 0.149 | R6: 0.144 | S6: 0.182 | T6: 0.116 | U6: 0.149 | V6: 0.138 | W6: 0.176
A7: 山西 | B7: 0.15 | C7: 0.155 | D7: 0.17 | E7: 0.2 | F7: 0.2141 | G7: 0.225 | H7: 0.235 | I7: 0.125 | J7: 0.135 | K7: 0.16 | L7: 0.19 | M7: 0.2025 | N7: 0.215 | O7: 0.232 | P7: 0.165 | Q7: 0.171 | R7: 0.188 | S7: 0.22 | T7: 0.138 | U7: 0.149 | V7: 0.176 | W7: 0.209
A8: 内蒙古 | B8: 0.185 | C8: 0.185 | D8: 0.18 | E8: 0.205 | F8: 0.2187 | G8: 0.23 | H8: 0.24 | I8: 0.18 | J8: 0.18 | K8: 0.165 | L8: 0.195 | M8: 0.2075 | N8: 0.22 | O8: 0.237 | P8: 0.204 | Q8: 0.204 | R8: 0.197 | S8: 0.226 | T8: 0.198 | U8: 0.198 | V8: 0.182 | W8: 0.215
A9: 辽宁 | B9: 0.12 | C9: 0.12 | D9: 0.15 | E9: 0.155 | F9: 0.169 | G9: 0.192 | H9: 0.202 | I9: 0.1 | J9: 0.1 | K9: 0.125 | L9: 0.135 | M9: 0.1475 | N9: 0.16 | O9: 0.177 | P9: 0.132 | Q9: 0.132 | R9: 0.166 | S9: 0.171 | T9: 0.11 | U9: 0.11 | V9: 0.138 | W9: 0.149
A10: 吉林 | B10: 0.2 | C10: 0.215 | D10: 0.24 | E10: 0.28 | F10: 0.2929 | G10: 0.313 | H10: 0.323 | I10: 0.15 | J10: 0.155 | K10: 0.185 | L10: 0.21 | M10: 0.2225 | N10: 0.235 | O10: 0.252 | P10: 0.22 | Q10: 0.237 | R10: 0.266 | S10: 0.309 | T10: 0.165 | U10: 0.171 | V10: 0.204 | W10: 0.231
A11: 黑龙江 | B11: 0.195 | C11: 0.215 | D11: 0.22 | E11: 0.22 | F11: 0.234 | G11: 0.245 | H11: 0.255 | I11: 0.15 | J11: 0.175 | K11: 0.2 | L11: 0.2 | M11: 0.2125 | N11: 0.227 | O11: 0.244 | P11: 0.215 | Q11: 0.237 | R11: 0.244 | S11: 0.242 | T11: 0.165 | U11: 0.193 | V11: 0.22 | W11: 0.22
A12: 上海 | B12: 0.315 | C12: 0.32 | D12: 0.325 | E12: 0.315 | F12: 0.3245 | G12: 0.3 | H12: 0.31 | I12: 0.025 | J12: 0.03 | K12: 0.04 | L12: 0.04 | M12: 0.0525 | N12: 0.06 | O12: 0.077 | P12: 0.349 | Q12: 0.352 | R12: 0.363 | S12: 0.35 | T12: 0.028 | U12: 0.033 | V12: 0.044 | W12: 0.044
A13: 江苏 | B13: 0.125 | C13: 0.135 | D13: 0.14 | E13: 0.165 | F13: 0.1771 | G13: 0.209 | H13: 0.219 | I13: 0.055 | J13: 0.065 | K13: 0.075 | L13: 0.105 | M13: 0.1175 | N13: 0.13 | O13: 0.147 | P13: 0.137 | Q13: 0.149 | R13: 0.154 | S13: 0.182 | T13: 0.061 | U13: 0.072 | V13: 0.083 | W13: 0.116
A14: 浙江 | B14: 0.18 | C14: 0.175 | D14: 0.175 | E14: 0.185 | F14: 0.1946 | G14: 0.216 | H14: 0.226 | I14: 0.05 | J14: 0.065 | K14: 0.075 | L14: 0.085 | M14: 0.0975 | N14: 0.11 | O14: 0.127 | P14: 0.198 | Q14: 0.193 | R14: 0.196 | S14: 0.205 | T14: 0.055 | U14: 0.072 | V14: 0.083 | W14: 0.094
A15: 安徽 | B15: 0.13 | C15: 0.135 | D15: 0.15 | E15: 0.16 | F15: 0.1734 | G15: 0.196 | H15: 0.206 | I15: 0.095 | J15: 0.105 | K15: 0.125 | L15: 0.14 | M15: 0.1525 | N15: 0.165 | O15: 0.182 | P15: 0.143 | Q15: 0.149 | R15: 0.167 | S15: 0.176 | T15: 0.105 | U15: 0.116 | V15: 0.138 | W15: 0.154
... A28: 云南 | B28: 0.8 | C28: 0.8 | D28: 0.8 | E28: 0.75 | F28: 0.7 | G28: 0.7 | H28: 0.7 | I28: 0.115 | J28: 0.115 | K28: 0.15 | L28: 0.15 | M28: 0.1625 | N28: 0.17 | O28: 0.192 | P28: 0.88 | Q28: 0.88 | R28: 0.89 | S28: 0.83 | T28: 0.127 | U28: 0.127 | V28: 0.165 | W28: 0.165
A29: 西藏 | B29: 不考核 | C29: 不考核 | D29: 不考核 | E29: 不考核 | F29: 不考核 | G29: 不考核 | H29: 不考核 | I29: 不考核 | J29: 不考核 | K29: 不考核 | L29: 不考核 | M29: 不考核 | N29: 不考核 | O29: 不考核 | P29: 不考核 | Q29: 不考核 | R29: 不考核 | S29: 不考核 | T29: 不考核 | U29: 不考核 | V29: 不考核 | W29: 不考核
A30: 陕西 | B30: 0.175 | C30: 0.185 | D30: 0.17 | E30: 0.25 | F30: 0.2589 | G30: 0.23 | H30: 0.26 | I30: 0.09 | J30: 0.105 | K30: 0.12 | L30: 0.15 | M30: 0.1625 | N30: 0.185 | O30: 0.202 | P30: 0.192 | Q30: 0.204 | R30: 0.188 | S30: 0.276 | T30: 0.099 | U30: 0.116 | V30: 0.132 | W30: 0.165
A31: 甘肃 | B31: 0.44 | C31: 0.44 | D31: 0.445 | E31: 0.495 | F31: 0.5 | G31: 0.5 | H31: 0.51 | I31: 0.145 | J31: 0.17 | K31: 0.165 | L31: 0.18 | M31: 0.1925 | N31: 0.215 | O31: 0.232 | P31: 0.484 | Q31: 0.484 | R31: 0.488 | S31: 0.548 | T31: 0.16 | U31: 0.187 | V31: 0.182 | W31: 0.198
A32: 青海 | B32: 0.7 | C32: 0.695 | D32: 0.635 | E32: 0.695 | F32: 0.7 | G32: 0.7 | H32: 0.7 | I32: 0.19 | J32: 0.23 | K32: 0.25 | L32: 0.245 | M32: 0.2575 | N32: 0.272 | O32: 0.289 | P32: 0.77 | Q32: 0.765 | R32: 0.707 | S32: 0.77 | T32: 0.209 | U32: 0.253 | V32: 0.275 | W32: 0.27
A33: 宁夏 | B33: 0.2 | C33: 0.2 | D33: 0.22 | E33: 0.24 | F33: 0.254 | G33: 0.265 | H33: 0.275 | I33: 0.18 | J33: 0.18 | K33: 0.2 | L33: 0.22 | M33: 0.2325 | N33: 0.245 | O33: 0.262 | P33: 0.222 | Q33: 0.22 | R33: 0.241 | S33: 0.264 | T33: 0.198 | U33: 0.198 | V33: 0.22 | W33: 0.242
A34: 新疆 | B34: 0.21 | C34: 0.21 | D34: 0.2 | E34: 0.22 | F34: 0.2288 | G34: 0.235 | H34: 未公布 | I34: 0.115 | J34: 0.12 | K34: 0.105 | L34: 0.125 | M34: 0.1375 | N34: 0.128 | O34: 未公布 | P34: 0.231 | Q34: 0.231 | R34: 0.221 | S34: 0.243 | T34: 0.127 | U34: 0.132 | V34: 0.116 | W34: 0.138

Sheet Provincial 145RPS
A1: 内蒙古自治区能源十四五规划

Sheet 14FYP workbook
A1: This sheet is used to calculate Shandong's RPS set for 14th FYP policy scenario, it does not influence calculation for BAU and not used for other provinces
A2: Data Sources:
A3: Inner Mongolia Policy | I3: Policy Targets
A4: Provincial Government and Energy Administration | I4: 展望 2030 年……新能源发电总量超过火电发电总量 “十四五”时期电力发展主要目标是： 化石能源占一次能源消费比重达到 20%左右，新能源装机比重超过 50%，新能源发电总量占总发电量比重超过 35 | P4: 2030
A5: 内蒙古自治区十四五电力发展规划 | P5: 0.5
A6: Inner Mongolia Electricity Development 14FYP | P6: 2025
A7: https://nyj.nmg.gov.cn/zwgk/zfxxgkzl/fdzdgknr/tzgg_16482/tz_16483/202203/P020220329568378960686.pdf | P7: 0.35
A11: Year | B11: 2020 | C11: 2021 | D11: 2022 | E11: 2023 | F11: 2024 | G11: 2025 | H11: 2026 | I11: 2027 | J11: 2028 | K11: 2029 | L11: 2030 | M11: 2031 | N11: 2032 | O11: 2033 | P11: 2034 | Q11: 2035 | R11: 2036 | S11: 2037 | T11: 2038 | U11: 2039 | V11: 2040 | W11: 2041 | X11: 2042 | Y11: 2043 | Z11: 2044 | AA11: 2045 | AB11: 2046 | AC11: 2047 | AD11: 2048 | AE11: 2049 | AF11: 2050 | AG11: 2051 | AH11: 2052 | AI11: 2053 | AJ11: 2054 | AK11: 2055 | AL11: 2056 | AM11: 2057 | AN11: 2058 | AO11: 2059 | AP11: 2060
A12: BAU RPS | B12: =BRPSPTY!B2 -> 0.3266088 | C12: =BRPSPTY!C2 -> 0.3266088 | D12: =BRPSPTY!D2 -> 0.3266088 | E12: =BRPSPTY!E2 -> 0.3266088 | F12: =BRPSPTY!F2 -> 0.3266088 | G12: =BRPSPTY!G2 -> 0.3266088 | H12: =BRPSPTY!H2 -> 0.3266088 | I12: =BRPSPTY!I2 -> 0.3266088 | ... AP12: =BRPSPTY!AP2 -> 0.3266088
A13: Policy RPS | B13: =B12 -> 0.3266088 | C13: =C12 -> 0.3266088 | D13: =D12 -> 0.3266088 | E13: =($G13-$G12)/3*(E11-$D11)+E12 -> 0.33440587 | F13: =($G13-$G12)/3*(F11-$D11)+F12 -> 0.34220293 | G13: =P7 -> 0.35 | H13: =($L13-$L12-$G13+$G12)/5*(H11-$G11)+H12+($G13-$G12) -> 0.38 | I13: =($L13-$L12-$G13+$G12)/5*(I11-$G11)+I12+($G13-$G12) -> 0.41 | J13: =($L13-$L12-$G13+$G12)/5*(J11-$G11)+J12+($G13-$G12) -> 0.44 | K13: =($L13-$L12-$G13+$G12)/5*(K11-$G11)+K12+($G13-$G12) -> 0.47 | L13: 0.5 | M13: =$L13-$L12+M12 -> 0.5 | N13: =$L13-$L12+N12 -> 0.5 | O13: =$L13-$L12+O12 -> 0.5 | P13: =$L13-$L12+P12 -> 0.5 | Q13: =$L13-$L12+Q12 -> 0.5 | R13: =$L13-$L12+R12 -> 0.5 | S13: =$L13-$L12+S12 -> 0.5 | T13: =$L13-$L12+T12 -> 0.5 | U13: =$Q13-$Q12+U12 -> 0.5 | V13: =$Q13-$Q12+V12 -> 0.5 | W13: =$Q13-$Q12+W12 -> 0.5 | X13: =$Q13-$Q12+X12 -> 0.5 | Y13: =$Q13-$Q12+Y12 -> 0.5 | Z13: =$Q13-$Q12+Z12 -> 0.5 | AA13: =$Q13-$Q12+AA12 -> 0.5 | AB13: =$Q13-$Q12+AB12 -> 0.5 | ... AP13: =$Q13-$Q12+AP12 -> 0.5
A14: FOPITY | B14: 0 | C14: 0 | D14: 0 | E14: =ROUND(E13/MAX(13:13),3) -> 0.669 | F14: =ROUND(F13/MAX(13:13),3) -> 0.684 | G14: =ROUND(G13/MAX(13:13),3) -> 0.7 | H14: =ROUND(H13/MAX(13:13),3) -> 0.76 | I14: =ROUND(I13/MAX(13:13),3) -> 0.82 | J14: =ROUND(J13/MAX(13:13),3) -> 0.88 | K14: =ROUND(K13/MAX(13:13),3) -> 0.94 | L14: =ROUND(L13/MAX(13:13),3) -> 1 | ... AP14: =ROUND(AP13/MAX(13:13),3) -> 1
A17: Time (Time) | B17: 2020 | C17: 2021 | D17: 2022 | E17: 2023 | F17: 2024 | G17: 2025 | H17: 2026 | I17: 2027 | J17: 2028 | K17: 2029 | L17: 2030 | M17: 2031 | N17: 2032 | O17: 2033 | P17: 2034 | Q17: 2035 | R17: 2036 | S17: 2037 | T17: 2038 | U17: 2039 | V17: 2040 | W17: 2041 | X17: 2042 | Y17: 2043 | Z17: 2044 | AA17: 2045 | AB17: 2046 | AC17: 2047 | AD17: 2048 | AE17: 2049 | AF17: 2050 | AG17: 2051 | AH17: 2052 | AI17: 2053 | AJ17: 2054 | AK17: 2055 | AL17: 2056 | AM17: 2057 | AN17: 2058 | AO17: 2059 | AP17: 2060
A18: Imported Electricity[hard coal es] : MostRecentRun | B18: 79300000 | C18: 81500000 | D18: 80100000 | E18: 89600000 | F18: 98800000 | G18: 108000000 | H18: 127000000 | I18: 145000000 | J18: 164000000 | K18: 182000000 | L18: 200000000 | M18: 205000000 | N18: 209000000 | O18: 213000000 | P18: 217000000 | Q18: 221000000 | R18: 224000000 | S18: 228000000 | T18: 231000000 | U18: 235000000 | V18: 235273000 | W18: 235545000 | X18: 235818000 | Y18: 236091000 | Z18: 236364000 | AA18: 236636000 | AB18: 236909000 | AC18: 237182000 | AD18: 237455000 | AE18: 237727000 | AF18: 238000000 | AG18: 241000000 | AH18: 244000000 | AI18: 248000000 | AJ18: 251000000 | AK18: 254000000 | AL18: 256000000 | AM18: 259000000 | AN18: 262000000 | AO18: 265000000 | AP18: 267000000
A19: Imported Electricity[natural gas nonpeaker es] : MostRecentRun | B19: 926000 | C19: 950000 | D19: 935000 | E19: 1050000 | F19: 1155000 | G19: 1260000 | H19: 1480000 | I19: 1690000 | J19: 1910000 | K19: 2120000 | L19: 2340000 | M19: 2390000 | N19: 2440000 | O19: 2490000 | P19: 2535000 | Q19: 2580000 | R19: 2620000 | S19: 2660000 | T19: 2700000 | U19: 2740000 | V19: 2743640 | W19: 2747270 | X19: 2750910 | Y19: 2754550 | Z19: 2758180 | AA19: 2761820 | AB19: 2765450 | AC19: 2769090 | AD19: 2772730 | AE19: 2776360 | AF19: 2780000 | AG19: 2820000 | AH19: 2850000 | AI19: 2890000 | AJ19: 2925000 | AK19: 2960000 | AL19: 2990000 | AM19: 3020000 | AN19: 3060000 | AO19: 3090000 | AP19: 3120000
A20: Imported Electricity[nuclear es] : MostRecentRun | B20: 0 | C20: 0 | D20: 0 | E20: 0 | F20: 0 | G20: 0 | H20: 0 | I20: 0 | J20: 0 | K20: 0 | L20: 0 | M20: 0 | N20: 0 | O20: 0 | P20: 0 | Q20: 0 | R20: 0 | S20: 0 | T20: 0 | U20: 0 | V20: 0 | W20: 0 | X20: 0 | Y20: 0 | Z20: 0 | AA20: 0 | AB20: 0 | AC20: 0 | AD20: 0 | AE20: 0 | AF20: 0 | AG20: 0 | AH20: 0 | AI20: 0 | AJ20: 0 | AK20: 0 | AL20: 0 | AM20: 0 | AN20: 0 | AO20: 0 | AP20: 0
A21: Imported Electricity[hydro es] : MostRecentRun | B21: 3260000 | C21: 3350000 | D21: 3300000 | E21: 3690000 | F21: 4070000 | G21: 4450000 | H21: 5210000 | I21: 5970000 | J21: 6730000 | K21: 7490000 | L21: 8250000 | M21: 8430000 | N21: 8600000 | O21: 8760000 | P21: 8920000 | Q21: 9080000 | R21: 9230000 | S21: 9380000 | T21: 9520000 | U21: 9660000 | V21: 9672730 | W21: 9685460 | X21: 9698180 | Y21: 9710910 | Z21: 9723640 | AA21: 9736360 | AB21: 9749090 | AC21: 9761820 | AD21: 9774550 | AE21: 9787270 | AF21: 9800000 | AG21: 9930000 | AH21: 10100000 | AI21: 10200000 | AJ21: 10300000 | AK21: 10400000 | AL21: 10500000 | AM21: 10700000 | AN21: 10800000 | AO21: 10900000 | AP21: 11000000
A22: Imported Electricity[onshore wind es] : MostRecentRun | B22: 19300000 | C22: 19800000 | D22: 19500000 | E22: 21800000 | F22: 24050000 | G22: 26300000 | H22: 30800000 | I22: 35300000 | J22: 39800000 | K22: 44300000 | L22: 48800000 | M22: 49900000 | N22: 50900000 | O22: 51900000 | P22: 52800000 | Q22: 53700000 | R22: 54600000 | S22: 55500000 | T22: 56300000 | U22: 57200000 | V22: 57272700 | W22: 57345500 | X22: 57418200 | Y22: 57490900 | Z22: 57563600 | AA22: 57636400 | AB22: 57709100 | AC22: 57781800 | AD22: 57854500 | AE22: 57927300 | AF22: 58000000 | AG22: 58700000 | AH22: 59500000 | AI22: 60300000 | AJ22: 61000000 | AK22: 61700000 | AL22: 62400000 | AM22: 63100000 | AN22: 63800000 | AO22: 64400000 | AP22: 65100000
A23: Imported Electricity[solar PV es] : MostRecentRun | B23: 10300000 | C23: 10600000 | D23: 10400000 | E23: 11700000 | F23: 12900000 | G23: 14100000 | H23: 16500000 | I23: 18900000 | J23: 21300000 | K23: 23700000 | L23: 26100000 | M23: 26700000 | N23: 27200000 | O23: 27700000 | P23: 28250000 | Q23: 28800000 | R23: 29200000 | S23: 29700000 | T23: 30100000 | U23: 30600000 | V23: 30636400 | W23: 30672700 | X23: 30709100 | Y23: 30745500 | Z23: 30781800 | AA23: 30818200 | AB23: 30854500 | AC23: 30890900 | AD23: 30927300 | AE23: 30963600 | AF23: 31000000 | AG23: 31400000 | AH23: 31800000 | AI23: 32200000 | AJ23: 32600000 | AK23: 33000000 | AL23: 33400000 | AM23: 33800000 | AN23: 34100000 | AO23: 34500000 | AP23: 34800000
A24: Imported Electricity[solar thermal es] : MostRecentRun | B24: 15 | C24: 16 | D24: 17 | E24: 18 | F24: 19 | G24: 20 | H24: 21 | I24: 22 | J24: 23 | K24: 24 | L24: 25 | M24: 26 | N24: 27 | O24: 28 | P24: 29 | Q24: 30 | R24: 31 | S24: 32 | T24: 33 | U24: 34 | V24: 34.0909 | W24: 34.1818 | X24: 34.2727 | Y24: 34.3636 | Z24: 34.4545 | AA24: 34.5455 | AB24: 34.6364 | AC24: 34.7273 | AD24: 34.8182 | AE24: 34.9091 | AF24: 35 | AG24: 36 | AH24: 37 | AI24: 38 | AJ24: 39 | AK24: 40 | AL24: 41 | AM24: 42 | AN24: 43 | AO24: 44 | AP24: 45
A25: Imported Electricity[biomass es] : MostRecentRun | B25: 3470000 | C25: 3560000 | D25: 3500000 | E25: 3920000 | F25: 4325000 | G25: 4730000 | H25: 5530000 | I25: 6340000 | J25: 7150000 | K25: 7960000 | L25: 8760000 | M25: 8960000 | N25: 9140000 | O25: 9310000 | P25: 9480000 | Q25: 9650000 | R25: 9810000 | S25: 9970000 | T25: 10100000 | U25: 10300000 | V25: 10309100 | W25: 10318200 | X25: 10327300 | Y25: 10336400 | Z25: 10345500 | AA25: 10354500 | AB25: 10363600 | AC25: 10372700 | AD25: 10381800 | AE25: 10390900 | AF25: 10400000 | AG25: 10600000 | AH25: 10700000 | AI25: 10800000 | AJ25: 10950000 | AK25: 11100000 | AL25: 11200000 | AM25: 11300000 | AN25: 11500000 | AO25: 11600000 | AP25: 11700000
A26: Imported Electricity[geothermal es] : MostRecentRun | B26: 15 | C26: 16 | D26: 17 | E26: 18 | F26: 19 | G26: 20 | H26: 21 | I26: 22 | J26: 23 | K26: 24 | L26: 25 | M26: 26 | N26: 27 | O26: 28 | P26: 29 | Q26: 30 | R26: 31 | S26: 32 | T26: 33 | U26: 34 | V26: 34.0909 | W26: 34.1818 | X26: 34.2727 | Y26: 34.3636 | Z26: 34.4545 | AA26: 34.5455 | AB26: 34.6364 | AC26: 34.7273 | AD26: 34.8182 | AE26: 34.9091 | AF26: 35 | AG26: 36 | AH26: 37 | AI26: 38 | AJ26: 39 | AK26: 40 | AL26: 41 | AM26: 42 | AN26: 43 | AO26: 44 | AP26: 45
A27: Imported Electricity[petroleum es] : MostRecentRun | B27: 0 | C27: 0 | D27: 0 | E27: 0 | F27: 0 | G27: 0 | H27: 0 | I27: 0 | J27: 0 | K27: 0 | L27: 0 | M27: 0 | N27: 0 | O27: 0 | P27: 0 | Q27: 0 | R27: 0 | S27: 0 | T27: 0 | U27: 0 | V27: 0 | W27: 0 | X27: 0 | Y27: 0 | Z27: 0 | AA27: 0 | AB27: 0 | AC27: 0 | AD27: 0 | AE27: 0 | AF27: 0 | AG27: 0 | AH27: 0 | AI27: 0 | AJ27: 0 | AK27: 0 | AL27: 0 | AM27: 0 | AN27: 0 | AO27: 0 | AP27: 0
A28: Imported Electricity[natural gas peaker es] : MostRecentRun | B28: 0 | C28: 0 | D28: 0 | E28: 0 | F28: 0 | G28: 0 | H28: 0 | I28: 0 | J28: 0 | K28: 0 | L28: 0 | M28: 0 | N28: 0 | O28: 0 | P28: 0 | Q28: 0 | R28: 0 | S28: 0 | T28: 0 | U28: 0 | V28: 0 | W28: 0 | X28: 0 | Y28: 0 | Z28: 0 | AA28: 0 | AB28: 0 | AC28: 0 | AD28: 0 | AE28: 0 | AF28: 0 | AG28: 0 | AH28: 0 | AI28: 0 | AJ28: 0 | AK28: 0 | AL28: 0 | AM28: 0 | AN28: 0 | AO28: 0 | AP28: 0
... A56: Elec Demand after Net Imports : MostRecentRun | B56: 551995000 | C56: 587959000 | D56: 643501000 | E56: 667828000 | F56: 695673000 | G56: 721143000 | H56: 731519000 | I56: 741133000 | J56: 748900000 | K56: 753179000 | L56: 751274000 | M56: 756315000 | N56: 762119000 | O56: 767101000 | P56: 773315000 | Q56: 781053000 | R56: 793598000 | S56: 804589000 | T56: 815082000 | U56: 825516000 | V56: 835452000 | W56: 845593000 | X56: 854328000 | Y56: 862652000 | Z56: 870243000 | AA56: 877366000 | AB56: 885514000 | AC56: 892460000 | AD56: 899465000 | AE56: 906119000 | AF56: 914648000 | AG56: 920246000 | AH56: 926518000 | AI56: 932761000 | AJ56: 939239000 | AK56: 944778000 | AL56: 949878000 | AM56: 954802000 | AN56: 959844000 | AO56: 964152000 | AP56: 968344000
A58: BAU Electricity Demand | B58: =SUM(B18:B33)-B34+B35 -> 667845030 | C58: =SUM(C18:C33)-C34+C35 -> 695848032 | D58: =SUM(D18:D33)-D34+D35 -> 735087034 | E58: =SUM(E18:E33)-E34+E35 -> 768097036 | F58: =SUM(F18:F33)-F34+F35 -> 798570538 | G58: =SUM(G18:G33)-G34+G35 -> 826671040 | H58: =SUM(H18:H33)-H34+H35 -> 853647042 | I58: =SUM(I18:I33)-I34+I35 -> 878068044 | ... AP58: =SUM(AP18:AP33)-AP34+AP35 -> 1355383090
A59: Policy Electricity Demand | B59: =SUM(B39:B54)-B55+B56 -> 667845030 | C59: =SUM(C39:C54)-C55+C56 -> 7.0902202e+08 | D59: =SUM(D39:D54)-D55+D56 -> 7.6240765e+08 | E59: =SUM(E39:E54)-E55+E56 -> 8.0674443e+08 | F59: =SUM(F39:F54)-F55+F56 -> 8.5290009e+08 | G59: =SUM(G39:G54)-G55+G56 -> 8.9727105e+08 | H59: =SUM(H39:H54)-H55+H56 -> 9.4337059e+08 | I59: =SUM(I39:I54)-I55+I56 -> 9.8930678e+08 | ... AP59: =SUM(AP39:AP54)-AP55+AP56 -> 1.3637709e+09
A61: BAU Import Electricty % | B61: =1-B35/B58 -> 0.17346843 | C61: =1-C35/C58 -> 0.17071692 | D61: =1-D35/D58 -> 0.15872275 | E61: =1-E35/E58 -> 0.17034181 | F61: =1-F35/F58 -> 0.18064095 | G61: =1-G35/G58 -> 0.19072888 | H61: =1-H35/H58 -> 0.21709212 | I61: =1-I35/I58 -> 0.24137087 | ... AP61: =1-AP35/AP58 -> 0.28709233
A62: Policy Required | B62: =B61 -> 0.17346843 | C62: =C61 -> 0.17071692 | D62: =D61 -> 0.15872275 | E62: =E61+($Q62-$Q61)/12*(E38-2022) -> 0.1720774 | F62: =F61+($Q62-$Q61)/12*(F38-2022) -> 0.18411213 | G62: =G61+($Q62-$Q61)/12*(G38-2022) -> 0.19593565 | H62: =H61+($Q62-$Q61)/12*(H38-2022) -> 0.22403448 | I62: =I61+($Q62-$Q61)/12*(I38-2022) -> 0.25004882 | J62: =J61+($Q62-$Q61)/12*(J38-2022) -> 0.27629031 | K62: =K61+($Q62-$Q61)/12*(K38-2022) -> 0.30061477 | L62: =L61+($Q62-$Q61)/12*(L38-2022) -> 0.3243474 | ... P62: =P61+($Q62-$Q61)/12*(P38-2022) -> 0.33251222 | Q62: 0.333 | R62: =$Q59*$Q62/R59 -> 0.32949216 | S62: =$Q59*$Q62/S59 -> 0.32648236 | T62: =$Q59*$Q62/T59 -> 0.32365802 | U62: =$Q59*$Q62/U59 -> 0.32090048 | V62: =$Q59*$Q62/V59 -> 0.31830857 | W62: =$Q59*$Q62/W59 -> 0.31570604 | X62: =$Q59*$Q62/X59 -> 0.313498 | Y62: =$Q59*$Q62/Y59 -> 0.31142235 | ... AP62: =$Q59*$Q62/AP59 -> 0.2873544
A64: Increased Electricity Demand | B64: =(B62*B59)/(B61*B58)-1 -> 0 | C64: =(C62*C59)/(C61*C58)-1 -> 0.018932277 | D64: =(D62*D59)/(D61*D58)-1 -> 0.037166502 | E64: =(E62*E59)/(E61*E58)-1 -> 0.061017297 | F64: =(F62*F59)/(F61*F58)-1 -> 0.088556744 | G64: =(G62*G59)/(G61*G58)-1 -> 0.11503356 | H64: =(H62*H59)/(H61*H58)-1 -> 0.14044619 | I64: =(I62*I59)/(I61*I58)-1 -> 0.16719326 | ... AP64: =(AP62*AP59)/(AP61*AP58)-1 -> 0.0071069919
A65: Percentage Change in Electricity Import | B65: 0.3
A66: FOPITY | B66: =B64/$B65 -> 0 | C66: =C64/$B65 -> 0.06310759 | D66: =D64/$B65 -> 0.12388834 | E66: =E64/$B65 -> 0.20339099 | F66: =F64/$B65 -> 0.29518915 | G66: =G64/$B65 -> 0.38344521 | H66: =H64/$B65 -> 0.46815396 | I66: =I64/$B65 -> 0.55731086 | ... AP66: =AP64/$B65 -> 0.023689973
A69: Time (Time) | B69: 2020 | C69: 2021 | D69: 2022 | E69: 2023 | F69: 2024 | G69: 2025 | H69: 2026 | I69: 2027 | J69: 2028 | K69: 2029 | L69: 2030 | M69: 2031 | N69: 2032 | O69: 2033 | P69: 2034 | Q69: 2035 | R69: 2036 | S69: 2037 | T69: 2038 | U69: 2039 | V69: 2040 | W69: 2041 | X69: 2042 | Y69: 2043 | Z69: 2044 | AA69: 2045 | AB69: 2046 | AC69: 2047 | AD69: 2048 | AE69: 2049 | AF69: 2050 | AG69: 2051 | AH69: 2052 | AI69: 2053 | AJ69: 2054 | AK69: 2055 | AL69: 2056 | AM69: 2057 | AN69: 2058 | AO69: 2059 | AP69: 2060
A70: Electricity Generation by Type[hard coal es,preexisting retiring] : MostRecentRun | B70: 413592000 | C70: 412815000 | D70: 434479000 | E70: 425429000 | F70: 417145000 | G70: 391041000 | H70: 383287000 | I70: 372597000 | J70: 347964000 | K70: 320459000 | L70: 287678000 | M70: 271244000 | N70: 266103000 | O70: 260848000 | P70: 256726000 | Q70: 253414000 | R70: 252681000 | S70: 250297000 | T70: 248716000 | U70: 246178000 | V70: 244383000 | W70: 240023000 | X70: 234837000 | Y70: 229610000 | Z70: 223927000 | AA70: 217883000 | AB70: 206766000 | AC70: 191776000 | AD70: 176008000 | AE70: 159891000 | AF70: 143783000 | AG70: 127508000 | AH70: 111530000 | AI70: 95872600 | AJ70: 80587800 | AK70: 65660700 | AL70: 51254800 | AM70: 37626800 | AN70: 24964000 | AO70: 11935000 | AP70: 173602
A71: Electricity Generation by Type[hard coal es,preexisting nonretiring] : MostRecentRun | B71: 0 | C71: 0 | D71: 0 | E71: 0 | F71: 0 | G71: 0 | H71: 0 | I71: 0 | J71: 0 | K71: 0 | L71: 0 | M71: 0 | N71: 0 | O71: 0 | P71: 0 | Q71: 0 | R71: 0 | S71: 0 | T71: 0 | U71: 0 | V71: 0 | W71: 0 | X71: 0 | Y71: 0 | Z71: 0 | AA71: 0 | AB71: 0 | AC71: 0 | AD71: 0 | AE71: 0 | AF71: 0 | AG71: 0 | AH71: 0 | AI71: 0 | AJ71: 0 | AK71: 0 | AL71: 0 | AM71: 0 | AN71: 0 | AO71: 0 | AP71: 0
A72: Electricity Generation by Type[hard coal es,newly built] : MostRecentRun | B72: 18827900 | C72: 25001900 | D72: 38126800 | E72: 52033800 | F72: 62463000 | G72: 67665300 | H72: 66373100 | I72: 65655700 | J72: 62222100 | K72: 57860400 | L72: 52953300 | M72: 50662100 | N72: 50881900 | O72: 50770900 | P72: 51143100 | Q72: 51975600 | R72: 53440700 | S72: 54826600 | T72: 56779300 | U72: 59013100 | V72: 61518400 | W72: 63711200 | X72: 66027500 | Y72: 68715200 | Z72: 71799800 | AA72: 75308700 | AB72: 77339300 | AC72: 78079400 | AD72: 78635300 | AE72: 78981200 | AF72: 79552000 | AG72: 80075500 | AH72: 80685100 | AI72: 81384300 | AJ72: 82177600 | AK72: 83029100 | AL72: 83916500 | AM72: 85141400 | AN72: 88021800 | AO72: 86809500 | AP72: 91823300
A73: Electricity Generation by Type[natural gas nonpeaker es,preexisting retiring] : MostRecentRun | B73: 4.10244 | C73: 0.728696 | D73: 0.11116 | E73: 0.252509 | F73: 0.304485 | G73: 0.279395 | H73: 0.229908 | I73: 0.309119 | J73: 0.417648 | K73: 0.305676 | L73: 0.237136 | M73: 0.189765 | N73: 0.175081 | O73: 0.151197 | P73: 0.133541 | Q73: 0.134912 | R73: 0.140793 | S73: 0.142453 | T73: 0.148757 | U73: 0.163269 | V73: 0.188659 | W73: 0.198675 | X73: 0.208469 | Y73: 0.199658 | Z73: 0.213266 | AA73: 0.206142 | AB73: 0.235079 | AC73: 0.225738 | AD73: 0.214074 | AE73: 0.21925 | AF73: 0.23084 | AG73: 0.205008 | AH73: 0.190519 | AI73: 0.18689 | AJ73: 0.181795 | AK73: 0.175554 | AL73: 0.159972 | AM73: 0.152615 | AN73: 0.148953 | AO73: 0.143872 | AP73: 0.144306
A74: Electricity Generation by Type[natural gas nonpeaker es,preexisting nonretiring] : MostRecentRun | B74: 0 | C74: 0 | D74: 0 | E74: 0 | F74: 0 | G74: 0 | H74: 0 | I74: 0 | J74: 0 | K74: 0 | L74: 0 | M74: 0 | N74: 0 | O74: 0 | P74: 0 | Q74: 0 | R74: 0 | S74: 0 | T74: 0 | U74: 0 | V74: 0 | W74: 0 | X74: 0 | Y74: 0 | Z74: 0 | AA74: 0 | AB74: 0 | AC74: 0 | AD74: 0 | AE74: 0 | AF74: 0 | AG74: 0 | AH74: 0 | AI74: 0 | AJ74: 0 | AK74: 0 | AL74: 0 | AM74: 0 | AN74: 0 | AO74: 0 | AP74: 0
A75: Electricity Generation by Type[natural gas nonpeaker es,newly built] : MostRecentRun | B75: 106.74 | C75: 23.2149 | D75: 1.95782 | E75: 5.88131 | F75: 7.52718 | G75: 6.72284 | H75: 5.19402 | I75: 7.67784 | J75: 11.3729 | K75: 7.93405 | L75: 5.67799 | M75: 4.22227 | N75: 3.79184 | O75: 3.27656 | P75: 2.77245 | Q75: 2.96331 | R75: 3.13824 | S75: 3.18811 | T75: 3.56915 | U75: 4.27921 | V75: 5.18673 | W75: 5.89199 | X75: 6.27939 | Y75: 6.30778 | Z75: 7.33784 | AA75: 7.50786 | AB75: 9.90996 | AC75: 13.1129 | AD75: 17.2401 | AE75: 23.778 | AF75: 34.2332 | AG75: 37.0333 | AH75: 42.0153 | AI75: 50.8154 | AJ75: 60.6537 | AK75: 71.8207 | AL75: 77.7412 | AM75: 90.3709 | AN75: 119.987 | AO75: 137.707 | AP75: 189.448
A76: Electricity Generation by Type[nuclear es,preexisting retiring] : MostRecentRun | B76: 18571200 | C76: 18658800 | D76: 18658800 | E76: 18658800 | F76: 18658800 | G76: 18658800 | H76: 18658800 | I76: 18658800 | J76: 18658800 | K76: 18658800 | L76: 18658800 | M76: 18658800 | N76: 18658800 | O76: 18658800 | P76: 18658800 | Q76: 18658800 | R76: 18658800 | S76: 18658800 | T76: 18658800 | U76: 18658800 | V76: 18658800 | W76: 18658800 | X76: 18658800 | Y76: 18658800 | Z76: 18658800 | AA76: 18658800 | AB76: 18658800 | AC76: 18658800 | AD76: 18658800 | AE76: 18658800 | AF76: 18658800 | AG76: 18658800 | AH76: 18658800 | AI76: 18658800 | AJ76: 18658800 | AK76: 18658800 | AL76: 18658800 | AM76: 18658800 | AN76: 18658800 | AO76: 18658800 | AP76: 18658800
A77: Electricity Generation by Type[nuclear es,preexisting nonretiring] : MostRecentRun | B77: 0 | C77: 0 | D77: 0 | E77: 0 | F77: 0 | G77: 0 | H77: 0 | I77: 0 | J77: 0 | K77: 0 | L77: 0 | M77: 0 | N77: 0 | O77: 0 | P77: 0 | Q77: 0 | R77: 0 | S77: 0 | T77: 0 | U77: 0 | V77: 0 | W77: 0 | X77: 0 | Y77: 0 | Z77: 0 | AA77: 0 | AB77: 0 | AC77: 0 | AD77: 0 | AE77: 0 | AF77: 0 | AG77: 0 | AH77: 0 | AI77: 0 | AJ77: 0 | AK77: 0 | AL77: 0 | AM77: 0 | AN77: 0 | AO77: 0 | AP77: 0
...

Sheet model calibration
A1: Time (Year) | B1: 2020 | C1: 2021 | D1: 2022 | E1: 2023 | F1: 2024 | G1: 2025 | H1: 2026 | I1: 2027 | J1: 2028 | K1: 2029 | L1: 2030 | M1: 2031 | N1: 2032 | O1: 2033 | P1: 2034 | Q1: 2035 | R1: 2036 | S1: 2037 | T1: 2038 | U1: 2039 | V1: 2040 | W1: 2041 | X1: 2042 | Y1: 2043 | Z1: 2044 | AA1: 2045 | AB1: 2046 | AC1: 2047 | AD1: 2048 | AE1: 2049 | AF1: 2050 | AG1: 2051 | AH1: 2052 | AI1: 2053 | AJ1: 2054 | AK1: 2055 | AL1: 2056 | AM1: 2057 | AN1: 2058 | AO1: 2059 | AP1: 2060
A2: Electricity Generation by Type[hard coal es,preexisting retiring] : MostRecentRun | B2: 375627000 | C2: 431988000 | D2: 418958000 | E2: 384280000 | F2: 396266000 | G2: 408727000 | H2: 415737000 | I2: 415610000 | J2: 409422000 | K2: 403146000 | L2: 395530000 | M2: 388055000 | N2: 379644000 | O2: 371117000 | P2: 360691000 | Q2: 352632000 | R2: 340580000 | S2: 328861000 | T2: 316306000 | U2: 303000000 | V2: 289401000 | W2: 275152000 | X2: 260507000 | Y2: 245604000 | Z2: 230355000 | AA2: 214828000 | AB2: 199145000 | AC2: 182875000 | AD2: 166307000 | AE2: 149806000 | AF2: 132815000 | AG2: 116360000 | AH2: 99533500 | AI2: 82747300 | AJ2: 66313000 | AK2: 50130100 | AL2: 34231300 | AM2: 18597900 | AN2: 3248210 | AO2: 0 | AP2: 0
A3: Electricity Generation by Type[hard coal es,preexisting nonretiring] : MostRecentRun | B3: 0 | C3: 0 | D3: 0 | E3: 0 | F3: 0 | G3: 0 | H3: 0 | I3: 0 | J3: 0 | K3: 0 | L3: 0 | M3: 0 | N3: 0 | O3: 0 | P3: 0 | Q3: 0 | R3: 0 | S3: 0 | T3: 0 | U3: 0 | V3: 0 | W3: 0 | X3: 0 | Y3: 0 | Z3: 0 | AA3: 0 | AB3: 0 | AC3: 0 | AD3: 0 | AE3: 0 | AF3: 0 | AG3: 0 | AH3: 0 | AI3: 0 | AJ3: 0 | AK3: 0 | AL3: 0 | AM3: 0 | AN3: 0 | AO3: 0 | AP3: 0
A4: Electricity Generation by Type[hard coal es,newly built] : MostRecentRun | B4: 15684900 | C4: 32873600 | D4: 60014700 | E4: 99860500 | F4: 104974000 | G4: 111554000 | H4: 114319000 | I4: 116784000 | J4: 117842000 | K4: 118463000 | L4: 119707000 | M4: 120148000 | N4: 120744000 | O4: 120904000 | P4: 120945000 | Q4: 122435000 | R4: 122573000 | S4: 123270000 | T4: 124128000 | U4: 125297000 | V4: 126220000 | W4: 127217000 | X4: 128273000 | Y4: 129376000 | Z4: 130619000 | AA4: 131913000 | AB4: 133319000 | AC4: 134723000 | AD4: 136132000 | AE4: 137810000 | AF4: 139385000 | AG4: 141646000 | AH4: 143590000 | AI4: 145638000 | AJ4: 148276000 | AK4: 150959000 | AL4: 153946000 | AM4: 157159000 | AN4: 160560000 | AO4: 152866000 | AP4: 142304000
A5: Electricity Generation by Type[natural gas nonpeaker es,preexisting retiring] : MostRecentRun | B5: 2483.58 | C5: 432.755 | D5: 29.0095 | E5: 72.9517 | F5: 105.098 | G5: 118.71 | H5: 100.901 | I5: 160.261 | J5: 259.034 | K5: 207.813 | L5: 176.727 | M5: 136.011 | N5: 121.187 | O5: 100.073 | P5: 82.3145 | Q5: 84.0051 | R5: 83.932 | S5: 78.3172 | T5: 79.4223 | U5: 85.9948 | V5: 97.0113 | W5: 98.983 | X5: 94.3004 | Y5: 83.565 | Z5: 84.87 | AA5: 74.7599 | AB5: 74.7745 | AC5: 70.2796 | AD5: 65.3556 | AE5: 67.7698 | AF5: 65.7098 | AG5: 56.3609 | AH5: 50.5374 | AI5: 41.684 | AJ5: 38.2834 | AK5: 26.2219 | AL5: 19.0037 | AM5: 12.1833 | AN5: 3.83644 | AO5: 0 | AP5: 0
A6: Electricity Generation by Type[natural gas nonpeaker es,preexisting nonretiring] : MostRecentRun | B6: 0 | C6: 0 | D6: 0 | E6: 0 | F6: 0 | G6: 0 | H6: 0 | I6: 0 | J6: 0 | K6: 0 | L6: 0 | M6: 0 | N6: 0 | O6: 0 | P6: 0 | Q6: 0 | R6: 0 | S6: 0 | T6: 0 | U6: 0 | V6: 0 | W6: 0 | X6: 0 | Y6: 0 | Z6: 0 | AA6: 0 | AB6: 0 | AC6: 0 | AD6: 0 | AE6: 0 | AF6: 0 | AG6: 0 | AH6: 0 | AI6: 0 | AJ6: 0 | AK6: 0 | AL6: 0 | AM6: 0 | AN6: 0 | AO6: 0 | AP6: 0
A7: Electricity Generation by Type[natural gas nonpeaker es,newly built] : MostRecentRun | B7: 0 | C7: 17.4141 | D7: 1.12656 | E7: 2.86884 | F7: 4.14764 | G7: 4.6833 | H7: 3.97446 | I7: 6.34148 | J7: 10.6647 | K7: 8.53378 | L7: 7.23773 | M7: 5.75953 | N7: 5.12479 | O7: 4.38674 | P7: 3.60146 | Q7: 3.82279 | R7: 3.82073 | S7: 3.7107 | T7: 3.92656 | U7: 4.4463 | V7: 5.02305 | W7: 8.05298 | X7: 10.7307 | Y7: 12.4898 | Z7: 16.0614 | AA7: 17.4412 | AB7: 22.5584 | AC7: 25.5107 | AD7: 28.3263 | AE7: 34.9658 | AF7: 44.1691 | AG7: 45.3756 | AH7: 49.0342 | AI7: 56.9237 | AJ7: 66.1486 | AK7: 76.5224 | AL7: 83.201 | AM7: 96.6074 | AN7: 112.179 | AO7: 102.169 | AP7: 103.221
A8: Electricity Generation by Type[nuclear es,preexisting retiring] : MostRecentRun | B8: 0 | C8: 0 | D8: 0 | E8: 0 | F8: 0 | G8: 0 | H8: 0 | I8: 0 | J8: 0 | K8: 0 | L8: 0 | M8: 0 | N8: 0 | O8: 0 | P8: 0 | Q8: 0 | R8: 0 | S8: 0 | T8: 0 | U8: 0 | V8: 0 | W8: 0 | X8: 0 | Y8: 0 | Z8: 0 | AA8: 0 | AB8: 0 | AC8: 0 | AD8: 0 | AE8: 0 | AF8: 0 | AG8: 0 | AH8: 0 | AI8: 0 | AJ8: 0 | AK8: 0 | AL8: 0 | AM8: 0 | AN8: 0 | AO8: 0 | AP8: 0
A9: Electricity Generation by Type[nuclear es,preexisting nonretiring] : MostRecentRun | B9: 0 | C9: 0 | D9: 0 | E9: 0 | F9: 0 | G9: 0 | H9: 0 | I9: 0 | J9: 0 | K9: 0 | L9: 0 | M9: 0 | N9: 0 | O9: 0 | P9: 0 | Q9: 0 | R9: 0 | S9: 0 | T9: 0 | U9: 0 | V9: 0 | W9: 0 | X9: 0 | Y9: 0 | Z9: 0 | AA9: 0 | AB9: 0 | AC9: 0 | AD9: 0 | AE9: 0 | AF9: 0 | AG9: 0 | AH9: 0 | AI9: 0 | AJ9: 0 | AK9: 0 | AL9: 0 | AM9: 0 | AN9: 0 | AO9: 0 | AP9: 0
A10: Electricity Generation by Type[nuclear es,newly built] : MostRecentRun | B10: 0 | C10: 0 | D10: 0 | E10: 0 | F10: 0 | G10: 0 | H10: 0 | I10: 0 | J10: 0 | K10: 0 | L10: 0 | M10: 0 | N10: 0 | O10: 0 | P10: 0 | Q10: 0 | R10: 0 | S10: 0 | T10: 0 | U10: 0 | V10: 0 | W10: 0 | X10: 0 | Y10: 0 | Z10: 0 | AA10: 0 | AB10: 0 | AC10: 0 | AD10: 0 | AE10: 0 | AF10: 0 | AG10: 0 | AH10: 0 | AI10: 0 | AJ10: 0 | AK10: 0 | AL10: 0 | AM10: 0 | AN10: 0 | AO10: 0 | AP10: 0
