Workbook
Name cpi_2019_to_2012: [1]About!$A$97
Name cpi_2020_to_2012: [1]About!$A$99

Sheet Sheet8
A2: 地区 | B2: 合计 | H2: 水电 | N2: 火电 | T2: 核电 | Z2: 风电 | AF2: 太阳能发电 | AL2: 其他 | AR2: 核电 | AX2: 风能
B3: 2021年 | C3: 2020年 | D3: 2019年 | E3: 2018年 | F3: 2017年 | G3: 2016年 | H3: 2021年 | I3: 2020年 | J3: 2019年 | K3: 2018年 | L3: 2017年 | M3: 2016年 | N3: 2021年 | O3: 2020年 | P3: 2019年 | Q3: 2018年 | R3: 2017年 | S3: 2016年 | T3: 2021年 | U3: 2020年 | V3: 2019年 | W3: 2018年 | X3: 2017年 | Y3: 2016年 | Z3: 2021年 | AA3: 2020年 | AB3: 2019年 | AC3: 2018年 | AD3: 2017年 | AE3: 2016年 | AF3: 2021年 | AG3: 2020年 | AH3: 2019年 | AI3: 2018年 | AJ3: 2017年 | AK3: 2016年 | AL3: 2021年 | AM3: 2020年 | AN3: 2019年 | AO3: 2018年 | AP3: 2017年 | AR3: 2021年 | AS3: 2020年 | AT3: 2019年 | AU3: 2018年 | AV3: 2017年 | AX3: 2021年 | AY3: 2020年 | AZ3: 2019年 | BA3: 2018年 | BB3: 2017年
A4: 全国 | B4: 237777 | C4: 220204 | D4: 201006 | E4: 190012 | F4: 178451 | G4: 165051 | H4: 39094 | I4: 37028 | J4: 35804 | K4: 35259 | L4: 34411 | M4: 33207 | N4: 129739 | O4: 124624 | P4: 118957 | Q4: 114408 | R4: 111009 | S4: 106094 | T4: 5326 | U4: 4989 | V4: 4874 | W4: 4466 | X4: 3582 | Y4: 3364 | Z4: 32871 | AA4: 28165 | AB4: 20915 | AC4: 18427 | AD4: 16400 | AE4: 14747 | AF4: 30654 | AG4: 25356 | AH4: 20429 | AI4: 17433 | AJ4: 13042 | AK4: 7631 | AL4: 94 | AM4: 41 | AN4: 37 | AO4: 20 | AP4: 7 | AR4: =IFERROR(T39/AVERAGE(T4:U4)*10000/8760,"") -> 0.90195375 | AS4: =IFERROR(U39/AVERAGE(U4:V4)*10000/8760,"") -> 0.84768636 | AT4: =IFERROR(V39/AVERAGE(V4:W4)*10000/8760,"") -> 0.8523755 | AU4: =IFERROR(W39/AVERAGE(W4:X4)*10000/8760,"") -> 0.83687373 | AV4: =IFERROR(X39/AVERAGE(X4:Y4)*10000/8760,"") -> 0.81548856 | AX4: =IFERROR(Z39/AVERAGE(Z4:AA4)*10000/8760,"") -> 0.24530773 | AY4: =IFERROR(AA39/AVERAGE(AA4:AB4)*10000/8760,"") -> 0.21700662 | AZ4: =IFERROR(AB39/AVERAGE(AB4:AC4)*10000/8760,"") -> 0.23520473 | BA4: =IFERROR(AC39/AVERAGE(AC4:AD4)*10000/8760,"") -> 0.2398024 | BB4: =IFERROR(AD39/AVERAGE(AD4:AE4)*10000/8760,"") -> 0.22327473
A5: 北京 | C5: 1316 | D5: 1304 | E5: 1276 | F5: 1219 | G5: 1103 | I5: 99 | J5: 99 | K5: 98 | L5: 98 | M5: 98 | O5: 1136 | P5: 1135 | Q5: 1119 | R5: 1077 | S5: 971 | AA5: 19 | AB5: 19 | AC5: 19 | AD5: 19 | AE5: 19 | AG5: 62 | AH5: 51 | AI5: 40 | AJ5: 25 | AK5: 15 | AR5: =IFERROR(T40/AVERAGE(T5:U5)*10000/8760,"") | AS5: =IFERROR(U40/AVERAGE(U5:V5)*10000/8760,"") | AT5: =IFERROR(V40/AVERAGE(V5:W5)*10000/8760,"") | AU5: =IFERROR(W40/AVERAGE(W5:X5)*10000/8760,"") | AV5: =IFERROR(X40/AVERAGE(X5:Y5)*10000/8760,"") | AX5: =IFERROR(Z40/AVERAGE(Z5:AA5)*10000/8760,"") -> 0 | AY5: =IFERROR(AA40/AVERAGE(AA5:AB5)*10000/8760,"") -> 0.24032684 | AZ5: =IFERROR(AB40/AVERAGE(AB5:AC5)*10000/8760,"") -> 0.18024513 | BA5: =IFERROR(AC40/AVERAGE(AC5:AD5)*10000/8760,"") -> 0.18024513 | BB5: =IFERROR(AD40/AVERAGE(AD5:AE5)*10000/8760,"") -> 0.18024513
A6: 天津 | C6: 1917 | D6: 1842 | E6: 1709 | F6: 1499 | G6: 1467 | I6: 1 | J6: 1 | K6: 1 | L6: 1 | M6: 1 | O6: 1668 | P6: 1639 | Q6: 1529 | R6: 1402 | S6: 1378 | AA6: 85 | AB6: 60 | AC6: 52 | AD6: 29 | AE6: 29 | AG6: 164 | AH6: 143 | AI6: 128 | AJ6: 68 | AK6: 60 | AR6: =IFERROR(T41/AVERAGE(T6:U6)*10000/8760,"") | AS6: =IFERROR(U41/AVERAGE(U6:V6)*10000/8760,"") | AT6: =IFERROR(V41/AVERAGE(V6:W6)*10000/8760,"") | AU6: =IFERROR(W41/AVERAGE(W6:X6)*10000/8760,"") | AV6: =IFERROR(X41/AVERAGE(X6:Y6)*10000/8760,"") | AX6: =IFERROR(Z41/AVERAGE(Z6:AA6)*10000/8760,"") -> 0 | AY6: =IFERROR(AA41/AVERAGE(AA6:AB6)*10000/8760,"") -> 0.18894662 | AZ6: =IFERROR(AB41/AVERAGE(AB6:AC6)*10000/8760,"") -> 0.22423353 | BA6: =IFERROR(AC41/AVERAGE(AC6:AD6)*10000/8760,"") -> 0.22549185 | BB6: =IFERROR(AD41/AVERAGE(AD6:AE6)*10000/8760,"") -> 0.23618328
A7: 河北 | C7: 10042 | D7: 8319 | E7: 7427 | F7: 6807 | G7: 6275 | I7: 182 | J7: 182 | K7: 182 | L7: 182 | M7: 182 | O7: 5391 | P7: 5021 | Q7: 4617 | R7: 4574 | S7: 4510 | AA7: 2274 | AB7: 1639 | AC7: 1391 | AD7: 1181 | AE7: 1138 | AG7: 2190 | AH7: 1474 | AI7: 1234 | AJ7: 868 | AK7: 443 | AM7: 4 | AN7: 3 | AO7: 3 | AP7: 2 | AR7: =IFERROR(T42/AVERAGE(T7:U7)*10000/8760,"") | AS7: =IFERROR(U42/AVERAGE(U7:V7)*10000/8760,"") | AT7: =IFERROR(V42/AVERAGE(V7:W7)*10000/8760,"") | AU7: =IFERROR(W42/AVERAGE(W7:X7)*10000/8760,"") | AV7: =IFERROR(X42/AVERAGE(X7:Y7)*10000/8760,"") | AX7: =IFERROR(Z42/AVERAGE(Z7:AA7)*10000/8760,"") -> 0 | AY7: =IFERROR(AA42/AVERAGE(AA7:AB7)*10000/8760,"") -> 0.21471573 | AZ7: =IFERROR(AB42/AVERAGE(AB7:AC7)*10000/8760,"") -> 0.239613 | BA7: =IFERROR(AC42/AVERAGE(AC7:AD7)*10000/8760,"") -> 0.25121257 | BB7: =IFERROR(AD42/AVERAGE(AD7:AE7)*10000/8760,"") -> 0.25892912
A8: 山西 | C8: 10383 | D8: 9249 | E8: 8758 | F8: 8073 | G8: 7640 | I8: 223 | J8: 223 | K8: 223 | L8: 244 | M8: 244 | O8: 6878 | P8: 6687 | Q8: 6628 | R8: 6366 | S8: 6329 | AA8: 1974 | AB8: 1251 | AC8: 1043 | AD8: 872 | AE8: 771 | AG8: 1309 | AH8: 1088 | AI8: 864 | AJ8: 590 | AK8: 297 | AR8: =IFERROR(T43/AVERAGE(T8:U8)*10000/8760,"") | AS8: =IFERROR(U43/AVERAGE(U8:V8)*10000/8760,"") | AT8: =IFERROR(V43/AVERAGE(V8:W8)*10000/8760,"") | AU8: =IFERROR(W43/AVERAGE(W8:X8)*10000/8760,"") | AV8: =IFERROR(X43/AVERAGE(X8:Y8)*10000/8760,"") | AX8: =IFERROR(Z43/AVERAGE(Z8:AA8)*10000/8760,"") -> 0 | AY8: =IFERROR(AA43/AVERAGE(AA8:AB8)*10000/8760,"") -> 0.18831192 | AZ8: =IFERROR(AB43/AVERAGE(AB8:AC8)*10000/8760,"") -> 0.22293615 | BA8: =IFERROR(AC43/AVERAGE(AC8:AD8)*10000/8760,"") -> 0.25275105 | BB8: =IFERROR(AD43/AVERAGE(AD8:AE8)*10000/8760,"") -> 0.22928322
A9: 内蒙古 | C9: 14639 | D9: 12931 | E9: 12285 | F9: 11826 | G9: 11045 | I9: 242 | J9: 239 | K9: 242 | L9: 242 | M9: 241 | O9: 9374 | P9: 8721 | Q9: 8229 | R9: 8170 | S9: 7609 | AA9: 3786 | AB9: 2920 | AC9: 2868 | AD9: 2670 | AE9: 2557 | AG9: 1237 | AH9: 1051 | AI9: 946 | AJ9: 743 | AK9: 638 | AR9: =IFERROR(T44/AVERAGE(T9:U9)*10000/8760,"") | AS9: =IFERROR(U44/AVERAGE(U9:V9)*10000/8760,"") | AT9: =IFERROR(V44/AVERAGE(V9:W9)*10000/8760,"") | AU9: =IFERROR(W44/AVERAGE(W9:X9)*10000/8760,"") | AV9: =IFERROR(X44/AVERAGE(X9:Y9)*10000/8760,"") | AX9: =IFERROR(Z44/AVERAGE(Z9:AA9)*10000/8760,"") -> 0 | AY9: =IFERROR(AA44/AVERAGE(AA9:AB9)*10000/8760,"") -> 0.24717182 | AZ9: =IFERROR(AB44/AVERAGE(AB9:AC9)*10000/8760,"") -> 0.26270697 | BA9: =IFERROR(AC44/AVERAGE(AC9:AD9)*10000/8760,"") -> 0.26054936 | BB9: =IFERROR(AD44/AVERAGE(AD9:AE9)*10000/8760,"") -> 0.24067168
A10: 辽宁 | C10: 5776 | D10: 5370 | E10: 5192 | F10: 4869 | G10: 4601 | I10: 305 | J10: 302 | K10: 299 | L10: 295 | M10: 293 | O10: 3643 | P10: 3446 | Q10: 3383 | R10: 3193 | S10: 3114 | U10: 448 | V10: 448 | W10: 448 | X10: 448 | Y10: 448 | AA10: 981 | AB10: 832 | AC10: 761 | AD10: 711 | AE10: 695 | AG10: 400 | AH10: 343 | AI10: 302 | AJ10: 223 | AK10: 52 | AR10: =IFERROR(T45/AVERAGE(T10:U10)*10000/8760,"") -> 0 | AS10: =IFERROR(U45/AVERAGE(U10:V10)*10000/8760,"") -> 0.83323141 | AT10: =IFERROR(V45/AVERAGE(V10:W10)*10000/8760,"") -> 0.83323141 | AU10: =IFERROR(W45/AVERAGE(W10:X10)*10000/8760,"") -> 0.7695287 | AV10: =IFERROR(X45/AVERAGE(X10:Y10)*10000/8760,"") -> 0.60135356 | AX10: =IFERROR(Z45/AVERAGE(Z10:AA10)*10000/8760,"") -> 0 | AY10: =IFERROR(AA45/AVERAGE(AA10:AB10)*10000/8760,"") -> 0.24430357 | AZ10: =IFERROR(AB45/AVERAGE(AB10:AC10)*10000/8760,"") -> 0.2622776 | BA10: =IFERROR(AC45/AVERAGE(AC10:AD10)*10000/8760,"") -> 0.2559187 | BB10: =IFERROR(AD45/AVERAGE(AD10:AE10)*10000/8760,"") -> 0.2435745
A11: 吉林 | C11: 3278 | D11: 3122 | E11: 3055 | F11: 2864 | G11: 2716 | I11: 510 | J11: 445 | K11: 385 | L11: 380 | M11: 378 | O11: 1852 | P11: 1845 | Q11: 1892 | R11: 1820 | S11: 1777 | AA11: 577 | AB11: 557 | AC11: 514 | AD11: 505 | AE11: 505 | AG11: 338 | AH11: 274 | AI11: 265 | AJ11: 159 | AK11: 56 | AR11: =IFERROR(T46/AVERAGE(T11:U11)*10000/8760,"") | AS11: =IFERROR(U46/AVERAGE(U11:V11)*10000/8760,"") | AT11: =IFERROR(V46/AVERAGE(V11:W11)*10000/8760,"") | AU11: =IFERROR(W46/AVERAGE(W11:X11)*10000/8760,"") | AV11: =IFERROR(X46/AVERAGE(X11:Y11)*10000/8760,"") | AX11: =IFERROR(Z46/AVERAGE(Z11:AA11)*10000/8760,"") -> 0 | AY11: =IFERROR(AA46/AVERAGE(AA11:AB11)*10000/8760,"") -> 0.26173162 | AZ11: =IFERROR(AB46/AVERAGE(AB11:AC11)*10000/8760,"") -> 0.24515133 | BA11: =IFERROR(AC46/AVERAGE(AC11:AD11)*10000/8760,"") -> 0.23525616 | BB11: =IFERROR(AD46/AVERAGE(AD11:AE11)*10000/8760,"") -> 0.1966635
A12: 黑龙江 | C12: 3536 | D12: 3246 | E12: 3129 | F12: 2969 | G12: 2783 | I12: 109 | J12: 108 | K12: 104 | L12: 103 | M12: 102 | O12: 2423 | P12: 2253 | Q12: 2212 | R12: 2201 | S12: 2104 | AA12: 686 | AB12: 611 | AC12: 598 | AD12: 570 | AE12: 561 | AG12: 318 | AH12: 274 | AI12: 215 | AJ12: 94 | AK12: 17 | AR12: =IFERROR(T47/AVERAGE(T12:U12)*10000/8760,"") | AS12: =IFERROR(U47/AVERAGE(U12:V12)*10000/8760,"") | AT12: =IFERROR(V47/AVERAGE(V12:W12)*10000/8760,"") | AU12: =IFERROR(W47/AVERAGE(W12:X12)*10000/8760,"") | AV12: =IFERROR(X47/AVERAGE(X12:Y12)*10000/8760,"") | AX12: =IFERROR(Z47/AVERAGE(Z12:AA12)*10000/8760,"") -> 0 | AY12: =IFERROR(AA47/AVERAGE(AA12:AB12)*10000/8760,"") -> 0.24820186 | AZ12: =IFERROR(AB47/AVERAGE(AB12:AC12)*10000/8760,"") -> 0.26437941 | BA12: =IFERROR(AC47/AVERAGE(AC12:AD12)*10000/8760,"") -> 0.24433915 | BB12: =IFERROR(AD47/AVERAGE(AD12:AE12)*10000/8760,"") -> 0.21801533
A13: 上海 | C13: 2669 | D13: 2664 | E13: 2525 | F13: 2400 | G13: 2371 | O13: 2450 | P13: 2475 | Q13: 2365 | R13: 2271 | S13: 2264 | AA13: 82 | AB13: 81 | AC13: 71 | AD13: 71 | AE13: 71 | AG13: 137 | AH13: 109 | AI13: 89 | AJ13: 58 | AK13: 35 | AR13: =IFERROR(T48/AVERAGE(T13:U13)*10000/8760,"") | AS13: =IFERROR(U48/AVERAGE(U13:V13)*10000/8760,"") | AT13: =IFERROR(V48/AVERAGE(V13:W13)*10000/8760,"") | AU13: =IFERROR(W48/AVERAGE(W13:X13)*10000/8760,"") | AV13: =IFERROR(X48/AVERAGE(X13:Y13)*10000/8760,"") | AX13: =IFERROR(Z48/AVERAGE(Z13:AA13)*10000/8760,"") -> 0 | AY13: =IFERROR(AA48/AVERAGE(AA13:AB13)*10000/8760,"") -> 0.26612881 | AZ13: =IFERROR(AB48/AVERAGE(AB13:AC13)*10000/8760,"") -> 0.25534727 | BA13: =IFERROR(AC48/AVERAGE(AC13:AD13)*10000/8760,"") -> 0.28940768 | BB13: =IFERROR(AD48/AVERAGE(AD13:AE13)*10000/8760,"") -> 0.27332947
A14: 江苏 | C14: 14146 | D14: 13288 | E14: 12657 | F14: 11469 | G14: 10160 | I14: 265 | J14: 265 | K14: 265 | L14: 265 | M14: 115 | O14: 10079 | P14: 10050 | Q14: 9749 | R14: 9430 | S14: 8727 | U14: 549 | V14: 437 | W14: 437 | X14: 212 | Y14: 212 | AA14: 1547 | AB14: 1041 | AC14: 865 | AD14: 656 | AE14: 561 | AG14: 1684 | AH14: 1486 | AI14: 1332 | AJ14: 907 | AK14: 546 | AM14: 23 | AN14: 10 | AO14: 10 | AR14: =IFERROR(T49/AVERAGE(T14:U14)*10000/8760,"") -> 0 | AS14: =IFERROR(U49/AVERAGE(U14:V14)*10000/8760,"") -> 0.82201043 | AT14: =IFERROR(V49/AVERAGE(V14:W14)*10000/8760,"") -> 0.85942969 | AU14: =IFERROR(W49/AVERAGE(W14:X14)*10000/8760,"") -> 0.8513273 | AV14: =IFERROR(X49/AVERAGE(X14:Y14)*10000/8760,"") -> 0.93154993 | AX14: =IFERROR(Z49/AVERAGE(Z14:AA14)*10000/8760,"") -> 0 | AY14: =IFERROR(AA49/AVERAGE(AA14:AB14)*10000/8760,"") -> 0.20202127 | AZ14: =IFERROR(AB49/AVERAGE(AB14:AC14)*10000/8760,"") -> 0.22040468 | BA14: =IFERROR(AC49/AVERAGE(AC14:AD14)*10000/8760,"") -> 0.25968256 | BB14: =IFERROR(AD49/AVERAGE(AD14:AE14)*10000/8760,"") -> 0.22512128
A15: 浙江 | C15: 10142 | D15: 9789 | E15: 9565 | F15: 8899 | G15: 8331 | I15: 1171 | J15: 1170 | K15: 1161 | L15: 1160 | M15: 1154 | O15: 6358 | P15: 6212 | Q15: 6209 | R15: 6134 | S15: 6062 | U15: 911 | V15: 908 | W15: 908 | X15: 657 | Y15: 657 | AA15: 186 | AB15: 160 | AC15: 148 | AD15: 133 | AE15: 119 | AG15: 1517 | AH15: 1339 | AI15: 1138 | AJ15: 814 | AK15: 338 | AM15: 1 | AN15: 1 | AO15: 0.4 | AP15: 0.4 | AR15: =IFERROR(T50/AVERAGE(T15:U15)*10000/8760,"") -> 0 | AS15: =IFERROR(U50/AVERAGE(U15:V15)*10000/8760,"") -> 0.89366178 | AT15: =IFERROR(V50/AVERAGE(V15:W15)*10000/8760,"") -> 0.79078913 | AU15: =IFERROR(W50/AVERAGE(W15:X15)*10000/8760,"") -> 0.85634674 | AV15: =IFERROR(X50/AVERAGE(X15:Y15)*10000/8760,"") -> 0.88787418 | AX15: =IFERROR(Z50/AVERAGE(Z15:AA15)*10000/8760,"") -> 0 | AY15: =IFERROR(AA50/AVERAGE(AA15:AB15)*10000/8760,"") -> 0.2375485 | AZ15: =IFERROR(AB50/AVERAGE(AB15:AC15)*10000/8760,"") -> 0.2446184 | BA15: =IFERROR(AC50/AVERAGE(AC15:AD15)*10000/8760,"") -> 0.2518728 | BB15: =IFERROR(AD50/AVERAGE(AD15:AE15)*10000/8760,"") -> 0.22649851
A16: 安徽 | C16: 7816 | D16: 7394 | E16: 7089 | F16: 6468 | G16: 5733 | I16: 474 | J16: 345 | K16: 312 | L16: 310 | M16: 295 | O16: 5561 | P16: 5521 | Q16: 5413 | R16: 5053 | S16: 4915 | AA16: 412 | AB16: 274 | AC16: 246 | AD16: 217 | AE16: 177 | AG16: 1370 | AH16: 1254 | AI16: 1118 | AJ16: 888 | AK16: 345 | AR16: =IFERROR(T51/AVERAGE(T16:U16)*10000/8760,"") | AS16: =IFERROR(U51/AVERAGE(U16:V16)*10000/8760,"") | AT16: =IFERROR(V51/AVERAGE(V16:W16)*10000/8760,"") | AU16: =IFERROR(W51/AVERAGE(W16:X16)*10000/8760,"") | AV16: =IFERROR(X51/AVERAGE(X16:Y16)*10000/8760,"") | AX16: =IFERROR(Z51/AVERAGE(Z16:AA16)*10000/8760,"") -> 0 | AY16: =IFERROR(AA51/AVERAGE(AA16:AB16)*10000/8760,"") -> 0.18970406 | AZ16: =IFERROR(AB51/AVERAGE(AB16:AC16)*10000/8760,"") -> 0.20635757 | BA16: =IFERROR(AC51/AVERAGE(AC16:AD16)*10000/8760,"") -> 0.24655562 | BB16: =IFERROR(AD51/AVERAGE(AD16:AE16)*10000/8760,"") -> 0.23758199
A17: 福建 | C17: 6372 | D17: 5909 | E17: 5770 | F17: 5597 | G17: 5210 | I17: 1331 | J17: 1321 | K17: 1322 | L17: 1307 | M17: 1304 | O17: 3478 | P17: 3172 | Q17: 3128 | R17: 3074 | S17: 2902 | U17: 871 | V17: 871 | W17: 871 | X17: 871 | Y17: 762 | AA17: 486 | AB17: 376 | AC17: 300 | AD17: 252 | AE17: 214 | AG17: 202 | AH17: 169 | AI17: 148 | AJ17: 92 | AK17: 27 | AM17: 3 | AR17: =IFERROR(T52/AVERAGE(T17:U17)*10000/8760,"") -> 0 | AS17: =IFERROR(U52/AVERAGE(U17:V17)*10000/8760,"") -> 0.8545261 | AT17: =IFERROR(V52/AVERAGE(V17:W17)*10000/8760,"") -> 0.8138968 | AU17: =IFERROR(W52/AVERAGE(W17:X17)*10000/8760,"") -> 0.84666237 | AV17: =IFERROR(X52/AVERAGE(X17:Y17)*10000/8760,"") -> 0.78293865 | AX17: =IFERROR(Z52/AVERAGE(Z17:AA17)*10000/8760,"") -> 0 | AY17: =IFERROR(AA52/AVERAGE(AA17:AB17)*10000/8760,"") -> 0.32313087 | AZ17: =IFERROR(AB52/AVERAGE(AB17:AC17)*10000/8760,"") -> 0.29383156 | BA17: =IFERROR(AC52/AVERAGE(AC17:AD17)*10000/8760,"") -> 0.29779631 | BB17: =IFERROR(AD52/AVERAGE(AD17:AE17)*10000/8760,"") -> 0.31845886
A18: 江西 | C18: 4401 | D18: 3782 | E18: 3554 | F18: 3167 | G18: 2866 | I18: 660 | J18: 661 | K18: 627 | L18: 615 | M18: 613 | O18: 2455 | P18: 2205 | Q18: 2165 | R18: 1934 | S18: 1918 | AA18: 510 | AB18: 286 | AC18: 225 | AD18: 169 | AE18: 108 | AG18: 776 | AH18: 630 | AI18: 536 | AJ18: 449 | AK18: 228 | AR18: =IFERROR(T53/AVERAGE(T18:U18)*10000/8760,"") | AS18: =IFERROR(U53/AVERAGE(U18:V18)*10000/8760,"") | AT18: =IFERROR(V53/AVERAGE(V18:W18)*10000/8760,"") | AU18: =IFERROR(W53/AVERAGE(W18:X18)*10000/8760,"") | AV18: =IFERROR(X53/AVERAGE(X18:Y18)*10000/8760,"") | AX18: =IFERROR(Z53/AVERAGE(Z18:AA18)*10000/8760,"") -> 0 | AY18: =IFERROR(AA53/AVERAGE(AA18:AB18)*10000/8760,"") -> 0.20364379 | AZ18: =IFERROR(AB53/AVERAGE(AB18:AC18)*10000/8760,"") -> 0.22786371 | BA18: =IFERROR(AC53/AVERAGE(AC18:AD18)*10000/8760,"") -> 0.23758199 | BB18: =IFERROR(AD53/AVERAGE(AD18:AE18)*10000/8760,"") -> 0.25550995
A19: 山东 | C19: 15560 | D19: 14044 | E19: 13107 | F19: 12556 | G19: 10942 | I19: 108 | J19: 108 | K19: 108 | L19: 108 | M19: 108 | O19: 11135 | P19: 10713 | Q19: 10367 | R19: 10335 | S19: 9540 | U19: 250 | V19: 250 | W19: 125 | X19: 0 | AA19: 1795 | AB19: 1354 | AC19: 1146 | AD19: 1061 | AE19: 839 | AG19: 2272 | AH19: 1619 | AI19: 1361 | AJ19: 1052 | AK19: 455 | AR19: =IFERROR(T54/AVERAGE(T19:U19)*10000/8760,"") -> 0 | AS19: =IFERROR(U54/AVERAGE(U19:V19)*10000/8760,"") -> 0.87214612 | AT19: =IFERROR(V54/AVERAGE(V19:W19)*10000/8760,"") -> 1.260274 | AU19: =IFERROR(W54/AVERAGE(W19:X19)*10000/8760,"") -> 0.71232877 | AV19: =IFERROR(X54/AVERAGE(X19:Y19)*10000/8760,"") | AX19: =IFERROR(Z54/AVERAGE(Z19:AA19)*10000/8760,"") -> 0 | AY19: =IFERROR(AA54/AVERAGE(AA19:AB19)*10000/8760,"") -> 0.18778158 | AZ19: =IFERROR(AB54/AVERAGE(AB19:AC19)*10000/8760,"") -> 0.20547945 | BA19: =IFERROR(AC54/AVERAGE(AC19:AD19)*10000/8760,"") -> 0.22137946 | BB19: =IFERROR(AD54/AVERAGE(AD19:AE19)*10000/8760,"") -> 0.19947128
A20: 河南 | C20: 10169 | D20: 9306 | E20: 8680 | F20: 7880 | G20: 7218 | I20: 408 | J20: 408 | K20: 401 | L20: 399 | M20: 399 | O20: 7068 | P20: 7050 | Q20: 6821 | R20: 6544 | S20: 6431 | AA20: 1518 | AB20: 794 | AC20: 468 | AD20: 233 | AE20: 104 | AG20: 1175 | AH20: 1054 | AI20: 991 | AJ20: 703 | AK20: 284 | AR20: =IFERROR(T55/AVERAGE(T20:U20)*10000/8760,"") | AS20: =IFERROR(U55/AVERAGE(U20:V20)*10000/8760,"") | AT20: =IFERROR(V55/AVERAGE(V20:W20)*10000/8760,"") | AU20: =IFERROR(W55/AVERAGE(W20:X20)*10000/8760,"") | AV20: =IFERROR(X55/AVERAGE(X20:Y20)*10000/8760,"") | AX20: =IFERROR(Z55/AVERAGE(Z20:AA20)*10000/8760,"") -> 0 | AY20: =IFERROR(AA55/AVERAGE(AA20:AB20)*10000/8760,"") -> 0.1372628 | AZ20: =IFERROR(AB55/AVERAGE(AB20:AC20)*10000/8760,"") -> 0.15920225 | BA20: =IFERROR(AC55/AVERAGE(AC20:AD20)*10000/8760,"") -> 0.18564477 | BB20: =IFERROR(AD55/AVERAGE(AD20:AE20)*10000/8760,"") -> 0.20324377
A21: 湖北 | C21: 8273 | D21: 7862 | E21: 7401 | F21: 7124 | G21: 6745 | I21: 3757 | J21: 3679 | K21: 3675 | L21: 3671 | M21: 3663 | O21: 3316 | P21: 3157 | Q21: 2884 | R21: 2787 | S21: 2694 | AA21: 502 | AB21: 405 | AC21: 331 | AD21: 253 | AE21: 201 | AG21: 698 | AH21: 621 | AI21: 510 | AJ21: 413 | AK21: 187 | AR21: =IFERROR(T56/AVERAGE(T21:U21)*10000/8760,"") | AS21: =IFERROR(U56/AVERAGE(U21:V21)*10000/8760,"") | AT21: =IFERROR(V56/AVERAGE(V21:W21)*10000/8760,"") | AU21: =IFERROR(W56/AVERAGE(W21:X21)*10000/8760,"") | AV21: =IFERROR(X56/AVERAGE(X21:Y21)*10000/8760,"") | AX21: =IFERROR(Z56/AVERAGE(Z21:AA21)*10000/8760,"") -> 0 | AY21: =IFERROR(AA56/AVERAGE(AA21:AB21)*10000/8760,"") -> 0.20641082 | AZ21: =IFERROR(AB56/AVERAGE(AB21:AC21)*10000/8760,"") -> 0.22955132 | BA21: =IFERROR(AC56/AVERAGE(AC21:AD21)*10000/8760,"") -> 0.25020329 | BB21: =IFERROR(AD56/AVERAGE(AD21:AE21)*10000/8760,"") -> 0.24138555
A22: 湖南 | C22: 4915 | D22: 4669 | E22: 4522 | F22: 4277 | G22: 4121 | I22: 1581 | J22: 1612 | K22: 1598 | L22: 1570 | M22: 1553 | O22: 2269 | P22: 2280 | Q22: 2284 | R22: 2267 | S22: 2322 | AA22: 669 | AB22: 427 | AC22: 348 | AD22: 263 | AE22: 217 | AG22: 391 | AH22: 344 | AI22: 292 | AJ22: 176 | AK22: 30 | AM22: 6 | AN22: 6 | AR22: =IFERROR(T57/AVERAGE(T22:U22)*10000/8760,"") | AS22: =IFERROR(U57/AVERAGE(U22:V22)*10000/8760,"") | AT22: =IFERROR(V57/AVERAGE(V22:W22)*10000/8760,"") | AU22: =IFERROR(W57/AVERAGE(W22:X22)*10000/8760,"") | AV22: =IFERROR(X57/AVERAGE(X22:Y22)*10000/8760,"") | AX22: =IFERROR(Z57/AVERAGE(Z22:AA22)*10000/8760,"") -> 0 | AY22: =IFERROR(AA57/AVERAGE(AA22:AB22)*10000/8760,"") -> 0.20622938 | AZ22: =IFERROR(AB57/AVERAGE(AB22:AC22)*10000/8760,"") -> 0.22094565 | BA22: =IFERROR(AC57/AVERAGE(AC22:AD22)*10000/8760,"") -> 0.22420017 | BB22: =IFERROR(AD57/AVERAGE(AD22:AE22)*10000/8760,"") -> 0.23782344
A23: 广东 | C23: 14224 | D23: 12870 | E23: 11929 | F23: 10968 | G23: 10457 | I23: 1666 | J23: 1576 | K23: 1576 | L23: 1486 | M23: 1411 | O23: 9582 | P23: 8628 | Q23: 8137 | R23: 7768 | S23: 7721 | U23: 1614 | V23: 1614 | W23: 1330 | X23: 1046 | Y23: 938 | AA23: 565 | AB23: 441 | AC23: 357 | AD23: 335 | AE23: 268 | AG23: 797 | AH23: 610 | AI23: 527 | AJ23: 332 | AK23: 117 | AN23: 2 | AO23: 2 | AP23: 2 | AR23: =IFERROR(T58/AVERAGE(T23:U23)*10000/8760,"") -> 0 | AS23: =IFERROR(U58/AVERAGE(U23:V23)*10000/8760,"") -> 0.82115394 | AT23: =IFERROR(V58/AVERAGE(V23:W23)*10000/8760,"") -> 0.85771541 | AU23: =IFERROR(W58/AVERAGE(W23:X23)*10000/8760,"") -> 0.8609689 | AV23: =IFERROR(X58/AVERAGE(X23:Y23)*10000/8760,"") -> 0.92060686 | AX23: =IFERROR(Z58/AVERAGE(Z23:AA23)*10000/8760,"") -> 0 | AY23: =IFERROR(AA58/AVERAGE(AA23:AB23)*10000/8760,"") -> 0.23375727 | AZ23: =IFERROR(AB58/AVERAGE(AB23:AC23)*10000/8760,"") -> 0.21171651 | BA23: =IFERROR(AC58/AVERAGE(AC23:AD23)*10000/8760,"") -> 0.20785494 | BB23: =IFERROR(AD58/AVERAGE(AD23:AE23)*10000/8760,"") -> 0.23474712
A24: 广西 | C24: 5178 | D24: 4615 | E24: 4513 | F24: 4332 | G24: 4152 | I24: 1759 | J24: 1681 | K24: 1677 | L24: 1669 | M24: 1665 | O24: 2344 | P24: 2294 | Q24: 2288 | R24: 2217 | S24: 2185 | U24: 217 | V24: 217 | W24: 217 | X24: 217 | Y24: 217 | AA24: 653 | AB24: 287 | AC24: 208 | AD24: 150 | AE24: 70 | AG24: 205 | AH24: 135 | AI24: 124 | AJ24: 78 | AK24: 16 | AR24: =IFERROR(T59/AVERAGE(T24:U24)*10000/8760,"") -> 0 | AS24: =IFERROR(U59/AVERAGE(U24:V24)*10000/8760,"") -> 0.88378259 | AT24: =IFERROR(V59/AVERAGE(V24:W24)*10000/8760,"") -> 0.90482503 | AU24: =IFERROR(W59/AVERAGE(W24:X24)*10000/8760,"") -> 0.84695831 | AV24: =IFERROR(X59/AVERAGE(X24:Y24)*10000/8760,"") -> 0.66809755 | AX24: =IFERROR(Z59/AVERAGE(Z24:AA24)*10000/8760,"") -> 0 | AY24: =IFERROR(AA59/AVERAGE(AA24:AB24)*10000/8760,"") -> 0.25745652 | AZ24: =IFERROR(AB59/AVERAGE(AB24:AC24)*10000/8760,"") -> 0.28135234 | BA24: =IFERROR(AC59/AVERAGE(AC24:AD24)*10000/8760,"") -> 0.26785031 | BB24: =IFERROR(AD59/AVERAGE(AD24:AE24)*10000/8760,"") -> 0.25944375
A25: 海南 | C25: 999 | D25: 918 | E25: 919 | F25: 786 | G25: 745 | I25: 151 | J25: 154 | K25: 154 | L25: 114 | M25: 91 | O25: 546 | P25: 465 | Q25: 465 | R25: 465 | S25: 464 | U25: 130 | V25: 130 | W25: 130 | X25: 130 | Y25: 130 | AA25: 29 | AB25: 29 | AC25: 34 | AD25: 34 | AE25: 31 | AG25: 143 | AH25: 140 | AI25: 136 | AJ25: 43 | AK25: 29 | AN25: 11 | AR25: =IFERROR(T60/AVERAGE(T25:U25)*10000/8760,"") -> 0 | AS25: =IFERROR(U60/AVERAGE(U25:V25)*10000/8760,"") -> 0.84299262 | AT25: =IFERROR(V60/AVERAGE(V25:W25)*10000/8760,"") -> 0.8517738 | AU25: =IFERROR(W60/AVERAGE(W25:X25)*10000/8760,"") -> 0.67615033 | AV25: =IFERROR(X60/AVERAGE(X25:Y25)*10000/8760,"") -> 0.65858799 | AX25: =IFERROR(Z60/AVERAGE(Z25:AA25)*10000/8760,"") -> 0 | AY25: =IFERROR(AA60/AVERAGE(AA25:AB25)*10000/8760,"") -> 0.23618328 | AZ25: =IFERROR(AB60/AVERAGE(AB25:AC25)*10000/8760,"") -> 0.18119881 | BA25: =IFERROR(AC60/AVERAGE(AC25:AD25)*10000/8760,"") -> 0.16787537 | BB25: =IFERROR(AD60/AVERAGE(AD25:AE25)*10000/8760,"") -> 0.21074816
A26: 重庆 | C26: 2488 | D26: 2448 | E26: 2386 | F26: 2326 | G26: 2178 | I26: 779 | J26: 772 | K26: 756 | L26: 736 | M26: 688 | O26: 1545 | P26: 1548 | Q26: 1537 | R26: 1544 | S26: 1462 | AA26: 97 | AB26: 64 | AC26: 50 | AD26: 33 | AE26: 28 | AG26: 67 | AH26: 65 | AI26: 43 | AJ26: 12 | AK26: 0. 46 | AR26: =IFERROR(T61/AVERAGE(T26:U26)*10000/8760,"") | AS26: =IFERROR(U61/AVERAGE(U26:V26)*10000/8760,"") | AT26: =IFERROR(V61/AVERAGE(V26:W26)*10000/8760,"") | AU26: =IFERROR(W61/AVERAGE(W26:X26)*10000/8760,"") | AV26: =IFERROR(X61/AVERAGE(X26:Y26)*10000/8760,"") | AX26: =IFERROR(Z61/AVERAGE(Z26:AA26)*10000/8760,"") -> 0 | AY26: =IFERROR(AA61/AVERAGE(AA26:AB26)*10000/8760,"") -> 0.19853087 | AZ26: =IFERROR(AB61/AVERAGE(AB26:AC26)*10000/8760,"") -> 0.22029961 | BA26: =IFERROR(AC61/AVERAGE(AC26:AD26)*10000/8760,"") -> 0.22005832 | BB26: =IFERROR(AD61/AVERAGE(AD26:AE26)*10000/8760,"") -> 0.26199566
A27: 四川 | C27: 10105 | D27: 9929 | E27: 9833 | F27: 9721 | G27: 9108 | I27: 7892 | J27: 7846 | K27: 7824 | L27: 7714 | M27: 7246 | O27: 1596 | P27: 1570 | Q27: 1575 | R27: 1662 | S27: 1642 | AA27: 426 | AB27: 325 | AC27: 253 | AD27: 210 | AE27: 125 | AG27: 191 | AH27: 188 | AI27: 181 | AJ27: 135 | AK27: 96 | AR27: =IFERROR(T62/AVERAGE(T27:U27)*10000/8760,"") | AS27: =IFERROR(U62/AVERAGE(U27:V27)*10000/8760,"") | AT27: =IFERROR(V62/AVERAGE(V27:W27)*10000/8760,"") | AU27: =IFERROR(W62/AVERAGE(W27:X27)*10000/8760,"") | AV27: =IFERROR(X62/AVERAGE(X27:Y27)*10000/8760,"") | AX27: =IFERROR(Z62/AVERAGE(Z27:AA27)*10000/8760,"") -> 0 | AY27: =IFERROR(AA62/AVERAGE(AA27:AB27)*10000/8760,"") -> 0.26144745 | AZ27: =IFERROR(AB62/AVERAGE(AB27:AC27)*10000/8760,"") -> 0.28045062 | BA27: =IFERROR(AC62/AVERAGE(AC27:AD27)*10000/8760,"") -> 0.27121118 | BB27: =IFERROR(AD62/AVERAGE(AD27:AE27)*10000/8760,"") -> 0.23853336
A28: 贵州 | C28: 7478 | D28: 6599 | E28: 6039 | F28: 5778 | G28: 5510 | I28: 2281 | J28: 2223 | K28: 2212 | L28: 2119 | M28: 2089 | O28: 3560 | P28: 3410 | Q28: 3263 | R28: 3160 | S28: 3014 | AA28: 580 | AB28: 457 | AC28: 386 | AD28: 363 | AE28: 362 | AG28: 1057 | AH28: 510 | AI28: 178 | AJ28: 135 | AK28: 46 | AR28: =IFERROR(T63/AVERAGE(T28:U28)*10000/8760,"") | AS28: =IFERROR(U63/AVERAGE(U28:V28)*10000/8760,"") | AT28: =IFERROR(V63/AVERAGE(V28:W28)*10000/8760,"") | AU28: =IFERROR(W63/AVERAGE(W28:X28)*10000/8760,"") | AV28: =IFERROR(X63/AVERAGE(X28:Y28)*10000/8760,"") | AX28: =IFERROR(Z63/AVERAGE(Z28:AA28)*10000/8760,"") -> 0 | AY28: =IFERROR(AA63/AVERAGE(AA28:AB28)*10000/8760,"") -> 0.21355949 | AZ28: =IFERROR(AB63/AVERAGE(AB28:AC28)*10000/8760,"") -> 0.21124815 | BA28: =IFERROR(AC63/AVERAGE(AC28:AD28)*10000/8760,"") -> 0.20727789 | BB28: =IFERROR(AD63/AVERAGE(AD28:AE28)*10000/8760,"") -> 0.19839395
A29: 云南 | C29: 10266 | D29: 9620 | E29: 9341 | F29: 8957 | G29: 8645 | I29: 7480 | J29: 6873 | K29: 6649 | L29: 6281 | M29: 6088 | O29: 1517 | P29: 1509 | Q29: 1508 | R29: 1613 | S29: 1612 | AA29: 881 | AB29: 863 | AC29: 857 | AD29: 825 | AE29: 737 | AG29: 388 | AH29: 375 | AI29: 326 | AJ29: 238 | AK29: 208 | AM29: 0.2 | AR29: =IFERROR(T64/AVERAGE(T29:U29)*10000/8760,"") | AS29: =IFERROR(U64/AVERAGE(U29:V29)*10000/8760,"") | AT29: =IFERROR(V64/AVERAGE(V29:W29)*10000/8760,"") | AU29: =IFERROR(W64/AVERAGE(W29:X29)*10000/8760,"") | AV29: =IFERROR(X64/AVERAGE(X29:Y29)*10000/8760,"") | AX29: =IFERROR(Z64/AVERAGE(Z29:AA29)*10000/8760,"") -> 0 | AY29: =IFERROR(AA64/AVERAGE(AA29:AB29)*10000/8760,"") -> 0.32727996 | AZ29: =IFERROR(AB64/AVERAGE(AB29:AC29)*10000/8760,"") -> 0.32122757 | BA29: =IFERROR(AC64/AVERAGE(AC29:AD29)*10000/8760,"") -> 0.29862254 | BB29: =IFERROR(AD64/AVERAGE(AD29:AE29)*10000/8760,"") -> 0.27479113
A30: 西藏 | C30: 395 | D30: 327 | E30: 304 | F30: 281 | G30: 233 | I30: 210 | J30: 170 | K30: 160 | L30: 158 | M30: 156 | O30: 43 | P30: 42 | Q30: 42 | R30: 40 | S30: 41 | AA30: 1 | AB30: 1 | AC30: 1 | AD30: 1 | AE30: 1 | AG30: 137 | AH30: 110 | AI30: 98 | AJ30: 79 | AK30: 33 | AM30: 4 | AN30: 4 | AO30: 4 | AP30: 3 | AR30: =IFERROR(T65/AVERAGE(T30:U30)*10000/8760,"") | AS30: =IFERROR(U65/AVERAGE(U30:V30)*10000/8760,"") | AT30: =IFERROR(V65/AVERAGE(V30:W30)*10000/8760,"") | AU30: =IFERROR(W65/AVERAGE(W30:X30)*10000/8760,"") | AV30: =IFERROR(X65/AVERAGE(X30:Y30)*10000/8760,"") | AX30: =IFERROR(Z65/AVERAGE(Z30:AA30)*10000/8760,"") -> 0 | AY30: =IFERROR(AA65/AVERAGE(AA30:AB30)*10000/8760,"") -> 0.15981735 | AZ30: =IFERROR(AB65/AVERAGE(AB30:AC30)*10000/8760,"") -> 0.1826484 | BA30: =IFERROR(AC65/AVERAGE(AC30:AD30)*10000/8760,"") -> 0.15981735 | BB30: =IFERROR(AD65/AVERAGE(AD30:AE30)*10000/8760,"") -> 0.11415525
A31: 陕西 | C31: 7366 | D31: 6242 | E31: 5443 | F31: 4935 | G31: 3740 | I31: 392 | J31: 391 | K31: 385 | L31: 379 | M31: 272 | O31: 4993 | P31: 4380 | Q31: 3937 | R31: 3658 | S31: 3043 | AA31: 892 | AB31: 532 | AC31: 405 | AD31: 364 | AE31: 179 | AG31: 1089 | AH31: 939 | AI31: 716 | AJ31: 535 | AK31: 246 | AR31: =IFERROR(T66/AVERAGE(T31:U31)*10000/8760,"") | AS31: =IFERROR(U66/AVERAGE(U31:V31)*10000/8760,"") | AT31: =IFERROR(V66/AVERAGE(V31:W31)*10000/8760,"") | AU31: =IFERROR(W66/AVERAGE(W31:X31)*10000/8760,"") | AV31: =IFERROR(X66/AVERAGE(X31:Y31)*10000/8760,"") | AX31: =IFERROR(Z66/AVERAGE(Z31:AA31)*10000/8760,"") -> 0 | AY31: =IFERROR(AA66/AVERAGE(AA31:AB31)*10000/8760,"") -> 0.15231389 | AZ31: =IFERROR(AB66/AVERAGE(AB31:AC31)*10000/8760,"") -> 0.20223876 | BA31: =IFERROR(AC66/AVERAGE(AC31:AD31)*10000/8760,"") -> 0.21376276 | BB31: =IFERROR(AD66/AVERAGE(AD31:AE31)*10000/8760,"") -> 0.22704912
A32: 甘肃 | C32: 5620 | D32: 5268 | E32: 5113 | F32: 4995 | G32: 4825 | I32: 957 | J32: 943 | K32: 927 | L32: 868 | M32: 861 | O32: 2308 | P32: 2104 | Q32: 2064 | R32: 2059 | S32: 2002 | AA32: 1373 | AB32: 1297 | AC32: 1282 | AD32: 1282 | AE32: 1277 | AG32: 982 | AH32: 924 | AI32: 839 | AJ32: 786 | AK32: 686 | AR32: =IFERROR(T67/AVERAGE(T32:U32)*10000/8760,"") | AS32: =IFERROR(U67/AVERAGE(U32:V32)*10000/8760,"") | AT32: =IFERROR(V67/AVERAGE(V32:W32)*10000/8760,"") | AU32: =IFERROR(W67/AVERAGE(W32:X32)*10000/8760,"") | AV32: =IFERROR(X67/AVERAGE(X32:Y32)*10000/8760,"") | AX32: =IFERROR(Z67/AVERAGE(Z32:AA32)*10000/8760,"") -> 0 | AY32: =IFERROR(AA67/AVERAGE(AA32:AB32)*10000/8760,"") -> 0.2103535 | AZ32: =IFERROR(AB67/AVERAGE(AB32:AC32)*10000/8760,"") -> 0.201841 | BA32: =IFERROR(AC67/AVERAGE(AC32:AD32)*10000/8760,"") -> 0.20480271 | BB32: =IFERROR(AD67/AVERAGE(AD32:AE32)*10000/8760,"") -> 0.16773105
A33: 青海 | C33: 4030 | D33: 3168 | E33: 2800 | F33: 2543 | G33: 2345 | I33: 1193 | J33: 1192 | K33: 1192 | L33: 1191 | M33: 1192 | O33: 393 | P33: 393 | Q33: 379 | R33: 399 | S33: 402 | AA33: 843 | AB33: 462 | AC33: 267 | AD33: 162 | AE33: 69 | AG33: 1601 | AH33: 1122 | AI33: 962 | AJ33: 791 | AK33: 682 | AR33: =IFERROR(T68/AVERAGE(T33:U33)*10000/8760,"") | AS33: =IFERROR(U68/AVERAGE(U33:V33)*10000/8760,"") | AT33: =IFERROR(V68/AVERAGE(V33:W33)*10000/8760,"") | AU33: =IFERROR(W68/AVERAGE(W33:X33)*10000/8760,"") | AV33: =IFERROR(X68/AVERAGE(X33:Y33)*10000/8760,"") | AX33: =IFERROR(Z68/AVERAGE(Z33:AA33)*10000/8760,"") -> 0 | AY33: =IFERROR(AA68/AVERAGE(AA33:AB33)*10000/8760,"") -> 0.14345947 | AZ33: =IFERROR(AB68/AVERAGE(AB33:AC33)*10000/8760,"") -> 0.20670087 | BA33: =IFERROR(AC68/AVERAGE(AC33:AD33)*10000/8760,"") -> 0.20223308 | BB33: =IFERROR(AD68/AVERAGE(AD33:AE33)*10000/8760,"") -> 0.17790429
A34: 宁夏 | C34: 5943 | D34: 5296 | E34: 4715 | F34: 4188 | G34: 3675 | I34: 43 | J34: 43 | K34: 43 | L34: 43 | M34: 43 | O34: 3326 | P34: 3219 | Q34: 2845 | R34: 2583 | S34: 2165 | AA34: 1377 | AB34: 1116 | AC34: 1011 | AD34: 942 | AE34: 942 | AG34: 1197 | AH34: 918 | AI34: 816 | AJ34: 620 | AK34: 526 | AR34: =IFERROR(T69/AVERAGE(T34:U34)*10000/8760,"") | AS34: =IFERROR(U69/AVERAGE(U34:V34)*10000/8760,"") | AT34: =IFERROR(V69/AVERAGE(V34:W34)*10000/8760,"") | AU34: =IFERROR(W69/AVERAGE(W34:X34)*10000/8760,"") | AV34: =IFERROR(X69/AVERAGE(X34:Y34)*10000/8760,"") | AX34: =IFERROR(Z69/AVERAGE(Z34:AA34)*10000/8760,"") -> 0 | AY34: =IFERROR(AA69/AVERAGE(AA34:AB34)*10000/8760,"") -> 0.17766642 | AZ34: =IFERROR(AB69/AVERAGE(AB34:AC34)*10000/8760,"") -> 0.19965093 | BA34: =IFERROR(AC69/AVERAGE(AC34:AD34)*10000/8760,"") -> 0.2186076 | BB34: =IFERROR(AD69/AVERAGE(AD34:AE34)*10000/8760,"") -> 0.18783507
A35: 新疆 | C35: 10763 | D35: 9614 | E35: 8978 | F35: 8679 | G35: 8109 | I35: 800 | J35: 773 | K35: 702 | L35: 702 | M35: 665 | O35: 6337 | P35: 5813 | Q35: 5377 | R35: 5207 | S35: 4775 | AA35: 2361 | AB35: 1956 | AC35: 1921 | AD35: 1836 | AE35: 1776 | AG35: 1266 | AH35: 1072 | AI35: 978 | AJ35: 934 | AK35: 893 | AR35: =IFERROR(T70/AVERAGE(T35:U35)*10000/8760,"") | AS35: =IFERROR(U70/AVERAGE(U35:V35)*10000/8760,"") | AT35: =IFERROR(V70/AVERAGE(V35:W35)*10000/8760,"") | AU35: =IFERROR(W70/AVERAGE(W35:X35)*10000/8760,"") | AV35: =IFERROR(X70/AVERAGE(X35:Y35)*10000/8760,"") | AX35: =IFERROR(Z70/AVERAGE(Z35:AA35)*10000/8760,"") -> 0 | AY35: =IFERROR(AA70/AVERAGE(AA35:AB35)*10000/8760,"") -> 0.22952689 | AZ35: =IFERROR(AB70/AVERAGE(AB35:AC35)*10000/8760,"") -> 0.23967597 | BA35: =IFERROR(AC70/AVERAGE(AC35:AD35)*10000/8760,"") -> 0.21755432 | BB35: =IFERROR(AD70/AVERAGE(AD35:AE35)*10000/8760,"") -> 0.20100426
A37: 地区 | B37: 合计 | H37: 水电 | N37: 火电 | T37: 核电 | Z37: 风电 | AF37: 太阳能发电 | AL37: 其他
B38: 2021年 | C38: 2020年 | D38: 2019年 | E38: 2018年 | F38: 2017年 | G38: 2016年 | H38: 2021年 | I38: 2020年 | J38: 2019年 | K38: 2018年 | L38: 2017年 | M38: 2016年 | N38: 2021年 | O38: 2020年 | P38: 2019年 | Q38: 2018年 | R38: 2017年 | S38: 2016年 | T38: 2021年 | U38: 2020年 | V38: 2019年 | W38: 2018年 | X38: 2017年 | Y38: 2016年 | Z38: 2021年 | AA38: 2020年 | AB38: 2019年 | AC38: 2018年 | AD38: 2017年 | AE38: 2016年 | AF38: 2021年 | AG38: 2020年 | AH38: 2019年 | AI38: 2018年 | AJ38: 2017年 | AK38: 2016年 | AL38: 2021年 | AM38: 2020年 | AN38: 2019年 | AO38: 2018年 | AP38: 2017年 | AX38: 2021年 | AY38: 2020年 | AZ38: 2019年 | BA38: 2018年 | BB38: 2017年 | BC38: 2016年
A39: 全国 | B39: 83959 | C39: 76264 | D39: 73269 | E39: 69947 | F39: 64529 | G39: 60228 | H39: 13399 | I39: 13553 | J39: 13021 | K39: 12321 | L39: 11947 | M39: 11748 | N39: 56655 | O39: 51770 | P39: 50465 | Q39: 49249 | R39: 45877 | S39: 43273 | T39: 4075 | U39: 3662 | V39: 3487 | W39: 2950 | X39: 2481 | Y39: 2132 | Z39: 6558 | AA39: 4665 | AB39: 4053 | AC39: 3658 | AD39: 3046 | AE39: 2409 | AF39: 3270 | AG39: 2611 | AH39: 2240 | AI39: 1769 | AJ39: 1178 | AK39: 665 | AL39: 2 | AM39: 3 | AN39: 3 | AO39: 1 | AP39: 1 | AV39: 发电量 | AW39: 水电 | AX39: 13399 | AY39: 13553 | AZ39: 13021 | BA39: 12321 | BB39: 11947 | BC39: 11748
A40: 北京 | C40: 456 | D40: 461 | E40: 449 | F40: 394 | G40: 436 | I40: 11 | J40: 10 | K40: 10 | L40: 11 | M40: 12 | O40: 434 | P40: 443 | Q40: 433 | R40: 377 | S40: 419 | AA40: 4 | AB40: 3 | AC40: 3 | AD40: 3 | AE40: 3 | AG40: 6 | AH40: 5 | AI40: 3 | AJ40: 2 | AK40: 1 | AW40: 抽蓄 | AX40: 390 | AY40: 335 | AZ40: 319 | BA40: 329 | BB40: 328 | BC40: 308
A41: 天津 | C41: 699 | D41: 673 | E41: 670 | F41: 596 | G41: 600 | I41: 0.1 | J41: 0.12 | K41: 0.15 | L41: 0.07 | M41: 0.03 | O41: 668 | P41: 647 | Q41: 654 | R41: 584 | S41: 591 | AA41: 12 | AB41: 11 | AC41: 8 | AD41: 6 | AE41: 6 | AG41: 19 | AH41: 15 | AI41: 8 | AJ41: 6.2 | AK41: 3 | AV41: 装机容量 | AW41: 水电 | AX41: 39094 | AY41: 37028 | AZ41: 35804 | BA41: 35259 | BB41: 34411 | BC41: 33207
A42: 河北 | C42: 2945 | D42: 2887 | E42: 2787 | F42: 2657 | G42: 2476 | I42: 15 | J42: 16 | K42: 17 | L42: 20 | M42: 24 | O42: 2352 | P42: 2377 | Q42: 2361 | R42: 2296 | S42: 2196 | AA42: 368 | AB42: 318 | AC42: 283 | AD42: 263 | AE42: 216 | AG42: 211 | AH42: 176 | AI42: 126 | AJ42: 77 | AK42: 40 | AW42: 抽蓄 | AX42: 3639 | AY42: 3149 | AZ42: 3029 | BA42: 2999 | BB42: 2869 | BC42: 2669
...

Sheet 2016
A1: 分地区新增发电装机容量（万KW）
A2: 地区 | B2: 合计 | C2: 水电 | E2: 火电 | S2: 核电 | T2: 风电 | U2: 太阳能发电 | V2: 其他
C3: 合计 | D3: 抽水蓄能 | E3: 合计 | F3: 燃煤 | I3: 燃气 | L3: 燃油 | M3: 其他 | AB3: 万千瓦 | AC3: 合计 | AD3: 水 | AE3: 火 | AF3: 风 | AG3: 光
F4: 合计 | G4: 常规燃煤 | H4: 煤矸石发电 | I4: 合计 | J4: 常规燃气 | K4: 煤层气发电 | M4: 合计 | N4: 余温、余气、余压发电 | O4: 垃圾焚烧发电 | P4: 秸秆、蔗渣、林木质发电 | Q4: 沼气 | R4: 技改增容 | AB4: 地区 | AC4: 2016 年 | AD4: 2016 年 | AE4: 2016 年 | AF4: 2016 年 | AG4: 2016 年
A5: 全国 | B5: 160522 | C5: 30010 | E5: 105580 | F5: 94654 | I5: 7011 | L5: 210 | M5: 4220 | O5: 576 | P5: 776 | Q5: 45 | S5: 3364 | T5: 14744 | U5: 6819 | V5: 5 | X5: =B5-C5-E5-S5-T5-U5-V5 -> 0 | Y5: =E5-F5-I5-L5-M5 -> -515 | Z5: =M5-N5-O5-P5 -> 2868 | AB5: 全国 | AC5: 12143 | AD5: 1179 | AE5: 5048 | AF5: 2024 | AG5: 3171 | AH5: =AC5-AD5-AE5-AF5-AG5 -> 721
A6: 北京 | B6: 1092 | C6: 98 | E6: 970 | F6: 85 | I6: 850 | L6: 22 | M6: 15 | O6: 13 | Q6: 1 | T6: 19 | U6: 5 | X6: =B6-C6-E6-S6-T6-U6-V6 -> 0 | Y6: =E6-F6-I6-L6-M6 -> -2 | Z6: =M6-N6-O6-P6 -> 2 | AB6: 北京 | AC6: 32 | AE6: 6 | AF6: 7 | AG6: 18 | AH6: =AC6-AD6-AE6-AF6-AG6 -> 1
A7: 天津 | B7: 1458 | E7: 1377 | F7: 1076 | I7: 277 | M7: 25 | O7: 10 | T7: 28 | U7: 54 | X7: =B7-C7-E7-S7-T7-U7-V7 -> -1 | Y7: =E7-F7-I7-L7-M7 -> -1 | Z7: =M7-N7-O7-P7 -> 15 | AB7: 天津 | AC7: 143 | AE7: 95 | AG7: 48 | AH7: =AC7-AD7-AE7-AF7-AG7 -> 0
A8: 河北 | B8: 6211 | C8: 165 | E8: 4503 | F8: 4251 | I8: 3 | M8: 257 | O8: 16 | P8: 38 | Q8: 1 | T8: 1138 | U8: 404 | V8: 2 | X8: =B8-C8-E8-S8-T8-U8-V8 -> -1 | Y8: =E8-F8-I8-L8-M8 -> -8 | Z8: =M8-N8-O8-P8 -> 203 | AB8: 河北 | AC8: 631 | AE8: 170 | AF8: 228 | AG8: 232 | AH8: =AC8-AD8-AE8-AF8-AG8 -> 1
A9: 山西 | B9: 7599 | C9: 235 | E9: 6309 | F9: 6003 | I9: 279 | M9: 46 | O9: 11 | P9: 19 | Q9: 15 | T9: 771 | U9: 284 | X9: =B9-C9-E9-S9-T9-U9-V9 -> 0 | Y9: =E9-F9-I9-L9-M9 -> -19 | Z9: =M9-N9-O9-P9 -> 16 | AB9: 山西 | AC9: 793 | AE9: 374 | AF9: 173 | AG9: 246 | AH9: =AC9-AD9-AE9-AF9-AG9 -> 0
A10: 内蒙古 | B10: 11030 | C10: 238 | E10: 7601 | F10: 7542 | I10: 42 | M10: 25 | O10: 4 | P10: 12 | T10: 2556 | U10: 636 | X10: =B10-C10-E10-S10-T10-U10-V10 -> -1 | Y10: =E10-F10-I10-L10-M10 -> -8 | Z10: =M10-N10-O10-P10 -> 9 | AB10: 内蒙古 | AC10: 473 | AE10: 366 | AF10: 81 | AG10: 26 | AH10: =AC10-AD10-AE10-AF10-AG10 -> 0
A11: 辽宁 | B11: 4572 | C11: 277 | E11: 3109 | F11: 3024 | I11: 4 | L11: 15 | M11: 72 | O11: 3 | P11: 5 | S11: 448 | T11: 694 | U11: 45 | X11: =B11-C11-E11-S11-T11-U11-V11 -> -1 | Y11: =E11-F11-I11-L11-M11 -> -6 | Z11: =M11-N11-O11-P11 -> 64 | AB11: 辽宁 | AC11: 147 | AE11: 1 | AF11: 14 | AG11: 21 | AH11: =AC11-AD11-AE11-AF11-AG11 -> 111
A12: 吉林 | B12: 2684 | C12: 353 | E12: 1775 | F12: 1688 | I12: 0 | M12: 88 | O12: 12 | P12: 40 | Q12: 0 | T12: 505 | U12: 52 | X12: =B12-C12-E12-S12-T12-U12-V12 -> -1 | Y12: =E12-F12-I12-L12-M12 -> -1 | Z12: =M12-N12-O12-P12 -> 36 | AB12: 吉林 | AC12: 84 | AE12: 11 | AF12: 22 | AG12: 52 | AH12: =AC12-AD12-AE12-AF12-AG12 -> -1
A13: 黑龙江 | B13: 2767 | C13: 95 | E13: 2099 | F13: 1991 | I13: 12 | L13: 2 | M13: 99 | O13: 7 | P13: 73 | Q13: 0 | T13: 561 | U13: 12 | X13: =B13-C13-E13-S13-T13-U13-V13 -> 0 | Y13: =E13-F13-I13-L13-M13 -> -5 | Z13: =M13-N13-O13-P13 -> 19 | AB13: 黑龙江 | AC13: 139 | AE13: 59 | AF13: 66 | AG13: 14 | AH13: =AC13-AD13-AE13-AF13-AG13 -> 0
A14: 上海 | B14: 2341 | E14: 2263 | F14: 1509 | I14: 570 | L14: 86 | M14: 98 | O14: 22 | Q14: 2 | T14: 71 | U14: 7 | X14: =B14-C14-E14-S14-T14-U14-V14 -> 0 | Y14: =E14-F14-I14-L14-M14 -> 0 | Z14: =M14-N14-O14-P14 -> 76 | AB14: 上海 | AC14: 45 | AE14: 11 | AF14: 20 | AG14: 15 | AH14: =AC14-AD14-AE14-AF14-AG14 -> -1
A15: 江苏 | B15: 9987 | C15: 110 | E15: 8711 | F15: 7448 | I15: 957 | M15: 322 | O15: 79 | P15: 44 | Q15: 2 | S15: 212 | T15: 561 | U15: 394 | X15: =B15-C15-E15-S15-T15-U15-V15 -> -1 | Y15: =E15-F15-I15-L15-M15 -> -16 | Z15: =M15-N15-O15-P15 -> 199 | AB15: 江苏 | AC15: 645 | AE15: 380 | AF15: 95 | AG15: 170 | AH15: =AC15-AD15-AE15-AF15-AG15 -> 0
A16: 浙江 | B16: 7927 | C16: 939 | E16: 6044 | F16: 4629 | I16: 1228 | L16: 6 | M16: 200 | O16: 102 | P16: 19 | Q16: 1 | S16: 657 | T16: 118 | U16: 169 | X16: =B16-C16-E16-S16-T16-U16-V16 -> 0 | Y16: =E16-F16-I16-L16-M16 -> -19 | Z16: =M16-N16-O16-P16 -> 79 | AB16: 浙江 | AC16: 496 | AD16: 177 | AE16: 64 | AF16: 27 | AG16: 228 | AH16: =AC16-AD16-AE16-AF16-AG16 -> 0
A17: 安徽 | B17: 5598 | C17: 241 | E17: 4894 | F17: 4669 | I17: 11 | M17: 236 | O17: 29 | P17: 66 | Q17: 1 | T17: 177 | U17: 287 | X17: =B17-C17-E17-S17-T17-U17-V17 -> -1 | Y17: =E17-F17-I17-L17-M17 -> -22 | Z17: =M17-N17-O17-P17 -> 141 | AB17: 安徽 | AC17: 503 | AD17: 5 | AE17: 301 | AF17: 45 | AG17: 153 | AH17: =AC17-AD17-AE17-AF17-AG17 -> -1
A18: 福建 | B18: 4807 | C18: 918 | E18: 2893 | F18: 2394 | I18: 387 | M18: 121 | O18: 30 | P18: 5 | Q18: 1 | S18: 762 | T18: 214 | U18: 20 | X18: =B18-C18-E18-S18-T18-U18-V18 -> 0 | Y18: =E18-F18-I18-L18-M18 -> -9 | Z18: =M18-N18-O18-P18 -> 86 | AB18: 福建 | AC18: 338 | AD18: 6 | AE18: 33 | AF18: 62 | AG18: 20 | AH18: =AC18-AD18-AE18-AF18-AG18 -> 217
A19: 江西 | B19: 2610 | C19: 412 | E19: 1913 | F19: 1721 | I19: 10 | M19: 187 | O19: 7 | P19: 20 | Q19: 0 | T19: 108 | U19: 178 | X19: =B19-C19-E19-S19-T19-U19-V19 -> -1 | Y19: =E19-F19-I19-L19-M19 -> -5 | Z19: =M19-N19-O19-P19 -> 160 | AB19: 江西 | AC19: 400 | AD19: 121 | AE19: 115 | AF19: 27 | AG19: 137 | AH19: =AC19-AD19-AE19-AF19-AG19 -> 0
A20: 山东 | B20: 10817 | C20: 101 | E20: 9521 | F20: 9015 | I20: 6 | M20: 519 | O20: 56 | P20: 117 | Q20: 6 | T20: 839 | U20: 356 | X20: =B20-C20-E20-S20-T20-U20-V20 -> 0 | Y20: =E20-F20-I20-L20-M20 -> -19 | Z20: =M20-N20-O20-P20 -> 346 | AB20: 山东 | AC20: 1281 | AE20: 883 | AF20: 111 | AG20: 286 | AH20: =AC20-AD20-AE20-AF20-AG20 -> 1
A21: 河南 | B21: 7165 | C21: 389 | E21: 6422 | F21: 6164 | I21: 161 | M21: 106 | O21: 8 | P21: 39 | T21: 104 | U21: 250 | X21: =B21-C21-E21-S21-T21-U21-V21 -> 0 | Y21: =E21-F21-I21-L21-M21 -> -9 | Z21: =M21-N21-O21-P21 -> 59 | AB21: 河南 | AC21: 387 | AE21: 102 | AF21: 34 | AG21: 250 | AH21: =AC21-AD21-AE21-AF21-AG21 -> 1
A22: 湖北 | B22: 6604 | C22: 3552 | E22: 2685 | F22: 2405 | I22: 76 | M22: 213 | O22: 21 | P22: 43 | Q22: 1 | T22: 201 | U22: 166 | X22: =B22-C22-E22-S22-T22-U22-V22 -> 0 | Y22: =E22-F22-I22-L22-M22 -> -9 | Z22: =M22-N22-O22-P22 -> 149 | AB22: 湖北 | AC22: 376 | AD22: 13 | AE22: 122 | AF22: 83 | AG22: 158 | AH22: =AC22-AD22-AE22-AF22-AG22 -> 0
A23: 湖南 | B23: 3774 | C23: 1236 | E23: 2311 | F23: 2113 | I23: 10 | L23: 7 | M23: 191 | O23: 10 | P23: 21 | Q23: 9 | T23: 217 | U23: 10 | X23: =B23-C23-E23-S23-T23-U23-V23 -> 0 | Y23: =E23-F23-I23-L23-M23 -> -10 | Z23: =M23-N23-O23-P23 -> 160 | AB23: 湖南 | AC23: 135 | AD23: 27 | AE23: 9 | AF23: 86 | AG23: 13 | AH23: =AC23-AD23-AE23-AF23-AG23 -> 0
A24: 广东 | B24: 9933 | C24: 954 | E24: 7709 | F24: 5992 | I24: 1569 | L24: 33 | M24: 128 | O24: 62 | P24: 16 | Q24: 4 | S24: 938 | T24: 268 | U24: 63 | V24: 1 | X24: =B24-C24-E24-S24-T24-U24-V24 -> 0 | Y24: =E24-F24-I24-L24-M24 -> -13 | Z24: =M24-N24-O24-P24 -> 50 | AB24: 广东 | AC24: 300 | AD24: 96 | AE24: 60 | AF24: 16 | AG24: 19 | AH24: =AC24-AD24-AE24-AF24-AG24 -> 109
A25: 广西 | B25: 3931 | C25: 1493 | E25: 2140 | F25: 1615 | I25: 12 | M25: 558 | O25: 8 | P25: 155 | S25: 217 | T25: 70 | U25: 12 | X25: =B25-C25-E25-S25-T25-U25-V25 -> -1 | Y25: =E25-F25-I25-L25-M25 -> -45 | Z25: =M25-N25-O25-P25 -> 395 | AB25: 广西 | AC25: 798 | AD25: 14 | AE25: 528 | AF25: 35 | AG25: 4 | AH25: =AC25-AD25-AE25-AF25-AG25 -> 217
A26: 海南 | B26: 711 | C26: 62 | E26: 463 | F26: 376 | I26: 72 | M26: 16 | O26: 7 | Q26: 0 | S26: 130 | T26: 31 | U26: 24 | X26: =B26-C26-E26-S26-T26-U26-V26 -> 1 | Y26: =E26-F26-I26-L26-M26 -> -1 | Z26: =M26-N26-O26-P26 -> 9 | AB26: 海南 | AC26: 66 | AG26: 1 | AH26: =AC26-AD26-AE26-AF26-AG26 -> 65
A27: 重庆 | B27: 2066 | C27: 581 | E27: 1457 | F27: 1256 | I27: 162 | M27: 44 | O27: 10 | P27: 4 | Q27: 0 | T27: 28 | X27: =B27-C27-E27-S27-T27-U27-V27 -> 0 | Y27: =E27-F27-I27-L27-M27 -> -5 | Z27: =M27-N27-O27-P27 -> 30 | AB27: 重庆 | AC27: 154 | AD27: 11 | AE27: 132 | AF27: 10 | AG27: 1 | AH27: =AC27-AD27-AE27-AF27-AG27 -> 0
A28: 四川 | B28: 8661 | C28: 6834 | E28: 1608 | F28: 1399 | I28: 122 | M28: 121 | O28: 27 | P28: 3 | T28: 125 | U28: 94 | X28: =B28-C28-E28-S28-T28-U28-V28 -> 0 | Y28: =E28-F28-I28-L28-M28 -> -34 | Z28: =M28-N28-O28-P28 -> 91 | AB28: 四川 | AC28: 489 | AD28: 308 | AE28: 30 | AF28: 68 | AG28: 83 | AH28: =AC28-AD28-AE28-AF28-AG28 -> 0
A29: 贵州 | B29: 5272 | C29: 1850 | E29: 3014 | F29: 3005 | M29: 8 | O29: 2 | P29: 6 | T29: 362 | U29: 46 | X29: =B29-C29-E29-S29-T29-U29-V29 -> 0 | Y29: =E29-F29-I29-L29-M29 -> 1 | Z29: =M29-N29-O29-P29 -> 0 | AB29: 贵州 | AC29: 359 | AD29: 9 | AE29: 318 | AF29: 32 | AH29: =AC29-AD29-AE29-AF29-AG29 -> 0
A30: 云南 | B30: 8236 | C30: 5895 | E30: 1396 | F30: 1301 | I30: 2 | M30: 309 | O30: 10 | P30: 20 | T30: 737 | U30: 208 | X30: =B30-C30-E30-S30-T30-U30-V30 -> 0 | Y30: =E30-F30-I30-L30-M30 -> -216 | Z30: =M30-N30-O30-P30 -> 279 | AB30: 云南 | AC30: 289 | AD30: 180 | AF30: 97 | AG30: 12 | AH30: =AC30-AD30-AE30-AF30-AG30 -> 0
A31: 西藏 | B31: 229 | C31: 153 | E31: 40 | L31: 39 | M31: 2 | T31: 1 | U31: 33 | V31: 2 | X31: =B31-C31-E31-S31-T31-U31-V31 -> 0 | Y31: =E31-F31-I31-L31-M31 -> -1 | Z31: =M31-N31-O31-P31 -> 2 | AB31: 西藏 | AC31: 60 | AD31: 41 | AE31: 3 | AG31: 16 | AH31: =AC31-AD31-AE31-AF31-AG31 -> 0
A32: 陕西 | B32: 3686 | C32: 232 | E32: 3036 | F32: 2997 | M32: 46 | O32: 2 | T32: 179 | U32: 239 | X32: =B32-C32-E32-S32-T32-U32-V32 -> 0 | Y32: =E32-F32-I32-L32-M32 -> -7 | Z32: =M32-N32-O32-P32 -> 44 | AB32: 陕西 | AC32: 450 | AD32: 15 | AE32: 149 | AF32: 91 | AG32: 194 | AH32: =AC32-AD32-AE32-AF32-AG32 -> 1
A33: 甘肃 | B33: 4703 | C33: 743 | E33: 2002 | F33: 1966 | I33: 7 | M33: 29 | O33: 5 | P33: 3 | T33: 1277 | U33: 681 | X33: =B33-C33-E33-S33-T33-U33-V33 -> 0 | Y33: =E33-F33-I33-L33-M33 -> 0 | Z33: =M33-N33-O33-P33 -> 21 | AB33: 甘肃 | AC33: 152 | AD33: 9 | AE33: 40 | AF33: 25 | AG33: 78 | AH33: =AC33-AD33-AE33-AF33-AG33 -> 0
A34: 青海 | B34: 2297 | C34: 1168 | E34: 381 | F34: 370 | I34: 33 | T34: 69 | U34: 680 | X34: =B34-C34-E34-S34-T34-U34-V34 -> -1 | Y34: =E34-F34-I34-L34-M34 -> -22 | Z34: =M34-N34-O34-P34 -> 0 | AB34: 青海 | AC34: 319 | AD34: 46 | AE34: 113 | AF34: 30 | AG34: 131 | AH34: =AC34-AD34-AE34-AF34-AG34 -> -1
A35: 宁夏 | B35: 3670 | C35: 42 | E35: 2164 | F35: 2008 | I35: 81 | M35: 75 | O35: 2 | P35: 5 | T35: 942 | U35: 522 | X35: =B35-C35-E35-S35-T35-U35-V35 -> 0 | Y35: =E35-F35-I35-L35-M35 -> 0 | Z35: =M35-N35-O35-P35 -> 68 | AB35: 宁夏 | AC35: 574 | AE35: 180 | AF35: 177 | AG35: 217 | AH35: =AC35-AD35-AE35-AF35-AG35 -> 0
A36: 新疆 | B36: 8083 | C36: 644 | E36: 4771 | F36: 4642 | I36: 68 | M36: 65 | P36: 3 | T36: 1776 | U36: 892 | X36: =B36-C36-E36-S36-T36-U36-V36 -> 0 | Y36: =E36-F36-I36-L36-M36 -> -4 | Z36: =M36-N36-O36-P36 -> 62 | AB36: 新疆 | AC36: 1085 | AD36: 98 | AE36: 394 | AF36: 262 | AG36: 330 | AH36: =AC36-AD36-AE36-AF36-AG36 -> 1
B38: =B5-SUM(B6:B36) -> 1 | C38: =C5-SUM(C6:C36) -> 0 | D38: =D5-SUM(D6:D36) -> 0 | E38: =E5-SUM(E6:E36) -> -1 | F38: =F5-SUM(F6:F36) -> 0 | H38: =H5-SUM(H6:H36) -> 0 | I38: =I5-SUM(I6:I36) -> 0 | J38: =J5-SUM(J6:J36) -> 0 | L38: =L5-SUM(L6:L36) -> 0 | M38: =M5-SUM(M6:M36) -> -1 | N38: =N5-SUM(N6:N36) -> 0 | O38: =O5-SUM(O6:O36) -> 1 | P38: =P5-SUM(P6:P36) -> 0 | S38: =S5-SUM(S6:S36) -> 0 | T38: =T5-SUM(T6:T36) -> -3 | U38: =U5-SUM(U6:U36) -> -4 | V38: =V5-SUM(V6:V36) -> 0

Sheet 2017
A1: 分地区装机容量（万KW） | X1: 分地区装机容量（万KW）
A2: 地区 | B2: 合计 | C2: 水电 | E2: 火电 | S2: 核电 | T2: 风电 | U2: 太阳能发电 | V2: 其他 | X2: 合计 | Y2: 水电 | Z2: 火电 | AA2: 核电 | AB2: 风电 | AC2: 太阳能发电 | AD2: 其他 | AE2: 分布式太阳能
C3: 合计 | D3: 抽水蓄能 | E3: 合计 | F3: 燃煤 | I3: 燃气 | L3: 燃油 | M3: 其他
F4: 合计 | G4: 常规燃煤 | H4: 煤矸石发电 | I4: 合计 | J4: 常规燃气 | K4: 煤层气发电 | M4: 合计 | N4: 余温、余气、余压发电 | O4: 垃圾焚烧发电 | P4: 秸秆、蔗渣、林木质发电 | Q4: 沼气 | R4: 技改增容
A5: 全国 | B5: 171249 | C5: 31071 | E5: 109992 | F5: 98130 | I5: 7570 | L5: 197 | M5: 4598 | O5: 731 | P5: 872 | Q5: 47 | S5: 3582 | T5: 16322 | U5: 10277 | V5: 5 | X5: 177708 | Y5: 34359 | Z5: 110495 | AA5: 3582 | AB5: 16325 | AC5: 12942 | AD5: 7 | AE5: 3658
A6: 北京 | B6: 1198 | C6: 98 | E6: 1076 | F6: 85 | I6: 950 | L6: 22 | M6: 20 | O6: 20 | Q6: 1 | T6: 19 | U6: 5 | X6: 1219 | Y6: 98 | Z6: 1077 | AB6: 19 | AC6: 25 | AE6: 22
A7: 天津 | B7: 1483 | E7: 1400 | F7: 1072 | I7: 304 | M7: 27 | O7: 10 | T7: 28 | U7: 55 | X7: 1499 | Y7: 1 | Z7: 1402 | AB7: 29 | AC7: 68 | AE7: 15
A8: 河北 | B8: 6576 | C8: 165 | E8: 4566 | F8: 4282 | I8: 3 | M8: 289 | O8: 24 | P8: 44 | Q8: 1 | T8: 1181 | U8: 662 | V8: 2 | X8: 6807 | Y8: 182 | Z8: 4574 | AB8: 1181 | AC8: 868 | AD8: 2 | AE8: 351
A9: 山西 | B9: 7992 | C9: 235 | E9: 6352 | F9: 5887 | I9: 291 | M9: 189 | O9: 11 | P9: 30 | Q9: 9 | T9: 872 | U9: 534 | X9: 8073 | Y9: 244 | Z9: 6366 | AB9: 872 | AC9: 590 | AE9: 60
A10: 内蒙古 | B10: 11810 | C10: 238 | E10: 8162 | F10: 8103 | I10: 42 | M10: 25 | O10: 4 | P10: 12 | T10: 2669 | U10: 740 | X10: 11826 | Y10: 242 | Z10: 8170 | AB10: 2670 | AC10: 743 | AE10: 2
A11: 辽宁 | B11: 4824 | C11: 279 | E11: 3188 | F11: 3093 | I11: 5 | L11: 15 | M11: 80 | O11: 8 | P11: 7 | S11: 448 | T11: 710 | U11: 200 | X11: 4869 | Y11: 295 | Z11: 3193 | AA11: 448 | AB11: 711 | AC11: 223 | AE11: 38
A12: 吉林 | B12: 2804 | C12: 353 | E12: 1817 | F12: 1728 | I12: 0.5 | M12: 91 | O12: 13 | P12: 40 | Q12: 0.3 | T12: 505 | U12: 130 | X12: 2864 | Y12: 380 | Z12: 1820 | AB12: 505 | AC12: 159 | AE12: 52
A13: 黑龙江 | B13: 2936 | C13: 97 | E13: 2197 | F13: 2078 | I13: 12 | L13: 2 | M13: 110 | O13: 8 | P13: 82 | Q13: 0.4 | T13: 570 | U13: 73 | X13: 2969 | Y13: 103 | Z13: 2201 | AB13: 570 | AC13: 94 | AE13: 30
A14: 上海 | B14: 2348 | E14: 2270 | F14: 1509 | I14: 573 | L14: 86 | M14: 102 | O14: 26 | Q14: 2 | T14: 71 | U14: 7 | X14: 2400 | Z14: 2271 | AB14: 71 | AC14: 58 | AE14: 59
A15: 江苏 | B15: 11112 | C15: 260 | E15: 9414 | F15: 7741 | I15: 1348 | M15: 340 | O15: 91 | P15: 50 | Q15: 4 | S15: 212 | T15: 655 | U15: 571 | X15: 11469 | Y15: 265 | Z15: 9430 | AA15: 212 | AB15: 656 | AC15: 907 | AE15: 327
A16: 浙江 | B16: 8175 | C16: 941 | E16: 6117 | F16: 4663 | I16: 1230 | L16: 6 | M16: 235 | O16: 133 | P16: 21 | Q16: 4 | S16: 657 | T16: 132 | U16: 328 | X16: 8899 | Y16: 1160 | Z16: 6134 | AA16: 657 | AB16: 133 | AC16: 814 | AD16: 0.4 | AE16: 499
A17: 安徽 | B17: 6099 | C17: 242 | E17: 5031 | F17: 4760 | I17: 12 | M17: 281 | O17: 43 | P17: 75 | Q17: 1 | T17: 217 | U17: 608 | X17: 6468 | Y17: 310 | Z17: 5053 | AB17: 217 | AC17: 888 | AE17: 323
A18: 福建 | B18: 5164 | C18: 917 | E18: 3064 | F18: 2545 | I18: 390 | L18: 1 | M18: 138 | O18: 39 | P18: 5 | Q18: 0.4 | S18: 871 | T18: 252 | U18: 60 | X18: 5597 | Y18: 1307 | Z18: 3074 | AA18: 871 | AB18: 252 | AC18: 92 | AE18: 109
A19: 江西 | B19: 2796 | C19: 412 | E19: 1928 | F19: 1721 | I19: 10 | M19: 202 | O19: 9 | P19: 20 | Q19: 1 | T19: 169 | U19: 287 | X19: 3167 | Y19: 615 | Z19: 1934 | AB19: 169 | AC19: 449 | AE19: 172
A20: 山东 | B20: 12117 | C20: 101 | E20: 10314 | F20: 9762 | I20: 5 | M20: 567 | O20: 80 | P20: 131 | Q20: 5 | T20: 1061 | U20: 640 | X20: 12556 | Y20: 108 | Z20: 10335 | AB20: 1061 | AC20: 1052 | AE20: 474
A21: 河南 | B21: 7687 | C21: 389 | E21: 6533 | F21: 6239 | I21: 164 | M21: 141 | O21: 6 | P21: 43 | Q21: 4 | T21: 233 | U21: 532 | X21: 7880 | Y21: 399 | Z21: 6544 | AB21: 233 | AC21: 703 | AE21: 211
A22: 湖北 | B22: 6890 | C22: 3558 | E22: 2777 | F22: 2450 | I22: 96 | M22: 241 | O22: 24 | P22: 48 | Q22: 1 | T22: 253 | U22: 301 | X22: 7124 | Y22: 3671 | Z22: 2787 | AB22: 253 | AC22: 413 | AE22: 177
A23: 湖南 | B23: 3879 | C23: 1247 | E23: 2255 | F23: 2053 | I23: 3 | L23: 7 | M23: 204 | O23: 9 | P23: 36 | Q23: 1 | T23: 263 | U23: 113 | X23: 4277 | Y23: 1570 | Z23: 2267 | AB23: 263 | AC23: 176 | AE23: 90
A24: 广东 | B24: 10356 | C24: 989 | E24: 7755 | F24: 6035 | I24: 1571 | L24: 21 | M24: 141 | O24: 77 | P24: 22 | Q24: 7 | S24: 1046 | T24: 335 | U24: 229 | V24: 1 | X24: 10968 | Y24: 1486 | Z24: 7768 | AA24: 1046 | AB24: 335 | AC24: 332 | AD24: 2 | AE24: 122
A25: 广西 | B25: 4114 | C25: 1497 | E25: 2181 | F25: 1797 | I25: 35 | M25: 386 | O25: 9 | P25: 155 | Q25: 2 | S25: 217 | T25: 150 | U25: 69 | X25: 4332 | Y25: 1669 | Z25: 2217 | AA25: 217 | AB25: 150 | AC25: 78 | AE25: 373
A26: 海南 | B26: 745 | C26: 84 | E26: 464 | F26: 376 | I26: 73 | M26: 17 | O26: 8 | Q26: 0.3 | S26: 130 | T26: 34 | U26: 33 | X26: 786 | Y26: 114 | Z26: 465 | AA26: 130 | AB26: 34 | AC26: 43 | AE26: 11
A27: 重庆 | B27: 2209 | C27: 626 | E27: 1540 | F27: 1332 | I27: 168 | M27: 45 | O27: 10 | P27: 7 | Q27: 1 | T27: 33 | U27: 10 | X27: 2326 | Y27: 736 | Z27: 1544 | AB27: 33 | AC27: 12 | AE27: 12
A28: 四川 | B28: 9264 | C28: 7291 | E28: 1630 | F28: 1336 | I28: 126 | M28: 200 | O28: 39 | P28: 3 | Q28: 2 | T28: 210 | U28: 132 | X28: 9721 | Y28: 7714 | Z28: 1662 | AB28: 210 | AC28: 135 | AE28: 19
A29: 贵州 | B29: 5539 | C29: 1880 | E29: 3160 | F29: 3146 | M29: 15 | O29: 9 | P29: 6 | T29: 363 | U29: 135 | X29: 5778 | Y29: 2119 | Z29: 3160 | AB29: 363 | AC29: 135
A30: 云南 | B30: 8545 | C30: 6084 | E30: 1398 | F30: 1301 | I30: 2 | M30: 310 | O30: 12 | P30: 20 | T30: 825 | U30: 238 | X30: 8957 | Y30: 6281 | Z30: 1613 | AB30: 825 | AC30: 238 | AE30: 0.5
A31: 西藏 | B31: 276 | C31: 155 | E31: 39 | L31: 38 | M31: 2 | T31: 1 | U31: 79 | V31: 2 | X31: 281 | Y31: 158 | Z31: 40 | AB31: 1 | AC31: 79 | AD31: 3
A32: 陕西 | B32: 4100 | C32: 269 | E32: 3137 | F32: 3087 | M32: 56 | O32: 3 | P32: 3 | T32: 288 | U32: 406 | X32: 4192 | Y32: 326 | Z32: 3144 | AB32: 288 | AC32: 434 | AE32: 51
A33: 甘肃 | B33: 4861 | C33: 751 | E33: 2059 | F33: 2020 | I33: 6 | M33: 33 | O33: 6 | P33: 3 | T33: 1282 | U33: 769 | X33: 4995 | Y33: 868 | Z33: 2059 | AB33: 1282 | AC33: 786 | AE33: 18
A34: 青海 | B34: 2493 | C34: 1168 | E34: 378 | F34: 375 | M34: 24 | O34: 0.4 | T34: 162 | U34: 785 | X34: 2543 | Y34: 1191 | Z34: 399 | AB34: 162 | AC34: 791 | AE34: 5
A35: 宁夏 | B35: 4178 | C35: 42 | E35: 2582 | F35: 2432 | I35: 70 | M35: 82 | O35: 2 | P35: 6 | T35: 942 | U35: 612 | X35: 4188 | Y35: 43 | Z35: 2583 | AB35: 942 | AC35: 620 | AE35: 33
A36: 新疆 | B36: 8679 | C36: 702 | E36: 5207 | F36: 5122 | I36: 83 | M36: 2 | P36: 2 | Q36: 0.2 | T36: 1836 | U36: 934 | X36: 8679 | Y36: 702 | Z36: 5207 | AB36: 1836 | AC36: 934 | AE36: 1
B38: =B5-SUM(B6:B36) -> 0 | C38: =C5-SUM(C6:C36) -> 1 | D38: =D5-SUM(D6:D36) -> 0 | E38: =E5-SUM(E6:E36) -> 1 | F38: =F5-SUM(F6:F36) -> 0 | H38: =H5-SUM(H6:H36) -> 0 | I38: =I5-SUM(I6:I36) -> -2.5 | J38: =J5-SUM(J6:J36) -> 0 | L38: =L5-SUM(L6:L36) -> -1 | M38: =M5-SUM(M6:M36) -> 3 | N38: =N5-SUM(N6:N36) -> 0 | O38: =O5-SUM(O6:O36) -> -2.4 | P38: =P5-SUM(P6:P36) -> 1 | S38: =S5-SUM(S6:S36) -> 1 | T38: =T5-SUM(T6:T36) -> 1 | U38: =U5-SUM(U6:U36) -> 0 | V38: =V5-SUM(V6:V36) -> 0

Sheet 2018
A1: 分地区装机容量（万KW） | X1: 分地区装机容量（万KW）
A2: 地区 | B2: 合计 | C2: 水电 | E2: 火电 | S2: 核电 | T2: 风电 | U2: 太阳能发电 | V2: 其他 | X2: 合计 | Y2: 水电 | Z2: 火电 | AA2: 核电 | AB2: 风电 | AC2: 太阳能发电 | AD2: 其他 | AE2: 分布式太阳能
C3: 合计 | D3: 抽水蓄能 | E3: 合计 | F3: 燃煤 | I3: 燃气 | L3: 燃油 | M3: 其他
F4: 合计 | G4: 常规燃煤 | H4: 煤矸石发电 | I4: 合计 | J4: 常规燃气 | K4: 煤层气发电 | M4: 合计 | N4: 余温、余气、余压发电 | O4: 垃圾焚烧发电 | P4: 秸秆、蔗渣、林木质发电 | Q4: 沼气 | R4: 技改增容
A5: 全国 | B5: 181753 | C5: 31861 | E5: 114408 | F5: 100835 | I5: 8375 | L5: 173 | M5: 5024 | O5: 58 | P5: 898 | Q5: 991 | S5: 4466 | T5: 18423 | U5: 12885 | V5: 19 | X5: 190012 | Y5: 35259 | Z5: 114408 | AA5: 4466 | AB5: 18427 | AC5: 17433 | AD5: 37 | AE5: 5027
A6: 北京 | B6: 1242 | C6: 98 | E6: 1119 | F6: 85 | I6: 985 | L6: 22 | M6: 27 | P6: 27 | T6: 19 | U6: 8 | X6: 1276 | Y6: 98 | Z6: 1119 | AB6: 19 | AC6: 40 | AE6: 35
A7: 天津 | B7: 1686 | E7: 1529 | F7: 1187 | I7: 317 | M7: 25 | P7: 10 | T7: 52 | U7: 108 | X7: 1709 | Y7: 1 | Z7: 1529 | AB7: 52 | AC7: 128 | AE7: 31
A8: 河北 | B8: 7027 | C8: 165 | E8: 4617 | F8: 4308 | I8: 3 | M8: 306 | O8: 1 | P8: 27 | Q8: 47 | T8: 1391 | U8: 859 | V8: 3 | X8: 7427 | Y8: 182 | Z8: 4617 | AB8: 1391 | AC8: 1234 | AD8: 3 | AE8: 378
A9: 山西 | B9: 8555 | C9: 214 | E9: 6628 | F9: 6108 | I9: 301 | M9: 218 | O9: 10 | P9: 11 | Q9: 30 | T9: 1043 | U9: 686 | X9: 8758 | Y9: 223 | Z9: 6628 | AB9: 1043 | AC9: 864 | AE9: 183
A10: 内蒙古 | B10: 12264 | C10: 238 | E10: 8229 | F10: 8158 | I10: 42 | M10: 29 | P10: 7 | Q10: 12 | T10: 2868 | U10: 933 | X10: 12285 | Y10: 242 | Z10: 8229 | AB10: 2868 | AC10: 946 | AE10: 13
A11: 辽宁 | B11: 5116 | C11: 283 | E11: 3383 | F11: 3283 | I11: 5 | L11: 15 | M11: 81 | P11: 8 | Q11: 7 | S11: 448 | T11: 760 | U11: 248 | X11: 5192 | Y11: 299 | Z11: 3383 | AA11: 448 | AB11: 761 | AC11: 302 | AE11: 83
A12: 吉林 | B12: 2986 | C12: 357 | E12: 1892 | F12: 1788 | I12: 0.5 | M12: 103 | O12: 0.3 | P12: 16 | Q12: 49 | T12: 514 | U12: 226 | X12: 3055 | Y12: 385 | Z12: 1892 | AB12: 514 | AC12: 265 | AE12: 62
A13: 黑龙江 | B13: 3046 | C13: 97 | E13: 2212 | F13: 2082 | I13: 12 | L13: 2 | M13: 116 | O13: 0.4 | P13: 11 | Q13: 85 | T13: 598 | U13: 144 | X13: 3129 | Y13: 104 | Z13: 2212 | AB13: 598 | AC13: 215 | AE13: 74
A14: 上海 | B14: 2447 | E14: 2365 | F14: 1511 | I14: 662 | L14: 86 | M14: 106 | O14: 2 | P14: 26 | T14: 71 | U14: 13 | X14: 2525 | Z14: 2365 | AB14: 71 | AC14: 89 | AE14: 82
A15: 江苏 | B15: 12079 | C15: 260 | E15: 9749 | F15: 7885 | I15: 1502 | M15: 362 | O15: 7 | P15: 103 | Q15: 52 | S15: 437 | T15: 864 | U15: 776 | V15: 10 | X15: 12657 | Y15: 265 | Z15: 9749 | AA15: 437 | AB15: 865 | AC15: 1332 | AD15: 10 | AE15: 540
A16: 浙江 | B16: 8564 | C16: 943 | E16: 6209 | F16: 4680 | I16: 1259 | L16: 2 | M16: 267 | O16: 5 | P16: 141 | Q16: 22 | S16: 908 | T16: 148 | U16: 376 | X16: 9565 | Y16: 1161 | Z16: 6209 | AA16: 908 | AB16: 148 | AC16: 1138 | AD16: 1 | AE16: 777
A17: 安徽 | B17: 6623 | C17: 243 | E17: 5413 | F17: 5071 | I17: 14 | M17: 329 | O17: 1 | P17: 51 | Q17: 111 | T17: 246 | U17: 743 | X17: 7089 | Y17: 312 | Z17: 5413 | AB17: 246 | AC17: 1118 | AE17: 441
A18: 福建 | B18: 5281 | C18: 926 | E18: 3128 | F18: 2574 | I18: 391 | L18: 1 | M18: 163 | O18: 0.6 | P18: 44 | Q18: 5 | S18: 871 | T18: 300 | U18: 67 | X18: 5770 | Y18: 1322 | Z18: 3128 | AA18: 871 | AB18: 300 | AC18: 148 | AE18: 111
A19: 江西 | B19: 3112 | C19: 419 | E19: 2165 | F19: 1925 | I19: 10 | M19: 230 | O19: 1 | P19: 12 | Q19: 21 | T19: 225 | U19: 309 | X19: 3554 | Y19: 627 | Z19: 2165 | AB19: 225 | AC19: 536 | AE19: 242
A20: 山东 | B20: 12422 | C20: 102 | E20: 10367 | F20: 9723 | I20: 8 | M20: 636 | O20: 8 | P20: 108 | Q20: 148 | S20: 125 | T20: 1146 | U20: 708 | X20: 13107 | Y20: 108 | Z20: 10367 | AA20: 125 | AB20: 1146 | AC20: 1361 | AE20: 713
A21: 河南 | B21: 8271 | C21: 391 | E21: 6821 | F21: 6446 | I21: 229 | M21: 146 | O21: 4 | P21: 13 | Q21: 44 | T21: 468 | U21: 602 | X21: 8680 | Y21: 401 | Z21: 6821 | AB21: 468 | AC21: 991 | AE21: 391
A22: 湖北 | B22: 7106 | C22: 3563 | E22: 2884 | F22: 2546 | I22: 94 | M22: 244 | O22: 2 | P22: 24 | Q22: 48 | T22: 331 | U22: 338 | X22: 7401 | Y22: 3675 | Z22: 2884 | AB22: 331 | AC22: 510 | AE22: 175
A23: 湖南 | B23: 4040 | C23: 1264 | E23: 2284 | F23: 2046 | I23: 7 | L23: 7 | M23: 224 | O23: 3 | P23: 24 | Q23: 41 | T23: 348 | U23: 160 | X23: 4522 | Y23: 1598 | Z23: 2284 | AB23: 348 | AC23: 292 | AD23: 6 | AE23: 166
A24: 广东 | B24: 11266 | C24: 1079 | E24: 8137 | F24: 5994 | I24: 1963 | M24: 180 | O24: 9 | P24: 110 | Q24: 22 | S24: 1330 | T24: 357 | U24: 370 | V24: 1 | X24: 11929 | Y24: 1576 | Z24: 8137 | AA24: 1330 | AB24: 357 | AC24: 527 | AD24: 2 | AE24: 209
A25: 广西 | B25: 4279 | C25: 1503 | E25: 2288 | F25: 1858 | I25: 35 | M25: 395 | O25: 2 | P25: 12 | Q25: 162 | S25: 217 | T25: 208 | U25: 99 | X25: 4513 | Y25: 1677 | Z25: 2288 | AA25: 217 | AB25: 208 | AC25: 124 | AE25: 29
A26: 海南 | B26: 878 | C26: 125 | E26: 465 | F26: 352 | I26: 73 | M26: 41 | O26: 0.3 | P26: 8 | Q26: 24 | S26: 130 | T26: 34 | U26: 125 | X26: 919 | Y26: 154 | Z26: 465 | AA26: 130 | AB26: 34 | AC26: 136 | AD26: 11 | AE26: 13
A27: 重庆 | B27: 2255 | C27: 635 | E27: 1537 | F27: 1312 | I27: 168 | M27: 57 | O27: 1 | P27: 22 | Q27: 7 | T27: 50 | U27: 38 | X27: 2386 | Y27: 756 | Z27: 1537 | AB27: 50 | AC27: 43 | AE27: 43
A28: 四川 | B28: 9365 | C28: 7395 | E28: 1575 | F28: 1240 | I28: 126 | M28: 209 | O28: 3 | P28: 36 | Q28: 9 | T28: 253 | U28: 175 | X28: 9833 | Y28: 7824 | Z28: 1575 | AB28: 253 | AC28: 181 | AE28: 13
A29: 贵州 | B29: 5754 | C29: 1927 | E29: 3263 | F29: 3242 | M29: 21 | P29: 12 | Q29: 9 | T29: 386 | U29: 178 | X29: 6039 | Y29: 2212 | Z29: 3263 | AB29: 386 | AC29: 178 | AE29: 17
A30: 云南 | B30: 9113 | C30: 6448 | E30: 1508 | F30: 1298 | I30: 3 | M30: 207 | P30: 17 | Q30: 26 | T30: 857 | U30: 326 | X30: 9341 | Y30: 6649 | Z30: 1508 | AB30: 857 | AC30: 326 | AE30: 14
A31: 西藏 | B31: 300 | C31: 156 | E31: 42 | L31: 38 | M31: 4 | P31: 2 | T31: 1 | U31: 98 | V31: 4 | X31: 304 | Y31: 160 | Z31: 42 | AB31: 1 | AC31: 98 | AD31: 4
A32: 陕西 | B32: 5317 | C32: 325 | E32: 3937 | F32: 3789 | I32: 11 | M32: 137 | P32: 6 | T32: 405 | U32: 659 | X32: 5443 | Y32: 385 | Z32: 3937 | AB32: 405 | AC32: 716 | AE32: 76
A33: 甘肃 | B33: 4926 | C33: 790 | E33: 2064 | F33: 2021 | I33: 6 | M33: 36 | P33: 7 | Q33: 3 | T33: 1282 | U33: 790 | X33: 5113 | Y33: 927 | Z33: 2064 | AB33: 1282 | AC33: 839 | AE33: 49
A34: 青海 | B34: 2760 | C34: 1169 | E34: 379 | F34: 375 | I34: 0.4 | M34: 3 | O34: 0.4 | T34: 267 | U34: 946 | X34: 2800 | Y34: 1192 | Z34: 379 | AB34: 267 | AC34: 962 | AE34: 10
A35: 宁夏 | B35: 4696 | C35: 42 | E35: 2845 | F35: 2658 | I35: 70 | M35: 117 | P35: 5 | Q35: 5 | T35: 1011 | U35: 799 | X35: 4715 | Y35: 43 | Z35: 2845 | AB35: 1011 | AC35: 816 | AE35: 55
A36: 新疆 | B36: 8978 | C36: 702 | E36: 5377 | F36: 5292 | I36: 83 | M36: 2 | Q36: 2 | T36: 1921 | U36: 978 | X36: 8978 | Y36: 702 | Z36: 5377 | AB36: 1921 | AC36: 978 | AE36: 2
B38: =B5-SUM(B6:B36) -> -1 | C38: =C5-SUM(C6:C36) -> 2 | D38: =D5-SUM(D6:D36) -> 0 | E38: =E5-SUM(E6:E36) -> -3 | F38: =F5-SUM(F6:F36) -> -2 | H38: =H5-SUM(H6:H36) -> 0 | I38: =I5-SUM(I6:I36) -> -4.9 | J38: =J5-SUM(J6:J36) -> 0 | L38: =L5-SUM(L6:L36) -> 0 | M38: =M5-SUM(M6:M36) -> 3 | N38: =N5-SUM(N6:N36) -> 0 | O38: =O5-SUM(O6:O36) -> -3 | P38: =P5-SUM(P6:P36) -> -2 | S38: =S5-SUM(S6:S36) -> 0 | T38: =T5-SUM(T6:T36) -> -1 | U38: =U5-SUM(U6:U36) -> 0 | V38: =V5-SUM(V6:V36) -> 1

Sheet 2019
A1: 分地区6000千万以上装机容量（万KW） | X1: 分地区装机容量（万KW）
A2: 地区 | B2: 合计 | C2: 水电 | E2: 火电 | S2: 核电 | T2: 风电 | U2: 太阳能发电 | V2: 其他 | X2: 合计 | Y2: 水电 | Z2: 火电 | AA2: 核电 | AB2: 风电 | AC2: 太阳能发电 | AD2: 其他 | AE2: 分布式太阳能
C3: 合计 | D3: 抽水蓄能 | E3: 合计 | F3: 燃煤 | I3: 燃气 | L3: 燃油 | M3: 其他
F4: 合计 | G4: 常规燃煤 | H4: 煤矸石发电 | I4: 合计 | J4: 常规燃气 | K4: 煤层气发电 | M4: 合计 | N4: 余温、余气、余压发电 | O4: 垃圾焚烧发电 | P4: 秸秆、蔗渣、林木质发电 | Q4: 沼气 | R4: 技改增容
A5: 全国 | B5: 191499 | E5: 118957 | F5: 104063 | I5: 9024 | L5: 175 | M5: 5696 | O5: 1173 | P5: 1117 | Q5: 71.2 | S5: 4874 | T5: 20905 | U5: 14709 | X5: 201006 | Y5: 35804 | Z5: 118957 | AA5: 4874 | AB5: 20915 | AC5: 20418 | AD5: 37 | AE5: 6180
A6: 北京 | B6: 1259 | E6: 1135 | F6: 85 | I6: 993 | L6: 22 | M6: 36 | O6: 35 | T6: 18 | U6: 8 | X6: 1304 | Y6: 99 | Z6: 1135 | AB6: 19 | AC6: 51 | AE6: 46
