Workbook
Name cpi_2019_to_2012: [1]About!$A$97
Name cpi_2020_to_2012: [1]About!$A$99
Name IQ_CH: 110000
Name IQ_CQ: 5000
Name IQ_CY: 10000
Name IQ_DAILY: 500000
Name IQ_FH: 100000
Name IQ_FQ: 500
Name IQ_FY: 1000
Name IQ_LTM: 2000
Name IQ_MONTH: 15000
Name IQ_NTM: 6000
Name IQ_WEEK: 50000
Name IQ_YTD: 3000

Sheet About
A1: BAU Expected Capacity Factors
A3: Source: | B3: Capacity, Generation and Operation Hours
B4: Thermal, Hydro, Nuclear, Onshore Wind, Solar, Biomass, MSW
B5: China Electricity Council
B6: 中国电力工业统计资料汇编 （Compilation of China Power Sector Statistics)
B7: 2016, 2017, 2018, 2019, 2020,2021,2022
B8: Chapter 2 (Power Generation)
B10: Distributed Solar & Solar Stations
B11: National Energy Administration
B12: 光伏发电建设运行情况 （Construction and Operation Status of Solar Power)
B13: 2016-2022
B14: 2022年光伏发电建设运行情况---国家能源局 (nea.gov.cn)
B15: 2021年光伏发电建设运行情况---国家能源局 (nea.gov.cn)
B16: 国家能源局公布2020年可再生能源发展情况_中国电力网 (chinapower.com.cn)
... B35: Gutiérrez-Negrín, L.C.A. Evolution of worldwide geothermal power 2020–2023. Geotherm Energy 12, 14 (2024). https://doi.org/10.1186/s40517-024-00290-w
A38: Notes: | B38: We do not distinguish between the expected CF for pre-exisint retiring, nonretiring and new facilities
B39: For 2019-2021, the exact CF is used
B40: For year beyond 2021, the median CF of 2016-2021 is used for incumben technology, and
B41: maximum CF is used for emerging technology
A42: Region Selector
A43: This excel file includes data required for all Chinese provinces (excluding Taiwan, Hong Kong, Macau,
A44: and sometimes Tibet). You can use the selector below to choose which province/region you would
A45: like to calculate for:
B46: Province Selector
B47: 全国 National
B49: Provincial Capacity Factors:
B50: Coal & Gangue (Lignite), Natural Gas (Peaker & Non-peaker), Biomass, PV, Onshore Wind, Hydro
B52: National Capacity Factors
B53: Nulcear, Solar Thermal, Geothermal, Oil (Petroleum, Crude & Fuel Oil)， Offshore Wind

Sheet Province Selector
A1: Code | B1: 地区名称 | C1: 地区全称 | D1: 地区简称 | E1: Name | F1: 缩写
A2: 00 | B2: 全国 National | C2: 全国 | D2: 全国 | E2: National | F2: CN
A3: 11 | B3: 北京市 Beijing | C3: 北京市 | D3: 北京 | E3: Beijing | F3: BJ
A4: 12 | B4: 天津市 Tianjin | C4: 天津市 | D4: 天津 | E4: Tianjin | F4: TJ
A5: 13 | B5: 河北省 Hebei | C5: 河北省 | D5: 河北 | E5: Hebei | F5: HE
A6: 14 | B6: 山西省 Shanxi | C6: 山西省 | D6: 山西 | E6: Shanxi | F6: SX
A7: 15 | B7: 内蒙古自治区 Inner Mongolia | C7: 内蒙古自治区 | D7: 内蒙古 | E7: Inner Mongolia | F7: NM
A8: 21 | B8: 辽宁省 Liaoning | C8: 辽宁省 | D8: 辽宁 | E8: Liaoning | F8: LN
A9: 22 | B9: 吉林省 Jilin | C9: 吉林省 | D9: 吉林 | E9: Jilin | F9: JL
A10: 23 | B10: 黑龙江省 Heilongjiang | C10: 黑龙江省 | D10: 黑龙江 | E10: Heilongjiang | F10: HL
A11: 31 | B11: 上海市 Shanghai | C11: 上海市 | D11: 上海 | E11: Shanghai | F11: SH
A12: 32 | B12: 江苏省 Jiangsu | C12: 江苏省 | D12: 江苏 | E12: Jiangsu | F12: JS
A13: 33 | B13: 浙江省 Zhejiang | C13: 浙江省 | D13: 浙江 | E13: Zhejiang | F13: ZJ
A14: 34 | B14: 安徽省 Anhui | C14: 安徽省 | D14: 安徽 | E14: Anhui | F14: AH
... A33: 65 | B33: 新疆维吾尔自治区 Xijiang | C33: 新疆维吾尔自治区 | D33: 新疆 | E33: Xijiang | F33: XJ

Sheet Renewable
A1: 年末装机量（万千瓦） Year End Total Capacity (10MW)
A2: 地区 | B2: 合计 | I2: 水电 | P2: 火电 | W2: 核电 | AD2: 风电 | AK2: 太阳能发电 | AR2: 其他 | AZ2: 地区 | BA2: 核电容量因子 | BG2: 风电容量因子 | BM2: 水电容量因子
B3: 2016年 | C3: 2017年 | D3: 2018年 | E3: 2019年 | F3: 2020年 | G3: 2021年 | H3: 2022年 | I3: 2016年 | J3: 2017年 | K3: 2018年 | L3: 2019年 | M3: 2020年 | N3: 2021年 | O3: 2022年 | P3: 2016年 | Q3: 2017年 | R3: 2018年 | S3: 2019年 | T3: 2020年 | U3: 2021年 | V3: 2022年 | W3: 2016年 | X3: 2017年 | Y3: 2018年 | Z3: 2019年 | AA3: 2020年 | AB3: 2021年 | AC3: 2022年 | AD3: 2016年 | AE3: 2017年 | AF3: 2018年 | AG3: 2019年 | AH3: 2020年 | AI3: 2021年 | AJ3: 2022年 | AK3: 2016年 | AL3: 2017年 | AM3: 2018年 | AN3: 2019年 | AO3: 2020年 | AP3: 2021年 | AQ3: 2022年 | AR3: 2016年 | AS3: 2017年 | AT3: 2018年 | AU3: 2019年 | AV3: 2020年 | AW3: 2021年 | AX3: 2022年 | BA3: 2017 | BB3: 2018 | BC3: 2019 | BD3: 2020 | BE3: 2021 | BF3: 2022 | BG3: 2017 | BH3: 2018 | BI3: 2019 | BJ3: 2020 | BK3: 2021 | BL3: 2022 | BM3: 2017 | BN3: 2018 | BO3: 2019 | BP3: 2020 | BQ3: 2021 | BR3: 2022
A4: 全国 | B4: 165051 | C4: 178451 | D4: 190012 | E4: 201006 | F4: 220540 | G4: 237777 | H4: 256798 | I4: 33207 | J4: 34411 | K4: 35259 | L4: 35804 | M4: 37028 | N4: 39094 | O4: 41406 | P4: 106094 | Q4: 111009 | R4: 114408 | S4: 118957 | T4: 124960 | U4: 129739 | V4: 133329 | W4: 3364 | X4: 3582 | Y4: 4466 | Z4: 4874 | AA4: 4989 | AB4: 5326 | AC4: 5557 | AD4: 14747 | AE4: 16400 | AF4: 18427 | AG4: 20915 | AH4: 28165 | AI4: 32871 | AJ4: 36564 | AK4: 7631 | AL4: 13042 | AM4: 17433 | AN4: 20429 | AO4: 25356 | AP4: 30654 | AQ4: 39268 | AS4: 7 | AT4: 20 | AU4: 37 | AV4: 41 | AW4: 94 | AX4: 675 | AZ4: 全国 | BA4: =IFERROR(X40/AVERAGE(W4:X4)*10000/8760,"") -> 0.81548856 | BB4: =IFERROR(Y40/AVERAGE(X4:Y4)*10000/8760,"") -> 0.83687373 | BC4: =IFERROR(Z40/AVERAGE(Y4:Z4)*10000/8760,"") -> 0.8523755 | BD4: =IFERROR(AA40/AVERAGE(Z4:AA4)*10000/8760,"") -> 0.84768636 | BE4: =IFERROR(AB40/AVERAGE(AA4:AB4)*10000/8760,"") -> 0.90195375 | BF4: =IFERROR(AC40/AVERAGE(AB4:AC4)*10000/8760,"") -> 0.87648744 | BG4: =IFERROR(AE40/AVERAGE(AD4:AE4)*10000/8760,"") -> 0.22327473 | BH4: =IFERROR(AF40/AVERAGE(AE4:AF4)*10000/8760,"") -> 0.2398024 | BI4: =IFERROR(AG40/AVERAGE(AF4:AG4)*10000/8760,"") -> 0.23520473 | BJ4: =IFERROR(AH40/AVERAGE(AG4:AH4)*10000/8760,"") -> 0.21700662 | BK4: =IFERROR(AI40/AVERAGE(AH4:AI4)*10000/8760,"") -> 0.24530773 | BL4: =IFERROR(AJ40/AVERAGE(AI4:AJ4)*10000/8760,"") -> 0.25068615 | BM4: =IFERROR(J40/((I4+J4)/2)*10000/8760,"") -> 0.4033875 | BN4: =IFERROR(K40/((J4+K4)/2)*10000/8760,"") -> 0.40376255 | BO4: =IFERROR(L40/((K4+L4)/2)*10000/8760,"") -> 0.4183374 | BP4: =IFERROR(M40/((L4+M4)/2)*10000/8760,"") -> 0.42485339 | BQ4: =IFERROR(N40/((M4+N4)/2)*10000/8760,"") -> 0.40187231 | BR4: =IFERROR(O40/((N4+O4)/2)*10000/8760,"") -> 0.38336311
A5: 北京 | B5: 1103 | C5: 1219 | D5: 1276 | E5: 1304 | F5: 1316 | G5: 1340 | H5: 1361 | I5: 98 | J5: 98 | K5: 98 | L5: 99 | M5: 99 | N5: 99 | O5: 102 | P5: 971 | Q5: 1077 | R5: 1119 | S5: 1135 | T5: 1136 | U5: 1137 | V5: 1137 | AD5: 19 | AE5: 19 | AF5: 19 | AG5: 19 | AH5: 19 | AI5: 24 | AJ5: 24 | AK5: 15 | AL5: 25 | AM5: 40 | AN5: 51 | AO5: 62 | AP5: 80 | AQ5: 95 | AX5: 3 | AZ5: 北京 | BA5: =IFERROR(X41/AVERAGE(W5:X5)*10000/8760,"") | BB5: =IFERROR(Y41/AVERAGE(X5:Y5)*10000/8760,"") | BC5: =IFERROR(Z41/AVERAGE(Y5:Z5)*10000/8760,"") | BD5: =IFERROR(AA41/AVERAGE(Z5:AA5)*10000/8760,"") | BE5: =IFERROR(AB41/AVERAGE(AA5:AB5)*10000/8760,"") | BF5: =IFERROR(AC41/AVERAGE(AB5:AC5)*10000/8760,"") | BG5: =IFERROR(AE41/AVERAGE(AD5:AE5)*10000/8760,"") -> 0.18024513 | BH5: =IFERROR(AF41/AVERAGE(AE5:AF5)*10000/8760,"") -> 0.18024513 | BI5: =IFERROR(AG41/AVERAGE(AF5:AG5)*10000/8760,"") -> 0.18024513 | BJ5: =IFERROR(AH41/AVERAGE(AG5:AH5)*10000/8760,"") -> 0.24032684 | BK5: =IFERROR(AI41/AVERAGE(AH5:AI5)*10000/8760,"") -> 0.21238186 | BL5: =IFERROR(AJ41/AVERAGE(AI5:AJ5)*10000/8760,"") -> 0.23782344 | BM5: =IFERROR(J41/((I5+J5)/2)*10000/8760,"") -> 0.12813345 | BN5: =IFERROR(K41/((J5+K5)/2)*10000/8760,"") -> 0.11648495 | BO5: =IFERROR(L41/((K5+L5)/2)*10000/8760,"") -> 0.11589366 | BP5: =IFERROR(M41/((L5+M5)/2)*10000/8760,"") -> 0.12683917 | BQ5: =IFERROR(N41/((M5+N5)/2)*10000/8760,"") -> 0.16143167 | BR5: =IFERROR(O41/((N5+O5)/2)*10000/8760,"") -> 0.10222858
A6: 天津 | B6: 1467 | C6: 1499 | D6: 1709 | E6: 1842 | F6: 1917 | G6: 2192 | H6: 2262 | I6: 1 | J6: 1 | K6: 1 | L6: 1 | M6: 1 | N6: 1 | O6: 1 | P6: 1378 | Q6: 1402 | R6: 1529 | S6: 1639 | T6: 1668 | U6: 1884 | V6: 1896 | AD6: 29 | AE6: 29 | AF6: 52 | AG6: 60 | AH6: 85 | AI6: 130 | AJ6: 145 | AK6: 60 | AL6: 68 | AM6: 128 | AN6: 143 | AO6: 164 | AP6: 178 | AQ6: 221 | AX6: 0.001 | AZ6: 天津 | BA6: =IFERROR(X42/AVERAGE(W6:X6)*10000/8760,"") | BB6: =IFERROR(Y42/AVERAGE(X6:Y6)*10000/8760,"") | BC6: =IFERROR(Z42/AVERAGE(Y6:Z6)*10000/8760,"") | BD6: =IFERROR(AA42/AVERAGE(Z6:AA6)*10000/8760,"") | BE6: =IFERROR(AB42/AVERAGE(AA6:AB6)*10000/8760,"") | BF6: =IFERROR(AC42/AVERAGE(AB6:AC6)*10000/8760,"") | BG6: =IFERROR(AE42/AVERAGE(AD6:AE6)*10000/8760,"") -> 0.23618328 | BH6: =IFERROR(AF42/AVERAGE(AE6:AF6)*10000/8760,"") -> 0.22549185 | BI6: =IFERROR(AG42/AVERAGE(AF6:AG6)*10000/8760,"") -> 0.22423353 | BJ6: =IFERROR(AH42/AVERAGE(AG6:AH6)*10000/8760,"") -> 0.18894662 | BK6: =IFERROR(AI42/AVERAGE(AH6:AI6)*10000/8760,"") -> 0.19114368 | BL6: =IFERROR(AJ42/AVERAGE(AI6:AJ6)*10000/8760,"") -> 0.2158572 | BM6: =IFERROR(J42/((I6+J6)/2)*10000/8760,"") -> 0.079908676 | BN6: =IFERROR(K42/((J6+K6)/2)*10000/8760,"") -> 0.17123288 | BO6: =IFERROR(L42/((K6+L6)/2)*10000/8760,"") -> 0.1369863 | BP6: =IFERROR(M42/((L6+M6)/2)*10000/8760,"") -> 0.11415525 | BQ6: =IFERROR(N42/((M6+N6)/2)*10000/8760,"") -> 0.2283105 | BR6: =IFERROR(O42/((N6+O6)/2)*10000/8760,"") -> 0.11415525
A7: 河北 | B7: 6275 | C7: 6807 | D7: 7427 | E7: 8319 | F7: 10042 | G7: 11078 | H7: 12459 | I7: 182 | J7: 182 | K7: 182 | L7: 182 | M7: 182 | N7: 182 | O7: 393 | P7: 4510 | Q7: 4574 | R7: 4617 | S7: 5021 | T7: 5391 | U7: 5424 | V7: 5383 | AD7: 1138 | AE7: 1181 | AF7: 1391 | AG7: 1639 | AH7: 2274 | AI7: 2546 | AJ7: 2797 | AK7: 443 | AL7: 868 | AM7: 1234 | AN7: 1474 | AO7: 2190 | AP7: 2921 | AQ7: 3855 | AS7: 2 | AT7: 3 | AU7: 3 | AV7: 4 | AW7: 4 | AX7: 31 | AZ7: 河北 | BA7: =IFERROR(X43/AVERAGE(W7:X7)*10000/8760,"") | BB7: =IFERROR(Y43/AVERAGE(X7:Y7)*10000/8760,"") | BC7: =IFERROR(Z43/AVERAGE(Y7:Z7)*10000/8760,"") | BD7: =IFERROR(AA43/AVERAGE(Z7:AA7)*10000/8760,"") | BE7: =IFERROR(AB43/AVERAGE(AA7:AB7)*10000/8760,"") | BF7: =IFERROR(AC43/AVERAGE(AB7:AC7)*10000/8760,"") | BG7: =IFERROR(AE43/AVERAGE(AD7:AE7)*10000/8760,"") -> 0.25892912 | BH7: =IFERROR(AF43/AVERAGE(AE7:AF7)*10000/8760,"") -> 0.25121257 | BI7: =IFERROR(AG43/AVERAGE(AF7:AG7)*10000/8760,"") -> 0.239613 | BJ7: =IFERROR(AH43/AVERAGE(AG7:AH7)*10000/8760,"") -> 0.21471573 | BK7: =IFERROR(AI43/AVERAGE(AH7:AI7)*10000/8760,"") -> 0.24204703 | BL7: =IFERROR(AJ43/AVERAGE(AI7:AJ7)*10000/8760,"") -> 0.25082962 | BM7: =IFERROR(J43/((I7+J7)/2)*10000/8760,"") -> 0.12544533 | BN7: =IFERROR(K43/((J7+K7)/2)*10000/8760,"") -> 0.10662853 | BO7: =IFERROR(L43/((K7+L7)/2)*10000/8760,"") -> 0.10035626 | BP7: =IFERROR(M43/((L7+M7)/2)*10000/8760,"") -> 0.094083998 | BQ7: =IFERROR(N43/((M7+N7)/2)*10000/8760,"") -> 0.1505344 | BR7: =IFERROR(O43/((N7+O7)/2)*10000/8760,"") -> 0.14691284
A8: 山西 | B8: 7640 | C8: 8073 | D8: 8758 | E8: 9249 | F8: 10383 | G8: 11338 | H8: 12091 | I8: 244 | J8: 244 | K8: 223 | L8: 223 | M8: 223 | N8: 224 | O8: 224 | P8: 6329 | Q8: 6366 | R8: 6628 | S8: 6687 | T8: 6878 | U8: 7533 | V8: 7842 | AD8: 771 | AE8: 872 | AF8: 1043 | AG8: 1251 | AH8: 1974 | AI8: 2123 | AJ8: 2318 | AK8: 297 | AL8: 590 | AM8: 864 | AN8: 1088 | AO8: 1309 | AP8: 1458 | AQ8: 1696 | AX8: 11 | AZ8: 山西 | BA8: =IFERROR(X44/AVERAGE(W8:X8)*10000/8760,"") | BB8: =IFERROR(Y44/AVERAGE(X8:Y8)*10000/8760,"") | BC8: =IFERROR(Z44/AVERAGE(Y8:Z8)*10000/8760,"") | BD8: =IFERROR(AA44/AVERAGE(Z8:AA8)*10000/8760,"") | BE8: =IFERROR(AB44/AVERAGE(AA8:AB8)*10000/8760,"") | BF8: =IFERROR(AC44/AVERAGE(AB8:AC8)*10000/8760,"") | BG8: =IFERROR(AE44/AVERAGE(AD8:AE8)*10000/8760,"") -> 0.22928322 | BH8: =IFERROR(AF44/AVERAGE(AE8:AF8)*10000/8760,"") -> 0.25275105 | BI8: =IFERROR(AG44/AVERAGE(AF8:AG8)*10000/8760,"") -> 0.22293615 | BJ8: =IFERROR(AH44/AVERAGE(AG8:AH8)*10000/8760,"") -> 0.18831192 | BK8: =IFERROR(AI44/AVERAGE(AH8:AI8)*10000/8760,"") -> 0.26135618 | BL8: =IFERROR(AJ44/AVERAGE(AI8:AJ8)*10000/8760,"") -> 0.23956923 | BM8: =IFERROR(J44/((I8+J8)/2)*10000/8760,"") -> 0.19649674 | BN8: =IFERROR(K44/((J8+K8)/2)*10000/8760,"") -> 0.21022166 | BO8: =IFERROR(L44/((K8+L8)/2)*10000/8760,"") -> 0.25083441 | BP8: =IFERROR(M44/((L8+M8)/2)*10000/8760,"") -> 0.24059627 | BQ8: =IFERROR(N44/((M8+N8)/2)*10000/8760,"") -> 0.19919708 | BR8: =IFERROR(O44/((N8+O8)/2)*10000/8760,"") -> 0.1834638
A9: 内蒙古 | B9: 11045 | C9: 11826 | D9: 12285 | E9: 12931 | F9: 14639 | G9: 15487 | H9: 16915 | I9: 241 | J9: 242 | K9: 242 | L9: 239 | M9: 242 | N9: 241 | O9: 241 | P9: 7609 | Q9: 8170 | R9: 8229 | S9: 8721 | T9: 9374 | U9: 9834 | V9: 10503 | AD9: 2557 | AE9: 2670 | AF9: 2868 | AG9: 2920 | AH9: 3786 | AI9: 3996 | AJ9: 4568 | AK9: 638 | AL9: 743 | AM9: 946 | AN9: 1051 | AO9: 1237 | AP9: 1412 | AQ9: 1568 | AW9: 3 | AX9: 35 | AZ9: 内蒙古 | BA9: =IFERROR(X45/AVERAGE(W9:X9)*10000/8760,"") | BB9: =IFERROR(Y45/AVERAGE(X9:Y9)*10000/8760,"") | BC9: =IFERROR(Z45/AVERAGE(Y9:Z9)*10000/8760,"") | BD9: =IFERROR(AA45/AVERAGE(Z9:AA9)*10000/8760,"") | BE9: =IFERROR(AB45/AVERAGE(AA9:AB9)*10000/8760,"") | BF9: =IFERROR(AC45/AVERAGE(AB9:AC9)*10000/8760,"") | BG9: =IFERROR(AE45/AVERAGE(AD9:AE9)*10000/8760,"") -> 0.24067168 | BH9: =IFERROR(AF45/AVERAGE(AE9:AF9)*10000/8760,"") -> 0.26054936 | BI9: =IFERROR(AG45/AVERAGE(AF9:AG9)*10000/8760,"") -> 0.26270697 | BJ9: =IFERROR(AH45/AVERAGE(AG9:AH9)*10000/8760,"") -> 0.24717182 | BK9: =IFERROR(AI45/AVERAGE(AH9:AI9)*10000/8760,"") -> 0.28370118 | BL9: =IFERROR(AJ45/AVERAGE(AI9:AJ9)*10000/8760,"") -> 0.28712098 | BM9: =IFERROR(J45/((I9+J9)/2)*10000/8760,"") -> 0.11344621 | BN9: =IFERROR(K45/((J9+K9)/2)*10000/8760,"") -> 0.21227216 | BO9: =IFERROR(L45/((K9+L9)/2)*10000/8760,"") -> 0.27530165 | BP9: =IFERROR(M45/((L9+M9)/2)*10000/8760,"") -> 0.27055507 | BQ9: =IFERROR(N45/((M9+N9)/2)*10000/8760,"") -> 0.29306938 | BR9: =IFERROR(O45/((N9+O9)/2)*10000/8760,"") -> 0.20367949
A10: 辽宁 | B10: 4601 | C10: 4869 | D10: 5192 | E10: 5370 | F10: 5776 | G10: 6164 | H10: 6595 | I10: 293 | J10: 295 | K10: 299 | L10: 302 | M10: 305 | N10: 305 | O10: 305 | P10: 3114 | Q10: 3193 | R10: 3383 | S10: 3446 | T10: 3643 | U10: 3737 | V10: 3835 | W10: 448 | X10: 448 | Y10: 448 | Z10: 448 | AA10: 448 | AB10: 558 | AC10: 668 | AD10: 695 | AE10: 711 | AF10: 761 | AG10: 832 | AH10: 981 | AI10: 1087 | AJ10: 1173 | AK10: 52 | AL10: 223 | AM10: 302 | AN10: 343 | AO10: 400 | AP10: 478 | AQ10: 601 | AX10: 15 | AZ10: 辽宁 | BA10: =IFERROR(X46/AVERAGE(W10:X10)*10000/8760,"") -> 0.60135356 | BB10: =IFERROR(Y46/AVERAGE(X10:Y10)*10000/8760,"") -> 0.7695287 | BC10: =IFERROR(Z46/AVERAGE(Y10:Z10)*10000/8760,"") -> 0.83323141 | BD10: =IFERROR(AA46/AVERAGE(Z10:AA10)*10000/8760,"") -> 0.83323141 | BE10: =IFERROR(AB46/AVERAGE(AA10:AB10)*10000/8760,"") -> 0.90779524 | BF10: =IFERROR(AC46/AVERAGE(AB10:AC10)*10000/8760,"") -> 0.84173203 | BG10: =IFERROR(AE46/AVERAGE(AD10:AE10)*10000/8760,"") -> 0.2435745 | BH10: =IFERROR(AF46/AVERAGE(AE10:AF10)*10000/8760,"") -> 0.2559187 | BI10: =IFERROR(AG46/AVERAGE(AF10:AG10)*10000/8760,"") -> 0.2622776 | BJ10: =IFERROR(AH46/AVERAGE(AG10:AH10)*10000/8760,"") -> 0.24430357 | BK10: =IFERROR(AI46/AVERAGE(AH10:AI10)*10000/8760,"") -> 0.25061162 | BL10: =IFERROR(AJ46/AVERAGE(AI10:AJ10)*10000/8760,"") -> 0.25760698 | BM10: =IFERROR(J46/((I10+J10)/2)*10000/8760,"") -> 0.17472743 | BN10: =IFERROR(K46/((J10+K10)/2)*10000/8760,"") -> 0.17680611 | BO10: =IFERROR(L46/((K10+L10)/2)*10000/8760,"") -> 0.16714912 | BP10: =IFERROR(M46/((L10+M10)/2)*10000/8760,"") -> 0.21439372 | BQ10: =IFERROR(N46/((M10+N10)/2)*10000/8760,"") -> 0.29193802 | BR10: =IFERROR(O46/((N10+O10)/2)*10000/8760,"") -> 0.29942361
A11: 吉林 | B11: 2716 | C11: 2864 | D11: 3055 | E11: 3122 | F11: 3278 | G11: 3485 | H11: 4030 | I11: 378 | J11: 380 | K11: 385 | L11: 445 | M11: 510 | N11: 619 | O11: 646 | P11: 1777 | Q11: 1820 | R11: 1892 | S11: 1845 | T11: 1852 | U11: 1855 | V11: 1855 | AD11: 505 | AE11: 505 | AF11: 514 | AG11: 557 | AH11: 577 | AI11: 665 | AJ11: 1143 | AK11: 56 | AL11: 159 | AM11: 265 | AN11: 274 | AO11: 338 | AP11: 346 | AQ11: 387 | AZ11: 吉林 | BA11: =IFERROR(X47/AVERAGE(W11:X11)*10000/8760,"") | BB11: =IFERROR(Y47/AVERAGE(X11:Y11)*10000/8760,"") | BC11: =IFERROR(Z47/AVERAGE(Y11:Z11)*10000/8760,"") | BD11: =IFERROR(AA47/AVERAGE(Z11:AA11)*10000/8760,"") | BE11: =IFERROR(AB47/AVERAGE(AA11:AB11)*10000/8760,"") | BF11: =IFERROR(AC47/AVERAGE(AB11:AC11)*10000/8760,"") | BG11: =IFERROR(AE47/AVERAGE(AD11:AE11)*10000/8760,"") -> 0.1966635 | BH11: =IFERROR(AF47/AVERAGE(AE11:AF11)*10000/8760,"") -> 0.23525616 | BI11: =IFERROR(AG47/AVERAGE(AF11:AG11)*10000/8760,"") -> 0.24515133 | BJ11: =IFERROR(AH47/AVERAGE(AG11:AH11)*10000/8760,"") -> 0.26173162 | BK11: =IFERROR(AI47/AVERAGE(AH11:AI11)*10000/8760,"") -> 0.25367834 | BL11: =IFERROR(AJ47/AVERAGE(AI11:AJ11)*10000/8760,"") -> 0.25381864 | BM11: =IFERROR(J47/((I11+J11)/2)*10000/8760,"") -> 0.23192492 | BN11: =IFERROR(K47/((J11+K11)/2)*10000/8760,"") -> 0.23577163 | BO11: =IFERROR(L47/((K11+L11)/2)*10000/8760,"") -> 0.18429884 | BP11: =IFERROR(M47/((L11+M11)/2)*10000/8760,"") -> 0.22472447 | BQ11: =IFERROR(N47/((M11+N11)/2)*10000/8760,"") -> 0.21233483 | BR11: =IFERROR(O47/((N11+O11)/2)*10000/8760,"") -> 0.21296948
A12: 黑龙江 | B12: 2783 | C12: 2969 | D12: 3129 | E12: 3246 | F12: 3536 | G12: 3955 | H12: 4180 | I12: 102 | J12: 103 | K12: 104 | L12: 108 | M12: 109 | N12: 169 | O12: 230 | P12: 2104 | Q12: 2201 | R12: 2212 | S12: 2253 | T12: 2423 | U12: 2531 | V12: 2531 | AD12: 561 | AE12: 570 | AF12: 598 | AG12: 611 | AH12: 686 | AI12: 835 | AJ12: 943 | AK12: 17 | AL12: 94 | AM12: 215 | AN12: 274 | AO12: 318 | AP12: 420 | AQ12: 475 | AZ12: 黑龙江 | BA12: =IFERROR(X48/AVERAGE(W12:X12)*10000/8760,"") | BB12: =IFERROR(Y48/AVERAGE(X12:Y12)*10000/8760,"") | BC12: =IFERROR(Z48/AVERAGE(Y12:Z12)*10000/8760,"") | BD12: =IFERROR(AA48/AVERAGE(Z12:AA12)*10000/8760,"") | BE12: =IFERROR(AB48/AVERAGE(AA12:AB12)*10000/8760,"") | BF12: =IFERROR(AC48/AVERAGE(AB12:AC12)*10000/8760,"") | BG12: =IFERROR(AE48/AVERAGE(AD12:AE12)*10000/8760,"") -> 0.21801533 | BH12: =IFERROR(AF48/AVERAGE(AE12:AF12)*10000/8760,"") -> 0.24433915 | BI12: =IFERROR(AG48/AVERAGE(AF12:AG12)*10000/8760,"") -> 0.26437941 | BJ12: =IFERROR(AH48/AVERAGE(AG12:AH12)*10000/8760,"") -> 0.24820186 | BK12: =IFERROR(AI48/AVERAGE(AH12:AI12)*10000/8760,"") -> 0.24317095 | BL12: =IFERROR(AJ48/AVERAGE(AI12:AJ12)*10000/8760,"") -> 0.29277162 | BM12: =IFERROR(J48/((I12+J12)/2)*10000/8760,"") -> 0.27842744 | BN12: =IFERROR(K48/((J12+K12)/2)*10000/8760,"") -> 0.28676681 | BO12: =IFERROR(L48/((K12+L12)/2)*10000/8760,"") -> 0.30154217 | BP12: =IFERROR(M48/((L12+M12)/2)*10000/8760,"") -> 0.33667908 | BQ12: =IFERROR(N48/((M12+N12)/2)*10000/8760,"") -> 0.22174042 | BR12: =IFERROR(O48/((N12+O12)/2)*10000/8760,"") -> 0.22888271
A13: 上海 | B13: 2371 | C13: 2400 | D13: 2525 | E13: 2664 | F13: 2669 | G13: 2786 | H13: 2830 | P13: 2264 | Q13: 2271 | R13: 2365 | S13: 2475 | T13: 2450 | U13: 2510 | V13: 2528 | AD13: 71 | AE13: 71 | AF13: 71 | AG13: 81 | AH13: 82 | AI13: 107 | AJ13: 107 | AK13: 35 | AL13: 58 | AM13: 89 | AN13: 109 | AO13: 137 | AP13: 168 | AQ13: 195 | AZ13: 上海 | BA13: =IFERROR(X49/AVERAGE(W13:X13)*10000/8760,"") | BB13: =IFERROR(Y49/AVERAGE(X13:Y13)*10000/8760,"") | BC13: =IFERROR(Z49/AVERAGE(Y13:Z13)*10000/8760,"") | BD13: =IFERROR(AA49/AVERAGE(Z13:AA13)*10000/8760,"") | BE13: =IFERROR(AB49/AVERAGE(AA13:AB13)*10000/8760,"") | BF13: =IFERROR(AC49/AVERAGE(AB13:AC13)*10000/8760,"") | BG13: =IFERROR(AE49/AVERAGE(AD13:AE13)*10000/8760,"") -> 0.27332947 | BH13: =IFERROR(AF49/AVERAGE(AE13:AF13)*10000/8760,"") -> 0.28940768 | BI13: =IFERROR(AG49/AVERAGE(AF13:AG13)*10000/8760,"") -> 0.25534727 | BJ13: =IFERROR(AH49/AVERAGE(AG13:AH13)*10000/8760,"") -> 0.26612881 | BK13: =IFERROR(AI49/AVERAGE(AH13:AI13)*10000/8760,"") -> 0.21743857 | BL13: =IFERROR(AJ49/AVERAGE(AI13:AJ13)*10000/8760,"") -> 0.26671788 | BM13: =IFERROR(J49/((I13+J13)/2)*10000/8760,"") | BN13: =IFERROR(K49/((J13+K13)/2)*10000/8760,"") | BO13: =IFERROR(L49/((K13+L13)/2)*10000/8760,"") | BP13: =IFERROR(M49/((L13+M13)/2)*10000/8760,"") | BQ13: =IFERROR(N49/((M13+N13)/2)*10000/8760,"") | BR13: =IFERROR(O49/((N13+O13)/2)*10000/8760,"")
A14: 江苏 | B14: 10160 | C14: 11469 | D14: 12657 | E14: 13288 | F14: 14146 | G14: 15420 | H14: 16156 | I14: 115 | J14: 265 | K14: 265 | L14: 265 | M14: 265 | N14: 265 | O14: 265 | P14: 8727 | Q14: 9430 | R14: 9749 | S14: 10050 | T14: 10079 | U14: 10322 | V14: 10437 | W14: 212 | X14: 212 | Y14: 437 | Z14: 437 | AA14: 549 | AB14: 661 | AC14: 661 | AD14: 561 | AE14: 656 | AF14: 865 | AG14: 1041 | AH14: 1547 | AI14: 2234 | AJ14: 2254 | AK14: 546 | AL14: 907 | AM14: 1332 | AN14: 1486 | AO14: 1684 | AP14: 1916 | AQ14: 2508 | AT14: 10 | AU14: 10 | AV14: 23 | AW14: 23 | AX14: 30 | AZ14: 江苏 | BA14: =IFERROR(X50/AVERAGE(W14:X14)*10000/8760,"") -> 0.93154993 | BB14: =IFERROR(Y50/AVERAGE(X14:Y14)*10000/8760,"") -> 0.8513273 | BC14: =IFERROR(Z50/AVERAGE(Y14:Z14)*10000/8760,"") -> 0.85942969 | BD14: =IFERROR(AA50/AVERAGE(Z14:AA14)*10000/8760,"") -> 0.82201043 | BE14: =IFERROR(AB50/AVERAGE(AA14:AB14)*10000/8760,"") -> 0.91512887 | BF14: =IFERROR(AC50/AVERAGE(AB14:AC14)*10000/8760,"") -> 0.90840639 | BG14: =IFERROR(AE50/AVERAGE(AD14:AE14)*10000/8760,"") -> 0.22512128 | BH14: =IFERROR(AF50/AVERAGE(AE14:AF14)*10000/8760,"") -> 0.25968256 | BI14: =IFERROR(AG50/AVERAGE(AF14:AG14)*10000/8760,"") -> 0.22040468 | BJ14: =IFERROR(AH50/AVERAGE(AG14:AH14)*10000/8760,"") -> 0.20202127 | BK14: =IFERROR(AI50/AVERAGE(AH14:AI14)*10000/8760,"") -> 0.2511959 | BL14: =IFERROR(AJ50/AVERAGE(AI14:AJ14)*10000/8760,"") -> 0.26096989 | BM14: =IFERROR(J50/((I14+J14)/2)*10000/8760,"") -> 0.17423696 | BN14: =IFERROR(K50/((J14+K14)/2)*10000/8760,"") -> 0.14646334 | BO14: =IFERROR(L50/((K14+L14)/2)*10000/8760,"") -> 0.13354011 | BP14: =IFERROR(M50/((L14+M14)/2)*10000/8760,"") -> 0.13784785 | BQ14: =IFERROR(N50/((M14+N14)/2)*10000/8760,"") -> 0.13354011 | BR14: =IFERROR(O50/((N14+O14)/2)*10000/8760,"") -> 0.13354011
A15: 浙江 | B15: 8331 | C15: 8899 | D15: 9565 | E15: 9789 | F15: 10142 | G15: 10857 | H15: 11810 | I15: 1154 | J15: 1160 | K15: 1161 | L15: 1170 | M15: 1171 | N15: 1278 | O15: 1384 | P15: 6062 | Q15: 6134 | R15: 6209 | S15: 6212 | T15: 6358 | U15: 6462 | V15: 6534 | W15: 657 | X15: 657 | Y15: 908 | Z15: 908 | AA15: 911 | AB15: 911 | AC15: 917 | AD15: 119 | AE15: 133 | AF15: 148 | AG15: 160 | AH15: 186 | AI15: 364 | AJ15: 423 | AK15: 338 | AL15: 814 | AM15: 1138 | AN15: 1339 | AO15: 1517 | AP15: 1842 | AQ15: 2539 | AS15: 0.4 | AT15: 0.4 | AU15: 1 | AV15: 1 | AW15: 1 | AX15: 14 | AZ15: 浙江 | BA15: =IFERROR(X51/AVERAGE(W15:X15)*10000/8760,"") -> 0.88787418 | BB15: =IFERROR(Y51/AVERAGE(X15:Y15)*10000/8760,"") -> 0.85634674 | BC15: =IFERROR(Z51/AVERAGE(Y15:Z15)*10000/8760,"") -> 0.79078913 | BD15: =IFERROR(AA51/AVERAGE(Z15:AA15)*10000/8760,"") -> 0.89366178 | BE15: =IFERROR(AB51/AVERAGE(AA15:AB15)*10000/8760,"") -> 0.91850493 | BF15: =IFERROR(AC51/AVERAGE(AB15:AC15)*10000/8760,"") -> 0.91299222 | BG15: =IFERROR(AE51/AVERAGE(AD15:AE15)*10000/8760,"") -> 0.22649851 | BH15: =IFERROR(AF51/AVERAGE(AE15:AF15)*10000/8760,"") -> 0.2518728 | BI15: =IFERROR(AG51/AVERAGE(AF15:AG15)*10000/8760,"") -> 0.2446184 | BJ15: =IFERROR(AH51/AVERAGE(AG15:AH15)*10000/8760,"") -> 0.2375485 | BK15: =IFERROR(AI51/AVERAGE(AH15:AI15)*10000/8760,"") -> 0.2034039 | BL15: =IFERROR(AJ51/AVERAGE(AI15:AJ15)*10000/8760,"") -> 0.27559718 | BM15: =IFERROR(J51/((I15+J15)/2)*10000/8760,"") -> 0.20916952 | BN15: =IFERROR(K51/((J15+K15)/2)*10000/8760,"") -> 0.18886522 | BO15: =IFERROR(L51/((K15+L15)/2)*10000/8760,"") -> 0.25171943 | BP15: =IFERROR(M51/((L15+M15)/2)*10000/8760,"") -> 0.20383125 | BQ15: =IFERROR(N51/((M15+N15)/2)*10000/8760,"") -> 0.22187791 | BR15: =IFERROR(O51/((N15+O15)/2)*10000/8760,"") -> 0.21098566
A16: 安徽 | B16: 5733 | C16: 6468 | D16: 7089 | E16: 7394 | F16: 7816 | G16: 8466 | H16: 9254 | I16: 295 | J16: 310 | K16: 312 | L16: 345 | M16: 474 | N16: 507 | O16: 622 | P16: 4915 | Q16: 5053 | R16: 5413 | S16: 5521 | T16: 5561 | U16: 5740 | V16: 5853 | AD16: 177 | AE16: 217 | AF16: 246 | AG16: 274 | AH16: 412 | AI16: 511 | AJ16: 590 | AK16: 345 | AL16: 888 | AM16: 1118 | AN16: 1254 | AO16: 1370 | AP16: 1707 | AQ16: 2154 | AX16: 35 | AZ16: 安徽 | BA16: =IFERROR(X52/AVERAGE(W16:X16)*10000/8760,"") | BB16: =IFERROR(Y52/AVERAGE(X16:Y16)*10000/8760,"") | BC16: =IFERROR(Z52/AVERAGE(Y16:Z16)*10000/8760,"") | BD16: =IFERROR(AA52/AVERAGE(Z16:AA16)*10000/8760,"") | BE16: =IFERROR(AB52/AVERAGE(AA16:AB16)*10000/8760,"") | BF16: =IFERROR(AC52/AVERAGE(AB16:AC16)*10000/8760,"") | BG16: =IFERROR(AE52/AVERAGE(AD16:AE16)*10000/8760,"") -> 0.23758199 | BH16: =IFERROR(AF52/AVERAGE(AE16:AF16)*10000/8760,"") -> 0.24655562 | BI16: =IFERROR(AG52/AVERAGE(AF16:AG16)*10000/8760,"") -> 0.20635757 | BJ16: =IFERROR(AH52/AVERAGE(AG16:AH16)*10000/8760,"") -> 0.18970406 | BK16: =IFERROR(AI52/AVERAGE(AH16:AI16)*10000/8760,"") -> 0.26467198 | BL16: =IFERROR(AJ52/AVERAGE(AI16:AJ16)*10000/8760,"") -> 0.24261879 | BM16: =IFERROR(J52/((I16+J16)/2)*10000/8760,"") -> 0.21510246 | BN16: =IFERROR(K52/((J16+K16)/2)*10000/8760,"") -> 0.1945411 | BO16: =IFERROR(L52/((K16+L16)/2)*10000/8760,"") -> 0.17722733 | BP16: =IFERROR(M52/((L16+M16)/2)*10000/8760,"") -> 0.18398649 | BQ16: =IFERROR(N52/((M16+N16)/2)*10000/8760,"") -> 0.18851326 | BR16: =IFERROR(O52/((N16+O16)/2)*10000/8760,"") -> 0.14560103
A17: 福建 | B17: 5210 | C17: 5597 | D17: 5770 | E17: 5909 | F17: 6372 | G17: 6983 | H17: 7531 | I17: 1304 | J17: 1307 | K17: 1322 | L17: 1321 | M17: 1331 | N17: 1386 | O17: 1538 | P17: 2902 | Q17: 3074 | R17: 3128 | S17: 3172 | T17: 3478 | U17: 3596 | V17: 3681 | W17: 762 | X17: 871 | Y17: 871 | Z17: 871 | AA17: 871 | AB17: 986 | AC17: 1101 | AD17: 214 | AE17: 252 | AF17: 300 | AG17: 376 | AH17: 486 | AI17: 735 | AJ17: 742 | AK17: 27 | AL17: 92 | AM17: 148 | AN17: 169 | AO17: 202 | AP17: 277 | AQ17: 465 | AV17: 3 | AW17: 3 | AX17: 3 | AZ17: 福建 | BA17: =IFERROR(X53/AVERAGE(W17:X17)*10000/8760,"") -> 0.78293865 | BB17: =IFERROR(Y53/AVERAGE(X17:Y17)*10000/8760,"") -> 0.84666237 | BC17: =IFERROR(Z53/AVERAGE(Y17:Z17)*10000/8760,"") -> 0.8138968 | BD17: =IFERROR(AA53/AVERAGE(Z17:AA17)*10000/8760,"") -> 0.8545261 | BE17: =IFERROR(AB53/AVERAGE(AA17:AB17)*10000/8760,"") -> 0.9552895 | BF17: =IFERROR(AC53/AVERAGE(AB17:AC17)*10000/8760,"") -> 0.91017891 | BG17: =IFERROR(AE53/AVERAGE(AD17:AE17)*10000/8760,"") -> 0.31845886 | BH17: =IFERROR(AF53/AVERAGE(AE17:AF17)*10000/8760,"") -> 0.29779631 | BI17: =IFERROR(AG53/AVERAGE(AF17:AG17)*10000/8760,"") -> 0.29383156 | BJ17: =IFERROR(AH53/AVERAGE(AG17:AH17)*10000/8760,"") -> 0.32313087 | BK17: =IFERROR(AI53/AVERAGE(AH17:AI17)*10000/8760,"") -> 0.28421946 | BL17: =IFERROR(AJ53/AVERAGE(AI17:AJ17)*10000/8760,"") -> 0.3570733 | BM17: =IFERROR(J53/((I17+J17)/2)*10000/8760,"") -> 0.36375783 | BN17: =IFERROR(K53/((J17+K17)/2)*10000/8760,"") -> 0.28224007 | BO17: =IFERROR(L53/((K17+L17)/2)*10000/8760,"") -> 0.38181325 | BP17: =IFERROR(M53/((L17+M17)/2)*10000/8760,"") -> 0.2513826 | BQ17: =IFERROR(N53/((M17+N17)/2)*10000/8760,"") -> 0.2302432 | BR17: =IFERROR(O53/((N17+O17)/2)*10000/8760,"") -> 0.30217566
A18: 江西 | B18: 2866 | C18: 3167 | D18: 3554 | E18: 3782 | F18: 4401 | G18: 4847 | H18: 5490 | I18: 613 | J18: 615 | K18: 627 | L18: 661 | M18: 660 | N18: 677 | O18: 686 | P18: 1918 | Q18: 1934 | R18: 2165 | S18: 2205 | T18: 2455 | U18: 2711 | V18: 3026 | AD18: 108 | AE18: 169 | AF18: 225 | AG18: 286 | AH18: 510 | AI18: 547 | AJ18: 555 | AK18: 228 | AL18: 449 | AM18: 536 | AN18: 630 | AO18: 776 | AP18: 911 | AQ18: 1202 | AX18: 21 | AZ18: 江西 | BA18: =IFERROR(X54/AVERAGE(W18:X18)*10000/8760,"") | BB18: =IFERROR(Y54/AVERAGE(X18:Y18)*10000/8760,"") | BC18: =IFERROR(Z54/AVERAGE(Y18:Z18)*10000/8760,"") | BD18: =IFERROR(AA54/AVERAGE(Z18:AA18)*10000/8760,"") | BE18: =IFERROR(AB54/AVERAGE(AA18:AB18)*10000/8760,"") | BF18: =IFERROR(AC54/AVERAGE(AB18:AC18)*10000/8760,"") | BG18: =IFERROR(AE54/AVERAGE(AD18:AE18)*10000/8760,"") -> 0.25550995 | BH18: =IFERROR(AF54/AVERAGE(AE18:AF18)*10000/8760,"") -> 0.23758199 | BI18: =IFERROR(AG54/AVERAGE(AF18:AG18)*10000/8760,"") -> 0.22786371 | BJ18: =IFERROR(AH54/AVERAGE(AG18:AH18)*10000/8760,"") -> 0.20364379 | BK18: =IFERROR(AI54/AVERAGE(AH18:AI18)*10000/8760,"") -> 0.22463853 | BL18: =IFERROR(AJ54/AVERAGE(AI18:AJ18)*10000/8760,"") -> 0.26518824 | BM18: =IFERROR(J54/((I18+J18)/2)*10000/8760,"") -> 0.29189535 | BN18: =IFERROR(K54/((J18+K18)/2)*10000/8760,"") -> 0.21323686 | BO18: =IFERROR(L54/((K18+L18)/2)*10000/8760,"") -> 0.29779631 | BP18: =IFERROR(M54/((L18+M18)/2)*10000/8760,"") -> 0.25060577 | BQ18: =IFERROR(N54/((M18+N18)/2)*10000/8760,"") -> 0.23223806 | BR18: =IFERROR(O54/((N18+O18)/2)*10000/8760,"") -> 0.27135951
A19: 山东 | B19: 10942 | C19: 12556 | D19: 13107 | E19: 14044 | F19: 15896 | G19: 17334 | H19: 18958 | I19: 108 | J19: 108 | K19: 108 | L19: 108 | M19: 108 | N19: 168 | O19: 228 | P19: 9540 | Q19: 10335 | R19: 10367 | S19: 10713 | T19: 11471 | U19: 11599 | V19: 11753 | X19: 0 | Y19: 125 | Z19: 250 | AA19: 250 | AB19: 250 | AC19: 250 | AD19: 839 | AE19: 1061 | AF19: 1146 | AG19: 1354 | AH19: 1795 | AI19: 1942 | AJ19: 2302 | AK19: 455 | AL19: 1052 | AM19: 1361 | AN19: 1619 | AO19: 2272 | AP19: 3343 | AQ19: 4270 | AW19: 31 | AX19: 155 | AZ19: 山东 | BA19: =IFERROR(X55/AVERAGE(W19:X19)*10000/8760,"") | BB19: =IFERROR(Y55/AVERAGE(X19:Y19)*10000/8760,"") -> 0.71232877 | BC19: =IFERROR(Z55/AVERAGE(Y19:Z19)*10000/8760,"") -> 1.260274 | BD19: =IFERROR(AA55/AVERAGE(Z19:AA19)*10000/8760,"") -> 0.87214612 | BE19: =IFERROR(AB55/AVERAGE(AA19:AB19)*10000/8760,"") -> 0.89954338 | BF19: =IFERROR(AC55/AVERAGE(AB19:AC19)*10000/8760,"") -> 0.94520548 | BG19: =IFERROR(AE55/AVERAGE(AD19:AE19)*10000/8760,"") -> 0.19947128 | BH19: =IFERROR(AF55/AVERAGE(AE19:AF19)*10000/8760,"") -> 0.22137946 | BI19: =IFERROR(AG55/AVERAGE(AF19:AG19)*10000/8760,"") -> 0.20547945 | BJ19: =IFERROR(AH55/AVERAGE(AG19:AH19)*10000/8760,"") -> 0.18778158 | BK19: =IFERROR(AI55/AVERAGE(AH19:AI19)*10000/8760,"") -> 0.24987689 | BL19: =IFERROR(AJ55/AVERAGE(AI19:AJ19)*10000/8760,"") -> 0.22325367 | BM19: =IFERROR(J55/((I19+J19)/2)*10000/8760,"") -> 0.073989515 | BN19: =IFERROR(K55/((J19+K19)/2)*10000/8760,"") -> 0.052849653 | BO19: =IFERROR(L55/((K19+L19)/2)*10000/8760,"") -> 0.052849653 | BP19: =IFERROR(M55/((L19+M19)/2)*10000/8760,"") -> 0.095129376 | BQ19: =IFERROR(N55/((M19+N19)/2)*10000/8760,"") -> 0.099265436 | BR19: =IFERROR(O55/((N19+O19)/2)*10000/8760,"") -> 0.16143167
A20: 河南 | B20: 7218 | C20: 7880 | D20: 8680 | E20: 9306 | F20: 10169 | G20: 11114 | H20: 11959 | I20: 399 | J20: 399 | K20: 401 | L20: 408 | M20: 408 | N20: 407 | O20: 439 | P20: 6431 | Q20: 6544 | R20: 6821 | S20: 7050 | T20: 7068 | U20: 7301 | V20: 7272 | AD20: 104 | AE20: 233 | AF20: 468 | AG20: 794 | AH20: 1518 | AI20: 1850 | AJ20: 1903 | AK20: 284 | AL20: 703 | AM20: 991 | AN20: 1054 | AO20: 1175 | AP20: 1556 | AQ20: 2333 | AX20: 13 | AZ20: 河南 | BA20: =IFERROR(X56/AVERAGE(W20:X20)*10000/8760,"") | BB20: =IFERROR(Y56/AVERAGE(X20:Y20)*10000/8760,"") | BC20: =IFERROR(Z56/AVERAGE(Y20:Z20)*10000/8760,"") | BD20: =IFERROR(AA56/AVERAGE(Z20:AA20)*10000/8760,"") | BE20: =IFERROR(AB56/AVERAGE(AA20:AB20)*10000/8760,"") | BF20: =IFERROR(AC56/AVERAGE(AB20:AC20)*10000/8760,"") | BG20: =IFERROR(AE56/AVERAGE(AD20:AE20)*10000/8760,"") -> 0.20324377 | BH20: =IFERROR(AF56/AVERAGE(AE20:AF20)*10000/8760,"") -> 0.18564477 | BI20: =IFERROR(AG56/AVERAGE(AF20:AG20)*10000/8760,"") -> 0.15920225 | BJ20: =IFERROR(AH56/AVERAGE(AG20:AH20)*10000/8760,"") -> 0.1372628 | BK20: =IFERROR(AI56/AVERAGE(AH20:AI20)*10000/8760,"") -> 0.22234514 | BL20: =IFERROR(AJ56/AVERAGE(AI20:AJ20)*10000/8760,"") -> 0.23238639 | BM20: =IFERROR(J56/((I20+J20)/2)*10000/8760,"") -> 0.28610339 | BN20: =IFERROR(K56/((J20+K20)/2)*10000/8760,"") -> 0.4109589 | BO20: =IFERROR(L56/((K20+L20)/2)*10000/8760,"") -> 0.40920918 | BP20: =IFERROR(M56/((L20+M20)/2)*10000/8760,"") -> 0.3917092 | BQ20: =IFERROR(N56/((M20+N20)/2)*10000/8760,"") -> 0.32495728 | BR20: =IFERROR(O56/((N20+O20)/2)*10000/8760,"") -> 0.3292421
A21: 湖北 | B21: 6745 | C21: 7124 | D21: 7401 | E21: 7862 | F21: 8273 | G21: 8816 | H21: 9438 | I21: 3663 | J21: 3671 | K21: 3675 | L21: 3679 | M21: 3757 | N21: 3771 | O21: 3780 | P21: 2694 | Q21: 2787 | R21: 2884 | S21: 3157 | T21: 3316 | U21: 3372 | V21: 3563 | AD21: 201 | AE21: 253 | AF21: 331 | AG21: 405 | AH21: 502 | AI21: 720 | AJ21: 778 | AK21: 187 | AL21: 413 | AM21: 510 | AN21: 621 | AO21: 698 | AP21: 953 | AQ21: 1316 | AX21: 1 | AZ21: 湖北 | BA21: =IFERROR(X57/AVERAGE(W21:X21)*10000/8760,"") | BB21: =IFERROR(Y57/AVERAGE(X21:Y21)*10000/8760,"") | BC21: =IFERROR(Z57/AVERAGE(Y21:Z21)*10000/8760,"") | BD21: =IFERROR(AA57/AVERAGE(Z21:AA21)*10000/8760,"") | BE21: =IFERROR(AB57/AVERAGE(AA21:AB21)*10000/8760,"") | BF21: =IFERROR(AC57/AVERAGE(AB21:AC21)*10000/8760,"") | BG21: =IFERROR(AE57/AVERAGE(AD21:AE21)*10000/8760,"") -> 0.24138555 | BH21: =IFERROR(AF57/AVERAGE(AE21:AF21)*10000/8760,"") -> 0.25020329 | BI21: =IFERROR(AG57/AVERAGE(AF21:AG21)*10000/8760,"") -> 0.22955132 | BJ21: =IFERROR(AH57/AVERAGE(AG21:AH21)*10000/8760,"") -> 0.20641082 | BK21: =IFERROR(AI57/AVERAGE(AH21:AI21)*10000/8760,"") -> 0.25035685 | BL21: =IFERROR(AJ57/AVERAGE(AI21:AJ21)*10000/8760,"") -> 0.24995275 | BM21: =IFERROR(J57/((I21+J21)/2)*10000/8760,"") -> 0.46508848 | BN21: =IFERROR(K57/((J21+K21)/2)*10000/8760,"") -> 0.45718044 | BO21: =IFERROR(L57/((K21+L21)/2)*10000/8760,"") -> 0.42129093 | BP21: =IFERROR(M57/((L21+M21)/2)*10000/8760,"") -> 0.50568504 | BQ21: =IFERROR(N57/((M21+N21)/2)*10000/8760,"") -> 0.48494752 | BR21: =IFERROR(O57/((N21+O21)/2)*10000/8760,"") -> 0.36887672
A22: 湖南 | B22: 4121 | C22: 4277 | D22: 4522 | E22: 4669 | F22: 4915 | G22: 5344 | H22: 5774 | I22: 1553 | J22: 1570 | K22: 1598 | L22: 1612 | M22: 1581 | N22: 1578 | O22: 1587 | P22: 2322 | Q22: 2267 | R22: 2284 | S22: 2280 | T22: 2269 | U22: 2502 | V22: 2588 | AD22: 217 | AE22: 263 | AF22: 348 | AG22: 427 | AH22: 669 | AI22: 803 | AJ22: 900 | AK22: 30 | AL22: 176 | AM22: 292 | AN22: 344 | AO22: 391 | AP22: 450 | AQ22: 636 | AU22: 6 | AV22: 6 | AW22: 12 | AX22: 63 | AZ22: 湖南 | BA22: =IFERROR(X58/AVERAGE(W22:X22)*10000/8760,"") | BB22: =IFERROR(Y58/AVERAGE(X22:Y22)*10000/8760,"") | BC22: =IFERROR(Z58/AVERAGE(Y22:Z22)*10000/8760,"") | BD22: =IFERROR(AA58/AVERAGE(Z22:AA22)*10000/8760,"") | BE22: =IFERROR(AB58/AVERAGE(AA22:AB22)*10000/8760,"") | BF22: =IFERROR(AC58/AVERAGE(AB22:AC22)*10000/8760,"") | BG22: =IFERROR(AE58/AVERAGE(AD22:AE22)*10000/8760,"") -> 0.23782344 | BH22: =IFERROR(AF58/AVERAGE(AE22:AF22)*10000/8760,"") -> 0.22420017 | BI22: =IFERROR(AG58/AVERAGE(AF22:AG22)*10000/8760,"") -> 0.22094565 | BJ22: =IFERROR(AH58/AVERAGE(AG22:AH22)*10000/8760,"") -> 0.20622938 | BK22: =IFERROR(AI58/AVERAGE(AH22:AI22)*10000/8760,"") -> 0.23265337 | BL22: =IFERROR(AJ58/AVERAGE(AI22:AJ22)*10000/8760,"") -> 0.24399596 | BM22: =IFERROR(J58/((I22+J22)/2)*10000/8760,"") -> 0.36406862 | BN22: =IFERROR(K58/((J22+K22)/2)*10000/8760,"") -> 0.3113325 | BO22: =IFERROR(L58/((K22+L22)/2)*10000/8760,"") -> 0.38691873 | BP22: =IFERROR(M58/((L22+M22)/2)*10000/8760,"") -> 0.41042978 | BQ22: =IFERROR(N58/((M22+N22)/2)*10000/8760,"") -> 0.3888289 | BR22: =IFERROR(O58/((N22+O22)/2)*10000/8760,"") -> 0.36500826
A23: 广东 | B23: 10457 | C23: 10968 | D23: 11929 | E23: 12870 | F23: 14224 | G23: 15821 | H23: 17212 | I23: 1411 | J23: 1486 | K23: 1576 | L23: 1576 | M23: 1666 | N23: 1736 | O23: 1912 | P23: 7721 | Q23: 7768 | R23: 8137 | S23: 8628 | T23: 9582 | U23: 10256 | V23: 10741 | W23: 938 | X23: 1046 | Y23: 1330 | Z23: 1614 | AA23: 1614 | AB23: 1614 | AC23: 1614 | AD23: 268 | AE23: 335 | AF23: 357 | AG23: 441 | AH23: 565 | AI23: 1195 | AJ23: 1357 | AK23: 117 | AL23: 332 | AM23: 527 | AN23: 610 | AO23: 797 | AP23: 1020 | AQ23: 1590 | AS23: 2 | AT23: 2 | AU23: 2 | AZ23: 广东 | BA23: =IFERROR(X59/AVERAGE(W23:X23)*10000/8760,"") -> 0.92060686 | BB23: =IFERROR(Y59/AVERAGE(X23:Y23)*10000/8760,"") -> 0.8609689 | BC23: =IFERROR(Z59/AVERAGE(Y23:Z23)*10000/8760,"") -> 0.85771541 | BD23: =IFERROR(AA59/AVERAGE(Z23:AA23)*10000/8760,"") -> 0.82115394 | BE23: =IFERROR(AB59/AVERAGE(AA23:AB23)*10000/8760,"") -> 0.85156705 | BF23: =IFERROR(AC59/AVERAGE(AB23:AC23)*10000/8760,"") -> 0.81266656 | BG23: =IFERROR(AE59/AVERAGE(AD23:AE23)*10000/8760,"") -> 0.23474712 | BH23: =IFERROR(AF59/AVERAGE(AE23:AF23)*10000/8760,"") -> 0.20785494 | BI23: =IFERROR(AG59/AVERAGE(AF23:AG23)*10000/8760,"") -> 0.21171651 | BJ23: =IFERROR(AH59/AVERAGE(AG23:AH23)*10000/8760,"") -> 0.23375727 | BK23: =IFERROR(AI59/AVERAGE(AH23:AI23)*10000/8760,"") -> 0.17771897 | BL23: =IFERROR(AJ59/AVERAGE(AI23:AJ23)*10000/8760,"") -> 0.24065645 | BM23: =IFERROR(J59/((I23+J23)/2)*10000/8760,"") -> 0.23721595 | BN23: =IFERROR(K59/((J23+K23)/2)*10000/8760,"") -> 0.21772262 | BO23: =IFERROR(L59/((K23+L23)/2)*10000/8760,"") -> 0.28756113 | BP23: =IFERROR(M59/((L23+M23)/2)*10000/8760,"") -> 0.20140902 | BQ23: =IFERROR(N59/((M23+N23)/2)*10000/8760,"") -> 0.1496568 | BR23: =IFERROR(O59/((N23+O23)/2)*10000/8760,"") -> 0.21466695
A24: 广西 | B24: 4152 | C24: 4332 | D24: 4513 | E24: 4615 | F24: 5178 | G24: 5533 | H24: 6277 | I24: 1665 | J24: 1669 | K24: 1677 | L24: 1681 | M24: 1759 | N24: 1768 | O24: 1832 | P24: 2185 | Q24: 2217 | R24: 2288 | S24: 2294 | T24: 2344 | U24: 2481 | V24: 2757 | W24: 217 | X24: 217 | Y24: 217 | Z24: 217 | AA24: 217 | AB24: 217 | AC24: 217 | AD24: 70 | AE24: 150 | AF24: 208 | AG24: 287 | AH24: 653 | AI24: 755 | AJ24: 946 | AK24: 16 | AL24: 78 | AM24: 124 | AN24: 135 | AO24: 205 | AP24: 312 | AQ24: 520 | AX24: 5 | AZ24: 广西 | BA24: =IFERROR(X60/AVERAGE(W24:X24)*10000/8760,"") -> 0.66809755 | BB24: =IFERROR(Y60/AVERAGE(X24:Y24)*10000/8760,"") -> 0.84695831 | BC24: =IFERROR(Z60/AVERAGE(Y24:Z24)*10000/8760,"") -> 0.90482503 | BD24: =IFERROR(AA60/AVERAGE(Z24:AA24)*10000/8760,"") -> 0.88378259 | BE24: =IFERROR(AB60/AVERAGE(AA24:AB24)*10000/8760,"") -> 0.95217053 | BF24: =IFERROR(AC60/AVERAGE(AB24:AC24)*10000/8760,"") -> 0.9363887 | BG24: =IFERROR(AE60/AVERAGE(AD24:AE24)*10000/8760,"") -> 0.25944375 | BH24: =IFERROR(AF60/AVERAGE(AE24:AF24)*10000/8760,"") -> 0.26785031 | BI24: =IFERROR(AG60/AVERAGE(AF24:AG24)*10000/8760,"") -> 0.28135234 | BJ24: =IFERROR(AH60/AVERAGE(AG24:AH24)*10000/8760,"") -> 0.25745652 | BK24: =IFERROR(AI60/AVERAGE(AH24:AI24)*10000/8760,"") -> 0.26106528 | BL24: =IFERROR(AJ60/AVERAGE(AI24:AJ24)*10000/8760,"") -> 0.26710047 | BM24: =IFERROR(J60/((I24+J24)/2)*10000/8760,"") -> 0.42046385 | BN24: =IFERROR(K60/((J24+K24)/2)*10000/8760,"") -> 0.41554422 | BO24: =IFERROR(L60/((K24+L24)/2)*10000/8760,"") -> 0.40318085 | BP24: =IFERROR(M60/((L24+M24)/2)*10000/8760,"") -> 0.40817139 | BQ24: =IFERROR(N60/((M24+N24)/2)*10000/8760,"") -> 0.33466552 | BR24: =IFERROR(O60/((N24+O24)/2)*10000/8760,"") -> 0.38812785
A25: 海南 | B25: 745 | C25: 786 | D25: 919 | E25: 918 | F25: 999 | G25: 1056 | H25: 1307 | I25: 91 | J25: 114 | K25: 154 | L25: 154 | M25: 151 | N25: 153 | O25: 153 | P25: 464 | Q25: 465 | R25: 465 | S25: 465 | T25: 546 | U25: 598 | V25: 750 | W25: 130 | X25: 130 | Y25: 130 | Z25: 130 | AA25: 130 | AB25: 130 | AC25: 130 | AD25: 31 | AE25: 34 | AF25: 34 | AG25: 29 | AH25: 29 | AI25: 29 | AJ25: 29 | AK25: 29 | AL25: 43 | AM25: 136 | AN25: 140 | AO25: 143 | AP25: 147 | AQ25: 246 | AU25: 11 | AZ25: 海南 | BA25: =IFERROR(X61/AVERAGE(W25:X25)*10000/8760,"") -> 0.65858799 | BB25: =IFERROR(Y61/AVERAGE(X25:Y25)*10000/8760,"") -> 0.67615033 | BC25: =IFERROR(Z61/AVERAGE(Y25:Z25)*10000/8760,"") -> 0.8517738 | BD25: =IFERROR(AA61/AVERAGE(Z25:AA25)*10000/8760,"") -> 0.84299262 | BE25: =IFERROR(AB61/AVERAGE(AA25:AB25)*10000/8760,"") -> 0.86055497 | BF25: =IFERROR(AC61/AVERAGE(AB25:AC25)*10000/8760,"") -> 0.92202318 | BG25: =IFERROR(AE61/AVERAGE(AD25:AE25)*10000/8760,"") -> 0.21074816 | BH25: =IFERROR(AF61/AVERAGE(AE25:AF25)*10000/8760,"") -> 0.16787537 | BI25: =IFERROR(AG61/AVERAGE(AF25:AG25)*10000/8760,"") -> 0.18119881 | BJ25: =IFERROR(AH61/AVERAGE(AG25:AH25)*10000/8760,"") -> 0.23618328 | BK25: =IFERROR(AI61/AVERAGE(AH25:AI25)*10000/8760,"") -> 0.1968194 | BL25: =IFERROR(AJ61/AVERAGE(AI25:AJ25)*10000/8760,"") -> 0.1968194 | BM25: =IFERROR(J61/((I25+J25)/2)*10000/8760,"") -> 0.28956454 | BN25: =IFERROR(K61/((J25+K25)/2)*10000/8760,"") -> 0.23001431 | BO25: =IFERROR(L61/((K25+L25)/2)*10000/8760,"") -> 0.12601554 | BP25: =IFERROR(M61/((L25+M25)/2)*10000/8760,"") -> 0.12725503 | BQ25: =IFERROR(N61/((M25+N25)/2)*10000/8760,"") -> 0.13518385 | BR25: =IFERROR(O61/((N25+O25)/2)*10000/8760,"") -> 0.20891157
A26: 重庆 | B26: 2178 | C26: 2326 | D26: 2386 | E26: 2448 | F26: 2488 | G26: 2574 | H26: 2685 | I26: 688 | J26: 736 | K26: 756 | L26: 772 | M26: 779 | N26: 789 | O26: 790 | P26: 1462 | Q26: 1544 | R26: 1537 | S26: 1548 | T26: 1545 | U26: 1553 | V26: 1644 | AD26: 28 | AE26: 33 | AF26: 50 | AG26: 64 | AH26: 97 | AI26: 169 | AJ26: 182 | AK26: 0. 46 | AL26: 12 | AM26: 43 | AN26: 65 | AO26: 67 | AP26: 63 | AQ26: 69 | AZ26: 重庆 | BA26: =IFERROR(X62/AVERAGE(W26:X26)*10000/8760,"") | BB26: =IFERROR(Y62/AVERAGE(X26:Y26)*10000/8760,"") | BC26: =IFERROR(Z62/AVERAGE(Y26:Z26)*10000/8760,"") | BD26: =IFERROR(AA62/AVERAGE(Z26:AA26)*10000/8760,"") | BE26: =IFERROR(AB62/AVERAGE(AA26:AB26)*10000/8760,"") | BF26: =IFERROR(AC62/AVERAGE(AB26:AC26)*10000/8760,"") | BG26: =IFERROR(AE62/AVERAGE(AD26:AE26)*10000/8760,"") -> 0.26199566 | BH26: =IFERROR(AF62/AVERAGE(AE26:AF26)*10000/8760,"") -> 0.22005832 | BI26: =IFERROR(AG62/AVERAGE(AF26:AG26)*10000/8760,"") -> 0.22029961 | BJ26: =IFERROR(AH62/AVERAGE(AG26:AH26)*10000/8760,"") -> 0.19853087 | BK26: =IFERROR(AI62/AVERAGE(AH26:AI26)*10000/8760,"") -> 0.19741134 | BL26: =IFERROR(AJ62/AVERAGE(AI26:AJ26)*10000/8760,"") -> 0.22115547 | BM26: =IFERROR(J62/((I26+J26)/2)*10000/8760,"") -> 0.40563593 | BN26: =IFERROR(K62/((J26+K26)/2)*10000/8760,"") -> 0.37031596 | BO26: =IFERROR(L62/((K26+L26)/2)*10000/8760,"") -> 0.36308542 | BP26: =IFERROR(M62/((L26+M26)/2)*10000/8760,"") -> 0.41363798 | BQ26: =IFERROR(N62/((M26+N26)/2)*10000/8760,"") -> 0.41206551 | BR26: =IFERROR(O62/((N26+O26)/2)*10000/8760,"") -> 0.2920755
A27: 四川 | B27: 9108 | C27: 9721 | D27: 9833 | E27: 9929 | F27: 10105 | G27: 11435 | H27: 12390 | I27: 7246 | J27: 7714 | K27: 7824 | L27: 7846 | M27: 7892 | N27: 8887 | O27: 9746 | P27: 1642 | Q27: 1662 | R27: 1575 | S27: 1570 | T27: 1596 | U27: 1825 | V27: 1840 | AD27: 125 | AE27: 210 | AF27: 253 | AG27: 325 | AH27: 426 | AI27: 527 | AJ27: 598 | AK27: 96 | AL27: 135 | AM27: 181 | AN27: 188 | AO27: 191 | AP27: 196 | AQ27: 206 | AX27: 0.1 | AZ27: 四川 | BA27: =IFERROR(X63/AVERAGE(W27:X27)*10000/8760,"") | BB27: =IFERROR(Y63/AVERAGE(X27:Y27)*10000/8760,"") | BC27: =IFERROR(Z63/AVERAGE(Y27:Z27)*10000/8760,"") | BD27: =IFERROR(AA63/AVERAGE(Z27:AA27)*10000/8760,"") | BE27: =IFERROR(AB63/AVERAGE(AA27:AB27)*10000/8760,"") | BF27: =IFERROR(AC63/AVERAGE(AB27:AC27)*10000/8760,"") | BG27: =IFERROR(AE63/AVERAGE(AD27:AE27)*10000/8760,"") -> 0.23853336 | BH27: =IFERROR(AF63/AVERAGE(AE27:AF27)*10000/8760,"") -> 0.27121118 | BI27: =IFERROR(AG63/AVERAGE(AF27:AG27)*10000/8760,"") -> 0.28045062 | BJ27: =IFERROR(AH63/AVERAGE(AG27:AH27)*10000/8760,"") -> 0.26144745 | BK27: =IFERROR(AI63/AVERAGE(AH27:AI27)*10000/8760,"") -> 0.26113163 | BL27: =IFERROR(AJ63/AVERAGE(AI27:AJ27)*10000/8760,"") -> 0.26788432 | BM27: =IFERROR(J63/((I27+J27)/2)*10000/8760,"") -> 0.48287061 | BN27: =IFERROR(K63/((J27+K27)/2)*10000/8760,"") -> 0.47739788 | BO27: =IFERROR(L63/((K27+L27)/2)*10000/8760,"") -> 0.48313824 | BP27: =IFERROR(M63/((L27+M27)/2)*10000/8760,"") -> 0.51369138 | BQ27: =IFERROR(N63/((M27+N27)/2)*10000/8760,"") -> 0.50672168 | BR27: =IFERROR(O63/((N27+O27)/2)*10000/8760,"") -> 0.47615232
A28: 贵州 | B28: 5510 | C28: 5778 | D28: 6039 | E28: 6599 | F28: 7478 | G28: 7573 | H28: 8087 | I28: 2089 | J28: 2119 | K28: 2212 | L28: 2223 | M28: 2281 | N28: 2283 | O28: 2282 | P28: 3014 | Q28: 3160 | R28: 3263 | S28: 3410 | T28: 3560 | U28: 3572 | V28: 3793 | AD28: 362 | AE28: 363 | AF28: 386 | AG28: 457 | AH28: 580 | AI28: 580 | AJ28: 592 | AK28: 46 | AL28: 135 | AM28: 178 | AN28: 510 | AO28: 1057 | AP28: 1137 | AQ28: 1420 | AZ28: 贵州 | BA28: =IFERROR(X64/AVERAGE(W28:X28)*10000/8760,"") | BB28: =IFERROR(Y64/AVERAGE(X28:Y28)*10000/8760,"") | BC28: =IFERROR(Z64/AVERAGE(Y28:Z28)*10000/8760,"") | BD28: =IFERROR(AA64/AVERAGE(Z28:AA28)*10000/8760,"") | BE28: =IFERROR(AB64/AVERAGE(AA28:AB28)*10000/8760,"") | BF28: =IFERROR(AC64/AVERAGE(AB28:AC28)*10000/8760,"") | BG28: =IFERROR(AE64/AVERAGE(AD28:AE28)*10000/8760,"") -> 0.19839395 | BH28: =IFERROR(AF64/AVERAGE(AE28:AF28)*10000/8760,"") -> 0.20727789 | BI28: =IFERROR(AG64/AVERAGE(AF28:AG28)*10000/8760,"") -> 0.21124815 | BJ28: =IFERROR(AH64/AVERAGE(AG28:AH28)*10000/8760,"") -> 0.21355949 | BK28: =IFERROR(AI64/AVERAGE(AH28:AI28)*10000/8760,"") -> 0.20666037 | BL28: =IFERROR(AJ64/AVERAGE(AI28:AJ28)*10000/8760,"") -> 0.21233656 | BM28: =IFERROR(J64/((I28+J28)/2)*10000/8760,"") -> 0.39769866 | BN28: =IFERROR(K64/((J28+K28)/2)*10000/8760,"") -> 0.40590877 | BO28: =IFERROR(L64/((K28+L28)/2)*10000/8760,"") -> 0.39587548 | BP28: =IFERROR(M64/((L28+M28)/2)*10000/8760,"") -> 0.42123896 | BQ28: =IFERROR(N64/((M28+N28)/2)*10000/8760,"") -> 0.36717771 | BR28: =IFERROR(O64/((N28+O28)/2)*10000/8760,"") -> 0.33908986
A29: 云南 | B29: 8645 | C29: 8957 | D29: 9341 | E29: 9620 | F29: 10266 | G29: 10635 | H29: 11177 | I29: 6088 | J29: 6281 | K29: 6649 | L29: 6873 | M29: 7480 | N29: 7823 | O29: 8146 | P29: 1612 | Q29: 1613 | R29: 1508 | S29: 1509 | T29: 1517 | U29: 1529 | V29: 1534 | AD29: 737 | AE29: 825 | AF29: 857 | AG29: 863 | AH29: 881 | AI29: 886 | AJ29: 912 | AK29: 208 | AL29: 238 | AM29: 326 | AN29: 375 | AO29: 388 | AP29: 397 | AQ29: 585 | AV29: 0.2 | AW29: 0.2 | AX29: 0.2 | AZ29: 云南 | BA29: =IFERROR(X65/AVERAGE(W29:X29)*10000/8760,"") | BB29: =IFERROR(Y65/AVERAGE(X29:Y29)*10000/8760,"") | BC29: =IFERROR(Z65/AVERAGE(Y29:Z29)*10000/8760,"") | BD29: =IFERROR(AA65/AVERAGE(Z29:AA29)*10000/8760,"") | BE29: =IFERROR(AB65/AVERAGE(AA29:AB29)*10000/8760,"") | BF29: =IFERROR(AC65/AVERAGE(AB29:AC29)*10000/8760,"") | BG29: =IFERROR(AE65/AVERAGE(AD29:AE29)*10000/8760,"") -> 0.27479113 | BH29: =IFERROR(AF65/AVERAGE(AE29:AF29)*10000/8760,"") -> 0.29862254 | BI29: =IFERROR(AG65/AVERAGE(AF29:AG29)*10000/8760,"") -> 0.32122757 | BJ29: =IFERROR(AH65/AVERAGE(AG29:AH29)*10000/8760,"") -> 0.32727996 | BK29: =IFERROR(AI65/AVERAGE(AH29:AI29)*10000/8760,"") -> 0.29976252 | BL29: =IFERROR(AJ65/AVERAGE(AI29:AJ29)*10000/8760,"") -> 0.27173775 | BM29: =IFERROR(J65/((I29+J29)/2)*10000/8760,"") -> 0.46182624 | BN29: =IFERROR(K65/((J29+K29)/2)*10000/8760,"") -> 0.47657389 | BO29: =IFERROR(L65/((K29+L29)/2)*10000/8760,"") -> 0.48188003 | BP29: =IFERROR(M65/((L29+M29)/2)*10000/8760,"") -> 0.4708417 | BQ29: =IFERROR(N65/((M29+N29)/2)*10000/8760,"") -> 0.45160811 | BR29: =IFERROR(O65/((N29+O29)/2)*10000/8760,"") -> 0.46937402
A30: 西藏 | B30: 233 | C30: 281 | D30: 304 | E30: 327 | F30: 395 | G30: 480 | H30: 540 | I30: 156 | J30: 158 | K30: 160 | L30: 170 | M30: 210 | N30: 291 | O30: 292 | P30: 41 | Q30: 40 | R30: 42 | S30: 42 | T30: 43 | U30: 43 | V30: 42 | AD30: 1 | AE30: 1 | AF30: 1 | AG30: 1 | AH30: 1 | AI30: 3 | AJ30: 3 | AK30: 33 | AL30: 79 | AM30: 98 | AN30: 110 | AO30: 137 | AP30: 139 | AQ30: 179 | AS30: 3 | AT30: 4 | AU30: 4 | AV30: 4 | AW30: 4 | AX30: 25 | AZ30: 西藏 | BA30: =IFERROR(X66/AVERAGE(W30:X30)*10000/8760,"") | BB30: =IFERROR(Y66/AVERAGE(X30:Y30)*10000/8760,"") | BC30: =IFERROR(Z66/AVERAGE(Y30:Z30)*10000/8760,"") | BD30: =IFERROR(AA66/AVERAGE(Z30:AA30)*10000/8760,"") | BE30: =IFERROR(AB66/AVERAGE(AA30:AB30)*10000/8760,"") | BF30: =IFERROR(AC66/AVERAGE(AB30:AC30)*10000/8760,"") | BG30: =IFERROR(AE66/AVERAGE(AD30:AE30)*10000/8760,"") -> 0.11415525 | BH30: =IFERROR(AF66/AVERAGE(AE30:AF30)*10000/8760,"") -> 0.15981735 | BI30: =IFERROR(AG66/AVERAGE(AF30:AG30)*10000/8760,"") -> 0.1826484 | BJ30: =IFERROR(AH66/AVERAGE(AG30:AH30)*10000/8760,"") -> 0.11415525 | BK30: =IFERROR(AI66/AVERAGE(AH30:AI30)*10000/8760,"") -> 0.057077626 | BL30: =IFERROR(AJ66/AVERAGE(AI30:AJ30)*10000/8760,"") -> 0.34246575 | BM30: =IFERROR(J66/((I30+J30)/2)*10000/8760,"") -> 0.37082279 | BN30: =IFERROR(K66/((J30+K30)/2)*10000/8760,"") -> 0.40923581 | BO30: =IFERROR(L66/((K30+L30)/2)*10000/8760,"") -> 0.470458 | BP30: =IFERROR(M66/((L30+M30)/2)*10000/8760,"") -> 0.42057198 | BQ30: =IFERROR(N66/((M30+N30)/2)*10000/8760,"") -> 0.42380991 | BR30: =IFERROR(O66/((N30+O30)/2)*10000/8760,"") -> 0.41511
A31: 陕西 | B31: 3740 | C31: 4935 | D31: 5443 | E31: 6242 | F31: 7366 | G31: 7636 | H31: 8110 | I31: 272 | J31: 379 | K31: 385 | L31: 391 | M31: 392 | N31: 349 | O31: 350 | P31: 3043 | Q31: 3658 | R31: 3937 | S31: 4380 | T31: 4993 | U31: 4952 | V31: 5080 | AD31: 179 | AE31: 364 | AF31: 405 | AG31: 532 | AH31: 892 | AI31: 1021 | AJ31: 1164 | AK31: 246 | AL31: 535 | AM31: 716 | AN31: 939 | AO31: 1089 | AP31: 1314 | AQ31: 1516 | AZ31: 陕西 | BA31: =IFERROR(X67/AVERAGE(W31:X31)*10000/8760,"") | BB31: =IFERROR(Y67/AVERAGE(X31:Y31)*10000/8760,"") | BC31: =IFERROR(Z67/AVERAGE(Y31:Z31)*10000/8760,"") | BD31: =IFERROR(AA67/AVERAGE(Z31:AA31)*10000/8760,"") | BE31: =IFERROR(AB67/AVERAGE(AA31:AB31)*10000/8760,"") | BF31: =IFERROR(AC67/AVERAGE(AB31:AC31)*10000/8760,"") | BG31: =IFERROR(AE67/AVERAGE(AD31:AE31)*10000/8760,"") -> 0.22704912 | BH31: =IFERROR(AF67/AVERAGE(AE31:AF31)*10000/8760,"") -> 0.21376276 | BI31: =IFERROR(AG67/AVERAGE(AF31:AG31)*10000/8760,"") -> 0.20223876 | BJ31: =IFERROR(AH67/AVERAGE(AG31:AH31)*10000/8760,"") -> 0.15231389 | BK31: =IFERROR(AI67/AVERAGE(AH31:AI31)*10000/8760,"") -> 0.21005044 | BL31: =IFERROR(AJ67/AVERAGE(AI31:AJ31)*10000/8760,"") -> 0.20897986 | BM31: =IFERROR(J67/((I31+J31)/2)*10000/8760,"") -> 0.38227104 | BN31: =IFERROR(K67/((J31+K31)/2)*10000/8760,"") -> 0.30481245 | BO31: =IFERROR(L67/((K31+L31)/2)*10000/8760,"") -> 0.37953679 | BP31: =IFERROR(M67/((L31+M31)/2)*10000/8760,"") -> 0.3732279 | BQ31: =IFERROR(N67/((M31+N31)/2)*10000/8760,"") -> 0.43443699 | BR31: =IFERROR(O67/((N31+O31)/2)*10000/8760,"") -> 0.28416329
A32: 甘肃 | B32: 4825 | C32: 4995 | D32: 5113 | E32: 5268 | F32: 5620 | G32: 6152 | H32: 6810 | I32: 861 | J32: 868 | K32: 927 | L32: 943 | M32: 957 | N32: 967 | O32: 972 | P32: 2002 | Q32: 2059 | R32: 2064 | S32: 2104 | T32: 2308 | U32: 2309 | V32: 2313 | AD32: 1277 | AE32: 1282 | AF32: 1282 | AG32: 1297 | AH32: 1373 | AI32: 1725 | AJ32: 2073 | AK32: 686 | AL32: 786 | AM32: 839 | AN32: 924 | AO32: 982 | AP32: 1146 | AQ32: 1417 | AW32: 6 | AX32: 35 | AZ32: 甘肃 | BA32: =IFERROR(X68/AVERAGE(W32:X32)*10000/8760,"") | BB32: =IFERROR(Y68/AVERAGE(X32:Y32)*10000/8760,"") | BC32: =IFERROR(Z68/AVERAGE(Y32:Z32)*10000/8760,"") | BD32: =IFERROR(AA68/AVERAGE(Z32:AA32)*10000/8760,"") | BE32: =IFERROR(AB68/AVERAGE(AA32:AB32)*10000/8760,"") | BF32: =IFERROR(AC68/AVERAGE(AB32:AC32)*10000/8760,"") | BG32: =IFERROR(AE68/AVERAGE(AD32:AE32)*10000/8760,"") -> 0.16773105 | BH32: =IFERROR(AF68/AVERAGE(AE32:AF32)*10000/8760,"") -> 0.20480271 | BI32: =IFERROR(AG68/AVERAGE(AF32:AG32)*10000/8760,"") -> 0.201841 | BJ32: =IFERROR(AH68/AVERAGE(AG32:AH32)*10000/8760,"") -> 0.2103535 | BK32: =IFERROR(AI68/AVERAGE(AH32:AI32)*10000/8760,"") -> 0.21224475 | BL32: =IFERROR(AJ68/AVERAGE(AI32:AJ32)*10000/8760,"") -> 0.20919446 | BM32: =IFERROR(J68/((I32+J32)/2)*10000/8760,"") -> 0.49385846 | BN32: =IFERROR(K68/((J32+K32)/2)*10000/8760,"") -> 0.56473461 | BO32: =IFERROR(L68/((K32+L32)/2)*10000/8760,"") -> 0.60557224 | BP32: =IFERROR(M68/((L32+M32)/2)*10000/8760,"") -> 0.60922855 | BQ32: =IFERROR(N68/((M32+N32)/2)*10000/8760,"") -> 0.53636355 | BR32: =IFERROR(O68/((N32+O32)/2)*10000/8760,"") -> 0.44154945
A33: 青海 | B33: 2345 | C33: 2543 | D33: 2800 | E33: 3168 | F33: 4030 | G33: 4114 | H33: 4519 | I33: 1192 | J33: 1191 | K33: 1192 | L33: 1192 | M33: 1193 | N33: 1193 | O33: 1261 | P33: 402 | Q33: 399 | R33: 379 | S33: 393 | T33: 393 | U33: 393 | V33: 393 | AD33: 69 | AE33: 162 | AF33: 267 | AG33: 462 | AH33: 843 | AI33: 896 | AJ33: 972 | AK33: 682 | AL33: 791 | AM33: 962 | AN33: 1122 | AO33: 1601 | AP33: 1632 | AQ33: 1842 | AX33: 51 | AZ33: 青海 | BA33: =IFERROR(X69/AVERAGE(W33:X33)*10000/8760,"") | BB33: =IFERROR(Y69/AVERAGE(X33:Y33)*10000/8760,"") | BC33: =IFERROR(Z69/AVERAGE(Y33:Z33)*10000/8760,"") | BD33: =IFERROR(AA69/AVERAGE(Z33:AA33)*10000/8760,"") | BE33: =IFERROR(AB69/AVERAGE(AA33:AB33)*10000/8760,"") | BF33: =IFERROR(AC69/AVERAGE(AB33:AC33)*10000/8760,"") | BG33: =IFERROR(AE69/AVERAGE(AD33:AE33)*10000/8760,"") -> 0.17790429 | BH33: =IFERROR(AF69/AVERAGE(AE33:AF33)*10000/8760,"") -> 0.20223308 | BI33: =IFERROR(AG69/AVERAGE(AF33:AG33)*10000/8760,"") -> 0.20670087 | BJ33: =IFERROR(AH69/AVERAGE(AG33:AH33)*10000/8760,"") -> 0.14345947 | BK33: =IFERROR(AI69/AVERAGE(AH33:AI33)*10000/8760,"") -> 0.1706749 | BL33: =IFERROR(AJ69/AVERAGE(AI33:AJ33)*10000/8760,"") -> 0.19066616 | BM33: =IFERROR(J69/((I33+J33)/2)*10000/8760,"") -> 0.31808261 | BN33: =IFERROR(K69/((J33+K33)/2)*10000/8760,"") -> 0.49532744 | BO33: =IFERROR(L69/((K33+L33)/2)*10000/8760,"") -> 0.53055377 | BP33: =IFERROR(M69/((L33+M33)/2)*10000/8760,"") -> 0.57340877 | BQ33: =IFERROR(N69/((M33+N33)/2)*10000/8760,"") -> 0.48322214 | BR33: =IFERROR(O69/((N33+O33)/2)*10000/8760,"") -> 0.397264
A34: 宁夏 | B34: 3675 | C34: 4188 | D34: 4715 | E34: 5296 | F34: 5943 | G34: 6214 | H34: 6477 | I34: 43 | J34: 43 | K34: 43 | L34: 43 | M34: 43 | N34: 43 | O34: 43 | P34: 2165 | Q34: 2583 | R34: 2845 | S34: 3219 | T34: 3326 | U34: 3333 | V34: 3304 | AD34: 942 | AE34: 942 | AF34: 1011 | AG34: 1116 | AH34: 1377 | AI34: 1455 | AJ34: 1457 | AK34: 526 | AL34: 620 | AM34: 816 | AN34: 918 | AO34: 1197 | AP34: 1384 | AQ34: 1584 | AX34: 90 | AZ34: 宁夏 | BA34: =IFERROR(X70/AVERAGE(W34:X34)*10000/8760,"") | BB34: =IFERROR(Y70/AVERAGE(X34:Y34)*10000/8760,"") | BC34: =IFERROR(Z70/AVERAGE(Y34:Z34)*10000/8760,"") | BD34: =IFERROR(AA70/AVERAGE(Z34:AA34)*10000/8760,"") | BE34: =IFERROR(AB70/AVERAGE(AA34:AB34)*10000/8760,"") | BF34: =IFERROR(AC70/AVERAGE(AB34:AC34)*10000/8760,"") | BG34: =IFERROR(AE70/AVERAGE(AD34:AE34)*10000/8760,"") -> 0.18783507 | BH34: =IFERROR(AF70/AVERAGE(AE34:AF34)*10000/8760,"") -> 0.2186076 | BI34: =IFERROR(AG70/AVERAGE(AF34:AG34)*10000/8760,"") -> 0.19965093 | BJ34: =IFERROR(AH70/AVERAGE(AG34:AH34)*10000/8760,"") -> 0.17766642 | BK34: =IFERROR(AI70/AVERAGE(AH34:AI34)*10000/8760,"") -> 0.2265369 | BL34: =IFERROR(AJ70/AVERAGE(AI34:AJ34)*10000/8760,"") -> 0.21560916 | BM34: =IFERROR(J70/((I34+J34)/2)*10000/8760,"") -> 0.42476373 | BN34: =IFERROR(K70/((J34+K34)/2)*10000/8760,"") -> 0.53095466 | BO34: =IFERROR(L70/((K34+L34)/2)*10000/8760,"") -> 0.58405012 | BP34: =IFERROR(M70/((L34+M34)/2)*10000/8760,"") -> 0.58405012 | BQ34: =IFERROR(N70/((M34+N34)/2)*10000/8760,"") -> 0.55750239 | BR34: =IFERROR(O70/((N34+O34)/2)*10000/8760,"") -> 0.47785919
A35: 新疆 | B35: 8109 | C35: 8679 | D35: 8978 | E35: 9614 | F35: 10763 | G35: 11547 | H35: 12112 | I35: 665 | J35: 702 | K35: 702 | L35: 773 | M35: 800 | N35: 934 | O35: 957 | P35: 4775 | Q35: 5207 | R35: 5377 | S35: 5813 | T35: 6337 | U35: 6845 | V35: 6924 | AD35: 1776 | AE35: 1836 | AF35: 1921 | AG35: 1956 | AH35: 2361 | AI35: 2408 | AJ35: 2614 | AK35: 893 | AL35: 934 | AM35: 978 | AN35: 1072 | AO35: 1266 | AP35: 1354 | AQ35: 1578 | AW35: 6 | AX35: 39 | AZ35: 新疆 | BA35: =IFERROR(X71/AVERAGE(W35:X35)*10000/8760,"") | BB35: =IFERROR(Y71/AVERAGE(X35:Y35)*10000/8760,"") | BC35: =IFERROR(Z71/AVERAGE(Y35:Z35)*10000/8760,"") | BD35: =IFERROR(AA71/AVERAGE(Z35:AA35)*10000/8760,"") | BE35: =IFERROR(AB71/AVERAGE(AA35:AB35)*10000/8760,"") | BF35: =IFERROR(AC71/AVERAGE(AB35:AC35)*10000/8760,"") | BG35: =IFERROR(AE71/AVERAGE(AD35:AE35)*10000/8760,"") -> 0.20100426 | BH35: =IFERROR(AF71/AVERAGE(AE35:AF35)*10000/8760,"") -> 0.21755432 | BI35: =IFERROR(AG71/AVERAGE(AF35:AG35)*10000/8760,"") -> 0.23967597 | BJ35: =IFERROR(AH71/AVERAGE(AG35:AH35)*10000/8760,"") -> 0.22952689 | BK35: =IFERROR(AI71/AVERAGE(AH35:AI35)*10000/8760,"") -> 0.26234883 | BL35: =IFERROR(AJ71/AVERAGE(AI35:AJ35)*10000/8760,"") -> 0.26731696 | BM35: =IFERROR(J71/((I35+J35)/2)*10000/8760,"") -> 0.42756027 | BN35: =IFERROR(K71/((J35+K35)/2)*10000/8760,"") -> 0.41304037 | BO35: =IFERROR(L71/((K35+L35)/2)*10000/8760,"") -> 0.44888167 | BP35: =IFERROR(M71/((L35+M35)/2)*10000/8760,"") -> 0.3889842 | BQ35: =IFERROR(N71/((M35+N35)/2)*10000/8760,"") -> 0.3765675 | BR35: =IFERROR(O71/((N35+O35)/2)*10000/8760,"") -> 0.40325599
A37: 年末发电量（亿千瓦时） Year End Total Capacity (10MW)
A38: 地区 | B38: 合计 | I38: 水电 | P38: 火电 | W38: 核电 | AD38: 风电 | AK38: 太阳能发电 | AR38: 其他 | AZ38: 地区 | BA38: 抽水蓄能装机容量 | BM38: 2016年 | BN38: 2017年 | BO38: 2018年 | BP38: 2019年 | BQ38: 2020年 | BR38: 2021年
B39: 2016年 | C39: 2017年 | D39: 2018年 | E39: 2019年 | F39: 2020年 | G39: 2021年 | H39: 2022年 | I39: 2016年 | J39: 2017年 | K39: 2018年 | L39: 2019年 | M39: 2020年 | N39: 2021年 | O39: 2022年 | P39: 2016年 | Q39: 2017年 | R39: 2018年 | S39: 2019年 | T39: 2020年 | U39: 2021年 | V39: 2022年 | W39: 2016年 | X39: 2017年 | Y39: 2018年 | Z39: 2019年 | AA39: 2020年 | AB39: 2021年 | AC39: 2022年 | AD39: 2016年 | AE39: 2017年 | AF39: 2018年 | AG39: 2019年 | AH39: 2020年 | AI39: 2021年 | AJ39: 2022年 | AK39: 2016年 | AL39: 2017年 | AM39: 2018年 | AN39: 2019年 | AO39: 2020年 | AP39: 2021年 | AQ39: 2022年 | AR39: 2016年 | AS39: 2017年 | AT39: 2018年 | AU39: 2019年 | AV39: 2020年 | AW39: 2021年 | AX39: 2022年 | BA39: 2016 | BB39: 2017 | BC39: 2018 | BD39: 2019 | BE39: 2020 | BF39: 2021 | BK39: 发电量 | BL39: 水电 | BM39: 11748 | BN39: 11947 | BO39: 12321 | BP39: 13021 | BQ39: 13553 | BR39: 13399
A40: 全国 | B40: 60228 | C40: 64529 | D40: 69947 | E40: 73269 | F40: 76264 | G40: 83959 | H40: 86945 | I40: 11748 | J40: 11947 | K40: 12321 | L40: 13021 | M40: 13553 | N40: 13399 | O40: 13517 | P40: 43273 | Q40: 45877 | R40: 49249 | S40: 50465 | T40: 51770 | U40: 56655 | V40: 57344 | W40: 2132 | X40: 2481 | Y40: 2950 | Z40: 3487 | AA40: 3662 | AB40: 4075 | AC40: 4178 | AD40: 2409 | AE40: 3046 | AF40: 3658 | AG40: 4053 | AH40: 4665 | AI40: 6558 | AJ40: 7624 | AK40: 665 | AL40: 1178 | AM40: 1769 | AN40: 2240 | AO40: 2611 | AP40: 3270 | AQ40: 4276 | AS40: 1 | AT40: 1 | AU40: 3 | AV40: 3 | AW40: 2.3 | AX40: 6 | AZ40: 全国 | BA40: 26923 | BB40: 28923 | BC40: 30223 | BD40: 30523 | BE40: 31723 | BF40: 36923 | BL40: 抽蓄 | BM40: 308 | BN40: 328 | BO40: 329 | BP40: 319 | BQ40: 335 | BR40: 390
A41: 北京 | B41: 436 | C41: 394 | D41: 449 | E41: 461 | F41: 456 | G41: 471 | H41: 465 | I41: 12 | J41: 11 | K41: 10 | L41: 10 | M41: 11 | N41: 14 | O41: 9 | P41: 419 | Q41: 377 | R41: 433 | S41: 443 | T41: 434 | U41: 447 | V41: 442 | AD41: 3 | AE41: 3 | AF41: 3 | AG41: 3 | AH41: 4 | AI41: 4 | AJ41: 5 | AK41: 1 | AL41: 2 | AM41: 3 | AN41: 5 | AO41: 6 | AP41: 6 | AQ41: 9 | AZ41: 北京 | BA41: 822 | BB41: 822 | BC41: 822 | BD41: 822 | BE41: 822 | BF41: 822 | BK41: 装机容量 | BL41: 水电 | BM41: 33207 | BN41: 34411 | BO41: 35259 | BP41: 35804 | BQ41: 37028 | BR41: 39094
...

Sheet Biomass
A1: 地区 | B1: 年份 | C1: 装机容量（万千瓦） | G1: 发电量（亿千瓦时） | K1: 利用小时数 | O1: 容量因子 | U1: 地区 | V1: 机组类型 | W1: 利用小时数折合容量因子
C2: 合计 | D2: 沼气发电 | E2: 垃圾焚烧发电 | F2: 秸秆、蔗渣、林木质发电 | G2: 合计 | H2: 沼气发电 | I2: 垃圾焚烧发电 | J2: 秸秆、蔗渣、林木质发电 | K2: 合计 | L2: 沼气发电 | M2: 垃圾焚烧发电 | N2: 秸秆、蔗渣、林木质发电 | O2: 合计 | P2: 沼气发电 | Q2: 垃圾焚烧发电 | R2: 秸秆、蔗渣、林木质发电 | S2: 除垃圾外生物质 | W2: 2016 | X2: 2017 | Y2: 2018 | Z2: 2019 | AA2: 2020 | AB2: 2021 | AC2: 2022
A3: 全国 | B3: 2016 | C3: 1396 | D3: 45 | E3: 576 | F3: 776 | G3: 687 | H3: 21 | I3: 315 | J3: 351 | K3: 5309 | L3: 6197 | M3: 5850 | N3: 4879 | O3: {=IFERROR(IF(G3>10,G3/C3*0.876,""),“”)} -> 0.43109742 | P3: {=IFERROR(IF(H3>10,H3/D3*0.876,""),“”)} -> 0.4088 | Q3: {=IFERROR(IF(I3>10,I3/E3*0.876,""),“”)} -> 0.4790625 | R3: {=IFERROR(IF(J3>10,J3/F3*0.876,""),“”)} -> 0.39623196 | S3: =IFERROR(IF((G3-I3)>10,(G3-I3)/(C3-E3)*0.876,""),"") -> 0.39740488 | U3: 全国 | V3: 生物质 | W3: =SUMIFS($K:$K,$A:$A,$U3,$B:$B,W$2)/8760 -> 0.60605023 | X3: =SUMIFS($K:$K,$A:$A,$U3,$B:$B,X$2)/8760 -> 0.60673516 | Y3: =SUMIFS($K:$K,$A:$A,$U3,$B:$B,Y$2)/8760 -> 0.58961187 | Z3: =SUMIFS($K:$K,$A:$A,$U3,$B:$B,Z$2)/8760 -> 0.59372146 | AA3: =SUMIFS($K:$K,$A:$A,$U3,$B:$B,AA$2)/8760 -> 0.59315068 | AB3: =SUMIFS($K:$K,$A:$A,$U3,$B:$B,AB$2)/8760 -> 0.56221461 | AC3: =SUMIFS($K:$K,$A:$A,$U3,$B:$B,AC$2)/8760 -> 0.53127854
