Workbook

Sheet About
B7: Definition of Energy Product not used as Fuel based on US EPS Model
B8: Coking Coal: Hard coal used in Iron and Steel Industry
B9: Petrochem: Natural Gas, Crude Oil, in refined petroleum and coke
B10: Chemical: Natural as Feedstock, LPG propane or butane as Feedstock
B12: Definition of "Energy Product used as Material"
B13: 4.2.1. #用作原料、材料
B14: “准确界定原料用能范畴”一节是《通知》的重要内容。该节具体指出，对原料用能的基本定义是:
B15: “指用作原材料的能源消费，即能源产品不作为燃料、动力使用，而作为生产非能源产品的原料、材料使用。”
B16: 具体范畴则表述为
B17: “用于生产非能源用途的烯烃、芳烃、炔烃、醇类、合成氨等产品的煤炭、石油、天然气及其制品等，属于原料用能范畴；若用作燃料、动力使用，不属于原料用能范畴”。

Sheet 终端消费
A1: 行 业 | B1: 煤合计_x000D_ (万吨)_x000D_ Coal Total_x000D_ (104 tons) | C1: 原煤_x000D_ (万吨)_x000D_ Raw Coal_x000D_ (104 tons) | D1: 洗精煤_x000D_ (万吨)_x000D_ Cleaned_x000D_ Coal_x000D_ (104 tons) | E1: 其他洗煤_x000D_ (万吨)_x000D_ Other_x000D_ Washed Coal_x000D_ (104 tons) | F1: 焦炭_x000D_ (万吨)_x000D_ Coke_x000D_ (104 tons) | G1: 焦炉煤气_x000D_ (亿立方米)_x000D_ Coke Oven_x000D_ Gas_x000D_ (108 cu.m) | H1: 高炉煤气_x000D_ (亿立方米)_x000D_ Blast Furnace_x000D_ Gas_x000D_ (108 cu.m) | I1: 转炉煤气_x000D_ (亿立方米)_x000D_ Converter_x000D_ Gas_x000D_ (108 cu.m) | J1: 其他煤气_x000D_ (亿立方米)_x000D_ Other Gas_x000D_ (108 cu.m) | K1: 其他焦化产品_x000D_ (万吨)_x000D_ Other Coking_x000D_ Products_x000D_ (104 tons) | L1: 油品合计_x000D_ (万吨)_x000D_ Petroleum_x000D_ Products Total_x000D_ (104 tons) | M1: 原油_x000D_ (万吨)_x000D_ Crude Oil_x000D_ (104 tons) | N1: 汽油_x000D_ (万吨)_x000D_ Gasoline_x000D_ (104 tons) | O1: 煤油_x000D_ (万吨)_x000D_ Kerosene_x000D_ (104 tons) | P1: 柴油_x000D_ (万吨)_x000D_ Diesel Oil_x000D_ (104 tons) | Q1: 燃料油_x000D_ (万吨)_x000D_ Fuel Oil_x000D_ (104 tons) | R1: 石脑油_x000D_ (万吨)_x000D_ Naphtha_x000D_ (104 tons) | S1: 润滑油_x000D_ (万吨)_x000D_ Lubricants_x000D_ (104 tons) | T1: 石蜡_x000D_ (万吨)_x000D_ Paraffin_x000D_ Waxes_x000D_ (104 tons) | U1: 溶剂油_x000D_ (万吨)_x000D_ White Spirit_x000D_ (104 tons) | V1: 石油沥青_x000D_ (万吨)_x000D_ Bitumen_x000D_ Asphalt_x000D_ (104 tons) | W1: 石油焦_x000D_ (万吨)_x000D_ Petroleum_x000D_ Coke_x000D_ (104 tons) | X1: 液化石油气_x000D_ (万吨)_x000D_ Liquefied_x000D_ Petroleum Gas_x000D_ (104 tons) | Y1: 炼厂干气_x000D_ (万吨)_x000D_ Refinery_x000D_ Gas_x000D_ (104 tons) | Z1: 其他石油制品_x000D_ (万吨)_x000D_ Other Petroleum_x000D_ Products_x000D_ (104 tons) | AA1: 天然气_x000D_ (亿立方米)_x000D_ Natural Gas_x000D_ (108 cu.m) | AB1: 液化天然气_x000D_ (万吨)_x000D_ Liquefied_x000D_ Natural Gas_x000D_ (104 tons) | AC1: 热力_x000D_ (万百万千焦)_x000D_ Heat_x000D_ (1010 kJ) | AD1: 电力_x000D_ (亿千瓦小时)_x000D_ Electricity_x000D_ (108 kW·h) | AE1: 其他能源_x000D_ (万吨标准煤)_x000D_ Other Energy_x000D_ (104 tce)
A2: 煤炭开采和洗选业 | B2: 2931.16 | C2: 1628.55 | E2: 1297.11 | F2: 48.92 | G2: 1.04 | H2: 25.03 | I2: 0.72 | J2: 1.42 | K2: 6.5 | L2: 351.52 | M2: 0.22 | N2: 4.95 | O2: 0.75 | P2: 152.6 | Q2: 0.27 | R2: 149.36 | S2: 1.01 | V2: 0.1 | X2: 41.75 | Z2: 0.52 | AA2: 14.35 | AB2: 13.45 | AC2: 705.5 | AD2: 1026.76 | AE2: 2.88
A3: 石油和天然气开采业 | B3: 105.6 | C3: 105.6 | L3: 347.07 | M3: 268.2 | N3: 6.99 | P3: 40.56 | Q3: 0.87 | S3: 0.01 | X3: 0.13 | Y3: 12.82 | Z3: 17.51 | AA3: 132.38 | AB3: 4.59 | AC3: 2778.26 | AD3: 434.44
A4: 黑色金属矿采选业 | B4: 175.95 | C4: 167.23 | E4: 5.54 | F4: 147.75 | G4: 3.17 | H4: 18.22 | I4: 0.56 | K4: 0.17 | L4: 43.64 | N4: 0.81 | P4: 42.54 | Q4: 0.05 | S4: 0.23 | AA4: 0.02 | AC4: 162.15 | AD4: 419.28 | AE4: 1.04
A5: 有色金属矿采选业 | B5: 80.3 | C5: 77.93 | E5: 1.84 | F5: 3.57 | L5: 25.06 | N5: 1.64 | O5: 0.46 | P5: 21.82 | Q5: 0.96 | S5: 0.03 | V5: 0.15 | AA5: 0.66 | AC5: 0.09 | AD5: 386.17 | AE5: 2.41
A6: 非金属矿采选业 | B6: 509.68 | C6: 247.69 | E6: 256.97 | F6: 7.74 | G6: 1.1 | I6: 1.39 | L6: 57.14 | N6: 1.05 | O6: 0.02 | P6: 53.79 | Q6: 0.04 | S6: 0.05 | V6: 0.6 | W6: 1.53 | X6: 0.01 | Z6: 0.05 | AA6: 0.62 | AB6: 7.24 | AC6: 2247.71 | AD6: 257.36 | AE6: 0.19
A7: 开采专业及辅助性活动 | B7: 6.95 | C7: 6.95 | L7: 158.72 | M7: 0.1 | N7: 3.82 | P7: 153.85 | Q7: 0.3 | S7: 0.28 | X7: 0.08 | Z7: 0.29 | AA7: 2.38 | AB7: 0.38 | AC7: 277.93 | AD7: 41.3
A8: 其他采矿业 | B8: 0.12 | C8: 0.12 | L8: 0.11 | P8: 0.1 | AD8: 211.62
A9: 农副食品加工业 | B9: 952.96 | C9: 929.67 | E9: 21.32 | F9: 124.44 | G9: 0.03 | H9: 26.33 | I9: 2.1 | J9: 0.16 | K9: 0.01 | L9: 33.01 | N9: 7.09 | O9: 0.09 | P9: 21.51 | Q9: 1.51 | S9: 0.09 | T9: 0.03 | U9: 1.5 | X9: 0.95 | Z9: 0.24 | AA9: 3.86 | AB9: 198.52 | AC9: 7615.31 | AD9: 797.43 | AE9: 221.48
A10: 食品制造业 | B10: 912.52 | C10: 906.34 | E10: 1.13 | F10: 1.57 | L10: 15.51 | N10: 4.21 | P10: 8.26 | Q10: 1.12 | T10: 0.41 | X10: 1.17 | Z10: 0.33 | AA10: 12.87 | AB10: 82.51 | AC10: 7297.6 | AD10: 301.94 | AE10: 39.14
A11: 酒、饮料和精制茶制造业 | B11: 523.51 | C11: 516.79 | E11: 5.74 | F11: 0.08 | G11: 0.03 | K11: 0.01 | L11: 8.81 | N11: 2.89 | O11: 0.06 | P11: 4.77 | Q11: 0.36 | S11: 0.01 | X11: 0.68 | Z11: 0.04 | AA11: 9.92 | AB11: 48.46 | AC11: 5461.59 | AD11: 173.56 | AE11: 13.23
A12: 烟草制品业 | B12: 6.57 | C12: 6.09 | E12: 0.44 | L12: 1.47 | N12: 0.38 | P12: 1.04 | X12: 0.05 | AA12: 1.21 | AC12: 257.7 | AD12: 52.91 | AE12: 2.52
A13: 纺织业 | B13: 417.78 | C13: 374.64 | E13: 6.41 | F13: 1.19 | I13: 0.01 | L13: 19.13 | N13: 5.59 | O13: 0.03 | P13: 5.91 | Q13: 3.45 | S13: 0.1 | V13: 1.56 | X13: 1.54 | Z13: 0.95 | AA13: 14.83 | AB13: 217.53 | AC13: 32377.38 | AD13: 1760.15 | AE13: 65.49
A14: 纺织服装、服饰业 | B14: 36.67 | C14: 35.95 | E14: 0.43 | F14: 0.05 | L14: 11.4 | N14: 4.89 | O14: 0.05 | P14: 5.37 | Q14: 0.49 | S14: 0.01 | X14: 0.37 | Z14: 0.22 | AA14: 1.31 | AB14: 68.93 | AC14: 593.54 | AD14: 231.59 | AE14: 8.27
A15: 皮革、毛皮、羽毛及其制品和制鞋业 | B15: 21.78 | C15: 20.18 | E15: 0.09 | L15: 5.7 | N15: 2.86 | O15: 0.01 | P15: 1.94 | Q15: 0.34 | R15: 0.01 | S15: 0.05 | T15: 0.04 | U15: 0.12 | X15: 0.29 | Z15: 0.04 | AA15: 0.12 | AB15: 14.82 | AC15: 227.8 | AD15: 156.81 | AE15: 9.7
A16: 木材加工和木、竹、藤、棕、草制品业 | B16: 48.66 | C16: 47.78 | E16: 0.88 | F16: 0.05 | L16: 9.07 | N16: 1.7 | P16: 5.21 | Q16: 0.21 | S16: 0.04 | T16: 1.71 | X16: 0.21 | AA16: 2.63 | AB16: 1.84 | AC16: 671.94 | AD16: 279.32 | AE16: 104.92
A17: 家具制造业 | B17: 2.09 | C17: 1.8 | E17: 0.26 | F17: 0.54 | L17: 5.82 | N17: 2.4 | P17: 2.99 | Q17: 0.14 | S17: 0.01 | X17: 0.27 | AA17: 1.35 | AB17: 2.34 | AC17: 60.67 | AD17: 115.36 | AE17: 5.01
A18: 造纸和纸制品业 | B18: 715.5 | C18: 654.92 | E18: 39.31 | F18: 0.23 | G18: 0.09 | L18: 27.98 | M18: 0.03 | N18: 2.51 | O18: 0.01 | P18: 14.99 | Q18: 8.01 | S18: 0.1 | T18: 0.03 | U18: 0.3 | X18: 1.9 | Z18: 0.09 | AA18: 4.86 | AB18: 123.83 | AC18: 21416.18 | AD18: 744.61 | AE18: 90.62
A19: 印刷和记录媒介复制业 | B19: 15.39 | C19: 14.67 | E19: 0.33 | F19: 0.02 | G19: 0.07 | J19: 0.09 | L19: 9.06 | N19: 3.59 | O19: 0.01 | P19: 4.22 | Q19: 0.4 | S19: 0.03 | U19: 0.05 | X19: 0.41 | Z19: 0.35 | AA19: 3.4 | AB19: 11.47 | AC19: 488.67 | AD19: 131.05 | AE19: 9.07
A20: 文教、工美、体育和娱乐用品制造业 | B20: 14.47 | C20: 13.69 | E20: 0.37 | F20: 0.43 | L20: 20.34 | N20: 3.31 | O20: 0.11 | P20: 3.49 | Q20: 0.46 | R20: 0.01 | S20: 0.02 | T20: 0.53 | U20: 0.01 | W20: 11.56 | X20: 0.67 | Z20: 0.18 | AA20: 2.97 | AB20: 80.6 | AC20: 86.85 | AD20: 89.78 | AE20: 5.89
A21: 石油、煤炭及其他燃料加工业 | B21: 2588.48 | C21: 1309.11 | E21: 1151.35 | F21: 52.92 | G21: 208.3 | H21: 97.9 | J21: 11.26 | K21: 143.22 | L21: 9293.13 | M21: 55.95 | N21: 1.42 | O21: 0.18 | P21: 22.54 | Q21: 27.38 | R21: 1390.01 | S21: 219.89 | T21: 0.06 | U21: 6.03 | V21: 4.87 | W21: 230.56 | X21: 1057.39 | Y21: 1739.05 | Z21: 4537.82 | AA21: 26.77 | AB21: 835.63 | AC21: 63440.85 | AD21: 1198.93 | AE21: 6.16
A22: 化学原料和化学制品制造业 | B22: 11986.77 | C22: 11475.78 | E22: 175.06 | F22: 3955.42 | G22: 79.54 | H22: 9 | I22: 10.06 | J22: 22.56 | K22: 624.81 | L22: 7269.24 | M22: 1.35 | N22: 12.09 | O22: 1.9 | P22: 37.97 | Q22: 44.02 | R22: 4207.62 | S22: 5.29 | T22: 252.74 | U22: 82.44 | V22: 1.52 | W22: 51.52 | X22: 1058.99 | Y22: 75.47 | Z22: 1436.3 | AA22: 206.99 | AB22: 1379.26 | AC22: 145178.14 | AD22: 5427.38 | AE22: 90.95
A23: 医药制造业 | B23: 468.86 | C23: 461.02 | E23: 1.92 | F23: 1.95 | G23: 0.37 | K23: 0.08 | L23: 13.7 | M23: 0.03 | N23: 3.92 | O23: 0.01 | P23: 5.73 | Q23: 2.72 | R23: 0.03 | T23: 0.03 | U23: 0.23 | X23: 0.21 | Z23: 0.78 | AA23: 7.46 | AB23: 53.64 | AC23: 10234.32 | AD23: 407.71 | AE23: 25.21
A24: 化学纤维制造业 | B24: 584.87 | C24: 478.34 | E24: 4.74 | F24: 18.57 | L24: 2.87 | N24: 0.61 | O24: 0.02 | P24: 1.64 | Q24: 0.38 | S24: 0.05 | U24: 0.04 | X24: 0.06 | Z24: 0.07 | AA24: 1.71 | AB24: 90.04 | AC24: 11473.54 | AD24: 455.15 | AE24: 12.62
A25: 橡胶和塑料制品业 | B25: 261.77 | C25: 244.32 | E25: 2.53 | F25: 0.03 | G25: 0.62 | K25: 5.33 | L25: 32.62 | M25: 0.01 | N25: 9.45 | O25: 0.06 | P25: 11.9 | Q25: 3.38 | S25: 0.45 | T25: 0.43 | U25: 0.41 | V25: 1.54 | X25: 2.26 | Z25: 2.73 | AA25: 7.95 | AB25: 63.03 | AC25: 3139.12 | AD25: 1426.38 | AE25: 16.28
A26: 非金属矿物制品业 | B26: 22238.05 | C26: 13725.93 | E26: 8413.71 | F26: 1340.43 | G26: 35.94 | H26: 42.5 | I26: 5.62 | J26: 8.56 | K26: 22.25 | L26: 3189.68 | M26: 0.1 | N26: 14.75 | O26: 0.83 | P26: 314.07 | Q26: 96.29 | S26: 0.59 | T26: 0.73 | U26: 0.16 | V26: 241.25 | W26: 2446.51 | X26: 61.41 | Y26: 0.11 | Z26: 12.87 | AA26: 36.98 | AB26: 1024.69 | AC26: 2518.62 | AD26: 3760.64 | AE26: 90.04
A27: 黑色金属冶炼和压延加工业 | B27: 9211.61 | C27: 8451.73 | E27: 669.94 | F27: 39247.4 | G27: 343.31 | H27: 8060.77 | I27: 556.61 | J27: 1.51 | K27: 304.58 | L27: 87.38 | N27: 3.35 | O27: 0.02 | P27: 52.53 | Q27: 0.64 | S27: 0.77 | T27: 0.02 | W27: 18.02 | X27: 9.6 | Y27: 1.58 | Z27: 0.85 | AA27: 46.6 | AB27: 654.5 | AC27: 19472.74 | AD27: 6459.68 | AE27: 101.48
A28: 有色金属冶炼和压延加工业 | B28: 2361.87 | C28: 2098.02 | E28: 256.64 | F28: 406.15 | G28: 19.34 | I28: 0.08 | J28: 89.53 | K28: 20.62 | L28: 332.3 | M28: 0.3 | N28: 3.39 | O28: 0.54 | P28: 33.38 | Q28: 13.82 | S28: 0.42 | U28: 0.1 | V28: 10.01 | W28: 262.09 | X28: 3.24 | Z28: 5.01 | AA28: 20.75 | AB28: 256.51 | AC28: 21858.02 | AD28: 6673.67 | AE28: 5.96
A29: 金属制品业 | B29: 255.08 | C29: 203.46 | E29: 50.46 | F29: 469.08 | G29: 4.55 | H29: 48.79 | I29: 2.22 | J29: 0.53 | K29: 2.61 | L29: 39.75 | N29: 11.6 | O29: 0.45 | P29: 19.52 | Q29: 1.6 | S29: 0.59 | T29: 0.02 | U29: 0.02 | V29: 0.32 | X29: 4.33 | Y29: 0.01 | Z29: 1.28 | AA29: 11.68 | AB29: 372.68 | AC29: 637.35 | AD29: 1672.84 | AE29: 4.88
A30: 通用设备制造业 | B30: 18.99 | C30: 17.21 | E30: 0.8 | F30: 244.56 | G30: 0.15 | H30: 0.08 | I30: 0.05 | L30: 46.46 | N30: 15.29 | O30: 1.62 | P30: 21.25 | Q30: 0.7 | R30: 0.03 | S30: 2.92 | T30: 0.08 | U30: 0.04 | X30: 2.8 | Z30: 1.73 | AA30: 10.36 | AB30: 82.5 | AC30: 343.7 | AD30: 1007.43 | AE30: 5.11
A31: 专用设备制造业 | B31: 20.01 | C31: 17.18 | E31: 1.5 | F31: 6.54 | G31: 1.34 | H31: 2.34 | J31: 3.51 | K31: 0.57 | L31: 37.97 | N31: 11.84 | O31: 0.77 | P31: 14.46 | Q31: 0.64 | S31: 2.89 | T31: 0.04 | U31: 0.08 | X31: 3.62 | Z31: 3.64 | AA31: 4.85 | AB31: 113.88 | AC31: 955.3 | AD31: 499.42 | AE31: 5.42
A32: 汽车制造业 | B32: 21.53 | C32: 20.87 | E32: 0.11 | F32: 14.23 | G32: 0.06 | H32: 0.03 | I32: 0.01 | J32: 0.18 | L32: 65.68 | M32: 0.01 | N32: 24.72 | O32: 0.27 | P32: 26.95 | Q32: 0.32 | R32: 0.01 | S32: 9.25 | T32: 0.01 | U32: 0.13 | V32: 0.01 | X32: 2.07 | Z32: 1.94 | AA32: 7.29 | AB32: 140.31 | AC32: 2982.62 | AD32: 1031.41 | AE32: 3.01
A33: 铁路、船舶、航空航天和其他运输设备制造业 | B33: 41.15 | C33: 20.35 | E33: 20.8 | F33: 0.28 | G33: 0.46 | J33: 0.01 | L33: 19.08 | M33: 0.01 | N33: 3.5 | O33: 0.95 | P33: 11.25 | Q33: 1.39 | S33: 0.23 | X33: 1.34 | Z33: 0.41 | AA33: 4.98 | AB33: 123.53 | AC33: 666.6 | AD33: 166.18 | AE33: 0.3
A34: 电气机械和器材制造业 | B34: 16.17 | C34: 16.05 | E34: 0.07 | F34: 0.56 | G34: 0.02 | L34: 35.46 | N34: 14.94 | O34: 0.42 | P34: 10.72 | Q34: 2.07 | S34: 1.81 | T34: 0.15 | U34: 0.05 | V34: 0.04 | W34: 0.38 | X34: 3.4 | Z34: 1.48 | AA34: 3.42 | AB34: 61.56 | AC34: 1414.4 | AD34: 859.31 | AE34: 6.19
A35: 计算机、通信和其他电子设备制造业 | B35: 17.03 | C35: 15.92 | E35: 1.11 | G35: 0.01 | H35: 0.01 | L35: 19.39 | N35: 9.59 | O35: 0.15 | P35: 6.43 | Q35: 0.41 | S35: 0.66 | T35: 0.02 | U35: 0.02 | X35: 1.96 | Z35: 0.14 | AA35: 11.61 | AB35: 164.44 | AC35: 1558.86 | AD35: 1500.45 | AE35: 2.26
A36: 仪器仪表制造业 | B36: 1.92 | C36: 1.92 | F36: 0.01 | L36: 5.52 | N36: 3.84 | O36: 0.12 | P36: 1.01 | Q36: 0.09 | S36: 0.1 | T36: 0.03 | X36: 0.17 | Z36: 0.15 | AA36: 0.52 | AB36: 3.94 | AC36: 57.44 | AD36: 74.53 | AE36: 1.47
A37: 其他制造业 | B37: 1.98 | C37: 1.45 | E37: 0.17 | G37: 0.01 | K37: 0.75 | L37: 4.94 | N37: 0.68 | O37: 0.08 | P37: 1.13 | X37: 3.04 | AA37: 0.04 | AB37: 31.96 | AC37: 68.84 | AD37: 578.41 | AE37: 1.04
A38: 废弃资源综合利用业 | B38: 132.4 | C38: 105.97 | E38: 19.47 | F38: 97.06 | G38: 0.51 | H38: 5.3 | I38: 2.1 | K38: 1.17 | L38: 6.81 | N38: 0.31 | O38: 0.02 | P38: 4.83 | Q38: 1.32 | S38: 0.02 | X38: 0.31 | AA38: 2.19 | AB38: 123.44 | AC38: 19.73 | AD38: 57.94 | AE38: 5.87
A39: 金属制品、机械和设备修理业 | B39: 0.5 | C39: 0.5 | G39: 0.07 | H39: 0.14 | L39: 6.17 | M39: 0.01 | N39: 0.44 | O39: 0.93 | P39: 4.4 | Q39: 0.31 | S39: 0.05 | X39: 0.02 | AA39: 0.21 | AB39: 2.98 | AC39: 14.9 | AD39: 16.56
A40: 电力、热力生产和供应业 | B40: 948.29 | C40: 945.4 | E40: 2.29 | F40: 39.08 | G40: 0.82 | H40: 0.21 | J40: 1.3 | K40: 0.43 | L40: 64.26 | M40: 0.17 | N40: 21.5 | P40: 28.23 | Q40: 0.9 | S40: 0.27 | V40: 2.47 | W40: 8.8 | X40: 0.03 | Y40: 1.51 | Z40: 0.38 | AA40: 1.25 | AC40: 9585.94 | AD40: 5703.13 | AE40: 10.76
...

Sheet 能源平衡表
A1: 项 目 | B1: 煤合计_x000D_ (万吨)_x000D_ Coal Total_x000D_ (104 tons) | C1: 原煤_x000D_ (万吨)_x000D_ Raw Coal_x000D_ (104 tons) | D1: 洗精煤_x000D_ (万吨)_x000D_ Cleaned_x000D_ Coal_x000D_ (104 tons) | E1: 其他洗煤_x000D_ (万吨)_x000D_ Other_x000D_ Washed_x000D_ Coal_x000D_ (104 tons) | F1: 煤制品_x000D_ (万吨)_x000D_ Briquettes_x000D_ (104 tons) | G1: 煤矸石_x000D_ (万吨)_x000D_ Gangue_x000D_ (104 tons) | H1: 焦炭_x000D_ (万吨)_x000D_ Coke_x000D_ (104 tons) | I1: 焦炉煤气_x000D_ (亿立方米)_x000D_ Coke Oven_x000D_ Gas_x000D_ (108 cu.m) | J1: 高炉煤气_x000D_ (亿立方米)_x000D_ Blast Furnace_x000D_ Gas_x000D_ (108 cu.m) | K1: 转炉煤气_x000D_ (亿立方米)_x000D_ Converter_x000D_ Gas_x000D_ (108 cu.m) | L1: 其他煤气_x000D_ (亿立方米)_x000D_ Other Gas_x000D_ (108 cu.m) | M1: 其他焦化产品_x000D_ (万吨)_x000D_ Other_x000D_ Coking_x000D_ Products_x000D_ (104 tons) | N1: 油品合计_x000D_ (万吨)_x000D_ Petroleum_x000D_ Products_x000D_ Total_x000D_ (104 tons) | O1: 原油_x000D_ (万吨)_x000D_ Crude Oil_x000D_ (104 tons) | P1: 汽油_x000D_ (万吨)_x000D_ Gasoline_x000D_ (104 tons) | Q1: 煤油_x000D_ (万吨)_x000D_ Kerosene_x000D_ (104 tons) | R1: 柴油_x000D_ (万吨)_x000D_ Diesel Oil_x000D_ (104 tons) | S1: 燃料油_x000D_ (万吨)_x000D_ Fuel Oil_x000D_ (104 tons) | T1: 石脑油_x000D_ (万吨)_x000D_ Naphtha_x000D_ (104 tons) | U1: 润滑油_x000D_ (万吨)_x000D_ Lubricants_x000D_ (104 tons) | V1: 石蜡_x000D_ (万吨)_x000D_ Paraffin_x000D_ Waxes_x000D_ (104 tons) | W1: 溶剂油_x000D_ (万吨)_x000D_ White Spirit_x000D_ (104 tons) | X1: 石油沥青_x000D_ (万吨)_x000D_ Bitumen_x000D_ Asphalt_x000D_ (104 tons) | Y1: 石油焦_x000D_ (万吨)_x000D_ Petroleum_x000D_ Coke_x000D_ (104 tons) | Z1: 液化石油气_x000D_ (万吨)_x000D_ Liquefied_x000D_ Petroleum Gas_x000D_ (104 tons) | AA1: 炼厂干气_x000D_ (万吨)_x000D_ Refinery_x000D_ Gas_x000D_ (104 tons) | AB1: 其他石油制品_x000D_ (万吨)_x000D_ Other_x000D_ Petroleum_x000D_ Products_x000D_ (104 tons) | AC1: 天然气_x000D_ (亿立方米)_x000D_ Natural Gas_x000D_ (108 cu.m) | AD1: 液化天然气_x000D_ (万吨)_x000D_ Liquefied_x000D_ Natural Gas_x000D_ (104 tons) | AE1: 热力_x000D_ (万百万千焦)_x000D_ Heat_x000D_ (1010 kJ) | AF1: 电力_x000D_ (亿千瓦小时)_x000D_ Electricity_x000D_ (108 kW·h) | AG1: 其他能源_x000D_ (万吨标准煤)_x000D_ Other_x000D_ Energy_x000D_ (104 tce)
A2: 一.可供本地区消费的能源量 | B2: 405537.18 | C2: 404267.01 | D2: 1359.01 | E2: -70 | F2: -18.84 | H2: -762.13 | N2: 66900.85 | O2: 68007.48 | P2: -1190.41 | Q2: -1319.79 | R2: -1948.68 | S2: 344.98 | T2: 657.9 | U2: 17.85 | V2: -35.93 | W2: 4.32 | X2: 274.38 | Y2: 590.42 | Z2: 1950.61 | AB2: -452.28 | AC2: 2227.84 | AD2: 6011.71 | AF2: 22664.83 | AG2: 7164.43
A3: 1.一次能源生产量 | B3: 384633.2 | C3: 384633.2 | N3: 19101.41 | O3: 19101.41 | AC3: 1761.74 | AF3: 22832.8 | AG3: 7164.43
A4: 水电 | AF4: 13044.38
A5: 核电 | AF5: 3483.55
A6: 风电 | AF6: 4060.32
A7: 2.进口量 | B7: 29976.88 | C7: 29976.88 | H7: 52.3 | N7: 56970.47 | O7: 50567.6 | P7: 33.34 | Q7: 366.75 | R7: 119.02 | S7: 1485.51 | T7: 702.22 | U7: 29.16 | V7: 9.85 | W7: 3.77 | X7: 428.39 | Y7: 830.52 | Z7: 2109.33 | AB7: 285 | AC7: 501.14 | AD7: 6019.12 | AF7: 48.58
A8: 3.境内飞机和轮船在境外的加油量 | N8: 1131.69 | Q8: 563.28 | R8: 25.44 | S8: 542.97
A9: 4.出口量(-) | B9: 602.86 | C9: 599.37 | F9: 3.5 | H9: 652.26 | N9: 7251.41 | O9: 81 | P9: 1637.06 | Q9: 1761.48 | R9: 2138.26 | S9: 1117.66 | U9: 11.25 | V9: 60.17 | W9: 0.26 | X9: 65.62 | Y9: 228.96 | Z9: 140.89 | AB9: 8.79 | AC9: 35.03 | AD9: 7.4 | AF9: 216.55
A10: 5.境外飞机和轮船在境内的加油量(-) | N10: 959.95 | Q10: 478.33 | R10: 50.81 | S10: 430.81
A11: 6.库存增(-)、减(+)量 | B11: -8470.04 | C11: -9743.71 | D11: 1359.01 | E11: -70 | F11: -15.34 | H11: -162.17 | N11: -2091.35 | O11: -1580.53 | P11: 413.31 | Q11: -10.02 | R11: 95.93 | S11: -135.04 | T11: -44.32 | U11: -0.06 | V11: 14.39 | W11: 0.81 | X11: -88.39 | Y11: -11.13 | Z11: -17.83 | AB11: -728.49
A12: 二.加工转换投入(-)产出(+)量 | B12: -328465.29 | C12: -341871.85 | D12: -1847.3 | E12: 13863.38 | F12: 1390.48 | G12: -16.05 | H12: 47206.48 | I12: 685.06 | J12: 8106.13 | K12: 587.04 | L12: 183.26 | M12: 1077.95 | N12: -3453.63 | O12: -66907.95 | P12: 14852.09 | Q12: 5322.59 | R12: 17195.94 | S12: 2111.07 | T12: 5096.12 | U12: 230.11 | V12: 302.72 | W12: 8236 | X12: 2970.43 | Y12: 2425.3 | Z12: 3606.75 | AA12: 1846.02 | AB12: 7412.81 | AC12: -676.86 | AD12: 900.26 | AE12: 550106.3 | AF12: 52201.48 | AG12: -967.2
A13: 1.火力发电 | B13: -210158.99 | C13: -205517.23 | E13: -4641.77 | G13: -2467.05 | H13: -25.3 | I13: -208.01 | J13: -2451.35 | K13: -329.03 | L13: -0.13 | N13: -308.27 | O13: -16.01 | R13: -24.18 | S13: -13.94 | T13: -12.01 | Y13: -181.18 | Z13: -0.11 | AA13: -52.59 | AB13: -8.25 | AC13: -391.87 | AD13: -231.28 | AE13: -111630.52 | AF13: 52201.48 | AG13: -1567.97
A14: 2.供热 | B14: -34441.79 | C14: -33027.91 | E14: -1413.87 | G14: -646.29 | H14: -47.51 | I14: -62.54 | J14: -573.41 | K14: -45.52 | L14: -1.2 | N14: -653.79 | P14: -0.05 | R14: -5.3 | S14: -60.21 | T14: -163.1 | Y14: -224.18 | Z14: -4.05 | AA14: -173.99 | AB14: -22.9 | AC14: -143.19 | AD14: -33.51 | AE14: 565138.68 | AG14: -391.96
A15: 3.煤炭洗选 | B15: -12213.46 | C15: -87588.72 | D15: 53863.4 | E15: 21511.86 | G15: 3097.3
A16: 4.炼焦 | B16: -65672.62 | C16: -9961.92 | D16: -55710.7 | H16: 47295.8 | I16: 955.61 | M16: 1387.39
A17: 5.炼油及煤制油 | B17: -3239.84 | C17: -3087.01 | E17: -152.83 | M17: -309.44 | N17: 9842.42 | O17: -66891.93 | P17: 14880.68 | Q17: 5322.59 | R17: 17308.27 | S17: 4506.05 | T17: 6620.07 | U17: 232.36 | V17: 308.88 | W17: 82.36 | X17: 3313.86 | Y17: 2838.81 | Z17: 4210.01 | AA17: 2187.92 | AB17: 14922.52 | AC17: -32.35 | AG17: -138.98
A18: #油品再投入量(-) | N18: -12330.3 | P18: -28.54 | R18: -82.86 | S18: -2320.83 | T18: -1348.83 | U18: -2.25 | V18: -6.15 | X18: -343.42 | Y18: -8.15 | Z18: -595.4 | AA18: -115.31 | AB18: -7478.56
A19: 6.制气 | B19: -2458.7 | C19: -2293.81 | E19: -164.89 | L19: 184.58 | N19: -3.69 | Z19: -3.69 | AC19: 64.73
A20: #焦炭再投入量(-) | H20: -16.51
A21: 7.天然气液化 | K21: -0.12 | AC21: -174.19 | AD21: 1165.05
A22: 8.煤制品加工 | B22: -279.88 | C22: -395.25 | E22: -1275.11 | F22: 1390.48
A23: 9.回收能 | J23: 11130.88 | K23: 961.71 | AE23: 96598.13 | AG23: 1131.7
A24: 三.损失量 | N24: 34.46 | O24: 33.83 | Z24: 0.63 | AC24: 20.95 | AD24: 6.26 | AE24: 5297.62 | AF24: 3330.1
A25: 四.终端消费量 | B25: 73449.39 | C25: 58985.75 | E25: 13101.54 | F25: 1362.1 | H25: 46336.64 | I25: 710.6 | J25: 8339.48 | K25: 581.53 | L25: 190.06 | M25: 1133.12 | N25: 61018.45 | O25: 326.5 | P25: 13599.38 | Q25: 3950.23 | R25: 14805.62 | S25: 2295.37 | T25: 5747.08 | U25: 248.37 | V25: 257.1 | W25: 91.74 | X25: 3256.43 | Y25: 3030.97 | Z25: 5462.48 | AA25: 1830.56 | AB25: 6116.62 | AC25: 1531.78 | AD25: 6909.09 | AE25: 54480839 | AF25: 71536.02 | AG25: 6091.03
A26: 1.农、林、牧、渔业 | B26: 2202.07 | C26: 2110.86 | E26: 91.21 | H26: 59.67 | N26: 1748.2 | P26: 253.18 | Q26: 10.95 | R26: 1475.05 | S26: 1.19 | Z26: 7.82 | AC26: 1.24 | AE26: 69.88 | AF26: 1336.2 | AG26: 675.84
A27: 2.工业 | B27: 58802.35 | C27: 45514.41 | E27: 12410.86 | F27: 877.09 | H27: 46230.86 | I27: 701.86 | J27: 8339.48 | K27: 581.53 | L27: 140.92 | M27: 1133.12 | N27: 21732.37 | O27: 326.5 | P27: 233.41 | Q27: 10.97 | R27: 1178.27 | S27: 217.56 | T27: 5747.08 | U27: 248.37 | V27: 257.1 | W27: 91.74 | X27: 264.42 | Y27: 3030.97 | Z27: 2266.99 | AA27: 1830.56 | AB27: 6028.41 | AC27: 631.02 | AD27: 6508.45 | AE27: 380696.5 | AF27: 47368.2 | AG27: 976.87
A28: #用作原料、材料 | B28: 12689.15 | C28: 10880.31 | E28: 1738.76 | F28: 70.08 | H28: 1474.76 | M28: 448.04 | N28: 11507.24 | P28: 2.15 | Q28: 1.17 | R28: 17.4 | S28: 31.3 | T28: 5505.3 | U28: 227.2 | V28: 252.77 | W28: 88.61 | X28: 206.89 | Y28: 2276.35 | Z28: 503.89 | AA28: 50.35 | AB28: 2343.85 | AC28: 92.44 | AD28: 94.35
A29: 3.建筑业 | B29: 639.81 | C29: 596.64 | E29: 43.17 | H29: 9.7 | N29: 4055.13 | P29: 499.89 | Q29: 16.03 | R29: 530.27 | S29: 31.84 | X29: 2874.87 | Z29: 14.03 | AB29: 88.21 | AC29: 2.81 | AE29: 2300.23 | AF29: 991.19 | AG29: 30.41
A30: 4.交通运输、仓储和邮政业 | B30: 282.61 | C30: 263.5 | E30: 19.11 | H30: 0.36 | N30: 22099.75 | P30: 6244.92 | Q30: 3689.21 | R30: 9867.31 | S30: 2025.31 | X30: 117.14 | Z30: 155.85 | AC30: 274.62 | AD30: 400.64 | AE30: 4152.02 | AF30: 1752.34 | AG30: 1486.9
A31: 5.批发和零售业、住宿和餐饮业 | B31: 2377.77 | C31: 2309.25 | E31: 39.92 | F31: 28.59 | H31: 16.91 | I31: 0.95 | L31: 9.43 | N31: 608.41 | P31: 287.95 | Q31: 15.47 | R31: 203.88 | S31: 10.22 | Z31: 90.89 | AC31: 62.46 | AE31: 9533.06 | AF31: 3187.1 | AG31: 67.01
A32: 6.其他 | B32: 2598.18 | C32: 2500.19 | E32: 89.23 | F32: 8.76 | H32: 6.32 | I32: 1.23 | N32: 3460.61 | P32: 2240.92 | Q32: 184.17 | R32: 954.04 | S32: 9.25 | Z32: 72.23 | AC32: 57.32 | AE32: 19224.64 | AF32: 6263.78 | AG32: 271.88
A33: 7.居民生活 | B33: 6546.6 | C33: 5690.91 | E33: 408.04 | F33: 447.65 | H33: 12.81 | I33: 6.56 | L33: 39.71 | N33: 7313.99 | P33: 3839.1 | Q33: 23.43 | R33: 596.79 | Z33: 2854.67 | AC33: 502.32 | AE33: 128832.05 | AF33: 10637.21 | AG33: 2582.12
A34: 城镇 | B34: 800.99 | C34: 623.77 | E34: 55.82 | F34: 121.4 | H34: 2.9 | I34: 5.02 | L34: 39.55 | N34: 4960.36 | P34: 2570.09 | Q34: 0.36 | R34: 274.46 | Z34: 2115.45 | AC34: 497.4 | AE34: 128832.05 | AF34: 5838.25 | AG34: 242.26
A35: 乡村 | B35: 5745.61 | C35: 5067.14 | E35: 352.22 | F35: 326.25 | H35: 9.91 | I35: 1.54 | L35: 0.16 | N35: 2353.63 | P35: 1269.01 | Q35: 23.07 | R35: 322.33 | Z35: 739.22 | AC35: 4.92 | AF35: 4798.96 | AG35: 2339.86
A36: 五.平衡差额 | B36: 3622.5 | C36: 3409.41 | D36: -488.29 | E36: 691.85 | F36: 9.54 | G36: -16.05 | H36: 107.72 | I36: -25.54 | J36: -23336 | K36: 5.51 | L36: -6.81 | M36: -55.16 | N36: 2394.31 | O36: 739.21 | P36: 62.3 | Q36: 52.56 | R36: 441.65 | S36: 160.68 | T36: 6.93 | U36: -0.41 | V36: 9.7 | W36: -5,07 | X36: -11.62 | Y36: -15.24 | Z36: 94.25 | AA36: 15.46 | AB36: 843.91 | AC36: -1.75 | AD36: -338 | AE36: 0.29 | AF36: 0.19 | AG36: 106.2
A37: 六.消费量合计 | B37: 401914.68 | C37: 400857.6 | D37: 55710.7 | E37: 20750.01 | F37: 1362.1 | G37: 3113.34 | H37: 46425.96 | I37: 981.15 | J37: 11364.24 | K37: 956.08 | L37: 19139 | M37: 1442.56 | N37: 64506.54 | O37: 67268.27 | P37: 13627.97 | Q37: 3950.23 | R37: 14917.95 | S37: 4690.34 | T37: 7271.04 | U37: 259.63 | V37: 263.25 | W37: 91.74 | X37: 3599.85 | Y37: 3444.47 | Z37: 6066.37 | AA37: 2172.45 | AB37: 1362633 | AC37: 2068.82 | AD37: 7180.14 | AE37: 661736.52 | AF37: 74866.12 | AG37: 8189.93

Sheet 总量
A1: 行 业 | B1: 2012 | C1: 2013 | D1: 2014 | E1: 2015 | F1: 2016 | G1: 2017 | H1: 2018 | I1: 2019 | J1: 2020
A2: 煤炭开采和洗选业 | B2: 15083 | C2: 14180 | D2: 11376 | E2: 10399 | F2: 9436 | G2: 9646 | H2: 9983 | I2: 10133 | J2: 8953
A3: 石油和天然气开采业 | B3: 3897 | C3: 4088 | D3: 4263 | E3: 4269 | F3: 3916 | G3: 3956 | H3: 3818 | I3: 3755 | J3: 3743
A4: 黑色金属矿采选业 | B4: 2065 | C4: 2224 | D4: 2169 | E4: 1663 | F4: 1458 | G4: 1537 | H4: 1566 | I4: 1660 | J4: 1728
A5: 有色金属矿采选业 | B5: 1231 | C5: 1280 | D5: 1266 | E5: 1177 | F5: 1076 | G5: 1106 | H5: 1253 | I5: 1258 | J5: 1090
A6: 非金属矿采选业 | B6: 1469 | C6: 1380 | D6: 1401 | E6: 1297 | F6: 1260 | G6: 1185 | H6: 1312 | I6: 1324 | J6: 1126
A7: 开采专业及辅助性活动 | B7: 481 | C7: 407 | D7: 397 | E7: 337 | F7: 286 | G7: 321 | H7: 464 | I7: 470 | J7: 322
A8: 其他采矿业 | B8: 305 | C8: 365 | D8: 414 | E8: 348 | F8: 341 | G8: 347 | H8: 584 | I8: 633 | J8: 488
A9: 农副食品加工业 | B9: 3784 | C9: 3905 | D9: 4138 | E9: 4266 | F9: 4241 | G9: 4145 | H9: 4036 | I9: 4126 | J9: 4002
A10: 食品制造业 | B10: 1841 | C10: 1890 | D10: 1833 | E10: 1840 | F10: 1976 | G10: 1965 | H10: 1959 | I10: 2042 | J10: 2148
A11: 酒、饮料和精制茶制造业 | B11: 1498 | C11: 1610 | D11: 1522 | E11: 1501 | F11: 1496 | G11: 1403 | H11: 1317 | I11: 1283 | J11: 1199
A12: 烟草制品业 | B12: 257 | C12: 256 | D12: 238 | E12: 230 | F12: 206 | G12: 200 | H12: 198 | I12: 192 | J12: 180
... A45: 一次能源生产总量 | B45: 351041 | C45: 358784 | D45: 362212 | E45: 362193 | F45: 345954 | G45: 358867 | H45: 378859 | I45: 397317 | J45: 407295
A46: 回收能
A47: 进口量 | B47: 68701 | C47: 73420 | D47: 78027 | E47: 77695 | F47: 90235 | G47: 100039 | H47: 110787 | I47: 119064 | J47: 124805
A48: 出口量(-) | B48: 7374 | C48: 8005 | D48: 8270 | E48: 9785 | F48: 11956 | G48: 12669 | H48: 13337 | I48: 14151 | J48: 12838
A49: 年初年末库存差额 | B49: -4773 | C49: -6784 | D49: -4540 | E49: 1532 | F49: 9888 | G49: 4206 | H49: -4623 | I49: -9052 | J49: -11784
A50: 能源消费总量 | B50: 402138 | C50: 416913 | D50: 428334 | E50: 434113 | F50: 441492 | G50: 455827 | H50: 471925 | I50: 487488 | J50: 498314
A51: 在总量中:
A52: 1.农、林、牧、渔业 | B52: 7804 | C52: 8055 | D52: 8020 | E52: 8271 | F52: 8585 | G52: 8945 | H52: 8781 | I52: 9018 | J52: 9263
A53: 2.工业 | B53: 284712 | C53: 291130 | D53: 298449 | E53: 295953 | F53: 295615 | G53: 302308 | H53: 311151 | I53: 322503 | J53: 332625
A54: 3.建筑业 | B54: 6337 | C54: 7017 | D54: 7377 | E54: 7545 | F54: 7847 | G54: 8243 | H54: 8685 | I54: 9142 | J54: 9320
A55: 4.交通运输、仓储和邮政业 | B55: 32561 | C55: 34819 | D55: 36343 | E55: 38510 | F55: 39883 | G55: 42140 | H55: 43617 | I55: 43909 | J55: 41309
A56: 5.批发和零售业、住宿和餐饮业 | B56: 10012 | C56: 10598 | D56: 10864 | E56: 11447 | F56: 12042 | G56: 12456 | H56: 12994 | I56: 13624 | J56: 13171
A57: 6.其他 | B57: 18407 | C57: 19763 | D57: 20069 | E57: 21925 | F57: 23185 | G57: 24277 | H57: 26262 | I57: 27582 | J57: 28245
A58: 7.居民生活 | B58: 42306 | C58: 45531 | D58: 47211 | E58: 50461 | F58: 54336 | G58: 57459 | H58: 60436 | I58: 61709 | J58: 64380
A59: 在总量中:
A60: (一)终端消费 | B60: 386888 | C60: 403814 | D60: 415456 | E60: 420110 | F60: 428342 | G60: 442255 | H60: 461020 | I60: 476219 | J60: 488156
A61: #工业 | B61: 269900 | C61: 278514 | D61: 285948 | E61: 282291 | F61: 282809 | G61: 289098 | H61: 300558 | I61: 311542 | J61: 322677
A62: (二)加工转换损失量 | B62: 16763 | C62: 15994 | D62: 17270 | E62: 18770 | F62: 18674 | G62: 19279 | H62: 20803 | I62: 22156 | J62: 23020
A63: #炼焦 | B63: 2179 | C63: 2433 | D63: 3540 | E63: 4261 | F63: 3887 | G63: 3721 | H63: 4129 | I63: 4209 | J63: 3938
A64: 炼油及煤制油 | B64: 2153 | C64: 1899 | D64: 2115 | E64: 2866 | F64: 3543 | G64: 4280 | H64: 5027 | I64: 5895 | J64: 6132
A65: (三)回收能(-) | B65: 11239 | C65: 13333 | D65: 14578 | E65: 14492 | F65: 15373 | G65: 15921 | H65: 20465 | I65: 21350 | J65: 23037
A66: (四)损失量 | B66: 9726 | C66: 10439 | D66: 10186 | E66: 9724 | F66: 9849 | G66: 10213 | H66: 10567 | I66: 10462 | J66: 10175
A67: 平衡差额 | B67: 5456 | C67: 502 | D67: -904 | E67: -2477 | F67: -7371 | G67: -5383 | H67: -239 | I67: 5690 | J67: 9165

Sheet 煤炭
A1: 行 业 | B1: 2012 | C1: 2013 | D1: 2014 | E1: 2015 | F1: 2016 | G1: 2017 | H1: 2018 | I1: 2019 | J1: 2020
A2: 煤炭开采和洗选业 | B2: 40786 | C2: 36772 | D2: 33174 | E2: 29103 | F2: 23793 | G2: 23874 | H2: 24234 | I2: 22140 | J2: 16886
A3: 石油和天然气开采业 | B3: 495 | C3: 481 | D3: 195 | E3: 186 | F3: 174 | G3: 131 | H3: 122 | I3: 112 | J3: 72
A4: 黑色金属矿采选业 | B4: 438 | C4: 481 | D4: 440 | E4: 378 | F4: 283 | G4: 245 | H4: 222 | I4: 198 | J4: 205
A5: 有色金属矿采选业 | B5: 220 | C5: 206 | D5: 203 | E5: 199 | F5: 120 | G5: 105 | H5: 137 | I5: 93 | J5: 85
A6: 非金属矿采选业 | B6: 973 | C6: 1037 | D6: 997 | E6: 819 | F6: 774 | G6: 662 | H6: 753 | I6: 742 | J6: 540
A7: 开采专业及辅助性活动 | B7: 186 | C7: 185 | D7: 159 | E7: 116 | F7: 97 | G7: 88 | H7: 595 | I7: 564 | J7: 63
A8: 其他采矿业 | B8: 2 | C8: 3 | D8: 2 | E8: 2 | F8: 5 | G8: 1 | J8: 8
A9: 农副食品加工业 | B9: 3302 | C9: 3211 | D9: 2779 | E9: 2601 | F9: 2570 | G9: 2234 | H9: 1871 | I9: 1720 | J9: 1577
A10: 食品制造业 | B10: 1866 | C10: 1961 | D10: 1814 | E10: 1617 | F10: 1679 | G10: 1526 | H10: 1619 | I10: 1642 | J10: 1639
A11: 酒、饮料和精制茶制造业 | B11: 1479 | C11: 1587 | D11: 1326 | E11: 1185 | F11: 1091 | G11: 956 | H11: 690 | I11: 619 | J11: 497
A12: 烟草制品业 | B12: 67 | C12: 62 | D12: 52 | E12: 43 | F12: 28 | G12: 22 | H12: 15 | I12: 7 | J12: 5
A13: 纺织业 | B13: 3053 | C13: 2896 | D13: 2460 | E13: 4729 | F13: 4211 | G13: 3308 | H13: 951 | I13: 790 | J13: 592
A14: 纺织服装、服饰业 | B14: 347 | C14: 315 | D14: 297 | E14: 257 | F14: 214 | G14: 142 | H14: 57 | I14: 45 | J14: 49
A15: 皮革、毛皮、羽毛及其制品和制鞋业 | B15: 202 | C15: 185 | D15: 162 | E15: 155 | F15: 135 | G15: 94 | H15: 33 | I15: 22 | J15: 18
A16: 木材加工和木、竹、藤、棕、草制品业 | B16: 662 | C16: 621 | D16: 520 | E16: 467 | F16: 326 | G16: 217 | H16: 108 | I16: 90 | J16: 40
A17: 家具制造业 | B17: 76 | C17: 71 | D17: 61 | E17: 57 | F17: 42 | G17: 17 | H17: 5 | I17: 2 | J17: 2
A18: 造纸和纸制品业 | B18: 5271 | C18: 5303 | D18: 4829 | E18: 4669 | F18: 4603 | G18: 4586 | H18: 4272 | I18: 3942 | J18: 3545
A19: 印刷和记录媒介复制业 | B19: 64 | C19: 69 | D19: 82 | E19: 81 | F19: 84 | G19: 46 | H19: 66 | I19: 62 | J19: 60
A20: 文教、工美、体育和娱乐用品制造业 | B20: 98 | C20: 110 | D20: 130 | E20: 124 | F20: 114 | G20: 75 | H20: 33 | I20: 14 | J20: 10
... A38: 废弃资源综合利用业 | B38: 68 | C38: 63 | D38: 65 | E38: 61 | F38: 68 | G38: 49 | H38: 60 | I38: 132 | J38: 333
A39: 金属制品、机械和设备修理业 | B39: 11 | C39: 13 | D39: 5 | E39: 5 | F39: 4 | G39: 3 | J39: 1
A40: 电力、热力生产和供应业 | B40: 181090 | C40: 189848 | D40: 177098 | E40: 165422 | F40: 169441 | G40: 183107 | H40: 192239 | I40: 201798 | J40: 211123
A41: 燃气生产和供应业 | B41: 1075 | C41: 935 | D41: 720 | E41: 570 | F41: 383 | G41: 730 | H41: 1318 | I41: 1707 | J41: 2057
A42: 水的生产和供应业 | B42: 64 | C42: 57 | D42: 45 | E42: 51 | F42: 22 | G42: 23 | H42: 27 | I42: 20 | J42: 22
A44: 可供量 | B44: 418654 | C44: 425015 | D44: 411834 | E44: 397074 | F44: 378494 | G44: 383480 | H44: 394848 | I44: 405537 | J44: 414519
A45: 生产量 | B45: 394513 | C45: 397432 | D45: 387392 | E45: 374654 | F45: 341060 | G45: 352356 | H45: 369774 | I45: 384633 | J45: 390158
A46: 进口量 | B46: 28841 | C46: 32702 | D46: 29122 | E46: 20406 | F46: 25555 | G46: 27093 | H46: 28210 | I46: 29977 | J46: 30361
A47: 出口量(-) | B47: 927 | C47: 751 | D47: 574 | E47: 534 | F47: 879 | G47: 809 | H47: 494 | I47: 603 | J47: 319
A48: 年初年末库存差额 | B48: -3772 | C48: -4368 | D48: -4106 | E48: 2547 | F48: 12758 | G48: 4839 | H48: -2642 | I48: -8470 | J48: -5680
A49: 消费量 | B49: 411727 | C49: 424426 | D49: 413633 | E49: 399834 | F49: 388820 | G49: 391403 | H49: 397452 | I49: 401915 | J49: 404860
A50: 在消费量中:
A51: 1.农、林、牧、渔业 | B51: 2266 | C51: 2451 | D51: 2479 | E51: 2625 | F51: 2778 | G51: 2834 | H51: 2363 | I51: 2202 | J51: 2254
A52: 2.工业 | B52: 391191 | C52: 403157 | D52: 392567 | E52: 378190 | F52: 367435 | G52: 371160 | H52: 380696 | I52: 387268 | J52: 390891
A53: 3.建筑业 | B53: 767 | C53: 811 | D53: 914 | E53: 878 | F53: 805 | G53: 733 | H53: 650 | I53: 640 | J53: 639
A54: 4.交通运输、仓储和邮政业 | B54: 614 | C54: 615 | D54: 558 | E54: 492 | F54: 404 | G54: 353 | H54: 321 | I54: 283 | J54: 241
A55: 5.批发和零售业、住宿和餐饮业 | B55: 3752 | C55: 3966 | D55: 3767 | E55: 3864 | F55: 3826 | G55: 3461 | H55: 2686 | I55: 2378 | J55: 1981
A56: 6.其他 | B56: 3883 | C56: 4136 | D56: 4046 | E56: 4159 | F56: 4081 | G56: 3580 | H56: 3021 | I56: 2598 | J56: 2571
A57: 7.居民生活 | B57: 9253 | C57: 9290 | D57: 9303 | E57: 9627 | F57: 9492 | G57: 9283 | H57: 7714 | I57: 6547 | J57: 6283
A58: 在消费量中:
...

Sheet 焦炭
B1: Sector Energy Consumption including Energy Conversion | L1: Sector Final Energy Consumption excluding Energy Conversion
A2: 行 业 | B2: 2012 | C2: 2013 | D2: 2014 | E2: 2015 | F2: 2016 | G2: 2017 | H2: 2018 | I2: 2019 | J2: 2020 | K2: difference | L2: 2012 | M2: 2013 | N2: 2014 | O2: 2015 | P2: 2016 | Q2: 2017 | R2: 2018 | S2: 2019 | T2: 2020
A3: 煤炭开采和洗选业 | B3: 65 | C3: 80 | D3: 88 | E3: 63 | F3: 75 | G3: 75 | H3: 34 | I3: 49 | J3: 11 | K3: =SUM(B3:J3)/SUM(L3:T3) -> 1.0103467 | L3: 65.41 | M3: 80.45 | N3: 87.92 | O3: 63 | P3: 75.21 | Q3: 74.92 | R3: 33.73 | S3: 48.92 | T3: 4.91 | U3: =CORREL(L$44:T$44,L3:T3) -> 0.33417319
A4: 石油和天然气开采业 | K4: =SUM(B4:J4)/SUM(L4:T4) -> #DIV/0! | U4: =CORREL(L$44:T$44,L4:T4) -> #DIV/0!
A5: 黑色金属矿采选业 | B5: 126 | C5: 180 | D5: 187 | E5: 158 | F5: 153 | G5: 116 | H5: 128 | I5: 148 | J5: 170 | K5: =SUM(B5:J5)/SUM(L5:T5) -> 1.0004028 | L5: 125.54 | M5: 180.04 | N5: 187.01 | O5: 157.54 | P5: 153.48 | Q5: 116.48 | R5: 127.98 | S5: 147.75 | T5: 169.63 | U5: =CORREL(L$44:T$44,L5:T5) -> 0.43879014
A6: 有色金属矿采选业 | B6: 14 | C6: 10 | D6: 10 | E6: 9 | F6: 5 | G6: 3 | H6: 4 | I6: 4 | J6: 4 | K6: =SUM(B6:J6)/SUM(L6:T6) -> 1.0217321 | L6: 13.81 | M6: 10.22 | N6: 9.84 | O6: 8.67 | P6: 4.75 | Q6: 3.49 | R6: 3.66 | S6: 3.57 | T6: 3.65 | U6: =CORREL(L$44:T$44,L6:T6) -> 0.045001359
A7: 非金属矿采选业 | B7: 46 | C7: 11 | D7: 7 | E7: 7 | F7: 10 | G7: 8 | H7: 9 | I7: 8 | J7: 15 | K7: =SUM(B7:J7)/SUM(L7:T7) -> 1.0032336 | L7: 46.1 | M7: 11.05 | N7: 7.39 | O7: 7.03 | P7: 10.02 | Q7: 8.01 | R7: 8.54 | S7: 7.74 | T7: 14.73 | U7: =CORREL(L$44:T$44,L7:T7) -> -0.16649575
A8: 开采专业及辅助性活动 | K8: =SUM(B8:J8)/SUM(L8:T8) -> 0 | M8: 0.02 | N8: 0.03 | O8: 0.03 | P8: 0.02 | U8: =CORREL(L$44:T$44,L8:T8) -> -0.50711145
A9: 其他采矿业 | K9: =SUM(B9:J9)/SUM(L9:T9) -> #DIV/0! | U9: =CORREL(L$44:T$44,L9:T9) -> #DIV/0!
A10: 农副食品加工业 | B10: 12 | C10: 10 | D10: 10 | E10: 141 | F10: 143 | G10: 138 | H10: 137 | I10: 125 | J10: 16 | K10: =SUM(B10:J10)/SUM(L10:T10) -> 1.0048596 | L10: 11.52 | M10: 9.94 | N10: 9.87 | O10: 141.25 | P10: 142.7 | Q10: 137.64 | R10: 137.1 | S10: 124.44 | T10: 14 | U10: =CORREL(L$44:T$44,L10:T10) -> 0.052975525
A11: 食品制造业 | B11: 2 | C11: 2 | D11: 3 | E11: 3 | F11: 2 | G11: 2 | H11: 1 | I11: 2 | J11: 16 | K11: =SUM(B11:J11)/SUM(L11:T11) -> 1.7286537 | L11: 1.9 | M11: 2.27 | N11: 2.77 | O11: 3.09 | P11: 2.17 | Q11: 2.36 | R11: 1.12 | S11: 1.57 | T11: 1.84 | U11: =CORREL(L$44:T$44,L11:T11) -> 0.50048223
A12: 酒、饮料和精制茶制造业 | B12: 1 | C12: 1 | D12: 1 | E12: 1 | F12: 1 | G12: 1 | J12: 4 | K12: =SUM(B12:J12)/SUM(L12:T12) -> 1.5503876 | L12: 0.97 | M12: 0.9 | N12: 1.39 | O12: 1.18 | P12: 0.92 | Q12: 0.85 | R12: 0.15 | S12: 0.08 | T12: 0.01 | U12: =CORREL(L$44:T$44,L12:T12) -> 0.438294
A13: 烟草制品业 | K13: =SUM(B13:J13)/SUM(L13:T13) -> #DIV/0! | U13: =CORREL(L$44:T$44,L13:T13) -> #DIV/0!
A14: 纺织业 | B14: 3 | C14: 3 | D14: 2 | E14: 2 | F14: 1 | G14: 1 | H14: 2 | I14: 3 | J14: 6 | K14: =SUM(B14:J14)/SUM(L14:T14) -> 1.1575239 | L14: 3.08 | M14: 2.81 | N14: 2.07 | O14: 1.93 | P14: 1.42 | Q14: 1.39 | R14: 2.05 | S14: 1.19 | T14: 3.93 | U14: =CORREL(L$44:T$44,L14:T14) -> -0.08938045
A15: 纺织服装、服饰业 | B15: 3 | C15: 2 | D15: 1 | E15: 2 | F15: 2 | G15: 1 | K15: =SUM(B15:J15)/SUM(L15:T15) -> 1.1375388 | L15: 2.69 | M15: 1.58 | N15: 1.13 | O15: 1.59 | P15: 1.86 | Q15: 0.65 | R15: 0.08 | S15: 0.05 | T15: 0.04 | U15: =CORREL(L$44:T$44,L15:T15) -> 0.44029024
A16: 皮革、毛皮、羽毛及其制品和制鞋业 | B16: 1 | C16: 1 | D16: 1 | K16: =SUM(B16:J16)/SUM(L16:T16) -> 0.96463023 | L16: 0.8 | M16: 0.81 | N16: 0.74 | O16: 0.34 | P16: 0.35 | Q16: 0.07 | U16: =CORREL(L$44:T$44,L16:T16) -> -0.18909804
A17: 木材加工和木、竹、藤、棕、草制品业 | D17: 1 | E17: 1 | F17: 1 | I17: 2 | K17: =SUM(B17:J17)/SUM(L17:T17) -> 0.9596929 | L17: 0.37 | M17: 0.39 | N17: 1.31 | O17: 1.43 | P17: 1.17 | Q17: 0.43 | R17: 0.05 | S17: 0.05 | T17: 0.01 | U17: =CORREL(L$44:T$44,L17:T17) -> 0.663262
A18: 家具制造业 | B18: 4 | C18: 2 | D18: 2 | E18: 2 | F18: 1 | G18: 1 | H18: 1 | I18: 1 | K18: =SUM(B18:J18)/SUM(L18:T18) -> 1.0502626 | L18: 3.79 | M18: 2.39 | N18: 1.67 | O18: 1.89 | P18: 1.43 | Q18: 0.74 | R18: 0.82 | S18: 0.54 | T18: 0.06 | U18: =CORREL(L$44:T$44,L18:T18) -> 0.079442312
A19: 造纸和纸制品业 | B19: 1 | C19: 1 | D19: 1 | E19: 1 | F19: 1 | J19: 30 | K19: =SUM(B19:J19)/SUM(L19:T19) -> 2.829426 | L19: 0.51 | M19: 0.61 | N19: 0.83 | O19: 0.77 | P19: 0.99 | Q19: 0.47 | R19: 0.03 | S19: 0.23 | T19: 7.93 | U19: =CORREL(L$44:T$44,L19:T19) -> 0.15662081
A20: 印刷和记录媒介复制业 | K20: =SUM(B20:J20)/SUM(L20:T20) -> 0 | L20: 0.33 | M20: 0.27 | N20: 0.46 | O20: 0.49 | P20: 0.48 | Q20: 0.36 | R20: 0.16 | S20: 0.02 | T20: 0.02 | U20: =CORREL(L$44:T$44,L20:T20) -> 0.56131128
A21: 文教、工美、体育和娱乐用品制造业 | B21: 5 | C21: 4 | D21: 4 | E21: 3 | F21: 3 | G21: 4 | H21: 2 | K21: =SUM(B21:J21)/SUM(L21:T21) -> 0.97427903 | L21: 4.67 | M21: 4.08 | N21: 3.94 | O21: 3.33 | P21: 3.15 | Q21: 3.97 | R21: 1.65 | S21: 0.43 | T21: 0.44 | U21: =CORREL(L$44:T$44,L21:T21) -> 0.22806458
A22: 石油、煤炭及其他燃料加工业 | B22: 74 | C22: 68 | D22: 46 | E22: 65 | F22: 32 | G22: 41 | H22: 56 | I22: 71 | J22: 59 | K22: =SUM(B22:J22)/SUM(L22:T22) -> 1.0898255 | L22: 73.65 | M22: 67.53 | N22: 46.39 | O22: 64.81 | P22: 31.66 | Q22: 41.33 | R22: 34.99 | S22: 52.92 | T22: 56.52 | U22: =CORREL(L$44:T$44,L22:T22) -> -0.2001525
A23: 化学原料和化学制品制造业 | B23: 3105 | C23: 3200 | D23: 3419 | E23: 3579 | F23: 3997 | G23: 3674 | H23: 3744 | I23: 4014 | J23: 4289 | K23: =SUM(B23:J23)/SUM(L23:T23) -> 1.0099909 | L23: 3104.7776 | M23: 3200.0165 | N23: 3382.02 | O23: 3576.25 | P23: 3997.23 | Q23: 3674.38 | R23: 3744.32 | S23: 3955.42 | T23: 4059.94 | U23: =CORREL(L$44:T$44,L23:T23) -> 0.20989347
A24: 医药制造业 | B24: 2 | C24: 1 | D24: 1 | E24: 1 | F24: 1 | G24: 2 | H24: 2 | I24: 3 | J24: 6 | K24: =SUM(B24:J24)/SUM(L24:T24) -> 1.380814 | L24: 1.62 | M24: 0.99 | N24: 0.77 | O24: 0.79 | P24: 0.92 | Q24: 1.52 | R24: 1.74 | S24: 1.95 | T24: 3.46 | U24: =CORREL(L$44:T$44,L24:T24) -> -0.34120061
A25: 化学纤维制造业 | B25: 1 | F25: 17 | G25: 17 | H25: 18 | I25: 20 | J25: 3 | K25: =SUM(B25:J25)/SUM(L25:T25) -> 1.0614525 | L25: 0.54 | M25: 0.25 | N25: 0.36 | O25: 0.32 | P25: 17.16 | Q25: 16.79 | R25: 17.54 | S25: 18.57 | T25: 0.07 | U25: =CORREL(L$44:T$44,L25:T25) -> -0.10830007
A26: 橡胶和塑料制品业 | B26: 4 | C26: 3 | D26: 5 | E26: 3 | F26: 2 | G26: 1 | J26: 2 | K26: =SUM(B26:J26)/SUM(L26:T26) -> 0.94831674 | L26: 4.12 | M26: 3.32 | N26: 4.71 | O26: 3.46 | P26: 2.05 | Q26: 1.22 | R26: 0.2 | S26: 0.03 | T26: 1.98 | U26: =CORREL(L$44:T$44,L26:T26) -> 0.34783952
A27: 非金属矿物制品业 | B27: 987 | C27: 1048 | D27: 1040 | E27: 904 | F27: 881 | G27: 773 | H27: 966 | I27: 1340 | J27: 1464 | K27: =SUM(B27:J27)/SUM(L27:T27) -> 1.000033 | L27: 986.74 | M27: 1047.55 | N27: 1039.94 | O27: 904.24 | P27: 881.4 | Q27: 773.28 | R27: 965.96 | S27: 1340.43 | T27: 1463.15 | U27: =CORREL(L$44:T$44,L27:T27) -> -0.18923405
A28: 黑色金属冶炼和压延加工业 | B28: 38367 | C28: 39313 | D28: 40146 | E28: 37336 | F28: 38439 | G28: 37521 | H28: 37152 | I28: 39247 | J28: 40335 | K28: =SUM(B28:J28)/SUM(L28:T28) -> 1.0016122 | L28: 38331.523 | M28: 39294.194 | N28: 39924.9 | O28: 37057.27 | P28: 38433.09 | Q28: 37520.6 | R28: 37151.72 | S28: 39247.4 | T28: 40335.4 | U28: =CORREL(L$44:T$44,L28:T28) -> 0.17682807
A29: 有色金属冶炼和压延加工业 | B29: 617 | C29: 586 | D29: 622 | E29: 565 | F29: 528 | G29: 518 | H29: 403 | I29: 406 | J29: 490 | K29: =SUM(B29:J29)/SUM(L29:T29) -> 1.0351265 | L29: 593.35 | M29: 574.34 | N29: 588.01 | O29: 564.52 | P29: 527.98 | Q29: 517.75 | R29: 402.56 | S29: 406.15 | T29: 399.66 | U29: =CORREL(L$44:T$44,L29:T29) -> 0.37451069
A30: 金属制品业 | B30: 104 | C30: 141 | D30: 100 | E30: 100 | F30: 66 | G30: 60 | H30: 450 | I30: 469 | J30: 589 | K30: =SUM(B30:J30)/SUM(L30:T30) -> 0.99920218 | L30: 104.25 | M30: 141.36 | N30: 100.19 | O30: 100.19 | P30: 66.2 | Q30: 60.38 | R30: 449.91 | S30: 469.08 | T30: 589.1 | U30: =CORREL(L$44:T$44,L30:T30) -> -0.44264888
A31: 通用设备制造业 | B31: 839 | C31: 695 | D31: 699 | E31: 684 | F31: 686 | G31: 444 | H31: 328 | I31: 245 | J31: 412 | K31: =SUM(B31:J31)/SUM(L31:T31) -> 1.0000656 | L31: 838.92 | M31: 694.73 | N31: 698.51 | O31: 684.25 | P31: 686.2 | Q31: 444.39 | R31: 328.03 | S31: 244.56 | T31: 412.08 | U31: =CORREL(L$44:T$44,L31:T31) -> 0.49823833
A32: 专用设备制造业 | B32: 45 | C32: 54 | D32: 75 | E32: 68 | F32: 71 | G32: 64 | H32: 20 | I32: 7 | K32: =SUM(B32:J32)/SUM(L32:T32) -> 1.0017357 | L32: 45.41 | M32: 53.5 | N32: 74.5 | O32: 67.91 | P32: 71.13 | Q32: 63.87 | R32: 20.44 | S32: 6.54 | U32: =CORREL(L$44:T$44,L32:T32) -> 0.69521186
A33: 汽车制造业 | B33: 185 | C33: 199 | D33: 162 | E33: 129 | F33: 123 | G33: 69 | H33: 31 | I33: 14 | J33: 12 | K33: =SUM(B33:J33)/SUM(L33:T33) -> 0.99912414 | L33: 185.01 | M33: 198.93 | N33: 162.38 | O33: 129.32 | P33: 123.4 | Q33: 69.2 | R33: 31.11 | S33: 14.23 | T33: 11.23 | U33: =CORREL(L$44:T$44,L33:T33) -> 0.3525602
A34: 铁路、船舶、航空航天和其他运输设备制造业 | B34: 12 | C34: 8 | D34: 7 | E34: 3 | F34: 2 | G34: 1 | H34: 1 | K34: =SUM(B34:J34)/SUM(L34:T34) -> 0.98981077 | L34: 12.33 | M34: 8 | N34: 7.28 | O34: 2.72 | P34: 1.57 | Q34: 1.19 | R34: 0.58 | S34: 0.28 | T34: 0.4 | U34: =CORREL(L$44:T$44,L34:T34) -> -0.025091134
A35: 电气机械和器材制造业 | B35: 18 | C35: 17 | D35: 14 | E35: 12 | F35: 7 | G35: 5 | H35: 2 | I35: 1 | J35: 1 | K35: =SUM(B35:J35)/SUM(L35:T35) -> 1.0024736 | L35: 17.9 | M35: 17.43 | N35: 14.13 | O35: 12 | P35: 6.91 | Q35: 5.43 | R35: 1.75 | S35: 0.56 | T35: 0.7 | U35: =CORREL(L$44:T$44,L35:T35) -> 0.19494577
A36: 计算机、通信和其他电子设备制造业 | B36: 9 | C36: 11 | D36: 12 | E36: 14 | F36: 14 | G36: 13 | K36: =SUM(B36:J36)/SUM(L36:T36) -> 0.99360283 | L36: 8.64 | M36: 10.74 | N36: 12.4 | O36: 14.31 | P36: 14.31 | Q36: 13 | R36: 0.05 | T36: 0.02 | U36: =CORREL(L$44:T$44,L36:T36) -> 0.55562399
A37: 仪器仪表制造业 | B37: 4 | C37: 5 | D37: 4 | E37: 3 | F37: 2 | G37: 1 | K37: =SUM(B37:J37)/SUM(L37:T37) -> 1.0106383 | L37: 4.17 | M37: 5.25 | N37: 4.35 | O37: 2.69 | P37: 1.75 | Q37: 0.51 | R37: 0.07 | S37: 0.01 | U37: =CORREL(L$44:T$44,L37:T37) -> 0.28534751
A38: 其他制造业 | B38: 1 | F38: 3 | G38: 2 | K38: =SUM(B38:J38)/SUM(L38:T38) -> 1 | L38: 0.5 | M38: 0.33 | N38: 0.25 | O38: 0.25 | P38: 2.58 | Q38: 2.03 | T38: 0.06 | U38: =CORREL(L$44:T$44,L38:T38) -> 0.51570133
A39: 废弃资源综合利用业 | B39: 20 | C39: 26 | D39: 27 | E39: 22 | F39: 16 | G39: 10 | H39: 31 | I39: 97 | J39: 69 | K39: =SUM(B39:J39)/SUM(L39:T39) -> 1.003028 | L39: 20.04 | M39: 25.65 | N39: 26.71 | O39: 21.67 | P39: 16.11 | Q39: 9.92 | R39: 31.03 | S39: 97.06 | T39: 68.85 | U39: =CORREL(L$44:T$44,L39:T39) -> -0.30635239
A40: 金属制品、机械和设备修理业 | B40: 12 | K40: =SUM(B40:J40)/SUM(L40:T40) -> 0.9375 | L40: 12.47 | M40: 0.12 | N40: 0.09 | O40: 0.05 | P40: 0.04 | Q40: 0.03 | U40: =CORREL(L$44:T$44,L40:T40) -> -0.43753528
...

Sheet 原油
B1: Sector Energy Consumption including Energy Conversion | L1: Sector Final Energy Consumption excluding Energy Conversion
A2: 行 业 | B2: 2012 | C2: 2013 | D2: 2014 | E2: 2015 | F2: 2016 | G2: 2017 | H2: 2018 | I2: 2019 | J2: 2020 | K2: difference | L2: 2012 | M2: 2013 | N2: 2014 | O2: 2015 | P2: 2016 | Q2: 2017 | R2: 2018 | S2: 2019 | T2: 2020
A3: 煤炭开采和洗选业 | C3: 0.04 | D3: 0.09 | E3: 0.03 | F3: 0.01 | G3: 0.06 | H3: 13.92 | I3: 0.22 | J3: 0.08 | K3: =SUM(B3:J3)/SUM(L3:T3) -> 24.491525 | P3: 0.01 | Q3: 0.06 | R3: 0.22 | S3: 0.22 | T3: 0.08 | U3: =CORREL(L$44:T$44,L3:T3) -> #DIV/0!
A4: 石油和天然气开采业 | B4: 1050.41 | C4: 1034.66 | D4: 1034.61 | E4: 987.5 | F4: 740.82 | G4: 713.31 | H4: 612.23 | I4: 636.91 | J4: 609.94 | K4: =SUM(B4:J4)/SUM(L4:T4) -> 2.2715874 | L4: 463.1 | M4: 482.34 | N4: 468.86 | O4: 440.4 | P4: 320.11 | Q4: 297.86 | R4: 278.23 | S4: 268.2 | T4: 247.51 | U4: =CORREL(L$44:T$44,L4:T4) -> 0.41884717
A5: 黑色金属矿采选业 | B5: 0.01 | K5: =SUM(B5:J5)/SUM(L5:T5) -> 1 | L5: 0.01 | U5: =CORREL(L$44:T$44,L5:T5) -> #DIV/0!
A6: 有色金属矿采选业 | F6: 1.23 | K6: =SUM(B6:J6)/SUM(L6:T6) -> 1 | P6: 1.23 | U6: =CORREL(L$44:T$44,L6:T6) -> #DIV/0!
A7: 非金属矿采选业 | K7: =SUM(B7:J7)/SUM(L7:T7) -> #DIV/0! | U7: =CORREL(L$44:T$44,L7:T7) -> #DIV/0!
A8: 开采专业及辅助性活动 | B8: 23.66 | C8: 24.51 | D8: 33.52 | E8: 36.64 | F8: 45.82 | G8: 26.59 | H8: 17.86 | I8: 0.1 | J8: 0.09 | K8: =SUM(B8:J8)/SUM(L8:T8) -> 51.0489 | L8: 0.9 | M8: 0.8 | N8: 1.28 | O8: 0.48 | P8: 0.16 | Q8: 0.16 | R8: 0.12 | S8: 0.1 | T8: 0.09 | U8: =CORREL(L$44:T$44,L8:T8) -> 0.7135608
A9: 其他采矿业 | K9: =SUM(B9:J9)/SUM(L9:T9) -> #DIV/0! | U9: =CORREL(L$44:T$44,L9:T9) -> #DIV/0!
A10: 农副食品加工业 | B10: 0.07 | C10: 0.24 | D10: 0.02 | E10: 0.03 | F10: 0.02 | G10: 0.02 | H10: 0.06 | K10: =SUM(B10:J10)/SUM(L10:T10) -> 1 | L10: 0.07 | M10: 0.24 | N10: 0.02 | O10: 0.03 | P10: 0.02 | Q10: 0.02 | R10: 0.06 | U10: =CORREL(L$44:T$44,L10:T10) -> -0.2662159
A11: 食品制造业 | K11: =SUM(B11:J11)/SUM(L11:T11) -> #DIV/0! | U11: =CORREL(L$44:T$44,L11:T11) -> #DIV/0!
A12: 酒、饮料和精制茶制造业 | B12: 0.01 | K12: =SUM(B12:J12)/SUM(L12:T12) -> 1 | L12: 0.01 | U12: =CORREL(L$44:T$44,L12:T12) -> #DIV/0!
A13: 烟草制品业 | K13: =SUM(B13:J13)/SUM(L13:T13) -> #DIV/0! | U13: =CORREL(L$44:T$44,L13:T13) -> #DIV/0!
A14: 纺织业 | C14: 0.01 | G14: 0.01 | H14: 0.07 | K14: =SUM(B14:J14)/SUM(L14:T14) -> 1 | M14: 0.01 | Q14: 0.01 | R14: 0.07 | U14: =CORREL(L$44:T$44,L14:T14) -> #DIV/0!
A15: 纺织服装、服饰业 | B15: 0.05 | C15: 0.02 | D15: 0.02 | E15: 0.01 | G15: 0.01 | K15: =SUM(B15:J15)/SUM(L15:T15) -> 1 | L15: 0.05 | M15: 0.02 | N15: 0.02 | O15: 0.01 | Q15: 0.01 | U15: =CORREL(L$44:T$44,L15:T15) -> -0.45270151
A16: 皮革、毛皮、羽毛及其制品和制鞋业 | B16: 0.1 | C16: 0.05 | D16: 0.01 | E16: 0.02 | F16: 0.02 | K16: =SUM(B16:J16)/SUM(L16:T16) -> 1 | L16: 0.1 | M16: 0.05 | N16: 0.01 | O16: 0.02 | P16: 0.02 | U16: =CORREL(L$44:T$44,L16:T16) -> -0.54872243
A17: 木材加工和木、竹、藤、棕、草制品业 | B17: 0.17 | C17: 0.16 | D17: 0.33 | E17: 0.04 | F17: 0.01 | K17: =SUM(B17:J17)/SUM(L17:T17) -> 1 | L17: 0.17 | M17: 0.16 | N17: 0.33 | O17: 0.04 | P17: 0.01 | U17: =CORREL(L$44:T$44,L17:T17) -> 0.7679509
A18: 家具制造业 | C18: 0.01 | E18: 0.01 | K18: =SUM(B18:J18)/SUM(L18:T18) -> 1 | M18: 0.01 | O18: 0.01 | U18: =CORREL(L$44:T$44,L18:T18) -> #DIV/0!
A19: 造纸和纸制品业 | B19: 0.1 | C19: 0.09 | D19: 0.05 | E19: 0.04 | F19: 0.04 | G19: 0.04 | H19: 0.03 | I19: 0.03 | J19: 0.03 | K19: =SUM(B19:J19)/SUM(L19:T19) -> 1 | L19: 0.1 | M19: 0.09 | N19: 0.05 | O19: 0.04 | P19: 0.04 | Q19: 0.04 | R19: 0.03 | S19: 0.03 | T19: 0.03 | U19: =CORREL(L$44:T$44,L19:T19) -> -0.33924173
A20: 印刷和记录媒介复制业 | B20: 0.01 | K20: =SUM(B20:J20)/SUM(L20:T20) -> 1 | L20: 0.01 | U20: =CORREL(L$44:T$44,L20:T20) -> #DIV/0!
A21: 文教、工美、体育和娱乐用品制造业 | B21: 0.01 | C21: 0.01 | D21: 0.01 | F21: 0.01 | K21: =SUM(B21:J21)/SUM(L21:T21) -> 1 | L21: 0.01 | M21: 0.01 | N21: 0.01 | P21: 0.01 | U21: =CORREL(L$44:T$44,L21:T21) -> #DIV/0!
A22: 石油、煤炭及其他燃料加工业 | B22: 42413.38 | C22: 44315.76 | D22: 46825.64 | E22: 50191.16 | F22: 52431.24 | G22: 55431.9 | H22: 59673.27 | I22: 63223.31 | J22: 65073.92 | K22: =SUM(B22:J22)/SUM(L22:T22) -> 860.58747 | L22: 52.77 | M22: 55.93 | N22: 72.19 | O22: 71.62 | P22: 66.33 | Q22: 63.45 | R22: 66.78 | S22: 55.95 | T22: 52.25 | U22: =CORREL(L$44:T$44,L22:T22) -> 0.6286905
A23: 化学原料和化学制品制造业 | B23: 3060.77 | C23: 3123.7 | D23: 3656.93 | E23: 3536.22 | F23: 3883.65 | G23: 3220.7 | H23: 2676.96 | I23: 3397.86 | J23: 3791.64 | K23: =SUM(B23:J23)/SUM(L23:T23) -> 28.51894 | L23: 29.76 | M23: 87.66 | N23: 312.4 | O23: 269.4 | P23: 241.47 | Q23: 2.18 | R23: 1.7 | S23: 1.35 | T23: 118.23 | U23: =CORREL(L$44:T$44,L23:T23) -> 0.63727821
A24: 医药制造业 | B24: 0.02 | I24: 0.03 | K24: =SUM(B24:J24)/SUM(L24:T24) -> 1 | L24: 0.02 | S24: 0.03 | U24: =CORREL(L$44:T$44,L24:T24) -> #DIV/0!
A25: 化学纤维制造业 | K25: =SUM(B25:J25)/SUM(L25:T25) -> #DIV/0! | U25: =CORREL(L$44:T$44,L25:T25) -> #DIV/0!
A26: 橡胶和塑料制品业 | B26: 0.04 | C26: 0.02 | D26: 0.01 | E26: 0.04 | F26: 0.04 | I26: 0.01 | J26: 0.05 | K26: =SUM(B26:J26)/SUM(L26:T26) -> 1 | L26: 0.04 | M26: 0.02 | N26: 0.01 | O26: 0.04 | P26: 0.04 | S26: 0.01 | T26: 0.05 | U26: =CORREL(L$44:T$44,L26:T26) -> -0.7928466
A27: 非金属矿物制品业 | B27: 7.78 | C27: 1.08 | D27: 0.17 | E27: 0.21 | F27: 0.21 | G27: 0.42 | H27: 0.46 | I27: 0.1 | J27: 0.37 | K27: =SUM(B27:J27)/SUM(L27:T27) -> 1 | L27: 7.78 | M27: 1.08 | N27: 0.17 | O27: 0.21 | P27: 0.21 | Q27: 0.42 | R27: 0.46 | S27: 0.1 | T27: 0.37 | U27: =CORREL(L$44:T$44,L27:T27) -> -0.41486063
A28: 黑色金属冶炼和压延加工业 | B28: 0.01 | C28: 0.02 | D28: 0.02 | E28: 0.02 | F28: 0.02 | G28: 0.01 | K28: =SUM(B28:J28)/SUM(L28:T28) -> 1 | L28: 0.01 | M28: 0.02 | N28: 0.02 | O28: 0.02 | P28: 0.02 | Q28: 0.01 | U28: =CORREL(L$44:T$44,L28:T28) -> 0.38183294
A29: 有色金属冶炼和压延加工业 | B29: 0.23 | C29: 0.24 | D29: 0.06 | E29: 0.01 | F29: 0.01 | H29: 0.36 | I29: 0.3 | J29: 0.21 | K29: =SUM(B29:J29)/SUM(L29:T29) -> 1 | L29: 0.23 | M29: 0.24 | N29: 0.06 | O29: 0.01 | P29: 0.01 | R29: 0.36 | S29: 0.3 | T29: 0.21 | U29: =CORREL(L$44:T$44,L29:T29) -> -0.29057648
A30: 金属制品业 | B30: 0.01 | C30: 0.02 | D30: 0.01 | E30: 0.01 | F30: 0.01 | G30: 0.01 | H30: 0.01 | K30: =SUM(B30:J30)/SUM(L30:T30) -> 1 | L30: 0.01 | M30: 0.02 | N30: 0.01 | O30: 0.01 | P30: 0.01 | Q30: 0.01 | R30: 0.01 | U30: =CORREL(L$44:T$44,L30:T30) -> -0.1684957
A31: 通用设备制造业 | B31: 0.03 | C31: 0.07 | D31: 0.04 | E31: 0.03 | F31: 0.03 | G31: 0.01 | H31: 0.01 | K31: =SUM(B31:J31)/SUM(L31:T31) -> 1 | L31: 0.03 | M31: 0.07 | N31: 0.04 | O31: 0.03 | P31: 0.03 | Q31: 0.01 | R31: 0.01 | U31: =CORREL(L$44:T$44,L31:T31) -> 0.0707675
A32: 专用设备制造业 | B32: 0.04 | C32: 0.15 | D32: 0.14 | E32: 0.08 | F32: 0.08 | G32: 0.09 | J32: 0.01 | K32: =SUM(B32:J32)/SUM(L32:T32) -> 1 | L32: 0.04 | M32: 0.15 | N32: 0.14 | O32: 0.08 | P32: 0.08 | Q32: 0.09 | T32: 0.01 | U32: =CORREL(L$44:T$44,L32:T32) -> 0.58629212
A33: 汽车制造业 | B33: 0.07 | C33: 0.16 | D33: 0.02 | E33: 0.02 | F33: 0.02 | G33: 0.06 | H33: 0.02 | I33: 0.01 | J33: 0.01 | K33: =SUM(B33:J33)/SUM(L33:T33) -> 1 | L33: 0.07 | M33: 0.16 | N33: 0.02 | O33: 0.02 | P33: 0.02 | Q33: 0.06 | R33: 0.02 | S33: 0.01 | T33: 0.01 | U33: =CORREL(L$44:T$44,L33:T33) -> -0.31295261
A34: 铁路、船舶、航空航天和其他运输设备制造业 | B34: 0.01 | C34: 0.06 | D34: 0.01 | E34: 0.01 | F34: 0.01 | G34: 0.01 | H34: 0.01 | I34: 0.01 | K34: =SUM(B34:J34)/SUM(L34:T34) -> 1 | L34: 0.01 | M34: 0.06 | N34: 0.01 | O34: 0.01 | P34: 0.01 | Q34: 0.01 | R34: 0.01 | S34: 0.01 | U34: =CORREL(L$44:T$44,L34:T34) -> -0.1684957
A35: 电气机械和器材制造业 | B35: 0.07 | C35: 0.07 | D35: 0.01 | G35: 0.02 | H35: 0.01 | K35: =SUM(B35:J35)/SUM(L35:T35) -> 1 | L35: 0.07 | M35: 0.07 | N35: 0.01 | Q35: 0.02 | R35: 0.01 | U35: =CORREL(L$44:T$44,L35:T35) -> -0.9887851
A36: 计算机、通信和其他电子设备制造业 | E36: 0.01 | F36: 0.01 | K36: =SUM(B36:J36)/SUM(L36:T36) -> 1 | O36: 0.01 | P36: 0.01 | U36: =CORREL(L$44:T$44,L36:T36) -> #DIV/0!
A37: 仪器仪表制造业 | C37: 0.01 | D37: 0.01 | E37: 0.01 | F37: 0.01 | G37: 0.01 | K37: =SUM(B37:J37)/SUM(L37:T37) -> 1 | M37: 0.01 | N37: 0.01 | O37: 0.01 | P37: 0.01 | Q37: 0.01 | U37: =CORREL(L$44:T$44,L37:T37) -> #DIV/0!
A38: 其他制造业 | K38: =SUM(B38:J38)/SUM(L38:T38) -> #DIV/0! | U38: =CORREL(L$44:T$44,L38:T38) -> #DIV/0!
A39: 废弃资源综合利用业 | K39: =SUM(B39:J39)/SUM(L39:T39) -> #DIV/0! | U39: =CORREL(L$44:T$44,L39:T39) -> #DIV/0!
A40: 金属制品、机械和设备修理业 | C40: 0.01 | D40: 0.01 | I40: 0.01 | K40: =SUM(B40:J40)/SUM(L40:T40) -> 1 | M40: 0.01 | N40: 0.01 | S40: 0.01 | U40: =CORREL(L$44:T$44,L40:T40) -> #DIV/0!
...

Sheet 煤油
B1: Sector Energy Consumption including Energy Conversion | L1: Sector Final Energy Consumption excluding Energy Conversion
A2: 行 业 | B2: 2012 | C2: 2013 | D2: 2014 | E2: 2015 | F2: 2016 | G2: 2017 | H2: 2018 | I2: 2019 | J2: 2020 | K2: difference | L2: 2012 | M2: 2013 | N2: 2014 | O2: 2015 | P2: 2016 | Q2: 2017 | R2: 2018 | S2: 2019 | T2: 2020
A3: 煤炭开采和洗选业 | B3: 2.16 | C3: 2.43 | D3: 1.89 | E3: 1.72 | F3: 1.59 | G3: 0.81 | H3: 0.67 | I3: 0.75 | J3: 0.61 | K3: =SUM(B3:J3)/SUM(L3:T3) -> 1 | L3: 2.16 | M3: 2.43 | N3: 1.89 | O3: 1.72 | P3: 1.59 | Q3: 0.81 | R3: 0.67 | S3: 0.75 | T3: 0.61 | U3: =CORREL(L$44:T$44,L3:T3) -> 0.85222944
A4: 石油和天然气开采业 | D4: 0.01 | K4: =SUM(B4:J4)/SUM(L4:T4) -> 1 | N4: 0.01 | U4: =CORREL(L$44:T$44,L4:T4) -> #DIV/0!
A5: 黑色金属矿采选业 | B5: 0.03 | C5: 0.04 | D5: 0.02 | E5: 0.07 | F5: 0.05 | G5: 0.02 | J5: 0.01 | K5: =SUM(B5:J5)/SUM(L5:T5) -> 1 | L5: 0.03 | M5: 0.04 | N5: 0.02 | O5: 0.07 | P5: 0.05 | Q5: 0.02 | T5: 0.01 | U5: =CORREL(L$44:T$44,L5:T5) -> 0.27140529
A6: 有色金属矿采选业 | B6: 0.41 | C6: 0.4 | D6: 0.39 | E6: 0.43 | F6: 0.37 | G6: 0.43 | H6: 0.39 | I6: 0.46 | J6: 0.4 | K6: =SUM(B6:J6)/SUM(L6:T6) -> 1 | L6: 0.41 | M6: 0.4 | N6: 0.39 | O6: 0.43 | P6: 0.37 | Q6: 0.43 | R6: 0.39 | S6: 0.46 | T6: 0.4 | U6: =CORREL(L$44:T$44,L6:T6) -> -0.43325261
A7: 非金属矿采选业 | B7: 0.04 | C7: 0.07 | D7: 0.21 | E7: 0.22 | F7: 0.14 | G7: 0.03 | H7: 0.02 | I7: 0.02 | J7: 0.01 | K7: =SUM(B7:J7)/SUM(L7:T7) -> 1 | L7: 0.04 | M7: 0.07 | N7: 0.21 | O7: 0.22 | P7: 0.14 | Q7: 0.03 | R7: 0.02 | S7: 0.02 | T7: 0.01 | U7: =CORREL(L$44:T$44,L7:T7) -> 0.30294671
A8: 开采专业及辅助性活动 | F8: 0.01 | K8: =SUM(B8:J8)/SUM(L8:T8) -> 1 | P8: 0.01 | U8: =CORREL(L$44:T$44,L8:T8) -> #DIV/0!
A9: 其他采矿业 | K9: =SUM(B9:J9)/SUM(L9:T9) -> #DIV/0! | U9: =CORREL(L$44:T$44,L9:T9) -> #DIV/0!
A10: 农副食品加工业 | B10: 0.12 | C10: 0.18 | D10: 0.21 | E10: 0.5 | F10: 0.35 | G10: 0.2 | H10: 0.14 | I10: 0.09 | J10: 0.04 | K10: =SUM(B10:J10)/SUM(L10:T10) -> 1 | L10: 0.12 | M10: 0.18 | N10: 0.21 | O10: 0.5 | P10: 0.35 | Q10: 0.2 | R10: 0.14 | S10: 0.09 | T10: 0.04 | U10: =CORREL(L$44:T$44,L10:T10) -> 0.23318223
A11: 食品制造业 | B11: 0.03 | C11: 0.04 | D11: 0.02 | E11: 0.05 | F11: 0.1 | G11: 0.01 | J11: 0.01 | K11: =SUM(B11:J11)/SUM(L11:T11) -> 1 | L11: 0.03 | M11: 0.04 | N11: 0.02 | O11: 0.05 | P11: 0.1 | Q11: 0.01 | T11: 0.01 | U11: =CORREL(L$44:T$44,L11:T11) -> 0.44268641
A12: 酒、饮料和精制茶制造业 | B12: 0.01 | C12: 0.01 | D12: 0.02 | E12: 0.08 | F12: 0.04 | G12: 0.05 | H12: 0.06 | I12: 0.06 | K12: =SUM(B12:J12)/SUM(L12:T12) -> 1 | L12: 0.01 | M12: 0.01 | N12: 0.02 | O12: 0.08 | P12: 0.04 | Q12: 0.05 | R12: 0.06 | S12: 0.06 | U12: =CORREL(L$44:T$44,L12:T12) -> -0.71073391
A13: 烟草制品业 | K13: =SUM(B13:J13)/SUM(L13:T13) -> #DIV/0! | U13: =CORREL(L$44:T$44,L13:T13) -> #DIV/0!
A14: 纺织业 | B14: 0.12 | C14: 0.16 | D14: 0.07 | E14: 0.15 | F14: 0.07 | G14: 0.05 | H14: 0.02 | I14: 0.03 | J14: 0.01 | K14: =SUM(B14:J14)/SUM(L14:T14) -> 1 | L14: 0.12 | M14: 0.16 | N14: 0.07 | O14: 0.15 | P14: 0.07 | Q14: 0.05 | R14: 0.02 | S14: 0.03 | T14: 0.01 | U14: =CORREL(L$44:T$44,L14:T14) -> 0.71994892
A15: 纺织服装、服饰业 | B15: 0.41 | C15: 0.06 | D15: 0.04 | E15: 0.04 | F15: 0.02 | I15: 0.05 | K15: =SUM(B15:J15)/SUM(L15:T15) -> 1 | L15: 0.41 | M15: 0.06 | N15: 0.04 | O15: 0.04 | P15: 0.02 | S15: 0.05 | U15: =CORREL(L$44:T$44,L15:T15) -> 0.49171207
A16: 皮革、毛皮、羽毛及其制品和制鞋业 | B16: 0.21 | C16: 0.11 | D16: 0.08 | E16: 0.12 | F16: 0.16 | G16: 0.08 | H16: 0.01 | I16: 0.01 | K16: =SUM(B16:J16)/SUM(L16:T16) -> 1 | L16: 0.21 | M16: 0.11 | N16: 0.08 | O16: 0.12 | P16: 0.16 | Q16: 0.08 | R16: 0.01 | S16: 0.01 | U16: =CORREL(L$44:T$44,L16:T16) -> 0.91616774
A17: 木材加工和木、竹、藤、棕、草制品业 | B17: 0.08 | C17: 0.12 | D17: 0.09 | E17: 0.52 | F17: 0.14 | G17: 0.02 | H17: 0.01 | K17: =SUM(B17:J17)/SUM(L17:T17) -> 1 | L17: 0.08 | M17: 0.12 | N17: 0.09 | O17: 0.52 | P17: 0.14 | Q17: 0.02 | R17: 0.01 | U17: =CORREL(L$44:T$44,L17:T17) -> 0.1353234
A18: 家具制造业 | B18: 0.05 | C18: 0.05 | D18: 0.01 | E18: 0.01 | F18: 0.01 | H18: 0.01 | J18: 0.02 | K18: =SUM(B18:J18)/SUM(L18:T18) -> 1 | L18: 0.05 | M18: 0.05 | N18: 0.01 | O18: 0.01 | P18: 0.01 | R18: 0.01 | T18: 0.02 | U18: =CORREL(L$44:T$44,L18:T18) -> 0.70298599
A19: 造纸和纸制品业 | B19: 0.09 | C19: 0.13 | D19: 0.02 | E19: 0.05 | F19: 0.39 | G19: 0.02 | I19: 0.01 | K19: =SUM(B19:J19)/SUM(L19:T19) -> 1 | L19: 0.09 | M19: 0.13 | N19: 0.02 | O19: 0.05 | P19: 0.39 | Q19: 0.02 | S19: 0.01 | U19: =CORREL(L$44:T$44,L19:T19) -> 0.50744038
A20: 印刷和记录媒介复制业 | B20: 0.08 | C20: 0.13 | D20: 0.03 | E20: 0.05 | F20: 0.04 | G20: 0.03 | H20: 0.01 | I20: 0.01 | J20: 0.01 | K20: =SUM(B20:J20)/SUM(L20:T20) -> 1 | L20: 0.08 | M20: 0.13 | N20: 0.03 | O20: 0.05 | P20: 0.04 | Q20: 0.03 | R20: 0.01 | S20: 0.01 | T20: 0.01 | U20: =CORREL(L$44:T$44,L20:T20) -> 0.79176789
A21: 文教、工美、体育和娱乐用品制造业 | B21: 0.23 | C21: 0.06 | D21: 0.04 | E21: 0.05 | F21: 0.04 | G21: 0.04 | H21: 0.1 | I21: 0.11 | K21: =SUM(B21:J21)/SUM(L21:T21) -> 1 | L21: 0.23 | M21: 0.06 | N21: 0.04 | O21: 0.05 | P21: 0.04 | Q21: 0.04 | R21: 0.1 | S21: 0.11 | U21: =CORREL(L$44:T$44,L21:T21) -> 0.19572395
A22: 石油、煤炭及其他燃料加工业 | B22: 0.21 | C22: 0.17 | D22: 0.21 | E22: 0.15 | F22: 0.19 | G22: 0.25 | H22: 0.07 | I22: 0.18 | J22: 0.03 | K22: =SUM(B22:J22)/SUM(L22:T22) -> 1.140625 | L22: 0.21 | M22: 0.17 | N22: 0.21 | O22: 0.15 | P22: 0.19 | Q22: 0.07 | R22: 0.07 | S22: 0.18 | T22: 0.03 | U22: =CORREL(L$44:T$44,L22:T22) -> 0.50132494
A23: 化学原料和化学制品制造业 | B23: 3.56 | C23: 3.22 | D23: 3.09 | E23: 3.44 | F23: 3.13 | G23: 2.17 | H23: 1.92 | I23: 1.9 | J23: 2 | K23: =SUM(B23:J23)/SUM(L23:T23) -> 1.0004095 | L23: 3.56 | M23: 3.22 | N23: 3.08 | O23: 3.44 | P23: 3.13 | Q23: 2.17 | R23: 1.92 | S23: 1.9 | T23: 2 | U23: =CORREL(L$44:T$44,L23:T23) -> 0.85369983
A24: 医药制造业 | B24: 0.27 | C24: 0.3 | D24: 0.16 | E24: 0.16 | F24: 0.04 | G24: 0.05 | H24: 0.02 | I24: 0.01 | J24: 0.01 | K24: =SUM(B24:J24)/SUM(L24:T24) -> 1 | L24: 0.27 | M24: 0.3 | N24: 0.16 | O24: 0.16 | P24: 0.04 | Q24: 0.05 | R24: 0.02 | S24: 0.01 | T24: 0.01 | U24: =CORREL(L$44:T$44,L24:T24) -> 0.77311625
A25: 化学纤维制造业 | D25: 0.02 | E25: 0.07 | F25: 0.05 | G25: 0.06 | H25: 0.02 | I25: 0.02 | J25: 0.02 | K25: =SUM(B25:J25)/SUM(L25:T25) -> 1 | N25: 0.02 | O25: 0.07 | P25: 0.05 | Q25: 0.06 | R25: 0.02 | S25: 0.02 | T25: 0.02 | U25: =CORREL(L$44:T$44,L25:T25) -> 0.4698838
A26: 橡胶和塑料制品业 | B26: 0.14 | C26: 0.1 | D26: 0.27 | E26: 0.27 | F26: 0.26 | G26: 0.24 | H26: 0.04 | I26: 0.06 | J26: 0.05 | K26: =SUM(B26:J26)/SUM(L26:T26) -> 1 | L26: 0.14 | M26: 0.1 | N26: 0.27 | O26: 0.27 | P26: 0.26 | Q26: 0.24 | R26: 0.04 | S26: 0.06 | T26: 0.05 | U26: =CORREL(L$44:T$44,L26:T26) -> 0.36071128
A27: 非金属矿物制品业 | B27: 4.69 | C27: 1.27 | D27: 1.09 | E27: 2.46 | F27: 1.58 | G27: 1 | H27: 0.82 | I27: 0.83 | J27: 0.53 | K27: =SUM(B27:J27)/SUM(L27:T27) -> 1 | L27: 4.69 | M27: 1.27 | N27: 1.09 | O27: 2.46 | P27: 1.58 | Q27: 1 | R27: 0.82 | S27: 0.83 | T27: 0.53 | U27: =CORREL(L$44:T$44,L27:T27) -> 0.6289058
A28: 黑色金属冶炼和压延加工业 | B28: 0.22 | C28: 0.22 | D28: 0.17 | E28: 0.24 | F28: 0.2 | G28: 0.09 | H28: 0.02 | I28: 0.02 | J28: 0.02 | K28: =SUM(B28:J28)/SUM(L28:T28) -> 1 | L28: 0.22 | M28: 0.22 | N28: 0.17 | O28: 0.24 | P28: 0.2 | Q28: 0.09 | R28: 0.02 | S28: 0.02 | T28: 0.02 | U28: =CORREL(L$44:T$44,L28:T28) -> 0.8359338
A29: 有色金属冶炼和压延加工业 | B29: 2.35 | C29: 1.35 | D29: 0.89 | E29: 0.73 | F29: 0.94 | G29: 1.08 | H29: 0.84 | I29: 0.54 | J29: 0.37 | K29: =SUM(B29:J29)/SUM(L29:T29) -> 1 | L29: 2.35 | M29: 1.35 | N29: 0.89 | O29: 0.73 | P29: 0.94 | Q29: 1.08 | R29: 0.84 | S29: 0.54 | T29: 0.37 | U29: =CORREL(L$44:T$44,L29:T29) -> 0.68176415
A30: 金属制品业 | B30: 1.33 | C30: 1.12 | D30: 0.98 | E30: 0.92 | F30: 0.76 | G30: 0.63 | H30: 0.56 | I30: 0.45 | J30: 0.3 | K30: =SUM(B30:J30)/SUM(L30:T30) -> 1 | L30: 1.33 | M30: 1.12 | N30: 0.98 | O30: 0.92 | P30: 0.76 | Q30: 0.63 | R30: 0.56 | S30: 0.45 | T30: 0.3 | U30: =CORREL(L$44:T$44,L30:T30) -> 0.78393293
A31: 通用设备制造业 | B31: 2.71 | C31: 2.52 | D31: 2.24 | E31: 2.5 | F31: 2.4 | G31: 2.11 | H31: 1.95 | I31: 1.62 | J31: 1.44 | K31: =SUM(B31:J31)/SUM(L31:T31) -> 1 | L31: 2.71 | M31: 2.52 | N31: 2.24 | O31: 2.5 | P31: 2.4 | Q31: 2.11 | R31: 1.95 | S31: 1.62 | T31: 1.44 | U31: =CORREL(L$44:T$44,L31:T31) -> 0.75647228
A32: 专用设备制造业 | B32: 0.35 | C32: 0.63 | D32: 0.59 | E32: 0.9 | F32: 0.92 | G32: 0.93 | H32: 0.78 | I32: 0.77 | J32: 0.88 | K32: =SUM(B32:J32)/SUM(L32:T32) -> 1 | L32: 0.35 | M32: 0.63 | N32: 0.59 | O32: 0.9 | P32: 0.92 | Q32: 0.93 | R32: 0.78 | S32: 0.77 | T32: 0.88 | U32: =CORREL(L$44:T$44,L32:T32) -> -0.47963156
A33: 汽车制造业 | B33: 0.96 | C33: 0.92 | D33: 0.65 | E33: 0.61 | F33: 0.5 | G33: 0.43 | H33: 0.4 | I33: 0.27 | J33: 0.24 | K33: =SUM(B33:J33)/SUM(L33:T33) -> 1 | L33: 0.96 | M33: 0.92 | N33: 0.65 | O33: 0.61 | P33: 0.5 | Q33: 0.43 | R33: 0.4 | S33: 0.27 | T33: 0.24 | U33: =CORREL(L$44:T$44,L33:T33) -> 0.81367615
A34: 铁路、船舶、航空航天和其他运输设备制造业 | B34: 8.34 | C34: 8.74 | D34: 1.98 | E34: 1.89 | F34: 2.61 | G34: 1.82 | H34: 13.06 | I34: 0.95 | J34: 1.3 | K34: =SUM(B34:J34)/SUM(L34:T34) -> 1 | L34: 8.34 | M34: 8.74 | N34: 1.98 | O34: 1.89 | P34: 2.61 | Q34: 1.82 | R34: 13.06 | S34: 0.95 | T34: 1.3 | U34: =CORREL(L$44:T$44,L34:T34) -> 0.092300585
A35: 电气机械和器材制造业 | B35: 0.46 | C35: 0.41 | D35: 0.3 | E35: 0.72 | F35: 0.7 | G35: 0.69 | H35: 0.44 | I35: 0.42 | J35: 0.12 | K35: =SUM(B35:J35)/SUM(L35:T35) -> 1 | L35: 0.46 | M35: 0.41 | N35: 0.3 | O35: 0.72 | P35: 0.7 | Q35: 0.69 | R35: 0.44 | S35: 0.42 | T35: 0.12 | U35: =CORREL(L$44:T$44,L35:T35) -> 0.10416236
