Workbook

Sheet About
A1: BIFUBC
B7: Definition of Energy Product not used as Fuel based on US EPS Model
B8: Coking Coal: Hard coal used in Iron and Steel Industry
B9: Petrochem: Natural Gas, Crude Oil, in refined petroleum and coke
B10: Chemical: Natural as Feedstock, LPG propane or butane as Feedstock
B12: Definition of "Energy Product used as Material"
B13: 4.2.1. #用作原料、材料
B14: “准确界定原料用能范畴”一节是《通知》的重要内容。该节具体指出，对原料用能的基本定义是:
B15: “指用作原材料的能源消费，即能源产品不作为燃料、动力使用，而作为生产非能源产品的原料、材料使用。”
B16: 具体范畴则表述为
B17: “用于生产非能源用途的烯烃、芳烃、炔烃、醇类、合成氨等产品的煤炭、石油、天然气及其制品等，属于原料用能范畴；若用作燃料、动力使用，不属于原料用能范畴”。

Sheet Sector Match
A1: 农、林、牧、渔业 | B1: agriculture and forestry 01T03
A2: 煤炭开采和洗选业 | B2: coal mining 05
A3: 石油和天然气开采业 | B3: oil and gas extraction 06
A4: 黑色金属矿采选业 | B4: other mining and quarrying 07T08
A5: 有色金属矿采选业 | B5: other mining and quarrying 07T08
A6: 非金属矿采选业 | B6: other mining and quarrying 07T08
A7: 开采专业及辅助性活动 | B7: Mining Support Service Activities 09
A8: 其他采矿业 | B8: Mining Support Service Activities 09
A9: 农副食品加工业 | B9: food beverage and tobacco 10T12
A10: 食品制造业 | B10: food beverage and tobacco 10T12
A11: 酒、饮料和精制茶制造业 | B11: food beverage and tobacco 10T12
A12: 烟草制品业 | B12: food beverage and tobacco 10T12
... A22: 化学原料和化学制品制造业 | B22: chemicals 20
A23: 医药制造业
A24: 化学纤维制造业 | B24: chemicals 20
A25: 橡胶和塑料制品业 | B25: rubber and plastic products 22
A26: 非金属矿物制品业 | B26: cement and other nonmetallic minerals 239
A27: 黑色金属冶炼和压延加工业 | B27: iron and steel 241
A28: 有色金属冶炼和压延加工业 | B28: other metals 242
A29: 金属制品业 | B29: metal products except machinery and vehicles 25
A30: 通用设备制造业 | B30: other manufacturing 31T33
A31: 专用设备制造业 | B31: glass and glass products 231
A32: 汽车制造业 | B32: road vehicles 29
A33: 铁路、船舶、航空航天和其他运输设备制造业 | B33: nonroad vehicles 30
A34: 电气机械和器材制造业 | B34: appliances and electrical equipment 27
A35: 计算机、通信和其他电子设备制造业 | B35: computers and electronics 26
... A39: 金属制品、机械和设备修理业 | B39: other machinery 28
A40: 电力、热力生产和供应业
A41: 燃气生产和供应业 | B41: energy pipelines and gas processing 352T353
A42: 水的生产和供应业 | B42: water and waste 36T39
A43: 建筑业 | B43: construction 41T43

Sheet Fuel Match
A1: Chinese Model Fuel | C1: EPS Fuel | D1: EPS Industrial Module Fuel
A2: Crude Oil | B2: 原油 | C2: crude oil | D2: crude oil
A3: Electricity | B3: 电力 | C3: electricity | D3: electricity
A4: Raw Coal | B4: 原煤 | C4: coal | D4: coal
A5: Cleaned Coal | B5: 洗精煤 | C5: coal | D5: coal
A6: Briquettes | B6: 煤制品 | C6: coal | D6: coal
A7: Heat | B7: 热力 | C7: heat | D7: heat
A8: Fuel Oil | B8: 燃料油 | C8: heavy fuel oil | D8: heavy fuel oil
A9: White Spirit | B9: 溶剂油 | C9: heavy fuel oil | D9: heavy fuel oil
A10: Other Petroleum Products | B10: 其他石油制品 | C10: heavy fuel oil | D10: heavy fuel oil
A11: Kerosene | B11: 煤油 | C11: jet fuel or kerosene | D11: petroleum diesel
A12: Gangue | B12: 煤矸石 | C12: lignite | D12: coal
A13: Other Washed Coal | B13: 其他洗煤 | C13: lignite | D13: coal
... A35: Other Energy | B35: 其他能源 | C35: other energy | D35: biomass

Sheet Heat Value
A1: Index | B1: 燃料品种 | C1: Energy Type Name | D1: SY2024 Appendix | E1: NBS Data | F1: GBT2589-2020 | G1: GBT2589-2008 | H1: Energy Balance 2023 | I1: Unit | J1: Kcal/Unit | K1: KJ/Unit | L1: 统计实物量单位 | M1: Statistical Unit | N1: TJ/统计单位 | O1: 万吨标煤/统计单位 | P1: BTU/统计单位 | Q1: Data Source | S1: 吨标煤/J | T1: J/Calorie | U1: BTU/J
A2: 1 | B2: 原煤 | C2: Raw Coal | D2: 20 908千焦/(5 000千卡)/千克 | E2: － | F2: 20934kJ/kg (5000kcal/kg) | G2: 20908kJ/kg (5000kcal/kg) | H2: #N/A | I2: kg | J2: 5450 | K2: =J2*$T$2 -> 22818.06 | L2: 万吨 | M2: 10^4 ton | N2: =K2*10^7/10^9 -> 228.1806 | O2: =N2*10^12*$S$2/10^4 -> 0.77857143 | P2: =N2*$U$2*10^12 -> 2.1627348e+11 | Q2: GBT2589-2020 | S2: 3.4120842e-11 | T2: 4.1868 | U2: 0.00094781712
A3: 2 | B3: 无烟煤 | C3: Anthracite | D3: #N/A | E3: 约6000千卡/千克以上 | F3: #N/A | G3: #N/A | H3: #N/A | I3: kg | J3: 6000 | K3: =J3*$T$2 -> 25120.8 | L3: 万吨 | M3: 10^4 ton | N3: =K3*10^7/10^9 -> 251.208 | O3: =N3*10^12*$S$2/10^4 -> 0.85714286 | P3: =N3*$U$2*10^12 -> 2.3809924e+11 | Q3: NBS Data
A4: 3 | B4: 炼焦烟煤 | C4: Coking Coal | D4: #N/A | E4: 约6000千卡/千克以上 | F4: #N/A | G4: #N/A | H4: #N/A | I4: kg | J4: 6000 | K4: =J4*$T$2 -> 25120.8 | L4: 万吨 | M4: 10^4 ton | N4: =K4*10^7/10^9 -> 251.208 | O4: =N4*10^12*$S$2/10^4 -> 0.85714286 | P4: =N4*$U$2*10^12 -> 2.3809924e+11 | Q4: NBS Data
A5: 4 | B5: 一般烟煤 | C5: Bituminous Coal | D5: #N/A | E5: 约4500-5500千卡/千克 | F5: #N/A | G5: #N/A | H5: #N/A | I5: kg | J5: 5000 | K5: =J5*$T$2 -> 20934 | L5: 万吨 | M5: 10^4 ton | N5: =K5*10^7/10^9 -> 209.34 | O5: =N5*10^12*$S$2/10^4 -> 0.71428571 | P5: =N5*$U$2*10^12 -> 1.9841604e+11 | Q5: NBS Data
A6: 5 | B6: 洗精煤 | C6: Cleaned Coal | D6: 26 344千焦/(6 300千卡)/千克 | E6: 约6000千卡/千克以上 | F6: 26377kJ/kg (6300kcal/kg) | G6: 26344kJ/kg (6300kcal/kg) | H6: #N/A | I6: kg | J6: 6300 | K6: =J6*$T$2 -> 26376.84 | L6: 万吨 | M6: 10^4 ton | N6: =K6*10^7/10^9 -> 263.7684 | O6: =N6*10^12*$S$2/10^4 -> 0.9 | P6: =N6*$U$2*10^12 -> 2.5000421e+11 | Q6: GBT2589-2020
A7: 6 | B7: 其他洗煤 | C7: Other Washed Coal | D7: 0 | E7: 约 2500-6000千卡/千克 | F7: #N/A | G7: #N/A | H7: #N/A | I7: kg | J7: 3780 | K7: =J7*$T$2 -> 15826.104 | L7: 万吨 | M7: 10^4 ton | N7: =K7*10^7/10^9 -> 158.26104 | O7: =N7*10^12*$S$2/10^4 -> 0.54 | P7: =N7*$U$2*10^12 -> 1.5000252e+11 | Q7: NBS Data
A8: 7 | B8: 洗中煤 | C8: Washed Middlings | D8: 8 363千焦/(2 000千卡)/千克 | E8: #N/A | F8: 8374kJ/kg (2000kcal/kg) | G8: 8363kJ/kg (2000kcal/kg) | H8: #N/A | I8: kg | J8: 2000 | K8: =J8*$T$2 -> 8373.6 | L8: 万吨 | M8: 10^4 ton | N8: =K8*10^7/10^9 -> 83.736 | O8: =N8*10^12*$S$2/10^4 -> 0.28571429 | P8: =N8*$U$2*10^12 -> 7.9366414e+10 | Q8: GBT2589-2020
A9: 8 | B9: 煤泥 | C9: Washed Slimes | D9: 8 363～12 545千焦/(2 000～3 000千卡)/千克 | E9: #N/A | F9: 8374kJ/kg～12560kJ/kg (2000kcal/kg～3000kcal/kg) | G9: 8363kJ/kg～12545kJ/kg (2000kcal/kg～3000kcal/kg) | H9: #N/A | I9: kg | J9: 2500 | K9: =J9*$T$2 -> 10467 | L9: 万吨 | M9: 10^4 ton | N9: =K9*10^7/10^9 -> 104.67 | O9: =N9*10^12*$S$2/10^4 -> 0.35714286 | P9: =N9*$U$2*10^12 -> 9.9208018e+10 | Q9: GBT2589-2020
A10: 9 | B10: 褐煤 | C10: Lignite | D10: #N/A | E10: 约2500-3500千卡/千克 | F10: #N/A | G10: #N/A | H10: #N/A | I10: kg | J10: 3000 | K10: =J10*$T$2 -> 12560.4 | L10: 万吨 | M10: 10^4 ton | N10: =K10*10^7/10^9 -> 125.604 | O10: =N10*10^12*$S$2/10^4 -> 0.42857143 | P10: =N10*$U$2*10^12 -> 1.1904962e+11 | Q10: NBS Data
A11: 10 | B11: 煤制品 | C11: Briquettes | D11: #N/A | E11: 约3000-5000千卡/千克 | F11: #N/A | G11: #N/A | H11: 4251.5059 | I11: kg | J11: 4251 | K11: =J11*$T$2 -> 17798.087 | L11: 万吨 | M11: 10^4 ton | N11: =K11*10^7/10^9 -> 177.98087 | O11: =N11*10^12*$S$2/10^4 -> 0.60728571 | P11: =N11*$U$2*10^12 -> 1.6869331e+11 | Q11: Calculated from Energy Balance 2023
A12: 11 | B12: 煤矸石 | C12: Gangue | D12: #N/A | E12: 约2000千卡/千克 | F12: 8374kJ/kg (2000kcal/kg) | G12: #N/A | H12: #N/A | I12: kg | J12: 2000 | K12: =J12*$T$2 -> 8373.6 | L12: 万吨 | M12: 10^4 ton | N12: =K12*10^7/10^9 -> 83.736 | O12: =N12*10^12*$S$2/10^4 -> 0.28571429 | P12: =N12*$U$2*10^12 -> 7.9366414e+10 | Q12: NBS Data
A13: 12 | B13: 焦炭 | C13: Coke | D13: 28 435千焦/(6 800千卡)/千克 | E13: 约6800千卡/千克 | F13: 28470kJ/kg (6800kcal/kg) | G13: 28435kJ/kg (6800kcal/kg) | H13: 6799.5591 | I13: kg | J13: 6800 | K13: =J13*$T$2 -> 28470.24 | L13: 万吨 | M13: 10^4 ton | N13: =K13*10^7/10^9 -> 284.7024 | O13: =N13*10^12*$S$2/10^4 -> 0.97142857 | P13: =N13*$U$2*10^12 -> 2.6984581e+11 | Q13: GBT2589-2020
A14: 13 | B14: 焦炉煤气 | C14: Coke Oven Gas | D14: 16 726～17 981千焦/(4 000～4 300千卡)/立方米 | E14: 约4000-4300千卡/立方米 | F14: 16747kJ/m³～18003kJ/m³ (4000kcal/m³～4300kcal/m³) | G14: 16726kJ/m³～17981kJ/m³ (4000kcal/m³～4300kcal/m³) | H14: 4002.5568 | I14: cu. m | J14: 4000 | K14: =J14*$T$2 -> 16747.2 | L14: 亿立方米 | M14: 10^8 cu. m | N14: =K14*10^8/10^9 -> 1674.72 | O14: =N14*10^12*$S$2/10^4 -> 5.7142857 | P14: =N14*$U$2*10^12 -> 1.5873283e+12 | Q14: GBT2589-2020
A15: 14 | B15: 高炉煤气 | C15: Blast Furnace Gas | D15: #N/A | E15: 约900千卡/立方米 | F15: 3768kJ/m³ (900kcal/m³) | G15: 3763kJ/m³ | H15: 899.9619 | I15: cu. m | J15: 900 | K15: =J15*$T$2 -> 3768.12 | L15: 亿立方米 | M15: 10^8 cu. m | N15: =K15*10^8/10^9 -> 376.812 | O15: =N15*10^12*$S$2/10^4 -> 1.2857143 | P15: =N15*$U$2*10^12 -> 3.5714886e+11 | Q15: NBS Data
A16: 15 | B16: 转炉煤气 | C16: Converter Gas | D16: #N/A | E16: 约1900千卡/立方米 | F16: #N/A | G16: #N/A | H16: 1899.8598 | I16: cu. m | J16: 1900 | K16: =J16*$T$2 -> 7954.92 | L16: 亿立方米 | M16: 10^8 cu. m | N16: =K16*10^8/10^9 -> 795.492 | O16: =N16*10^12*$S$2/10^4 -> 2.7142857 | P16: =N16*$U$2*10^12 -> 7.5398094e+11 | Q16: NBS Data
A17: 16 | B17: 其他煤气 | C17: Other Coal Gas | D17: 0 | E17: #N/A | F17: #N/A | G17: #N/A | H17: 1234.7749 | I17: cu. m | J17: 1250 | K17: =J17*$T$2 -> 5233.5 | L17: 亿立方米 | M17: 10^8 cu. m | N17: =K17*10^8/10^9 -> 523.35 | O17: =N17*10^12*$S$2/10^4 -> 1.7857143 | P17: =N17*$U$2*10^12 -> 4.9604009e+11 | Q17: Calculated from Energy Balance 2023
A18: 17 | B18: 发生炉煤气 | C18: Gas By Gas Furnace | D18: 5 227千焦/(1 250千卡)/立方米 | E18: 约1250千卡/立方米 | F18: 5234kJ/m³ (1250kcal/m³) | G18: 5227kJ/m³ (1250kcal/m³) | H18: #N/A | I18: cu. m | J18: 1250 | K18: =J18*$T$2 -> 5233.5 | L18: 亿立方米 | M18: 10^8 cu. m | N18: =K18*10^8/10^9 -> 523.35 | O18: =N18*10^12*$S$2/10^4 -> 1.7857143 | P18: =N18*$U$2*10^12 -> 4.9604009e+11 | Q18: GBT2589-2020
A19: 18 | B19: 重油催化裂解煤气 | C19: Gas By Heavy Oil Catalytic Cracking | D19: 19 235千焦/(4 600千卡)/立方米 | E19: 约4600千卡/立方米 | F19: 19259kJ/m³ (4600kcal/m³) | G19: 19235kJ/m³ (4600kcal/m³) | H19: #N/A | I19: cu. m | J19: 4600 | K19: =J19*$T$2 -> 19259.28 | L19: 亿立方米 | M19: 10^8 cu. m | N19: =K19*10^8/10^9 -> 1925.928 | O19: =N19*10^12*$S$2/10^4 -> 6.5714286 | P19: =N19*$U$2*10^12 -> 1.8254275e+12 | Q19: GBT2589-2020
A20: 19 | B20: 重油热裂解煤气 | C20: Gas By Heavy Oil Thermal Cracking | D20: 35 544千焦/(8 500千卡)/立方米 | E20: 约8500千卡/立方米 | F20: 35588kJ/m³ (8500kcal/m³) | G20: 35544kJ/m³ (8500kcal/m³) | H20: #N/A | I20: cu. m | J20: 8500 | K20: =J20*$T$2 -> 35587.8 | L20: 亿立方米 | M20: 10^8 cu. m | N20: =K20*10^8/10^9 -> 3558.78 | O20: =N20*10^12*$S$2/10^4 -> 12.142857 | P20: =N20*$U$2*10^12 -> 3.3730726e+12 | Q20: GBT2589-2020
A21: 20 | B21: 焦炭制气 | C21: Coke Gas | D21: 16 308千焦/(3 900千卡)/立方米 | E21: 约3900千卡/立方米 | F21: 16329kJ/m³ (3900kcal/m³) | G21: 16308kJ/m³ (3900kcal/m³) | H21: #N/A | I21: cu. m | J21: 3900 | K21: =J21*$T$2 -> 16328.52 | L21: 亿立方米 | M21: 10^8 cu. m | N21: =K21*10^8/10^9 -> 1632.852 | O21: =N21*10^12*$S$2/10^4 -> 5.5714286 | P21: =N21*$U$2*10^12 -> 1.5476451e+12 | Q21: GBT2589-2020
A22: 21 | B22: 压力气化煤气 | C22: Gas By Pressure Gasification | D22: 15 054千焦/(3 600千卡)/立方米 | E22: 约3600千卡/立方米 | F22: 15072kJ/m³ (3600kcal/m³) | G22: 15054kJ/m³ (3600kcal/m³) | H22: #N/A | I22: cu. m | J22: 3600 | K22: =J22*$T$2 -> 15072.48 | L22: 亿立方米 | M22: 10^8 cu. m | N22: =K22*10^8/10^9 -> 1507.248 | O22: =N22*10^12*$S$2/10^4 -> 5.1428571 | P22: =N22*$U$2*10^12 -> 1.4285955e+12 | Q22: GBT2589-2020
A23: 22 | B23: 水煤气 | C23: Water Coal Gas | D23: 10 454千焦/(2 500千卡)/立方米 | E23: 约2500千卡/立方米 | F23: 10467kJ/m³ (2500kcal/m³) | G23: 10454kJ/m³ (2500kcal/m³) | H23: #N/A | I23: cu. m | J23: 2500 | K23: =J23*$T$2 -> 10467 | L23: 亿立方米 | M23: 10^8 cu. m | N23: =K23*10^8/10^9 -> 1046.7 | O23: =N23*10^12*$S$2/10^4 -> 3.5714286 | P23: =N23*$U$2*10^12 -> 9.9208018e+11 | Q23: GBT2589-2020
A24: 23 | B24: 其他焦化产品 | C24: Other Coking Products | D24: #N/A | E24: #N/A | F24: #N/A | G24: #N/A | H24: 8077.951 | I24: kg | J24: 8078 | K24: =J24*$T$2 -> 33820.97 | L24: 万吨 | M24: 10^4 ton | N24: =K24*10^7/10^9 -> 338.2097 | O24: =N24*10^12*$S$2/10^4 -> 1.154 | P24: =N24*$U$2*10^12 -> 3.2056095e+11 | Q24: Calculated from Energy Balance 2023
A25: 24 | B25: 煤焦油 | C25: Coal Tar | D25: 33 453千焦/(8 000千卡)/千克 | E25: 约8000千卡/千克 | F25: 33494kJ/kg (8000kcal/kg) | G25: 33453kJ/kg (8000kcal/kg) | H25: #N/A | I25: kg | J25: 8000 | K25: =J25*$T$2 -> 33494.4 | L25: 万吨 | M25: 10^4 ton | N25: =K25*10^7/10^9 -> 334.944 | O25: =N25*10^12*$S$2/10^4 -> 1.1428571 | P25: =N25*$U$2*10^12 -> 3.1746566e+11 | Q25: GBT2589-2020
A26: 25 | B26: 粗苯 | C26: Benzene | D26: 41 816千焦/(10 000千卡)/千克 | E26: 约10000千卡/千克 | F26: 41868kJ/kg (10000kcal/kg) | G26: 41816kJ/kg (10000kcal/kg) | H26: #N/A | I26: kg | J26: 10000 | K26: =J26*$T$2 -> 41868 | L26: 万吨 | M26: 10^4 ton | N26: =K26*10^7/10^9 -> 418.68 | O26: =N26*10^12*$S$2/10^4 -> 1.4285714 | P26: =N26*$U$2*10^12 -> 3.9683207e+11 | Q26: GBT2589-2020
A27: 26 | B27: 原油 | C27: Crude Oil | D27: 41 816千焦/(10 000千卡)/千克 | E27: 约10000千卡/千克 | F27: 41868kJ/kg (10000kcal/kg) | G27: 41816kJ/kg (10000kcal/kg) | H27: 9988.7846 | I27: kg | J27: 10000 | K27: =J27*$T$2 -> 41868 | L27: 万吨 | M27: 10^4 ton | N27: =K27*10^7/10^9 -> 418.68 | O27: =N27*10^12*$S$2/10^4 -> 1.4285714 | P27: =N27*$U$2*10^12 -> 3.9683207e+11 | Q27: GBT2589-2020
A28: 27 | B28: 汽油 | C28: Gasoline | D28: 43 070千焦/(10 300千卡)/千克 | E28: 约10300千卡/千克 | F28: 43124kJ/kg (10300kcal/kg) | G28: 43070kJ/kg (10300kcal/kg) | H28: 10299.835 | I28: kg | J28: 10300 | K28: =J28*$T$2 -> 43124.04 | L28: 万吨 | M28: 10^4 ton | N28: =K28*10^7/10^9 -> 431.2404 | O28: =N28*10^12*$S$2/10^4 -> 1.4714286 | P28: =N28*$U$2*10^12 -> 4.0873703e+11 | Q28: GBT2589-2020
A29: 28 | B29: 煤油 | C29: Kerosene | D29: 43 070千焦/(10 300千卡)/千克 | E29: 约10300千卡/千克 | F29: 43124kJ/kg (10300kcal/kg) | G29: 43070kJ/kg (10300kcal/kg) | H29: 10303.545 | I29: kg | J29: 10300 | K29: =J29*$T$2 -> 43124.04 | L29: 万吨 | M29: 10^4 ton | N29: =K29*10^7/10^9 -> 431.2404 | O29: =N29*10^12*$S$2/10^4 -> 1.4714286 | P29: =N29*$U$2*10^12 -> 4.0873703e+11 | Q29: GBT2589-2020
A30: 29 | B30: 柴油 | C30: Diesel | D30: 42 652千焦/(10 200千卡)/千克 | E30: 约10200千卡/千克 | F30: 42705kJ/kg (10200kcal/kg) | G30: 42652kJ/kg (10200kcal/kg) | H30: 10198.757 | I30: kg | J30: 10200 | K30: =J30*$T$2 -> 42705.36 | L30: 万吨 | M30: 10^4 ton | N30: =K30*10^7/10^9 -> 427.0536 | O30: =N30*10^12*$S$2/10^4 -> 1.4571429 | P30: =N30*$U$2*10^12 -> 4.0476871e+11 | Q30: GBT2589-2020
A31: 30 | B31: 燃料油 | C31: Fuel Oil | D31: 41 816千焦/(10 000千卡)/千克 | E31: 约10000千卡/千克 | F31: 41868kJ/kg (10000kcal/kg) | G31: 41816kJ/kg (10000kcal/kg) | H31: 9995.4875 | I31: kg | J31: 10000 | K31: =J31*$T$2 -> 41868 | L31: 万吨 | M31: 10^4 ton | N31: =K31*10^7/10^9 -> 418.68 | O31: =N31*10^12*$S$2/10^4 -> 1.4285714 | P31: =N31*$U$2*10^12 -> 3.9683207e+11 | Q31: GBT2589-2020
A32: 31 | B32: 石脑油 | C32: Naphtha | D32: #N/A | E32: 约10500千卡/千克 | F32: #N/A | G32: #N/A | H32: 10499.809 | I32: kg | J32: 10500 | K32: =J32*$T$2 -> 43961.4 | L32: 万吨 | M32: 10^4 ton | N32: =K32*10^7/10^9 -> 439.614 | O32: =N32*10^12*$S$2/10^4 -> 1.5 | P32: =N32*$U$2*10^12 -> 4.1667368e+11 | Q32: Calculated from Energy Balance 2023
A33: 32 | B33: 润滑油 | C33: Lubricants | D33: #N/A | E33: 约9900千卡/千克 | F33: #N/A | G33: #N/A | H33: 9899.6153 | I33: kg | J33: 9900 | K33: =J33*$T$2 -> 41449.32 | L33: 万吨 | M33: 10^4 ton | N33: =K33*10^7/10^9 -> 414.4932 | O33: =N33*10^12*$S$2/10^4 -> 1.4142857 | P33: =N33*$U$2*10^12 -> 3.9286375e+11 | Q33: Calculated from Energy Balance 2023
A34: 33 | B34: 石蜡 | C34: Paraffin Waxes | D34: #N/A | E34: 约9550千卡/千克 | F34: #N/A | G34: #N/A | H34: 9553.7997 | I34: kg | J34: 9550 | K34: =J34*$T$2 -> 39983.94 | L34: 万吨 | M34: 10^4 ton | N34: =K34*10^7/10^9 -> 399.8394 | O34: =N34*10^12*$S$2/10^4 -> 1.3642857 | P34: =N34*$U$2*10^12 -> 3.7897463e+11 | Q34: Calculated from Energy Balance 2023
A35: 34 | B35: 溶剂油 | C35: White Spirit | D35: #N/A | E35: 约10270千卡/千克 | F35: #N/A | G35: #N/A | H35: 10265.955 | I35: kg | J35: 10270 | K35: =J35*$T$2 -> 42998.436 | L35: 万吨 | M35: 10^4 ton | N35: =K35*10^7/10^9 -> 429.98436 | O35: =N35*10^12*$S$2/10^4 -> 1.4671429 | P35: =N35*$U$2*10^12 -> 4.0754654e+11 | Q35: NBS Data
A36: 35 | B36: 石油沥青 | C36: Bitumen Asphalt | D36: #N/A | E36: 约9310千卡/千克 | F36: #N/A | G36: #N/A | H36: 9169.9409 | I36: kg | J36: 9170 | K36: =J36*$T$2 -> 38392.956 | L36: 万吨 | M36: 10^4 ton | N36: =K36*10^7/10^9 -> 383.92956 | O36: =N36*10^12*$S$2/10^4 -> 1.31 | P36: =N36*$U$2*10^12 -> 3.6389501e+11 | Q36: Calculated from Energy Balance 2023
A37: 36 | B37: 石油焦 | C37: Petroleum Coke | D37: #N/A | E37: 约7640千卡/千克 | F37: #N/A | G37: #N/A | H37: 7349.8353 | I37: kg | J37: 7350 | K37: =J37*$T$2 -> 30772.98 | L37: 万吨 | M37: 10^4 ton | N37: =K37*10^7/10^9 -> 307.7298 | O37: =N37*10^12*$S$2/10^4 -> 1.05 | P37: =N37*$U$2*10^12 -> 2.9167157e+11 | Q37: Calculated from Energy Balance 2023
A38: 37 | B38: 液化石油气 | C38: Liquefied Petroleum Gas | D38: 50 179千焦/(12 000千卡)/千克 | E38: 约12000千卡/千克 | F38: 50242kJ/kg (12000kcal/kg) | G38: 50179kJ/kg (12000kcal/kg) | H38: 12011.096 | I38: kg | J38: 12000 | K38: =J38*$T$2 -> 50241.6 | L38: 万吨 | M38: 10^4 ton | N38: =K38*10^7/10^9 -> 502.416 | O38: =N38*10^12*$S$2/10^4 -> 1.7142857 | P38: =N38*$U$2*10^12 -> 4.7619849e+11 | Q38: GBT2589-2020
A39: 38 | B39: 炼厂干气 | C39: Refinery Gas | D39: 45 998千焦/(11 000千卡)/千克 | E39: 约11000千卡/千克 | F39: 46055kJ/kg (11000kcal/kg) | G39: 46055kJ/kg (11000kcal/kg) | H39: 10999.623 | I39: kg | J39: 11000 | K39: =J39*$T$2 -> 46054.8 | L39: 万吨 | M39: 10^4 ton | N39: =K39*10^7/10^9 -> 460.548 | O39: =N39*10^12*$S$2/10^4 -> 1.5714286 | P39: =N39*$U$2*10^12 -> 4.3651528e+11 | Q39: GBT2589-2020
A40: 39 | B40: 其他石油制品 | C40: Other Petroleum Products | D40: #N/A | E40: 约9800千卡/千克 | F40: #N/A | G40: #N/A | H40: 9310.364 | I40: kg | J40: 9800 | K40: =J40*$T$2 -> 41030.64 | L40: 万吨 | M40: 10^4 ton | N40: =K40*10^7/10^9 -> 410.3064 | O40: =N40*10^12*$S$2/10^4 -> 1.4 | P40: =N40*$U$2*10^12 -> 3.8889543e+11 | Q40: NBS Data
...

Sheet Final Energy Consumption-2019
A1: 4-2 工业分行业终端能源消费量(标准量)-2019 | AG1: 电力数据来自《电力工业统计资料汇编2019》
A2: 行 业 | B2: (发电煤耗_x000D_ 计算法)_x000D_ (Coal_x000D_ Equivalent_x000D_ C alculation) | C2: (电热当量_x000D_ 计算法)_x000D_ (Calorific_x000D_ Value_x000D_ C alculation) | D2: 煤合计_x000D_ Coal Total | E2: 原煤_x000D_ Raw Coal | F2: 洗精煤_x000D_ Cleaned_x000D_ Coal | G2: 其他洗煤_x000D_ Other_x000D_ Washed_x000D_ Coal | H2: 煤制品_x000D_ Briquettes | I2: 焦炭_x000D_ Coke | J2: 焦炉煤气_x000D_ Coke Oven_x000D_ Gas | K2: 高炉煤气_x000D_ Blast Furnace_x000D_ Gas | L2: 转炉煤气_x000D_ Converter_x000D_ Gas | M2: 其他煤气_x000D_ Other Gas | N2: 其他焦化产品_x000D_ Other_x000D_ Coking_x000D_ Products | O2: 油品合计_x000D_ Petroleum_x000D_ Products_x000D_ Total | P2: 原油_x000D_ Crude Oil | Q2: 汽油_x000D_ Gasoline | R2: 煤油_x000D_ Kerosene | S2: 柴油_x000D_ Diesel Oil | T2: 燃料油_x000D_ Fuel Oil | U2: 石脑油_x000D_ Naphtha | V2: 润滑油_x000D_ Lubricants | W2: 石蜡_x000D_ Paraffin_x000D_ Waxes | X2: 溶剂油_x000D_ White Spirit | Y2: 石油沥青_x000D_ Bitumen_x000D_ Asphalt | Z2: 石油焦_x000D_ Petroleum_x000D_ Coke | AA2: 液化石油气_x000D_ Liquefied_x000D_ Petroleum Gas | AB2: 炼厂干气_x000D_ Refinery_x000D_ Gas | AC2: 其他石油制品_x000D_ Other_x000D_ Petroleum_x000D_ Products | AD2: 天然气_x000D_ Natural Gas | AE2: 液化天然气_x000D_ Liquefied_x000D_ Natural Gas | AF2: 热力_x000D_ Heat | AG2: 电力_x000D_ (亿千瓦小时)_x000D_ Electricity_x000D_ (108 kW·h) | AH2: 其他能源_x000D_ Other Energy
A3: 煤炭开采和洗选业 | B3: 5779.93 | C3: 3972.78 | D3: 1850.19 | E3: 1146.41 | G3: 700.44 | H3: =D3-SUM(E3:G3) -> 3.34 | I3: 47.52 | J3: 5.97 | K3: 32.19 | L3: 1.96 | M3: 2.54 | N3: 7.5 | O3: 529.29 | P3: 0.31 | Q3: 7.28 | R3: 1.1 | S3: 222.35 | T3: 0.38 | U3: 224.05 | V3: 1.43 | Y3: 0.13 | AA3: 71.58 | AC3: 0.69 | AD3: 183.12 | AE3: 23.68 | AF3: 24.06 | AG3: 1026.756 | AH3: 2.88
A4: 石油和天然气开采业 | B4: 3669.27 | C4: 2904.63 | D4: 81.19 | E4: 81.19 | H4: =D4-SUM(E4:G4) -> 0 | O4: 497.42 | P4: 383.15 | Q4: 10.28 | S4: 59.09 | T4: 1.24 | V4: 0.02 | AA4: 0.22 | AB4: 20.14 | AC4: 23.29 | AD4: 1689.28 | AE4: 8.08 | AF4: 94.74 | AG4: 434.4397
A5: 黑色金属矿采选业 | B5: 1655.37 | C5: 917.42 | D5: 145.01 | E5: 140.09 | G5: 2.99 | H5: =D5-SUM(E5:G5) -> 1.93 | I5: 143.52 | J5: 18.11 | K5: 23.43 | L5: 1.51 | N5: 0.2 | O5: 63.58 | Q5: 1.19 | S5: 61.99 | T5: 0.07 | V5: 0.32 | AC5: 0.01 | AD5: 0.2 | AF5: 5.53 | AG5: 419.2783 | AH5: 1.04
A6: 有色金属矿采选业 | B6: 1260.98 | C6: 581.29 | D6: 55.83 | E6: 54.52 | G6: 0.99 | H6: =D6-SUM(E6:G6) -> 0.32 | I6: 3.46 | O6: 36.5 | Q6: 2.42 | R6: 0.67 | S6: 31.79 | T6: 1.38 | V6: 0.05 | Y6: 0.19 | AD6: 8.48 | AG6: 386.1734 | AH6: 2.41
A7: 非金属矿采选业 | B7: 1305.96 | C7: 853 | D7: 339.01 | E7: 197.2 | G7: 138.76 | H7: =D7-SUM(E7:G7) -> 3.05 | I7: 7.52 | J7: 6.31 | L7: 3.77 | O7: 82.55 | Q7: 1.54 | R7: 0.03 | S7: 78.38 | T7: 0.05 | V7: 0.08 | Y7: 0.78 | Z7: 1.61 | AA7: 0.02 | AC7: 0.07 | AD7: 7.97 | AE7: 12.75 | AF7: 76.65 | AG7: 257.3577 | AH7: 0.19
A8: 开采专业及辅助性活动 | B8: 400.62 | C8: 327.94 | D8: 5.35 | E8: 5.35 | H8: =D8-SUM(E8:G8) -> 0 | O8: 231.28 | P8: 0.14 | Q8: 5.62 | S8: 224.18 | T8: 0.43 | V8: 0.39 | AA8: 0.13 | AC8: 0.39 | AD8: 30.4 | AE8: 0.67 | AF8: 9.48 | AG8: 0
A9: 其他采矿业 | B9: 632.79 | C9: 260.33 | D9: 0.09 | E9: 0.09 | H9: =D9-SUM(E9:G9) -> 0 | O9: 0.15 | S9: 0.15 | AG9: 211.6198
A10: 农副食品加工业 | B10: 4151.98 | C10: 2748.45 | D10: 679.19 | E10: 666.49 | G10: 11.52 | H10: =D10-SUM(E10:G10) -> 1.18 | I10: 120.88 | J10: 0.16 | K10: 33.85 | L10: 5.69 | M10: 0.29 | N10: 0.01 | O10: 48.38 | Q10: 10.43 | R10: 0.14 | S10: 31.34 | T10: 2.16 | V10: 0.13 | W10: 0.04 | X10: 2.21 | AA10: 1.63 | AC10: 0.32 | AD10: 49.19 | AE10: 349.6 | AF10: 259.68 | AG10: 656.7766 | AH10: 221.48
A11: 食品制造业 | B11: 1999.83 | C11: 1468.4 | D11: 475.38 | E11: 471.7 | G11: 0.61 | H11: =D11-SUM(E11:G11) -> 3.07 | I11: 1.53 | O11: 22.85 | Q11: 6.19 | R11: 0.01 | S11: 12.04 | T11: 1.6 | V11: 0.01 | W11: 0.56 | AA11: 2 | AC11: 0.44 | AD11: 164.27 | AE11: 145.3 | AF11: 248.85 | AG11: 371.5912 | AH11: 39.14
A12: 酒、饮料和精制茶制造业 | B12: 1277.65 | C12: 972.17 | D12: 334.13 | E12: 330.43 | G12: 3.1 | H12: =D12-SUM(E12:G12) -> 0.6 | I12: 0.08 | J12: 0.17 | N12: 0.01 | O12: 13.04 | Q12: 4.26 | R12: 0.09 | S12: 6.95 | T12: 0.51 | V12: 0.02 | AA12: 1.17 | AC12: 0.05 | AD12: 126.61 | AE12: 85.34 | AF12: 186.24 | AG12: 147.1486 | AH12: 13.23
A13: 烟草制品业 | B13: 192.09 | C13: 98.97 | D13: 4.99 | E13: 4.73 | G13: 0.24 | H13: =D13-SUM(E13:G13) -> 0.02 | O13: 2.16 | Q13: 0.55 | S13: 1.52 | AA13: 0.09 | AD13: 15.48 | AF13: 8.79 | AG13: 38.6689 | AH13: 2.52
A14: 纺织业 | B14: 7347.67 | C14: 4249.69 | D14: 315.51 | E14: 289.75 | G14: 3.46 | H14: =D14-SUM(E14:G14) -> 22.3 | I14: 1.16 | L14: 0.03 | O14: 27.9 | Q14: 8.22 | R14: 0.04 | S14: 8.61 | T14: 4.93 | V14: 0.15 | Y14: 2.04 | AA14: 2.64 | AC14: 1.27 | AD14: 189.22 | AE14: 383.08 | AF14: 1104.07 | AG14: 1648.9851 | AH14: 65.49
A15: 纺织服装、服饰业 | B15: 904.33 | C15: 496.72 | D15: 28.75 | E15: 28.35 | G15: 0.23 | H15: =D15-SUM(E15:G15) -> 0.17 | I15: 0.05 | O15: 16.73 | Q15: 7.19 | R15: 0.07 | S15: 7.82 | T15: 0.7 | V15: 0.02 | AA15: 0.63 | AC15: 0.29 | AD15: 16.68 | AE15: 121.39 | AF15: 20.24 | AG15: 343.0478 | AH15: 8.27
A16: 皮革、毛皮、羽毛及其制品和制鞋业 | B16: 538.88 | C16: 262.88 | D16: 16.62 | E16: 15.65 | G16: 0.05 | H16: =D16-SUM(E16:G16) -> 0.92 | O16: 8.41 | Q16: 4.21 | R16: 0.02 | S16: 2.82 | T16: 0.49 | U16: 0.01 | V16: 0.07 | W16: 0.06 | X16: 0.18 | AA16: 0.5 | AC16: 0.05 | AD16: 1.57 | AE16: 26.1 | AF16: 7.77 | AG16: 222.5382 | AH16: 9.7
A17: 木材加工和木、竹、藤、棕、草制品业 | B17: 1050.22 | C17: 558.6 | D17: 37.52 | E17: 37.05 | G17: 0.47 | H17: =D17-SUM(E17:G17) -> 0 | I17: 0.04 | O17: 13.13 | Q17: 2.5 | S17: 7.59 | T17: 0.29 | V17: 0.05 | W17: 2.34 | AA17: 0.36 | AD17: 33.56 | AE17: 3.24 | AF17: 22.91 | AG17: 350.2031 | AH17: 104.92
A18: 家具制造业 | B18: 383.91 | C18: 180.87 | D18: 1.56 | E18: 1.4 | G18: 0.14 | H18: =D18-SUM(E18:G18) -> 0.02 | I18: 0.52 | O18: 8.58 | Q18: 3.54 | S18: 4.35 | T18: 0.21 | V18: 0.02 | AA18: 0.47 | AD18: 17.23 | AE18: 4.13 | AF18: 2.07 | AG18: 162.3502 | AH18: 5.01
A19: 造纸和纸制品业 | B19: 3839.71 | C19: 2529.15 | D19: 471.3 | E19: 437.16 | G19: 21.23 | H19: =D19-SUM(E19:G19) -> 12.91 | I19: 0.22 | J19: 0.52 | O19: 41.04 | P19: 0.05 | Q19: 3.69 | R19: 0.01 | S19: 21.85 | T19: 11.44 | V19: 0.14 | W19: 0.04 | X19: 0.44 | AA19: 3.26 | AC19: 0.13 | AD19: 61.96 | AE19: 218.07 | AF19: 730.29 | AG19: 744.609 | AH19: 90.62
A20: 印刷和记录媒介复制业 | B20: 506.51 | C20: 275.86 | D20: 11.62 | E20: 11.2 | G20: 0.18 | H20: =D20-SUM(E20:G20) -> 0.24 | I20: 0.02 | J20: 0.41 | M20: 0.17 | O20: 13.3 | Q20: 5.29 | R20: 0.02 | S20: 6.14 | T20: 0.57 | V20: 0.04 | X20: 0.07 | AA20: 0.7 | AC20: 0.47 | AD20: 43.34 | AE20: 20.2 | AF20: 16.66 | AG20: 131.0519 | AH20: 9.07
A21: 文教、工美、体育和娱乐用品制造业 | B21: 493.36 | C21: 335.35 | D21: 10.88 | E21: 10.43 | G21: 0.2 | H21: =D21-SUM(E21:G21) -> 0.25 | I21: 0.42 | O21: 25.07 | Q21: 4.87 | R21: 0.15 | S21: 5.09 | T21: 0.66 | U21: 0.01 | V21: 0.03 | W21: 0.73 | X21: 0.01 | Z21: 12.14 | AA21: 1.14 | AC21: 0.24 | AD21: 37.86 | AE21: 141.94 | AF21: 2.96 | AG21: 162.6521 | AH21: 5.89
A22: 石油、煤炭及其他燃料加工业 | B22: 24273.48 | C22: 22163.29 | D22: 1765.81 | E22: 1066.35 | G22: 621.73 | H22: =D22-SUM(E22:G22) -> 77.73 | I22: 51.4 | J22: 1190.25 | K22: 125.9 | M22: 20.11 | N22: 165.28 | O22: 13388.35 | P22: 79.93 | Q22: 2.09 | R22: 0.26 | S22: 32.84 | T22: 39.11 | U22: 2085.02 | V22: 310.99 | W22: 0.08 | X22: 8.85 | Y22: 6.37 | Z22: 242.08 | AA22: 1812.69 | AB22: 2732.75 | AC22: 6035.31 | AD22: 341.61 | AE22: 1471.59 | AF22: 2163.33 | AG22: 1279.3437 | AH22: 6.16
A23: 化学原料和化学制品制造业 | B23: 51424.21 | C23: 41871.71 | D23: 9166.6 | E23: 8868.09 | G23: 94.53 | H23: =D23-SUM(E23:G23) -> 203.98 | I23: 3842.3 | J23: 454.49 | K23: 11.58 | L23: 27.3 | M23: 40.29 | N23: 721.04 | O23: 10825.95 | P23: 1.92 | Q23: 17.79 | R23: 2.79 | S23: 55.33 | T23: 62.89 | U23: 6311.43 | V23: 7.48 | W23: 344.95 | X23: 120.96 | Y23: 1.99 | Z23: 54.1 | AA23: 1815.43 | AB23: 118.6 | AC23: 1910.28 | AD23: 2641.46 | AE23: 2428.94 | AF23: 4950.57 | AG23: 4505.6718 | AH23: 90.95
A24: 医药制造业 | B24: 2164.39 | C24: 1446.79 | D24: 357.85 | E24: 353.22 | G24: 1.04 | H24: =D24-SUM(E24:G24) -> 3.59 | I24: 1.9 | J24: 2.1 | N24: 0.09 | O24: 19.9 | P24: 0.04 | Q24: 5.77 | R24: 0.02 | S24: 8.35 | T24: 3.89 | U24: 0.05 | V24: 0.01 | W24: 0.04 | X24: 0.34 | AA24: 0.36 | AC24: 1.03 | AD24: 95.2 | AE24: 94.47 | AF24: 348.99 | AG24: 407.7124 | AH24: 25.21
A25: 化学纤维制造业 | B25: 2399.65 | C25: 1598.55 | D25: 432.74 | E25: 368.37 | G25: 2.56 | H25: =D25-SUM(E25:G25) -> 61.81 | I25: 18.04 | O25: 4.18 | Q25: 0.9 | R25: 0.03 | S25: 2.39 | T25: 0.55 | V25: 0.07 | X25: 0.06 | AA25: 0.1 | AC25: 0.09 | AD25: 21.79 | AE25: 158.56 | AF25: 391.25 | AG25: 411.1229 | AH25: 12.62
A26: 橡胶和塑料制品业 | B26: 4849.68 | C26: 2339.16 | D26: 193.12 | E26: 182.69 | G26: 1.37 | H26: =D26-SUM(E26:G26) -> 9.06 | I26: 0.03 | J26: 3.55 | N26: 6.15 | O26: 47.53 | P26: 0.01 | Q26: 13.91 | R26: 0.09 | S26: 17.34 | T26: 4.82 | V26: 0.64 | W26: 0.59 | X26: 0.6 | Y26: 2.01 | AA26: 3.87 | AC26: 3.64 | AD26: 101.44 | AE26: 110.99 | AF26: 107.04 | AG26: 1426.3838 | AH26: 16.28
A27: 非金属矿物制品业 | B27: 34298.86 | C27: 27679.91 | D27: 15359.62 | E27: 10756.46 | G27: 4543.4 | H27: =D27-SUM(E27:G27) -> 59.76 | I27: 1302.1 | J27: 205.38 | K27: 54.66 | L27: 15.24 | M27: 15.28 | N27: 25.68 | O27: 3627.77 | P27: 0.14 | Q27: 21.71 | R27: 1.23 | S27: 457.63 | T27: 137.56 | V27: 0.84 | W27: 0.99 | X27: 0.23 | Y27: 316.04 | Z27: 2568.84 | AA27: 105.27 | AB27: 0.18 | AC27: 17.12 | AD27: 471.89 | AE27: 1804.53 | AF27: 85.88 | AG27: 3760.643 | AH27: 90.04
A28: 黑色金属冶炼和压延加工业 | B28: 82285.93 | C28: 70916.51 | D28: 8024.63 | E28: 7608.25 | G28: 361.77 | H28: =D28-SUM(E28:G28) -> 54.61 | I28: 38124.93 | J28: 1961.68 | K28: 10366.15 | L28: 1510.63 | M28: 2.7 | N28: 351.48 | O28: 122.52 | Q28: 4.93 | R28: 0.04 | S28: 76.54 | T28: 0.92 | V28: 1.09 | W28: 0.02 | Z28: 18.92 | AA28: 16.45 | AB28: 2.48 | AC28: 1.13 | AD28: 594.73 | AE28: 1152.6 | AF28: 664.02 | AG28: 5682.4769 | AH28: 101.48
A29: 有色金属冶炼和压延加工业 | B29: 24252.12 | C29: 12506.07 | D29: 1771.45 | E29: 1628.48 | G29: 138.59 | H29: =D29-SUM(E29:G29) -> 4.38 | I29: 394.53 | J29: 110.51 | L29: 0.22 | M29: 159.89 | N29: 23.8 | O29: 375.86 | P29: 0.43 | Q29: 4.99 | R29: 0.79 | S29: 48.64 | T29: 19.75 | V29: 0.6 | W29: 0.01 | X29: 0.15 | Y29: 13.11 | Z29: 275.19 | AA29: 5.55 | AC29: 6.66 | AD29: 264.81 | AE29: 451.72 | AF29: 745.36 | AG29: 6214.9202 | AH29: 5.96
A30: 金属制品业 | B30: 6644.59 | C30: 3700.29 | D30: 199.1 | E30: 171.15 | G30: 27.25 | H30: =D30-SUM(E30:G30) -> 0.7 | I30: 455.67 | J30: 25.99 | K30: 62.75 | L30: 6.04 | M30: 0.94 | N30: 3.01 | O30: 58.92 | P30: 0.01 | Q30: 17.06 | R30: 0.67 | S30: 28.44 | T30: 2.29 | V30: 0.84 | W30: 0.02 | X30: 0.03 | Y30: 0.42 | AA30: 7.42 | AB30: 0.02 | AC30: 1.71 | AD30: 149.04 | AE30: 656.31 | AF30: 21.73 | AG30: 2344.5871 | AH30: 4.88
A31: 通用设备制造业 | B31: 3626.98 | C31: 1853.84 | D31: 14.51 | E31: 13.48 | G31: 0.43 | H31: =D31-SUM(E31:G31) -> 0.6 | I31: 237.57 | J31: 0.85 | K31: 0.1 | L31: 0.13 | O31: 68.29 | Q31: 22.5 | R31: 2.38 | S31: 30.96 | T31: 0.99 | U31: 0.05 | V31: 4.12 | W31: 0.11 | X31: 0.06 | AA31: 4.8 | AB31: 0.01 | AC31: 2.3 | AD31: 132.15 | AE31: 145.28 | AF31: 11.72 | AG31: 917.2368 | AH31: 5.11
A32: 专用设备制造业 | B32: 1887.75 | C32: 1008.75 | D32: 14.67 | E32: 13.05 | G32: 0.81 | H32: =D32-SUM(E32:G32) -> 0.81 | I32: 6.36 | J32: 7.68 | K32: 3.01 | L32: 0.01 | M32: 6.27 | N32: 0.65 | O32: 55.83 | Q32: 17.42 | R32: 1.13 | S32: 21.07 | T32: 0.92 | V32: 4.08 | W32: 0.05 | X32: 0.11 | AA32: 6.2 | AC32: 4.83 | AD32: 61.94 | AE32: 200.55 | AF32: 32.58 | AG32: 388.6379 | AH32: 5.42
A33: 汽车制造业 | B33: 3654.46 | C33: 1839.12 | D33: 16.24 | E33: 15.85 | G33: 0.06 | H33: =D33-SUM(E33:G33) -> 0.33 | I33: 13.82 | J33: 0.33 | K33: 0.04 | L33: 0.03 | M33: 0.32 | O33: 95.95 | P33: 0.01 | Q33: 36.38 | R33: 0.4 | S33: 39.27 | T33: 0.45 | U33: 0.02 | V33: 13.08 | W33: 0.01 | X33: 0.19 | Y33: 0.01 | AA33: 3.56 | AC33: 2.58 | AD33: 93 | AE33: 247.08 | AF33: 101.71 | AG33: 495.7558 | AH33: 3.01
A34: 铁路、船舶、航空航天和其他运输设备制造业 | B34: 853.16 | C34: 560.67 | D34: 21.32 | E34: 10.09 | G34: 11.23 | H34: =D34-SUM(E34:G34) -> 0 | I34: 0.27 | J34: 2.65 | M34: 0.01 | O34: 28.11 | P34: 0.01 | Q34: 5.15 | R34: 1.4 | S34: 16.4 | T34: 1.98 | V34: 0.33 | AA34: 2.29 | AC34: 0.55 | AD34: 63.5 | AE34: 217.54 | AF34: 22.73 | AG34: 339.7783 | AH34: 0.3
A35: 电气机械和器材制造业 | B35: 2841.16 | C35: 1328.72 | D35: 13.17 | E35: 13.1 | G35: 0.04 | H35: =D35-SUM(E35:G35) -> 0.03 | I35: 0.55 | J35: 0.13 | O35: 52.26 | Q35: 21.99 | R35: 0.62 | S35: 15.61 | T35: 2.96 | V35: 2.56 | W35: 0.2 | X35: 0.07 | Y35: 0.05 | Z35: 0.4 | AA35: 5.82 | AC35: 1.97 | AD35: 43.69 | AE35: 108.41 | AF35: 48.23 | AG35: 837.6747 | AH35: 6.19
A36: 计算机、通信和其他电子设备制造业 | B36: 5019.84 | C36: 2378.96 | D36: 12.89 | E36: 12.29 | G36: 0.6 | H36: =D36-SUM(E36:G36) -> 0 | J36: 0.05 | K36: 0.01 | O36: 28.83 | P36: 0.01 | Q36: 14.11 | R36: 0.23 | S36: 9.37 | T36: 0.58 | V36: 0.94 | W36: 0.03 | X36: 0.03 | AA36: 3.35 | AC36: 0.19 | AD36: 148.12 | AE36: 289.59 | AF36: 53.16 | AG36: 1572.7347 | AH36: 2.26
A37: 仪器仪表制造业 | B37: 249.47 | C37: 118.29 | D37: 1.55 | E37: 1.55 | H37: =D37-SUM(E37:G37) -> 0 | I37: 0.01 | O37: 8.11 | Q37: 5.65 | R37: 0.17 | S37: 1.47 | T37: 0.14 | V37: 0.14 | W37: 0.04 | AA37: 0.29 | AC37: 0.21 | AD37: 6.65 | AE37: 6.94 | AF37: 1.96 | AG37: 75.4896 | AH37: 1.47
A38: 其他制造业 | B38: 1799.44 | C38: 781.41 | D38: 1.42 | E38: 1.11 | G38: 0.09 | H38: =D38-SUM(E38:G38) -> 0.22 | J38: 0.06 | N38: 0.86 | O38: 7.99 | Q38: 1 | R38: 0.12 | S38: 1.65 | AA38: 5.22 | AD38: 0.53 | AE38: 56.29 | AF38: 2.35 | AG38: 532.1327 | AH38: 1.04
A39: 废弃资源综合利用业 | B39: 642.51 | C39: 540.54 | D39: 96.39 | E39: 81.64 | G39: 10.51 | H39: =D39-SUM(E39:G39) -> 4.24 | I39: 94.29 | J39: 2.91 | K39: 6.82 | L39: 5.71 | N39: 1.35 | O39: 9.97 | Q39: 0.45 | R39: 0.03 | S39: 7.03 | T39: 1.88 | V39: 0.03 | AA39: 0.54 | AD39: 27.97 | AE39: 217.39 | AF39: 0.67 | AG39: 109.3667 | AH39: 5.87
A40: 金属制品、机械和设备修理业 | B40: 67.91 | C40: 38.76 | D40: 0.41 | E40: 0.41 | H40: =D40-SUM(E40:G40) -> 0 | J40: 0.41 | K40: 0.18 | O40: 9 | P40: 0.02 | Q40: 0.64 | R40: 1.37 | S40: 6.41 | T40: 0.45 | V40: 0.07 | X40: 0.01 | AA40: 0.04 | AD40: 2.65 | AE40: 5.25 | AF40: 0.51 | AG40: 101.368
...

Sheet Feedstock Split-2019
B1: 煤合计_x000D_ Coal Total | C1: 原煤_x000D_ Raw Coal | D1: 洗精煤_x000D_ Cleaned_x000D_ Coal | E1: 其他洗煤_x000D_ Other_x000D_ Washed_x000D_ Coal | F1: 煤制品_x000D_ Briquettes | G1: 煤矸石_x000D_ Gangue | H1: 焦炭_x000D_ Coke | I1: 焦炉煤气_x000D_ Coke Oven_x000D_ Gas | J1: 高炉煤气_x000D_ Blast Furnace_x000D_ Gas | K1: 转炉煤气_x000D_ Converter_x000D_ Gas | L1: 其他煤气_x000D_ Other Gas | M1: 其他焦化产品_x000D_ Other_x000D_ Coking_x000D_ Products | N1: 油品合计_x000D_ Petroleum_x000D_ Products_x000D_ Total | O1: 原油_x000D_ Crude Oil | P1: 汽油_x000D_ Gasoline | Q1: 煤油_x000D_ Kerosene | R1: 柴油_x000D_ Diesel Oil | S1: 燃料油_x000D_ Fuel Oil | T1: 石脑油_x000D_ Naphtha | U1: 润滑油_x000D_ Lubricants | V1: 石蜡_x000D_ Paraffin_x000D_ Waxes | W1: 溶剂油_x000D_ White spirit | X1: 石油沥青_x000D_ Bitumen_x000D_ Asphalt | Y1: 石油焦_x000D_ Petroleum_x000D_ Coke | Z1: 液化石油气_x000D_ Liquefied_x000D_ Petroleum Gas | AA1: 炼厂干气_x000D_ Refinery_x000D_ Gas | AB1: 其他石油制品_x000D_ Other_x000D_ Petroleum_x000D_ Products | AC1: 天然气_x000D_ Natural Gas | AD1: 液化天然气_x000D_ Liquefied_x000D_ Natural Gas | AE1: 热力_x000D_ Heat | AF1: 电力_x000D_ Electricity | AG1: 其他能源_x000D_ Other_x000D_ Energy
A2: 工业 | B2: =SUM(B3:B43) -> 0 | C2: =SUM(C3:C43) -> 1 | D2: =SUM(D3:D43) -> 1 | E2: =SUM(E3:E43) -> 1 | F2: =SUM(F3:F43) -> 1 | G2: =SUM(G3:G43) -> 1 | H2: =SUM(H3:H43) -> 1 | I2: =SUM(I3:I43) -> 1 | ... AG2: =SUM(AG3:AG43) -> 1
A3: 煤炭开采和洗选业 | C3: 0 | D3: 0 | E3: 0 | F3: 0 | G3: 0 | H3: 0 | I3: 0 | J3: 0 | K3: 0 | L3: 0 | M3: 0 | O3: 0 | P3: 0 | Q3: 0 | R3: 0 | S3: 0 | T3: 0 | U3: 0 | V3: 0 | W3: 0 | X3: 0 | Y3: 0 | Z3: 0 | AA3: 0 | AB3: 0 | AC3: 0 | AD3: 0 | AE3: 0 | AF3: 0 | AG3: 0
A4: 石油和天然气开采业 | C4: 0 | D4: 0 | E4: 0 | F4: 0 | G4: 0 | H4: 0 | I4: 0 | J4: 0 | K4: 0 | L4: 0 | M4: 0 | O4: 0 | P4: 0 | Q4: 0 | R4: 0 | S4: 0 | T4: 0 | U4: 0 | V4: 0 | W4: 0 | X4: 0 | Y4: 0 | Z4: 0 | AA4: 0 | AB4: 0 | AC4: 0 | AD4: 0 | AE4: 0 | AF4: 0 | AG4: 0
A5: 黑色金属矿采选业 | C5: 0 | D5: 0 | E5: 0 | F5: 0 | G5: 0 | H5: 0 | I5: 0 | J5: 0 | K5: 0 | L5: 0 | M5: 0 | O5: 0 | P5: 0 | Q5: 0 | R5: 0 | S5: 0 | T5: 0 | U5: 0 | V5: 0 | W5: 0 | X5: 0 | Y5: 0 | Z5: 0 | AA5: 0 | AB5: 0 | AC5: 0 | AD5: 0 | AE5: 0 | AF5: 0 | AG5: 0
A6: 有色金属矿采选业 | C6: 0 | D6: 0 | E6: 0 | F6: 0 | G6: 0 | H6: 0 | I6: 0 | J6: 0 | K6: 0 | L6: 0 | M6: 0 | O6: 0 | P6: 0 | Q6: 0 | R6: 0 | S6: 0 | T6: 0 | U6: 0 | V6: 0 | W6: 0 | X6: 0 | Y6: 0 | Z6: 0 | AA6: 0 | AB6: 0 | AC6: 0 | AD6: 0 | AE6: 0 | AF6: 0 | AG6: 0
A7: 非金属矿采选业 | C7: 0 | D7: 0 | E7: 0 | F7: 0 | G7: 0 | H7: 0 | I7: 0 | J7: 0 | K7: 0 | L7: 0 | M7: 0 | O7: 0 | P7: 0 | Q7: 0 | R7: 0 | S7: 0 | T7: 0 | U7: 0 | V7: 0 | W7: 0 | X7: 0 | Y7: 0 | Z7: 0 | AA7: 0 | AB7: 0 | AC7: 0 | AD7: 0 | AE7: 0 | AF7: 0 | AG7: 0
A8: 开采专业及辅助性活动 | C8: 0 | D8: 0 | E8: 0 | F8: 0 | G8: 0 | H8: 0 | I8: 0 | J8: 0 | K8: 0 | L8: 0 | M8: 0 | O8: 0 | P8: 0 | Q8: 0 | R8: 0 | S8: 0 | T8: 0 | U8: 0 | V8: 0 | W8: 0 | X8: 0 | Y8: 0 | Z8: 0 | AA8: 0 | AB8: 0 | AC8: 0 | AD8: 0 | AE8: 0 | AF8: 0 | AG8: 0
A9: 其他采矿业 | C9: 0 | D9: 0 | E9: 0 | F9: 0 | G9: 0 | H9: 0 | I9: 0 | J9: 0 | K9: 0 | L9: 0 | M9: 0 | O9: 0 | P9: 0 | Q9: 0 | R9: 0 | S9: 0 | T9: 0 | U9: 0 | V9: 0 | W9: 0 | X9: 0 | Y9: 0 | Z9: 0 | AA9: 0 | AB9: 0 | AC9: 0 | AD9: 0 | AE9: 0 | AF9: 0 | AG9: 0
A10: 农副食品加工业 | C10: 0 | D10: 0 | E10: 0 | F10: 0 | G10: 0 | H10: 0 | I10: 0 | J10: 0 | K10: 0 | L10: 0 | M10: 0 | O10: 0 | P10: 0 | Q10: 0 | R10: 0 | S10: 0 | T10: 0 | U10: 0 | V10: 0 | W10: 0 | X10: 0 | Y10: 0 | Z10: 0 | AA10: 0 | AB10: 0 | AC10: 0 | AD10: 0 | AE10: 0 | AF10: 0 | AG10: =AE65 -> 0.54200622
A11: 食品制造业 | C11: 0 | D11: 0 | E11: 0 | F11: 0 | G11: 0 | H11: 0 | I11: 0 | J11: 0 | K11: 0 | L11: 0 | M11: 0 | O11: 0 | P11: 0 | Q11: 0 | R11: 0 | S11: 0 | T11: 0 | U11: 0 | V11: =V55 -> 0.0016063335 | W11: 0 | X11: 0 | Y11: 0 | Z11: 0 | AA11: 0 | AB11: 0 | AC11: 0 | AD11: 0 | AE11: 0 | AF11: 0 | AG11: 0
A12: 酒、饮料和精制茶制造业 | C12: 0 | D12: 0 | E12: 0 | F12: 0 | G12: 0 | H12: 0 | I12: 0 | J12: 0 | K12: 0 | L12: 0 | M12: 0 | O12: 0 | P12: 0 | Q12: 0 | R12: 0 | S12: 0 | T12: 0 | U12: 0 | V12: 0 | W12: 0 | X12: 0 | Y12: 0 | Z12: 0 | AA12: 0 | AB12: 0 | AC12: 0 | AD12: 0 | AE12: 0 | AF12: 0 | AG12: 0
A13: 烟草制品业 | C13: 0 | D13: 0 | E13: 0 | F13: 0 | G13: 0 | H13: 0 | I13: 0 | J13: 0 | K13: 0 | L13: 0 | M13: 0 | O13: 0 | P13: 0 | Q13: 0 | R13: 0 | S13: 0 | T13: 0 | U13: 0 | V13: 0 | W13: 0 | X13: 0 | Y13: 0 | Z13: 0 | AA13: 0 | AB13: 0 | AC13: 0 | AD13: 0 | AE13: 0 | AF13: 0 | AG13: 0
A14: 纺织业 | C14: 0 | D14: 0 | E14: 0 | F14: 0 | G14: 0 | H14: 0 | I14: 0 | J14: 0 | K14: 0 | L14: 0 | M14: 0 | O14: 0 | P14: 0 | Q14: 0 | R14: 0 | S14: 0 | T14: 0 | U14: 0 | V14: 0 | W14: 0 | X14: 0 | Y14: 0 | Z14: 0 | AA14: 0 | AB14: 0 | AC14: 0 | AD14: 0 | AE14: 0 | AF14: 0 | AG14: 0
A15: 纺织服装、服饰业 | C15: 0 | D15: 0 | E15: 0 | F15: 0 | G15: 0 | H15: 0 | I15: 0 | J15: 0 | K15: 0 | L15: 0 | M15: 0 | O15: 0 | P15: 0 | Q15: 0 | R15: 0 | S15: 0 | T15: 0 | U15: 0 | V15: 0 | W15: 0 | X15: 0 | Y15: 0 | Z15: 0 | AA15: 0 | AB15: 0 | AC15: 0 | AD15: 0 | AE15: 0 | AF15: 0 | AG15: 0
A16: 皮革、毛皮、羽毛及其制品和制鞋业 | C16: 0 | D16: 0 | E16: 0 | F16: 0 | G16: 0 | H16: 0 | I16: 0 | J16: 0 | K16: 0 | L16: 0 | M16: 0 | O16: 0 | P16: 0 | Q16: 0 | R16: 0 | S16: 0 | T16: 0 | U16: 0 | V16: 0 | W16: 0 | X16: 0 | Y16: 0 | Z16: 0 | AA16: 0 | AB16: 0 | AC16: 0 | AD16: 0 | AE16: 0 | AF16: 0 | AG16: 0
A17: 木材加工和木、竹、藤、棕、草制品业 | C17: 0 | D17: 0 | E17: 0 | F17: 0 | G17: 0 | H17: 0 | I17: 0 | J17: 0 | K17: 0 | L17: 0 | M17: 0 | O17: 0 | P17: 0 | Q17: 0 | R17: 0 | S17: 0 | T17: 0 | U17: 0 | V17: =V56 -> 0.0067121795 | W17: 0 | X17: 0 | Y17: 0 | Z17: 0 | AA17: 0 | AB17: 0 | AC17: 0 | AD17: 0 | AE17: 0 | AF17: 0 | AG17: 0
A18: 家具制造业 | C18: 0 | D18: 0 | E18: 0 | F18: 0 | G18: 0 | H18: 0 | I18: 0 | J18: 0 | K18: 0 | L18: 0 | M18: 0 | O18: 0 | P18: 0 | Q18: 0 | R18: 0 | S18: 0 | T18: 0 | U18: 0 | V18: 0 | W18: 0 | X18: 0 | Y18: 0 | Z18: 0 | AA18: 0 | AB18: 0 | AC18: 0 | AD18: 0 | AE18: 0 | AF18: 0 | AG18: 0
A19: 造纸和纸制品业 | C19: 0 | D19: 0 | E19: 0 | F19: 0 | G19: 0 | H19: 0 | I19: 0 | J19: 0 | K19: 0 | L19: 0 | M19: 0 | O19: 0 | P19: 0 | Q19: 0 | R19: 0 | S19: 0 | T19: 0 | U19: 0 | V19: 0 | W19: 0 | X19: 0 | Y19: 0 | Z19: 0 | AA19: 0 | AB19: 0 | AC19: 0 | AD19: 0 | AE19: 0 | AF19: 0 | AG19: 0
A20: 印刷和记录媒介复制业 | C20: 0 | D20: 0 | E20: 0 | F20: 0 | G20: 0 | H20: 0 | I20: 0 | J20: 0 | K20: 0 | L20: 0 | M20: 0 | O20: 0 | P20: 0 | Q20: 0 | R20: 0 | S20: 0 | T20: 0 | U20: 0 | V20: 0 | W20: 0 | X20: 0 | Y20: 0 | Z20: 0 | AA20: 0 | AB20: 0 | AC20: 0 | AD20: 0 | AE20: 0 | AF20: 0 | AG20: 0
A21: 文教、工美、体育和娱乐用品制造业 | C21: 0 | D21: 0 | E21: 0 | F21: 0 | G21: 0 | H21: 0 | I21: 0 | J21: 0 | K21: 0 | L21: 0 | M21: 0 | O21: 0 | P21: 0 | Q21: 0 | R21: 0 | S21: 0 | T21: 0 | U21: 0 | V21: =V57 -> 0.0020939705 | W21: 0 | X21: 0 | Y21: 0 | Z21: 0 | AA21: 0 | AB21: 0 | AC21: 0 | AD21: 0 | AE21: 0 | AF21: 0 | AG21: 0
A22: 石油、煤炭及其他燃料加工业 | C22: =C59 -> 0.060786003 | D22: =B65 -> 1 | E22: =C69 -> 0.11249163 | F22: =C69 -> 0.11249163 | G22: =C69 -> 0.11249163 | H22: 0 | I22: 0 | J22: 0 | K22: 0 | L22: 0 | M22: =C88 -> 0.13081331 | O22: 0 | P22: =L60 -> 0.061852619 | Q22: 0 | R22: =L71 -> 0 | S22: =L75 -> 0.38343137 | T22: =L78 -> 0.24832161 | U22: =L83 -> 0.93502706 | V22: 0 | W22: =V63 -> 0.068055983 | X22: =V70 -> 0.019636252 | Y22: 0 | Z22: =V79 -> 0.49962239 | AA22: =U84 -> 1 | AB22: =V88 -> 0.75957984 | AC22: 0 | AD22: 0 | AE22: 0 | AF22: 0 | AG22: =AE62 -> 0.015074762
A23: 化学原料和化学制品制造业 | C23: =C60 -> 0.50551483 | D23: 0 | E23: 0 | F23: 0 | G23: 0 | H23: =C77 -> 0.091554768 | I23: =B83 -> 1 | J23: =B83 -> 1 | K23: =B83 -> 1 | L23: =B83 -> 1 | M23: =C89 -> 0.57067781 | O23: =K54 -> 1 | P23: =L59 -> 0.52648713 | Q23: =L64 -> 0.37051793 | R23: =K70 -> 1 | S23: =L74 -> 0.61656863 | T23: =L79 -> 0.75167839 | U23: 0 | V23: =V58 -> 0.98947278 | W23: =V64 -> 0.93017533 | X23: =V68 -> 0.006134402 | Y23: =W68 -> 0 | Z23: =V80 -> 0.50037761 | AA23: 0 | AB23: =V89 -> 0.24042016 | AC23: =AD53 -> 1 | AD23: =AD57 -> 1 | AE23: 0 | AF23: 0 | AG23: =AE63 -> 0.22257299
A24: 医药制造业 | C24: 0 | D24: 0 | E24: 0 | F24: 0 | G24: 0 | H24: 0 | I24: 0 | J24: 0 | K24: 0 | L24: 0 | M24: 0 | O24: 0 | P24: 0 | Q24: 0 | R24: 0 | S24: 0 | T24: 0 | U24: 0 | V24: =V59 -> 0.00011473811 | W24: =W59 -> 0 | X24: 0 | Y24: 0 | Z24: 0 | AA24: 0 | AB24: 0 | AC24: 0 | AD24: 0 | AE24: 0 | AF24: 0 | AG24: 0
A25: 化学纤维制造业 | C25: 0 | D25: 0 | E25: 0 | F25: 0 | G25: 0 | H25: 0 | I25: 0 | J25: 0 | K25: 0 | L25: 0 | M25: 0 | O25: 0 | P25: 0 | Q25: 0 | R25: 0 | S25: 0 | T25: 0 | U25: 0 | V25: 0 | W25: 0 | X25: 0 | Y25: 0 | Z25: 0 | AA25: 0 | AB25: 0 | AC25: 0 | AD25: 0 | AE25: 0 | AF25: 0 | AG25: 0
A26: 橡胶和塑料制品业 | C26: 0 | D26: 0 | E26: 0 | F26: 0 | G26: 0 | H26: 0 | I26: 0 | J26: 0 | K26: 0 | L26: 0 | M26: 0 | O26: 0 | P26: =L58 -> 0.41166025 | Q26: =L63 -> 0.16334661 | R26: 0 | S26: 0 | T26: 0 | U26: 0 | V26: 0 | W26: 0 | X26: 0 | Y26: 0 | Z26: 0 | AA26: 0 | AB26: 0 | AC26: 0 | AD26: 0 | AE26: 0 | AF26: 0 | AG26: 0
A27: 非金属矿物制品业 | C27: 0 | D27: 0 | E27: =C70 -> 0.82205214 | F27: =C70 -> 0.82205214 | G27: =C70 -> 0.82205214 | H27: 0 | I27: 0 | J27: 0 | K27: 0 | L27: 0 | M27: =C90 -> 0.020324817 | O27: 0 | P27: 0 | Q27: 0 | R27: 0 | S27: 0 | T27: 0 | U27: 0 | V27: 0 | W27: =V65 -> 0.0017686866 | X27: =V69 -> 0.97422935 | Y27: =V74 -> 0.90323942 | Z27: 0 | AA27: 0 | AB27: 0 | AC27: 0 | AD27: 0 | AE27: 0 | AF27: 0 | AG27: =AE64 -> 0.22034603
A28: 黑色金属冶炼和压延加工业 | C28: =C61 -> 0.43369916 | D28: 0 | E28: =C71 -> 0.065456223 | F28: =C71 -> 0.065456223 | G28: =C71 -> 0.065456223 | H28: =C78 -> 0.90844523 | I28: 0 | J28: 0 | K28: 0 | L28: 0 | M28: =C91 -> 0.27818406 | O28: 0 | P28: 0 | Q28: 0 | R28: 0 | S28: 0 | T28: 0 | U28: 0 | V28: 0 | W28: 0 | X28: 0 | Y28: 0 | Z28: 0 | AA28: 0 | AB28: 0 | AC28: 0 | AD28: 0 | AE28: 0 | AF28: 0 | AG28: 0
A29: 有色金属冶炼和压延加工业 | C29: 0 | D29: 0 | E29: 0 | F29: 0 | G29: 0 | H29: 0 | I29: 0 | J29: 0 | K29: 0 | L29: 0 | M29: 0 | O29: 0 | P29: 0 | Q29: 0 | R29: 0 | S29: 0 | T29: 0 | U29: 0 | V29: 0 | W29: 0 | X29: 0 | Y29: =V73 -> 0.096760583 | Z29: 0 | AA29: 0 | AB29: 0 | AC29: 0 | AD29: 0 | AE29: 0 | AF29: 0 | AG29: 0
A30: 金属制品业 | C30: 0 | D30: 0 | E30: 0 | F30: 0 | G30: 0 | H30: 0 | I30: 0 | J30: 0 | K30: 0 | L30: 0 | M30: 0 | O30: 0 | P30: 0 | Q30: 0 | R30: 0 | S30: 0 | T30: 0 | U30: 0 | V30: 0 | W30: 0 | X30: 0 | Y30: 0 | Z30: 0 | AA30: 0 | AB30: 0 | AC30: 0 | AD30: 0 | AE30: 0 | AF30: 0 | AG30: 0
A31: 通用设备制造业 | C31: 0 | D31: 0 | E31: 0 | F31: 0 | G31: 0 | H31: 0 | I31: 0 | J31: 0 | K31: 0 | L31: 0 | M31: 0 | O31: 0 | P31: 0 | Q31: =L65 -> 0.31606906 | R31: 0 | S31: 0 | T31: 0 | U31: =L84 -> 0.012387252 | V31: 0 | W31: 0 | X31: 0 | Y31: 0 | Z31: 0 | AA31: 0 | AB31: 0 | AC31: 0 | AD31: 0 | AE31: 0 | AF31: 0 | AG31: 0
A32: 专用设备制造业 | C32: 0 | D32: 0 | E32: 0 | F32: 0 | G32: 0 | H32: 0 | I32: 0 | J32: 0 | K32: 0 | L32: 0 | M32: 0 | O32: 0 | P32: 0 | Q32: =L66 -> 0.1500664 | R32: 0 | S32: 0 | T32: 0 | U32: =L85 -> 0.012266987 | V32: 0 | W32: 0 | X32: 0 | Y32: 0 | Z32: 0 | AA32: 0 | AB32: 0 | AC32: 0 | AD32: 0 | AE32: 0 | AF32: 0 | AG32: 0
A33: 汽车制造业 | C33: 0 | D33: 0 | E33: 0 | F33: 0 | G33: 0 | H33: 0 | I33: 0 | J33: 0 | K33: 0 | L33: 0 | M33: 0 | O33: 0 | P33: 0 | Q33: 0 | R33: 0 | S33: 0 | T33: 0 | U33: =L86 -> 0.039326518 | V33: 0 | W33: 0 | X33: 0 | Y33: 0 | Z33: 0 | AA33: 0 | AB33: 0 | AC33: 0 | AD33: 0 | AE33: 0 | AF33: 0 | AG33: 0
A34: 铁路、船舶、航空航天和其他运输设备制造业 | C34: 0 | D34: 0 | E34: 0 | F34: 0 | G34: 0 | H34: 0 | I34: 0 | J34: 0 | K34: 0 | L34: 0 | M34: 0 | O34: 0 | P34: 0 | Q34: 0 | R34: 0 | S34: 0 | T34: 0 | U34: =L87 -> 0.0009921828 | V34: 0 | W34: 0 | X34: 0 | Y34: 0 | Z34: 0 | AA34: 0 | AB34: 0 | AC34: 0 | AD34: 0 | AE34: 0 | AF34: 0 | AG34: 0
A35: 电气机械和器材制造业 | C35: 0 | D35: 0 | E35: 0 | F35: 0 | G35: 0 | H35: 0 | I35: 0 | J35: 0 | K35: 0 | L35: 0 | M35: 0 | O35: 0 | P35: 0 | Q35: 0 | R35: 0 | S35: 0 | T35: 0 | U35: 0 | V35: 0 | W35: 0 | X35: 0 | Y35: 0 | Z35: 0 | AA35: 0 | AB35: 0 | AC35: 0 | AD35: 0 | AE35: 0 | AF35: 0 | AG35: 0
A36: 计算机、通信和其他电子设备制造业 | C36: 0 | D36: 0 | E36: 0 | F36: 0 | G36: 0 | H36: 0 | I36: 0 | J36: 0 | K36: 0 | L36: 0 | M36: 0 | O36: 0 | P36: 0 | Q36: 0 | R36: 0 | S36: 0 | T36: 0 | U36: 0 | V36: 0 | W36: 0 | X36: 0 | Y36: 0 | Z36: 0 | AA36: 0 | AB36: 0 | AC36: 0 | AD36: 0 | AE36: 0 | AF36: 0 | AG36: 0
A37: 仪器仪表制造业 | C37: 0 | D37: 0 | E37: 0 | F37: 0 | G37: 0 | H37: 0 | I37: 0 | J37: 0 | K37: 0 | L37: 0 | M37: 0 | O37: 0 | P37: 0 | Q37: 0 | R37: 0 | S37: 0 | T37: 0 | U37: 0 | V37: 0 | W37: 0 | X37: 0 | Y37: 0 | Z37: 0 | AA37: 0 | AB37: 0 | AC37: 0 | AD37: 0 | AE37: 0 | AF37: 0 | AG37: 0
A38: 其他制造业 | C38: 0 | D38: 0 | E38: 0 | F38: 0 | G38: 0 | H38: 0 | I38: 0 | J38: 0 | K38: 0 | L38: 0 | M38: 0 | O38: 0 | P38: 0 | Q38: 0 | R38: 0 | S38: 0 | T38: 0 | U38: 0 | V38: 0 | W38: 0 | X38: 0 | Y38: 0 | Z38: 0 | AA38: 0 | AB38: 0 | AC38: 0 | AD38: 0 | AE38: 0 | AF38: 0 | AG38: 0
A39: 废弃资源综合利用业 | C39: 0 | D39: 0 | E39: 0 | F39: 0 | G39: 0 | H39: 0 | I39: 0 | J39: 0 | K39: 0 | L39: 0 | M39: 0 | O39: 0 | P39: 0 | Q39: 0 | R39: 0 | S39: 0 | T39: 0 | U39: 0 | V39: 0 | W39: 0 | X39: 0 | Y39: 0 | Z39: 0 | AA39: 0 | AB39: 0 | AC39: 0 | AD39: 0 | AE39: 0 | AF39: 0 | AG39: 0
A40: 金属制品、机械和设备修理业 | C40: 0 | D40: 0 | E40: 0 | F40: 0 | G40: 0 | H40: 0 | I40: 0 | J40: 0 | K40: 0 | L40: 0 | M40: 0 | O40: 0 | P40: 0 | Q40: 0 | R40: 0 | S40: 0 | T40: 0 | U40: 0 | V40: 0 | W40: 0 | X40: 0 | Y40: 0 | Z40: 0 | AA40: 0 | AB40: 0 | AC40: 0 | AD40: 0 | AE40: 0 | AF40: 0 | AG40: 0
...

Sheet Final Energy Consumption-2020
A1: 4-2 工业分行业终端能源消费量(标准量)-2020 | AG1: 电力数据来自《电力工业统计资料汇编2020》
A2: 行 业 | B2: (发电煤耗_x000D_ 计算法)_x000D_ (Coal_x000D_ Equivalent_x000D_ C alculation) | C2: (电热当量_x000D_ 计算法)_x000D_ (Calorific_x000D_ Value_x000D_ C alculation) | D2: 煤合计_x000D_ Coal Total | E2: 原煤_x000D_ Raw Coal | F2: 洗精煤_x000D_ Cleaned_x000D_ Coal | G2: 其他洗煤_x000D_ Other_x000D_ Washed_x000D_ Coal | H2: 煤制品_x000D_ Briquettes | I2: 焦炭_x000D_ Coke | J2: 焦炉煤气_x000D_ Coke Oven_x000D_ Gas | K2: 高炉煤气_x000D_ Blast Furnace_x000D_ Gas | L2: 转炉煤气_x000D_ Converter_x000D_ Gas | M2: 其他煤气_x000D_ Other Gas | N2: 其他焦化产品_x000D_ Other_x000D_ Coking_x000D_ Products | O2: 油品合计_x000D_ Petroleum_x000D_ Products_x000D_ Total | P2: 原油_x000D_ Crude Oil | Q2: 汽油_x000D_ Gasoline | R2: 煤油_x000D_ Kerosene | S2: 柴油_x000D_ Diesel Oil | T2: 燃料油_x000D_ Fuel Oil | U2: 石脑油_x000D_ Naphtha | V2: 润滑油_x000D_ Lubricants | W2: 石蜡_x000D_ Paraffin_x000D_ Waxes | X2: 溶剂油_x000D_ White Spirit | Y2: 石油沥青_x000D_ Bitumen_x000D_ Asphalt | Z2: 石油焦_x000D_ Petroleum_x000D_ Coke | AA2: 液化石油气_x000D_ Liquefied_x000D_ Petroleum Gas | AB2: 炼厂干气_x000D_ Refinery_x000D_ Gas | AC2: 其他石油制品_x000D_ Other_x000D_ Petroleum_x000D_ Products | AD2: 天然气_x000D_ Natural Gas | AE2: 液化天然气_x000D_ Liquefied_x000D_ Natural Gas | AF2: 热力_x000D_ Heat | AG2: 电力_x000D_ (亿千瓦小时)_x000D_ Electricity_x000D_ (108 kW·h) | AH2: 其他能源_x000D_ Other Energy
A3: 煤炭开采和洗选业 | B3: 4621.67 | C3: 3030.46 | D3: 1240.31 | E3: 769.07 | G3: 468.72 | H3: =D3-SUM(E3:G3) -> 2.52 | I3: 4.77 | J3: 5.41 | K3: 0.5 | M3: 2.01 | N3: 0.66 | O3: 500.09 | P3: 0.12 | Q3: 4.74 | R3: 0.9 | S3: 214.81 | T3: 0.28 | U3: 213.9 | V3: 1.73 | Y3: 0.47 | AA3: 62.48 | AC3: 0.67 | AD3: 110.48 | AE3: 26.79 | AF3: 21.4 | AG3: 908.8095 | AH3: 1.13
A4: 石油和天然气开采业 | B4: 3593.39 | C4: 2782.16 | D4: 49.1 | E4: 49.1 | H4: =D4-SUM(E4:G4) -> 0 | O4: 437.32 | P4: 353.6 | Q4: 8.31 | S4: 36.43 | T4: 0.42 | V4: 0.01 | AA4: 0.17 | AB4: 16.7 | AC4: 21.69 | AD4: 1614.22 | AE4: 20.52 | AF4: 91.57 | AG4: 463.3245
A5: 黑色金属矿采选业 | B5: 1728.07 | C5: 944.66 | D5: 128.89 | E5: 121.31 | G5: 2.77 | H5: =D5-SUM(E5:G5) -> 4.81 | I5: 164.78 | J5: 15.8 | K5: 25.33 | L5: 0.28 | O5: 52.16 | Q5: 0.88 | R5: 0.01 | S5: 50.84 | T5: 0.01 | V5: 0.41 | AC5: 0.01 | AD5: 0.68 | AF5: 4.45 | AG5: 447.4405 | AH5: 2.39
A6: 有色金属矿采选业 | B6: 1089.22 | C6: 512.36 | D6: 53.54 | E6: 52.86 | G6: 0.68 | H6: =D6-SUM(E6:G6) -> 0 | I6: 3.54 | J6: 5.76 | O6: 27.94 | Q6: 1.57 | R6: 0.6 | S6: 24.14 | T6: 0.74 | V6: 0.05 | Y6: 0.52 | Z6: 0.33 | AD6: 10.63 | AF6: 0.01 | AG6: 329.4696 | AH6: 6.01
A7: 非金属矿采选业 | B7: 1104.47 | C7: 709.3 | D7: 212.27 | E7: 190.6 | G7: 18.16 | H7: =D7-SUM(E7:G7) -> 3.51 | I7: 14.31 | J7: 9.5 | L7: 3.32 | O7: 72.85 | Q7: 1.14 | R7: 0.02 | S7: 69.67 | T7: 0.05 | V7: 0.23 | Y7: 0.77 | Z7: 0.76 | AA7: 0.11 | AC7: 0.1 | AD7: 10.73 | AE7: 30.54 | AF7: 78.07 | AG7: 225.6995 | AH7: 0.33
A8: 开采专业及辅助性活动 | B8: 296.1 | C8: 244.39 | D8: 2.52 | E8: 2.52 | H8: =D8-SUM(E8:G8) -> 0 | O8: 158.23 | P8: 0.13 | Q8: 3.81 | S8: 153.24 | T8: 0.1 | V8: 0.62 | AA8: 0.11 | AC8: 0.23 | AD8: 37.89 | AE8: 0.88 | AF8: 8.56 | AG8: 0
A9: 其他采矿业 | B9: 488.4 | C9: 205.28 | D9: 6.21 | E9: 6.21 | H9: =D9-SUM(E9:G9) -> 0 | O9: 0.33 | S9: 0.33 | AG9: 161.7055
A10: 农副食品加工业 | B10: 3950.36 | C10: 2475.39 | D10: 527.85 | E10: 488.83 | G10: 36.48 | H10: =D10-SUM(E10:G10) -> 2.54 | I10: 13.6 | J10: 0.18 | M10: 0.24 | O10: 30.44 | Q10: 7.14 | R10: 0.05 | S10: 17.97 | T10: 1.33 | V10: 0.04 | W10: 0.02 | X10: 1.97 | AA10: 1.67 | AC10: 0.25 | AD10: 53.65 | AE10: 329.48 | AF10: 297.8 | AG10: 693.8324 | AH10: 186.82
A11: 食品制造业 | B11: 2092.87 | C11: 1507.92 | D11: 406.06 | E11: 400.57 | G11: 1.57 | H11: =D11-SUM(E11:G11) -> 3.92 | I11: 1.79 | O11: 16.73 | Q11: 5.42 | R11: 0.02 | S11: 7.3 | T11: 0.62 | V11: 0.01 | AA11: 2.07 | AC11: 1.29 | AD11: 176.97 | AE11: 157.22 | AF11: 299.93 | AG11: 411.1613 | AH11: 38.62
A12: 酒、饮料和精制茶制造业 | B12: 1192.16 | C12: 883.9 | D12: 254.33 | E12: 250.52 | G12: 2.69 | H12: =D12-SUM(E12:G12) -> 1.12 | I12: 0.01 | J12: 0.09 | L12: 0.01 | M12: 0.03 | N12: 0.01 | O12: 8.66 | Q12: 2.68 | S12: 4.21 | T12: 0.55 | V12: 0.02 | AA12: 1.2 | AC12: 0.01 | AD12: 127.28 | AE12: 61.12 | AF12: 200.84 | AG12: 149.265 | AH12: 15.13
A13: 烟草制品业 | B13: 179.81 | C13: 90.75 | D13: 3.09 | E13: 3.09 | H13: =D13-SUM(E13:G13) -> 0 | O13: 1 | Q13: 0.12 | S13: 0.81 | AA13: 0.06 | AD13: 14.58 | AF13: 7.33 | AG13: 37.1766 | AH13: 2.23
A14: 纺织业 | B14: 6939.37 | C14: 4049.75 | D14: 207.58 | E14: 174.82 | G14: 3.93 | H14: =D14-SUM(E14:G14) -> 28.83 | I14: 3.82 | O14: 17.34 | Q14: 4.81 | R14: 0.02 | S14: 5.54 | T14: 1.67 | V14: 0.15 | Y14: 2.06 | AA14: 2.34 | AC14: 0.75 | AD14: 202.85 | AE14: 444.87 | AF14: 1092.9 | AG14: 1546.1442 | AH14: 52.08
A15: 纺织服装、服饰业 | B15: 851.69 | C15: 466.07 | D15: 22.05 | E15: 21.84 | G15: 0.16 | H15: =D15-SUM(E15:G15) -> 0.05 | I15: 0.04 | O15: 8.19 | Q15: 4.25 | S15: 3.15 | T15: 0.36 | V15: 0.03 | AA15: 0.35 | AC15: 0.04 | AD15: 12.87 | AE15: 135.03 | AF15: 10.96 | AG15: 326.2436 | AH15: 6.26
A16: 皮革、毛皮、羽毛及其制品和制鞋业 | B16: 489.29 | C16: 242.49 | D16: 13.1 | E16: 11.82 | G16: 0.01 | H16: =D16-SUM(E16:G16) -> 1.27 | K16: 0.09 | O16: 4.63 | Q16: 2.3 | S16: 1.46 | T16: 0.2 | V16: 0.06 | X16: 0.15 | AA16: 0.35 | AC16: 0.1 | AD16: 1.43 | AE16: 35.96 | AF16: 6.3 | AG16: 200.0444 | AH16: 7.75
A17: 木材加工和木、竹、藤、棕、草制品业 | B17: 1027.01 | C17: 529.8 | D17: 25.64 | E17: 25.36 | G17: 0.28 | H17: =D17-SUM(E17:G17) -> 0 | I17: 0.01 | O17: 10.51 | Q17: 1.86 | S17: 5.65 | T17: 0.19 | V17: 0.09 | W17: 2.3 | AA17: 0.41 | AD17: 35.89 | AE17: 4.03 | AF17: 23.67 | AG17: 356.0435 | AH17: 81.03
A18: 家具制造业 | B18: 394.02 | C18: 182.62 | D18: 1.4 | E18: 1.29 | G18: 0.1 | H18: =D18-SUM(E18:G18) -> 0.01 | I18: 0.06 | O18: 5.67 | Q18: 2.4 | R18: 0.02 | S18: 2.75 | T18: 0.08 | V18: 0.11 | AA18: 0.31 | AD18: 17.44 | AE18: 3.92 | AF18: 2.6 | AG18: 169.9242 | AH18: 3.13
A19: 造纸和纸制品业 | B19: 3887.64 | C19: 2490 | D19: 369.4 | E19: 328.83 | G19: 23.4 | H19: =D19-SUM(E19:G19) -> 17.17 | I19: 7.7 | J19: 0.42 | O19: 22.87 | P19: 0.04 | Q19: 2.4 | S19: 13.44 | T19: 3.88 | V19: 0.12 | W19: 0.05 | X19: 0.38 | AA19: 2.43 | AC19: 0.12 | AD19: 65.25 | AE19: 205.88 | AF19: 774.59 | AG19: 798.2513 | AH19: 62.84
A20: 印刷和记录媒介复制业 | B20: 501.23 | C20: 269.18 | D20: 9.52 | E20: 9.02 | G20: 0.17 | H20: =D20-SUM(E20:G20) -> 0.33 | I20: 0.02 | J20: 2.28 | O20: 10.03 | Q20: 4.17 | R20: 0.01 | S20: 4.54 | T20: 0.23 | V20: 0.08 | X20: 0.04 | AA20: 0.71 | AC20: 0.25 | AD20: 45.56 | AE20: 14.49 | AF20: 17.09 | AG20: 132.5307 | AH20: 7.32
A21: 文教、工美、体育和娱乐用品制造业 | B21: 500.92 | C21: 352.01 | D21: 7.63 | E21: 7.34 | H21: =D21-SUM(E21:G21) -> 0.29 | I21: 0.43 | O21: 20.15 | Q21: 3.03 | S21: 2.88 | T21: 0.39 | V21: 0.03 | W21: 0.69 | X21: 0.08 | Z21: 11.63 | AA21: 1.21 | AC21: 0.19 | AD21: 41.31 | AE21: 168.98 | AF21: 3.67 | AG21: 154.0847 | AH21: 5.31
A22: 石油、煤炭及其他燃料加工业 | B22: 26515.09 | C22: 24268.19 | D22: 1208.77 | E22: 793.44 | G22: 391.48 | H22: =D22-SUM(E22:G22) -> 23.85 | I22: 54.9 | J22: 1124.43 | K22: 128.8 | L22: 7.82 | M22: 4.59 | N22: 105.17 | O22: 16377.38 | P22: 74.64 | Q22: 1.76 | R22: 0.04 | S22: 17.08 | T22: 166.66 | U22: 1942.97 | V22: 341.29 | W22: 0.02 | X22: 1.54 | Y22: 10.32 | Z22: 230.53 | AA22: 2605.08 | AB22: 2609.06 | AC22: 8376.38 | AD22: 350.23 | AE22: 1010.49 | AF22: 2266.33 | AG22: 1357.828 | AH22: 52.1
A23: 化学原料和化学制品制造业 | B23: 55001.55 | C23: 44879.46 | D23: 9309.45 | E23: 9064.65 | G23: 124.04 | H23: =D23-SUM(E23:G23) -> 120.76 | I23: 3943.83 | J23: 516.65 | K23: 12.11 | L23: 23.29 | M23: 23.88 | N23: 629.69 | O23: 11992.61 | P23: 168.9 | Q23: 12.93 | R23: 2.95 | S23: 37.14 | T23: 42.54 | U23: 7111.11 | V23: 1.68 | W23: 263.44 | X23: 58.17 | Y23: 51.17 | Z23: 89.14 | AA23: 1440.52 | AB23: 299.23 | AC23: 2413.68 | AD23: 2382.17 | AE23: 3020.82 | AF23: 5687.64 | AG23: 4783.9282 | AH23: 232.29
A24: 医药制造业 | B24: 2244.73 | C24: 1491.05 | D24: 300.49 | E24: 292.51 | G24: 1.8 | H24: =D24-SUM(E24:G24) -> 6.18 | I24: 3.36 | J24: 0.86 | M24: 0.03 | N24: 0.01 | O24: 14.35 | Q24: 4.38 | R24: 0.01 | S24: 5.47 | T24: 2.15 | V24: 0.01 | W24: 0.04 | X24: 0.5 | AA24: 0.79 | AC24: 1.01 | AD24: 101.95 | AE24: 144.22 | AF24: 376.85 | AG24: 430.4539 | AH24: 19.9
A25: 化学纤维制造业 | B25: 2349.36 | C25: 1560.82 | D25: 378.47 | E25: 269.4 | G25: 2.31 | H25: =D25-SUM(E25:G25) -> 106.76 | I25: 0.06 | O25: 3.49 | Q25: 0.55 | R25: 0.02 | S25: 1.62 | T25: 0.9 | V25: 0.06 | X25: 0.13 | AA25: 0.15 | AC25: 0.07 | AD25: 28.91 | AE25: 204.1 | AF25: 377.49 | AG25: 406.8015 | AH25: 14.79
A26: 橡胶和塑料制品业 | B26: 4978.63 | C26: 2385.99 | D26: 157.25 | E26: 143.67 | G26: 1.02 | H26: =D26-SUM(E26:G26) -> 12.56 | I26: 1.92 | J26: 4.04 | N26: 2.96 | O26: 38.55 | P26: 0.06 | Q26: 8.71 | R26: 0.07 | S26: 11.2 | T26: 3.16 | V26: 0.77 | W26: 1.72 | X26: 0.74 | Y26: 3.78 | AA26: 4.37 | AB26: 0.01 | AC26: 3.96 | AD26: 105.66 | AE26: 135.3 | AF26: 106.59 | AG26: 1480.7648 | AH26: 13.85
A27: 非金属矿物制品业 | B27: 36429.51 | C27: 29549.37 | D27: 16206.53 | E27: 10780.99 | G27: 5307.4 | H27: =D27-SUM(E27:G27) -> 118.14 | I27: 1421.3 | J27: 218.69 | K27: 59.31 | L27: 25.62 | M27: 15.14 | N27: 19.11 | O27: 3619.49 | P27: 0.52 | Q27: 19.01 | R27: 0.77 | S27: 338.44 | T27: 83.27 | V27: 1.11 | W27: 1.21 | X27: 0.38 | Y27: 367.88 | Z27: 2692.85 | AA27: 93.38 | AB27: 0.13 | AC27: 20.55 | AD27: 541.56 | AE27: 2347.01 | AF27: 163.19 | AG27: 3929.5293 | AH27: 83.03
A28: 黑色金属冶炼和压延加工业 | B28: 85274.38 | C28: 73393.66 | D28: 8414.73 | E28: 7868.94 | G28: 477.41 | H28: =D28-SUM(E28:G28) -> 68.38 | I28: 39181.81 | J28: 2020.99 | K28: 10739.35 | L28: 1688.54 | M28: 2.8 | N28: 379.71 | O28: 105.13 | Q28: 3.68 | R28: 0.03 | S28: 59.67 | T28: 0.38 | V28: 1.83 | W28: 0.01 | Z28: 22.37 | AA28: 15.17 | AB28: 1.45 | AC28: 0.54 | AD28: 616.31 | AE28: 1218.21 | AF28: 639.34 | AG28: 5949.9543 | AH28: 47.29
A29: 有色金属冶炼和压延加工业 | B29: 25385.6 | C29: 12896.7 | D29: 1699.95 | E29: 1543.04 | G29: 151.46 | H29: =D29-SUM(E29:G29) -> 5.45 | I29: 388.23 | J29: 134.98 | L29: 5.01 | M29: 122.79 | N29: 11.3 | O29: 356.9 | P29: 0.3 | Q29: 3.65 | R29: 0.55 | S29: 35.32 | T29: 11.03 | V29: 0.68 | W29: 0.01 | X29: 0.15 | Y29: 20.56 | Z29: 270.77 | AA29: 4.75 | AC29: 9.12 | AD29: 279.32 | AE29: 385.99 | AF29: 738.79 | AG29: 6642.6004 | AH29: 7.08
A30: 金属制品业 | B30: 6555.24 | C30: 3838.12 | D30: 188.24 | E30: 159.89 | G30: 27.64 | H30: =D30-SUM(E30:G30) -> 0.71 | I30: 572.26 | J30: 18.32 | K30: 121.63 | L30: 8.26 | M30: 1.12 | N30: 3.47 | O30: 44.29 | Q30: 12.12 | R30: 0.44 | S30: 19.1 | T30: 1.07 | V30: 0.94 | W30: 0.04 | X30: 0.03 | Y30: 0.25 | AA30: 9.58 | AB30: 0.01 | AC30: 0.71 | AD30: 172.49 | AE30: 774.7 | AF30: 21.47 | AG30: 2175.0266 | AH30: 4.64
A31: 通用设备制造业 | B31: 3981.56 | C31: 2095.03 | D31: 10.6 | E31: 9.56 | G31: 0.25 | H31: =D31-SUM(E31:G31) -> 0.79 | I31: 400.3 | J31: 6.7 | K31: 0.31 | L31: 1.01 | O31: 52.33 | Q31: 16.01 | R31: 2.12 | S31: 21.39 | T31: 0.65 | U31: 0.04 | V31: 5.09 | W31: 0.19 | X31: 0.06 | AA31: 4.75 | AB31: 0.01 | AC31: 2.04 | AD31: 133.13 | AE31: 149.4 | AF31: 11.98 | AG31: 981.0091 | AH31: 5.06
A32: 专用设备制造业 | B32: 1820.34 | C32: 947.46 | D32: 6.94 | E32: 2.95 | H32: =D32-SUM(E32:G32) -> 3.99 | J32: 1.91 | K32: 4.79 | L32: 0.01 | M32: 0.89 | N32: 3.2 | O32: 52.18 | P32: 0.01 | Q32: 12.22 | R32: 1.3 | S32: 21.87 | T32: 0.54 | V32: 5.22 | W32: 0.05 | X32: 0.06 | AA32: 6.72 | AC32: 4.2 | AD32: 67.34 | AE32: 164.74 | AF32: 28.41 | AG32: 387.9522 | AH32: 4.35
A33: 汽车制造业 | B33: 4069.55 | C33: 1998.63 | D33: 12.42 | E33: 11.79 | G33: 0.03 | H33: =D33-SUM(E33:G33) -> 0.6 | I33: 10.91 | J33: 0.37 | K33: 0.02 | L33: 0.03 | M33: 0.29 | O33: 61.07 | P33: 0.01 | Q33: 20.05 | R33: 0.36 | S33: 23.79 | T33: 0.25 | U33: 0.01 | V33: 11.83 | W33: 0.02 | X33: 0.18 | Y33: 0.01 | AA33: 2.73 | AC33: 1.83 | AD33: 87.82 | AE33: 280.67 | AF33: 89.08 | AG33: 568.5171 | AH33: 2.32
A34: 铁路、船舶、航空航天和其他运输设备制造业 | B34: 826.62 | C34: 546.9 | D34: 18.42 | E34: 7.48 | G34: 10.94 | H34: =D34-SUM(E34:G34) -> 0 | I34: 0.39 | J34: 1.34 | M34: 0.01 | O34: 21.89 | Q34: 3.99 | R34: 1.92 | S34: 11.06 | T34: 1.4 | V34: 0.48 | W34: 0.3 | X34: 0.04 | AA34: 2.25 | AC34: 0.43 | AD34: 63.66 | AE34: 224.41 | AF34: 20.2 | AG34: 326.6488 | AH34: 0.24
A35: 电气机械和器材制造业 | B35: 3105.62 | C35: 1454.78 | D35: 8.61 | E35: 8.61 | H35: =D35-SUM(E35:G35) -> 0 | I35: 0.68 | J35: 0.03 | M35: 0.01 | O35: 35.92 | Q35: 15.1 | R35: 0.18 | S35: 9.46 | T35: 1.7 | V35: 2.67 | W35: 0.2 | X35: 0.14 | Y35: 0.05 | Z35: 0.33 | AA35: 4.55 | AC35: 1.55 | AD35: 43.86 | AE35: 154.49 | AF35: 47.65 | AG35: 919.1269 | AH35: 4.76
A36: 计算机、通信和其他电子设备制造业 | B36: 5115.51 | C36: 2365.55 | D36: 11.68 | E36: 11.2 | G36: 0.47 | H36: =D36-SUM(E36:G36) -> 0.01 | I36: 0.02 | J36: 0.26 | K36: 0.01 | O36: 18.67 | Q36: 9.26 | R36: 0.04 | S36: 5.13 | T36: 0.38 | V36: 0.45 | W36: 0.01 | X36: 0.04 | AA36: 2.64 | AC36: 0.72 | AD36: 159.29 | AE36: 199.67 | AF36: 42.81 | AG36: 1825.0708 | AH36: 2.87
A37: 仪器仪表制造业 | B37: 252.35 | C37: 117.12 | D37: 1.66 | E37: 1.66 | H37: =D37-SUM(E37:G37) -> 0 | O37: 5.61 | Q37: 3.9 | R37: 0.06 | S37: 1.02 | T37: 0.1 | V37: 0.12 | W37: 0.08 | AA37: 0.15 | AC37: 0.18 | AD37: 6.61 | AE37: 4.77 | AF37: 2.33 | AG37: 78.2265 | AH37: 1.21
A38: 其他制造业 | B38: 1857.49 | C38: 805.74 | D38: 2.66 | E38: 2.63 | H38: =D38-SUM(E38:G38) -> 0.03 | I38: 0.06 | K38: 0.89 | O38: 7.15 | Q38: 0.66 | R38: 0.13 | S38: 1.21 | V38: 0.01 | W38: 0.1 | AA38: 5.05 | AD38: 0.58 | AE38: 52.57 | AF38: 2.82 | AG38: 552.6412 | AH38: 0.76
A39: 废弃资源综合利用业 | B39: 703.74 | C39: 586.26 | D39: 188.33 | E39: 59 | G39: 126.46 | H39: =D39-SUM(E39:G39) -> 2.87 | I39: 66.88 | J39: 6.51 | K39: 14.1 | L39: 4.62 | N39: 0.69 | O39: 10.62 | Q39: 0.35 | R39: 0.01 | S39: 5.96 | T39: 0.92 | V39: 0.03 | Z39: 2.86 | AA39: 0.44 | AC39: 0.03 | AD39: 37.19 | AE39: 167.5 | AF39: 1.36 | AG39: 124.8874 | AH39: 6
A40: 金属制品、机械和设备修理业 | B40: 63.4 | C40: 37.41 | D40: 0.93 | E40: 0.93 | H40: =D40-SUM(E40:G40) -> 0 | J40: 0.35 | M40: 0.01 | O40: 8.89 | Q40: 0.61 | R40: 1.16 | S40: 6.69 | T40: 0.25 | V40: 0.14 | AA40: 0.04 | AD40: 2.87 | AE40: 5.12 | AF40: 0.99 | AG40: 90.8547
...

Sheet Feedstock Split-2020
B1: 煤合计_x000D_ Coal Total | C1: 原煤_x000D_ Raw Coal | D1: 洗精煤_x000D_ Cleaned_x000D_ Coal | E1: 其他洗煤_x000D_ Other_x000D_ Washed_x000D_ Coal | F1: 煤制品_x000D_ Briquettes | G1: 煤矸石_x000D_ Gangue | H1: 焦炭_x000D_ Coke | I1: 焦炉煤气_x000D_ Coke Oven_x000D_ Gas | J1: 高炉煤气_x000D_ Blast Furnace_x000D_ Gas | K1: 转炉煤气_x000D_ Converter_x000D_ Gas | L1: 其他煤气_x000D_ Other Gas | M1: 其他焦化产品_x000D_ Other_x000D_ Coking_x000D_ Products | N1: 油品合计_x000D_ Petroleum_x000D_ Products_x000D_ Total | O1: 原油_x000D_ Crude Oil | P1: 汽油_x000D_ Gasoline | Q1: 煤油_x000D_ Kerosene | R1: 柴油_x000D_ Diesel Oil | S1: 燃料油_x000D_ Fuel Oil | T1: 石脑油_x000D_ Naphtha | U1: 润滑油_x000D_ Lubricants | V1: 石蜡_x000D_ Paraffin_x000D_ Waxes | W1: 溶剂油_x000D_ White spirit | X1: 石油沥青_x000D_ Bitumen_x000D_ Asphalt | Y1: 石油焦_x000D_ Petroleum_x000D_ Coke | Z1: 液化石油气_x000D_ Liquefied_x000D_ Petroleum Gas | AA1: 炼厂干气_x000D_ Refinery_x000D_ Gas | AB1: 其他石油制品_x000D_ Other_x000D_ Petroleum_x000D_ Products | AC1: 天然气_x000D_ Natural Gas | AD1: 液化天然气_x000D_ Liquefied_x000D_ Natural Gas | AE1: 热力_x000D_ Heat | AF1: 电力_x000D_ Electricity | AG1: 其他能源_x000D_ Other_x000D_ Energy
