Workbook

Sheet About
A1: PPRiFUfERoIF Potential Perc Reduction in Fuel Use from Early Retirement of Inefficient Facilities
A2: PPRiFUfIIaIoE Potential Perc Reduction in Fuel Use from Improved Installation and Integration of Eqpt
A3: PPRiFUfICaWHR Potential Perc Reduction in Fuel Use from Increased Cogen and Waste Heat Recovery
A6: Source: | B6: Energy saving potential of key technologies in some key industries
B7: Ministry of Industry and Information Technology of the People's Republic of China 中华人民共和国工业和信息化部
B8: National Recommended Catalogue of Industrial Energy Conservation Technologies 2020 2021 2022
B9: 国家工业节能技术推荐目录 2020 2021 2022
B10: https://wap.miit.gov.cn/zwgk/zcwj/wjfb/gg/art/2020/art_e0190e6c3c404e54a7958e863d68d6a2.html
B11: 中华人民共和国工业和信息化部公告2021年 第30号
B12: 《国家工业和信息化领域节能技术装备推荐目录（2022年版）》（中华人民共和国工业和信息化部公告2022年第29号）
A14: Notes:

Sheet Sector & Policy Match
A1: 节能技术适用范围 | B1: EPS行业 | D1: 重点用能设备 | E1: 适用范围 | G1: 节能技术类型 | H1: EPS政策
A2: 煤炭开采 | B2: coal mining 05 | D2: 工业锅炉 | E2: 电力、热力生产 | G2: 流程工业节能 | H2: Early Facility Retirement
A3: 油气开采 | B3: oil and gas extraction 06 | D3: 工业锅炉 | E3: 石化 | G3: 重点用能设备及系统节能 | H3: Improvement in Eqpt Efficiency Standards
A4: 其他采矿 | B4: other mining and quarrying 07T08 | D4: 工业锅炉 | E4: 化工 | G4: 能源信息化 | H4: Installation and System Integration
A5: 食品 | B5: food beverage and tobacco 10T12 | D5: 工业锅炉 | E5: 钢铁 | G5: 可再生能源高效利用 | H5: Early Facility Retirement
A6: 造纸 | B6: pulp paper and printing 17T18 | D6: 工业锅炉 | E6: 纺织 | G6: 化石能源清洁高效利用 | H6: Early Facility Retirement
A7: 纺织 | B7: textiles apparel and leather 13T15 | D7: 工业锅炉 | E7: 造纸 | G7: 智慧能源管控系统 | H7: Installation and System Integration
A8: 建材 | B8: cement and other nonmetallic minerals 239 | D8: 工业锅炉 | E8: 食品 | G8: 余热余压利用 | H8: Cogeneration and Waste Heat Recovery
A9: 钢铁 | B9: iron and steel 241 | D9: 工业循环水 | E9: 石化
A10: 石化 | B10: refined petroleum and coke 19 | D10: 工业循环水 | E10: 化工
A11: 化工 | B11: chemicals 20 | D11: 工业循环水 | E11: 钢铁
A12: 有色金属 | B12: other metals 242 | D12: 工业循环水 | E12: 有色金属
A13: 汽车制造 | B13: road vehicles 29 | D13: 工业循环水 | E13: 造纸
A14: 非道路交通制造 | B14: nonroad vehicles 30 | D14: 工业循环水 | E14: 纺织
A15: 船舶 | B15: nonroad vehicles 30 | D15: 工业循环水 | E15: 食品
A16: 燃气生产和供应业 | B16: energy pipelines and gas processing 352T353 | D16: 微型燃气轮机 | E16: 非道路交通制造
A17: 废弃物处理 | B17: water and waste 36T39 | D17: 微型燃气轮机 | E17: 电力、热力生产
A18: 电气机械 | B18: appliances and electrical equipment 27 | D18: 压缩空气系统 | E18: 电力、热力生产
A19: 电子设备 | B19: computers and electronics 26 | D19: 压缩空气系统 | E19: 纺织
A20: 仪器仪表 | B20: computers and electronics 27 | D20: 压缩空气系统 | E20: 食品
... A42: 工业水泵 | B42: 工业水泵 | D42: 除尘器 | E42: 煤炭开采
D43: 除尘器 | E43: 钢铁
D44: 除尘器 | E44: 有色金属
D45: 除尘器 | E45: 石化
D46: 除尘器 | E46: 电力、热力生产
D47: 机械行业 | E47: 通用设备
D48: 机械行业 | E48: 专用设备
D49: 机械行业 | E49: 仪器仪表
D50: 机械行业 | E50: 电气机械
D51: 机械行业 | E51: 汽车制造
D52: 工业水泵 | E52: 农业
D53: 工业水泵 | E53: 煤炭开采
D54: 工业水泵 | E54: 油气开采
... D64: 冷却塔 | E64: 纺织

Sheet BIFUbC
A1: Unit:BTU | B1: 2019 | C1: 2020 | D1: 2021 | E1: 2022 | F1: 2023 | G1: 2024 | H1: 2025 | I1: 2026 | J1: 2027 | K1: 2028 | L1: 2029 | M1: 2030 | N1: 2031 | O1: 2032 | P1: 2033 | Q1: 2034 | R1: 2035 | S1: 2036 | T1: 2037 | U1: 2038 | V1: 2039 | W1: 2040 | X1: 2041 | Y1: 2042 | Z1: 2043 | AA1: 2044 | AB1: 2045 | AC1: 2046 | AD1: 2047 | AE1: 2048 | AF1: 2049 | AG1: 2050 | AH1: 2051 | AI1: 2052 | AJ1: 2053 | AK1: 2054 | AL1: 2055 | AM1: 2056 | AN1: 2057 | AO1: 2058 | AP1: 2059 | AQ1: 2060
A2: agriculture and forestry 01T03 | B2: ='[1]BIFUbC-coal'!B2+'[1]BIFUbC-LPG-propane-or-butane'!B2+'[1]BIFUbC-petroleum-diesel'!B2+'[1]BIFUbC-crude-oil'!B2+'[1]BIFUbC-heavy-or-residual-oil'!B2+'[1]BIFUbC-natural-gas'!B2+'[1]BIFUbC-electricity'!B2+'[1]BIFUbC-heat'!B2+'[1]BIFUbC-biomass'!B2+'[1]BIFUbC-hydrogen'!D2 -> 1.7092054e+15 | C2: ='[1]BIFUbC-coal'!C2+'[1]BIFUbC-LPG-propane-or-butane'!C2+'[1]BIFUbC-petroleum-diesel'!C2+'[1]BIFUbC-crude-oil'!C2+'[1]BIFUbC-heavy-or-residual-oil'!C2+'[1]BIFUbC-natural-gas'!C2+'[1]BIFUbC-electricity'!C2+'[1]BIFUbC-heat'!C2+'[1]BIFUbC-biomass'!C2+'[1]BIFUbC-hydrogen'!E2 -> 1.736652e+15 | D2: ='[1]BIFUbC-coal'!D2+'[1]BIFUbC-LPG-propane-or-butane'!D2+'[1]BIFUbC-petroleum-diesel'!D2+'[1]BIFUbC-crude-oil'!D2+'[1]BIFUbC-heavy-or-residual-oil'!D2+'[1]BIFUbC-natural-gas'!D2+'[1]BIFUbC-electricity'!D2+'[1]BIFUbC-heat'!D2+'[1]BIFUbC-biomass'!D2+'[1]BIFUbC-hydrogen'!F2 -> 1.7691173e+15 | E2: ='[1]BIFUbC-coal'!E2+'[1]BIFUbC-LPG-propane-or-butane'!E2+'[1]BIFUbC-petroleum-diesel'!E2+'[1]BIFUbC-crude-oil'!E2+'[1]BIFUbC-heavy-or-residual-oil'!E2+'[1]BIFUbC-natural-gas'!E2+'[1]BIFUbC-electricity'!E2+'[1]BIFUbC-heat'!E2+'[1]BIFUbC-biomass'!E2+'[1]BIFUbC-hydrogen'!G2 -> 1.8458256e+15 | F2: ='[1]BIFUbC-coal'!F2+'[1]BIFUbC-LPG-propane-or-butane'!F2+'[1]BIFUbC-petroleum-diesel'!F2+'[1]BIFUbC-crude-oil'!F2+'[1]BIFUbC-heavy-or-residual-oil'!F2+'[1]BIFUbC-natural-gas'!F2+'[1]BIFUbC-electricity'!F2+'[1]BIFUbC-heat'!F2+'[1]BIFUbC-biomass'!F2+'[1]BIFUbC-hydrogen'!H2 -> 1.9779481e+15 | G2: ='[1]BIFUbC-coal'!G2+'[1]BIFUbC-LPG-propane-or-butane'!G2+'[1]BIFUbC-petroleum-diesel'!G2+'[1]BIFUbC-crude-oil'!G2+'[1]BIFUbC-heavy-or-residual-oil'!G2+'[1]BIFUbC-natural-gas'!G2+'[1]BIFUbC-electricity'!G2+'[1]BIFUbC-heat'!G2+'[1]BIFUbC-biomass'!G2+'[1]BIFUbC-hydrogen'!I2 -> 2.0746055e+15 | H2: ='[1]BIFUbC-coal'!H2+'[1]BIFUbC-LPG-propane-or-butane'!H2+'[1]BIFUbC-petroleum-diesel'!H2+'[1]BIFUbC-crude-oil'!H2+'[1]BIFUbC-heavy-or-residual-oil'!H2+'[1]BIFUbC-natural-gas'!H2+'[1]BIFUbC-electricity'!H2+'[1]BIFUbC-heat'!H2+'[1]BIFUbC-biomass'!H2+'[1]BIFUbC-hydrogen'!J2 -> 2.1282554e+15 | I2: ='[1]BIFUbC-coal'!I2+'[1]BIFUbC-LPG-propane-or-butane'!I2+'[1]BIFUbC-petroleum-diesel'!I2+'[1]BIFUbC-crude-oil'!I2+'[1]BIFUbC-heavy-or-residual-oil'!I2+'[1]BIFUbC-natural-gas'!I2+'[1]BIFUbC-electricity'!I2+'[1]BIFUbC-heat'!I2+'[1]BIFUbC-biomass'!I2+'[1]BIFUbC-hydrogen'!K2 -> 2.2653655e+15 | ... AQ2: ='[1]BIFUbC-coal'!AQ2+'[1]BIFUbC-LPG-propane-or-butane'!AQ2+'[1]BIFUbC-petroleum-diesel'!AQ2+'[1]BIFUbC-crude-oil'!AQ2+'[1]BIFUbC-heavy-or-residual-oil'!AQ2+'[1]BIFUbC-natural-gas'!AQ2+'[1]BIFUbC-electricity'!AQ2+'[1]BIFUbC-heat'!AQ2+'[1]BIFUbC-biomass'!AQ2+'[1]BIFUbC-hydrogen'!AS2 -> 3.3698001e+15
A3: coal mining 05 | B3: ='[1]BIFUbC-coal'!B3+'[1]BIFUbC-LPG-propane-or-butane'!B3+'[1]BIFUbC-petroleum-diesel'!B3+'[1]BIFUbC-crude-oil'!B3+'[1]BIFUbC-heavy-or-residual-oil'!B3+'[1]BIFUbC-natural-gas'!B3+'[1]BIFUbC-electricity'!B3+'[1]BIFUbC-heat'!B3+'[1]BIFUbC-biomass'!B3+'[1]BIFUbC-hydrogen'!D3 -> 2.3308125e+15 | C3: ='[1]BIFUbC-coal'!C3+'[1]BIFUbC-LPG-propane-or-butane'!C3+'[1]BIFUbC-petroleum-diesel'!C3+'[1]BIFUbC-crude-oil'!C3+'[1]BIFUbC-heavy-or-residual-oil'!C3+'[1]BIFUbC-natural-gas'!C3+'[1]BIFUbC-electricity'!C3+'[1]BIFUbC-heat'!C3+'[1]BIFUbC-biomass'!C3+'[1]BIFUbC-hydrogen'!E3 -> 2.0884633e+15 | D3: ='[1]BIFUbC-coal'!D3+'[1]BIFUbC-LPG-propane-or-butane'!D3+'[1]BIFUbC-petroleum-diesel'!D3+'[1]BIFUbC-crude-oil'!D3+'[1]BIFUbC-heavy-or-residual-oil'!D3+'[1]BIFUbC-natural-gas'!D3+'[1]BIFUbC-electricity'!D3+'[1]BIFUbC-heat'!D3+'[1]BIFUbC-biomass'!D3+'[1]BIFUbC-hydrogen'!F3 -> 2.1917576e+15 | E3: ='[1]BIFUbC-coal'!E3+'[1]BIFUbC-LPG-propane-or-butane'!E3+'[1]BIFUbC-petroleum-diesel'!E3+'[1]BIFUbC-crude-oil'!E3+'[1]BIFUbC-heavy-or-residual-oil'!E3+'[1]BIFUbC-natural-gas'!E3+'[1]BIFUbC-electricity'!E3+'[1]BIFUbC-heat'!E3+'[1]BIFUbC-biomass'!E3+'[1]BIFUbC-hydrogen'!G3 -> 2.3644156e+15 | F3: ='[1]BIFUbC-coal'!F3+'[1]BIFUbC-LPG-propane-or-butane'!F3+'[1]BIFUbC-petroleum-diesel'!F3+'[1]BIFUbC-crude-oil'!F3+'[1]BIFUbC-heavy-or-residual-oil'!F3+'[1]BIFUbC-natural-gas'!F3+'[1]BIFUbC-electricity'!F3+'[1]BIFUbC-heat'!F3+'[1]BIFUbC-biomass'!F3+'[1]BIFUbC-hydrogen'!H3 -> 2.5413516e+15 | G3: ='[1]BIFUbC-coal'!G3+'[1]BIFUbC-LPG-propane-or-butane'!G3+'[1]BIFUbC-petroleum-diesel'!G3+'[1]BIFUbC-crude-oil'!G3+'[1]BIFUbC-heavy-or-residual-oil'!G3+'[1]BIFUbC-natural-gas'!G3+'[1]BIFUbC-electricity'!G3+'[1]BIFUbC-heat'!G3+'[1]BIFUbC-biomass'!G3+'[1]BIFUbC-hydrogen'!I3 -> 2.6718565e+15 | H3: ='[1]BIFUbC-coal'!H3+'[1]BIFUbC-LPG-propane-or-butane'!H3+'[1]BIFUbC-petroleum-diesel'!H3+'[1]BIFUbC-crude-oil'!H3+'[1]BIFUbC-heavy-or-residual-oil'!H3+'[1]BIFUbC-natural-gas'!H3+'[1]BIFUbC-electricity'!H3+'[1]BIFUbC-heat'!H3+'[1]BIFUbC-biomass'!H3+'[1]BIFUbC-hydrogen'!J3 -> 2.8021532e+15 | I3: ='[1]BIFUbC-coal'!I3+'[1]BIFUbC-LPG-propane-or-butane'!I3+'[1]BIFUbC-petroleum-diesel'!I3+'[1]BIFUbC-crude-oil'!I3+'[1]BIFUbC-heavy-or-residual-oil'!I3+'[1]BIFUbC-natural-gas'!I3+'[1]BIFUbC-electricity'!I3+'[1]BIFUbC-heat'!I3+'[1]BIFUbC-biomass'!I3+'[1]BIFUbC-hydrogen'!K3 -> 2.847561e+15 | ... AQ3: ='[1]BIFUbC-coal'!AQ3+'[1]BIFUbC-LPG-propane-or-butane'!AQ3+'[1]BIFUbC-petroleum-diesel'!AQ3+'[1]BIFUbC-crude-oil'!AQ3+'[1]BIFUbC-heavy-or-residual-oil'!AQ3+'[1]BIFUbC-natural-gas'!AQ3+'[1]BIFUbC-electricity'!AQ3+'[1]BIFUbC-heat'!AQ3+'[1]BIFUbC-biomass'!AQ3+'[1]BIFUbC-hydrogen'!AS3 -> 1.9979417e+15
A4: oil and gas extraction 06 | B4: ='[1]BIFUbC-coal'!B4+'[1]BIFUbC-LPG-propane-or-butane'!B4+'[1]BIFUbC-petroleum-diesel'!B4+'[1]BIFUbC-crude-oil'!B4+'[1]BIFUbC-heavy-or-residual-oil'!B4+'[1]BIFUbC-natural-gas'!B4+'[1]BIFUbC-electricity'!B4+'[1]BIFUbC-heat'!B4+'[1]BIFUbC-biomass'!B4+'[1]BIFUbC-hydrogen'!D4 -> 800257778884091 | C4: ='[1]BIFUbC-coal'!C4+'[1]BIFUbC-LPG-propane-or-butane'!C4+'[1]BIFUbC-petroleum-diesel'!C4+'[1]BIFUbC-crude-oil'!C4+'[1]BIFUbC-heavy-or-residual-oil'!C4+'[1]BIFUbC-natural-gas'!C4+'[1]BIFUbC-electricity'!C4+'[1]BIFUbC-heat'!C4+'[1]BIFUbC-biomass'!C4+'[1]BIFUbC-hydrogen'!E4 -> 7.6829851e+14 | D4: ='[1]BIFUbC-coal'!D4+'[1]BIFUbC-LPG-propane-or-butane'!D4+'[1]BIFUbC-petroleum-diesel'!D4+'[1]BIFUbC-crude-oil'!D4+'[1]BIFUbC-heavy-or-residual-oil'!D4+'[1]BIFUbC-natural-gas'!D4+'[1]BIFUbC-electricity'!D4+'[1]BIFUbC-heat'!D4+'[1]BIFUbC-biomass'!D4+'[1]BIFUbC-hydrogen'!F4 -> 8.1083431e+14 | E4: ='[1]BIFUbC-coal'!E4+'[1]BIFUbC-LPG-propane-or-butane'!E4+'[1]BIFUbC-petroleum-diesel'!E4+'[1]BIFUbC-crude-oil'!E4+'[1]BIFUbC-heavy-or-residual-oil'!E4+'[1]BIFUbC-natural-gas'!E4+'[1]BIFUbC-electricity'!E4+'[1]BIFUbC-heat'!E4+'[1]BIFUbC-biomass'!E4+'[1]BIFUbC-hydrogen'!G4 -> 8.8219109e+14 | F4: ='[1]BIFUbC-coal'!F4+'[1]BIFUbC-LPG-propane-or-butane'!F4+'[1]BIFUbC-petroleum-diesel'!F4+'[1]BIFUbC-crude-oil'!F4+'[1]BIFUbC-heavy-or-residual-oil'!F4+'[1]BIFUbC-natural-gas'!F4+'[1]BIFUbC-electricity'!F4+'[1]BIFUbC-heat'!F4+'[1]BIFUbC-biomass'!F4+'[1]BIFUbC-hydrogen'!H4 -> 9.6875596e+14 | G4: ='[1]BIFUbC-coal'!G4+'[1]BIFUbC-LPG-propane-or-butane'!G4+'[1]BIFUbC-petroleum-diesel'!G4+'[1]BIFUbC-crude-oil'!G4+'[1]BIFUbC-heavy-or-residual-oil'!G4+'[1]BIFUbC-natural-gas'!G4+'[1]BIFUbC-electricity'!G4+'[1]BIFUbC-heat'!G4+'[1]BIFUbC-biomass'!G4+'[1]BIFUbC-hydrogen'!I4 -> 1.0224203e+15 | H4: ='[1]BIFUbC-coal'!H4+'[1]BIFUbC-LPG-propane-or-butane'!H4+'[1]BIFUbC-petroleum-diesel'!H4+'[1]BIFUbC-crude-oil'!H4+'[1]BIFUbC-heavy-or-residual-oil'!H4+'[1]BIFUbC-natural-gas'!H4+'[1]BIFUbC-electricity'!H4+'[1]BIFUbC-heat'!H4+'[1]BIFUbC-biomass'!H4+'[1]BIFUbC-hydrogen'!J4 -> 1.0758661e+15 | I4: ='[1]BIFUbC-coal'!I4+'[1]BIFUbC-LPG-propane-or-butane'!I4+'[1]BIFUbC-petroleum-diesel'!I4+'[1]BIFUbC-crude-oil'!I4+'[1]BIFUbC-heavy-or-residual-oil'!I4+'[1]BIFUbC-natural-gas'!I4+'[1]BIFUbC-electricity'!I4+'[1]BIFUbC-heat'!I4+'[1]BIFUbC-biomass'!I4+'[1]BIFUbC-hydrogen'!K4 -> 1.1020124e+15 | ... AQ4: ='[1]BIFUbC-coal'!AQ4+'[1]BIFUbC-LPG-propane-or-butane'!AQ4+'[1]BIFUbC-petroleum-diesel'!AQ4+'[1]BIFUbC-crude-oil'!AQ4+'[1]BIFUbC-heavy-or-residual-oil'!AQ4+'[1]BIFUbC-natural-gas'!AQ4+'[1]BIFUbC-electricity'!AQ4+'[1]BIFUbC-heat'!AQ4+'[1]BIFUbC-biomass'!AQ4+'[1]BIFUbC-hydrogen'!AS4 -> 1.5031581e+15
A5: other mining and quarrying 07T08 | B5: ='[1]BIFUbC-coal'!B5+'[1]BIFUbC-LPG-propane-or-butane'!B5+'[1]BIFUbC-petroleum-diesel'!B5+'[1]BIFUbC-crude-oil'!B5+'[1]BIFUbC-heavy-or-residual-oil'!B5+'[1]BIFUbC-natural-gas'!B5+'[1]BIFUbC-electricity'!B5+'[1]BIFUbC-heat'!B5+'[1]BIFUbC-biomass'!B5+'[1]BIFUbC-hydrogen'!D5 -> 6.3951414e+14 | C5: ='[1]BIFUbC-coal'!C5+'[1]BIFUbC-LPG-propane-or-butane'!C5+'[1]BIFUbC-petroleum-diesel'!C5+'[1]BIFUbC-crude-oil'!C5+'[1]BIFUbC-heavy-or-residual-oil'!C5+'[1]BIFUbC-natural-gas'!C5+'[1]BIFUbC-electricity'!C5+'[1]BIFUbC-heat'!C5+'[1]BIFUbC-biomass'!C5+'[1]BIFUbC-hydrogen'!E5 -> 5.903518e+14 | D5: ='[1]BIFUbC-coal'!D5+'[1]BIFUbC-LPG-propane-or-butane'!D5+'[1]BIFUbC-petroleum-diesel'!D5+'[1]BIFUbC-crude-oil'!D5+'[1]BIFUbC-heavy-or-residual-oil'!D5+'[1]BIFUbC-natural-gas'!D5+'[1]BIFUbC-electricity'!D5+'[1]BIFUbC-heat'!D5+'[1]BIFUbC-biomass'!D5+'[1]BIFUbC-hydrogen'!F5 -> 6.1594592e+14 | E5: ='[1]BIFUbC-coal'!E5+'[1]BIFUbC-LPG-propane-or-butane'!E5+'[1]BIFUbC-petroleum-diesel'!E5+'[1]BIFUbC-crude-oil'!E5+'[1]BIFUbC-heavy-or-residual-oil'!E5+'[1]BIFUbC-natural-gas'!E5+'[1]BIFUbC-electricity'!E5+'[1]BIFUbC-heat'!E5+'[1]BIFUbC-biomass'!E5+'[1]BIFUbC-hydrogen'!G5 -> 658962917833617 | F5: ='[1]BIFUbC-coal'!F5+'[1]BIFUbC-LPG-propane-or-butane'!F5+'[1]BIFUbC-petroleum-diesel'!F5+'[1]BIFUbC-crude-oil'!F5+'[1]BIFUbC-heavy-or-residual-oil'!F5+'[1]BIFUbC-natural-gas'!F5+'[1]BIFUbC-electricity'!F5+'[1]BIFUbC-heat'!F5+'[1]BIFUbC-biomass'!F5+'[1]BIFUbC-hydrogen'!H5 -> 7.1434944e+14 | G5: ='[1]BIFUbC-coal'!G5+'[1]BIFUbC-LPG-propane-or-butane'!G5+'[1]BIFUbC-petroleum-diesel'!G5+'[1]BIFUbC-crude-oil'!G5+'[1]BIFUbC-heavy-or-residual-oil'!G5+'[1]BIFUbC-natural-gas'!G5+'[1]BIFUbC-electricity'!G5+'[1]BIFUbC-heat'!G5+'[1]BIFUbC-biomass'!G5+'[1]BIFUbC-hydrogen'!I5 -> 7.4645974e+14 | H5: ='[1]BIFUbC-coal'!H5+'[1]BIFUbC-LPG-propane-or-butane'!H5+'[1]BIFUbC-petroleum-diesel'!H5+'[1]BIFUbC-crude-oil'!H5+'[1]BIFUbC-heavy-or-residual-oil'!H5+'[1]BIFUbC-natural-gas'!H5+'[1]BIFUbC-electricity'!H5+'[1]BIFUbC-heat'!H5+'[1]BIFUbC-biomass'!H5+'[1]BIFUbC-hydrogen'!J5 -> 7.7843874e+14 | I5: ='[1]BIFUbC-coal'!I5+'[1]BIFUbC-LPG-propane-or-butane'!I5+'[1]BIFUbC-petroleum-diesel'!I5+'[1]BIFUbC-crude-oil'!I5+'[1]BIFUbC-heavy-or-residual-oil'!I5+'[1]BIFUbC-natural-gas'!I5+'[1]BIFUbC-electricity'!I5+'[1]BIFUbC-heat'!I5+'[1]BIFUbC-biomass'!I5+'[1]BIFUbC-hydrogen'!K5 -> 7.9893676e+14 | ... AQ5: ='[1]BIFUbC-coal'!AQ5+'[1]BIFUbC-LPG-propane-or-butane'!AQ5+'[1]BIFUbC-petroleum-diesel'!AQ5+'[1]BIFUbC-crude-oil'!AQ5+'[1]BIFUbC-heavy-or-residual-oil'!AQ5+'[1]BIFUbC-natural-gas'!AQ5+'[1]BIFUbC-electricity'!AQ5+'[1]BIFUbC-heat'!AQ5+'[1]BIFUbC-biomass'!AQ5+'[1]BIFUbC-hydrogen'!AS5 -> 5.4733883e+14
A6: food beverage and tobacco 10T12 | B6: ='[1]BIFUbC-coal'!B6+'[1]BIFUbC-LPG-propane-or-butane'!B6+'[1]BIFUbC-petroleum-diesel'!B6+'[1]BIFUbC-crude-oil'!B6+'[1]BIFUbC-heavy-or-residual-oil'!B6+'[1]BIFUbC-natural-gas'!B6+'[1]BIFUbC-electricity'!B6+'[1]BIFUbC-heat'!B6+'[1]BIFUbC-biomass'!B6+'[1]BIFUbC-hydrogen'!D6 -> 1.4221279e+15 | C6: ='[1]BIFUbC-coal'!C6+'[1]BIFUbC-LPG-propane-or-butane'!C6+'[1]BIFUbC-petroleum-diesel'!C6+'[1]BIFUbC-crude-oil'!C6+'[1]BIFUbC-heavy-or-residual-oil'!C6+'[1]BIFUbC-natural-gas'!C6+'[1]BIFUbC-electricity'!C6+'[1]BIFUbC-heat'!C6+'[1]BIFUbC-biomass'!C6+'[1]BIFUbC-hydrogen'!E6 -> 1.3332016e+15 | D6: ='[1]BIFUbC-coal'!D6+'[1]BIFUbC-LPG-propane-or-butane'!D6+'[1]BIFUbC-petroleum-diesel'!D6+'[1]BIFUbC-crude-oil'!D6+'[1]BIFUbC-heavy-or-residual-oil'!D6+'[1]BIFUbC-natural-gas'!D6+'[1]BIFUbC-electricity'!D6+'[1]BIFUbC-heat'!D6+'[1]BIFUbC-biomass'!D6+'[1]BIFUbC-hydrogen'!F6 -> 1.5018553e+15 | E6: ='[1]BIFUbC-coal'!E6+'[1]BIFUbC-LPG-propane-or-butane'!E6+'[1]BIFUbC-petroleum-diesel'!E6+'[1]BIFUbC-crude-oil'!E6+'[1]BIFUbC-heavy-or-residual-oil'!E6+'[1]BIFUbC-natural-gas'!E6+'[1]BIFUbC-electricity'!E6+'[1]BIFUbC-heat'!E6+'[1]BIFUbC-biomass'!E6+'[1]BIFUbC-hydrogen'!G6 -> 1.5609278e+15 | F6: ='[1]BIFUbC-coal'!F6+'[1]BIFUbC-LPG-propane-or-butane'!F6+'[1]BIFUbC-petroleum-diesel'!F6+'[1]BIFUbC-crude-oil'!F6+'[1]BIFUbC-heavy-or-residual-oil'!F6+'[1]BIFUbC-natural-gas'!F6+'[1]BIFUbC-electricity'!F6+'[1]BIFUbC-heat'!F6+'[1]BIFUbC-biomass'!F6+'[1]BIFUbC-hydrogen'!H6 -> 1.6168956e+15 | G6: ='[1]BIFUbC-coal'!G6+'[1]BIFUbC-LPG-propane-or-butane'!G6+'[1]BIFUbC-petroleum-diesel'!G6+'[1]BIFUbC-crude-oil'!G6+'[1]BIFUbC-heavy-or-residual-oil'!G6+'[1]BIFUbC-natural-gas'!G6+'[1]BIFUbC-electricity'!G6+'[1]BIFUbC-heat'!G6+'[1]BIFUbC-biomass'!G6+'[1]BIFUbC-hydrogen'!I6 -> 1.6574126e+15 | H6: ='[1]BIFUbC-coal'!H6+'[1]BIFUbC-LPG-propane-or-butane'!H6+'[1]BIFUbC-petroleum-diesel'!H6+'[1]BIFUbC-crude-oil'!H6+'[1]BIFUbC-heavy-or-residual-oil'!H6+'[1]BIFUbC-natural-gas'!H6+'[1]BIFUbC-electricity'!H6+'[1]BIFUbC-heat'!H6+'[1]BIFUbC-biomass'!H6+'[1]BIFUbC-hydrogen'!J6 -> 1.7123956e+15 | I6: ='[1]BIFUbC-coal'!I6+'[1]BIFUbC-LPG-propane-or-butane'!I6+'[1]BIFUbC-petroleum-diesel'!I6+'[1]BIFUbC-crude-oil'!I6+'[1]BIFUbC-heavy-or-residual-oil'!I6+'[1]BIFUbC-natural-gas'!I6+'[1]BIFUbC-electricity'!I6+'[1]BIFUbC-heat'!I6+'[1]BIFUbC-biomass'!I6+'[1]BIFUbC-hydrogen'!K6 -> 1.7737552e+15 | ... AQ6: ='[1]BIFUbC-coal'!AQ6+'[1]BIFUbC-LPG-propane-or-butane'!AQ6+'[1]BIFUbC-petroleum-diesel'!AQ6+'[1]BIFUbC-crude-oil'!AQ6+'[1]BIFUbC-heavy-or-residual-oil'!AQ6+'[1]BIFUbC-natural-gas'!AQ6+'[1]BIFUbC-electricity'!AQ6+'[1]BIFUbC-heat'!AQ6+'[1]BIFUbC-biomass'!AQ6+'[1]BIFUbC-hydrogen'!AS6 -> 2.0954223e+15
A7: textiles apparel and leather 13T15 | B7: ='[1]BIFUbC-coal'!B7+'[1]BIFUbC-LPG-propane-or-butane'!B7+'[1]BIFUbC-petroleum-diesel'!B7+'[1]BIFUbC-crude-oil'!B7+'[1]BIFUbC-heavy-or-residual-oil'!B7+'[1]BIFUbC-natural-gas'!B7+'[1]BIFUbC-electricity'!B7+'[1]BIFUbC-heat'!B7+'[1]BIFUbC-biomass'!B7+'[1]BIFUbC-hydrogen'!D7 -> 1.4079388e+15 | C7: ='[1]BIFUbC-coal'!C7+'[1]BIFUbC-LPG-propane-or-butane'!C7+'[1]BIFUbC-petroleum-diesel'!C7+'[1]BIFUbC-crude-oil'!C7+'[1]BIFUbC-heavy-or-residual-oil'!C7+'[1]BIFUbC-natural-gas'!C7+'[1]BIFUbC-electricity'!C7+'[1]BIFUbC-heat'!C7+'[1]BIFUbC-biomass'!C7+'[1]BIFUbC-hydrogen'!E7 -> 1.3389501e+15 | D7: ='[1]BIFUbC-coal'!D7+'[1]BIFUbC-LPG-propane-or-butane'!D7+'[1]BIFUbC-petroleum-diesel'!D7+'[1]BIFUbC-crude-oil'!D7+'[1]BIFUbC-heavy-or-residual-oil'!D7+'[1]BIFUbC-natural-gas'!D7+'[1]BIFUbC-electricity'!D7+'[1]BIFUbC-heat'!D7+'[1]BIFUbC-biomass'!D7+'[1]BIFUbC-hydrogen'!F7 -> 1.4315709e+15 | E7: ='[1]BIFUbC-coal'!E7+'[1]BIFUbC-LPG-propane-or-butane'!E7+'[1]BIFUbC-petroleum-diesel'!E7+'[1]BIFUbC-crude-oil'!E7+'[1]BIFUbC-heavy-or-residual-oil'!E7+'[1]BIFUbC-natural-gas'!E7+'[1]BIFUbC-electricity'!E7+'[1]BIFUbC-heat'!E7+'[1]BIFUbC-biomass'!E7+'[1]BIFUbC-hydrogen'!G7 -> 1.4184904e+15 | F7: ='[1]BIFUbC-coal'!F7+'[1]BIFUbC-LPG-propane-or-butane'!F7+'[1]BIFUbC-petroleum-diesel'!F7+'[1]BIFUbC-crude-oil'!F7+'[1]BIFUbC-heavy-or-residual-oil'!F7+'[1]BIFUbC-natural-gas'!F7+'[1]BIFUbC-electricity'!F7+'[1]BIFUbC-heat'!F7+'[1]BIFUbC-biomass'!F7+'[1]BIFUbC-hydrogen'!H7 -> 1.4599344e+15 | G7: ='[1]BIFUbC-coal'!G7+'[1]BIFUbC-LPG-propane-or-butane'!G7+'[1]BIFUbC-petroleum-diesel'!G7+'[1]BIFUbC-crude-oil'!G7+'[1]BIFUbC-heavy-or-residual-oil'!G7+'[1]BIFUbC-natural-gas'!G7+'[1]BIFUbC-electricity'!G7+'[1]BIFUbC-heat'!G7+'[1]BIFUbC-biomass'!G7+'[1]BIFUbC-hydrogen'!I7 -> 1.4722207e+15 | H7: ='[1]BIFUbC-coal'!H7+'[1]BIFUbC-LPG-propane-or-butane'!H7+'[1]BIFUbC-petroleum-diesel'!H7+'[1]BIFUbC-crude-oil'!H7+'[1]BIFUbC-heavy-or-residual-oil'!H7+'[1]BIFUbC-natural-gas'!H7+'[1]BIFUbC-electricity'!H7+'[1]BIFUbC-heat'!H7+'[1]BIFUbC-biomass'!H7+'[1]BIFUbC-hydrogen'!J7 -> 1.4896157e+15 | I7: ='[1]BIFUbC-coal'!I7+'[1]BIFUbC-LPG-propane-or-butane'!I7+'[1]BIFUbC-petroleum-diesel'!I7+'[1]BIFUbC-crude-oil'!I7+'[1]BIFUbC-heavy-or-residual-oil'!I7+'[1]BIFUbC-natural-gas'!I7+'[1]BIFUbC-electricity'!I7+'[1]BIFUbC-heat'!I7+'[1]BIFUbC-biomass'!I7+'[1]BIFUbC-hydrogen'!K7 -> 1.5108502e+15 | ... AQ7: ='[1]BIFUbC-coal'!AQ7+'[1]BIFUbC-LPG-propane-or-butane'!AQ7+'[1]BIFUbC-petroleum-diesel'!AQ7+'[1]BIFUbC-crude-oil'!AQ7+'[1]BIFUbC-heavy-or-residual-oil'!AQ7+'[1]BIFUbC-natural-gas'!AQ7+'[1]BIFUbC-electricity'!AQ7+'[1]BIFUbC-heat'!AQ7+'[1]BIFUbC-biomass'!AQ7+'[1]BIFUbC-hydrogen'!AS7 -> 1.2168061e+15
A8: wood products 16 | B8: ='[1]BIFUbC-coal'!B8+'[1]BIFUbC-LPG-propane-or-butane'!B8+'[1]BIFUbC-petroleum-diesel'!B8+'[1]BIFUbC-crude-oil'!B8+'[1]BIFUbC-heavy-or-residual-oil'!B8+'[1]BIFUbC-natural-gas'!B8+'[1]BIFUbC-electricity'!B8+'[1]BIFUbC-heat'!B8+'[1]BIFUbC-biomass'!B8+'[1]BIFUbC-hydrogen'!D8 -> 2.4337882e+14 | C8: ='[1]BIFUbC-coal'!C8+'[1]BIFUbC-LPG-propane-or-butane'!C8+'[1]BIFUbC-petroleum-diesel'!C8+'[1]BIFUbC-crude-oil'!C8+'[1]BIFUbC-heavy-or-residual-oil'!C8+'[1]BIFUbC-natural-gas'!C8+'[1]BIFUbC-electricity'!C8+'[1]BIFUbC-heat'!C8+'[1]BIFUbC-biomass'!C8+'[1]BIFUbC-hydrogen'!E8 -> 2.3764655e+14 | D8: ='[1]BIFUbC-coal'!D8+'[1]BIFUbC-LPG-propane-or-butane'!D8+'[1]BIFUbC-petroleum-diesel'!D8+'[1]BIFUbC-crude-oil'!D8+'[1]BIFUbC-heavy-or-residual-oil'!D8+'[1]BIFUbC-natural-gas'!D8+'[1]BIFUbC-electricity'!D8+'[1]BIFUbC-heat'!D8+'[1]BIFUbC-biomass'!D8+'[1]BIFUbC-hydrogen'!F8 -> 2.7428264e+14 | E8: ='[1]BIFUbC-coal'!E8+'[1]BIFUbC-LPG-propane-or-butane'!E8+'[1]BIFUbC-petroleum-diesel'!E8+'[1]BIFUbC-crude-oil'!E8+'[1]BIFUbC-heavy-or-residual-oil'!E8+'[1]BIFUbC-natural-gas'!E8+'[1]BIFUbC-electricity'!E8+'[1]BIFUbC-heat'!E8+'[1]BIFUbC-biomass'!E8+'[1]BIFUbC-hydrogen'!G8 -> 2.7226809e+14 | F8: ='[1]BIFUbC-coal'!F8+'[1]BIFUbC-LPG-propane-or-butane'!F8+'[1]BIFUbC-petroleum-diesel'!F8+'[1]BIFUbC-crude-oil'!F8+'[1]BIFUbC-heavy-or-residual-oil'!F8+'[1]BIFUbC-natural-gas'!F8+'[1]BIFUbC-electricity'!F8+'[1]BIFUbC-heat'!F8+'[1]BIFUbC-biomass'!F8+'[1]BIFUbC-hydrogen'!H8 -> 2.8042507e+14 | G8: ='[1]BIFUbC-coal'!G8+'[1]BIFUbC-LPG-propane-or-butane'!G8+'[1]BIFUbC-petroleum-diesel'!G8+'[1]BIFUbC-crude-oil'!G8+'[1]BIFUbC-heavy-or-residual-oil'!G8+'[1]BIFUbC-natural-gas'!G8+'[1]BIFUbC-electricity'!G8+'[1]BIFUbC-heat'!G8+'[1]BIFUbC-biomass'!G8+'[1]BIFUbC-hydrogen'!I8 -> 2.8350181e+14 | H8: ='[1]BIFUbC-coal'!H8+'[1]BIFUbC-LPG-propane-or-butane'!H8+'[1]BIFUbC-petroleum-diesel'!H8+'[1]BIFUbC-crude-oil'!H8+'[1]BIFUbC-heavy-or-residual-oil'!H8+'[1]BIFUbC-natural-gas'!H8+'[1]BIFUbC-electricity'!H8+'[1]BIFUbC-heat'!H8+'[1]BIFUbC-biomass'!H8+'[1]BIFUbC-hydrogen'!J8 -> 288152732002939 | I8: ='[1]BIFUbC-coal'!I8+'[1]BIFUbC-LPG-propane-or-butane'!I8+'[1]BIFUbC-petroleum-diesel'!I8+'[1]BIFUbC-crude-oil'!I8+'[1]BIFUbC-heavy-or-residual-oil'!I8+'[1]BIFUbC-natural-gas'!I8+'[1]BIFUbC-electricity'!I8+'[1]BIFUbC-heat'!I8+'[1]BIFUbC-biomass'!I8+'[1]BIFUbC-hydrogen'!K8 -> 2.9423729e+14 | ... AQ8: ='[1]BIFUbC-coal'!AQ8+'[1]BIFUbC-LPG-propane-or-butane'!AQ8+'[1]BIFUbC-petroleum-diesel'!AQ8+'[1]BIFUbC-crude-oil'!AQ8+'[1]BIFUbC-heavy-or-residual-oil'!AQ8+'[1]BIFUbC-natural-gas'!AQ8+'[1]BIFUbC-electricity'!AQ8+'[1]BIFUbC-heat'!AQ8+'[1]BIFUbC-biomass'!AQ8+'[1]BIFUbC-hydrogen'!AS8 -> 2.5806836e+14
A9: pulp paper and printing 17T18 | B9: ='[1]BIFUbC-coal'!B9+'[1]BIFUbC-LPG-propane-or-butane'!B9+'[1]BIFUbC-petroleum-diesel'!B9+'[1]BIFUbC-crude-oil'!B9+'[1]BIFUbC-heavy-or-residual-oil'!B9+'[1]BIFUbC-natural-gas'!B9+'[1]BIFUbC-electricity'!B9+'[1]BIFUbC-heat'!B9+'[1]BIFUbC-biomass'!B9+'[1]BIFUbC-hydrogen'!D9 -> 8.9160106e+14 | C9: ='[1]BIFUbC-coal'!C9+'[1]BIFUbC-LPG-propane-or-butane'!C9+'[1]BIFUbC-petroleum-diesel'!C9+'[1]BIFUbC-crude-oil'!C9+'[1]BIFUbC-heavy-or-residual-oil'!C9+'[1]BIFUbC-natural-gas'!C9+'[1]BIFUbC-electricity'!C9+'[1]BIFUbC-heat'!C9+'[1]BIFUbC-biomass'!C9+'[1]BIFUbC-hydrogen'!E9 -> 883986747789292 | D9: ='[1]BIFUbC-coal'!D9+'[1]BIFUbC-LPG-propane-or-butane'!D9+'[1]BIFUbC-petroleum-diesel'!D9+'[1]BIFUbC-crude-oil'!D9+'[1]BIFUbC-heavy-or-residual-oil'!D9+'[1]BIFUbC-natural-gas'!D9+'[1]BIFUbC-electricity'!D9+'[1]BIFUbC-heat'!D9+'[1]BIFUbC-biomass'!D9+'[1]BIFUbC-hydrogen'!F9 -> 9.5346821e+14 | E9: ='[1]BIFUbC-coal'!E9+'[1]BIFUbC-LPG-propane-or-butane'!E9+'[1]BIFUbC-petroleum-diesel'!E9+'[1]BIFUbC-crude-oil'!E9+'[1]BIFUbC-heavy-or-residual-oil'!E9+'[1]BIFUbC-natural-gas'!E9+'[1]BIFUbC-electricity'!E9+'[1]BIFUbC-heat'!E9+'[1]BIFUbC-biomass'!E9+'[1]BIFUbC-hydrogen'!G9 -> 1.0112595e+15 | F9: ='[1]BIFUbC-coal'!F9+'[1]BIFUbC-LPG-propane-or-butane'!F9+'[1]BIFUbC-petroleum-diesel'!F9+'[1]BIFUbC-crude-oil'!F9+'[1]BIFUbC-heavy-or-residual-oil'!F9+'[1]BIFUbC-natural-gas'!F9+'[1]BIFUbC-electricity'!F9+'[1]BIFUbC-heat'!F9+'[1]BIFUbC-biomass'!F9+'[1]BIFUbC-hydrogen'!H9 -> 1.0909293e+15 | G9: ='[1]BIFUbC-coal'!G9+'[1]BIFUbC-LPG-propane-or-butane'!G9+'[1]BIFUbC-petroleum-diesel'!G9+'[1]BIFUbC-crude-oil'!G9+'[1]BIFUbC-heavy-or-residual-oil'!G9+'[1]BIFUbC-natural-gas'!G9+'[1]BIFUbC-electricity'!G9+'[1]BIFUbC-heat'!G9+'[1]BIFUbC-biomass'!G9+'[1]BIFUbC-hydrogen'!I9 -> 1.1394085e+15 | H9: ='[1]BIFUbC-coal'!H9+'[1]BIFUbC-LPG-propane-or-butane'!H9+'[1]BIFUbC-petroleum-diesel'!H9+'[1]BIFUbC-crude-oil'!H9+'[1]BIFUbC-heavy-or-residual-oil'!H9+'[1]BIFUbC-natural-gas'!H9+'[1]BIFUbC-electricity'!H9+'[1]BIFUbC-heat'!H9+'[1]BIFUbC-biomass'!H9+'[1]BIFUbC-hydrogen'!J9 -> 1.1896401e+15 | I9: ='[1]BIFUbC-coal'!I9+'[1]BIFUbC-LPG-propane-or-butane'!I9+'[1]BIFUbC-petroleum-diesel'!I9+'[1]BIFUbC-crude-oil'!I9+'[1]BIFUbC-heavy-or-residual-oil'!I9+'[1]BIFUbC-natural-gas'!I9+'[1]BIFUbC-electricity'!I9+'[1]BIFUbC-heat'!I9+'[1]BIFUbC-biomass'!I9+'[1]BIFUbC-hydrogen'!K9 -> 1.2210021e+15 | ... AQ9: ='[1]BIFUbC-coal'!AQ9+'[1]BIFUbC-LPG-propane-or-butane'!AQ9+'[1]BIFUbC-petroleum-diesel'!AQ9+'[1]BIFUbC-crude-oil'!AQ9+'[1]BIFUbC-heavy-or-residual-oil'!AQ9+'[1]BIFUbC-natural-gas'!AQ9+'[1]BIFUbC-electricity'!AQ9+'[1]BIFUbC-heat'!AQ9+'[1]BIFUbC-biomass'!AQ9+'[1]BIFUbC-hydrogen'!AS9 -> 1.1617261e+15
A10: refined petroleum and coke 19 | B10: ='[1]BIFUbC-coal'!B10+'[1]BIFUbC-LPG-propane-or-butane'!B10+'[1]BIFUbC-petroleum-diesel'!B10+'[1]BIFUbC-crude-oil'!B10+'[1]BIFUbC-heavy-or-residual-oil'!B10+'[1]BIFUbC-natural-gas'!B10+'[1]BIFUbC-electricity'!B10+'[1]BIFUbC-heat'!B10+'[1]BIFUbC-biomass'!B10+'[1]BIFUbC-hydrogen'!D10 -> 4.1539861e+16 | C10: ='[1]BIFUbC-coal'!C10+'[1]BIFUbC-LPG-propane-or-butane'!C10+'[1]BIFUbC-petroleum-diesel'!C10+'[1]BIFUbC-crude-oil'!C10+'[1]BIFUbC-heavy-or-residual-oil'!C10+'[1]BIFUbC-natural-gas'!C10+'[1]BIFUbC-electricity'!C10+'[1]BIFUbC-heat'!C10+'[1]BIFUbC-biomass'!C10+'[1]BIFUbC-hydrogen'!E10 -> 4.3980181e+16 | D10: ='[1]BIFUbC-coal'!D10+'[1]BIFUbC-LPG-propane-or-butane'!D10+'[1]BIFUbC-petroleum-diesel'!D10+'[1]BIFUbC-crude-oil'!D10+'[1]BIFUbC-heavy-or-residual-oil'!D10+'[1]BIFUbC-natural-gas'!D10+'[1]BIFUbC-electricity'!D10+'[1]BIFUbC-heat'!D10+'[1]BIFUbC-biomass'!D10+'[1]BIFUbC-hydrogen'!F10 -> 4.6070175e+16 | E10: ='[1]BIFUbC-coal'!E10+'[1]BIFUbC-LPG-propane-or-butane'!E10+'[1]BIFUbC-petroleum-diesel'!E10+'[1]BIFUbC-crude-oil'!E10+'[1]BIFUbC-heavy-or-residual-oil'!E10+'[1]BIFUbC-natural-gas'!E10+'[1]BIFUbC-electricity'!E10+'[1]BIFUbC-heat'!E10+'[1]BIFUbC-biomass'!E10+'[1]BIFUbC-hydrogen'!G10 -> 4.9137752e+16 | F10: ='[1]BIFUbC-coal'!F10+'[1]BIFUbC-LPG-propane-or-butane'!F10+'[1]BIFUbC-petroleum-diesel'!F10+'[1]BIFUbC-crude-oil'!F10+'[1]BIFUbC-heavy-or-residual-oil'!F10+'[1]BIFUbC-natural-gas'!F10+'[1]BIFUbC-electricity'!F10+'[1]BIFUbC-heat'!F10+'[1]BIFUbC-biomass'!F10+'[1]BIFUbC-hydrogen'!H10 -> 5.2337276e+16 | G10: ='[1]BIFUbC-coal'!G10+'[1]BIFUbC-LPG-propane-or-butane'!G10+'[1]BIFUbC-petroleum-diesel'!G10+'[1]BIFUbC-crude-oil'!G10+'[1]BIFUbC-heavy-or-residual-oil'!G10+'[1]BIFUbC-natural-gas'!G10+'[1]BIFUbC-electricity'!G10+'[1]BIFUbC-heat'!G10+'[1]BIFUbC-biomass'!G10+'[1]BIFUbC-hydrogen'!I10 -> 5.5192407e+16 | H10: ='[1]BIFUbC-coal'!H10+'[1]BIFUbC-LPG-propane-or-butane'!H10+'[1]BIFUbC-petroleum-diesel'!H10+'[1]BIFUbC-crude-oil'!H10+'[1]BIFUbC-heavy-or-residual-oil'!H10+'[1]BIFUbC-natural-gas'!H10+'[1]BIFUbC-electricity'!H10+'[1]BIFUbC-heat'!H10+'[1]BIFUbC-biomass'!H10+'[1]BIFUbC-hydrogen'!J10 -> 5.8046384e+16 | I10: ='[1]BIFUbC-coal'!I10+'[1]BIFUbC-LPG-propane-or-butane'!I10+'[1]BIFUbC-petroleum-diesel'!I10+'[1]BIFUbC-crude-oil'!I10+'[1]BIFUbC-heavy-or-residual-oil'!I10+'[1]BIFUbC-natural-gas'!I10+'[1]BIFUbC-electricity'!I10+'[1]BIFUbC-heat'!I10+'[1]BIFUbC-biomass'!I10+'[1]BIFUbC-hydrogen'!K10 -> 5.9334474e+16 | ... AQ10: ='[1]BIFUbC-coal'!AQ10+'[1]BIFUbC-LPG-propane-or-butane'!AQ10+'[1]BIFUbC-petroleum-diesel'!AQ10+'[1]BIFUbC-crude-oil'!AQ10+'[1]BIFUbC-heavy-or-residual-oil'!AQ10+'[1]BIFUbC-natural-gas'!AQ10+'[1]BIFUbC-electricity'!AQ10+'[1]BIFUbC-heat'!AQ10+'[1]BIFUbC-biomass'!AQ10+'[1]BIFUbC-hydrogen'!AS10 -> 3.5155883e+16
A11: chemicals 20 | B11: ='[1]BIFUbC-coal'!B11+'[1]BIFUbC-LPG-propane-or-butane'!B11+'[1]BIFUbC-petroleum-diesel'!B11+'[1]BIFUbC-crude-oil'!B11+'[1]BIFUbC-heavy-or-residual-oil'!B11+'[1]BIFUbC-natural-gas'!B11+'[1]BIFUbC-electricity'!B11+'[1]BIFUbC-heat'!B11+'[1]BIFUbC-biomass'!B11+'[1]BIFUbC-hydrogen'!D11 -> 1.1736426e+16 | C11: ='[1]BIFUbC-coal'!C11+'[1]BIFUbC-LPG-propane-or-butane'!C11+'[1]BIFUbC-petroleum-diesel'!C11+'[1]BIFUbC-crude-oil'!C11+'[1]BIFUbC-heavy-or-residual-oil'!C11+'[1]BIFUbC-natural-gas'!C11+'[1]BIFUbC-electricity'!C11+'[1]BIFUbC-heat'!C11+'[1]BIFUbC-biomass'!C11+'[1]BIFUbC-hydrogen'!E11 -> 1.253828e+16 | D11: ='[1]BIFUbC-coal'!D11+'[1]BIFUbC-LPG-propane-or-butane'!D11+'[1]BIFUbC-petroleum-diesel'!D11+'[1]BIFUbC-crude-oil'!D11+'[1]BIFUbC-heavy-or-residual-oil'!D11+'[1]BIFUbC-natural-gas'!D11+'[1]BIFUbC-electricity'!D11+'[1]BIFUbC-heat'!D11+'[1]BIFUbC-biomass'!D11+'[1]BIFUbC-hydrogen'!F11 -> 1.3367227e+16 | E11: ='[1]BIFUbC-coal'!E11+'[1]BIFUbC-LPG-propane-or-butane'!E11+'[1]BIFUbC-petroleum-diesel'!E11+'[1]BIFUbC-crude-oil'!E11+'[1]BIFUbC-heavy-or-residual-oil'!E11+'[1]BIFUbC-natural-gas'!E11+'[1]BIFUbC-electricity'!E11+'[1]BIFUbC-heat'!E11+'[1]BIFUbC-biomass'!E11+'[1]BIFUbC-hydrogen'!G11 -> 1.4685287e+16 | F11: ='[1]BIFUbC-coal'!F11+'[1]BIFUbC-LPG-propane-or-butane'!F11+'[1]BIFUbC-petroleum-diesel'!F11+'[1]BIFUbC-crude-oil'!F11+'[1]BIFUbC-heavy-or-residual-oil'!F11+'[1]BIFUbC-natural-gas'!F11+'[1]BIFUbC-electricity'!F11+'[1]BIFUbC-heat'!F11+'[1]BIFUbC-biomass'!F11+'[1]BIFUbC-hydrogen'!H11 -> 1.6101704e+16 | G11: ='[1]BIFUbC-coal'!G11+'[1]BIFUbC-LPG-propane-or-butane'!G11+'[1]BIFUbC-petroleum-diesel'!G11+'[1]BIFUbC-crude-oil'!G11+'[1]BIFUbC-heavy-or-residual-oil'!G11+'[1]BIFUbC-natural-gas'!G11+'[1]BIFUbC-electricity'!G11+'[1]BIFUbC-heat'!G11+'[1]BIFUbC-biomass'!G11+'[1]BIFUbC-hydrogen'!I11 -> 1.7118185e+16 | H11: ='[1]BIFUbC-coal'!H11+'[1]BIFUbC-LPG-propane-or-butane'!H11+'[1]BIFUbC-petroleum-diesel'!H11+'[1]BIFUbC-crude-oil'!H11+'[1]BIFUbC-heavy-or-residual-oil'!H11+'[1]BIFUbC-natural-gas'!H11+'[1]BIFUbC-electricity'!H11+'[1]BIFUbC-heat'!H11+'[1]BIFUbC-biomass'!H11+'[1]BIFUbC-hydrogen'!J11 -> 1.813956e+16 | I11: ='[1]BIFUbC-coal'!I11+'[1]BIFUbC-LPG-propane-or-butane'!I11+'[1]BIFUbC-petroleum-diesel'!I11+'[1]BIFUbC-crude-oil'!I11+'[1]BIFUbC-heavy-or-residual-oil'!I11+'[1]BIFUbC-natural-gas'!I11+'[1]BIFUbC-electricity'!I11+'[1]BIFUbC-heat'!I11+'[1]BIFUbC-biomass'!I11+'[1]BIFUbC-hydrogen'!K11 -> 1.8810302e+16 | ... AQ11: ='[1]BIFUbC-coal'!AQ11+'[1]BIFUbC-LPG-propane-or-butane'!AQ11+'[1]BIFUbC-petroleum-diesel'!AQ11+'[1]BIFUbC-crude-oil'!AQ11+'[1]BIFUbC-heavy-or-residual-oil'!AQ11+'[1]BIFUbC-natural-gas'!AQ11+'[1]BIFUbC-electricity'!AQ11+'[1]BIFUbC-heat'!AQ11+'[1]BIFUbC-biomass'!AQ11+'[1]BIFUbC-hydrogen'!AS11 -> 2.3735712e+16
A12: rubber and plastic products 22 | B12: ='[1]BIFUbC-coal'!B12+'[1]BIFUbC-LPG-propane-or-butane'!B12+'[1]BIFUbC-petroleum-diesel'!B12+'[1]BIFUbC-crude-oil'!B12+'[1]BIFUbC-heavy-or-residual-oil'!B12+'[1]BIFUbC-natural-gas'!B12+'[1]BIFUbC-electricity'!B12+'[1]BIFUbC-heat'!B12+'[1]BIFUbC-biomass'!B12+'[1]BIFUbC-hydrogen'!D12 -> 645211326511539 | C12: ='[1]BIFUbC-coal'!C12+'[1]BIFUbC-LPG-propane-or-butane'!C12+'[1]BIFUbC-petroleum-diesel'!C12+'[1]BIFUbC-crude-oil'!C12+'[1]BIFUbC-heavy-or-residual-oil'!C12+'[1]BIFUbC-natural-gas'!C12+'[1]BIFUbC-electricity'!C12+'[1]BIFUbC-heat'!C12+'[1]BIFUbC-biomass'!C12+'[1]BIFUbC-hydrogen'!E12 -> 659795827134432 | D12: ='[1]BIFUbC-coal'!D12+'[1]BIFUbC-LPG-propane-or-butane'!D12+'[1]BIFUbC-petroleum-diesel'!D12+'[1]BIFUbC-crude-oil'!D12+'[1]BIFUbC-heavy-or-residual-oil'!D12+'[1]BIFUbC-natural-gas'!D12+'[1]BIFUbC-electricity'!D12+'[1]BIFUbC-heat'!D12+'[1]BIFUbC-biomass'!D12+'[1]BIFUbC-hydrogen'!F12 -> 7.2988675e+14 | E12: ='[1]BIFUbC-coal'!E12+'[1]BIFUbC-LPG-propane-or-butane'!E12+'[1]BIFUbC-petroleum-diesel'!E12+'[1]BIFUbC-crude-oil'!E12+'[1]BIFUbC-heavy-or-residual-oil'!E12+'[1]BIFUbC-natural-gas'!E12+'[1]BIFUbC-electricity'!E12+'[1]BIFUbC-heat'!E12+'[1]BIFUbC-biomass'!E12+'[1]BIFUbC-hydrogen'!G12 -> 7.2795082e+14 | F12: ='[1]BIFUbC-coal'!F12+'[1]BIFUbC-LPG-propane-or-butane'!F12+'[1]BIFUbC-petroleum-diesel'!F12+'[1]BIFUbC-crude-oil'!F12+'[1]BIFUbC-heavy-or-residual-oil'!F12+'[1]BIFUbC-natural-gas'!F12+'[1]BIFUbC-electricity'!F12+'[1]BIFUbC-heat'!F12+'[1]BIFUbC-biomass'!F12+'[1]BIFUbC-hydrogen'!H12 -> 756983095291253 | G12: ='[1]BIFUbC-coal'!G12+'[1]BIFUbC-LPG-propane-or-butane'!G12+'[1]BIFUbC-petroleum-diesel'!G12+'[1]BIFUbC-crude-oil'!G12+'[1]BIFUbC-heavy-or-residual-oil'!G12+'[1]BIFUbC-natural-gas'!G12+'[1]BIFUbC-electricity'!G12+'[1]BIFUbC-heat'!G12+'[1]BIFUbC-biomass'!G12+'[1]BIFUbC-hydrogen'!I12 -> 7.8196777e+14 | H12: ='[1]BIFUbC-coal'!H12+'[1]BIFUbC-LPG-propane-or-butane'!H12+'[1]BIFUbC-petroleum-diesel'!H12+'[1]BIFUbC-crude-oil'!H12+'[1]BIFUbC-heavy-or-residual-oil'!H12+'[1]BIFUbC-natural-gas'!H12+'[1]BIFUbC-electricity'!H12+'[1]BIFUbC-heat'!H12+'[1]BIFUbC-biomass'!H12+'[1]BIFUbC-hydrogen'!J12 -> 8.1329575e+14 | I12: ='[1]BIFUbC-coal'!I12+'[1]BIFUbC-LPG-propane-or-butane'!I12+'[1]BIFUbC-petroleum-diesel'!I12+'[1]BIFUbC-crude-oil'!I12+'[1]BIFUbC-heavy-or-residual-oil'!I12+'[1]BIFUbC-natural-gas'!I12+'[1]BIFUbC-electricity'!I12+'[1]BIFUbC-heat'!I12+'[1]BIFUbC-biomass'!I12+'[1]BIFUbC-hydrogen'!K12 -> 8.4376042e+14 | ... AQ12: ='[1]BIFUbC-coal'!AQ12+'[1]BIFUbC-LPG-propane-or-butane'!AQ12+'[1]BIFUbC-petroleum-diesel'!AQ12+'[1]BIFUbC-crude-oil'!AQ12+'[1]BIFUbC-heavy-or-residual-oil'!AQ12+'[1]BIFUbC-natural-gas'!AQ12+'[1]BIFUbC-electricity'!AQ12+'[1]BIFUbC-heat'!AQ12+'[1]BIFUbC-biomass'!AQ12+'[1]BIFUbC-hydrogen'!AS12 -> 8.3295027e+14
A13: glass and glass products 231 | B13: ='[1]BIFUbC-coal'!B13+'[1]BIFUbC-LPG-propane-or-butane'!B13+'[1]BIFUbC-petroleum-diesel'!B13+'[1]BIFUbC-crude-oil'!B13+'[1]BIFUbC-heavy-or-residual-oil'!B13+'[1]BIFUbC-natural-gas'!B13+'[1]BIFUbC-electricity'!B13+'[1]BIFUbC-heat'!B13+'[1]BIFUbC-biomass'!B13+'[1]BIFUbC-hydrogen'!D13 -> 2.369744e+14 | C13: ='[1]BIFUbC-coal'!C13+'[1]BIFUbC-LPG-propane-or-butane'!C13+'[1]BIFUbC-petroleum-diesel'!C13+'[1]BIFUbC-crude-oil'!C13+'[1]BIFUbC-heavy-or-residual-oil'!C13+'[1]BIFUbC-natural-gas'!C13+'[1]BIFUbC-electricity'!C13+'[1]BIFUbC-heat'!C13+'[1]BIFUbC-biomass'!C13+'[1]BIFUbC-hydrogen'!E13 -> 2.2110683e+14 | D13: ='[1]BIFUbC-coal'!D13+'[1]BIFUbC-LPG-propane-or-butane'!D13+'[1]BIFUbC-petroleum-diesel'!D13+'[1]BIFUbC-crude-oil'!D13+'[1]BIFUbC-heavy-or-residual-oil'!D13+'[1]BIFUbC-natural-gas'!D13+'[1]BIFUbC-electricity'!D13+'[1]BIFUbC-heat'!D13+'[1]BIFUbC-biomass'!D13+'[1]BIFUbC-hydrogen'!F13 -> 2.5909232e+14 | E13: ='[1]BIFUbC-coal'!E13+'[1]BIFUbC-LPG-propane-or-butane'!E13+'[1]BIFUbC-petroleum-diesel'!E13+'[1]BIFUbC-crude-oil'!E13+'[1]BIFUbC-heavy-or-residual-oil'!E13+'[1]BIFUbC-natural-gas'!E13+'[1]BIFUbC-electricity'!E13+'[1]BIFUbC-heat'!E13+'[1]BIFUbC-biomass'!E13+'[1]BIFUbC-hydrogen'!G13 -> 2.726151e+14 | F13: ='[1]BIFUbC-coal'!F13+'[1]BIFUbC-LPG-propane-or-butane'!F13+'[1]BIFUbC-petroleum-diesel'!F13+'[1]BIFUbC-crude-oil'!F13+'[1]BIFUbC-heavy-or-residual-oil'!F13+'[1]BIFUbC-natural-gas'!F13+'[1]BIFUbC-electricity'!F13+'[1]BIFUbC-heat'!F13+'[1]BIFUbC-biomass'!F13+'[1]BIFUbC-hydrogen'!H13 -> 2.8584868e+14 | G13: ='[1]BIFUbC-coal'!G13+'[1]BIFUbC-LPG-propane-or-butane'!G13+'[1]BIFUbC-petroleum-diesel'!G13+'[1]BIFUbC-crude-oil'!G13+'[1]BIFUbC-heavy-or-residual-oil'!G13+'[1]BIFUbC-natural-gas'!G13+'[1]BIFUbC-electricity'!G13+'[1]BIFUbC-heat'!G13+'[1]BIFUbC-biomass'!G13+'[1]BIFUbC-hydrogen'!I13 -> 3.0125427e+14 | H13: ='[1]BIFUbC-coal'!H13+'[1]BIFUbC-LPG-propane-or-butane'!H13+'[1]BIFUbC-petroleum-diesel'!H13+'[1]BIFUbC-crude-oil'!H13+'[1]BIFUbC-heavy-or-residual-oil'!H13+'[1]BIFUbC-natural-gas'!H13+'[1]BIFUbC-electricity'!H13+'[1]BIFUbC-heat'!H13+'[1]BIFUbC-biomass'!H13+'[1]BIFUbC-hydrogen'!J13 -> 3.2080221e+14 | I13: ='[1]BIFUbC-coal'!I13+'[1]BIFUbC-LPG-propane-or-butane'!I13+'[1]BIFUbC-petroleum-diesel'!I13+'[1]BIFUbC-crude-oil'!I13+'[1]BIFUbC-heavy-or-residual-oil'!I13+'[1]BIFUbC-natural-gas'!I13+'[1]BIFUbC-electricity'!I13+'[1]BIFUbC-heat'!I13+'[1]BIFUbC-biomass'!I13+'[1]BIFUbC-hydrogen'!K13 -> 3.3980057e+14 | ... AQ13: ='[1]BIFUbC-coal'!AQ13+'[1]BIFUbC-LPG-propane-or-butane'!AQ13+'[1]BIFUbC-petroleum-diesel'!AQ13+'[1]BIFUbC-crude-oil'!AQ13+'[1]BIFUbC-heavy-or-residual-oil'!AQ13+'[1]BIFUbC-natural-gas'!AQ13+'[1]BIFUbC-electricity'!AQ13+'[1]BIFUbC-heat'!AQ13+'[1]BIFUbC-biomass'!AQ13+'[1]BIFUbC-hydrogen'!AS13 -> 6.6249157e+14
... A26: construction 41T43 | B26: ='[1]BIFUbC-coal'!B26+'[1]BIFUbC-LPG-propane-or-butane'!B26+'[1]BIFUbC-petroleum-diesel'!B26+'[1]BIFUbC-crude-oil'!B26+'[1]BIFUbC-heavy-or-residual-oil'!B26+'[1]BIFUbC-natural-gas'!B26+'[1]BIFUbC-electricity'!B26+'[1]BIFUbC-heat'!B26+'[1]BIFUbC-biomass'!B26+'[1]BIFUbC-hydrogen'!D26 -> 1.9112433e+15 | C26: ='[1]BIFUbC-coal'!C26+'[1]BIFUbC-LPG-propane-or-butane'!C26+'[1]BIFUbC-petroleum-diesel'!C26+'[1]BIFUbC-crude-oil'!C26+'[1]BIFUbC-heavy-or-residual-oil'!C26+'[1]BIFUbC-natural-gas'!C26+'[1]BIFUbC-electricity'!C26+'[1]BIFUbC-heat'!C26+'[1]BIFUbC-biomass'!C26+'[1]BIFUbC-hydrogen'!E26 -> 2.0972686e+15 | D26: ='[1]BIFUbC-coal'!D26+'[1]BIFUbC-LPG-propane-or-butane'!D26+'[1]BIFUbC-petroleum-diesel'!D26+'[1]BIFUbC-crude-oil'!D26+'[1]BIFUbC-heavy-or-residual-oil'!D26+'[1]BIFUbC-natural-gas'!D26+'[1]BIFUbC-electricity'!D26+'[1]BIFUbC-heat'!D26+'[1]BIFUbC-biomass'!D26+'[1]BIFUbC-hydrogen'!F26 -> 2.2174681e+15 | E26: ='[1]BIFUbC-coal'!E26+'[1]BIFUbC-LPG-propane-or-butane'!E26+'[1]BIFUbC-petroleum-diesel'!E26+'[1]BIFUbC-crude-oil'!E26+'[1]BIFUbC-heavy-or-residual-oil'!E26+'[1]BIFUbC-natural-gas'!E26+'[1]BIFUbC-electricity'!E26+'[1]BIFUbC-heat'!E26+'[1]BIFUbC-biomass'!E26+'[1]BIFUbC-hydrogen'!G26 -> 2.2565239e+15 | F26: ='[1]BIFUbC-coal'!F26+'[1]BIFUbC-LPG-propane-or-butane'!F26+'[1]BIFUbC-petroleum-diesel'!F26+'[1]BIFUbC-crude-oil'!F26+'[1]BIFUbC-heavy-or-residual-oil'!F26+'[1]BIFUbC-natural-gas'!F26+'[1]BIFUbC-electricity'!F26+'[1]BIFUbC-heat'!F26+'[1]BIFUbC-biomass'!F26+'[1]BIFUbC-hydrogen'!H26 -> 2.4016292e+15 | G26: ='[1]BIFUbC-coal'!G26+'[1]BIFUbC-LPG-propane-or-butane'!G26+'[1]BIFUbC-petroleum-diesel'!G26+'[1]BIFUbC-crude-oil'!G26+'[1]BIFUbC-heavy-or-residual-oil'!G26+'[1]BIFUbC-natural-gas'!G26+'[1]BIFUbC-electricity'!G26+'[1]BIFUbC-heat'!G26+'[1]BIFUbC-biomass'!G26+'[1]BIFUbC-hydrogen'!I26 -> 2.523109e+15 | H26: ='[1]BIFUbC-coal'!H26+'[1]BIFUbC-LPG-propane-or-butane'!H26+'[1]BIFUbC-petroleum-diesel'!H26+'[1]BIFUbC-crude-oil'!H26+'[1]BIFUbC-heavy-or-residual-oil'!H26+'[1]BIFUbC-natural-gas'!H26+'[1]BIFUbC-electricity'!H26+'[1]BIFUbC-heat'!H26+'[1]BIFUbC-biomass'!H26+'[1]BIFUbC-hydrogen'!J26 -> 2.6261285e+15 | I26: ='[1]BIFUbC-coal'!I26+'[1]BIFUbC-LPG-propane-or-butane'!I26+'[1]BIFUbC-petroleum-diesel'!I26+'[1]BIFUbC-crude-oil'!I26+'[1]BIFUbC-heavy-or-residual-oil'!I26+'[1]BIFUbC-natural-gas'!I26+'[1]BIFUbC-electricity'!I26+'[1]BIFUbC-heat'!I26+'[1]BIFUbC-biomass'!I26+'[1]BIFUbC-hydrogen'!K26 -> 2.7630203e+15 | ... AQ26: ='[1]BIFUbC-coal'!AQ26+'[1]BIFUbC-LPG-propane-or-butane'!AQ26+'[1]BIFUbC-petroleum-diesel'!AQ26+'[1]BIFUbC-crude-oil'!AQ26+'[1]BIFUbC-heavy-or-residual-oil'!AQ26+'[1]BIFUbC-natural-gas'!AQ26+'[1]BIFUbC-electricity'!AQ26+'[1]BIFUbC-heat'!AQ26+'[1]BIFUbC-biomass'!AQ26+'[1]BIFUbC-hydrogen'!AS26 -> 4.5356026e+15
A27: 电力、热力生产 | B27: 2.2694301e+15 | C27: 2.2694301e+15

Sheet 工业节能技术装备推荐目录
A1: 发布时间 | B1: 技术名称 | C1: 适用范围 | D1: EPS行业 | E1: 技术类型 | F1: EPS政策 | G1: 目前 推广比例 | H1: 推广 起始年 | I1: 推广 结束年 | J1: 推广期 实现比例 | K1: 推广期的节能能力 (万tce/a) | L1: 100%推广的节能能力 (万tce/a) | M1: 推广100% 实现的年份
A2: 2020 | B2: 外循环生料立磨技术 | C2: 建材 | D2: =IFERROR(VLOOKUP(C2,'Sector & Policy Match'!$A$1:$B$42,2,0),"") -> cement and other nonmetallic minerals 239 | E2: 流程工业节能 | F2: =VLOOKUP(E2,'Sector & Policy Match'!$G$1:$H$8,2,0) -> Early Facility Retirement | G2: <5% | H2: 2021 | I2: 2025 | J2: 0.1 | K2: 9.65 | L2: =(1-IF(G2="<5%",0,G2))/(J2-IF(G2="<5%",0,G2))*K2 -> 96.5 | M2: 2060
A3: 2020 | B3: 钢渣/矿渣辊压机终粉磨系统 | C3: 建材 | D3: =IFERROR(VLOOKUP(C3,'Sector & Policy Match'!$A$1:$B$42,2,0),"") -> cement and other nonmetallic minerals 239 | E3: 流程工业节能 | F3: =VLOOKUP(E3,'Sector & Policy Match'!$G$1:$H$8,2,0) -> Early Facility Retirement | G3: <5% | H3: 2021 | I3: 2025 | J3: 0.2 | K3: 8.72 | L3: =(1-IF(G3="<5%",0,G3))/(J3-IF(G3="<5%",0,G3))*K3 -> 43.6 | M3: 2060
A4: 2020 | B4: 陶瓷原料连续制浆系统 | C4: 建材 | D4: =IFERROR(VLOOKUP(C4,'Sector & Policy Match'!$A$1:$B$42,2,0),"") -> cement and other nonmetallic minerals 239 | E4: 流程工业节能 | F4: =VLOOKUP(E4,'Sector & Policy Match'!$G$1:$H$8,2,0) -> Early Facility Retirement | G4: <5% | H4: 2021 | I4: 2025 | J4: 0.1 | K4: 92.1 | L4: =(1-IF(G4="<5%",0,G4))/(J4-IF(G4="<5%",0,G4))*K4 -> 921 | M4: 2060
A5: 2020 | B5: 带中段辊破的列进式冷却机 | C5: 建材 | D5: =IFERROR(VLOOKUP(C5,'Sector & Policy Match'!$A$1:$B$42,2,0),"") -> cement and other nonmetallic minerals 239 | E5: 流程工业节能 | F5: =VLOOKUP(E5,'Sector & Policy Match'!$G$1:$H$8,2,0) -> Early Facility Retirement | G5: <5% | H5: 2021 | I5: 2025 | J5: 0.1 | K5: 26.6 | L5: =(1-IF(G5="<5%",0,G5))/(J5-IF(G5="<5%",0,G5))*K5 -> 266 | M5: 2060
A6: 2020 | B6: 卧式玻璃直线四边砂轮式磨边技术 | C6: 建材 | D6: =IFERROR(VLOOKUP(C6,'Sector & Policy Match'!$A$1:$B$42,2,0),"") -> cement and other nonmetallic minerals 239 | E6: 流程工业节能 | F6: =VLOOKUP(E6,'Sector & Policy Match'!$G$1:$H$8,2,0) -> Early Facility Retirement | G6: <5% | H6: 2021 | I6: 2025 | J6: 0.1 | K6: 3.5 | L6: =(1-IF(G6="<5%",0,G6))/(J6-IF(G6="<5%",0,G6))*K6 -> 35 | M6: 2060
A7: 2020 | B7: 宽粒级磁铁矿湿式弱磁预选分级磨矿技术 | C7: 钢铁 | D7: =IFERROR(VLOOKUP(C7,'Sector & Policy Match'!$A$1:$B$42,2,0),"") -> iron and steel 241 | E7: 流程工业节能 | F7: =VLOOKUP(E7,'Sector & Policy Match'!$G$1:$H$8,2,0) -> Early Facility Retirement | G7: <5% | H7: 2021 | I7: 2025 | J7: 0.15 | K7: 18 | L7: =(1-IF(G7="<5%",0,G7))/(J7-IF(G7="<5%",0,G7))*K7 -> 120 | M7: 2060
A8: 2020 | B8: 新型水泥熟料冷却技术及装备 | C8: 建材 | D8: =IFERROR(VLOOKUP(C8,'Sector & Policy Match'!$A$1:$B$42,2,0),"") -> cement and other nonmetallic minerals 239 | E8: 流程工业节能 | F8: =VLOOKUP(E8,'Sector & Policy Match'!$G$1:$H$8,2,0) -> Early Facility Retirement | G8: 0.05 | H8: 2021 | I8: 2025 | J8: 0.5 | K8: 120 | L8: =(1-IF(G8="<5%",0,G8))/(J8-IF(G8="<5%",0,G8))*K8 -> 253.33333 | M8: 2060
A9: 2020 | B9: 高能效长寿化双膛立式石灰窑装备及控制技术 | C9: 钢铁 | D9: =IFERROR(VLOOKUP(C9,'Sector & Policy Match'!$A$1:$B$42,2,0),"") -> iron and steel 241 | E9: 流程工业节能 | F9: =VLOOKUP(E9,'Sector & Policy Match'!$G$1:$H$8,2,0) -> Early Facility Retirement | G9: 0.05 | H9: 2021 | I9: 2025 | J9: 0.35 | K9: 178 | L9: =(1-IF(G9="<5%",0,G9))/(J9-IF(G9="<5%",0,G9))*K9 -> 563.66667 | M9: 2060
A10: 2020 | B10: 机械磨损陶瓷合金自动修复技术 | D10: =IFERROR(VLOOKUP(C10,'Sector & Policy Match'!$A$1:$B$42,2,0),"") | E10: 流程工业节能 | F10: =VLOOKUP(E10,'Sector & Policy Match'!$G$1:$H$8,2,0) -> Early Facility Retirement | G10: 0.05 | H10: 2021 | I10: 2025 | J10: 0.15 | K10: 95 | L10: =(1-IF(G10="<5%",0,G10))/(J10-IF(G10="<5%",0,G10))*K10 -> 902.5 | M10: 2060
A11: 2020 | B11: 焦炉加热优化控制及管理技术 | C11: 钢铁 | D11: =IFERROR(VLOOKUP(C11,'Sector & Policy Match'!$A$1:$B$42,2,0),"") -> iron and steel 241 | E11: 流程工业节能 | F11: =VLOOKUP(E11,'Sector & Policy Match'!$G$1:$H$8,2,0) -> Early Facility Retirement | G11: 0.05 | H11: 2021 | I11: 2025 | J11: 0.2 | K11: 21 | L11: =(1-IF(G11="<5%",0,G11))/(J11-IF(G11="<5%",0,G11))*K11 -> 133 | M11: 2060
A12: 2020 | B12: 升膜多效蒸发技术 | C12: 化工 | D12: =IFERROR(VLOOKUP(C12,'Sector & Policy Match'!$A$1:$B$42,2,0),"") -> chemicals 20 | E12: 流程工业节能 | F12: =VLOOKUP(E12,'Sector & Policy Match'!$G$1:$H$8,2,0) -> Early Facility Retirement | G12: 0.05 | H12: 2021 | I12: 2025 | J12: 0.15 | K12: 13 | L12: =(1-IF(G12="<5%",0,G12))/(J12-IF(G12="<5%",0,G12))*K12 -> 123.5 | M12: 2060
A13: 2020 | B13: 利用高热值危险废弃物替代水泥窑燃料综合技术 | C13: 建材 | D13: =IFERROR(VLOOKUP(C13,'Sector & Policy Match'!$A$1:$B$42,2,0),"") -> cement and other nonmetallic minerals 239 | E13: 流程工业节能 | F13: =VLOOKUP(E13,'Sector & Policy Match'!$G$1:$H$8,2,0) -> Early Facility Retirement | G13: 0.1 | H13: 2021 | I13: 2025 | J13: 0.3 | K13: 15 | L13: =(1-IF(G13="<5%",0,G13))/(J13-IF(G13="<5%",0,G13))*K13 -> 67.5 | M13: 2060
A14: 2020 | B14: 钢渣立磨终粉磨技术 | C14: 建材\钢铁 | D14: =IFERROR(VLOOKUP(C14,'Sector & Policy Match'!$A$1:$B$42,2,0),"") | E14: 流程工业节能 | F14: =VLOOKUP(E14,'Sector & Policy Match'!$G$1:$H$8,2,0) -> Early Facility Retirement | G14: 0.1 | H14: 2021 | I14: 2025 | J14: 0.3 | K14: 8.9 | L14: =(1-IF(G14="<5%",0,G14))/(J14-IF(G14="<5%",0,G14))*K14 -> 40.05 | M14: 2060
A15: 2020 | B15: 钢渣立磨终粉磨技术 | C15: 建材 | D15: =IFERROR(VLOOKUP(C15,'Sector & Policy Match'!$A$1:$B$42,2,0),"") -> cement and other nonmetallic minerals 239 | E15: 流程工业节能 | F15: =VLOOKUP(E15,'Sector & Policy Match'!$G$1:$H$8,2,0) -> Early Facility Retirement | G15: 0.1 | H15: 2021 | I15: 2025 | J15: 0.3 | K15: =BIFUbC!B14/(BIFUbC!B14+BIFUbC!B15)*K14 -> 2.51467 | L15: =(1-IF(G15="<5%",0,G15))/(J15-IF(G15="<5%",0,G15))*K15 -> 11.316015 | M15: 2060
A16: 2020 | B16: 钢渣立磨终粉磨技术 | C16: 钢铁 | D16: =IFERROR(VLOOKUP(C16,'Sector & Policy Match'!$A$1:$B$42,2,0),"") -> iron and steel 241 | E16: 流程工业节能 | F16: =VLOOKUP(E16,'Sector & Policy Match'!$G$1:$H$8,2,0) -> Early Facility Retirement | G16: 0.1 | H16: 2021 | I16: 2025 | J16: 0.3 | K16: =BIFUbC!B15/(BIFUbC!B14+BIFUbC!B15)*K14 -> 6.38533 | L16: =(1-IF(G16="<5%",0,G16))/(J16-IF(G16="<5%",0,G16))*K16 -> 28.733985 | M16: 2060
A17: 2020 | B17: 炉窑烟气节能降耗一体化技术 | C17: 工业锅炉 | D17: =IFERROR(VLOOKUP(C17,'Sector & Policy Match'!$A$1:$B$42,2,0),"") -> 工业锅炉 | E17: 流程工业节能 | F17: =VLOOKUP(E17,'Sector & Policy Match'!$G$1:$H$8,2,0) -> Early Facility Retirement | G17: 0.15 | H17: 2021 | I17: 2025 | J17: 0.35 | K17: 36 | L17: =(1-IF(G17="<5%",0,G17))/(J17-IF(G17="<5%",0,G17))*K17 -> 153 | M17: 2060
A18: 2020 | B18: 低导热多层复合莫来石砖 | C18: 建材 | D18: =IFERROR(VLOOKUP(C18,'Sector & Policy Match'!$A$1:$B$42,2,0),"") -> cement and other nonmetallic minerals 239 | E18: 流程工业节能 | F18: =VLOOKUP(E18,'Sector & Policy Match'!$G$1:$H$8,2,0) -> Early Facility Retirement | G18: 0.2 | H18: 2021 | I18: 2025 | J18: 0.4 | K18: 68.3 | L18: =(1-IF(G18="<5%",0,G18))/(J18-IF(G18="<5%",0,G18))*K18 -> 273.2 | M18: 2060
A19: 2020 | B19: 大型清洁高效水煤浆气化技术 | C19: 化工 | D19: =IFERROR(VLOOKUP(C19,'Sector & Policy Match'!$A$1:$B$42,2,0),"") -> chemicals 20 | E19: 流程工业节能 | F19: =VLOOKUP(E19,'Sector & Policy Match'!$G$1:$H$8,2,0) -> Early Facility Retirement | G19: 0.2 | H19: 2021 | I19: 2025 | J19: 0.4 | K19: 36 | L19: =(1-IF(G19="<5%",0,G19))/(J19-IF(G19="<5%",0,G19))*K19 -> 144 | M19: 2060
A20: 2020 | B20: 铜冶炼领域汽电双驱同轴压缩机组(MCRT)技术 | C20: 有色金属 | D20: =IFERROR(VLOOKUP(C20,'Sector & Policy Match'!$A$1:$B$42,2,0),"") -> other metals 242 | E20: 流程工业节能 | F20: =VLOOKUP(E20,'Sector & Policy Match'!$G$1:$H$8,2,0) -> Early Facility Retirement | G20: 0.2 | H20: 2021 | I20: 2025 | J20: 0.4 | K20: 10 | L20: =(1-IF(G20="<5%",0,G20))/(J20-IF(G20="<5%",0,G20))*K20 -> 40 | M20: 2060
A21: 2020 | B21: 汽轮驱动高炉鼓风机与电动/发电机同轴机组技术 | C21: 钢铁 | D21: =IFERROR(VLOOKUP(C21,'Sector & Policy Match'!$A$1:$B$42,2,0),"") -> iron and steel 241 | E21: 流程工业节能 | F21: =VLOOKUP(E21,'Sector & Policy Match'!$G$1:$H$8,2,0) -> Early Facility Retirement | G21: 0.4 | H21: 2021 | I21: 2025 | J21: 0.6 | K21: 40 | L21: =(1-IF(G21="<5%",0,G21))/(J21-IF(G21="<5%",0,G21))*K21 -> 120 | M21: 2060
A22: 2020 | B22: 锅炉烟气深度冷却技术 | C22: 工业锅炉 | D22: =IFERROR(VLOOKUP(C22,'Sector & Policy Match'!$A$1:$B$42,2,0),"") -> 工业锅炉 | E22: 余热余压利用 | F22: =VLOOKUP(E22,'Sector & Policy Match'!$G$1:$H$8,2,0) -> Cogeneration and Waste Heat Recovery | G22: <5% | H22: 2021 | I22: 2025 | J22: 0.1 | K22: 66 | L22: =(1-IF(G22="<5%",0,G22))/(J22-IF(G22="<5%",0,G22))*K22 -> 660 | M22: 2060
A23: 2020 | B23: 工业循环水余压能量闭环回收利用技术 | C23: 工业循环水 | D23: =IFERROR(VLOOKUP(C23,'Sector & Policy Match'!$A$1:$B$42,2,0),"") -> 工业循环水 | E23: 余热余压利用 | F23: =VLOOKUP(E23,'Sector & Policy Match'!$G$1:$H$8,2,0) -> Cogeneration and Waste Heat Recovery | G23: <5% | H23: 2021 | I23: 2025 | J23: 0.15 | K23: 38 | L23: =(1-IF(G23="<5%",0,G23))/(J23-IF(G23="<5%",0,G23))*K23 -> 253.33333 | M23: 2060
A24: 2020 | B24: 微型燃气轮机能源梯级利用节能技术 | C24: 微型燃气轮机 | D24: =IFERROR(VLOOKUP(C24,'Sector & Policy Match'!$A$1:$B$42,2,0),"") -> 微型燃气轮机 | E24: 余热余压利用 | F24: =VLOOKUP(E24,'Sector & Policy Match'!$G$1:$H$8,2,0) -> Cogeneration and Waste Heat Recovery | G24: <5% | H24: 2021 | I24: 2025 | J24: 0.15 | K24: 36 | L24: =(1-IF(G24="<5%",0,G24))/(J24-IF(G24="<5%",0,G24))*K24 -> 240 | M24: 2060
A25: 2020 | B25: 工业燃煤机组烟气低品位余热回收利用技术 | C25: 电力、热力生产 | D25: =IFERROR(VLOOKUP(C25,'Sector & Policy Match'!$A$1:$B$42,2,0),"") -> 电力、热力生产 | E25: 余热余压利用 | F25: =VLOOKUP(E25,'Sector & Policy Match'!$G$1:$H$8,2,0) -> Cogeneration and Waste Heat Recovery | G25: <5% | H25: 2021 | I25: 2025 | J25: 0.1 | K25: 100 | L25: =(1-IF(G25="<5%",0,G25))/(J25-IF(G25="<5%",0,G25))*K25 -> 1000 | M25: 2060
A26: 2020 | B26: 电厂用低压驱动热泵技术 | C26: 电力、热力生产 | D26: =IFERROR(VLOOKUP(C26,'Sector & Policy Match'!$A$1:$B$42,2,0),"") -> 电力、热力生产 | E26: 余热余压利用 | F26: =VLOOKUP(E26,'Sector & Policy Match'!$G$1:$H$8,2,0) -> Cogeneration and Waste Heat Recovery | G26: 0.1 | H26: 2021 | I26: 2025 | J26: 0.3 | K26: 58 | L26: =(1-IF(G26="<5%",0,G26))/(J26-IF(G26="<5%",0,G26))*K26 -> 261 | M26: 2060
A27: 2020 | B27: 旋转电磁制热技术 | C27: 电力、热力生产 | D27: =IFERROR(VLOOKUP(C27,'Sector & Policy Match'!$A$1:$B$42,2,0),"") -> 电力、热力生产 | E27: 重点用能设备及系统节能 | F27: =VLOOKUP(E27,'Sector & Policy Match'!$G$1:$H$8,2,0) -> Improvement in Eqpt Efficiency Standards | G27: <5% | H27: 2021 | I27: 2025 | J27: 0.1 | K27: 9.5 | L27: =(1-IF(G27="<5%",0,G27))/(J27-IF(G27="<5%",0,G27))*K27 -> 95 | M27: 2060
A28: 2020 | B28: 多模式节能型低露点干燥技术 | C28: 压缩空气系统 | D28: =IFERROR(VLOOKUP(C28,'Sector & Policy Match'!$A$1:$B$42,2,0),"") -> 压缩空气系统 | E28: 重点用能设备及系统节能 | F28: =VLOOKUP(E28,'Sector & Policy Match'!$G$1:$H$8,2,0) -> Improvement in Eqpt Efficiency Standards | G28: <5% | H28: 2021 | I28: 2025 | J28: 0.2 | K28: 6.6 | L28: =(1-IF(G28="<5%",0,G28))/(J28-IF(G28="<5%",0,G28))*K28 -> 33 | M28: 2060
A29: 2020 | B29: 异步电机永磁化改造技术 | C29: 电动机系统 | D29: =IFERROR(VLOOKUP(C29,'Sector & Policy Match'!$A$1:$B$42,2,0),"") -> 电动机系统 | E29: 重点用能设备及系统节能 | F29: =VLOOKUP(E29,'Sector & Policy Match'!$G$1:$H$8,2,0) -> Improvement in Eqpt Efficiency Standards | G29: <5% | H29: 2021 | I29: 2025 | J29: 0.1 | K29: 4.3 | L29: =(1-IF(G29="<5%",0,G29))/(J29-IF(G29="<5%",0,G29))*K29 -> 43 | M29: 2060
A30: 2020 | B30: 特制电机技术 | C30: 电动机系统 | D30: =IFERROR(VLOOKUP(C30,'Sector & Policy Match'!$A$1:$B$42,2,0),"") -> 电动机系统 | E30: 重点用能设备及系统节能 | F30: =VLOOKUP(E30,'Sector & Policy Match'!$G$1:$H$8,2,0) -> Improvement in Eqpt Efficiency Standards | G30: <5% | H30: 2021 | I30: 2025 | J30: 0.06 | K30: 4.9 | L30: =(1-IF(G30="<5%",0,G30))/(J30-IF(G30="<5%",0,G30))*K30 -> 81.666667 | M30: 2060
A31: 2020 | B31: 中央空调热水锅炉 | C31: 空调系统 | D31: =IFERROR(VLOOKUP(C31,'Sector & Policy Match'!$A$1:$B$42,2,0),"") -> 空调系统 | E31: 重点用能设备及系统节能 | F31: =VLOOKUP(E31,'Sector & Policy Match'!$G$1:$H$8,2,0) -> Improvement in Eqpt Efficiency Standards | G31: <5% | H31: 2021 | I31: 2025 | J31: 0.15 | K31: 21.5 | L31: =(1-IF(G31="<5%",0,G31))/(J31-IF(G31="<5%",0,G31))*K31 -> 143.33333 | M31: 2060
A32: 2020 | B32: 电缸驱动游梁式抽油机技术 | C32: 油气开采 | D32: =IFERROR(VLOOKUP(C32,'Sector & Policy Match'!$A$1:$B$42,2,0),"") -> oil and gas extraction 06 | E32: 重点用能设备及系统节能 | F32: =VLOOKUP(E32,'Sector & Policy Match'!$G$1:$H$8,2,0) -> Improvement in Eqpt Efficiency Standards | G32: <5% | H32: 2021 | I32: 2025 | J32: 0.1 | K32: 68 | L32: =(1-IF(G32="<5%",0,G32))/(J32-IF(G32="<5%",0,G32))*K32 -> 680 | M32: 2060
A33: 2020 | B33: 智能磁悬浮透平真空泵综合节能技术 | C33: 造纸 | D33: =IFERROR(VLOOKUP(C33,'Sector & Policy Match'!$A$1:$B$42,2,0),"") -> pulp paper and printing 17T18 | E33: 重点用能设备及系统节能 | F33: =VLOOKUP(E33,'Sector & Policy Match'!$G$1:$H$8,2,0) -> Improvement in Eqpt Efficiency Standards | G33: <5% | H33: 2021 | I33: 2025 | J33: 0.1 | K33: 53 | L33: =(1-IF(G33="<5%",0,G33))/(J33-IF(G33="<5%",0,G33))*K33 -> 530 | M33: 2060
A34: 2020 | B34: 超大型4段蓄热式高速燃烧技术 | C34: 工业锅炉 | D34: =IFERROR(VLOOKUP(C34,'Sector & Policy Match'!$A$1:$B$42,2,0),"") -> 工业锅炉 | E34: 重点用能设备及系统节能 | F34: =VLOOKUP(E34,'Sector & Policy Match'!$G$1:$H$8,2,0) -> Improvement in Eqpt Efficiency Standards | G34: 0.05 | H34: 2021 | I34: 2025 | J34: 0.15 | K34: 8.4 | L34: =(1-IF(G34="<5%",0,G34))/(J34-IF(G34="<5%",0,G34))*K34 -> 79.8 | M34: 2060
A35: 2020 | B35: 卧式油冷型永磁调速器技术 | C35: 电动机系统 | D35: =IFERROR(VLOOKUP(C35,'Sector & Policy Match'!$A$1:$B$42,2,0),"") -> 电动机系统 | E35: 重点用能设备及系统节能 | F35: =VLOOKUP(E35,'Sector & Policy Match'!$G$1:$H$8,2,0) -> Improvement in Eqpt Efficiency Standards | G35: 0.05 | H35: 2021 | I35: 2025 | J35: 0.23 | K35: 34 | L35: =(1-IF(G35="<5%",0,G35))/(J35-IF(G35="<5%",0,G35))*K35 -> 179.44444 | M35: 2060
A36: 2020 | B36: 电极锅炉设计技术开发及制造 | C36: 电力、热力生产 | D36: =IFERROR(VLOOKUP(C36,'Sector & Policy Match'!$A$1:$B$42,2,0),"") -> 电力、热力生产 | E36: 重点用能设备及系统节能 | F36: =VLOOKUP(E36,'Sector & Policy Match'!$G$1:$H$8,2,0) -> Improvement in Eqpt Efficiency Standards | G36: 0.05 | H36: 2021 | I36: 2025 | J36: 0.15 | K36: 39 | L36: =(1-IF(G36="<5%",0,G36))/(J36-IF(G36="<5%",0,G36))*K36 -> 370.5 | M36: 2060
A37: 2020 | B37: 汽轮机变工况运行改造节能技术 | C37: 油气开采 | D37: =IFERROR(VLOOKUP(C37,'Sector & Policy Match'!$A$1:$B$42,2,0),"") -> oil and gas extraction 06 | E37: 重点用能设备及系统节能 | F37: =VLOOKUP(E37,'Sector & Policy Match'!$G$1:$H$8,2,0) -> Improvement in Eqpt Efficiency Standards | G37: 0.1 | H37: 2021 | I37: 2025 | J37: 0.4 | K37: 40 | L37: =(1-IF(G37="<5%",0,G37))/(J37-IF(G37="<5%",0,G37))*K37 -> 120 | M37: 2060
A38: 2020 | B38: 循环水系统节能技术 | C38: 化工 | D38: =IFERROR(VLOOKUP(C38,'Sector & Policy Match'!$A$1:$B$42,2,0),"") -> chemicals 20 | E38: 重点用能设备及系统节能 | F38: =VLOOKUP(E38,'Sector & Policy Match'!$G$1:$H$8,2,0) -> Improvement in Eqpt Efficiency Standards | G38: 0.1 | H38: 2021 | I38: 2025 | J38: 0.2 | K38: 5.28 | L38: =(1-IF(G38="<5%",0,G38))/(J38-IF(G38="<5%",0,G38))*K38 -> 47.52 | M38: 2060
A39: 2020 | B39: 燃煤锅炉智能调载趋零积灰趋零结露深度节能技术 | C39: 工业锅炉 | D39: =IFERROR(VLOOKUP(C39,'Sector & Policy Match'!$A$1:$B$42,2,0),"") -> 工业锅炉 | E39: 重点用能设备及系统节能 | F39: =VLOOKUP(E39,'Sector & Policy Match'!$G$1:$H$8,2,0) -> Improvement in Eqpt Efficiency Standards | G39: 0.12 | H39: 2021 | I39: 2025 | J39: 0.5 | K39: 146 | L39: =(1-IF(G39="<5%",0,G39))/(J39-IF(G39="<5%",0,G39))*K39 -> 338.10526 | M39: 2060
A40: 2020 | B40: 低温空气源热泵供热技术 | C40: Bldgs | D40: =IFERROR(VLOOKUP(C40,'Sector & Policy Match'!$A$1:$B$42,2,0),"") | E40: 重点用能设备及系统节能 | F40: =VLOOKUP(E40,'Sector & Policy Match'!$G$1:$H$8,2,0) -> Improvement in Eqpt Efficiency Standards | G40: 0.15 | H40: 2021 | I40: 2025 | J40: 0.4 | K40: 9.8 | L40: =(1-IF(G40="<5%",0,G40))/(J40-IF(G40="<5%",0,G40))*K40 -> 33.32 | M40: 2060
...

Sheet 用能设备节能分配
A1: 发布时间 | B1: 重点用能设备 | C1: EPS政策 | D1: 推广期的节能能力 (万tce/a) | E1: 100%推广的节能能力 (万tce/a) | G1: 重点用能设备 | H1: 适用范围 | I1: EPS行业 | J1: BIFUbC 2020 | K1: 占比 | M1: 发布时间 | N1: 重点用能设备 | O1: EPS行业 | P1: EPS政策 | Q1: 推广期的节能能力 (万tce/a) | R1: 100%推广的节能能力 (万tce/a)
A2: 2020 | B2: 工业锅炉 | C2: Early Facility Retirement | D2: =SUMIFS(工业节能技术装备推荐目录!K:K,工业节能技术装备推荐目录!C:C,用能设备节能分配!B2,工业节能技术装备推荐目录!F:F,用能设备节能分配!C2,工业节能技术装备推荐目录!A:A,用能设备节能分配!A2) -> 36 | E2: =SUMIFS(工业节能技术装备推荐目录!L:L,工业节能技术装备推荐目录!C:C,用能设备节能分配!B2,工业节能技术装备推荐目录!F:F,用能设备节能分配!C2,工业节能技术装备推荐目录!A:A,用能设备节能分配!A2) -> 153 | G2: 工业锅炉 | H2: 电力、热力生产 | I2: =VLOOKUP(H2,'Sector & Policy Match'!$A$1:$B$42,2,0) -> 电力、热力生产 | J2: =IFERROR(VLOOKUP(I2,BIFUbC!$A$1:$C$27,3,0),0) -> 2.2694301e+15 | K2: =J2/SUM($J$2:$J$8) -> 0.027528252 | M2: 2020 | N2: 工业锅炉 | O2: =I$3 -> refined petroleum and coke 19 | P2: Early Facility Retirement | Q2: =SUMIFS(D:D,B:B,N2,C:C,P2,A:A,M2)*SUMIFS(K:K,G:G,N2,I:I,O2) -> 19.20531 | R2: =SUMIFS(E:E,B:B,N2,C:C,P2,A:A,M2)*SUMIFS(K:K,G:G,N2,I:I,O2) -> 81.622568
A3: 2020 | B3: 工业锅炉 | C3: Installation and System Integration | D3: =SUMIFS(工业节能技术装备推荐目录!K:K,工业节能技术装备推荐目录!C:C,用能设备节能分配!B3,工业节能技术装备推荐目录!F:F,用能设备节能分配!C3,工业节能技术装备推荐目录!A:A,用能设备节能分配!A3) -> 0 | E3: =SUMIFS(工业节能技术装备推荐目录!L:L,工业节能技术装备推荐目录!C:C,用能设备节能分配!B3,工业节能技术装备推荐目录!F:F,用能设备节能分配!C3,工业节能技术装备推荐目录!A:A,用能设备节能分配!A3) -> 0 | G3: 工业锅炉 | H3: 石化 | I3: =VLOOKUP(H3,'Sector & Policy Match'!$A$1:$B$42,2,0) -> refined petroleum and coke 19 | J3: =IFERROR(VLOOKUP(I3,BIFUbC!$A$1:$C$27,3,0),0) -> 4.3980181e+16 | K3: =J3/SUM($J$2:$J$8) -> 0.53348084 | M3: 2020 | N3: 工业锅炉 | O3: =I$3 -> refined petroleum and coke 19 | P3: Installation and System Integration | Q3: =SUMIFS(D:D,B:B,N3,C:C,P3,A:A,M3)*SUMIFS(K:K,G:G,N3,I:I,O3) -> 0 | R3: =SUMIFS(E:E,B:B,N3,C:C,P3,A:A,M3)*SUMIFS(K:K,G:G,N3,I:I,O3) -> 0
A4: 2020 | B4: 工业锅炉 | C4: Cogeneration and Waste Heat Recovery | D4: =SUMIFS(工业节能技术装备推荐目录!K:K,工业节能技术装备推荐目录!C:C,用能设备节能分配!B4,工业节能技术装备推荐目录!F:F,用能设备节能分配!C4,工业节能技术装备推荐目录!A:A,用能设备节能分配!A4) -> 66 | E4: =SUMIFS(工业节能技术装备推荐目录!L:L,工业节能技术装备推荐目录!C:C,用能设备节能分配!B4,工业节能技术装备推荐目录!F:F,用能设备节能分配!C4,工业节能技术装备推荐目录!A:A,用能设备节能分配!A4) -> 660 | G4: 工业锅炉 | H4: 化工 | I4: =VLOOKUP(H4,'Sector & Policy Match'!$A$1:$B$42,2,0) -> chemicals 20 | J4: =IFERROR(VLOOKUP(I4,BIFUbC!$A$1:$C$27,3,0),0) -> 1.253828e+16 | K4: =J4/SUM($J$2:$J$8) -> 0.15208969 | M4: 2020 | N4: 工业锅炉 | O4: =I$3 -> refined petroleum and coke 19 | P4: Cogeneration and Waste Heat Recovery | Q4: =SUMIFS(D:D,B:B,N4,C:C,P4,A:A,M4)*SUMIFS(K:K,G:G,N4,I:I,O4) -> 35.209735 | R4: =SUMIFS(E:E,B:B,N4,C:C,P4,A:A,M4)*SUMIFS(K:K,G:G,N4,I:I,O4) -> 352.09735
A5: 2020 | B5: 工业锅炉 | C5: Improvement in Eqpt Efficiency Standards | D5: =SUMIFS(工业节能技术装备推荐目录!K:K,工业节能技术装备推荐目录!C:C,用能设备节能分配!B5,工业节能技术装备推荐目录!F:F,用能设备节能分配!C5,工业节能技术装备推荐目录!A:A,用能设备节能分配!A5) -> 154.4 | E5: =SUMIFS(工业节能技术装备推荐目录!L:L,工业节能技术装备推荐目录!C:C,用能设备节能分配!B5,工业节能技术装备推荐目录!F:F,用能设备节能分配!C5,工业节能技术装备推荐目录!A:A,用能设备节能分配!A5) -> 417.90526 | G5: 工业锅炉 | H5: 钢铁 | I5: =VLOOKUP(H5,'Sector & Policy Match'!$A$1:$B$42,2,0) -> iron and steel 241 | J5: =IFERROR(VLOOKUP(I5,BIFUbC!$A$1:$C$27,3,0),0) -> 2.0096009e+16 | K5: =J5/SUM($J$2:$J$8) -> 0.24376516 | M5: 2020 | N5: 工业锅炉 | O5: =I$3 -> refined petroleum and coke 19 | P5: Improvement in Eqpt Efficiency Standards | Q5: =SUMIFS(D:D,B:B,N5,C:C,P5,A:A,M5)*SUMIFS(K:K,G:G,N5,I:I,O5) -> 82.369441 | R5: =SUMIFS(E:E,B:B,N5,C:C,P5,A:A,M5)*SUMIFS(K:K,G:G,N5,I:I,O5) -> 222.94445
A6: 2020 | B6: 工业循环水 | C6: Early Facility Retirement | D6: =SUMIFS(工业节能技术装备推荐目录!K:K,工业节能技术装备推荐目录!C:C,用能设备节能分配!B6,工业节能技术装备推荐目录!F:F,用能设备节能分配!C6,工业节能技术装备推荐目录!A:A,用能设备节能分配!A6) -> 0 | E6: =SUMIFS(工业节能技术装备推荐目录!L:L,工业节能技术装备推荐目录!C:C,用能设备节能分配!B6,工业节能技术装备推荐目录!F:F,用能设备节能分配!C6,工业节能技术装备推荐目录!A:A,用能设备节能分配!A6) -> 0 | G6: 工业锅炉 | H6: 纺织 | I6: =VLOOKUP(H6,'Sector & Policy Match'!$A$1:$B$42,2,0) -> textiles apparel and leather 13T15 | J6: =IFERROR(VLOOKUP(I6,BIFUbC!$A$1:$C$27,3,0),0) -> 1.3389501e+15 | K6: =J6/SUM($J$2:$J$8) -> 0.016241503 | M6: 2020 | N6: 工业锅炉 | O6: =I$4 -> chemicals 20 | P6: =P2 -> Early Facility Retirement | Q6: =SUMIFS(D:D,B:B,N6,C:C,P6,A:A,M6)*SUMIFS(K:K,G:G,N6,I:I,O6) -> 5.4752288 | R6: =SUMIFS(E:E,B:B,N6,C:C,P6,A:A,M6)*SUMIFS(K:K,G:G,N6,I:I,O6) -> 23.269722
A7: 2020 | B7: 工业循环水 | C7: Installation and System Integration | D7: =SUMIFS(工业节能技术装备推荐目录!K:K,工业节能技术装备推荐目录!C:C,用能设备节能分配!B7,工业节能技术装备推荐目录!F:F,用能设备节能分配!C7,工业节能技术装备推荐目录!A:A,用能设备节能分配!A7) -> 0 | E7: =SUMIFS(工业节能技术装备推荐目录!L:L,工业节能技术装备推荐目录!C:C,用能设备节能分配!B7,工业节能技术装备推荐目录!F:F,用能设备节能分配!C7,工业节能技术装备推荐目录!A:A,用能设备节能分配!A7) -> 0 | G7: 工业锅炉 | H7: 造纸 | I7: =VLOOKUP(H7,'Sector & Policy Match'!$A$1:$B$42,2,0) -> pulp paper and printing 17T18 | J7: =IFERROR(VLOOKUP(I7,BIFUbC!$A$1:$C$27,3,0),0) -> 883986747789292 | K7: =J7/SUM($J$2:$J$8) -> 0.010722784 | M7: 2020 | N7: 工业锅炉 | O7: =I$4 -> chemicals 20 | P7: =P3 -> Installation and System Integration | Q7: =SUMIFS(D:D,B:B,N7,C:C,P7,A:A,M7)*SUMIFS(K:K,G:G,N7,I:I,O7) -> 0 | R7: =SUMIFS(E:E,B:B,N7,C:C,P7,A:A,M7)*SUMIFS(K:K,G:G,N7,I:I,O7) -> 0
