Workbook

Sheet 高情景
A1: 行业 | B1: 计量指标 | C1: 计量单位 | D1: 数据来源 | E1: 2020 | F1: 2021 | G1: 2022 | H1: 2023 | I1: 2024 | J1: 2025 | K1: 2026 | L1: 2027 | M1: 2028 | N1: 2029 | O1: 2030 | P1: 2031 | Q1: 2032 | R1: 2033 | S1: 2034 | T1: 2035 | U1: 2036 | V1: 2037 | W1: 2038 | X1: 2039 | Y1: 2040 | Z1: 2041 | AA1: 2042 | AB1: 2043 | AC1: 2044 | AD1: 2045 | AE1: 2046 | AF1: 2047 | AG1: 2048 | AH1: 2049 | AI1: 2050 | AJ1: 2051 | AK1: 2052 | AL1: 2053 | AM1: 2054 | AN1: 2055 | AO1: 2056 | AP1: 2057 | AQ1: 2058 | AR1: 2059 | AS1: 2060
A2: 煤炭开采和洗选业 | B2: 原煤 | C2: 亿吨 | D2: 中石化《中国能源展望2060》 | E2: 39.02 | F2: 41.26 | G2: 45.59 | H2: =G2+($J2-$G2)/3 -> 46.726667 | I2: =H2+($J2-$G2)/3 -> 47.863333 | J2: 49 | K2: =J2+($O2-$J2)/5 -> 49.8 | L2: =K2+($O2-$J2)/5 -> 50.6 | M2: =L2+($O2-$J2)/5 -> 51.4 | N2: =M2+($O2-$J2)/5 -> 52.2 | O2: 53 | P2: =O2+($T2-$O2)/5 -> 53.3 | Q2: =P2+($T2-$O2)/5 -> 53.6 | R2: =Q2+($T2-$O2)/5 -> 53.9 | S2: =R2+($T2-$O2)/5 -> 54.2 | T2: =54.5 -> 54.5 | U2: =T2+($Y2-$T2)/5 -> 54 | V2: =U2+($Y2-$T2)/5 -> 53.5 | W2: =V2+($Y2-$T2)/5 -> 53 | X2: =W2+($Y2-$T2)/5 -> 52.5 | Y2: 52 | Z2: =Y2+($AD2-$Y2)/5 -> 51.2 | AA2: =Z2+($AD2-$Y2)/5 -> 50.4 | AB2: =AA2+($AD2-$Y2)/5 -> 49.6 | AC2: =AB2+($AD2-$Y2)/5 -> 48.8 | AD2: 48 | AE2: =AD2+($AI2-$AD2)/5 -> 47.2 | AF2: =AE2+($AI2-$AD2)/5 -> 46.4 | AG2: =AF2+($AI2-$AD2)/5 -> 45.6 | AH2: =AG2+($AI2-$AD2)/5 -> 44.8 | AI2: 44 | AJ2: =AI2+($AN2-$AI2)/5 -> 43 | AK2: =AJ2+($AN2-$AI2)/5 -> 42 | AL2: =AK2+($AN2-$AI2)/5 -> 41 | AM2: =AL2+($AN2-$AI2)/5 -> 40 | AN2: 39 | AO2: =AN2+($AS2-$AN2)/5 -> 38.2 | AP2: =AO2+($AS2-$AN2)/5 -> 37.4 | AQ2: =AP2+($AS2-$AN2)/5 -> 36.6 | AR2: =AQ2+($AS2-$AN2)/5 -> 35.8 | AS2: 35
A3: 石油和天然气开采业 | B3: 原油 | C3: 亿吨 | D3: 中石油《世界与中国能源展望2021》 | E3: 1.9477 | F3: 1.9888 | G3: 2.0472 | H3: =G3+($J3-$G3)/3 -> 2.0881333 | I3: =H3+($J3-$G3)/3 -> 2.1290667 | J3: 2.17 | K3: =J3+($O3-$J3)/5 -> 2.176 | L3: =K3+($O3-$J3)/5 -> 2.182 | M3: =L3+($O3-$J3)/5 -> 2.188 | N3: =M3+($O3-$J3)/5 -> 2.194 | O3: 2.2 | P3: =O3+($T3-$O3)/5 -> 2.216 | Q3: =P3+($T3-$O3)/5 -> 2.232 | R3: =Q3+($T3-$O3)/5 -> 2.248 | S3: =R3+($T3-$O3)/5 -> 2.264 | T3: 2.28 | U3: =T3+($Y3-$T3)/5 -> 2.284 | V3: =U3+($Y3-$T3)/5 -> 2.288 | W3: =V3+($Y3-$T3)/5 -> 2.292 | X3: =W3+($Y3-$T3)/5 -> 2.296 | Y3: 2.3 | Z3: =Y3+($AD3-$Y3)/5 -> 2.28 | AA3: =Z3+($AD3-$Y3)/5 -> 2.26 | AB3: =AA3+($AD3-$Y3)/5 -> 2.24 | AC3: =AB3+($AD3-$Y3)/5 -> 2.22 | AD3: 2.2 | AE3: =AD3+($AI3-$AD3)/5 -> 2.18 | AF3: =AE3+($AI3-$AD3)/5 -> 2.16 | AG3: =AF3+($AI3-$AD3)/5 -> 2.14 | AH3: =AG3+($AI3-$AD3)/5 -> 2.12 | AI3: 2.1 | AJ3: =AI3+($AN3-$AI3)/5 -> 2.07 | AK3: =AJ3+($AN3-$AI3)/5 -> 2.04 | AL3: =AK3+($AN3-$AI3)/5 -> 2.01 | AM3: =AL3+($AN3-$AI3)/5 -> 1.98 | AN3: 1.95 | AO3: =AN3+($AS3-$AN3)/5 -> 1.938 | AP3: =AO3+($AS3-$AN3)/5 -> 1.926 | AQ3: =AP3+($AS3-$AN3)/5 -> 1.914 | AR3: =AQ3+($AS3-$AN3)/5 -> 1.902 | AS3: 1.89
A4: 石油和天然气开采业 | B4: 天然气 | C4: 亿立方米 | D4: 中石油《世界与中国能源展望2021》 | E4: 1924.95 | F4: 2075.84 | G4: 2201.1 | H4: =G4+($J4-$G4)/3 -> 2298.4 | I4: =H4+($J4-$G4)/3 -> 2395.7 | J4: 2493 | K4: =J4+($O4-$J4)/5 -> 2554.4 | L4: =K4+($O4-$J4)/5 -> 2615.8 | M4: =L4+($O4-$J4)/5 -> 2677.2 | N4: =M4+($O4-$J4)/5 -> 2738.6 | O4: 2800 | P4: =O4+($T4-$O4)/5 -> 2840 | Q4: =P4+($T4-$O4)/5 -> 2880 | R4: =Q4+($T4-$O4)/5 -> 2920 | S4: =R4+($T4-$O4)/5 -> 2960 | T4: 3000 | U4: =T4+($Y4-$T4)/5 -> 3040 | V4: =U4+($Y4-$T4)/5 -> 3080 | W4: =V4+($Y4-$T4)/5 -> 3120 | X4: =W4+($Y4-$T4)/5 -> 3160 | Y4: 3200 | Z4: =Y4+($AD4-$Y4)/5 -> 3220 | AA4: =Z4+($AD4-$Y4)/5 -> 3240 | AB4: =AA4+($AD4-$Y4)/5 -> 3260 | AC4: =AB4+($AD4-$Y4)/5 -> 3280 | AD4: 3300 | AE4: =AD4+($AI4-$AD4)/5 -> 3320 | AF4: =AE4+($AI4-$AD4)/5 -> 3340 | AG4: =AF4+($AI4-$AD4)/5 -> 3360 | AH4: =AG4+($AI4-$AD4)/5 -> 3380 | AI4: 3400 | AJ4: =AI4+($AN4-$AI4)/5 -> 3420 | AK4: =AJ4+($AN4-$AI4)/5 -> 3440 | AL4: =AK4+($AN4-$AI4)/5 -> 3460 | AM4: =AL4+($AN4-$AI4)/5 -> 3480 | AN4: 3500 | AO4: =AN4+($AS4-$AN4)/5 -> 3500 | AP4: =AO4+($AS4-$AN4)/5 -> 3500 | AQ4: =AP4+($AS4-$AN4)/5 -> 3500 | AR4: =AQ4+($AS4-$AN4)/5 -> 3500 | AS4: 3500
A5: 黑色金属矿采选业 | B5: 铁矿石原矿 | C5: 亿吨 | D5: 产品产量与粗钢产量挂钩 | E5: 8.6672 | F5: 9.8053 | G5: 9.6787 | H5: =G5+($J5-$G5)/3 -> 10.445804 | I5: =H5+($J5-$G5)/3 -> 11.212909 | J5: =J18/G18*G5 -> 11.980013 | K5: =J5+($O5-$J5)/5 -> 12.246235 | L5: =K5+($O5-$J5)/5 -> 12.512458 | M5: =L5+($O5-$J5)/5 -> 12.77868 | N5: =M5+($O5-$J5)/5 -> 13.044903 | O5: =O18/J18*J5 -> 13.311125 | P5: =O5+($T5-$O5)/5 -> 13.330141 | Q5: =P5+($T5-$O5)/5 -> 13.349157 | R5: =Q5+($T5-$O5)/5 -> 13.368173 | S5: =R5+($T5-$O5)/5 -> 13.387189 | T5: =T18/O18*O5 -> 13.406205 | U5: =T5+($Y5-$T5)/5 -> 13.254078 | V5: =U5+($Y5-$T5)/5 -> 13.101951 | W5: =V5+($Y5-$T5)/5 -> 12.949824 | X5: =W5+($Y5-$T5)/5 -> 12.797696 | Y5: =Y18/T18*T5 -> 12.645569 | Z5: =Y5+($AD5-$Y5)/5 -> 12.360331 | AA5: =Z5+($AD5-$Y5)/5 -> 12.075092 | AB5: =AA5+($AD5-$Y5)/5 -> 11.789854 | AC5: =AB5+($AD5-$Y5)/5 -> 11.504616 | AD5: =AD18/Y18*Y5 -> 11.219377 | AE5: =AD5+($AI5-$AD5)/5 -> 10.934139 | AF5: =AE5+($AI5-$AD5)/5 -> 10.6489 | AG5: =AF5+($AI5-$AD5)/5 -> 10.363662 | AH5: =AG5+($AI5-$AD5)/5 -> 10.078424 | AI5: =AI18/AD18*AD5 -> 9.7931852 | AJ5: =AI5+($AN5-$AI5)/5 -> 9.5459786 | AK5: =AJ5+($AN5-$AI5)/5 -> 9.298772 | AL5: =AK5+($AN5-$AI5)/5 -> 9.0515653 | AM5: =AL5+($AN5-$AI5)/5 -> 8.8043587 | AN5: =AN18/AI18*AI5 -> 8.5571521 | AO5: =AN5+($AS5-$AN5)/5 -> 8.2975267 | AP5: =AO5+($AS5-$AN5)/5 -> 8.0379013 | AQ5: =AP5+($AS5-$AN5)/5 -> 7.7782758 | AR5: =AQ5+($AS5-$AN5)/5 -> 7.5186504 | AS5: =AS18/AN18*AN5 -> 7.259025
A6: 有色金属矿采选业 | B6: 铜矿 | C6: 万吨 | D6: 产量与精炼铜产量挂钩；https://www.wkqh.cn/ueditor/jsp/upload/file/20240603/1717376096015027949.pdf | E6: 172 | F6: 191 | G6: 194 | H6: =G6+($J6-$G6)/3 -> 219.50934 | I6: =H6+($J6-$G6)/3 -> 245.01867 | J6: =J20/G20*G6 -> 270.52801 | K6: =J6+($O6-$J6)/5 -> 282.7454 | L6: =K6+($O6-$J6)/5 -> 294.9628 | M6: =L6+($O6-$J6)/5 -> 307.18019 | N6: =M6+($O6-$J6)/5 -> 319.39759 | O6: =O20/J20*J6 -> 331.61498 | P6: =O6+($T6-$O6)/5 -> 338.59635 | Q6: =P6+($T6-$O6)/5 -> 345.57772 | R6: =Q6+($T6-$O6)/5 -> 352.55909 | S6: =R6+($T6-$O6)/5 -> 359.54045 | T6: =T20/O20*O6 -> 366.52182 | U6: =T6+($Y6-$T6)/5 -> 370.01251 | V6: =U6+($Y6-$T6)/5 -> 373.50319 | W6: =V6+($Y6-$T6)/5 -> 376.99387 | X6: =W6+($Y6-$T6)/5 -> 380.48456 | Y6: =Y20/T20*T6 -> 383.97524 | Z6: =Y6+($AD6-$Y6)/5 -> 385.72058 | AA6: =Z6+($AD6-$Y6)/5 -> 387.46593 | AB6: =AA6+($AD6-$Y6)/5 -> 389.21127 | AC6: =AB6+($AD6-$Y6)/5 -> 390.95661 | AD6: =AD20/Y20*Y6 -> 392.70195 | AE6: =AD6+($AI6-$AD6)/5 -> 394.44729 | AF6: =AE6+($AI6-$AD6)/5 -> 396.19264 | AG6: =AF6+($AI6-$AD6)/5 -> 397.93798 | AH6: =AG6+($AI6-$AD6)/5 -> 399.68332 | AI6: =AI20/AD20*AD6 -> 401.42866 | AJ6: =AI6+($AN6-$AI6)/5 -> 403.174 | AK6: =AJ6+($AN6-$AI6)/5 -> 404.91935 | AL6: =AK6+($AN6-$AI6)/5 -> 406.66469 | AM6: =AL6+($AN6-$AI6)/5 -> 408.41003 | AN6: =AN20/AI20*AI6 -> 410.15537 | AO6: =AN6+($AS6-$AN6)/5 -> 411.55165 | AP6: =AO6+($AS6-$AN6)/5 -> 412.94792 | AQ6: =AP6+($AS6-$AN6)/5 -> 414.34419 | AR6: =AQ6+($AS6-$AN6)/5 -> 415.74047 | AS6: =AS20/AN20*AN6 -> 417.13674
A7: 有色金属矿采选业 | B7: 铝土矿 | C7: 万吨 | D7: 产量与电解铝产量挂钩 | E7: 9269 | F7: 8500 | G7: 9000 | H7: =G7+($J7-$G7)/3 -> 9736.5205 | I7: =H7+($J7-$G7)/3 -> 10473.041 | J7: =J19/G19*G7 -> 11209.562 | K7: =J7+($O7-$J7)/5 -> 11792.459 | L7: =K7+($O7-$J7)/5 -> 12375.356 | M7: =L7+($O7-$J7)/5 -> 12958.253 | N7: =M7+($O7-$J7)/5 -> 13541.15 | O7: =O19/J19*J7 -> 14124.047 | P7: =O7+($T7-$O7)/5 -> 14437.915 | Q7: =P7+($T7-$O7)/5 -> 14751.783 | R7: =Q7+($T7-$O7)/5 -> 15065.651 | S7: =R7+($T7-$O7)/5 -> 15379.518 | T7: =T19/O19*O7 -> 15693.386 | U7: =T7+($Y7-$T7)/5 -> 15783.063 | V7: =U7+($Y7-$T7)/5 -> 15872.739 | W7: =V7+($Y7-$T7)/5 -> 15962.416 | X7: =W7+($Y7-$T7)/5 -> 16052.092 | Y7: =Y19/T19*T7 -> 16141.769 | Z7: =Y7+($AD7-$Y7)/5 -> 16096.93 | AA7: =Z7+($AD7-$Y7)/5 -> 16052.092 | AB7: =AA7+($AD7-$Y7)/5 -> 16007.254 | AC7: =AB7+($AD7-$Y7)/5 -> 15962.416 | AD7: =AD19/Y19*Y7 -> 15917.577 | AE7: =AD7+($AI7-$AD7)/5 -> 15693.386 | AF7: =AE7+($AI7-$AD7)/5 -> 15469.195 | AG7: =AF7+($AI7-$AD7)/5 -> 15245.004 | AH7: =AG7+($AI7-$AD7)/5 -> 15020.812 | AI7: =AI19/AD19*AD7 -> 14796.621 | AJ7: =AI7+($AN7-$AI7)/5 -> 14437.915 | AK7: =AJ7+($AN7-$AI7)/5 -> 14079.209 | AL7: =AK7+($AN7-$AI7)/5 -> 13720.503 | AM7: =AL7+($AN7-$AI7)/5 -> 13361.797 | AN7: =AN19/AI19*AI7 -> 13003.091 | AO7: =AN7+($AS7-$AN7)/5 -> 12644.385 | AP7: =AO7+($AS7-$AN7)/5 -> 12285.679 | AQ7: =AP7+($AS7-$AN7)/5 -> 11926.973 | AR7: =AQ7+($AS7-$AN7)/5 -> 11568.267 | AS7: =AS19/AN19*AN7 -> 11209.562
A8: 非金属矿采选业 | B8: 石灰石 | C8: 亿吨 | D8: 产品产量与水泥产量挂钩;https://www.sohu.com/a/716515038_121388092 | E8: 31.55 | F8: 31.4 | G8: 28.79 | H8: =G8+($J8-$G8)/3 -> 29.733239 | I8: =H8+($J8-$G8)/3 -> 30.676478 | J8: =J16/E16*E8 -> 31.619718 | K8: =J8+($O8-$J8)/5 -> 32.014964 | L8: =K8+($O8-$J8)/5 -> 32.41021 | M8: =L8+($O8-$J8)/5 -> 32.805457 | N8: =M8+($O8-$J8)/5 -> 33.200703 | O8: =O16/J16*J8 -> 33.59595 | P8: =O8+($T8-$O8)/5 -> 33.200703 | Q8: =P8+($T8-$O8)/5 -> 32.805457 | R8: =Q8+($T8-$O8)/5 -> 32.41021 | S8: =R8+($T8-$O8)/5 -> 32.014964 | T8: =T16/O16*O8 -> 31.619718 | U8: =T8+($Y8-$T8)/5 -> 31.066372 | V8: =U8+($Y8-$T8)/5 -> 30.513027 | W8: =V8+($Y8-$T8)/5 -> 29.959682 | X8: =W8+($Y8-$T8)/5 -> 29.406337 | Y8: =Y16/T16*T8 -> 28.852992 | Z8: =Y8+($AD8-$Y8)/5 -> 28.088849 | AA8: =Z8+($AD8-$Y8)/5 -> 27.324706 | AB8: =AA8+($AD8-$Y8)/5 -> 26.560563 | AC8: =AB8+($AD8-$Y8)/5 -> 25.79642 | AD8: =AD16/Y16*Y8 -> 25.032276 | AE8: =AD8+($AI8-$AD8)/5 -> 24.452582 | AF8: =AE8+($AI8-$AD8)/5 -> 23.872887 | AG8: =AF8+($AI8-$AD8)/5 -> 23.293192 | AH8: =AG8+($AI8-$AD8)/5 -> 22.713497 | AI8: =AI16/AD16*AD8 -> 22.133802 | AJ8: =AI8+($AN8-$AI8)/5 -> 21.791255 | AK8: =AJ8+($AN8-$AI8)/5 -> 21.448708 | AL8: =AK8+($AN8-$AI8)/5 -> 21.106161 | AM8: =AL8+($AN8-$AI8)/5 -> 20.763615 | AN8: =AN16/AI16*AI8 -> 20.421068 | AO8: =AN8+($AS8-$AN8)/5 -> 20.264261 | AP8: =AO8+($AS8-$AN8)/5 -> 20.107454 | AQ8: =AP8+($AS8-$AN8)/5 -> 19.950647 | AR8: =AQ8+($AS8-$AN8)/5 -> 19.793841 | AS8: =AS16/AN16*AN8 -> 19.637034
A9: 造纸和纸制品业 | B9: 纸和纸板 | C9: 万吨 | D9: 中国能源研究会-内部报告 | E9: 12700.63 | F9: 13583.87 | G9: 13691.4 | H9: =G9+($J9-$G9)/3 -> 14460.933 | I9: =H9+($J9-$G9)/3 -> 15230.467 | J9: 16000 | K9: =J9+($O9-$J9)/5 -> 16400 | L9: =K9+($O9-$J9)/5 -> 16800 | M9: =L9+($O9-$J9)/5 -> 17200 | N9: =M9+($O9-$J9)/5 -> 17600 | O9: 18000 | P9: =O9+($T9-$O9)/5 -> 18200 | Q9: =P9+($T9-$O9)/5 -> 18400 | R9: =Q9+($T9-$O9)/5 -> 18600 | S9: =R9+($T9-$O9)/5 -> 18800 | T9: 19000 | U9: =T9+($Y9-$T9)/5 -> 19100 | V9: =U9+($Y9-$T9)/5 -> 19200 | W9: =V9+($Y9-$T9)/5 -> 19300 | X9: =W9+($Y9-$T9)/5 -> 19400 | Y9: 19500 | Z9: =Y9+($AD9-$Y9)/5 -> 19400 | AA9: =Z9+($AD9-$Y9)/5 -> 19300 | AB9: =AA9+($AD9-$Y9)/5 -> 19200 | AC9: =AB9+($AD9-$Y9)/5 -> 19100 | AD9: 19000 | AE9: =AD9+($AI9-$AD9)/5 -> 18760 | AF9: =AE9+($AI9-$AD9)/5 -> 18520 | AG9: =AF9+($AI9-$AD9)/5 -> 18280 | AH9: =AG9+($AI9-$AD9)/5 -> 18040 | AI9: 17800 | AJ9: =AI9+($AN9-$AI9)/5 -> 17540 | AK9: =AJ9+($AN9-$AI9)/5 -> 17280 | AL9: =AK9+($AN9-$AI9)/5 -> 17020 | AM9: =AL9+($AN9-$AI9)/5 -> 16760 | AN9: 16500 | AO9: =AN9+($AS9-$AN9)/5 -> 16200 | AP9: =AO9+($AS9-$AN9)/5 -> 15900 | AQ9: =AP9+($AS9-$AN9)/5 -> 15600 | AR9: =AQ9+($AS9-$AN9)/5 -> 15300 | AS9: 15000
A10: 石油、煤炭及其他燃料加工业 | B10: 原油加工量 | C10: 亿吨 | D10: 加工量与原油产量挂钩 | E10: 6.7441 | F10: 7 | G10: 6.759 | H10: =G10+($J10-$G10)/3 -> 6.8941448 | I10: =H10+($J10-$G10)/3 -> 7.0292896 | J10: =J3/G3*G10 -> 7.1644343 | K10: =J10+($O10-$J10)/5 -> 7.1842438 | L10: =K10+($O10-$J10)/5 -> 7.2040533 | M10: =L10+($O10-$J10)/5 -> 7.2238628 | N10: =M10+($O10-$J10)/5 -> 7.2436723 | O10: =O3/J3*J10 -> 7.2634818 | P10: =O10+($T10-$O10)/5 -> 7.3163072 | Q10: =P10+($T10-$O10)/5 -> 7.3691325 | R10: =Q10+($T10-$O10)/5 -> 7.4219578 | S10: =R10+($T10-$O10)/5 -> 7.4747831 | T10: =T3/O3*O10 -> 7.5276084 | U10: =T10+($Y10-$T10)/5 -> 7.5408148 | V10: =U10+($Y10-$T10)/5 -> 7.5540211 | W10: =V10+($Y10-$T10)/5 -> 7.5672274 | X10: =W10+($Y10-$T10)/5 -> 7.5804338 | Y10: =Y3/T3*T10 -> 7.5936401 | Z10: =Y10+($AD10-$Y10)/5 -> 7.5276084 | AA10: =Z10+($AD10-$Y10)/5 -> 7.4615768 | AB10: =AA10+($AD10-$Y10)/5 -> 7.3955451 | AC10: =AB10+($AD10-$Y10)/5 -> 7.3295135 | AD10: =AD3/Y3*Y10 -> 7.2634818 | AE10: =AD10+($AI10-$AD10)/5 -> 7.1974502 | AF10: =AE10+($AI10-$AD10)/5 -> 7.1314185 | AG10: =AF10+($AI10-$AD10)/5 -> 7.0653869 | AH10: =AG10+($AI10-$AD10)/5 -> 6.9993552 | AI10: =AI3/AD3*AD10 -> 6.9333236 | AJ10: =AI10+($AN10-$AI10)/5 -> 6.8342761 | AK10: =AJ10+($AN10-$AI10)/5 -> 6.7352286 | AL10: =AK10+($AN10-$AI10)/5 -> 6.6361811 | AM10: =AL10+($AN10-$AI10)/5 -> 6.5371336 | AN10: =AN3/AI3*AI10 -> 6.4380862 | AO10: =AN10+($AS10-$AN10)/5 -> 6.3984672 | AP10: =AO10+($AS10-$AN10)/5 -> 6.3588482 | AQ10: =AP10+($AS10-$AN10)/5 -> 6.3192292 | AR10: =AQ10+($AS10-$AN10)/5 -> 6.2796102 | AS10: =AS3/AN3*AN10 -> 6.2399912
A11: 石油、煤炭及其他燃料加工业 | B11: 焦炭 | C11: 万吨 | D11: 焦炭产量与钢铁产量挂钩 | E11: 47116 | F11: 46400 | G11: 47300 | H11: =G11+($J11-$G11)/3 -> 51048.854 | I11: =H11+($J11-$G11)/3 -> 54797.708 | J11: =J18/G18*G11 -> 58546.562 | K11: =J11+($O11-$J11)/5 -> 59847.597 | L11: =K11+($O11-$J11)/5 -> 61148.632 | M11: =L11+($O11-$J11)/5 -> 62449.666 | N11: =M11+($O11-$J11)/5 -> 63750.701 | O11: =O18/J18*J11 -> 65051.736 | P11: =O11+($T11-$O11)/5 -> 65144.667 | Q11: =P11+($T11-$O11)/5 -> 65237.598 | R11: =Q11+($T11-$O11)/5 -> 65330.529 | S11: =R11+($T11-$O11)/5 -> 65423.46 | T11: =T18/O18*O11 -> 65516.391 | U11: =T11+($Y11-$T11)/5 -> 64772.943 | V11: =U11+($Y11-$T11)/5 -> 64029.494 | W11: =V11+($Y11-$T11)/5 -> 63286.046 | X11: =W11+($Y11-$T11)/5 -> 62542.597 | Y11: =Y18/T18*T11 -> 61799.149 | Z11: =Y11+($AD11-$Y11)/5 -> 60405.183 | AA11: =Z11+($AD11-$Y11)/5 -> 59011.218 | AB11: =AA11+($AD11-$Y11)/5 -> 57617.252 | AC11: =AB11+($AD11-$Y11)/5 -> 56223.286 | AD11: =AD18/Y18*Y11 -> 54829.32 | AE11: =AD11+($AI11-$AD11)/5 -> 53435.354 | AF11: =AE11+($AI11-$AD11)/5 -> 52041.389 | AG11: =AF11+($AI11-$AD11)/5 -> 50647.423 | AH11: =AG11+($AI11-$AD11)/5 -> 49253.457 | AI11: =AI18/AD18*AD11 -> 47859.491 | AJ11: =AI11+($AN11-$AI11)/5 -> 46651.388 | AK11: =AJ11+($AN11-$AI11)/5 -> 45443.284 | AL11: =AK11+($AN11-$AI11)/5 -> 44235.18 | AM11: =AL11+($AN11-$AI11)/5 -> 43027.077 | AN11: =AN18/AI18*AI11 -> 41818.973 | AO11: =AN11+($AS11-$AN11)/5 -> 40550.178 | AP11: =AO11+($AS11-$AN11)/5 -> 39281.384 | AQ11: =AP11+($AS11-$AN11)/5 -> 38012.589 | AR11: =AQ11+($AS11-$AN11)/5 -> 36743.795 | AS11: =AS18/AN18*AN11 -> 35475
A12: 化学原料和化学制品制造业 | B12: 烧碱 | C12: 万吨 | D12: 中国能源研究会-内部报告 | E12: 3673.87 | F12: 3891.31 | G12: 3463.08 | H12: =G12+($J12-$G12)/3 -> 3842.0533 | I12: =H12+($J12-$G12)/3 -> 4221.0267 | J12: 4600 | K12: =J12+($O12-$J12)/5 -> 4800 | L12: =K12+($O12-$J12)/5 -> 5000 | M12: =L12+($O12-$J12)/5 -> 5200 | N12: =M12+($O12-$J12)/5 -> 5400 | O12: 5600 | P12: =O12+($T12-$O12)/5 -> 5720 | Q12: =P12+($T12-$O12)/5 -> 5840 | R12: =Q12+($T12-$O12)/5 -> 5960 | S12: =R12+($T12-$O12)/5 -> 6080 | T12: 6200 | U12: =T12+($Y12-$T12)/5 -> 6260 | V12: =U12+($Y12-$T12)/5 -> 6320 | W12: =V12+($Y12-$T12)/5 -> 6380 | X12: =W12+($Y12-$T12)/5 -> 6440 | Y12: 6500 | Z12: =Y12+($AD12-$Y12)/5 -> 6520 | AA12: =Z12+($AD12-$Y12)/5 -> 6540 | AB12: =AA12+($AD12-$Y12)/5 -> 6560 | AC12: =AB12+($AD12-$Y12)/5 -> 6580 | AD12: 6600 | AE12: =AD12+($AI12-$AD12)/5 -> 6580 | AF12: =AE12+($AI12-$AD12)/5 -> 6560 | AG12: =AF12+($AI12-$AD12)/5 -> 6540 | AH12: =AG12+($AI12-$AD12)/5 -> 6520 | AI12: 6500 | AJ12: =AI12+($AN12-$AI12)/5 -> 6440 | AK12: =AJ12+($AN12-$AI12)/5 -> 6380 | AL12: =AK12+($AN12-$AI12)/5 -> 6320 | AM12: =AL12+($AN12-$AI12)/5 -> 6260 | AN12: 6200 | AO12: =AN12+($AS12-$AN12)/5 -> 6120 | AP12: =AO12+($AS12-$AN12)/5 -> 6040 | AQ12: =AP12+($AS12-$AN12)/5 -> 5960 | AR12: =AQ12+($AS12-$AN12)/5 -> 5880 | AS12: 5800
A13: 化学原料和化学制品制造业 | B13: 纯碱 | C13: 万吨 | D13: 中国能源研究会-内部报告 | E13: 2812.37 | F13: 2913.25 | G13: 2920.2 | H13: =G13+($J13-$G13)/3 -> 3146.8 | I13: =H13+($J13-$G13)/3 -> 3373.4 | J13: 3600 | K13: =J13+($O13-$J13)/5 -> 3760 | L13: =K13+($O13-$J13)/5 -> 3920 | M13: =L13+($O13-$J13)/5 -> 4080 | N13: =M13+($O13-$J13)/5 -> 4240 | O13: 4400 | P13: =O13+($T13-$O13)/5 -> 4480 | Q13: =P13+($T13-$O13)/5 -> 4560 | R13: =Q13+($T13-$O13)/5 -> 4640 | S13: =R13+($T13-$O13)/5 -> 4720 | T13: 4800 | U13: =T13+($Y13-$T13)/5 -> 4820 | V13: =U13+($Y13-$T13)/5 -> 4840 | W13: =V13+($Y13-$T13)/5 -> 4860 | X13: =W13+($Y13-$T13)/5 -> 4880 | Y13: 4900 | Z13: =Y13+($AD13-$Y13)/5 -> 4890 | AA13: =Z13+($AD13-$Y13)/5 -> 4880 | AB13: =AA13+($AD13-$Y13)/5 -> 4870 | AC13: =AB13+($AD13-$Y13)/5 -> 4860 | AD13: 4850 | AE13: =AD13+($AI13-$AD13)/5 -> 4820 | AF13: =AE13+($AI13-$AD13)/5 -> 4790 | AG13: =AF13+($AI13-$AD13)/5 -> 4760 | AH13: =AG13+($AI13-$AD13)/5 -> 4730 | AI13: 4700 | AJ13: =AI13+($AN13-$AI13)/5 -> 4660 | AK13: =AJ13+($AN13-$AI13)/5 -> 4620 | AL13: =AK13+($AN13-$AI13)/5 -> 4580 | AM13: =AL13+($AN13-$AI13)/5 -> 4540 | AN13: 4500 | AO13: =AN13+($AS13-$AN13)/5 -> 4440 | AP13: =AO13+($AS13-$AN13)/5 -> 4380 | AQ13: =AP13+($AS13-$AN13)/5 -> 4320 | AR13: =AQ13+($AS13-$AN13)/5 -> 4260 | AS13: 4200
A14: 化学原料和化学制品制造业 | B14: 乙烯 | C14: 万吨 | D14: 中国能源研究会-内部报告 | E14: 2159.96 | F14: 2825.67 | G14: 2897.51 | H14: =G14+($J14-$G14)/3 -> 3398.34 | I14: =H14+($J14-$G14)/3 -> 3899.17 | J14: 4400 | K14: =J14+($O14-$J14)/5 -> 4600 | L14: =K14+($O14-$J14)/5 -> 4800 | M14: =L14+($O14-$J14)/5 -> 5000 | N14: =M14+($O14-$J14)/5 -> 5200 | O14: 5400 | P14: =O14+($T14-$O14)/5 -> 5520 | Q14: =P14+($T14-$O14)/5 -> 5640 | R14: =Q14+($T14-$O14)/5 -> 5760 | S14: =R14+($T14-$O14)/5 -> 5880 | T14: 6000 | U14: =T14+($Y14-$T14)/5 -> 6060 | V14: =U14+($Y14-$T14)/5 -> 6120 | W14: =V14+($Y14-$T14)/5 -> 6180 | X14: =W14+($Y14-$T14)/5 -> 6240 | Y14: 6300 | Z14: =Y14+($AD14-$Y14)/5 -> 6320 | AA14: =Z14+($AD14-$Y14)/5 -> 6340 | AB14: =AA14+($AD14-$Y14)/5 -> 6360 | AC14: =AB14+($AD14-$Y14)/5 -> 6380 | AD14: 6400 | AE14: =AD14+($AI14-$AD14)/5 -> 6360 | AF14: =AE14+($AI14-$AD14)/5 -> 6320 | AG14: =AF14+($AI14-$AD14)/5 -> 6280 | AH14: =AG14+($AI14-$AD14)/5 -> 6240 | AI14: 6200 | AJ14: =AI14+($AN14-$AI14)/5 -> 6140 | AK14: =AJ14+($AN14-$AI14)/5 -> 6080 | AL14: =AK14+($AN14-$AI14)/5 -> 6020 | AM14: =AL14+($AN14-$AI14)/5 -> 5960 | AN14: 5900 | AO14: =AN14+($AS14-$AN14)/5 -> 5850 | AP14: =AO14+($AS14-$AN14)/5 -> 5800 | AQ14: =AP14+($AS14-$AN14)/5 -> 5750 | AR14: =AQ14+($AS14-$AN14)/5 -> 5700 | AS14: 5650
A15: 化学原料和化学制品制造业 | B15: 合成氨 | C15: 万吨 | D15: 中国能源研究会-内部报告 | E15: 5117.13 | F15: 5189.38 | G15: 5321.01 | H15: =G15+($J15-$G15)/3 -> 5647.34 | I15: =H15+($J15-$G15)/3 -> 5973.67 | J15: 6300 | K15: =J15+($O15-$J15)/5 -> 6480 | L15: =K15+($O15-$J15)/5 -> 6660 | M15: =L15+($O15-$J15)/5 -> 6840 | N15: =M15+($O15-$J15)/5 -> 7020 | O15: 7200 | P15: =O15+($T15-$O15)/5 -> 7300 | Q15: =P15+($T15-$O15)/5 -> 7400 | R15: =Q15+($T15-$O15)/5 -> 7500 | S15: =R15+($T15-$O15)/5 -> 7600 | T15: 7700 | U15: =T15+($Y15-$T15)/5 -> 7760 | V15: =U15+($Y15-$T15)/5 -> 7820 | W15: =V15+($Y15-$T15)/5 -> 7880 | X15: =W15+($Y15-$T15)/5 -> 7940 | Y15: 8000 | Z15: =Y15+($AD15-$Y15)/5 -> 8040 | AA15: =Z15+($AD15-$Y15)/5 -> 8080 | AB15: =AA15+($AD15-$Y15)/5 -> 8120 | AC15: =AB15+($AD15-$Y15)/5 -> 8160 | AD15: 8200 | AE15: =AD15+($AI15-$AD15)/5 -> 8240 | AF15: =AE15+($AI15-$AD15)/5 -> 8280 | AG15: =AF15+($AI15-$AD15)/5 -> 8320 | AH15: =AG15+($AI15-$AD15)/5 -> 8360 | AI15: 8400 | AJ15: =AI15+($AN15-$AI15)/5 -> 8420 | AK15: =AJ15+($AN15-$AI15)/5 -> 8440 | AL15: =AK15+($AN15-$AI15)/5 -> 8460 | AM15: =AL15+($AN15-$AI15)/5 -> 8480 | AN15: 8500 | AO15: =AN15+($AS15-$AN15)/5 -> 8520 | AP15: =AO15+($AS15-$AN15)/5 -> 8540 | AQ15: =AP15+($AS15-$AN15)/5 -> 8560 | AR15: =AQ15+($AS15-$AN15)/5 -> 8580 | AS15: 8600
A16: 非金属矿物制品业 | B16: 水泥 | C16: 万吨 | D16: 中国能源研究会-内部报告 | E16: 239470.83 | F16: 237724.49 | G16: 212927.18 | H16: =G16+($J16-$G16)/3 -> 221951.45 | I16: =H16+($J16-$G16)/3 -> 230975.73 | J16: 240000 | K16: =J16+($O16-$J16)/5 -> 243000 | L16: =K16+($O16-$J16)/5 -> 246000 | M16: =L16+($O16-$J16)/5 -> 249000 | N16: =M16+($O16-$J16)/5 -> 252000 | O16: 255000 | P16: =O16+($T16-$O16)/5 -> 252000 | Q16: =P16+($T16-$O16)/5 -> 249000 | R16: =Q16+($T16-$O16)/5 -> 246000 | S16: =R16+($T16-$O16)/5 -> 243000 | T16: 240000 | U16: =T16+($Y16-$T16)/5 -> 235800 | V16: =U16+($Y16-$T16)/5 -> 231600 | W16: =V16+($Y16-$T16)/5 -> 227400 | X16: =W16+($Y16-$T16)/5 -> 223200 | Y16: 219000 | Z16: =Y16+($AD16-$Y16)/5 -> 213200 | AA16: =Z16+($AD16-$Y16)/5 -> 207400 | AB16: =AA16+($AD16-$Y16)/5 -> 201600 | AC16: =AB16+($AD16-$Y16)/5 -> 195800 | AD16: 190000 | AE16: =AD16+($AI16-$AD16)/5 -> 185600 | AF16: =AE16+($AI16-$AD16)/5 -> 181200 | AG16: =AF16+($AI16-$AD16)/5 -> 176800 | AH16: =AG16+($AI16-$AD16)/5 -> 172400 | AI16: 168000 | AJ16: =AI16+($AN16-$AI16)/5 -> 165400 | AK16: =AJ16+($AN16-$AI16)/5 -> 162800 | AL16: =AK16+($AN16-$AI16)/5 -> 160200 | AM16: =AL16+($AN16-$AI16)/5 -> 157600 | AN16: 155000 | AO16: =AN16+($AS16-$AN16)/5 -> 153809.81 | AP16: =AO16+($AS16-$AN16)/5 -> 152619.61 | AQ16: =AP16+($AS16-$AN16)/5 -> 151429.42 | AR16: =AQ16+($AS16-$AN16)/5 -> 150239.22 | AS16: =G16*0.7 -> 149049.03
A17: 非金属矿物制品业 | B17: 平板玻璃 | C17: 万重量厢 | D17: 中国能源研究会-内部报告 | E17: 95227.79 | F17: 101727.37 | G17: 101668.65 | H17: =G17+($J17-$G17)/3 -> 107779.1 | I17: =H17+($J17-$G17)/3 -> 113889.55 | J17: 120000 | K17: =J17+($O17-$J17)/5 -> 122000 | L17: =K17+($O17-$J17)/5 -> 124000 | M17: =L17+($O17-$J17)/5 -> 126000 | N17: =M17+($O17-$J17)/5 -> 128000 | O17: 130000 | P17: =O17+($T17-$O17)/5 -> 129800 | Q17: =P17+($T17-$O17)/5 -> 129600 | R17: =Q17+($T17-$O17)/5 -> 129400 | S17: =R17+($T17-$O17)/5 -> 129200 | T17: 129000 | U17: =T17+($Y17-$T17)/5 -> 127800 | V17: =U17+($Y17-$T17)/5 -> 126600 | W17: =V17+($Y17-$T17)/5 -> 125400 | X17: =W17+($Y17-$T17)/5 -> 124200 | Y17: 123000 | Z17: =Y17+($AD17-$Y17)/5 -> 121800 | AA17: =Z17+($AD17-$Y17)/5 -> 120600 | AB17: =AA17+($AD17-$Y17)/5 -> 119400 | AC17: =AB17+($AD17-$Y17)/5 -> 118200 | AD17: 117000 | AE17: =AD17+($AI17-$AD17)/5 -> 115200 | AF17: =AE17+($AI17-$AD17)/5 -> 113400 | AG17: =AF17+($AI17-$AD17)/5 -> 111600 | AH17: =AG17+($AI17-$AD17)/5 -> 109800 | AI17: 108000 | AJ17: =AI17+($AN17-$AI17)/5 -> 106400 | AK17: =AJ17+($AN17-$AI17)/5 -> 104800 | AL17: =AK17+($AN17-$AI17)/5 -> 103200 | AM17: =AL17+($AN17-$AI17)/5 -> 101600 | AN17: 100000 | AO17: =AN17+($AS17-$AN17)/5 -> 98000 | AP17: =AO17+($AS17-$AN17)/5 -> 96000 | AQ17: =AP17+($AS17-$AN17)/5 -> 94000 | AR17: =AQ17+($AS17-$AN17)/5 -> 92000 | AS17: 90000
A18: 黑色金属冶炼和压延加工业 | B18: 钢铁 | C18: 万吨 | D18: 中国能源研究会-内部报告 | E18: 106476.68 | F18: 103524.26 | G18: 101795.9 | H18: =G18+($J18-$G18)/3 -> 109863.93 | I18: =H18+($J18-$G18)/3 -> 117931.97 | J18: 126000 | K18: =J18+($O18-$J18)/5 -> 128800 | L18: =K18+($O18-$J18)/5 -> 131600 | M18: =L18+($O18-$J18)/5 -> 134400 | N18: =M18+($O18-$J18)/5 -> 137200 | O18: 140000 | P18: =O18+($T18-$O18)/5 -> 140200 | Q18: =P18+($T18-$O18)/5 -> 140400 | R18: =Q18+($T18-$O18)/5 -> 140600 | S18: =R18+($T18-$O18)/5 -> 140800 | T18: 141000 | U18: =T18+($Y18-$T18)/5 -> 139400 | V18: =U18+($Y18-$T18)/5 -> 137800 | W18: =V18+($Y18-$T18)/5 -> 136200 | X18: =W18+($Y18-$T18)/5 -> 134600 | Y18: 133000 | Z18: =Y18+($AD18-$Y18)/5 -> 130000 | AA18: =Z18+($AD18-$Y18)/5 -> 127000 | AB18: =AA18+($AD18-$Y18)/5 -> 124000 | AC18: =AB18+($AD18-$Y18)/5 -> 121000 | AD18: 118000 | AE18: =AD18+($AI18-$AD18)/5 -> 115000 | AF18: =AE18+($AI18-$AD18)/5 -> 112000 | AG18: =AF18+($AI18-$AD18)/5 -> 109000 | AH18: =AG18+($AI18-$AD18)/5 -> 106000 | AI18: 103000 | AJ18: =AI18+($AN18-$AI18)/5 -> 100400 | AK18: =AJ18+($AN18-$AI18)/5 -> 97800 | AL18: =AK18+($AN18-$AI18)/5 -> 95200 | AM18: =AL18+($AN18-$AI18)/5 -> 92600 | AN18: 90000 | AO18: =AN18+($AS18-$AN18)/5 -> 87269.385 | AP18: =AO18+($AS18-$AN18)/5 -> 84538.77 | AQ18: =AP18+($AS18-$AN18)/5 -> 81808.155 | AR18: =AQ18+($AS18-$AN18)/5 -> 79077.54 | AS18: =G18*0.75 -> 76346.925
A19: 有色金属冶炼和压延加工业 | B19: 电解铝 | C19: 万吨 | D19: 中国能源研究会-内部报告 | E19: 3708.04 | F19: 3850.32 | G19: 4014.43 | H19: =G19+($J19-$G19)/3 -> 4342.9533 | I19: =H19+($J19-$G19)/3 -> 4671.4767 | J19: 5000 | K19: =J19+($O19-$J19)/5 -> 5260 | L19: =K19+($O19-$J19)/5 -> 5520 | M19: =L19+($O19-$J19)/5 -> 5780 | N19: =M19+($O19-$J19)/5 -> 6040 | O19: 6300 | P19: =O19+($T19-$O19)/5 -> 6440 | Q19: =P19+($T19-$O19)/5 -> 6580 | R19: =Q19+($T19-$O19)/5 -> 6720 | S19: =R19+($T19-$O19)/5 -> 6860 | T19: 7000 | U19: =T19+($Y19-$T19)/5 -> 7040 | V19: =U19+($Y19-$T19)/5 -> 7080 | W19: =V19+($Y19-$T19)/5 -> 7120 | X19: =W19+($Y19-$T19)/5 -> 7160 | Y19: 7200 | Z19: =Y19+($AD19-$Y19)/5 -> 7180 | AA19: =Z19+($AD19-$Y19)/5 -> 7160 | AB19: =AA19+($AD19-$Y19)/5 -> 7140 | AC19: =AB19+($AD19-$Y19)/5 -> 7120 | AD19: 7100 | AE19: =AD19+($AI19-$AD19)/5 -> 7000 | AF19: =AE19+($AI19-$AD19)/5 -> 6900 | AG19: =AF19+($AI19-$AD19)/5 -> 6800 | AH19: =AG19+($AI19-$AD19)/5 -> 6700 | AI19: 6600 | AJ19: =AI19+($AN19-$AI19)/5 -> 6440 | AK19: =AJ19+($AN19-$AI19)/5 -> 6280 | AL19: =AK19+($AN19-$AI19)/5 -> 6120 | AM19: =AL19+($AN19-$AI19)/5 -> 5960 | AN19: 5800 | AO19: =AN19+($AS19-$AN19)/5 -> 5640 | AP19: =AO19+($AS19-$AN19)/5 -> 5480 | AQ19: =AP19+($AS19-$AN19)/5 -> 5320 | AR19: =AQ19+($AS19-$AN19)/5 -> 5160 | AS19: 5000
A20: 有色金属冶炼和压延加工业 | B20: 精炼铜 | C20: 万吨 | D20: 拍数 | E20: 1002.51 | F20: 1048.67 | G20: 1111.53 | H20: =G20+($J20-$G20)/3 -> 1257.6867 | I20: =H20+($J20-$G20)/3 -> 1403.8433 | J20: 1550 | K20: =J20+($O20-$J20)/5 -> 1620 | L20: =K20+($O20-$J20)/5 -> 1690 | M20: =L20+($O20-$J20)/5 -> 1760 | N20: =M20+($O20-$J20)/5 -> 1830 | O20: 1900 | P20: =O20+($T20-$O20)/5 -> 1940 | Q20: =P20+($T20-$O20)/5 -> 1980 | R20: =Q20+($T20-$O20)/5 -> 2020 | S20: =R20+($T20-$O20)/5 -> 2060 | T20: 2100 | U20: =T20+($Y20-$T20)/5 -> 2120 | V20: =U20+($Y20-$T20)/5 -> 2140 | W20: =V20+($Y20-$T20)/5 -> 2160 | X20: =W20+($Y20-$T20)/5 -> 2180 | Y20: 2200 | Z20: =Y20+($AD20-$Y20)/5 -> 2210 | AA20: =Z20+($AD20-$Y20)/5 -> 2220 | AB20: =AA20+($AD20-$Y20)/5 -> 2230 | AC20: =AB20+($AD20-$Y20)/5 -> 2240 | AD20: 2250 | AE20: =AD20+($AI20-$AD20)/5 -> 2260 | AF20: =AE20+($AI20-$AD20)/5 -> 2270 | AG20: =AF20+($AI20-$AD20)/5 -> 2280 | AH20: =AG20+($AI20-$AD20)/5 -> 2290 | AI20: 2300 | AJ20: =AI20+($AN20-$AI20)/5 -> 2310 | AK20: =AJ20+($AN20-$AI20)/5 -> 2320 | AL20: =AK20+($AN20-$AI20)/5 -> 2330 | AM20: =AL20+($AN20-$AI20)/5 -> 2340 | AN20: 2350 | AO20: =AN20+($AS20-$AN20)/5 -> 2358 | AP20: =AO20+($AS20-$AN20)/5 -> 2366 | AQ20: =AP20+($AS20-$AN20)/5 -> 2374 | AR20: =AQ20+($AS20-$AN20)/5 -> 2382 | AS20: 2390
A21: 汽车制造业 | B21: 汽车 | C21: 万辆 | D21: 2023节能与新能源汽车发展报告-结果微调 | E21: 2532.49 | F21: 2625.7 | G21: 2713.63 | H21: =G21+($J21-$G21)/3 -> 2948.7072 | I21: =H21+($J21-$G21)/3 -> 3183.7843 | J21: =E21*(2700/2000) -> 3418.8615 | K21: =J21+($O21-$J21)/5 -> 3520.1611 | L21: =K21+($O21-$J21)/5 -> 3621.4607 | M21: =L21+($O21-$J21)/5 -> 3722.7603 | N21: =M21+($O21-$J21)/5 -> 3824.0599 | O21: =J21*(3100/2700) -> 3925.3595 | P21: =O21+($T21-$O21)/5 -> 3976.0093 | Q21: =P21+($T21-$O21)/5 -> 4026.6591 | R21: =Q21+($T21-$O21)/5 -> 4077.3089 | S21: =R21+($T21-$O21)/5 -> 4127.9587 | T21: =O21*(3300/3100) -> 4178.6085 | U21: =T21+($Y21-$T21)/5 -> 4165.946 | V21: =U21+($Y21-$T21)/5 -> 4153.2836 | W21: =V21+($Y21-$T21)/5 -> 4140.6211 | X21: =W21+($Y21-$T21)/5 -> 4127.9587 | Y21: =T21*(3250/3300) -> 4115.2962 | Z21: =Y21+($AD21-$Y21)/5 -> 4102.6338 | AA21: =Z21+($AD21-$Y21)/5 -> 4089.9713 | AB21: =AA21+($AD21-$Y21)/5 -> 4077.3089 | AC21: =AB21+($AD21-$Y21)/5 -> 4064.6465 | AD21: =Y21*(3200/3250) -> 4051.984 | AE21: =AD21+($AI21-$AD21)/5 -> 4039.3215 | AF21: =AE21+($AI21-$AD21)/5 -> 4026.6591 | AG21: =AF21+($AI21-$AD21)/5 -> 4013.9967 | AH21: =AG21+($AI21-$AD21)/5 -> 4001.3342 | AI21: =AD21*(3150/3200) -> 3988.6717 | AJ21: =AI21+($AN21-$AI21)/5 -> 3983.6068 | AK21: =AJ21+($AN21-$AI21)/5 -> 3978.5418 | AL21: =AK21+($AN21-$AI21)/5 -> 3973.4768 | AM21: =AL21+($AN21-$AI21)/5 -> 3968.4118 | AN21: =AI21*(3130/3150) -> 3963.3468 | AO21: =AN21+($AS21-$AN21)/5 -> 3955.7494 | AP21: =AO21+($AS21-$AN21)/5 -> 3948.1519 | AQ21: =AP21+($AS21-$AN21)/5 -> 3940.5544 | AR21: =AQ21+($AS21-$AN21)/5 -> 3932.957 | AS21: =AN21*(3100/3130) -> 3925.3595
A25: 用于BPE
A26: 行业 | B26: 温室气体 | C26: 产品产量 | D26: 单位 | E26: 数据来源 | F26: 2018 | G26: 2019 | H26: 2020 | I26: 2021 | J26: 2022 | K26: 2023 | L26: 2024 | M26: 2025 | N26: 2026 | O26: 2027 | P26: 2028 | Q26: 2029 | R26: 2030 | S26: 2031 | T26: 2032 | U26: 2033 | V26: 2034 | W26: 2035 | X26: 2036 | Y26: 2037 | Z26: 2038 | AA26: 2039 | AB26: 2040 | AC26: 2041 | AD26: 2042 | AE26: 2043 | AF26: 2044 | AG26: 2045 | AH26: 2046 | AI26: 2047 | AJ26: 2048 | AK26: 2049 | AL26: 2050 | AM26: 2051 | AN26: 2052 | AO26: 2053 | AP26: 2054 | AQ26: 2055 | AR26: 2056 | AS26: 2057 | AT26: 2058 | AU26: 2059 | AV26: 2060
A27: 农、林、牧、渔业 | B27: CH4+N2O | C27: 人口 | D27: 亿人 | E27: WR | F27: =F40 -> 13.9538 | G27: =G40 -> 14.007931 | H27: =H40 -> 14.131352 | I27: =I40 -> 14.16016 | J27: =J40 -> 14.188968 | K27: =K40 -> 14.217777 | L27: =L40 -> 14.246585 | M27: =M40 -> 14.275393 | ... AV27: =AV40 -> 12.351956
A28: 煤炭开采和洗选业 | B28: CH4 | C28: 原煤 | D28: 亿吨 | E28: 中石化《中国能源展望2060》 | F28: 36.98 | G28: 38.46 | H28: =E2 -> 39.02 | I28: =F2 -> 41.26 | J28: =G2 -> 45.59 | K28: =H2 -> 46.726667 | L28: =I2 -> 47.863333 | M28: =J2 -> 49 | N28: =K2 -> 49.8 | O28: =L2 -> 50.6 | ... AV28: =AS2 -> 35
A29: 石油和天然气开采业 | B29: CH4 | C29: 原油 | D29: 亿吨 | E29: 中石油《世界与中国能源展望2021》 | F29: 1.8932 | G29: 1.9101 | H29: =E3 -> 1.9477 | I29: =F3 -> 1.9888 | J29: =G3 -> 2.0472 | K29: =H3 -> 2.0881333 | L29: =I3 -> 2.1290667 | M29: =J3 -> 2.17 | N29: =K3 -> 2.176 | O29: =L3 -> 2.182 | ... AV29: =AS3 -> 1.89
A30: 石油和天然气开采业 | B30: CH4 | C30: 天然气 | D30: 亿立方米 | E30: 中石油《世界与中国能源展望2021》 | F30: 1601.59 | G30: 1761.74 | H30: =E4 -> 1924.95 | I30: =F4 -> 2075.84 | J30: =G4 -> 2201.1 | K30: =H4 -> 2298.4 | L30: =I4 -> 2395.7 | M30: =J4 -> 2493 | N30: =K4 -> 2554.4 | O30: =L4 -> 2615.8 | ... AV30: =AS4 -> 3500
A31: 石油、煤炭及其他燃料加工业 | B31: CO2 | C31: 原油加工 | D31: 亿吨 | E31: 加工量与原油产量挂钩 | F31: 6 | G31: 6.5 | H31: =E10 -> 6.7441 | I31: =F10 -> 7 | J31: =G10 -> 6.759 | K31: =H10 -> 6.8941448 | L31: =I10 -> 7.0292896 | M31: =J10 -> 7.1644343 | N31: =K10 -> 7.1842438 | O31: =L10 -> 7.2040533 | ... AV31: =AS10 -> 6.2399912
A32: 化学原料和化学制品制造业 | B32: CO2 | C32: 电石 | D32: 万吨 | E32: 拍数 | F32: 2688.48 | G32: 2522.49 | H32: 2795 | I32: 2820 | J32: 2850 | K32: =J32+($M32-$J32)/3 -> 2966.6667 | L32: =K32+($M32-$J32)/3 -> 3083.3333 | M32: 3200 | N32: =M32+($R32-$M32)/5 -> 3280 | O32: =N32+($R32-$M32)/5 -> 3360 | P32: =O32+($R32-$M32)/5 -> 3440 | Q32: =P32+($R32-$M32)/5 -> 3520 | R32: 3600 | S32: =R32+($W32-$R32)/5 -> 3630 | T32: =S32+($W32-$R32)/5 -> 3660 | U32: =T32+($W32-$R32)/5 -> 3690 | V32: =U32+($W32-$R32)/5 -> 3720 | W32: 3750 | X32: =W32+($AG32-$W32)/10 -> 3735 | Y32: =X32+($AG32-$W32)/10 -> 3720 | Z32: =Y32+($AG32-$W32)/10 -> 3705 | AA32: =Z32+($AG32-$W32)/10 -> 3690 | AB32: =AA32+($AG32-$W32)/10 -> 3675 | AC32: =AB32+($AG32-$W32)/10 -> 3660 | AD32: =AC32+($AG32-$W32)/10 -> 3645 | AE32: =AD32+($AG32-$W32)/10 -> 3630 | AF32: =AE32+($AG32-$W32)/10 -> 3615 | AG32: 3600 | AH32: =AG32+($AV32-$AG32)/15 -> 3573.3333 | AI32: =AH32+($AV32-$AG32)/15 -> 3546.6667 | AJ32: =AI32+($AV32-$AG32)/15 -> 3520 | AK32: =AJ32+($AV32-$AG32)/15 -> 3493.3333 | AL32: =AK32+($AV32-$AG32)/15 -> 3466.6667 | AM32: =AL32+($AV32-$AG32)/15 -> 3440 | AN32: =AM32+($AV32-$AG32)/15 -> 3413.3333 | AO32: =AN32+($AV32-$AG32)/15 -> 3386.6667 | ... AU32: =AT32+($AV32-$AG32)/15 -> 3226.6667 | AV32: 3200
A33: 化学原料和化学制品制造业 | B33: N2O | C33: 己二酸 | D33: 万吨 | E33: 拍数 | F33: 137.54 | G33: 140.04 | H33: 155.71 | I33: 189 | J33: =I33+($M33-$I33)/4 -> 204.25 | K33: =J33+($M33-$I33)/4 -> 219.5 | L33: =K33+($M33-$I33)/4 -> 234.75 | M33: 250 | N33: =M33+($W33-$M33)/10 -> 254 | O33: =N33+($W33-$M33)/10 -> 258 | P33: =O33+($W33-$M33)/10 -> 262 | Q33: =P33+($W33-$M33)/10 -> 266 | R33: =Q33+($W33-$M33)/10 -> 270 | S33: =R33+($W33-$M33)/10 -> 274 | T33: =S33+($W33-$M33)/10 -> 278 | U33: =T33+($W33-$M33)/10 -> 282 | V33: =U33+($W33-$M33)/10 -> 286 | W33: 290 | X33: =W33+($AG33-$W33)/10 -> 288 | Y33: =X33+($AG33-$W33)/10 -> 286 | Z33: =Y33+($AG33-$W33)/10 -> 284 | AA33: =Z33+($AG33-$W33)/10 -> 282 | AB33: =AA33+($AG33-$W33)/10 -> 280 | AC33: =AB33+($AG33-$W33)/10 -> 278 | AD33: =AC33+($AG33-$W33)/10 -> 276 | AE33: =AD33+($AG33-$W33)/10 -> 274 | AF33: =AE33+($AG33-$W33)/10 -> 272 | AG33: 270 | AH33: =AG33+($AV33-$AG33)/15 -> 266.66667 | AI33: =AH33+($AV33-$AG33)/15 -> 263.33333 | AJ33: =AI33+($AV33-$AG33)/15 -> 260 | AK33: =AJ33+($AV33-$AG33)/15 -> 256.66667 | AL33: =AK33+($AV33-$AG33)/15 -> 253.33333 | AM33: =AL33+($AV33-$AG33)/15 -> 250 | AN33: =AM33+($AV33-$AG33)/15 -> 246.66667 | AO33: =AN33+($AV33-$AG33)/15 -> 243.33333 | ... AU33: =AT33+($AV33-$AG33)/15 -> 223.33333 | AV33: 220
A34: 化学原料和化学制品制造业 | B34: N2O | C34: 浓硝酸 | D34: 万吨 | E34: 拍数 | F34: 246.85 | G34: 244.17 | H34: 232.31 | I34: 224.95 | J34: 201.43 | K34: =J34+($M34-$J34)/3 -> 209.28667 | L34: =K34+($M34-$J34)/3 -> 217.14333 | M34: 225 | N34: =M34+($W34-$M34)/10 -> 223.5 | O34: =N34+($W34-$M34)/10 -> 222 | P34: =O34+($W34-$M34)/10 -> 220.5 | Q34: =P34+($W34-$M34)/10 -> 219 | R34: =Q34+($W34-$M34)/10 -> 217.5 | S34: =R34+($W34-$M34)/10 -> 216 | T34: =S34+($W34-$M34)/10 -> 214.5 | U34: =T34+($W34-$M34)/10 -> 213 | V34: =U34+($W34-$M34)/10 -> 211.5 | W34: 210 | X34: =W34+($AV34-$W34)/25 -> 207.2 | Y34: =X34+($AV34-$W34)/25 -> 204.4 | Z34: =Y34+($AV34-$W34)/25 -> 201.6 | AA34: =Z34+($AV34-$W34)/25 -> 198.8 | AB34: =AA34+($AV34-$W34)/25 -> 196 | AC34: =AB34+($AV34-$W34)/25 -> 193.2 | AD34: =AC34+($AV34-$W34)/25 -> 190.4 | AE34: =AD34+($AV34-$W34)/25 -> 187.6 | ... AU34: =AT34+($AV34-$W34)/25 -> 142.8 | AV34: 140
A35: 化学原料和化学制品制造业 | B35: F-gases | C35: HCFCs | D35: 万吨 | E35: 拍数 | F35: 85.17 | G35: 88.95 | H35: 86.69 | I35: 93.16 | J35: =I35+($M35-$I35)/4 -> 99.87 | K35: =J35+($M35-$I35)/4 -> 106.58 | L35: =K35+($M35-$I35)/4 -> 113.29 | M35: 120 | N35: =M35+($W35-$M35)/10 -> 123 | O35: =N35+($W35-$M35)/10 -> 126 | P35: =O35+($W35-$M35)/10 -> 129 | Q35: =P35+($W35-$M35)/10 -> 132 | R35: =Q35+($W35-$M35)/10 -> 135 | S35: =R35+($W35-$M35)/10 -> 138 | T35: =S35+($W35-$M35)/10 -> 141 | U35: =T35+($W35-$M35)/10 -> 144 | V35: =U35+($W35-$M35)/10 -> 147 | W35: 150 | X35: =W35+($AV35-$W35)/25 -> 149 | Y35: =X35+($AV35-$W35)/25 -> 148 | Z35: =Y35+($AV35-$W35)/25 -> 147 | AA35: =Z35+($AV35-$W35)/25 -> 146 | AB35: =AA35+($AV35-$W35)/25 -> 145 | AC35: =AB35+($AV35-$W35)/25 -> 144 | AD35: =AC35+($AV35-$W35)/25 -> 143 | AE35: =AD35+($AV35-$W35)/25 -> 142 | ... AU35: =AT35+($AV35-$W35)/25 -> 126 | AV35: 125
A36: 非金属矿物制品业 | B36: CO2 | C36: 水泥 | D36: 万吨 | E36: 中国能源研究会-内部报告 | F36: 223609.62 | G36: 234430.62 | H36: =E16 -> 239470.83 | I36: =F16 -> 237724.49 | J36: =G16 -> 212927.18 | K36: =H16 -> 221951.45 | L36: =I16 -> 230975.73 | M36: =J16 -> 240000 | N36: =K16 -> 243000 | O36: =L16 -> 246000 | ... AV36: =AS16 -> 149049.03
A37: 黑色金属冶炼和压延加工业 | B37: CO2+CH4 | C37: 粗钢 | D37: 万吨 | E37: 中国能源研究会-内部报告 | F37: 92903.84 | G37: 99541.89 | H37: =E18 -> 106476.68 | I37: =F18 -> 103524.26 | J37: =G18 -> 101795.9 | K37: =H18 -> 109863.93 | L37: =I18 -> 117931.97 | M37: =J18 -> 126000 | N37: =K18 -> 128800 | O37: =L18 -> 131600 | ... AV37: =AS18 -> 76346.925
A38: 有色金属冶炼和压延加工业 | B38: F-gases | C38: 电解铝 | D38: 万吨 | E38: 中国能源研究会-内部报告 | F38: 3683.1 | G38: 3512.96 | H38: =E19 -> 3708.04 | I38: =F19 -> 3850.32 | J38: =G19 -> 4014.43 | K38: =H19 -> 4342.9533 | L38: =I19 -> 4671.4767 | M38: =J19 -> 5000 | N38: =K19 -> 5260 | O38: =L19 -> 5520 | ... AV38: =AS19 -> 5000
A39: 电气机械和器材制造业 | B39: F-gases | C39: 用电量 | D39: 亿千瓦时 | E39: WR | F39: 68449 | G39: 72255 | H39: 75110 | I39: 83128 | J39: 86372 | K39: 92908 | L39: 98236 | M39: 103441 | N39: 108529 | O39: 113482 | P39: 118298 | Q39: 122964 | R39: 127474 | S39: 131817 | T39: 135982 | U39: 139961 | V39: 143743 | W39: 147316 | X39: 150667 | Y39: 153788 | Z39: 156673 | AA39: 159316 | AB39: 161710 | AC39: 163854 | AD39: 165743 | AE39: 167375 | AF39: 168754 | AG39: 169877 | AH39: 170749 | AI39: 171374 | AJ39: 171758 | AK39: 171907 | AL39: 171827 | AM39: 171527 | AN39: 171015 | AO39: 170299 | AP39: 169391 | AQ39: 168299 | AR39: 167033 | AS39: 165602 | AT39: 164017 | AU39: 162290 | AV39: 160429
A40: 废弃资源综合利用业 | B40: CO2+CH4+N2O | C40: 人口 | D40: 亿人 | E40: WR | F40: 13.9538 | G40: 14.007931 | H40: 14.131352 | I40: 14.16016 | J40: 14.188968 | K40: 14.217777 | L40: 14.246585 | M40: 14.275393 | N40: 14.271093 | O40: 14.266794 | P40: 14.262494 | Q40: 14.258194 | R40: 14.253895 | S40: 14.234383 | T40: 14.214872 | U40: 14.195361 | V40: 14.17585 | W40: 14.156338 | X40: 14.120965 | Y40: 14.085592 | Z40: 14.050219 | AA40: 14.014845 | AB40: 13.979472 | AC40: 13.931014 | AD40: 13.882556 | AE40: 13.834097 | AF40: 13.785639 | AG40: 13.737181 | AH40: 13.667318 | AI40: 13.597456 | AJ40: 13.527593 | AK40: 13.457731 | AL40: 13.387868 | AM40: 13.293637 | AN40: 13.199406 | AO40: 13.105175 | AP40: 13.010944 | AQ40: 12.916713 | AR40: 12.803762 | AS40: 12.690811 | AT40: 12.577859 | AU40: 12.464908 | AV40: 12.351956

Sheet 中情景
A1: 行业 | B1: 计量指标 | C1: 计量单位 | D1: 数据来源 | E1: 2020 | F1: 2021 | G1: 2022 | H1: 2023 | I1: 2024 | J1: 2025 | K1: 2026 | L1: 2027 | M1: 2028 | N1: 2029 | O1: 2030 | P1: 2031 | Q1: 2032 | R1: 2033 | S1: 2034 | T1: 2035 | U1: 2036 | V1: 2037 | W1: 2038 | X1: 2039 | Y1: 2040 | Z1: 2041 | AA1: 2042 | AB1: 2043 | AC1: 2044 | AD1: 2045 | AE1: 2046 | AF1: 2047 | AG1: 2048 | AH1: 2049 | AI1: 2050 | AJ1: 2051 | AK1: 2052 | AL1: 2053 | AM1: 2054 | AN1: 2055 | AO1: 2056 | AP1: 2057 | AQ1: 2058 | AR1: 2059 | AS1: 2060
A2: 煤炭开采和洗选业 | B2: 原煤 | C2: 亿吨 | D2: 中石化《中国能源展望2060》 | E2: =高情景!E2*0.5+低情景!E2*0.5 -> 39.02 | F2: =高情景!F2*0.5+低情景!F2*0.5 -> 41.26 | G2: =高情景!G2*0.7+低情景!G2*0.3 -> 45.59 | H2: =高情景!H2*0.7+低情景!H2*0.3 -> 46.826667 | I2: =高情景!I2*0.7+低情景!I2*0.3 -> 48.063333 | J2: =高情景!J2*0.75+低情景!J2*0.25 -> 49.25 | K2: =高情景!K2*0.75+低情景!K2*0.25 -> 50.05 | L2: =高情景!L2*0.75+低情景!L2*0.25 -> 50.85 | M2: =高情景!M2*0.75+低情景!M2*0.25 -> 51.65 | N2: =高情景!N2*0.72+低情景!N2*0.28 -> 52.48 | O2: =高情景!O2*0.7+低情景!O2*0.3 -> 53.3 | P2: =高情景!P2*0.7+低情景!P2*0.3 -> 53.45 | Q2: =高情景!Q2*0.68+低情景!Q2*0.32 -> 53.6 | R2: =高情景!R2*0.65+低情景!R2*0.35 -> 53.725 | S2: =高情景!S2*0.6+低情景!S2*0.4 -> 53.8 | T2: =高情景!T2*0.55+低情景!T2*0.45 -> 53.825 | U2: =高情景!U2*0.55+低情景!U2*0.45 -> 53.19 | V2: =高情景!V2*0.55+低情景!V2*0.45 -> 52.555 | W2: =高情景!W2*0.55+低情景!W2*0.45 -> 51.92 | X2: =高情景!X2*0.55+低情景!X2*0.45 -> 51.285 | Y2: =高情景!Y2*0.55+低情景!Y2*0.45 -> 50.65 | Z2: =高情景!Z2*0.55+低情景!Z2*0.45 -> 49.67 | AA2: =高情景!AA2*0.55+低情景!AA2*0.45 -> 48.69 | ... AS2: =高情景!AS2*0.55+低情景!AS2*0.45 -> 31.85
A3: 石油和天然气开采业 | B3: 原油 | C3: 亿吨 | D3: 中石油《世界与中国能源展望2021》 | E3: =高情景!E3*0.5+低情景!E3*0.5 -> 1.9477 | F3: =高情景!F3*0.5+低情景!F3*0.5 -> 1.9888 | G3: =高情景!G3*0.7+低情景!G3*0.3 -> 2.0472 | H3: =高情景!H3*0.7+低情景!H3*0.3 -> 2.0911333 | I3: =高情景!I3*0.7+低情景!I3*0.3 -> 2.1350667 | J3: =高情景!J3*0.75+低情景!J3*0.25 -> 2.1775 | K3: =高情景!K3*0.75+低情景!K3*0.25 -> 2.1895 | L3: =高情景!L3*0.75+低情景!L3*0.25 -> 2.2015 | M3: =高情景!M3*0.75+低情景!M3*0.25 -> 2.2135 | N3: =高情景!N3*0.72+低情景!N3*0.28 -> 2.22928 | O3: =高情景!O3*0.7+低情景!O3*0.3 -> 2.245 | P3: =高情景!P3*0.7+低情景!P3*0.3 -> 2.258 | Q3: =高情景!Q3*0.68+低情景!Q3*0.32 -> 2.2736 | R3: =高情景!R3*0.65+低情景!R3*0.35 -> 2.29 | S3: =高情景!S3*0.6+低情景!S3*0.4 -> 2.308 | T3: =高情景!T3*0.55+低情景!T3*0.45 -> 2.325 | U3: =高情景!U3*0.55+低情景!U3*0.45 -> 2.3254 | V3: =高情景!V3*0.55+低情景!V3*0.45 -> 2.3258 | W3: =高情景!W3*0.55+低情景!W3*0.45 -> 2.3262 | X3: =高情景!X3*0.55+低情景!X3*0.45 -> 2.3266 | Y3: =高情景!Y3*0.55+低情景!Y3*0.45 -> 2.327 | Z3: =高情景!Z3*0.55+低情景!Z3*0.45 -> 2.3088 | AA3: =高情景!AA3*0.55+低情景!AA3*0.45 -> 2.2906 | ... AS3: =高情景!AS3*0.55+低情景!AS3*0.45 -> 1.782
A4: 石油和天然气开采业 | B4: 天然气 | C4: 亿立方米 | D4: 中石油《世界与中国能源展望2021》 | E4: =高情景!E4*0.5+低情景!E4*0.5 -> 1924.95 | F4: =高情景!F4*0.5+低情景!F4*0.5 -> 2075.84 | G4: =高情景!G4*0.7+低情景!G4*0.3 -> 2201.1 | H4: =高情景!H4*0.7+低情景!H4*0.3 -> 2309.1 | I4: =高情景!I4*0.7+低情景!I4*0.3 -> 2417.1 | J4: =高情景!J4*0.75+低情景!J4*0.25 -> 2519.75 | K4: =高情景!K4*0.75+低情景!K4*0.25 -> 2590.8 | L4: =高情景!L4*0.75+低情景!L4*0.25 -> 2661.85 | M4: =高情景!M4*0.75+低情景!M4*0.25 -> 2732.9 | N4: =高情景!N4*0.72+低情景!N4*0.28 -> 2811.792 | O4: =高情景!O4*0.7+低情景!O4*0.3 -> 2890 | P4: =高情景!P4*0.7+低情景!P4*0.3 -> 2933 | Q4: =高情景!Q4*0.68+低情景!Q4*0.32 -> 2982.4 | R4: =高情景!R4*0.65+低情景!R4*0.35 -> 3035.5 | S4: =高情景!S4*0.6+低情景!S4*0.4 -> 3096 | T4: =高情景!T4*0.55+低情景!T4*0.45 -> 3157.5 | U4: =高情景!U4*0.55+低情景!U4*0.45 -> 3197.5 | V4: =高情景!V4*0.55+低情景!V4*0.45 -> 3237.5 | W4: =高情景!W4*0.55+低情景!W4*0.45 -> 3277.5 | X4: =高情景!X4*0.55+低情景!X4*0.45 -> 3317.5 | Y4: =高情景!Y4*0.55+低情景!Y4*0.45 -> 3357.5 | Z4: =高情景!Z4*0.55+低情景!Z4*0.45 -> 3380.2 | AA4: =高情景!AA4*0.55+低情景!AA4*0.45 -> 3402.9 | ... AS4: =高情景!AS4*0.55+低情景!AS4*0.45 -> 3680
A5: 黑色金属矿采选业 | B5: 铁矿石原矿 | C5: 亿吨 | D5: 产品产量与粗钢产量挂钩 | E5: =高情景!E5*0.5+低情景!E5*0.5 -> 8.6672 | F5: =高情景!F5*0.5+低情景!F5*0.5 -> 9.8053 | G5: =高情景!G5*0.7+低情景!G5*0.3 -> 9.6787 | H5: =高情景!H5*0.7+低情景!H5*0.3 -> 10.312693 | I5: =高情景!I5*0.7+低情景!I5*0.3 -> 10.946686 | J5: =高情景!J5*0.75+低情景!J5*0.25 -> 11.647235 | K5: =高情景!K5*0.75+低情景!K5*0.25 -> 11.865918 | L5: =高情景!L5*0.75+低情景!L5*0.25 -> 12.0846 | M5: =高情景!M5*0.75+低情景!M5*0.25 -> 12.303283 | N5: =高情景!N5*0.72+低情景!N5*0.28 -> 12.459213 | O5: =高情景!O5*0.7+低情景!O5*0.3 -> 12.626553 | P5: =高情景!P5*0.7+低情景!P5*0.3 -> 12.599931 | Q5: =高情景!Q5*0.68+低情景!Q5*0.32 -> 12.521586 | R5: =高情景!R5*0.65+低情景!R5*0.35 -> 12.409772 | S5: =高情景!S5*0.6+低情景!S5*0.4 -> 12.231023 | T5: =高情景!T5*0.55+低情景!T5*0.45 -> 12.037061 | U5: =高情景!U5*0.55+低情景!U5*0.45 -> 11.876376 | V5: =高情景!V5*0.55+低情景!V5*0.45 -> 11.715692 | W5: =高情景!W5*0.55+低情景!W5*0.45 -> 11.555008 | X5: =高情景!X5*0.55+低情景!X5*0.45 -> 11.394323 | Y5: =高情景!Y5*0.55+低情景!Y5*0.45 -> 11.233639 | Z5: =高情景!Z5*0.55+低情景!Z5*0.45 -> 10.982629 | AA5: =高情景!AA5*0.55+低情景!AA5*0.45 -> 10.73162 | ... AS5: =高情景!AS5*0.55+低情景!AS5*0.45 -> 6.387942
A6: 有色金属矿采选业 | B6: 铜矿 | C6: 万吨 | D6: 产量与精炼铜产量挂钩；https://www.wkqh.cn/ueditor/jsp/upload/file/20240603/1717376096015027949.pdf | E6: =高情景!E6*0.5+低情景!E6*0.5 -> 172 | F6: =高情景!F6*0.5+低情景!F6*0.5 -> 191 | G6: =高情景!G6*0.7+低情景!G6*0.3 -> 194 | H6: =高情景!H6*0.7+低情景!H6*0.3 -> 219.50934 | I6: =高情景!I6*0.7+低情景!I6*0.3 -> 245.01867 | J6: =高情景!J6*0.75+低情景!J6*0.25 -> 270.52801 | K6: =高情景!K6*0.75+低情景!K6*0.25 -> 283.61808 | L6: =高情景!L6*0.75+低情景!L6*0.25 -> 296.70814 | M6: =高情景!M6*0.75+低情景!M6*0.25 -> 309.79821 | N6: =高情景!N6*0.72+低情景!N6*0.28 -> 323.30715 | O6: =高情景!O6*0.7+低情景!O6*0.3 -> 336.85101 | P6: =高情景!P6*0.7+低情景!P6*0.3 -> 344.87958 | Q6: =高情景!Q6*0.68+低情景!Q6*0.32 -> 353.39685 | R6: =高情景!R6*0.65+低情景!R6*0.35 -> 362.333 | S6: =高情景!S6*0.6+低情景!S6*0.4 -> 372.10692 | T6: =高情景!T6*0.55+低情景!T6*0.45 -> 382.2299 | U6: =高情景!U6*0.55+低情景!U6*0.45 -> 387.29139 | V6: =高情景!V6*0.55+低情景!V6*0.45 -> 392.35288 | W6: =高情景!W6*0.55+低情景!W6*0.45 -> 397.41437 | X6: =高情景!X6*0.55+低情景!X6*0.45 -> 402.47587 | Y6: =高情景!Y6*0.55+低情景!Y6*0.45 -> 407.53736 | Z6: =高情景!Z6*0.55+低情景!Z6*0.45 -> 411.63891 | AA6: =高情景!AA6*0.55+低情景!AA6*0.45 -> 415.74047 | ... AS6: =高情景!AS6*0.55+低情景!AS6*0.45 -> 472.90042
A7: 有色金属矿采选业 | B7: 铝土矿 | C7: 万吨 | D7: 产量与电解铝产量挂钩 | E7: =高情景!E7*0.5+低情景!E7*0.5 -> 9269 | F7: =高情景!F7*0.5+低情景!F7*0.5 -> 8500 | G7: =高情景!G7*0.7+低情景!G7*0.3 -> 9000 | H7: =高情景!H7*0.7+低情景!H7*0.3 -> 9680.4727 | I7: =高情景!I7*0.7+低情景!I7*0.3 -> 10360.945 | J7: =高情景!J7*0.75+低情景!J7*0.25 -> 11069.442 | K7: =高情景!K7*0.75+低情景!K7*0.25 -> 11585.082 | L7: =高情景!L7*0.75+低情景!L7*0.25 -> 12100.722 | M7: =高情景!M7*0.75+低情景!M7*0.25 -> 12616.361 | N7: =高情景!N7*0.72+低情景!N7*0.28 -> 13082.903 | O7: =高情景!O7*0.7+低情景!O7*0.3 -> 13552.36 | P7: =高情景!P7*0.7+低情景!P7*0.3 -> 13825.873 | Q7: =高情景!Q7*0.68+低情景!Q7*0.32 -> 14055.893 | R7: =高情景!R7*0.65+低情景!R7*0.35 -> 14257.441 | S7: =高情景!S7*0.6+低情景!S7*0.4 -> 14402.045 | T7: =高情景!T7*0.55+低情景!T7*0.45 -> 14533.196 | U7: =高情景!U7*0.55+低情景!U7*0.45 -> 14542.164 | V7: =高情景!V7*0.55+低情景!V7*0.45 -> 14551.132 | W7: =高情景!W7*0.55+低情景!W7*0.45 -> 14560.099 | X7: =高情景!X7*0.55+低情景!X7*0.45 -> 14569.067 | Y7: =高情景!Y7*0.55+低情景!Y7*0.45 -> 14578.035 | Z7: =高情景!Z7*0.55+低情景!Z7*0.45 -> 14462.576 | AA7: =高情景!AA7*0.55+低情景!AA7*0.45 -> 14347.118 | ... AS7: =高情景!AS7*0.55+低情景!AS7*0.45 -> 9998.9289
A8: 非金属矿采选业 | B8: 石灰石 | C8: 亿吨 | D8: 产品产量与水泥产量挂钩;https://www.sohu.com/a/716515038_121388092 | E8: =高情景!E8*0.5+低情景!E8*0.5 -> 31.55 | F8: =高情景!F8*0.5+低情景!F8*0.5 -> 31.4 | G8: =高情景!G8*0.7+低情景!G8*0.3 -> 28.79 | H8: =高情景!H8*0.7+低情景!H8*0.3 -> 29.545899 | I8: =高情景!I8*0.7+低情景!I8*0.3 -> 30.301799 | J8: =高情景!J8*0.75+低情景!J8*0.25 -> 31.151368 | K8: =高情景!K8*0.75+低情景!K8*0.25 -> 31.427521 | L8: =高情景!L8*0.75+低情景!L8*0.25 -> 31.703675 | M8: =高情景!M8*0.75+低情景!M8*0.25 -> 31.979828 | N8: =高情景!N8*0.72+低情景!N8*0.28 -> 32.142615 | O8: =高情景!O8*0.7+低情景!O8*0.3 -> 32.319371 | P8: =高情景!P8*0.7+低情景!P8*0.3 -> 31.921009 | Q8: =高情景!Q8*0.68+低情景!Q8*0.32 -> 31.437127 | R8: =高情景!R8*0.65+低情景!R8*0.35 -> 30.909964 | S8: =高情景!S8*0.6+低情景!S8*0.4 -> 30.296243 | T8: =高情景!T8*0.55+低情景!T8*0.45 -> 29.681483 | U8: =高情景!U8*0.55+低情景!U8*0.45 -> 29.109426 | V8: =高情景!V8*0.55+低情景!V8*0.45 -> 28.53737 | W8: =高情景!W8*0.55+低情景!W8*0.45 -> 27.965313 | X8: =高情景!X8*0.55+低情景!X8*0.45 -> 27.393257 | Y8: =高情景!Y8*0.55+低情景!Y8*0.45 -> 26.8212 | Z8: =高情景!Z8*0.55+低情景!Z8*0.45 -> 26.035853 | AA8: =高情景!AA8*0.55+低情景!AA8*0.45 -> 25.250505 | ... AS8: =高情景!AS8*0.55+低情景!AS8*0.45 -> 17.278119
A9: 造纸和纸制品业 | B9: 纸和纸板 | C9: 万吨 | D9: 中国能源研究会-内部报告 | E9: =高情景!E9*0.5+低情景!E9*0.5 -> 12700.63 | F9: =高情景!F9*0.5+低情景!F9*0.5 -> 13583.87 | G9: =高情景!G9*0.7+低情景!G9*0.3 -> 13691.4 | H9: =高情景!H9*0.7+低情景!H9*0.3 -> 14410.933 | I9: =高情景!I9*0.7+低情景!I9*0.3 -> 15130.467 | J9: =高情景!J9*0.75+低情景!J9*0.25 -> 15875 | K9: =高情景!K9*0.75+低情景!K9*0.25 -> 16250 | L9: =高情景!L9*0.75+低情景!L9*0.25 -> 16625 | M9: =高情景!M9*0.75+低情景!M9*0.25 -> 17000 | N9: =高情景!N9*0.72+低情景!N9*0.28 -> 17348 | O9: =高情景!O9*0.7+低情景!O9*0.3 -> 17700 | P9: =高情景!P9*0.7+低情景!P9*0.3 -> 17870 | Q9: =高情景!Q9*0.68+低情景!Q9*0.32 -> 18016 | R9: =高情景!R9*0.65+低情景!R9*0.35 -> 18145 | S9: =高情景!S9*0.6+低情景!S9*0.4 -> 18240 | T9: =高情景!T9*0.55+低情景!T9*0.45 -> 18325 | U9: =高情景!U9*0.55+低情景!U9*0.45 -> 18335 | V9: =高情景!V9*0.55+低情景!V9*0.45 -> 18345 | W9: =高情景!W9*0.55+低情景!W9*0.45 -> 18355 | X9: =高情景!X9*0.55+低情景!X9*0.45 -> 18365 | Y9: =高情景!Y9*0.55+低情景!Y9*0.45 -> 18375 | Z9: =高情景!Z9*0.55+低情景!Z9*0.45 -> 18230 | AA9: =高情景!AA9*0.55+低情景!AA9*0.45 -> 18085 | ... AS9: =高情景!AS9*0.55+低情景!AS9*0.45 -> 13875
A10: 石油、煤炭及其他燃料加工业 | B10: 原油加工量 | C10: 亿吨 | D10: 加工量与原油产量挂钩 | E10: =高情景!E10*0.5+低情景!E10*0.5 -> 6.7441 | F10: =高情景!F10*0.5+低情景!F10*0.5 -> 7 | G10: =高情景!G10*0.7+低情景!G10*0.3 -> 6.759 | H10: =高情景!H10*0.7+低情景!H10*0.3 -> 6.9040495 | I10: =高情景!I10*0.7+低情景!I10*0.3 -> 7.0490991 | J10: =高情景!J10*0.75+低情景!J10*0.25 -> 7.1891962 | K10: =高情景!K10*0.75+低情景!K10*0.25 -> 7.2288152 | L10: =高情景!L10*0.75+低情景!L10*0.25 -> 7.2684342 | M10: =高情景!M10*0.75+低情景!M10*0.25 -> 7.3080532 | N10: =高情景!N10*0.72+低情景!N10*0.28 -> 7.3601522 | O10: =高情景!O10*0.7+低情景!O10*0.3 -> 7.412053 | P10: =高情景!P10*0.7+低情景!P10*0.3 -> 7.4549736 | Q10: =高情景!Q10*0.68+低情景!Q10*0.32 -> 7.5064783 | R10: =高情景!R10*0.65+低情景!R10*0.35 -> 7.5606243 | S10: =高情景!S10*0.6+低情景!S10*0.4 -> 7.6200528 | T10: =高情景!T10*0.55+低情景!T10*0.45 -> 7.6761797 | U10: =高情景!U10*0.55+低情景!U10*0.45 -> 7.6775003 | V10: =高情景!V10*0.55+低情景!V10*0.45 -> 7.6788209 | W10: =高情景!W10*0.55+低情景!W10*0.45 -> 7.6801416 | X10: =高情景!X10*0.55+低情景!X10*0.45 -> 7.6814622 | Y10: =高情景!Y10*0.55+低情景!Y10*0.45 -> 7.6827828 | Z10: =高情景!Z10*0.55+低情景!Z10*0.45 -> 7.622694 | AA10: =高情景!AA10*0.55+低情景!AA10*0.45 -> 7.5626052 | ... AS10: =高情景!AS10*0.55+低情景!AS10*0.45 -> 5.8834203
A11: 石油、煤炭及其他燃料加工业 | B11: 焦炭 | C11: 万吨 | D11: 焦炭产量与钢铁产量挂钩 | E11: =高情景!E11*0.5+低情景!E11*0.5 -> 47116 | F11: =高情景!F11*0.5+低情景!F11*0.5 -> 46400 | G11: =高情景!G11*0.7+低情景!G11*0.3 -> 47300 | H11: =高情景!H11*0.7+低情景!H11*0.3 -> 50398.337 | I11: =高情景!I11*0.7+低情景!I11*0.3 -> 53496.673 | J11: =高情景!J11*0.75+低情景!J11*0.25 -> 56920.269 | K11: =高情景!K11*0.75+低情景!K11*0.25 -> 57988.976 | L11: =高情景!L11*0.75+低情景!L11*0.25 -> 59057.683 | M11: =高情景!M11*0.75+低情景!M11*0.25 -> 60126.39 | N11: =高情景!N11*0.72+低情景!N11*0.28 -> 60888.425 | O11: =高情景!O11*0.7+低情景!O11*0.3 -> 61706.218 | P11: =高情景!P11*0.7+低情景!P11*0.3 -> 61576.115 | Q11: =高情景!Q11*0.68+低情景!Q11*0.32 -> 61193.239 | R11: =高情景!R11*0.65+低情景!R11*0.35 -> 60646.804 | S11: =高情景!S11*0.6+低情景!S11*0.4 -> 59773.252 | T11: =高情景!T11*0.55+低情景!T11*0.45 -> 58825.355 | U11: =高情景!U11*0.55+低情景!U11*0.45 -> 58040.088 | V11: =高情景!V11*0.55+低情景!V11*0.45 -> 57254.821 | W11: =高情景!W11*0.55+低情景!W11*0.45 -> 56469.553 | X11: =高情景!X11*0.55+低情景!X11*0.45 -> 55684.286 | Y11: =高情景!Y11*0.55+低情景!Y11*0.45 -> 54899.019 | Z11: =高情景!Z11*0.55+低情景!Z11*0.45 -> 53672.329 | AA11: =高情景!AA11*0.55+低情景!AA11*0.45 -> 52445.639 | ... AS11: =高情景!AS11*0.55+低情景!AS11*0.45 -> 31218
A12: 化学原料和化学制品制造业 | B12: 烧碱 | C12: 万吨 | D12: 中国能源研究会-内部报告 | E12: =高情景!E12*0.5+低情景!E12*0.5 -> 3673.87 | F12: =高情景!F12*0.5+低情景!F12*0.5 -> 3891.31 | G12: =高情景!G12*0.7+低情景!G12*0.3 -> 3463.08 | H12: =高情景!H12*0.7+低情景!H12*0.3 -> 3812.0533 | I12: =高情景!I12*0.7+低情景!I12*0.3 -> 4161.0267 | J12: =高情景!J12*0.75+低情景!J12*0.25 -> 4525 | K12: =高情景!K12*0.75+低情景!K12*0.25 -> 4715 | L12: =高情景!L12*0.75+低情景!L12*0.25 -> 4905 | M12: =高情景!M12*0.75+低情景!M12*0.25 -> 5095 | N12: =高情景!N12*0.72+低情景!N12*0.28 -> 5271.2 | O12: =高情景!O12*0.7+低情景!O12*0.3 -> 5450 | P12: =高情景!P12*0.7+低情景!P12*0.3 -> 5558 | Q12: =高情景!Q12*0.68+低情景!Q12*0.32 -> 5654.4 | R12: =高情景!R12*0.65+低情景!R12*0.35 -> 5743 | S12: =高情景!S12*0.6+低情景!S12*0.4 -> 5816 | T12: =高情景!T12*0.55+低情景!T12*0.45 -> 5885 | U12: =高情景!U12*0.55+低情景!U12*0.45 -> 5936 | V12: =高情景!V12*0.55+低情景!V12*0.45 -> 5987 | W12: =高情景!W12*0.55+低情景!W12*0.45 -> 6038 | X12: =高情景!X12*0.55+低情景!X12*0.45 -> 6089 | Y12: =高情景!Y12*0.55+低情景!Y12*0.45 -> 6140 | Z12: =高情景!Z12*0.55+低情景!Z12*0.45 -> 6133 | AA12: =高情景!AA12*0.55+低情景!AA12*0.45 -> 6126 | ... AS12: =高情景!AS12*0.55+低情景!AS12*0.45 -> 5215
A13: 化学原料和化学制品制造业 | B13: 纯碱 | C13: 万吨 | D13: 中国能源研究会-内部报告 | E13: =高情景!E13*0.5+低情景!E13*0.5 -> 2812.37 | F13: =高情景!F13*0.5+低情景!F13*0.5 -> 2913.25 | G13: =高情景!G13*0.7+低情景!G13*0.3 -> 2920.2 | H13: =高情景!H13*0.7+低情景!H13*0.3 -> 3131.8 | I13: =高情景!I13*0.7+低情景!I13*0.3 -> 3343.4 | J13: =高情景!J13*0.75+低情景!J13*0.25 -> 3562.5 | K13: =高情景!K13*0.75+低情景!K13*0.25 -> 3704.5 | L13: =高情景!L13*0.75+低情景!L13*0.25 -> 3846.5 | M13: =高情景!M13*0.75+低情景!M13*0.25 -> 3988.5 | N13: =高情景!N13*0.72+低情景!N13*0.28 -> 4117.36 | O13: =高情景!O13*0.7+低情景!O13*0.3 -> 4247 | P13: =高情景!P13*0.7+低情景!P13*0.3 -> 4314.4 | Q13: =高情景!Q13*0.68+低情景!Q13*0.32 -> 4369.92 | R13: =高情景!R13*0.65+低情景!R13*0.35 -> 4417.4 | S13: =高情景!S13*0.6+低情景!S13*0.4 -> 4448.8 | T13: =高情景!T13*0.55+低情景!T13*0.45 -> 4476 | U13: =高情景!U13*0.55+低情景!U13*0.45 -> 4491.5 | V13: =高情景!V13*0.55+低情景!V13*0.45 -> 4507 | W13: =高情景!W13*0.55+低情景!W13*0.45 -> 4522.5 | X13: =高情景!X13*0.55+低情景!X13*0.45 -> 4538 | Y13: =高情景!Y13*0.55+低情景!Y13*0.45 -> 4553.5 | Z13: =高情景!Z13*0.55+低情景!Z13*0.45 -> 4536.3 | AA13: =高情景!AA13*0.55+低情景!AA13*0.45 -> 4519.1 | ... AS13: =高情景!AS13*0.55+低情景!AS13*0.45 -> 3840
... A15: 化学原料和化学制品制造业 | B15: 合成氨 | C15: 万吨 | D15: 中国能源研究会-内部报告 | E15: =高情景!E15*0.5+低情景!E15*0.5 -> 5117.13 | F15: =高情景!F15*0.5+低情景!F15*0.5 -> 5189.38 | G15: =高情景!G15*0.7+低情景!G15*0.3 -> 5321.01 | H15: =高情景!H15*0.7+低情景!H15*0.3 -> 5607.34 | I15: =高情景!I15*0.7+低情景!I15*0.3 -> 5893.67 | J15: =高情景!J15*0.75+低情景!J15*0.25 -> 6200 | K15: =高情景!K15*0.75+低情景!K15*0.25 -> 6380 | L15: =高情景!L15*0.75+低情景!L15*0.25 -> 6560 | M15: =高情景!M15*0.75+低情景!M15*0.25 -> 6740 | N15: =高情景!N15*0.72+低情景!N15*0.28 -> 6908 | O15: =高情景!O15*0.7+低情景!O15*0.3 -> 7080 | P15: =高情景!P15*0.7+低情景!P15*0.3 -> 7186 | Q15: =高情景!Q15*0.68+低情景!Q15*0.32 -> 7284.8 | R15: =高情景!R15*0.65+低情景!R15*0.35 -> 7381 | S15: =高情景!S15*0.6+低情景!S15*0.4 -> 7472 | T15: =高情景!T15*0.55+低情景!T15*0.45 -> 7565 | U15: =高情景!U15*0.55+低情景!U15*0.45 -> 7616 | V15: =高情景!V15*0.55+低情景!V15*0.45 -> 7667 | W15: =高情景!W15*0.55+低情景!W15*0.45 -> 7718 | X15: =高情景!X15*0.55+低情景!X15*0.45 -> 7769 | Y15: =高情景!Y15*0.55+低情景!Y15*0.45 -> 7820 | Z15: =高情景!Z15*0.55+低情景!Z15*0.45 -> 7833 | AA15: =高情景!AA15*0.55+低情景!AA15*0.45 -> 7846 | ... AS15: =高情景!AS15*0.55+低情景!AS15*0.45 -> 7745
A16: 非金属矿物制品业 | B16: 水泥 | C16: 万吨 | D16: 中国能源研究会-内部报告 | E16: =高情景!E16*0.5+低情景!E16*0.5 -> 239470.83 | F16: =高情景!F16*0.5+低情景!F16*0.5 -> 237724.49 | G16: =高情景!G16*0.7+低情景!G16*0.3 -> 212927.18 | H16: =高情景!H16*0.7+低情景!H16*0.3 -> 219951.45 | I16: =高情景!I16*0.7+低情景!I16*0.3 -> 226975.73 | J16: =高情景!J16*0.75+低情景!J16*0.25 -> 235000 | K16: =高情景!K16*0.75+低情景!K16*0.25 -> 237100 | L16: =高情景!L16*0.75+低情景!L16*0.25 -> 239200 | M16: =高情景!M16*0.75+低情景!M16*0.25 -> 241300 | N16: =高情景!N16*0.72+低情景!N16*0.28 -> 242368 | O16: =高情景!O16*0.7+低情景!O16*0.3 -> 243600 | P16: =高情景!P16*0.7+低情景!P16*0.3 -> 240600 | Q16: =高情景!Q16*0.68+低情景!Q16*0.32 -> 236840 | R16: =高情景!R16*0.65+低情景!R16*0.35 -> 232700 | S16: =高情景!S16*0.6+低情景!S16*0.4 -> 227800 | T16: =高情景!T16*0.55+低情景!T16*0.45 -> 222900 | U16: =高情景!U16*0.55+低情景!U16*0.45 -> 218610 | V16: =高情景!V16*0.55+低情景!V16*0.45 -> 214320 | W16: =高情景!W16*0.55+低情景!W16*0.45 -> 210030 | X16: =高情景!X16*0.55+低情景!X16*0.45 -> 205740 | Y16: =高情景!Y16*0.55+低情景!Y16*0.45 -> 201450 | Z16: =高情景!Z16*0.55+低情景!Z16*0.45 -> 195560 | AA16: =高情景!AA16*0.55+低情景!AA16*0.45 -> 189670 | ... AS16: =高情景!AS16*0.55+低情景!AS16*0.45 -> 129885.58 | AT16: =AS16/G16 -> 0.61
A17: 非金属矿物制品业 | B17: 平板玻璃 | C17: 万重量厢 | D17: 中国能源研究会-内部报告 | E17: =高情景!E17*0.5+低情景!E17*0.5 -> 95227.79 | F17: =高情景!F17*0.5+低情景!F17*0.5 -> 101727.37 | G17: =高情景!G17*0.7+低情景!G17*0.3 -> 101668.65 | H17: =高情景!H17*0.7+低情景!H17*0.3 -> 107279.1 | I17: =高情景!I17*0.7+低情景!I17*0.3 -> 112889.55 | J17: =高情景!J17*0.75+低情景!J17*0.25 -> 118750 | K17: =高情景!K17*0.75+低情景!K17*0.25 -> 120550 | L17: =高情景!L17*0.75+低情景!L17*0.25 -> 122350 | M17: =高情景!M17*0.75+低情景!M17*0.25 -> 124150 | N17: =高情景!N17*0.72+低情景!N17*0.28 -> 125704 | O17: =高情景!O17*0.7+低情景!O17*0.3 -> 127300 | P17: =高情景!P17*0.7+低情景!P17*0.3 -> 126980 | Q17: =高情景!Q17*0.68+低情景!Q17*0.32 -> 126464 | R17: =高情景!R17*0.65+低情景!R17*0.35 -> 125830 | S17: =高情景!S17*0.6+低情景!S17*0.4 -> 124960 | T17: =高情景!T17*0.55+低情景!T17*0.45 -> 124050 | U17: =高情景!U17*0.55+低情景!U17*0.45 -> 122490 | V17: =高情景!V17*0.55+低情景!V17*0.45 -> 120930 | W17: =高情景!W17*0.55+低情景!W17*0.45 -> 119370 | X17: =高情景!X17*0.55+低情景!X17*0.45 -> 117810 | Y17: =高情景!Y17*0.55+低情景!Y17*0.45 -> 116250 | Z17: =高情景!Z17*0.55+低情景!Z17*0.45 -> 114510 | AA17: =高情景!AA17*0.55+低情景!AA17*0.45 -> 112770 | ... AS17: =高情景!AS17*0.55+低情景!AS17*0.45 -> 82350 | AT17: =AS17/G17 -> 0.8099842
A18: 黑色金属冶炼和压延加工业 | B18: 钢铁 | C18: 万吨 | D18: 中国能源研究会-内部报告 | E18: =高情景!E18*0.5+低情景!E18*0.5 -> 106476.68 | F18: =高情景!F18*0.5+低情景!F18*0.5 -> 103524.26 | G18: =高情景!G18*0.7+低情景!G18*0.3 -> 101795.9 | H18: =高情景!H18*0.7+低情景!H18*0.3 -> 108463.93 | I18: =高情景!I18*0.7+低情景!I18*0.3 -> 115131.97 | J18: =高情景!J18*0.75+低情景!J18*0.25 -> 122500 | K18: =高情景!K18*0.75+低情景!K18*0.25 -> 124800 | L18: =高情景!L18*0.75+低情景!L18*0.25 -> 127100 | M18: =高情景!M18*0.75+低情景!M18*0.25 -> 129400 | N18: =高情景!N18*0.72+低情景!N18*0.28 -> 131040 | O18: =高情景!O18*0.7+低情景!O18*0.3 -> 132800 | P18: =高情景!P18*0.7+低情景!P18*0.3 -> 132520 | Q18: =高情景!Q18*0.68+低情景!Q18*0.32 -> 131696 | R18: =高情景!R18*0.65+低情景!R18*0.35 -> 130520 | S18: =高情景!S18*0.6+低情景!S18*0.4 -> 128640 | T18: =高情景!T18*0.55+低情景!T18*0.45 -> 126600 | U18: =高情景!U18*0.55+低情景!U18*0.45 -> 124910 | V18: =高情景!V18*0.55+低情景!V18*0.45 -> 123220 | W18: =高情景!W18*0.55+低情景!W18*0.45 -> 121530 | X18: =高情景!X18*0.55+低情景!X18*0.45 -> 119840 | Y18: =高情景!Y18*0.55+低情景!Y18*0.45 -> 118150 | Z18: =高情景!Z18*0.55+低情景!Z18*0.45 -> 115510 | AA18: =高情景!AA18*0.55+低情景!AA18*0.45 -> 112870 | ... AS18: =高情景!AS18*0.55+低情景!AS18*0.45 -> 67185.294 | AT18: =AS18/G18 -> 0.66
A19: 有色金属冶炼和压延加工业 | B19: 电解铝 | C19: 万吨 | D19: 中国能源研究会-内部报告 | E19: =高情景!E19*0.5+低情景!E19*0.5 -> 3708.04 | F19: =高情景!F19*0.5+低情景!F19*0.5 -> 3850.32 | G19: =高情景!G19*0.7+低情景!G19*0.3 -> 4014.43 | H19: =高情景!H19*0.7+低情景!H19*0.3 -> 4317.9533 | I19: =高情景!I19*0.7+低情景!I19*0.3 -> 4621.4767 | J19: =高情景!J19*0.75+低情景!J19*0.25 -> 4937.5 | K19: =高情景!K19*0.75+低情景!K19*0.25 -> 5167.5 | L19: =高情景!L19*0.75+低情景!L19*0.25 -> 5397.5 | M19: =高情景!M19*0.75+低情景!M19*0.25 -> 5627.5 | N19: =高情景!N19*0.72+低情景!N19*0.28 -> 5835.6 | O19: =高情景!O19*0.7+低情景!O19*0.3 -> 6045 | P19: =高情景!P19*0.7+低情景!P19*0.3 -> 6167 | Q19: =高情景!Q19*0.68+低情景!Q19*0.32 -> 6269.6 | R19: =高情景!R19*0.65+低情景!R19*0.35 -> 6359.5 | S19: =高情景!S19*0.6+低情景!S19*0.4 -> 6424 | T19: =高情景!T19*0.55+低情景!T19*0.45 -> 6482.5 | U19: =高情景!U19*0.55+低情景!U19*0.45 -> 6486.5 | V19: =高情景!V19*0.55+低情景!V19*0.45 -> 6490.5 | W19: =高情景!W19*0.55+低情景!W19*0.45 -> 6494.5 | X19: =高情景!X19*0.55+低情景!X19*0.45 -> 6498.5 | Y19: =高情景!Y19*0.55+低情景!Y19*0.45 -> 6502.5 | Z19: =高情景!Z19*0.55+低情景!Z19*0.45 -> 6451 | AA19: =高情景!AA19*0.55+低情景!AA19*0.45 -> 6399.5 | ... AS19: =高情景!AS19*0.55+低情景!AS19*0.45 -> 4460
A20: 有色金属冶炼和压延加工业 | B20: 精炼铜 | C20: 万吨 | D20: 拍数 | E20: =高情景!E20*0.5+低情景!E20*0.5 -> 1002.51 | F20: =高情景!F20*0.5+低情景!F20*0.5 -> 1048.67 | G20: =高情景!G20*0.7+低情景!G20*0.3 -> 1111.53 | H20: =高情景!H20*0.7+低情景!H20*0.3 -> 1257.6867 | I20: =高情景!I20*0.7+低情景!I20*0.3 -> 1403.8433 | J20: =高情景!J20*0.75+低情景!J20*0.25 -> 1550 | K20: =高情景!K20*0.75+低情景!K20*0.25 -> 1625 | L20: =高情景!L20*0.75+低情景!L20*0.25 -> 1700 | M20: =高情景!M20*0.75+低情景!M20*0.25 -> 1775 | N20: =高情景!N20*0.72+低情景!N20*0.28 -> 1852.4 | O20: =高情景!O20*0.7+低情景!O20*0.3 -> 1930 | P20: =高情景!P20*0.7+低情景!P20*0.3 -> 1976 | Q20: =高情景!Q20*0.68+低情景!Q20*0.32 -> 2024.8 | R20: =高情景!R20*0.65+低情景!R20*0.35 -> 2076 | S20: =高情景!S20*0.6+低情景!S20*0.4 -> 2132 | T20: =高情景!T20*0.55+低情景!T20*0.45 -> 2190 | U20: =高情景!U20*0.55+低情景!U20*0.45 -> 2219 | V20: =高情景!V20*0.55+低情景!V20*0.45 -> 2248 | W20: =高情景!W20*0.55+低情景!W20*0.45 -> 2277 | X20: =高情景!X20*0.55+低情景!X20*0.45 -> 2306 | Y20: =高情景!Y20*0.55+低情景!Y20*0.45 -> 2335 | Z20: =高情景!Z20*0.55+低情景!Z20*0.45 -> 2358.5 | AA20: =高情景!AA20*0.55+低情景!AA20*0.45 -> 2382 | ... AS20: =高情景!AS20*0.55+低情景!AS20*0.45 -> 2709.5
A21: 汽车制造业 | B21: 汽车 | C21: 万辆 | D21: 2023节能与新能源汽车发展报告-结果微调 | E21: =高情景!E21*0.5+低情景!E21*0.5 -> 2532.49 | F21: =高情景!F21*0.5+低情景!F21*0.5 -> 2625.7 | G21: =高情景!G21*0.7+低情景!G21*0.3 -> 2713.63 | H21: =高情景!H21*0.7+低情景!H21*0.3 -> 2961.3696 | I21: =高情景!I21*0.7+低情景!I21*0.3 -> 3209.1092 | J21: =高情景!J21*0.75+低情景!J21*0.25 -> 3450.5176 | K21: =高情景!K21*0.75+低情景!K21*0.25 -> 3552.7552 | L21: =高情景!L21*0.75+低情景!L21*0.25 -> 3654.9927 | M21: =高情景!M21*0.75+低情景!M21*0.25 -> 3757.2303 | N21: =高情景!N21*0.72+低情景!N21*0.28 -> 3863.7168 | O21: =高情景!O21*0.7+低情景!O21*0.3 -> 3968.9746 | P21: =高情景!P21*0.7+低情景!P21*0.3 -> 4020.1872 | Q21: =高情景!Q21*0.68+低情景!Q21*0.32 -> 4074.3825 | R21: =高情景!R21*0.65+低情景!R21*0.35 -> 4130.1629 | S21: =高情景!S21*0.6+低情景!S21*0.4 -> 4189.1136 | T21: =高情景!T21*0.55+低情景!T21*0.45 -> 4248.252 | U21: =高情景!U21*0.55+低情景!U21*0.45 -> 4259.0151 | V21: =高情景!V21*0.55+低情景!V21*0.45 -> 4269.7781 | W21: =高情景!W21*0.55+低情景!W21*0.45 -> 4280.5412 | X21: =高情景!X21*0.55+低情景!X21*0.45 -> 4291.3043 | Y21: =高情景!Y21*0.55+低情景!Y21*0.45 -> 4302.0674 | Z21: =高情景!Z21*0.55+低情景!Z21*0.45 -> 4301.3758 | AA21: =高情景!AA21*0.55+低情景!AA21*0.45 -> 4300.6843 | ... AS21: =高情景!AS21*0.55+低情景!AS21*0.45 -> 4164.278
A25: 用于BPE
A26: 行业 | B26: 温室气体 | C26: 产品产量 | D26: 单位 | E26: 数据来源 | F26: 2018 | G26: 2019 | H26: 2020 | I26: 2021 | J26: 2022 | K26: 2023 | L26: 2024 | M26: 2025 | N26: 2026 | O26: 2027 | P26: 2028 | Q26: 2029 | R26: 2030 | S26: 2031 | T26: 2032 | U26: 2033 | V26: 2034 | W26: 2035 | X26: 2036 | Y26: 2037 | Z26: 2038 | AA26: 2039 | AB26: 2040 | AC26: 2041 | AD26: 2042 | AE26: 2043 | AF26: 2044 | AG26: 2045 | AH26: 2046 | AI26: 2047 | AJ26: 2048 | AK26: 2049 | AL26: 2050 | AM26: 2051 | AN26: 2052 | AO26: 2053 | AP26: 2054 | AQ26: 2055 | AR26: 2056 | AS26: 2057 | AT26: 2058 | AU26: 2059 | AV26: 2060
A27: 农、林、牧、渔业 | B27: CH4+N2O | C27: 人口 | D27: 亿人 | E27: WR | F27: =F40 -> 13.9538 | G27: =G40 -> 14.007931 | H27: =H40 -> 14.131352 | I27: =I40 -> 14.16016 | J27: =J40 -> 14.188968 | K27: =K40 -> 14.217777 | L27: =L40 -> 14.246585 | M27: =M40 -> 14.275393 | ... AV27: =AV40 -> 12.351956
A28: 煤炭开采和洗选业 | B28: CH4 | C28: 原煤 | D28: 亿吨 | E28: 中石化《中国能源展望2060》 | F28: 36.98 | G28: 38.46 | H28: =E2 -> 39.02 | I28: =F2 -> 41.26 | J28: =G2 -> 45.59 | K28: =H2 -> 46.826667 | L28: =I2 -> 48.063333 | M28: =J2 -> 49.25 | N28: =K2 -> 50.05 | O28: =L2 -> 50.85 | ... AV28: =AS2 -> 31.85
A29: 石油和天然气开采业 | B29: CH4 | C29: 原油 | D29: 亿吨 | E29: 中石油《世界与中国能源展望2021》 | F29: 1.8932 | G29: 1.9101 | H29: =E3 -> 1.9477 | I29: =F3 -> 1.9888 | J29: =G3 -> 2.0472 | K29: =H3 -> 2.0911333 | L29: =I3 -> 2.1350667 | M29: =J3 -> 2.1775 | N29: =K3 -> 2.1895 | O29: =L3 -> 2.2015 | ... AV29: =AS3 -> 1.782
A30: 石油和天然气开采业 | B30: CH4 | C30: 天然气 | D30: 亿立方米 | E30: 中石油《世界与中国能源展望2021》 | F30: 1601.59 | G30: 1761.74 | H30: =E4 -> 1924.95 | I30: =F4 -> 2075.84 | J30: =G4 -> 2201.1 | K30: =H4 -> 2309.1 | L30: =I4 -> 2417.1 | M30: =J4 -> 2519.75 | N30: =K4 -> 2590.8 | O30: =L4 -> 2661.85 | ... AV30: =AS4 -> 3680
