Workbook

Sheet About
A1: 低情景-制氢产业增加值预测
B2: 2019 | C2: 2020-2025 | D2: 2026-2035 | E2: 2036-2050 | F2: 数据来源
A3: 产业产值(亿元) | B3: 3000 | C3: 10000 | D3: 50000 | E3: 120000 | F3: 中国氢能联盟
A4: 氢气制取成本(元/公斤) | B4: <20 | C4: <20 | D4: <15 | E4: <10 | F4: 中国氢能联盟
A5: 终端销售价格(元/公斤) | B5: 35 | C5: 30 | D5: 30 | E5: 20 | F5: https://new.qq.com/rain/a/20220609A02TW900;《中国氢能产业发展报告2020》
A6: 成本/终端售价(%) | B6: =20/35 -> 0.57142857 | C6: =20/30 -> 0.66666667 | D6: =15/30 -> 0.5 | E6: =10/20 -> 0.5
A7: 增加值（亿元) | B7: =B3-B3*B6 -> 1285.7143 | C7: =C3-C3*C6 -> 3333.3333 | D7: =D3-D3*D6 -> 25000 | E7: =E3-E3*E6 -> 60000
A8: 增加值增量(亿元) | B8: 0 | C8: =C7-B7 -> 2047.619 | D8: =D7-C7 -> 21666.667 | E8: =E7-D7 -> 35000

Sheet 情景假设
A1: 假设1：实际GDP年均增速
B2: 2020-2025 | C2: 2025-2030 | D2: 2030-2035 | E2: 2035-2040 | F2: 2040-2045 | G2: 2045-2050 | H2: 2050-2055 | I2: 2055-2060
A3: 高情景 | B3: 0.053258208 | C3: 0.049592697 | D3: 0.036428571 | E3: 0.03 | F3: 0.029 | G3: 0.028 | H3: 0.0265 | I3: 0.025
A4: 中情景 | B4: 0.053554477 | C4: 0.051198243 | D4: 0.038396035 | E4: 0.033 | F4: 0.0315 | G4: 0.03 | H4: 0.0285 | I4: 0.0265
A5: 低情景 | B5: 0.053718794 | C5: 0.051812646 | D5: 0.040696755 | E5: 0.036 | F5: 0.034 | G5: 0.032 | H5: 0.03 | I5: 0.028
A7: 结果1：实际GDP | B7: 步骤1：根据假设1计算2025、2030、2035和2060年实际GDP。步骤2：:将数据粘贴至"数据平滑/输入/假设1：GDP-2020年不变价.xlsx"；通过运行python代码假设1；结果保存至"数据平滑/输出/结果1：GDP数据平滑.xlsx"。步骤3：将Python结果粘贴至“Python数据平滑"sheet的对应位置，下方列表会自动更新。
A8: GDP（2020年不变价） | B8: 2020 | C8: 2021 | D8: 2022 | E8: 2023 | F8: 2024 | G8: 2025 | H8: 2026 | I8: 2027 | J8: 2028 | K8: 2029 | L8: 2030 | M8: 2031 | N8: 2032 | O8: 2033 | P8: 2034 | Q8: 2035 | R8: 2036 | S8: 2037 | T8: 2038 | U8: 2039 | V8: 2040 | W8: 2041 | X8: 2042 | Y8: 2043 | Z8: 2044 | AA8: 2045 | AB8: 2046 | AC8: 2047 | AD8: 2048 | AE8: 2049 | AF8: 2050 | AG8: 2051 | AH8: 2052 | AI8: 2053 | AJ8: 2054 | AK8: 2055 | AL8: 2056 | AM8: 2057 | AN8: 2058 | AO8: 2059 | AP8: 2060
A9: 高情景 | B9: 1013567 | C9: 1098706.6 | D9: 1131667.8 | E9: =VLOOKUP($A9,Python数据平滑!$A$2:$AN$5,COLUMN(Python数据平滑!C$2),0) -> 1193070.7 | F9: =VLOOKUP($A9,Python数据平滑!$A$2:$AN$5,COLUMN(Python数据平滑!D$2),0) -> 1256709.5 | G9: =D9*(1+B3)^3 -> 1322280.3 | H9: =VLOOKUP($A9,Python数据平滑!$A$2:$AN$5,COLUMN(Python数据平滑!F$2),0) -> 1391094.7 | I9: =VLOOKUP($A9,Python数据平滑!$A$2:$AN$5,COLUMN(Python数据平滑!G$2),0) -> 1463691.4 | J9: =VLOOKUP($A9,Python数据平滑!$A$2:$AN$5,COLUMN(Python数据平滑!H$2),0) -> 1538282.7 | K9: =VLOOKUP($A9,Python数据平滑!$A$2:$AN$5,COLUMN(Python数据平滑!I$2),0) -> 1612689.6 | L9: =G9*(1+C3)^5 -> 1684331.3 | M9: =VLOOKUP($A9,Python数据平滑!$A$2:$AN$5,COLUMN(Python数据平滑!K$2),0) -> 1752648.1 | N9: =VLOOKUP($A9,Python数据平滑!$A$2:$AN$5,COLUMN(Python数据平滑!L$2),0) -> 1819256.8 | O9: =VLOOKUP($A9,Python数据平滑!$A$2:$AN$5,COLUMN(Python数据平滑!M$2),0) -> 1884644.2 | P9: =VLOOKUP($A9,Python数据平滑!$A$2:$AN$5,COLUMN(Python数据平滑!N$2),0) -> 1949417.4 | Q9: =L9*(1+D3)^5 -> 2014301.2 | R9: =VLOOKUP($A9,Python数据平滑!$A$2:$AN$5,COLUMN(Python数据平滑!P$2),0) -> 2078635.3 | S9: =VLOOKUP($A9,Python数据平滑!$A$2:$AN$5,COLUMN(Python数据平滑!Q$2),0) -> 2141814.9 | T9: =VLOOKUP($A9,Python数据平滑!$A$2:$AN$5,COLUMN(Python数据平滑!R$2),0) -> 2204840.9 | U9: =VLOOKUP($A9,Python数据平滑!$A$2:$AN$5,COLUMN(Python数据平滑!S$2),0) -> 2268851.9 | V9: =Q9*(1+E3)^5 -> 2335127.2 | W9: =VLOOKUP($A9,Python数据平滑!$A$2:$AN$5,COLUMN(Python数据平滑!U$2),0) -> 2403770.6 | X9: =VLOOKUP($A9,Python数据平滑!$A$2:$AN$5,COLUMN(Python数据平滑!V$2),0) -> 2473965.9 | Y9: =VLOOKUP($A9,Python数据平滑!$A$2:$AN$5,COLUMN(Python数据平滑!W$2),0) -> 2545721.3 | Z9: =VLOOKUP($A9,Python数据平滑!$A$2:$AN$5,COLUMN(Python数据平滑!X$2),0) -> 2619043.3 | AA9: =V9*(1+F3)^5 -> 2693936.8 | AB9: =VLOOKUP($A9,Python数据平滑!$A$2:$AN$5,COLUMN(Python数据平滑!Z$2),0) -> 2770546.3 | AC9: =VLOOKUP($A9,Python数据平滑!$A$2:$AN$5,COLUMN(Python数据平滑!AA$2),0) -> 2848914.1 | AD9: =VLOOKUP($A9,Python数据平滑!$A$2:$AN$5,COLUMN(Python数据平滑!AB$2),0) -> 2928875 | AE9: =VLOOKUP($A9,Python数据平滑!$A$2:$AN$5,COLUMN(Python数据平滑!AC$2),0) -> 3010242.7 | AF9: =AA9*(1+G3)^5 -> 3092808.1 | AG9: =VLOOKUP($A9,Python数据平滑!$A$2:$AN$5,COLUMN(Python数据平滑!AE$2),0) -> 3176593.4 | AH9: =VLOOKUP($A9,Python数据平滑!$A$2:$AN$5,COLUMN(Python数据平滑!AF$2),0) -> 3261743.4 | AI9: =VLOOKUP($A9,Python数据平滑!$A$2:$AN$5,COLUMN(Python数据平滑!AG$2),0) -> 3348213.3 | AJ9: =VLOOKUP($A9,Python数据平滑!$A$2:$AN$5,COLUMN(Python数据平滑!AH$2),0) -> 3435953.1 | AK9: =AF9*(1+H3)^5 -> 3524907.7 | AL9: =VLOOKUP($A9,Python数据平滑!$A$2:$AN$5,COLUMN(Python数据平滑!AJ$2),0) -> 3615095.8 | AM9: =VLOOKUP($A9,Python数据平滑!$A$2:$AN$5,COLUMN(Python数据平滑!AK$2),0) -> 3706550.8 | AN9: =VLOOKUP($A9,Python数据平滑!$A$2:$AN$5,COLUMN(Python数据平滑!AL$2),0) -> 3799233.8 | AO9: =VLOOKUP($A9,Python数据平滑!$A$2:$AN$5,COLUMN(Python数据平滑!AM$2),0) -> 3893102 | AP9: =AK9*(1+I3)^5 -> 3988109.5 | AQ9: =AP9/B9 -> 3.9347271
A10: 中情景 | B10: 1013567 | C10: 1098706.6 | D10: 1131667.8 | E10: =VLOOKUP($A10,Python数据平滑!$A$2:$AN$5,COLUMN(Python数据平滑!C$2),0) -> 1192997.2 | F10: =VLOOKUP($A10,Python数据平滑!$A$2:$AN$5,COLUMN(Python数据平滑!D$2),0) -> 1256946.5 | G10: =D10*(1+B4)^3 -> 1323396.4 | H10: =VLOOKUP($A10,Python数据平滑!$A$2:$AN$5,COLUMN(Python数据平滑!F$2),0) -> 1393766.9 | I10: =VLOOKUP($A10,Python数据平滑!$A$2:$AN$5,COLUMN(Python数据平滑!G$2),0) -> 1468542.8 | J10: =VLOOKUP($A10,Python数据平滑!$A$2:$AN$5,COLUMN(Python数据平滑!H$2),0) -> 1545878.3 | K10: =VLOOKUP($A10,Python数据平滑!$A$2:$AN$5,COLUMN(Python数据平滑!I$2),0) -> 1623499.4 | L10: =G10*(1+C4)^5 -> 1698685.9 | M10: =VLOOKUP($A10,Python数据平滑!$A$2:$AN$5,COLUMN(Python数据平滑!K$2),0) -> 1770660.5 | N10: =VLOOKUP($A10,Python数据平滑!$A$2:$AN$5,COLUMN(Python数据平滑!L$2),0) -> 1841070.2 | O10: =VLOOKUP($A10,Python数据平滑!$A$2:$AN$5,COLUMN(Python数据平滑!M$2),0) -> 1910626.4 | P10: =VLOOKUP($A10,Python数据平滑!$A$2:$AN$5,COLUMN(Python数据平滑!N$2),0) -> 1980200.7 | Q10: =L10*(1+D4)^5 -> 2050823.1 | R10: =VLOOKUP($A10,Python数据平滑!$A$2:$AN$5,COLUMN(Python数据平滑!P$2),0) -> 2122024.8 | S10: =VLOOKUP($A10,Python数据平滑!$A$2:$AN$5,COLUMN(Python数据平滑!Q$2),0) -> 2192996 | T10: =VLOOKUP($A10,Python数据平滑!$A$2:$AN$5,COLUMN(Python数据平滑!R$2),0) -> 2264458 | U10: =VLOOKUP($A10,Python数据平滑!$A$2:$AN$5,COLUMN(Python数据平滑!S$2),0) -> 2337241.7 | V10: =Q10*(1+E4)^5 -> 2412291.6 | W10: =VLOOKUP($A10,Python数据平滑!$A$2:$AN$5,COLUMN(Python数据平滑!U$2),0) -> 2489706.4 | X10: =VLOOKUP($A10,Python数据平滑!$A$2:$AN$5,COLUMN(Python数据平滑!V$2),0) -> 2568890.5 | Y10: =VLOOKUP($A10,Python数据平滑!$A$2:$AN$5,COLUMN(Python数据平滑!W$2),0) -> 2649832.9 | Z10: =VLOOKUP($A10,Python数据平滑!$A$2:$AN$5,COLUMN(Python数据平滑!X$2),0) -> 2732518.9 | AA10: =V10*(1+F4)^5 -> 2816929.4 | AB10: =VLOOKUP($A10,Python数据平滑!$A$2:$AN$5,COLUMN(Python数据平滑!Z$2),0) -> 2903103.3 | AC10: =VLOOKUP($A10,Python数据平滑!$A$2:$AN$5,COLUMN(Python数据平滑!AA$2),0) -> 2991081.3 | AD10: =VLOOKUP($A10,Python数据平滑!$A$2:$AN$5,COLUMN(Python数据平滑!AB$2),0) -> 3080841.1 | AE10: =VLOOKUP($A10,Python数据平滑!$A$2:$AN$5,COLUMN(Python数据平滑!AC$2),0) -> 3172355.6 | AF10: =AA10*(1+G4)^5 -> 3265593.3 | AG10: =VLOOKUP($A10,Python数据平滑!$A$2:$AN$5,COLUMN(Python数据平滑!AE$2),0) -> 3360731.8 | AH10: =VLOOKUP($A10,Python数据平滑!$A$2:$AN$5,COLUMN(Python数据平滑!AF$2),0) -> 3457824.4 | AI10: =VLOOKUP($A10,Python数据平滑!$A$2:$AN$5,COLUMN(Python数据平滑!AG$2),0) -> 3556626.7 | AJ10: =VLOOKUP($A10,Python数据平滑!$A$2:$AN$5,COLUMN(Python数据平滑!AH$2),0) -> 3656864.3 | AK10: =AF10*(1+H4)^5 -> 3758231.9 | AL10: =VLOOKUP($A10,Python数据平滑!$A$2:$AN$5,COLUMN(Python数据平滑!AJ$2),0) -> 3860743.6 | AM10: =VLOOKUP($A10,Python数据平滑!$A$2:$AN$5,COLUMN(Python数据平滑!AK$2),0) -> 3964585.3 | AN10: =VLOOKUP($A10,Python数据平滑!$A$2:$AN$5,COLUMN(Python数据平滑!AL$2),0) -> 4069680.9 | AO10: =VLOOKUP($A10,Python数据平滑!$A$2:$AN$5,COLUMN(Python数据平滑!AM$2),0) -> 4175948.1 | AP10: =AK10*(1+I4)^5 -> 4283298.5 | AQ10: =AP10/B10 -> 4.2259648
A11: 低情景 | B11: 1013567 | C11: 1098706.6 | D11: 1131667.8 | E11: =VLOOKUP($A11,Python数据平滑!$A$2:$AN$5,COLUMN(Python数据平滑!C$2),0) -> 1193043.8 | F11: =VLOOKUP($A11,Python数据平滑!$A$2:$AN$5,COLUMN(Python数据平滑!D$2),0) -> 1257179.2 | G11: =D11*(1+B5)^3 -> 1324015.7 | H11: =VLOOKUP($A11,Python数据平滑!$A$2:$AN$5,COLUMN(Python数据平滑!F$2),0) -> 1394801 | I11: =VLOOKUP($A11,Python数据平滑!$A$2:$AN$5,COLUMN(Python数据平滑!G$2),0) -> 1469972.4 | J11: =VLOOKUP($A11,Python数据平滑!$A$2:$AN$5,COLUMN(Python数据平滑!H$2),0) -> 1547981.5 | K11: =VLOOKUP($A11,Python数据平滑!$A$2:$AN$5,COLUMN(Python数据平滑!I$2),0) -> 1626911.1 | L11: =G11*(1+C5)^5 -> 1704453.2 | M11: =VLOOKUP($A11,Python数据平滑!$A$2:$AN$5,COLUMN(Python数据平滑!K$2),0) -> 1779831.6 | N11: =VLOOKUP($A11,Python数据平滑!$A$2:$AN$5,COLUMN(Python数据平滑!L$2),0) -> 1854381.9 | O11: =VLOOKUP($A11,Python数据平滑!$A$2:$AN$5,COLUMN(Python数据平滑!M$2),0) -> 1928788.7 | P11: =VLOOKUP($A11,Python数据平滑!$A$2:$AN$5,COLUMN(Python数据平滑!N$2),0) -> 2003890.8 | Q11: =L11*(1+D5)^5 -> 2080683.8 | R11: =VLOOKUP($A11,Python数据平滑!$A$2:$AN$5,COLUMN(Python数据平滑!P$2),0) -> 2158866.1 | S11: =VLOOKUP($A11,Python数据平滑!$A$2:$AN$5,COLUMN(Python数据平滑!Q$2),0) -> 2237676.8 | T11: =VLOOKUP($A11,Python数据平滑!$A$2:$AN$5,COLUMN(Python数据平滑!R$2),0) -> 2317603.2 | U11: =VLOOKUP($A11,Python数据平滑!$A$2:$AN$5,COLUMN(Python数据平滑!S$2),0) -> 2399213.6 | V11: =Q11*(1+E5)^5 -> 2483160.9 | W11: =VLOOKUP($A11,Python数据平滑!$A$2:$AN$5,COLUMN(Python数据平滑!U$2),0) -> 2569541.8 | X11: =VLOOKUP($A11,Python数据平滑!$A$2:$AN$5,COLUMN(Python数据平滑!V$2),0) -> 2657953.6 | Y11: =VLOOKUP($A11,Python数据平滑!$A$2:$AN$5,COLUMN(Python数据平滑!W$2),0) -> 2748362.2 | Z11: =VLOOKUP($A11,Python数据平滑!$A$2:$AN$5,COLUMN(Python数据平滑!X$2),0) -> 2840726.1 | AA11: =V11*(1+F5)^5 -> 2934996.3 | AB11: =VLOOKUP($A11,Python数据平滑!$A$2:$AN$5,COLUMN(Python数据平滑!Z$2),0) -> 3031222.7 | AC11: =VLOOKUP($A11,Python数据平滑!$A$2:$AN$5,COLUMN(Python数据平滑!AA$2),0) -> 3129458.9 | AD11: =VLOOKUP($A11,Python数据平滑!$A$2:$AN$5,COLUMN(Python数据平滑!AB$2),0) -> 3229649.3 | AE11: =VLOOKUP($A11,Python数据平滑!$A$2:$AN$5,COLUMN(Python数据平滑!AC$2),0) -> 3331729.8 | AF11: =AA11*(1+G5)^5 -> 3435627.3 | AG11: =VLOOKUP($A11,Python数据平滑!$A$2:$AN$5,COLUMN(Python数据平滑!AE$2),0) -> 3541393 | AH11: =VLOOKUP($A11,Python数据平滑!$A$2:$AN$5,COLUMN(Python数据平滑!AF$2),0) -> 3649082 | AI11: =VLOOKUP($A11,Python数据平滑!$A$2:$AN$5,COLUMN(Python数据平滑!AG$2),0) -> 3758613.8 | AJ11: =VLOOKUP($A11,Python数据平滑!$A$2:$AN$5,COLUMN(Python数据平滑!AH$2),0) -> 3869897.8 | AK11: =AF11*(1+H5)^5 -> 3982833.7 | AL11: =VLOOKUP($A11,Python数据平滑!$A$2:$AN$5,COLUMN(Python数据平滑!AJ$2),0) -> 4097450.8 | AM11: =VLOOKUP($A11,Python数据平滑!$A$2:$AN$5,COLUMN(Python数据平滑!AK$2),0) -> 4213806 | AN11: =VLOOKUP($A11,Python数据平滑!$A$2:$AN$5,COLUMN(Python数据平滑!AL$2),0) -> 4331826.9 | AO11: =VLOOKUP($A11,Python数据平滑!$A$2:$AN$5,COLUMN(Python数据平滑!AM$2),0) -> 4451434.4 | AP11: =AK11*(1+I5)^5 -> 4572542.4 | AQ11: =AP11/B11 -> 4.5113371
A15: 假设2：三次产业结构 | V15: 高情景年均增速 | AB15: 中情景年均增速 | AH15: 低情景年均增速
A16: 高情景 | B16: 2025 | C16: 2030 | D16: 2035 | E16: 2050 | F16: 2060 | G16: 2022 | H16: 中情景 | I16: 2025 | J16: 2030 | K16: 2035 | L16: 2050 | M16: 2060 | O16: 低情景 | P16: 2025 | Q16: 2030 | R16: 2035 | S16: 2050 | T16: 2060 | V16: 2025 | W16: 2030 | X16: 2035 | Y16: 2050 | Z16: 2060 | AB16: 2025 | AC16: 2030 | AD16: 2035 | AE16: 2050 | AF16: 2060 | AH16: 2025 | AI16: 2030 | AJ16: 2035 | AK16: 2050 | AL16: 2060
A17: 农业 | B17: 0.075 | C17: 0.0715 | D17: 0.069 | E17: 0.0645 | F17: 0.063 | G17: =D27/$D$9 -> 0.07650128 | H17: 农业 | I17: =B17*0.4+P17*0.6 -> 0.075 | J17: =C17*0.4+Q17*0.6 -> 0.0715 | K17: =D17*0.4+R17*0.6 -> 0.0684 | L17: =E17*0.4+S17*0.6 -> 0.0624 | M17: =F17*0.4+T17*0.6 -> 0.0606 | O17: 农业 | P17: 0.075 | Q17: 0.0715 | R17: 0.068 | S17: 0.061 | T17: 0.059 | V17: =(G27/D27)^(1/3)-1 -> 0.046322841 | W17: =(L27/G27)^0.2-1 -> 0.039608342 | X17: =(Q27/L27)^0.2-1 -> 0.029077272 | Y17: =(AF27/Q27)^(1/15)-1 -> 0.024383591 | Z17: =(AP27/AF27)^0.1-1 -> 0.023338923 | AB17: =(G33/D33)^(1/3)-1 -> 0.046617159 | AC17: =(L33/G33)^0.2-1 -> 0.041198616 | AD17: =(Q33/L33)^0.2-1 -> 0.029231414 | AE17: =(AF33/Q33)^(1/15)-1 -> 0.025205259 | AF17: =(AP33/AF33)^0.1-1 -> 0.02449638 | AH17: =(G39/D39)^(1/3)-1 -> 0.046780394 | AI17: =(L39/G39)^0.2-1 -> 0.041807174 | AJ17: =(Q39/L39)^0.2-1 -> 0.03030255 | AK17: =(AF39/Q39)^(1/15)-1 -> 0.026537278 | AL17: =(AP39/AF39)^0.1-1 -> 0.025574909
A18: 工业 | B18: 0.315 | C18: 0.29 | D18: 0.273 | E18: 0.23 | F18: 0.21 | G18: =D28/$D$9 -> 0.33188061 | H18: 工业 | I18: =B18*0.4+P18*0.6 -> 0.3138 | J18: =C18*0.4+Q18*0.6 -> 0.287 | K18: =D18*0.4+R18*0.6 -> 0.2706 | L18: =E18*0.4+S18*0.6 -> 0.2228 | M18: =F18*0.4+T18*0.6 -> 0.2028 | O18: 工业 | P18: 0.313 | Q18: 0.285 | R18: 0.269 | S18: 0.218 | T18: 0.198 | V18: =(G28/D28)^(1/3)-1 -> 0.035089123 | W18: =(L28/G28)^0.2-1 -> 0.032376925 | X18: =(Q28/L28)^0.2-1 -> 0.023981962 | Y18: =(AF28/Q28)^(1/15)-1 -> 0.017309072 | Z18: =(AP28/AF28)^0.1-1 -> 0.016460615 | AB18: =(G34/D34)^(1/3)-1 -> 0.03406384 | AC18: =(L34/G34)^0.2-1 -> 0.032595951 | AD18: =(Q34/L34)^0.2-1 -> 0.026247708 | AE18: =(AF34/Q34)^(1/15)-1 -> 0.018219521 | AF18: =(AP34/AF34)^0.1-1 -> 0.01788075 | AH18: =(G40/D40)^(1/3)-1 -> 0.033345486 | AI18: =(L40/G40)^0.2-1 -> 0.032282328 | AJ18: =(Q40/L40)^0.2-1 -> 0.028740137 | AK18: =(AF40/Q40)^(1/15)-1 -> 0.019608885 | AL18: =(AP40/AF40)^0.1-1 -> 0.019145144
A19: 建筑业 | B19: 0.068 | C19: 0.063 | D19: 0.059 | E19: 0.052 | F19: 0.048 | G19: =D29/$D$9 -> 0.068899855 | H19: 建筑业 | I19: =B19*0.4+P19*0.6 -> 0.0668 | J19: =C19*0.4+Q19*0.6 -> 0.0612 | K19: =D19*0.4+R19*0.6 -> 0.0566 | L19: =E19*0.4+S19*0.6 -> 0.0478 | M19: =F19*0.4+T19*0.6 -> 0.0432 | O19: 建筑业 | P19: 0.066 | Q19: 0.06 | R19: 0.055 | S19: 0.045 | T19: 0.04 | V19: =(G29/D29)^(1/3)-1 -> 0.048652802 | W19: =(L29/G29)^0.2-1 -> 0.033682414 | X19: =(Q29/L29)^0.2-1 -> 0.022919998 | Y19: =(AF29/Q29)^(1/15)-1 -> 0.0203723 | Z19: =(AP29/AF29)^0.1-1 -> 0.017572119 | AB19: =(G35/D35)^(1/3)-1 -> 0.042740839 | AC19: =(L35/G35)^0.2-1 -> 0.032950757 | AD19: =(Q35/L35)^0.2-1 -> 0.022294497 | AE19: =(AF35/Q35)^(1/15)-1 -> 0.01994407 | AF19: =(AP35/AF35)^0.1-1 -> 0.017155168 | AH19: =(G41/D41)^(1/3)-1 -> 0.03872345 | AI19: =(L41/G41)^0.2-1 -> 0.031952841 | AJ19: =(Q41/L41)^0.2-1 -> 0.022742935 | AK19: =(AF41/Q41)^(1/15)-1 -> 0.020257945 | AL19: =(AP41/AF41)^0.1-1 -> 0.016950742
A20: 服务业 | B20: =1-SUM(B17:B19) -> 0.542 | C20: =1-SUM(C17:C19) -> 0.5755 | D20: =1-SUM(D17:D19) -> 0.599 | E20: =1-SUM(E17:E19) -> 0.6535 | F20: =1-SUM(F17:F19) -> 0.679 | G20: =D30/$D$9 -> 0.52271826 | H20: 服务业 | I20: =B20*0.4+P20*0.6 -> 0.5444 | J20: =C20*0.4+Q20*0.6 -> 0.5803 | K20: =D20*0.4+R20*0.6 -> 0.6044 | L20: =E20*0.4+S20*0.6 -> 0.667 | M20: =F20*0.4+T20*0.6 -> 0.6934 | O20: 服务业 | P20: =1-SUM(P17:P19) -> 0.546 | Q20: =1-SUM(Q17:Q19) -> 0.5835 | R20: =1-SUM(R17:R19) -> 0.608 | S20: =1-SUM(S17:S19) -> 0.676 | T20: =1-SUM(T17:T19) -> 0.703 | V20: =(G30/D30)^(1/3)-1 -> 0.066052823 | W20: =(L30/G30)^0.2-1 -> 0.062257995 | X20: =(Q30/L30)^0.2-1 -> 0.044757928 | Y20: =(AF30/Q30)^(1/15)-1 -> 0.0349908 | Z20: =(AP30/AF30)^0.1-1 -> 0.029683676 | AB20: =(G36/D36)^(1/3)-1 -> 0.067924325 | AC20: =(L36/G36)^0.2-1 -> 0.064710451 | AD20: =(Q36/L36)^0.2-1 -> 0.046881194 | AE20: =(AF36/Q36)^(1/15)-1 -> 0.038298798 | AF20: =(AP36/AF36)^0.1-1 -> 0.031495708 | AH20: =(G42/D42)^(1/3)-1 -> 0.069136238 | AI20: =(L42/G42)^0.2-1 -> 0.065879309 | AJ20: =(Q42/L42)^0.2-1 -> 0.049292924 | AK20: =(AF42/Q42)^(1/15)-1 -> 0.041332777 | AL20: =(AP42/AF42)^0.1-1 -> 0.033037371
D21: 20.4
D22: 0.068
A23: 二产 | D23: 0.35 | F23: 0.3
A25: 结果2：农、工、建筑和服务业增加值
A26: 高情景 | B26: 2020 | C26: 2021 | D26: 2022 | E26: 2023 | F26: 2024 | G26: 2025 | H26: 2026 | I26: 2027 | J26: 2028 | K26: 2029 | L26: 2030 | M26: 2031 | N26: 2032 | O26: 2033 | P26: 2034 | Q26: 2035 | R26: 2036 | S26: 2037 | T26: 2038 | U26: 2039 | V26: 2040 | W26: 2041 | X26: 2042 | Y26: 2043 | Z26: 2044 | AA26: 2045 | AB26: 2046 | AC26: 2047 | AD26: 2048 | AE26: 2049 | AF26: 2050 | AG26: 2051 | AH26: 2052 | AI26: 2053 | AJ26: 2054 | AK26: 2055 | AL26: 2056 | AM26: 2057 | AN26: 2058 | AO26: 2059 | AP26: 2060
A27: 农业-高情景 | B27: ='高情景（2001-2060, 2020RMB）'!U3 -> 81396.5 | C27: ='高情景（2001-2060, 2020RMB）'!V3 -> 82959.622 | D27: ='高情景（2001-2060, 2020RMB）'!W3 -> 86574.037 | E27: =VLOOKUP($A27,Python数据平滑!$A$9:$AN$21,COLUMN(Python数据平滑!C$9),0)/SUM(Python数据平滑!C$10:C$13)*情景假设!E$9 -> 90742.731 | F27: =VLOOKUP($A27,Python数据平滑!$A$9:$AN$21,COLUMN(Python数据平滑!D$9),0)/SUM(Python数据平滑!D$10:D$13)*情景假设!F$9 -> 94959.47 | G27: =G$9*B17 -> 99171.022 | H27: =VLOOKUP($A27,Python数据平滑!$A$9:$AN$21,COLUMN(Python数据平滑!F$9),0)/SUM(Python数据平滑!F$10:F$13)*情景假设!H$9 -> 103422.66 | I27: =VLOOKUP($A27,Python数据平滑!$A$9:$AN$21,COLUMN(Python数据平滑!G$9),0)/SUM(Python数据平滑!G$10:G$13)*情景假设!I$9 -> 107753.21 | J27: =VLOOKUP($A27,Python数据平滑!$A$9:$AN$21,COLUMN(Python数据平滑!H$9),0)/SUM(Python数据平滑!H$10:H$13)*情景假设!J$9 -> 112087.45 | K27: =VLOOKUP($A27,Python数据平滑!$A$9:$AN$21,COLUMN(Python数据平滑!I$9),0)/SUM(Python数据平滑!I$10:I$13)*情景假设!K$9 -> 116342.73 | L27: =L$9*C17 -> 120429.69 | M27: =VLOOKUP($A27,Python数据平滑!$A$9:$AN$21,COLUMN(Python数据平滑!K$9),0)/SUM(Python数据平滑!K$10:K$13)*情景假设!M$9 -> 124312.56 | N27: =VLOOKUP($A27,Python数据平滑!$A$9:$AN$21,COLUMN(Python数据平滑!L$9),0)/SUM(Python数据平滑!L$10:L$13)*情景假设!N$9 -> 128050.95 | O27: =VLOOKUP($A27,Python数据平滑!$A$9:$AN$21,COLUMN(Python数据平滑!M$9),0)/SUM(Python数据平滑!M$10:M$13)*情景假设!O$9 -> 131699.95 | P27: =VLOOKUP($A27,Python数据平滑!$A$9:$AN$21,COLUMN(Python数据平滑!N$9),0)/SUM(Python数据平滑!N$10:N$13)*情景假设!P$9 -> 135322.05 | Q27: =Q$9*D17 -> 138986.78 | R27: =VLOOKUP($A27,Python数据平滑!$A$9:$AN$21,COLUMN(Python数据平滑!P$9),0)/SUM(Python数据平滑!P$10:P$13)*情景假设!R$9 -> 142625.93 | S27: =VLOOKUP($A27,Python数据平滑!$A$9:$AN$21,COLUMN(Python数据平滑!Q$9),0)/SUM(Python数据平滑!Q$10:Q$13)*情景假设!S$9 -> 146164.82 | T27: =VLOOKUP($A27,Python数据平滑!$A$9:$AN$21,COLUMN(Python数据平滑!R$9),0)/SUM(Python数据平滑!R$10:R$13)*情景假设!T$9 -> 149674.57 | U27: =VLOOKUP($A27,Python数据平滑!$A$9:$AN$21,COLUMN(Python数据平滑!S$9),0)/SUM(Python数据平滑!S$10:S$13)*情景假设!U$9 -> 153234.1 | V27: =VLOOKUP($A27,Python数据平滑!$A$9:$AN$21,COLUMN(Python数据平滑!T$9),0)/SUM(Python数据平滑!T$10:T$13)*情景假设!V$9 -> 156930.24 | W27: =VLOOKUP($A27,Python数据平滑!$A$9:$AN$21,COLUMN(Python数据平滑!U$9),0)/SUM(Python数据平滑!U$10:U$13)*情景假设!W$9 -> 160769.58 | X27: =VLOOKUP($A27,Python数据平滑!$A$9:$AN$21,COLUMN(Python数据平滑!V$9),0)/SUM(Python数据平滑!V$10:V$13)*情景假设!X$9 -> 164697.48 | Y27: =VLOOKUP($A27,Python数据平滑!$A$9:$AN$21,COLUMN(Python数据平滑!W$9),0)/SUM(Python数据平滑!W$10:W$13)*情景假设!Y$9 -> 168715.04 | ... AE27: =VLOOKUP($A27,Python数据平滑!$A$9:$AN$21,COLUMN(Python数据平滑!AC$9),0)/SUM(Python数据平滑!AC$10:AC$13)*情景假设!AE$9 -> 194825.29 | AF27: =E17*$AF$9 -> 199486.13 | AG27: =VLOOKUP($A27,Python数据平滑!$A$9:$AN$21,COLUMN(Python数据平滑!AE$9),0)/SUM(Python数据平滑!AE$10:AE$13)*情景假设!AG$9 -> 204227.06 | AH27: =VLOOKUP($A27,Python数据平滑!$A$9:$AN$21,COLUMN(Python数据平滑!AF$9),0)/SUM(Python数据平滑!AF$10:AF$13)*情景假设!AH$9 -> 209064.08 | AI27: =VLOOKUP($A27,Python数据平滑!$A$9:$AN$21,COLUMN(Python数据平滑!AG$9),0)/SUM(Python数据平滑!AG$10:AG$13)*情景假设!AI$9 -> 213996.56 | AJ27: =VLOOKUP($A27,Python数据平滑!$A$9:$AN$21,COLUMN(Python数据平滑!AH$9),0)/SUM(Python数据平滑!AH$10:AH$13)*情景假设!AJ$9 -> 219023.64 | AK27: =VLOOKUP($A27,Python数据平滑!$A$9:$AN$21,COLUMN(Python数据平滑!AI$9),0)/SUM(Python数据平滑!AI$10:AI$13)*情景假设!AK$9 -> 224144.22 | AL27: =VLOOKUP($A27,Python数据平滑!$A$9:$AN$21,COLUMN(Python数据平滑!AJ$9),0)/SUM(Python数据平滑!AJ$10:AJ$13)*情景假设!AL$9 -> 229361.95 | AM27: =VLOOKUP($A27,Python数据平滑!$A$9:$AN$21,COLUMN(Python数据平滑!AK$9),0)/SUM(Python数据平滑!AK$10:AK$13)*情景假设!AM$9 -> 234681.48 | AN27: =VLOOKUP($A27,Python数据平滑!$A$9:$AN$21,COLUMN(Python数据平滑!AL$9),0)/SUM(Python数据平滑!AL$10:AL$13)*情景假设!AN$9 -> 240102.89 | AO27: =VLOOKUP($A27,Python数据平滑!$A$9:$AN$21,COLUMN(Python数据平滑!AM$9),0)/SUM(Python数据平滑!AM$10:AM$13)*情景假设!AO$9 -> 245626.11 | AP27: =AP$9*F17 -> 251250.9
A28: 工业-高情景 | B28: ='高情景（2001-2060, 2020RMB）'!U4 -> 312902.9 | C28: ='高情景（2001-2060, 2020RMB）'!V4 -> 356193.68 | D28: ='高情景（2001-2060, 2020RMB）'!W4 -> 375578.61 | E28: =VLOOKUP($A28,Python数据平滑!$A$9:$AN$21,COLUMN(Python数据平滑!C$9),0)/SUM(Python数据平滑!C$10:C$13)*情景假设!E$9 -> 389021.39 | F28: =VLOOKUP($A28,Python数据平滑!$A$9:$AN$21,COLUMN(Python数据平滑!D$9),0)/SUM(Python数据平滑!D$10:D$13)*情景假设!F$9 -> 402682.28 | G28: =G$9*B18 -> 416518.29 | H28: =VLOOKUP($A28,Python数据平滑!$A$9:$AN$21,COLUMN(Python数据平滑!F$9),0)/SUM(Python数据平滑!F$10:F$13)*情景假设!H$9 -> 430756.29 | I28: =VLOOKUP($A28,Python数据平滑!$A$9:$AN$21,COLUMN(Python数据平滑!G$9),0)/SUM(Python数据平滑!G$10:G$13)*情景假设!I$9 -> 445436.87 | J28: =VLOOKUP($A28,Python数据平滑!$A$9:$AN$21,COLUMN(Python数据平滑!H$9),0)/SUM(Python数据平滑!H$10:H$13)*情景假设!J$9 -> 460207.79 | K28: =VLOOKUP($A28,Python数据平滑!$A$9:$AN$21,COLUMN(Python数据平滑!I$9),0)/SUM(Python数据平滑!I$10:I$13)*情景假设!K$9 -> 474685.21 | L28: =L$9*C18 -> 488456.09 | M28: =VLOOKUP($A28,Python数据平滑!$A$9:$AN$21,COLUMN(Python数据平滑!K$9),0)/SUM(Python数据平滑!K$10:K$13)*情景假设!M$9 -> 501530.51 | N28: =VLOOKUP($A28,Python数据平滑!$A$9:$AN$21,COLUMN(Python数据平滑!L$9),0)/SUM(Python数据平滑!L$10:L$13)*情景假设!N$9 -> 514208.9 | O28: =VLOOKUP($A28,Python数据平滑!$A$9:$AN$21,COLUMN(Python数据平滑!M$9),0)/SUM(Python数据平滑!M$10:M$13)*情景假设!O$9 -> 526494.48 | P28: =VLOOKUP($A28,Python数据平滑!$A$9:$AN$21,COLUMN(Python数据平滑!N$9),0)/SUM(Python数据平滑!N$10:N$13)*情景假设!P$9 -> 538391.31 | Q28: =Q$9*D18 -> 549904.23 | R28: =VLOOKUP($A28,Python数据平滑!$A$9:$AN$21,COLUMN(Python数据平滑!P$9),0)/SUM(Python数据平滑!P$10:P$13)*情景假设!R$9 -> 560802.44 | S28: =VLOOKUP($A28,Python数据平滑!$A$9:$AN$21,COLUMN(Python数据平滑!Q$9),0)/SUM(Python数据平滑!Q$10:Q$13)*情景假设!S$9 -> 571034.03 | T28: =VLOOKUP($A28,Python数据平滑!$A$9:$AN$21,COLUMN(Python数据平滑!R$9),0)/SUM(Python数据平滑!R$10:R$13)*情景假设!T$9 -> 580892.06 | U28: =VLOOKUP($A28,Python数据平滑!$A$9:$AN$21,COLUMN(Python数据平滑!S$9),0)/SUM(Python数据平滑!S$10:S$13)*情景假设!U$9 -> 590693.75 | V28: =VLOOKUP($A28,Python数据平滑!$A$9:$AN$21,COLUMN(Python数据平滑!T$9),0)/SUM(Python数据平滑!T$10:T$13)*情景假设!V$9 -> 600779.3 | W28: =VLOOKUP($A28,Python数据平滑!$A$9:$AN$21,COLUMN(Python数据平滑!U$9),0)/SUM(Python数据平滑!U$10:U$13)*情景假设!W$9 -> 611175.71 | X28: =VLOOKUP($A28,Python数据平滑!$A$9:$AN$21,COLUMN(Python数据平滑!V$9),0)/SUM(Python数据平滑!V$10:V$13)*情景假设!X$9 -> 621679.02 | Y28: =VLOOKUP($A28,Python数据平滑!$A$9:$AN$21,COLUMN(Python数据平滑!W$9),0)/SUM(Python数据平滑!W$10:W$13)*情景假设!Y$9 -> 632301.1 | ... AE28: =VLOOKUP($A28,Python数据平滑!$A$9:$AN$21,COLUMN(Python数据平滑!AC$9),0)/SUM(Python数据平滑!AC$10:AC$13)*情景假设!AE$9 -> 699531.94 | AF28: =E18*$AF$9 -> 711345.87 | AG28: =VLOOKUP($A28,Python数据平滑!$A$9:$AN$21,COLUMN(Python数据平滑!AE$9),0)/SUM(Python数据平滑!AE$10:AE$13)*情景假设!AG$9 -> 723301.31 | AH28: =VLOOKUP($A28,Python数据平滑!$A$9:$AN$21,COLUMN(Python数据平滑!AF$9),0)/SUM(Python数据平滑!AF$10:AF$13)*情景假设!AH$9 -> 735413.25 | AI28: =VLOOKUP($A28,Python数据平滑!$A$9:$AN$21,COLUMN(Python数据平滑!AG$9),0)/SUM(Python数据平滑!AG$10:AG$13)*情景假设!AI$9 -> 747674.84 | AJ28: =VLOOKUP($A28,Python数据平滑!$A$9:$AN$21,COLUMN(Python数据平滑!AH$9),0)/SUM(Python数据平滑!AH$10:AH$13)*情景假设!AJ$9 -> 760078.57 | AK28: =VLOOKUP($A28,Python数据平滑!$A$9:$AN$21,COLUMN(Python数据平滑!AI$9),0)/SUM(Python数据平滑!AI$10:AI$13)*情景假设!AK$9 -> 772616.25 | AL28: =VLOOKUP($A28,Python数据平滑!$A$9:$AN$21,COLUMN(Python数据平滑!AJ$9),0)/SUM(Python数据平滑!AJ$10:AJ$13)*情景假设!AL$9 -> 785296.1 | AM28: =VLOOKUP($A28,Python数据平滑!$A$9:$AN$21,COLUMN(Python数据平滑!AK$9),0)/SUM(Python数据平滑!AK$10:AK$13)*情景假设!AM$9 -> 798129.42 | AN28: =VLOOKUP($A28,Python数据平滑!$A$9:$AN$21,COLUMN(Python数据平滑!AL$9),0)/SUM(Python数据平滑!AL$10:AL$13)*情景假设!AN$9 -> 811111.73 | AO28: =VLOOKUP($A28,Python数据平滑!$A$9:$AN$21,COLUMN(Python数据平滑!AM$9),0)/SUM(Python数据平滑!AM$10:AM$13)*情景假设!AO$9 -> 824238.07 | AP28: =AP$9*F18 -> 837503
A29: 建筑业-高情景 | B29: ='高情景（2001-2060, 2020RMB）'!U5 -> 72444.7 | C29: ='高情景（2001-2060, 2020RMB）'!V5 -> 76614.92 | D29: ='高情景（2001-2060, 2020RMB）'!W5 -> 77971.749 | E29: =VLOOKUP($A29,Python数据平滑!$A$9:$AN$21,COLUMN(Python数据平滑!C$9),0)/SUM(Python数据平滑!C$10:C$13)*情景假设!E$9 -> 82102.135 | F29: =VLOOKUP($A29,Python数据平滑!$A$9:$AN$21,COLUMN(Python数据平滑!D$9),0)/SUM(Python数据平滑!D$10:D$13)*情景假设!F$9 -> 86141.36 | G29: =G$9*B19 -> 89915.06 | H29: =VLOOKUP($A29,Python数据平滑!$A$9:$AN$21,COLUMN(Python数据平滑!F$9),0)/SUM(Python数据平滑!F$10:F$13)*情景假设!H$9 -> 93435.146 | I29: =VLOOKUP($A29,Python数据平滑!$A$9:$AN$21,COLUMN(Python数据平滑!G$9),0)/SUM(Python数据平滑!G$10:G$13)*情景假设!I$9 -> 96828.844 | J29: =VLOOKUP($A29,Python数据平滑!$A$9:$AN$21,COLUMN(Python数据平滑!H$9),0)/SUM(Python数据平滑!H$10:H$13)*情景假设!J$9 -> 100079.88 | K29: =VLOOKUP($A29,Python数据平滑!$A$9:$AN$21,COLUMN(Python数据平滑!I$9),0)/SUM(Python数据平滑!I$10:I$13)*情景假设!K$9 -> 103176.7 | L29: =L$9*C19 -> 106112.87 | M29: =VLOOKUP($A29,Python数据平滑!$A$9:$AN$21,COLUMN(Python数据平滑!K$9),0)/SUM(Python数据平滑!K$10:K$13)*情景假设!M$9 -> 108856.54 | N29: =VLOOKUP($A29,Python数据平滑!$A$9:$AN$21,COLUMN(Python数据平滑!L$9),0)/SUM(Python数据平滑!L$10:L$13)*情景假设!N$9 -> 111423.28 | O29: =VLOOKUP($A29,Python数据平滑!$A$9:$AN$21,COLUMN(Python数据平滑!M$9),0)/SUM(Python数据平滑!M$10:M$13)*情景假设!O$9 -> 113887.68 | P29: =VLOOKUP($A29,Python数据平滑!$A$9:$AN$21,COLUMN(Python数据平滑!N$9),0)/SUM(Python数据平滑!N$10:N$13)*情景假设!P$9 -> 116331.6 | Q29: =Q$9*D19 -> 118843.77 | R29: =VLOOKUP($A29,Python数据平滑!$A$9:$AN$21,COLUMN(Python数据平滑!P$9),0)/SUM(Python数据平滑!P$10:P$13)*情景假设!R$9 -> 121370.51 | S29: =VLOOKUP($A29,Python数据平滑!$A$9:$AN$21,COLUMN(Python数据平滑!Q$9),0)/SUM(Python数据平滑!Q$10:Q$13)*情景假设!S$9 -> 123831.03 | T29: =VLOOKUP($A29,Python数据平滑!$A$9:$AN$21,COLUMN(Python数据平滑!R$9),0)/SUM(Python数据平滑!R$10:R$13)*情景假设!T$9 -> 126282.3 | U29: =VLOOKUP($A29,Python数据平滑!$A$9:$AN$21,COLUMN(Python数据平滑!S$9),0)/SUM(Python数据平滑!S$10:S$13)*情景假设!U$9 -> 128786.2 | V29: =VLOOKUP($A29,Python数据平滑!$A$9:$AN$21,COLUMN(Python数据平滑!T$9),0)/SUM(Python数据平滑!T$10:T$13)*情景假设!V$9 -> 131409.64 | W29: =VLOOKUP($A29,Python数据平滑!$A$9:$AN$21,COLUMN(Python数据平滑!U$9),0)/SUM(Python数据平滑!U$10:U$13)*情景假设!W$9 -> 134151.08 | X29: =VLOOKUP($A29,Python数据平滑!$A$9:$AN$21,COLUMN(Python数据平滑!V$9),0)/SUM(Python数据平滑!V$10:V$13)*情景假设!X$9 -> 136957.45 | Y29: =VLOOKUP($A29,Python数据平滑!$A$9:$AN$21,COLUMN(Python数据平滑!W$9),0)/SUM(Python数据平滑!W$10:W$13)*情景假设!Y$9 -> 139821.94 | ... AE29: =VLOOKUP($A29,Python数据平滑!$A$9:$AN$21,COLUMN(Python数据平滑!AC$9),0)/SUM(Python数据平滑!AC$10:AC$13)*情景假设!AE$9 -> 157814.03 | AF29: =E19*$AF$9 -> 160826.02 | AG29: =VLOOKUP($A29,Python数据平滑!$A$9:$AN$21,COLUMN(Python数据平滑!AE$9),0)/SUM(Python数据平滑!AE$10:AE$13)*情景假设!AG$9 -> 163825.73 | AH29: =VLOOKUP($A29,Python数据平滑!$A$9:$AN$21,COLUMN(Python数据平滑!AF$9),0)/SUM(Python数据平滑!AF$10:AF$13)*情景假设!AH$9 -> 166843.57 | AI29: =VLOOKUP($A29,Python数据平滑!$A$9:$AN$21,COLUMN(Python数据平滑!AG$9),0)/SUM(Python数据平滑!AG$10:AG$13)*情景假设!AI$9 -> 169877.1 | AJ29: =VLOOKUP($A29,Python数据平滑!$A$9:$AN$21,COLUMN(Python数据平滑!AH$9),0)/SUM(Python数据平滑!AH$10:AH$13)*情景假设!AJ$9 -> 172923.67 | AK29: =VLOOKUP($A29,Python数据平滑!$A$9:$AN$21,COLUMN(Python数据平滑!AI$9),0)/SUM(Python数据平滑!AI$10:AI$13)*情景假设!AK$9 -> 175980.48 | AL29: =VLOOKUP($A29,Python数据平滑!$A$9:$AN$21,COLUMN(Python数据平滑!AJ$9),0)/SUM(Python数据平滑!AJ$10:AJ$13)*情景假设!AL$9 -> 179048.49 | AM29: =VLOOKUP($A29,Python数据平滑!$A$9:$AN$21,COLUMN(Python数据平滑!AK$9),0)/SUM(Python数据平滑!AK$10:AK$13)*情景假设!AM$9 -> 182129.36 | AN29: =VLOOKUP($A29,Python数据平滑!$A$9:$AN$21,COLUMN(Python数据平滑!AL$9),0)/SUM(Python数据平滑!AL$10:AL$13)*情景假设!AN$9 -> 185221.15 | AO29: =VLOOKUP($A29,Python数据平滑!$A$9:$AN$21,COLUMN(Python数据平滑!AM$9),0)/SUM(Python数据平滑!AM$10:AM$13)*情景假设!AO$9 -> 188321.83 | AP29: =AP$9*F19 -> 191429.26
A30: 服务业-高情景 | B30: ='高情景（2001-2060, 2020RMB）'!U56 -> 546822.9 | C30: ='高情景（2001-2060, 2020RMB）'!V56 -> 582938.41 | D30: ='高情景（2001-2060, 2020RMB）'!W56 -> 591543.44 | E30: =VLOOKUP($A30,Python数据平滑!$A$9:$AN$21,COLUMN(Python数据平滑!C$9),0)/SUM(Python数据平滑!C$10:C$13)*情景假设!E$9 -> 631204.49 | F30: =VLOOKUP($A30,Python数据平滑!$A$9:$AN$21,COLUMN(Python数据平滑!D$9),0)/SUM(Python数据平滑!D$10:D$13)*情景假设!F$9 -> 672926.43 | G30: =G$9*B20 -> 716675.92 | H30: =VLOOKUP($A30,Python数据平滑!$A$9:$AN$21,COLUMN(Python数据平滑!F$9),0)/SUM(Python数据平滑!F$10:F$13)*情景假设!H$9 -> 763480.56 | I30: =VLOOKUP($A30,Python数据平滑!$A$9:$AN$21,COLUMN(Python数据平滑!G$9),0)/SUM(Python数据平滑!G$10:G$13)*情景假设!I$9 -> 813672.46 | J30: =VLOOKUP($A30,Python数据平滑!$A$9:$AN$21,COLUMN(Python数据平滑!H$9),0)/SUM(Python数据平滑!H$10:H$13)*情景假设!J$9 -> 865907.62 | K30: =VLOOKUP($A30,Python数据平滑!$A$9:$AN$21,COLUMN(Python数据平滑!I$9),0)/SUM(Python数据平滑!I$10:I$13)*情景假设!K$9 -> 918484.99 | L30: =L$9*C20 -> 969332.68 | M30: =VLOOKUP($A30,Python数据平滑!$A$9:$AN$21,COLUMN(Python数据平滑!K$9),0)/SUM(Python数据平滑!K$10:K$13)*情景假设!M$9 -> 1017948.5 | N30: =VLOOKUP($A30,Python数据平滑!$A$9:$AN$21,COLUMN(Python数据平滑!L$9),0)/SUM(Python数据平滑!L$10:L$13)*情景假设!N$9 -> 1065573.7 | O30: =VLOOKUP($A30,Python数据平滑!$A$9:$AN$21,COLUMN(Python数据平滑!M$9),0)/SUM(Python数据平滑!M$10:M$13)*情景假设!O$9 -> 1112562.1 | P30: =VLOOKUP($A30,Python数据平滑!$A$9:$AN$21,COLUMN(Python数据平滑!N$9),0)/SUM(Python数据平滑!N$10:N$13)*情景假设!P$9 -> 1159372.4 | Q30: =Q$9*D20 -> 1206566.4 | R30: =VLOOKUP($A30,Python数据平滑!$A$9:$AN$21,COLUMN(Python数据平滑!P$9),0)/SUM(Python数据平滑!P$10:P$13)*情景假设!R$9 -> 1253836.4 | S30: =VLOOKUP($A30,Python数据平滑!$A$9:$AN$21,COLUMN(Python数据平滑!Q$9),0)/SUM(Python数据平滑!Q$10:Q$13)*情景假设!S$9 -> 1300785 | T30: =VLOOKUP($A30,Python数据平滑!$A$9:$AN$21,COLUMN(Python数据平滑!R$9),0)/SUM(Python数据平滑!R$10:R$13)*情景假设!T$9 -> 1347991.9 | U30: =VLOOKUP($A30,Python数据平滑!$A$9:$AN$21,COLUMN(Python数据平滑!S$9),0)/SUM(Python数据平滑!S$10:S$13)*情景假设!U$9 -> 1396137.8 | V30: =VLOOKUP($A30,Python数据平滑!$A$9:$AN$21,COLUMN(Python数据平滑!T$9),0)/SUM(Python数据平滑!T$10:T$13)*情景假设!V$9 -> 1446008 | W30: =VLOOKUP($A30,Python数据平滑!$A$9:$AN$21,COLUMN(Python数据平滑!U$9),0)/SUM(Python数据平滑!U$10:U$13)*情景假设!W$9 -> 1497674.2 | X30: =VLOOKUP($A30,Python数据平滑!$A$9:$AN$21,COLUMN(Python数据平滑!V$9),0)/SUM(Python数据平滑!V$10:V$13)*情景假设!X$9 -> 1550631.9 | Y30: =VLOOKUP($A30,Python数据平滑!$A$9:$AN$21,COLUMN(Python数据平滑!W$9),0)/SUM(Python数据平滑!W$10:W$13)*情景假设!Y$9 -> 1604883.2 | ... AE30: =VLOOKUP($A30,Python数据平滑!$A$9:$AN$21,COLUMN(Python数据平滑!AC$9),0)/SUM(Python数据平滑!AC$10:AC$13)*情景假设!AE$9 -> 1958071.4 | AF30: =E20*$AF$9 -> 2021150.1 | AG30: =VLOOKUP($A30,Python数据平滑!$A$9:$AN$21,COLUMN(Python数据平滑!AE$9),0)/SUM(Python数据平滑!AE$10:AE$13)*情景假设!AG$9 -> 2085239.3 | AH30: =VLOOKUP($A30,Python数据平滑!$A$9:$AN$21,COLUMN(Python数据平滑!AF$9),0)/SUM(Python数据平滑!AF$10:AF$13)*情景假设!AH$9 -> 2150422.5 | AI30: =VLOOKUP($A30,Python数据平滑!$A$9:$AN$21,COLUMN(Python数据平滑!AG$9),0)/SUM(Python数据平滑!AG$10:AG$13)*情景假设!AI$9 -> 2216664.8 | AJ30: =VLOOKUP($A30,Python数据平滑!$A$9:$AN$21,COLUMN(Python数据平滑!AH$9),0)/SUM(Python数据平滑!AH$10:AH$13)*情景假设!AJ$9 -> 2283927.2 | AK30: =VLOOKUP($A30,Python数据平滑!$A$9:$AN$21,COLUMN(Python数据平滑!AI$9),0)/SUM(Python数据平滑!AI$10:AI$13)*情景假设!AK$9 -> 2352166.8 | AL30: =VLOOKUP($A30,Python数据平滑!$A$9:$AN$21,COLUMN(Python数据平滑!AJ$9),0)/SUM(Python数据平滑!AJ$10:AJ$13)*情景假设!AL$9 -> 2421389.2 | AM30: =VLOOKUP($A30,Python数据平滑!$A$9:$AN$21,COLUMN(Python数据平滑!AK$9),0)/SUM(Python数据平滑!AK$10:AK$13)*情景假设!AM$9 -> 2491610.5 | AN30: =VLOOKUP($A30,Python数据平滑!$A$9:$AN$21,COLUMN(Python数据平滑!AL$9),0)/SUM(Python数据平滑!AL$10:AL$13)*情景假设!AN$9 -> 2562798 | AO30: =VLOOKUP($A30,Python数据平滑!$A$9:$AN$21,COLUMN(Python数据平滑!AM$9),0)/SUM(Python数据平滑!AM$10:AM$13)*情景假设!AO$9 -> 2634916 | AP30: =AP$9*F20 -> 2707926.4
A32: 中情景 | B32: 2020 | C32: 2021 | D32: 2022 | E32: 2023 | F32: 2024 | G32: 2025 | H32: 2026 | I32: 2027 | J32: 2028 | K32: 2029 | L32: 2030 | M32: 2031 | N32: 2032 | O32: 2033 | P32: 2034 | Q32: 2035 | R32: 2036 | S32: 2037 | T32: 2038 | U32: 2039 | V32: 2040 | W32: 2041 | X32: 2042 | Y32: 2043 | Z32: 2044 | AA32: 2045 | AB32: 2046 | AC32: 2047 | AD32: 2048 | AE32: 2049 | AF32: 2050 | AG32: 2051 | AH32: 2052 | AI32: 2053 | AJ32: 2054 | AK32: 2055 | AL32: 2056 | AM32: 2057 | AN32: 2058 | AO32: 2059 | AP32: 2060
A33: 农业-中情景 | B33: ='高情景（2001-2060, 2020RMB）'!U3 -> 81396.5 | C33: ='高情景（2001-2060, 2020RMB）'!V3 -> 82959.622 | D33: ='高情景（2001-2060, 2020RMB）'!W3 -> 86574.037 | E33: =VLOOKUP($A33,Python数据平滑!$A$9:$AN$21,COLUMN(Python数据平滑!C$9),0)/SUM(Python数据平滑!C$14:C$17)*情景假设!E$10 -> 90737.474 | F33: =VLOOKUP($A33,Python数据平滑!$A$9:$AN$21,COLUMN(Python数据平滑!D$9),0)/SUM(Python数据平滑!D$14:D$17)*情景假设!F$10 -> 94977.09 | G33: =G$10*I17 -> 99254.733 | H33: =VLOOKUP($A33,Python数据平滑!$A$9:$AN$21,COLUMN(Python数据平滑!F$9),0)/SUM(Python数据平滑!F$14:F$17)*情景假设!H$10 -> 103642.1 | I33: =VLOOKUP($A33,Python数据平滑!$A$9:$AN$21,COLUMN(Python数据平滑!G$9),0)/SUM(Python数据平滑!G$14:G$17)*情景假设!I$10 -> 108173.01 | J33: =VLOOKUP($A33,Python数据平滑!$A$9:$AN$21,COLUMN(Python数据平滑!H$9),0)/SUM(Python数据平滑!H$14:H$17)*情景假设!J$10 -> 112737.28 | K33: =VLOOKUP($A33,Python数据平滑!$A$9:$AN$21,COLUMN(Python数据平滑!I$9),0)/SUM(Python数据平滑!I$14:I$17)*情景假设!K$10 -> 117210.75 | L33: =L$10*J17 -> 121456.04 | M33: =VLOOKUP($A33,Python数据平滑!$A$9:$AN$21,COLUMN(Python数据平滑!K$9),0)/SUM(Python数据平滑!K$14:K$17)*情景假设!M$10 -> 125414.64 | N33: =VLOOKUP($A33,Python数据平滑!$A$9:$AN$21,COLUMN(Python数据平滑!L$9),0)/SUM(Python数据平滑!L$14:L$17)*情景假设!N$10 -> 129180.11 | O33: =VLOOKUP($A33,Python数据平滑!$A$9:$AN$21,COLUMN(Python数据平滑!M$9),0)/SUM(Python数据平滑!M$14:M$17)*情景假设!O$10 -> 132842.91 | P33: =VLOOKUP($A33,Python数据平滑!$A$9:$AN$21,COLUMN(Python数据平滑!N$9),0)/SUM(Python数据平滑!N$14:N$17)*情景假设!P$10 -> 136504.38 | Q33: =Q$10*K17 -> 140276.3 | R33: =VLOOKUP($A33,Python数据平滑!$A$9:$AN$21,COLUMN(Python数据平滑!P$9),0)/SUM(Python数据平滑!P$14:P$17)*情景假设!R$10 -> 144096.86 | S33: =VLOOKUP($A33,Python数据平滑!$A$9:$AN$21,COLUMN(Python数据平滑!Q$9),0)/SUM(Python数据平滑!Q$14:Q$17)*情景假设!S$10 -> 147855.94 | T33: =VLOOKUP($A33,Python数据平滑!$A$9:$AN$21,COLUMN(Python数据平滑!R$9),0)/SUM(Python数据平滑!R$14:R$17)*情景假设!T$10 -> 151605.36 | U33: =VLOOKUP($A33,Python数据平滑!$A$9:$AN$21,COLUMN(Python数据平滑!S$9),0)/SUM(Python数据平滑!S$14:S$17)*情景假设!U$10 -> 155403.15 | V33: =VLOOKUP($A33,Python数据平滑!$A$9:$AN$21,COLUMN(Python数据平滑!T$9),0)/SUM(Python数据平滑!T$14:T$17)*情景假设!V$10 -> 159313.66 | W33: =VLOOKUP($A33,Python数据平滑!$A$9:$AN$21,COLUMN(Python数据平滑!U$9),0)/SUM(Python数据平滑!U$14:U$17)*情景假设!W$10 -> 163344.49 | X33: =VLOOKUP($A33,Python数据平滑!$A$9:$AN$21,COLUMN(Python数据平滑!V$9),0)/SUM(Python数据平滑!V$14:V$17)*情景假设!X$10 -> 167458.32 | Y33: =VLOOKUP($A33,Python数据平滑!$A$9:$AN$21,COLUMN(Python数据平滑!W$9),0)/SUM(Python数据平滑!W$14:W$17)*情景假设!Y$10 -> 171657.22 | ... AE33: =VLOOKUP($A33,Python数据平滑!$A$9:$AN$21,COLUMN(Python数据平滑!AC$9),0)/SUM(Python数据平滑!AC$14:AC$17)*情景假设!AE$10 -> 198856.1 | AF33: =$AF$10*L17 -> 203773.02 | AG33: =VLOOKUP($A33,Python数据平滑!$A$9:$AN$21,COLUMN(Python数据平滑!AE$9),0)/SUM(Python数据平滑!AE$14:AE$17)*情景假设!AG$10 -> 208822.17 | AH33: =VLOOKUP($A33,Python数据平滑!$A$9:$AN$21,COLUMN(Python数据平滑!AF$9),0)/SUM(Python数据平滑!AF$14:AF$17)*情景假设!AH$10 -> 214007.73 | AI33: =VLOOKUP($A33,Python数据平滑!$A$9:$AN$21,COLUMN(Python数据平滑!AG$9),0)/SUM(Python数据平滑!AG$14:AG$17)*情景假设!AI$10 -> 219318.28 | AJ33: =VLOOKUP($A33,Python数据平滑!$A$9:$AN$21,COLUMN(Python数据平滑!AH$9),0)/SUM(Python数据平滑!AH$14:AH$17)*情景假设!AJ$10 -> 224740.94 | AK33: =VLOOKUP($A33,Python数据平滑!$A$9:$AN$21,COLUMN(Python数据平滑!AI$9),0)/SUM(Python数据平滑!AI$14:AI$17)*情景假设!AK$10 -> 230261.3 | AL33: =VLOOKUP($A33,Python数据平滑!$A$9:$AN$21,COLUMN(Python数据平滑!AJ$9),0)/SUM(Python数据平滑!AJ$14:AJ$17)*情景假设!AL$10 -> 235884.75 | AM33: =VLOOKUP($A33,Python数据平滑!$A$9:$AN$21,COLUMN(Python数据平滑!AK$9),0)/SUM(Python数据平滑!AK$14:AK$17)*情景假设!AM$10 -> 241627.25 | AN33: =VLOOKUP($A33,Python数据平滑!$A$9:$AN$21,COLUMN(Python数据平滑!AL$9),0)/SUM(Python数据平滑!AL$14:AL$17)*情景假设!AN$10 -> 247488.81 | AO33: =VLOOKUP($A33,Python数据平滑!$A$9:$AN$21,COLUMN(Python数据平滑!AM$9),0)/SUM(Python数据平滑!AM$14:AM$17)*情景假设!AO$10 -> 253469.18 | AP33: =AP$10*M17 -> 259567.89
A34: 工业-中情景 | B34: ='高情景（2001-2060, 2020RMB）'!U4 -> 312902.9 | C34: ='高情景（2001-2060, 2020RMB）'!V4 -> 356193.68 | D34: ='高情景（2001-2060, 2020RMB）'!W4 -> 375578.61 | E34: =VLOOKUP($A34,Python数据平滑!$A$9:$AN$21,COLUMN(Python数据平滑!C$9),0)/SUM(Python数据平滑!C$14:C$17)*情景假设!E$10 -> 388513.47 | F34: =VLOOKUP($A34,Python数据平滑!$A$9:$AN$21,COLUMN(Python数据平滑!D$9),0)/SUM(Python数据平滑!D$14:D$17)*情景假设!F$10 -> 401748.08 | G34: =G$10*I18 -> 415281.8 | H34: =VLOOKUP($A34,Python数据平滑!$A$9:$AN$21,COLUMN(Python数据平滑!F$9),0)/SUM(Python数据平滑!F$14:F$17)*情景假设!H$10 -> 429303.7 | I34: =VLOOKUP($A34,Python数据平滑!$A$9:$AN$21,COLUMN(Python数据平滑!G$9),0)/SUM(Python数据平滑!G$14:G$17)*情景假设!I$10 -> 443827.99 | J34: =VLOOKUP($A34,Python数据平滑!$A$9:$AN$21,COLUMN(Python数据平滑!H$9),0)/SUM(Python数据平滑!H$14:H$17)*情景假设!J$10 -> 458575.41 | K34: =VLOOKUP($A34,Python数据平滑!$A$9:$AN$21,COLUMN(Python数据平滑!I$9),0)/SUM(Python数据平滑!I$14:I$17)*情景假设!K$10 -> 473246.64 | L34: =L$10*J18 -> 487522.86 | M34: =VLOOKUP($A34,Python数据平滑!$A$9:$AN$21,COLUMN(Python数据平滑!K$9),0)/SUM(Python数据平滑!K$14:K$17)*情景假设!M$10 -> 501468.86 | N34: =VLOOKUP($A34,Python数据平滑!$A$9:$AN$21,COLUMN(Python数据平滑!L$9),0)/SUM(Python数据平滑!L$14:L$17)*情景假设!N$10 -> 515305.72 | O34: =VLOOKUP($A34,Python数据平滑!$A$9:$AN$21,COLUMN(Python数据平滑!M$9),0)/SUM(Python数据平滑!M$14:M$17)*情景假设!O$10 -> 528921.12 | P34: =VLOOKUP($A34,Python数据平滑!$A$9:$AN$21,COLUMN(Python数据平滑!N$9),0)/SUM(Python数据平滑!N$14:N$17)*情景假设!P$10 -> 542185.53 | Q34: =Q$10*K18 -> 554952.73 | R34: =VLOOKUP($A34,Python数据平滑!$A$9:$AN$21,COLUMN(Python数据平滑!P$9),0)/SUM(Python数据平滑!P$14:P$17)*情景假设!R$10 -> 567031.37 | S34: =VLOOKUP($A34,Python数据平滑!$A$9:$AN$21,COLUMN(Python数据平滑!Q$9),0)/SUM(Python数据平滑!Q$14:Q$17)*情景假设!S$10 -> 578472.33 | T34: =VLOOKUP($A34,Python数据平滑!$A$9:$AN$21,COLUMN(Python数据平滑!R$9),0)/SUM(Python数据平滑!R$14:R$17)*情景假设!T$10 -> 589497.96 | U34: =VLOOKUP($A34,Python数据平滑!$A$9:$AN$21,COLUMN(Python数据平滑!S$9),0)/SUM(Python数据平滑!S$14:S$17)*情景假设!U$10 -> 600352.77 | V34: =VLOOKUP($A34,Python数据平滑!$A$9:$AN$21,COLUMN(Python数据平滑!T$9),0)/SUM(Python数据平滑!T$14:T$17)*情景假设!V$10 -> 611302.25 | W34: =VLOOKUP($A34,Python数据平滑!$A$9:$AN$21,COLUMN(Python数据平滑!U$9),0)/SUM(Python数据平滑!U$14:U$17)*情景假设!W$10 -> 622391.17 | X34: =VLOOKUP($A34,Python数据平滑!$A$9:$AN$21,COLUMN(Python数据平滑!V$9),0)/SUM(Python数据平滑!V$14:V$17)*情景假设!X$10 -> 633495.62 | Y34: =VLOOKUP($A34,Python数据平滑!$A$9:$AN$21,COLUMN(Python数据平滑!W$9),0)/SUM(Python数据平滑!W$14:W$17)*情景假设!Y$10 -> 644645.87 | ... AE34: =VLOOKUP($A34,Python数据平滑!$A$9:$AN$21,COLUMN(Python数据平滑!AC$9),0)/SUM(Python数据平滑!AC$14:AC$17)*情景假设!AE$10 -> 714845.3 | AF34: =$AF$10*L18 -> 727574.18 | AG34: =VLOOKUP($A34,Python数据平滑!$A$9:$AN$21,COLUMN(Python数据平滑!AE$9),0)/SUM(Python数据平滑!AE$14:AE$17)*情景假设!AG$10 -> 740679.47 | AH34: =VLOOKUP($A34,Python数据平滑!$A$9:$AN$21,COLUMN(Python数据平滑!AF$9),0)/SUM(Python数据平滑!AF$14:AF$17)*情景假设!AH$10 -> 754087.55 | AI34: =VLOOKUP($A34,Python数据平滑!$A$9:$AN$21,COLUMN(Python数据平滑!AG$9),0)/SUM(Python数据平滑!AG$14:AG$17)*情景假设!AI$10 -> 767751.61 | AJ34: =VLOOKUP($A34,Python数据平滑!$A$9:$AN$21,COLUMN(Python数据平滑!AH$9),0)/SUM(Python数据平滑!AH$14:AH$17)*情景假设!AJ$10 -> 781620.86 | AK34: =VLOOKUP($A34,Python数据平滑!$A$9:$AN$21,COLUMN(Python数据平滑!AI$9),0)/SUM(Python数据平滑!AI$14:AI$17)*情景假设!AK$10 -> 795640.41 | AL34: =VLOOKUP($A34,Python数据平滑!$A$9:$AN$21,COLUMN(Python数据平滑!AJ$9),0)/SUM(Python数据平滑!AJ$14:AJ$17)*情景假设!AL$10 -> 809824.77 | AM34: =VLOOKUP($A34,Python数据平滑!$A$9:$AN$21,COLUMN(Python数据平滑!AK$9),0)/SUM(Python数据平滑!AK$14:AK$17)*情景假设!AM$10 -> 824223.98 | AN34: =VLOOKUP($A34,Python数据平滑!$A$9:$AN$21,COLUMN(Python数据平滑!AL$9),0)/SUM(Python数据平滑!AL$14:AL$17)*情景假设!AN$10 -> 838832.63 | AO34: =VLOOKUP($A34,Python数据平滑!$A$9:$AN$21,COLUMN(Python数据平滑!AM$9),0)/SUM(Python数据平滑!AM$14:AM$17)*情景假设!AO$10 -> 853644.58 | AP34: =AP$10*M18 -> 868652.93
A35: 建筑业-中情景 | B35: ='高情景（2001-2060, 2020RMB）'!U5 -> 72444.7 | C35: ='高情景（2001-2060, 2020RMB）'!V5 -> 76614.92 | D35: ='高情景（2001-2060, 2020RMB）'!W5 -> 77971.749 | E35: =VLOOKUP($A35,Python数据平滑!$A$9:$AN$21,COLUMN(Python数据平滑!C$9),0)/SUM(Python数据平滑!C$14:C$17)*情景假设!E$10 -> 81519.684 | F35: =VLOOKUP($A35,Python数据平滑!$A$9:$AN$21,COLUMN(Python数据平滑!D$9),0)/SUM(Python数据平滑!D$14:D$17)*情景假设!F$10 -> 85027.663 | G35: =G$10*I19 -> 88402.882 | H35: =VLOOKUP($A35,Python数据平滑!$A$9:$AN$21,COLUMN(Python数据平滑!F$9),0)/SUM(Python数据平滑!F$14:F$17)*情景假设!H$10 -> 91679.592 | I35: =VLOOKUP($A35,Python数据平滑!$A$9:$AN$21,COLUMN(Python数据平滑!G$9),0)/SUM(Python数据平滑!G$14:G$17)*情景假设!I$10 -> 94926.186 | J35: =VLOOKUP($A35,Python数据平滑!$A$9:$AN$21,COLUMN(Python数据平滑!H$9),0)/SUM(Python数据平滑!H$14:H$17)*情景假设!J$10 -> 98090.684 | K35: =VLOOKUP($A35,Python数据平滑!$A$9:$AN$21,COLUMN(Python数据平滑!I$9),0)/SUM(Python数据平滑!I$14:I$17)*情景假设!K$10 -> 101119.77 | L35: =L$10*J19 -> 103959.58 | M35: =VLOOKUP($A35,Python数据平滑!$A$9:$AN$21,COLUMN(Python数据平滑!K$9),0)/SUM(Python数据平滑!K$14:K$17)*情景假设!M$10 -> 106569.51 | N35: =VLOOKUP($A35,Python数据平滑!$A$9:$AN$21,COLUMN(Python数据平滑!L$9),0)/SUM(Python数据平滑!L$14:L$17)*情景假设!N$10 -> 108997.71 | O35: =VLOOKUP($A35,Python数据平滑!$A$9:$AN$21,COLUMN(Python数据平滑!M$9),0)/SUM(Python数据平滑!M$14:M$17)*情景假设!O$10 -> 111329.15 | P35: =VLOOKUP($A35,Python数据平滑!$A$9:$AN$21,COLUMN(Python数据平滑!N$9),0)/SUM(Python数据平滑!N$14:N$17)*情景假设!P$10 -> 113655.88 | Q35: =Q$10*K19 -> 116076.59 | R35: =VLOOKUP($A35,Python数据平滑!$A$9:$AN$21,COLUMN(Python数据平滑!P$9),0)/SUM(Python数据平滑!P$14:P$17)*情景假设!R$10 -> 118545.54 | S35: =VLOOKUP($A35,Python数据平滑!$A$9:$AN$21,COLUMN(Python数据平滑!Q$9),0)/SUM(Python数据平滑!Q$14:Q$17)*情景假设!S$10 -> 120972.04 | T35: =VLOOKUP($A35,Python数据平滑!$A$9:$AN$21,COLUMN(Python数据平滑!R$9),0)/SUM(Python数据平滑!R$14:R$17)*情景假设!T$10 -> 123395.05 | U35: =VLOOKUP($A35,Python数据平滑!$A$9:$AN$21,COLUMN(Python数据平滑!S$9),0)/SUM(Python数据平滑!S$14:S$17)*情景假设!U$10 -> 125857.06 | V35: =VLOOKUP($A35,Python数据平滑!$A$9:$AN$21,COLUMN(Python数据平滑!T$9),0)/SUM(Python数据平滑!T$14:T$17)*情景假设!V$10 -> 128404.19 | W35: =VLOOKUP($A35,Python数据平滑!$A$9:$AN$21,COLUMN(Python数据平滑!U$9),0)/SUM(Python数据平滑!U$14:U$17)*情景假设!W$10 -> 131035.58 | X35: =VLOOKUP($A35,Python数据平滑!$A$9:$AN$21,COLUMN(Python数据平滑!V$9),0)/SUM(Python数据平滑!V$14:V$17)*情景假设!X$10 -> 133713.83 | Y35: =VLOOKUP($A35,Python数据平滑!$A$9:$AN$21,COLUMN(Python数据平滑!W$9),0)/SUM(Python数据平滑!W$14:W$17)*情景假设!Y$10 -> 136432.89 | ... AE35: =VLOOKUP($A35,Python数据平滑!$A$9:$AN$21,COLUMN(Python数据平滑!AC$9),0)/SUM(Python数据平滑!AC$14:AC$17)*情景假设!AE$10 -> 153264.86 | AF35: =$AF$10*L19 -> 156095.36 | AG35: =VLOOKUP($A35,Python数据平滑!$A$9:$AN$21,COLUMN(Python数据平滑!AE$9),0)/SUM(Python数据平滑!AE$14:AE$17)*情景假设!AG$10 -> 158939.12 | AH35: =VLOOKUP($A35,Python数据平滑!$A$9:$AN$21,COLUMN(Python数据平滑!AF$9),0)/SUM(Python数据平滑!AF$14:AF$17)*情景假设!AH$10 -> 161814.52 | AI35: =VLOOKUP($A35,Python数据平滑!$A$9:$AN$21,COLUMN(Python数据平滑!AG$9),0)/SUM(Python数据平滑!AG$14:AG$17)*情景假设!AI$10 -> 164710.28 | AJ35: =VLOOKUP($A35,Python数据平滑!$A$9:$AN$21,COLUMN(Python数据平滑!AH$9),0)/SUM(Python数据平滑!AH$14:AH$17)*情景假设!AJ$10 -> 167614.27 | AK35: =VLOOKUP($A35,Python数据平滑!$A$9:$AN$21,COLUMN(Python数据平滑!AI$9),0)/SUM(Python数据平滑!AI$14:AI$17)*情景假设!AK$10 -> 170513.5 | AL35: =VLOOKUP($A35,Python数据平滑!$A$9:$AN$21,COLUMN(Python数据平滑!AJ$9),0)/SUM(Python数据平滑!AJ$14:AJ$17)*情景假设!AL$10 -> 173409.88 | AM35: =VLOOKUP($A35,Python数据平滑!$A$9:$AN$21,COLUMN(Python数据平滑!AK$9),0)/SUM(Python数据平滑!AK$14:AK$17)*情景假设!AM$10 -> 176312.97 | AN35: =VLOOKUP($A35,Python数据平滑!$A$9:$AN$21,COLUMN(Python数据平滑!AL$9),0)/SUM(Python数据平滑!AL$14:AL$17)*情景假设!AN$10 -> 179220.43 | AO35: =VLOOKUP($A35,Python数据平滑!$A$9:$AN$21,COLUMN(Python数据平滑!AM$9),0)/SUM(Python数据平滑!AM$14:AM$17)*情景假设!AO$10 -> 182129.8 | AP35: =AP$10*M19 -> 185038.49
A36: 服务业-中情景 | B36: ='高情景（2001-2060, 2020RMB）'!U56 -> 546822.9 | C36: ='高情景（2001-2060, 2020RMB）'!V56 -> 582938.41 | D36: ='高情景（2001-2060, 2020RMB）'!W56 -> 591543.44 | E36: =VLOOKUP($A36,Python数据平滑!$A$9:$AN$21,COLUMN(Python数据平滑!C$9),0)/SUM(Python数据平滑!C$14:C$17)*情景假设!E$10 -> 632226.57 | F36: =VLOOKUP($A36,Python数据平滑!$A$9:$AN$21,COLUMN(Python数据平滑!D$9),0)/SUM(Python数据平滑!D$14:D$17)*情景假设!F$10 -> 675193.64 | G36: =G$10*I20 -> 720457.02 | H36: =VLOOKUP($A36,Python数据平滑!$A$9:$AN$21,COLUMN(Python数据平滑!F$9),0)/SUM(Python数据平滑!F$14:F$17)*情景假设!H$10 -> 769141.55 | I36: =VLOOKUP($A36,Python数据平滑!$A$9:$AN$21,COLUMN(Python数据平滑!G$9),0)/SUM(Python数据平滑!G$14:G$17)*情景假设!I$10 -> 821615.66 | J36: =VLOOKUP($A36,Python数据平滑!$A$9:$AN$21,COLUMN(Python数据平滑!H$9),0)/SUM(Python数据平滑!H$14:H$17)*情景假设!J$10 -> 876474.9 | K36: =VLOOKUP($A36,Python数据平滑!$A$9:$AN$21,COLUMN(Python数据平滑!I$9),0)/SUM(Python数据平滑!I$14:I$17)*情景假设!K$10 -> 931922.24 | L36: =L$10*J20 -> 985747.45 | M36: =VLOOKUP($A36,Python数据平滑!$A$9:$AN$21,COLUMN(Python数据平滑!K$9),0)/SUM(Python数据平滑!K$14:K$17)*情景假设!M$10 -> 1037207.5 | N36: =VLOOKUP($A36,Python数据平滑!$A$9:$AN$21,COLUMN(Python数据平滑!L$9),0)/SUM(Python数据平滑!L$14:L$17)*情景假设!N$10 -> 1087586.6 | O36: =VLOOKUP($A36,Python数据平滑!$A$9:$AN$21,COLUMN(Python数据平滑!M$9),0)/SUM(Python数据平滑!M$14:M$17)*情景假设!O$10 -> 1137533.2 | P36: =VLOOKUP($A36,Python数据平滑!$A$9:$AN$21,COLUMN(Python数据平滑!N$9),0)/SUM(Python数据平滑!N$14:N$17)*情景假设!P$10 -> 1187854.9 | Q36: =Q$10*K20 -> 1239517.5 | R36: =VLOOKUP($A36,Python数据平滑!$A$9:$AN$21,COLUMN(Python数据平滑!P$9),0)/SUM(Python数据平滑!P$14:P$17)*情景假设!R$10 -> 1292351 | S36: =VLOOKUP($A36,Python数据平滑!$A$9:$AN$21,COLUMN(Python数据平滑!Q$9),0)/SUM(Python数据平滑!Q$14:Q$17)*情景假设!S$10 -> 1345695.7 | T36: =VLOOKUP($A36,Python数据平滑!$A$9:$AN$21,COLUMN(Python数据平滑!R$9),0)/SUM(Python数据平滑!R$14:R$17)*情景假设!T$10 -> 1399959.6 | U36: =VLOOKUP($A36,Python数据平滑!$A$9:$AN$21,COLUMN(Python数据平滑!S$9),0)/SUM(Python数据平滑!S$14:S$17)*情景假设!U$10 -> 1455628.7 | V36: =VLOOKUP($A36,Python数据平滑!$A$9:$AN$21,COLUMN(Python数据平滑!T$9),0)/SUM(Python数据平滑!T$14:T$17)*情景假设!V$10 -> 1513271.5 | W36: =VLOOKUP($A36,Python数据平滑!$A$9:$AN$21,COLUMN(Python数据平滑!U$9),0)/SUM(Python数据平滑!U$14:U$17)*情景假设!W$10 -> 1572935.2 | X36: =VLOOKUP($A36,Python数据平滑!$A$9:$AN$21,COLUMN(Python数据平滑!V$9),0)/SUM(Python数据平滑!V$14:V$17)*情景假设!X$10 -> 1634222.7 | Y36: =VLOOKUP($A36,Python数据平滑!$A$9:$AN$21,COLUMN(Python数据平滑!W$9),0)/SUM(Python数据平滑!W$14:W$17)*情景假设!Y$10 -> 1697096.9 | ... AE36: =VLOOKUP($A36,Python数据平滑!$A$9:$AN$21,COLUMN(Python数据平滑!AC$9),0)/SUM(Python数据平滑!AC$14:AC$17)*情景假设!AE$10 -> 2105389.4 | AF36: =$AF$10*L20 -> 2178150.7 | AG36: =VLOOKUP($A36,Python数据平滑!$A$9:$AN$21,COLUMN(Python数据平滑!AE$9),0)/SUM(Python数据平滑!AE$14:AE$17)*情景假设!AG$10 -> 2252291.1 | AH36: =VLOOKUP($A36,Python数据平滑!$A$9:$AN$21,COLUMN(Python数据平滑!AF$9),0)/SUM(Python数据平滑!AF$14:AF$17)*情景假设!AH$10 -> 2327914.6 | AI36: =VLOOKUP($A36,Python数据平滑!$A$9:$AN$21,COLUMN(Python数据平滑!AG$9),0)/SUM(Python数据平滑!AG$14:AG$17)*情景假设!AI$10 -> 2404846.5 | AJ36: =VLOOKUP($A36,Python数据平滑!$A$9:$AN$21,COLUMN(Python数据平滑!AH$9),0)/SUM(Python数据平滑!AH$14:AH$17)*情景假设!AJ$10 -> 2482888.2 | AK36: =VLOOKUP($A36,Python数据平滑!$A$9:$AN$21,COLUMN(Python数据平滑!AI$9),0)/SUM(Python数据平滑!AI$14:AI$17)*情景假设!AK$10 -> 2561816.7 | AL36: =VLOOKUP($A36,Python数据平滑!$A$9:$AN$21,COLUMN(Python数据平滑!AJ$9),0)/SUM(Python数据平滑!AJ$14:AJ$17)*情景假设!AL$10 -> 2641624.2 | AM36: =VLOOKUP($A36,Python数据平滑!$A$9:$AN$21,COLUMN(Python数据平滑!AK$9),0)/SUM(Python数据平滑!AK$14:AK$17)*情景假设!AM$10 -> 2722421.1 | AN36: =VLOOKUP($A36,Python数据平滑!$A$9:$AN$21,COLUMN(Python数据平滑!AL$9),0)/SUM(Python数据平滑!AL$14:AL$17)*情景假设!AN$10 -> 2804139 | AO36: =VLOOKUP($A36,Python数据平滑!$A$9:$AN$21,COLUMN(Python数据平滑!AM$9),0)/SUM(Python数据平滑!AM$14:AM$17)*情景假设!AO$10 -> 2886704.6 | AP36: =AP$10*M20 -> 2970039.2
A38: 低情景 | B38: 2020 | C38: 2021 | D38: 2022 | E38: 2023 | F38: 2024 | G38: 2025 | H38: 2026 | I38: 2027 | J38: 2028 | K38: 2029 | L38: 2030 | M38: 2031 | N38: 2032 | O38: 2033 | P38: 2034 | Q38: 2035 | R38: 2036 | S38: 2037 | T38: 2038 | U38: 2039 | V38: 2040 | W38: 2041 | X38: 2042 | Y38: 2043 | Z38: 2044 | AA38: 2045 | AB38: 2046 | AC38: 2047 | AD38: 2048 | AE38: 2049 | AF38: 2050 | AG38: 2051 | AH38: 2052 | AI38: 2053 | AJ38: 2054 | AK38: 2055 | AL38: 2056 | AM38: 2057 | AN38: 2058 | AO38: 2059 | AP38: 2060
A39: 农业-低情景 | B39: ='高情景（2001-2060, 2020RMB）'!U3 -> 81396.5 | C39: ='高情景（2001-2060, 2020RMB）'!V3 -> 82959.622 | D39: ='高情景（2001-2060, 2020RMB）'!W3 -> 86574.037 | E39: =VLOOKUP($A39,Python数据平滑!$A$9:$AN$21,COLUMN(Python数据平滑!C$9),0)/SUM(Python数据平滑!C$18:C$21)*情景假设!E$11 -> 90741.676 | F39: =VLOOKUP($A39,Python数据平滑!$A$9:$AN$21,COLUMN(Python数据平滑!D$9),0)/SUM(Python数据平滑!D$18:D$21)*情景假设!F$11 -> 94995.041 | G39: =G$11*P17 -> 99301.18 | H39: =VLOOKUP($A39,Python数据平滑!$A$9:$AN$21,COLUMN(Python数据平滑!F$9),0)/SUM(Python数据平滑!F$18:F$21)*情景假设!H$11 -> 103731.16 | I39: =VLOOKUP($A39,Python数据平滑!$A$9:$AN$21,COLUMN(Python数据平滑!G$9),0)/SUM(Python数据平滑!G$18:G$21)*情景假设!I$11 -> 108316.24 | J39: =VLOOKUP($A39,Python数据平滑!$A$9:$AN$21,COLUMN(Python数据平滑!H$9),0)/SUM(Python数据平滑!H$18:H$21)*情景假设!J$11 -> 112949.74 | K39: =VLOOKUP($A39,Python数据平滑!$A$9:$AN$21,COLUMN(Python数据平滑!I$9),0)/SUM(Python数据平滑!I$18:I$21)*情景假设!K$11 -> 117511.49 | L39: =L$11*Q17 -> 121868.41 | M39: =VLOOKUP($A39,Python数据平滑!$A$9:$AN$21,COLUMN(Python数据平滑!K$9),0)/SUM(Python数据平滑!K$18:K$21)*情景假设!M$11 -> 125950.92 | N39: =VLOOKUP($A39,Python数据平滑!$A$9:$AN$21,COLUMN(Python数据平滑!L$9),0)/SUM(Python数据平滑!L$18:L$21)*情景假设!N$11 -> 129846.01 | O39: =VLOOKUP($A39,Python数据平滑!$A$9:$AN$21,COLUMN(Python数据平滑!M$9),0)/SUM(Python数据平滑!M$18:M$21)*情景假设!O$11 -> 133655.73 | P39: =VLOOKUP($A39,Python数据平滑!$A$9:$AN$21,COLUMN(Python数据平滑!N$9),0)/SUM(Python数据平滑!N$18:N$21)*情景假设!P$11 -> 137494.04 | Q39: =Q$11*R17 -> 141486.5 | R39: =VLOOKUP($A39,Python数据平滑!$A$9:$AN$21,COLUMN(Python数据平滑!P$9),0)/SUM(Python数据平滑!P$18:P$21)*情景假设!R$11 -> 145577.48 | S39: =VLOOKUP($A39,Python数据平滑!$A$9:$AN$21,COLUMN(Python数据平滑!Q$9),0)/SUM(Python数据平滑!Q$18:Q$21)*情景假设!S$11 -> 149643.09 | T39: =VLOOKUP($A39,Python数据平滑!$A$9:$AN$21,COLUMN(Python数据平滑!R$9),0)/SUM(Python数据平滑!R$18:R$21)*情景假设!T$11 -> 153718.85 | U39: =VLOOKUP($A39,Python数据平滑!$A$9:$AN$21,COLUMN(Python数据平滑!S$9),0)/SUM(Python数据平滑!S$18:S$21)*情景假设!U$11 -> 157845.09 | V39: =VLOOKUP($A39,Python数据平滑!$A$9:$AN$21,COLUMN(Python数据平滑!T$9),0)/SUM(Python数据平滑!T$18:T$21)*情景假设!V$11 -> 162067.08 | W39: =VLOOKUP($A39,Python数据平滑!$A$9:$AN$21,COLUMN(Python数据平滑!U$9),0)/SUM(Python数据平滑!U$18:U$21)*情景假设!W$11 -> 166393.45 | X39: =VLOOKUP($A39,Python数据平滑!$A$9:$AN$21,COLUMN(Python数据平滑!V$9),0)/SUM(Python数据平滑!V$18:V$21)*情景假设!X$11 -> 170801.37 | Y39: =VLOOKUP($A39,Python数据平滑!$A$9:$AN$21,COLUMN(Python数据平滑!W$9),0)/SUM(Python数据平滑!W$18:W$21)*情景假设!Y$11 -> 175293.19 | ... AE39: =VLOOKUP($A39,Python数据平滑!$A$9:$AN$21,COLUMN(Python数据平滑!AC$9),0)/SUM(Python数据平滑!AC$18:AC$21)*情景假设!AE$11 -> 204316.07 | AF39: =$AF$11*S17 -> 209573.27 | AG39: =VLOOKUP($A39,Python数据平滑!$A$9:$AN$21,COLUMN(Python数据平滑!AE$9),0)/SUM(Python数据平滑!AE$18:AE$21)*情景假设!AG$11 -> 214965.7 | AH39: =VLOOKUP($A39,Python数据平滑!$A$9:$AN$21,COLUMN(Python数据平滑!AF$9),0)/SUM(Python数据平滑!AF$18:AF$21)*情景假设!AH$11 -> 220491.71 | AI39: =VLOOKUP($A39,Python数据平滑!$A$9:$AN$21,COLUMN(Python数据平滑!AG$9),0)/SUM(Python数据平滑!AG$18:AG$21)*情景假设!AI$11 -> 226151.87 | AJ39: =VLOOKUP($A39,Python数据平滑!$A$9:$AN$21,COLUMN(Python数据平滑!AH$9),0)/SUM(Python数据平滑!AH$18:AH$21)*情景假设!AJ$11 -> 231946.47 | AK39: =VLOOKUP($A39,Python数据平滑!$A$9:$AN$21,COLUMN(Python数据平滑!AI$9),0)/SUM(Python数据平滑!AI$18:AI$21)*情景假设!AK$11 -> 237875.5 | AL39: =VLOOKUP($A39,Python数据平滑!$A$9:$AN$21,COLUMN(Python数据平滑!AJ$9),0)/SUM(Python数据平滑!AJ$18:AJ$21)*情景假设!AL$11 -> 243947.01 | AM39: =VLOOKUP($A39,Python数据平滑!$A$9:$AN$21,COLUMN(Python数据平滑!AK$9),0)/SUM(Python数据平滑!AK$18:AK$21)*情景假设!AM$11 -> 250170.87 | AN39: =VLOOKUP($A39,Python数据平滑!$A$9:$AN$21,COLUMN(Python数据平滑!AL$9),0)/SUM(Python数据平滑!AL$18:AL$21)*情景假设!AN$11 -> 256549.48 | AO39: =VLOOKUP($A39,Python数据平滑!$A$9:$AN$21,COLUMN(Python数据平滑!AM$9),0)/SUM(Python数据平滑!AM$18:AM$21)*情景假设!AO$11 -> 263085.14 | AP39: =AP$11*T17 -> 269780
A40: 工业-低情景 | B40: ='高情景（2001-2060, 2020RMB）'!U4 -> 312902.9 | C40: ='高情景（2001-2060, 2020RMB）'!V4 -> 356193.68 | D40: ='高情景（2001-2060, 2020RMB）'!W4 -> 375578.61 | E40: =VLOOKUP($A40,Python数据平滑!$A$9:$AN$21,COLUMN(Python数据平滑!C$9),0)/SUM(Python数据平滑!C$18:C$21)*情景假设!E$11 -> 388206.51 | F40: =VLOOKUP($A40,Python数据平滑!$A$9:$AN$21,COLUMN(Python数据平滑!D$9),0)/SUM(Python数据平滑!D$18:D$21)*情景假设!F$11 -> 401148.42 | G40: =G$11*P18 -> 414416.93 | H40: =VLOOKUP($A40,Python数据平滑!$A$9:$AN$21,COLUMN(Python数据平滑!F$9),0)/SUM(Python数据平滑!F$18:F$21)*情景假设!H$11 -> 428110.04 | I40: =VLOOKUP($A40,Python数据平滑!$A$9:$AN$21,COLUMN(Python数据平滑!G$9),0)/SUM(Python数据平滑!G$18:G$21)*情景假设!I$11 -> 442226.52 | J40: =VLOOKUP($A40,Python数据平滑!$A$9:$AN$21,COLUMN(Python数据平滑!H$9),0)/SUM(Python数据平滑!H$18:H$21)*情景假设!J$11 -> 456631.11 | K40: =VLOOKUP($A40,Python数据平滑!$A$9:$AN$21,COLUMN(Python数据平滑!I$9),0)/SUM(Python数据平滑!I$18:I$21)*情景假设!K$11 -> 471189.68 | L40: =L$11*Q18 -> 485769.17 | M40: =VLOOKUP($A40,Python数据平滑!$A$9:$AN$21,COLUMN(Python数据平滑!K$9),0)/SUM(Python数据平滑!K$18:K$21)*情景假设!M$11 -> 500532.46 | N40: =VLOOKUP($A40,Python数据平滑!$A$9:$AN$21,COLUMN(Python数据平滑!L$9),0)/SUM(Python数据平滑!L$18:L$21)*情景假设!N$11 -> 515582.37 | O40: =VLOOKUP($A40,Python数据平滑!$A$9:$AN$21,COLUMN(Python数据平滑!M$9),0)/SUM(Python数据平滑!M$18:M$21)*情景假设!O$11 -> 530664.45 | P40: =VLOOKUP($A40,Python数据平滑!$A$9:$AN$21,COLUMN(Python数据平滑!N$9),0)/SUM(Python数据平滑!N$18:N$21)*情景假设!P$11 -> 545483.5 | Q40: =Q$11*R18 -> 559703.95 | R40: =VLOOKUP($A40,Python数据平滑!$A$9:$AN$21,COLUMN(Python数据平滑!P$9),0)/SUM(Python数据平滑!P$18:P$21)*情景假设!R$11 -> 573162.07 | S40: =VLOOKUP($A40,Python数据平滑!$A$9:$AN$21,COLUMN(Python数据平滑!Q$9),0)/SUM(Python数据平滑!Q$18:Q$21)*情景假设!S$11 -> 586034.15 | T40: =VLOOKUP($A40,Python数据平滑!$A$9:$AN$21,COLUMN(Python数据平滑!R$9),0)/SUM(Python数据平滑!R$18:R$21)*情景假设!T$11 -> 598480.12 | U40: =VLOOKUP($A40,Python数据平滑!$A$9:$AN$21,COLUMN(Python数据平滑!S$9),0)/SUM(Python数据平滑!S$18:S$21)*情景假设!U$11 -> 610679.86 | V40: =VLOOKUP($A40,Python数据平滑!$A$9:$AN$21,COLUMN(Python数据平滑!T$9),0)/SUM(Python数据平滑!T$18:T$21)*情景假设!V$11 -> 622832.24 | W40: =VLOOKUP($A40,Python数据平滑!$A$9:$AN$21,COLUMN(Python数据平滑!U$9),0)/SUM(Python数据平滑!U$18:U$21)*情景假设!W$11 -> 634995.03 | X40: =VLOOKUP($A40,Python数据平滑!$A$9:$AN$21,COLUMN(Python数据平滑!V$9),0)/SUM(Python数据平滑!V$18:V$21)*情景假设!X$11 -> 647109.24 | Y40: =VLOOKUP($A40,Python数据平滑!$A$9:$AN$21,COLUMN(Python数据平滑!W$9),0)/SUM(Python数据平滑!W$18:W$21)*情景假设!Y$11 -> 659216.31 | ... AE40: =VLOOKUP($A40,Python数据平滑!$A$9:$AN$21,COLUMN(Python数据平滑!AC$9),0)/SUM(Python数据平滑!AC$18:AC$21)*情景假设!AE$11 -> 735079.11 | AF40: =$AF$11*S18 -> 748966.75 | AG40: =VLOOKUP($A40,Python数据平滑!$A$9:$AN$21,COLUMN(Python数据平滑!AE$9),0)/SUM(Python数据平滑!AE$18:AE$21)*情景假设!AG$11 -> 763272.62 | AH40: =VLOOKUP($A40,Python数据平滑!$A$9:$AN$21,COLUMN(Python数据平滑!AF$9),0)/SUM(Python数据平滑!AF$18:AF$21)*情景假设!AH$11 -> 777870.53 | AI40: =VLOOKUP($A40,Python数据平滑!$A$9:$AN$21,COLUMN(Python数据平滑!AG$9),0)/SUM(Python数据平滑!AG$18:AG$21)*情景假设!AI$11 -> 792756.4 | AJ40: =VLOOKUP($A40,Python数据平滑!$A$9:$AN$21,COLUMN(Python数据平滑!AH$9),0)/SUM(Python数据平滑!AH$18:AH$21)*情景假设!AJ$11 -> 807925.21 | AK40: =VLOOKUP($A40,Python数据平滑!$A$9:$AN$21,COLUMN(Python数据平滑!AI$9),0)/SUM(Python数据平滑!AI$18:AI$21)*情景假设!AK$11 -> 823370.96 | AL40: =VLOOKUP($A40,Python数据平滑!$A$9:$AN$21,COLUMN(Python数据平滑!AJ$9),0)/SUM(Python数据平滑!AJ$18:AJ$21)*情景假设!AL$11 -> 839115.42 | AM40: =VLOOKUP($A40,Python数据平滑!$A$9:$AN$21,COLUMN(Python数据平滑!AK$9),0)/SUM(Python数据平滑!AK$18:AK$21)*情景假设!AM$11 -> 855185.91 | AN40: =VLOOKUP($A40,Python数据平滑!$A$9:$AN$21,COLUMN(Python数据平滑!AL$9),0)/SUM(Python数据平滑!AL$18:AL$21)*情景假设!AN$11 -> 871583.69 | AO40: =VLOOKUP($A40,Python数据平滑!$A$9:$AN$21,COLUMN(Python数据平滑!AM$9),0)/SUM(Python数据平滑!AM$18:AM$21)*情景假设!AO$11 -> 888309.48 | AP40: =AP$11*T18 -> 905363.4
A41: 建筑业-低情景 | B41: ='高情景（2001-2060, 2020RMB）'!U5 -> 72444.7 | C41: ='高情景（2001-2060, 2020RMB）'!V5 -> 76614.92 | D41: ='高情景（2001-2060, 2020RMB）'!W5 -> 77971.749 | E41: =VLOOKUP($A41,Python数据平滑!$A$9:$AN$21,COLUMN(Python数据平滑!C$9),0)/SUM(Python数据平滑!C$18:C$21)*情景假设!E$11 -> 81138.16 | F41: =VLOOKUP($A41,Python数据平滑!$A$9:$AN$21,COLUMN(Python数据平滑!D$9),0)/SUM(Python数据平滑!D$18:D$21)*情景假设!F$11 -> 84293.695 | G41: =G$11*P19 -> 87385.039 | H41: =VLOOKUP($A41,Python数据平滑!$A$9:$AN$21,COLUMN(Python数据平滑!F$9),0)/SUM(Python数据平滑!F$18:F$21)*情景假设!H$11 -> 90448.119 | I41: =VLOOKUP($A41,Python数据平滑!$A$9:$AN$21,COLUMN(Python数据平滑!G$9),0)/SUM(Python数据平滑!G$18:G$21)*情景假设!I$11 -> 93522.801 | J41: =VLOOKUP($A41,Python数据平滑!$A$9:$AN$21,COLUMN(Python数据平滑!H$9),0)/SUM(Python数据平滑!H$18:H$21)*情景假设!J$11 -> 96555.102 | K41: =VLOOKUP($A41,Python数据平滑!$A$9:$AN$21,COLUMN(Python数据平滑!I$9),0)/SUM(Python数据平滑!I$18:I$21)*情景假设!K$11 -> 99489.047 | L41: =L$11*Q19 -> 102267.19 | M41: =VLOOKUP($A41,Python数据平滑!$A$9:$AN$21,COLUMN(Python数据平滑!K$9),0)/SUM(Python数据平滑!K$18:K$21)*情景假设!M$11 -> 104844.8 | N41: =VLOOKUP($A41,Python数据平滑!$A$9:$AN$21,COLUMN(Python数据平滑!L$9),0)/SUM(Python数据平滑!L$18:L$21)*情景假设!N$11 -> 107266.74 | O41: =VLOOKUP($A41,Python数据平滑!$A$9:$AN$21,COLUMN(Python数据平滑!M$9),0)/SUM(Python数据平滑!M$18:M$21)*情景假设!O$11 -> 109613.91 | P41: =VLOOKUP($A41,Python数据平滑!$A$9:$AN$21,COLUMN(Python数据平滑!N$9),0)/SUM(Python数据平滑!N$18:N$21)*情景假设!P$11 -> 111973.27 | Q41: =Q$11*R19 -> 114437.61 | R41: =VLOOKUP($A41,Python数据平滑!$A$9:$AN$21,COLUMN(Python数据平滑!P$9),0)/SUM(Python数据平滑!P$18:P$21)*情景假设!R$11 -> 116968.15 | S41: =VLOOKUP($A41,Python数据平滑!$A$9:$AN$21,COLUMN(Python数据平滑!Q$9),0)/SUM(Python数据平滑!Q$18:Q$21)*情景假设!S$11 -> 119476.51 | T41: =VLOOKUP($A41,Python数据平滑!$A$9:$AN$21,COLUMN(Python数据平滑!R$9),0)/SUM(Python数据平滑!R$18:R$21)*情景假设!T$11 -> 121987.31 | U41: =VLOOKUP($A41,Python数据平滑!$A$9:$AN$21,COLUMN(Python数据平滑!S$9),0)/SUM(Python数据平滑!S$18:S$21)*情景假设!U$11 -> 124527.69 | V41: =VLOOKUP($A41,Python数据平滑!$A$9:$AN$21,COLUMN(Python数据平滑!T$9),0)/SUM(Python数据平滑!T$18:T$21)*情景假设!V$11 -> 127127.41 | W41: =VLOOKUP($A41,Python数据平滑!$A$9:$AN$21,COLUMN(Python数据平滑!U$9),0)/SUM(Python数据平滑!U$18:U$21)*情景假设!W$11 -> 129786.28 | X41: =VLOOKUP($A41,Python数据平滑!$A$9:$AN$21,COLUMN(Python数据平滑!V$9),0)/SUM(Python数据平滑!V$18:V$21)*情景假设!X$11 -> 132479.06 | Y41: =VLOOKUP($A41,Python数据平滑!$A$9:$AN$21,COLUMN(Python数据平滑!W$9),0)/SUM(Python数据平滑!W$18:W$21)*情景假设!Y$11 -> 135199.72 | ... AE41: =VLOOKUP($A41,Python数据平滑!$A$9:$AN$21,COLUMN(Python数据平滑!AC$9),0)/SUM(Python数据平滑!AC$18:AC$21)*情景假设!AE$11 -> 151826.68 | AF41: =$AF$11*S19 -> 154603.23 | AG41: =VLOOKUP($A41,Python数据平滑!$A$9:$AN$21,COLUMN(Python数据平滑!AE$9),0)/SUM(Python数据平滑!AE$18:AE$21)*情景假设!AG$11 -> 157381.15 | AH41: =VLOOKUP($A41,Python数据平滑!$A$9:$AN$21,COLUMN(Python数据平滑!AF$9),0)/SUM(Python数据平滑!AF$18:AF$21)*情景假设!AH$11 -> 160174.5 | AI41: =VLOOKUP($A41,Python数据平滑!$A$9:$AN$21,COLUMN(Python数据平滑!AG$9),0)/SUM(Python数据平滑!AG$18:AG$21)*情景假设!AI$11 -> 162980.67 | AJ41: =VLOOKUP($A41,Python数据平滑!$A$9:$AN$21,COLUMN(Python数据平滑!AH$9),0)/SUM(Python数据平滑!AH$18:AH$21)*情景假设!AJ$11 -> 165796.85 | AK41: =VLOOKUP($A41,Python数据平滑!$A$9:$AN$21,COLUMN(Python数据平滑!AI$9),0)/SUM(Python数据平滑!AI$18:AI$21)*情景假设!AK$11 -> 168620.02 | AL41: =VLOOKUP($A41,Python数据平滑!$A$9:$AN$21,COLUMN(Python数据平滑!AJ$9),0)/SUM(Python数据平滑!AJ$18:AJ$21)*情景假设!AL$11 -> 171452.85 | AM41: =VLOOKUP($A41,Python数据平滑!$A$9:$AN$21,COLUMN(Python数据平滑!AK$9),0)/SUM(Python数据平滑!AK$18:AK$21)*情景假设!AM$11 -> 174299.1 | AN41: =VLOOKUP($A41,Python数据平滑!$A$9:$AN$21,COLUMN(Python数据平滑!AL$9),0)/SUM(Python数据平滑!AL$18:AL$21)*情景假设!AN$11 -> 177157.16 | AO41: =VLOOKUP($A41,Python数据平滑!$A$9:$AN$21,COLUMN(Python数据平滑!AM$9),0)/SUM(Python数据平滑!AM$18:AM$21)*情景假设!AO$11 -> 180025.31 | AP41: =AP$11*T19 -> 182901.7
