Workbook

Sheet About

Sheet 情景假设
A1: 假设1：实际GDP年均增速
B2: 十四五 | C2: 十五五 | D2: 十六五 | E2: 2035-2060
A3: 高情景 | B3: 0.053 | C3: 0.052 | D3: 0.036 | E3: 0.018
A4: 中情景 | B4: 0.054 | C4: 0.051 | D4: 0.038 | E4: 0.02
A5: 低情景 | B5: 0.054 | C5: 0.052 | D5: 0.041 | E5: 0.025
A7: 结果1：实际GDP | B7: 步骤1：根据假设1计算2025、2030、2035和2060年实际GDP。步骤2：:将数据粘贴至"数据平滑/输入/假设1：GDP-2020年不变价.xlsx"；通过运行python代码假设1；结果保存至"数据平滑/输出/结果1：GDP数据平滑.xlsx"。步骤3：将Python结果粘贴至“Python数据平滑"sheet的对应位置，下方列表会自动更新。
A8: GDP（2020年不变价） | B8: 2020 | C8: 2021 | D8: 2022 | E8: 2023 | F8: 2024 | G8: 2025 | H8: 2026 | I8: 2027 | J8: 2028 | K8: 2029 | L8: 2030 | M8: 2031 | N8: 2032 | O8: 2033 | P8: 2034 | Q8: 2035 | R8: 2036 | S8: 2037 | T8: 2038 | U8: 2039 | V8: 2040 | W8: 2041 | X8: 2042 | Y8: 2043 | Z8: 2044 | AA8: 2045 | AB8: 2046 | AC8: 2047 | AD8: 2048 | AE8: 2049 | AF8: 2050 | AG8: 2051 | AH8: 2052 | AI8: 2053 | AJ8: 2054 | AK8: 2055 | AL8: 2056 | AM8: 2057 | AN8: 2058 | AO8: 2059 | AP8: 2060
A9: 高情景 | B9: 1013567 | C9: 1098706.6 | D9: 1131667.8 | E9: =SUM(E24:E27) -> 1164334.3 | F9: =SUM(F24:F27) -> 1235105.3 | G9: =D9*(1+B3)^3 -> 1321308.1 | H9: =SUM(H24:H27) -> 1410244.4 | I9: =SUM(I24:I27) -> 1490036.1 | J9: =SUM(J24:J27) -> 1563852.7 | K9: =SUM(K24:K27) -> 1633103.3 | L9: =G9*(1+C3)^5 -> 1702483 | M9: =SUM(M24:M27) -> 1766182.6 | N9: =SUM(N24:N27) -> 1832645.3 | O9: =SUM(O24:O27) -> 1899252.6 | P9: =SUM(P24:P27) -> 1966014.7 | Q9: =L9*(1+D3)^5 -> 2031802.8 | R9: =SUM(R24:R27) -> 2099845.9 | S9: =SUM(S24:S27) -> 2166683.7 | T9: =SUM(T24:T27) -> 2233246.9 | U9: =SUM(U24:U27) -> 2299352.4 | V9: =SUM(V24:V27) -> 2364806.1 | W9: =SUM(W24:W27) -> 2429402.9 | X9: =SUM(X24:X27) -> 2492926.7 | Y9: =SUM(Y24:Y27) -> 2555151 | ... AO9: =SUM(AO24:AO27) -> 3170582.7 | AP9: =Q9*(1+E3)^25 -> 3173774.1
A10: 中情景 | B10: 1013567 | C10: 1098706.6 | D10: 1131667.8 | E10: =SUM(E30:E33) -> 1165087.9 | F10: =SUM(F30:F33) -> 1237214.5 | G10: =D10*(1+B4)^3 -> 1325076 | H10: =SUM(H30:H33) -> 1413639.4 | I10: =SUM(I30:I33) -> 1492187.9 | J10: =SUM(J30:J33) -> 1564031 | K10: =SUM(K30:K33) -> 1631323.5 | L10: =G10*(1+C4)^5 -> 1699238.7 | M10: =SUM(M30:M33) -> 1764094.9 | N10: =SUM(N30:N33) -> 1833047.7 | O10: =SUM(O30:O33) -> 1903653.4 | P10: =SUM(P30:P33) -> 1975607.9 | Q10: =L10*(1+D4)^5 -> 2047581.3 | R10: =SUM(R30:R33) -> 2121912.6 | S10: =SUM(S30:S33) -> 2195584.9 | T10: =SUM(T30:T33) -> 2269339.5 | U10: =SUM(U30:U33) -> 2342974.2 | V10: =SUM(V30:V33) -> 2416270.3 | W10: =SUM(W30:W33) -> 2488991.8 | X10: =SUM(X30:X33) -> 2560886 | Y10: =SUM(Y30:Y33) -> 2631683.3 | ... AO10: =SUM(AO30:AO33) -> 3357974.4 | AP10: =Q10*(1+E4)^25 -> 3359274.1
A11: 低情景 | B11: 1013567 | C11: 1098706.6 | D11: 1131667.8 | E11: =SUM(E36:E39) -> 1164956.8 | F11: =SUM(F36:F39) -> 1237027.6 | G11: =D11*(1+B5)^3 -> 1325076 | H11: =SUM(H36:H39) -> 1414405.5 | I11: =SUM(I36:I39) -> 1493970.2 | J11: =SUM(J36:J39) -> 1567246.7 | K11: =SUM(K36:K39) -> 1636535.1 | L11: =G11*(1+C5)^5 -> 1707338 | M11: =SUM(M36:M39) -> 1775868.9 | N11: =SUM(N36:N39) -> 1849776.5 | O11: =SUM(O36:O39) -> 1926615 | P11: =SUM(P36:P39) -> 2006196.1 | Q11: =L11*(1+D5)^5 -> 2087243.6 | R11: =SUM(R36:R39) -> 2172363.4 | S11: =SUM(S36:S39) -> 2258400.4 | T11: =SUM(T36:T39) -> 2346164.4 | U11: =SUM(U36:U39) -> 2435445 | V11: =SUM(V36:V39) -> 2525993.8 | W11: =SUM(W36:W39) -> 2617522.8 | X11: =SUM(X36:X39) -> 2709701.2 | Y11: =SUM(Y36:Y39) -> 2802154.9 | ... AO11: =SUM(AO36:AO39) -> 3868365.7 | AP11: =Q11*(1+E5)^25 -> 3869633
A15: 假设2：三次产业结构
A16: 高情景 | B16: 十四五 | C16: 十五五 | D16: 十六五 | E16: 2060 | G16: 中情景 | H16: 十四五 | I16: 十五五 | J16: 十六五 | K16: 2060 | M16: 低情景 | N16: 十四五 | O16: 十五五 | P16: 十六五 | Q16: 2060
A17: 农业 | B17: 0.074 | C17: 0.072 | D17: 0.067 | E17: 0.049 | G17: 农业 | H17: =AVERAGE(B17,N17) -> 0.074 | I17: =AVERAGE(C17,O17) -> 0.072 | J17: =AVERAGE(D17,P17) -> 0.067 | K17: =AVERAGE(E17,Q17) -> 0.048 | M17: 农业 | N17: 0.074 | O17: 0.072 | P17: 0.067 | Q17: 0.047
A18: 工业 | B18: 0.318 | C18: 0.293 | D18: 0.271 | E18: 0.212 | G18: 工业 | H18: =AVERAGE(B18,N18) -> 0.3155 | I18: =AVERAGE(C18,O18) -> 0.2915 | J18: =AVERAGE(D18,P18) -> 0.2745 | K18: =AVERAGE(E18,Q18) -> 0.226 | M18: 工业 | N18: 0.313 | O18: 0.29 | P18: 0.278 | Q18: 0.24
A19: 建筑业 | B19: 0.068 | C19: 0.065 | D19: 0.062 | E19: 0.049 | G19: 建筑业 | H19: =AVERAGE(B19,N19) -> 0.068 | I19: =AVERAGE(C19,O19) -> 0.065 | J19: =AVERAGE(D19,P19) -> 0.061 | K19: =AVERAGE(E19,Q19) -> 0.046 | M19: 建筑业 | N19: 0.068 | O19: 0.065 | P19: 0.06 | Q19: 0.043
A20: 服务业 | B20: 0.54 | C20: 0.57 | D20: 0.6 | E20: 0.69 | G20: 服务业 | H20: =AVERAGE(B20,N20) -> 0.5425 | I20: =AVERAGE(C20,O20) -> 0.5715 | J20: =AVERAGE(D20,P20) -> 0.5975 | K20: =AVERAGE(E20,Q20) -> 0.68 | M20: 服务业 | N20: 0.545 | O20: 0.573 | P20: 0.595 | Q20: 0.67
A22: 结果2：农、工、建筑和服务业增加值
A23: 高情景 | B23: 2020 | C23: 2021 | D23: 2022 | E23: 2023 | F23: 2024 | G23: 2025 | H23: 2026 | I23: 2027 | J23: 2028 | K23: 2029 | L23: 2030 | M23: 2031 | N23: 2032 | O23: 2033 | P23: 2034 | Q23: 2035 | R23: 2036 | S23: 2037 | T23: 2038 | U23: 2039 | V23: 2040 | W23: 2041 | X23: 2042 | Y23: 2043 | Z23: 2044 | AA23: 2045 | AB23: 2046 | AC23: 2047 | AD23: 2048 | AE23: 2049 | AF23: 2050 | AG23: 2051 | AH23: 2052 | AI23: 2053 | AJ23: 2054 | AK23: 2055 | AL23: 2056 | AM23: 2057 | AN23: 2058 | AO23: 2059 | AP23: 2060
A24: 农业-高情景 | B24: ='高情景（2001-2060, 2020RMB）'!U3 -> 81396.5 | C24: ='高情景（2001-2060, 2020RMB）'!V3 -> 82959.622 | D24: ='高情景（2001-2060, 2020RMB）'!W3 -> 86574.037 | E24: =VLOOKUP($A24,Python数据平滑!$A$9:$AN$21,COLUMN(Python数据平滑!C$9),0) -> 90508.221 | F24: =VLOOKUP($A24,Python数据平滑!$A$9:$AN$21,COLUMN(Python数据平滑!D$9),0) -> 95121.373 | G24: =G$9*B17 -> 97776.796 | H24: =VLOOKUP($A24,Python数据平滑!$A$9:$AN$21,COLUMN(Python数据平滑!F$9),0) -> 104107.17 | I24: =VLOOKUP($A24,Python数据平滑!$A$9:$AN$21,COLUMN(Python数据平滑!G$9),0) -> 108437.05 | J24: =VLOOKUP($A24,Python数据平滑!$A$9:$AN$21,COLUMN(Python数据平滑!H$9),0) -> 112631.95 | K24: =VLOOKUP($A24,Python数据平滑!$A$9:$AN$21,COLUMN(Python数据平滑!I$9),0) -> 116674.18 | L24: =L$9*C17 -> 122578.78 | M24: =VLOOKUP($A24,Python数据平滑!$A$9:$AN$21,COLUMN(Python数据平滑!K$9),0) -> 124238.97 | N24: =VLOOKUP($A24,Python数据平滑!$A$9:$AN$21,COLUMN(Python数据平滑!L$9),0) -> 127735.73 | O24: =VLOOKUP($A24,Python数据平滑!$A$9:$AN$21,COLUMN(Python数据平滑!M$9),0) -> 131028.36 | P24: =VLOOKUP($A24,Python数据平滑!$A$9:$AN$21,COLUMN(Python数据平滑!N$9),0) -> 134109.3 | Q24: =Q$9*D17 -> 136130.79 | R24: =VLOOKUP($A24,Python数据平滑!$A$9:$AN$21,COLUMN(Python数据平滑!P$9),0) -> 139616.67 | S24: =VLOOKUP($A24,Python数据平滑!$A$9:$AN$21,COLUMN(Python数据平滑!Q$9),0) -> 142038.69 | T24: =VLOOKUP($A24,Python数据平滑!$A$9:$AN$21,COLUMN(Python数据平滑!R$9),0) -> 144240.07 | U24: =VLOOKUP($A24,Python数据平滑!$A$9:$AN$21,COLUMN(Python数据平滑!S$9),0) -> 146223.55 | V24: =VLOOKUP($A24,Python数据平滑!$A$9:$AN$21,COLUMN(Python数据平滑!T$9),0) -> 147993.68 | W24: =VLOOKUP($A24,Python数据平滑!$A$9:$AN$21,COLUMN(Python数据平滑!U$9),0) -> 149556.67 | X24: =VLOOKUP($A24,Python数据平滑!$A$9:$AN$21,COLUMN(Python数据平滑!V$9),0) -> 150920.21 | Y24: =VLOOKUP($A24,Python数据平滑!$A$9:$AN$21,COLUMN(Python数据平滑!W$9),0) -> 152093.4 | ... AO24: =VLOOKUP($A24,Python数据平滑!$A$9:$AN$21,COLUMN(Python数据平滑!AM$9),0) -> 155500.47 | AP24: =AP$9*E17 -> 155514.93
A25: 工业-高情景 | B25: ='高情景（2001-2060, 2020RMB）'!U4 -> 312902.9 | C25: ='高情景（2001-2060, 2020RMB）'!V4 -> 356193.68 | D25: ='高情景（2001-2060, 2020RMB）'!W4 -> 375578.61 | E25: =SUM(E60:E65) -> 382345.32 | F25: =SUM(F60:F65) -> 399078.83 | G25: =G$9*B18 -> 420175.96 | H25: =SUM(H60:H65) -> 440090.76 | I25: =SUM(I60:I65) -> 457638.82 | J25: =SUM(J60:J65) -> 473019.34 | K25: =SUM(K60:K65) -> 486587.17 | L25: =L$9*C18 -> 498827.52 | M25: =SUM(M60:M65) -> 510246.33 | N25: =SUM(N60:N65) -> 521034.08 | O25: =SUM(O60:O65) -> 531296.03 | P25: =SUM(P60:P65) -> 541130.53 | Q25: =Q$9*D18 -> 550618.56 | R25: =SUM(R60:R65) -> 559808.83 | S25: =SUM(S60:S65) -> 568699.92 | T25: =SUM(T60:T65) -> 577281.12 | U25: =SUM(U60:U65) -> 585542.75 | V25: =SUM(V60:V65) -> 593475.87 | W25: =SUM(W60:W65) -> 601072.15 | X25: =SUM(X60:X65) -> 608323.61 | Y25: =SUM(Y60:Y65) -> 615222.57 | ... AO25: =SUM(AO60:AO65) -> 672657.16 | AP25: =AP$9*E18 -> 672840.1
A26: 建筑业-高情景 | B26: ='高情景（2001-2060, 2020RMB）'!U5 -> 72444.7 | C26: ='高情景（2001-2060, 2020RMB）'!V5 -> 76614.92 | D26: ='高情景（2001-2060, 2020RMB）'!W5 -> 77971.749 | E26: =VLOOKUP($A26,Python数据平滑!$A$9:$AN$21,COLUMN(Python数据平滑!C$9),0) -> 82009.725 | F26: =VLOOKUP($A26,Python数据平滑!$A$9:$AN$21,COLUMN(Python数据平滑!D$9),0) -> 86241.13 | G26: =G$9*B19 -> 89848.948 | H26: =VLOOKUP($A26,Python数据平滑!$A$9:$AN$21,COLUMN(Python数据平滑!F$9),0) -> 94546.138 | I26: =VLOOKUP($A26,Python数据平滑!$A$9:$AN$21,COLUMN(Python数据平滑!G$9),0) -> 98583.718 | J26: =VLOOKUP($A26,Python数据平滑!$A$9:$AN$21,COLUMN(Python数据平滑!H$9),0) -> 102522.33 | K26: =VLOOKUP($A26,Python数据平滑!$A$9:$AN$21,COLUMN(Python数据平滑!I$9),0) -> 106346.75 | L26: =L$9*C19 -> 110661.39 | M26: =VLOOKUP($A26,Python数据平滑!$A$9:$AN$21,COLUMN(Python数据平滑!K$9),0) -> 113599.22 | N26: =VLOOKUP($A26,Python数据平滑!$A$9:$AN$21,COLUMN(Python数据平滑!L$9),0) -> 117004.3 | O26: =VLOOKUP($A26,Python数据平滑!$A$9:$AN$21,COLUMN(Python数据平滑!M$9),0) -> 120249.42 | P26: =VLOOKUP($A26,Python数据平滑!$A$9:$AN$21,COLUMN(Python数据平滑!N$9),0) -> 123327.35 | Q26: =Q$9*D19 -> 125971.77 | R26: =VLOOKUP($A26,Python数据平滑!$A$9:$AN$21,COLUMN(Python数据平滑!P$9),0) -> 128961.55 | S26: =VLOOKUP($A26,Python数据平滑!$A$9:$AN$21,COLUMN(Python数据平滑!Q$9),0) -> 131512.13 | T26: =VLOOKUP($A26,Python数据平滑!$A$9:$AN$21,COLUMN(Python数据平滑!R$9),0) -> 133884.06 | U26: =VLOOKUP($A26,Python数据平滑!$A$9:$AN$21,COLUMN(Python数据平滑!S$9),0) -> 136078.65 | V26: =VLOOKUP($A26,Python数据平滑!$A$9:$AN$21,COLUMN(Python数据平滑!T$9),0) -> 138098.74 | W26: =VLOOKUP($A26,Python数据平滑!$A$9:$AN$21,COLUMN(Python数据平滑!U$9),0) -> 139948.62 | X26: =VLOOKUP($A26,Python数据平滑!$A$9:$AN$21,COLUMN(Python数据平滑!V$9),0) -> 141633.92 | Y26: =VLOOKUP($A26,Python数据平滑!$A$9:$AN$21,COLUMN(Python数据平滑!W$9),0) -> 143161.5 | ... AO26: =VLOOKUP($A26,Python数据平滑!$A$9:$AN$21,COLUMN(Python数据平滑!AM$9),0) -> 154905.79 | AP26: =AP$9*E19 -> 155514.93
A27: 服务业-高情景 | B27: ='高情景（2001-2060, 2020RMB）'!U56 -> 546822.9 | C27: ='高情景（2001-2060, 2020RMB）'!V56 -> 582938.41 | D27: ='高情景（2001-2060, 2020RMB）'!W56 -> 591543.44 | E27: =SUM(E67:E69) -> 609471 | F27: =SUM(F67:F69) -> 654663.99 | G27: =G$9*B20 -> 713506.35 | H27: =SUM(H67:H69) -> 771500.33 | I27: =SUM(I67:I69) -> 825376.52 | J27: =SUM(J67:J69) -> 875679.04 | K27: =SUM(K67:K69) -> 923495.23 | L27: =L$9*C20 -> 970415.31 | M27: =SUM(M67:M69) -> 1018098.1 | N27: =SUM(N67:N69) -> 1066871.2 | O27: =SUM(O67:O69) -> 1116678.8 | P27: =SUM(P67:P69) -> 1167447.5 | Q27: =Q$9*D20 -> 1219081.7 | R27: =SUM(R67:R69) -> 1271458.9 | S27: =SUM(S67:S69) -> 1324432.9 | T27: =SUM(T67:T69) -> 1377841.6 | U27: =SUM(U67:U69) -> 1431507.4 | V27: =SUM(V67:V69) -> 1485237.8 | W27: =SUM(W67:W69) -> 1538825.5 | X27: =SUM(X67:X69) -> 1592049 | Y27: =SUM(Y67:Y69) -> 1644673.6 | ... AO27: =SUM(AO67:AO69) -> 2187519.3 | AP27: =AP$9*E20 -> 2189904.1
A29: 中情景 | B29: 2020 | C29: 2021 | D29: 2022 | E29: 2023 | F29: 2024 | G29: 2025 | H29: 2026 | I29: 2027 | J29: 2028 | K29: 2029 | L29: 2030 | M29: 2031 | N29: 2032 | O29: 2033 | P29: 2034 | Q29: 2035 | R29: 2036 | S29: 2037 | T29: 2038 | U29: 2039 | V29: 2040 | W29: 2041 | X29: 2042 | Y29: 2043 | Z29: 2044 | AA29: 2045 | AB29: 2046 | AC29: 2047 | AD29: 2048 | AE29: 2049 | AF29: 2050 | AG29: 2051 | AH29: 2052 | AI29: 2053 | AJ29: 2054 | AK29: 2055 | AL29: 2056 | AM29: 2057 | AN29: 2058 | AO29: 2059 | AP29: 2060
A30: 农业-中情景 | B30: ='高情景（2001-2060, 2020RMB）'!U3 -> 81396.5 | C30: ='高情景（2001-2060, 2020RMB）'!V3 -> 82959.622 | D30: ='高情景（2001-2060, 2020RMB）'!W3 -> 86574.037 | E30: =VLOOKUP($A30,Python数据平滑!$A$9:$AN$21,COLUMN(Python数据平滑!C$9),0) -> 90558.743 | F30: =VLOOKUP($A30,Python数据平滑!$A$9:$AN$21,COLUMN(Python数据平滑!D$9),0) -> 95114.072 | G30: =G$10*H17 -> 98055.627 | H30: =VLOOKUP($A30,Python数据平滑!$A$9:$AN$21,COLUMN(Python数据平滑!F$9),0) -> 104045.39 | I30: =VLOOKUP($A30,Python数据平滑!$A$9:$AN$21,COLUMN(Python数据平滑!G$9),0) -> 108382.38 | J30: =VLOOKUP($A30,Python数据平滑!$A$9:$AN$21,COLUMN(Python数据平滑!H$9),0) -> 112609.19 | K30: =VLOOKUP($A30,Python数据平滑!$A$9:$AN$21,COLUMN(Python数据平滑!I$9),0) -> 116709 | L30: =L$10*I17 -> 122345.18 | M30: =VLOOKUP($A30,Python数据平滑!$A$9:$AN$21,COLUMN(Python数据平滑!K$9),0) -> 124467.5 | N30: =VLOOKUP($A30,Python数据平滑!$A$9:$AN$21,COLUMN(Python数据平滑!L$9),0) -> 128100.02 | O30: =VLOOKUP($A30,Python数据平滑!$A$9:$AN$21,COLUMN(Python数据平滑!M$9),0) -> 131553.42 | P30: =VLOOKUP($A30,Python数据平滑!$A$9:$AN$21,COLUMN(Python数据平滑!N$9),0) -> 134818.93 | Q30: =Q$10*J17 -> 137187.95 | R30: =VLOOKUP($A30,Python数据平滑!$A$9:$AN$21,COLUMN(Python数据平滑!P$9),0) -> 140760.28 | S30: =VLOOKUP($A30,Python数据平滑!$A$9:$AN$21,COLUMN(Python数据平滑!Q$9),0) -> 143427.62 | T30: =VLOOKUP($A30,Python数据平滑!$A$9:$AN$21,COLUMN(Python数据平滑!R$9),0) -> 145890.02 | U30: =VLOOKUP($A30,Python数据平滑!$A$9:$AN$21,COLUMN(Python数据平滑!S$9),0) -> 148147.59 | V30: =VLOOKUP($A30,Python数据平滑!$A$9:$AN$21,COLUMN(Python数据平滑!T$9),0) -> 150202.06 | W30: =VLOOKUP($A30,Python数据平滑!$A$9:$AN$21,COLUMN(Python数据平滑!U$9),0) -> 152056.7 | X30: =VLOOKUP($A30,Python数据平滑!$A$9:$AN$21,COLUMN(Python数据平滑!V$9),0) -> 153716.22 | Y30: =VLOOKUP($A30,Python数据平滑!$A$9:$AN$21,COLUMN(Python数据平滑!W$9),0) -> 155186.66 | ... AO30: =VLOOKUP($A30,Python数据平滑!$A$9:$AN$21,COLUMN(Python数据平滑!AM$9),0) -> 161304.37 | AP30: =AP$10*K17 -> 161245.16
A31: 工业-中情景 | B31: ='高情景（2001-2060, 2020RMB）'!U4 -> 312902.9 | C31: ='高情景（2001-2060, 2020RMB）'!V4 -> 356193.68 | D31: ='高情景（2001-2060, 2020RMB）'!W4 -> 375578.61 | E31: =SUM(E72:E77) -> 382017.76 | F31: =SUM(F72:F77) -> 397956.03 | G31: =G$10*H18 -> 418061.49 | H31: =SUM(H72:H77) -> 437012.43 | I31: =SUM(I72:I77) -> 453769.03 | J31: =SUM(J72:J77) -> 468688.24 | K31: =SUM(K72:K77) -> 482310.21 | L31: =L$10*I18 -> 495328.07 | M31: =SUM(M72:M77) -> 508417.71 | N31: =SUM(N72:N77) -> 521698 | O31: =SUM(O72:O77) -> 535122.03 | P31: =SUM(P72:P77) -> 548614.61 | Q31: =Q$10*J18 -> 562061.06 | R31: =SUM(R72:R77) -> 575328.11 | S31: =SUM(S72:S77) -> 588363.38 | T31: =SUM(T72:T77) -> 601138.51 | U31: =SUM(U72:U77) -> 613624.78 | V31: =SUM(V72:V77) -> 625792.99 | W31: =SUM(W72:W77) -> 637613.58 | X31: =SUM(X72:X77) -> 649056.6 | Y31: =SUM(Y72:Y77) -> 660091.85 | ... AO31: =SUM(AO72:AO77) -> 758842.08 | AP31: =AP$10*K18 -> 759195.95
A32: 建筑业-中情景 | B32: ='高情景（2001-2060, 2020RMB）'!U5 -> 72444.7 | C32: ='高情景（2001-2060, 2020RMB）'!V5 -> 76614.92 | D32: ='高情景（2001-2060, 2020RMB）'!W5 -> 77971.749 | E32: =VLOOKUP($A32,Python数据平滑!$A$9:$AN$21,COLUMN(Python数据平滑!C$9),0) -> 82115.328 | F32: =VLOOKUP($A32,Python数据平滑!$A$9:$AN$21,COLUMN(Python数据平滑!D$9),0) -> 86399.496 | G32: =G$10*H19 -> 90105.171 | H32: =VLOOKUP($A32,Python数据平滑!$A$9:$AN$21,COLUMN(Python数据平滑!F$9),0) -> 94727.032 | I32: =VLOOKUP($A32,Python数据平滑!$A$9:$AN$21,COLUMN(Python数据平滑!G$9),0) -> 98731.578 | J32: =VLOOKUP($A32,Python数据平滑!$A$9:$AN$21,COLUMN(Python数据平滑!H$9),0) -> 102606.85 | K32: =VLOOKUP($A32,Python数据平滑!$A$9:$AN$21,COLUMN(Python数据平滑!I$9),0) -> 106337.87 | L32: =L$10*I19 -> 110450.51 | M32: =VLOOKUP($A32,Python数据平滑!$A$9:$AN$21,COLUMN(Python数据平滑!K$9),0) -> 113317.77 | N32: =VLOOKUP($A32,Python数据平滑!$A$9:$AN$21,COLUMN(Python数据平滑!L$9),0) -> 116547.47 | O32: =VLOOKUP($A32,Python数据平滑!$A$9:$AN$21,COLUMN(Python数据平滑!M$9),0) -> 119594.67 | P32: =VLOOKUP($A32,Python数据平滑!$A$9:$AN$21,COLUMN(Python数据平滑!N$9),0) -> 122455.47 | Q32: =Q$10*J19 -> 124902.46 | R32: =VLOOKUP($A32,Python数据平滑!$A$9:$AN$21,COLUMN(Python数据平滑!P$9),0) -> 127613.25 | S32: =VLOOKUP($A32,Python数据平滑!$A$9:$AN$21,COLUMN(Python数据平滑!Q$9),0) -> 129913.23 | T32: =VLOOKUP($A32,Python数据平滑!$A$9:$AN$21,COLUMN(Python数据平滑!R$9),0) -> 132032.6 | U32: =VLOOKUP($A32,Python数据平滑!$A$9:$AN$21,COLUMN(Python数据平滑!S$9),0) -> 133977.65 | V32: =VLOOKUP($A32,Python数据平滑!$A$9:$AN$21,COLUMN(Python数据平滑!T$9),0) -> 135756.34 | W32: =VLOOKUP($A32,Python数据平滑!$A$9:$AN$21,COLUMN(Python数据平滑!U$9),0) -> 137378.14 | X32: =VLOOKUP($A32,Python数据平滑!$A$9:$AN$21,COLUMN(Python数据平滑!V$9),0) -> 138853.93 | Y32: =VLOOKUP($A32,Python数据平滑!$A$9:$AN$21,COLUMN(Python数据平滑!W$9),0) -> 140195.76 | ... AO32: =VLOOKUP($A32,Python数据平滑!$A$9:$AN$21,COLUMN(Python数据平滑!AM$9),0) -> 156278.2 | AP32: =AP$10*K19 -> 154526.61
A33: 服务业-中情景 | B33: ='高情景（2001-2060, 2020RMB）'!U56 -> 546822.9 | C33: ='高情景（2001-2060, 2020RMB）'!V56 -> 582938.41 | D33: ='高情景（2001-2060, 2020RMB）'!W56 -> 591543.44 | E33: =SUM(E79:E81) -> 610396.07 | F33: =SUM(F79:F81) -> 657744.9 | G33: =G$10*H20 -> 718853.75 | H33: =SUM(H79:H81) -> 777854.57 | I33: =SUM(I79:I81) -> 831304.93 | J33: =SUM(J79:J81) -> 880126.75 | K33: =SUM(K79:K81) -> 925966.42 | L33: =L$10*I20 -> 971114.9 | M33: =SUM(M79:M81) -> 1017891.9 | N33: =SUM(N79:N81) -> 1066702.2 | O33: =SUM(O79:O81) -> 1117383.3 | P33: =SUM(P79:P81) -> 1169718.9 | Q33: =Q$10*J20 -> 1223429.8 | R33: =SUM(R79:R81) -> 1278211 | S33: =SUM(S79:S81) -> 1333880.7 | T33: =SUM(T79:T81) -> 1390278.3 | U33: =SUM(U79:U81) -> 1447224.2 | V33: =SUM(V79:V81) -> 1504518.9 | W33: =SUM(W79:W81) -> 1561943.4 | X33: =SUM(X79:X81) -> 1619259.2 | Y33: =SUM(Y79:Y81) -> 1676209 | ... AO33: =SUM(AO79:AO81) -> 2281549.7 | AP33: =AP$10*K20 -> 2284306.4
A35: 低情景 | B35: 2020 | C35: 2021 | D35: 2022 | E35: 2023 | F35: 2024 | G35: 2025 | H35: 2026 | I35: 2027 | J35: 2028 | K35: 2029 | L35: 2030 | M35: 2031 | N35: 2032 | O35: 2033 | P35: 2034 | Q35: 2035 | R35: 2036 | S35: 2037 | T35: 2038 | U35: 2039 | V35: 2040 | W35: 2041 | X35: 2042 | Y35: 2043 | Z35: 2044 | AA35: 2045 | AB35: 2046 | AC35: 2047 | AD35: 2048 | AE35: 2049 | AF35: 2050 | AG35: 2051 | AH35: 2052 | AI35: 2053 | AJ35: 2054 | AK35: 2055 | AL35: 2056 | AM35: 2057 | AN35: 2058 | AO35: 2059 | AP35: 2060
A36: 农业-低情景 | B36: ='高情景（2001-2060, 2020RMB）'!U3 -> 81396.5 | C36: ='高情景（2001-2060, 2020RMB）'!V3 -> 82959.622 | D36: ='高情景（2001-2060, 2020RMB）'!W3 -> 86574.037 | E36: =VLOOKUP($A36,Python数据平滑!$A$9:$AN$21,COLUMN(Python数据平滑!C$9),0) -> 90517.822 | F36: =VLOOKUP($A36,Python数据平滑!$A$9:$AN$21,COLUMN(Python数据平滑!D$9),0) -> 95040.61 | G36: =G$11*N17 -> 98055.627 | H36: =VLOOKUP($A36,Python数据平滑!$A$9:$AN$21,COLUMN(Python数据平滑!F$9),0) -> 104025.52 | I36: =VLOOKUP($A36,Python数据平滑!$A$9:$AN$21,COLUMN(Python数据平滑!G$9),0) -> 108455.52 | J36: =VLOOKUP($A36,Python数据平滑!$A$9:$AN$21,COLUMN(Python数据平滑!H$9),0) -> 112823.22 | K36: =VLOOKUP($A36,Python数据平滑!$A$9:$AN$21,COLUMN(Python数据平滑!I$9),0) -> 117113.91 | L36: =L$11*O17 -> 122928.33 | M36: =VLOOKUP($A36,Python数据平滑!$A$9:$AN$21,COLUMN(Python数据平滑!K$9),0) -> 125409.47 | N36: =VLOOKUP($A36,Python数据平滑!$A$9:$AN$21,COLUMN(Python数据平滑!L$9),0) -> 129389.3 | O36: =VLOOKUP($A36,Python数据平滑!$A$9:$AN$21,COLUMN(Python数据平滑!M$9),0) -> 133242.26 | P36: =VLOOKUP($A36,Python数据平滑!$A$9:$AN$21,COLUMN(Python数据平滑!N$9),0) -> 136958.57 | Q36: =Q$11*P17 -> 139845.32 | R36: =VLOOKUP($A36,Python数据平滑!$A$9:$AN$21,COLUMN(Python数据平滑!P$9),0) -> 143948.44 | S36: =VLOOKUP($A36,Python数据平滑!$A$9:$AN$21,COLUMN(Python数据平滑!Q$9),0) -> 147208.77 | T36: =VLOOKUP($A36,Python数据平滑!$A$9:$AN$21,COLUMN(Python数据平滑!R$9),0) -> 150306.04 | U36: =VLOOKUP($A36,Python数据平滑!$A$9:$AN$21,COLUMN(Python数据平滑!S$9),0) -> 153236.87 | V36: =VLOOKUP($A36,Python数据平滑!$A$9:$AN$21,COLUMN(Python数据平滑!T$9),0) -> 155999.18 | W36: =VLOOKUP($A36,Python数据平滑!$A$9:$AN$21,COLUMN(Python数据平滑!U$9),0) -> 158592.15 | X36: =VLOOKUP($A36,Python数据平滑!$A$9:$AN$21,COLUMN(Python数据平滑!V$9),0) -> 161016.15 | Y36: =VLOOKUP($A36,Python数据平滑!$A$9:$AN$21,COLUMN(Python数据平滑!W$9),0) -> 163272.74 | ... AO36: =VLOOKUP($A36,Python数据平滑!$A$9:$AN$21,COLUMN(Python数据平滑!AM$9),0) -> 181396.95 | AP36: =AP$11*Q17 -> 181872.75
A37: 工业-低情景 | B37: ='高情景（2001-2060, 2020RMB）'!U4 -> 312902.9 | C37: ='高情景（2001-2060, 2020RMB）'!V4 -> 356193.68 | D37: ='高情景（2001-2060, 2020RMB）'!W4 -> 375578.61 | E37: =SUM(E84:E89) -> 381410.94 | F37: =SUM(F84:F89) -> 396001.71 | G37: =G$11*N18 -> 414748.8 | H37: =SUM(H84:H89) -> 432963.42 | I37: =SUM(I84:I89) -> 449702.01 | J37: =SUM(J84:J89) -> 465280.75 | K37: =SUM(K84:K89) -> 480201.59 | L37: =L$11*O18 -> 495128.01 | M37: =SUM(M84:M89) -> 510725.26 | N37: =SUM(N84:N89) -> 527113.35 | O37: =SUM(O84:O89) -> 544238.47 | P37: =SUM(P84:P89) -> 562003.86 | Q37: =Q$11*P18 -> 580253.73 | R37: =SUM(R84:R89) -> 598801.01 | S37: =SUM(S84:S89) -> 617565.96 | T37: =SUM(T84:T89) -> 636497.26 | U37: =SUM(U84:U89) -> 655537.77 | V37: =SUM(V84:V89) -> 674624.35 | W37: =SUM(W84:W89) -> 693687.84 | X37: =SUM(X84:X89) -> 712653.11 | Y37: =SUM(Y84:Y89) -> 731439.2 | ... AO37: =SUM(AO84:AO89) -> 927838.22 | AP37: =AP$11*Q18 -> 928711.93
A38: 建筑业-低情景 | B38: ='高情景（2001-2060, 2020RMB）'!U5 -> 72444.7 | C38: ='高情景（2001-2060, 2020RMB）'!V5 -> 76614.92 | D38: ='高情景（2001-2060, 2020RMB）'!W5 -> 77971.749 | E38: =VLOOKUP($A38,Python数据平滑!$A$9:$AN$21,COLUMN(Python数据平滑!C$9),0) -> 82138.959 | F38: =VLOOKUP($A38,Python数据平滑!$A$9:$AN$21,COLUMN(Python数据平滑!D$9),0) -> 86500.47 | G38: =G$11*N19 -> 90105.171 | H38: =VLOOKUP($A38,Python数据平滑!$A$9:$AN$21,COLUMN(Python数据平滑!F$9),0) -> 94950.216 | I38: =VLOOKUP($A38,Python数据平滑!$A$9:$AN$21,COLUMN(Python数据平滑!G$9),0) -> 98999.445 | J38: =VLOOKUP($A38,Python数据平滑!$A$9:$AN$21,COLUMN(Python数据平滑!H$9),0) -> 102909.15 | K38: =VLOOKUP($A38,Python数据平滑!$A$9:$AN$21,COLUMN(Python数据平滑!I$9),0) -> 106665.5 | L38: =L$11*O19 -> 110976.97 | M38: =VLOOKUP($A38,Python数据平滑!$A$9:$AN$21,COLUMN(Python数据平滑!K$9),0) -> 113675.61 | N38: =VLOOKUP($A38,Python数据平滑!$A$9:$AN$21,COLUMN(Python数据平滑!L$9),0) -> 116914.74 | O38: =VLOOKUP($A38,Python数据平滑!$A$9:$AN$21,COLUMN(Python数据平滑!M$9),0) -> 119971.23 | P38: =VLOOKUP($A38,Python数据平滑!$A$9:$AN$21,COLUMN(Python数据平滑!N$9),0) -> 122844.36 | Q38: =Q$11*P19 -> 125234.62 | R38: =VLOOKUP($A38,Python数据平滑!$A$9:$AN$21,COLUMN(Python数据平滑!P$9),0) -> 128049.89 | S38: =VLOOKUP($A38,Python数据平滑!$A$9:$AN$21,COLUMN(Python数据平滑!Q$9),0) -> 130392.83 | T38: =VLOOKUP($A38,Python数据平滑!$A$9:$AN$21,COLUMN(Python数据平滑!R$9),0) -> 132573.16 | U38: =VLOOKUP($A38,Python数据平滑!$A$9:$AN$21,COLUMN(Python数据平滑!S$9),0) -> 134601.28 | V38: =VLOOKUP($A38,Python数据平滑!$A$9:$AN$21,COLUMN(Python数据平滑!T$9),0) -> 136489.36 | W38: =VLOOKUP($A38,Python数据平滑!$A$9:$AN$21,COLUMN(Python数据平滑!U$9),0) -> 138251.13 | X38: =VLOOKUP($A38,Python数据平滑!$A$9:$AN$21,COLUMN(Python数据平滑!V$9),0) -> 139901.75 | Y38: =VLOOKUP($A38,Python数据平滑!$A$9:$AN$21,COLUMN(Python数据平滑!W$9),0) -> 141457.66 | ... AO38: =VLOOKUP($A38,Python数据平滑!$A$9:$AN$21,COLUMN(Python数据平滑!AM$9),0) -> 170684.32 | AP38: =AP$11*Q19 -> 166394.22
A39: 服务业-低情景 | B39: ='高情景（2001-2060, 2020RMB）'!U56 -> 546822.9 | C39: ='高情景（2001-2060, 2020RMB）'!V56 -> 582938.41 | D39: ='高情景（2001-2060, 2020RMB）'!W56 -> 591543.44 | E39: =SUM(E91:E93) -> 610889.12 | F39: =SUM(F91:F93) -> 659484.77 | G39: =G$11*N20 -> 722166.44 | H39: =SUM(H91:H93) -> 782466.3 | I39: =SUM(I91:I93) -> 836813.19 | J39: =SUM(J91:J93) -> 886233.61 | K39: =SUM(K91:K93) -> 932554.06 | L39: =L$11*O20 -> 978304.66 | M39: =SUM(M91:M93) -> 1026058.5 | N39: =SUM(N91:N93) -> 1076359.1 | O39: =SUM(O91:O93) -> 1129163 | P39: =SUM(P91:P93) -> 1184389.3 | Q39: =Q$11*P20 -> 1241910 | R39: =SUM(R91:R93) -> 1301564.1 | S39: =SUM(S91:S93) -> 1363232.8 | T39: =SUM(T91:T93) -> 1426788 | U39: =SUM(U91:U93) -> 1492069 | V39: =SUM(V91:V93) -> 1558880.9 | W39: =SUM(W91:W93) -> 1626991.6 | X39: =SUM(X91:X93) -> 1696130.2 | Y39: =SUM(Y91:Y93) -> 1765985.3 | ... AO39: =SUM(AO91:AO93) -> 2588446.2 | AP39: =AP$11*Q20 -> 2592654.1
A43: 假设3：产业大类结构
A44: 高情景 | B44: 2019 | C44: 2022 | D44: 十四五 | E44: 十五五 | F44: 十六五 | G44: 2060 | I44: 中情景 | J44: 十四五 | K44: 十五五 | L44: 十六五 | M44: 2060 | O44: 低情景 | P44: 十四五 | Q44: 十五五 | R44: 十六五 | S44: 2060
A45: 能源产业 | B45: =SUM('高情景（2001-2060, 2020RMB）'!T14:T15,'高情景（2001-2060, 2020RMB）'!T33,'高情景（2001-2060, 2020RMB）'!T53:T54)/'高情景（2001-2060, 2020RMB）'!T13 -> 0.11241444 | C45: =SUM('高情景（2001-2060, 2020RMB）'!W14:W15,'高情景（2001-2060, 2020RMB）'!W33,'高情景（2001-2060, 2020RMB）'!W53:W54)/'高情景（2001-2060, 2020RMB）'!W13 -> 0.10728573 | D45: 0.105 | E45: 0.102 | F45: 0.098 | G45: 0.078 | I45: 能源产业 | J45: =(D45+P45)/2 -> 0.104 | K45: =(E45+Q45)/2 -> 0.0995 | L45: =(F45+R45)/2 -> 0.0915 | M45: =(G45+S45)/2 -> 0.07 | O45: 能源产业 | P45: 0.103 | Q45: 0.097 | R45: 0.085 | S45: 0.062
A46: 电力与热力产业 | B46: ='高情景（2001-2060, 2020RMB）'!T52/'高情景（2001-2060, 2020RMB）'!T13 -> 0.045856952 | C46: ='高情景（2001-2060, 2020RMB）'!W52/'高情景（2001-2060, 2020RMB）'!W13 -> 0.046516835 | D46: 0.05 | E46: 0.053 | F46: 0.061 | G46: 0.083 | I46: 电力与热力产业 | J46: =(D46+P46)/2 -> 0.05 | K46: =(E46+Q46)/2 -> 0.053 | L46: =(F46+R46)/2 -> 0.0605 | M46: =(G46+S46)/2 -> 0.082 | O46: 电力与热力产业 | P46: 0.05 | Q46: 0.053 | R46: 0.06 | S46: 0.081
A47: 传统高耗能产业 | B47: =SUM('高情景（2001-2060, 2020RMB）'!T25:T26,'高情景（2001-2060, 2020RMB）'!T30,'高情景（2001-2060, 2020RMB）'!T34,'高情景（2001-2060, 2020RMB）'!T36:T37,'高情景（2001-2060, 2020RMB）'!T38:T40)/'高情景（2001-2060, 2020RMB）'!T13 -> 0.28901451 | C47: =SUM('高情景（2001-2060, 2020RMB）'!W25:W26,'高情景（2001-2060, 2020RMB）'!W30,'高情景（2001-2060, 2020RMB）'!W34,'高情景（2001-2060, 2020RMB）'!W36:W37,'高情景（2001-2060, 2020RMB）'!W38:W40)/'高情景（2001-2060, 2020RMB）'!W13 -> 0.27105648 | D47: 0.268 | E47: 0.26 | F47: 0.238 | G47: 0.19 | I47: 传统高耗能产业 | J47: =(D47+P47)/2 -> 0.263 | K47: =(E47+Q47)/2 -> 0.25 | L47: =(F47+R47)/2 -> 0.2255 | M47: =(G47+S47)/2 -> 0.163 | O47: 传统高耗能产业 | P47: 0.258 | Q47: 0.24 | R47: 0.213 | S47: 0.136
A48: 装备制造业 | B48: =SUM('高情景（2001-2060, 2020RMB）'!T41:T46)/'高情景（2001-2060, 2020RMB）'!T13 -> 0.25386829 | C48: =SUM('高情景（2001-2060, 2020RMB）'!W41:W46)/'高情景（2001-2060, 2020RMB）'!W13 -> 0.2703341 | D48: 0.273 | E48: 0.278 | F48: 0.282 | G48: 0.295 | I48: 装备制造业 | J48: =(D48+P48)/2 -> 0.2765 | K48: =(E48+Q48)/2 -> 0.285 | L48: =(F48+R48)/2 -> 0.2935 | M48: =(G48+S48)/2 -> 0.315 | O48: 装备制造业 | P48: 0.28 | Q48: 0.292 | R48: 0.305 | S48: 0.335
A49: 高技术产业 | B49: =SUM('高情景（2001-2060, 2020RMB）'!T47:T48,'高情景（2001-2060, 2020RMB）'!T35)/'高情景（2001-2060, 2020RMB）'!T13 -> 0.12956589 | C49: =SUM('高情景（2001-2060, 2020RMB）'!W47:W48,'高情景（2001-2060, 2020RMB）'!W35)/'高情景（2001-2060, 2020RMB）'!W13 -> 0.14591243 | D49: 0.152 | E49: 0.157 | F49: 0.172 | G49: 0.23 | I49: 高技术产业 | J49: =(D49+P49)/2 -> 0.156 | K49: =(E49+Q49)/2 -> 0.1665 | L49: =(F49+R49)/2 -> 0.186 | M49: =(G49+S49)/2 -> 0.254 | O49: 高技术产业 | P49: 0.16 | Q49: 0.176 | R49: 0.2 | S49: 0.278
A50: 其他产业 | B50: =SUM('高情景（2001-2060, 2020RMB）'!T16:T24,'高情景（2001-2060, 2020RMB）'!T27:T29,'高情景（2001-2060, 2020RMB）'!T31:T32,'高情景（2001-2060, 2020RMB）'!T49:T51)/'高情景（2001-2060, 2020RMB）'!T13 -> 0.16927992 | C50: =SUM('高情景（2001-2060, 2020RMB）'!W16:W24,'高情景（2001-2060, 2020RMB）'!W27:W29,'高情景（2001-2060, 2020RMB）'!W31:W32,'高情景（2001-2060, 2020RMB）'!W49:W51)/'高情景（2001-2060, 2020RMB）'!W13 -> 0.15889442 | D50: =D51-SUM(D45:D49) -> 0.152 | E50: =E51-SUM(E45:E49) -> 0.15 | F50: =F51-SUM(F45:F49) -> 0.149 | G50: =G51-SUM(G45:G49) -> 0.124 | I50: 其他产业 | J50: =(D50+P50)/2 -> 0.1505 | K50: =(E50+Q50)/2 -> 0.146 | L50: =(F50+R50)/2 -> 0.143 | M50: =(G50+S50)/2 -> 0.116 | O50: 其他产业 | P50: =P51-SUM(P45:P49) -> 0.149 | Q50: =Q51-SUM(Q45:Q49) -> 0.142 | R50: =R51-SUM(R45:R49) -> 0.137 | S50: =S51-SUM(S45:S49) -> 0.108 | U50: 电力需求-GDP 弹性
...

Sheet Python数据平滑
A1: 结果1：GDP平滑
B2: 2022 | C2: 2023 | D2: 2024 | E2: 2025 | F2: 2026 | G2: 2027 | H2: 2028 | I2: 2029 | J2: 2030 | K2: 2031 | L2: 2032 | M2: 2033 | N2: 2034 | O2: 2035 | P2: 2036 | Q2: 2037 | R2: 2038 | S2: 2039 | T2: 2040 | U2: 2041 | V2: 2042 | W2: 2043 | X2: 2044 | Y2: 2045 | Z2: 2046 | AA2: 2047 | AB2: 2048 | AC2: 2049 | AD2: 2050 | AE2: 2051 | AF2: 2052 | AG2: 2053 | AH2: 2054 | AI2: 2055 | AJ2: 2056 | AK2: 2057 | AL2: 2058 | AM2: 2059 | AN2: 2060
A3: 高情景 | B3: 1131667.8 | C3: 1194812 | D3: 1263623.2 | E3: 1321308.1 | F3: 1403841.6 | G3: 1474848.1 | H3: 1546180.7 | I3: 1617634 | J3: 1702483 | K3: 1760090.2 | L3: 1830696 | M3: 1900631.8 | N3: 1969715.6 | O3: 2031802.8 | P3: 2104647.1 | Q3: 2170182.2 | R3: 2234242.3 | S3: 2296702.8 | T3: 2357453.6 | U3: 2416399.1 | V3: 2473458.8 | W3: 2528567.4 | X3: 2581674.9 | Y3: 2632746.9 | Z3: 2681763.7 | AA3: 2728720.8 | AB3: 2773628.1 | AC3: 2816509.6 | AD3: 2857402.8 | AE3: 2896358 | AF3: 2933438 | AG3: 2968717.2 | AH3: 3002280.8 | AI3: 3034224.4 | AJ3: 3064653.3 | AK3: 3093681.4 | AL3: 3121431.1 | AM3: 3148032.4 | AN3: 3173774.1
A4: 中情景 | B4: 1131667.8 | C4: 1195506.2 | D4: 1263585.2 | E4: 1325076 | F4: 1403070.8 | G4: 1474143.5 | H4: 1545872.2 | I4: 1618079.8 | J4: 1699238.7 | K4: 1763217.3 | L4: 1835790.7 | M4: 1908133 | N4: 1980072.8 | O4: 2047581.3 | P4: 2122085.6 | Q4: 2191845.3 | R4: 2260578.3 | S4: 2328148.8 | T4: 2394431.1 | U4: 2459310.1 | V4: 2522681.9 | W4: 2584454 | X4: 2644546.2 | Y4: 2702890.5 | Z4: 2759431.2 | AA4: 2814125.3 | AB4: 2866942.1 | AC4: 2917863.4 | AD4: 2966883 | AE4: 3014006.8 | AF4: 3059252.1 | AG4: 3102647.5 | AH4: 3144232.5 | AI4: 3184056.8 | AJ4: 3222180 | AK4: 3258671 | AL4: 3293607.8 | AM4: 3327076.4 | AN4: 3359274.1
A5: 低情景 | B5: 1131667.8 | C5: 1194993.8 | D5: 1262669.4 | E5: 1325076 | F5: 1402866.5 | G5: 1475178.2 | H5: 1548814.6 | I5: 1623655.6 | J5: 1707338 | K5: 1776447.7 | L5: 1854137.3 | M5: 1932510.1 | N5: 2011429.6 | O5: 2087243.6 | P5: 2170357.9 | Q5: 2250091.8 | R5: 2329824.4 | S5: 2409422.3 | T5: 2488755 | U5: 2567696.1 | V5: 2646123.1 | W5: 2723918.7 | X5: 2800971.1 | Y5: 2877174.8 | Z5: 2952430.8 | AA5: 3026647 | AB5: 3099738.9 | AC5: 3171629.7 | AD5: 3242250.6 | AE5: 3311541.2 | AF5: 3379449.2 | AG5: 3445931.3 | AH5: 3510952.4 | AI5: 3574486.2 | AJ5: 3636515.2 | AK5: 3697030.2 | AL5: 3756030.6 | AM5: 3813524.2 | AN5: 3869633
A8: 结果2：三次产业增加值平滑
B9: 2022 | C9: 2023 | D9: 2024 | E9: 2025 | F9: 2026 | G9: 2027 | H9: 2028 | I9: 2029 | J9: 2030 | K9: 2031 | L9: 2032 | M9: 2033 | N9: 2034 | O9: 2035 | P9: 2036 | Q9: 2037 | R9: 2038 | S9: 2039 | T9: 2040 | U9: 2041 | V9: 2042 | W9: 2043 | X9: 2044 | Y9: 2045 | Z9: 2046 | AA9: 2047 | AB9: 2048 | AC9: 2049 | AD9: 2050 | AE9: 2051 | AF9: 2052 | AG9: 2053 | AH9: 2054 | AI9: 2055 | AJ9: 2056 | AK9: 2057 | AL9: 2058 | AM9: 2059 | AN9: 2060
A10: 农业-高情景 | B10: 86574.037 | C10: 90508.221 | D10: 95121.373 | E10: 97776.796 | F10: 104107.17 | G10: 108437.05 | H10: 112631.95 | I10: 116674.18 | J10: 122578.78 | K10: 124238.97 | L10: 127735.73 | M10: 131028.36 | N10: 134109.3 | O10: 136130.79 | P10: 139616.67 | Q10: 142038.69 | R10: 144240.07 | S10: 146223.55 | T10: 147993.68 | U10: 149556.67 | V10: 150920.21 | W10: 152093.4 | X10: 153086.52 | Y10: 153910.94 | Z10: 154578.9 | AA10: 155103.45 | AB10: 155498.25 | AC10: 155777.47 | AD10: 155955.68 | AE10: 156047.73 | AF10: 156068.65 | AG10: 156033.62 | AH10: 155957.87 | AI10: 155856.62 | AJ10: 155745.09 | AK10: 155638.47 | AL10: 155551.89 | AM10: 155500.47 | AN10: 155514.93
A11: 工业-高情景 | B11: 375578.61 | C11: 391019.38 | D11: 407383.51 | E11: 420175.96 | F11: 438880.73 | G11: 453904.51 | H11: 468381.99 | I11: 482273.73 | J11: 498827.52 | K11: 508175.62 | L11: 520140.53 | M11: 531429.28 | N11: 542036.09 | O11: 550618.56 | P11: 561212.91 | Q11: 569802.65 | R11: 577749.25 | S11: 585076.24 | T11: 591811.95 | U11: 597989.06 | V11: 603644.2 | W11: 608817.51 | X11: 613552.33 | Y11: 617894.72 | Z11: 621893.2 | AA11: 625598.38 | AB11: 629062.74 | AC11: 632340.32 | AD11: 635486.6 | AE11: 638558.34 | AF11: 641613.45 | AG11: 644711 | AH11: 647911.19 | AI11: 651275.45 | AJ11: 654866.53 | AK11: 658748.73 | AL11: 662988.1 | AM11: 667652.79 | AN11: 672840.1
A12: 建筑业-高情景 | B12: 77971.749 | C12: 82009.725 | D12: 86241.13 | E12: 89848.948 | F12: 94546.138 | G12: 98583.718 | H12: 102522.33 | I12: 106346.75 | J12: 110661.39 | K12: 113599.22 | L12: 117004.3 | M12: 120249.42 | N12: 123327.35 | O12: 125971.77 | P12: 128961.55 | Q12: 131512.13 | R12: 133884.06 | S12: 136078.65 | T12: 138098.74 | U12: 139948.62 | V12: 141633.92 | W12: 143161.5 | X12: 144539.33 | Y12: 145776.42 | Z12: 146882.65 | AA12: 147868.7 | AB12: 148745.94 | AC12: 149526.32 | AD12: 150222.29 | AE12: 150846.74 | AF12: 151412.87 | AG12: 151934.21 | AH12: 152424.51 | AI12: 152897.75 | AJ12: 153368.07 | AK12: 153849.81 | AL12: 154357.48 | AM12: 154905.79 | AN12: 155514.93
A13: 服务业-高情景 | B13: 591543.44 | C13: 631348.33 | D13: 675016.11 | E13: 713506.35 | F13: 766425.28 | G13: 813975.58 | H13: 862613.15 | I13: 912219.59 | J13: 970415.31 | K13: 1013827.1 | L13: 1065555.4 | M13: 1117709.1 | N13: 1170139.4 | O13: 1219081.7 | P13: 1275221.2 | Q13: 1327564.2 | R13: 1379569.7 | S13: 1431084.5 | T13: 1481958.2 | U13: 1532043.7 | V13: 1581198.4 | W13: 1629285.1 | X13: 1676173 | Y13: 1721738 | Z13: 1765864.1 | AA13: 1808443.6 | AB13: 1849377.7 | AC13: 1888577.2 | AD13: 1925962.5 | AE13: 1961464 | AF13: 1995022.5 | AG13: 2026589 | AH13: 2056124.9 | AI13: 2083601.7 | AJ13: 2109001.2 | AK13: 2132314.9 | AL13: 2153543.9 | AM13: 2172698.7 | AN13: 2189904.1
A14: 农业-中情景 | B14: 86574.037 | C14: 90558.743 | D14: 95114.072 | E14: 98055.627 | F14: 104045.39 | G14: 108382.38 | H14: 112609.19 | I14: 116709 | J14: 122345.18 | K14: 124467.5 | L14: 128100.02 | M14: 131553.42 | N14: 134818.93 | O14: 137187.95 | P14: 140760.28 | Q14: 143427.62 | R14: 145890.02 | S14: 148147.59 | T14: 150202.06 | U14: 152056.7 | V14: 153716.22 | W14: 155186.66 | X14: 156475.27 | Y14: 157590.39 | Z14: 158541.34 | AA14: 159338.31 | AB14: 159992.21 | AC14: 160514.59 | AD14: 160917.5 | AE14: 161213.45 | AF14: 161415.24 | AG14: 161535.94 | AH14: 161588.79 | AI14: 161587.15 | AJ14: 161544.45 | AK14: 161474.12 | AL14: 161389.62 | AM14: 161304.37 | AN14: 161245.16
A15: 工业-中情景 | B15: 375578.61 | C15: 389833.57 | D15: 404800.97 | E15: 418061.49 | F15: 434712.7 | G15: 449593.83 | H15: 464383.15 | I15: 479049.53 | J15: 495328.07 | K15: 507891.57 | L15: 522007.98 | M15: 535883.28 | N15: 549490.2 | O15: 562061.06 | P15: 575795.89 | Q15: 588446.45 | R15: 600732.43 | S15: 612633.47 | T15: 624130.82 | U15: 635207.44 | V15: 645848.02 | W15: 656038.98 | X15: 665768.58 | Y15: 675026.84 | Z15: 683805.59 | AA15: 692098.45 | AB15: 699900.8 | AC15: 707209.79 | AD15: 714024.24 | AE15: 720344.65 | AF15: 726173.1 | AG15: 731513.24 | AH15: 736370.2 | AI15: 740750.52 | AJ15: 744662.06 | AK15: 748113.96 | AL15: 751116.54 | AM15: 753681.23 | AN15: 755836.68
A16: 建筑业-中情景 | B16: 77971.749 | C16: 82115.328 | D16: 86399.496 | E16: 90105.171 | F16: 94727.032 | G16: 98731.578 | H16: 102606.85 | I16: 106337.87 | J16: 110450.51 | K16: 113317.77 | L16: 116547.47 | M16: 119594.67 | N16: 122455.47 | O16: 124902.46 | P16: 127613.25 | Q16: 129913.23 | R16: 132032.6 | S16: 133977.65 | T16: 135756.34 | U16: 137378.14 | V16: 138853.93 | W16: 140195.76 | X16: 141416.79 | Y16: 142531.11 | Z16: 143553.63 | AA16: 144499.95 | AB16: 145386.27 | AC16: 146229.34 | AD16: 147046.36 | AE16: 147854.94 | AF16: 148673.11 | AG16: 149519.3 | AH16: 150412.35 | AI16: 151371.6 | AJ16: 152416.9 | AK16: 153568.77 | AL16: 154848.47 | AM16: 156278.2 | AN16: 157885.88
A17: 服务业-中情景 | B17: 591543.44 | C17: 632955.51 | D17: 677191.85 | E17: 718853.75 | F17: 769521.91 | G17: 817406.55 | H17: 866285.73 | I17: 916037.67 | J17: 971114.9 | K17: 1017648.6 | L17: 1069243.4 | M17: 1121184.8 | N17: 1173337.5 | O17: 1223429.8 | P17: 1277740.3 | Q17: 1329728.1 | R17: 1381405 | S17: 1432650.6 | T17: 1483350.7 | U17: 1533398.1 | V17: 1582692.9 | W17: 1631144 | X17: 1678668.9 | Y17: 1725194.5 | Z17: 1770657.5 | AA17: 1815004.7 | AB17: 1858192.9 | AC17: 1900189.6 | AD17: 1940972.3 | AE17: 1980529.1 | AF17: 2018858 | AG17: 2055967.3 | AH17: 2091874.8 | AI17: 2126607.9 | AJ17: 2160203.3 | AK17: 2192706.5 | AL17: 2224171.2 | AM17: 2254659.6 | AN17: 2284306.4
A18: 农业-低情景 | B18: 86574.037 | C18: 90517.822 | D18: 95040.61 | E18: 98055.627 | F18: 104025.52 | G18: 108455.52 | H18: 112823.22 | I18: 117113.91 | J18: 122928.33 | K18: 125409.47 | L18: 129389.3 | M18: 133242.26 | N18: 136958.57 | O18: 139845.32 | P18: 143948.44 | Q18: 147208.77 | R18: 150306.04 | S18: 153236.87 | T18: 155999.18 | U18: 158592.15 | V18: 161016.15 | W18: 163272.74 | X18: 165364.59 | Y18: 167295.41 | Z18: 169069.91 | AA18: 170693.7 | AB18: 172173.23 | AC18: 173515.71 | AD18: 174729.07 | AE18: 175821.81 | AF18: 176803.03 | AG18: 177682.27 | AH18: 178469.5 | AI18: 179175.06 | AJ18: 179809.59 | AK18: 180383.97 | AL18: 180909.32 | AM18: 181396.95 | AN18: 181872.75
A19: 工业-低情景 | B19: 375578.61 | C19: 388251.49 | D19: 401946.02 | E19: 414748.8 | F19: 430744.93 | G19: 445833.96 | H19: 461367.92 | I19: 477331.92 | J19: 495128.01 | K19: 510473.78 | L19: 527604.47 | M19: 545070.42 | N19: 562838.06 | O19: 580253.73 | P19: 599122.35 | Q19: 617549.65 | R19: 636099.74 | S19: 654716.23 | T19: 673338 | U19: 691899.2 | V19: 710329.43 | W19: 728553.79 | X19: 746493.17 | Y19: 764064.54 | Z19: 781181.22 | AA19: 797753.42 | AB19: 813688.62 | AC19: 828892.25 | AD19: 843268.26 | AE19: 856719.86 | AF19: 869150.33 | AG19: 880463.81 | AH19: 890566.28 | AI19: 899366.44 | AJ19: 906776.74 | AK19: 912714.41 | AL19: 917102.43 | AM19: 919870.66 | AN19: 920972.66
A20: 建筑业-低情景 | B20: 77971.749 | C20: 82138.959 | D20: 86500.47 | E20: 90105.171 | F20: 94950.216 | G20: 98999.445 | H20: 102909.15 | I20: 106665.5 | J20: 110976.97 | K20: 113675.61 | L20: 116914.74 | M20: 119971.23 | N20: 122844.36 | O20: 125234.62 | P20: 128049.89 | Q20: 130392.83 | R20: 132573.16 | S20: 134601.28 | T20: 136489.36 | U20: 138251.13 | V20: 139901.75 | W20: 141457.66 | X20: 142936.45 | Y20: 144356.72 | Z20: 145737.99 | AA20: 147100.65 | AB20: 148465.93 | AC20: 149855.83 | AD20: 151293.22 | AE20: 152801.82 | AF20: 154406.34 | AG20: 156132.6 | AH20: 158007.68 | AI20: 160060.15 | AJ20: 162320.35 | AK20: 164820.71 | AL20: 167596.1 | AM20: 170684.32 | AN20: 174133.49
A21: 服务业-低情景 | B21: 591543.44 | C21: 633921.84 | D21: 678896.02 | E21: 722166.44 | F21: 772932.8 | G21: 821809.1 | H21: 871790.89 | I21: 922773.29 | J21: 978304.66 | K21: 1027308.5 | L21: 1080643.2 | M21: 1134544.8 | N21: 1188907.3 | O21: 1241910 | P21: 1298608.5 | Q21: 1353756.1 | R21: 1408984.4 | S21: 1464214.4 | T21: 1519375 | U21: 1574404.4 | V21: 1629250 | W21: 1683869.5 | X21: 1738231.2 | Y21: 1792314.4 | Z21: 1846109.8 | AA21: 1899619.9 | AB21: 1952858.8 | AC21: 2005852.9 | AD21: 2058640.8 | AE21: 2111273.3 | AF21: 2163813.6 | AG21: 2216337.6 | AH21: 2268933.7 | AI21: 2321702.8 | AJ21: 2374758.9 | AK21: 2428229.1 | AL21: 2482253.6 | AM21: 2536986.5 | AN21: 2592654.1
A24: 结果3：大类产业增加值平滑 | B24: =SUM(B26:B31) -> 375578.61 | C24: =SUM(C26:C31) -> 382373.73 | D24: =SUM(D26:D31) -> 399129.66 | E24: =SUM(E26:E31) -> 420175.96 | F24: =SUM(F26:F31) -> 440023.25 | G24: =SUM(G26:G31) -> 457539.47 | H24: =SUM(H26:H31) -> 472933.8 | I24: =SUM(I26:I31) -> 486546.44 | ... AN24: =SUM(AN26:AN31) -> 672840.1
B25: 2022 | C25: 2023 | D25: 2024 | E25: 2025 | F25: 2026 | G25: 2027 | H25: 2028 | I25: 2029 | J25: 2030 | K25: 2031 | L25: 2032 | M25: 2033 | N25: 2034 | O25: 2035 | P25: 2036 | Q25: 2037 | R25: 2038 | S25: 2039 | T25: 2040 | U25: 2041 | V25: 2042 | W25: 2043 | X25: 2044 | Y25: 2045 | Z25: 2046 | AA25: 2047 | AB25: 2048 | AC25: 2049 | AD25: 2050 | AE25: 2051 | AF25: 2052 | AG25: 2053 | AH25: 2054 | AI25: 2055 | AJ25: 2056 | AK25: 2057 | AL25: 2058 | AM25: 2059 | AN25: 2060
A26: 能源产业-高情景 | B26: 40294.225 | C26: 40875.213 | D26: 42308.521 | E26: 44118.476 | F26: 45860.65 | G26: 47424.311 | H26: 48791.594 | I26: 49947.549 | J26: 50880.407 | K26: 51588.335 | L26: 52099.723 | M26: 52453.685 | N26: 52692.28 | O26: 52859.382 | P26: 52992.575 | Q26: 53100.635 | R26: 53185.112 | S26: 53247.6 | T26: 53289.733 | U26: 53313.17 | V26: 53319.597 | W26: 53310.718 | X26: 53288.249 | Y26: 53253.917 | Z26: 53209.45 | AA26: 53156.578 | AB26: 53097.03 | AC26: 53032.529 | AD26: 52964.793 | AE26: 52895.53 | AF26: 52826.44 | AG26: 52759.216 | AH26: 52695.541 | AI26: 52637.089 | AJ26: 52585.532 | AK26: 52542.533 | AL26: 52509.755 | AM26: 52488.864 | AN26: 52481.528
A27: 电力与热力产业-高情景 | B27: 17470.728 | C27: 18018.849 | D27: 19361.585 | E27: 21008.798 | F27: 22450.271 | G27: 23614.332 | H27: 24586.803 | I27: 25482.345 | J27: 26437.858 | K27: 27577.617 | L27: 28903.23 | M27: 30378.495 | N27: 31958.57 | O27: 33587.732 | P27: 35209.589 | Q27: 36805.906 | R27: 38369.253 | S27: 39892.52 | T27: 41368.988 | U27: 42792.399 | V27: 44157.013 | W27: 45457.66 | X27: 46689.776 | Y27: 47849.439 | Z27: 48933.386 | AA27: 49939.024 | AB27: 50864.431 | AC27: 51708.355 | AD27: 52470.189 | AE27: 53149.96 | AF27: 53748.29 | AG27: 54266.371 | AH27: 54705.921 | AI27: 55069.142 | AJ27: 55358.68 | AK27: 55577.575 | AL27: 55729.214 | AM27: 55817.284 | AN27: 55845.729
A28: 传统高耗能产业-高情景 | B28: 101803.01 | C28: 103460.68 | D28: 107528.74 | E28: 112607.16 | F28: 117362.28 | G28: 121429.9 | H28: 124721.66 | I28: 127163.31 | J28: 128697.5 | K28: 129323.29 | L28: 129209.24 | M28: 128575.43 | N28: 127646.01 | O28: 126642.27 | P28: 125742.59 | Q28: 124973.96 | R28: 124326.55 | S28: 123791.08 | T28: 123358.71 | U28: 123020.97 | V28: 122769.7 | W28: 122597 | X28: 122495.17 | Y28: 122456.65 | Z28: 122474.03 | AA28: 122539.95 | AB28: 122647.11 | AC28: 122788.23 | AD28: 122956.03 | AE28: 123143.21 | AF28: 123342.44 | AG28: 123546.32 | AH28: 123747.46 | AI28: 123938.36 | AJ28: 124111.52 | AK28: 124259.38 | AL28: 124374.37 | AM28: 124448.9 | AN28: 124475.42
A29: 装备制造业-高情景 | B29: 101531.7 | C29: 103538.17 | D29: 108486.42 | E29: 114708.04 | F29: 120596.27 | G29: 125838.79 | H29: 130516.48 | I29: 134745.96 | J29: 138674.05 | K29: 142442.51 | L29: 146086.77 | M29: 149615.77 | N29: 153040.84 | O29: 156375.67 | P29: 159632.13 | Q29: 162807.47 | R29: 165895.25 | S29: 168889.2 | T29: 171783.26 | U29: 174571.56 | V29: 177248.5 | W29: 179808.72 | X29: 182247.16 | Y29: 184559.03 | Z29: 186739.88 | AA29: 188785.55 | AB29: 190692.26 | AC29: 192456.55 | AD29: 194075.34 | AE29: 195545.92 | AF29: 196865.95 | AG29: 198033.46 | AH29: 199046.88 | AI29: 199905.03 | AJ29: 200607.11 | AK29: 201152.69 | AL29: 201541.75 | AM29: 201774.63 | AN29: 201852.03
A30: 高技术产业-高情景 | B30: 54801.587 | C30: 56208.386 | D30: 59646.202 | E30: 63866.746 | F30: 67624.977 | G30: 70743.022 | H30: 73400.909 | I30: 75832.932 | J30: 78315.92 | K30: 81099.898 | L30: 84195.904 | M30: 87544.612 | N30: 91075.816 | O30: 94706.393 | P30: 98355.142 | Q30: 101995.65 | R30: 105616.06 | S30: 109204.06 | T30: 112747 | U30: 116231.93 | V30: 119645.68 | W30: 122974.92 | X30: 126206.25 | Y30: 129326.31 | Z30: 132321.81 | AA30: 135179.66 | AB30: 137887.06 | AC30: 140431.58 | AD30: 142801.24 | AE30: 144984.65 | AF30: 146971.01 | AG30: 148750.31 | AH30: 150313.32 | AI30: 151651.7 | AJ30: 152758.07 | AK30: 153626.1 | AL30: 154250.52 | AM30: 154627.21 | AN30: 154753.22
A31: 其他产业-高情景 | B31: 59677.346 | C31: 60272.433 | D31: 61798.194 | E31: 63866.746 | F31: 66128.8 | G31: 68489.109 | H31: 70916.35 | I31: 73374.34 | J31: 75821.783 | K31: 78214.633 | L31: 80514.077 | M31: 82680.723 | N31: 84672.856 | O31: 86447.115 | P31: 87967.201 | Q31: 89229.344 | R31: 90240.757 | S31: 91011.718 | T31: 91555.175 | U31: 91886.334 | V31: 92022.251 | W31: 91981.421 | X31: 91783.406 | Y31: 91448.474 | Z31: 90997.286 | AA31: 90450.62 | AB31: 89829.139 | AC31: 89153.203 | AD31: 88442.73 | AE31: 87717.097 | AF31: 86995.087 | AG31: 86294.879 | AH31: 85634.07 | AI31: 85029.741 | AJ31: 84498.556 | AK31: 84056.892 | AL31: 83721.002 | AM31: 83507.217 | AN31: 83432.173
A32: 交通运输业-高情景 | B32: 46450.003 | C32: 47824.422 | D32: 51257.762 | E32: 55653.495 | F32: 59863.721 | G32: 63627.288 | H32: 66979.226 | I32: 69994.26 | J32: 72781.148 | K32: 75451.913 | L32: 78034.336 | M32: 80535.386 | N32: 82964.949 | O32: 85335.718 | P32: 87659.192 | Q32: 89933.1 | R32: 92151.62 | S32: 94309.08 | T32: 96399.988 | U32: 98419.057 | V32: 100361.23 | W32: 102221.72 | X32: 103995.98 | Y32: 105679.79 | Z32: 107269.23 | AA32: 108760.7 | AB32: 110150.97 | AC32: 111437.13 | AD32: 112616.65 | AE32: 113687.37 | AF32: 114647.48 | AG32: 115495.58 | AH32: 116230.63 | AI32: 116851.95 | AJ32: 117359.24 | AK32: 117752.59 | AL32: 118032.4 | AM32: 118199.44 | AN32: 118254.82
A33: 传统服务业-高情景 | B33: 123782.33 | C33: 127089.58 | D33: 135416.26 | E33: 146268.8 | F33: 157090.23 | G33: 167264.7 | H33: 176784.54 | I33: 185693.34 | J33: 194083.06 | K33: 202070.92 | L33: 209731.73 | M33: 217143.21 | N33: 224402.55 | O33: 231625.52 | P33: 238918.36 | Q33: 246288.15 | R33: 253714.06 | S33: 261173.24 | T33: 268640.89 | U33: 276090.18 | V33: 283492.35 | W33: 290816.74 | X33: 298030.89 | Y33: 305100.63 | Z33: 311990.23 | AA33: 318662.61 | AB33: 325079.48 | AC33: 331201.65 | AD33: 336989.24 | AE33: 342402.02 | AF33: 347399.73 | AG33: 351942.45 | AH33: 355990.96 | AI33: 359507.18 | AJ33: 362454.57 | AK33: 364798.57 | AL33: 366507.07 | AM33: 367550.82 | AN33: 367903.89
A34: 现代服务业-高情景 | B34: 421311.1 | C34: 434592 | D34: 468055.13 | E34: 511584.05 | F34: 554442.46 | G34: 594314.73 | H34: 631749.1 | I34: 667710.93 | J34: 703551.1 | K34: 740641.84 | L34: 779195.77 | M34: 819078.49 | N34: 860121.66 | O34: 902120.45 | P34: 944856.38 | Q34: 988180.01 | R34: 1031951.3 | S34: 1076016.9 | T34: 1120210.3 | U34: 1164352.7 | V34: 1208253.1 | W34: 1251709.4 | X34: 1294509.4 | Y34: 1336432.1 | Z34: 1377248.9 | AA34: 1416725.5 | AB34: 1454623.6 | AC34: 1490702.5 | AD34: 1524722.2 | AE34: 1556444.6 | AF34: 1585636.8 | AG34: 1612073.2 | AH34: 1635538 | AI34: 1655828.1 | AJ34: 1672755.4 | AK34: 1686149.6 | AL34: 1695860.5 | AM34: 1701760.2 | AN34: 1703745.4
A35: 能源产业-中情景 | B35: 40294.225 | C35: 40776.227 | D35: 41967.337 | E35: 43478.395 | F35: 44951.49 | G35: 46292.09 | H35: 47476.473 | I35: 48481.485 | J35: 49285.143 | K35: 49876.722 | L35: 50286.321 | M35: 50557.139 | N35: 50734.848 | O35: 50866.526 | P35: 50991.884 | Q35: 51118.497 | R35: 51245.853 | S35: 51373.436 | T35: 51500.725 | U35: 51627.193 | V35: 51752.308 | W35: 51875.535 | X35: 51996.331 | Y35: 52114.151 | Z35: 52228.443 | AA35: 52338.654 | AB35: 52444.227 | AC35: 52544.599 | AD35: 52639.207 | AE35: 52727.485 | AF35: 52808.867 | AG35: 52882.784 | AH35: 52948.669 | AI35: 53005.954 | AJ35: 53054.075 | AK35: 53092.468 | AL35: 53120.575 | AM35: 53137.84 | AN35: 53143.717
A36: 电力与热力产业-中情景 | B36: 17470.728 | C36: 18003.918 | D36: 19307.854 | E36: 20903.075 | F36: 22295.121 | G36: 23421.315 | H36: 24372.986 | I36: 25269.491 | J36: 26252.388 | K36: 27450.577 | L36: 28866.649 | M36: 30464.002 | N36: 32196.351 | O36: 34004.694 | P36: 35828.073 | Q36: 37646.605 | R36: 39451.887 | S36: 41235.49 | T36: 42989.042 | U36: 44704.313 | V36: 46373.295 | W36: 47988.278 | X36: 49541.925 | Y36: 51027.338 | Z36: 52438.116 | AA36: 53768.412 | AB36: 55012.972 | AC36: 56167.177 | AD36: 57227.068 | AE36: 58189.365 | AF36: 59051.479 | AG36: 59811.515 | AH36: 60468.265 | AI36: 61021.195 | AJ36: 61470.425 | AK36: 61816.706 | AL36: 62061.382 | AM36: 62206.361 | AN36: 62254.068
A37: 传统高耗能产业-中情景 | B37: 101803.01 | C37: 103050.14 | D37: 106112.52 | E37: 109950.17 | F37: 113604.52 | G37: 116825.17 | H37: 119554.81 | I37: 121740.79 | J37: 123336.69 | K37: 124328.42 | L37: 124810.21 | M37: 124910.02 | N37: 124760.67 | O37: 124496.52 | P37: 124229.21 | Q37: 123980.41 | R37: 123749.41 | S37: 123535.51 | T37: 123338.04 | U37: 123156.32 | V37: 122989.68 | W37: 122837.46 | X37: 122699.03 | Y37: 122573.72 | Z37: 122460.93 | AA37: 122360.01 | AB37: 122270.34 | AC37: 122191.31 | AD37: 122122.3 | AE37: 122062.7 | AF37: 122011.92 | AG37: 121969.34 | AH37: 121934.37 | AI37: 121906.41 | AJ37: 121884.87 | AK37: 121869.14 | AL37: 121858.64 | AM37: 121852.77 | AN37: 121850.95
... A52: 现代服务业-低情景 | B52: 421311.1 | C52: 436150.16 | D52: 473413.5 | E52: 521404.17 | F52: 567347.13 | G52: 608539.4 | H52: 645910.62 | I52: 681049.15 | J52: 716119.01 | K52: 753299.22 | L52: 793023.41 | M52: 835213.89 | N52: 879750.81 | O52: 926464.84 | P52: 975163.85 | Q52: 1025741.3 | R52: 1078094.8 | S52: 1132093.1 | T52: 1187574 | U52: 1244342.2 | V52: 1302167.5 | W52: 1360783.3 | X52: 1419885.9 | Y52: 1479134.1 | Z52: 1538149.3 | AA52: 1596517 | AB52: 1653788.5 | AC52: 1709483.9 | AD52: 1763095.8 | AE52: 1814094.6 | AF52: 1861934.2 | AG52: 1906059 | AH52: 1945912.1 | AI52: 1980944.1 | AJ52: 2010622.8 | AK52: 2034443.4 | AL52: 2051939.3 | AM52: 2062692.6 | AN52: 2066345.4
A55: 结果4-1：高情景细分产业增加值平滑
B56: 2022 | C56: 2023 | D56: 2024 | E56: 2025 | F56: 2026 | G56: 2027 | H56: 2028 | I56: 2029 | J56: 2030 | K56: 2031 | L56: 2032 | M56: 2033 | N56: 2034 | O56: 2035 | P56: 2036 | Q56: 2037 | R56: 2038 | S56: 2039 | T56: 2040 | U56: 2041 | V56: 2042 | W56: 2043 | X56: 2044 | Y56: 2045 | Z56: 2046 | AA56: 2047 | AB56: 2048 | AC56: 2049 | AD56: 2050 | AE56: 2051 | AF56: 2052 | AG56: 2053 | AH56: 2054 | AI56: 2055 | AJ56: 2056 | AK56: 2057 | AL56: 2058 | AM56: 2059 | AN56: 2060
A57: 煤炭开采和洗选业 | B57: 18002.061 | C57: 18269.324 | D57: 18926.657 | E57: 19751.617 | F57: 20536.505 | G57: 21233.916 | H57: 21841.856 | I57: 22360.478 | J57: 22791.924 | K57: 23139.662 | L57: 23406.86 | M57: 23597.446 | N57: 23716.363 | O57: 23769.386 | P57: 23762.578 | Q57: 23701.031 | R57: 23589.824 | S57: 23434.283 | T57: 23239.878 | U57: 23012.138 | V57: 22756.566 | W57: 22478.579 | X57: 22183.449 | Y57: 21876.259 | Z57: 21561.877 | AA57: 21244.929 | AB57: 20929.794 | AC57: 20620.599 | AD57: 20321.228 | AE57: 20035.34 | AF57: 19766.386 | AG57: 19517.642 | AH57: 19292.24 | AI57: 19093.207 | AJ57: 18923.514 | AK57: 18786.118 | AL57: 18684.024 | AM57: 18620.338 | AN57: 18598.342
A58: 石油和天然气开采业 | B58: 12304.163 | C58: 12408.764 | D58: 12665.018 | E58: 12985.418 | F58: 13291.709 | G58: 13564.451 | H58: 13799.775 | I58: 13994.002 | J58: 14143.725 | K58: 14246.941 | L58: 14306.335 | M58: 14326.143 | N58: 14310.984 | O58: 14265.737 | P58: 14195.008 | Q58: 14101.786 | R58: 13988.688 | S58: 13858.351 | T58: 13713.401 | U58: 13556.424 | V58: 13389.947 | W58: 13216.413 | X58: 13038.172 | Y58: 12857.471 | Z58: 12676.444 | AA58: 12497.114 | AB58: 12321.39 | AC58: 12151.077 | AD58: 11987.875 | AE58: 11833.395 | AF58: 11689.167 | AG58: 11556.655 | AH58: 11437.273 | AI58: 11332.399 | AJ58: 11243.399 | AK58: 11171.645 | AL58: 11118.538 | AM58: 11085.535 | AN58: 11074.174
A59: 石油、煤炭及其他燃料加工业 | B59: 6224.4128 | C59: 6283.2968 | D59: 6423.7162 | E59: 6590.0931 | F59: 6733.0606 | G59: 6843.9775 | H59: 6925.5061 | I59: 6980.928 | J59: 7013.9926 | K59: 7028.1623 | L59: 7024.6467 | M59: 7004.1805 | N59: 6967.6163 | O59: 6915.906 | P59: 6850.1916 | Q59: 6772.1024 | R59: 6683.3897 | S59: 6585.789 | T59: 6480.9981 | U59: 6370.6586 | V59: 6256.341 | W59: 6139.5342 | X59: 6021.6385 | Y59: 5903.9607 | Z59: 5787.714 | AA59: 5674.019 | AB59: 5563.9078 | AC59: 5458.3298 | AD59: 5358.1593 | AE59: 5264.2046 | AF59: 5177.2186 | AG59: 5097.9096 | AH59: 5026.9543 | AI59: 4965.0111 | AJ59: 4912.7344 | AK59: 4870.79 | AL59: 4839.8722 | AM59: 4820.7214 | AN59: 4814.1445
A60: 燃气生产和供应业 | B60: 2464.9908 | C60: 2577.3639 | D60: 2865.236 | E60: 3248.062 | F60: 3628.719 | G60: 3981.5904 | H60: 4308.9749 | I60: 4618.9727 | J60: 4925.0517 | K60: 5242.0202 | L60: 5573.0379 | M60: 5917.8265 | N60: 6275.9706 | O60: 6646.9061 | P60: 7029.904 | Q60: 7424.0444 | R60: 7828.2176 | S60: 8241.1194 | T60: 8661.2456 | U60: 9086.8878 | V60: 9516.1324 | W60: 9946.8628 | X60: 10376.764 | Y60: 10803.333 | Z60: 11223.891 | AA60: 11635.601 | AB60: 12035.487 | AC60: 12420.466 | AD60: 12787.373 | AE60: 13132.994 | AF60: 13454.113 | AG60: 13747.542 | AH60: 14010.176 | AI60: 14239.032 | AJ60: 14431.304 | AK60: 14584.405 | AL60: 14696.02 | AM60: 14764.151 | AN60: 14787.159
...

Sheet 高情景（2001-2060, 2020RMB）
A1: 全国 | B1: 2001 | C1: 2002 | D1: 2003 | E1: 2004 | F1: 2005 | G1: 2006 | H1: 2007 | I1: 2008 | J1: 2009 | K1: 2010 | L1: 2011 | M1: 2012 | N1: 2013 | O1: 2014 | P1: 2015 | Q1: 2016 | R1: 2017 | S1: 2018 | T1: 2019 | U1: 2020 | V1: 2021 | W1: 2022 | X1: 2023 | Y1: 2024 | Z1: 2025 | AA1: 2026 | AB1: 2027 | AC1: 2028 | AD1: 2029 | AE1: 2030 | AF1: 2031 | AG1: 2032 | AH1: 2033 | AI1: 2034 | AJ1: 2035 | AK1: 2036 | AL1: 2037 | AM1: 2038 | AN1: 2039 | AO1: 2040 | AP1: 2041 | AQ1: 2042 | AR1: 2043 | AS1: 2044 | AT1: 2045 | AU1: 2046 | AV1: 2047 | AW1: 2048 | AX1: 2049 | AY1: 2050 | AZ1: 2051 | BA1: 2052 | BB1: 2053 | BC1: 2054 | BD1: 2055 | BE1: 2056 | BF1: 2057 | BG1: 2058 | BH1: 2059 | BI1: 2060
A2: 地区生产总值 | B2: ='历史数据 (2001-2022, 当年价) '!B2*B$77 -> 208489.63 | C2: ='历史数据 (2001-2022, 当年价) '!C2*C$77 -> 227462.19 | D2: ='历史数据 (2001-2022, 当年价) '!D2*D$77 -> 250208.41 | E2: ='历史数据 (2001-2022, 当年价) '!E2*E$77 -> 275479.46 | F2: ='历史数据 (2001-2022, 当年价) '!F2*F$77 -> 306884.11 | G2: ='历史数据 (2001-2022, 当年价) '!G2*G$77 -> 345858.4 | H2: ='历史数据 (2001-2022, 当年价) '!H2*H$77 -> 394970.29 | I2: ='历史数据 (2001-2022, 当年价) '!I2*I$77 -> 433282.41 | ... W2: ='历史数据 (2001-2022, 当年价) '!W2*W$77 -> 1131667.8 | X2: =情景假设!E9 -> 1164334.3 | Y2: =情景假设!F9 -> 1235105.3 | Z2: =情景假设!G9 -> 1321308.1 | AA2: =情景假设!H9 -> 1410244.4 | AB2: =情景假设!I9 -> 1490036.1 | AC2: =情景假设!J9 -> 1563852.7 | AD2: =情景假设!K9 -> 1633103.3 | AE2: =情景假设!L9 -> 1702483 | ... BI2: =情景假设!AP9 -> 3173774.1
A3: 农业 | B3: ='历史数据 (2001-2022, 当年价) '!B3*B$77 -> 29675.937 | C3: ='历史数据 (2001-2022, 当年价) '!C3*C$77 -> 30901.469 | D3: ='历史数据 (2001-2022, 当年价) '!D3*D$77 -> 31645.386 | E3: ='历史数据 (2001-2022, 当年价) '!E3*E$77 -> 36444.641 | F3: ='历史数据 (2001-2022, 当年价) '!F3*F$77 -> 36724.408 | G3: ='历史数据 (2001-2022, 当年价) '!G3*G$77 -> 37883.921 | H3: ='历史数据 (2001-2022, 当年价) '!H3*H$77 -> 41653.225 | I3: ='历史数据 (2001-2022, 当年价) '!I3*I$77 -> 45368.998 | ... W3: ='历史数据 (2001-2022, 当年价) '!W3*W$77 -> 86574.037 | X3: =情景假设!E24 -> 90508.221 | Y3: =情景假设!F24 -> 95121.373 | Z3: =情景假设!G24 -> 97776.796 | AA3: =情景假设!H24 -> 104107.17 | AB3: =情景假设!I24 -> 108437.05 | AC3: =情景假设!J24 -> 112631.95 | AD3: =情景假设!K24 -> 116674.18 | AE3: =情景假设!L24 -> 122578.78 | ... BI3: =情景假设!AP24 -> 155514.93
A4: 工业 | B4: ='历史数据 (2001-2022, 当年价) '!B4*B$77 -> 82472.589 | C4: ='历史数据 (2001-2022, 当年价) '!C4*C$77 -> 89280.442 | D4: ='历史数据 (2001-2022, 当年价) '!D4*D$77 -> 100799.64 | E4: ='历史数据 (2001-2022, 当年价) '!E4*E$77 -> 111960.03 | F4: ='历史数据 (2001-2022, 当年价) '!F4*F$77 -> 127718.9 | G4: ='历史数据 (2001-2022, 当年价) '!G4*G$77 -> 145373.42 | H4: ='历史数据 (2001-2022, 当年价) '!H4*H$77 -> 163331.38 | I4: ='历史数据 (2001-2022, 当年价) '!I4*I$77 -> 178777.31 | ... W4: ='历史数据 (2001-2022, 当年价) '!W4*W$77 -> 375578.61 | X4: =情景假设!E25 -> 382345.32 | Y4: =情景假设!F25 -> 399078.83 | Z4: =情景假设!G25 -> 420175.96 | AA4: =情景假设!H25 -> 440090.76 | AB4: =情景假设!I25 -> 457638.82 | AC4: =情景假设!J25 -> 473019.34 | AD4: =情景假设!K25 -> 486587.17 | AE4: =情景假设!L25 -> 498827.52 | ... BI4: =情景假设!AP25 -> 672840.1
A5: 建筑业 | B5: ='历史数据 (2001-2022, 当年价) '!B5*B$77 -> 11181.133 | C5: ='历史数据 (2001-2022, 当年价) '!C5*C$77 -> 12113.573 | D5: ='历史数据 (2001-2022, 当年价) '!D5*D$77 -> 13675.142 | E5: ='历史数据 (2001-2022, 当年价) '!E5*E$77 -> 14843.769 | F5: ='历史数据 (2001-2022, 当年价) '!F5*F$77 -> 17039.115 | G5: ='历史数据 (2001-2022, 当年价) '!G5*G$77 -> 19622.681 | H5: ='历史数据 (2001-2022, 当年价) '!H5*H$77 -> 22444.194 | I5: ='历史数据 (2001-2022, 当年价) '!I5*I$77 -> 25525.889 | ... W5: ='历史数据 (2001-2022, 当年价) '!W5*W$77 -> 77971.749 | X5: =情景假设!E26 -> 82009.725 | Y5: =情景假设!F26 -> 86241.13 | Z5: =情景假设!G26 -> 89848.948 | AA5: =情景假设!H26 -> 94546.138 | AB5: =情景假设!I26 -> 98583.718 | AC5: =情景假设!J26 -> 102522.33 | AD5: =情景假设!K26 -> 106346.75 | AE5: =情景假设!L26 -> 110661.39 | ... BI5: =情景假设!AP26 -> 155514.93
A6: 交运仓邮 | B6: ='历史数据 (2001-2022, 当年价) '!B6*B$77 -> 12922.197 | C6: ='历史数据 (2001-2022, 当年价) '!C6*C$77 -> 14005.145 | D6: ='历史数据 (2001-2022, 当年价) '!D6*D$77 -> 14410.717 | E6: ='历史数据 (2001-2022, 当年价) '!E6*E$77 -> 15841.241 | F6: ='历史数据 (2001-2022, 当年价) '!F6*F$77 -> 17478.67 | G6: ='历史数据 (2001-2022, 当年价) '!G6*G$77 -> 19206.904 | H6: ='历史数据 (2001-2022, 当年价) '!H6*H$77 -> 21357.812 | I6: ='历史数据 (2001-2022, 当年价) '!I6*I$77 -> 22214.293 | ... W6: ='历史数据 (2001-2022, 当年价) '!W6*W$77 -> 46450.003 | X6: =X57 -> 47824.422 | Y6: =Y57 -> 51257.762 | Z6: =Z57 -> 55653.495 | AA6: =AA57 -> 59863.721 | AB6: =AB57 -> 63627.288 | AC6: =AC57 -> 66979.226 | AD6: =AD57 -> 69994.26 | AE6: =AE57 -> 72781.148 | ... BI6: =BI57 -> 118254.82
A7: 批发零售 | B7: ='历史数据 (2001-2022, 当年价) '!B7*B$77 -> 17152.616 | C7: ='历史数据 (2001-2022, 当年价) '!C7*C$77 -> 18681.75 | D7: ='历史数据 (2001-2022, 当年价) '!D7*D$77 -> 20339.743 | E7: ='历史数据 (2001-2022, 当年价) '!E7*E$77 -> 21201.883 | F7: ='历史数据 (2001-2022, 当年价) '!F7*F$77 -> 22884.561 | G7: ='历史数据 (2001-2022, 当年价) '!G7*G$77 -> 26058.396 | H7: ='历史数据 (2001-2022, 当年价) '!H7*H$77 -> 30623.281 | I7: ='历史数据 (2001-2022, 当年价) '!I7*I$77 -> 35540.209 | ... W7: ='历史数据 (2001-2022, 当年价) '!W7*W$77 -> 107085.79 | X7: =X58 -> 110102.83 | Y7: =Y58 -> 117708.35 | Z7: =Z58 -> 127635.48 | AA7: =AA58 -> 137531.7 | AB7: =AB58 -> 146827.65 | AC7: =AC58 -> 155521.9 | AD7: =AD58 -> 163666.18 | AE7: =AE58 -> 171362.19 | ... BI7: =BI58 -> 338661.06
A8: 餐饮住宿 | B8: ='历史数据 (2001-2022, 当年价) '!B8*B$77 -> 4513.6386 | C8: ='历史数据 (2001-2022, 当年价) '!C8*C$77 -> 5092.0326 | D8: ='历史数据 (2001-2022, 当年价) '!D8*D$77 -> 5691.7852 | E8: ='历史数据 (2001-2022, 当年价) '!E8*E$77 -> 6238.1109 | F8: ='历史数据 (2001-2022, 当年价) '!F8*F$77 -> 6873.8055 | G8: ='历史数据 (2001-2022, 当年价) '!G8*G$77 -> 7553.6469 | H8: ='历史数据 (2001-2022, 当年价) '!H8*H$77 -> 8113.2808 | I8: ='历史数据 (2001-2022, 当年价) '!I8*I$77 -> 8979.4463 | ... W8: ='历史数据 (2001-2022, 当年价) '!W8*W$77 -> 16696.536 | X8: =X59 -> 16983.911 | Y8: =Y59 -> 17702.761 | Z8: =Z59 -> 18633.324 | AA8: =AA59 -> 19566.185 | AB8: =AB59 -> 20449.126 | AC8: =AC59 -> 21273.988 | AD8: =AD59 -> 22033.392 | AE8: =AE59 -> 22720.866 | ... BI8: =BI59 -> 29242.832
A9: 金融业 | B9: ='历史数据 (2001-2022, 当年价) '!B9*B$77 -> 9784.4085 | C9: ='历史数据 (2001-2022, 当年价) '!C9*C$77 -> 10382.529 | D9: ='历史数据 (2001-2022, 当年价) '!D9*D$77 -> 11007.59 | E9: ='历史数据 (2001-2022, 当年价) '!E9*E$77 -> 11234.659 | F9: ='历史数据 (2001-2022, 当年价) '!F9*F$77 -> 12264.296 | G9: ='历史数据 (2001-2022, 当年价) '!G9*G$77 -> 15717.405 | H9: ='历史数据 (2001-2022, 当年价) '!H9*H$77 -> 22227.766 | I9: ='历史数据 (2001-2022, 当年价) '!I9*I$77 -> 24898.857 | ... W9: ='历史数据 (2001-2022, 当年价) '!W9*W$77 -> 90528.212 | X9: =X60 -> 93078.581 | Y9: =Y60 -> 99473.509 | Z9: =Z60 -> 107732.66 | AA9: =AA60 -> 115813.47 | AB9: =AB60 -> 123290.27 | AC9: =AC60 -> 130269.26 | AD9: =AD60 -> 136925.35 | AE9: =AE60 -> 143496.06 | ... BI9: =BI60 -> 302746.35
A10: 房地产 | B10: ='历史数据 (2001-2022, 当年价) '!B10*B$77 -> 8849.7481 | C10: ='历史数据 (2001-2022, 当年价) '!C10*C$77 -> 9968.9695 | D10: ='历史数据 (2001-2022, 当年价) '!D10*D$77 -> 11210.237 | E10: ='历史数据 (2001-2022, 当年价) '!E10*E$77 -> 12174.087 | F10: ='历史数据 (2001-2022, 当年价) '!F10*F$77 -> 13897.188 | G10: ='历史数据 (2001-2022, 当年价) '!G10*G$77 -> 16266.835 | H10: ='历史数据 (2001-2022, 当年价) '!H10*H$77 -> 20054.709 | I10: ='历史数据 (2001-2022, 当年价) '!I10*I$77 -> 19815.693 | ... W10: ='历史数据 (2001-2022, 当年价) '!W10*W$77 -> 69030.485 | X10: =X61 -> 70637.504 | Y10: =Y61 -> 74645.659 | Z10: =Z61 -> 79786.151 | AA10: =AA61 -> 84802.387 | AB10: =AB61 -> 89443.716 | AC10: =AC61 -> 93773.751 | AD10: =AD61 -> 97888.337 | AE10: =AE61 -> 101912.47 | ... BI10: =BI61 -> 186689.22
A11: 其他三产 | B11: ='历史数据 (2001-2022, 当年价) '!B11*B$77 -> 31937.552 | C11: ='历史数据 (2001-2022, 当年价) '!C11*C$77 -> 37036.464 | D11: ='历史数据 (2001-2022, 当年价) '!D11*D$77 -> 41428.534 | E11: ='历史数据 (2001-2022, 当年价) '!E11*E$77 -> 45540.865 | F11: ='历史数据 (2001-2022, 当年价) '!F11*F$77 -> 52003.008 | G11: ='历史数据 (2001-2022, 当年价) '!G11*G$77 -> 58175.344 | H11: ='历史数据 (2001-2022, 当年价) '!H11*H$77 -> 65164.644 | I11: ='历史数据 (2001-2022, 当年价) '!I11*I$77 -> 72161.98 | ... W11: ='历史数据 (2001-2022, 当年价) '!W11*W$77 -> 261752.41 | X11: =SUM(X62:X70) -> 270843.75 | Y11: =SUM(Y62:Y70) -> 293875.96 | Z11: =SUM(Z62:Z70) -> 324065.25 | AA11: =SUM(AA62:AA70) -> 353922.86 | AB11: =SUM(AB62:AB70) -> 381738.47 | AC11: =SUM(AC62:AC70) -> 407860.92 | AD11: =SUM(AD62:AD70) -> 432987.71 | AE11: =SUM(AE62:AE70) -> 458142.56 | ... BI11: =SUM(BI62:BI70) -> 1214309.8
A13: 工业 | B13: =B4 -> 82472.589 | C13: =C4 -> 89280.442 | D13: =D4 -> 100799.64 | E13: =E4 -> 111960.03 | F13: =F4 -> 127718.9 | G13: =G4 -> 145373.42 | H13: =H4 -> 163331.38 | I13: =I4 -> 178777.31 | ... BI13: =BI4 -> 672840.1
