Workbook

Sheet 地热2020年累计“十三五新增”
A1: 各类地热能利用技术特点， 有序开展地热能发电、供暖以及 多种形式的综合利用。 (三)发展目标 在“十三五”时期，新增地热能供暖(制冷)面积 11 亿平方米， 其中： 新增浅层地热能供暖(制冷) 面积 7 亿平 方米； 新增水热型地热供暖面积 4 亿平方米。新增地热发电 装机容量 500MW。到 2020 年， 地热供暖(制冷) 面积累计 达到 16 亿平方米，地热发电装机容量约 530MW。2020 年 地热能年利用量 7000 万吨标准煤，地热能供暖年利用量 4000 万吨标准煤。京津冀地区地热能年利用量达到约 2000 万吨标准煤。 表 3 我国地热能开发目标
B3: “十三五”新增 | E3: 2020 年累计
B4: 浅层地热能 供暖/制冷 面积 (104m2 ) | C4: 水热型地热 能供暖面积 (104m2) | D4: 发电装 机容量 (MW) | E4: 浅层地热能 供暖/制冷 面积 (104m2 ) | F4: 水热型地热 能供暖面积 (104m2) | G4: 发电装 机容量 (MW)
A5: 北京 | B5: 4000 | C5: 2500 | E5: 8000 | F5: 3000
A6: 天津 | B6: 4000 | C6: 2500 | D6: 10 | E6: 5000 | F6: 4600 | G6: 10
A7: 河北 | B7: 7000 | C7: 11000 | D7: 10 | E7: 9800 | F7: 13600 | G7: 10.4
A8: 山西 | B8: 500 | C8: 5500 | E8: 1000 | F8: 5700
A9: 内蒙古 | B9: 450 | C9: 1850 | E9: 950 | F9: 1950
A10: 山东 | B10: 5000 | C10: 5000 | D10: 10 | E10: 8000 | F10: 6000 | G10: 10
A11: 河南 | B11: 5700 | C11: 2500 | E11: 8600 | F11: 3100
A12: 陕西 | B12: 500 | C12: 4500 | D12: 10 | E12: 1500 | F12: 6000 | G12: 10
A13: 甘肃 | B13: 500 | C13: 100 | E13: 900 | F13: 100
A14: 宁夏 | B14: 500 | E14: 750
A15: 青海 | C15: 200 | D15: 30 | F15: 250 | G15: 30
A16: 新疆 | B16: 500 | C16: 250 | D16: 5 | E16: 800 | F16: 350 | G16: 5
A17: 四川 | B17: 3000 | D17: 15 | E17: 4000 | G17: 15
A18: 重庆 | B18: 3700 | E18: 4400
B19: “十三五”新增 | E19: 2020 年累计
B20: 浅层地热能 供暖/制冷 面积 (104m2 ) | C20: 水热型地热 能供暖面积 (104m2) | D20: 发电装 机容量 (MW) | E20: 浅层地热能 供暖/制冷 面积 (104m2 ) | F20: 水热型地热 能供暖面积 (104m2) | G20: 发电装 机容量 (MW)
A21: 湖北 | B21: 6200 | E21: 7400
A22: 湖南 | B22: 4000 | E22: 4200
A23: 江西 | B23: 3000 | E23: 3600
A24: 安徽 | B24: 3000 | E24: 4800 | F24: 50
A25: 江苏 | B25: 6000 | C25: 200 | D25: 20 | E25: 8500 | F25: 250 | G25: 20
A26: 上海 | B26: 2700 | E26: 3700
A27: 浙江 | B27: 3000 | E27: 5200
A28: 辽宁 | B28: 1000 | C28: 1000 | E28: 8000 | F28: 1200
A29: 吉林 | B29: 1000 | C29: 1000 | E29: 1200 | F29: 1500
A30: 黑龙江 | B30: 1000 | C30: 1600 | E30: 1300 | F30: 2250
A31: 广东 | B31: 2000 | D31: 10 | E31: 2500 | G31: 10.3
A32: 福建 | B32: 400 | D32: 10 | E32: 500 | G32: 10
A33: 海南 | B33: 500 | D33: 10 | E33: 600 | G33: 10
A34: 云南 | B34: 100 | D34: 10 | E34: 250 | G34: 10
A35: 贵州 | B35: 2000 | C35: 50 | E35: 2800 | F35: 60
A36: 广西 | B36: 1400 | E36: 3600
A37: 西藏 | B37: 0 | C37: 250 | D37: 350 | F37: 250 | G37: 376.58
A38: 全国 | B38: 72650 | C38: 40000 | D38: 500 | E38: 111850 | F38: 50210 | G38: 527.28

Sheet 2000
A1: 分地区新增发电装机容量（万KW）
A2: 地区 | B2: 合计 | C2: 水电 | E2: 火电 | S2: 核电 | T2: 风电 | U2: 太阳能发电 | V2: 其他
C3: 合计 | D3: 抽水蓄能 | E3: 合计 | F3: 燃煤 | I3: 燃气 | L3: 燃油 | M3: 其他
F4: 合计 | G4: 常规燃煤 | H4: 煤矸石发电 | I4: 合计 | J4: 常规燃气 | K4: 煤层气发电 | M4: 合计 | N4: 余温、余气、余压发电 | O4: 垃圾焚烧发电 | P4: 秸秆、蔗渣、林木质发电 | Q4: 沼气 | R4: 技改增容
A5: 全国 | X5: =B5-C5-E5-S5-T5-U5-V5 -> 0 | Y5: =E5-F5-I5-L5-M5 -> 0 | Z5: =M5-N5-O5-P5 -> 0
A6: 北京 | X6: =B6-C6-E6-S6-T6-U6-V6 -> 0 | Y6: =E6-F6-I6-L6-M6 -> 0 | Z6: =M6-N6-O6-P6 -> 0
A7: 天津 | X7: =B7-C7-E7-S7-T7-U7-V7 -> 0 | Y7: =E7-F7-I7-L7-M7 -> 0 | Z7: =M7-N7-O7-P7 -> 0
A8: 河北 | X8: =B8-C8-E8-S8-T8-U8-V8 -> 0 | Y8: =E8-F8-I8-L8-M8 -> 0 | Z8: =M8-N8-O8-P8 -> 0
A9: 山西 | X9: =B9-C9-E9-S9-T9-U9-V9 -> 0 | Y9: =E9-F9-I9-L9-M9 -> 0 | Z9: =M9-N9-O9-P9 -> 0
A10: 内蒙古 | X10: =B10-C10-E10-S10-T10-U10-V10 -> 0 | Y10: =E10-F10-I10-L10-M10 -> 0 | Z10: =M10-N10-O10-P10 -> 0
A11: 辽宁 | X11: =B11-C11-E11-S11-T11-U11-V11 -> 0 | Y11: =E11-F11-I11-L11-M11 -> 0 | Z11: =M11-N11-O11-P11 -> 0
A12: 吉林 | X12: =B12-C12-E12-S12-T12-U12-V12 -> 0 | Y12: =E12-F12-I12-L12-M12 -> 0 | Z12: =M12-N12-O12-P12 -> 0
A13: 黑龙江 | X13: =B13-C13-E13-S13-T13-U13-V13 -> 0 | Y13: =E13-F13-I13-L13-M13 -> 0 | Z13: =M13-N13-O13-P13 -> 0
A14: 上海 | X14: =B14-C14-E14-S14-T14-U14-V14 -> 0 | Y14: =E14-F14-I14-L14-M14 -> 0 | Z14: =M14-N14-O14-P14 -> 0
A15: 江苏 | X15: =B15-C15-E15-S15-T15-U15-V15 -> 0 | Y15: =E15-F15-I15-L15-M15 -> 0 | Z15: =M15-N15-O15-P15 -> 0
A16: 浙江 | X16: =B16-C16-E16-S16-T16-U16-V16 -> 0 | Y16: =E16-F16-I16-L16-M16 -> 0 | Z16: =M16-N16-O16-P16 -> 0
... A36: 新疆 | X36: =B36-C36-E36-S36-T36-U36-V36 -> 0 | Y36: =E36-F36-I36-L36-M36 -> 0 | Z36: =M36-N36-O36-P36 -> 0
B38: =B5-SUM(B6:B36) -> 0 | C38: =C5-SUM(C6:C36) -> 0 | D38: =D5-SUM(D6:D36) -> 0 | E38: =E5-SUM(E6:E36) -> 0 | F38: =F5-SUM(F6:F36) -> 0 | H38: =H5-SUM(H6:H36) -> 0 | I38: =I5-SUM(I6:I36) -> 0 | J38: =J5-SUM(J6:J36) -> 0 | K38: =K5-SUM(K6:K36) -> 0 | L38: =L5-SUM(L6:L36) -> 0 | M38: =M5-SUM(M6:M36) -> 0 | N38: =N5-SUM(N6:N36) -> 0 | O38: =O5-SUM(O6:O36) -> 0 | P38: =P5-SUM(P6:P36) -> 0 | S38: =S5-SUM(S6:S36) -> 0 | T38: =T5-SUM(T6:T36) -> 0 | U38: =U5-SUM(U6:U36) -> 0 | V38: =V5-SUM(V6:V36) -> 0

Sheet 2001
A1: 分地区新增发电装机容量（万KW）
A2: 地区 | B2: 合计 | C2: 水电 | E2: 火电 | S2: 核电 | T2: 风电 | U2: 太阳能发电 | V2: 其他
C3: 合计 | D3: 抽水蓄能 | E3: 合计 | F3: 燃煤 | I3: 燃气 | L3: 燃油 | M3: 其他
F4: 合计 | G4: 常规燃煤 | H4: 煤矸石发电 | I4: 合计 | J4: 常规燃气 | K4: 煤层气发电 | M4: 合计 | N4: 余温、余气、余压发电 | O4: 垃圾焚烧发电 | P4: 秸秆、蔗渣、林木质发电 | Q4: 沼气 | R4: 技改增容
A5: 全国 | X5: =B5-C5-E5-S5-T5-U5-V5 -> 0 | Y5: =E5-F5-I5-L5-M5 -> 0 | Z5: =M5-N5-O5-P5 -> 0
A6: 北京 | X6: =B6-C6-E6-S6-T6-U6-V6 -> 0 | Y6: =E6-F6-I6-L6-M6 -> 0 | Z6: =M6-N6-O6-P6 -> 0
A7: 天津 | X7: =B7-C7-E7-S7-T7-U7-V7 -> 0 | Y7: =E7-F7-I7-L7-M7 -> 0 | Z7: =M7-N7-O7-P7 -> 0
A8: 河北 | X8: =B8-C8-E8-S8-T8-U8-V8 -> 0 | Y8: =E8-F8-I8-L8-M8 -> 0 | Z8: =M8-N8-O8-P8 -> 0
A9: 山西 | X9: =B9-C9-E9-S9-T9-U9-V9 -> 0 | Y9: =E9-F9-I9-L9-M9 -> 0 | Z9: =M9-N9-O9-P9 -> 0
A10: 内蒙古 | X10: =B10-C10-E10-S10-T10-U10-V10 -> 0 | Y10: =E10-F10-I10-L10-M10 -> 0 | Z10: =M10-N10-O10-P10 -> 0
A11: 辽宁 | X11: =B11-C11-E11-S11-T11-U11-V11 -> 0 | Y11: =E11-F11-I11-L11-M11 -> 0 | Z11: =M11-N11-O11-P11 -> 0
A12: 吉林 | X12: =B12-C12-E12-S12-T12-U12-V12 -> 0 | Y12: =E12-F12-I12-L12-M12 -> 0 | Z12: =M12-N12-O12-P12 -> 0
A13: 黑龙江 | X13: =B13-C13-E13-S13-T13-U13-V13 -> 0 | Y13: =E13-F13-I13-L13-M13 -> 0 | Z13: =M13-N13-O13-P13 -> 0
A14: 上海 | X14: =B14-C14-E14-S14-T14-U14-V14 -> 0 | Y14: =E14-F14-I14-L14-M14 -> 0 | Z14: =M14-N14-O14-P14 -> 0
A15: 江苏 | X15: =B15-C15-E15-S15-T15-U15-V15 -> 0 | Y15: =E15-F15-I15-L15-M15 -> 0 | Z15: =M15-N15-O15-P15 -> 0
A16: 浙江 | X16: =B16-C16-E16-S16-T16-U16-V16 -> 0 | Y16: =E16-F16-I16-L16-M16 -> 0 | Z16: =M16-N16-O16-P16 -> 0
... A36: 新疆 | X36: =B36-C36-E36-S36-T36-U36-V36 -> 0 | Y36: =E36-F36-I36-L36-M36 -> 0 | Z36: =M36-N36-O36-P36 -> 0
B38: =B5-SUM(B6:B36) -> 0 | C38: =C5-SUM(C6:C36) -> 0 | D38: =D5-SUM(D6:D36) -> 0 | E38: =E5-SUM(E6:E36) -> 0 | F38: =F5-SUM(F6:F36) -> 0 | H38: =H5-SUM(H6:H36) -> 0 | I38: =I5-SUM(I6:I36) -> 0 | J38: =J5-SUM(J6:J36) -> 0 | K38: =K5-SUM(K6:K36) -> 0 | L38: =L5-SUM(L6:L36) -> 0 | M38: =M5-SUM(M6:M36) -> 0 | N38: =N5-SUM(N6:N36) -> 0 | O38: =O5-SUM(O6:O36) -> 0 | P38: =P5-SUM(P6:P36) -> 0 | S38: =S5-SUM(S6:S36) -> 0 | T38: =T5-SUM(T6:T36) -> 0 | U38: =U5-SUM(U6:U36) -> 0 | V38: =V5-SUM(V6:V36) -> 0

Sheet 2002
A1: 分地区新增发电装机容量（万KW）
A2: 地区 | B2: 合计 | C2: 水电 | E2: 火电 | S2: 核电 | T2: 风电 | U2: 太阳能发电 | V2: 其他
C3: 合计 | D3: 抽水蓄能 | E3: 合计 | F3: 燃煤 | I3: 燃气 | L3: 燃油 | M3: 其他
F4: 合计 | G4: 常规燃煤 | H4: 煤矸石发电 | I4: 合计 | J4: 常规燃气 | K4: 煤层气发电 | M4: 合计 | N4: 余温、余气、余压发电 | O4: 垃圾焚烧发电 | P4: 秸秆、蔗渣、林木质发电 | Q4: 沼气 | R4: 技改增容
A5: 全国 | X5: =B5-C5-E5-S5-T5-U5-V5 -> 0 | Y5: =E5-F5-I5-L5-M5 -> 0 | Z5: =M5-N5-O5-P5 -> 0
A6: 北京 | X6: =B6-C6-E6-S6-T6-U6-V6 -> 0 | Y6: =E6-F6-I6-L6-M6 -> 0 | Z6: =M6-N6-O6-P6 -> 0
A7: 天津 | X7: =B7-C7-E7-S7-T7-U7-V7 -> 0 | Y7: =E7-F7-I7-L7-M7 -> 0 | Z7: =M7-N7-O7-P7 -> 0
A8: 河北 | X8: =B8-C8-E8-S8-T8-U8-V8 -> 0 | Y8: =E8-F8-I8-L8-M8 -> 0 | Z8: =M8-N8-O8-P8 -> 0
A9: 山西 | X9: =B9-C9-E9-S9-T9-U9-V9 -> 0 | Y9: =E9-F9-I9-L9-M9 -> 0 | Z9: =M9-N9-O9-P9 -> 0
A10: 内蒙古 | X10: =B10-C10-E10-S10-T10-U10-V10 -> 0 | Y10: =E10-F10-I10-L10-M10 -> 0 | Z10: =M10-N10-O10-P10 -> 0
A11: 辽宁 | X11: =B11-C11-E11-S11-T11-U11-V11 -> 0 | Y11: =E11-F11-I11-L11-M11 -> 0 | Z11: =M11-N11-O11-P11 -> 0
A12: 吉林 | X12: =B12-C12-E12-S12-T12-U12-V12 -> 0 | Y12: =E12-F12-I12-L12-M12 -> 0 | Z12: =M12-N12-O12-P12 -> 0
A13: 黑龙江 | X13: =B13-C13-E13-S13-T13-U13-V13 -> 0 | Y13: =E13-F13-I13-L13-M13 -> 0 | Z13: =M13-N13-O13-P13 -> 0
A14: 上海 | X14: =B14-C14-E14-S14-T14-U14-V14 -> 0 | Y14: =E14-F14-I14-L14-M14 -> 0 | Z14: =M14-N14-O14-P14 -> 0
A15: 江苏 | X15: =B15-C15-E15-S15-T15-U15-V15 -> 0 | Y15: =E15-F15-I15-L15-M15 -> 0 | Z15: =M15-N15-O15-P15 -> 0
A16: 浙江 | X16: =B16-C16-E16-S16-T16-U16-V16 -> 0 | Y16: =E16-F16-I16-L16-M16 -> 0 | Z16: =M16-N16-O16-P16 -> 0
... A36: 新疆 | X36: =B36-C36-E36-S36-T36-U36-V36 -> 0 | Y36: =E36-F36-I36-L36-M36 -> 0 | Z36: =M36-N36-O36-P36 -> 0
B38: =B5-SUM(B6:B36) -> 0 | C38: =C5-SUM(C6:C36) -> 0 | D38: =D5-SUM(D6:D36) -> 0 | E38: =E5-SUM(E6:E36) -> 0 | F38: =F5-SUM(F6:F36) -> 0 | H38: =H5-SUM(H6:H36) -> 0 | I38: =I5-SUM(I6:I36) -> 0 | J38: =J5-SUM(J6:J36) -> 0 | K38: =K5-SUM(K6:K36) -> 0 | L38: =L5-SUM(L6:L36) -> 0 | M38: =M5-SUM(M6:M36) -> 0 | N38: =N5-SUM(N6:N36) -> 0 | O38: =O5-SUM(O6:O36) -> 0 | P38: =P5-SUM(P6:P36) -> 0 | S38: =S5-SUM(S6:S36) -> 0 | T38: =T5-SUM(T6:T36) -> 0 | U38: =U5-SUM(U6:U36) -> 0 | V38: =V5-SUM(V6:V36) -> 0

Sheet 2003
A1: 分地区新增发电装机容量（万KW）
A2: 地区 | B2: 合计 | C2: 水电 | E2: 火电 | S2: 核电 | T2: 风电 | U2: 太阳能发电 | V2: 其他
C3: 合计 | D3: 抽水蓄能 | E3: 合计 | F3: 燃煤 | I3: 燃气 | L3: 燃油 | M3: 其他
F4: 合计 | G4: 常规燃煤 | H4: 煤矸石发电 | I4: 合计 | J4: 常规燃气 | K4: 煤层气发电 | M4: 合计 | N4: 余温、余气、余压发电 | O4: 垃圾焚烧发电 | P4: 秸秆、蔗渣、林木质发电 | Q4: 沼气 | R4: 技改增容
A5: 全国 | X5: =B5-C5-E5-S5-T5-U5-V5 -> 0 | Y5: =E5-F5-I5-L5-M5 -> 0 | Z5: =M5-N5-O5-P5 -> 0
A6: 北京 | X6: =B6-C6-E6-S6-T6-U6-V6 -> 0 | Y6: =E6-F6-I6-L6-M6 -> 0 | Z6: =M6-N6-O6-P6 -> 0
A7: 天津 | X7: =B7-C7-E7-S7-T7-U7-V7 -> 0 | Y7: =E7-F7-I7-L7-M7 -> 0 | Z7: =M7-N7-O7-P7 -> 0
A8: 河北 | X8: =B8-C8-E8-S8-T8-U8-V8 -> 0 | Y8: =E8-F8-I8-L8-M8 -> 0 | Z8: =M8-N8-O8-P8 -> 0
A9: 山西 | X9: =B9-C9-E9-S9-T9-U9-V9 -> 0 | Y9: =E9-F9-I9-L9-M9 -> 0 | Z9: =M9-N9-O9-P9 -> 0
A10: 内蒙古 | X10: =B10-C10-E10-S10-T10-U10-V10 -> 0 | Y10: =E10-F10-I10-L10-M10 -> 0 | Z10: =M10-N10-O10-P10 -> 0
A11: 辽宁 | X11: =B11-C11-E11-S11-T11-U11-V11 -> 0 | Y11: =E11-F11-I11-L11-M11 -> 0 | Z11: =M11-N11-O11-P11 -> 0
A12: 吉林 | X12: =B12-C12-E12-S12-T12-U12-V12 -> 0 | Y12: =E12-F12-I12-L12-M12 -> 0 | Z12: =M12-N12-O12-P12 -> 0
A13: 黑龙江 | X13: =B13-C13-E13-S13-T13-U13-V13 -> 0 | Y13: =E13-F13-I13-L13-M13 -> 0 | Z13: =M13-N13-O13-P13 -> 0
A14: 上海 | X14: =B14-C14-E14-S14-T14-U14-V14 -> 0 | Y14: =E14-F14-I14-L14-M14 -> 0 | Z14: =M14-N14-O14-P14 -> 0
A15: 江苏 | X15: =B15-C15-E15-S15-T15-U15-V15 -> 0 | Y15: =E15-F15-I15-L15-M15 -> 0 | Z15: =M15-N15-O15-P15 -> 0
A16: 浙江 | X16: =B16-C16-E16-S16-T16-U16-V16 -> 0 | Y16: =E16-F16-I16-L16-M16 -> 0 | Z16: =M16-N16-O16-P16 -> 0
... A36: 新疆 | X36: =B36-C36-E36-S36-T36-U36-V36 -> 0 | Y36: =E36-F36-I36-L36-M36 -> 0 | Z36: =M36-N36-O36-P36 -> 0
B38: =B5-SUM(B6:B36) -> 0 | C38: =C5-SUM(C6:C36) -> 0 | D38: =D5-SUM(D6:D36) -> 0 | E38: =E5-SUM(E6:E36) -> 0 | F38: =F5-SUM(F6:F36) -> 0 | H38: =H5-SUM(H6:H36) -> 0 | I38: =I5-SUM(I6:I36) -> 0 | J38: =J5-SUM(J6:J36) -> 0 | K38: =K5-SUM(K6:K36) -> 0 | L38: =L5-SUM(L6:L36) -> 0 | M38: =M5-SUM(M6:M36) -> 0 | N38: =N5-SUM(N6:N36) -> 0 | O38: =O5-SUM(O6:O36) -> 0 | P38: =P5-SUM(P6:P36) -> 0 | S38: =S5-SUM(S6:S36) -> 0 | T38: =T5-SUM(T6:T36) -> 0 | U38: =U5-SUM(U6:U36) -> 0 | V38: =V5-SUM(V6:V36) -> 0

Sheet 2004
A1: 分地区新增发电装机容量（万KW）
A2: 地区 | B2: 合计 | C2: 水电 | E2: 火电 | S2: 核电 | T2: 风电 | U2: 太阳能发电 | V2: 其他
C3: 合计 | D3: 抽水蓄能 | E3: 合计 | F3: 燃煤 | I3: 燃气 | L3: 燃油 | M3: 其他
F4: 合计 | G4: 常规燃煤 | H4: 煤矸石发电 | I4: 合计 | J4: 常规燃气 | K4: 煤层气发电 | M4: 合计 | N4: 余温、余气、余压发电 | O4: 垃圾焚烧发电 | P4: 秸秆、蔗渣、林木质发电 | Q4: 沼气 | R4: 技改增容
A5: 全国 | X5: =B5-C5-E5-S5-T5-U5-V5 -> 0 | Y5: =E5-F5-I5-L5-M5 -> 0 | Z5: =M5-N5-O5-P5 -> 0
A6: 北京 | X6: =B6-C6-E6-S6-T6-U6-V6 -> 0 | Y6: =E6-F6-I6-L6-M6 -> 0 | Z6: =M6-N6-O6-P6 -> 0
A7: 天津 | X7: =B7-C7-E7-S7-T7-U7-V7 -> 0 | Y7: =E7-F7-I7-L7-M7 -> 0 | Z7: =M7-N7-O7-P7 -> 0
A8: 河北 | X8: =B8-C8-E8-S8-T8-U8-V8 -> 0 | Y8: =E8-F8-I8-L8-M8 -> 0 | Z8: =M8-N8-O8-P8 -> 0
A9: 山西 | X9: =B9-C9-E9-S9-T9-U9-V9 -> 0 | Y9: =E9-F9-I9-L9-M9 -> 0 | Z9: =M9-N9-O9-P9 -> 0
A10: 内蒙古 | X10: =B10-C10-E10-S10-T10-U10-V10 -> 0 | Y10: =E10-F10-I10-L10-M10 -> 0 | Z10: =M10-N10-O10-P10 -> 0
A11: 辽宁 | X11: =B11-C11-E11-S11-T11-U11-V11 -> 0 | Y11: =E11-F11-I11-L11-M11 -> 0 | Z11: =M11-N11-O11-P11 -> 0
A12: 吉林 | X12: =B12-C12-E12-S12-T12-U12-V12 -> 0 | Y12: =E12-F12-I12-L12-M12 -> 0 | Z12: =M12-N12-O12-P12 -> 0
A13: 黑龙江 | X13: =B13-C13-E13-S13-T13-U13-V13 -> 0 | Y13: =E13-F13-I13-L13-M13 -> 0 | Z13: =M13-N13-O13-P13 -> 0
A14: 上海 | X14: =B14-C14-E14-S14-T14-U14-V14 -> 0 | Y14: =E14-F14-I14-L14-M14 -> 0 | Z14: =M14-N14-O14-P14 -> 0
A15: 江苏 | X15: =B15-C15-E15-S15-T15-U15-V15 -> 0 | Y15: =E15-F15-I15-L15-M15 -> 0 | Z15: =M15-N15-O15-P15 -> 0
A16: 浙江 | X16: =B16-C16-E16-S16-T16-U16-V16 -> 0 | Y16: =E16-F16-I16-L16-M16 -> 0 | Z16: =M16-N16-O16-P16 -> 0
... A36: 新疆 | X36: =B36-C36-E36-S36-T36-U36-V36 -> 0 | Y36: =E36-F36-I36-L36-M36 -> 0 | Z36: =M36-N36-O36-P36 -> 0
B38: =B5-SUM(B6:B36) -> 0 | C38: =C5-SUM(C6:C36) -> 0 | D38: =D5-SUM(D6:D36) -> 0 | E38: =E5-SUM(E6:E36) -> 0 | F38: =F5-SUM(F6:F36) -> 0 | H38: =H5-SUM(H6:H36) -> 0 | I38: =I5-SUM(I6:I36) -> 0 | J38: =J5-SUM(J6:J36) -> 0 | K38: =K5-SUM(K6:K36) -> 0 | L38: =L5-SUM(L6:L36) -> 0 | M38: =M5-SUM(M6:M36) -> 0 | N38: =N5-SUM(N6:N36) -> 0 | O38: =O5-SUM(O6:O36) -> 0 | P38: =P5-SUM(P6:P36) -> 0 | S38: =S5-SUM(S6:S36) -> 0 | T38: =T5-SUM(T6:T36) -> 0 | U38: =U5-SUM(U6:U36) -> 0 | V38: =V5-SUM(V6:V36) -> 0

Sheet 2005
A1: 分地区新增发电装机容量（万KW）
A2: 地区 | B2: 合计 | C2: 水电 | E2: 火电 | S2: 核电 | T2: 风电 | U2: 太阳能发电 | V2: 其他
C3: 合计 | D3: 抽水蓄能 | E3: 合计 | F3: 燃煤 | I3: 燃气 | L3: 燃油 | M3: 其他
F4: 合计 | G4: 常规燃煤 | H4: 煤矸石发电 | I4: 合计 | J4: 常规燃气 | K4: 煤层气发电 | M4: 合计 | N4: 余温、余气、余压发电 | O4: 垃圾焚烧发电 | P4: 秸秆、蔗渣、林木质发电 | Q4: 沼气 | R4: 技改增容
A5: 全国 | X5: =B5-C5-E5-S5-T5-U5-V5 -> 0 | Y5: =E5-F5-I5-L5-M5 -> 0 | Z5: =M5-N5-O5-P5 -> 0
A6: 北京 | X6: =B6-C6-E6-S6-T6-U6-V6 -> 0 | Y6: =E6-F6-I6-L6-M6 -> 0 | Z6: =M6-N6-O6-P6 -> 0
A7: 天津 | X7: =B7-C7-E7-S7-T7-U7-V7 -> 0 | Y7: =E7-F7-I7-L7-M7 -> 0 | Z7: =M7-N7-O7-P7 -> 0
A8: 河北 | X8: =B8-C8-E8-S8-T8-U8-V8 -> 0 | Y8: =E8-F8-I8-L8-M8 -> 0 | Z8: =M8-N8-O8-P8 -> 0
A9: 山西 | X9: =B9-C9-E9-S9-T9-U9-V9 -> 0 | Y9: =E9-F9-I9-L9-M9 -> 0 | Z9: =M9-N9-O9-P9 -> 0
A10: 内蒙古 | X10: =B10-C10-E10-S10-T10-U10-V10 -> 0 | Y10: =E10-F10-I10-L10-M10 -> 0 | Z10: =M10-N10-O10-P10 -> 0
A11: 辽宁 | X11: =B11-C11-E11-S11-T11-U11-V11 -> 0 | Y11: =E11-F11-I11-L11-M11 -> 0 | Z11: =M11-N11-O11-P11 -> 0
A12: 吉林 | X12: =B12-C12-E12-S12-T12-U12-V12 -> 0 | Y12: =E12-F12-I12-L12-M12 -> 0 | Z12: =M12-N12-O12-P12 -> 0
A13: 黑龙江 | X13: =B13-C13-E13-S13-T13-U13-V13 -> 0 | Y13: =E13-F13-I13-L13-M13 -> 0 | Z13: =M13-N13-O13-P13 -> 0
A14: 上海 | X14: =B14-C14-E14-S14-T14-U14-V14 -> 0 | Y14: =E14-F14-I14-L14-M14 -> 0 | Z14: =M14-N14-O14-P14 -> 0
A15: 江苏 | X15: =B15-C15-E15-S15-T15-U15-V15 -> 0 | Y15: =E15-F15-I15-L15-M15 -> 0 | Z15: =M15-N15-O15-P15 -> 0
A16: 浙江 | X16: =B16-C16-E16-S16-T16-U16-V16 -> 0 | Y16: =E16-F16-I16-L16-M16 -> 0 | Z16: =M16-N16-O16-P16 -> 0
... A36: 新疆 | X36: =B36-C36-E36-S36-T36-U36-V36 -> 0 | Y36: =E36-F36-I36-L36-M36 -> 0 | Z36: =M36-N36-O36-P36 -> 0
B38: =B5-SUM(B6:B36) -> 0 | C38: =C5-SUM(C6:C36) -> 0 | D38: =D5-SUM(D6:D36) -> 0 | E38: =E5-SUM(E6:E36) -> 0 | F38: =F5-SUM(F6:F36) -> 0 | H38: =H5-SUM(H6:H36) -> 0 | I38: =I5-SUM(I6:I36) -> 0 | J38: =J5-SUM(J6:J36) -> 0 | K38: =K5-SUM(K6:K36) -> 0 | L38: =L5-SUM(L6:L36) -> 0 | M38: =M5-SUM(M6:M36) -> 0 | N38: =N5-SUM(N6:N36) -> 0 | O38: =O5-SUM(O6:O36) -> 0 | P38: =P5-SUM(P6:P36) -> 0 | S38: =S5-SUM(S6:S36) -> 0 | T38: =T5-SUM(T6:T36) -> 0 | U38: =U5-SUM(U6:U36) -> 0 | V38: =V5-SUM(V6:V36) -> 0

Sheet 2006
A1: 分地区新增发电装机容量（万KW）
A2: 地区 | B2: 合计 | C2: 水电 | E2: 火电 | S2: 核电 | T2: 风电 | U2: 太阳能发电 | V2: 其他
C3: 合计 | D3: 抽水蓄能 | E3: 合计 | F3: 燃煤 | I3: 燃气 | L3: 燃油 | M3: 其他
F4: 合计 | G4: 常规燃煤 | H4: 煤矸石发电 | I4: 合计 | J4: 常规燃气 | K4: 煤层气发电 | M4: 合计 | N4: 余温、余气、余压发电 | O4: 垃圾焚烧发电 | P4: 秸秆、蔗渣、林木质发电 | Q4: 沼气 | R4: 技改增容
A5: 全国 | X5: =B5-C5-E5-S5-T5-U5-V5 -> 0 | Y5: =E5-F5-I5-L5-M5 -> 0 | Z5: =M5-N5-O5-P5 -> 0
A6: 北京 | X6: =B6-C6-E6-S6-T6-U6-V6 -> 0 | Y6: =E6-F6-I6-L6-M6 -> 0 | Z6: =M6-N6-O6-P6 -> 0
A7: 天津 | X7: =B7-C7-E7-S7-T7-U7-V7 -> 0 | Y7: =E7-F7-I7-L7-M7 -> 0 | Z7: =M7-N7-O7-P7 -> 0
A8: 河北 | X8: =B8-C8-E8-S8-T8-U8-V8 -> 0 | Y8: =E8-F8-I8-L8-M8 -> 0 | Z8: =M8-N8-O8-P8 -> 0
A9: 山西 | X9: =B9-C9-E9-S9-T9-U9-V9 -> 0 | Y9: =E9-F9-I9-L9-M9 -> 0 | Z9: =M9-N9-O9-P9 -> 0
A10: 内蒙古 | X10: =B10-C10-E10-S10-T10-U10-V10 -> 0 | Y10: =E10-F10-I10-L10-M10 -> 0 | Z10: =M10-N10-O10-P10 -> 0
A11: 辽宁 | X11: =B11-C11-E11-S11-T11-U11-V11 -> 0 | Y11: =E11-F11-I11-L11-M11 -> 0 | Z11: =M11-N11-O11-P11 -> 0
A12: 吉林 | X12: =B12-C12-E12-S12-T12-U12-V12 -> 0 | Y12: =E12-F12-I12-L12-M12 -> 0 | Z12: =M12-N12-O12-P12 -> 0
A13: 黑龙江 | X13: =B13-C13-E13-S13-T13-U13-V13 -> 0 | Y13: =E13-F13-I13-L13-M13 -> 0 | Z13: =M13-N13-O13-P13 -> 0
A14: 上海 | X14: =B14-C14-E14-S14-T14-U14-V14 -> 0 | Y14: =E14-F14-I14-L14-M14 -> 0 | Z14: =M14-N14-O14-P14 -> 0
A15: 江苏 | X15: =B15-C15-E15-S15-T15-U15-V15 -> 0 | Y15: =E15-F15-I15-L15-M15 -> 0 | Z15: =M15-N15-O15-P15 -> 0
A16: 浙江 | X16: =B16-C16-E16-S16-T16-U16-V16 -> 0 | Y16: =E16-F16-I16-L16-M16 -> 0 | Z16: =M16-N16-O16-P16 -> 0
... A36: 新疆 | X36: =B36-C36-E36-S36-T36-U36-V36 -> 0 | Y36: =E36-F36-I36-L36-M36 -> 0 | Z36: =M36-N36-O36-P36 -> 0
B38: =B5-SUM(B6:B36) -> 0 | C38: =C5-SUM(C6:C36) -> 0 | D38: =D5-SUM(D6:D36) -> 0 | E38: =E5-SUM(E6:E36) -> 0 | F38: =F5-SUM(F6:F36) -> 0 | H38: =H5-SUM(H6:H36) -> 0 | I38: =I5-SUM(I6:I36) -> 0 | J38: =J5-SUM(J6:J36) -> 0 | K38: =K5-SUM(K6:K36) -> 0 | L38: =L5-SUM(L6:L36) -> 0 | M38: =M5-SUM(M6:M36) -> 0 | N38: =N5-SUM(N6:N36) -> 0 | O38: =O5-SUM(O6:O36) -> 0 | P38: =P5-SUM(P6:P36) -> 0 | S38: =S5-SUM(S6:S36) -> 0 | T38: =T5-SUM(T6:T36) -> 0 | U38: =U5-SUM(U6:U36) -> 0 | V38: =V5-SUM(V6:V36) -> 0

Sheet 2007
A1: 分地区新增发电装机容量（万KW）
A2: 地区 | B2: 合计 | C2: 水电 | E2: 火电 | S2: 核电 | T2: 风电 | U2: 太阳能发电 | V2: 其他
C3: 合计 | D3: 抽水蓄能 | E3: 合计 | F3: 燃煤 | I3: 燃气 | L3: 燃油 | M3: 其他
F4: 合计 | G4: 常规燃煤 | H4: 煤矸石发电 | I4: 合计 | J4: 常规燃气 | K4: 煤层气发电 | M4: 合计 | N4: 余温、余气、余压发电 | O4: 垃圾焚烧发电 | P4: 秸秆、蔗渣、林木质发电 | Q4: 沼气 | R4: 技改增容
A5: 全国 | X5: =B5-C5-E5-S5-T5-U5-V5 -> 0 | Y5: =E5-F5-I5-L5-M5 -> 0 | Z5: =M5-N5-O5-P5 -> 0
A6: 北京 | X6: =B6-C6-E6-S6-T6-U6-V6 -> 0 | Y6: =E6-F6-I6-L6-M6 -> 0 | Z6: =M6-N6-O6-P6 -> 0
A7: 天津 | X7: =B7-C7-E7-S7-T7-U7-V7 -> 0 | Y7: =E7-F7-I7-L7-M7 -> 0 | Z7: =M7-N7-O7-P7 -> 0
A8: 河北 | X8: =B8-C8-E8-S8-T8-U8-V8 -> 0 | Y8: =E8-F8-I8-L8-M8 -> 0 | Z8: =M8-N8-O8-P8 -> 0
A9: 山西 | X9: =B9-C9-E9-S9-T9-U9-V9 -> 0 | Y9: =E9-F9-I9-L9-M9 -> 0 | Z9: =M9-N9-O9-P9 -> 0
A10: 内蒙古 | X10: =B10-C10-E10-S10-T10-U10-V10 -> 0 | Y10: =E10-F10-I10-L10-M10 -> 0 | Z10: =M10-N10-O10-P10 -> 0
A11: 辽宁 | X11: =B11-C11-E11-S11-T11-U11-V11 -> 0 | Y11: =E11-F11-I11-L11-M11 -> 0 | Z11: =M11-N11-O11-P11 -> 0
A12: 吉林 | X12: =B12-C12-E12-S12-T12-U12-V12 -> 0 | Y12: =E12-F12-I12-L12-M12 -> 0 | Z12: =M12-N12-O12-P12 -> 0
A13: 黑龙江 | X13: =B13-C13-E13-S13-T13-U13-V13 -> 0 | Y13: =E13-F13-I13-L13-M13 -> 0 | Z13: =M13-N13-O13-P13 -> 0
A14: 上海 | X14: =B14-C14-E14-S14-T14-U14-V14 -> 0 | Y14: =E14-F14-I14-L14-M14 -> 0 | Z14: =M14-N14-O14-P14 -> 0
A15: 江苏 | X15: =B15-C15-E15-S15-T15-U15-V15 -> 0 | Y15: =E15-F15-I15-L15-M15 -> 0 | Z15: =M15-N15-O15-P15 -> 0
A16: 浙江 | X16: =B16-C16-E16-S16-T16-U16-V16 -> 0 | Y16: =E16-F16-I16-L16-M16 -> 0 | Z16: =M16-N16-O16-P16 -> 0
... A36: 新疆 | X36: =B36-C36-E36-S36-T36-U36-V36 -> 0 | Y36: =E36-F36-I36-L36-M36 -> 0 | Z36: =M36-N36-O36-P36 -> 0
B38: =B5-SUM(B6:B36) -> 0 | C38: =C5-SUM(C6:C36) -> 0 | D38: =D5-SUM(D6:D36) -> 0 | E38: =E5-SUM(E6:E36) -> 0 | F38: =F5-SUM(F6:F36) -> 0 | H38: =H5-SUM(H6:H36) -> 0 | I38: =I5-SUM(I6:I36) -> 0 | J38: =J5-SUM(J6:J36) -> 0 | K38: =K5-SUM(K6:K36) -> 0 | L38: =L5-SUM(L6:L36) -> 0 | M38: =M5-SUM(M6:M36) -> 0 | N38: =N5-SUM(N6:N36) -> 0 | O38: =O5-SUM(O6:O36) -> 0 | P38: =P5-SUM(P6:P36) -> 0 | S38: =S5-SUM(S6:S36) -> 0 | T38: =T5-SUM(T6:T36) -> 0 | U38: =U5-SUM(U6:U36) -> 0 | V38: =V5-SUM(V6:V36) -> 0

Sheet 2008
A1: 分地区新增发电装机容量（万KW）
A2: 地区 | B2: 合计 | C2: 水电 | E2: 火电 | S2: 核电 | T2: 风电 | U2: 太阳能发电 | V2: 其他
C3: 合计 | D3: 抽水蓄能 | E3: 合计 | F3: 燃煤 | I3: 燃气 | L3: 燃油 | M3: 其他
F4: 合计 | G4: 常规燃煤 | H4: 煤矸石发电 | I4: 合计 | J4: 常规燃气 | K4: 煤层气发电 | M4: 合计 | N4: 余温、余气、余压发电 | O4: 垃圾焚烧发电 | P4: 秸秆、蔗渣、林木质发电 | Q4: 沼气 | R4: 技改增容
A5: 全国 | X5: =B5-C5-E5-S5-T5-U5-V5 -> 0 | Y5: =E5-F5-I5-L5-M5 -> 0 | Z5: =M5-N5-O5-P5 -> 0
A6: 北京 | X6: =B6-C6-E6-S6-T6-U6-V6 -> 0 | Y6: =E6-F6-I6-L6-M6 -> 0 | Z6: =M6-N6-O6-P6 -> 0
A7: 天津 | X7: =B7-C7-E7-S7-T7-U7-V7 -> 0 | Y7: =E7-F7-I7-L7-M7 -> 0 | Z7: =M7-N7-O7-P7 -> 0
A8: 河北 | X8: =B8-C8-E8-S8-T8-U8-V8 -> 0 | Y8: =E8-F8-I8-L8-M8 -> 0 | Z8: =M8-N8-O8-P8 -> 0
A9: 山西 | X9: =B9-C9-E9-S9-T9-U9-V9 -> 0 | Y9: =E9-F9-I9-L9-M9 -> 0 | Z9: =M9-N9-O9-P9 -> 0
A10: 内蒙古 | X10: =B10-C10-E10-S10-T10-U10-V10 -> 0 | Y10: =E10-F10-I10-L10-M10 -> 0 | Z10: =M10-N10-O10-P10 -> 0
A11: 辽宁 | X11: =B11-C11-E11-S11-T11-U11-V11 -> 0 | Y11: =E11-F11-I11-L11-M11 -> 0 | Z11: =M11-N11-O11-P11 -> 0
A12: 吉林 | X12: =B12-C12-E12-S12-T12-U12-V12 -> 0 | Y12: =E12-F12-I12-L12-M12 -> 0 | Z12: =M12-N12-O12-P12 -> 0
A13: 黑龙江 | X13: =B13-C13-E13-S13-T13-U13-V13 -> 0 | Y13: =E13-F13-I13-L13-M13 -> 0 | Z13: =M13-N13-O13-P13 -> 0
A14: 上海 | X14: =B14-C14-E14-S14-T14-U14-V14 -> 0 | Y14: =E14-F14-I14-L14-M14 -> 0 | Z14: =M14-N14-O14-P14 -> 0
A15: 江苏 | X15: =B15-C15-E15-S15-T15-U15-V15 -> 0 | Y15: =E15-F15-I15-L15-M15 -> 0 | Z15: =M15-N15-O15-P15 -> 0
A16: 浙江 | X16: =B16-C16-E16-S16-T16-U16-V16 -> 0 | Y16: =E16-F16-I16-L16-M16 -> 0 | Z16: =M16-N16-O16-P16 -> 0
... A36: 新疆 | X36: =B36-C36-E36-S36-T36-U36-V36 -> 0 | Y36: =E36-F36-I36-L36-M36 -> 0 | Z36: =M36-N36-O36-P36 -> 0
B38: =B5-SUM(B6:B36) -> 0 | C38: =C5-SUM(C6:C36) -> 0 | D38: =D5-SUM(D6:D36) -> 0 | E38: =E5-SUM(E6:E36) -> 0 | F38: =F5-SUM(F6:F36) -> 0 | H38: =H5-SUM(H6:H36) -> 0 | I38: =I5-SUM(I6:I36) -> 0 | J38: =J5-SUM(J6:J36) -> 0 | K38: =K5-SUM(K6:K36) -> 0 | L38: =L5-SUM(L6:L36) -> 0 | M38: =M5-SUM(M6:M36) -> 0 | N38: =N5-SUM(N6:N36) -> 0 | O38: =O5-SUM(O6:O36) -> 0 | P38: =P5-SUM(P6:P36) -> 0 | S38: =S5-SUM(S6:S36) -> 0 | T38: =T5-SUM(T6:T36) -> 0 | U38: =U5-SUM(U6:U36) -> 0 | V38: =V5-SUM(V6:V36) -> 0

Sheet 2009
A1: 分地区新增发电装机容量（万KW）
A2: 地区 | B2: 合计 | C2: 水电 | E2: 火电 | S2: 核电 | T2: 风电 | U2: 太阳能发电 | V2: 其他
C3: 合计 | D3: 抽水蓄能 | E3: 合计 | F3: 燃煤 | I3: 燃气 | L3: 燃油 | M3: 其他
F4: 合计 | G4: 常规燃煤 | H4: 煤矸石发电 | I4: 合计 | J4: 常规燃气 | K4: 煤层气发电 | M4: 合计 | N4: 余温、余气、余压发电 | O4: 垃圾焚烧发电 | P4: 秸秆、蔗渣、林木质发电 | Q4: 沼气 | R4: 技改增容
A5: 全国 | X5: =B5-C5-E5-S5-T5-U5-V5 -> 0 | Y5: =E5-F5-I5-L5-M5 -> 0 | Z5: =M5-SUM(N5:R5) -> 0
A6: 北京 | X6: =B6-C6-E6-S6-T6-U6-V6 -> 0 | Y6: =E6-F6-I6-L6-M6 -> 0 | Z6: =M6-SUM(N6:R6) -> 0
A7: 天津 | X7: =B7-C7-E7-S7-T7-U7-V7 -> 0 | Y7: =E7-F7-I7-L7-M7 -> 0 | Z7: =M7-SUM(N7:R7) -> 0
A8: 河北 | X8: =B8-C8-E8-S8-T8-U8-V8 -> 0 | Y8: =E8-F8-I8-L8-M8 -> 0 | Z8: =M8-SUM(N8:R8) -> 0
A9: 山西 | X9: =B9-C9-E9-S9-T9-U9-V9 -> 0 | Y9: =E9-F9-I9-L9-M9 -> 0 | Z9: =M9-SUM(N9:R9) -> 0
A10: 内蒙古 | X10: =B10-C10-E10-S10-T10-U10-V10 -> 0 | Y10: =E10-F10-I10-L10-M10 -> 0 | Z10: =M10-SUM(N10:R10) -> 0
A11: 辽宁 | X11: =B11-C11-E11-S11-T11-U11-V11 -> 0 | Y11: =E11-F11-I11-L11-M11 -> 0 | Z11: =M11-SUM(N11:R11) -> 0
A12: 吉林 | X12: =B12-C12-E12-S12-T12-U12-V12 -> 0 | Y12: =E12-F12-I12-L12-M12 -> 0 | Z12: =M12-SUM(N12:R12) -> 0
A13: 黑龙江 | X13: =B13-C13-E13-S13-T13-U13-V13 -> 0 | Y13: =E13-F13-I13-L13-M13 -> 0 | Z13: =M13-SUM(N13:R13) -> 0
A14: 上海 | X14: =B14-C14-E14-S14-T14-U14-V14 -> 0 | Y14: =E14-F14-I14-L14-M14 -> 0 | Z14: =M14-SUM(N14:R14) -> 0
A15: 江苏 | X15: =B15-C15-E15-S15-T15-U15-V15 -> 0 | Y15: =E15-F15-I15-L15-M15 -> 0 | Z15: =M15-SUM(N15:R15) -> 0
A16: 浙江 | X16: =B16-C16-E16-S16-T16-U16-V16 -> 0 | Y16: =E16-F16-I16-L16-M16 -> 0 | Z16: =M16-SUM(N16:R16) -> 0
... A36: 新疆 | X36: =B36-C36-E36-S36-T36-U36-V36 -> 0 | Y36: =E36-F36-I36-L36-M36 -> 0 | Z36: =M36-SUM(N36:R36) -> 0
B38: =B5-SUM(B6:B36) -> 0 | C38: =C5-SUM(C6:C36) -> 0 | D38: =D5-SUM(D6:D36) -> 0 | E38: =E5-SUM(E6:E36) -> 0 | F38: =F5-SUM(F6:F36) -> 0 | H38: =H5-SUM(H6:H36) -> 0 | I38: =I5-SUM(I6:I36) -> 0 | J38: =J5-SUM(J6:J36) -> 0 | K38: =K5-SUM(K6:K36) -> 0 | L38: =L5-SUM(L6:L36) -> 0 | M38: =M5-SUM(M6:M36) -> 0 | N38: =N5-SUM(N6:N36) -> 0 | O38: =O5-SUM(O6:O36) -> 0 | P38: =P5-SUM(P6:P36) -> 0 | S38: =S5-SUM(S6:S36) -> 0 | T38: =T5-SUM(T6:T36) -> 0 | U38: =U5-SUM(U6:U36) -> 0 | V38: =V5-SUM(V6:V36) -> 0

Sheet 2010
A1: 分地区新增发电装机容量（万KW）
A2: 地区 | B2: 合计 | C2: 水电 | E2: 火电 | S2: 核电 | T2: 风电 | U2: 太阳能发电 | V2: 其他
C3: 合计 | D3: 抽水蓄能 | E3: 合计 | F3: 燃煤 | I3: 燃气 | L3: 燃油 | M3: 其他
F4: 合计 | G4: 常规燃煤 | H4: 煤矸石发电 | I4: 合计 | J4: 常规燃气 | K4: 煤层气发电 | M4: 合计 | N4: 余温、余气、余压发电 | O4: 垃圾焚烧发电 | P4: 秸秆、蔗渣、林木质发电 | Q4: 沼气 | R4: 技改增容
A5: 全国 | X5: =B5-C5-E5-S5-T5-U5-V5 -> 0 | Y5: =E5-F5-I5-L5-M5 -> 0 | Z5: =M5-N5-O5-P5 -> 0
A6: 北京 | X6: =B6-C6-E6-S6-T6-U6-V6 -> 0 | Y6: =E6-F6-I6-L6-M6 -> 0 | Z6: =M6-N6-O6-P6 -> 0
A7: 天津 | X7: =B7-C7-E7-S7-T7-U7-V7 -> 0 | Y7: =E7-F7-I7-L7-M7 -> 0 | Z7: =M7-N7-O7-P7 -> 0
A8: 河北 | X8: =B8-C8-E8-S8-T8-U8-V8 -> 0 | Y8: =E8-F8-I8-L8-M8 -> 0 | Z8: =M8-N8-O8-P8 -> 0
A9: 山西 | X9: =B9-C9-E9-S9-T9-U9-V9 -> 0 | Y9: =E9-F9-I9-L9-M9 -> 0 | Z9: =M9-N9-O9-P9 -> 0
A10: 内蒙古 | X10: =B10-C10-E10-S10-T10-U10-V10 -> 0 | Y10: =E10-F10-I10-L10-M10 -> 0 | Z10: =M10-N10-O10-P10 -> 0
A11: 辽宁 | X11: =B11-C11-E11-S11-T11-U11-V11 -> 0 | Y11: =E11-F11-I11-L11-M11 -> 0 | Z11: =M11-N11-O11-P11 -> 0
A12: 吉林 | X12: =B12-C12-E12-S12-T12-U12-V12 -> 0 | Y12: =E12-F12-I12-L12-M12 -> 0 | Z12: =M12-N12-O12-P12 -> 0
A13: 黑龙江 | X13: =B13-C13-E13-S13-T13-U13-V13 -> 0 | Y13: =E13-F13-I13-L13-M13 -> 0 | Z13: =M13-N13-O13-P13 -> 0
A14: 上海 | X14: =B14-C14-E14-S14-T14-U14-V14 -> 0 | Y14: =E14-F14-I14-L14-M14 -> 0 | Z14: =M14-N14-O14-P14 -> 0
A15: 江苏 | X15: =B15-C15-E15-S15-T15-U15-V15 -> 0 | Y15: =E15-F15-I15-L15-M15 -> 0 | Z15: =M15-N15-O15-P15 -> 0
A16: 浙江 | X16: =B16-C16-E16-S16-T16-U16-V16 -> 0 | Y16: =E16-F16-I16-L16-M16 -> 0 | Z16: =M16-N16-O16-P16 -> 0
... A36: 新疆 | X36: =B36-C36-E36-S36-T36-U36-V36 -> 0 | Y36: =E36-F36-I36-L36-M36 -> 0 | Z36: =M36-N36-O36-P36 -> 0
B38: =B5-SUM(B6:B36) -> 0 | C38: =C5-SUM(C6:C36) -> 0 | D38: =D5-SUM(D6:D36) -> 0 | E38: =E5-SUM(E6:E36) -> 0 | F38: =F5-SUM(F6:F36) -> 0 | H38: =H5-SUM(H6:H36) -> 0 | I38: =I5-SUM(I6:I36) -> 0 | J38: =J5-SUM(J6:J36) -> 0 | K38: =K5-SUM(K6:K36) -> 0 | L38: =L5-SUM(L6:L36) -> 0 | M38: =M5-SUM(M6:M36) -> 0 | N38: =N5-SUM(N6:N36) -> 0 | O38: =O5-SUM(O6:O36) -> 0 | P38: =P5-SUM(P6:P36) -> 0 | S38: =S5-SUM(S6:S36) -> 0 | T38: =T5-SUM(T6:T36) -> 0 | U38: =U5-SUM(U6:U36) -> 0 | V38: =V5-SUM(V6:V36) -> 0

Sheet 2011
A1: 分地区新增发电装机容量（万KW）
A2: 地区 | B2: 合计 | C2: 水电 | E2: 火电 | S2: 核电 | T2: 风电 | U2: 太阳能发电 | V2: 其他
C3: 合计 | D3: 抽水蓄能 | E3: 合计 | F3: 燃煤 | I3: 燃气 | L3: 燃油 | M3: 其他
F4: 合计 | G4: 常规燃煤 | H4: 煤矸石发电 | I4: 合计 | J4: 常规燃气 | K4: 煤层气发电 | M4: 合计 | N4: 余温、余气、余压发电 | O4: 垃圾焚烧发电 | P4: 秸秆、蔗渣、林木质发电 | Q4: 沼气 | R4: 技改增容
A5: 全国 | X5: =B5-C5-E5-S5-T5-U5-V5 -> 0 | Y5: =E5-F5-I5-L5-M5 -> 0 | Z5: =M5-N5-O5-P5 -> 0
A6: 北京 | X6: =B6-C6-E6-S6-T6-U6-V6 -> 0 | Y6: =E6-F6-I6-L6-M6 -> 0 | Z6: =M6-N6-O6-P6 -> 0
A7: 天津 | X7: =B7-C7-E7-S7-T7-U7-V7 -> 0 | Y7: =E7-F7-I7-L7-M7 -> 0 | Z7: =M7-N7-O7-P7 -> 0
A8: 河北 | X8: =B8-C8-E8-S8-T8-U8-V8 -> 0 | Y8: =E8-F8-I8-L8-M8 -> 0 | Z8: =M8-N8-O8-P8 -> 0
A9: 山西 | X9: =B9-C9-E9-S9-T9-U9-V9 -> 0 | Y9: =E9-F9-I9-L9-M9 -> 0 | Z9: =M9-N9-O9-P9 -> 0
A10: 内蒙古 | X10: =B10-C10-E10-S10-T10-U10-V10 -> 0 | Y10: =E10-F10-I10-L10-M10 -> 0 | Z10: =M10-N10-O10-P10 -> 0
A11: 辽宁 | X11: =B11-C11-E11-S11-T11-U11-V11 -> 0 | Y11: =E11-F11-I11-L11-M11 -> 0 | Z11: =M11-N11-O11-P11 -> 0
A12: 吉林 | X12: =B12-C12-E12-S12-T12-U12-V12 -> 0 | Y12: =E12-F12-I12-L12-M12 -> 0 | Z12: =M12-N12-O12-P12 -> 0
A13: 黑龙江 | X13: =B13-C13-E13-S13-T13-U13-V13 -> 0 | Y13: =E13-F13-I13-L13-M13 -> 0 | Z13: =M13-N13-O13-P13 -> 0
A14: 上海 | X14: =B14-C14-E14-S14-T14-U14-V14 -> 0 | Y14: =E14-F14-I14-L14-M14 -> 0 | Z14: =M14-N14-O14-P14 -> 0
A15: 江苏 | X15: =B15-C15-E15-S15-T15-U15-V15 -> 0 | Y15: =E15-F15-I15-L15-M15 -> 0 | Z15: =M15-N15-O15-P15 -> 0
A16: 浙江 | X16: =B16-C16-E16-S16-T16-U16-V16 -> 0 | Y16: =E16-F16-I16-L16-M16 -> 0 | Z16: =M16-N16-O16-P16 -> 0
... A36: 新疆 | X36: =B36-C36-E36-S36-T36-U36-V36 -> 0 | Y36: =E36-F36-I36-L36-M36 -> 0 | Z36: =M36-N36-O36-P36 -> 0
B38: =B5-SUM(B6:B36) -> 0 | C38: =C5-SUM(C6:C36) -> 0 | D38: =D5-SUM(D6:D36) -> 0 | E38: =E5-SUM(E6:E36) -> 0 | F38: =F5-SUM(F6:F36) -> 0 | H38: =H5-SUM(H6:H36) -> 0 | I38: =I5-SUM(I6:I36) -> 0 | J38: =J5-SUM(J6:J36) -> 0 | K38: =K5-SUM(K6:K36) -> 0 | L38: =L5-SUM(L6:L36) -> 0 | M38: =M5-SUM(M6:M36) -> 0 | N38: =N5-SUM(N6:N36) -> 0 | O38: =O5-SUM(O6:O36) -> 0 | P38: =P5-SUM(P6:P36) -> 0 | S38: =S5-SUM(S6:S36) -> 0 | T38: =T5-SUM(T6:T36) -> 0 | U38: =U5-SUM(U6:U36) -> 0 | V38: =V5-SUM(V6:V36) -> 0

Sheet 2012
A1: 分地区新增发电装机容量（万KW）
A2: 地区 | B2: 合计 | C2: 水电 | E2: 火电 | S2: 核电 | T2: 风电 | U2: 太阳能发电 | V2: 其他
C3: 合计 | D3: 抽水蓄能 | E3: 合计 | F3: 燃煤 | I3: 燃气 | L3: 燃油 | M3: 其他
F4: 合计 | G4: 常规燃煤 | H4: 煤矸石发电 | I4: 合计 | J4: 常规燃气 | K4: 煤层气发电 | M4: 合计 | N4: 余温、余气、余压发电 | O4: 垃圾焚烧发电 | P4: 秸秆、蔗渣、林木质发电 | Q4: 沼气 | R4: 技改增容
A5: 全国 | X5: =B5-C5-E5-S5-T5-U5-V5 -> 0 | Y5: =E5-F5-I5-L5-M5 -> 0 | Z5: =M5-N5-O5-P5 -> 0
A6: 北京 | X6: =B6-C6-E6-S6-T6-U6-V6 -> 0 | Y6: =E6-F6-I6-L6-M6 -> 0 | Z6: =M6-N6-O6-P6 -> 0
A7: 天津 | X7: =B7-C7-E7-S7-T7-U7-V7 -> 0 | Y7: =E7-F7-I7-L7-M7 -> 0 | Z7: =M7-N7-O7-P7 -> 0
A8: 河北 | X8: =B8-C8-E8-S8-T8-U8-V8 -> 0 | Y8: =E8-F8-I8-L8-M8 -> 0 | Z8: =M8-N8-O8-P8 -> 0
A9: 山西 | X9: =B9-C9-E9-S9-T9-U9-V9 -> 0 | Y9: =E9-F9-I9-L9-M9 -> 0 | Z9: =M9-N9-O9-P9 -> 0
A10: 内蒙古 | X10: =B10-C10-E10-S10-T10-U10-V10 -> 0 | Y10: =E10-F10-I10-L10-M10 -> 0 | Z10: =M10-N10-O10-P10 -> 0
A11: 辽宁 | X11: =B11-C11-E11-S11-T11-U11-V11 -> 0 | Y11: =E11-F11-I11-L11-M11 -> 0 | Z11: =M11-N11-O11-P11 -> 0
A12: 吉林 | X12: =B12-C12-E12-S12-T12-U12-V12 -> 0 | Y12: =E12-F12-I12-L12-M12 -> 0 | Z12: =M12-N12-O12-P12 -> 0
A13: 黑龙江 | X13: =B13-C13-E13-S13-T13-U13-V13 -> 0 | Y13: =E13-F13-I13-L13-M13 -> 0 | Z13: =M13-N13-O13-P13 -> 0
A14: 上海 | X14: =B14-C14-E14-S14-T14-U14-V14 -> 0 | Y14: =E14-F14-I14-L14-M14 -> 0 | Z14: =M14-N14-O14-P14 -> 0
A15: 江苏 | X15: =B15-C15-E15-S15-T15-U15-V15 -> 0 | Y15: =E15-F15-I15-L15-M15 -> 0 | Z15: =M15-N15-O15-P15 -> 0
A16: 浙江 | X16: =B16-C16-E16-S16-T16-U16-V16 -> 0 | Y16: =E16-F16-I16-L16-M16 -> 0 | Z16: =M16-N16-O16-P16 -> 0
... A36: 新疆 | X36: =B36-C36-E36-S36-T36-U36-V36 -> 0 | Y36: =E36-F36-I36-L36-M36 -> 0 | Z36: =M36-N36-O36-P36 -> 0
B38: =B5-SUM(B6:B36) -> 0 | C38: =C5-SUM(C6:C36) -> 0 | D38: =D5-SUM(D6:D36) -> 0 | E38: =E5-SUM(E6:E36) -> 0 | F38: =F5-SUM(F6:F36) -> 0 | H38: =H5-SUM(H6:H36) -> 0 | I38: =I5-SUM(I6:I36) -> 0 | J38: =J5-SUM(J6:J36) -> 0 | K38: =K5-SUM(K6:K36) -> 0 | L38: =L5-SUM(L6:L36) -> 0 | M38: =M5-SUM(M6:M36) -> 0 | N38: =N5-SUM(N6:N36) -> 0 | O38: =O5-SUM(O6:O36) -> 0 | P38: =P5-SUM(P6:P36) -> 0 | S38: =S5-SUM(S6:S36) -> 0 | T38: =T5-SUM(T6:T36) -> 0 | U38: =U5-SUM(U6:U36) -> 0 | V38: =V5-SUM(V6:V36) -> 0

Sheet 2013
A1: 分地区新增发电装机容量（万KW）
A2: 地区 | B2: 合计 | C2: 水电 | E2: 火电 | S2: 核电 | T2: 风电 | U2: 太阳能发电 | V2: 其他
C3: 合计 | D3: 抽水蓄能 | E3: 合计 | F3: 燃煤 | I3: 燃气 | L3: 燃油 | M3: 其他
F4: 合计 | G4: 常规燃煤 | H4: 煤矸石发电 | I4: 合计 | J4: 常规燃气 | K4: 煤层气发电 | M4: 合计 | N4: 余温、余气、余压发电 | O4: 垃圾焚烧发电 | P4: 秸秆、蔗渣、林木质发电 | Q4: 沼气 | R4: 技改增容
A5: 全国 | X5: =B5-C5-E5-S5-T5-U5-V5 -> 0 | Y5: =E5-F5-I5-L5-M5 -> 0 | Z5: =M5-N5-O5-P5 -> 0
A6: 北京 | X6: =B6-C6-E6-S6-T6-U6-V6 -> 0 | Y6: =E6-F6-I6-L6-M6 -> 0 | Z6: =M6-N6-O6-P6 -> 0
A7: 天津 | X7: =B7-C7-E7-S7-T7-U7-V7 -> 0 | Y7: =E7-F7-I7-L7-M7 -> 0 | Z7: =M7-N7-O7-P7 -> 0
A8: 河北 | X8: =B8-C8-E8-S8-T8-U8-V8 -> 0 | Y8: =E8-F8-I8-L8-M8 -> 0 | Z8: =M8-N8-O8-P8 -> 0
A9: 山西 | X9: =B9-C9-E9-S9-T9-U9-V9 -> 0 | Y9: =E9-F9-I9-L9-M9 -> 0 | Z9: =M9-N9-O9-P9 -> 0
A10: 内蒙古 | X10: =B10-C10-E10-S10-T10-U10-V10 -> 0 | Y10: =E10-F10-I10-L10-M10 -> 0 | Z10: =M10-N10-O10-P10 -> 0
A11: 辽宁 | X11: =B11-C11-E11-S11-T11-U11-V11 -> 0 | Y11: =E11-F11-I11-L11-M11 -> 0 | Z11: =M11-N11-O11-P11 -> 0
A12: 吉林 | X12: =B12-C12-E12-S12-T12-U12-V12 -> 0 | Y12: =E12-F12-I12-L12-M12 -> 0 | Z12: =M12-N12-O12-P12 -> 0
A13: 黑龙江 | X13: =B13-C13-E13-S13-T13-U13-V13 -> 0 | Y13: =E13-F13-I13-L13-M13 -> 0 | Z13: =M13-N13-O13-P13 -> 0
A14: 上海 | X14: =B14-C14-E14-S14-T14-U14-V14 -> 0 | Y14: =E14-F14-I14-L14-M14 -> 0 | Z14: =M14-N14-O14-P14 -> 0
A15: 江苏 | X15: =B15-C15-E15-S15-T15-U15-V15 -> 0 | Y15: =E15-F15-I15-L15-M15 -> 0 | Z15: =M15-N15-O15-P15 -> 0
A16: 浙江 | X16: =B16-C16-E16-S16-T16-U16-V16 -> 0 | Y16: =E16-F16-I16-L16-M16 -> 0 | Z16: =M16-N16-O16-P16 -> 0
... A36: 新疆 | X36: =B36-C36-E36-S36-T36-U36-V36 -> 0 | Y36: =E36-F36-I36-L36-M36 -> 0 | Z36: =M36-N36-O36-P36 -> 0
B38: =B5-SUM(B6:B36) -> 0 | C38: =C5-SUM(C6:C36) -> 0 | D38: =D5-SUM(D6:D36) -> 0 | E38: =E5-SUM(E6:E36) -> 0 | F38: =F5-SUM(F6:F36) -> 0 | H38: =H5-SUM(H6:H36) -> 0 | I38: =I5-SUM(I6:I36) -> 0 | J38: =J5-SUM(J6:J36) -> 0 | L38: =L5-SUM(L6:L36) -> 0 | M38: =M5-SUM(M6:M36) -> 0 | N38: =N5-SUM(N6:N36) -> 0 | O38: =O5-SUM(O6:O36) -> 0 | P38: =P5-SUM(P6:P36) -> 0 | S38: =S5-SUM(S6:S36) -> 0 | T38: =T5-SUM(T6:T36) -> 0 | U38: =U5-SUM(U6:U36) -> 0 | V38: =V5-SUM(V6:V36) -> 0

Sheet 2014
A1: 分地区新增发电装机容量（万KW）
A2: 地区 | B2: 合计 | C2: 水电 | E2: 火电 | S2: 核电 | T2: 风电 | U2: 太阳能发电 | V2: 其他
C3: 合计 | D3: 抽水蓄能 | E3: 合计 | F3: 燃煤 | I3: 燃气 | L3: 燃油 | M3: 其他
F4: 合计 | G4: 常规燃煤 | H4: 煤矸石发电 | I4: 合计 | J4: 常规燃气 | K4: 煤层气发电 | M4: 合计 | N4: 余温、余气、余压发电 | O4: 垃圾焚烧发电 | P4: 秸秆、蔗渣、林木质发电 | Q4: 沼气 | R4: 技改增容
A5: 全国 | X5: =B5-C5-E5-S5-T5-U5-V5 -> 0 | Y5: =E5-F5-I5-L5-M5 -> 0 | Z5: =M5-N5-O5-P5 -> 0
A6: 北京 | X6: =B6-C6-E6-S6-T6-U6-V6 -> 0 | Y6: =E6-F6-I6-L6-M6 -> 0 | Z6: =M6-N6-O6-P6 -> 0
A7: 天津 | X7: =B7-C7-E7-S7-T7-U7-V7 -> 0 | Y7: =E7-F7-I7-L7-M7 -> 0 | Z7: =M7-N7-O7-P7 -> 0
A8: 河北 | X8: =B8-C8-E8-S8-T8-U8-V8 -> 0 | Y8: =E8-F8-I8-L8-M8 -> 0 | Z8: =M8-N8-O8-P8 -> 0
A9: 山西 | X9: =B9-C9-E9-S9-T9-U9-V9 -> 0 | Y9: =E9-F9-I9-L9-M9 -> 0 | Z9: =M9-N9-O9-P9 -> 0
A10: 内蒙古 | X10: =B10-C10-E10-S10-T10-U10-V10 -> 0 | Y10: =E10-F10-I10-L10-M10 -> 0 | Z10: =M10-N10-O10-P10 -> 0
A11: 辽宁 | X11: =B11-C11-E11-S11-T11-U11-V11 -> 0 | Y11: =E11-F11-I11-L11-M11 -> 0 | Z11: =M11-N11-O11-P11 -> 0
A12: 吉林 | X12: =B12-C12-E12-S12-T12-U12-V12 -> 0 | Y12: =E12-F12-I12-L12-M12 -> 0 | Z12: =M12-N12-O12-P12 -> 0
A13: 黑龙江 | X13: =B13-C13-E13-S13-T13-U13-V13 -> 0 | Y13: =E13-F13-I13-L13-M13 -> 0 | Z13: =M13-N13-O13-P13 -> 0
A14: 上海 | X14: =B14-C14-E14-S14-T14-U14-V14 -> 0 | Y14: =E14-F14-I14-L14-M14 -> 0 | Z14: =M14-N14-O14-P14 -> 0
A15: 江苏 | X15: =B15-C15-E15-S15-T15-U15-V15 -> 0 | Y15: =E15-F15-I15-L15-M15 -> 0 | Z15: =M15-N15-O15-P15 -> 0
A16: 浙江 | X16: =B16-C16-E16-S16-T16-U16-V16 -> 0 | Y16: =E16-F16-I16-L16-M16 -> 0 | Z16: =M16-N16-O16-P16 -> 0
... A36: 新疆 | X36: =B36-C36-E36-S36-T36-U36-V36 -> 0 | Y36: =E36-F36-I36-L36-M36 -> 0 | Z36: =M36-N36-O36-P36 -> 0
B38: =B5-SUM(B6:B36) -> 0 | C38: =C5-SUM(C6:C36) -> 0 | D38: =D5-SUM(D6:D36) -> 0 | E38: =E5-SUM(E6:E36) -> 0 | F38: =F5-SUM(F6:F36) -> 0 | H38: =H5-SUM(H6:H36) -> 0 | I38: =I5-SUM(I6:I36) -> 0 | J38: =J5-SUM(J6:J36) -> 0 | L38: =L5-SUM(L6:L36) -> 0 | M38: =M5-SUM(M6:M36) -> 0 | N38: =N5-SUM(N6:N36) -> 0 | O38: =O5-SUM(O6:O36) -> 0 | P38: =P5-SUM(P6:P36) -> 0 | S38: =S5-SUM(S6:S36) -> 0 | T38: =T5-SUM(T6:T36) -> 0 | U38: =U5-SUM(U6:U36) -> 0 | V38: =V5-SUM(V6:V36) -> 0

Sheet 2015
A1: 分地区新增发电装机容量（万KW）
A2: 地区 | B2: 合计 | C2: 水电 | E2: 火电 | S2: 核电 | T2: 风电 | U2: 太阳能发电 | V2: 其他
C3: 合计 | D3: 抽水蓄能 | E3: 合计 | F3: 燃煤 | I3: 燃气 | L3: 燃油 | M3: 其他
F4: 合计 | G4: 常规燃煤 | H4: 煤矸石发电 | I4: 合计 | J4: 常规燃气 | K4: 煤层气发电 | M4: 合计 | N4: 余温、余气、余压发电 | O4: 垃圾焚烧发电 | P4: 秸秆、蔗渣、林木质发电 | Q4: 沼气 | R4: 技改增容
A5: 全国 | X5: =B5-C5-E5-S5-T5-U5-V5 -> 0 | Y5: =E5-F5-I5-L5-M5 -> 0 | Z5: =M5-N5-O5-P5 -> 0
A6: 北京 | X6: =B6-C6-E6-S6-T6-U6-V6 -> 0 | Y6: =E6-F6-I6-L6-M6 -> 0 | Z6: =M6-N6-O6-P6 -> 0
A7: 天津 | X7: =B7-C7-E7-S7-T7-U7-V7 -> 0 | Y7: =E7-F7-I7-L7-M7 -> 0 | Z7: =M7-N7-O7-P7 -> 0
A8: 河北 | X8: =B8-C8-E8-S8-T8-U8-V8 -> 0 | Y8: =E8-F8-I8-L8-M8 -> 0 | Z8: =M8-N8-O8-P8 -> 0
A9: 山西 | X9: =B9-C9-E9-S9-T9-U9-V9 -> 0 | Y9: =E9-F9-I9-L9-M9 -> 0 | Z9: =M9-N9-O9-P9 -> 0
A10: 内蒙古 | X10: =B10-C10-E10-S10-T10-U10-V10 -> 0 | Y10: =E10-F10-I10-L10-M10 -> 0 | Z10: =M10-N10-O10-P10 -> 0
A11: 辽宁 | X11: =B11-C11-E11-S11-T11-U11-V11 -> 0 | Y11: =E11-F11-I11-L11-M11 -> 0 | Z11: =M11-N11-O11-P11 -> 0
A12: 吉林 | X12: =B12-C12-E12-S12-T12-U12-V12 -> 0 | Y12: =E12-F12-I12-L12-M12 -> 0 | Z12: =M12-N12-O12-P12 -> 0
A13: 黑龙江 | X13: =B13-C13-E13-S13-T13-U13-V13 -> 0 | Y13: =E13-F13-I13-L13-M13 -> 0 | Z13: =M13-N13-O13-P13 -> 0
A14: 上海 | X14: =B14-C14-E14-S14-T14-U14-V14 -> 0 | Y14: =E14-F14-I14-L14-M14 -> 0 | Z14: =M14-N14-O14-P14 -> 0
A15: 江苏 | X15: =B15-C15-E15-S15-T15-U15-V15 -> 0 | Y15: =E15-F15-I15-L15-M15 -> 0 | Z15: =M15-N15-O15-P15 -> 0
A16: 浙江 | X16: =B16-C16-E16-S16-T16-U16-V16 -> 0 | Y16: =E16-F16-I16-L16-M16 -> 0 | Z16: =M16-N16-O16-P16 -> 0
... A36: 新疆 | X36: =B36-C36-E36-S36-T36-U36-V36 -> 0 | Y36: =E36-F36-I36-L36-M36 -> 0 | Z36: =M36-N36-O36-P36 -> 0
B38: =B5-SUM(B6:B36) -> 0 | C38: =C5-SUM(C6:C36) -> 0 | D38: =D5-SUM(D6:D36) -> 0 | E38: =E5-SUM(E6:E36) -> 0 | F38: =F5-SUM(F6:F36) -> 0 | H38: =H5-SUM(H6:H36) -> 0 | I38: =I5-SUM(I6:I36) -> 0 | J38: =J5-SUM(J6:J36) -> 0 | L38: =L5-SUM(L6:L36) -> 0 | M38: =M5-SUM(M6:M36) -> 0 | N38: =N5-SUM(N6:N36) -> 0 | O38: =O5-SUM(O6:O36) -> 0 | P38: =P5-SUM(P6:P36) -> 0 | S38: =S5-SUM(S6:S36) -> 0 | T38: =T5-SUM(T6:T36) -> 0 | U38: =U5-SUM(U6:U36) -> 0 | V38: =V5-SUM(V6:V36) -> 0

Sheet 2016
A1: 分地区新增发电装机容量（万KW）
A2: 地区 | B2: 合计 | C2: 水电 | E2: 火电 | S2: 核电 | T2: 风电 | U2: 太阳能发电 | V2: 其他
C3: 合计 | D3: 抽水蓄能 | E3: 合计 | F3: 燃煤 | I3: 燃气 | L3: 燃油 | M3: 其他 | AB3: 万千瓦 | AC3: 合计 | AD3: 水 | AE3: 火 | AF3: 风 | AG3: 光
F4: 合计 | G4: 常规燃煤 | H4: 煤矸石发电 | I4: 合计 | J4: 常规燃气 | K4: 煤层气发电 | M4: 合计 | N4: 余温、余气、余压发电 | O4: 垃圾焚烧发电 | P4: 秸秆、蔗渣、林木质发电 | Q4: 沼气 | R4: 技改增容 | AB4: 地区 | AC4: 2016 年 | AD4: 2016 年 | AE4: 2016 年 | AF4: 2016 年 | AG4: 2016 年
A5: 全国 | B5: 160522 | C5: 30010 | E5: 105580 | F5: 94654 | I5: 7011 | L5: 210 | M5: 4220 | O5: 576 | P5: 776 | Q5: 45 | S5: 3364 | T5: 14744 | U5: 6819 | V5: 5 | X5: =B5-C5-E5-S5-T5-U5-V5 -> 0 | Y5: =E5-F5-I5-L5-M5 -> -515 | Z5: =M5-N5-O5-P5 -> 2868 | AB5: 全国 | AC5: 12143 | AD5: 1179 | AE5: 5048 | AF5: 2024 | AG5: 3171 | AH5: =AC5-AD5-AE5-AF5-AG5 -> 721
A6: 北京 | B6: 1092 | C6: 98 | E6: 970 | F6: 85 | I6: 850 | L6: 22 | M6: 15 | O6: 13 | Q6: 1 | T6: 19 | U6: 5 | X6: =B6-C6-E6-S6-T6-U6-V6 -> 0 | Y6: =E6-F6-I6-L6-M6 -> -2 | Z6: =M6-N6-O6-P6 -> 2 | AB6: 北京 | AC6: 32 | AE6: 6 | AF6: 7 | AG6: 18 | AH6: =AC6-AD6-AE6-AF6-AG6 -> 1
A7: 天津 | B7: 1458 | E7: 1377 | F7: 1076 | I7: 277 | M7: 25 | O7: 10 | T7: 28 | U7: 54 | X7: =B7-C7-E7-S7-T7-U7-V7 -> -1 | Y7: =E7-F7-I7-L7-M7 -> -1 | Z7: =M7-N7-O7-P7 -> 15 | AB7: 天津 | AC7: 143 | AE7: 95 | AG7: 48 | AH7: =AC7-AD7-AE7-AF7-AG7 -> 0
A8: 河北 | B8: 6211 | C8: 165 | E8: 4503 | F8: 4251 | I8: 3 | M8: 257 | O8: 16 | P8: 38 | Q8: 1 | T8: 1138 | U8: 404 | V8: 2 | X8: =B8-C8-E8-S8-T8-U8-V8 -> -1 | Y8: =E8-F8-I8-L8-M8 -> -8 | Z8: =M8-N8-O8-P8 -> 203 | AB8: 河北 | AC8: 631 | AE8: 170 | AF8: 228 | AG8: 232 | AH8: =AC8-AD8-AE8-AF8-AG8 -> 1
A9: 山西 | B9: 7599 | C9: 235 | E9: 6309 | F9: 6003 | I9: 279 | M9: 46 | O9: 11 | P9: 19 | Q9: 15 | T9: 771 | U9: 284 | X9: =B9-C9-E9-S9-T9-U9-V9 -> 0 | Y9: =E9-F9-I9-L9-M9 -> -19 | Z9: =M9-N9-O9-P9 -> 16 | AB9: 山西 | AC9: 793 | AE9: 374 | AF9: 173 | AG9: 246 | AH9: =AC9-AD9-AE9-AF9-AG9 -> 0
A10: 内蒙古 | B10: 11030 | C10: 238 | E10: 7601 | F10: 7542 | I10: 42 | M10: 25 | O10: 4 | P10: 12 | T10: 2556 | U10: 636 | X10: =B10-C10-E10-S10-T10-U10-V10 -> -1 | Y10: =E10-F10-I10-L10-M10 -> -8 | Z10: =M10-N10-O10-P10 -> 9 | AB10: 内蒙古 | AC10: 473 | AE10: 366 | AF10: 81 | AG10: 26 | AH10: =AC10-AD10-AE10-AF10-AG10 -> 0
A11: 辽宁 | B11: 4572 | C11: 277 | E11: 3109 | F11: 3024 | I11: 4 | L11: 15 | M11: 72 | O11: 3 | P11: 5 | S11: 448 | T11: 694 | U11: 45 | X11: =B11-C11-E11-S11-T11-U11-V11 -> -1 | Y11: =E11-F11-I11-L11-M11 -> -6 | Z11: =M11-N11-O11-P11 -> 64 | AB11: 辽宁 | AC11: 147 | AE11: 1 | AF11: 14 | AG11: 21 | AH11: =AC11-AD11-AE11-AF11-AG11 -> 111
A12: 吉林 | B12: 2684 | C12: 353 | E12: 1775 | F12: 1688 | I12: 0 | M12: 88 | O12: 12 | P12: 40 | Q12: 0 | T12: 505 | U12: 52 | X12: =B12-C12-E12-S12-T12-U12-V12 -> -1 | Y12: =E12-F12-I12-L12-M12 -> -1 | Z12: =M12-N12-O12-P12 -> 36 | AB12: 吉林 | AC12: 84 | AE12: 11 | AF12: 22 | AG12: 52 | AH12: =AC12-AD12-AE12-AF12-AG12 -> -1
A13: 黑龙江 | B13: 2767 | C13: 95 | E13: 2099 | F13: 1991 | I13: 12 | L13: 2 | M13: 99 | O13: 7 | P13: 73 | Q13: 0 | T13: 561 | U13: 12 | X13: =B13-C13-E13-S13-T13-U13-V13 -> 0 | Y13: =E13-F13-I13-L13-M13 -> -5 | Z13: =M13-N13-O13-P13 -> 19 | AB13: 黑龙江 | AC13: 139 | AE13: 59 | AF13: 66 | AG13: 14 | AH13: =AC13-AD13-AE13-AF13-AG13 -> 0
A14: 上海 | B14: 2341 | E14: 2263 | F14: 1509 | I14: 570 | L14: 86 | M14: 98 | O14: 22 | Q14: 2 | T14: 71 | U14: 7 | X14: =B14-C14-E14-S14-T14-U14-V14 -> 0 | Y14: =E14-F14-I14-L14-M14 -> 0 | Z14: =M14-N14-O14-P14 -> 76 | AB14: 上海 | AC14: 45 | AE14: 11 | AF14: 20 | AG14: 15 | AH14: =AC14-AD14-AE14-AF14-AG14 -> -1
A15: 江苏 | B15: 9987 | C15: 110 | E15: 8711 | F15: 7448 | I15: 957 | M15: 322 | O15: 79 | P15: 44 | Q15: 2 | S15: 212 | T15: 561 | U15: 394 | X15: =B15-C15-E15-S15-T15-U15-V15 -> -1 | Y15: =E15-F15-I15-L15-M15 -> -16 | Z15: =M15-N15-O15-P15 -> 199 | AB15: 江苏 | AC15: 645 | AE15: 380 | AF15: 95 | AG15: 170 | AH15: =AC15-AD15-AE15-AF15-AG15 -> 0
A16: 浙江 | B16: 7927 | C16: 939 | E16: 6044 | F16: 4629 | I16: 1228 | L16: 6 | M16: 200 | O16: 102 | P16: 19 | Q16: 1 | S16: 657 | T16: 118 | U16: 169 | X16: =B16-C16-E16-S16-T16-U16-V16 -> 0 | Y16: =E16-F16-I16-L16-M16 -> -19 | Z16: =M16-N16-O16-P16 -> 79 | AB16: 浙江 | AC16: 496 | AD16: 177 | AE16: 64 | AF16: 27 | AG16: 228 | AH16: =AC16-AD16-AE16-AF16-AG16 -> 0
A17: 安徽 | B17: 5598 | C17: 241 | E17: 4894 | F17: 4669 | I17: 11 | M17: 236 | O17: 29 | P17: 66 | Q17: 1 | T17: 177 | U17: 287 | X17: =B17-C17-E17-S17-T17-U17-V17 -> -1 | Y17: =E17-F17-I17-L17-M17 -> -22 | Z17: =M17-N17-O17-P17 -> 141 | AB17: 安徽 | AC17: 503 | AD17: 5 | AE17: 301 | AF17: 45 | AG17: 153 | AH17: =AC17-AD17-AE17-AF17-AG17 -> -1
A18: 福建 | B18: 4807 | C18: 918 | E18: 2893 | F18: 2394 | I18: 387 | M18: 121 | O18: 30 | P18: 5 | Q18: 1 | S18: 762 | T18: 214 | U18: 20 | X18: =B18-C18-E18-S18-T18-U18-V18 -> 0 | Y18: =E18-F18-I18-L18-M18 -> -9 | Z18: =M18-N18-O18-P18 -> 86 | AB18: 福建 | AC18: 338 | AD18: 6 | AE18: 33 | AF18: 62 | AG18: 20 | AH18: =AC18-AD18-AE18-AF18-AG18 -> 217
A19: 江西 | B19: 2610 | C19: 412 | E19: 1913 | F19: 1721 | I19: 10 | M19: 187 | O19: 7 | P19: 20 | Q19: 0 | T19: 108 | U19: 178 | X19: =B19-C19-E19-S19-T19-U19-V19 -> -1 | Y19: =E19-F19-I19-L19-M19 -> -5 | Z19: =M19-N19-O19-P19 -> 160 | AB19: 江西 | AC19: 400 | AD19: 121 | AE19: 115 | AF19: 27 | AG19: 137 | AH19: =AC19-AD19-AE19-AF19-AG19 -> 0
A20: 山东 | B20: 10817 | C20: 101 | E20: 9521 | F20: 9015 | I20: 6 | M20: 519 | O20: 56 | P20: 117 | Q20: 6 | T20: 839 | U20: 356 | X20: =B20-C20-E20-S20-T20-U20-V20 -> 0 | Y20: =E20-F20-I20-L20-M20 -> -19 | Z20: =M20-N20-O20-P20 -> 346 | AB20: 山东 | AC20: 1281 | AE20: 883 | AF20: 111 | AG20: 286 | AH20: =AC20-AD20-AE20-AF20-AG20 -> 1
A21: 河南 | B21: 7165 | C21: 389 | E21: 6422 | F21: 6164 | I21: 161 | M21: 106 | O21: 8 | P21: 39 | T21: 104 | U21: 250 | X21: =B21-C21-E21-S21-T21-U21-V21 -> 0 | Y21: =E21-F21-I21-L21-M21 -> -9 | Z21: =M21-N21-O21-P21 -> 59 | AB21: 河南 | AC21: 387 | AE21: 102 | AF21: 34 | AG21: 250 | AH21: =AC21-AD21-AE21-AF21-AG21 -> 1
A22: 湖北 | B22: 6604 | C22: 3552 | E22: 2685 | F22: 2405 | I22: 76 | M22: 213 | O22: 21 | P22: 43 | Q22: 1 | T22: 201 | U22: 166 | X22: =B22-C22-E22-S22-T22-U22-V22 -> 0 | Y22: =E22-F22-I22-L22-M22 -> -9 | Z22: =M22-N22-O22-P22 -> 149 | AB22: 湖北 | AC22: 376 | AD22: 13 | AE22: 122 | AF22: 83 | AG22: 158 | AH22: =AC22-AD22-AE22-AF22-AG22 -> 0
A23: 湖南 | B23: 3774 | C23: 1236 | E23: 2311 | F23: 2113 | I23: 10 | L23: 7 | M23: 191 | O23: 10 | P23: 21 | Q23: 9 | T23: 217 | U23: 10 | X23: =B23-C23-E23-S23-T23-U23-V23 -> 0 | Y23: =E23-F23-I23-L23-M23 -> -10 | Z23: =M23-N23-O23-P23 -> 160 | AB23: 湖南 | AC23: 135 | AD23: 27 | AE23: 9 | AF23: 86 | AG23: 13 | AH23: =AC23-AD23-AE23-AF23-AG23 -> 0
A24: 广东 | B24: 9933 | C24: 954 | E24: 7709 | F24: 5992 | I24: 1569 | L24: 33 | M24: 128 | O24: 62 | P24: 16 | Q24: 4 | S24: 938 | T24: 268 | U24: 63 | V24: 1 | X24: =B24-C24-E24-S24-T24-U24-V24 -> 0 | Y24: =E24-F24-I24-L24-M24 -> -13 | Z24: =M24-N24-O24-P24 -> 50 | AB24: 广东 | AC24: 300 | AD24: 96 | AE24: 60 | AF24: 16 | AG24: 19 | AH24: =AC24-AD24-AE24-AF24-AG24 -> 109
A25: 广西 | B25: 3931 | C25: 1493 | E25: 2140 | F25: 1615 | I25: 12 | M25: 558 | O25: 8 | P25: 155 | S25: 217 | T25: 70 | U25: 12 | X25: =B25-C25-E25-S25-T25-U25-V25 -> -1 | Y25: =E25-F25-I25-L25-M25 -> -45 | Z25: =M25-N25-O25-P25 -> 395 | AB25: 广西 | AC25: 798 | AD25: 14 | AE25: 528 | AF25: 35 | AG25: 4 | AH25: =AC25-AD25-AE25-AF25-AG25 -> 217
A26: 海南 | B26: 711 | C26: 62 | E26: 463 | F26: 376 | I26: 72 | M26: 16 | O26: 7 | Q26: 0 | S26: 130 | T26: 31 | U26: 24 | X26: =B26-C26-E26-S26-T26-U26-V26 -> 1 | Y26: =E26-F26-I26-L26-M26 -> -1 | Z26: =M26-N26-O26-P26 -> 9 | AB26: 海南 | AC26: 66 | AG26: 1 | AH26: =AC26-AD26-AE26-AF26-AG26 -> 65
A27: 重庆 | B27: 2066 | C27: 581 | E27: 1457 | F27: 1256 | I27: 162 | M27: 44 | O27: 10 | P27: 4 | Q27: 0 | T27: 28 | X27: =B27-C27-E27-S27-T27-U27-V27 -> 0 | Y27: =E27-F27-I27-L27-M27 -> -5 | Z27: =M27-N27-O27-P27 -> 30 | AB27: 重庆 | AC27: 154 | AD27: 11 | AE27: 132 | AF27: 10 | AG27: 1 | AH27: =AC27-AD27-AE27-AF27-AG27 -> 0
A28: 四川 | B28: 8661 | C28: 6834 | E28: 1608 | F28: 1399 | I28: 122 | M28: 121 | O28: 27 | P28: 3 | T28: 125 | U28: 94 | X28: =B28-C28-E28-S28-T28-U28-V28 -> 0 | Y28: =E28-F28-I28-L28-M28 -> -34 | Z28: =M28-N28-O28-P28 -> 91 | AB28: 四川 | AC28: 489 | AD28: 308 | AE28: 30 | AF28: 68 | AG28: 83 | AH28: =AC28-AD28-AE28-AF28-AG28 -> 0
A29: 贵州 | B29: 5272 | C29: 1850 | E29: 3014 | F29: 3005 | M29: 8 | O29: 2 | P29: 6 | T29: 362 | U29: 46 | X29: =B29-C29-E29-S29-T29-U29-V29 -> 0 | Y29: =E29-F29-I29-L29-M29 -> 1 | Z29: =M29-N29-O29-P29 -> 0 | AB29: 贵州 | AC29: 359 | AD29: 9 | AE29: 318 | AF29: 32 | AH29: =AC29-AD29-AE29-AF29-AG29 -> 0
A30: 云南 | B30: 8236 | C30: 5895 | E30: 1396 | F30: 1301 | I30: 2 | M30: 309 | O30: 10 | P30: 20 | T30: 737 | U30: 208 | X30: =B30-C30-E30-S30-T30-U30-V30 -> 0 | Y30: =E30-F30-I30-L30-M30 -> -216 | Z30: =M30-N30-O30-P30 -> 279 | AB30: 云南 | AC30: 289 | AD30: 180 | AF30: 97 | AG30: 12 | AH30: =AC30-AD30-AE30-AF30-AG30 -> 0
A31: 西藏 | B31: 229 | C31: 153 | E31: 40 | L31: 39 | M31: 2 | T31: 1 | U31: 33 | V31: 2 | X31: =B31-C31-E31-S31-T31-U31-V31 -> 0 | Y31: =E31-F31-I31-L31-M31 -> -1 | Z31: =M31-N31-O31-P31 -> 2 | AB31: 西藏 | AC31: 60 | AD31: 41 | AE31: 3 | AG31: 16 | AH31: =AC31-AD31-AE31-AF31-AG31 -> 0
A32: 陕西 | B32: 3686 | C32: 232 | E32: 3036 | F32: 2997 | M32: 46 | O32: 2 | T32: 179 | U32: 239 | X32: =B32-C32-E32-S32-T32-U32-V32 -> 0 | Y32: =E32-F32-I32-L32-M32 -> -7 | Z32: =M32-N32-O32-P32 -> 44 | AB32: 陕西 | AC32: 450 | AD32: 15 | AE32: 149 | AF32: 91 | AG32: 194 | AH32: =AC32-AD32-AE32-AF32-AG32 -> 1
A33: 甘肃 | B33: 4703 | C33: 743 | E33: 2002 | F33: 1966 | I33: 7 | M33: 29 | O33: 5 | P33: 3 | T33: 1277 | U33: 681 | X33: =B33-C33-E33-S33-T33-U33-V33 -> 0 | Y33: =E33-F33-I33-L33-M33 -> 0 | Z33: =M33-N33-O33-P33 -> 21 | AB33: 甘肃 | AC33: 152 | AD33: 9 | AE33: 40 | AF33: 25 | AG33: 78 | AH33: =AC33-AD33-AE33-AF33-AG33 -> 0
A34: 青海 | B34: 2297 | C34: 1168 | E34: 381 | F34: 370 | I34: 33 | T34: 69 | U34: 680 | X34: =B34-C34-E34-S34-T34-U34-V34 -> -1 | Y34: =E34-F34-I34-L34-M34 -> -22 | Z34: =M34-N34-O34-P34 -> 0 | AB34: 青海 | AC34: 319 | AD34: 46 | AE34: 113 | AF34: 30 | AG34: 131 | AH34: =AC34-AD34-AE34-AF34-AG34 -> -1
A35: 宁夏 | B35: 3670 | C35: 42 | E35: 2164 | F35: 2008 | I35: 81 | M35: 75 | O35: 2 | P35: 5 | T35: 942 | U35: 522 | X35: =B35-C35-E35-S35-T35-U35-V35 -> 0 | Y35: =E35-F35-I35-L35-M35 -> 0 | Z35: =M35-N35-O35-P35 -> 68 | AB35: 宁夏 | AC35: 574 | AE35: 180 | AF35: 177 | AG35: 217 | AH35: =AC35-AD35-AE35-AF35-AG35 -> 0
A36: 新疆 | B36: 8083 | C36: 644 | E36: 4771 | F36: 4642 | I36: 68 | M36: 65 | P36: 3 | T36: 1776 | U36: 892 | X36: =B36-C36-E36-S36-T36-U36-V36 -> 0 | Y36: =E36-F36-I36-L36-M36 -> -4 | Z36: =M36-N36-O36-P36 -> 62 | AB36: 新疆 | AC36: 1085 | AD36: 98 | AE36: 394 | AF36: 262 | AG36: 330 | AH36: =AC36-AD36-AE36-AF36-AG36 -> 1
B38: =B5-SUM(B6:B36) -> 1 | C38: =C5-SUM(C6:C36) -> 0 | D38: =D5-SUM(D6:D36) -> 0 | E38: =E5-SUM(E6:E36) -> -1 | F38: =F5-SUM(F6:F36) -> 0 | H38: =H5-SUM(H6:H36) -> 0 | I38: =I5-SUM(I6:I36) -> 0 | J38: =J5-SUM(J6:J36) -> 0 | L38: =L5-SUM(L6:L36) -> 0 | M38: =M5-SUM(M6:M36) -> -1 | N38: =N5-SUM(N6:N36) -> 0 | O38: =O5-SUM(O6:O36) -> 1 | P38: =P5-SUM(P6:P36) -> 0 | S38: =S5-SUM(S6:S36) -> 0 | T38: =T5-SUM(T6:T36) -> -3 | U38: =U5-SUM(U6:U36) -> -4 | V38: =V5-SUM(V6:V36) -> 0

Sheet 2017
A1: 分地区装机容量（万KW） | X1: 分地区装机容量（万KW）
A2: 地区 | B2: 合计 | C2: 水电 | E2: 火电 | S2: 核电 | T2: 风电 | U2: 太阳能发电 | V2: 其他 | X2: 合计 | Y2: 水电 | Z2: 火电 | AA2: 核电 | AB2: 风电 | AC2: 太阳能发电 | AD2: 其他 | AE2: 分布式太阳能
C3: 合计 | D3: 抽水蓄能 | E3: 合计 | F3: 燃煤 | I3: 燃气 | L3: 燃油 | M3: 其他
F4: 合计 | G4: 常规燃煤 | H4: 煤矸石发电 | I4: 合计 | J4: 常规燃气 | K4: 煤层气发电 | M4: 合计 | N4: 余温、余气、余压发电 | O4: 垃圾焚烧发电 | P4: 秸秆、蔗渣、林木质发电 | Q4: 沼气 | R4: 技改增容
A5: 全国 | B5: 171249 | C5: 31071 | E5: 109992 | F5: 98130 | I5: 7570 | L5: 197 | M5: 4598 | O5: 731 | P5: 872 | Q5: 47 | S5: 3582 | T5: 16322 | U5: 10277 | V5: 5 | X5: 177708 | Y5: 34359 | Z5: 110495 | AA5: 3582 | AB5: 16325 | AC5: 12942 | AD5: 7 | AE5: 3658
A6: 北京 | B6: 1198 | C6: 98 | E6: 1076 | F6: 85 | I6: 950 | L6: 22 | M6: 20 | O6: 20 | Q6: 1 | T6: 19 | U6: 5 | X6: 1219 | Y6: 98 | Z6: 1077 | AB6: 19 | AC6: 25 | AE6: 22
A7: 天津 | B7: 1483 | E7: 1400 | F7: 1072 | I7: 304 | M7: 27 | O7: 10 | T7: 28 | U7: 55 | X7: 1499 | Y7: 1 | Z7: 1402 | AB7: 29 | AC7: 68 | AE7: 15
A8: 河北 | B8: 6576 | C8: 165 | E8: 4566 | F8: 4282 | I8: 3 | M8: 289 | O8: 24 | P8: 44 | Q8: 1 | T8: 1181 | U8: 662 | V8: 2 | X8: 6807 | Y8: 182 | Z8: 4574 | AB8: 1181 | AC8: 868 | AD8: 2 | AE8: 351
A9: 山西 | B9: 7992 | C9: 235 | E9: 6352 | F9: 5887 | I9: 291 | M9: 189 | O9: 11 | P9: 30 | Q9: 9 | T9: 872 | U9: 534 | X9: 8073 | Y9: 244 | Z9: 6366 | AB9: 872 | AC9: 590 | AE9: 60
A10: 内蒙古 | B10: 11810 | C10: 238 | E10: 8162 | F10: 8103 | I10: 42 | M10: 25 | O10: 4 | P10: 12 | T10: 2669 | U10: 740 | X10: 11826 | Y10: 242 | Z10: 8170 | AB10: 2670 | AC10: 743 | AE10: 2
A11: 辽宁 | B11: 4824 | C11: 279 | E11: 3188 | F11: 3093 | I11: 5 | L11: 15 | M11: 80 | O11: 8 | P11: 7 | S11: 448 | T11: 710 | U11: 200 | X11: 4869 | Y11: 295 | Z11: 3193 | AA11: 448 | AB11: 711 | AC11: 223 | AE11: 38
A12: 吉林 | B12: 2804 | C12: 353 | E12: 1817 | F12: 1728 | I12: 0.5 | M12: 91 | O12: 13 | P12: 40 | Q12: 0.3 | T12: 505 | U12: 130 | X12: 2864 | Y12: 380 | Z12: 1820 | AB12: 505 | AC12: 159 | AE12: 52
A13: 黑龙江 | B13: 2936 | C13: 97 | E13: 2197 | F13: 2078 | I13: 12 | L13: 2 | M13: 110 | O13: 8 | P13: 82 | Q13: 0.4 | T13: 570 | U13: 73 | X13: 2969 | Y13: 103 | Z13: 2201 | AB13: 570 | AC13: 94 | AE13: 30
A14: 上海 | B14: 2348 | E14: 2270 | F14: 1509 | I14: 573 | L14: 86 | M14: 102 | O14: 26 | Q14: 2 | T14: 71 | U14: 7 | X14: 2400 | Z14: 2271 | AB14: 71 | AC14: 58 | AE14: 59
A15: 江苏 | B15: 11112 | C15: 260 | E15: 9414 | F15: 7741 | I15: 1348 | M15: 340 | O15: 91 | P15: 50 | Q15: 4 | S15: 212 | T15: 655 | U15: 571 | X15: 11469 | Y15: 265 | Z15: 9430 | AA15: 212 | AB15: 656 | AC15: 907 | AE15: 327
A16: 浙江 | B16: 8175 | C16: 941 | E16: 6117 | F16: 4663 | I16: 1230 | L16: 6 | M16: 235 | O16: 133 | P16: 21 | Q16: 4 | S16: 657 | T16: 132 | U16: 328 | X16: 8899 | Y16: 1160 | Z16: 6134 | AA16: 657 | AB16: 133 | AC16: 814 | AD16: 0.4 | AE16: 499
A17: 安徽 | B17: 6099 | C17: 242 | E17: 5031 | F17: 4760 | I17: 12 | M17: 281 | O17: 43 | P17: 75 | Q17: 1 | T17: 217 | U17: 608 | X17: 6468 | Y17: 310 | Z17: 5053 | AB17: 217 | AC17: 888 | AE17: 323
A18: 福建 | B18: 5164 | C18: 917 | E18: 3064 | F18: 2545 | I18: 390 | L18: 1 | M18: 138 | O18: 39 | P18: 5 | Q18: 0.4 | S18: 871 | T18: 252 | U18: 60 | X18: 5597 | Y18: 1307 | Z18: 3074 | AA18: 871 | AB18: 252 | AC18: 92 | AE18: 109
A19: 江西 | B19: 2796 | C19: 412 | E19: 1928 | F19: 1721 | I19: 10 | M19: 202 | O19: 9 | P19: 20 | Q19: 1 | T19: 169 | U19: 287 | X19: 3167 | Y19: 615 | Z19: 1934 | AB19: 169 | AC19: 449 | AE19: 172
A20: 山东 | B20: 12117 | C20: 101 | E20: 10314 | F20: 9762 | I20: 5 | M20: 567 | O20: 80 | P20: 131 | Q20: 5 | T20: 1061 | U20: 640 | X20: 12556 | Y20: 108 | Z20: 10335 | AB20: 1061 | AC20: 1052 | AE20: 474
A21: 河南 | B21: 7687 | C21: 389 | E21: 6533 | F21: 6239 | I21: 164 | M21: 141 | O21: 6 | P21: 43 | Q21: 4 | T21: 233 | U21: 532 | X21: 7880 | Y21: 399 | Z21: 6544 | AB21: 233 | AC21: 703 | AE21: 211
A22: 湖北 | B22: 6890 | C22: 3558 | E22: 2777 | F22: 2450 | I22: 96 | M22: 241 | O22: 24 | P22: 48 | Q22: 1 | T22: 253 | U22: 301 | X22: 7124 | Y22: 3671 | Z22: 2787 | AB22: 253 | AC22: 413 | AE22: 177
A23: 湖南 | B23: 3879 | C23: 1247 | E23: 2255 | F23: 2053 | I23: 3 | L23: 7 | M23: 204 | O23: 9 | P23: 36 | Q23: 1 | T23: 263 | U23: 113 | X23: 4277 | Y23: 1570 | Z23: 2267 | AB23: 263 | AC23: 176 | AE23: 90
A24: 广东 | B24: 10356 | C24: 989 | E24: 7755 | F24: 6035 | I24: 1571 | L24: 21 | M24: 141 | O24: 77 | P24: 22 | Q24: 7 | S24: 1046 | T24: 335 | U24: 229 | V24: 1 | X24: 10968 | Y24: 1486 | Z24: 7768 | AA24: 1046 | AB24: 335 | AC24: 332 | AD24: 2 | AE24: 122
A25: 广西 | B25: 4114 | C25: 1497 | E25: 2181 | F25: 1797 | I25: 35 | M25: 386 | O25: 9 | P25: 155 | Q25: 2 | S25: 217 | T25: 150 | U25: 69 | X25: 4332 | Y25: 1669 | Z25: 2217 | AA25: 217 | AB25: 150 | AC25: 78 | AE25: 373
A26: 海南 | B26: 745 | C26: 84 | E26: 464 | F26: 376 | I26: 73 | M26: 17 | O26: 8 | Q26: 0.3 | S26: 130 | T26: 34 | U26: 33 | X26: 786 | Y26: 114 | Z26: 465 | AA26: 130 | AB26: 34 | AC26: 43 | AE26: 11
A27: 重庆 | B27: 2209 | C27: 626 | E27: 1540 | F27: 1332 | I27: 168 | M27: 45 | O27: 10 | P27: 7 | Q27: 1 | T27: 33 | U27: 10 | X27: 2326 | Y27: 736 | Z27: 1544 | AB27: 33 | AC27: 12 | AE27: 12
A28: 四川 | B28: 9264 | C28: 7291 | E28: 1630 | F28: 1336 | I28: 126 | M28: 200 | O28: 39 | P28: 3 | Q28: 2 | T28: 210 | U28: 132 | X28: 9721 | Y28: 7714 | Z28: 1662 | AB28: 210 | AC28: 135 | AE28: 19
A29: 贵州 | B29: 5539 | C29: 1880 | E29: 3160 | F29: 3146 | M29: 15 | O29: 9 | P29: 6 | T29: 363 | U29: 135 | X29: 5778 | Y29: 2119 | Z29: 3160 | AB29: 363 | AC29: 135
A30: 云南 | B30: 8545 | C30: 6084 | E30: 1398 | F30: 1301 | I30: 2 | M30: 310 | O30: 12 | P30: 20 | T30: 825 | U30: 238 | X30: 8957 | Y30: 6281 | Z30: 1613 | AB30: 825 | AC30: 238 | AE30: 0.5
A31: 西藏 | B31: 276 | C31: 155 | E31: 39 | L31: 38 | M31: 2 | T31: 1 | U31: 79 | V31: 2 | X31: 281 | Y31: 158 | Z31: 40 | AB31: 1 | AC31: 79 | AD31: 3
A32: 陕西 | B32: 4100 | C32: 269 | E32: 3137 | F32: 3087 | M32: 56 | O32: 3 | P32: 3 | T32: 288 | U32: 406 | X32: 4192 | Y32: 326 | Z32: 3144 | AB32: 288 | AC32: 434 | AE32: 51
A33: 甘肃 | B33: 4861 | C33: 751 | E33: 2059 | F33: 2020 | I33: 6 | M33: 33 | O33: 6 | P33: 3 | T33: 1282 | U33: 769 | X33: 4995 | Y33: 868 | Z33: 2059 | AB33: 1282 | AC33: 786 | AE33: 18
A34: 青海 | B34: 2493 | C34: 1168 | E34: 378 | F34: 375 | M34: 24 | O34: 0.4 | T34: 162 | U34: 785 | X34: 2543 | Y34: 1191 | Z34: 399 | AB34: 162 | AC34: 791 | AE34: 5
A35: 宁夏 | B35: 4178 | C35: 42 | E35: 2582 | F35: 2432 | I35: 70 | M35: 82 | O35: 2 | P35: 6 | T35: 942 | U35: 612 | X35: 4188 | Y35: 43 | Z35: 2583 | AB35: 942 | AC35: 620 | AE35: 33
A36: 新疆 | B36: 8679 | C36: 702 | E36: 5207 | F36: 5122 | I36: 83 | M36: 2 | P36: 2 | Q36: 0.2 | T36: 1836 | U36: 934 | X36: 8679 | Y36: 702 | Z36: 5207 | AB36: 1836 | AC36: 934 | AE36: 1
B38: =B5-SUM(B6:B36) -> 0 | C38: =C5-SUM(C6:C36) -> 1 | D38: =D5-SUM(D6:D36) -> 0 | E38: =E5-SUM(E6:E36) -> 1 | F38: =F5-SUM(F6:F36) -> 0 | H38: =H5-SUM(H6:H36) -> 0 | I38: =I5-SUM(I6:I36) -> -2.5 | J38: =J5-SUM(J6:J36) -> 0 | L38: =L5-SUM(L6:L36) -> -1 | M38: =M5-SUM(M6:M36) -> 3 | N38: =N5-SUM(N6:N36) -> 0 | O38: =O5-SUM(O6:O36) -> -2.4 | P38: =P5-SUM(P6:P36) -> 1 | S38: =S5-SUM(S6:S36) -> 1 | T38: =T5-SUM(T6:T36) -> 1 | U38: =U5-SUM(U6:U36) -> 0 | V38: =V5-SUM(V6:V36) -> 0

Sheet 2018
A1: 分地区装机容量（万KW） | X1: 分地区装机容量（万KW）
A2: 地区 | B2: 合计 | C2: 水电 | E2: 火电 | S2: 核电 | T2: 风电 | U2: 太阳能发电 | V2: 其他 | X2: 合计 | Y2: 水电 | Z2: 火电 | AA2: 核电 | AB2: 风电 | AC2: 太阳能发电 | AD2: 其他 | AE2: 分布式太阳能
C3: 合计 | D3: 抽水蓄能 | E3: 合计 | F3: 燃煤 | I3: 燃气 | L3: 燃油 | M3: 其他
F4: 合计 | G4: 常规燃煤 | H4: 煤矸石发电 | I4: 合计 | J4: 常规燃气 | K4: 煤层气发电 | M4: 合计 | N4: 余温、余气、余压发电 | O4: 垃圾焚烧发电 | P4: 秸秆、蔗渣、林木质发电 | Q4: 沼气 | R4: 技改增容
A5: 全国 | B5: 181753 | C5: 31861 | E5: 114408 | F5: 100835 | I5: 8375 | L5: 173 | M5: 5024 | O5: 58 | P5: 898 | Q5: 991 | S5: 4466 | T5: 18423 | U5: 12885 | V5: 19 | X5: 190012 | Y5: 35259 | Z5: 114408 | AA5: 4466 | AB5: 18427 | AC5: 17433 | AD5: 37 | AE5: 5027
A6: 北京 | B6: 1242 | C6: 98 | E6: 1119 | F6: 85 | I6: 985 | L6: 22 | M6: 27 | P6: 27 | T6: 19 | U6: 8 | X6: 1276 | Y6: 98 | Z6: 1119 | AB6: 19 | AC6: 40 | AE6: 35
A7: 天津 | B7: 1686 | E7: 1529 | F7: 1187 | I7: 317 | M7: 25 | P7: 10 | T7: 52 | U7: 108 | X7: 1709 | Y7: 1 | Z7: 1529 | AB7: 52 | AC7: 128 | AE7: 31
A8: 河北 | B8: 7027 | C8: 165 | E8: 4617 | F8: 4308 | I8: 3 | M8: 306 | O8: 1 | P8: 27 | Q8: 47 | T8: 1391 | U8: 859 | V8: 3 | X8: 7427 | Y8: 182 | Z8: 4617 | AB8: 1391 | AC8: 1234 | AD8: 3 | AE8: 378
A9: 山西 | B9: 8555 | C9: 214 | E9: 6628 | F9: 6108 | I9: 301 | M9: 218 | O9: 10 | P9: 11 | Q9: 30 | T9: 1043 | U9: 686 | X9: 8758 | Y9: 223 | Z9: 6628 | AB9: 1043 | AC9: 864 | AE9: 183
A10: 内蒙古 | B10: 12264 | C10: 238 | E10: 8229 | F10: 8158 | I10: 42 | M10: 29 | P10: 7 | Q10: 12 | T10: 2868 | U10: 933 | X10: 12285 | Y10: 242 | Z10: 8229 | AB10: 2868 | AC10: 946 | AE10: 13
A11: 辽宁 | B11: 5116 | C11: 283 | E11: 3383 | F11: 3283 | I11: 5 | L11: 15 | M11: 81 | P11: 8 | Q11: 7 | S11: 448 | T11: 760 | U11: 248 | X11: 5192 | Y11: 299 | Z11: 3383 | AA11: 448 | AB11: 761 | AC11: 302 | AE11: 83
A12: 吉林 | B12: 2986 | C12: 357 | E12: 1892 | F12: 1788 | I12: 0.5 | M12: 103 | O12: 0.3 | P12: 16 | Q12: 49 | T12: 514 | U12: 226 | X12: 3055 | Y12: 385 | Z12: 1892 | AB12: 514 | AC12: 265 | AE12: 62
A13: 黑龙江 | B13: 3046 | C13: 97 | E13: 2212 | F13: 2082 | I13: 12 | L13: 2 | M13: 116 | O13: 0.4 | P13: 11 | Q13: 85 | T13: 598 | U13: 144 | X13: 3129 | Y13: 104 | Z13: 2212 | AB13: 598 | AC13: 215 | AE13: 74
A14: 上海 | B14: 2447 | E14: 2365 | F14: 1511 | I14: 662 | L14: 86 | M14: 106 | O14: 2 | P14: 26 | T14: 71 | U14: 13 | X14: 2525 | Z14: 2365 | AB14: 71 | AC14: 89 | AE14: 82
A15: 江苏 | B15: 12079 | C15: 260 | E15: 9749 | F15: 7885 | I15: 1502 | M15: 362 | O15: 7 | P15: 103 | Q15: 52 | S15: 437 | T15: 864 | U15: 776 | V15: 10 | X15: 12657 | Y15: 265 | Z15: 9749 | AA15: 437 | AB15: 865 | AC15: 1332 | AD15: 10 | AE15: 540
A16: 浙江 | B16: 8564 | C16: 943 | E16: 6209 | F16: 4680 | I16: 1259 | L16: 2 | M16: 267 | O16: 5 | P16: 141 | Q16: 22 | S16: 908 | T16: 148 | U16: 376 | X16: 9565 | Y16: 1161 | Z16: 6209 | AA16: 908 | AB16: 148 | AC16: 1138 | AD16: 1 | AE16: 777
A17: 安徽 | B17: 6623 | C17: 243 | E17: 5413 | F17: 5071 | I17: 14 | M17: 329 | O17: 1 | P17: 51 | Q17: 111 | T17: 246 | U17: 743 | X17: 7089 | Y17: 312 | Z17: 5413 | AB17: 246 | AC17: 1118 | AE17: 441
A18: 福建 | B18: 5281 | C18: 926 | E18: 3128 | F18: 2574 | I18: 391 | L18: 1 | M18: 163 | O18: 0.6 | P18: 44 | Q18: 5 | S18: 871 | T18: 300 | U18: 67 | X18: 5770 | Y18: 1322 | Z18: 3128 | AA18: 871 | AB18: 300 | AC18: 148 | AE18: 111
A19: 江西 | B19: 3112 | C19: 419 | E19: 2165 | F19: 1925 | I19: 10 | M19: 230 | O19: 1 | P19: 12 | Q19: 21 | T19: 225 | U19: 309 | X19: 3554 | Y19: 627 | Z19: 2165 | AB19: 225 | AC19: 536 | AE19: 242
A20: 山东 | B20: 12422 | C20: 102 | E20: 10367 | F20: 9723 | I20: 8 | M20: 636 | O20: 8 | P20: 108 | Q20: 148 | S20: 125 | T20: 1146 | U20: 708 | X20: 13107 | Y20: 108 | Z20: 10367 | AA20: 125 | AB20: 1146 | AC20: 1361 | AE20: 713
A21: 河南 | B21: 8271 | C21: 391 | E21: 6821 | F21: 6446 | I21: 229 | M21: 146 | O21: 4 | P21: 13 | Q21: 44 | T21: 468 | U21: 602 | X21: 8680 | Y21: 401 | Z21: 6821 | AB21: 468 | AC21: 991 | AE21: 391
A22: 湖北 | B22: 7106 | C22: 3563 | E22: 2884 | F22: 2546 | I22: 94 | M22: 244 | O22: 2 | P22: 24 | Q22: 48 | T22: 331 | U22: 338 | X22: 7401 | Y22: 3675 | Z22: 2884 | AB22: 331 | AC22: 510 | AE22: 175
A23: 湖南 | B23: 4040 | C23: 1264 | E23: 2284 | F23: 2046 | I23: 7 | L23: 7 | M23: 224 | O23: 3 | P23: 24 | Q23: 41 | T23: 348 | U23: 160 | X23: 4522 | Y23: 1598 | Z23: 2284 | AB23: 348 | AC23: 292 | AD23: 6 | AE23: 166
A24: 广东 | B24: 11266 | C24: 1079 | E24: 8137 | F24: 5994 | I24: 1963 | M24: 180 | O24: 9 | P24: 110 | Q24: 22 | S24: 1330 | T24: 357 | U24: 370 | V24: 1 | X24: 11929 | Y24: 1576 | Z24: 8137 | AA24: 1330 | AB24: 357 | AC24: 527 | AD24: 2 | AE24: 209
