Workbook
Name _Toc93782300: 'About '!$B$16
Name _Toc93782301: 'About '!$B$17
Name Eno_TM: '[1]1997 Table 1a Modified'!#REF!
Name Eno_TM: '[1]1997 Table 1a Modified'!#REF!
Name Eno_TM: '[1]1997 Table 1a Modified'!#REF!
Name Eno_TM: '[1]1997 Table 1a Modified'!#REF!
Name Eno_TM: '[2]1997 Table 1a Modified'!#REF!
Name Eno_Tons: '[1]1997 Table 1a Modified'!#REF!
Name Eno_Tons: '[1]1997 Table 1a Modified'!#REF!
Name Eno_Tons: '[1]1997 Table 1a Modified'!#REF!
Name Eno_Tons: '[1]1997 Table 1a Modified'!#REF!
Name Eno_Tons: '[2]1997 Table 1a Modified'!#REF!
Name Sum_T2: '[1]1997 Table 1a Modified'!#REF!
Name Sum_T2: '[1]1997 Table 1a Modified'!#REF!
Name Sum_T2: '[1]1997 Table 1a Modified'!#REF!
Name Sum_T2: '[1]1997 Table 1a Modified'!#REF!
Name Sum_T2: '[2]1997 Table 1a Modified'!#REF!
Name Sum_TTM: '[1]1997 Table 1a Modified'!#REF!
Name Sum_TTM: '[1]1997 Table 1a Modified'!#REF!
Name Sum_TTM: '[1]1997 Table 1a Modified'!#REF!
Name Sum_TTM: '[1]1997 Table 1a Modified'!#REF!
Name Sum_TTM: '[2]1997 Table 1a Modified'!#REF!
Name ti_tbl_50: #REF!
Name ti_tbl_50: #REF!
Name ti_tbl_50: #REF!
Name ti_tbl_50: #REF!
Name ti_tbl_50: #REF!
Name ti_tbl_69: #REF!
Name ti_tbl_69: #REF!
Name ti_tbl_69: #REF!
Name ti_tbl_69: #REF!

Sheet About 
A1: BCDTRtSY BAU Cargo Dist Transported Relative to Start Year
A3: Sources: | B3: LDVs and HDVs
B4: Argonne National Laboratory
B5: 2019
B6: China Vehicle Fleet Model
B7: Model Outputs using GDP and Population data for EPS
B10: rail road ship
B11: National Data
B12: China Statistical Yearbook
B13: http://data.stats.gov.cn/easyquery.htm?cn=C01&zb=A0G05&sj=2018
B14: passenger-turnover,cargo-turnover
B15: passenger and freight prediction in BAU
B16: 《中国交通碳排放及其分解模型研究》smart-trans2022年的报告
A18: Notes
A19: For LDVs and HDVs we use data from the China Vehicle Fleet Model with GDP and Population data from the EPS.
A21: For other modes, we follow the methodology outlined below:
A23: This variable contains ratios of cargo distance transported in each year of the model run relative to the start year. The start year is the year before the
A24: first simulated year. So if the first year for which the model outputs data is 2018, the start year is 2017. The start year column does not have to be
A25: included in the outputs but is retained here for visual clarity.
A27: We use two methods: time series estimation and yearly increase rate extrapolation, both based on
A28: historical data of recent 10 years or 5 years. Then we compare the results of both methods, and choose the most reasonable one.
A29: The fina method that we chose is highlighted in red for different transportation modes.

Sheet raw data
A1: 旅客周转量（1978-2021年） | H1: 货物周转量（1978-2021年）
A2: Year | B2: Total | C2: Railways | D2: Highways | E2: Waterways | F2: Civial Aviation | H2: Year | I2: Total | J2: Railways | K2: Highways | L2: Waterways | N2: Civial Aviation
M3: Ocean
A4: 1978 | B4: 1743.1 | C4: 1093.22 | D4: 521.3 | E4: 100.63 | F4: 27.91 | H4: 1978 | I4: 9928 | J4: 5345.19 | K4: 350.3 | L4: 3801.8 | M4: 2487 | N4: 0.97
A5: 1980 | B5: 2281.3 | C5: 1383.16 | D5: 729.5 | E5: 129.12 | F5: 39.56 | H5: 1980 | I5: 11629 | J5: 5717.5 | K5: 342.9 | L5: 5076.5 | M5: 3532 | N5: 1.41
A6: 1985 | B6: 4435.3863 | C6: 2416.14 | D6: 1724.88 | E6: 178.65 | F6: 115.7163 | H6: 1985 | I6: 18365 | J6: 8125.66 | K6: 1903 | L6: 7729.3 | M6: 5329 | N6: 4.15 | P6: Covid Impact
A7: 1990 | B7: 5628.4 | C7: 2612.63 | D7: 2620.32 | E7: 164.91 | F7: 230.48 | H7: 1990 | I7: 26208 | J7: 10622.38 | K7: 3358.1 | L7: 11591.9 | M7: 8140.86 | N7: 8.18 | R7: Railways | S7: Highways | T7: Waterways | U7: Civial Aviation
A8: 1991 | B8: 6178.3 | C8: 2828.1 | D8: 2871.74 | E8: 177.2 | F8: 301.32 | H8: 1991 | I8: 27987 | J8: 10972 | K8: 3428 | L8: 12955.4 | M8: 8990.4 | N8: 10.1
A9: 1992 | B9: 6949.4 | C9: 3152.24 | D9: 3192.64 | E9: 198.35 | F9: 406.12 | H9: 1992 | I9: 29218 | J9: 11575.55 | K9: 3755.39 | L9: 13256.2 | M9: 9034 | N9: 13.42 | P9: Passenger | Q9: 2019 | R9: 1 | S9: 1 | T9: 1 | U9: 1
A10: 1993 | B10: 7858 | C10: 3483.3 | D10: 3700.7 | E10: 196.4 | F10: 477.6 | H10: 1993 | I10: 30646.81 | J10: 12090.9 | K10: 4070.5 | L10: 13860.8 | M10: 9133.9 | N10: 16.61 | Q10: 2020 | R10: =C37/C$36 -> 0.56207349 | S10: =D37/D$36 -> 0.52398754 | T10: =E37/E$36 -> 0.41134663 | U10: =F37/F$36 -> 0.53919061
A11: 1994 | B11: 8591.4 | C11: 3636 | D11: 4220.3 | E11: 183.5 | F11: 551.58 | H11: 1994 | I11: 33435.48 | J11: 12632 | K11: 4486.3 | L11: 15686.6 | M11: 10267.7 | N11: 18.58 | Q11: 2021 | R11: =C38/C$36 -> 0.65057933 | S11: =D38/D$36 -> 0.40956295 | T11: =E38/E$36 -> 0.41284289 | U11: =F38/F$36 -> 0.55784914
A12: 1995 | B12: 9001.9 | C12: 3545.7 | D12: 4603.1 | E12: 171.8 | F12: 681.3 | H12: 1995 | I12: 35908.9 | J12: 13049.48 | K12: 4694.9 | L12: 17552.2 | M12: 11938 | N12: 22.3 | Q12: 2022 | R12: =C39/C$36 -> 0.44725021 | S12: =D39/D$36 -> 0.27182058 | T12: =E39/E$36 -> 0.28182419 | U12: =F39/F$36 -> 0.33435853
A13: 1996 | B13: 9164.8 | C13: 3347.6 | D13: 4908.79 | E13: 160.57 | F13: 747.84 | H13: 1996 | I13: 36589.8 | J13: 13106.2 | K13: 5011.2 | L13: 17862.5 | M13: 11254 | N13: 24.93 | P13: Freight | Q13: 2019 | R13: 1 | S13: 1 | T13: 1 | U13: 1
A14: 1997 | B14: 10055.48 | C14: 3584.86 | D14: 5541.4 | E14: 155.7 | F14: 773.52 | H14: 1997 | I14: 38384.7 | J14: 13269.9 | K14: 5271.5 | L14: 19235 | M14: 14874.7 | N14: 29.1 | Q14: 2020 | R14: =J37/J$36 -> 1.0110168 | S14: =K37/K$36 -> 1.0089787 | T14: =L37/L$36 -> 1.0180006 | U14: =N37/N$36 -> 0.91261398
A15: 1998 | B15: 10636.7 | C15: 3773.42 | D15: 5942.81 | E15: 120.27 | F15: 800.24 | H15: 1998 | I15: 38088.7 | J15: 12560.1 | K15: 5483.38 | L15: 19405.8 | M15: 14920.28 | N15: 33.45 | Q15: 2021 | R15: =J38/J$36 -> 1.1012542 | S15: =K38/K$36 -> 1.1584814 | T15: =L38/L$36 -> 1.1117173 | U15: =N38/N$36 -> 1.0568389
A16: 1999 | B16: 11299.7 | C16: 4135.9 | D16: 6199.24 | E16: 107.28 | F16: 857.3 | H16: 1999 | I16: 40567.8 | J16: 12910.3 | K16: 5724.3 | L16: 21262.8 | M16: 17014.4 | N16: 42.34 | Q16: 2022 | R16: =J39/J$36 -> 1.1909665 | S16: =K39/K$36 -> 1.1579849 | T16: =L39/L$36 -> 1.1639053 | U16: =N39/N$36 -> 0.96542553
A17: 2000 | B17: 12261.1 | C17: 4532.59 | D17: 6657.42 | E17: 100.54 | F17: 970.54 | H17: 2000 | I17: 44320.5 | J17: 13770.49 | K17: 6129.4 | L17: 23734.2 | M17: 17073 | N17: 50.27
A18: 2001 | B18: 13155.13 | C18: 4766.82 | D18: 7207.08 | E18: 89.88 | F18: 1091.35 | H18: 2001 | I18: 47709.9 | J18: 14694.1 | K18: 6330.4 | L18: 25988.9 | M18: 20873 | N18: 43.72
A19: 2002 | B19: 14125.6 | C19: 4969.4 | D19: 7805.8 | E19: 81.8 | F19: 1268.7 | H19: 2002 | I19: 50685.9 | J19: 15658.4 | K19: 6782.5 | L19: 27510.6 | M19: 21733 | N19: 51.55 | Q19: Passenger
A20: 2003 | B20: 13810.5 | C20: 4788.61 | D20: 7695.6 | E20: 63.1 | F20: 1263.19 | H20: 2003 | I20: 53859.2 | J20: 17246.7 | K20: 7099.4756 | L20: 28715.8 | M20: 22304.77 | N20: 57.9 | S20: 2019 | T20: 2020 | U20: 2021 | V20: 2022 | W20: 2023
A21: 2004 | B21: 16309.1 | C21: 5712.2 | D21: 8748.4 | E21: 66.3 | F21: 1782.3 | H21: 2004 | I21: 69445 | J21: 19288.8 | K21: 7840.9 | L21: 41428.7 | M21: 32255 | N21: 71.8 | Q21: Railways | S21: {=TRANSPOSE(R9:U12)} -> 1 | T21: 0.56207349 | U21: 0.65057933 | V21: 0.44725021 | W21: =(1-V21)*0.85+V21 -> 0.91708753
A22: 2005 | B22: 17466.74 | C22: 6061.96 | D22: 9292.08 | E22: 67.77 | F22: 2044.93 | H22: 2005 | I22: 80258.1 | J22: 20726 | K22: 8693.2 | L22: 49672.3 | M22: 38552 | N22: 78.9 | Q22: Highways | S22: 1 | T22: 0.52398754 | U22: 0.40956295 | V22: 0.27182058 | W22: =(1-V22)*0.85+V22 -> 0.89077309
A23: 2006 | B23: 19197.211 | C23: 6622.1222 | D23: 10130.846 | E23: 73.5825 | F23: 2370.66 | H23: 2006 | I23: 88839.851 | J23: 21954.41 | K23: 9754.2476 | L23: 55485.749 | M23: 42577.3 | N23: 94.27526 | Q23: Waterways | S23: 1 | T23: 0.41134663 | U23: 0.41284289 | V23: 0.28182419 | W23: =(1-V23)*0.85+V23 -> 0.89227363
A24: 2007 | B24: 21592.581 | C24: 7216.31 | D24: 11506.767 | E24: 77.7783 | F24: 2791.7258 | H24: 2007 | I24: 101418.81 | J24: 23797 | K24: 11354.687 | L24: 64284.846 | M24: 48685.894 | N24: 116.38667 | Q24: Civial Aviation | S24: 1 | T24: 0.53919061 | U24: 0.55784914 | V24: 0.33435853 | W24: =(1-V24)*0.85+V24 -> 0.90015378
A25: 2008 | B25: 23196.698 | C25: 7778.6046 | D25: 12476.115 | E25: 59.1796 | F25: 2882.7993 | H25: 2008 | I25: 110300 | J25: 25106.282 | K25: 32868.186 | L25: 50262.704 | M25: 32851 | N25: 119.60227 | Q25: Freight
A26: 2009 | B26: 24834.942 | C26: 7878.8885 | D26: 13511.438 | E26: 69.3802 | F26: 3375.2354 | H26: 2009 | I26: 122133.31 | J26: 25239.169 | K26: 37188.821 | L26: 57556.672 | M26: 39524 | N26: 126.2307 | S26: 2019 | T26: 2020 | U26: 2021 | V26: 2022
A27: 2010 | B27: 27894.257 | C27: 8762.1783 | D27: 15020.812 | E27: 72.2701 | F27: 4038.996 | H27: 2010 | I27: 141837.42 | J27: 27644.133 | K27: 43389.672 | L27: 68427.526 | M27: 45999 | N27: 178.89816 | Q27: Railways | S27: {=TRANSPOSE(R13:U16)} -> 1 | T27: 1.0110168 | U27: 1.1012542 | V27: 1.1909665
A28: 2011 | B28: 30984.03 | C28: 9612.2936 | D28: 16760.247 | E28: 74.5285 | F28: 4536.9629 | H28: 2011 | I28: 159323.6 | J28: 29465.785 | K28: 51374.741 | L28: 75423.836 | M28: 49355 | N28: 173.91 | Q28: Highways | S28: 1 | T28: 1.0089787 | U28: 1.1584814 | V28: 1.1579849
A29: 2012 | B29: 33383.089 | C29: 9812.3272 | D29: 18467.546 | E29: 77.4791 | F29: 5025.7366 | H29: 2012 | I29: 173804.46 | J29: 29187.086 | K29: 59534.865 | L29: 81707.579 | M29: 53412.101 | N29: 163.88936 | Q29: Waterways | S29: 1 | T29: 1.0180006 | U29: 1.1117173 | V29: 1.1639053
A30: 2013 | B30: 27571.654 | C30: 10595.619 | D30: 11250.943 | E30: 68.3326 | F30: 5656.7596 | H30: 2013 | I30: 168013.8 | J30: 29173.891 | K30: 55738.077 | L30: 79435.651 | M30: 48705.368 | N30: 170.29181 | Q30: Civial Aviation | S30: 1 | T30: 0.91261398 | U30: 1.0568389 | V30: 0.96542553
A31: 2014 | B31: 28647.132 | C31: 11241.85 | D31: 10996.75 | E31: 74.341293 | F31: 6334.1903 | H31: 2014 | I31: 181667.69 | J31: 27530.19 | K31: 56846.9 | L31: 92774.556 | M31: 55935.062 | N31: 187.77149
A32: 2015 | B32: 30058.898 | C32: 11960.604 | D32: 10742.658 | E32: 73.084 | F32: 7282.5513 | H32: 2015 | I32: 178355.9 | J32: 23754.308 | K32: 57955.724 | L32: 91772.451 | M32: 54236.094 | N32: 208.0683
A33: 2016 | B33: 31258.462 | C33: 12579.293 | D33: 10228.708 | E33: 72.326542 | F33: 8378.1348 | H33: 2016 | I33: 186629.48 | J33: 23792.262 | K33: 61080.097 | L33: 97338.802 | M33: 58074.6 | N33: 222.44934
A34: 2017 | B34: 32812.8 | C34: 13456.92 | D34: 9765.1794 | E34: 77.664137 | F34: 9513.0358 | H34: 2017 | I34: 197372.65 | J34: 26962.204 | K34: 66771.516 | L34: 98611.246 | M34: 55083.857 | N34: 243.55229
A35: 2018 | B35: 34218.152 | C35: 14146.582 | D35: 9279.6786 | E35: 79.574191 | F35: 10712.317 | H35: 2018 | I35: 204686.24 | J35: 28820.986 | K35: 71249.212 | L35: 99052.815 | M35: 51926.58 | N35: 262.49911
A36: 2019 | B36: =SUM(C36:F36) -> 35349 | C36: 14706.6 | D36: 8857.1 | E36: 80.2 | F36: 11705.1 | H36: 2019 | I36: =SUM(J36:N36)-M36 -> 194044.58 | J36: 30181.95 | K36: 59636.39 | L36: 103963.04 | M36: 54057 | N36: 263.2
A37: 2020 | B37: =SUM(C37:F37) -> 19251.47 | C37: 8266.19 | D37: 4641.01 | E37: 32.99 | F37: 6311.28 | H37: 2020 | I37: =SUM(J37:N37)-M37 -> 196760.95 | J37: 30514.46 | K37: 60171.85 | L37: 105834.44 | M37: 89897 | N37: 240.2
A38: 2021 | B38: =SUM(C38:F38) -> 19758.14 | C38: 9567.81 | D38: 3627.54 | E38: 33.11 | F38: 6529.68 | H38: 2021 | I38: =SUM(J38:N38)-M38 -> 218181.32 | J38: 33238 | K38: 69087.65 | L38: 115577.51 | M38: 97842 | N38: 278.16
A39: 2022 | B39: =C39+D39+E39+F39 -> 12921.374 | C39: 6577.53 | D39: 2407.5421 | E39: 22.6023 | F39: 3913.7 | H39: 2022 | I39: =SUM(J39:N39)-M39 -> 226260.96 | J39: 35945.69 | K39: 69058.038 | L39: 121003.14 | N39: 254.1
B43: passenger | C43: from SVYbT | D43: average loading from AVLo | E43: freight | F43: from SVYbT | G43: average loading from AVLo
...

Sheet passenger
A1: Year | D1: 1978 | E1: 1980 | F1: 1985 | G1: 1990 | H1: 1991 | I1: 1992 | J1: 1993 | K1: 1994 | L1: 1995 | M1: 1996 | N1: 1997 | O1: 1998 | P1: 1999 | Q1: 2000 | R1: 2001 | S1: 2002 | T1: 2003 | U1: 2004 | V1: 2005 | W1: 2006 | X1: 2007 | Y1: 2008 | Z1: 2009 | AA1: 2010 | AB1: 2011 | AC1: 2012 | AD1: 2013 | AE1: 2014 | AF1: 2015 | AG1: 2016 | AH1: 2017 | AI1: 2018 | AJ1: 2019 | AK1: 2020 | AL1: 2021 | AM1: 2022 | AN1: 2023 | AO1: 2024 | AP1: 2025 | AQ1: 2026 | AR1: 2027 | AS1: 2028 | AT1: 2029 | AU1: 2030 | AV1: 2031 | AW1: 2032 | AX1: 2033 | AY1: 2034 | AZ1: 2035 | BA1: 2036 | BB1: 2037 | BC1: 2038 | BD1: 2039 | BE1: 2040 | BF1: 2041 | BG1: 2042 | BH1: 2043 | BI1: 2044 | BJ1: 2045 | BK1: 2046 | BL1: 2047 | BM1: 2048 | BN1: 2049 | BO1: 2050 | BP1: 2051 | BQ1: 2052 | BR1: 2053 | BS1: 2054 | BT1: 2055 | BU1: 2056 | BV1: 2057 | BW1: 2058 | BX1: 2059 | BY1: 2060
A2: Total | D2: 1743.1 | E2: 2281.3 | F2: 4435.3863 | G2: 5628.4 | H2: 6178.3 | I2: 6949.4 | J2: 7858 | K2: 8591.4 | L2: 9001.9 | M2: 9164.8 | N2: 10055.48 | O2: 10636.7 | P2: 11299.7 | Q2: 12261.1 | R2: 13155.13 | S2: 14125.6 | T2: 13810.5 | U2: 16309.1 | V2: 17466.74 | W2: 19197.211 | X2: 21592.581 | Y2: 23196.698 | Z2: 24834.942 | AA2: 27894.257 | AB2: 30984.03 | AC2: 33383.089 | AD2: 27571.654 | AE2: 28647.132 | AF2: 30058.898 | AG2: 31258.462 | AH2: 32812.8 | AI2: 34218.152 | AJ2: =SUM(AJ3:AJ6) -> 35349 | AK2: =SUM(AK3:AK6) -> 75267.57 | AL2: =SUM(AL3:AL6) -> 78471.417
A3: Railways | D3: 1093.22 | E3: 1383.16 | F3: 2416.14 | G3: 2612.63 | H3: 2828.1 | I3: 3152.24 | J3: 3483.3 | K3: 3636 | L3: 3545.7 | M3: 3347.6 | N3: 3584.86 | O3: 3773.42 | P3: 4135.9 | Q3: 4532.59 | R3: 4766.82 | S3: 4969.4 | T3: 4788.61 | U3: 5712.2 | V3: 6061.96 | W3: 6622.1222 | X3: 7216.31 | Y3: 7778.6046 | Z3: 7878.8885 | AA3: 8762.1783 | AB3: 9612.2936 | AC3: 9812.3272 | AD3: 10595.619 | AE3: 11241.85 | AF3: 11960.604 | AG3: 12579.293 | AH3: 13456.92 | AI3: 14146.582 | AJ3: 14706.6 | AK3: 14713.28 | AL3: =($AU$3-$AJ$3)/11*(11-($AU$1-AL1))+$AJ$3 -> 14527.128 | AM3: =($AU$3-$AJ$3)/11*(11-($AU$1-AM1))+$AJ$3 -> 14437.392 | AN3: =($AU$3-$AJ$3)/11*(11-($AU$1-AN1))+$AJ$3 -> 14347.657 | AO3: =($AU$3-$AJ$3)/11*(11-($AU$1-AO1))+$AJ$3 -> 14257.921 | AP3: =($AU$3-$AJ$3)/11*(11-($AU$1-AP1))+$AJ$3 -> 14168.185 | AQ3: =($AU$3-$AJ$3)/11*(11-($AU$1-AQ1))+$AJ$3 -> 14078.449 | AR3: =($AU$3-$AJ$3)/11*(11-($AU$1-AR1))+$AJ$3 -> 13988.713 | AS3: =($AU$3-$AJ$3)/11*(11-($AU$1-AS1))+$AJ$3 -> 13898.977 | AT3: =($AU$3-$AJ$3)/11*(11-($AU$1-AT1))+$AJ$3 -> 13809.241 | AU3: 13719.505 | AV3: =($BE$3-$AU$3)/10*(10-($BE$1-AV1))+$AU$3 -> 13971.614 | AW3: =($BE$3-$AU$3)/10*(10-($BE$1-AW1))+$AU$3 -> 14223.722 | AX3: =($BE$3-$AU$3)/10*(10-($BE$1-AX1))+$AU$3 -> 14475.83 | AY3: =($BE$3-$AU$3)/10*(10-($BE$1-AY1))+$AU$3 -> 14727.938 | AZ3: =($BE$3-$AU$3)/10*(10-($BE$1-AZ1))+$AU$3 -> 14980.046 | BA3: =($BE$3-$AU$3)/10*(10-($BE$1-BA1))+$AU$3 -> 15232.154 | BB3: =($BE$3-$AU$3)/10*(10-($BE$1-BB1))+$AU$3 -> 15484.262 | BC3: =($BE$3-$AU$3)/10*(10-($BE$1-BC1))+$AU$3 -> 15736.37 | BD3: =($BE$3-$AU$3)/10*(10-($BE$1-BD1))+$AU$3 -> 15988.478 | BE3: 16240.586 | BF3: =($BO$3-$BE$3)/10*(10-($BO$1-BF1))+$BE$3 -> 16432.399 | BG3: =($BO$3-$BE$3)/10*(10-($BO$1-BG1))+$BE$3 -> 16624.211 | BH3: =($BO$3-$BE$3)/10*(10-($BO$1-BH1))+$BE$3 -> 16816.024 | BI3: =($BO$3-$BE$3)/10*(10-($BO$1-BI1))+$BE$3 -> 17007.837 | BJ3: =($BO$3-$BE$3)/10*(10-($BO$1-BJ1))+$BE$3 -> 17199.649 | BK3: =($BO$3-$BE$3)/10*(10-($BO$1-BK1))+$BE$3 -> 17391.462 | BL3: =($BO$3-$BE$3)/10*(10-($BO$1-BL1))+$BE$3 -> 17583.274 | BM3: =($BO$3-$BE$3)/10*(10-($BO$1-BM1))+$BE$3 -> 17775.087 | BN3: =($BO$3-$BE$3)/10*(10-($BO$1-BN1))+$BE$3 -> 17966.9 | BO3: 18158.712 | BP3: =($BY$3-$BO$3)/10*(10-($BY$1-BP1))+$BO$3 -> 18317.131 | BQ3: =($BY$3-$BO$3)/10*(10-($BY$1-BQ1))+$BO$3 -> 18475.55 | BR3: =($BY$3-$BO$3)/10*(10-($BY$1-BR1))+$BO$3 -> 18633.969 | BS3: =($BY$3-$BO$3)/10*(10-($BY$1-BS1))+$BO$3 -> 18792.388 | BT3: =($BY$3-$BO$3)/10*(10-($BY$1-BT1))+$BO$3 -> 18950.807 | BU3: =($BY$3-$BO$3)/10*(10-($BY$1-BU1))+$BO$3 -> 19109.226 | BV3: =($BY$3-$BO$3)/10*(10-($BY$1-BV1))+$BO$3 -> 19267.645 | BW3: =($BY$3-$BO$3)/10*(10-($BY$1-BW1))+$BO$3 -> 19426.064 | BX3: =($BY$3-$BO$3)/10*(10-($BY$1-BX1))+$BO$3 -> 19584.483 | BY3: 19742.902
A4: Highways | D4: 521.3 | E4: 729.5 | F4: 1724.88 | G4: 2620.32 | H4: 2871.74 | I4: 3192.64 | J4: 3700.7 | K4: 4220.3 | L4: 4603.1 | M4: 4908.79 | N4: 5541.4 | O4: 5942.81 | P4: 6199.24 | Q4: 6657.42 | R4: 7207.08 | S4: 7805.8 | T4: 7695.6 | U4: 8748.4 | V4: 9292.08 | W4: 10130.846 | X4: 11506.767 | Y4: 12476.115 | Z4: 13511.438 | AA4: 15020.812 | AB4: 16760.247 | AC4: 18467.546 | AD4: 11250.943 | AE4: 10996.75 | AF4: 10742.658 | AG4: 10228.708 | AH4: 9765.1794 | AI4: 9279.6786 | AJ4: 8857.1 | AK4: 51514 | AL4: =($AU$4-$AK$4)/10*(10-($AU$1-AL1))+$AK$4 -> 52290.76 | AM4: =($AU$4-$AK$4)/10*(10-($AU$1-AM1))+$AK$4 -> 53067.519 | AN4: =($AU$4-$AK$4)/10*(10-($AU$1-AN1))+$AK$4 -> 53844.279 | AO4: =($AU$4-$AK$4)/10*(10-($AU$1-AO1))+$AK$4 -> 54621.039 | AP4: =($AU$4-$AK$4)/10*(10-($AU$1-AP1))+$AK$4 -> 55397.799 | AQ4: =($AU$4-$AK$4)/10*(10-($AU$1-AQ1))+$AK$4 -> 56174.558 | AR4: =($AU$4-$AK$4)/10*(10-($AU$1-AR1))+$AK$4 -> 56951.318 | AS4: =($AU$4-$AK$4)/10*(10-($AU$1-AS1))+$AK$4 -> 57728.078 | AT4: =($AU$4-$AK$4)/10*(10-($AU$1-AT1))+$AK$4 -> 58504.838 | AU4: 59281.597 | AV4: =($BE$4-$AU$4)/10*(10-($BE$1-AV1))+$AU$4 -> 59105.158 | AW4: =($BE$4-$AU$4)/10*(10-($BE$1-AW1))+$AU$4 -> 58928.719 | AX4: =($BE$4-$AU$4)/10*(10-($BE$1-AX1))+$AU$4 -> 58752.28 | AY4: =($BE$4-$AU$4)/10*(10-($BE$1-AY1))+$AU$4 -> 58575.84 | AZ4: =($BE$4-$AU$4)/10*(10-($BE$1-AZ1))+$AU$4 -> 58399.401 | BA4: =($BE$4-$AU$4)/10*(10-($BE$1-BA1))+$AU$4 -> 58222.962 | BB4: =($BE$4-$AU$4)/10*(10-($BE$1-BB1))+$AU$4 -> 58046.523 | BC4: =($BE$4-$AU$4)/10*(10-($BE$1-BC1))+$AU$4 -> 57870.084 | BD4: =($BE$4-$AU$4)/10*(10-($BE$1-BD1))+$AU$4 -> 57693.644 | BE4: 57517.205 | BF4: =($BO$4-$BE$4)/10*(10-($BO$1-BF1))+$BE$4 -> 57014.624 | BG4: =($BO$4-$BE$4)/10*(10-($BO$1-BG1))+$BE$4 -> 56512.043 | BH4: =($BO$4-$BE$4)/10*(10-($BO$1-BH1))+$BE$4 -> 56009.462 | BI4: =($BO$4-$BE$4)/10*(10-($BO$1-BI1))+$BE$4 -> 55506.881 | BJ4: =($BO$4-$BE$4)/10*(10-($BO$1-BJ1))+$BE$4 -> 55004.3 | BK4: =($BO$4-$BE$4)/10*(10-($BO$1-BK1))+$BE$4 -> 54501.719 | BL4: =($BO$4-$BE$4)/10*(10-($BO$1-BL1))+$BE$4 -> 53999.138 | BM4: =($BO$4-$BE$4)/10*(10-($BO$1-BM1))+$BE$4 -> 53496.557 | BN4: =($BO$4-$BE$4)/10*(10-($BO$1-BN1))+$BE$4 -> 52993.976 | BO4: 52491.395 | BP4: =($BY$4-$BO$4)/10*(10-($BY$1-BP1))+$BO$4 -> 51744.939 | BQ4: =($BY$4-$BO$4)/10*(10-($BY$1-BQ1))+$BO$4 -> 50998.483 | BR4: =($BY$4-$BO$4)/10*(10-($BY$1-BR1))+$BO$4 -> 50252.027 | BS4: =($BY$4-$BO$4)/10*(10-($BY$1-BS1))+$BO$4 -> 49505.571 | BT4: =($BY$4-$BO$4)/10*(10-($BY$1-BT1))+$BO$4 -> 48759.115 | BU4: =($BY$4-$BO$4)/10*(10-($BY$1-BU1))+$BO$4 -> 48012.659 | BV4: =($BY$4-$BO$4)/10*(10-($BY$1-BV1))+$BO$4 -> 47266.203 | BW4: =($BY$4-$BO$4)/10*(10-($BY$1-BW1))+$BO$4 -> 46519.747 | BX4: =($BY$4-$BO$4)/10*(10-($BY$1-BX1))+$BO$4 -> 45773.291 | BY4: 45026.835
A5: Waterways | D5: 100.63 | E5: 129.12 | F5: 178.65 | G5: 164.91 | H5: 177.2 | I5: 198.35 | J5: 196.4 | K5: 183.5 | L5: 171.8 | M5: 160.57 | N5: 155.7 | O5: 120.27 | P5: 107.28 | Q5: 100.54 | R5: 89.88 | S5: 81.8 | T5: 63.1 | U5: 66.3 | V5: 67.77 | W5: 73.5825 | X5: 77.7783 | Y5: 59.1796 | Z5: 69.3802 | AA5: 72.2701 | AB5: 74.5285 | AC5: 77.4791 | AD5: 68.3326 | AE5: 74.341293 | AF5: 73.084 | AG5: 72.326542 | AH5: 77.664137 | AI5: 79.574191 | AJ5: 80.2 | AK5: 79.07 | AL5: =($AU$5-$AJ$5)/11*(11-($AU$1-AL1))+$AJ$5 -> 76.25149 | AM5: =($AU$5-$AJ$5)/11*(11-($AU$1-AM1))+$AJ$5 -> 74.277234 | AN5: =($AU$5-$AJ$5)/11*(11-($AU$1-AN1))+$AJ$5 -> 72.302979 | AO5: =($AU$5-$AJ$5)/11*(11-($AU$1-AO1))+$AJ$5 -> 70.328724 | AP5: =($AU$5-$AJ$5)/11*(11-($AU$1-AP1))+$AJ$5 -> 68.354469 | AQ5: =($AU$5-$AJ$5)/11*(11-($AU$1-AQ1))+$AJ$5 -> 66.380214 | AR5: =($AU$5-$AJ$5)/11*(11-($AU$1-AR1))+$AJ$5 -> 64.405958 | AS5: =($AU$5-$AJ$5)/11*(11-($AU$1-AS1))+$AJ$5 -> 62.431703 | AT5: =($AU$5-$AJ$5)/11*(11-($AU$1-AT1))+$AJ$5 -> 60.457448 | AU5: 58.483193 | AV5: =($BE$5-$AU$5)/10*(10-($BE$1-AV1))+$AU$5 -> 57.940162 | AW5: =($BE$5-$AU$5)/10*(10-($BE$1-AW1))+$AU$5 -> 57.397131 | AX5: =($BE$5-$AU$5)/10*(10-($BE$1-AX1))+$AU$5 -> 56.854101 | AY5: =($BE$5-$AU$5)/10*(10-($BE$1-AY1))+$AU$5 -> 56.31107 | AZ5: =($BE$5-$AU$5)/10*(10-($BE$1-AZ1))+$AU$5 -> 55.76804 | BA5: =($BE$5-$AU$5)/10*(10-($BE$1-BA1))+$AU$5 -> 55.225009 | BB5: =($BE$5-$AU$5)/10*(10-($BE$1-BB1))+$AU$5 -> 54.681978 | BC5: =($BE$5-$AU$5)/10*(10-($BE$1-BC1))+$AU$5 -> 54.138948 | BD5: =($BE$5-$AU$5)/10*(10-($BE$1-BD1))+$AU$5 -> 53.595917 | BE5: 53.052886 | BF5: =($BO$5-$BE$5)/10*(10-($BO$1-BF1))+$BE$5 -> 52.395832 | BG5: =($BO$5-$BE$5)/10*(10-($BO$1-BG1))+$BE$5 -> 51.738777 | BH5: =($BO$5-$BE$5)/10*(10-($BO$1-BH1))+$BE$5 -> 51.081723 | BI5: =($BO$5-$BE$5)/10*(10-($BO$1-BI1))+$BE$5 -> 50.424668 | BJ5: =($BO$5-$BE$5)/10*(10-($BO$1-BJ1))+$BE$5 -> 49.767613 | BK5: =($BO$5-$BE$5)/10*(10-($BO$1-BK1))+$BE$5 -> 49.110559 | BL5: =($BO$5-$BE$5)/10*(10-($BO$1-BL1))+$BE$5 -> 48.453504 | BM5: =($BO$5-$BE$5)/10*(10-($BO$1-BM1))+$BE$5 -> 47.796449 | BN5: =($BO$5-$BE$5)/10*(10-($BO$1-BN1))+$BE$5 -> 47.139395 | BO5: 46.48234 | BP5: =($BY$5-$BO$5)/10*(10-($BY$1-BP1))+$BO$5 -> 45.846047 | BQ5: =($BY$5-$BO$5)/10*(10-($BY$1-BQ1))+$BO$5 -> 45.209755 | BR5: =($BY$5-$BO$5)/10*(10-($BY$1-BR1))+$BO$5 -> 44.573462 | BS5: =($BY$5-$BO$5)/10*(10-($BY$1-BS1))+$BO$5 -> 43.937169 | BT5: =($BY$5-$BO$5)/10*(10-($BY$1-BT1))+$BO$5 -> 43.300877 | BU5: =($BY$5-$BO$5)/10*(10-($BY$1-BU1))+$BO$5 -> 42.664584 | BV5: =($BY$5-$BO$5)/10*(10-($BY$1-BV1))+$BO$5 -> 42.028291 | BW5: =($BY$5-$BO$5)/10*(10-($BY$1-BW1))+$BO$5 -> 41.391999 | BX5: =($BY$5-$BO$5)/10*(10-($BY$1-BX1))+$BO$5 -> 40.755706 | BY5: 40.119413
A6: Civil | B6: Aviation | D6: 27.91 | E6: 39.56 | F6: 115.7163 | G6: 230.48 | H6: 301.32 | I6: 406.12 | J6: 477.6 | K6: 551.58 | L6: 681.3 | M6: 747.84 | N6: 773.52 | O6: 800.24 | P6: 857.3 | Q6: 970.54 | R6: 1091.35 | S6: 1268.7 | T6: 1263.19 | U6: 1782.3 | V6: 2044.93 | W6: 2370.66 | X6: 2791.7258 | Y6: 2882.7993 | Z6: 3375.2354 | AA6: 4038.996 | AB6: 4536.9629 | AC6: 5025.7366 | AD6: 5656.7596 | AE6: 6334.1903 | AF6: 7282.5513 | AG6: 8378.1348 | AH6: 9513.0358 | AI6: 10712.317 | AJ6: 11705.1 | AK6: 8961.22 | AL6: =($AU$6-$AJ$6)/11*(11-($AU$1-AL1))+$AJ$6 -> 11577.278 | AM6: =($AU$6-$AJ$6)/11*(11-($AU$1-AM1))+$AJ$6 -> 11513.366 | AN6: =($AU$6-$AJ$6)/11*(11-($AU$1-AN1))+$AJ$6 -> 11449.455 | AO6: =($AU$6-$AJ$6)/11*(11-($AU$1-AO1))+$AJ$6 -> 11385.544 | AP6: =($AU$6-$AJ$6)/11*(11-($AU$1-AP1))+$AJ$6 -> 11321.633 | AQ6: =($AU$6-$AJ$6)/11*(11-($AU$1-AQ1))+$AJ$6 -> 11257.721 | AR6: =($AU$6-$AJ$6)/11*(11-($AU$1-AR1))+$AJ$6 -> 11193.81 | AS6: =($AU$6-$AJ$6)/11*(11-($AU$1-AS1))+$AJ$6 -> 11129.899 | AT6: =($AU$6-$AJ$6)/11*(11-($AU$1-AT1))+$AJ$6 -> 11065.988 | AU6: 11002.076 | AV6: =($BE$6-$AU$6)/10*(10-($BE$1-AV1))+$AU$6 -> 11376.262 | AW6: =($BE$6-$AU$6)/10*(10-($BE$1-AW1))+$AU$6 -> 11750.447 | AX6: =($BE$6-$AU$6)/10*(10-($BE$1-AX1))+$AU$6 -> 12124.633 | AY6: =($BE$6-$AU$6)/10*(10-($BE$1-AY1))+$AU$6 -> 12498.818 | AZ6: =($BE$6-$AU$6)/10*(10-($BE$1-AZ1))+$AU$6 -> 12873.003 | BA6: =($BE$6-$AU$6)/10*(10-($BE$1-BA1))+$AU$6 -> 13247.189 | BB6: =($BE$6-$AU$6)/10*(10-($BE$1-BB1))+$AU$6 -> 13621.374 | BC6: =($BE$6-$AU$6)/10*(10-($BE$1-BC1))+$AU$6 -> 13995.56 | BD6: =($BE$6-$AU$6)/10*(10-($BE$1-BD1))+$AU$6 -> 14369.745 | BE6: 14743.931 | BF6: =($BO$6-$BE$6)/10*(10-($BO$1-BF1))+$BE$6 -> 15054.558 | BG6: =($BO$6-$BE$6)/10*(10-($BO$1-BG1))+$BE$6 -> 15365.185 | BH6: =($BO$6-$BE$6)/10*(10-($BO$1-BH1))+$BE$6 -> 15675.812 | BI6: =($BO$6-$BE$6)/10*(10-($BO$1-BI1))+$BE$6 -> 15986.439 | BJ6: =($BO$6-$BE$6)/10*(10-($BO$1-BJ1))+$BE$6 -> 16297.067 | BK6: =($BO$6-$BE$6)/10*(10-($BO$1-BK1))+$BE$6 -> 16607.694 | BL6: =($BO$6-$BE$6)/10*(10-($BO$1-BL1))+$BE$6 -> 16918.321 | BM6: =($BO$6-$BE$6)/10*(10-($BO$1-BM1))+$BE$6 -> 17228.948 | BN6: =($BO$6-$BE$6)/10*(10-($BO$1-BN1))+$BE$6 -> 17539.575 | BO6: 17850.202 | BP6: =($BY$6-$BO$6)/10*(10-($BY$1-BP1))+$BO$6 -> 18116.707 | BQ6: =($BY$6-$BO$6)/10*(10-($BY$1-BQ1))+$BO$6 -> 18383.211 | BR6: =($BY$6-$BO$6)/10*(10-($BY$1-BR1))+$BO$6 -> 18649.715 | BS6: =($BY$6-$BO$6)/10*(10-($BY$1-BS1))+$BO$6 -> 18916.219 | BT6: =($BY$6-$BO$6)/10*(10-($BY$1-BT1))+$BO$6 -> 19182.723 | BU6: =($BY$6-$BO$6)/10*(10-($BY$1-BU1))+$BO$6 -> 19449.227 | BV6: =($BY$6-$BO$6)/10*(10-($BY$1-BV1))+$BO$6 -> 19715.731 | BW6: =($BY$6-$BO$6)/10*(10-($BY$1-BW1))+$BO$6 -> 19982.235 | BX6: =($BY$6-$BO$6)/10*(10-($BY$1-BX1))+$BO$6 -> 20248.739 | BY6: 20515.243
AM8: 6600
D9: passenger ratio | AM9: 2407
D10: LDV | E10: 0.88825236 | AM10: 23
D11: HDV | E11: 0.11174764 | AM11: 4085.96
C13: LDV | D13: =D4*$E$10 -> 463.04595 | E13: =E4*$E$10 -> 647.98009 | F13: =F4*$E$10 -> 1532.1287 | G13: =G4*$E$10 -> 2327.5054 | H13: =H4*$E$10 -> 2550.8298 | I13: =I4*$E$10 -> 2835.87 | J13: =J4*$E$10 -> 3287.1555 | K13: =K4*$E$10 -> 3748.6914 | ... BY13: =BY4*$E$10 -> 39995.192
C14: HDV | D14: =D4*$E$11 -> 58.254047 | E14: =E4*$E$11 -> 81.519906 | F14: =F4*$E$11 -> 192.75128 | G14: =G4*$E$11 -> 292.81459 | H14: =H4*$E$11 -> 320.91018 | I14: =I4*$E$11 -> 356.77 | J14: =J4*$E$11 -> 413.54451 | K14: =K4*$E$11 -> 471.60858 | ... BY14: =BY4*$E$11 -> 5031.6427
C15: air | D15: 27.91 | E15: 39.56 | F15: 115.7163 | G15: 230.48 | H15: 301.32 | I15: 406.12 | J15: 477.6 | K15: 551.58 | L15: 681.3 | M15: 747.84 | N15: 773.52 | O15: 800.24 | P15: 857.3 | Q15: 970.54 | R15: 1091.35 | S15: 1268.7 | T15: 1263.19 | U15: 1782.3 | V15: 2044.93 | W15: 2370.66 | X15: 2791.7258 | Y15: 2882.7993 | Z15: 3375.2354 | AA15: 4038.996 | AB15: 4536.9629 | AC15: 5025.7366 | AD15: 5656.7596 | AE15: 6334.1903 | AF15: 7282.5513 | AG15: 8378.1348 | AH15: 9513.0358 | AI15: 10712.317 | AJ15: 11705.1 | AK15: 11641.189 | AL15: 11577.278 | AM15: 11513.366 | AN15: 11449.455 | AO15: 11385.544 | AP15: 11321.633 | AQ15: 11257.721 | AR15: 11193.81 | AS15: 11129.899 | AT15: 11065.988 | AU15: 11002.076 | AV15: 11376.262 | AW15: 11750.447 | AX15: 12124.633 | AY15: 12498.818 | AZ15: 12873.003 | BA15: 13247.189 | BB15: 13621.374 | BC15: 13995.56 | BD15: 14369.745 | BE15: 14743.931 | BF15: 15054.558 | BG15: 15365.185 | BH15: 15675.812 | BI15: 15986.439 | BJ15: 16297.067 | BK15: 16607.694 | BL15: 16918.321 | BM15: 17228.948 | BN15: 17539.575 | BO15: 17850.202 | BP15: 18116.707 | BQ15: 18383.211 | BR15: 18649.715 | BS15: 18916.219 | BT15: 19182.723 | BU15: 19449.227 | BV15: 19715.731 | BW15: 19982.235 | BX15: 20248.739 | BY15: 20515.243
C16: rail | D16: 1093.22 | E16: 1383.16 | F16: 2416.14 | G16: 2612.63 | H16: 2828.1 | I16: 3152.24 | J16: 3483.3 | K16: 3636 | L16: 3545.7 | M16: 3347.6 | N16: 3584.86 | O16: 3773.42 | P16: 4135.9 | Q16: 4532.59 | R16: 4766.82 | S16: 4969.4 | T16: 4788.61 | U16: 5712.2 | V16: 6061.96 | W16: 6622.1222 | X16: 7216.31 | Y16: 7778.6046 | Z16: 7878.8885 | AA16: 8762.1783 | AB16: 9612.2936 | AC16: 9812.3272 | AD16: 10595.619 | AE16: 11241.85 | AF16: 11960.604 | AG16: 12579.293 | AH16: 13456.92 | AI16: 14146.582 | AJ16: 14706.6 | AK16: 14713.28 | AL16: 14527.128 | AM16: 14437.392 | AN16: 14347.657 | AO16: 14257.921 | AP16: 14168.185 | AQ16: 14078.449 | AR16: 13988.713 | AS16: 13898.977 | AT16: 13809.241 | AU16: 13719.505 | AV16: 13971.614 | AW16: 14223.722 | AX16: 14475.83 | AY16: 14727.938 | AZ16: 14980.046 | BA16: 15232.154 | BB16: 15484.262 | BC16: 15736.37 | BD16: 15988.478 | BE16: 16240.586 | BF16: 16432.399 | BG16: 16624.211 | BH16: 16816.024 | BI16: 17007.837 | BJ16: 17199.649 | BK16: 17391.462 | BL16: 17583.274 | BM16: 17775.087 | BN16: 17966.9 | BO16: 18158.712 | BP16: 18317.131 | BQ16: 18475.55 | BR16: 18633.969 | BS16: 18792.388 | BT16: 18950.807 | BU16: 19109.226 | BV16: 19267.645 | BW16: 19426.064 | BX16: 19584.483 | BY16: 19742.902
C17: ship | D17: 100.63 | E17: 129.12 | F17: 178.65 | G17: 164.91 | H17: 177.2 | I17: 198.35 | J17: 196.4 | K17: 183.5 | L17: 171.8 | M17: 160.57 | N17: 155.7 | O17: 120.27 | P17: 107.28 | Q17: 100.54 | R17: 89.88 | S17: 81.8 | T17: 63.1 | U17: 66.3 | V17: 67.77 | W17: 73.5825 | X17: 77.7783 | Y17: 59.1796 | Z17: 69.3802 | AA17: 72.2701 | AB17: 74.5285 | AC17: 77.4791 | AD17: 68.3326 | AE17: 74.341293 | AF17: 73.084 | AG17: 72.326542 | AH17: 77.664137 | AI17: 79.574191 | AJ17: 80.2 | AK17: 78.225745 | AL17: 76.25149 | AM17: 74.277234 | AN17: 72.302979 | AO17: 70.328724 | AP17: 68.354469 | AQ17: 66.380214 | AR17: 64.405958 | AS17: 62.431703 | AT17: 60.457448 | AU17: 58.483193 | AV17: 57.940162 | AW17: 57.397131 | AX17: 56.854101 | AY17: 56.31107 | AZ17: 55.76804 | BA17: 55.225009 | BB17: 54.681978 | BC17: 54.138948 | BD17: 53.595917 | BE17: 53.052886 | BF17: 52.395832 | BG17: 51.738777 | BH17: 51.081723 | BI17: 50.424668 | BJ17: 49.767613 | BK17: 49.110559 | BL17: 48.453504 | BM17: 47.796449 | BN17: 47.139395 | BO17: 46.48234 | BP17: 45.846047 | BQ17: 45.209755 | BR17: 44.573462 | BS17: 43.937169 | BT17: 43.300877 | BU17: 42.664584 | BV17: 42.028291 | BW17: 41.391999 | BX17: 40.755706 | BY17: 40.119413
C20: relative to 2020
C21: LDV | D21: =D13/$AK$13 -> 0.010119579 | E21: =E13/$AK$13 -> 0.014161199 | F21: =F13/$AK$13 -> 0.033483713 | G21: =G13/$AK$13 -> 0.050866172 | H21: =H13/$AK$13 -> 0.055746787 | I21: =I13/$AK$13 -> 0.061976162 | J21: =J13/$AK$13 -> 0.071838723 | K21: =K13/$AK$13 -> 0.081925302 | ... BY21: =BY13/$AK$13 -> 0.87406987
C22: HDV | D22: =D14/$AK$14 -> 0.010119579 | E22: =E14/$AK$14 -> 0.014161199 | F22: =F14/$AK$14 -> 0.033483713 | G22: =G14/$AK$14 -> 0.050866172 | H22: =H14/$AK$14 -> 0.055746787 | I22: =I14/$AK$14 -> 0.061976162 | J22: =J14/$AK$14 -> 0.071838723 | K22: =K14/$AK$14 -> 0.081925302 | ... BY22: =BY14/$AK$14 -> 0.87406987
C23: air | D23: =D15/$AK$15 -> 0.0023975215 | E23: =E15/$AK$15 -> 0.0033982784 | F23: =F15/$AK$15 -> 0.0099402477 | G23: =G15/$AK$15 -> 0.019798665 | H23: =H15/$AK$15 -> 0.025883954 | I23: =I15/$AK$15 -> 0.034886472 | J23: =J15/$AK$15 -> 0.041026738 | K23: =K15/$AK$15 -> 0.047381759 | ... BY23: =BY15/$AK$15 -> 1.7622979
C24: rail | D24: =D16/$AK$16 -> 0.074301581 | E24: =E16/$AK$16 -> 0.094007588 | F24: =F16/$AK$16 -> 0.16421491 | G24: =G16/$AK$16 -> 0.17756951 | H24: =H16/$AK$16 -> 0.1922141 | I24: =I16/$AK$16 -> 0.21424454 | J24: =J16/$AK$16 -> 0.2367453 | K24: =K16/$AK$16 -> 0.24712368 | ... BY24: =BY16/$AK$16 -> 1.3418423
C25: ship | D25: =D17/$AK$17 -> 1.2864051 | E25: =E17/$AK$17 -> 1.6506075 | F25: =F17/$AK$17 -> 2.283775 | G25: =G17/$AK$17 -> 2.1081295 | H25: =H17/$AK$17 -> 2.2652389 | I25: =I17/$AK$17 -> 2.5356102 | J25: =J17/$AK$17 -> 2.5106824 | K25: =K17/$AK$17 -> 2.345775 | ... BY25: =BY17/$AK$17 -> 0.51286713
E28: 2019 | F28: 2020 | G28: 2021 | H28: 2022 | I28: 2023 | J28: 2024 | K28: 2025 | L28: 2026 | M28: 2027 | N28: 2028 | O28: 2029 | P28: 2030 | Q28: 2031 | R28: 2032 | S28: 2033 | T28: 2034 | U28: 2035 | V28: 2036 | W28: 2037 | X28: 2038 | Y28: 2039 | Z28: 2040 | AA28: 2041 | AB28: 2042 | AC28: 2043 | AD28: 2044 | AE28: 2045 | AF28: 2046 | AG28: 2047 | AH28: 2048 | AI28: 2049 | AJ28: 2050 | AK28: 2051 | AL28: 2052 | AM28: 2053 | AN28: 2054 | AO28: 2055 | AP28: 2056 | AQ28: 2057 | AR28: 2058 | AS28: 2059 | AT28: 2060
C29: 客运航空 | D29: 周转量 | E29: 11705.3 | F29: 6311.3 | G29: 6529.7 | H29: 3913.9 | I29: 10309 | J29: 12914.7 | K29: 14626 | L29: =($P29/$K29)^(0.2)*K29 -> 15498.981 | M29: =($P$29/$K$29)^(0.2)*L29 -> 16424.068 | N29: =($P$29/$K$29)^(0.2)*M29 -> 17404.37 | O29: =($P$29/$K$29)^(0.2)*N29 -> 18443.183 | P29: 19544 | Q29: =($U$29/$P$29)^(0.2)*P29 -> 20380.638 | R29: =($U$29/$P$29)^(0.2)*Q29 -> 21253.091 | S29: =($U$29/$P$29)^(0.2)*R29 -> 22162.891 | T29: =($U$29/$P$29)^(0.2)*S29 -> 23111.639 | U29: 24101 | V29: =($Z$29/$U$29)^(0.2)*U29 -> 24179.487 | W29: =($Z$29/$U$29)^(0.2)*V29 -> 24258.23 | X29: =($Z$29/$U$29)^(0.2)*W29 -> 24337.229 | Y29: =($Z$29/$U$29)^(0.2)*X29 -> 24416.485 | Z29: 24496 | AA29: =($AE$29/$Z$29)^(0.2)*Z29 -> 24624.25 | AB29: =($AE$29/$Z$29)^(0.2)*AA29 -> 24753.172 | AC29: =($AE$29/$Z$29)^(0.2)*AB29 -> 24882.768 | AD29: =($AE$29/$Z$29)^(0.2)*AC29 -> 25013.043 | AE29: 25144 | AF29: =($AJ$29/$AE$29)^(0.2)*AE29 -> 24979.666 | AG29: =($AJ$29/$AE$29)^(0.2)*AF29 -> 24816.406 | AH29: =($AJ$29/$AE$29)^(0.2)*AG29 -> 24654.213 | AI29: =($AJ$29/$AE$29)^(0.2)*AH29 -> 24493.08 | AJ29: 24333 | AK29: =($AO$29/$AJ$29)^(0.2)*AJ29 -> 23785.073 | AL29: =($AO$29/$AJ$29)^(0.2)*AK29 -> 23249.484 | AM29: =($AO$29/$AJ$29)^(0.2)*AL29 -> 22725.956 | AN29: =($AO$29/$AJ$29)^(0.2)*AM29 -> 22214.216 | AO29: 21714 | AP29: =($AT$29/$AO$29)^(0.2)*AO29 -> 21025.274 | AQ29: =($AT$29/$AO$29)^(0.2)*AP29 -> 20358.393 | AR29: =($AT$29/$AO$29)^(0.2)*AQ29 -> 19712.664 | AS29: =($AT$29/$AO$29)^(0.2)*AR29 -> 19087.416 | AT29: 18482
D30: BCD | E30: =E29/$E$29 -> 1 | F30: =F29/$E$29 -> 0.53918311 | G30: =G29/$E$29 -> 0.55784132 | H30: =H29/$E$29 -> 0.3343699 | I30: =I29/$E$29 -> 0.88071216 | J30: =J29/$E$29 -> 1.1033207 | K30: =K29/$E$29 -> 1.2495194 | L30: =L29/$E$29 -> 1.3240994 | ... AT30: =AT29/$E$29 -> 1.5789429
C31: 客运铁路 | D31: 周转量 | E31: 14706.6 | F31: 8266.2 | G31: 9567.8 | H31: 6577.5 | I31: 14729.4 | J31: 15799.1 | K31: 15603.503 | L31: 16059.819 | M31: 16529.48 | N31: 17012.875 | O31: 17510.407 | P31: 18022.49 | Q31: 18549.547 | R31: 19092.018 | S31: 19650.354 | T31: 20225.018 | U31: 20816.487 | V31: 21232.817 | W31: 21657.473 | X31: 22090.623 | Y31: 22532.435 | Z31: 22983.084 | AA31: 23442.746 | AB31: 23911.6 | AC31: 24389.832 | AD31: 24877.629 | AE31: 25375.182 | AF31: 25628.934 | AG31: 25885.223 | AH31: 26144.075 | AI31: 26405.516 | AJ31: 26669.571 | AK31: 26936.267 | AL31: 27205.629 | AM31: 27477.686 | AN31: 27752.463 | AO31: 27752.463 | AP31: 27891.225 | AQ31: 28030.681 | AR31: 28170.834 | AS31: 28311.689 | AT31: 28453.247
D32: BCD | E32: =E31/$E31 -> 1 | F32: =F31/$E$31 -> 0.56207417 | G32: =G31/$E$31 -> 0.65057865 | H32: =H31/$E$31 -> 0.44724817 | I32: =I31/$E$31 -> 1.0015503 | J32: =J31/$E$31 -> 1.0742864 | K32: =K31/$E$31 -> 1.0609865 | L32: =L31/$E$31 -> 1.0920144 | M32: =M31/$E$31 -> 1.1239498 | ... AT32: =AT31/$E$31 -> 1.9347264
C33: 客运水运 | D33: 周转量 | E33: 80.2 | F33: 33 | G33: 33.1 | H33: 22.6 | I33: 53.8 | J33: 54.7 | K33: 55.97352 | L33: 57.09299 | M33: 58.23485 | N33: 59.399547 | O33: 60.587538 | P33: 61.799289 | Q33: 63.035275 | R33: 64.29598 | S33: 65.5819 | T33: 66.893538 | U33: 68.231409 | V33: 68.572566 | W33: 68.915428 | X33: 69.260006 | Y33: 69.606306 | Z33: 69.954337 | AA33: 70.304109 | AB33: 70.655629 | AC33: 71.008907 | AD33: 71.363952 | AE33: 71.720772 | AF33: 71.864213 | AG33: 72.007942 | AH33: 72.151958 | AI33: 72.296262 | AJ33: 72.440854 | AK33: 72.585736 | AL33: 72.730907 | AM33: 72.876369 | AN33: 73.022122 | AO33: 73.022122 | AP33: 73.168166 | AQ33: 73.314502 | AR33: 73.461131 | AS33: 73.608054 | AT33: 73.75527
D34: BCD | E34: =E33/$E33 -> 1 | F34: =F33/$E33 -> 0.41147132 | G34: =G33/$E33 -> 0.4127182 | H34: =H33/$E33 -> 0.28179551 | I34: =I33/$E33 -> 0.67082294 | J34: =J33/$E33 -> 0.68204489 | K34: =K33/$E33 -> 0.69792419 | L34: =L33/$E33 -> 0.71188267 | ... AT34: =AT33/$E33 -> 0.91964177
C35: LDV | D35: 周转量 | E35: =E41+E42 -> 40404.153 | F35: =F41+F42 -> 37647.358 | G35: =G41+G42 -> 39816.103 | H35: =H41+H42 -> 38580.837 | I35: =I41+I42 -> 37514.213 | J35: =J41+J42 -> 37015.327 | K35: =K41+K42 -> 38945.826 | L35: =L41+L42 -> 40714.742 | ... AT35: =AT41+AT42 -> 38561.536
D36: BCD | E36: =E35/$E35 -> 1 | F36: =F35/$E35 -> 0.93176953 | G36: =G35/$E35 -> 0.98544582 | H36: =H35/$E35 -> 0.95487307 | I36: =I35/$E35 -> 0.9284742 | J36: =J35/$E35 -> 0.91612681 | K36: =K35/$E35 -> 0.96390652 | L36: =L35/$E35 -> 1.0076871 | ... AT36: =AT35/$E35 -> 0.95439536
C37: HDV | D37: 周转量 | E37: =E43+E44 -> 20683.627 | F37: =F43+F44 -> 15024.314 | G37: =G43+G44 -> 14677.075 | H37: =H43+H44 -> 13325.719 | I37: =I43+I44 -> 15802.422 | J37: =J43+J44 -> 15742.834 | K37: =K43+K44 -> 15674.563 | L37: =L43+L44 -> 15608.444 | ... AT37: =AT43+AT44 -> 14891.741
D38: BCD | E38: =E37/$E37 -> 1 | F38: =F37/$E37 -> 0.72638682 | G38: =G37/$E37 -> 0.70959871 | H38: =H37/$E37 -> 0.64426416 | I38: =I37/$E37 -> 0.76400637 | J38: =J37/$E37 -> 0.7611254 | K38: =K37/$E37 -> 0.75782468 | L38: =L37/$E37 -> 0.75462803 | ... AT38: =AT37/$E37 -> 0.71997726
C39: 道路客运
C40: 客运周转量 | E40: 2019 | F40: 2020 | G40: 2021 | H40: 2022 | I40: 2023 | J40: 2024 | K40: 2025 | L40: 2026 | M40: 2027 | N40: 2028 | O40: 2029 | P40: 2030 | Q40: 2031 | R40: 2032 | S40: 2033 | T40: 2034 | U40: 2035 | V40: 2036 | W40: 2037 | X40: 2038 | Y40: 2039 | Z40: 2040 | AA40: 2041 | AB40: 2042 | AC40: 2043 | AD40: 2044 | AE40: 2045 | AF40: 2046 | AG40: 2047 | AH40: 2048 | AI40: 2049 | AJ40: 2050 | AK40: 2051 | AL40: 2052 | AM40: 2053 | AN40: 2054 | AO40: 2055 | AP40: 2056 | AQ40: 2057 | AR40: 2058 | AS40: 2059 | AT40: 2060
C41: 乘用车 | E41: =22241.62*1.25*1.11111235721358/0.873698773342676 -> 35356.778 | F41: =23940.89*1.25*0.965899928884944/0.873698773342676 -> 33084.206 | G41: =25797.39*1.25*0.93/0.873698773342676 -> 34324.72 | H41: 33421.897 | I41: 32306.333 | J41: 31815.001 | K41: 33754.178 | L41: 35531.525 | M41: 36888.525 | N41: 37957.195 | O41: 38817.161 | P41: 39566.082 | Q41: 40188.48 | R41: 40751.631 | S41: 41226.597 | T41: 41613.746 | U41: 41909.001 | V41: 42145.008 | W41: 42294.919 | X41: 42370.706 | Y41: 42378.835 | Z41: 42324.934 | AA41: 42219.096 | AB41: 42059.964 | AC41: 41852.067 | AD41: 41600.035 | AE41: 41307.452 | AF41: 40980.79 | AG41: 40619.883 | AH41: 40228.019 | AI41: 39809.236 | AJ41: 39366.704 | AK41: 38911.382 | AL41: 38429.874 | AM41: 37922.537 | AN41: 37389.427 | AO41: 36830.342 | AP41: 36245.306 | AQ41: 35633.171 | AR41: 34993.231 | AS41: 34324.637 | AT41: 33626.075
C42: 出租车 | E42: =9.6*1.25*330.741*1.11111235721358/0.873698773342676 -> 5047.3745 | F42: =9.6*1.25*343.964277*0.965899928884944/0.873698773342676 -> 4563.1526 | G42: =9.6*1.25*429.9117*0.93/0.873698773342676 -> 5491.383 | H42: 5158.9404 | I42: 5207.88 | J42: 5200.3266 | K42: 5191.6484 | L42: 5183.2167 | M42: 5176.302 | N42: 5170.3804 | O42: 5165.1384 | P42: 5160.0679 | Q42: 5155.3018 | R42: 5150.3884 | S42: 5145.5256 | T42: 5140.7324 | U42: 5125.894 | V42: 5110.5768 | W42: 5095.9007 | X42: 5081.6911 | Y42: 5067.9753 | Z42: 5054.7893 | AA42: 5041.7769 | AB42: 5029.3718 | AC42: 5017.6164 | AD42: 5006.5477 | AE42: 4996.2089 | AF42: 4985.9989 | AG42: 4976.5876 | AH42: 4968.0101 | AI42: 4960.2895 | AJ42: 4953.4532 | AK42: 4946.7206 | AL42: 4940.9957 | AM42: 4936.3276 | AN42: 4932.7669 | AO42: 4930.3653 | AP42: 4928.5976 | AQ42: 4928.0892 | AR42: 4928.8957 | AS42: 4931.0739 | AT42: 4935.4606
C43: 公交车 | E43: =(47701.5602677324+536324.439732268)*45000*45/10^8 -> 11826.527 | F43: =(48186.3139605286+541774.686039471)*4.4*40/10^4 -> 10383.314 | G43: =(57945.2593223947+651497.740677605)*4.45*35/10^4 -> 11049.575 | H43: 10918.219 | I43: 11062.422 | J43: 11030.333 | K43: 10993.519 | L43: 10957.81 | M43: 10928.573 | N43: 10903.569 | O43: 10881.46 | P43: 10860.096 | Q43: 10840.034 | R43: 10819.371 | S43: 10798.94 | T43: 10778.821 | U43: 10767.154 | V43: 10755.089 | W43: 10743.507 | X43: 10732.273 | Y43: 10721.41 | Z43: 10710.949 | AA43: 10700.609 | AB43: 10690.736 | AC43: 10681.366 | AD43: 10672.53 | AE43: 10664.265 | AF43: 10656.093 | AG43: 10648.55 | AH43: 10641.667 | AI43: 10635.466 | AJ43: 10629.969 | AK43: 10624.551 | AL43: 10619.94 | AM43: 10616.178 | AN43: 10613.306 | AO43: 10611.368 | AP43: 10609.941 | AQ43: 10609.531 | AR43: 10610.182 | AS43: 10611.94 | AT43: 10615.481
C44: 道路客车 | E44: 8857.1 | F44: 4641 | G44: 3627.5 | H44: 2407.5 | I44: 4740 | J44: 4712.5007 | K44: 4681.0442 | L44: 4650.6346 | M44: 4625.8177 | N44: 4604.6504 | O44: 4585.9766 | P44: 4567.9688 | Q44: 4551.0921 | R44: 4533.7419 | S44: 4516.6194 | T44: 4499.79 | U44: 4483.5546 | V44: 4466.8074 | W44: 4450.7732 | X44: 4435.2598 | Y44: 4420.296 | Z44: 4405.9199 | AA44: 4391.7424 | AB44: 4378.2353 | AC44: 4365.4434 | AD44: 4353.4059 | AE44: 4342.1683 | AF44: 4331.0766 | AG44: 4320.8577 | AH44: 4311.5486 | AI44: 4303.173 | AJ44: 4295.7597 | AK44: 4288.4614 | AL44: 4282.2574 | AM44: 4277.2003 | AN44: 4273.3437 | AO44: 4270.7431 | AP44: 4268.829 | AQ44: 4268.2787 | AR44: 4269.1517 | AS44: 4271.51 | AT44: 4276.26

Sheet 2022交科院
B1: 铁路旅客周转量(亿人公里) | C1: 公路旅客周转量(亿人公里) | D1: 水运旅客周转量(亿人公里) | E1: 民用航空旅客周转量(亿人公里) | F1: 公交车(亿人次) | G1: 轨道交通(亿人次) | H1: 巡游出租车(亿人次) | I1: 网约车(亿人次) | J1: 私家车出行(亿人次) | K1: 铁路货物周转量(亿吨公里) | L1: 公路货物周转量(亿吨公里) | M1: 内河货运周转量 (亿吨公里) | N1: 沿海货运周转量(亿吨公里) | O1: 民用航空货物周转量(亿吨公里) | P1: 远洋
A2: 2020 | B2: 8266 | C2: 4641 | D2: 33.00 | E2: 5892 | F2: 442 | G2: 176 | H2: 320 | I2: 379 | J2: 249 | K2: 30515 | L2: 83282 | M2: 16764 | N2: 34036 | O2: 67
A3: 2025 | B3: 19740 | C3: 8515 | D3: 90 | E3: 14626 | F3: 676 | G3: 357 | H3: 304 | I3: 409 | J3: 1664 | K3: 38622 | L3: 93599 | M3: 19278 | N3: 37672 | O3: 95 | P3: 88108.832
A4: 2030 | B4: 26143 | C4: 8467 | D4: 98 | E4: 19544 | F4: 670 | G4: 591 | H4: 289 | I4: 429 | J4: 2393 | K4: 41810 | L4: 109910 | M4: 21364 | N4: 41580 | O4: 112 | P4: 95744.317
A5: 2035 | B5: 32149 | C5: 7079 | D5: 97 | E5: 24101 | F5: 644 | G5: 920 | H5: 266 | I5: 447 | J5: 2724 | K5: 44461 | L5: 127932 | M5: 23726 | N5: 45505 | O5: 127 | P5: 100761.26
A6: 2040 | B6: 39395 | C6: 8496 | D6: 89 | E6: 24496 | F6: 606 | G6: 1117 | H6: 239 | I6: 461 | J6: 3337 | K6: 48066 | L6: 143831 | M6: 26279 | N6: 49367 | O6: 139 | P6: 105362.26
A7: 2045 | B7: 47081 | C7: 8035 | D7: 76 | E7: 25144 | F7: 551 | G7: 1133 | H7: 227 | I7: 472 | J7: 4062 | K7: 49671 | L7: 162610 | M7: 26388 | N7: 50374 | O7: 143 | P7: 109254.24
A8: 2050 | B8: 53109 | C8: 6996 | D8: 56 | E8: 24333 | F8: 498 | G8: 1091 | H8: 215 | I8: 484 | J8: 4585 | K8: 51277 | L8: 181928 | M8: 26498 | N8: 51381 | O8: 146 | P8: 112762.26
A9: 2055 | B9: 60948 | C9: 4853 | D9: 48 | E9: 21714 | F9: 412 | G9: 989 | H9: 194 | I9: 489 | J9: 4790 | K9: 53097 | L9: 197391 | M9: 26625 | N9: 51704 | O9: 148 | P9: 113973.62
A10: 2060 | B10: 67849 | C10: 2481 | D10: 48 | E10: 18482 | F10: 332 | G10: 901 | H10: 172 | I10: 494 | J10: 4720 | K10: 54917 | L10: 204943 | M10: 26752 | N10: 52026 | O10: 150 | P10: 115184.98

Sheet freight
A1: Year | D1: 1978 | E1: 1980 | F1: 1985 | G1: 1990 | H1: 1991 | I1: 1992 | J1: 1993 | K1: 1994 | L1: 1995 | M1: 1996 | N1: 1997 | O1: 1998 | P1: 1999 | Q1: 2000 | R1: 2001 | S1: 2002 | T1: 2003 | U1: 2004 | V1: 2005 | W1: 2006 | X1: 2007 | Y1: 2008 | Z1: 2009 | AA1: 2010 | AB1: 2011 | AC1: 2012 | AD1: 2013 | AE1: 2014 | AF1: 2015 | AG1: 2016 | AH1: 2017 | AI1: 2018 | AJ1: 2019 | AK1: 2020 | AL1: 2021 | AM1: 2022 | AN1: 2023 | AO1: 2024 | AP1: 2025 | AQ1: 2026 | AR1: 2027 | AS1: 2028 | AT1: 2029 | AU1: 2030 | AV1: 2031 | AW1: 2032 | AX1: 2033 | AY1: 2034 | AZ1: 2035 | BA1: 2036 | BB1: 2037 | BC1: 2038 | BD1: 2039 | BE1: 2040 | BF1: 2041 | BG1: 2042 | BH1: 2043 | BI1: 2044 | BJ1: 2045 | BK1: 2046 | BL1: 2047 | BM1: 2048 | BN1: 2049 | BO1: 2050 | BP1: 2051 | BQ1: 2052 | BR1: 2053 | BS1: 2054 | BT1: 2055 | BU1: 2056 | BV1: 2057 | BW1: 2058 | BX1: 2059 | BY1: 2060
A2: Total | D2: 9928 | E2: 11629 | F2: 18365 | G2: 26208 | H2: 27987 | I2: 29218 | J2: 30646.81 | K2: 33435.48 | L2: 35908.9 | M2: 36589.8 | N2: 38384.7 | O2: 38088.7 | P2: 40567.8 | Q2: 44320.5 | R2: 47709.9 | S2: 50685.9 | T2: 53859.2 | U2: 69445 | V2: 80258.1 | W2: 88839.851 | X2: 101418.81 | Y2: 110300 | Z2: 122133.31 | AA2: 141837.42 | AB2: 159323.6 | AC2: 173804.46 | AD2: 168013.8 | AE2: 181667.69 | AF2: 178355.9 | AG2: 186629.48 | AH2: 197372.65 | AI2: 204686.24 | AJ2: =SUM(AJ3:AJ7) -> 248101.58 | AK2: =SUM(AK3:AK7) -> 286657.95 | AL2: =SUM(AL3:AL7) -> 302296.96
A3: Railways | D3: 5345.19 | E3: 5717.5 | F3: 8125.66 | G3: 10622.38 | H3: 10972 | I3: 11575.55 | J3: 12090.9 | K3: 12632 | L3: 13049.48 | M3: 13106.2 | N3: 13269.9 | O3: 12560.1 | P3: 12910.3 | Q3: 13770.49 | R3: 14694.1 | S3: 15658.4 | T3: 17246.7 | U3: 19288.8 | V3: 20726 | W3: 21954.41 | X3: 23797 | Y3: 25106.282 | Z3: 25239.169 | AA3: 27644.133 | AB3: 29465.785 | AC3: 29187.086 | AD3: 29173.891 | AE3: 27530.19 | AF3: 23754.308 | AG3: 23792.262 | AH3: 26962.204 | AI3: 28820.986 | AJ3: 30181.95 | AK3: 30514.46 | AL3: =($AU$3-$AK$3)/10*(10-($AU$1-AL1))+$AK$3 -> 33223.014 | AM3: =($AU$3-$AK$3)/10*(10-($AU$1-AM1))+$AK$3 -> 35931.568 | AN3: =($AU$3-$AK$3)/10*(10-($AU$1-AN1))+$AK$3 -> 38640.122 | AO3: =($AU$3-$AK$3)/10*(10-($AU$1-AO1))+$AK$3 -> 41348.676 | AP3: =($AU$3-$AK$3)/10*(10-($AU$1-AP1))+$AK$3 -> 44057.23 | AQ3: =($AU$3-$AK$3)/10*(10-($AU$1-AQ1))+$AK$3 -> 46765.784 | AR3: =($AU$3-$AK$3)/10*(10-($AU$1-AR1))+$AK$3 -> 49474.338 | AS3: =($AU$3-$AK$3)/10*(10-($AU$1-AS1))+$AK$3 -> 52182.892 | AT3: =($AU$3-$AK$3)/10*(10-($AU$1-AT1))+$AK$3 -> 54891.446 | AU3: 57600 | AV3: =($BE$3-$AU$3)/10*1+$AU$3 -> 60520 | AW3: =($BE$3-$AU$3)/10*2+$AU$3 -> 63440 | AX3: =($BE$3-$AU$3)/10*3+$AU$3 -> 66360 | AY3: =($BE$3-$AU$3)/10*4+$AU$3 -> 69280 | AZ3: =($BE$3-$AU$3)/10*5+$AU$3 -> 72200 | BA3: =($BE$3-$AU$3)/10*6+$AU$3 -> 75120 | BB3: =($BE$3-$AU$3)/10*7+$AU$3 -> 78040 | BC3: =($BE$3-$AU$3)/10*8+$AU$3 -> 80960 | BD3: =($BE$3-$AU$3)/10*9+$AU$3 -> 83880 | BE3: 86800 | BF3: =($BO$3-$BE$3)/10*(10-($BO$1-BF1))+$BE$3 -> 90020 | BG3: =($BO$3-$BE$3)/10*(10-($BO$1-BG1))+$BE$3 -> 93240 | BH3: =($BO$3-$BE$3)/10*(10-($BO$1-BH1))+$BE$3 -> 96460 | BI3: =($BO$3-$BE$3)/10*(10-($BO$1-BI1))+$BE$3 -> 99680 | BJ3: =($BO$3-$BE$3)/10*(10-($BO$1-BJ1))+$BE$3 -> 102900 | BK3: =($BO$3-$BE$3)/10*(10-($BO$1-BK1))+$BE$3 -> 106120 | BL3: =($BO$3-$BE$3)/10*(10-($BO$1-BL1))+$BE$3 -> 109340 | BM3: =($BO$3-$BE$3)/10*(10-($BO$1-BM1))+$BE$3 -> 112560 | BN3: =($BO$3-$BE$3)/10*(10-($BO$1-BN1))+$BE$3 -> 115780 | BO3: 119000 | BP3: =($BY$3-$BO$3)/10*(10-($BY$1-BP1))+$BO$3 -> 121200 | BQ3: =($BY$3-$BO$3)/10*(10-($BY$1-BQ1))+$BO$3 -> 123400 | BR3: =($BY$3-$BO$3)/10*(10-($BY$1-BR1))+$BO$3 -> 125600 | BS3: =($BY$3-$BO$3)/10*(10-($BY$1-BS1))+$BO$3 -> 127800 | BT3: =($BY$3-$BO$3)/10*(10-($BY$1-BT1))+$BO$3 -> 130000 | BU3: =($BY$3-$BO$3)/10*(10-($BY$1-BU1))+$BO$3 -> 132200 | BV3: =($BY$3-$BO$3)/10*(10-($BY$1-BV1))+$BO$3 -> 134400 | BW3: =($BY$3-$BO$3)/10*(10-($BY$1-BW1))+$BO$3 -> 136600 | BX3: =($BY$3-$BO$3)/10*(10-($BY$1-BX1))+$BO$3 -> 138800 | BY3: 141000
A4: Highways | D4: 350.3 | E4: 342.9 | F4: 1903 | G4: 3358.1 | H4: 3428 | I4: 3755.39 | J4: 4070.5 | K4: 4486.3 | L4: 4694.9 | M4: 5011.2 | N4: 5271.5 | O4: 5483.38 | P4: 5724.3 | Q4: 6129.4 | R4: 6330.4 | S4: 6782.5 | T4: 7099.4756 | U4: 7840.9 | V4: 8693.2 | W4: 9754.2476 | X4: 11354.687 | Y4: 32868.186 | Z4: 37188.821 | AA4: 43389.672 | AB4: 51374.741 | AC4: 59534.865 | AD4: 55738.077 | AE4: 56846.9 | AF4: 57955.724 | AG4: 61080.097 | AH4: 66771.516 | AI4: 71249.212 | AJ4: 59636.39 | AK4: 60171.85 | AL4: =($AU$4-$AK$4)/10*(10-($AU$1-AL1))+$AK$4 -> 61904.665 | AM4: =($AU$4-$AK$4)/10*(10-($AU$1-AM1))+$AK$4 -> 63637.48 | AN4: =($AU$4-$AK$4)/10*(10-($AU$1-AN1))+$AK$4 -> 65370.295 | AO4: =($AU$4-$AK$4)/10*(10-($AU$1-AO1))+$AK$4 -> 67103.11 | AP4: =($AU$4-$AK$4)/10*(10-($AU$1-AP1))+$AK$4 -> 68835.925 | AQ4: =($AU$4-$AK$4)/10*(10-($AU$1-AQ1))+$AK$4 -> 70568.74 | AR4: =($AU$4-$AK$4)/10*(10-($AU$1-AR1))+$AK$4 -> 72301.555 | AS4: =($AU$4-$AK$4)/10*(10-($AU$1-AS1))+$AK$4 -> 74034.37 | AT4: =($AU$4-$AK$4)/10*(10-($AU$1-AT1))+$AK$4 -> 75767.185 | AU4: 77500 | AV4: =($BE$4-$AU$4)/10*(10-($BE$1-AV1))+$AU$4 -> 78580 | AW4: =($BE$4-$AU$4)/10*(10-($BE$1-AW1))+$AU$4 -> 79660 | AX4: =($BE$4-$AU$4)/10*(10-($BE$1-AX1))+$AU$4 -> 80740 | AY4: =($BE$4-$AU$4)/10*(10-($BE$1-AY1))+$AU$4 -> 81820 | AZ4: =($BE$4-$AU$4)/10*(10-($BE$1-AZ1))+$AU$4 -> 82900 | BA4: =($BE$4-$AU$4)/10*(10-($BE$1-BA1))+$AU$4 -> 83980 | BB4: =($BE$4-$AU$4)/10*(10-($BE$1-BB1))+$AU$4 -> 85060 | BC4: =($BE$4-$AU$4)/10*(10-($BE$1-BC1))+$AU$4 -> 86140 | BD4: =($BE$4-$AU$4)/10*(10-($BE$1-BD1))+$AU$4 -> 87220 | BE4: 88300 | BF4: =($BO$4-$BE$4)/10*(10-($BO$1-BF1))+$BE$4 -> 89060 | BG4: =($BO$4-$BE$4)/10*(10-($BO$1-BG1))+$BE$4 -> 89820 | BH4: =($BO$4-$BE$4)/10*(10-($BO$1-BH1))+$BE$4 -> 90580 | BI4: =($BO$4-$BE$4)/10*(10-($BO$1-BI1))+$BE$4 -> 91340 | BJ4: =($BO$4-$BE$4)/10*(10-($BO$1-BJ1))+$BE$4 -> 92100 | BK4: =($BO$4-$BE$4)/10*(10-($BO$1-BK1))+$BE$4 -> 92860 | BL4: =($BO$4-$BE$4)/10*(10-($BO$1-BL1))+$BE$4 -> 93620 | BM4: =($BO$4-$BE$4)/10*(10-($BO$1-BM1))+$BE$4 -> 94380 | BN4: =($BO$4-$BE$4)/10*(10-($BO$1-BN1))+$BE$4 -> 95140 | BO4: 95900 | BP4: =($BY$4-$BO$4)/10*(10-($BY$1-BP1))+$BO$4 -> 96110 | BQ4: =($BY$4-$BO$4)/10*(10-($BY$1-BQ1))+$BO$4 -> 96320 | BR4: =($BY$4-$BO$4)/10*(10-($BY$1-BR1))+$BO$4 -> 96530 | BS4: =($BY$4-$BO$4)/10*(10-($BY$1-BS1))+$BO$4 -> 96740 | BT4: =($BY$4-$BO$4)/10*(10-($BY$1-BT1))+$BO$4 -> 96950 | BU4: =($BY$4-$BO$4)/10*(10-($BY$1-BU1))+$BO$4 -> 97160 | BV4: =($BY$4-$BO$4)/10*(10-($BY$1-BV1))+$BO$4 -> 97370 | BW4: =($BY$4-$BO$4)/10*(10-($BY$1-BW1))+$BO$4 -> 97580 | BX4: =($BY$4-$BO$4)/10*(10-($BY$1-BX1))+$BO$4 -> 97790 | BY4: 98000
A5: Waterways | D5: 3801.8 | E5: 5076.5 | F5: 7729.3 | G5: 11591.9 | H5: 12955.4 | I5: 13256.2 | J5: 13860.8 | K5: 15686.6 | L5: 17552.2 | M5: 17862.5 | N5: 19235 | O5: 19405.8 | P5: 21262.8 | Q5: 23734.2 | R5: 25988.9 | S5: 27510.6 | T5: 28715.8 | U5: 41428.7 | V5: 49672.3 | W5: 55485.749 | X5: 64284.846 | Y5: 50262.704 | Z5: 57556.672 | AA5: 68427.526 | AB5: 75423.836 | AC5: 81707.579 | AD5: 79435.651 | AE5: 92774.556 | AF5: 91772.451 | AG5: 97338.802 | AH5: 98611.246 | AI5: 99052.815 | AJ5: 103963.04 | AK5: 105834.44 | AL5: =($AU$5-$AK$5)/10*(10-($AU$1-AL1))+$AK$5 -> 109051 | AM5: =($AU$5-$AK$5)/10*(10-($AU$1-AM1))+$AK$5 -> 112267.55 | AN5: =($AU$5-$AK$5)/10*(10-($AU$1-AN1))+$AK$5 -> 115484.11 | AO5: =($AU$5-$AK$5)/10*(10-($AU$1-AO1))+$AK$5 -> 118700.66 | AP5: =($AU$5-$AK$5)/10*(10-($AU$1-AP1))+$AK$5 -> 121917.22 | AQ5: =($AU$5-$AK$5)/10*(10-($AU$1-AQ1))+$AK$5 -> 125133.78 | AR5: =($AU$5-$AK$5)/10*(10-($AU$1-AR1))+$AK$5 -> 128350.33 | AS5: =($AU$5-$AK$5)/10*(10-($AU$1-AS1))+$AK$5 -> 131566.89 | AT5: =($AU$5-$AK$5)/10*(10-($AU$1-AT1))+$AK$5 -> 134783.44 | AU5: 138000 | AV5: =($BE$5-$AU$5)/10*(10-($BE$1-AV1))+$AU$5 -> 140800 | AW5: =($BE$5-$AU$5)/10*(10-($BE$1-AW1))+$AU$5 -> 143600 | AX5: =($BE$5-$AU$5)/10*(10-($BE$1-AX1))+$AU$5 -> 146400 | AY5: =($BE$5-$AU$5)/10*(10-($BE$1-AY1))+$AU$5 -> 149200 | AZ5: =($BE$5-$AU$5)/10*(10-($BE$1-AZ1))+$AU$5 -> 152000 | BA5: =($BE$5-$AU$5)/10*(10-($BE$1-BA1))+$AU$5 -> 154800 | BB5: =($BE$5-$AU$5)/10*(10-($BE$1-BB1))+$AU$5 -> 157600 | BC5: =($BE$5-$AU$5)/10*(10-($BE$1-BC1))+$AU$5 -> 160400 | BD5: =($BE$5-$AU$5)/10*(10-($BE$1-BD1))+$AU$5 -> 163200 | BE5: 166000 | BF5: =($BO$5-$BE$5)/10*(10-($BO$1-BF1))+$BE$5 -> 167800 | BG5: =($BO$5-$BE$5)/10*(10-($BO$1-BG1))+$BE$5 -> 169600 | BH5: =($BO$5-$BE$5)/10*(10-($BO$1-BH1))+$BE$5 -> 171400 | BI5: =($BO$5-$BE$5)/10*(10-($BO$1-BI1))+$BE$5 -> 173200 | BJ5: =($BO$5-$BE$5)/10*(10-($BO$1-BJ1))+$BE$5 -> 175000 | BK5: =($BO$5-$BE$5)/10*(10-($BO$1-BK1))+$BE$5 -> 176800 | BL5: =($BO$5-$BE$5)/10*(10-($BO$1-BL1))+$BE$5 -> 178600 | BM5: =($BO$5-$BE$5)/10*(10-($BO$1-BM1))+$BE$5 -> 180400 | BN5: =($BO$5-$BE$5)/10*(10-($BO$1-BN1))+$BE$5 -> 182200 | BO5: 184000 | BP5: =($BY$5-$BO$5)/10*(10-($BY$1-BP1))+$BO$5 -> 185900 | BQ5: =($BY$5-$BO$5)/10*(10-($BY$1-BQ1))+$BO$5 -> 187800 | BR5: =($BY$5-$BO$5)/10*(10-($BY$1-BR1))+$BO$5 -> 189700 | BS5: =($BY$5-$BO$5)/10*(10-($BY$1-BS1))+$BO$5 -> 191600 | BT5: =($BY$5-$BO$5)/10*(10-($BY$1-BT1))+$BO$5 -> 193500 | BU5: =($BY$5-$BO$5)/10*(10-($BY$1-BU1))+$BO$5 -> 195400 | BV5: =($BY$5-$BO$5)/10*(10-($BY$1-BV1))+$BO$5 -> 197300 | BW5: =($BY$5-$BO$5)/10*(10-($BY$1-BW1))+$BO$5 -> 199200 | BX5: =($BY$5-$BO$5)/10*(10-($BY$1-BX1))+$BO$5 -> 201100 | BY5: 203000
B6: Ocean | D6: 2487 | E6: 3532 | F6: 5329 | G6: 8140.86 | H6: 8990.4 | I6: 9034 | J6: 9133.9 | K6: 10267.7 | L6: 11938 | M6: 11254 | N6: 14874.7 | O6: 14920.28 | P6: 17014.4 | Q6: 17073 | R6: 20873 | S6: 21733 | T6: 22304.77 | U6: 32255 | V6: 38552 | W6: 42577.3 | X6: 48685.894 | Y6: 32851 | Z6: 39524 | AA6: 45999 | AB6: 49355 | AC6: 53412.101 | AD6: 48705.368 | AE6: 55935.062 | AF6: 54236.094 | AG6: 58074.6 | AH6: 55083.857 | AI6: 51926.58 | AJ6: 54057 | AK6: 89897 | AL6: 97842
A7: Civil | B7: Aviation | D7: 0.97 | E7: 1.41 | F7: 4.15 | G7: 8.18 | H7: 10.1 | I7: 13.42 | J7: 16.61 | K7: 18.58 | L7: 22.3 | M7: 24.93 | N7: 29.1 | O7: 33.45 | P7: 42.34 | Q7: 50.27 | R7: 43.72 | S7: 51.55 | T7: 57.9 | U7: 71.8 | V7: 78.9 | W7: 94.27526 | X7: 116.38667 | Y7: 119.60227 | Z7: 126.2307 | AA7: 178.89816 | AB7: 173.91 | AC7: 163.88936 | AD7: 170.29181 | AE7: 187.77149 | AF7: 208.0683 | AG7: 222.44934 | AH7: 243.55229 | AI7: 262.49911 | AJ7: 263.2 | AK7: 240.2 | AL7: =($AU$7-$AK$7)/10*(10-($AU$1-AL1))+$AK$7 -> 276.28 | AM7: =($AU$7-$AK$7)/10*(10-($AU$1-AM1))+$AK$7 -> 312.36 | AN7: =($AU$7-$AK$7)/10*(10-($AU$1-AN1))+$AK$7 -> 348.44 | AO7: =($AU$7-$AK$7)/10*(10-($AU$1-AO1))+$AK$7 -> 384.52 | AP7: =($AU$7-$AK$7)/10*(10-($AU$1-AP1))+$AK$7 -> 420.6 | AQ7: =($AU$7-$AK$7)/10*(10-($AU$1-AQ1))+$AK$7 -> 456.68 | AR7: =($AU$7-$AK$7)/10*(10-($AU$1-AR1))+$AK$7 -> 492.76 | AS7: =($AU$7-$AK$7)/10*(10-($AU$1-AS1))+$AK$7 -> 528.84 | AT7: =($AU$7-$AK$7)/10*(10-($AU$1-AT1))+$AK$7 -> 564.92 | AU7: 601 | AV7: =($BE$7-$AU$7)/10*(10-($BE$1-AV1))+$AU$7 -> 633.2 | AW7: =($BE$7-$AU$7)/10*(10-($BE$1-AW1))+$AU$7 -> 665.4 | AX7: =($BE$7-$AU$7)/10*(10-($BE$1-AX1))+$AU$7 -> 697.6 | AY7: =($BE$7-$AU$7)/10*(10-($BE$1-AY1))+$AU$7 -> 729.8 | AZ7: =($BE$7-$AU$7)/10*(10-($BE$1-AZ1))+$AU$7 -> 762 | BA7: =($BE$7-$AU$7)/10*(10-($BE$1-BA1))+$AU$7 -> 794.2 | BB7: =($BE$7-$AU$7)/10*(10-($BE$1-BB1))+$AU$7 -> 826.4 | BC7: =($BE$7-$AU$7)/10*(10-($BE$1-BC1))+$AU$7 -> 858.6 | BD7: =($BE$7-$AU$7)/10*(10-($BE$1-BD1))+$AU$7 -> 890.8 | BE7: 923 | BF7: =($BO$7-$BE$7)/10*(10-($BO$1-BF1))+$BE$7 -> 947.7 | BG7: =($BO$7-$BE$7)/10*(10-($BO$1-BG1))+$BE$7 -> 972.4 | BH7: =($BO$7-$BE$7)/10*(10-($BO$1-BH1))+$BE$7 -> 997.1 | BI7: =($BO$7-$BE$7)/10*(10-($BO$1-BI1))+$BE$7 -> 1021.8 | BJ7: =($BO$7-$BE$7)/10*(10-($BO$1-BJ1))+$BE$7 -> 1046.5 | BK7: =($BO$7-$BE$7)/10*(10-($BO$1-BK1))+$BE$7 -> 1071.2 | BL7: =($BO$7-$BE$7)/10*(10-($BO$1-BL1))+$BE$7 -> 1095.9 | BM7: =($BO$7-$BE$7)/10*(10-($BO$1-BM1))+$BE$7 -> 1120.6 | BN7: =($BO$7-$BE$7)/10*(10-($BO$1-BN1))+$BE$7 -> 1145.3 | BO7: 1170 | BP7: =($BY$7-$BO$7)/10*(10-($BY$1-BP1))+$BO$7 -> 1211 | BQ7: =($BY$7-$BO$7)/10*(10-($BY$1-BQ1))+$BO$7 -> 1252 | BR7: =($BY$7-$BO$7)/10*(10-($BY$1-BR1))+$BO$7 -> 1293 | BS7: =($BY$7-$BO$7)/10*(10-($BY$1-BS1))+$BO$7 -> 1334 | BT7: =($BY$7-$BO$7)/10*(10-($BY$1-BT1))+$BO$7 -> 1375 | BU7: =($BY$7-$BO$7)/10*(10-($BY$1-BU1))+$BO$7 -> 1416 | BV7: =($BY$7-$BO$7)/10*(10-($BY$1-BV1))+$BO$7 -> 1457 | BW7: =($BY$7-$BO$7)/10*(10-($BY$1-BW1))+$BO$7 -> 1498 | BX7: =($BY$7-$BO$7)/10*(10-($BY$1-BX1))+$BO$7 -> 1539 | BY7: 1580
AM8: 35900
AM9: 66896.355
AM10: 116571.43
A11: freight ratio | AM11: 599.3
A12: LDV | B12: 0.21888727
A13: HDV | B13: 0.78111273
C14: LDV | D14: =D4*$B$12 -> 76.676211 | E14: =E4*$B$12 -> 75.056445 | F14: =F4*$B$12 -> 416.54248 | G14: =G4*$B$12 -> 735.04535 | H14: =H4*$B$12 -> 750.34557 | I14: =I4*$B$12 -> 822.00707 | J14: =J4*$B$12 -> 890.98064 | K14: =K4*$B$12 -> 981.99397 | ... BY14: =BY4*$B$12 -> 21450.953
C15: HDV | D15: =D4*$B$13 -> 273.62379 | E15: =E4*$B$13 -> 267.84355 | F15: =F4*$B$13 -> 1486.4575 | G15: =G4*$B$13 -> 2623.0547 | H15: =H4*$B$13 -> 2677.6544 | I15: =I4*$B$13 -> 2933.3829 | J15: =J4*$B$13 -> 3179.5194 | K15: =K4*$B$13 -> 3504.306 | ... BY15: =BY4*$B$13 -> 76549.047
C16: air | D16: 0.97 | E16: 1.41 | F16: 4.15 | G16: 8.18 | H16: 10.1 | I16: 13.42 | J16: 16.61 | K16: 18.58 | L16: 22.3 | M16: 24.93 | N16: 29.1 | O16: 33.45 | P16: 42.34 | Q16: 50.27 | R16: 43.72 | S16: 51.55 | T16: 57.9 | U16: 71.8 | V16: 78.9 | W16: 94.27526 | X16: 116.38667 | Y16: 119.60227 | Z16: 126.2307 | AA16: 178.89816 | AB16: 173.91 | AC16: 163.88936 | AD16: 170.29181 | AE16: 187.77149 | AF16: 208.0683 | AG16: 222.44934 | AH16: 243.55229 | AI16: 262.49911 | AJ16: 263.2 | AK16: 240.2 | AL16: 276.28 | AM16: 312.36 | AN16: 348.44 | AO16: 384.52 | AP16: 420.6 | AQ16: 456.68 | AR16: 492.76 | AS16: 528.84 | AT16: 564.92 | AU16: 601 | AV16: 633.2 | AW16: 665.4 | AX16: 697.6 | AY16: 729.8 | AZ16: 762 | BA16: 794.2 | BB16: 826.4 | BC16: 858.6 | BD16: 890.8 | BE16: 923 | BF16: 947.7 | BG16: 972.4 | BH16: 997.1 | BI16: 1021.8 | BJ16: 1046.5 | BK16: 1071.2 | BL16: 1095.9 | BM16: 1120.6 | BN16: 1145.3 | BO16: 1170 | BP16: 1211 | BQ16: 1252 | BR16: 1293 | BS16: 1334 | BT16: 1375 | BU16: 1416 | BV16: 1457 | BW16: 1498 | BX16: 1539 | BY16: 1580
C17: rail | D17: 5345.19 | E17: 5717.5 | F17: 8125.66 | G17: 10622.38 | H17: 10972 | I17: 11575.55 | J17: 12090.9 | K17: 12632 | L17: 13049.48 | M17: 13106.2 | N17: 13269.9 | O17: 12560.1 | P17: 12910.3 | Q17: 13770.49 | R17: 14694.1 | S17: 15658.4 | T17: 17246.7 | U17: 19288.8 | V17: 20726 | W17: 21954.41 | X17: 23797 | Y17: 25106.282 | Z17: 25239.169 | AA17: 27644.133 | AB17: 29465.785 | AC17: 29187.086 | AD17: 29173.891 | AE17: 27530.19 | AF17: 23754.308 | AG17: 23792.262 | AH17: 26962.204 | AI17: 28820.986 | AJ17: 30181.95 | AK17: 30514.46 | AL17: 33223.014 | AM17: 35931.568 | AN17: 38640.122 | AO17: 41348.676 | AP17: 44057.23 | AQ17: 46765.784 | AR17: 49474.338 | AS17: 52182.892 | AT17: 54891.446 | AU17: 57600 | AV17: 60520 | AW17: 63440 | AX17: 66360 | AY17: 69280 | AZ17: 72200 | BA17: 75120 | BB17: 78040 | BC17: 80960 | BD17: 83880 | BE17: 86800 | BF17: 90020 | BG17: 93240 | BH17: 96460 | BI17: 99680 | BJ17: 102900 | BK17: 106120 | BL17: 109340 | BM17: 112560 | BN17: 115780 | BO17: 119000 | BP17: 121200 | BQ17: 123400 | BR17: 125600 | BS17: 127800 | BT17: 130000 | BU17: 132200 | BV17: 134400 | BW17: 136600 | BX17: 138800 | BY17: 141000
C18: ship | D18: 3801.8 | E18: 5076.5 | F18: 7729.3 | G18: 11591.9 | H18: 12955.4 | I18: 13256.2 | J18: 13860.8 | K18: 15686.6 | L18: 17552.2 | M18: 17862.5 | N18: 19235 | O18: 19405.8 | P18: 21262.8 | Q18: 23734.2 | R18: 25988.9 | S18: 27510.6 | T18: 28715.8 | U18: 41428.7 | V18: 49672.3 | W18: 55485.749 | X18: 64284.846 | Y18: 50262.704 | Z18: 57556.672 | AA18: 68427.526 | AB18: 75423.836 | AC18: 81707.579 | AD18: 79435.651 | AE18: 92774.556 | AF18: 91772.451 | AG18: 97338.802 | AH18: 98611.246 | AI18: 99052.815 | AJ18: 103963.04 | AK18: 105834.44 | AL18: 109051 | AM18: 112267.55 | AN18: 115484.11 | AO18: 118700.66 | AP18: 121917.22 | AQ18: 125133.78 | AR18: 128350.33 | AS18: 131566.89 | AT18: 134783.44 | AU18: 138000 | AV18: 140800 | AW18: 143600 | AX18: 146400 | AY18: 149200 | AZ18: 152000 | BA18: 154800 | BB18: 157600 | BC18: 160400 | BD18: 163200 | BE18: 166000 | BF18: 167800 | BG18: 169600 | BH18: 171400 | BI18: 173200 | BJ18: 175000 | BK18: 176800 | BL18: 178600 | BM18: 180400 | BN18: 182200 | BO18: 184000 | BP18: 185900 | BQ18: 187800 | BR18: 189700 | BS18: 191600 | BT18: 193500 | BU18: 195400 | BV18: 197300 | BW18: 199200 | BX18: 201100 | BY18: 203000
C20: relative to 2020
C21: LDV | D21: =D14/$AK$14 -> 0.0058216591 | E21: =E14/$AK$14 -> 0.005698678 | F21: =F14/$AK$14 -> 0.031626084 | G21: =G14/$AK$14 -> 0.055808489 | H21: =H14/$AK$14 -> 0.056970161 | I21: =I14/$AK$14 -> 0.062411078 | J21: =J14/$AK$14 -> 0.067647912 | K21: =K14/$AK$14 -> 0.07455812 | ... BY21: =BY14/$AK$14 -> 1.6286686
C22: HDV | D22: =D15/$AK$15 -> 0.0058216591 | E22: =E15/$AK$15 -> 0.005698678 | F22: =F15/$AK$15 -> 0.031626084 | G22: =G15/$AK$15 -> 0.055808489 | H22: =H15/$AK$15 -> 0.056970161 | I22: =I15/$AK$15 -> 0.062411078 | J22: =J15/$AK$15 -> 0.067647912 | K22: =K15/$AK$15 -> 0.07455812 | ... BY22: =BY15/$AK$15 -> 1.6286686
C23: air | D23: =D16/$AK$16 -> 0.0040383014 | E23: =E16/$AK$16 -> 0.0058701082 | F23: =F16/$AK$16 -> 0.017277269 | G23: =G16/$AK$16 -> 0.034054954 | H23: =H16/$AK$16 -> 0.042048293 | I23: =I16/$AK$16 -> 0.055870108 | J23: =J16/$AK$16 -> 0.069150708 | K23: =K16/$AK$16 -> 0.077352206 | ... BY23: =BY16/$AK$16 -> 6.5778518
C24: rail | D24: =D17/$AK$17 -> 0.17516908 | E24: =E17/$AK$17 -> 0.18737018 | F24: =F17/$AK$17 -> 0.26628883 | G24: =G17/$AK$17 -> 0.34810972 | H24: =H17/$AK$17 -> 0.35956723 | I24: =I17/$AK$17 -> 0.37934638 | J24: =J17/$AK$17 -> 0.3962351 | K24: =K17/$AK$17 -> 0.41396767 | ... BY24: =BY17/$AK$17 -> 4.6207601
C25: ship | D25: =D18/$AK$18 -> 0.035922144 | E25: =E18/$AK$18 -> 0.047966428 | F25: =F18/$AK$18 -> 0.073031992 | G25: =G18/$AK$18 -> 0.10952862 | H25: =H18/$AK$18 -> 0.12241195 | I25: =I18/$AK$18 -> 0.12525412 | J25: =J18/$AK$18 -> 0.13096682 | K25: =K18/$AK$18 -> 0.14821829 | ... BY25: =BY18/$AK$18 -> 1.9180902
