Workbook

Sheet About
A1: PPRiFUfERoIF Potential Perc Reduction in Fuel Use from Early Retirement of Inefficient Facilities
A2: PPRiFUfIIaIoE Potential Perc Reduction in Fuel Use from Improved Installation and Integration of Eqpt
A3: PPRiFUfICaWHR Potential Perc Reduction in Fuel Use from Increased Cogen and Waste Heat Recovery
A6: Source: | B6: Energy saving potential of key technologies in some key industries
B7: Ministry of Industry and Information Technology of the People's Republic of China 中华人民共和国工业和信息化部
B8: National Recommended Catalogue of Industrial Energy Conservation Technologies 2020 2021 2022
B9: 国家工业节能技术推荐目录 2020 2021 2022
B10: https://wap.miit.gov.cn/zwgk/zcwj/wjfb/gg/art/2020/art_e0190e6c3c404e54a7958e863d68d6a2.html
B11: 中华人民共和国工业和信息化部公告2021年 第30号
B12: 《国家工业和信息化领域节能技术装备推荐目录（2022年版）》（中华人民共和国工业和信息化部公告2022年第29号）
A14: Notes:

Sheet Sector & Policy Match
A1: 节能技术适用范围 | B1: EPS行业 | D1: 重点用能设备 | E1: 适用范围 | G1: 节能技术类型 | H1: EPS政策
A2: 煤炭开采 | B2: coal mining 05 | D2: 工业锅炉 | E2: 电力、热力生产 | G2: 流程工业节能 | H2: Early Facility Retirement
A3: 油气开采 | B3: oil and gas extraction 06 | D3: 工业锅炉 | E3: 石化 | G3: 重点用能设备及系统节能 | H3: Improvement in Eqpt Efficiency Standards
A4: 其他采矿 | B4: other mining and quarrying 07T08 | D4: 工业锅炉 | E4: 化工 | G4: 能源信息化 | H4: Installation and System Integration
A5: 食品 | B5: food beverage and tobacco 10T12 | D5: 工业锅炉 | E5: 钢铁 | G5: 可再生能源高效利用 | H5: Early Facility Retirement
A6: 造纸 | B6: pulp paper and printing 17T18 | D6: 工业锅炉 | E6: 纺织 | G6: 化石能源清洁高效利用 | H6: Early Facility Retirement
A7: 纺织 | B7: textiles apparel and leather 13T15 | D7: 工业锅炉 | E7: 造纸 | G7: 智慧能源管控系统 | H7: Installation and System Integration
A8: 建材 | B8: cement and other nonmetallic minerals 239 | D8: 工业锅炉 | E8: 食品 | G8: 余热余压利用 | H8: Cogeneration and Waste Heat Recovery
A9: 钢铁 | B9: iron and steel 241 | D9: 工业循环水 | E9: 石化
A10: 石化 | B10: refined petroleum and coke 19 | D10: 工业循环水 | E10: 化工
A11: 化工 | B11: chemicals 20 | D11: 工业循环水 | E11: 钢铁
A12: 有色金属 | B12: other metals 242 | D12: 工业循环水 | E12: 有色金属
A13: 汽车制造 | B13: road vehicles 29 | D13: 工业循环水 | E13: 造纸
A14: 非道路交通制造 | B14: nonroad vehicles 30 | D14: 工业循环水 | E14: 纺织
A15: 船舶 | B15: nonroad vehicles 30 | D15: 工业循环水 | E15: 食品
A16: 燃气生产和供应业 | B16: energy pipelines and gas processing 352T353 | D16: 微型燃气轮机 | E16: 非道路交通制造
A17: 废弃物处理 | B17: water and waste 36T39 | D17: 微型燃气轮机 | E17: 电力、热力生产
A18: 电气机械 | B18: appliances and electrical equipment 27 | D18: 压缩空气系统 | E18: 电力、热力生产
A19: 电子设备 | B19: computers and electronics 26 | D19: 压缩空气系统 | E19: 纺织
A20: 仪器仪表 | B20: computers and electronics 27 | D20: 压缩空气系统 | E20: 食品
... A42: 工业水泵 | B42: 工业水泵 | D42: 除尘器 | E42: 煤炭开采
D43: 除尘器 | E43: 钢铁
D44: 除尘器 | E44: 有色金属
D45: 除尘器 | E45: 石化
D46: 除尘器 | E46: 电力、热力生产
D47: 机械行业 | E47: 通用设备
D48: 机械行业 | E48: 专用设备
D49: 机械行业 | E49: 仪器仪表
D50: 机械行业 | E50: 电气机械
D51: 机械行业 | E51: 汽车制造
D52: 工业水泵 | E52: 农业
D53: 工业水泵 | E53: 煤炭开采
D54: 工业水泵 | E54: 油气开采
... D64: 冷却塔 | E64: 纺织

Sheet BIFUbC
A1: Unit:BTU | B1: 2019 | C1: 2020 | D1: 2021 | E1: 2022 | F1: 2023 | G1: 2024 | H1: 2025 | I1: 2026 | J1: 2027 | K1: 2028 | L1: 2029 | M1: 2030 | N1: 2031 | O1: 2032 | P1: 2033 | Q1: 2034 | R1: 2035 | S1: 2036 | T1: 2037 | U1: 2038 | V1: 2039 | W1: 2040 | X1: 2041 | Y1: 2042 | Z1: 2043 | AA1: 2044 | AB1: 2045 | AC1: 2046 | AD1: 2047 | AE1: 2048 | AF1: 2049 | AG1: 2050 | AH1: 2051 | AI1: 2052 | AJ1: 2053 | AK1: 2054 | AL1: 2055 | AM1: 2056 | AN1: 2057 | AO1: 2058 | AP1: 2059 | AQ1: 2060
A2: agriculture and forestry 01T03 | B2: 1.655906e+15 | C2: 1.6924155e+15 | D2: 1.7162917e+15 | E2: 1.7820674e+15 | F2: 1.8536406e+15 | G2: 1.9382306e+15 | H2: 1.9821736e+15 | I2: 2.1012194e+15 | J2: 2.1789379e+15 | K2: 2.2531839e+15 | L2: 2.3236409e+15 | M2: 2.4303007e+15 | N2: 2.4533637e+15 | O2: 2.5122844e+15 | P2: 2.5666519e+15 | Q2: 2.6163673e+15 | R2: 2.6450091e+15 | S2: 2.7100268e+15 | T2: 2.7542796e+15 | U2: 2.794164e+15 | V2: 2.8297462e+15 | W2: 2.8611266e+15 | X2: 2.8884375e+15 | Y2: 2.9118397e+15 | Z2: 2.93152e+15 | AA2: 2.9476874e+15 | AB2: 2.960571e+15 | AC2: 2.9704163e+15 | AD2: 2.9774824e+15 | AE2: 2.98204e+15 | AF2: 2.9843681e+15 | AG2: 2.984752e+15 | AH2: 2.9834816e+15 | AI2: 2.9808492e+15 | AJ2: 2.9771485e+15 | AK2: 2.9726727e+15 | AL2: 2.9677146e+15 | AM2: 2.9625649e+15 | AN2: 2.9575127e+15 | AO2: 2.9528452e+15 | AP2: 2.9488476e+15 | AQ2: 2.930992e+15
A3: coal mining 05 | B3: 1.8369744e+16 | C3: 1.8652997e+16 | D3: 1.972081e+16 | E3: 2.1787093e+16 | F3: 2.2326911e+16 | G3: 2.2866565e+16 | H3: 2.3406054e+16 | I3: 2.3785241e+16 | J3: 2.4164333e+16 | K3: 2.4543331e+16 | L3: 2.4922233e+16 | M3: 2.5301041e+16 | N3: 2.5441556e+16 | O3: 2.5582042e+16 | P3: 2.5722497e+16 | Q3: 2.5862921e+16 | R3: 2.6003316e+16 | S3: 2.5764061e+16 | T3: 2.552482e+16 | U3: 2.5285591e+16 | V3: 2.5046376e+16 | W3: 2.4807173e+16 | X3: 2.4424868e+16 | Y3: 2.4042584e+16 | Z3: 2.366032e+16 | AA3: 2.3278077e+16 | AB3: 2.2895854e+16 | AC3: 2.2513652e+16 | AD3: 2.2131471e+16 | AE3: 2.1749309e+16 | AF3: 2.1367169e+16 | AG3: 2.0985048e+16 | AH3: 2.0507565e+16 | AI3: 2.0030107e+16 | AJ3: 1.9552674e+16 | AK3: 1.9075267e+16 | AL3: 1.8597886e+16 | AM3: 1.8215902e+16 | AN3: 1.7833938e+16 | AO3: 1.7451994e+16 | AP3: 1.7070071e+16 | AQ3: 1.6685927e+16
A4: oil and gas extraction 06 | B4: 7.8256971e+14 | C4: 750491822304952 | D4: 8.0636336e+14 | E4: 8.5190779e+14 | F4: 8.8632176e+14 | G4: 9.2046276e+14 | H4: 954330785705933 | I4: 974883364760133 | J4: 9.9529503e+14 | K4: 1.0155658e+15 | L4: 1.0356956e+15 | M4: 1.0556845e+15 | N4: 1.0679759e+15 | O4: 1.080189e+15 | P4: 1.0923236e+15 | Q4: 1.1043798e+15 | R4: 1.1163577e+15 | S4: 1.1304785e+15 | T4: 1.1445795e+15 | U4: 1.1586606e+15 | V4: 1.1727219e+15 | W4: 1.1867634e+15 | X4: 1.1933691e+15 | Y4: 1.199965e+15 | Z4: 1.2065509e+15 | AA4: 1.2131269e+15 | AB4: 1.2196931e+15 | AC4: 1.2262493e+15 | AD4: 1.2327956e+15 | AE4: 1.239332e+15 | AF4: 1.2458586e+15 | AG4: 1.2523752e+15 | AH4: 1.2588782e+15 | AI4: 1.2653713e+15 | AJ4: 1.2718545e+15 | AK4: 1.2783278e+15 | AL4: 1.2847913e+15 | AM4: 1.2839188e+15 | AN4: 1.2830463e+15 | AO4: 1.2821738e+15 | AP4: 1.2813013e+15 | AQ4: 1.2760884e+15
A5: other mining and quarrying 07T08 | B5: 6.2163651e+14 | C5: 5.8850085e+14 | D5: 6.0783312e+14 | E5: 5.9387496e+14 | F5: 6.3116541e+14 | G5: 668168755362959 | H5: 7.0488501e+14 | I5: 7.2159434e+14 | J5: 7.3819039e+14 | K5: 754673152020337 | L5: 7.7104263e+14 | M5: 7.8729883e+14 | N5: 788168393148035 | O5: 7.8902275e+14 | P5: 7.898619e+14 | Q5: 790685848526573 | R5: 7.9149459e+14 | S5: 784834776363428 | T5: 7.7818315e+14 | U5: 7.715397e+14 | V5: 7.6490443e+14 | W5: 758277341413722 | X5: 7.4475235e+14 | Y5: 7.3124479e+14 | Z5: 7.1775466e+14 | AA5: 7.0428195e+14 | AB5: 6.9082667e+14 | AC5: 6.7587817e+14 | AD5: 6.6094913e+14 | AE5: 6.4603955e+14 | AF5: 6.3114942e+14 | AG5: 616278748657400 | AH5: 6.0192326e+14 | AI5: 5.8758656e+14 | AJ5: 5.7326865e+14 | AK5: 5.5896953e+14 | AL5: 544689196215482 | AM5: 5.3112616e+14 | AN5: 5.1758096e+14 | AO5: 504053612404257 | AP5: 490544104087213 | AQ5: 4.7543531e+14
A6: food beverage and tobacco 10T12 | B6: 1.5180729e+15 | C6: 1.4307956e+15 | D6: 1.6044239e+15 | E6: 1.6596026e+15 | F6: 1.6690306e+15 | G6: 1.7055387e+15 | H6: 1.7565846e+15 | I6: 1.8120331e+15 | J6: 1.8672012e+15 | K6: 1.920698e+15 | L6: 1.9710355e+15 | M6: 2.0166424e+15 | N6: 2.0572096e+15 | O6: 2.0916164e+15 | P6: 2.1200943e+15 | Q6: 2.1429592e+15 | R6: 2.1605991e+15 | S6: 2.1801026e+15 | T6: 2.1951838e+15 | U6: 2.2060851e+15 | V6: 2.2130781e+15 | W6: 2.2164575e+15 | X6: 2.2165357e+15 | Y6: 2.2136377e+15 | Z6: 2.2080968e+15 | AA6: 2.2002498e+15 | AB6: 2.1904341e+15 | AC6: 2.1789843e+15 | AD6: 2.16623e+15 | AE6: 2.1524939e+15 | AF6: 2.13809e+15 | AG6: 2.1233236e+15 | AH6: 2.1084904e+15 | AI6: 2.0938767e+15 | AJ6: 2.07976e+15 | AK6: 2.0664101e+15 | AL6: 2.0540903e+15 | AM6: 2.0430591e+15 | AN6: 2.0335722e+15 | AO6: 2.0258851e+15 | AP6: 2.0202558e+15 | AQ6: 2.0066635e+15
A7: textiles apparel and leather 13T15 | B7: 1.3736513e+15 | C7: 1.3057732e+15 | D7: 1.3861366e+15 | E7: 1.3660934e+15 | F7: 1.3648645e+15 | G7: 1.372278e+15 | H7: 1.3843385e+15 | I7: 1.3983918e+15 | J7: 1.4112535e+15 | K7: 1.4210714e+15 | L7: 1.4259625e+15 | M7: 1.4240627e+15 | N7: 1.4149074e+15 | O7: 1.3991216e+15 | P7: 1.3786718e+15 | Q7: 1.3554795e+15 | R7: 1.3313721e+15 | S7: 1.3118367e+15 | T7: 1.2929964e+15 | U7: 1.274856e+15 | V7: 1.2574211e+15 | W7: 1.240698e+15 | X7: 1.2246929e+15 | Y7: 1.2094121e+15 | Z7: 1.1948613e+15 | AA7: 1.181046e+15 | AB7: 1.167971e+15 | AC7: 1.1556404e+15 | AD7: 1.1440581e+15 | AE7: 1.1332272e+15 | AF7: 1.1231508e+15 | AG7: 1.1138314e+15 | AH7: 1.1052718e+15 | AI7: 1.0974749e+15 | AJ7: 1.0904437e+15 | AK7: 1.084182e+15 | AL7: 1.0786943e+15 | AM7: 1.0739863e+15 | AN7: 1.0700647e+15 | AO7: 1.0669379e+15 | AP7: 1.0646163e+15 | AQ7: 1.0576604e+15
A8: wood products 16 | B8: 2.0367106e+14 | C8: 1.9657993e+14 | D8: 2.2577758e+14 | E8: 2.233889e+14 | F8: 223357561759607 | G8: 2.2512184e+14 | H8: 2.2811488e+14 | I8: 2.3198699e+14 | J8: 2.3624467e+14 | K8: 2.4058818e+14 | L8: 2.4469549e+14 | M8: 2.4822333e+14 | N8: 2.510047e+14 | O8: 2.5288923e+14 | P8: 2.5392472e+14 | Q8: 2.5416905e+14 | R8: 2.5368821e+14 | S8: 2.5333019e+14 | T8: 252374417087754 | U8: 2.5087855e+14 | V8: 2.4890275e+14 | W8: 2.4650852e+14 | X8: 2.4375772e+14 | Y8: 2.4071166e+14 | Z8: 2.3743039e+14 | AA8: 2.3397208e+14 | AB8: 2.3039255e+14 | AC8: 2.2674494e+14 | AD8: 2.230795e+14 | AE8: 2.194435e+14 | AF8: 2.1588123e+14 | AG8: 2.1243412e+14 | AH8: 2.0914091e+14 | AI8: 2.0603792e+14 | AJ8: 203159381158532 | AK8: 2.0053781e+14 | AL8: 1.9820445e+14 | AM8: 1.961898e+14 | AN8: 1.9452411e+14 | AO8: 1.9323801e+14 | AP8: 1.9236315e+14 | AQ8: 1.9095224e+14
A9: pulp paper and printing 17T18 | B9: 8.7152832e+14 | C9: 8.6381753e+14 | D9: 9.3874521e+14 | E9: 9.4106334e+14 | F9: 980459031956785 | G9: 1.0224505e+15 | H9: 1.0657057e+15 | I9: 1.0899398e+15 | J9: 1.114059e+15 | K9: 1.1378806e+15 | L9: 1.1612032e+15 | M9: 1.1838098e+15 | N9: 1.1958097e+15 | O9: 1.2069821e+15 | P9: 1.2173579e+15 | Q9: 1.226978e+15 | R9: 1.2358919e+15 | S9: 1.2418023e+15 | T9: 1.2471577e+15 | U9: 1.2519911e+15 | V9: 1.2563388e+15 | W9: 1.2602401e+15 | X9: 1.2534564e+15 | Y9: 1.2463317e+15 | Z9: 1.23891e+15 | AA9: 1.2312359e+15 | AB9: 1.2233538e+15 | AC9: 1.2081473e+15 | AD9: 1.1928343e+15 | AE9: 1.1774567e+15 | AF9: 1.1620554e+15 | AG9: 1.1466697e+15 | AH9: 1.1303201e+15 | AI9: 1.114063e+15 | AJ9: 1.0979337e+15 | AK9: 1.0819665e+15 | AL9: 1.0661945e+15 | AM9: 1.0486251e+15 | AN9: 1.0313194e+15 | AO9: 1.0143091e+15 | AP9: 9.9762613e+14 | AQ9: 9.762722e+14
A10: refined petroleum and coke 19 | B10: 5.4451105e+16 | C10: 5.7028297e+16 | D10: 5.6146066e+16 | E10: 5.7219149e+16 | F10: 6.1736943e+16 | G10: 6.6252212e+16 | H10: 7.0764956e+16 | I10: 7.2321007e+16 | J10: 7.3876341e+16 | K10: 7.5430958e+16 | L10: 7.6984857e+16 | M10: 7.853804e+16 | N10: 7.8634915e+16 | O10: 7.8731746e+16 | P10: 7.8828533e+16 | Q10: 7.8925277e+16 | R10: 7.9021977e+16 | S10: 7.8121424e+16 | T10: 7.7220961e+16 | U10: 7.6320586e+16 | V10: 7.5420299e+16 | W10: 7.4520101e+16 | X10: 7.2835608e+16 | Y10: 7.1151281e+16 | Z10: 6.946712e+16 | AA10: 6.7783125e+16 | AB10: 6.6099296e+16 | AC10: 6.4415633e+16 | AD10: 6.2732136e+16 | AE10: 6.1048805e+16 | AF10: 5.936564e+16 | AG10: 5.7682641e+16 | AH10: 5.6223802e+16 | AI10: 5.4765108e+16 | AJ10: 5.3306557e+16 | AK10: 5.184815e+16 | AL10: 5.0389887e+16 | AM10: 4.8858647e+16 | AN10: 4.7327558e+16 | AO10: 4.579662e+16 | AP10: 4.4265834e+16 | AQ10: 4.2724637e+16
A11: chemicals 20 | B11: 1.1779139e+16 | C11: 1.264658e+16 | D11: 1.3477958e+16 | E11: 1.3349479e+16 | F11: 1.4511807e+16 | G11: 1.5684376e+16 | H11: 1.6857832e+16 | I11: 1.7446566e+16 | J11: 1.8028063e+16 | K11: 1.8602326e+16 | L11: 1.9169588e+16 | M11: 1.9730275e+16 | N11: 2.0041807e+16 | O11: 2.0349213e+16 | P11: 2.0653157e+16 | Q11: 2.095434e+16 | R11: 2.1253486e+16 | S11: 2.1418802e+16 | T11: 2.158382e+16 | U11: 2.1748542e+16 | V11: 2.1912973e+16 | W11: 2.2077112e+16 | X11: 2.2145565e+16 | Y11: 2.2213824e+16 | Z11: 2.228189e+16 | AA11: 2.2349768e+16 | AB11: 2.2417459e+16 | AC11: 2.2403116e+16 | AD11: 2.2388662e+16 | AE11: 2.2374098e+16 | AF11: 2.2359429e+16 | AG11: 2.2344658e+16 | AH11: 2.2255778e+16 | AI11: 2.2166875e+16 | AJ11: 2.2077952e+16 | AK11: 2.1989011e+16 | AL11: 2.1900056e+16 | AM11: 2.1797483e+16 | AN11: 2.1694913e+16 | AO11: 2.159235e+16 | AP11: 2.1489797e+16 | AQ11: 2.1328549e+16
A12: rubber and plastic products 22 | B12: 643092814091311 | C12: 6.5703908e+14 | D12: 7.2356702e+14 | E12: 7.1816755e+14 | F12: 724929837871160 | G12: 7.4655005e+14 | H12: 7.7404742e+14 | I12: 7.9975081e+14 | J12: 8.2105133e+14 | K12: 8.376089e+14 | L12: 8.4916967e+14 | M12: 8.5557235e+14 | N12: 8.5735008e+14 | O12: 8.5494658e+14 | P12: 8.4945554e+14 | Q12: 8.4198582e+14 | R12: 8.3362919e+14 | S12: 8.2782356e+14 | T12: 8.2216539e+14 | U12: 8.1666008e+14 | V12: 8.1131288e+14 | W12: 8.0612894e+14 | X12: 801113298265240 | Y12: 7.9627089e+14 | Z12: 791606563949065 | AA12: 7.8712513e+14 | AB12: 7.8283132e+14 | AC12: 7.7872985e+14 | AD12: 774825403460177 | AE12: 7.7112265e+14 | AF12: 767626294255642 | AG12: 7.6434104e+14 | AH12: 7.6127165e+14 | AI12: 7.5842294e+14 | AJ12: 7.5579981e+14 | AK12: 753407243963022 | AL12: 751250356574488 | AM12: 7.4933438e+14 | AN12: 7.4766472e+14 | AO12: 7.4624692e+14 | AP12: 7.4508676e+14 | AQ12: 7.4037677e+14
... A26: construction 41T43 | B26: 1.8245932e+15 | C26: 1.8704611e+15 | D26: 1.9741323e+15 | E26: 2.0050223e+15 | F26: 2.1045757e+15 | G26: 2.2086612e+15 | H26: 2.296367e+15 | I26: 2.4121826e+15 | J26: 2.5107779e+15 | K26: 2.6064955e+15 | L26: 2.698962e+15 | M26: 2.8035052e+15 | N26: 2.8734074e+15 | O26: 2.9548759e+15 | P26: 3.0320398e+15 | Q26: 3.1047364e+15 | R26: 3.1662915e+15 | S26: 3.2401809e+15 | T26: 3.3029812e+15 | U26: 3.3612466e+15 | V26: 3.4150153e+15 | W26: 3.4643636e+15 | X26: 3.5094043e+15 | Y26: 3.5502833e+15 | Z26: 3.5871774e+15 | AA26: 3.6202911e+15 | AB26: 3.649854e+15 | AC26: 3.6761177e+15 | AD26: 3.6993531e+15 | AE26: 3.7198482e+15 | AF26: 3.7379048e+15 | AG26: 3.753837e+15 | AH26: 3.7679689e+15 | AI26: 3.7806326e+15 | AJ26: 3.7921673e+15 | AK26: 3.8029175e+15 | AL26: 3.8132324e+15 | AM26: 3.8234654e+15 | AN26: 3.8339737e+15 | AO26: 3.8451186e+15 | AP26: 3.8572657e+15 | AQ26: 3.8633281e+15
A27: 电力、热力生产 | B27: 2.2694301e+15

Sheet 工业节能技术装备推荐目录
A1: 发布时间 | B1: 技术名称 | C1: 适用范围 | D1: EPS行业 | E1: 技术类型 | F1: EPS政策 | G1: 目前 推广比例 | H1: 推广 起始年 | I1: 推广 结束年 | J1: 推广期 实现比例 | K1: 推广期的节能能力 (万tce/a) | L1: 100%推广的节能能力 (万tce/a) | M1: 推广100% 实现的年份
A2: 2020 | B2: 外循环生料立磨技术 | C2: 建材 | D2: =IFERROR(VLOOKUP(C2,'Sector & Policy Match'!$A$1:$B$42,2,0),"") -> cement and other nonmetallic minerals 239 | E2: 流程工业节能 | F2: =VLOOKUP(E2,'Sector & Policy Match'!$G$1:$H$8,2,0) -> Early Facility Retirement | G2: <5% | H2: 2021 | I2: 2025 | J2: 0.1 | K2: 9.65 | L2: =(1-IF(G2="<5%",0,G2))/(J2-IF(G2="<5%",0,G2))*K2 -> 96.5 | M2: 2060
A3: 2020 | B3: 钢渣/矿渣辊压机终粉磨系统 | C3: 建材 | D3: =IFERROR(VLOOKUP(C3,'Sector & Policy Match'!$A$1:$B$42,2,0),"") -> cement and other nonmetallic minerals 239 | E3: 流程工业节能 | F3: =VLOOKUP(E3,'Sector & Policy Match'!$G$1:$H$8,2,0) -> Early Facility Retirement | G3: <5% | H3: 2021 | I3: 2025 | J3: 0.2 | K3: 8.72 | L3: =(1-IF(G3="<5%",0,G3))/(J3-IF(G3="<5%",0,G3))*K3 -> 43.6 | M3: 2060
A4: 2020 | B4: 陶瓷原料连续制浆系统 | C4: 建材 | D4: =IFERROR(VLOOKUP(C4,'Sector & Policy Match'!$A$1:$B$42,2,0),"") -> cement and other nonmetallic minerals 239 | E4: 流程工业节能 | F4: =VLOOKUP(E4,'Sector & Policy Match'!$G$1:$H$8,2,0) -> Early Facility Retirement | G4: <5% | H4: 2021 | I4: 2025 | J4: 0.1 | K4: 92.1 | L4: =(1-IF(G4="<5%",0,G4))/(J4-IF(G4="<5%",0,G4))*K4 -> 921 | M4: 2060
A5: 2020 | B5: 带中段辊破的列进式冷却机 | C5: 建材 | D5: =IFERROR(VLOOKUP(C5,'Sector & Policy Match'!$A$1:$B$42,2,0),"") -> cement and other nonmetallic minerals 239 | E5: 流程工业节能 | F5: =VLOOKUP(E5,'Sector & Policy Match'!$G$1:$H$8,2,0) -> Early Facility Retirement | G5: <5% | H5: 2021 | I5: 2025 | J5: 0.1 | K5: 26.6 | L5: =(1-IF(G5="<5%",0,G5))/(J5-IF(G5="<5%",0,G5))*K5 -> 266 | M5: 2060
A6: 2020 | B6: 卧式玻璃直线四边砂轮式磨边技术 | C6: 建材 | D6: =IFERROR(VLOOKUP(C6,'Sector & Policy Match'!$A$1:$B$42,2,0),"") -> cement and other nonmetallic minerals 239 | E6: 流程工业节能 | F6: =VLOOKUP(E6,'Sector & Policy Match'!$G$1:$H$8,2,0) -> Early Facility Retirement | G6: <5% | H6: 2021 | I6: 2025 | J6: 0.1 | K6: 3.5 | L6: =(1-IF(G6="<5%",0,G6))/(J6-IF(G6="<5%",0,G6))*K6 -> 35 | M6: 2060
A7: 2020 | B7: 宽粒级磁铁矿湿式弱磁预选分级磨矿技术 | C7: 钢铁 | D7: =IFERROR(VLOOKUP(C7,'Sector & Policy Match'!$A$1:$B$42,2,0),"") -> iron and steel 241 | E7: 流程工业节能 | F7: =VLOOKUP(E7,'Sector & Policy Match'!$G$1:$H$8,2,0) -> Early Facility Retirement | G7: <5% | H7: 2021 | I7: 2025 | J7: 0.15 | K7: 18 | L7: =(1-IF(G7="<5%",0,G7))/(J7-IF(G7="<5%",0,G7))*K7 -> 120 | M7: 2060
A8: 2020 | B8: 新型水泥熟料冷却技术及装备 | C8: 建材 | D8: =IFERROR(VLOOKUP(C8,'Sector & Policy Match'!$A$1:$B$42,2,0),"") -> cement and other nonmetallic minerals 239 | E8: 流程工业节能 | F8: =VLOOKUP(E8,'Sector & Policy Match'!$G$1:$H$8,2,0) -> Early Facility Retirement | G8: 0.05 | H8: 2021 | I8: 2025 | J8: 0.5 | K8: 120 | L8: =(1-IF(G8="<5%",0,G8))/(J8-IF(G8="<5%",0,G8))*K8 -> 253.33333 | M8: 2060
A9: 2020 | B9: 高能效长寿化双膛立式石灰窑装备及控制技术 | C9: 钢铁 | D9: =IFERROR(VLOOKUP(C9,'Sector & Policy Match'!$A$1:$B$42,2,0),"") -> iron and steel 241 | E9: 流程工业节能 | F9: =VLOOKUP(E9,'Sector & Policy Match'!$G$1:$H$8,2,0) -> Early Facility Retirement | G9: 0.05 | H9: 2021 | I9: 2025 | J9: 0.35 | K9: 178 | L9: =(1-IF(G9="<5%",0,G9))/(J9-IF(G9="<5%",0,G9))*K9 -> 563.66667 | M9: 2060
A10: 2020 | B10: 机械磨损陶瓷合金自动修复技术 | D10: =IFERROR(VLOOKUP(C10,'Sector & Policy Match'!$A$1:$B$42,2,0),"") | E10: 流程工业节能 | F10: =VLOOKUP(E10,'Sector & Policy Match'!$G$1:$H$8,2,0) -> Early Facility Retirement | G10: 0.05 | H10: 2021 | I10: 2025 | J10: 0.15 | K10: 95 | L10: =(1-IF(G10="<5%",0,G10))/(J10-IF(G10="<5%",0,G10))*K10 -> 902.5 | M10: 2060
A11: 2020 | B11: 焦炉加热优化控制及管理技术 | C11: 钢铁 | D11: =IFERROR(VLOOKUP(C11,'Sector & Policy Match'!$A$1:$B$42,2,0),"") -> iron and steel 241 | E11: 流程工业节能 | F11: =VLOOKUP(E11,'Sector & Policy Match'!$G$1:$H$8,2,0) -> Early Facility Retirement | G11: 0.05 | H11: 2021 | I11: 2025 | J11: 0.2 | K11: 21 | L11: =(1-IF(G11="<5%",0,G11))/(J11-IF(G11="<5%",0,G11))*K11 -> 133 | M11: 2060
A12: 2020 | B12: 升膜多效蒸发技术 | C12: 化工 | D12: =IFERROR(VLOOKUP(C12,'Sector & Policy Match'!$A$1:$B$42,2,0),"") -> chemicals 20 | E12: 流程工业节能 | F12: =VLOOKUP(E12,'Sector & Policy Match'!$G$1:$H$8,2,0) -> Early Facility Retirement | G12: 0.05 | H12: 2021 | I12: 2025 | J12: 0.15 | K12: 13 | L12: =(1-IF(G12="<5%",0,G12))/(J12-IF(G12="<5%",0,G12))*K12 -> 123.5 | M12: 2060
A13: 2020 | B13: 利用高热值危险废弃物替代水泥窑燃料综合技术 | C13: 建材 | D13: =IFERROR(VLOOKUP(C13,'Sector & Policy Match'!$A$1:$B$42,2,0),"") -> cement and other nonmetallic minerals 239 | E13: 流程工业节能 | F13: =VLOOKUP(E13,'Sector & Policy Match'!$G$1:$H$8,2,0) -> Early Facility Retirement | G13: 0.1 | H13: 2021 | I13: 2025 | J13: 0.3 | K13: 15 | L13: =(1-IF(G13="<5%",0,G13))/(J13-IF(G13="<5%",0,G13))*K13 -> 67.5 | M13: 2060
A14: 2020 | B14: 钢渣立磨终粉磨技术 | C14: 建材\钢铁 | D14: =IFERROR(VLOOKUP(C14,'Sector & Policy Match'!$A$1:$B$42,2,0),"") | E14: 流程工业节能 | F14: =VLOOKUP(E14,'Sector & Policy Match'!$G$1:$H$8,2,0) -> Early Facility Retirement | G14: 0.1 | H14: 2021 | I14: 2025 | J14: 0.3 | K14: 8.9 | L14: =(1-IF(G14="<5%",0,G14))/(J14-IF(G14="<5%",0,G14))*K14 -> 40.05 | M14: 2060
A15: 2020 | B15: 钢渣立磨终粉磨技术 | C15: 建材 | D15: =IFERROR(VLOOKUP(C15,'Sector & Policy Match'!$A$1:$B$42,2,0),"") -> cement and other nonmetallic minerals 239 | E15: 流程工业节能 | F15: =VLOOKUP(E15,'Sector & Policy Match'!$G$1:$H$8,2,0) -> Early Facility Retirement | G15: 0.1 | H15: 2021 | I15: 2025 | J15: 0.3 | K15: =BIFUbC!B14/(BIFUbC!B14+BIFUbC!B15)*K14 -> 2.3363802 | L15: =(1-IF(G15="<5%",0,G15))/(J15-IF(G15="<5%",0,G15))*K15 -> 10.513711 | M15: 2060
A16: 2020 | B16: 钢渣立磨终粉磨技术 | C16: 钢铁 | D16: =IFERROR(VLOOKUP(C16,'Sector & Policy Match'!$A$1:$B$42,2,0),"") -> iron and steel 241 | E16: 流程工业节能 | F16: =VLOOKUP(E16,'Sector & Policy Match'!$G$1:$H$8,2,0) -> Early Facility Retirement | G16: 0.1 | H16: 2021 | I16: 2025 | J16: 0.3 | K16: =BIFUbC!B15/(BIFUbC!B14+BIFUbC!B15)*K14 -> 6.5636198 | L16: =(1-IF(G16="<5%",0,G16))/(J16-IF(G16="<5%",0,G16))*K16 -> 29.536289 | M16: 2060
A17: 2020 | B17: 炉窑烟气节能降耗一体化技术 | C17: 工业锅炉 | D17: =IFERROR(VLOOKUP(C17,'Sector & Policy Match'!$A$1:$B$42,2,0),"") -> 工业锅炉 | E17: 流程工业节能 | F17: =VLOOKUP(E17,'Sector & Policy Match'!$G$1:$H$8,2,0) -> Early Facility Retirement | G17: 0.15 | H17: 2021 | I17: 2025 | J17: 0.35 | K17: 36 | L17: =(1-IF(G17="<5%",0,G17))/(J17-IF(G17="<5%",0,G17))*K17 -> 153 | M17: 2060
A18: 2020 | B18: 低导热多层复合莫来石砖 | C18: 建材 | D18: =IFERROR(VLOOKUP(C18,'Sector & Policy Match'!$A$1:$B$42,2,0),"") -> cement and other nonmetallic minerals 239 | E18: 流程工业节能 | F18: =VLOOKUP(E18,'Sector & Policy Match'!$G$1:$H$8,2,0) -> Early Facility Retirement | G18: 0.2 | H18: 2021 | I18: 2025 | J18: 0.4 | K18: 68.3 | L18: =(1-IF(G18="<5%",0,G18))/(J18-IF(G18="<5%",0,G18))*K18 -> 273.2 | M18: 2060
A19: 2020 | B19: 大型清洁高效水煤浆气化技术 | C19: 化工 | D19: =IFERROR(VLOOKUP(C19,'Sector & Policy Match'!$A$1:$B$42,2,0),"") -> chemicals 20 | E19: 流程工业节能 | F19: =VLOOKUP(E19,'Sector & Policy Match'!$G$1:$H$8,2,0) -> Early Facility Retirement | G19: 0.2 | H19: 2021 | I19: 2025 | J19: 0.4 | K19: 36 | L19: =(1-IF(G19="<5%",0,G19))/(J19-IF(G19="<5%",0,G19))*K19 -> 144 | M19: 2060
A20: 2020 | B20: 铜冶炼领域汽电双驱同轴压缩机组(MCRT)技术 | C20: 有色金属 | D20: =IFERROR(VLOOKUP(C20,'Sector & Policy Match'!$A$1:$B$42,2,0),"") -> other metals 242 | E20: 流程工业节能 | F20: =VLOOKUP(E20,'Sector & Policy Match'!$G$1:$H$8,2,0) -> Early Facility Retirement | G20: 0.2 | H20: 2021 | I20: 2025 | J20: 0.4 | K20: 10 | L20: =(1-IF(G20="<5%",0,G20))/(J20-IF(G20="<5%",0,G20))*K20 -> 40 | M20: 2060
A21: 2020 | B21: 汽轮驱动高炉鼓风机与电动/发电机同轴机组技术 | C21: 钢铁 | D21: =IFERROR(VLOOKUP(C21,'Sector & Policy Match'!$A$1:$B$42,2,0),"") -> iron and steel 241 | E21: 流程工业节能 | F21: =VLOOKUP(E21,'Sector & Policy Match'!$G$1:$H$8,2,0) -> Early Facility Retirement | G21: 0.4 | H21: 2021 | I21: 2025 | J21: 0.6 | K21: 40 | L21: =(1-IF(G21="<5%",0,G21))/(J21-IF(G21="<5%",0,G21))*K21 -> 120 | M21: 2060
A22: 2020 | B22: 锅炉烟气深度冷却技术 | C22: 工业锅炉 | D22: =IFERROR(VLOOKUP(C22,'Sector & Policy Match'!$A$1:$B$42,2,0),"") -> 工业锅炉 | E22: 余热余压利用 | F22: =VLOOKUP(E22,'Sector & Policy Match'!$G$1:$H$8,2,0) -> Cogeneration and Waste Heat Recovery | G22: <5% | H22: 2021 | I22: 2025 | J22: 0.1 | K22: 66 | L22: =(1-IF(G22="<5%",0,G22))/(J22-IF(G22="<5%",0,G22))*K22 -> 660 | M22: 2060
A23: 2020 | B23: 工业循环水余压能量闭环回收利用技术 | C23: 工业循环水 | D23: =IFERROR(VLOOKUP(C23,'Sector & Policy Match'!$A$1:$B$42,2,0),"") -> 工业循环水 | E23: 余热余压利用 | F23: =VLOOKUP(E23,'Sector & Policy Match'!$G$1:$H$8,2,0) -> Cogeneration and Waste Heat Recovery | G23: <5% | H23: 2021 | I23: 2025 | J23: 0.15 | K23: 38 | L23: =(1-IF(G23="<5%",0,G23))/(J23-IF(G23="<5%",0,G23))*K23 -> 253.33333 | M23: 2060
A24: 2020 | B24: 微型燃气轮机能源梯级利用节能技术 | C24: 微型燃气轮机 | D24: =IFERROR(VLOOKUP(C24,'Sector & Policy Match'!$A$1:$B$42,2,0),"") -> 微型燃气轮机 | E24: 余热余压利用 | F24: =VLOOKUP(E24,'Sector & Policy Match'!$G$1:$H$8,2,0) -> Cogeneration and Waste Heat Recovery | G24: <5% | H24: 2021 | I24: 2025 | J24: 0.15 | K24: 36 | L24: =(1-IF(G24="<5%",0,G24))/(J24-IF(G24="<5%",0,G24))*K24 -> 240 | M24: 2060
A25: 2020 | B25: 工业燃煤机组烟气低品位余热回收利用技术 | C25: 电力、热力生产 | D25: =IFERROR(VLOOKUP(C25,'Sector & Policy Match'!$A$1:$B$42,2,0),"") -> 电力、热力生产 | E25: 余热余压利用 | F25: =VLOOKUP(E25,'Sector & Policy Match'!$G$1:$H$8,2,0) -> Cogeneration and Waste Heat Recovery | G25: <5% | H25: 2021 | I25: 2025 | J25: 0.1 | K25: 100 | L25: =(1-IF(G25="<5%",0,G25))/(J25-IF(G25="<5%",0,G25))*K25 -> 1000 | M25: 2060
A26: 2020 | B26: 电厂用低压驱动热泵技术 | C26: 电力、热力生产 | D26: =IFERROR(VLOOKUP(C26,'Sector & Policy Match'!$A$1:$B$42,2,0),"") -> 电力、热力生产 | E26: 余热余压利用 | F26: =VLOOKUP(E26,'Sector & Policy Match'!$G$1:$H$8,2,0) -> Cogeneration and Waste Heat Recovery | G26: 0.1 | H26: 2021 | I26: 2025 | J26: 0.3 | K26: 58 | L26: =(1-IF(G26="<5%",0,G26))/(J26-IF(G26="<5%",0,G26))*K26 -> 261 | M26: 2060
A27: 2020 | B27: 旋转电磁制热技术 | C27: 电力、热力生产 | D27: =IFERROR(VLOOKUP(C27,'Sector & Policy Match'!$A$1:$B$42,2,0),"") -> 电力、热力生产 | E27: 重点用能设备及系统节能 | F27: =VLOOKUP(E27,'Sector & Policy Match'!$G$1:$H$8,2,0) -> Improvement in Eqpt Efficiency Standards | G27: <5% | H27: 2021 | I27: 2025 | J27: 0.1 | K27: 9.5 | L27: =(1-IF(G27="<5%",0,G27))/(J27-IF(G27="<5%",0,G27))*K27 -> 95 | M27: 2060
A28: 2020 | B28: 多模式节能型低露点干燥技术 | C28: 压缩空气系统 | D28: =IFERROR(VLOOKUP(C28,'Sector & Policy Match'!$A$1:$B$42,2,0),"") -> 压缩空气系统 | E28: 重点用能设备及系统节能 | F28: =VLOOKUP(E28,'Sector & Policy Match'!$G$1:$H$8,2,0) -> Improvement in Eqpt Efficiency Standards | G28: <5% | H28: 2021 | I28: 2025 | J28: 0.2 | K28: 6.6 | L28: =(1-IF(G28="<5%",0,G28))/(J28-IF(G28="<5%",0,G28))*K28 -> 33 | M28: 2060
A29: 2020 | B29: 异步电机永磁化改造技术 | C29: 电动机系统 | D29: =IFERROR(VLOOKUP(C29,'Sector & Policy Match'!$A$1:$B$42,2,0),"") -> 电动机系统 | E29: 重点用能设备及系统节能 | F29: =VLOOKUP(E29,'Sector & Policy Match'!$G$1:$H$8,2,0) -> Improvement in Eqpt Efficiency Standards | G29: <5% | H29: 2021 | I29: 2025 | J29: 0.1 | K29: 4.3 | L29: =(1-IF(G29="<5%",0,G29))/(J29-IF(G29="<5%",0,G29))*K29 -> 43 | M29: 2060
A30: 2020 | B30: 特制电机技术 | C30: 电动机系统 | D30: =IFERROR(VLOOKUP(C30,'Sector & Policy Match'!$A$1:$B$42,2,0),"") -> 电动机系统 | E30: 重点用能设备及系统节能 | F30: =VLOOKUP(E30,'Sector & Policy Match'!$G$1:$H$8,2,0) -> Improvement in Eqpt Efficiency Standards | G30: <5% | H30: 2021 | I30: 2025 | J30: 0.06 | K30: 4.9 | L30: =(1-IF(G30="<5%",0,G30))/(J30-IF(G30="<5%",0,G30))*K30 -> 81.666667 | M30: 2060
A31: 2020 | B31: 中央空调热水锅炉 | C31: 空调系统 | D31: =IFERROR(VLOOKUP(C31,'Sector & Policy Match'!$A$1:$B$42,2,0),"") -> 空调系统 | E31: 重点用能设备及系统节能 | F31: =VLOOKUP(E31,'Sector & Policy Match'!$G$1:$H$8,2,0) -> Improvement in Eqpt Efficiency Standards | G31: <5% | H31: 2021 | I31: 2025 | J31: 0.15 | K31: 21.5 | L31: =(1-IF(G31="<5%",0,G31))/(J31-IF(G31="<5%",0,G31))*K31 -> 143.33333 | M31: 2060
A32: 2020 | B32: 电缸驱动游梁式抽油机技术 | C32: 油气开采 | D32: =IFERROR(VLOOKUP(C32,'Sector & Policy Match'!$A$1:$B$42,2,0),"") -> oil and gas extraction 06 | E32: 重点用能设备及系统节能 | F32: =VLOOKUP(E32,'Sector & Policy Match'!$G$1:$H$8,2,0) -> Improvement in Eqpt Efficiency Standards | G32: <5% | H32: 2021 | I32: 2025 | J32: 0.1 | K32: 68 | L32: =(1-IF(G32="<5%",0,G32))/(J32-IF(G32="<5%",0,G32))*K32 -> 680 | M32: 2060
A33: 2020 | B33: 智能磁悬浮透平真空泵综合节能技术 | C33: 造纸 | D33: =IFERROR(VLOOKUP(C33,'Sector & Policy Match'!$A$1:$B$42,2,0),"") -> pulp paper and printing 17T18 | E33: 重点用能设备及系统节能 | F33: =VLOOKUP(E33,'Sector & Policy Match'!$G$1:$H$8,2,0) -> Improvement in Eqpt Efficiency Standards | G33: <5% | H33: 2021 | I33: 2025 | J33: 0.1 | K33: 53 | L33: =(1-IF(G33="<5%",0,G33))/(J33-IF(G33="<5%",0,G33))*K33 -> 530 | M33: 2060
A34: 2020 | B34: 超大型4段蓄热式高速燃烧技术 | C34: 工业锅炉 | D34: =IFERROR(VLOOKUP(C34,'Sector & Policy Match'!$A$1:$B$42,2,0),"") -> 工业锅炉 | E34: 重点用能设备及系统节能 | F34: =VLOOKUP(E34,'Sector & Policy Match'!$G$1:$H$8,2,0) -> Improvement in Eqpt Efficiency Standards | G34: 0.05 | H34: 2021 | I34: 2025 | J34: 0.15 | K34: 8.4 | L34: =(1-IF(G34="<5%",0,G34))/(J34-IF(G34="<5%",0,G34))*K34 -> 79.8 | M34: 2060
A35: 2020 | B35: 卧式油冷型永磁调速器技术 | C35: 电动机系统 | D35: =IFERROR(VLOOKUP(C35,'Sector & Policy Match'!$A$1:$B$42,2,0),"") -> 电动机系统 | E35: 重点用能设备及系统节能 | F35: =VLOOKUP(E35,'Sector & Policy Match'!$G$1:$H$8,2,0) -> Improvement in Eqpt Efficiency Standards | G35: 0.05 | H35: 2021 | I35: 2025 | J35: 0.23 | K35: 34 | L35: =(1-IF(G35="<5%",0,G35))/(J35-IF(G35="<5%",0,G35))*K35 -> 179.44444 | M35: 2060
A36: 2020 | B36: 电极锅炉设计技术开发及制造 | C36: 电力、热力生产 | D36: =IFERROR(VLOOKUP(C36,'Sector & Policy Match'!$A$1:$B$42,2,0),"") -> 电力、热力生产 | E36: 重点用能设备及系统节能 | F36: =VLOOKUP(E36,'Sector & Policy Match'!$G$1:$H$8,2,0) -> Improvement in Eqpt Efficiency Standards | G36: 0.05 | H36: 2021 | I36: 2025 | J36: 0.15 | K36: 39 | L36: =(1-IF(G36="<5%",0,G36))/(J36-IF(G36="<5%",0,G36))*K36 -> 370.5 | M36: 2060
A37: 2020 | B37: 汽轮机变工况运行改造节能技术 | C37: 油气开采 | D37: =IFERROR(VLOOKUP(C37,'Sector & Policy Match'!$A$1:$B$42,2,0),"") -> oil and gas extraction 06 | E37: 重点用能设备及系统节能 | F37: =VLOOKUP(E37,'Sector & Policy Match'!$G$1:$H$8,2,0) -> Improvement in Eqpt Efficiency Standards | G37: 0.1 | H37: 2021 | I37: 2025 | J37: 0.4 | K37: 40 | L37: =(1-IF(G37="<5%",0,G37))/(J37-IF(G37="<5%",0,G37))*K37 -> 120 | M37: 2060
A38: 2020 | B38: 循环水系统节能技术 | C38: 化工 | D38: =IFERROR(VLOOKUP(C38,'Sector & Policy Match'!$A$1:$B$42,2,0),"") -> chemicals 20 | E38: 重点用能设备及系统节能 | F38: =VLOOKUP(E38,'Sector & Policy Match'!$G$1:$H$8,2,0) -> Improvement in Eqpt Efficiency Standards | G38: 0.1 | H38: 2021 | I38: 2025 | J38: 0.2 | K38: 5.28 | L38: =(1-IF(G38="<5%",0,G38))/(J38-IF(G38="<5%",0,G38))*K38 -> 47.52 | M38: 2060
A39: 2020 | B39: 燃煤锅炉智能调载趋零积灰趋零结露深度节能技术 | C39: 工业锅炉 | D39: =IFERROR(VLOOKUP(C39,'Sector & Policy Match'!$A$1:$B$42,2,0),"") -> 工业锅炉 | E39: 重点用能设备及系统节能 | F39: =VLOOKUP(E39,'Sector & Policy Match'!$G$1:$H$8,2,0) -> Improvement in Eqpt Efficiency Standards | G39: 0.12 | H39: 2021 | I39: 2025 | J39: 0.5 | K39: 146 | L39: =(1-IF(G39="<5%",0,G39))/(J39-IF(G39="<5%",0,G39))*K39 -> 338.10526 | M39: 2060
A40: 2020 | B40: 低温空气源热泵供热技术 | C40: Bldgs | D40: =IFERROR(VLOOKUP(C40,'Sector & Policy Match'!$A$1:$B$42,2,0),"") | E40: 重点用能设备及系统节能 | F40: =VLOOKUP(E40,'Sector & Policy Match'!$G$1:$H$8,2,0) -> Improvement in Eqpt Efficiency Standards | G40: 0.15 | H40: 2021 | I40: 2025 | J40: 0.4 | K40: 9.8 | L40: =(1-IF(G40="<5%",0,G40))/(J40-IF(G40="<5%",0,G40))*K40 -> 33.32 | M40: 2060
...

Sheet 用能设备节能分配
A1: 发布时间 | B1: 重点用能设备 | C1: EPS政策 | D1: 推广期的节能能力 (万tce/a) | E1: 100%推广的节能能力 (万tce/a) | G1: 重点用能设备 | H1: 适用范围 | I1: EPS行业 | J1: BIFUbC 2022 | K1: 占比 | M1: 发布时间 | N1: 重点用能设备 | O1: EPS行业 | P1: EPS政策 | Q1: 推广期的节能能力 (万tce/a) | R1: 100%推广的节能能力 (万tce/a)
A2: 2020 | B2: 工业锅炉 | C2: Early Facility Retirement | D2: =SUMIFS(工业节能技术装备推荐目录!K:K,工业节能技术装备推荐目录!C:C,用能设备节能分配!B2,工业节能技术装备推荐目录!F:F,用能设备节能分配!C2,工业节能技术装备推荐目录!A:A,用能设备节能分配!A2) -> 36 | E2: =SUMIFS(工业节能技术装备推荐目录!L:L,工业节能技术装备推荐目录!C:C,用能设备节能分配!B2,工业节能技术装备推荐目录!F:F,用能设备节能分配!C2,工业节能技术装备推荐目录!A:A,用能设备节能分配!A2) -> 153 | G2: 工业锅炉 | H2: 电力、热力生产 | I2: =VLOOKUP(H2,'Sector & Policy Match'!$A$1:$B$42,2,0) -> 电力、热力生产 | J2: =IFERROR(VLOOKUP(I2,BIFUbC!$A$1:$B$27,2,0),0) -> 2.2694301e+15 | K2: =J2/SUM($J$2:$J$8) -> 0.024815538 | M2: 2020 | N2: 工业锅炉 | O2: =I$3 -> refined petroleum and coke 19 | P2: Early Facility Retirement | Q2: =SUMIFS(D:D,B:B,N2,C:C,P2,A:A,M2)*SUMIFS(K:K,G:G,N2,I:I,O2) -> 21.434634 | R2: =SUMIFS(E:E,B:B,N2,C:C,P2,A:A,M2)*SUMIFS(K:K,G:G,N2,I:I,O2) -> 91.097194
A3: 2020 | B3: 工业锅炉 | C3: Installation and System Integration | D3: =SUMIFS(工业节能技术装备推荐目录!K:K,工业节能技术装备推荐目录!C:C,用能设备节能分配!B3,工业节能技术装备推荐目录!F:F,用能设备节能分配!C3,工业节能技术装备推荐目录!A:A,用能设备节能分配!A3) -> 0 | E3: =SUMIFS(工业节能技术装备推荐目录!L:L,工业节能技术装备推荐目录!C:C,用能设备节能分配!B3,工业节能技术装备推荐目录!F:F,用能设备节能分配!C3,工业节能技术装备推荐目录!A:A,用能设备节能分配!A3) -> 0 | G3: 工业锅炉 | H3: 石化 | I3: =VLOOKUP(H3,'Sector & Policy Match'!$A$1:$B$42,2,0) -> refined petroleum and coke 19 | J3: =IFERROR(VLOOKUP(I3,BIFUbC!$A$1:$B$27,2,0),0) -> 5.4451105e+16 | K3: =J3/SUM($J$2:$J$8) -> 0.5954065 | M3: 2020 | N3: 工业锅炉 | O3: =I$3 -> refined petroleum and coke 19 | P3: Installation and System Integration | Q3: =SUMIFS(D:D,B:B,N3,C:C,P3,A:A,M3)*SUMIFS(K:K,G:G,N3,I:I,O3) -> 0 | R3: =SUMIFS(E:E,B:B,N3,C:C,P3,A:A,M3)*SUMIFS(K:K,G:G,N3,I:I,O3) -> 0
A4: 2020 | B4: 工业锅炉 | C4: Cogeneration and Waste Heat Recovery | D4: =SUMIFS(工业节能技术装备推荐目录!K:K,工业节能技术装备推荐目录!C:C,用能设备节能分配!B4,工业节能技术装备推荐目录!F:F,用能设备节能分配!C4,工业节能技术装备推荐目录!A:A,用能设备节能分配!A4) -> 66 | E4: =SUMIFS(工业节能技术装备推荐目录!L:L,工业节能技术装备推荐目录!C:C,用能设备节能分配!B4,工业节能技术装备推荐目录!F:F,用能设备节能分配!C4,工业节能技术装备推荐目录!A:A,用能设备节能分配!A4) -> 660 | G4: 工业锅炉 | H4: 化工 | I4: =VLOOKUP(H4,'Sector & Policy Match'!$A$1:$B$42,2,0) -> chemicals 20 | J4: =IFERROR(VLOOKUP(I4,BIFUbC!$A$1:$B$27,2,0),0) -> 1.1779139e+16 | K4: =J4/SUM($J$2:$J$8) -> 0.12880135 | M4: 2020 | N4: 工业锅炉 | O4: =I$3 -> refined petroleum and coke 19 | P4: Cogeneration and Waste Heat Recovery | Q4: =SUMIFS(D:D,B:B,N4,C:C,P4,A:A,M4)*SUMIFS(K:K,G:G,N4,I:I,O4) -> 39.296829 | R4: =SUMIFS(E:E,B:B,N4,C:C,P4,A:A,M4)*SUMIFS(K:K,G:G,N4,I:I,O4) -> 392.96829
A5: 2020 | B5: 工业锅炉 | C5: Improvement in Eqpt Efficiency Standards | D5: =SUMIFS(工业节能技术装备推荐目录!K:K,工业节能技术装备推荐目录!C:C,用能设备节能分配!B5,工业节能技术装备推荐目录!F:F,用能设备节能分配!C5,工业节能技术装备推荐目录!A:A,用能设备节能分配!A5) -> 154.4 | E5: =SUMIFS(工业节能技术装备推荐目录!L:L,工业节能技术装备推荐目录!C:C,用能设备节能分配!B5,工业节能技术装备推荐目录!F:F,用能设备节能分配!C5,工业节能技术装备推荐目录!A:A,用能设备节能分配!A5) -> 417.90526 | G5: 工业锅炉 | H5: 钢铁 | I5: =VLOOKUP(H5,'Sector & Policy Match'!$A$1:$B$42,2,0) -> iron and steel 241 | J5: =IFERROR(VLOOKUP(I5,BIFUbC!$A$1:$B$27,2,0),0) -> 1.9189057e+16 | K5: =J5/SUM($J$2:$J$8) -> 0.20982658 | M5: 2020 | N5: 工业锅炉 | O5: =I$3 -> refined petroleum and coke 19 | P5: Improvement in Eqpt Efficiency Standards | Q5: =SUMIFS(D:D,B:B,N5,C:C,P5,A:A,M5)*SUMIFS(K:K,G:G,N5,I:I,O5) -> 91.930763 | R5: =SUMIFS(E:E,B:B,N5,C:C,P5,A:A,M5)*SUMIFS(K:K,G:G,N5,I:I,O5) -> 248.82351
A6: 2020 | B6: 工业循环水 | C6: Early Facility Retirement | D6: =SUMIFS(工业节能技术装备推荐目录!K:K,工业节能技术装备推荐目录!C:C,用能设备节能分配!B6,工业节能技术装备推荐目录!F:F,用能设备节能分配!C6,工业节能技术装备推荐目录!A:A,用能设备节能分配!A6) -> 0 | E6: =SUMIFS(工业节能技术装备推荐目录!L:L,工业节能技术装备推荐目录!C:C,用能设备节能分配!B6,工业节能技术装备推荐目录!F:F,用能设备节能分配!C6,工业节能技术装备推荐目录!A:A,用能设备节能分配!A6) -> 0 | G6: 工业锅炉 | H6: 纺织 | I6: =VLOOKUP(H6,'Sector & Policy Match'!$A$1:$B$42,2,0) -> textiles apparel and leather 13T15 | J6: =IFERROR(VLOOKUP(I6,BIFUbC!$A$1:$B$27,2,0),0) -> 1.3736513e+15 | K6: =J6/SUM($J$2:$J$8) -> 0.015020465 | M6: 2020 | N6: 工业锅炉 | O6: =I$4 -> chemicals 20 | P6: =P2 -> Early Facility Retirement | Q6: =SUMIFS(D:D,B:B,N6,C:C,P6,A:A,M6)*SUMIFS(K:K,G:G,N6,I:I,O6) -> 4.6368486 | R6: =SUMIFS(E:E,B:B,N6,C:C,P6,A:A,M6)*SUMIFS(K:K,G:G,N6,I:I,O6) -> 19.706607
A7: 2020 | B7: 工业循环水 | C7: Installation and System Integration | D7: =SUMIFS(工业节能技术装备推荐目录!K:K,工业节能技术装备推荐目录!C:C,用能设备节能分配!B7,工业节能技术装备推荐目录!F:F,用能设备节能分配!C7,工业节能技术装备推荐目录!A:A,用能设备节能分配!A7) -> 0 | E7: =SUMIFS(工业节能技术装备推荐目录!L:L,工业节能技术装备推荐目录!C:C,用能设备节能分配!B7,工业节能技术装备推荐目录!F:F,用能设备节能分配!C7,工业节能技术装备推荐目录!A:A,用能设备节能分配!A7) -> 0 | G7: 工业锅炉 | H7: 造纸 | I7: =VLOOKUP(H7,'Sector & Policy Match'!$A$1:$B$42,2,0) -> pulp paper and printing 17T18 | J7: =IFERROR(VLOOKUP(I7,BIFUbC!$A$1:$B$27,2,0),0) -> 8.7152832e+14 | K7: =J7/SUM($J$2:$J$8) -> 0.0095299007 | M7: 2020 | N7: 工业锅炉 | O7: =I$4 -> chemicals 20 | P7: =P3 -> Installation and System Integration | Q7: =SUMIFS(D:D,B:B,N7,C:C,P7,A:A,M7)*SUMIFS(K:K,G:G,N7,I:I,O7) -> 0 | R7: =SUMIFS(E:E,B:B,N7,C:C,P7,A:A,M7)*SUMIFS(K:K,G:G,N7,I:I,O7) -> 0
A8: 2020 | B8: 工业循环水 | C8: Cogeneration and Waste Heat Recovery | D8: =SUMIFS(工业节能技术装备推荐目录!K:K,工业节能技术装备推荐目录!C:C,用能设备节能分配!B8,工业节能技术装备推荐目录!F:F,用能设备节能分配!C8,工业节能技术装备推荐目录!A:A,用能设备节能分配!A8) -> 38 | E8: =SUMIFS(工业节能技术装备推荐目录!L:L,工业节能技术装备推荐目录!C:C,用能设备节能分配!B8,工业节能技术装备推荐目录!F:F,用能设备节能分配!C8,工业节能技术装备推荐目录!A:A,用能设备节能分配!A8) -> 253.33333 | G8: 工业锅炉 | H8: 食品 | I8: =VLOOKUP(H8,'Sector & Policy Match'!$A$1:$B$42,2,0) -> food beverage and tobacco 10T12 | J8: =IFERROR(VLOOKUP(I8,BIFUbC!$A$1:$B$27,2,0),0) -> 1.5180729e+15 | K8: =J8/SUM($J$2:$J$8) -> 0.016599672 | M8: 2020 | N8: 工业锅炉 | O8: =I$4 -> chemicals 20 | P8: =P4 -> Cogeneration and Waste Heat Recovery | Q8: =SUMIFS(D:D,B:B,N8,C:C,P8,A:A,M8)*SUMIFS(K:K,G:G,N8,I:I,O8) -> 8.5008892 | R8: =SUMIFS(E:E,B:B,N8,C:C,P8,A:A,M8)*SUMIFS(K:K,G:G,N8,I:I,O8) -> 85.008892
A9: 2020 | B9: 工业循环水 | C9: Improvement in Eqpt Efficiency Standards | D9: =SUMIFS(工业节能技术装备推荐目录!K:K,工业节能技术装备推荐目录!C:C,用能设备节能分配!B9,工业节能技术装备推荐目录!F:F,用能设备节能分配!C9,工业节能技术装备推荐目录!A:A,用能设备节能分配!A9) -> 0 | E9: =SUMIFS(工业节能技术装备推荐目录!L:L,工业节能技术装备推荐目录!C:C,用能设备节能分配!B9,工业节能技术装备推荐目录!F:F,用能设备节能分配!C9,工业节能技术装备推荐目录!A:A,用能设备节能分配!A9) -> 0 | G9: 工业循环水 | H9: 石化 | I9: =VLOOKUP(H9,'Sector & Policy Match'!$A$1:$B$42,2,0) -> refined petroleum and coke 19 | J9: =IFERROR(VLOOKUP(I9,BIFUbC!$A$1:$B$27,2,0),0) -> 5.4451105e+16 | K9: =J9/SUM($J$9:$J$15) -> 0.58802909 | M9: 2020 | N9: 工业锅炉 | O9: =I$4 -> chemicals 20 | P9: =P5 -> Improvement in Eqpt Efficiency Standards | Q9: =SUMIFS(D:D,B:B,N9,C:C,P9,A:A,M9)*SUMIFS(K:K,G:G,N9,I:I,O9) -> 19.886929 | R9: =SUMIFS(E:E,B:B,N9,C:C,P9,A:A,M9)*SUMIFS(K:K,G:G,N9,I:I,O9) -> 53.826763
A10: 2020 | B10: 微型燃气轮机 | C10: Early Facility Retirement | D10: =SUMIFS(工业节能技术装备推荐目录!K:K,工业节能技术装备推荐目录!C:C,用能设备节能分配!B10,工业节能技术装备推荐目录!F:F,用能设备节能分配!C10,工业节能技术装备推荐目录!A:A,用能设备节能分配!A10) -> 0 | E10: =SUMIFS(工业节能技术装备推荐目录!L:L,工业节能技术装备推荐目录!C:C,用能设备节能分配!B10,工业节能技术装备推荐目录!F:F,用能设备节能分配!C10,工业节能技术装备推荐目录!A:A,用能设备节能分配!A10) -> 0 | G10: 工业循环水 | H10: 化工 | I10: =VLOOKUP(H10,'Sector & Policy Match'!$A$1:$B$42,2,0) -> chemicals 20 | J10: =IFERROR(VLOOKUP(I10,BIFUbC!$A$1:$B$27,2,0),0) -> 1.1779139e+16 | K10: =J10/SUM($J$9:$J$15) -> 0.12720543 | M10: 2020 | N10: 工业锅炉 | O10: =I$5 -> iron and steel 241 | P10: =P6 -> Early Facility Retirement | Q10: =SUMIFS(D:D,B:B,N10,C:C,P10,A:A,M10)*SUMIFS(K:K,G:G,N10,I:I,O10) -> 7.5537568 | R10: =SUMIFS(E:E,B:B,N10,C:C,P10,A:A,M10)*SUMIFS(K:K,G:G,N10,I:I,O10) -> 32.103466
A11: 2020 | B11: 微型燃气轮机 | C11: Installation and System Integration | D11: =SUMIFS(工业节能技术装备推荐目录!K:K,工业节能技术装备推荐目录!C:C,用能设备节能分配!B11,工业节能技术装备推荐目录!F:F,用能设备节能分配!C11,工业节能技术装备推荐目录!A:A,用能设备节能分配!A11) -> 0 | E11: =SUMIFS(工业节能技术装备推荐目录!L:L,工业节能技术装备推荐目录!C:C,用能设备节能分配!B11,工业节能技术装备推荐目录!F:F,用能设备节能分配!C11,工业节能技术装备推荐目录!A:A,用能设备节能分配!A11) -> 0 | G11: 工业循环水 | H11: 钢铁 | I11: =VLOOKUP(H11,'Sector & Policy Match'!$A$1:$B$42,2,0) -> iron and steel 241 | J11: =IFERROR(VLOOKUP(I11,BIFUbC!$A$1:$B$27,2,0),0) -> 1.9189057e+16 | K11: =J11/SUM($J$9:$J$15) -> 0.20722671 | M11: 2020 | N11: 工业锅炉 | O11: =I$5 -> iron and steel 241 | P11: =P7 -> Installation and System Integration | Q11: =SUMIFS(D:D,B:B,N11,C:C,P11,A:A,M11)*SUMIFS(K:K,G:G,N11,I:I,O11) -> 0 | R11: =SUMIFS(E:E,B:B,N11,C:C,P11,A:A,M11)*SUMIFS(K:K,G:G,N11,I:I,O11) -> 0
A12: 2020 | B12: 微型燃气轮机 | C12: Cogeneration and Waste Heat Recovery | D12: =SUMIFS(工业节能技术装备推荐目录!K:K,工业节能技术装备推荐目录!C:C,用能设备节能分配!B12,工业节能技术装备推荐目录!F:F,用能设备节能分配!C12,工业节能技术装备推荐目录!A:A,用能设备节能分配!A12) -> 36 | E12: =SUMIFS(工业节能技术装备推荐目录!L:L,工业节能技术装备推荐目录!C:C,用能设备节能分配!B12,工业节能技术装备推荐目录!F:F,用能设备节能分配!C12,工业节能技术装备推荐目录!A:A,用能设备节能分配!A12) -> 240 | G12: 工业循环水 | H12: 有色金属 | I12: =VLOOKUP(H12,'Sector & Policy Match'!$A$1:$B$42,2,0) -> other metals 242 | J12: =IFERROR(VLOOKUP(I12,BIFUbC!$A$1:$B$27,2,0),0) -> 3.4167861e+15 | K12: =J12/SUM($J$9:$J$15) -> 0.036898602 | M12: 2020 | N12: 工业锅炉 | O12: =I$5 -> iron and steel 241 | P12: =P8 -> Cogeneration and Waste Heat Recovery | Q12: =SUMIFS(D:D,B:B,N12,C:C,P12,A:A,M12)*SUMIFS(K:K,G:G,N12,I:I,O12) -> 13.848554 | R12: =SUMIFS(E:E,B:B,N12,C:C,P12,A:A,M12)*SUMIFS(K:K,G:G,N12,I:I,O12) -> 138.48554
A13: 2020 | B13: 微型燃气轮机 | C13: Improvement in Eqpt Efficiency Standards | D13: =SUMIFS(工业节能技术装备推荐目录!K:K,工业节能技术装备推荐目录!C:C,用能设备节能分配!B13,工业节能技术装备推荐目录!F:F,用能设备节能分配!C13,工业节能技术装备推荐目录!A:A,用能设备节能分配!A13) -> 0 | E13: =SUMIFS(工业节能技术装备推荐目录!L:L,工业节能技术装备推荐目录!C:C,用能设备节能分配!B13,工业节能技术装备推荐目录!F:F,用能设备节能分配!C13,工业节能技术装备推荐目录!A:A,用能设备节能分配!A13) -> 0 | G13: 工业循环水 | H13: 造纸 | I13: =VLOOKUP(H13,'Sector & Policy Match'!$A$1:$B$42,2,0) -> pulp paper and printing 17T18 | J13: =IFERROR(VLOOKUP(I13,BIFUbC!$A$1:$B$27,2,0),0) -> 8.7152832e+14 | K13: =J13/SUM($J$9:$J$15) -> 0.0094118201 | M13: 2020 | N13: 工业锅炉 | O13: =I$5 -> iron and steel 241 | P13: =P9 -> Improvement in Eqpt Efficiency Standards | Q13: =SUMIFS(D:D,B:B,N13,C:C,P13,A:A,M13)*SUMIFS(K:K,G:G,N13,I:I,O13) -> 32.397224 | R13: =SUMIFS(E:E,B:B,N13,C:C,P13,A:A,M13)*SUMIFS(K:K,G:G,N13,I:I,O13) -> 87.687631
A14: 2020 | B14: 压缩空气系统 | C14: Early Facility Retirement | D14: =SUMIFS(工业节能技术装备推荐目录!K:K,工业节能技术装备推荐目录!C:C,用能设备节能分配!B14,工业节能技术装备推荐目录!F:F,用能设备节能分配!C14,工业节能技术装备推荐目录!A:A,用能设备节能分配!A14) -> 0 | E14: =SUMIFS(工业节能技术装备推荐目录!L:L,工业节能技术装备推荐目录!C:C,用能设备节能分配!B14,工业节能技术装备推荐目录!F:F,用能设备节能分配!C14,工业节能技术装备推荐目录!A:A,用能设备节能分配!A14) -> 0 | G14: 工业循环水 | H14: 纺织 | I14: =VLOOKUP(H14,'Sector & Policy Match'!$A$1:$B$42,2,0) -> textiles apparel and leather 13T15 | J14: =IFERROR(VLOOKUP(I14,BIFUbC!$A$1:$B$27,2,0),0) -> 1.3736513e+15 | K14: =J14/SUM($J$9:$J$15) -> 0.014834354 | M14: 2020 | N14: 工业锅炉 | O14: =I$6 -> textiles apparel and leather 13T15 | P14: =P10 -> Early Facility Retirement | Q14: =SUMIFS(D:D,B:B,N14,C:C,P14,A:A,M14)*SUMIFS(K:K,G:G,N14,I:I,O14) -> 0.54073675 | R14: =SUMIFS(E:E,B:B,N14,C:C,P14,A:A,M14)*SUMIFS(K:K,G:G,N14,I:I,O14) -> 2.2981312
A15: 2020 | B15: 压缩空气系统 | C15: Installation and System Integration | D15: =SUMIFS(工业节能技术装备推荐目录!K:K,工业节能技术装备推荐目录!C:C,用能设备节能分配!B15,工业节能技术装备推荐目录!F:F,用能设备节能分配!C15,工业节能技术装备推荐目录!A:A,用能设备节能分配!A15) -> 0 | E15: =SUMIFS(工业节能技术装备推荐目录!L:L,工业节能技术装备推荐目录!C:C,用能设备节能分配!B15,工业节能技术装备推荐目录!F:F,用能设备节能分配!C15,工业节能技术装备推荐目录!A:A,用能设备节能分配!A15) -> 0 | G15: 工业循环水 | H15: 食品 | I15: =VLOOKUP(H15,'Sector & Policy Match'!$A$1:$B$42,2,0) -> food beverage and tobacco 10T12 | J15: =IFERROR(VLOOKUP(I15,BIFUbC!$A$1:$B$27,2,0),0) -> 1.5180729e+15 | K15: =J15/SUM($J$9:$J$15) -> 0.016393993 | M15: 2020 | N15: 工业锅炉 | O15: =I$6 -> textiles apparel and leather 13T15 | P15: =P11 -> Installation and System Integration | Q15: =SUMIFS(D:D,B:B,N15,C:C,P15,A:A,M15)*SUMIFS(K:K,G:G,N15,I:I,O15) -> 0 | R15: =SUMIFS(E:E,B:B,N15,C:C,P15,A:A,M15)*SUMIFS(K:K,G:G,N15,I:I,O15) -> 0
A16: 2020 | B16: 压缩空气系统 | C16: Cogeneration and Waste Heat Recovery | D16: =SUMIFS(工业节能技术装备推荐目录!K:K,工业节能技术装备推荐目录!C:C,用能设备节能分配!B16,工业节能技术装备推荐目录!F:F,用能设备节能分配!C16,工业节能技术装备推荐目录!A:A,用能设备节能分配!A16) -> 0 | E16: =SUMIFS(工业节能技术装备推荐目录!L:L,工业节能技术装备推荐目录!C:C,用能设备节能分配!B16,工业节能技术装备推荐目录!F:F,用能设备节能分配!C16,工业节能技术装备推荐目录!A:A,用能设备节能分配!A16) -> 0 | G16: 微型燃气轮机 | H16: 非道路交通制造 | I16: =VLOOKUP(H16,'Sector & Policy Match'!$A$1:$B$42,2,0) -> nonroad vehicles 30 | J16: =IFERROR(VLOOKUP(I16,BIFUbC!$A$1:$B$27,2,0),0) -> 1.5444635e+14 | K16: =J16/SUM($J$16:$J$17) -> 0.063718737 | M16: 2020 | N16: 工业锅炉 | O16: =I$6 -> textiles apparel and leather 13T15 | P16: =P12 -> Cogeneration and Waste Heat Recovery | Q16: =SUMIFS(D:D,B:B,N16,C:C,P16,A:A,M16)*SUMIFS(K:K,G:G,N16,I:I,O16) -> 0.99135071 | R16: =SUMIFS(E:E,B:B,N16,C:C,P16,A:A,M16)*SUMIFS(K:K,G:G,N16,I:I,O16) -> 9.9135071
A17: 2020 | B17: 压缩空气系统 | C17: Improvement in Eqpt Efficiency Standards | D17: =SUMIFS(工业节能技术装备推荐目录!K:K,工业节能技术装备推荐目录!C:C,用能设备节能分配!B17,工业节能技术装备推荐目录!F:F,用能设备节能分配!C17,工业节能技术装备推荐目录!A:A,用能设备节能分配!A17) -> 6.6 | E17: =SUMIFS(工业节能技术装备推荐目录!L:L,工业节能技术装备推荐目录!C:C,用能设备节能分配!B17,工业节能技术装备推荐目录!F:F,用能设备节能分配!C17,工业节能技术装备推荐目录!A:A,用能设备节能分配!A17) -> 33 | G17: 微型燃气轮机 | H17: 电力、热力生产 | I17: =VLOOKUP(H17,'Sector & Policy Match'!$A$1:$B$42,2,0) -> 电力、热力生产 | J17: =IFERROR(VLOOKUP(I17,BIFUbC!$A$1:$B$27,2,0),0) -> 2.2694301e+15 | K17: =J17/SUM($J$16:$J$17) -> 0.93628126 | M17: 2020 | N17: 工业锅炉 | O17: =I$6 -> textiles apparel and leather 13T15 | P17: =P13 -> Improvement in Eqpt Efficiency Standards | Q17: =SUMIFS(D:D,B:B,N17,C:C,P17,A:A,M17)*SUMIFS(K:K,G:G,N17,I:I,O17) -> 2.3191598 | R17: =SUMIFS(E:E,B:B,N17,C:C,P17,A:A,M17)*SUMIFS(K:K,G:G,N17,I:I,O17) -> 6.2771315
A18: 2020 | B18: 电动机系统 | C18: Early Facility Retirement | D18: =SUMIFS(工业节能技术装备推荐目录!K:K,工业节能技术装备推荐目录!C:C,用能设备节能分配!B18,工业节能技术装备推荐目录!F:F,用能设备节能分配!C18,工业节能技术装备推荐目录!A:A,用能设备节能分配!A18) -> 0 | E18: =SUMIFS(工业节能技术装备推荐目录!L:L,工业节能技术装备推荐目录!C:C,用能设备节能分配!B18,工业节能技术装备推荐目录!F:F,用能设备节能分配!C18,工业节能技术装备推荐目录!A:A,用能设备节能分配!A18) -> 0 | G18: 压缩空气系统 | H18: 电力、热力生产 | I18: =VLOOKUP(H18,'Sector & Policy Match'!$A$1:$B$42,2,0) -> 电力、热力生产 | J18: =IFERROR(VLOOKUP(I18,BIFUbC!$A$1:$B$27,2,0),0) -> 2.2694301e+15 | K18: =J18/SUM($J$18:$J$23) -> 0.057386899 | M18: 2020 | N18: 工业锅炉 | O18: =I$7 -> pulp paper and printing 17T18 | P18: =P14 -> Early Facility Retirement | Q18: =SUMIFS(D:D,B:B,N18,C:C,P18,A:A,M18)*SUMIFS(K:K,G:G,N18,I:I,O18) -> 0.34307643 | R18: =SUMIFS(E:E,B:B,N18,C:C,P18,A:A,M18)*SUMIFS(K:K,G:G,N18,I:I,O18) -> 1.4580748
A19: 2020 | B19: 电动机系统 | C19: Installation and System Integration | D19: =SUMIFS(工业节能技术装备推荐目录!K:K,工业节能技术装备推荐目录!C:C,用能设备节能分配!B19,工业节能技术装备推荐目录!F:F,用能设备节能分配!C19,工业节能技术装备推荐目录!A:A,用能设备节能分配!A19) -> 0 | E19: =SUMIFS(工业节能技术装备推荐目录!L:L,工业节能技术装备推荐目录!C:C,用能设备节能分配!B19,工业节能技术装备推荐目录!F:F,用能设备节能分配!C19,工业节能技术装备推荐目录!A:A,用能设备节能分配!A19) -> 0 | G19: 压缩空气系统 | H19: 纺织 | I19: =VLOOKUP(H19,'Sector & Policy Match'!$A$1:$B$42,2,0) -> textiles apparel and leather 13T15 | J19: =IFERROR(VLOOKUP(I19,BIFUbC!$A$1:$B$27,2,0),0) -> 1.3736513e+15 | K19: =J19/SUM($J$18:$J$23) -> 0.034735412 | M19: 2020 | N19: 工业锅炉 | O19: =I$7 -> pulp paper and printing 17T18 | P19: =P15 -> Installation and System Integration | Q19: =SUMIFS(D:D,B:B,N19,C:C,P19,A:A,M19)*SUMIFS(K:K,G:G,N19,I:I,O19) -> 0 | R19: =SUMIFS(E:E,B:B,N19,C:C,P19,A:A,M19)*SUMIFS(K:K,G:G,N19,I:I,O19) -> 0
A20: 2020 | B20: 电动机系统 | C20: Cogeneration and Waste Heat Recovery | D20: =SUMIFS(工业节能技术装备推荐目录!K:K,工业节能技术装备推荐目录!C:C,用能设备节能分配!B20,工业节能技术装备推荐目录!F:F,用能设备节能分配!C20,工业节能技术装备推荐目录!A:A,用能设备节能分配!A20) -> 0 | E20: =SUMIFS(工业节能技术装备推荐目录!L:L,工业节能技术装备推荐目录!C:C,用能设备节能分配!B20,工业节能技术装备推荐目录!F:F,用能设备节能分配!C20,工业节能技术装备推荐目录!A:A,用能设备节能分配!A20) -> 0 | G20: 压缩空气系统 | H20: 食品 | I20: =VLOOKUP(H20,'Sector & Policy Match'!$A$1:$B$42,2,0) -> food beverage and tobacco 10T12 | J20: =IFERROR(VLOOKUP(I20,BIFUbC!$A$1:$B$27,2,0),0) -> 1.5180729e+15 | K20: =J20/SUM($J$18:$J$23) -> 0.038387388 | M20: 2020 | N20: 工业锅炉 | O20: =I$7 -> pulp paper and printing 17T18 | P20: =P16 -> Cogeneration and Waste Heat Recovery | Q20: =SUMIFS(D:D,B:B,N20,C:C,P20,A:A,M20)*SUMIFS(K:K,G:G,N20,I:I,O20) -> 0.62897345 | R20: =SUMIFS(E:E,B:B,N20,C:C,P20,A:A,M20)*SUMIFS(K:K,G:G,N20,I:I,O20) -> 6.2897345
A21: 2020 | B21: 电动机系统 | C21: Improvement in Eqpt Efficiency Standards | D21: =SUMIFS(工业节能技术装备推荐目录!K:K,工业节能技术装备推荐目录!C:C,用能设备节能分配!B21,工业节能技术装备推荐目录!F:F,用能设备节能分配!C21,工业节能技术装备推荐目录!A:A,用能设备节能分配!A21) -> 43.2 | E21: =SUMIFS(工业节能技术装备推荐目录!L:L,工业节能技术装备推荐目录!C:C,用能设备节能分配!B21,工业节能技术装备推荐目录!F:F,用能设备节能分配!C21,工业节能技术装备推荐目录!A:A,用能设备节能分配!A21) -> 304.11111 | G21: 压缩空气系统 | H21: 化工 | I21: =VLOOKUP(H21,'Sector & Policy Match'!$A$1:$B$42,2,0) -> chemicals 20 | J21: =IFERROR(VLOOKUP(I21,BIFUbC!$A$1:$B$27,2,0),0) -> 1.1779139e+16 | K21: =J21/SUM($J$18:$J$23) -> 0.29785815 | M21: 2020 | N21: 工业锅炉 | O21: =I$7 -> pulp paper and printing 17T18 | P21: =P17 -> Improvement in Eqpt Efficiency Standards | Q21: =SUMIFS(D:D,B:B,N21,C:C,P21,A:A,M21)*SUMIFS(K:K,G:G,N21,I:I,O21) -> 1.4714167 | R21: =SUMIFS(E:E,B:B,N21,C:C,P21,A:A,M21)*SUMIFS(K:K,G:G,N21,I:I,O21) -> 3.9825957
A22: 2020 | B22: 空调系统 | C22: Early Facility Retirement | D22: =SUMIFS(工业节能技术装备推荐目录!K:K,工业节能技术装备推荐目录!C:C,用能设备节能分配!B22,工业节能技术装备推荐目录!F:F,用能设备节能分配!C22,工业节能技术装备推荐目录!A:A,用能设备节能分配!A22) -> 0 | E22: =SUMIFS(工业节能技术装备推荐目录!L:L,工业节能技术装备推荐目录!C:C,用能设备节能分配!B22,工业节能技术装备推荐目录!F:F,用能设备节能分配!C22,工业节能技术装备推荐目录!A:A,用能设备节能分配!A22) -> 0 | G22: 压缩空气系统 | H22: 钢铁 | I22: =VLOOKUP(H22,'Sector & Policy Match'!$A$1:$B$42,2,0) -> iron and steel 241 | J22: =IFERROR(VLOOKUP(I22,BIFUbC!$A$1:$B$27,2,0),0) -> 1.9189057e+16 | K22: =J22/SUM($J$18:$J$23) -> 0.48523215 | M22: 2020 | N22: 工业锅炉 | O22: =I$8 -> food beverage and tobacco 10T12 | P22: =P18 -> Early Facility Retirement | Q22: =SUMIFS(D:D,B:B,N22,C:C,P22,A:A,M22)*SUMIFS(K:K,G:G,N22,I:I,O22) -> 0.59758818 | R22: =SUMIFS(E:E,B:B,N22,C:C,P22,A:A,M22)*SUMIFS(K:K,G:G,N22,I:I,O22) -> 2.5397498
A23: 2020 | B23: 空调系统 | C23: Installation and System Integration | D23: =SUMIFS(工业节能技术装备推荐目录!K:K,工业节能技术装备推荐目录!C:C,用能设备节能分配!B23,工业节能技术装备推荐目录!F:F,用能设备节能分配!C23,工业节能技术装备推荐目录!A:A,用能设备节能分配!A23) -> 67.5 | E23: =SUMIFS(工业节能技术装备推荐目录!L:L,工业节能技术装备推荐目录!C:C,用能设备节能分配!B23,工业节能技术装备推荐目录!F:F,用能设备节能分配!C23,工业节能技术装备推荐目录!A:A,用能设备节能分配!A23) -> 422 | G23: 压缩空气系统 | H23: 有色金属 | I23: =VLOOKUP(H23,'Sector & Policy Match'!$A$1:$B$42,2,0) -> other metals 242 | J23: =IFERROR(VLOOKUP(I23,BIFUbC!$A$1:$B$27,2,0),0) -> 3.4167861e+15 | K23: =J23/SUM($J$18:$J$23) -> 0.086399999 | M23: 2020 | N23: 工业锅炉 | O23: =I$8 -> food beverage and tobacco 10T12 | P23: =P19 -> Installation and System Integration | Q23: =SUMIFS(D:D,B:B,N23,C:C,P23,A:A,M23)*SUMIFS(K:K,G:G,N23,I:I,O23) -> 0 | R23: =SUMIFS(E:E,B:B,N23,C:C,P23,A:A,M23)*SUMIFS(K:K,G:G,N23,I:I,O23) -> 0
A24: 2020 | B24: 空调系统 | C24: Cogeneration and Waste Heat Recovery | D24: =SUMIFS(工业节能技术装备推荐目录!K:K,工业节能技术装备推荐目录!C:C,用能设备节能分配!B24,工业节能技术装备推荐目录!F:F,用能设备节能分配!C24,工业节能技术装备推荐目录!A:A,用能设备节能分配!A24) -> 0 | E24: =SUMIFS(工业节能技术装备推荐目录!L:L,工业节能技术装备推荐目录!C:C,用能设备节能分配!B24,工业节能技术装备推荐目录!F:F,用能设备节能分配!C24,工业节能技术装备推荐目录!A:A,用能设备节能分配!A24) -> 0 | G24: 风机系统 | H24: 煤炭开采 | I24: =VLOOKUP(H24,'Sector & Policy Match'!$A$1:$B$42,2,0) -> coal mining 05 | J24: =IFERROR(VLOOKUP(I24,BIFUbC!$A$1:$B$27,2,0),0) -> 1.8369744e+16 | K24: =J24/SUM($J$24:$J$28) -> 0.17320393 | M24: 2020 | N24: 工业锅炉 | O24: =I$8 -> food beverage and tobacco 10T12 | P24: =P20 -> Cogeneration and Waste Heat Recovery | Q24: =SUMIFS(D:D,B:B,N24,C:C,P24,A:A,M24)*SUMIFS(K:K,G:G,N24,I:I,O24) -> 1.0955783 | R24: =SUMIFS(E:E,B:B,N24,C:C,P24,A:A,M24)*SUMIFS(K:K,G:G,N24,I:I,O24) -> 10.955783
A25: 2020 | B25: 空调系统 | C25: Improvement in Eqpt Efficiency Standards | D25: =SUMIFS(工业节能技术装备推荐目录!K:K,工业节能技术装备推荐目录!C:C,用能设备节能分配!B25,工业节能技术装备推荐目录!F:F,用能设备节能分配!C25,工业节能技术装备推荐目录!A:A,用能设备节能分配!A25) -> 21.5 | E25: =SUMIFS(工业节能技术装备推荐目录!L:L,工业节能技术装备推荐目录!C:C,用能设备节能分配!B25,工业节能技术装备推荐目录!F:F,用能设备节能分配!C25,工业节能技术装备推荐目录!A:A,用能设备节能分配!A25) -> 143.33333 | G25: 风机系统 | H25: 石化 | I25: =VLOOKUP(H25,'Sector & Policy Match'!$A$1:$B$42,2,0) -> refined petroleum and coke 19 | J25: =IFERROR(VLOOKUP(I25,BIFUbC!$A$1:$B$27,2,0),0) -> 5.4451105e+16 | K25: =J25/SUM($J$24:$J$28) -> 0.51340645 | M25: 2020 | N25: 工业锅炉 | O25: =I$8 -> food beverage and tobacco 10T12 | P25: =P21 -> Improvement in Eqpt Efficiency Standards | Q25: =SUMIFS(D:D,B:B,N25,C:C,P25,A:A,M25)*SUMIFS(K:K,G:G,N25,I:I,O25) -> 2.5629893 | R25: =SUMIFS(E:E,B:B,N25,C:C,P25,A:A,M25)*SUMIFS(K:K,G:G,N25,I:I,O25) -> 6.9370901
A26: 2020 | B26: 能源系统 | C26: Early Facility Retirement | D26: =SUMIFS(工业节能技术装备推荐目录!K:K,工业节能技术装备推荐目录!C:C,用能设备节能分配!B26,工业节能技术装备推荐目录!F:F,用能设备节能分配!C26,工业节能技术装备推荐目录!A:A,用能设备节能分配!A26) -> 0 | E26: =SUMIFS(工业节能技术装备推荐目录!L:L,工业节能技术装备推荐目录!C:C,用能设备节能分配!B26,工业节能技术装备推荐目录!F:F,用能设备节能分配!C26,工业节能技术装备推荐目录!A:A,用能设备节能分配!A26) -> 0 | G26: 风机系统 | H26: 化工 | I26: =VLOOKUP(H26,'Sector & Policy Match'!$A$1:$B$42,2,0) -> chemicals 20 | J26: =IFERROR(VLOOKUP(I26,BIFUbC!$A$1:$B$27,2,0),0) -> 1.1779139e+16 | K26: =J26/SUM($J$24:$J$28) -> 0.11106268 | M26: 2020 | N26: =G$9 -> 工业循环水 | O26: =I$9 -> refined petroleum and coke 19 | P26: =P22 -> Early Facility Retirement | Q26: =SUMIFS(D:D,B:B,N26,C:C,P26,A:A,M26)*SUMIFS(K:K,G:G,N26,I:I,O26) -> 0 | R26: =SUMIFS(E:E,B:B,N26,C:C,P26,A:A,M26)*SUMIFS(K:K,G:G,N26,I:I,O26) -> 0
A27: 2020 | B27: 能源系统 | C27: Installation and System Integration | D27: =SUMIFS(工业节能技术装备推荐目录!K:K,工业节能技术装备推荐目录!C:C,用能设备节能分配!B27,工业节能技术装备推荐目录!F:F,用能设备节能分配!C27,工业节能技术装备推荐目录!A:A,用能设备节能分配!A27) -> 84.7 | E27: =SUMIFS(工业节能技术装备推荐目录!L:L,工业节能技术装备推荐目录!C:C,用能设备节能分配!B27,工业节能技术装备推荐目录!F:F,用能设备节能分配!C27,工业节能技术装备推荐目录!A:A,用能设备节能分配!A27) -> 861.83333 | G27: 风机系统 | H27: 钢铁 | I27: =VLOOKUP(H27,'Sector & Policy Match'!$A$1:$B$42,2,0) -> iron and steel 241 | J27: =IFERROR(VLOOKUP(I27,BIFUbC!$A$1:$B$27,2,0),0) -> 1.9189057e+16 | K27: =J27/SUM($J$24:$J$28) -> 0.18092903 | M27: 2020 | N27: =G$9 -> 工业循环水 | O27: =I$9 -> refined petroleum and coke 19 | P27: =P23 -> Installation and System Integration | Q27: =SUMIFS(D:D,B:B,N27,C:C,P27,A:A,M27)*SUMIFS(K:K,G:G,N27,I:I,O27) -> 0 | R27: =SUMIFS(E:E,B:B,N27,C:C,P27,A:A,M27)*SUMIFS(K:K,G:G,N27,I:I,O27) -> 0
A28: 2020 | B28: 能源系统 | C28: Cogeneration and Waste Heat Recovery | D28: =SUMIFS(工业节能技术装备推荐目录!K:K,工业节能技术装备推荐目录!C:C,用能设备节能分配!B28,工业节能技术装备推荐目录!F:F,用能设备节能分配!C28,工业节能技术装备推荐目录!A:A,用能设备节能分配!A28) -> 0 | E28: =SUMIFS(工业节能技术装备推荐目录!L:L,工业节能技术装备推荐目录!C:C,用能设备节能分配!B28,工业节能技术装备推荐目录!F:F,用能设备节能分配!C28,工业节能技术装备推荐目录!A:A,用能设备节能分配!A28) -> 0 | G28: 风机系统 | H28: 电力、热力生产 | I28: =VLOOKUP(H28,'Sector & Policy Match'!$A$1:$B$42,2,0) -> 电力、热力生产 | J28: =IFERROR(VLOOKUP(I28,BIFUbC!$A$1:$B$27,2,0),0) -> 2.2694301e+15 | K28: =J28/SUM($J$24:$J$28) -> 0.021397914 | M28: 2020 | N28: =G$9 -> 工业循环水 | O28: =I$9 -> refined petroleum and coke 19 | P28: =P24 -> Cogeneration and Waste Heat Recovery | Q28: =SUMIFS(D:D,B:B,N28,C:C,P28,A:A,M28)*SUMIFS(K:K,G:G,N28,I:I,O28) -> 22.345105 | R28: =SUMIFS(E:E,B:B,N28,C:C,P28,A:A,M28)*SUMIFS(K:K,G:G,N28,I:I,O28) -> 148.96737
A29: 2020 | B29: 能源系统 | C29: Improvement in Eqpt Efficiency Standards | D29: =SUMIFS(工业节能技术装备推荐目录!K:K,工业节能技术装备推荐目录!C:C,用能设备节能分配!B29,工业节能技术装备推荐目录!F:F,用能设备节能分配!C29,工业节能技术装备推荐目录!A:A,用能设备节能分配!A29) -> 0 | E29: =SUMIFS(工业节能技术装备推荐目录!L:L,工业节能技术装备推荐目录!C:C,用能设备节能分配!B29,工业节能技术装备推荐目录!F:F,用能设备节能分配!C29,工业节能技术装备推荐目录!A:A,用能设备节能分配!A29) -> 0 | G29: 汽轮机 | H29: 石化 | I29: =VLOOKUP(H29,'Sector & Policy Match'!$A$1:$B$42,2,0) -> refined petroleum and coke 19 | J29: =IFERROR(VLOOKUP(I29,BIFUbC!$A$1:$B$27,2,0),0) -> 5.4451105e+16 | K29: =J29/SUM($J$29:$J$34) -> 0.67597695 | M29: 2020 | N29: =G$9 -> 工业循环水 | O29: =I$9 -> refined petroleum and coke 19 | P29: =P25 -> Improvement in Eqpt Efficiency Standards | Q29: =SUMIFS(D:D,B:B,N29,C:C,P29,A:A,M29)*SUMIFS(K:K,G:G,N29,I:I,O29) -> 0 | R29: =SUMIFS(E:E,B:B,N29,C:C,P29,A:A,M29)*SUMIFS(K:K,G:G,N29,I:I,O29) -> 0
A30: 2020 | B30: 风机系统 | C30: Early Facility Retirement | D30: =SUMIFS(工业节能技术装备推荐目录!K:K,工业节能技术装备推荐目录!C:C,用能设备节能分配!B30,工业节能技术装备推荐目录!F:F,用能设备节能分配!C30,工业节能技术装备推荐目录!A:A,用能设备节能分配!A30) -> 0 | E30: =SUMIFS(工业节能技术装备推荐目录!L:L,工业节能技术装备推荐目录!C:C,用能设备节能分配!B30,工业节能技术装备推荐目录!F:F,用能设备节能分配!C30,工业节能技术装备推荐目录!A:A,用能设备节能分配!A30) -> 0 | G30: 汽轮机 | H30: 钢铁 | I30: =VLOOKUP(H30,'Sector & Policy Match'!$A$1:$B$42,2,0) -> iron and steel 241 | J30: =IFERROR(VLOOKUP(I30,BIFUbC!$A$1:$B$27,2,0),0) -> 1.9189057e+16 | K30: =J30/SUM($J$29:$J$34) -> 0.23822033 | M30: 2020 | N30: =G$9 -> 工业循环水 | O30: =I$10 -> chemicals 20 | P30: =P26 -> Early Facility Retirement | Q30: =SUMIFS(D:D,B:B,N30,C:C,P30,A:A,M30)*SUMIFS(K:K,G:G,N30,I:I,O30) -> 0 | R30: =SUMIFS(E:E,B:B,N30,C:C,P30,A:A,M30)*SUMIFS(K:K,G:G,N30,I:I,O30) -> 0
A31: 2020 | B31: 风机系统 | C31: Installation and System Integration | D31: =SUMIFS(工业节能技术装备推荐目录!K:K,工业节能技术装备推荐目录!C:C,用能设备节能分配!B31,工业节能技术装备推荐目录!F:F,用能设备节能分配!C31,工业节能技术装备推荐目录!A:A,用能设备节能分配!A31) -> 0 | E31: =SUMIFS(工业节能技术装备推荐目录!L:L,工业节能技术装备推荐目录!C:C,用能设备节能分配!B31,工业节能技术装备推荐目录!F:F,用能设备节能分配!C31,工业节能技术装备推荐目录!A:A,用能设备节能分配!A31) -> 0 | G31: 汽轮机 | H31: 有色金属 | I31: =VLOOKUP(H31,'Sector & Policy Match'!$A$1:$B$42,2,0) -> other metals 242 | J31: =IFERROR(VLOOKUP(I31,BIFUbC!$A$1:$B$27,2,0),0) -> 3.4167861e+15 | K31: =J31/SUM($J$29:$J$34) -> 0.042417297 | M31: 2020 | N31: =G$9 -> 工业循环水 | O31: =I$10 -> chemicals 20 | P31: =P27 -> Installation and System Integration | Q31: =SUMIFS(D:D,B:B,N31,C:C,P31,A:A,M31)*SUMIFS(K:K,G:G,N31,I:I,O31) -> 0 | R31: =SUMIFS(E:E,B:B,N31,C:C,P31,A:A,M31)*SUMIFS(K:K,G:G,N31,I:I,O31) -> 0
A32: 2020 | B32: 风机系统 | C32: Cogeneration and Waste Heat Recovery | D32: =SUMIFS(工业节能技术装备推荐目录!K:K,工业节能技术装备推荐目录!C:C,用能设备节能分配!B32,工业节能技术装备推荐目录!F:F,用能设备节能分配!C32,工业节能技术装备推荐目录!A:A,用能设备节能分配!A32) -> 0 | E32: =SUMIFS(工业节能技术装备推荐目录!L:L,工业节能技术装备推荐目录!C:C,用能设备节能分配!B32,工业节能技术装备推荐目录!F:F,用能设备节能分配!C32,工业节能技术装备推荐目录!A:A,用能设备节能分配!A32) -> 0 | G32: 汽轮机 | H32: 造纸 | I32: =VLOOKUP(H32,'Sector & Policy Match'!$A$1:$B$42,2,0) -> pulp paper and printing 17T18 | J32: =IFERROR(VLOOKUP(I32,BIFUbC!$A$1:$B$27,2,0),0) -> 8.7152832e+14 | K32: =J32/SUM($J$29:$J$34) -> 0.010819488 | M32: 2020 | N32: =G$9 -> 工业循环水 | O32: =I$10 -> chemicals 20 | P32: =P28 -> Cogeneration and Waste Heat Recovery | Q32: =SUMIFS(D:D,B:B,N32,C:C,P32,A:A,M32)*SUMIFS(K:K,G:G,N32,I:I,O32) -> 4.8338064 | R32: =SUMIFS(E:E,B:B,N32,C:C,P32,A:A,M32)*SUMIFS(K:K,G:G,N32,I:I,O32) -> 32.225376
A33: 2020 | B33: 风机系统 | C33: Improvement in Eqpt Efficiency Standards | D33: =SUMIFS(工业节能技术装备推荐目录!K:K,工业节能技术装备推荐目录!C:C,用能设备节能分配!B33,工业节能技术装备推荐目录!F:F,用能设备节能分配!C33,工业节能技术装备推荐目录!A:A,用能设备节能分配!A33) -> 0 | E33: =SUMIFS(工业节能技术装备推荐目录!L:L,工业节能技术装备推荐目录!C:C,用能设备节能分配!B33,工业节能技术装备推荐目录!F:F,用能设备节能分配!C33,工业节能技术装备推荐目录!A:A,用能设备节能分配!A33) -> 0 | G33: 汽轮机 | H33: 电力、热力生产 | I33: =VLOOKUP(H33,'Sector & Policy Match'!$A$1:$B$42,2,0) -> 电力、热力生产 | J33: =IFERROR(VLOOKUP(I33,BIFUbC!$A$1:$B$27,2,0),0) -> 2.2694301e+15 | K33: =J33/SUM($J$29:$J$34) -> 0.028173578 | M33: 2020 | N33: =G$9 -> 工业循环水 | O33: =I$10 -> chemicals 20 | P33: =P29 -> Improvement in Eqpt Efficiency Standards | Q33: =SUMIFS(D:D,B:B,N33,C:C,P33,A:A,M33)*SUMIFS(K:K,G:G,N33,I:I,O33) -> 0 | R33: =SUMIFS(E:E,B:B,N33,C:C,P33,A:A,M33)*SUMIFS(K:K,G:G,N33,I:I,O33) -> 0
A34: 2020 | B34: 汽轮机 | C34: Early Facility Retirement | D34: =SUMIFS(工业节能技术装备推荐目录!K:K,工业节能技术装备推荐目录!C:C,用能设备节能分配!B34,工业节能技术装备推荐目录!F:F,用能设备节能分配!C34,工业节能技术装备推荐目录!A:A,用能设备节能分配!A34) -> 0 | E34: =SUMIFS(工业节能技术装备推荐目录!L:L,工业节能技术装备推荐目录!C:C,用能设备节能分配!B34,工业节能技术装备推荐目录!F:F,用能设备节能分配!C34,工业节能技术装备推荐目录!A:A,用能设备节能分配!A34) -> 0 | G34: 汽轮机 | H34: 废弃物处理 | I34: =VLOOKUP(H34,'Sector & Policy Match'!$A$1:$B$42,2,0) -> water and waste 36T39 | J34: =IFERROR(VLOOKUP(I34,BIFUbC!$A$1:$B$27,2,0),0) -> 353812120372585 | K34: =J34/SUM($J$29:$J$34) -> 0.0043923597 | M34: 2020 | N34: =G$9 -> 工业循环水 | O34: =I$11 -> iron and steel 241 | P34: =P30 -> Early Facility Retirement | Q34: =SUMIFS(D:D,B:B,N34,C:C,P34,A:A,M34)*SUMIFS(K:K,G:G,N34,I:I,O34) -> 0 | R34: =SUMIFS(E:E,B:B,N34,C:C,P34,A:A,M34)*SUMIFS(K:K,G:G,N34,I:I,O34) -> 0
A35: 2020 | B35: 汽轮机 | C35: Installation and System Integration | D35: =SUMIFS(工业节能技术装备推荐目录!K:K,工业节能技术装备推荐目录!C:C,用能设备节能分配!B35,工业节能技术装备推荐目录!F:F,用能设备节能分配!C35,工业节能技术装备推荐目录!A:A,用能设备节能分配!A35) -> 0 | E35: =SUMIFS(工业节能技术装备推荐目录!L:L,工业节能技术装备推荐目录!C:C,用能设备节能分配!B35,工业节能技术装备推荐目录!F:F,用能设备节能分配!C35,工业节能技术装备推荐目录!A:A,用能设备节能分配!A35) -> 0 | G35: 工业炉窑 | H35: 钢铁 | I35: =VLOOKUP(H35,'Sector & Policy Match'!$A$1:$B$42,2,0) -> iron and steel 241 | J35: =IFERROR(VLOOKUP(I35,BIFUbC!$A$1:$B$27,2,0),0) -> 1.9189057e+16 | K35: =J35/SUM($J$35:$J$38) -> 0.2287476 | M35: 2020 | N35: =G$9 -> 工业循环水 | O35: =I$11 -> iron and steel 241 | P35: =P31 -> Installation and System Integration | Q35: =SUMIFS(D:D,B:B,N35,C:C,P35,A:A,M35)*SUMIFS(K:K,G:G,N35,I:I,O35) -> 0 | R35: =SUMIFS(E:E,B:B,N35,C:C,P35,A:A,M35)*SUMIFS(K:K,G:G,N35,I:I,O35) -> 0
A36: 2020 | B36: 汽轮机 | C36: Cogeneration and Waste Heat Recovery | D36: =SUMIFS(工业节能技术装备推荐目录!K:K,工业节能技术装备推荐目录!C:C,用能设备节能分配!B36,工业节能技术装备推荐目录!F:F,用能设备节能分配!C36,工业节能技术装备推荐目录!A:A,用能设备节能分配!A36) -> 0 | E36: =SUMIFS(工业节能技术装备推荐目录!L:L,工业节能技术装备推荐目录!C:C,用能设备节能分配!B36,工业节能技术装备推荐目录!F:F,用能设备节能分配!C36,工业节能技术装备推荐目录!A:A,用能设备节能分配!A36) -> 0 | G36: 工业炉窑 | H36: 石化 | I36: =VLOOKUP(H36,'Sector & Policy Match'!$A$1:$B$42,2,0) -> refined petroleum and coke 19 | J36: =IFERROR(VLOOKUP(I36,BIFUbC!$A$1:$B$27,2,0),0) -> 5.4451105e+16 | K36: =J36/SUM($J$35:$J$38) -> 0.64909702 | M36: 2020 | N36: =G$9 -> 工业循环水 | O36: =I$11 -> iron and steel 241 | P36: =P32 -> Cogeneration and Waste Heat Recovery | Q36: =SUMIFS(D:D,B:B,N36,C:C,P36,A:A,M36)*SUMIFS(K:K,G:G,N36,I:I,O36) -> 7.8746151 | R36: =SUMIFS(E:E,B:B,N36,C:C,P36,A:A,M36)*SUMIFS(K:K,G:G,N36,I:I,O36) -> 52.497434
A37: 2020 | B37: 汽轮机 | C37: Improvement in Eqpt Efficiency Standards | D37: =SUMIFS(工业节能技术装备推荐目录!K:K,工业节能技术装备推荐目录!C:C,用能设备节能分配!B37,工业节能技术装备推荐目录!F:F,用能设备节能分配!C37,工业节能技术装备推荐目录!A:A,用能设备节能分配!A37) -> 0 | E37: =SUMIFS(工业节能技术装备推荐目录!L:L,工业节能技术装备推荐目录!C:C,用能设备节能分配!B37,工业节能技术装备推荐目录!F:F,用能设备节能分配!C37,工业节能技术装备推荐目录!A:A,用能设备节能分配!A37) -> 0 | G37: 工业炉窑 | H37: 有色金属 | I37: =VLOOKUP(H37,'Sector & Policy Match'!$A$1:$B$42,2,0) -> other metals 242 | J37: =IFERROR(VLOOKUP(I37,BIFUbC!$A$1:$B$27,2,0),0) -> 3.4167861e+15 | K37: =J37/SUM($J$35:$J$38) -> 0.040730591 | M37: 2020 | N37: =G$9 -> 工业循环水 | O37: =I$11 -> iron and steel 241 | P37: =P33 -> Improvement in Eqpt Efficiency Standards | Q37: =SUMIFS(D:D,B:B,N37,C:C,P37,A:A,M37)*SUMIFS(K:K,G:G,N37,I:I,O37) -> 0 | R37: =SUMIFS(E:E,B:B,N37,C:C,P37,A:A,M37)*SUMIFS(K:K,G:G,N37,I:I,O37) -> 0
A38: 2020 | B38: 工业炉窑 | C38: Early Facility Retirement | D38: =SUMIFS(工业节能技术装备推荐目录!K:K,工业节能技术装备推荐目录!C:C,用能设备节能分配!B38,工业节能技术装备推荐目录!F:F,用能设备节能分配!C38,工业节能技术装备推荐目录!A:A,用能设备节能分配!A38) -> 0 | E38: =SUMIFS(工业节能技术装备推荐目录!L:L,工业节能技术装备推荐目录!C:C,用能设备节能分配!B38,工业节能技术装备推荐目录!F:F,用能设备节能分配!C38,工业节能技术装备推荐目录!A:A,用能设备节能分配!A38) -> 0 | G38: 工业炉窑 | H38: 建材 | I38: =VLOOKUP(H38,'Sector & Policy Match'!$A$1:$B$42,2,0) -> cement and other nonmetallic minerals 239 | J38: =IFERROR(VLOOKUP(I38,BIFUbC!$A$1:$B$27,2,0),0) -> 6.8305194e+15 | K38: =J38/SUM($J$35:$J$38) -> 0.08142479 | M38: 2020 | N38: =G$9 -> 工业循环水 | O38: =I$12 -> other metals 242 | P38: =P34 -> Early Facility Retirement | Q38: =SUMIFS(D:D,B:B,N38,C:C,P38,A:A,M38)*SUMIFS(K:K,G:G,N38,I:I,O38) -> 0 | R38: =SUMIFS(E:E,B:B,N38,C:C,P38,A:A,M38)*SUMIFS(K:K,G:G,N38,I:I,O38) -> 0
