Workbook

Sheet 20240130
A1: 新建 既改 都作用于 heating cooling lighting
A2: 新建 既改之间的关系
A3: 集中供暖受电碳因子的影响
A4: 生活设施 heating考虑下热泵
A5: COP2.5

Sheet 情景输入参数
A1: 一、关键时间点参数（重点核对） | C1: 是否核对 | D1: 目前数值
A2: 2020年建筑运行碳排放 | B2: 21.8亿吨
A3: 2030年建筑运行碳排放（峰值） | B3: 26亿吨
A4: 2020-2060建筑新建面积总和 | B4: 392亿㎡ | C4: 是 | D4: 350.3亿
A5: 建面2050 2060年建面 | B5: 约750亿㎡ | C5: 是 | D5: 60年757.5 50年751.6
A6: 建筑总改造量 | B6: 起始年份建面的40% | C6: 是 | D6: 0.4
A7: 建筑总拆除量 | B7: 起始年份建面的20% | C7: 目前存在问题 | D7: 若要满足750亿㎡，392亿新建，那拆除必须高。建议用：我国城镇住房拆除率及影响因素研究-黄禹 表4.10 中的0.71%每年
A8: 2020年集中供暖面积 | B8: 156亿㎡ | C8: 是 | D8: 181.9亿㎡
A9: 2050年集中供暖面积 | B9: 218亿㎡ | C9: 是 | D9: 255亿㎡
A10: 2050年集中供暖量 | B10: 54亿GJ | C10: 是 | D10: BAU越高34% 这个数可能带了政策
A12: 各能效水平下建筑节能率
B13: 住宅 | C13: 公建
A14: 2016年节能 | B14: 0.65 | C14: 0.65
A15: 2022年新规 | B15: 严寒寒冷75% 其他65% | C15: 0.72
A16: 超低能耗 | B16: 严寒寒冷83% 其他75% | C16: 0.75
A17: 近零能耗 | B17: 0.82 | C17: 0.82
A18: 零碳建筑 | B18: 0.82 | C18: 0.82
A20: 按南北方加权： | B20: 住宅 | C20: 公建
A21: 2016年节能 | B21: 0.65 | C21: 0.65
A22: 2022年新规 | B22: =0.75*人口变化预测!F8+0.65*(1-人口变化预测!F8) -> 0.690908 | C22: 0.72
A23: 超低能耗 | B23: =0.83*人口变化预测!F8+0.75*(1-人口变化预测!F8) -> 0.7827264 | C23: 0.75
A24: 近零能耗 | B24: 0.82 | C24: 0.82
A25: 零碳建筑 | B25: 0.82 | C25: 0.82
A26: 注：此表仅考虑维护结构热工性能提升带来的节能率，可再生能源另行计算
A28: 新建建筑能效分布
A29: BAU情景 | B29: 16年规定能耗建筑 | C29: 22年新规能耗建筑 | D29: 超低能耗建筑 | E29: 近零能耗建筑
A30: 2020 | B30: 1 | C30: 0 | D30: 0 | E30: 0
A31: 2022 | B31: 1 | C31: 0 | D31: 0 | E31: 0
A32: 2025 | B32: 1 | C32: 0 | D32: 0 | E32: 0
A33: 2030 | B33: 1 | C33: 0 | D33: 0 | E33: 0
A34: 2035 | B34: 1 | C34: 0 | D34: 0 | E34: 0
A35: 2040以后 | B35: 1 | C35: 0 | D35: 0 | E35: 0
A37: 政策情景 | B37: 16年规定能耗建筑 | C37: 22年新规能耗建筑 | D37: 超低能耗建筑 | E37: 近零能耗建筑
A38: 2020 | B38: 1 | C38: 0 | D38: 0 | E38: 0
A39: 2022 | B39: 0 | C39: 1 | D39: 0 | E39: 0
A40: 2025 | B40: 0 | C40: 0.6 | D40: 0.4 | E40: 0
A41: 2030 | B41: 0 | C41: 0 | D41: 1 | E41: 0
A42: 2035 | B42: 0 | C42: 0 | D42: 0.6 | E42: 0.4
A43: 2040以后 | B43: 0 | C43: 0 | D43: 0 | E43: 1
A44: 注：绿建三星在围护结构上与22年新规相同，零碳建筑在围护结构上与近零能耗相同，故去掉这两个能效等级
...

Sheet 情景介绍 (2)
B1: BAU情景 | C1: 减排情景
A2: 新建建筑能效 | B2: 新建建筑能效始终保持在2016标准节能水平 | C2: 新建建筑能效逐步提升，到2060年新建建筑100%为零碳建筑。具体能效分布见附表1 | D2: 2020年建筑运行碳排放21.8亿吨co2 | E2: 另一个口径是21.6亿 | F2: 改SYCEU
A3: 既存建筑改造 | B3: 不进行建筑节能改造。2020年之前建成的建筑，其能效水平一直保持不变。 | C3: 仅改造2020年之前建成的建筑，这部分建筑每年改造1%，改造后的能效从2022标准节能逐步提升至近零能耗，详见附表2。2020年后新建的建筑不改造
A4: 分布式光伏 | B4: 光伏装机量一直保持在2020年水平，不再增加 | C4: 屋顶光伏装机量随时间线性增加，到2050年，农村屋顶光伏装机20亿kW,城镇屋顶光伏装机8亿kW。
A5: 集中供暖电气化 | B5: 集中供暖电气化率一直保持在2020年水平，不再增加 | C5: 集中供暖电气化率随时间线性增加，到2050年集中供暖全部电气化
A6: 家用设施电气化 | B6: 家用设施电气化率一直保持在2020年水平，不再增加 | C6: 家用设施电气化率随时间线性增加，到2030年，公建设施100%电气化，住宅设施80%电气化 | D6: 家用设施稍小点，农村化石能源建筑排放应该是6亿吨co2，参考 | E6: 2040年住宅也要完全电气化，情景保守了
A7: 电力系统优化 | B7: 电力系统一直保持在2020年水平，不进行改造 | C7: 2020年后新建建筑全部进行电力系统优化，既存建筑的节能改造也全部进行电力系统优化
A10: 16年新规是 | B10: 0.65 | C10: 0.65
A11: 附表3：各能效水平建筑相较于基线能效建筑的节能率 | B11: 住宅 | C11: 公建
A12: 22年新规 | B12: 严寒寒冷75% 其他65% | C12: 0.72
A13: 绿建三星 | B13: - | C13: -
A14: 超低能耗 | B14: 严寒寒冷83% 其他75% | C14: 0.75
A15: 近零能耗 | B15: 0.82 | C15: 0.82
A16: 零碳建筑 | B16: 0.82 | C16: 0.82 | D16: 新建、既改一个柱子两个颜色
A17: 注：附表3仅考虑围护结构热工性能提升带来的节能率，分布式光伏和电力系统优化的节能另行计算
A26: 附表1：新建建筑能效分布 | B26: 16年规定能耗建筑 | C26: 22年新规能耗建筑 | D26: 超低能耗建筑 | E26: 近零能耗建筑
A27: 2020 | B27: 1 | C27: 0 | D27: 0 | E27: 0
A28: 2022 | B28: 0 | C28: 1 | D28: 0 | E28: 0
A29: 2025 | B29: 0 | C29: 0.6 | D29: 0.4 | E29: 0
A30: 2030 | B30: 0 | C30: 0 | D30: 1 | E30: 0
A31: 2035 | B31: 0 | C31: 0 | D31: 0.6 | E31: 0.4
A32: 2040以后 | B32: 0 | C32: 0 | D32: 0 | E32: 1
A35: 附表2：既存建筑改造后能效水平分布 | B35: 22年新规 | C35: 绿建三星 | D35: 超低能耗 | E35: 近零能耗 | F35: 零能耗
A36: 2020-2029 | B36: 1 | C36: 0 | D36: 0 | E36: 0 | F36: 0
A37: 2030-2039 | B37: 0 | C37: 1 | D37: 0 | E37: 0 | F37: 0
A38: 2040-2049 | B38: 0 | C38: 0 | D38: 1 | E38: 0 | F38: 0
A39: 2050-2060 | B39: 0 | C39: 0 | D39: 0 | E39: 1 | F39: 0
D53: =5.4*10^18/1055 -> 5.1184834e+15
D54: =6.89*10^15 -> 6.89e+15
D55: =D54/D53 -> 1.3461019

Sheet 情景介绍
B1: BAU情景 | C1: 减排情景
A2: 新建建筑能效 | B2: 新建建筑能效始终保持在2016标准节能水平 | C2: 新建建筑能效逐步提升，到2060年新建建筑100%为零碳建筑。具体能效分布见附表1 | D2: 2020年建筑运行碳排放21,8亿吨co2 | E2: 另一个口径是21.6亿
A3: 既存建筑改造 | B3: 不进行建筑节能改造。2020年之前建成的建筑，其能效水平一直保持不变。 | C3: 仅改造2020年之前建成的建筑，这部分建筑每年改造1%，改造后的能效从2022标准节能逐步提升至近零能耗，详见附表2。2020年后新建的建筑不改造 | D3: 新建占比过大，不科学
A4: 分布式光伏 | B4: 光伏装机量一直保持在2020年水平，不再增加 | C4: 屋顶光伏装机量随时间线性增加，到2050年，农村屋顶光伏装机20亿kW,城镇屋顶光伏装机8亿kW。 | D4: 既改很激进，但减碳量低
A5: 集中供暖电气化 | B5: 集中供暖电气化率一直保持在2020年水平，不再增加 | C5: 集中供暖电气化率随时间线性增加，到2050年集中供暖全部电气化 | D5: 集中供暖有多少是换热源、有多少是转电，这个比例解释清楚 | E5: 吴博士说是20%的热泵 | F5: 电气化就只是本地化石能源电气化，不含别的
A6: 家用设施电气化 | B6: 家用设施电气化率一直保持在2020年水平，不再增加 | C6: 家用设施电气化率随时间线性增加，到2030年，公建设施100%电气化，住宅设施80%电气化 | D6: 家用设施稍小点，农村化石能源建筑排放应该是6亿吨co2，参考 | E6: 2040年住宅也要完全电气化，情景保守了
A7: 电力系统优化 | B7: 电力系统一直保持在2020年水平，不进行改造 | C7: 2020年后新建建筑全部进行电力系统优化，既存建筑的节能改造也全部进行电力系统优化 | D7: 电碳因子目前接近BAU,政策情景电碳因子用赵言冰发的，最终结果电碳因子加上
D8: 电碳因子单独分出来
D9: 写零碳政策情景
A10: 16年新规是 | B10: 0.65 | C10: 0.65 | D10: 建筑用电调峰，言冰老师认为直接说节能量不合适，建议不放了
A11: 附表3：各能效水平建筑相较于基线能效建筑的节能率 | B11: 住宅 | C11: 公建 | D11: 光伏有效日照小时数全国应为1200小时，现在可能偏低，需要核实
A12: 22年新规 | B12: 严寒寒冷75% 其他65% | C12: 0.72 | D12: 2030年建筑碳排放峰值约为26亿吨
A13: 绿建三星 | B13: - | C13: - | D13: 确认下2060年为什么碳排放还有剩余？正常肯定没了
A14: 超低能耗 | B14: 严寒寒冷83% 其他75% | C14: 0.75 | D14: 2020-2060年新建总392亿㎡
A15: 近零能耗 | B15: 0.82 | C15: 0.82 | D15: 电力系统优化（柔性），去掉，不考虑了
A16: 零碳建筑 | B16: 0.82 | C16: 0.82 | D16: 新建、既改一个柱子两个颜色
A17: 注：附表3仅考虑围护结构热工性能提升带来的节能率，分布式光伏和电力系统优化的节能另行计算 | D17: 建面到2060年调到2050年 2060年750亿，参考750亿情景
D18: 绿建去掉
D19: 2030年全部达到超低及以上 | E19: 住宅超低83% 公建78%
D20: 2040年全部达到近零及以上
D21: 最高近零能耗
D22: 建筑2040年新建建筑全部电气化
D23: 2040年住宅既存电气化80% | E23: 按江亿的
A26: 附表1：新建建筑能效分布 | B26: 16年规定能耗建筑 | C26: 22年新规能耗建筑 | D26: 超低能耗建筑 | E26: 近零能耗建筑
A27: 2020 | B27: 1 | C27: 0 | D27: 0 | E27: 0
A28: 2022 | B28: 0 | C28: 1 | D28: 0 | E28: 0
A29: 2025 | B29: 0 | C29: 0.6 | D29: 0.4 | E29: 0
A30: 2030 | B30: 0 | C30: 0 | D30: 1 | E30: 0
A31: 2035 | B31: 0 | C31: 0 | D31: 0.6 | E31: 0.4
A32: 2040以后 | B32: 0 | C32: 0 | D32: 0 | E32: 1
A35: 附表2：既存建筑改造后能效水平分布 | B35: 22年新规 | C35: 绿建三星 | D35: 超低能耗 | E35: 近零能耗 | F35: 零能耗
A36: 2020-2029 | B36: 1 | C36: 0 | D36: 0 | E36: 0 | F36: 0
A37: 2030-2039 | B37: 0 | C37: 1 | D37: 0 | E37: 0 | F37: 0
A38: 2040-2049 | B38: 0 | C38: 0 | D38: 1 | E38: 0 | F38: 0
A39: 2050-2060 | B39: 0 | C39: 0 | D39: 0 | E39: 1 | F39: 0
D41: 建筑改造，改造到节能率75%
D42: 既存建筑有40%是不节能的（能效低于16年标准），只改造这一部分，改之前基线，改之后节能率65%
D43: 20-60年拆除量不能超过改造面积的20%，即起始年份的8%
D46: 2020集中供暖面积 156亿㎡
D48: 2030年，燃煤锅炉全部取消
...

Sheet About中文
A1: BCEU BAU Components Energy Use
A3: source: | B3: 人口计算
B4: Leslie人口模型
B6: 建筑面积计算
B7: Chongqing University & Energy Statistics Committee of China Building Energy Conservation Association
B8: 2018
B9: 2018 Annual Report on China Building Energy Consumption
B10: https://kns.cnki.net/kcms2/article/abstract?v=3uoqIhG8C44YLTlOAiTRKibYlV5Vjs7iLik5jEcCI09uHa3oBxtWoLXBqMuT2L2CQ_SDgkvzeuyHBRpPejPl_DToiZ2ygw3-&uniplatform=NZKPT
A18: note: | B18: 1.根据Leslie人口模型的数据，预测中国城市人口，农村人口，采暖人口的变化
B19: 2.从<2018 Annual Report on China Building Energy Consumption >中获取起始年份中国的人均城市住宅面积、人均农村住宅面积、人均公建面积。咨询专家得知，未来中国人均建面年增长率为0.3%，据此预测未来中国人均建筑面积的变化
B20: 3.用人口乘以人均建面可获取未来城市住宅、农村住宅、公共建筑面积的变化趋势。建筑面积的变化量由新建量和拆除量构成，建筑的拆除量按住宅每年拆除1/70,公建每年拆除1/50考虑，然后用前后两年的总变化量加上上年拆除量即为上年新建量。由此可将每年的建筑面积分为起始年份留存面积和新建面积
B21: 4.从SYCEU中获取起始年份留存建筑的总能耗，除以建面即得留存建筑的能耗强度。 从<2018 Annual Report on China Building Energy Consumption >获取各类建筑的基线能耗强度，从<建筑节能与可再生能源利用通用规范>中获取未来新建建筑的节能率，据此计算未来新建建筑的能耗强度
B22: 5.用既存建筑面积和新建建筑面积分别乘以各自对应的能耗强度，即可得到各类建筑未来的能耗变化趋势
B23: 6.将建筑能耗按SYCEU的比例拆分

Sheet 人口变化预测
A1: 山东历年人口数据&人口变化预测 | B1: 2016 | C1: 2017 | D1: 2018 | E1: 2019 | F1: 2020 | G1: 2021 | H1: 2022 | I1: 2023 | J1: 2024 | K1: 2025 | L1: 2026 | M1: 2027 | N1: 2028 | O1: 2029 | P1: 2030 | Q1: 2031 | R1: 2032 | S1: 2033 | T1: 2034 | U1: 2035 | V1: 2036 | W1: 2037 | X1: 2038 | Y1: 2039 | Z1: 2040 | AA1: 2041 | AB1: 2042 | AC1: 2043 | AD1: 2044 | AE1: 2045 | AF1: 2046 | AG1: 2047 | AH1: 2048 | AI1: 2049 | AJ1: 2050 | AK1: 2051 | AL1: 2052 | AM1: 2053 | AN1: 2054 | AO1: 2055 | AP1: 2056 | AQ1: 2057 | AR1: 2058 | AS1: 2059 | AT1: 2060
A2: 城镇化率 | B2: 0.588 | C2: =$B$2*($F$2/$B$2)^((C1-2016)/4) -> 0.60035511 | D2: =$B$2*($F$2/$B$2)^((D1-2016)/4) -> 0.61296982 | E2: =$B$2*($F$2/$B$2)^((E1-2016)/4) -> 0.62584959 | F2: 0.639 | G2: =$F$2*(0.8/$F$2)^((G1-2020)/40) -> 0.6425998 | H2: =$F$2*(0.8/$F$2)^((H1-2020)/40) -> 0.64621988 | I2: =$F$2*(0.8/$F$2)^((I1-2020)/40) -> 0.64986035 | J2: =$F$2*(0.8/$F$2)^((J1-2020)/40) -> 0.65352134 | K2: =$F$2*(0.8/$F$2)^((K1-2020)/40) -> 0.65720294 | L2: =$F$2*(0.8/$F$2)^((L1-2020)/40) -> 0.66090529 | M2: =$F$2*(0.8/$F$2)^((M1-2020)/40) -> 0.66462849 | N2: =$F$2*(0.8/$F$2)^((N1-2020)/40) -> 0.66837267 | ... AT2: =$F$2*(0.8/$F$2)^((AT1-2020)/40) -> 0.8
A3: 总人口 | B3: =SUM(D12:D378) -> 1.3860024e+09 | C3: =SUM(E12:E378) -> 1.3934428e+09 | D3: =SUM(F12:F378) -> 1.4003134e+09 | E3: =SUM(G12:G378) -> 1400793135 | F3: =SUM(H12:H378) -> 1410976903 | G3: =SUM(I12:I378) -> 1420266066 | H3: =SUM(J12:J378) -> 1428670957 | I3: =SUM(K12:K378) -> 1436203098 | ... AT3: =SUM(AV12:AV378) -> 1314032289
A4: 城市人口 | B4: =B3*B2 -> 8.149694e+08 | C4: =C3*C2 -> 8.3656047e+08 | D4: =D3*D2 -> 8.5834985e+08 | E4: =E3*E2 -> 8.7668582e+08 | F4: =F3*F2 -> 9.0161424e+08 | G4: =G3*G2 -> 9.1266269e+08 | H4: =H3*H2 -> 9.2323557e+08 | I4: =I3*I2 -> 9.3333145e+08 | ... AT4: =AT3*AT2 -> 1.0512258e+09
A5: 农村人口 | B5: =B3-B4 -> 5.7103298e+08 | C5: =C3-C4 -> 5.5688228e+08 | D5: =D3-D4 -> 5.4196354e+08 | E5: =E3-E4 -> 5.2410732e+08 | F5: =F3-F4 -> 5.0936266e+08 | G5: =G3-G4 -> 5.0760338e+08 | H5: =H3-H4 -> 5.0543538e+08 | I5: =I3-I4 -> 5.0287164e+08 | ... AT5: =AT3-AT4 -> 2.6280646e+08
A6: 采暖省份人口 | B6: =SUMIFS(D12:D378,$C$12:$C$378,"是") -> 5.8676683e+08 | C6: =SUMIFS(E12:E378,$C$12:$C$378,"是") -> 5.8998437e+08 | D6: =SUMIFS(F12:F378,$C$12:$C$378,"是") -> 5.9293631e+08 | E6: =SUMIFS(G12:G378,$C$12:$C$378,"是") -> 573112213 | F6: =SUMIFS(H12:H378,$C$12:$C$378,"是") -> 577202419 | G6: =SUMIFS(I12:I378,$C$12:$C$378,"是") -> 580887802 | H6: =SUMIFS(J12:J378,$C$12:$C$378,"是") -> 584177205 | I6: =SUMIFS(K12:K378,$C$12:$C$378,"是") -> 587079716 | ... AT6: =SUMIFS(AV12:AV378,$C$12:$C$378,"是") -> 529796515
A7: 采暖人口 | B7: =SUMIFS(D12:D378,$C$12:$C$378,"是")*B2 -> 3.450189e+08 | C7: =SUMIFS(E12:E378,$C$12:$C$378,"是")*C2 -> 3.5420013e+08 | D7: =SUMIFS(F12:F378,$C$12:$C$378,"是")*D2 -> 3.6345206e+08 | E7: =SUMIFS(G12:G378,$C$12:$C$378,"是")*E2 -> 3.5868205e+08 | F7: =SUMIFS(H12:H378,$C$12:$C$378,"是")*F2 -> 3.6883235e+08 | G7: =SUMIFS(I12:I378,$C$12:$C$378,"是")*G2 -> 3.7327839e+08 | H7: =SUMIFS(J12:J378,$C$12:$C$378,"是")*H2 -> 3.7750692e+08 | I7: =SUMIFS(K12:K378,$C$12:$C$378,"是")*I2 -> 3.8151983e+08 | ... AT7: =SUMIFS(AV12:AV378,$C$12:$C$378,"是")*AT2 -> 423837212
A8: 采暖省份的人口占比 | B8: =B7/B2/B3 -> 0.42335196 | C8: =C7/C2/C3 -> 0.42340051 | D8: =D7/D2/D3 -> 0.42343115 | E8: =E7/E2/E3 -> 0.40913408 | F8: =F7/F2/F3 -> 0.40907999 | G8: =G7/G2/G3 -> 0.40899928 | H8: =H7/H2/H3 -> 0.40889556 | I8: =I7/I2/I3 -> 0.40877207 | ... AT8: =AT7/AT2/AT3 -> 0.40318379
A10: Leslie人口源数据：
A11: City | C11: 是否采暖 | D11: 2016 | E11: 2017 | F11: 2018 | G11: 2019 | H11: 2020 | I11: 2021 | J11: 2022 | K11: 2023 | L11: 2024 | M11: 2025 | N11: 2026 | O11: 2027 | P11: 2028 | Q11: 2029 | R11: 2030 | S11: 2031 | T11: 2032 | U11: 2033 | V11: 2034 | W11: 2035 | X11: 2036 | Y11: 2037 | Z11: 2038 | AA11: 2039 | AB11: 2040 | AC11: 2041 | AD11: 2042 | AE11: 2043 | AF11: 2044 | AG11: 2045 | AH11: 2046 | AI11: 2047 | AJ11: 2048 | AK11: 2049 | AL11: 2050 | AM11: 2051 | AN11: 2052 | AO11: 2053 | AP11: 2054 | AQ11: 2055 | AR11: 2056 | AS11: 2057 | AT11: 2058 | AU11: 2059 | AV11: 2060
A12: 北京市 | B12: 北京 | C12: 是 | D12: 20876818 | E12: 21043312 | F12: 21192712 | G12: 21641222 | H12: 21891193 | I12: 22092349 | J12: 22249167 | K12: 22365919 | L12: 22446671 | M12: 22495287 | N12: 22515425 | O12: 22510539 | P12: 22483879 | Q12: 22438490 | R12: 22377211 | S12: 22302681 | T12: 22217329 | U12: 22123385 | V12: 22022870 | W12: 21917603 | X12: 21809199 | Y12: 21699066 | Z12: 21588410 | AA12: 21478232 | AB12: 21369328 | AC12: 21262290 | AD12: 21157505 | AE12: 21055156 | AF12: 20955222 | AG12: 20857477 | AH12: 20761490 | AI12: 20666628 | AJ12: 20572049 | AK12: 20476712 | AL12: 20379368 | AM12: 20278564 | AN12: 20172643 | AO12: 20059744 | AP12: 19937802 | AQ12: 19804545 | AR12: 19657500 | AS12: 19493987 | AT12: 19311122 | AU12: 19105817 | AV12: 18874781
A13: 天津市 | B13: 天津 | C13: 是 | D13: 13567334 | E13: 13653977 | F13: 13732217 | G13: 13739203 | H13: 13864934 | I13: 13965579 | J13: 14043199 | K13: 14099770 | L13: 14137179 | M13: 14157227 | N13: 14161631 | O13: 14152018 | P13: 14129932 | Q13: 14096828 | R13: 14054075 | S13: 14002956 | T13: 13944668 | U13: 13880322 | V13: 13810939 | W13: 13737458 | X13: 13660729 | Y13: 13581517 | Z13: 13500498 | AA13: 13418265 | AB13: 13335323 | AC13: 13252088 | AD13: 13168894 | AE13: 13085986 | AF13: 13003523 | AG13: 12921577 | AH13: 12840135 | AI13: 12759095 | AJ13: 12678272 | AK13: 12597391 | AL13: 12516094 | AM13: 12433933 | AN13: 12350377 | AO13: 12264805 | AP13: 12176513 | AQ13: 12084708 | AR13: 11988512 | AS13: 11886960 | AT13: 11779000 | AU13: 11663494 | AV13: 11539219
A14: 石家庄市 | B14: 石家庄 | C14: 是 | D14: 10686651 | E14: 10759180 | F14: 10826289 | G14: 11135097 | H14: 11234139 | I14: 11322464 | J14: 11400612 | K14: 11469108 | L14: 11528463 | M14: 11579176 | N14: 11621729 | O14: 11656594 | P14: 11684227 | Q14: 11705069 | R14: 11719549 | S14: 11728082 | T14: 11731069 | U14: 11728896 | V14: 11721937 | W14: 11710551 | X14: 11695084 | Y14: 11675867 | Z14: 11653217 | AA14: 11627439 | AB14: 11598822 | AC14: 11567644 | AD14: 11534165 | AE14: 11498636 | AF14: 11461289 | AG14: 11422347 | AH14: 11382015 | AI14: 11340488 | AJ14: 11297944 | AK14: 11254549 | AL14: 11210455 | AM14: 11165798 | AN14: 11120704 | AO14: 11075281 | AP14: 11029627 | AQ14: 10983823 | AR14: 10937938 | AS14: 10892027 | AT14: 10846130 | AU14: 10800274 | AV14: 10754473
A15: 唐山市 | B15: 唐山 | C15: 是 | D15: 7874731.2 | E15: 7909764 | F15: 7940411.9 | G15: 7678887 | H15: 7717136 | I15: 7749822 | J15: 7777124 | K15: 7799223 | L15: 7816298 | M15: 7828530 | N15: 7836100 | O15: 7839190 | P15: 7837984 | Q15: 7832663 | R15: 7823411 | S15: 7810414 | T15: 7793854 | U15: 7773918 | V15: 7750791 | W15: 7724660 | X15: 7695713 | Y15: 7664135 | Z15: 7630116 | AA15: 7593844 | AB15: 7555509 | AC15: 7515300 | AD15: 7473408 | AE15: 7430023 | AF15: 7385337 | AG15: 7339543 | AH15: 7292832 | AI15: 7245399 | AJ15: 7197436 | AK15: 7149139 | AL15: 7100701 | AM15: 7052320 | AN15: 7004189 | AO15: 6956507 | AP15: 6909471 | AQ15: 6863277 | AR15: 6818125 | AS15: 6774213 | AT15: 6731741 | AU15: 6690909 | AV15: 6651916
A16: 秦皇岛市 | B16: 秦皇岛 | C16: 是 | D16: 3106235 | E16: 3121107.7 | F16: 3134335.6 | G16: 3118115 | H16: 3136546 | I16: 3152301 | J16: 3165496 | K16: 3176243 | L16: 3184654 | M16: 3190839 | N16: 3194906 | O16: 3196962 | P16: 3197112 | Q16: 3195459 | R16: 3192105 | S16: 3187150 | T16: 3180692 | U16: 3172828 | V16: 3163652 | W16: 3153260 | X16: 3141741 | Y16: 3129187 | Z16: 3115685 | AA16: 3101323 | AB16: 3086185 | AC16: 3070356 | AD16: 3053917 | AE16: 3036948 | AF16: 3019527 | AG16: 3001732 | AH16: 2983639 | AI16: 2965319 | AJ16: 2946846 | AK16: 2928290 | AL16: 2909719 | AM16: 2891201 | AN16: 2872800 | AO16: 2854581 | AP16: 2836605 | AQ16: 2818933 | AR16: 2801623 | AS16: 2784733 | AT16: 2768318 | AU16: 2752432 | AV16: 2737126
A17: 邯郸市 | B17: 邯郸 | C17: 是 | D17: 9673167.1 | E17: 9731065.4 | F17: 9783611.7 | G17: 9366372 | H17: 9413329 | I17: 9462180 | J17: 9512262 | K17: 9562952 | L17: 9613662 | M17: 9663844 | N17: 9712987 | O17: 9760617 | P17: 9806298 | Q17: 9849633 | R17: 9890260 | S17: 9927857 | T17: 9962140 | U17: 9992860 | V17: 10019810 | W17: 10042816 | X17: 10061745 | Y17: 10076500 | Z17: 10087024 | AA17: 10093294 | AB17: 10095328 | AC17: 10093180 | AD17: 10086943 | AE17: 10076746 | AF17: 10062758 | AG17: 10045183 | AH17: 10024266 | AI17: 10000285 | AJ17: 9973561 | AK17: 9944450 | AL17: 9913345 | AM17: 9880678 | AN17: 9846919 | AO17: 9812575 | AP17: 9778191 | AQ17: 9744349 | AR17: 9711669 | AS17: 9680811 | AT17: 9652468 | AU17: 9627376 | AV17: 9606304
A18: 邢台市 | B18: 邢台 | C18: 是 | D18: 7482383 | E18: 7531475.8 | F18: 7576754.7 | G18: 7058880 | H18: 7110576 | I18: 7159488 | J18: 7205534 | K18: 7248644 | L18: 7288757 | M18: 7325823 | N18: 7359802 | O18: 7390663 | P18: 7418388 | Q18: 7442968 | R18: 7464404 | S18: 7482708 | T18: 7497902 | U18: 7510018 | V18: 7519098 | W18: 7525196 | X18: 7528375 | Y18: 7528709 | Z18: 7526282 | AA18: 7521187 | AB18: 7513531 | AC18: 7503427 | AD18: 7491001 | AE18: 7476388 | AF18: 7459735 | AG18: 7441198 | AH18: 7420943 | AI18: 7399148 | AJ18: 7376000 | AK18: 7351696 | AL18: 7326444 | AM18: 7300463 | AN18: 7273981 | AO18: 7247237 | AP18: 7220481 | AQ18: 7193972 | AR18: 7167980 | AS18: 7142785 | AT18: 7118678 | AU18: 7095960 | AV18: 7074941
A19: 保定市 | B19: 保定 | C19: 是 | D19: 11726942 | E19: 11792754 | F19: 11852313 | G19: 11475860 | H19: 11542974 | I19: 11605691 | J19: 11663886 | K19: 11717453 | L19: 11766300 | M19: 11810353 | N19: 11849553 | O19: 11883859 | P19: 11913244 | Q19: 11937700 | R19: 11957233 | S19: 11971868 | T19: 11981643 | U19: 11986615 | V19: 11986856 | W19: 11982455 | X19: 11973518 | Y19: 11960165 | Z19: 11942535 | AA19: 11920781 | AB19: 11895075 | AC19: 11865602 | AD19: 11832567 | AE19: 11796189 | AF19: 11756704 | AG19: 11714363 | AH19: 11669436 | AI19: 11622207 | AJ19: 11572979 | AK19: 11522067 | AL19: 11469807 | AM19: 11416549 | AN19: 11362659 | AO19: 11308520 | AP19: 11254532 | AQ19: 11201110 | AR19: 11148687 | AS19: 11097710 | AT19: 11048645 | AU19: 11001973 | AV19: 10958191
A20: 张家口市 | B20: 张家口 | C20: 是 | D20: 4466424.4 | E20: 4479270 | F20: 4490122.7 | G20: 4107476 | H20: 4118494 | I20: 4128506 | J20: 4137368 | K20: 4144948 | L20: 4151128 | M20: 4155802 | N20: 4158876 | O20: 4160270 | P20: 4159916 | Q20: 4157759 | R20: 4153756 | S20: 4147879 | T20: 4140110 | U20: 4130445 | V20: 4118892 | W20: 4105474 | X20: 4090223 | Y20: 4073187 | Z20: 4054425 | AA20: 4034009 | AB20: 4012024 | AC20: 3988568 | AD20: 3963751 | AE20: 3937696 | AF20: 3910540 | AG20: 3882430 | AH20: 3853528 | AI20: 3824008 | AJ20: 3794056 | AK20: 3763873 | AL20: 3733669 | AM20: 3703671 | AN20: 3674116 | AO20: 3645253 | AP20: 3617347 | AQ20: 3590673 | AR20: 3565519 | AS20: 3542188 | AT20: 3520991 | AU20: 3502258 | AV20: 3486326
A21: 承德市 | B21: 承德 | C21: 是 | D21: 3599572.4 | E21: 3613787.7 | F21: 3626369.1 | G21: 3341797 | H21: 3354153 | I21: 3366260 | J21: 3377932 | K21: 3388991 | L21: 3399277 | M21: 3408640 | N21: 3416946 | O21: 3424074 | P21: 3429915 | Q21: 3434376 | R21: 3437374 | S21: 3438844 | T21: 3438731 | U21: 3436994 | V21: 3433608 | W21: 3428558 | X21: 3421844 | Y21: 3413481 | Z21: 3403495 | AA21: 3391928 | AB21: 3378833 | AC21: 3364277 | AD21: 3348343 | AE21: 3331125 | AF21: 3312731 | AG21: 3293283 | AH21: 3272915 | AI21: 3251777 | AJ21: 3230032 | AK21: 3207853 | AL21: 3185432 | AM21: 3162970 | AN21: 3140684 | AO21: 3118803 | AP21: 3097571 | AQ21: 3077245 | AR21: 3058094 | AS21: 3040403 | AT21: 3024468 | AU21: 3010602 | AV21: 2999127
A22: 沧州市 | B22: 沧州 | C22: 是 | D22: 7456414.9 | E22: 7494078.1 | F22: 7527827.4 | G22: 7266521 | H22: 7300129 | I22: 7332887 | J22: 7364507 | K22: 7394719 | L22: 7423274 | M22: 7449946 | N22: 7474526 | O22: 7496828 | P22: 7516685 | Q22: 7533952 | R22: 7548503 | S22: 7560233 | T22: 7569060 | U22: 7574918 | V22: 7577765 | W22: 7577579 | X22: 7574358 | Y22: 7568120 | Z22: 7558904 | AA22: 7546770 | AB22: 7531799 | AC22: 7514091 | AD22: 7493768 | AE22: 7470971 | AF22: 7445863 | AG22: 7418628 | AH22: 7389467 | AI22: 7358607 | AJ22: 7326291 | AK22: 7292785 | AL22: 7258374 | AM22: 7223364 | AN22: 7188084 | AO22: 7152879 | AP22: 7118118 | AQ22: 7084189 | AR22: 7051502 | AS22: 7020485 | AT22: 6991590 | AU22: 6965287 | AV22: 6942067
A23: 廊坊市 | B23: 廊坊 | C23: 是 | D23: 4593015.8 | E23: 4625006.9 | F23: 4654532.2 | G23: 5414885 | H23: 5463661 | I23: 5507146 | J23: 5545612 | K23: 5579322 | L23: 5608534 | M23: 5633497 | N23: 5654453 | O23: 5671636 | P23: 5685274 | Q23: 5695585 | R23: 5702781 | S23: 5707067 | T23: 5708639 | U23: 5707688 | V23: 5704394 | W23: 5698931 | X23: 5691468 | Y23: 5682163 | Z23: 5671168 | AA23: 5658627 | AB23: 5644677 | AC23: 5629447 | AD23: 5613060 | AE23: 5595629 | AF23: 5577261 | AG23: 5558056 | AH23: 5538104 | AI23: 5517492 | AJ23: 5496295 | AK23: 5474582 | AL23: 5452416 | AM23: 5429850 | AN23: 5406932 | AO23: 5383701 | AP23: 5360187 | AQ23: 5336417 | AR23: 5312406 | AS23: 5288163 | AT23: 5263691 | AU23: 5238983 | AV23: 5214027
... A378: 胡杨河市 | B378: 胡杨河 | C378: 是 | D378: 84392.012 | E378: 84943.323 | F378: 85454.48 | G378: 247189 | H378: 248110 | I378: 248922 | J378: 249616 | K378: 250186 | L378: 250624 | M378: 250926 | N378: 251084 | O378: 251097 | P378: 250960 | Q378: 250671 | R378: 250228 | S378: 249630 | T378: 248878 | U378: 247972 | V378: 246914 | W378: 245707 | X378: 244354 | Y378: 242859 | Z378: 241228 | AA378: 239465 | AB378: 237579 | AC378: 235577 | AD378: 233467 | AE378: 231258 | AF378: 228960 | AG378: 226586 | AH378: 224145 | AI378: 221651 | AJ378: 219118 | AK378: 216559 | AL378: 213991 | AM378: 211428 | AN378: 208888 | AO378: 206389 | AP378: 203948 | AQ378: 201586 | AR378: 199322 | AS378: 197178 | AT378: 195175 | AU378: 193336 | AV378: 191685

Sheet BAU建筑面积计算
A2: 各类建筑既存和新建面积计算结果
B3: 2018 | C3: 2019 | D3: 2020 | E3: 2021 | F3: 2022 | G3: 2023 | H3: 2024 | I3: 2025 | J3: 2026 | K3: 2027 | L3: 2028 | M3: 2029 | N3: 2030 | O3: 2031 | P3: 2032 | Q3: 2033 | R3: 2034 | S3: 2035 | T3: 2036 | U3: 2037 | V3: 2038 | W3: 2039 | X3: 2040 | Y3: 2041 | Z3: 2042 | AA3: 2043 | AB3: 2044 | AC3: 2045 | AD3: 2046 | AE3: 2047 | AF3: 2048 | AG3: 2049 | AH3: 2050 | AI3: 2051 | AJ3: 2052 | AK3: 2053 | AL3: 2054 | AM3: 2055 | AN3: 2056 | AO3: 2057 | AP3: 2058 | AQ3: 2059 | AR3: 2060
A4: 城市住宅建面 万㎡ | B4: =D44*人口变化预测!D4/10000 -> 2968187.3 | C4: =E44*人口变化预测!E4/10000 -> 3046751.3 | D4: =F44*人口变化预测!F4/10000 -> 3149052.1 | E4: =G44*人口变化预测!G4/10000 -> 3203579.1 | F4: =H44*人口变化预测!H4/10000 -> 3256894.9 | G4: =I44*人口变化预测!I4/10000 -> 3308972.6 | H4: =J44*人口变化预测!J4/10000 -> 3359787.9 | I4: =K44*人口变化预测!K4/10000 -> 3409319.2 | ... AR4: =AT44*人口变化预测!AT4/10000 -> 4482265.6
A5: 其中：拆除 | B5: =$B4*0.71% -> 21074.13 | C5: =$B4*0.71% -> 21074.13 | D5: =$B4*0.71% -> 21074.13 | E5: =$B4*0.71% -> 21074.13 | F5: =$B4*0.71% -> 21074.13 | G5: =$B4*0.71% -> 21074.13 | H5: =$B4*0.71% -> 21074.13 | I5: =$B4*0.71% -> 21074.13 | ... AR5: =$B4*0.71% -> 21074.13
A6: 拆除量修正值 | C6: =IF(B4-C4-B5>0,B4-C4-B5,0) -> 0 | D6: =IF(C4-D4-C5>0,C4-D4-C5,0) -> 0 | E6: =IF(D4-E4-D5>0,D4-E4-D5,0) -> 0 | F6: =IF(E4-F4-E5>0,E4-F4-E5,0) -> 0 | G6: =IF(F4-G4-F5>0,F4-G4-F5,0) -> 0 | H6: =IF(G4-H4-G5>0,G4-H4-G5,0) -> 0 | I6: =IF(H4-I4-H5>0,H4-I4-H5,0) -> 0 | J6: =IF(I4-J4-I5>0,I4-J4-I5,0) -> 0 | ... AR6: =IF(AQ4-AR4-AQ5>0,AQ4-AR4-AQ5,0) -> 0
A7: 当年新建 | C7: =IF(C4-B4+B5>0,C4-B4+B5,0) -> 99638.165 | D7: =IF(D4-C4+C5>0,D4-C4+C5,0) -> 123374.96 | E7: =IF(E4-D4+D5>0,E4-D4+D5,0) -> 75601.059 | F7: =IF(F4-E4+E5>0,F4-E4+E5,0) -> 74389.952 | G7: =IF(G4-F4+F5>0,G4-F4+F5,0) -> 73151.876 | H7: =IF(H4-G4+G5>0,H4-G4+G5,0) -> 71889.383 | I7: =IF(I4-H4+H5>0,I4-H4+H5,0) -> 70605.414 | J7: =IF(J4-I4+I5>0,J4-I4+I5,0) -> 69302.725 | ... AR7: =IF(AR4-AQ4+AQ5>0,AR4-AQ4+AQ5,0) -> 48382.392
A8: 新建面积累计 | B8: 0 | C8: =SUM($C7:C7) -> 99638.165 | D8: =SUM($C7:D7) -> 223013.12 | E8: =SUM($C7:E7) -> 298614.18 | F8: =SUM($C7:F7) -> 373004.13 | G8: =SUM($C7:G7) -> 446156.01 | H8: =SUM($C7:H7) -> 518045.39 | I8: =SUM($C7:I7) -> 588650.81 | J8: =SUM($C7:J7) -> 657953.53 | ... AR8: =SUM($C7:AR7) -> 2399191.7
A9: 起始年份留存 | B9: =B4 -> 2968187.3 | C9: =$B4-SUM($B5:B5)-SUM($B6:B6) -> 2947113.1 | D9: =$B4-SUM($B5:C5)-SUM($B6:C6) -> 2926039 | E9: =$B4-SUM($B5:D5)-SUM($B6:D6) -> 2904964.9 | F9: =$B4-SUM($B5:E5)-SUM($B6:E6) -> 2883890.8 | G9: =$B4-SUM($B5:F5)-SUM($B6:F6) -> 2862816.6 | H9: =$B4-SUM($B5:G5)-SUM($B6:G6) -> 2841742.5 | I9: =$B4-SUM($B5:H5)-SUM($B6:H6) -> 2820668.4 | J9: =$B4-SUM($B5:I5)-SUM($B6:I6) -> 2799594.2 | ... AR9: =$B4-SUM($B5:AQ5)-SUM($B6:AQ6) -> 2083073.8
B11: 2018 | C11: 2019 | D11: 2020 | E11: 2021 | F11: 2022 | G11: 2023 | H11: 2024 | I11: 2025 | J11: 2026 | K11: 2027 | L11: 2028 | M11: 2029 | N11: 2030 | O11: 2031 | P11: 2032 | Q11: 2033 | R11: 2034 | S11: 2035 | T11: 2036 | U11: 2037 | V11: 2038 | W11: 2039 | X11: 2040 | Y11: 2041 | Z11: 2042 | AA11: 2043 | AB11: 2044 | AC11: 2045 | AD11: 2046 | AE11: 2047 | AF11: 2048 | AG11: 2049 | AH11: 2050 | AI11: 2051 | AJ11: 2052 | AK11: 2053 | AL11: 2054 | AM11: 2055 | AN11: 2056 | AO11: 2057 | AP11: 2058 | AQ11: 2059 | AR11: 2060
A12: 农村住宅建面 万㎡ | B12: =D45*人口变化预测!D5/10000 -> 2082627.4 | C12: =E45*人口变化预测!E5/10000 -> 2024080.5 | D12: =F45*人口变化预测!F5/10000 -> 1976972.9 | E12: =G45*人口变化预测!G5/10000 -> 1979995.4 | F12: =H45*人口变化预测!H5/10000 -> 1981396.5 | G12: =I45*人口变化预测!I5/10000 -> 1981202.9 | H12: =J45*人口变化预测!J5/10000 -> 1979443.5 | I12: =K45*人口变化预测!K5/10000 -> 1976149.4 | ... AR12: =AT45*人口变化预测!AT5/10000 -> 1245237.3
A13: 其中：拆除 | B13: =$B12*0.71% -> 14786.654 | C13: =$B12*0.71% -> 14786.654 | D13: =$B12*0.71% -> 14786.654 | E13: =$B12*0.71% -> 14786.654 | F13: =$B12*0.71% -> 14786.654 | G13: =$B12*0.71% -> 14786.654 | H13: =$B12*0.71% -> 14786.654 | I13: =$B12*0.71% -> 14786.654 | ... AR13: =$B12*0.71% -> 14786.654
A14: 拆除量修正值 | C14: =IF(B12-C12-B13>0,B12-C12-B13,0) -> 43760.199 | D14: =IF(C12-D12-C13>0,C12-D12-C13,0) -> 32320.909 | E14: =IF(D12-E12-D13>0,D12-E12-D13,0) -> 0 | F14: =IF(E12-F12-E13>0,E12-F12-E13,0) -> 0 | G14: =IF(F12-G12-F13>0,F12-G12-F13,0) -> 0 | H14: =IF(G12-H12-G13>0,G12-H12-G13,0) -> 0 | I14: =IF(H12-I12-H13>0,H12-I12-H13,0) -> 0 | J14: =IF(I12-J12-I13>0,I12-J12-I13,0) -> 0 | ... AR14: =IF(AQ12-AR12-AQ13>0,AQ12-AR12-AQ13,0) -> 12488.188
A15: 当年新建 | C15: =IF(C12-B12+B13>0,C12-B12+B13,0) -> 0 | D15: =IF(D12-C12+C13>0,D12-C12+C13,0) -> 0 | E15: =IF(E12-D12+D13>0,E12-D12+D13,0) -> 17809.115 | F15: =IF(F12-E12+E13>0,F12-E12+E13,0) -> 16187.712 | G15: =IF(G12-F12+F13>0,G12-F12+F13,0) -> 14593.078 | H15: =IF(H12-G12+G13>0,H12-G12+G13,0) -> 13027.295 | I15: =IF(I12-H12+H13>0,I12-H12+H13,0) -> 11492.541 | J15: =IF(J12-I12+I13>0,J12-I12+I13,0) -> 9990.7403 | ... AR15: =IF(AR12-AQ12+AQ13>0,AR12-AQ12+AQ13,0) -> 0
A16: 新建面积累计 | B16: 0 | C16: =SUM($C15:C15) -> 0 | D16: =SUM($C15:D15) -> 0 | E16: =SUM($C15:E15) -> 17809.115 | F16: =SUM($C15:F15) -> 33996.827 | G16: =SUM($C15:G15) -> 48589.905 | H16: =SUM($C15:H15) -> 61617.2 | I16: =SUM($C15:I15) -> 73109.741 | J16: =SUM($C15:J15) -> 83100.481 | ... AR16: =SUM($C15:AR15) -> 114160.18
A17: 起始年份留存 | B17: =B12 -> 2082627.4 | C17: =$B12-SUM($B13:B13)-SUM($B14:B14) -> 2067840.7 | D17: =$B12-SUM($B13:C13)-SUM($B14:C14) -> 2009293.9 | E17: =$B12-SUM($B13:D13)-SUM($B14:D14) -> 1962186.3 | F17: =$B12-SUM($B13:E13)-SUM($B14:E14) -> 1947399.6 | G17: =$B12-SUM($B13:F13)-SUM($B14:F14) -> 1932613 | H17: =$B12-SUM($B13:G13)-SUM($B14:G14) -> 1917826.3 | I17: =$B12-SUM($B13:H13)-SUM($B14:H14) -> 1903039.7 | J17: =$B12-SUM($B13:I13)-SUM($B14:I14) -> 1888253 | ... AR17: =$B12-SUM($B13:AQ13)-SUM($B14:AQ14) -> 1143565.3
B19: 2018 | C19: 2019 | D19: 2020 | E19: 2021 | F19: 2022 | G19: 2023 | H19: 2024 | I19: 2025 | J19: 2026 | K19: 2027 | L19: 2028 | M19: 2029 | N19: 2030 | O19: 2031 | P19: 2032 | Q19: 2033 | R19: 2034 | S19: 2035 | T19: 2036 | U19: 2037 | V19: 2038 | W19: 2039 | X19: 2040 | Y19: 2041 | Z19: 2042 | AA19: 2043 | AB19: 2044 | AC19: 2045 | AD19: 2046 | AE19: 2047 | AF19: 2048 | AG19: 2049 | AH19: 2050 | AI19: 2051 | AJ19: 2052 | AK19: 2053 | AL19: 2054 | AM19: 2055 | AN19: 2056 | AO19: 2057 | AP19: 2058 | AQ19: 2059 | AR19: 2060
A20: 公共建筑建面 万㎡ | B20: =D46*人口变化预测!D4/10000 -> 1223992.8 | C20: =E46*人口变化预测!E4/10000 -> 1256390.3 | D20: =F46*人口变化预测!F4/10000 -> 1298576.2 | E20: =G46*人口变化预测!G4/10000 -> 1321061.5 | F20: =H46*人口变化预测!H4/10000 -> 1343047.3 | G20: =I46*人口变化预测!I4/10000 -> 1364522.7 | H20: =J46*人口变化预测!J4/10000 -> 1385477.4 | I20: =K46*人口变化预测!K4/10000 -> 1405902.6 | ... AR20: =AT46*人口变化预测!AT4/10000 -> 1848354
A21: 其中：拆除 | B21: =$B20*0.71% -> 8690.3492 | C21: =$B20*0.71% -> 8690.3492 | D21: =$B20*0.71% -> 8690.3492 | E21: =$B20*0.71% -> 8690.3492 | F21: =$B20*0.71% -> 8690.3492 | G21: =$B20*0.71% -> 8690.3492 | H21: =$B20*0.71% -> 8690.3492 | I21: =$B20*0.71% -> 8690.3492 | ... AR21: =$B20*0.71% -> 8690.3492
A22: 拆除量修正值 | C22: =IF(B20-C20-B21>0,B20-C20-B21,0) -> 0 | D22: =IF(C20-D20-C21>0,C20-D20-C21,0) -> 0 | E22: =IF(D20-E20-D21>0,D20-E20-D21,0) -> 0 | F22: =IF(E20-F20-E21>0,E20-F20-E21,0) -> 0 | G22: =IF(F20-G20-F21>0,F20-G20-F21,0) -> 0 | H22: =IF(G20-H20-G21>0,G20-H20-G21,0) -> 0 | I22: =IF(H20-I20-H21>0,H20-I20-H21,0) -> 0 | J22: =IF(I20-J20-I21>0,I20-J20-I21,0) -> 0 | ... AR22: =IF(AQ20-AR20-AQ21>0,AQ20-AR20-AQ21,0) -> 0
A23: 当年新建 | C23: =IF(C20-B20+B21>0,C20-B20+B21,0) -> 41087.839 | D23: =IF(D20-C20+C21>0,D20-C20+C21,0) -> 50876.192 | E23: =IF(E20-D20+D21>0,E20-D20+D21,0) -> 31175.646 | F23: =IF(F20-E20+E21>0,F20-E20+E21,0) -> 30676.221 | G23: =IF(G20-F20+F21>0,G20-F20+F21,0) -> 30165.675 | H23: =IF(H20-G20+G21>0,H20-G20+G21,0) -> 29645.06 | I23: =IF(I20-H20+H21>0,I20-H20+H21,0) -> 29115.589 | J23: =IF(J20-I20+I21>0,J20-I20+I21,0) -> 28578.399 | ... AR23: =IF(AR20-AQ20+AQ21>0,AR20-AQ20+AQ21,0) -> 19951.471
A24: 新建面积累计 | B24: 0 | C24: =SUM($C23:C23) -> 41087.839 | D24: =SUM($C23:D23) -> 91964.031 | E24: =SUM($C23:E23) -> 123139.68 | F24: =SUM($C23:F23) -> 153815.9 | G24: =SUM($C23:G23) -> 183981.57 | H24: =SUM($C23:H23) -> 213626.63 | I24: =SUM($C23:I23) -> 242742.22 | J24: =SUM($C23:J23) -> 271320.62 | ... AR24: =SUM($C23:AR23) -> 989355.87
A25: 起始年份留存 | B25: =B20 -> 1223992.8 | C25: =$B20-SUM($B21:B21)-SUM($B22:B22) -> 1215302.5 | D25: =$B20-SUM($B21:C21)-SUM($B22:C22) -> 1206612.1 | E25: =$B20-SUM($B21:D21)-SUM($B22:D22) -> 1197921.8 | F25: =$B20-SUM($B21:E21)-SUM($B22:E22) -> 1189231.4 | G25: =$B20-SUM($B21:F21)-SUM($B22:F22) -> 1180541.1 | H25: =$B20-SUM($B21:G21)-SUM($B22:G22) -> 1171850.7 | I25: =$B20-SUM($B21:H21)-SUM($B22:H22) -> 1163160.4 | J25: =$B20-SUM($B21:I21)-SUM($B22:I22) -> 1154470 | ... AR25: =$B20-SUM($B21:AQ21)-SUM($B22:AQ22) -> 858998.17
B27: 2018 | C27: 2019 | D27: 2020 | E27: 2021 | F27: 2022 | G27: 2023 | H27: 2024 | I27: 2025 | J27: 2026 | K27: 2027 | L27: 2028 | M27: 2029 | N27: 2030 | O27: 2031 | P27: 2032 | Q27: 2033 | R27: 2034 | S27: 2035 | T27: 2036 | U27: 2037 | V27: 2038 | W27: 2039 | X27: 2040 | Y27: 2041 | Z27: 2042 | AA27: 2043 | AB27: 2044 | AC27: 2045 | AD27: 2046 | AE27: 2047 | AF27: 2048 | AG27: 2049 | AH27: 2050 | AI27: 2051 | AJ27: 2052 | AK27: 2053 | AL27: 2054 | AM27: 2055 | AN27: 2056 | AO27: 2057 | AP27: 2058 | AQ27: 2059 | AR27: 2060
A28: 住宅采暖建面 万㎡ | B28: =D44*人口变化预测!D7/10000 -> 1256823 | C28: =E44*人口变化预测!E7/10000 -> 1246529.8 | D28: =F44*人口变化预测!F7/10000 -> 1288214.2 | E28: =G44*人口变化预测!G7/10000 -> 1310261.5 | F28: =H44*人口变化预测!H7/10000 -> 1331729.8 | G28: =I44*人口变化预测!I7/10000 -> 1352615.6 | H28: =J44*人口变化预测!J7/10000 -> 1372916.2 | I28: =K44*人口变化预测!K7/10000 -> 1392630 | ... AR28: =AT44*人口变化预测!AT7/10000 -> 1807176.8
A29: 其中：拆除 | B29: =$B28*0.71% -> 8923.443 | C29: =$B28*0.71% -> 8923.443 | D29: =$B28*0.71% -> 8923.443 | E29: =$B28*0.71% -> 8923.443 | F29: =$B28*0.71% -> 8923.443 | G29: =$B28*0.71% -> 8923.443 | H29: =$B28*0.71% -> 8923.443 | I29: =$B28*0.71% -> 8923.443 | ... AR29: =$B28*0.71% -> 8923.443
A30: 改造 | C30: =IF(B28-C28-B29>0,B28-C28-B29,0) -> 1369.7151 | D30: =IF(C28-D28-C29>0,C28-D28-C29,0) -> 0 | E30: =IF(D28-E28-D29>0,D28-E28-D29,0) -> 0 | F30: =IF(E28-F28-E29>0,E28-F28-E29,0) -> 0 | G30: =IF(F28-G28-F29>0,F28-G28-F29,0) -> 0 | H30: =IF(G28-H28-G29>0,G28-H28-G29,0) -> 0 | I30: =IF(H28-I28-H29>0,H28-I28-H29,0) -> 0 | J30: =IF(I28-J28-I29>0,I28-J28-I29,0) -> 0 | ... AR30: =IF(AQ28-AR28-AQ29>0,AQ28-AR28-AQ29,0) -> 0
A31: 当年新建 | C31: =IF(C28-B28+B29>0,C28-B28+B29,0) -> 0 | D31: =IF(D28-C28+C29>0,D28-C28+C29,0) -> 50607.864 | E31: =IF(E28-D28+D29>0,E28-D28+D29,0) -> 30970.762 | F31: =IF(F28-E28+E29>0,F28-E28+E29,0) -> 30391.749 | G31: =IF(G28-F28+F29>0,G28-F28+F29,0) -> 29809.197 | H31: =IF(H28-G28+G29>0,H28-G28+G29,0) -> 29223.995 | I31: =IF(I28-H28+H29>0,I28-H28+H29,0) -> 28637.27 | J31: =IF(J28-I28+I29>0,J28-I28+I29,0) -> 28049.969 | ... AR31: =IF(AR28-AQ28+AQ29>0,AR28-AQ28+AQ29,0) -> 19219.651
A32: 新建面积累计 | B32: 0 | C32: =SUM($C31:C31) -> 0 | D32: =SUM($C31:D31) -> 50607.864 | E32: =SUM($C31:E31) -> 81578.627 | F32: =SUM($C31:F31) -> 111970.38 | G32: =SUM($C31:G31) -> 141779.57 | H32: =SUM($C31:H31) -> 171003.57 | I32: =SUM($C31:I31) -> 199640.84 | J32: =SUM($C31:J31) -> 227690.81 | ... AR32: =SUM($C31:AR31) -> 926508.16
A33: 起始年份留存 | B33: =B28 -> 1256823 | C33: =$B28-SUM($B29:B29)-SUM($B30:B30) -> 1247899.5 | D33: =$B28-SUM($B29:C29)-SUM($B30:C30) -> 1237606.4 | E33: =$B28-SUM($B29:D29)-SUM($B30:D30) -> 1228682.9 | F33: =$B28-SUM($B29:E29)-SUM($B30:E30) -> 1219759.5 | G33: =$B28-SUM($B29:F29)-SUM($B30:F30) -> 1210836 | H33: =$B28-SUM($B29:G29)-SUM($B30:G30) -> 1201912.6 | I33: =$B28-SUM($B29:H29)-SUM($B30:H30) -> 1192989.1 | J33: =$B28-SUM($B29:I29)-SUM($B30:I30) -> 1184065.7 | ... AR33: =$B28-SUM($B29:AQ29)-SUM($B30:AQ30) -> 880668.64
B35: 2018 | C35: 2019 | D35: 2020 | E35: 2021 | F35: 2022 | G35: 2023 | H35: 2024 | I35: 2025 | J35: 2026 | K35: 2027 | L35: 2028 | M35: 2029 | N35: 2030 | O35: 2031 | P35: 2032 | Q35: 2033 | R35: 2034 | S35: 2035 | T35: 2036 | U35: 2037 | V35: 2038 | W35: 2039 | X35: 2040 | Y35: 2041 | Z35: 2042 | AA35: 2043 | AB35: 2044 | AC35: 2045 | AD35: 2046 | AE35: 2047 | AF35: 2048 | AG35: 2049 | AH35: 2050 | AI35: 2051 | AJ35: 2052 | AK35: 2053 | AL35: 2054 | AM35: 2055 | AN35: 2056 | AO35: 2057 | AP35: 2058 | AQ35: 2059 | AR35: 2060
A36: 公建采暖建面 万㎡ | B36: =D46*人口变化预测!D7/10000 -> 518276.7 | C36: =E46*人口变化预测!E7/10000 -> 514032.1 | D36: =F46*人口变化预测!F7/10000 -> 531221.53 | E36: =G46*人口变化预测!G7/10000 -> 540313.19 | F36: =H46*人口变化预测!H7/10000 -> 549166.09 | G36: =I46*人口变化预测!I7/10000 -> 557778.76 | H36: =J46*人口变化预测!J7/10000 -> 566150.11 | I36: =K46*人口变化预测!K7/10000 -> 574279.51 | ... AR36: =AT46*人口变化预测!AT7/10000 -> 745226.38
A37: 其中：拆除 | B37: =$B36*0.71% -> 3679.7646 | C37: =$B36*0.71% -> 3679.7646 | D37: =$B36*0.71% -> 3679.7646 | E37: =$B36*0.71% -> 3679.7646 | F37: =$B36*0.71% -> 3679.7646 | G37: =$B36*0.71% -> 3679.7646 | H37: =$B36*0.71% -> 3679.7646 | I37: =$B36*0.71% -> 3679.7646 | ... AR37: =$B36*0.71% -> 3679.7646
A38: 改造 | C38: =IF(B36-C36-B37>0,B36-C36-B37,0) -> 564.83007 | D38: =IF(C36-D36-C37>0,C36-D36-C37,0) -> 0 | E38: =IF(D36-E36-D37>0,D36-E36-D37,0) -> 0 | F38: =IF(E36-F36-E37>0,E36-F36-E37,0) -> 0 | G38: =IF(F36-G36-F37>0,F36-G36-F37,0) -> 0 | H38: =IF(G36-H36-G37>0,G36-H36-G37,0) -> 0 | I38: =IF(H36-I36-H37>0,H36-I36-H37,0) -> 0 | J38: =IF(I36-J36-I37>0,I36-J36-I37,0) -> 0 | ... AR38: =IF(AQ36-AR36-AQ37>0,AQ36-AR36-AQ37,0) -> 0
A39: 当年新建 | C39: =IF(C36-B36+B37>0,C36-B36+B37,0) -> 0 | D39: =IF(D36-C36+C37>0,D36-C36+C37,0) -> 20869.19 | E39: =IF(E36-D36+D37>0,E36-D36+D37,0) -> 12771.428 | F39: =IF(F36-E36+E37>0,F36-E36+E37,0) -> 12532.66 | G39: =IF(G36-F36+F37>0,G36-F36+F37,0) -> 12292.433 | H39: =IF(H36-G36+G37>0,H36-G36+G37,0) -> 12051.113 | I39: =IF(I36-H36+H37>0,I36-H36+H37,0) -> 11809.165 | J39: =IF(J36-I36+I37>0,J36-I36+I37,0) -> 11566.979 | ... AR39: =IF(AR36-AQ36+AQ37>0,AR36-AQ36+AQ37,0) -> 7925.6171
A40: 新建面积累计 | B40: 0 | C40: =SUM($C39:C39) -> 0 | D40: =SUM($C39:D39) -> 20869.19 | E40: =SUM($C39:E39) -> 33640.618 | F40: =SUM($C39:F39) -> 46173.279 | G40: =SUM($C39:G39) -> 58465.712 | H40: =SUM($C39:H39) -> 70516.825 | I40: =SUM($C39:I39) -> 82325.99 | J40: =SUM($C39:J39) -> 93892.97 | ... AR40: =SUM($C39:AR39) -> 382064.63
A41: 起始年份留存 | B41: =B36 -> 518276.7 | C41: =$B36-SUM($B37:B37)-SUM($B38:B38) -> 514596.93 | D41: =$B36-SUM($B37:C37)-SUM($B38:C38) -> 510352.34 | E41: =$B36-SUM($B37:D37)-SUM($B38:D38) -> 506672.57 | F41: =$B36-SUM($B37:E37)-SUM($B38:E38) -> 502992.81 | G41: =$B36-SUM($B37:F37)-SUM($B38:F38) -> 499313.05 | H41: =$B36-SUM($B37:G37)-SUM($B38:G38) -> 495633.28 | I41: =$B36-SUM($B37:H37)-SUM($B38:H38) -> 491953.52 | J41: =$B36-SUM($B37:I37)-SUM($B38:I38) -> 488273.75 | ... AR41: =$B36-SUM($B37:AQ37)-SUM($B38:AQ38) -> 363161.76
B43: 2016 | C43: 2017 | D43: 2018 | E43: 2019 | F43: 2020 | G43: 2021 | H43: 2022 | I43: 2023 | J43: 2024 | K43: 2025 | L43: 2026 | M43: 2027 | N43: 2028 | O43: 2029 | P43: 2030 | Q43: 2031 | R43: 2032 | S43: 2033 | T43: 2034 | U43: 2035 | V43: 2036 | W43: 2037 | X43: 2038 | Y43: 2039 | Z43: 2040 | AA43: 2041 | AB43: 2042 | AC43: 2043 | AD43: 2044 | AE43: 2045 | AF43: 2046 | AG43: 2047 | AH43: 2048 | AI43: 2049 | AJ43: 2050 | AK43: 2051 | AL43: 2052 | AM43: 2053 | AN43: 2054 | AO43: 2055 | AP43: 2056 | AQ43: 2057 | AR43: 2058 | AS43: 2059 | AT43: 2060
A44: 城市住宅人均建面 ㎡ | B44: =E55*10000/人口变化预测!B4 -> 34.236932 | C44: =$B44*(1+$B$49)^(C$43-$B$43) -> 34.408117 | D44: =$B44*(1+$B$49)^(D$43-$B$43) -> 34.580157 | E44: =$B44*(1+$B$49)^(E$43-$B$43) -> 34.753058 | F44: =$B44*(1+$B$49)^(F$43-$B$43) -> 34.926823 | G44: =$B44*(1+$B$49)^(G$43-$B$43) -> 35.101458 | H44: =$B44*(1+$B$49)^(H$43-$B$43) -> 35.276965 | I44: =$B44*(1+$B$49)^(I$43-$B$43) -> 35.45335 | J44: =$B44*(1+$B$49)^(J$43-$B$43) -> 35.630616 | ... AT44: =$B44*(1+$B$49)^(AT$43-$B$43) -> 42.638465
A45: 农村住宅人均建面 ㎡ | B45: =G55*10000/人口变化预测!B5 -> 38.046032 | C45: =$B45*(1+$B$49)^(C$43-$B$43) -> 38.236263 | D45: =$B45*(1+$B$49)^(D$43-$B$43) -> 38.427444 | E45: =$B45*(1+$B$49)^(E$43-$B$43) -> 38.619581 | F45: =$B45*(1+$B$49)^(F$43-$B$43) -> 38.812679 | G45: =$B45*(1+$B$49)^(G$43-$B$43) -> 39.006742 | H45: =$B45*(1+$B$49)^(H$43-$B$43) -> 39.201776 | I45: =$B45*(1+$B$49)^(I$43-$B$43) -> 39.397785 | J45: =$B45*(1+$B$49)^(J$43-$B$43) -> 39.594774 | ... AT45: =$B45*(1+$B$49)^(AT$43-$B$43) -> 47.382295
A46: 公共建筑人均建面 ㎡ | B46: =D55*10000/人口变化预测!B4 -> 14.1183 | C46: =$B46*(1+$B$49)^(C$43-$B$43) -> 14.188892 | D46: =$B46*(1+$B$49)^(D$43-$B$43) -> 14.259836 | E46: =$B46*(1+$B$49)^(E$43-$B$43) -> 14.331136 | F46: =$B46*(1+$B$49)^(F$43-$B$43) -> 14.402791 | G46: =$B46*(1+$B$49)^(G$43-$B$43) -> 14.474805 | H46: =$B46*(1+$B$49)^(H$43-$B$43) -> 14.547179 | I46: =$B46*(1+$B$49)^(I$43-$B$43) -> 14.619915 | J46: =$B46*(1+$B$49)^(J$43-$B$43) -> 14.693015 | ... AT46: =$B46*(1+$B$49)^(AT$43-$B$43) -> 17.582845
...

Sheet 改造情景建筑面积计算 
A2: 各类建筑既存和新建面积计算结果
B3: 2018 | C3: 2019 | D3: 2020 | E3: 2021 | F3: 2022 | G3: 2023 | H3: 2024 | I3: 2025 | J3: 2026 | K3: 2027 | L3: 2028 | M3: 2029 | N3: 2030 | O3: 2031 | P3: 2032 | Q3: 2033 | R3: 2034 | S3: 2035 | T3: 2036 | U3: 2037 | V3: 2038 | W3: 2039 | X3: 2040 | Y3: 2041 | Z3: 2042 | AA3: 2043 | AB3: 2044 | AC3: 2045 | AD3: 2046 | AE3: 2047 | AF3: 2048 | AG3: 2049 | AH3: 2050 | AI3: 2051 | AJ3: 2052 | AK3: 2053 | AL3: 2054 | AM3: 2055 | AN3: 2056 | AO3: 2057 | AP3: 2058 | AQ3: 2059 | AR3: 2060
A4: 城市住宅建面 万㎡ | B4: =D49*人口变化预测!D4/10000 -> 2956385.3 | C4: =E49*人口变化预测!E4/10000 -> 3028597.9 | D4: =F49*人口变化预测!F4/10000 -> 3124059.8 | E4: =G49*人口变化预测!G4/10000 -> 3171829.3 | F4: =H49*人口变化预测!H4/10000 -> 3218199.6 | G4: =I49*人口变化预测!I4/10000 -> 3263151.8 | H4: =J49*人口变化预测!J4/10000 -> 3306669.8 | I4: =K49*人口变化预测!K4/10000 -> 3348740.6 | ... AR4: =AT49*人口变化预测!AT4/10000 -> 4106122.7
A5: 其中：拆除 | B5: =$B4*0.71% -> 20990.336 | C5: =$B4*0.71% -> 20990.336 | D5: =$B4*0.71% -> 20990.336 | E5: =$B4*0.71% -> 20990.336 | F5: =$B4*0.71% -> 20990.336 | G5: =$B4*0.71% -> 20990.336 | H5: =$B4*0.71% -> 20990.336 | I5: =$B4*0.71% -> 20990.336 | ... AR5: =$B4*0.71% -> 20990.336
A6: 拆除量修正值 | C6: =IF(B4-C4-B5>0,B4-C4-B5,0) -> 0 | D6: =IF(C4-D4-C5>0,C4-D4-C5,0) -> 0 | E6: =IF(D4-E4-D5>0,D4-E4-D5,0) -> 0 | F6: =IF(E4-F4-E5>0,E4-F4-E5,0) -> 0 | G6: =IF(F4-G4-F5>0,F4-G4-F5,0) -> 0 | H6: =IF(G4-H4-G5>0,G4-H4-G5,0) -> 0 | I6: =IF(H4-I4-H5>0,H4-I4-H5,0) -> 0 | J6: =IF(I4-J4-I5>0,I4-J4-I5,0) -> 0 | ... AR6: =IF(AQ4-AR4-AQ5>0,AQ4-AR4-AQ5,0) -> 0
A7: 当年改造 | D7: =$C$4*0.01 -> 30285.979 | E7: =$C$4*0.01 -> 30285.979 | F7: =$C$4*0.01 -> 30285.979 | G7: =$C$4*0.01 -> 30285.979 | H7: =$C$4*0.01 -> 30285.979 | I7: =$C$4*0.01 -> 30285.979 | J7: =$C$4*0.01 -> 30285.979 | K7: =$C$4*0.01 -> 30285.979 | ... AR7: =$C$4*0.01 -> 30285.979
A8: 当年新建 | C8: =IF(C4-B4+B5>0,C4-B4+B5,0) -> 93202.911 | D8: =IF(D4-C4+C5>0,D4-C4+C5,0) -> 116452.2 | E8: =IF(E4-D4+D5>0,E4-D4+D5,0) -> 68759.829 | F8: =IF(F4-E4+E5>0,F4-E4+E5,0) -> 67360.612 | G8: =IF(G4-F4+F5>0,G4-F4+F5,0) -> 65942.561 | H8: =IF(H4-G4+G5>0,H4-G4+G5,0) -> 64508.368 | I8: =IF(I4-H4+H5>0,I4-H4+H5,0) -> 63061.084 | J8: =IF(J4-I4+I5>0,J4-I4+I5,0) -> 61603.548 | ... AR8: =IF(AR4-AQ4+AQ5>0,AR4-AQ4+AQ5,0) -> 37869.144
A9: 新建面积累计 | B9: 0 | C9: =SUM($C8:C8) -> 93202.911 | D9: =SUM($C8:D8) -> 209655.11 | E9: =SUM($C8:E8) -> 278414.94 | F9: =SUM($C8:F8) -> 345775.55 | G9: =SUM($C8:G8) -> 411718.11 | H9: =SUM($C8:H8) -> 476226.48 | I9: =SUM($C8:I8) -> 539287.56 | J9: =SUM($C8:J8) -> 600891.11 | ... AR9: =SUM($C8:AR8) -> 2031331.4
A10: 起始年份留存 | B10: =$B4-SUM(A5:$B5)-SUM(A6:$B6)-SUM(A7:$B7) -> 2935395 | C10: =$B4-SUM($B5:B5)-SUM($B6:B6)-SUM($B7:B7) -> 2935395 | D10: =$B4-SUM($B5:C5)-SUM($B6:C6)-SUM($B7:C7) -> 2914404.7 | E10: =$B4-SUM($B5:D5)-SUM($B6:D6)-SUM($B7:D7) -> 2863128.4 | F10: =$B4-SUM($B5:E5)-SUM($B6:E6)-SUM($B7:E7) -> 2811852 | G10: =$B4-SUM($B5:F5)-SUM($B6:F6)-SUM($B7:F7) -> 2760575.7 | H10: =$B4-SUM($B5:G5)-SUM($B6:G6)-SUM($B7:G7) -> 2709299.4 | I10: =$B4-SUM($B5:H5)-SUM($B6:H6)-SUM($B7:H7) -> 2658023.1 | J10: =$B4-SUM($B5:I5)-SUM($B6:I6)-SUM($B7:I7) -> 2606746.8 | ... AR10: =$B4-SUM($B5:AQ5)-SUM($B6:AQ6)-SUM($B7:AQ7) -> 863352.07
B12: 2018 | C12: 2019 | D12: 2020 | E12: 2021 | F12: 2022 | G12: 2023 | H12: 2024 | I12: 2025 | J12: 2026 | K12: 2027 | L12: 2028 | M12: 2029 | N12: 2030 | O12: 2031 | P12: 2032 | Q12: 2033 | R12: 2034 | S12: 2035 | T12: 2036 | U12: 2037 | V12: 2038 | W12: 2039 | X12: 2040 | Y12: 2041 | Z12: 2042 | AA12: 2043 | AB12: 2044 | AC12: 2045 | AD12: 2046 | AE12: 2047 | AF12: 2048 | AG12: 2049 | AH12: 2050 | AI12: 2051 | AJ12: 2052 | AK12: 2053 | AL12: 2054 | AM12: 2055 | AN12: 2056 | AO12: 2057 | AP12: 2058 | AQ12: 2059 | AR12: 2060
A13: 农村住宅建面 万㎡ | B13: =D50*人口变化预测!D5/10000 -> 2074346.6 | C13: =E50*人口变化预测!E5/10000 -> 2012020.5 | D13: =F50*人口变化预测!F5/10000 -> 1961282.8 | E13: =G50*人口变化预测!G5/10000 -> 1960372.2 | F13: =H50*人口变化预测!H5/10000 -> 1957855.4 | G13: =I50*人口变化预测!I5/10000 -> 1953768.3 | H13: =J50*人口变化预测!J5/10000 -> 1948148.6 | I13: =K50*人口变化预测!K5/10000 -> 1941036.1 | ... AR13: =AT50*人口变化预测!AT5/10000 -> 1140739.4
A14: 其中：拆除 | B14: =$B13*0.71% -> 14727.861 | C14: =$B13*0.71% -> 14727.861 | D14: =$B13*0.71% -> 14727.861 | E14: =$B13*0.71% -> 14727.861 | F14: =$B13*0.71% -> 14727.861 | G14: =$B13*0.71% -> 14727.861 | H14: =$B13*0.71% -> 14727.861 | I14: =$B13*0.71% -> 14727.861 | ... AR14: =$B13*0.71% -> 14727.861
A15: 拆除量修正值 | C15: =IF(B13-C13-B14>0,B13-C13-B14,0) -> 47598.207 | D15: =IF(C13-D13-C14>0,C13-D13-C14,0) -> 36009.856 | E15: =IF(D13-E13-D14>0,D13-E13-D14,0) -> 0 | F15: =IF(E13-F13-E14>0,E13-F13-E14,0) -> 0 | G15: =IF(F13-G13-F14>0,F13-G13-F14,0) -> 0 | H15: =IF(G13-H13-G14>0,G13-H13-G14,0) -> 0 | I15: =IF(H13-I13-H14>0,H13-I13-H14,0) -> 0 | J15: =IF(I13-J13-I14>0,I13-J13-I14,0) -> 0 | ... AR15: =IF(AQ13-AR13-AQ14>0,AQ13-AR13-AQ14,0) -> 12582.608
A16: 当年改造 | D16: =$C$13*0.01 -> 20120.205 | E16: =$C$13*0.01 -> 20120.205 | F16: =$C$13*0.01 -> 20120.205 | G16: =$C$13*0.01 -> 20120.205 | H16: =$C$13*0.01 -> 20120.205 | I16: =$C$13*0.01 -> 20120.205 | J16: =$C$13*0.01 -> 20120.205 | K16: =$C$13*0.01 -> 20120.205 | ... AR16: =$C$13*0.01 -> 20120.205
A17: 当年新建 | C17: =IF(C13-B13+B14>0,C13-B13+B14,0) -> 0 | D17: =IF(D13-C13+C14>0,D13-C13+C14,0) -> 0 | E17: =IF(E13-D13+D14>0,E13-D13+D14,0) -> 13817.316 | F17: =IF(F13-E13+E14>0,F13-E13+E14,0) -> 12211.034 | G17: =IF(G13-F13+F14>0,G13-F13+F14,0) -> 10640.735 | H17: =IF(H13-G13+G14>0,H13-G13+G14,0) -> 9108.2204 | I17: =IF(I13-H13+H14>0,I13-H13+H14,0) -> 7615.3659 | J17: =IF(J13-I13+I14>0,J13-I13+I14,0) -> 6163.7789 | ... AR17: =IF(AR13-AQ13+AQ14>0,AR13-AQ13+AQ14,0) -> 0
A18: 新建面积累计 | B18: 0 | C18: =SUM($C17:C17) -> 0 | D18: =SUM($C17:D17) -> 0 | E18: =SUM($C17:E17) -> 13817.316 | F18: =SUM($C17:F17) -> 26028.35 | G18: =SUM($C17:G17) -> 36669.085 | H18: =SUM($C17:H17) -> 45777.306 | I18: =SUM($C17:I17) -> 53392.672 | J18: =SUM($C17:J17) -> 59556.45 | ... AR18: =SUM($C17:AR17) -> 70578.642
A19: 起始年份留存 | B19: =$B13-SUM(A14:$B14)-SUM(A15:$B15)-SUM(A16:$B16) -> 2059618.7 | C19: =$B13-SUM($B14:B14)-SUM($B15:B15)-SUM($B16:B16) -> 2059618.7 | D19: =$B13-SUM($B14:C14)-SUM($B15:C15)-SUM($B16:C16) -> 1997292.6 | E19: =$B13-SUM($B14:D14)-SUM($B15:D15)-SUM($B16:D16) -> 1926434.7 | F19: =$B13-SUM($B14:E14)-SUM($B15:E15)-SUM($B16:E16) -> 1891586.6 | G19: =$B13-SUM($B14:F14)-SUM($B15:F15)-SUM($B16:F16) -> 1856738.6 | H19: =$B13-SUM($B14:G14)-SUM($B15:G15)-SUM($B16:G16) -> 1821890.5 | I19: =$B13-SUM($B14:H14)-SUM($B15:H15)-SUM($B16:H16) -> 1787042.4 | J19: =$B13-SUM($B14:I14)-SUM($B15:I15)-SUM($B16:I16) -> 1752194.4 | ... AR19: =$B13-SUM($B14:AQ14)-SUM($B15:AQ15)-SUM($B16:AQ16) -> 277935.22
B21: 2018 | C21: 2019 | D21: 2020 | E21: 2021 | F21: 2022 | G21: 2023 | H21: 2024 | I21: 2025 | J21: 2026 | K21: 2027 | L21: 2028 | M21: 2029 | N21: 2030 | O21: 2031 | P21: 2032 | Q21: 2033 | R21: 2034 | S21: 2035 | T21: 2036 | U21: 2037 | V21: 2038 | W21: 2039 | X21: 2040 | Y21: 2041 | Z21: 2042 | AA21: 2043 | AB21: 2044 | AC21: 2045 | AD21: 2046 | AE21: 2047 | AF21: 2048 | AG21: 2049 | AH21: 2050 | AI21: 2051 | AJ21: 2052 | AK21: 2053 | AL21: 2054 | AM21: 2055 | AN21: 2056 | AO21: 2057 | AP21: 2058 | AQ21: 2059 | AR21: 2060
A22: 公共建筑建面 万㎡ | B22: =D51*人口变化预测!D4/10000 -> 1219126.1 | C22: =E51*人口变化预测!E4/10000 -> 1248904.4 | D22: =F51*人口变化预测!F4/10000 -> 1288270.1 | E22: =G51*人口变化预测!G4/10000 -> 1307968.8 | F22: =H51*人口变化预测!H4/10000 -> 1327090.5 | G22: =I51*人口变化预测!I4/10000 -> 1345627.5 | H22: =J51*人口变化预测!J4/10000 -> 1363573 | I22: =K51*人口变化预测!K4/10000 -> 1380921.8 | ... AR22: =AT51*人口变化预测!AT4/10000 -> 1693243.8
A23: 其中：拆除 | B23: =$B22*0.71% -> 8655.7951 | C23: =$B22*0.71% -> 8655.7951 | D23: =$B22*0.71% -> 8655.7951 | E23: =$B22*0.71% -> 8655.7951 | F23: =$B22*0.71% -> 8655.7951 | G23: =$B22*0.71% -> 8655.7951 | H23: =$B22*0.71% -> 8655.7951 | I23: =$B22*0.71% -> 8655.7951 | ... AR23: =$B22*0.71% -> 8655.7951
A24: 拆除量修正值 | C24: =IF(B22-C22-B23>0,B22-C22-B23,0) -> 0 | D24: =IF(C22-D22-C23>0,C22-D22-C23,0) -> 0 | E24: =IF(D22-E22-D23>0,D22-E22-D23,0) -> 0 | F24: =IF(E22-F22-E23>0,E22-F22-E23,0) -> 0 | G24: =IF(F22-G22-F23>0,F22-G22-F23,0) -> 0 | H24: =IF(G22-H22-G23>0,G22-H22-G23,0) -> 0 | I24: =IF(H22-I22-H23>0,H22-I22-H23,0) -> 0 | J24: =IF(I22-J22-I23>0,I22-J22-I23,0) -> 0 | ... AR24: =IF(AQ22-AR22-AQ23>0,AQ22-AR22-AQ23,0) -> 0
A25: 当年改造 | D25: =$C$22*0.01 -> 12489.044 | E25: =$C$22*0.01 -> 12489.044 | F25: =$C$22*0.01 -> 12489.044 | G25: =$C$22*0.01 -> 12489.044 | H25: =$C$22*0.01 -> 12489.044 | I25: =$C$22*0.01 -> 12489.044 | J25: =$C$22*0.01 -> 12489.044 | K25: =$C$22*0.01 -> 12489.044 | ... AR25: =$C$22*0.01 -> 12489.044
A26: 当年新建 | C26: =IF(C22-B22+B23>0,C22-B22+B23,0) -> 38434.13 | D26: =IF(D22-C22+C23>0,D22-C22+C23,0) -> 48021.449 | E26: =IF(E22-D22+D23>0,E22-D22+D23,0) -> 28354.525 | F26: =IF(F22-E22+E23>0,F22-E22+E23,0) -> 27777.529 | G26: =IF(G22-F22+F23>0,G22-F22+F23,0) -> 27192.766 | H26: =IF(H22-G22+G23>0,H22-G22+G23,0) -> 26601.347 | I26: =IF(I22-H22+H23>0,I22-H22+H23,0) -> 26004.53 | J26: =IF(J22-I22+I23>0,J22-I22+I23,0) -> 25403.485 | ... AR26: =IF(AR22-AQ22+AQ23>0,AR22-AQ22+AQ23,0) -> 15616.118
A27: 新建面积累计 | B27: 0 | C27: =SUM($C26:C26) -> 38434.13 | D27: =SUM($C26:D26) -> 86455.579 | E27: =SUM($C26:E26) -> 114810.1 | F27: =SUM($C26:F26) -> 142587.63 | G27: =SUM($C26:G26) -> 169780.4 | H27: =SUM($C26:H26) -> 196381.75 | I27: =SUM($C26:I26) -> 222386.28 | J27: =SUM($C26:J26) -> 247789.76 | ... AR27: =SUM($C26:AR26) -> 837661.13
A28: 起始年份留存 | B28: =$B22-SUM(A23:$B23)-SUM(A24:$B24)-SUM(A25:$B25) -> 1210470.3 | C28: =$B22-SUM($B23:B23)-SUM($B24:B24)-SUM($B25:B25) -> 1210470.3 | D28: =$B22-SUM($B23:C23)-SUM($B24:C24)-SUM($B25:C25) -> 1201814.5 | E28: =$B22-SUM($B23:D23)-SUM($B24:D24)-SUM($B25:D25) -> 1180669.6 | F28: =$B22-SUM($B23:E23)-SUM($B24:E24)-SUM($B25:E25) -> 1159524.8 | G28: =$B22-SUM($B23:F23)-SUM($B24:F24)-SUM($B25:F25) -> 1138380 | H28: =$B22-SUM($B23:G23)-SUM($B24:G24)-SUM($B25:G25) -> 1117235.1 | I28: =$B22-SUM($B23:H23)-SUM($B24:H24)-SUM($B25:H25) -> 1096090.3 | J28: =$B22-SUM($B23:I23)-SUM($B24:I24)-SUM($B25:I25) -> 1074945.4 | ... AR28: =$B22-SUM($B23:AQ23)-SUM($B24:AQ24)-SUM($B25:AQ25) -> 356020.92
B30: 2018 | C30: 2019 | D30: 2020 | E30: 2021 | F30: 2022 | G30: 2023 | H30: 2024 | I30: 2025 | J30: 2026 | K30: 2027 | L30: 2028 | M30: 2029 | N30: 2030 | O30: 2031 | P30: 2032 | Q30: 2033 | R30: 2034 | S30: 2035 | T30: 2036 | U30: 2037 | V30: 2038 | W30: 2039 | X30: 2040 | Y30: 2041 | Z30: 2042 | AA30: 2043 | AB30: 2044 | AC30: 2045 | AD30: 2046 | AE30: 2047 | AF30: 2048 | AG30: 2049 | AH30: 2050 | AI30: 2051 | AJ30: 2052 | AK30: 2053 | AL30: 2054 | AM30: 2055 | AN30: 2056 | AO30: 2057 | AP30: 2058 | AQ30: 2059 | AR30: 2060
A31: 住宅采暖建面 万㎡ | B31: =D49*人口变化预测!D7/10000 -> 1251825.7 | C31: =E49*人口变化预测!E7/10000 -> 1239102.6 | D31: =F49*人口变化预测!F7/10000 -> 1277990.3 | E31: =G49*人口变化预测!G7/10000 -> 1297275.9 | F31: =H49*人口变化预测!H7/10000 -> 1315907.5 | G31: =I49*人口变化预测!I7/10000 -> 1333885.3 | H31: =J49*人口变化预测!J7/10000 -> 1351210.4 | I31: =K49*人口变化预测!K7/10000 -> 1367885 | ... AR31: =AT49*人口变化预测!AT7/10000 -> 1655522.1
A32: 其中：拆除 | B32: =$B31*0.71% -> 8887.9621 | C32: =$B31*0.71% -> 8887.9621 | D32: =$B31*0.71% -> 8887.9621 | E32: =$B31*0.71% -> 8887.9621 | F32: =$B31*0.71% -> 8887.9621 | G32: =$B31*0.71% -> 8887.9621 | H32: =$B31*0.71% -> 8887.9621 | I32: =$B31*0.71% -> 8887.9621 | ... AR32: =$B31*0.71% -> 8887.9621
A33: 拆除量修正值 | C33: =IF(B31-C31-B32>0,B31-C31-B32,0) -> 3835.0618 | D33: =IF(C31-D31-C32>0,C31-D31-C32,0) -> 0 | E33: =IF(D31-E31-D32>0,D31-E31-D32,0) -> 0 | F33: =IF(E31-F31-E32>0,E31-F31-E32,0) -> 0 | G33: =IF(F31-G31-F32>0,F31-G31-F32,0) -> 0 | H33: =IF(G31-H31-G32>0,G31-H31-G32,0) -> 0 | I33: =IF(H31-I31-H32>0,H31-I31-H32,0) -> 0 | J33: =IF(I31-J31-I32>0,I31-J31-I32,0) -> 0 | ... AR33: =IF(AQ31-AR31-AQ32>0,AQ31-AR31-AQ32,0) -> 0
A34: 当年改造 | D34: =$C$31*0.01 -> 12391.026 | E34: =$C$31*0.01 -> 12391.026 | F34: =$C$31*0.01 -> 12391.026 | G34: =$C$31*0.01 -> 12391.026 | H34: =$C$31*0.01 -> 12391.026 | I34: =$C$31*0.01 -> 12391.026 | J34: =$C$31*0.01 -> 12391.026 | K34: =$C$31*0.01 -> 12391.026 | ... AR34: =$C$31*0.01 -> 12391.026
A35: 当年新建 | C35: =IF(C31-B31+B32>0,C31-B31+B32,0) -> 0 | D35: =IF(D31-C31+C32>0,D31-C31+C32,0) -> 47775.681 | E35: =IF(E31-D31+D32>0,E31-D31+D32,0) -> 28173.512 | F35: =IF(F31-E31+E32>0,F31-E31+E32,0) -> 27519.558 | G35: =IF(G31-F31+F32>0,G31-F31+F32,0) -> 26865.78 | H35: =IF(H31-G31+G32>0,H31-G31+G32,0) -> 26213.066 | I35: =IF(I31-H31+H32>0,I31-H31+H32,0) -> 25562.528 | J35: =IF(J31-I31+I32>0,J31-I31+I32,0) -> 24915.092 | ... AR35: =IF(AR31-AQ31+AQ32>0,AR31-AQ31+AQ32,0) -> 15037.8
A36: 新建面积累计 | B36: 0 | C36: =SUM($C35:C35) -> 0 | D36: =SUM($C35:D35) -> 47775.681 | E36: =SUM($C35:E35) -> 75949.193 | F36: =SUM($C35:F35) -> 103468.75 | G36: =SUM($C35:G35) -> 130334.53 | H36: =SUM($C35:H35) -> 156547.6 | I36: =SUM($C35:I35) -> 182110.12 | J36: =SUM($C35:J35) -> 207025.22 | ... AR36: =SUM($C35:AR35) -> 780825.9
A37: 起始年份留存 | B37: =$B31-SUM(A32:$B32)-SUM(A33:$B33)-SUM(A34:$B34) -> 1242937.7 | C37: =$B31-SUM($B32:B32)-SUM($B33:B33)-SUM($B34:B34) -> 1242937.7 | D37: =$B31-SUM($B32:C32)-SUM($B33:C33)-SUM($B34:C34) -> 1230214.7 | E37: =$B31-SUM($B32:D32)-SUM($B33:D33)-SUM($B34:D34) -> 1208935.7 | F37: =$B31-SUM($B32:E32)-SUM($B33:E33)-SUM($B34:E34) -> 1187656.7 | G37: =$B31-SUM($B32:F32)-SUM($B33:F33)-SUM($B34:F34) -> 1166377.7 | H37: =$B31-SUM($B32:G32)-SUM($B33:G33)-SUM($B34:G34) -> 1145098.7 | I37: =$B31-SUM($B32:H32)-SUM($B33:H33)-SUM($B34:H34) -> 1123819.7 | J37: =$B31-SUM($B32:I32)-SUM($B33:I33)-SUM($B34:I34) -> 1102540.7 | ... AR37: =$B31-SUM($B32:AQ32)-SUM($B33:AQ33)-SUM($B34:AQ34) -> 379055.13
B39: 2018 | C39: 2019 | D39: 2020 | E39: 2021 | F39: 2022 | G39: 2023 | H39: 2024 | I39: 2025 | J39: 2026 | K39: 2027 | L39: 2028 | M39: 2029 | N39: 2030 | O39: 2031 | P39: 2032 | Q39: 2033 | R39: 2034 | S39: 2035 | T39: 2036 | U39: 2037 | V39: 2038 | W39: 2039 | X39: 2040 | Y39: 2041 | Z39: 2042 | AA39: 2043 | AB39: 2044 | AC39: 2045 | AD39: 2046 | AE39: 2047 | AF39: 2048 | AG39: 2049 | AH39: 2050 | AI39: 2051 | AJ39: 2052 | AK39: 2053 | AL39: 2054 | AM39: 2055 | AN39: 2056 | AO39: 2057 | AP39: 2058 | AQ39: 2059 | AR39: 2060
A40: 公建采暖建面 万㎡ | B40: =D51*人口变化预测!D7/10000 -> 516215.96 | C40: =E51*人口变化预测!E7/10000 -> 510969.36 | D40: =F51*人口变化预测!F7/10000 -> 527005.51 | E40: =G51*人口变化预测!G7/10000 -> 534958.3 | F40: =H51*人口变化预测!H7/10000 -> 542641.42 | G40: =I51*人口变化预测!I7/10000 -> 550054.94 | H40: =J51*人口变化预测!J7/10000 -> 557199.3 | I40: =K51*人口变化预测!K7/10000 -> 564075.4 | ... AR40: =AT51*人口变化预测!AT7/10000 -> 682688.45
A41: 其中：拆除 | B41: =$B40*0.71% -> 3665.1333 | C41: =$B40*0.71% -> 3665.1333 | D41: =$B40*0.71% -> 3665.1333 | E41: =$B40*0.71% -> 3665.1333 | F41: =$B40*0.71% -> 3665.1333 | G41: =$B40*0.71% -> 3665.1333 | H41: =$B40*0.71% -> 3665.1333 | I41: =$B40*0.71% -> 3665.1333 | ... AR41: =$B40*0.71% -> 3665.1333
A42: 拆除量修正值 | C42: =IF(B40-C40-B41>0,B40-C40-B41,0) -> 1581.4663 | D42: =IF(C40-D40-C41>0,C40-D40-C41,0) -> 0 | E42: =IF(D40-E40-D41>0,D40-E40-D41,0) -> 0 | F42: =IF(E40-F40-E41>0,E40-F40-E41,0) -> 0 | G42: =IF(F40-G40-F41>0,F40-G40-F41,0) -> 0 | H42: =IF(G40-H40-G41>0,G40-H40-G41,0) -> 0 | I42: =IF(H40-I40-H41>0,H40-I40-H41,0) -> 0 | J42: =IF(I40-J40-I41>0,I40-J40-I41,0) -> 0 | ... AR42: =IF(AQ40-AR40-AQ41>0,AQ40-AR40-AQ41,0) -> 0
A43: 当年改造 | D43: =$C$40*0.01 -> 5109.6936 | E43: =$C$40*0.01 -> 5109.6936 | F43: =$C$40*0.01 -> 5109.6936 | G43: =$C$40*0.01 -> 5109.6936 | H43: =$C$40*0.01 -> 5109.6936 | I43: =$C$40*0.01 -> 5109.6936 | J43: =$C$40*0.01 -> 5109.6936 | K43: =$C$40*0.01 -> 5109.6936 | ... AR43: =$C$40*0.01 -> 5109.6936
A44: 当年新建 | C44: =IF(C40-B40+B41>0,C40-B40+B41,0) -> 0 | D44: =IF(D40-C40+C41>0,D40-C40+C41,0) -> 19701.281 | E44: =IF(E40-D40+D41>0,E40-D40+D41,0) -> 11617.925 | F44: =IF(F40-E40+E41>0,F40-E40+E41,0) -> 11348.254 | G44: =IF(G40-F40+F41>0,G40-F40+F41,0) -> 11078.655 | H44: =IF(H40-G40+G41>0,H40-G40+G41,0) -> 10809.495 | I44: =IF(I40-H40+H41>0,I40-H40+H41,0) -> 10541.232 | J44: =IF(J40-I40+I41>0,J40-I40+I41,0) -> 10274.249 | ... AR44: =IF(AR40-AQ40+AQ41>0,AR40-AQ40+AQ41,0) -> 6201.145
A45: 新建面积累计 | B45: 0 | C45: =SUM($C44:C44) -> 0 | D45: =SUM($C44:D44) -> 19701.281 | E45: =SUM($C44:E44) -> 31319.206 | F45: =SUM($C44:F44) -> 42667.46 | G45: =SUM($C44:G44) -> 53746.115 | H45: =SUM($C44:H44) -> 64555.609 | I45: =SUM($C44:I44) -> 75096.841 | J45: =SUM($C44:J44) -> 85371.09 | ... AR45: =SUM($C44:AR44) -> 321989.56
...

Sheet BAU建筑总能耗计算
A1: 一.建筑能耗的计算
A2: 建筑总能耗 单位万tce | B2: 2018 | C2: 2019 | D2: 2020 | E2: 2021 | F2: 2022 | G2: 2023 | H2: 2024 | I2: 2025 | J2: 2026 | K2: 2027 | L2: 2028 | M2: 2029 | N2: 2030 | O2: 2031 | P2: 2032 | Q2: 2033 | R2: 2034 | S2: 2035 | T2: 2036 | U2: 2037 | V2: 2038 | W2: 2039 | X2: 2040 | Y2: 2041 | Z2: 2042 | AA2: 2043 | AB2: 2044 | AC2: 2045 | AD2: 2046 | AE2: 2047 | AF2: 2048 | AG2: 2049 | AH2: 2050 | AI2: 2051 | AJ2: 2052 | AK2: 2053 | AL2: 2054 | AM2: 2055 | AN2: 2056 | AO2: 2057 | AP2: 2058 | AQ2: 2059 | AR2: 2060
A3: 公共建筑 | B3: =B10+B17 -> 21428.796 | C3: =C10+C17 -> 21709.655 | D3: =D10+D17 -> 22093.67 | E3: =E10+E17 -> 22270.07 | F3: =F10+F17 -> 22441.207 | G3: =G10+G17 -> 22606.963 | H3: =H10+H17 -> 22767.233 | I3: =I10+I17 -> 22921.923 | ... AR3: =AR10+AR17 -> 25465.056
A4: 城市住宅 | B4: =B11+B18 -> 15291.291 | C4: =C11+C18 -> 15607.132 | D4: =D11+D18 -> 16024.08 | E4: =E11+E18 -> 16237.534 | F4: =F11+F18 -> 16445.83 | G4: =G11+G18 -> 16648.852 | H4: =H11+H18 -> 16846.497 | I4: =I11+I18 -> 17038.672 | ... AR4: =AR11+AR18 -> 20950.785
A5: 农村住宅 | B5: =B12+B19 -> 11819.943 | C5: =C12+C19 -> 11736.021 | D5: =D12+D19 -> 11403.739 | E5: =E12+E19 -> 11191.606 | F5: =F12+F19 -> 11157.882 | G5: =G12+G19 -> 11119.214 | H5: =H12+H19 -> 11075.69 | I5: =I12+I19 -> 11027.407 | ... AR5: =AR12+AR19 -> 6844.3108
A6: 住宅采暖 | B6: =B13+B20 -> 9051.9024 | C6: =C13+C20 -> 8987.6339 | D6: =D13+D20 -> 9207.5321 | E6: =E13+E20 -> 9323.2037 | F6: =F13+F20 -> 9435.5113 | G6: =G13+G20 -> 9544.4342 | H6: =H13+H20 -> 9649.9571 | I6: =I13+I20 -> 9752.0711 | ... AR6: =AR13+AR20 -> 11725.773
A7: 公建采暖 | B7: =B14+B21 -> 4065.1262 | C7: =C14+C21 -> 4274.9842 | D7: =D14+D21 -> 4537.2822 | E7: =E14+E21 -> 4689.5503 | F7: =F14+F21 -> 4838.9167 | G7: =G14+G21 -> 4985.3169 | H7: =H14+H21 -> 5128.6923 | I7: =I14+I21 -> 5268.9915 | ... AR7: =AR14+AR21 -> 8596.6329
A9: 既存建筑能耗 单位万tce | B9: 2018 | C9: 2019 | D9: 2020 | E9: 2021 | F9: 2022 | G9: 2023 | H9: 2024 | I9: 2025 | J9: 2026 | K9: 2027 | L9: 2028 | M9: 2029 | N9: 2030 | O9: 2031 | P9: 2032 | Q9: 2033 | R9: 2034 | S9: 2035 | T9: 2036 | U9: 2037 | V9: 2038 | W9: 2039 | X9: 2040 | Y9: 2041 | Z9: 2042 | AA9: 2043 | AB9: 2044 | AC9: 2045 | AD9: 2046 | AE9: 2047 | AF9: 2048 | AG9: 2049 | AH9: 2050 | AI9: 2051 | AJ9: 2052 | AK9: 2053 | AL9: 2054 | AM9: 2055 | AN9: 2056 | AO9: 2057 | AP9: 2058 | AQ9: 2059 | AR9: 2060
A10: 公共建筑 | B10: =BAU建筑面积计算!B25*$D$26/1000 -> 21428.796 | C10: =BAU建筑面积计算!C25*$D$26/1000 -> 21276.651 | D10: =BAU建筑面积计算!D25*$D$26/1000 -> 21124.507 | E10: =BAU建筑面积计算!E25*$D$26/1000 -> 20972.362 | F10: =BAU建筑面积计算!F25*$D$26/1000 -> 20820.218 | G10: =BAU建筑面积计算!G25*$D$26/1000 -> 20668.073 | H10: =BAU建筑面积计算!H25*$D$26/1000 -> 20515.929 | I10: =BAU建筑面积计算!I25*$D$26/1000 -> 20363.785 | ... AR10: =BAU建筑面积计算!AR25*$D$26/1000 -> 15038.729
A11: 城市住宅 | B11: =BAU建筑面积计算!B9*$D$27/1000 -> 15291.291 | C11: =BAU建筑面积计算!C9*$D$27/1000 -> 15182.723 | D11: =BAU建筑面积计算!D9*$D$27/1000 -> 15074.155 | E11: =BAU建筑面积计算!E9*$D$27/1000 -> 14965.587 | F11: =BAU建筑面积计算!F9*$D$27/1000 -> 14857.019 | G11: =BAU建筑面积计算!G9*$D$27/1000 -> 14748.451 | H11: =BAU建筑面积计算!H9*$D$27/1000 -> 14639.882 | I11: =BAU建筑面积计算!I9*$D$27/1000 -> 14531.314 | ... AR11: =BAU建筑面积计算!AR9*$D$27/1000 -> 10731.428
A12: 农村住宅 | B12: =BAU建筑面积计算!B17*$D$28/1000 -> 11819.943 | C12: =BAU建筑面积计算!C17*$D$28/1000 -> 11736.021 | D12: =BAU建筑面积计算!D17*$D$28/1000 -> 11403.739 | E12: =BAU建筑面积计算!E17*$D$28/1000 -> 11136.38 | F12: =BAU建筑面积计算!F17*$D$28/1000 -> 11052.458 | G12: =BAU建筑面积计算!G17*$D$28/1000 -> 10968.537 | H12: =BAU建筑面积计算!H17*$D$28/1000 -> 10884.615 | I12: =BAU建筑面积计算!I17*$D$28/1000 -> 10800.694 | ... AR12: =BAU建筑面积计算!AR17*$D$28/1000 -> 6490.3
A13: 住宅采暖 | B13: =BAU建筑面积计算!B33*$D$29/1000 -> 9051.9024 | C13: =BAU建筑面积计算!C33*$D$29/1000 -> 8987.6339 | D13: =BAU建筑面积计算!D33*$D$29/1000 -> 8913.5004 | E13: =BAU建筑面积计算!E33*$D$29/1000 -> 8849.2319 | F13: =BAU建筑面积计算!F33*$D$29/1000 -> 8784.9634 | G13: =BAU建筑面积计算!G33*$D$29/1000 -> 8720.6949 | H13: =BAU建筑面积计算!H33*$D$29/1000 -> 8656.4264 | I13: =BAU建筑面积计算!I33*$D$29/1000 -> 8592.1579 | ... AR13: =BAU建筑面积计算!AR33*$D$29/1000 -> 6342.7601
A14: 公建采暖 | B14: =BAU建筑面积计算!B41*$D$30/1000 -> 4065.1262 | C14: =BAU建筑面积计算!C41*$D$30/1000 -> 4036.2638 | D14: =BAU建筑面积计算!D41*$D$30/1000 -> 4002.9712 | E14: =BAU建筑面积计算!E41*$D$30/1000 -> 3974.1088 | F14: =BAU建筑面积计算!F41*$D$30/1000 -> 3945.2464 | G14: =BAU建筑面积计算!G41*$D$30/1000 -> 3916.384 | H14: =BAU建筑面积计算!H41*$D$30/1000 -> 3887.5216 | I14: =BAU建筑面积计算!I41*$D$30/1000 -> 3858.6592 | ... AR14: =BAU建筑面积计算!AR41*$D$30/1000 -> 2848.4753
A16: 新建建筑能耗 单位万tce | B16: 2018 | C16: 2019 | D16: 2020 | E16: 2021 | F16: 2022 | G16: 2023 | H16: 2024 | I16: 2025 | J16: 2026 | K16: 2027 | L16: 2028 | M16: 2029 | N16: 2030 | O16: 2031 | P16: 2032 | Q16: 2033 | R16: 2034 | S16: 2035 | T16: 2036 | U16: 2037 | V16: 2038 | W16: 2039 | X16: 2040 | Y16: 2041 | Z16: 2042 | AA16: 2043 | AB16: 2044 | AC16: 2045 | AD16: 2046 | AE16: 2047 | AF16: 2048 | AG16: 2049 | AH16: 2050 | AI16: 2051 | AJ16: 2052 | AK16: 2053 | AL16: 2054 | AM16: 2055 | AN16: 2056 | AO16: 2057 | AP16: 2058 | AQ16: 2059 | AR16: 2060
A17: 公共建筑 | B17: =BAU建筑面积计算!B24*B42/1000 -> 0 | C17: =BAU建筑面积计算!C24*C42/1000 -> 433.00419 | D17: =BAU建筑面积计算!D24*D42/1000 -> 969.16294 | E17: =BAU建筑面积计算!E24*E42/1000 -> 1297.7075 | F17: =BAU建筑面积计算!F24*F42/1000 -> 1620.9888 | G17: =BAU建筑面积计算!G24*G42/1000 -> 1938.8898 | H17: =BAU建筑面积计算!H24*H42/1000 -> 2251.3043 | I17: =BAU建筑面积计算!I24*I42/1000 -> 2558.1389 | ... AR17: =BAU建筑面积计算!AR24*AR42/1000 -> 10426.327
