Workbook

Sheet About
A1: BAU Heat Rate by Electricity Fuel
A3: Source: | B3: All Fuel Sources Except Nuclear
B4: Energy Information Administration
B5: 2020
B6: Form 923 (with data for 2019)
B7: https://www.eia.gov/electricity/data/eia923/
B8: Page 1 Generation and Fuel Data
B10: Preexisting Nuclear
B11: Energy Information Administration
B12: 2020
B13: Electric Power Annual 2020 (with data for 2019)
B14: http://www.eia.gov/electricity/annual/
B15: Tables 8.1
B17: Some Newly Built Sources
B18: Lazard
B19: 2015
B20: Lazard's Levelized Cost of Energy Analysis - Version 12
B21: https://www.lazard.com/media/2390/lazards-levelized-cost-of-energy-analysis-90.pdf
B22: p.16-18 "Levelized Cost of Energy - Key Assumptions
A24: Notes
A25: For the U.S., the natural gas preexisting retiring designation for natural gas nonpeakers refers to steam turbines, while the
A26: preexisting nonretiring designation refers to combined cycle.
A28: 1055.0558 | B28: Joules/BTU
A29: 29307.6 | B29: kj/kgce
A30: =(1000/A28)*A29 -> 27778.245 | B30: BTU/kgce

Sheet Cross-Page Data
A1: Form 860 Prime Mover Codes | D1: Form 860 Energy Source Codes | H1: Cross-walk for 2-check fuels
A3: Prime Mover Code | B3: Prime Mover Description | D3: Code | E3: Energy Source Description | F3: Corresponding Model Subscript | H3: Fuel Type | I3: Primer Mover | J3: Model Energy Source
A4: BA | B4: Energy Storage, Battery | D4: AB | E4: Agriculture Crop Byproducts/Straw/Energy Crops | F4: biomass | H4: NG | I4: CA | J4: natural gas nonpeaker - preexisting nonretiring
A5: CE | B5: Energy Storage, Compressed Air | D5: ANT | E5: Anthracite Coal | F5: hard coal | H5: NG | I5: CC | J5: natural gas nonpeaker - preexisting nonretiring
A6: CP | B6: Energy Storage, Concentrated Solar Power | D6: BFG | E6: Blast-Furnace Gas | F6: other | H6: NG | I6: CE | J6: other
A7: FW | B7: Energy Storage, Flywheel | D7: BIT | E7: Bituminous Coal | F7: hard coal | H7: NG | I7: CS | J7: natural gas nonpeaker - preexisting nonretiring
A8: PS | B8: Energy Storage, Reversible Hydraulic Turbine (Pumped Storage) | D8: BLQ | E8: Black Liquor | F8: biomass | H8: NG | I8: CT | J8: natural gas nonpeaker - preexisting nonretiring
A9: ES | B9: Energy Storage, Other (specify in SCHEDULE 7) | D9: CUR | E9: Water, Current | F9: hydro | H9: NG | I9: FC | J9: other
A10: ST | B10: Steam Turbine, including nuclear, geothermal and solar steam (does not include combined cycle) | D10: DFO | E10: Disillate Fuel Oil (all Diesel, and No. 1, No. 2, and No. 4 Fuel Oils) | F10: heavy or residual fuel oil | H10: NG | I10: GT | J10: natural gas peaker
A11: GT | B11: Combustion (Gas) Turbine (does not include the combustion turbine part of a combined cycle; see code CT, below) | D11: GEO | E11: Geothermal | F11: geothermal | H11: NG | I11: IC | J11: natural gas peaker
A12: IC | B12: Internal Combustion Engine (diesel, piston, reciprocating) | D12: JF | E12: Jet Fuel | F12: petroleum | H12: NG | I12: OT | J12: other
A13: CA | B13: Combined Cycle Steam Part | D13: KER | E13: Kerosene | F13: other | H13: NG | I13: ST | J13: natural gas nonpeaker - preexisting retiring
A14: CT | B14: Combined Cycle Combustion Turbine Part | D14: LFG | E14: Landfill Gas | F14: biomass | H14: SUN | I14: CA | J14: solar thermal
... A17: HA | B17: Hydrokinetic, Axial Flow Turbine | D17: MSB | E17: Biogenic Municipal Solid Waste | F17: municipal solid waste | H17: SUN | I17: ST | J17: solar thermal
A18: HB | B18: Hydrokinetic, Wave Buoy | D18: MSN | E18: Non-biogenic Municipal Solid Waste | F18: municipal solid waste
A19: HK | B19: Hydrokinetic, Other (specify in SCHEDULE 7) | D19: MSW | E19: Municipal Solid Waste | F19: municipal solid waste
A20: HY | B20: Hydroelectric Turbine (includes turbines associated with delivery of water by pipeline) | D20: NA | E20: Not Available at this Time | F20: other
A21: BT | B21: Turbines Used in a Binary Cycle (including those used for geothermal applications) | D21: NG | E21: Natural Gas | F21: natural gas
A22: PV | B22: Photovoltaic | D22: NUC | E22: Nuclear (Uranium, Plutonium, Thorium) | F22: nuclear
A23: WT | B23: Wind Turbine, Onshore | D23: OBG | E23: Other Biomass Gases (Digester Gas, Methane, and other Biomass Gases) | F23: biomass
A24: WS | B24: Wind Turbine, Offshore | D24: OBL | E24: Other Biomass Liquids (Fish Oil, Liquid Acetonitrite Waste, Medical Waste, Tall Oil, ethanol, Waste Alcohol, and other Biomass Liquids not specified) | F24: biomass
A25: FC | B25: Fuel Cell | D25: OBS | E25: Other Biomass Solids (Animal Manure and Waste, Solid Byproducts, and Other Solid Biomass not specified) | F25: biomass
A26: OT | B26: Other (specify in SCHEDULE 7) | D26: OG | E26: Other Gas (Coke-Oven, Coal Processes, Butane, Refinery, Other Process) | F26: other
D27: OTH | E27: Other (Batteries, Chemicals. Hydrogen, Pitch, Sulfur, Miscellaneous technologies) | F27: other
D28: PC | E28: Petroleum Coke | F28: petroleum
D29: PG | E29: Propane | F29: other
D30: PUR | E30: Purchased Steam | F30: other
D31: RC | E31: Refined Coal | F31: hard coal
D32: RFO | E32: Residual Fuel Oil (Include No. 5, and No. 6 Fuel Oil, and Bunker C Fuel Oil) | F32: heavy or residual fuel oil
D33: SC | E33: Coal-based Synfuel. Including briquettes, pellets, or extrusions, which are formed by binding materials or processes that recycle materials. | F33: hard coal
D34: SGP | E34: Synthesis Gas from Petroleum Coke | F34: other
D35: SGC | E35: Coal-Derived Synthetic Gas | F35: natural gas
D36: SLW | E36: Sludge waste | F36: biomass
D37: SUB | E37: Subbituminous Coal | F37: hard coal
D38: SUN | E38: Solar (Photovoltaic, Thermal) | F38: solar
... D48: WV | E48: Water, Waves | F48: hydro

Sheet Form 923
A1: U.S. Department of Energy, The Energy Information Administration (EIA)
A2: EIA-923 Monthly Generation and Fuel Consumption Time Series File, 2014 Final Release
A3: Sources: EIA-923 and EIA-860 Reports
A5: Plant Id | B5: Combined Heat And Power Plant | C5: Sector Name | D5: Reported Prime Mover | E5: Reported Fuel Type Code | F5: Elec Fuel Consumption MMBtu | G5: Net Generation (Megawatthours) | H5: YEAR | I5: Model Energy Source | J5: Energy Type | K5: Include?
A6: 2 | B6: N | C6: Electric Utility | D6: HY | E6: WAT | F6: 0 | G6: -284 | H6: 2019 | I6: =IF(J6="natural gas",VLOOKUP(D6,'Cross-Page Data'!$I$4:$J$13,2,FALSE),IF(J6="solar",VLOOKUP('Form 923'!D6,'Cross-Page Data'!$I$14:$J$117,2,FALSE),J6)) -> hydro | J6: =VLOOKUP(E6,'Cross-Page Data'!$D$4:$F$48,3,FALSE) -> hydro | K6: =IF(AND($N$6=FALSE,OR(C6="Commercial NAICS Cogen",C6="Industrial NAICS Cogen",C6="NAICS-22 Cogen")),FALSE,IF(AND($N$7=FALSE,OR(C6="Commercial NAICS Cogen",C6="Commercial NAICS Non-Cogen",C6="industrial NAICS Cogen",C6="industrial NAICS non-cogen")),FALSE,TRUE)) -> TRUE | M6: Include CHP Plants? | N6: FALSE
A7: 3 | B7: N | C7: Electric Utility | D7: CA | E7: NG | F7: 1499638 | G7: 2824887 | H7: 2019 | I7: =IF(J7="natural gas",VLOOKUP(D7,'Cross-Page Data'!$I$4:$J$13,2,FALSE),IF(J7="solar",VLOOKUP('Form 923'!D7,'Cross-Page Data'!$I$14:$J$117,2,FALSE),J7)) -> natural gas nonpeaker - preexisting nonretiring | J7: =VLOOKUP(E7,'Cross-Page Data'!$D$4:$F$48,3,FALSE) -> natural gas | K7: =IF(AND($N$6=FALSE,OR(C7="Commercial NAICS Cogen",C7="Industrial NAICS Cogen",C7="NAICS-22 Cogen")),FALSE,IF(AND($N$7=FALSE,OR(C7="Commercial NAICS Cogen",C7="Commercial NAICS Non-Cogen",C7="industrial NAICS Cogen",C7="industrial NAICS non-cogen")),FALSE,TRUE)) -> TRUE | M7: Include Non-Utilty Plants? | N7: FALSE
A8: 3 | B8: N | C8: Electric Utility | D8: CT | E8: NG | F8: 55606180 | G8: 5306391 | H8: 2019 | I8: =IF(J8="natural gas",VLOOKUP(D8,'Cross-Page Data'!$I$4:$J$13,2,FALSE),IF(J8="solar",VLOOKUP('Form 923'!D8,'Cross-Page Data'!$I$14:$J$117,2,FALSE),J8)) -> natural gas nonpeaker - preexisting nonretiring | J8: =VLOOKUP(E8,'Cross-Page Data'!$D$4:$F$48,3,FALSE) -> natural gas | K8: =IF(AND($N$6=FALSE,OR(C8="Commercial NAICS Cogen",C8="Industrial NAICS Cogen",C8="NAICS-22 Cogen")),FALSE,IF(AND($N$7=FALSE,OR(C8="Commercial NAICS Cogen",C8="Commercial NAICS Non-Cogen",C8="industrial NAICS Cogen",C8="industrial NAICS non-cogen")),FALSE,TRUE)) -> TRUE
A9: 3 | B9: N | C9: Electric Utility | D9: ST | E9: BIT | F9: 41521966 | G9: 4174904.2 | H9: 2019 | I9: =IF(J9="natural gas",VLOOKUP(D9,'Cross-Page Data'!$I$4:$J$13,2,FALSE),IF(J9="solar",VLOOKUP('Form 923'!D9,'Cross-Page Data'!$I$14:$J$117,2,FALSE),J9)) -> hard coal | J9: =VLOOKUP(E9,'Cross-Page Data'!$D$4:$F$48,3,FALSE) -> hard coal | K9: =IF(AND($N$6=FALSE,OR(C9="Commercial NAICS Cogen",C9="Industrial NAICS Cogen",C9="NAICS-22 Cogen")),FALSE,IF(AND($N$7=FALSE,OR(C9="Commercial NAICS Cogen",C9="Commercial NAICS Non-Cogen",C9="industrial NAICS Cogen",C9="industrial NAICS non-cogen")),FALSE,TRUE)) -> TRUE
A10: 3 | B10: N | C10: Electric Utility | D10: ST | E10: NG | F10: 1662458 | G10: 164624.81 | H10: 2019 | I10: =IF(J10="natural gas",VLOOKUP(D10,'Cross-Page Data'!$I$4:$J$13,2,FALSE),IF(J10="solar",VLOOKUP('Form 923'!D10,'Cross-Page Data'!$I$14:$J$117,2,FALSE),J10)) -> natural gas nonpeaker - preexisting retiring | J10: =VLOOKUP(E10,'Cross-Page Data'!$D$4:$F$48,3,FALSE) -> natural gas | K10: =IF(AND($N$6=FALSE,OR(C10="Commercial NAICS Cogen",C10="Industrial NAICS Cogen",C10="NAICS-22 Cogen")),FALSE,IF(AND($N$7=FALSE,OR(C10="Commercial NAICS Cogen",C10="Commercial NAICS Non-Cogen",C10="industrial NAICS Cogen",C10="industrial NAICS non-cogen")),FALSE,TRUE)) -> TRUE
A11: 3 | B11: N | C11: Electric Utility | D11: ST | E11: SUB | F11: 0 | G11: 0 | H11: 2019 | I11: =IF(J11="natural gas",VLOOKUP(D11,'Cross-Page Data'!$I$4:$J$13,2,FALSE),IF(J11="solar",VLOOKUP('Form 923'!D11,'Cross-Page Data'!$I$14:$J$117,2,FALSE),J11)) -> hard coal | J11: =VLOOKUP(E11,'Cross-Page Data'!$D$4:$F$48,3,FALSE) -> hard coal | K11: =IF(AND($N$6=FALSE,OR(C11="Commercial NAICS Cogen",C11="Industrial NAICS Cogen",C11="NAICS-22 Cogen")),FALSE,IF(AND($N$7=FALSE,OR(C11="Commercial NAICS Cogen",C11="Commercial NAICS Non-Cogen",C11="industrial NAICS Cogen",C11="industrial NAICS non-cogen")),FALSE,TRUE)) -> TRUE
A12: 4 | B12: N | C12: Electric Utility | D12: HY | E12: WAT | F12: 6442288 | G12: 723690 | H12: 2019 | I12: =IF(J12="natural gas",VLOOKUP(D12,'Cross-Page Data'!$I$4:$J$13,2,FALSE),IF(J12="solar",VLOOKUP('Form 923'!D12,'Cross-Page Data'!$I$14:$J$117,2,FALSE),J12)) -> hydro | J12: =VLOOKUP(E12,'Cross-Page Data'!$D$4:$F$48,3,FALSE) -> hydro | K12: =IF(AND($N$6=FALSE,OR(C12="Commercial NAICS Cogen",C12="Industrial NAICS Cogen",C12="NAICS-22 Cogen")),FALSE,IF(AND($N$7=FALSE,OR(C12="Commercial NAICS Cogen",C12="Commercial NAICS Non-Cogen",C12="industrial NAICS Cogen",C12="industrial NAICS non-cogen")),FALSE,TRUE)) -> TRUE
A13: 7 | B13: Y | C13: Electric Utility | D13: ST | E13: NG | F13: 1981699 | G13: 169977 | H13: 2019 | I13: =IF(J13="natural gas",VLOOKUP(D13,'Cross-Page Data'!$I$4:$J$13,2,FALSE),IF(J13="solar",VLOOKUP('Form 923'!D13,'Cross-Page Data'!$I$14:$J$117,2,FALSE),J13)) -> natural gas nonpeaker - preexisting retiring | J13: =VLOOKUP(E13,'Cross-Page Data'!$D$4:$F$48,3,FALSE) -> natural gas | K13: =IF(AND($N$6=FALSE,OR(C13="Commercial NAICS Cogen",C13="Industrial NAICS Cogen",C13="NAICS-22 Cogen")),FALSE,IF(AND($N$7=FALSE,OR(C13="Commercial NAICS Cogen",C13="Commercial NAICS Non-Cogen",C13="industrial NAICS Cogen",C13="industrial NAICS non-cogen")),FALSE,TRUE)) -> TRUE
A14: 8 | B14: N | C14: Electric Utility | D14: ST | E14: BIT | F14: 4840441 | G14: 489541.89 | H14: 2019 | I14: =IF(J14="natural gas",VLOOKUP(D14,'Cross-Page Data'!$I$4:$J$13,2,FALSE),IF(J14="solar",VLOOKUP('Form 923'!D14,'Cross-Page Data'!$I$14:$J$117,2,FALSE),J14)) -> hard coal | J14: =VLOOKUP(E14,'Cross-Page Data'!$D$4:$F$48,3,FALSE) -> hard coal | K14: =IF(AND($N$6=FALSE,OR(C14="Commercial NAICS Cogen",C14="Industrial NAICS Cogen",C14="NAICS-22 Cogen")),FALSE,IF(AND($N$7=FALSE,OR(C14="Commercial NAICS Cogen",C14="Commercial NAICS Non-Cogen",C14="industrial NAICS Cogen",C14="industrial NAICS non-cogen")),FALSE,TRUE)) -> TRUE
A15: 8 | B15: N | C15: Electric Utility | D15: ST | E15: DFO | F15: 12615 | G15: 1218.11 | H15: 2019 | I15: =IF(J15="natural gas",VLOOKUP(D15,'Cross-Page Data'!$I$4:$J$13,2,FALSE),IF(J15="solar",VLOOKUP('Form 923'!D15,'Cross-Page Data'!$I$14:$J$117,2,FALSE),J15)) -> heavy or residual fuel oil | J15: =VLOOKUP(E15,'Cross-Page Data'!$D$4:$F$48,3,FALSE) -> heavy or residual fuel oil | K15: =IF(AND($N$6=FALSE,OR(C15="Commercial NAICS Cogen",C15="Industrial NAICS Cogen",C15="NAICS-22 Cogen")),FALSE,IF(AND($N$7=FALSE,OR(C15="Commercial NAICS Cogen",C15="Commercial NAICS Non-Cogen",C15="industrial NAICS Cogen",C15="industrial NAICS non-cogen")),FALSE,TRUE)) -> TRUE
A16: 9 | B16: N | C16: Electric Utility | D16: GT | E16: DFO | F16: 0 | G16: 0 | H16: 2019 | I16: =IF(J16="natural gas",VLOOKUP(D16,'Cross-Page Data'!$I$4:$J$13,2,FALSE),IF(J16="solar",VLOOKUP('Form 923'!D16,'Cross-Page Data'!$I$14:$J$117,2,FALSE),J16)) -> heavy or residual fuel oil | J16: =VLOOKUP(E16,'Cross-Page Data'!$D$4:$F$48,3,FALSE) -> heavy or residual fuel oil | K16: =IF(AND($N$6=FALSE,OR(C16="Commercial NAICS Cogen",C16="Industrial NAICS Cogen",C16="NAICS-22 Cogen")),FALSE,IF(AND($N$7=FALSE,OR(C16="Commercial NAICS Cogen",C16="Commercial NAICS Non-Cogen",C16="industrial NAICS Cogen",C16="industrial NAICS non-cogen")),FALSE,TRUE)) -> TRUE
A17: 9 | B17: N | C17: Electric Utility | D17: GT | E17: NG | F17: 688549 | G17: 39534 | H17: 2019 | I17: =IF(J17="natural gas",VLOOKUP(D17,'Cross-Page Data'!$I$4:$J$13,2,FALSE),IF(J17="solar",VLOOKUP('Form 923'!D17,'Cross-Page Data'!$I$14:$J$117,2,FALSE),J17)) -> natural gas peaker | J17: =VLOOKUP(E17,'Cross-Page Data'!$D$4:$F$48,3,FALSE) -> natural gas | K17: =IF(AND($N$6=FALSE,OR(C17="Commercial NAICS Cogen",C17="Industrial NAICS Cogen",C17="NAICS-22 Cogen")),FALSE,IF(AND($N$7=FALSE,OR(C17="Commercial NAICS Cogen",C17="Commercial NAICS Non-Cogen",C17="industrial NAICS Cogen",C17="industrial NAICS non-cogen")),FALSE,TRUE)) -> TRUE
A18: 10 | B18: N | C18: Electric Utility | D18: GT | E18: DFO | F18: 1452 | G18: 104.114 | H18: 2019 | I18: =IF(J18="natural gas",VLOOKUP(D18,'Cross-Page Data'!$I$4:$J$13,2,FALSE),IF(J18="solar",VLOOKUP('Form 923'!D18,'Cross-Page Data'!$I$14:$J$117,2,FALSE),J18)) -> heavy or residual fuel oil | J18: =VLOOKUP(E18,'Cross-Page Data'!$D$4:$F$48,3,FALSE) -> heavy or residual fuel oil | K18: =IF(AND($N$6=FALSE,OR(C18="Commercial NAICS Cogen",C18="Industrial NAICS Cogen",C18="NAICS-22 Cogen")),FALSE,IF(AND($N$7=FALSE,OR(C18="Commercial NAICS Cogen",C18="Commercial NAICS Non-Cogen",C18="industrial NAICS Cogen",C18="industrial NAICS non-cogen")),FALSE,TRUE)) -> TRUE
A19: 10 | B19: N | C19: Electric Utility | D19: GT | E19: NG | F19: 605246 | G19: 43505.886 | H19: 2019 | I19: =IF(J19="natural gas",VLOOKUP(D19,'Cross-Page Data'!$I$4:$J$13,2,FALSE),IF(J19="solar",VLOOKUP('Form 923'!D19,'Cross-Page Data'!$I$14:$J$117,2,FALSE),J19)) -> natural gas peaker | J19: =VLOOKUP(E19,'Cross-Page Data'!$D$4:$F$48,3,FALSE) -> natural gas | K19: =IF(AND($N$6=FALSE,OR(C19="Commercial NAICS Cogen",C19="Industrial NAICS Cogen",C19="NAICS-22 Cogen")),FALSE,IF(AND($N$7=FALSE,OR(C19="Commercial NAICS Cogen",C19="Commercial NAICS Non-Cogen",C19="industrial NAICS Cogen",C19="industrial NAICS non-cogen")),FALSE,TRUE)) -> TRUE
... A14148: 99999 | B14148: N | C14148: NAICS-22 Non-Cogen | D14148: WT | E14148: WND | F14148: 2853118 | G14148: 320502.82 | H14148: 2019 | I14148: =IF(J14148="natural gas",VLOOKUP(D14148,'Cross-Page Data'!$I$4:$J$13,2,FALSE),IF(J14148="solar",VLOOKUP('Form 923'!D14148,'Cross-Page Data'!$I$14:$J$117,2,FALSE),J14148)) -> wind | J14148: =VLOOKUP(E14148,'Cross-Page Data'!$D$4:$F$48,3,FALSE) -> wind | K14148: =IF(AND($N$6=FALSE,OR(C14148="Commercial NAICS Cogen",C14148="Industrial NAICS Cogen",C14148="NAICS-22 Cogen")),FALSE,IF(AND($N$7=FALSE,OR(C14148="Commercial NAICS Cogen",C14148="Commercial NAICS Non-Cogen",C14148="industrial NAICS Cogen",C14148="industrial NAICS non-cogen")),FALSE,TRUE)) -> TRUE

Sheet Calculations
A1: Row Labels | B1: Sum of Elec Fuel Consumption MMBtu | C1: Sum of Net Generation (Megawatthours) | D1: Operating Heat Rate
A2: biomass | B2: 487475053 | C2: 51409317 | D2: =B2/C2*10^6 -> 9482231.6
A3: crude oil | B3: 7948669 | C3: 1030533.6 | D3: =B3/C3*10^6 -> 7713158.3
A4: geothermal | B4: 138080172 | C4: 15511140 | D4: =B4/C4*10^6 -> 8902000.4
A5: hard coal | B5: 9872136038 | C5: 9.3918074e+08 | D5: =B5/C5*10^6 -> 10511434
A6: heavy or residual fuel oil | B6: 109984770 | C6: 10260584 | D6: =B6/C6*10^6 -> 10719153
A7: hydro | B7: 2561152904 | C7: 2.8244214e+08 | D7: =B7/C7*10^6 -> 9067885.3
A8: lignite | B8: 273885241 | C8: 23839374 | D8: =B8/C8*10^6 -> 11488776
A9: municipal solid waste | B9: 255810262 | C9: 13539084 | D9: =B9/C9*10^6 -> 18894208
A10: natural gas nonpeaker - preexisting nonretiring | B10: 9604147209 | C10: 1.3414893e+09 | D10: =B10/C10*10^6 -> 7159317.1
A11: natural gas nonpeaker - preexisting retiring | B11: 1121815715 | C11: 1.0696093e+08 | D11: =B11/C11*10^6 -> 10488088
A12: natural gas peaker | B12: 1269286581 | C12: 1.3529815e+08 | D12: =B12/C12*10^6 -> 9381403.7
A13: nuclear | B13: 0 | C13: 809409262 | D13: =B13/C13*10^6 -> 0
... A19: #N/A | B19: 4139 | C19: 465 | D19: =B19/C19*10^6 -> 8901075.3
A20: Grand Total | B20: 29189111028 | C20: 4.125207e+09

Sheet Coal Caculation
A1: 地区 | B1: 年份 | C1: 项 目 | D1: 能源品种 | E1: 实物消费量 | G1: BTU Consumption
A2: 全国 | B2: 2015 | C2: 2.1. 火力发电 | D2: 其他能源(万吨标准煤) | E2: -1058.97 | F2: =VLOOKUP(D2,'Coal Caculation'!J$22:K$39,2,FALSE) -> Biomass | G2: =-VLOOKUP(D2,'Heat Rate by Fuel'!E$3:F$34,2,FALSE)*E2 -> 293795483266474 | J2: Fossil Generation (10^8 KWh)
A3: 全国 | B3: 2015 | C3: 2.1. 火力发电 | D3: 原煤(万吨) | E3: -176893.54 | F3: =VLOOKUP(D3,'Coal Caculation'!J$22:K$39,2,FALSE) -> Coal | G3: =-VLOOKUP(D3,'Heat Rate by Fuel'!E$3:F$34,2,FALSE)*E3 -> 3.505487e+16 | K3: 2015 | L3: 2016 | M3: 2017 | N3: 2018 | O3: 2019 | P3: 2020
A4: 全国 | B4: 2015 | C4: 2.1. 火力发电 | D4: 其他洗煤(万吨) | E4: -2643.02 | F4: =VLOOKUP(D4,'Coal Caculation'!J$22:K$39,2,FALSE) -> Coal | G4: =-VLOOKUP(D4,'Heat Rate by Fuel'!E$3:F$34,2,FALSE)*E4 -> 209501165978314 | J4: Coal | K4: 39462 | L4: 39462 | M4: 41498 | N4: 44829 | O4: 45538 | P4: 46296
A5: 全国 | B5: 2015 | C5: 2.1. 火力发电 | D5: 煤矸石(万吨) | E5: -2709.6 | F5: =VLOOKUP(D5,'Coal Caculation'!J$22:K$39,2,FALSE) -> Coal | G5: =-VLOOKUP(D5,'Heat Rate by Fuel'!E$3:F$34,2,FALSE)*E5 -> 215061186893652 | J5: Natural Gas | K5: 1883 | L5: 1883 | M5: 2028 | N5: 2155 | O5: 2325 | P5: 2525
A6: 全国 | B6: 2015 | C6: 2.1. 火力发电 | D6: 焦炭(万吨) | E6: -5.92 | F6: =VLOOKUP(D6,'Coal Caculation'!J$22:K$39,2,FALSE) -> Coal | G6: =-VLOOKUP(D6,'Heat Rate by Fuel'!E$3:F$34,2,FALSE)*E6 -> 1.5955075e+12 | J6: Oil | K6: 28 | L6: 28 | M6: 27 | N6: 15 | O6: 13 | P6: 12
A7: 全国 | B7: 2015 | C7: 2.1. 火力发电 | D7: 石油焦(万吨) | E7: -136.27 | F7: =VLOOKUP(D7,'Coal Caculation'!J$22:K$39,2,FALSE) -> Coal | G7: =-VLOOKUP(D7,'Heat Rate by Fuel'!E$3:F$34,2,FALSE)*E7 -> 4.1262376e+13 | J7: Total | K7: =K4+K5+K6 -> 41373 | L7: =L4+L5+L6 -> 41373 | M7: =M4+M5+M6 -> 43553 | N7: =N4+N5+N6 -> 46999 | O7: =O4+O5+O6 -> 47876 | P7: =P4+P5+P6 -> 48833
A8: 全国 | B8: 2015 | C8: 2.1. 火力发电 | D8: 焦炉煤气(亿立方米) | E8: -169.63 | F8: =VLOOKUP(D8,'Coal Caculation'!J$22:K$39,2,FALSE) -> Natural Gas | G8: =-VLOOKUP(D8,'Heat Rate by Fuel'!E$3:F$34,2,FALSE)*E8 -> 279006062617935
A9: 全国 | B9: 2015 | C9: 2.1. 火力发电 | D9: 高炉煤气(亿立方米) | E9: -1465.75 | F9: =VLOOKUP(D9,'Coal Caculation'!J$22:K$39,2,FALSE) -> Natural Gas | G9: =-VLOOKUP(D9,'Heat Rate by Fuel'!E$3:F$34,2,FALSE)*E9 -> 522778862285836 | J9: Fossil Generation Heat Rate (BTU/MWh)
A10: 全国 | B10: 2015 | C10: 2.1. 火力发电 | D10: 转炉煤气(亿立方米) | E10: -113.46 | F10: =VLOOKUP(D10,'Coal Caculation'!J$22:K$39,2,FALSE) -> Natural Gas | G10: =-VLOOKUP(D10,'Heat Rate by Fuel'!E$3:F$34,2,FALSE)*E10 -> 8.543987e+13 | K10: 2015 | L10: 2016 | M10: 2017 | N10: 2018 | O10: 2019 | P10: 2020
A11: 全国 | B11: 2015 | C11: 2.1. 火力发电 | D11: 其他煤气(亿立方米) | E11: -2.8 | F11: =VLOOKUP(D11,'Coal Caculation'!J$22:K$39,2,FALSE) -> Natural Gas | G11: =-VLOOKUP(D11,'Heat Rate by Fuel'!E$3:F$34,2,FALSE)*E11 -> 1.3871851e+12 | J11: Coal | K11: =SUMIFS($G:$G,$F:$F,$J11,$B:$B,K$10)/(K4*10^5) -> 9001644.7 | L11: =SUMIFS($G:$G,$F:$F,$J11,$B:$B,L$10)/(L4*10^5) -> 9150132.6 | M11: =SUMIFS($G:$G,$F:$F,$J11,$B:$B,M$10)/(M4*10^5) -> 9241614.1 | N11: =SUMIFS($G:$G,$F:$F,$J11,$B:$B,N$10)/(N4*10^5) -> 9031393.6 | O11: =SUMIFS($G:$G,$F:$F,$J11,$B:$B,O$10)/(O4*10^5) -> 9080906.1 | P11: =SUMIFS($G:$G,$F:$F,$J11,$B:$B,P$10)/(P4*10^5) -> 8998762.5
A12: 全国 | B12: 2015 | C12: 2.1. 火力发电 | D12: 炼厂干气(万吨) | E12: -50.42 | F12: =VLOOKUP(D12,'Coal Caculation'!J$22:K$39,2,FALSE) -> Natural Gas | G12: =-VLOOKUP(D12,'Heat Rate by Fuel'!E$3:F$34,2,FALSE)*E12 -> 2.1981923e+13 | J12: Natural Gas | K12: =SUMIFS($G:$G,$F:$F,$J12,$B:$B,K$10)/(K5*10^5) -> 10481022 | L12: =SUMIFS($G:$G,$F:$F,$J12,$B:$B,L$10)/(L5*10^5) -> 12150430 | M12: =SUMIFS($G:$G,$F:$F,$J12,$B:$B,M$10)/(M5*10^5) -> 11893799 | N12: =SUMIFS($G:$G,$F:$F,$J12,$B:$B,N$10)/(N5*10^5) -> 12910117 | O12: =SUMIFS($G:$G,$F:$F,$J12,$B:$B,O$10)/(O5*10^5) -> 12566395 | P12: =SUMIFS($G:$G,$F:$F,$J12,$B:$B,P$10)/(P5*10^5) -> 12907103
A13: 全国 | B13: 2015 | C13: 2.1. 火力发电 | D13: 天然气(亿立方米) | E13: -291.59 | F13: =VLOOKUP(D13,'Coal Caculation'!J$22:K$39,2,FALSE) -> Natural Gas | G13: =-VLOOKUP(D13,'Heat Rate by Fuel'!E$3:F$34,2,FALSE)*E13 -> 983461565265205 | J13: Oil | K13: =SUMIFS($G:$G,$F:$F,$J13,$B:$B,K$10)/(K6*10^5) -> 11165471 | L13: =SUMIFS($G:$G,$F:$F,$J13,$B:$B,L$10)/(L6*10^5) -> 10878759 | M13: =SUMIFS($G:$G,$F:$F,$J13,$B:$B,M$10)/(M6*10^5) -> 8391608.9 | N13: =SUMIFS($G:$G,$F:$F,$J13,$B:$B,N$10)/(N6*10^5) -> 16022391 | O13: =SUMIFS($G:$G,$F:$F,$J13,$B:$B,O$10)/(O6*10^5) -> 19115252 | P13: =SUMIFS($G:$G,$F:$F,$J13,$B:$B,P$10)/(P6*10^5) -> 26995894
A14: 全国 | B14: 2015 | C14: 2.1. 火力发电 | D14: 液化天然气(万吨) | E14: -163.12 | F14: =VLOOKUP(D14,'Coal Caculation'!J$22:K$39,2,FALSE) -> Natural Gas | G14: =-VLOOKUP(D14,'Heat Rate by Fuel'!E$3:F$34,2,FALSE)*E14 -> 79520922838116 | J14: Total | K14: =SUMIFS($G:$G,$B:$B,K$10)/(K7*10^5) -> 9141451.1 | L14: =SUMIFS($G:$G,$B:$B,L$10)/(L7*10^5) -> 9369517.8 | M14: =SUMIFS($G:$G,$B:$B,M$10)/(M7*10^5) -> 9454254.7 | N14: =SUMIFS($G:$G,$B:$B,N$10)/(N7*10^5) -> 9305154 | O14: =SUMIFS($G:$G,$B:$B,O$10)/(O7*10^5) -> 9343758.2 | P14: =SUMIFS($G:$G,$B:$B,P$10)/(P7*10^5) -> 9319912.6
A15: 全国 | B15: 2015 | C15: 2.1. 火力发电 | D15: 原油(万吨) | E15: -12.46 | F15: =VLOOKUP(D15,'Coal Caculation'!J$22:K$39,2,FALSE) -> Oil | G15: =-VLOOKUP(D15,'Heat Rate by Fuel'!E$3:F$34,2,FALSE)*E15 -> 4.9383791e+12
A16: 全国 | B16: 2015 | C16: 2.1. 火力发电 | D16: 柴油(万吨) | E16: -22.36 | F16: =VLOOKUP(D16,'Coal Caculation'!J$22:K$39,2,FALSE) -> Oil | G16: =-VLOOKUP(D16,'Heat Rate by Fuel'!E$3:F$34,2,FALSE)*E16 -> 9.0393062e+12 | J16: Fossil Generation Heat Rate (kgce/MWh)
A17: 全国 | B17: 2015 | C17: 2.1. 火力发电 | D17: 燃料油(万吨) | E17: -31.52 | F17: =VLOOKUP(D17,'Coal Caculation'!J$22:K$39,2,FALSE) -> Oil | G17: =-VLOOKUP(D17,'Heat Rate by Fuel'!E$3:F$34,2,FALSE)*E17 -> 1.2492593e+13 | K17: 2015 | L17: 2016 | M17: 2017 | N17: 2018 | O17: 2019 | P17: 2020
A18: 全国 | B18: 2015 | C18: 2.1. 火力发电 | D18: 其他石油制品(万吨) | E18: -12.34 | F18: =VLOOKUP(D18,'Coal Caculation'!J$22:K$39,2,FALSE) -> Oil | G18: =-VLOOKUP(D18,'Heat Rate by Fuel'!E$3:F$34,2,FALSE)*E18 -> 4.7930395e+12 | J18: Coal | K18: =K11/('Heat Rate by Fuel'!$F$4/'Heat Rate by Fuel'!$D$4)*10^7 -> 324.1383 | L18: =L11/('Heat Rate by Fuel'!$F$4/'Heat Rate by Fuel'!$D$4)*10^7 -> 329.48517 | M18: =M11/('Heat Rate by Fuel'!$F$4/'Heat Rate by Fuel'!$D$4)*10^7 -> 332.77931 | N18: =N11/('Heat Rate by Fuel'!$F$4/'Heat Rate by Fuel'!$D$4)*10^7 -> 325.20952 | O18: =O11/('Heat Rate by Fuel'!$F$4/'Heat Rate by Fuel'!$D$4)*10^7 -> 326.99241 | P18: =P11/('Heat Rate by Fuel'!$F$4/'Heat Rate by Fuel'!$D$4)*10^7 -> 324.03452
J19: Natural Gas | K19: =K12/('Heat Rate by Fuel'!$F$4/'Heat Rate by Fuel'!$D$4)*10^7 -> 377.40887 | L19: =L12/('Heat Rate by Fuel'!$F$4/'Heat Rate by Fuel'!$D$4)*10^7 -> 437.52224 | M19: =M12/('Heat Rate by Fuel'!$F$4/'Heat Rate by Fuel'!$D$4)*10^7 -> 428.28126 | N19: =N12/('Heat Rate by Fuel'!$F$4/'Heat Rate by Fuel'!$D$4)*10^7 -> 464.87763 | O19: =O12/('Heat Rate by Fuel'!$F$4/'Heat Rate by Fuel'!$D$4)*10^7 -> 452.50062 | P19: =P12/('Heat Rate by Fuel'!$F$4/'Heat Rate by Fuel'!$D$4)*10^7 -> 464.76911
J20: Oil | K20: =K13/('Heat Rate by Fuel'!$F$4/'Heat Rate by Fuel'!$D$4)*10^7 -> 402.05505 | L20: =L13/('Heat Rate by Fuel'!$F$4/'Heat Rate by Fuel'!$D$4)*10^7 -> 391.7309 | M20: =M13/('Heat Rate by Fuel'!$F$4/'Heat Rate by Fuel'!$D$4)*10^7 -> 302.17165 | N20: =N13/('Heat Rate by Fuel'!$F$4/'Heat Rate by Fuel'!$D$4)*10^7 -> 576.94686 | O20: =O13/('Heat Rate by Fuel'!$F$4/'Heat Rate by Fuel'!$D$4)*10^7 -> 688.31703 | P20: =P13/('Heat Rate by Fuel'!$F$4/'Heat Rate by Fuel'!$D$4)*10^7 -> 972.08937
A21: 全国 | B21: 2016 | C21: 2.1. 火力发电 | D21: 其他能源(万吨标准煤) | E21: -1217.82 | F21: =VLOOKUP(D21,'Coal Caculation'!J$22:K$39,2,FALSE) -> Biomass | G21: =-VLOOKUP(D21,'Heat Rate by Fuel'!E$3:F$34,2,FALSE)*E21 -> 337866054214546
A22: 全国 | B22: 2016 | C22: 2.1. 火力发电 | D22: 原煤(万吨) | E22: -179635.55 | F22: =VLOOKUP(D22,'Coal Caculation'!J$22:K$39,2,FALSE) -> Coal | G22: =-VLOOKUP(D22,'Heat Rate by Fuel'!E$3:F$34,2,FALSE)*E22 -> 3.5598252e+16 | J22: 其他能源(万吨标准煤) | K22: Biomass
A23: 全国 | B23: 2016 | C23: 2.1. 火力发电 | D23: 其他洗煤(万吨) | E23: -3030.1 | F23: =VLOOKUP(D23,'Coal Caculation'!J$22:K$39,2,FALSE) -> Coal | G23: =-VLOOKUP(D23,'Heat Rate by Fuel'!E$3:F$34,2,FALSE)*E23 -> 240183382278942 | J23: 原煤(万吨) | K23: Coal
A24: 全国 | B24: 2016 | C24: 2.1. 火力发电 | D24: 煤矸石(万吨) | E24: -2803.63 | F24: =VLOOKUP(D24,'Coal Caculation'!J$22:K$39,2,FALSE) -> Coal | G24: =-VLOOKUP(D24,'Heat Rate by Fuel'!E$3:F$34,2,FALSE)*E24 -> 222524356145058 | J24: 其他洗煤(万吨) | K24: Coal
A25: 全国 | B25: 2016 | C25: 2.1. 火力发电 | D25: 焦炭(万吨) | E25: -5.12 | F25: =VLOOKUP(D25,'Coal Caculation'!J$22:K$39,2,FALSE) -> Coal | G25: =-VLOOKUP(D25,'Heat Rate by Fuel'!E$3:F$34,2,FALSE)*E25 -> 1.3798983e+12 | J25: 煤矸石(万吨) | K25: Coal
A26: 全国 | B26: 2016 | C26: 2.1. 火力发电 | D26: 石油焦(万吨) | E26: -151.63 | F26: =VLOOKUP(D26,'Coal Caculation'!J$22:K$39,2,FALSE) -> Coal | G26: =-VLOOKUP(D26,'Heat Rate by Fuel'!E$3:F$34,2,FALSE)*E26 -> 4.5913364e+13 | J26: 焦炭(万吨) | K26: Coal
A27: 全国 | B27: 2016 | C27: 2.1. 火力发电 | D27: 焦炉煤气(亿立方米) | E27: -193.14 | F27: =VLOOKUP(D27,'Coal Caculation'!J$22:K$39,2,FALSE) -> Natural Gas | G27: =-VLOOKUP(D27,'Heat Rate by Fuel'!E$3:F$34,2,FALSE)*E27 -> 317675121936143 | J27: 石油焦(万吨) | K27: Coal
A28: 全国 | B28: 2016 | C28: 2.1. 火力发电 | D28: 高炉煤气(亿立方米) | E28: -1703.1 | F28: =VLOOKUP(D28,'Coal Caculation'!J$22:K$39,2,FALSE) -> Natural Gas | G28: =-VLOOKUP(D28,'Heat Rate by Fuel'!E$3:F$34,2,FALSE)*E28 -> 607432836676792 | J28: 天然气(亿立方米) | K28: Natural Gas
A29: 全国 | B29: 2016 | C29: 2.1. 火力发电 | D29: 转炉煤气(亿立方米) | E29: -149.02 | F29: =VLOOKUP(D29,'Coal Caculation'!J$22:K$39,2,FALSE) -> Natural Gas | G29: =-VLOOKUP(D29,'Heat Rate by Fuel'!E$3:F$34,2,FALSE)*E29 -> 112217957224915 | J29: 高炉煤气(亿立方米) | K29: Natural Gas
A30: 全国 | B30: 2016 | C30: 2.1. 火力发电 | D30: 其他煤气(亿立方米) | E30: -1.46 | F30: =VLOOKUP(D30,'Coal Caculation'!J$22:K$39,2,FALSE) -> Natural Gas | G30: =-VLOOKUP(D30,'Heat Rate by Fuel'!E$3:F$34,2,FALSE)*E30 -> 7.2331797e+11 | J30: 焦炉煤气(亿立方米) | K30: Natural Gas
A31: 全国 | B31: 2016 | C31: 2.1. 火力发电 | D31: 液化石油气(万吨) | E31: -0.13 | F31: =VLOOKUP(D31,'Coal Caculation'!J$22:K$39,2,FALSE) -> Natural Gas | G31: =-VLOOKUP(D31,'Heat Rate by Fuel'!E$3:F$34,2,FALSE)*E31 -> 6.1828577e+10 | J31: 转炉煤气(亿立方米) | K31: Natural Gas
A32: 全国 | B32: 2016 | C32: 2.1. 火力发电 | D32: 炼厂干气(万吨) | E32: -56.44 | F32: =VLOOKUP(D32,'Coal Caculation'!J$22:K$39,2,FALSE) -> Natural Gas | G32: =-VLOOKUP(D32,'Heat Rate by Fuel'!E$3:F$34,2,FALSE)*E32 -> 2.46065e+13 | J32: 液化天然气(万吨) | K32: Natural Gas
A33: 全国 | B33: 2016 | C33: 2.1. 火力发电 | D33: 天然气(亿立方米) | E33: -332.42 | F33: =VLOOKUP(D33,'Coal Caculation'!J$22:K$39,2,FALSE) -> Natural Gas | G33: =-VLOOKUP(D33,'Heat Rate by Fuel'!E$3:F$34,2,FALSE)*E33 -> 1.1211711e+15 | J33: 炼厂干气(万吨) | K33: Natural Gas
... A38: 全国 | B38: 2016 | C38: 2.1. 火力发电 | D38: 其他石油制品(万吨) | E38: -2.94 | F38: =VLOOKUP(D38,'Coal Caculation'!J$22:K$39,2,FALSE) -> Oil | G38: =-VLOOKUP(D38,'Heat Rate by Fuel'!E$3:F$34,2,FALSE)*E38 -> 1.1419397e+12 | J38: 原油(万吨) | K38: Oil
J39: 其他石油制品(万吨) | K39: Oil
A41: 全国 | B41: 2017 | C41: 2.1. 火力发电 | D41: 其他能源(万吨标准煤) | E41: -1407.7 | F41: =VLOOKUP(D41,'Coal Caculation'!J$22:K$39,2,FALSE) -> Biomass | G41: =-VLOOKUP(D41,'Heat Rate by Fuel'!E$3:F$34,2,FALSE)*E41 -> 390545437353481
A42: 全国 | B42: 2017 | C42: 2.1. 火力发电 | D42: 原煤(万吨) | E42: -190693.32 | F42: =VLOOKUP(D42,'Coal Caculation'!J$22:K$39,2,FALSE) -> Coal | G42: =-VLOOKUP(D42,'Heat Rate by Fuel'!E$3:F$34,2,FALSE)*E42 -> 3.7789563e+16
A43: 全国 | B43: 2017 | C43: 2.1. 火力发电 | D43: 其他洗煤(万吨) | E43: -3231.34 | F43: =VLOOKUP(D43,'Coal Caculation'!J$22:K$39,2,FALSE) -> Coal | G43: =-VLOOKUP(D43,'Heat Rate by Fuel'!E$3:F$34,2,FALSE)*E43 -> 256134837296867
A44: 全国 | B44: 2017 | C44: 2.1. 火力发电 | D44: 煤矸石(万吨) | E44: -3288.22 | F44: =VLOOKUP(D44,'Coal Caculation'!J$22:K$39,2,FALSE) -> Coal | G44: =-VLOOKUP(D44,'Heat Rate by Fuel'!E$3:F$34,2,FALSE)*E44 -> 260986306453884
A45: 全国 | B45: 2017 | C45: 2.1. 火力发电 | D45: 石油焦(万吨) | E45: -145.86 | F45: =VLOOKUP(D45,'Coal Caculation'!J$22:K$39,2,FALSE) -> Coal | G45: =-VLOOKUP(D45,'Heat Rate by Fuel'!E$3:F$34,2,FALSE)*E45 -> 4.4166216e+13
...

Sheet Heat Rate by Fuel
A1: 能源名称 | B1: 实物量单位 | C1: 平均低位发热量 | D1: 平均低位发热量 | F1: 平均发热量
C2: TJ/单位 | D2: 万tce/单位 | F2: BTU/单位
A3: 煤合计 | C3: 0 | E3: =A3&"("&B3&")" -> 煤合计()
A4: 原煤 | B4: 万吨 | C4: 209.08 | D4: =C4/293 -> 0.71358362 | E4: =A4&"("&B4&")" -> 原煤(万吨) | F4: =D4*2.7771*10^11 -> 1.9816931e+11
A5: 洗精煤 | B5: 万吨 | C5: 263.44 | D5: =C5/293 -> 0.89911263 | E5: =A5&"("&B5&")" -> 洗精煤(万吨) | F5: =D5*2.7771*10^11 -> 2.4969257e+11
A6: 其他洗煤 | B6: 万吨 | C6: 83.63 | D6: =C6/293 -> 0.28542662 | E6: =A6&"("&B6&")" -> 其他洗煤(万吨) | F6: =D6*2.7771*10^11 -> 7.9265827e+10
A7: 型煤 | B7: 万吨 | C7: 154.73 | D7: =C7/293 -> 0.52808874 | E7: =A7&"("&B7&")" -> 型煤(万吨) | F7: =D7*2.7771*10^11 -> 1.4665552e+11
A8: 煤矸石 | B8: 万吨 | C8: 83.74 | D8: =C8/293 -> 0.28580205 | E8: =A8&"("&B8&")" -> 煤矸石(万吨) | F8: =D8*2.7771*10^11 -> 7.9370087e+10
A9: 焦炭 | B9: 万吨 | C9: 284.35 | D9: =C9/293 -> 0.97047782 | E9: =A9&"("&B9&")" -> 焦炭(万吨) | F9: =D9*2.7771*10^11 -> 2.6951139e+11
A10: 焦炉煤气 | B10: 亿立方米 | C10: 1735.35 | D10: =C10/293 -> 5.9226962 | E10: =A10&"("&B10&")" -> 焦炉煤气(亿立方米) | F10: =D10*2.7771*10^11 -> 1.644792e+12
A11: 高炉煤气 | B11: 亿立方米 | C11: 376.3 | D11: =C11/293 -> 1.2843003 | E11: =A11&"("&B11&")" -> 高炉煤气(亿立方米) | F11: =D11*2.7771*10^11 -> 3.5666305e+11
A12: 转炉煤气 | B12: 亿立方米 | C12: 794.5 | D12: =C12/293 -> 2.7116041 | E12: =A12&"("&B12&")" -> 转炉煤气(亿立方米) | F12: =D12*2.7771*10^11 -> 7.5303957e+11
A13: 其他煤气 | B13: 亿立方米 | C13: 522.7 | D13: =C13/293 -> 1.783959 | E13: =A13&"("&B13&")" -> 其他煤气(亿立方米) | F13: =D13*2.7771*10^11 -> 4.9542327e+11
A14: 其他焦化产品 | B14: 万吨 | C14: 334.53 | D14: =C14/293 -> 1.1417406 | E14: =A14&"("&B14&")" -> 其他焦化产品(万吨) | F14: =D14*2.7771*10^11 -> 3.1707279e+11
A15: 油品合计 | C15: 0 | D15: =C15/293 -> 0 | E15: =A15&"("&B15&")" -> 油品合计() | F15: =D15*2.7771*10^11 -> 0
A16: 原油 | B16: 万吨 | C16: 418.16 | D16: =C16/293 -> 1.4271672 | E16: =A16&"("&B16&")" -> 原油(万吨) | F16: =D16*2.7771*10^11 -> 3.9633861e+11
A17: 汽油 | B17: 万吨 | C17: 430.7 | D17: =C17/293 -> 1.4699659 | E17: =A17&"("&B17&")" -> 汽油(万吨) | F17: =D17*2.7771*10^11 -> 4.0822422e+11
A18: 煤油 | B18: 万吨 | C18: 430.7 | D18: =C18/293 -> 1.4699659 | E18: =A18&"("&B18&")" -> 煤油(万吨) | F18: =D18*2.7771*10^11 -> 4.0822422e+11
A19: 柴油 | B19: 万吨 | C19: 426.52 | D19: =C19/293 -> 1.4556997 | E19: =A19&"("&B19&")" -> 柴油(万吨) | F19: =D19*2.7771*10^11 -> 4.0426235e+11
A20: 燃料油 | B20: 万吨 | C20: 418.16 | D20: =C20/293 -> 1.4271672 | E20: =A20&"("&B20&")" -> 燃料油(万吨) | F20: =D20*2.7771*10^11 -> 3.9633861e+11
A21: 石脑油 | B21: 万吨 | C21: 439.07 | D21: =C21/293 -> 1.4985324 | E21: =A21&"("&B21&")" -> 石脑油(万吨) | F21: =D21*2.7771*10^11 -> 4.1615744e+11
A22: 润滑油 | B22: 万吨 | C22: 413.98 | D22: =C22/293 -> 1.412901 | E22: =A22&"("&B22&")" -> 润滑油(万吨) | F22: =D22*2.7771*10^11 -> 3.9237674e+11
A23: 石蜡 | B23: 万吨 | C23: 399.25 | D23: =C23/293 -> 1.362628 | E23: =A23&"("&B23&")" -> 石蜡(万吨) | F23: =D23*2.7771*10^11 -> 3.7841542e+11
A24: 溶剂油 | B24: 万吨 | C24: 429.45 | D24: =C24/293 -> 1.4656997 | E24: =A24&"("&B24&")" -> 溶剂油(万吨) | F24: =D24*2.7771*10^11 -> 4.0703945e+11
A25: 石油沥青 | B25: 万吨 | C25: 389.31 | D25: =C25/293 -> 1.3287031 | E25: =A25&"("&B25&")" -> 石油沥青(万吨) | F25: =D25*2.7771*10^11 -> 3.6899413e+11
A26: 石油焦 | B26: 万吨 | C26: 319.47 | D26: =C26/293 -> 1.0903413 | E26: =A26&"("&B26&")" -> 石油焦(万吨) | F26: =D26*2.7771*10^11 -> 3.0279868e+11
A27: 液化石油气 | B27: 万吨 | C27: 501.79 | D27: =C27/293 -> 1.7125939 | E27: =A27&"("&B27&")" -> 液化石油气(万吨) | F27: =D27*2.7771*10^11 -> 4.7560444e+11
... A34: 其他能源 | B34: 万吨标准煤 | C34: 292.71 | D34: =C34/293 -> 0.99901024 | E34: =A34&"("&B34&")" -> 其他能源(万吨标准煤) | F34: =D34*2.7771*10^11 -> 2.7743513e+11

Sheet Fire Generation
A1: 地区 | B1: 发电量（亿千瓦时） | G1: 发电量（亿千瓦时） | L1: 发电量（亿千瓦时） | Q1: 发电量（亿千瓦时） | V1: 发电量（亿千瓦时） | AA1: 发电量（亿千瓦时） | AF1: 发电量（亿千瓦时） | AK1: 发电量（亿千瓦时） | AP1: 发电量（亿千瓦时） | AU1: 发电量（亿千瓦时） | AZ1: 发电量（亿千瓦时） | BE1: 发电量（亿千瓦时）
B2: 合计 | C2: 燃煤 | D2: 燃气 | E2: 燃油 | F2: 其他 | G2: 合计 | H2: 沼气发电 | I2: 垃圾焚烧发电 | J2: 秸秆、蔗渣、林木质发电 | L2: 合计 | M2: 燃煤 | N2: 燃气 | O2: 燃油 | P2: 其他 | Q2: 合计 | R2: 沼气发电 | S2: 垃圾焚烧发电 | T2: 秸秆、蔗渣、林木质发电 | V2: 合计 | W2: 燃煤 | X2: 燃气 | Y2: 燃油 | Z2: 其他 | AA2: 合计 | AB2: 沼气发电 | AC2: 垃圾焚烧发电 | AD2: 秸秆、蔗渣、林木质发电 | AF2: 合计 | AG2: 燃煤 | AH2: 燃气 | AI2: 燃油 | AJ2: 其他 | AK2: 合计 | AL2: 沼气发电 | AM2: 垃圾焚烧发电 | AN2: 秸秆、蔗渣、林木质发电 | AP2: 合计 | AQ2: 燃煤 | AR2: 燃气 | AS2: 燃油 | AT2: 其他 | AU2: 合计 | AV2: 沼气发电 | AW2: 垃圾焚烧发电 | AX2: 秸秆、蔗渣、林木质发电 | AZ2: 合计 | BA2: 燃煤 | BB2: 燃气 | BC2: 燃油 | BD2: 其他 | BE2: 合计 | BF2: 沼气发电 | BG2: 垃圾焚烧发电 | BH2: 秸秆、蔗渣、林木质发电
A3: 全国 | B3: 51770 | C3: 46296 | D3: 2525 | E3: 12 | F3: 2936 | G3: 1355 | H3: 38 | I3: 785 | J3: 533 | L3: 50465 | M3: 45538 | N3: 2325 | O3: 13 | P3: 2589 | Q3: 1126 | R3: 30.3 | S3: 611 | T3: 485 | V3: 49249 | W3: 44829 | X3: 2155 | Y3: 15 | Z3: 2249 | AA3: 936 | AB3: 22 | AC3: 485 | AD3: 429 | AF3: =SUM(AG3:AJ3) -> 45558 | AG3: 41498 | AH3: 2028 | AI3: 27 | AJ3: 2005 | AK3: 813 | AL3: 18 | AM3: 380 | AN3: 415 | AP3: =SUM(AQ3:AT3) -> 43273 | AQ3: 39462 | AR3: 1883 | AS3: 28 | AT3: 1900 | AU3: 687 | AV3: 21 | AW3: 315 | AX3: 351 | AZ3: =SUM(BA3:BD3) -> 43273 | BA3: 39462 | BB3: 1883 | BC3: 28 | BD3: 1900 | BE3: 687 | BF3: 21 | BG3: 315 | BH3: 351
A4: 北京 | B4: 434 | C4: 10 | D4: 397 | E4: 4 | F4: 23 | G4: 24 | H4: 1 | I4: 23 | L4: 443 | M4: 15 | N4: 404 | O4: 5 | P4: 20 | Q4: 19 | S4: 19 | V4: 433 | W4: 17 | X4: 395 | Y4: 5 | Z4: 15 | AA4: 15 | AC4: 15 | AF4: =SUM(AG4:AJ4) -> 377 | AG4: 13 | AH4: 347 | AI4: 4 | AJ4: 13 | AK4: 13 | AL4: 1 | AM4: 12 | AP4: =SUM(AQ4:AT4) -> 419 | AQ4: 34 | AR4: 371 | AS4: 6 | AT4: 8 | AU4: 8 | AV4: 1 | AW4: 7 | AZ4: =SUM(BA4:BD4) -> 419 | BA4: 34 | BB4: 371 | BC4: 6 | BD4: 8 | BE4: 8 | BF4: 1 | BG4: 7
A5: 天津 | B5: 668 | C5: 513 | D5: 134 | F5: 21 | G5: 10 | I5: 8 | J5: 3 | L5: 647 | M5: 518 | N5: 114 | P5: 14 | Q5: 9 | S5: 6 | T5: 3 | V5: 654 | W5: 531 | X5: 112 | Z5: 11 | AA5: 6 | AC5: 6 | AF5: =SUM(AG5:AJ5) -> 584 | AG5: 467 | AH5: 106 | AJ5: 11 | AK5: 5 | AM5: 5 | AP5: =SUM(AQ5:AT5) -> 591 | AQ5: 476 | AR5: 104 | AT5: 11 | AU5: 5 | AW5: 5 | AZ5: =SUM(BA5:BD5) -> 591 | BA5: 476 | BB5: 104 | BD5: 11 | BE5: 5 | BG5: 5
A6: 河北 | B6: 2352 | C6: 2224 | D6: 8 | F6: 120 | G6: 51 | I6: 22 | J6: 29 | L6: 2377 | M6: 2274 | N6: 1 | P6: 102 | Q6: 43 | R6: 0.3 | S6: 15 | T6: 27 | V6: 2361 | W6: 2266 | X6: 0.6 | Z6: 94 | AA6: 38 | AB6: 0.3 | AC6: 12 | AD6: 26 | AF6: =SUM(AG6:AJ6) -> 2295.4 | AG6: 2194 | AH6: 0.4 | AJ6: 101 | AK6: 34 | AL6: 0.2 | AM6: 10 | AN6: 23 | AP6: =SUM(AQ6:AT6) -> 2195 | AQ6: 2092 | AR6: 0 | AT6: 103 | AU6: 26 | AV6: 0 | AW6: 7 | AX6: 19 | AZ6: =SUM(BA6:BD6) -> 2195 | BA6: 2092 | BB6: 0 | BD6: 103 | BE6: 26 | BF6: 0 | BG6: 7 | BH6: 19
A7: 山西 | B7: 2924 | C7: 2722 | D7: 108 | F7: 95 | G7: 27 | H7: 0.2 | I7: 9 | J7: 18 | L7: 2852 | M7: 2666 | N7: 105 | P7: 82 | Q7: 27 | R7: 3 | S7: 6 | T7: 19 | V7: 2739 | W7: 2574 | X7: 100 | Z7: 64 | AA7: 25 | AB7: 2 | AC7: 6 | AD7: 16 | AF7: =SUM(AG7:AJ7) -> 2502 | AG7: 2335 | AH7: 110 | AJ7: 57 | AK7: 25 | AL7: 2 | AM7: 6 | AN7: 17 | AP7: =SUM(AQ7:AT7) -> 2309 | AQ7: 2191 | AR7: 95 | AT7: 23 | AU7: 22 | AV7: 5 | AW7: 6 | AX7: 11 | AZ7: =SUM(BA7:BD7) -> 2309 | BA7: 2191 | BB7: 95 | BD7: 23 | BE7: 22 | BF7: 5 | BG7: 6 | BH7: 11
A8: 内蒙古 | B8: 4731 | C8: 4677 | D8: 28.4 | F8: 25 | G8: 10 | H8: 0.1 | I8: 2 | J8: 8 | L8: 4564 | M8: 4551 | N8: 0.3 | P8: 12 | Q8: 8 | R8: 0.01 | S8: 2 | T8: 6 | V8: 4198 | W8: 4187 | X8: 0.4 | Z8: 11 | AA8: 8 | AB8: 0.03 | AC8: 2 | AD8: 6 | AF8: =SUM(AG8:AJ8) -> 3736.5 | AG8: 3726 | AH8: 0.5 | AJ8: 10 | AK8: 7 | AL8: 0.05 | AM8: 1 | AN8: 7 | AP8: =SUM(AQ8:AT8) -> 3375 | AQ8: 3364 | AR8: 0 | AT8: 11 | AU8: 7 | AW8: 1 | AX8: 7 | AZ8: =SUM(BA8:BD8) -> 3375 | BA8: 3364 | BB8: 0 | BD8: 11 | BE8: 7 | BG8: 1 | BH8: 7
A9: 辽宁 | B9: 1410 | C9: 1340 | D9: 3 | E9: 4 | F9: 63 | G9: 25 | H9: 1 | I9: 15 | J9: 9 | L9: 1395 | M9: 1343 | N9: 3 | O9: 4 | P9: 46 | Q9: 13 | S9: 6 | T9: 6 | V9: 1381 | W9: 1335 | X9: 2 | Y9: 6 | Z9: 39 | AA9: 9 | AC9: 5 | AD9: 4 | AF9: =SUM(AG9:AJ9) -> 1348 | AG9: 1306 | AH9: 1 | AI9: 5 | AJ9: 36 | AK9: 8 | AM9: 3 | AN9: 4 | AP9: =SUM(AQ9:AT9) -> 1345 | AQ9: 1306 | AR9: 1 | AS9: 5 | AT9: 33 | AU9: 6 | AW9: 2 | AX9: 3 | AZ9: =SUM(BA9:BD9) -> 1345 | BA9: 1306 | BB9: 1 | BC9: 5 | BD9: 33 | BE9: 6 | BG9: 2 | BH9: 3
A10: 吉林 | B10: 721 | C10: 677 | D10: 0.1 | F10: 45 | G10: 33 | H10: 0.03 | I10: 9 | J10: 24 | L10: 705 | M10: 659 | N10: 0.1 | P10: 46 | Q10: 35 | S10: 9 | T10: 26 | V10: 664 | W10: 627 | X10: 0. 1 | Z10: 37 | AA10: 27 | AC10: 6 | AD10: 21 | AF10: =SUM(AG10:AJ10) -> 606 | AG10: 568 | AH10: 0. 1 | AJ10: 38 | AK10: 28 | AL10: 0. 04 | AM10: 5 | AN10: 23 | AP10: =SUM(AQ10:AT10) -> 588 | AQ10: 550 | AR10: 0 | AT10: 38 | AU10: 28 | AV10: 0 | AW10: 4 | AX10: 23 | AZ10: =SUM(BA10:BD10) -> 588 | BA10: 550 | BB10: 0 | BD10: 38 | BE10: 28 | BF10: 0 | BG10: 4 | BH10: 23
A11: 黑龙江 | B11: 895 | C11: 815 | D11: 3 | F11: 76 | G11: 65 | H11: 0.3 | I11: 5 | J11: 59 | L11: 887 | M11: 818 | N11: 3 | P11: 66 | Q11: 58 | R11: 0.1 | S11: 5 | T11: 54 | V11: 859 | W11: 801 | X11: 3 | Y11: 0.3 | Z11: 54 | AA11: 51 | AB11: 0.1 | AC11: 3 | AD11: 47 | AF11: =SUM(AG11:AJ11) -> 815.3 | AG11: 762 | AH11: 2 | AI11: 0.3 | AJ11: 51 | AK11: 47 | AL11: 0.07 | AM11: 3 | AN11: 44 | AP11: =SUM(AQ11:AT11) -> 807 | AQ11: 761 | AR11: 3 | AS11: 0 | AT11: 43 | AU11: 39 | AV11: 0 | AW11: 2 | AX11: 37 | AZ11: =SUM(BA11:BD11) -> 807 | BA11: 761 | BB11: 3 | BC11: 0 | BD11: 43 | BE11: 39 | BF11: 0 | BG11: 2 | BH11: 37
A12: 上海 | B12: 835 | C12: 619 | D12: 152 | E12: 1 | F12: 63 | G12: 33 | H12: 1 | I12: 32 | L12: 812 | M12: 607 | N12: 149 | O12: 1 | P12: 55 | Q12: 26 | R12: 1.3 | S12: 24 | V12: 833 | W12: 649 | X12: 128 | Y12: 1 | Z12: 55 | AA12: 20 | AB12: 1 | AC12: 19 | AF12: =SUM(AG12:AJ12) -> 846 | AG12: 680 | AH12: 110 | AI12: 1 | AJ12: 55 | AK12: 19 | AL12: 1 | AM12: 18 | AP12: =SUM(AQ12:AT12) -> 817 | AQ12: 663 | AR12: 102 | AS12: 1 | AT12: 51 | AU12: 15 | AV12: 1 | AW12: 14 | AZ12: =SUM(BA12:BD12) -> 817 | BA12: 663 | BB12: 102 | BC12: 1 | BD12: 51 | BE12: 15 | BF12: 1 | BG12: 14
A13: 江苏 | B13: 4290 | C13: 3570 | D13: 477 | F13: 243 | G13: 126 | H13: 2 | I13: 86 | J13: 37 | L13: 4364 | M13: 3604 | N13: 532 | P13: 228 | Q13: 110 | R13: 2 | S13: 73 | T13: 35 | V13: 4462 | W13: 3711 | X13: 549 | Z13: 203 | AA13: 95 | AB13: 2 | AC13: 62 | AD13: 31 | AF13: =SUM(AG13:AJ13) -> 4481 | AG13: 3823 | AH13: 449 | AJ13: 209 | AK13: 90 | AL13: 1 | AM13: 57 | AN13: 33 | AP13: =SUM(AQ13:AT13) -> 4438 | AQ13: 3923 | AR13: 308 | AT13: 207 | AU13: 81 | AV13: 1 | AW13: 50 | AX13: 30 | AZ13: =SUM(BA13:BD13) -> 4438 | BA13: 3923 | BB13: 308 | BD13: 207 | BE13: 81 | BF13: 1 | BG13: 50 | BH13: 30
A14: 浙江 | B14: 2432 | C14: 2102 | D14: 163 | E14: 0.03 | F14: 166 | G14: 111 | H14: 3 | I14: 96 | J14: 13 | L14: 2507 | M14: 2193 | N14: 150 | O14: 0.02 | P14: 164 | Q14: 107 | R14: 2.8 | S14: 92 | T14: 12 | V14: 2598 | W14: 2298 | X14: 157 | Y14: 0.01 | Z14: 143 | AA14: 92 | AB14: 3 | AC14: 78 | AD14: 12 | AF14: =SUM(AG14:AJ14) -> 2543 | AG14: 2268 | AH14: 153 | AI14: 0. 02 | AJ14: 122 | AK14: 82 | AL14: 2 | AM14: 69 | AN14: 12 | AP14: =SUM(AQ14:AT14) -> 2366 | AQ14: 2098 | AR14: 156 | AS14: 0 | AT14: 112 | AU14: 71 | AV14: 1 | AW14: 61 | AX14: 9 | AZ14: =SUM(BA14:BD14) -> 2366 | BA14: 2098 | BB14: 156 | BC14: 0 | BD14: 112 | BE14: 71 | BF14: 1 | BG14: 61 | BH14: 9
A15: 安徽 | B15: 2531 | C15: 2314 | D15: 3 | F15: 214 | G15: 111 | H15: 0.4 | I15: 42 | J15: 69 | L15: 2657 | M15: 2463 | N15: 4 | P15: 190 | Q15: 98 | R15: 0.5 | S15: 33 | T15: 64 | V15: 2519 | W15: 2353 | X15: 4 | Z15: 161 | AA15: 77 | AB15: 1 | AC15: 28 | AD15: 49 | AF15: =SUM(AG15:AJ15) -> 2311 | AG15: 2151 | AH15: 5 | AJ15: 155 | AK15: 69 | AL15: 1 | AM15: 20 | AN15: 49 | AP15: =SUM(AQ15:AT15) -> 2134 | AQ15: 1997 | AR15: 6 | AT15: 131 | AU15: 55 | AV15: 0 | AW15: 17 | AX15: 38 | AZ15: =SUM(BA15:BD15) -> 2134 | BA15: 1997 | BB15: 6 | BD15: 131 | BE15: 55 | BF15: 0 | BG15: 17 | BH15: 38
A16: 福建 | B16: 1551 | C16: 1380 | D16: 64 | F16: 106 | G16: 39 | H16: 1 | I16: 35 | J16: 4 | L16: 1406 | M16: 1242 | N16: 67 | O16: 0.01 | P16: 98 | Q16: 31 | R16: 0.5 | S16: 27 | T16: 4 | V16: 1405 | W16: 1252 | X16: 64 | Z16: 89 | AA16: 28 | AB16: 0.2 | AC16: 25 | AD16: 3 | AF16: =SUM(AG16:AJ16) -> 1139.04 | AG16: 1007 | AH16: 60 | AI16: 0.04 | AJ16: 72 | AK16: 24 | AL16: 0.2 | AM16: 21 | AN16: 3 | AP16: =SUM(AQ16:AT16) -> 916 | AQ16: 781 | AR16: 67 | AS16: 1 | AT16: 67 | AU16: 22 | AV16: 0 | AW16: 19 | AX16: 3 | AZ16: =SUM(BA16:BD16) -> 916 | BA16: 781 | BB16: 67 | BC16: 1 | BD16: 67 | BE16: 22 | BF16: 0 | BG16: 19 | BH16: 3
A17: 江西 | B17: 1199 | C17: 1018 | D17: 4 | F17: 177 | G17: 32 | H17: 2 | I17: 17 | J17: 13 | L17: 1128 | M17: 973 | N17: 6 | P17: 149 | Q17: 20 | R17: 1.6 | S17: 9 | T17: 10 | V17: 1093 | W17: 956 | X17: 5 | Z17: 131 | AA17: 14 | AB17: 0.4 | AC17: 5 | AD17: 9 | AF17: =SUM(AG17:AJ17) -> 967 | AG17: 842 | AH17: 5 | AJ17: 120 | AK17: 17 | AL17: 0.2 | AM17: 3 | AN17: 14 | AP17: =SUM(AQ17:AT17) -> 856 | AQ17: 745 | AR17: 4 | AT17: 107 | AU17: 13 | AV17: 0 | AW17: 2 | AX17: 11 | AZ17: =SUM(BA17:BD17) -> 856 | BA17: 745 | BB17: 4 | BD17: 107 | BE17: 13 | BF17: 0 | BG17: 2 | BH17: 11
A18: 山东 | B18: 5116 | C18: 4752 | D18: 3 | F18: 362 | G18: 159 | H18: 3 | I18: 81 | J18: 75 | L18: 4680 | M18: 4381 | N18: 2 | P18: 297 | Q18: 141 | R18: 2.2 | S18: 64 | T18: 74 | V18: 4824 | W18: 4558 | X18: 2 | Z18: 264 | AA18: 135 | AB18: 2 | AC18: 51 | AD18: 81 | AF18: =SUM(AG18:AJ18) -> 4614 | AG18: 4378 | AH18: 1 | AJ18: 235 | AK18: 107 | AL18: 1 | AM18: 35 | AN18: 71 | AP18: =SUM(AQ18:AT18) -> 4671 | AQ18: 4455 | AR18: 3 | AT18: 213 | AU18: 89 | AV18: 3 | AW18: 27 | AX18: 59 | AZ18: =SUM(BA18:BD18) -> 4671 | BA18: 4455 | BB18: 3 | BD18: 213 | BE18: 89 | BF18: 3 | BG18: 27 | BH18: 59
A19: 河南 | B19: 2400 | C19: 2300 | D19: 29 | F19: 71 | G19: 51 | H19: 2 | I19: 12 | J19: 37 | L19: 2481 | M19: 2400 | N19: 24 | P19: 57 | Q19: 37 | S19: 9 | T19: 28 | V19: 2689 | W19: 2601 | X19: 39 | Z19: 49 | AA19: 30 | AC19: 7 | AD19: 23 | AF19: =SUM(AG19:AJ19) -> 2528 | AG19: 2457 | AH19: 31 | AJ19: 40 | AK19: 24 | AL19: 0.2 | AM19: 3 | AN19: 20 | AP19: =SUM(AQ19:AT19) -> 2474 | AQ19: 2403 | AR19: 34 | AT19: 37 | AU19: 23 | AW19: 4 | AX19: 18 | AZ19: =SUM(BA19:BD19) -> 2474 | BA19: 2403 | BB19: 34 | BD19: 37 | BE19: 23 | BG19: 4 | BH19: 18
A20: 湖北 | B20: 1243 | C20: 1102 | D20: 30 | F20: 111 | G20: 37 | H20: 2 | I20: 19 | J20: 17 | L20: 1485 | M20: 1351 | N20: 33 | P20: 102 | Q20: 30 | R20: 1.1 | S20: 15 | T20: 13 | V20: 1267 | W20: 1139 | X20: 31 | Z20: 97 | AA20: 25 | AB20: 0.6 | AC20: 14 | AD20: 11 | AF20: =SUM(AG20:AJ20) -> 1075 | AG20: 945 | AH20: 28 | AJ20: 102 | AK20: 37 | AL20: 0.3 | AM20: 13 | AN20: 24 | AP20: =SUM(AQ20:AT20) -> 1048 | AQ20: 928 | AR20: 28 | AT20: 92 | AU20: 34 | AV20: 0 | AW20: 12 | AX20: 22 | AZ20: =SUM(BA20:BD20) -> 1048 | BA20: 928 | BB20: 28 | BD20: 92 | BE20: 34 | BF20: 0 | BG20: 12 | BH20: 22
A21: 湖南 | B21: 849 | C21: 710 | D21: 3 | E21: 3 | F21: 134 | G21: 39 | H21: 2 | I21: 25 | J21: 12 | L21: 906 | M21: 776 | N21: 2 | O21: 3 | P21: 124 | Q21: 32 | R21: 1.1 | S21: 19 | T21: 1 | V21: 919 | W21: 792 | X21: 2 | Y21: 3 | Z21: 122 | AA21: 30 | AB21: 1 | AC21: 16 | AD21: 13 | AF21: =SUM(AG21:AJ21) -> 786 | AG21: 667 | AH21: 1 | AI21: 3 | AJ21: 115 | AK21: 22 | AL21: 1 | AM21: 5 | AN21: 16 | AP21: =SUM(AQ21:AT21) -> 732 | AQ21: 614 | AR21: 6 | AS21: 3 | AT21: 109 | AU21: 19 | AV21: 6 | AW21: 4 | AX21: 9 | AZ21: =SUM(BA21:BD21) -> 732 | BA21: 614 | BB21: 6 | BC21: 3 | BD21: 109 | BE21: 19 | BF21: 6 | BG21: 4 | BH21: 9
A22: 广东 | B22: 3425 | C22: 2518 | D22: 751 | F22: 156 | G22: 166 | H22: 10 | I22: 131 | J22: 25 | L22: 3222 | M22: 2508 | N22: 594 | P22: 120 | Q22: 120 | R22: 8.2 | S22: 93 | T22: 19 | V22: 3283 | W22: 2766 | X22: 434 | Z22: 83 | AA22: 81 | AB22: 5 | AC22: 61 | AD22: 15 | AF22: =SUM(AG22:AJ22) -> 3164 | AG22: 2578 | AH22: 515 | AI22: 13 | AJ22: 58 | AK22: 61 | AL22: 5 | AM22: 42 | AN22: 15 | AP22: =SUM(AQ22:AT22) -> 2850 | AQ22: 2297 | AR22: 489 | AS22: 12 | AT22: 52 | AU22: 49 | AV22: 2 | AW22: 35 | AX22: 11 | AZ22: =SUM(BA22:BD22) -> 2850 | BA22: 2297 | BB22: 489 | BC22: 12 | BD22: 52 | BE22: 49 | BF22: 2 | BG22: 35 | BH22: 11
A23: 广西 | B23: 1032 | C23: 865 | D23: 9 | F23: 157 | G23: 58 | H23: 1 | I23: 13 | J23: 43 | L23: 988 | M23: 833 | N23: 5 | P23: 150 | Q23: 52 | R23: 1.1 | S23: 11 | T23: 40 | V23: 796 | W23: 649 | X23: 6 | Z23: 141 | AA23: 40 | AB23: 1 | AC23: 8 | AD23: 31 | AF23: =SUM(AG23:AJ23) -> 575 | AG23: 444 | AH23: 2 | AJ23: 129 | AK23: 33 | AL23: 1 | AM23: 5 | AN23: 27 | AP23: =SUM(AQ23:AT23) -> 558 | AQ23: 360 | AR23: 1 | AT23: 197 | AU23: 30 | AW23: 3 | AX23: 27 | AZ23: =SUM(BA23:BD23) -> 558 | BA23: 360 | BB23: 1 | BD23: 197 | BE23: 30 | BG23: 3 | BH23: 27
A24: 海南 | B24: 215 | C24: 160 | D24: 28 | F24: 28 | G24: 22 | H24: 0.4 | I24: 7 | J24: 14 | L24: 212 | M24: 173 | N24: 14 | P24: 25 | Q24: 20 | R24: 0.3 | S24: 5 | T24: 14 | V24: 211 | W24: 174 | X24: 12 | Z24: 26 | AA24: 20 | AB24: 0.2 | AC24: 5 | AD24: 14 | AF24: =SUM(AG24:AJ24) -> 195 | AG24: 173 | AH24: 11 | AJ24: 11 | AK24: 5 | AL24: 0.2 | AM24: 5 | AP24: =SUM(AQ24:AT24) -> 197 | AQ24: 176 | AR24: 10 | AT24: 11 | AU24: 5 | AV24: 0 | AW24: 5 | AZ24: =SUM(BA24:BD24) -> 197 | BA24: 176 | BB24: 10 | BD24: 11 | BE24: 5 | BF24: 0 | BG24: 5
A25: 重庆 | B25: 538 | C25: 458 | D25: 42 | F25: 38 | G25: 21 | H25: 0.1 | I25: 19 | J25: 2 | L25: 554 | M25: 467 | N25: 50 | P25: 37 | Q25: 19 | R25: 0.1 | S25: 17 | T25: 2 | V25: 547 | W25: 469 | X25: 49 | Z25: 29 | AA25: 12 | AB25: 0.5 | AC25: 10 | AD25: 1 | AF25: =SUM(AG25:AJ25) -> 467 | AG25: 405 | AH25: 37 | AJ25: 25 | AK25: 10 | AL25: 1 | AM25: 7 | AN25: 2 | AP25: =SUM(AQ25:AT25) -> 431 | AQ25: 371 | AR25: 36 | AT25: 24 | AU25: 8 | AV25: 0 | AW25: 6 | AX25: 2 | AZ25: =SUM(BA25:BD25) -> 431 | BA25: 371 | BB25: 36 | BD25: 24 | BE25: 8 | BF25: 0 | BG25: 6 | BH25: 2
A26: 四川 | B26: 513 | C26: 361 | D26: 26 | F26: 125 | G26: 50 | H26: 3 | I26: 35 | J26: 12 | L26: 488 | M26: 352 | N26: 26 | P26: 110 | Q26: 40 | R26: 2.5 | S26: 28 | T26: 9 | V26: 435 | W26: 315 | X26: 22 | Z26: 97 | AA26: 29 | AB26: 2 | AC26: 22 | AD26: 6 | AF26: =SUM(AG26:AJ26) -> 354 | AG26: 249 | AH26: 19 | AJ26: 86 | AK26: 21 | AL26: 1 | AM26: 18 | AN26: 2 | AP26: =SUM(AQ26:AT26) -> 349 | AQ26: 273 | AR26: 22 | AT26: 54 | AU26: 14 | AW26: 12 | AX26: 2 | AZ26: =SUM(BA26:BD26) -> 349 | BA26: 273 | BB26: 22 | BD26: 54 | BE26: 14 | BG26: 12 | BH26: 2
A27: 贵州 | B27: 1354 | C27: 1323 | D27: 19 | F27: 12 | G27: 12 | I27: 11 | J27: 1 | L27: 1390 | M27: 1381 | P27: 8 | Q27: 8 | S27: 7 | T27: 1 | V27: 1263 | W27: 1254 | Z27: 9 | AA27: 9 | AC27: 6 | AD27: 3 | AF27: =SUM(AG27:AJ27) -> 1210 | AG27: 1201 | AJ27: 9 | AK27: 6 | AM27: 2 | AN27: 4 | AP27: =SUM(AQ27:AT27) -> 1172 | AQ27: 1167 | AT27: 5 | AU27: 5 | AW27: 1 | AX27: 3 | AZ27: =SUM(BA27:BD27) -> 1172 | BA27: 1167 | BD27: 5 | BE27: 5 | BG27: 1 | BH27: 3
A28: 云南 | B28: 415 | C28: 318 | D28: 0.5 | F28: 97 | G28: 14 | H28: 0.1 | I28: 7 | J28: 7 | L28: 318 | M28: 223 | N28: 0.5 | P28: 95 | Q28: 9 | S28: 6 | T28: 3 | V28: 290 | W28: 207 | X28: 0.5 | Z28: 82 | AA28: 9 | AC28: 7 | AD28: 3 | AF28: =SUM(AG28:AJ28) -> 240 | AG28: 167 | AH28: 1 | AJ28: 72 | AK28: 8 | AM28: 6 | AN28: 2 | AP28: =SUM(AQ28:AT28) -> 252 | AQ28: 170 | AR28: 0 | AT28: 82 | AU28: 7 | AW28: 5 | AX28: 2 | AZ28: =SUM(BA28:BD28) -> 252 | BA28: 170 | BB28: 0 | BD28: 82 | BE28: 7 | BG28: 5 | BH28: 2
A29: 西藏 | B29: 1 | F29: 1 | G29: 1 | I29: 1 | L29: 1 | O29: 0.4 | P29: 1 | Q29: 1 | S29: 1 | V29: 1.2 | Y29: 0.6 | Z29: 1 | AA29: 1 | AC29: 1 | AF29: =SUM(AG29:AJ29) -> 0.4 | AI29: 0.4 | AP29: =SUM(AQ29:AT29) -> 0 | AS29: 0 | AZ29: =SUM(BA29:BD29) -> 0 | BC29: 0
A30: 陕西 | B30: 2084 | C30: 1974 | D30: 8 | F30: 103 | G30: 16 | H30: 1 | I30: 13 | J30: 1 | L30: 1917 | M30: 1828 | N30: 5 | P30: 84 | Q30: 3 | R30: 1.3 | S30: 1 | T30: 11 | V30: 1761 | W30: 1679 | X30: 5 | Z30: 78 | AA30: 2 | AC30: 2 | AF30: =SUM(AG30:AJ30) -> 1427 | AG30: 1404 | AJ30: 23 | AK30: 2 | AM30: 1 | AN30: 1 | AP30: =SUM(AQ30:AT30) -> 1346 | AQ30: 1331 | AT30: 15 | AU30: 1 | AW30: 1 | AZ30: =SUM(BA30:BD30) -> 1346 | BA30: 1331 | BD30: 15 | BE30: 1 | BG30: 1
A31: 甘肃 | B31: 901 | C31: 885 | F31: 16 | G31: 6 | I31: 6 | J31: 0.1 | L31: 817 | M31: 803 | P31: 14 | Q31: 6 | S31: 5 | T31: 1 | V31: 830 | W31: 821 | Z31: 9 | AA31: 5 | AC31: 4 | AD31: 1 | AF31: =SUM(AG31:AJ31) -> 707 | AG31: 696 | AH31: 0. 1 | AJ31: 11 | AK31: 5 | AM31: 3 | AN31: 2 | AP31: =SUM(AQ31:AT31) -> 699 | AQ31: 694 | AR31: 0 | AT31: 5 | AU31: 2 | AW31: 1 | AX31: 1 | AZ31: =SUM(BA31:BD31) -> 699 | BA31: 694 | BB31: 0 | BD31: 5 | BE31: 2 | BG31: 1 | BH31: 1
A32: 青海 | B32: 101 | C32: 100 | D32: 0.1 | F32: 1 | G32: 0.1 | H32: 0.1 | L32: 104 | M32: 100 | N32: 0.1 | P32: 4 | Q32: 0.1 | R32: 0.1 | V32: 120 | W32: 118 | X32: 0.2 | Z32: 1 | AA32: 0.2 | AB32: 0.2 | AF32: =SUM(AG32:AJ32) -> 153 | AG32: 152 | AJ32: 1 | AK32: 0.2 | AM32: 0.2 | AP32: =SUM(AQ32:AT32) -> 151 | AQ32: 150 | AR32: 1 | AS32: 0 | AZ32: =SUM(BA32:BD32) -> 151 | BA32: 150 | BB32: 1 | BC32: 0
A33: 宁夏 | B33: 1415 | C33: 1351 | D33: 12 | F33: 52 | G33: 3 | I33: 3 | J33: 0.1 | L33: 1381 | M33: 1310 | N33: 13 | P33: 58 | Q33: 2 | S33: 2 | T33: 0.02 | V33: 1310 | W33: 1240 | X33: 16 | Z33: 54 | AA33: 2 | AC33: 2 | AD33: 0.1 | AF33: =SUM(AG33:AJ33) -> 1159 | AG33: 1113 | AH33: 11 | AJ33: 35 | AK33: 2 | AM33: 1 | AN33: 1 | AP33: =SUM(AQ33:AT33) -> 989 | AQ33: 943 | AR33: 15 | AT33: 31 | AU33: 3 | AW33: 2 | AX33: 1 | AZ33: =SUM(BA33:BD33) -> 989 | BA33: 943 | BB33: 15 | BD33: 31 | BE33: 3 | BG33: 2 | BH33: 1
A34: 新疆 | B34: 3193 | C34: 3137 | D34: 18 | F34: 38 | G34: 4 | H34: 0.1 | I34: 2 | J34: 2 | L34: 2777 | M34: 2726 | N34: 19 | P34: 32 | Q34: 3 | R34: 0.1 | S34: 1 | T34: 2 | V34: 2506 | W34: 2488 | X34: 16 | Z34: 2 | AA34: 2 | AD34: 2 | AF34: =SUM(AG34:AJ34) -> 2348 | AG34: 2326 | AH34: 20 | AJ34: 2 | AK34: 2 | AL34: 0 | AN34: 2 | AP34: =SUM(AQ34:AT34) -> 2194 | AQ34: 2149 | AR34: 17 | AT34: 28 | AU34: 2 | AX34: 2 | AZ34: =SUM(BA34:BD34) -> 2194 | BA34: 2149 | BB34: 17 | BD34: 28 | BE34: 2 | BH34: 2

Sheet Generation Fuel Consumption
A1: 索引 | B1: 地区 | C1: 年份 | D1: 项目 | E1: 能源品种 | F1: 能源品种 | G1: 实物消费量 | H1: 标煤消费量 | K1: 求和项:标煤消费量 | L1: 列标签
A2: 50936 | B2: 安徽省 | C2: 2019 | D2: 2.1. 火力发电 | E2: 柴油(万吨) | F2: =VLOOKUP(E2,'Fuel Heat Rate'!C:D,2,FALSE) -> 燃油 | G2: -0.38 | H2: =VLOOKUP($E2,'Fuel Heat Rate'!$C$3:$K$33,4,FALSE)*G2 -> -0.553698 | L2: 电力 | O2: 煤矸石 | R2: 其他 | U2: 燃煤 | X2: 燃气 | AA2: 燃油 | AD2: 生物质 | AG2: 总计
A3: 50901 | B3: 安徽省 | C3: 2020 | D3: 2.1. 火力发电 | E3: 柴油(万吨) | F3: =VLOOKUP(E3,'Fuel Heat Rate'!C:D,2,FALSE) -> 燃油 | G3: -0.39 | H3: =VLOOKUP($E3,'Fuel Heat Rate'!$C$3:$K$33,4,FALSE)*G3 -> -0.568269 | K3: 行标签 | L3: 2019 | M3: 2020 | N3: 2021 | O3: 2019 | P3: 2020 | Q3: 2021 | R3: 2019 | S3: 2020 | T3: 2021 | U3: 2019 | V3: 2020 | W3: 2021 | X3: 2019 | Y3: 2020 | Z3: 2021 | AA3: 2019 | AB3: 2020 | AC3: 2021 | AD3: 2019 | AE3: 2020 | AF3: 2021
A4: 17686 | B4: 安徽省 | C4: 2021 | D4: 2.1. 火力发电 | E4: 柴油(万吨) | F4: =VLOOKUP(E4,'Fuel Heat Rate'!C:D,2,FALSE) -> 燃油 | G4: -0.35 | H4: =VLOOKUP($E4,'Fuel Heat Rate'!$C$3:$K$33,4,FALSE)*G4 -> -0.509985 | K4: 安徽省 | L4: 3276.492 | M4: 3143.4998 | N4: 3371.5531 | O4: -60.712215 | P4: -62.998114 | Q4: -58.331905 | R4: -287.91561 | S4: -284.25692 | T4: -295.09122 | U4: -7337.663 | V4: -6860.1557 | W4: -7389.8501 | X4: -20.7765 | Y4: -21.7485 | Z4: -22.113 | AA4: -0.553698 | AB4: -0.568269 | AC4: -1.122831 | AD4: -307.3705 | AE4: -404.20381 | AF4: -428.77465 | AG4: -14052.662
A5: 51496 | B5: 安徽省 | C5: 2019 | D5: 2.1. 火力发电 | E5: 电力(亿千瓦小时) | F5: =VLOOKUP(E5,'Fuel Heat Rate'!C:D,2,FALSE) -> 电力 | G5: 2663.97 | H5: =VLOOKUP($E5,'Fuel Heat Rate'!$C$3:$K$33,4,FALSE)*G5 -> 3276.492 | K5: 北京市 | L5: 544.88282 | M5: 536.35941 | N5: 551.84421 | S5: -10.996242 | T5: -11.22412 | U5: -25.636227 | V5: -15.514596 | W5: -21.771864 | X5: -842.86114 | Y5: -812.74779 | Z5: -838.74622 | AA5: -8.3459378 | AB5: -7.5347783 | AC5: -1.0351563 | AD5: -119.43408 | AE5: -135.96465 | AF5: -140.28479 | AG5: -1359.0112
A6: 51461 | B6: 安徽省 | C6: 2020 | D6: 2.1. 火力发电 | E6: 电力(亿千瓦小时) | F6: =VLOOKUP(E6,'Fuel Heat Rate'!C:D,2,FALSE) -> 电力 | G6: 2555.84 | H6: =VLOOKUP($E6,'Fuel Heat Rate'!$C$3:$K$33,4,FALSE)*G6 -> 3143.4998 | K6: 福建省 | L6: 1729.439 | M6: 1925.219 | N6: 2118.453 | R6: -133.29006 | S6: -152.7933 | T6: -174.49573 | U6: -3872.9775 | V6: -4174.2978 | W6: -4769.8097 | X6: -155.277 | Y6: -146.8935 | Z6: -158.5575 | AA6: -80.025182 | AB6: -58.123121 | AC6: -54.918494 | AD6: -156.90536 | AE6: -230.00786 | AF6: -250.12855 | AG6: -8795.3895
A7: 32876 | B7: 安徽省 | C7: 2021 | D7: 2.1. 火力发电 | E7: 电力(亿千瓦小时) | F7: =VLOOKUP(E7,'Fuel Heat Rate'!C:D,2,FALSE) -> 电力 | G7: 2741.26 | H7: =VLOOKUP($E7,'Fuel Heat Rate'!$C$3:$K$33,4,FALSE)*G7 -> 3371.5531 | K7: 甘肃省 | L7: 1016.6218 | M7: 1121.6085 | N7: 1284.9306 | O7: -11.063293 | P7: -6.7289539 | Q7: -8.4455237 | R7: -21.269559 | S7: -36.472839 | T7: -42.995217 | U7: -2599.652 | V7: -2845.5569 | W7: -3380.9248 | X7: -11.664 | Z7: -3.888 | AA7: -1.375116 | AB7: -1.111977 | AC7: -1.271118 | AD7: -23.960819 | AE7: -31.771085 | AF7: -35.291206 | AG7: -5640.2815
A8: 52056 | B8: 安徽省 | C8: 2019 | D8: 2.1. 火力发电 | E8: 高炉煤气(亿立方米) | F8: =VLOOKUP(E8,'Fuel Heat Rate'!C:D,2,FALSE) -> 0 | G8: -118.87 | H8: =VLOOKUP($E8,'Fuel Heat Rate'!$C$3:$K$33,4,FALSE)*G8 -> -152.82125 | K8: 广东省 | L8: 4223.4383 | M8: 4431.5791 | N8: 5705.1083 | O8: -68.794398 | P8: -97.006224 | Q8: -87.167418 | R8: -117.76016 | S8: -144.34575 | T8: -183.32901 | U8: -7958.6047 | V8: -7780.6691 | W8: -10644.211 | X8: -1327.7336 | Y8: -1721.1033 | Z8: -2052.0069 | AA8: -67.711535 | AB8: -77.620083 | AC8: -67.046797 | AD8: -524.80793 | AE8: -813.8578 | AF8: -917.60135 | AG8: -20291.252
A9: 52021 | B9: 安徽省 | C9: 2020 | D9: 2.1. 火力发电 | E9: 高炉煤气(亿立方米) | F9: =VLOOKUP(E9,'Fuel Heat Rate'!C:D,2,FALSE) -> 0 | G9: -156.9 | H9: =VLOOKUP($E9,'Fuel Heat Rate'!$C$3:$K$33,4,FALSE)*G9 -> -201.71326 | K9: 广西壮族自治区 | L9: 1237.9351 | M9: 1309.7383 | N9: 1469.2969 | Q9: -62.445951 | R9: -189.63888 | S9: -258.35975 | T9: -247.45097 | U9: -2938.6802 | V9: -2909.5153 | W9: -3039.5304 | X9: -14.7015 | Y9: -23.142732 | Z9: -22.891692 | AA9: -15.026551 | AB9: -29.008194 | AC9: -56.607695 | AD9: -228.63781 | AE9: -223.28763 | AF9: -235.09803 | AG9: -6477.0531
A10: 9006 | B10: 安徽省 | C10: 2021 | D10: 2.1. 火力发电 | E10: 高炉煤气(亿立方米) | F10: =VLOOKUP(E10,'Fuel Heat Rate'!C:D,2,FALSE) -> 0 | G10: -145.94 | H10: =VLOOKUP($E10,'Fuel Heat Rate'!$C$3:$K$33,4,FALSE)*G10 -> -187.6229 | K10: 贵州省 | L10: 1709.1206 | M10: 1638.3997 | N10: 1779.1896 | O10: -29.716685 | P10: -35.770455 | Q10: -46.144259 | R10: -148.17424 | S10: -153.6481 | T10: -140.23984 | U10: -3919.3962 | V10: -3353.6464 | W10: -4159.7827 | X10: -42.4035 | Y10: -62.208 | Z10: -65.2455 | AA10: -3.890457 | AB10: -3.744747 | AC10: -4.487868 | AD10: -43.951502 | AE10: -68.48234 | AF10: -77.022631 | AG10: -7231.2454
A11: 52441 | B11: 安徽省 | C11: 2019 | D11: 2.1. 火力发电 | E11: 焦炉煤气(亿立方米) | F11: =VLOOKUP(E11,'Fuel Heat Rate'!C:D,2,FALSE) -> 0 | G11: -6.61 | H11: =VLOOKUP($E11,'Fuel Heat Rate'!$C$3:$K$33,4,FALSE)*G11 -> -39.187385 | K11: 海南省 | L11: 261.31056 | M11: 262.04851 | N11: 312.88145 | R11: -38.932354 | S11: -36.920396 | T11: -46.536044 | U11: -597.0048 | V11: -540.74653 | W11: -603.24064 | X11: -35.478 | Y11: -72.657 | Z11: -127.9395 | AA11: -0.043713 | AB11: -0.029142 | AC11: -0.029142 | AD11: -32.721118 | AE11: -26.660911 | AF11: -50.111712 | AG11: -1372.8105
A12: 52406 | B12: 安徽省 | C12: 2020 | D12: 2.1. 火力发电 | E12: 焦炉煤气(亿立方米) | F12: =VLOOKUP(E12,'Fuel Heat Rate'!C:D,2,FALSE) -> 0 | G12: -6.53 | H12: =VLOOKUP($E12,'Fuel Heat Rate'!$C$3:$K$33,4,FALSE)*G12 -> -38.713105 | K12: 河北省 | L12: 3493.5743 | M12: 3482.8247 | N12: 3319.2566 | O12: -89.138612 | P12: -79.61451 | Q12: -66.162325 | R12: -417.55996 | S12: -505.67919 | T12: -559.48753 | U12: -6731.6439 | V12: -6634.0393 | W12: -6613.8862 | X12: -9.5985 | Y12: -17.739 | Z12: -20.5335 | AA12: -4.8560111 | AB12: -6.5916418 | AC12: -6.7059146 | AD12: -190.3965 | AE12: -226.96775 | AF12: -242.78829 | AG12: -12127.733
A13: 7921 | B13: 安徽省 | C13: 2021 | D13: 2.1. 火力发电 | E13: 焦炉煤气(亿立方米) | F13: =VLOOKUP(E13,'Fuel Heat Rate'!C:D,2,FALSE) -> 0 | G13: -4.74 | H13: =VLOOKUP($E13,'Fuel Heat Rate'!$C$3:$K$33,4,FALSE)*G13 -> -28.10109 | K13: 河南省 | L13: 3140.6218 | M13: 3093.4417 | N13: 3024.1107 | O13: -59.032838 | P13: -38.64571 | Q13: -41.369334 | R13: -123.01298 | S13: -143.54629 | T13: -137.01811 | U13: -7164.705 | V13: -6847.7372 | W13: -6863.6887 | X13: -48.2355 | Y13: -47.385 | Z13: -40.9455 | AA13: -8.5948444 | AB13: -10.554984 | AC13: -9.9808978 | AD13: -326.05114 | AE13: -353.43207 | AF13: -348.86192 | AG13: -13354.624
A14: 27451 | B14: 安徽省 | C14: 2021 | D14: 2.1. 火力发电 | E14: 炼厂干气(万吨) | F14: =VLOOKUP(E14,'Fuel Heat Rate'!C:D,2,FALSE) -> 燃油 | G14: -0.39 | H14: =VLOOKUP($E14,'Fuel Heat Rate'!$C$3:$K$33,4,FALSE)*G14 -> -0.612846 | K14: 黑龙江省 | L14: 1119.5176 | M14: 1133.711 | N14: 1166.7837 | O14: -108.38136 | P14: -108.08954 | Q14: -94.628775 | S14: -3.017424 | T14: -28.411343 | U14: -3165.471 | V14: -3001.5778 | W14: -3267.0935 | X14: -16.4025 | Y14: -26.692716 | Z14: -24.057 | AA14: -8.907858 | AB14: -10.232688 | AC14: -7.415613 | AD14: -614.771 | AE14: -333.43139 | AF14: -325.16111 | AG14: -7723.7303
A15: 54121 | B15: 安徽省 | C15: 2019 | D15: 2.1. 火力发电 | E15: 煤矸石(万吨) | F15: =VLOOKUP(E15,'Fuel Heat Rate'!C:D,2,FALSE) -> 煤矸石 | G15: -212.21 | H15: =VLOOKUP($E15,'Fuel Heat Rate'!$C$3:$K$33,4,FALSE)*G15 -> -60.712215 | K15: 湖北省 | L15: 1807.9207 | M15: 1503.2552 | N15: 1815.3864 | Q15: -7.0980164 | R15: -92.896481 | S15: -126.81004 | T15: -126.81004 | U15: -3825.7408 | V15: -3032.3678 | W15: -3647.5372 | X15: -81.2835 | Y15: -67.068 | Z15: -86.022 | AA15: -3.3221903 | AB15: -7.9819016 | AC15: -20.894463 | AD15: -140.5448 | AE15: -130.07444 | AF15: -149.01509 | AG15: -6418.9044
A16: 54086 | B16: 安徽省 | C16: 2020 | D16: 2.1. 火力发电 | E16: 煤矸石(万吨) | F16: =VLOOKUP(E16,'Fuel Heat Rate'!C:D,2,FALSE) -> 煤矸石 | G16: -220.2 | H16: =VLOOKUP($E16,'Fuel Heat Rate'!$C$3:$K$33,4,FALSE)*G16 -> -62.998114 | K16: 湖南省 | L16: 1124.8924 | M16: 1047.739 | N16: 1250.4681 | O16: -34.065329 | P16: -28.094527 | Q16: -18.10409 | S16: -8.3163649 | T16: -74.54766 | U16: -2371.8046 | V16: -2116.5423 | W16: -2611.2308 | X16: -0.3645 | Y16: -1.701 | Z16: -1.8225 | AA16: -16.487929 | AB16: -17.955993 | AC16: -17.862709 | AD16: -185.87635 | AE16: -244.98837 | AF16: -192.88659 | AG16: -4519.5522
