Workbook

Sheet BAU燃油经济性
A1: 手动输入区域 | B1: 起始年 | C1: 终止年 | D1: 乘用车 | F1: 出租车 | H1: 轻型货车 | J1: 中型公交车 | L1: 道路客车 | N1: 中型货车 | P1: 重型货车 | R1: 大型公交车
A2: stage | D2: PV(汽油) | E2: PV(柴油) | F2: Taxi(汽油) | G2: Taxi(柴油) | H2: l_Truck(汽油) | I2: l_Truck(柴油) | J2: city bus(汽油) | K2: city bus(柴油) | L2: road bus(汽油) | M2: road bus(柴油) | N2: h_Truck(汽油) | O2: h_Truck(柴油) | P2: h_Truck(汽油) | Q2: h_Truck(柴油) | R2: h_Truck(汽油) | S2: h_Truck(柴油)
A3: 阶段0 | B3: 2001 | C3: 5 | D3: 11.61 | E3: 0 | F3: 11.61 | G3: 0 | H3: 19.52 | I3: 13.82 | J3: 0 | K3: 14.83 | L3: 0 | M3: 28.22 | N3: 0 | O3: 25.3 | P3: 0 | Q3: 47.75 | R3: 0 | S3: 28.22
B4: 2002 | D4: =D3-0.2 -> 11.41 | F4: =F3-0.2 -> 11.41 | H4: =H3-0.34 -> 19.18 | I4: =I3-0.14 -> 13.68 | K4: =K3-0.58 -> 14.25 | M4: =M3-1.12 -> 27.1 | O4: =O3-1.34 -> 23.96 | Q4: =Q3-1.32 -> 46.43 | S4: =S3-1.12 -> 27.1
B5: 2003 | D5: =D4-0.2 -> 11.21 | F5: =F4-0.2 -> 11.21 | H5: =H4-0.34 -> 18.84 | I5: =I4-0.14 -> 13.54 | K5: =K4-0.58 -> 13.67 | M5: =M4-1.12 -> 25.98 | O5: =O4-1.34 -> 22.62 | Q5: =Q4-1.32 -> 45.11 | S5: =S4-1.12 -> 25.98
B6: 2004 | D6: =D5-0.2 -> 11.01 | F6: =F5-0.2 -> 11.01 | H6: =H5-0.34 -> 18.5 | I6: =I5-0.14 -> 13.4 | K6: =K5-0.58 -> 13.09 | M6: =M5-1.12 -> 24.86 | O6: =O5-1.34 -> 21.28 | Q6: =Q5-1.32 -> 43.79 | S6: =S5-1.12 -> 24.86
B7: 2005 | D7: =D6-0.2 -> 10.81 | F7: =F6-0.2 -> 10.81 | H7: =H6-0.34 -> 18.16 | I7: =I6-0.14 -> 13.26 | K7: =K6-0.58 -> 12.51 | M7: =M6-1.12 -> 23.74 | O7: =O6-1.34 -> 19.94 | Q7: =Q6-1.32 -> 42.47 | S7: =S6-1.12 -> 23.74
A8: 阶段1 | B8: 2006 | C8: 10 | D8: =D7-0.2 -> 10.61 | E8: 0 | F8: =F7-0.2 -> 10.61 | G8: 0 | H8: =H7-0.34 -> 17.82 | I8: =I7-0.14 -> 13.12 | J8: 0 | K8: =K7-0.58 -> 11.93 | L8: 0 | M8: =M7-1.12 -> 22.62 | N8: 0 | O8: 18.55 | P8: 0 | Q8: 41.22 | R8: 0 | S8: =S7-1.12 -> 22.62
B9: 2007 | D9: =D8-0.2 -> 10.41 | F9: =F8-0.2 -> 10.41 | H9: =H8-0.34 -> 17.48 | I9: =I8-0.16 -> 12.96 | K9: =K8-0.26 -> 11.67 | M9: =M8-0.46 -> 22.16 | O9: =O8-0.44 -> 18.11 | Q9: =Q8-0.96 -> 40.26 | S9: =S8-0.46 -> 22.16
B10: 2008 | D10: =D9-0.2 -> 10.21 | F10: =F9-0.2 -> 10.21 | H10: =H9-0.34 -> 17.14 | I10: =I9-0.16 -> 12.8 | K10: =K9-0.26 -> 11.41 | M10: =M9-0.46 -> 21.7 | O10: =O9-0.44 -> 17.67 | Q10: =Q9-0.96 -> 39.3 | S10: =S9-0.46 -> 21.7
B11: 2009 | D11: =D10-0.2 -> 10.01 | F11: =F10-0.2 -> 10.01 | H11: =H10-0.34 -> 16.8 | I11: =I10-0.16 -> 12.64 | K11: =K10-0.26 -> 11.15 | M11: =M10-0.46 -> 21.24 | O11: =O10-0.44 -> 17.23 | Q11: =Q10-0.96 -> 38.34 | S11: =S10-0.46 -> 21.24
B12: 2010 | D12: =D11-0.2 -> 9.81 | F12: =F11-0.2 -> 9.81 | H12: =H11-0.34 -> 16.46 | I12: =I11-0.16 -> 12.48 | K12: =K11-0.26 -> 10.89 | M12: =M11-0.46 -> 20.78 | O12: =O11-0.44 -> 16.79 | Q12: =Q11-0.96 -> 37.38 | S12: =S11-0.46 -> 20.78
A13: 阶段2 | B13: 2011 | C13: 15 | D13: 9.6 | E13: 0 | F13: 9.6 | G13: 0 | H13: =H12-0.34 -> 16.12 | I13: =I12-0.16 -> 12.32 | J13: 0 | K13: 10.57 | L13: 0 | M13: =M12-0.46 -> 20.32 | N13: 0 | O13: =O12-0.44 -> 16.35 | P13: 0 | Q13: 36.38 | R13: 0 | S13: 20.33
B14: 2012 | D14: 9.6 | F14: 9.6 | H14: =H13-0.76 -> 15.36 | I14: =I13-0.44 -> 11.88 | K14: =K13-0.32 -> 10.25 | M14: =M13-0.52 -> 19.8 | O14: =O13-0.48 -> 15.87 | Q14: =Q13-1.04 -> 35.34 | S14: =S13-0.52 -> 19.81
B15: 2013 | D15: 9.6 | F15: 9.6 | H15: =H14-0.76 -> 14.6 | I15: =I14-0.44 -> 11.44 | K15: =K14-0.32 -> 9.93 | M15: =M14-0.52 -> 19.28 | O15: =O14-0.48 -> 15.39 | Q15: =Q14-1.04 -> 34.3 | S15: =S14-0.52 -> 19.29
B16: 2014 | D16: 9.6 | F16: 9.6 | H16: =H15-0.76 -> 13.84 | I16: =I15-0.44 -> 11 | K16: =K15-0.32 -> 9.61 | M16: =M15-0.52 -> 18.76 | O16: =O15-0.48 -> 14.91 | Q16: =Q15-1.04 -> 33.26 | S16: =S15-0.52 -> 18.77
B17: 2015 | D17: 9.6 | F17: 9.6 | H17: =H16-0.76 -> 13.08 | I17: =I16-0.44 -> 10.56 | K17: =K16-0.32 -> 9.29 | M17: =M16-0.52 -> 18.24 | O17: =O16-0.48 -> 14.43 | Q17: =Q16-1.04 -> 32.22 | S17: =S16-0.52 -> 18.25
A18: 阶段3 | B18: 2016 | C18: 20 | D18: 9.6 | E18: 0 | F18: 9.6 | G18: 0 | H18: 12.3 | I18: =I17-0.44 -> 10.12 | J18: 0 | K18: 8.97 | L18: 0 | M18: 17.69 | N18: 0 | O18: 13.98 | P18: 0 | Q18: 31.16 | R18: 0 | S18: 17.69
B19: 2017 | D19: =D18-0.4 -> 9.2 | F19: =F18-0.4 -> 9.2 | H19: 12.3 | I19: 10.1 | K19: 8.97 | M19: 17.69 | O19: 13.98 | Q19: 31.16 | S19: 17.69
B20: 2018 | D20: =D19-0.4 -> 8.8 | F20: =F19-0.4 -> 8.8 | H20: 12.3 | I20: 10.1 | K20: 8.97 | M20: 17.69 | O20: 13.98 | Q20: 31.16 | S20: 17.69
B21: 2019 | D21: =D20-0.4 -> 8.4 | F21: =F20-0.4 -> 8.4 | H21: 12.3 | I21: 10.1 | K21: 8.97 | M21: 17.69 | O21: 13.98 | Q21: 31.16 | S21: 17.69
B22: 2020 | D22: =D21-0.4 -> 8 | F22: =F21-0.4 -> 8 | H22: 12.3 | I22: 10.1 | K22: 8.97 | M22: 17.69 | O22: 13.98 | Q22: 31.16 | S22: 17.69
A23: 阶段4 | B23: 2021 | C23: 25 | D23: 7.61 | E23: 0 | F23: 7.61 | G23: 0 | H23: 12.3 | I23: 10.1 | J23: 0 | K23: 8.97 | L23: 0 | M23: 17.69 | N23: 0 | O23: 13.98 | P23: 0 | Q23: 31.16 | R23: 0 | S23: 17.69
B24: 2022 | D24: =D23-0.72 -> 6.89 | F24: =F23-0.72 -> 6.89 | H24: =H23-0.34 -> 11.96 | I24: =I23-0.26 -> 9.84 | K24: =K23-0.2 -> 8.77 | M24: =M23-1.48 -> 16.21 | O24: =O23-0.74 -> 13.24 | Q24: =Q23-0.86 -> 30.3 | S24: =S23-1.48 -> 16.21
B25: 2023 | D25: =D24-0.72 -> 6.17 | F25: =F24-0.72 -> 6.17 | H25: =H24-0.34 -> 11.62 | I25: =I24-0.26 -> 9.58 | K25: =K24-0.2 -> 8.57 | M25: =M24-1.48 -> 14.73 | O25: =O24-0.74 -> 12.5 | Q25: =Q24-0.86 -> 29.44 | S25: =S24-1.48 -> 14.73
B26: 2024 | D26: =D25-0.72 -> 5.45 | F26: =F25-0.72 -> 5.45 | H26: =H25-0.34 -> 11.28 | I26: =I25-0.26 -> 9.32 | K26: =K25-0.2 -> 8.37 | M26: =M25-1.48 -> 13.25 | O26: =O25-0.74 -> 11.76 | Q26: =Q25-0.86 -> 28.58 | S26: =S25-1.48 -> 13.25
B27: 2025 | D27: =D26-0.72 -> 4.73 | F27: =F26-0.72 -> 4.73 | H27: =H26-0.34 -> 10.94 | I27: =I26-0.26 -> 9.06 | K27: =K26-0.2 -> 8.17 | M27: =M26-1.48 -> 11.77 | O27: =O26-0.74 -> 11.02 | Q27: =Q26-0.86 -> 27.72 | S27: =S26-1.48 -> 11.77
A28: stage5 | B28: 2026 | C28: 30 | D28: 4 | E28: 0 | F28: 4 | G28: 0 | H28: 10.5984 | I28: =I27-0.26 -> 8.8 | J28: 0 | K28: =K27-0.2 -> 7.97 | L28: 0 | M28: 10.3 | N28: 0 | O28: 10.3 | P28: 0 | Q28: 26.864 | R28: 0 | S28: 10.3
B29: 2027 | D29: 4 | F29: 4 | H29: =H28-0.04 -> 10.5584 | I29: =I28-0.04 -> 8.76 | K29: 8 | M29: 10.3 | O29: 10.3 | Q29: =Q28-0.12 -> 26.744 | S29: 10.3
B30: 2028 | D30: 4 | F30: 4 | H30: =H29-0.04 -> 10.5184 | I30: =I29-0.04 -> 8.72 | K30: 8 | M30: 10.3 | O30: 10.3 | Q30: =Q29-0.12 -> 26.624 | S30: 10.3
B31: 2029 | D31: 4 | F31: 4 | H31: =H30-0.04 -> 10.4784 | I31: =I30-0.04 -> 8.68 | K31: 8 | M31: 10.3 | O31: 10.3 | Q31: =Q30-0.12 -> 26.504 | S31: 10.3
B32: 2030 | D32: 4 | F32: 4 | H32: =H31-0.04 -> 10.4384 | I32: =I31-0.04 -> 8.64 | K32: 8 | M32: 10.3 | O32: 10.3 | Q32: =Q31-0.12 -> 26.384 | S32: 10.3
A33: stage6 | B33: 2031 | C33: 40 | D33: 4 | E33: 0 | F33: 4 | G33: 0 | H33: =H32-0.04 -> 10.3984 | I33: =I32-0.04 -> 8.6 | J33: 0 | K33: 8 | L33: 0 | M33: 10.3 | N33: 0 | O33: 10.3 | P33: 0 | Q33: 26.28 | R33: 0 | S33: 10.3
B34: 2032 | D34: 4 | F34: 4 | H34: =H33-0.06 -> 10.3384 | I34: =I33-0.04 -> 8.56 | K34: 8 | M34: 10.3 | O34: 10.3 | Q34: =Q33-0.15 -> 26.13 | S34: 10.3
B35: 2033 | D35: 4 | F35: 4 | H35: =H34-0.06 -> 10.2784 | I35: =I34-0.04 -> 8.52 | K35: 8 | M35: 10.3 | O35: 10.3 | Q35: =Q34-0.15 -> 25.98 | S35: 10.3
B36: 2034 | D36: 4 | F36: 4 | H36: =H35-0.06 -> 10.2184 | I36: =I35-0.04 -> 8.48 | K36: 8 | M36: 10.3 | O36: 10.3 | Q36: =Q35-0.15 -> 25.83 | S36: 10.3
B37: 2035 | D37: 4 | F37: 4 | H37: =H36-0.06 -> 10.1584 | I37: =I36-0.04 -> 8.44 | K37: 8 | M37: 10.3 | O37: 10.3 | Q37: =Q36-0.15 -> 25.68 | S37: 10.3
B38: 2036 | D38: 4 | F38: 4 | H38: =H37-0.06 -> 10.0984 | I38: =I37-0.04 -> 8.4 | K38: 8 | M38: 10.3 | O38: 10.3 | Q38: =Q37-0.15 -> 25.53 | S38: 10.3
B39: 2037 | D39: 4 | F39: 4 | H39: =H38-0.06 -> 10.0384 | I39: =I38-0.04 -> 8.36 | K39: 8 | M39: 10.3 | O39: 10.3 | Q39: =Q38-0.15 -> 25.38 | S39: 10.3
B40: 2038 | D40: 4 | F40: 4 | H40: =H39-0.06 -> 9.9784 | I40: =I39-0.04 -> 8.32 | K40: 8 | M40: 10.3 | O40: 10.3 | Q40: =Q39-0.15 -> 25.23 | S40: 10.3
...

Sheet CNS燃油经济性
A1: 手动输入区域 | B1: 起始年 | C1: 终止年 | D1: 乘用车 | F1: 出租车 | H1: 轻型货车 | J1: 中型公交车 | L1: 道路客车 | N1: 中型货车 | P1: 重型货车 | R1: 大型公交车
A2: stage | D2: PV(汽油) | E2: PV(柴油) | F2: Taxi(汽油) | G2: Taxi(柴油) | H2: l_Truck(汽油) | I2: l_Truck(柴油) | J2: city bus(汽油) | K2: city bus(柴油) | L2: road bus(汽油) | M2: road bus(柴油) | N2: h_Truck(汽油) | O2: h_Truck(柴油) | P2: h_Truck(汽油) | Q2: h_Truck(柴油) | R2: h_Truck(汽油) | S2: h_Truck(柴油)
A3: 阶段0 | B3: 2001 | C3: 5
B4: 2002
B5: 2003
B6: 2004
B7: 2005
A8: 阶段1 | B8: 2006 | C8: 10
B9: 2007
B10: 2008
B11: 2009
B12: 2010
A13: 阶段2 | B13: 2011 | C13: 15
B14: 2012
B15: 2013
B16: 2014
B17: 2015
A18: 阶段3 | B18: 2016 | C18: 20 | D18: 9.6 | E18: 0 | F18: 9.6 | G18: 0 | H18: 12.3 | I18: 10.1 | J18: 0 | K18: 8.97 | L18: 0 | M18: 17.69 | N18: 0 | O18: 13.98 | P18: 0 | Q18: 31.16 | R18: 0 | S18: 17.69
B19: 2017 | D19: =D18-(D$18-D$23)/5 -> 9.202 | E19: =E18-(E$18-E$23)/5 -> 0 | F19: =F18-(F$18-F$23)/5 -> 9.202 | G19: =G18-(G$18-G$23)/5 -> 0 | H19: =H18-(H$18-H$23)/5 -> 12.3 | I19: =I18-(I$18-I$23)/5 -> 10.1 | J19: =J18-(J$18-J$23)/5 -> 0 | K19: =K18-(K$18-K$23)/5 -> 8.97 | ... S19: =S18-(S$18-S$23)/5 -> 17.69
B20: 2018 | D20: =D19-(D$18-D$23)/5 -> 8.804 | E20: =E19-(E$18-E$23)/5 -> 0 | F20: =F19-(F$18-F$23)/5 -> 8.804 | G20: =G19-(G$18-G$23)/5 -> 0 | H20: =H19-(H$18-H$23)/5 -> 12.3 | I20: =I19-(I$18-I$23)/5 -> 10.1 | J20: =J19-(J$18-J$23)/5 -> 0 | K20: =K19-(K$18-K$23)/5 -> 8.97 | ... S20: =S19-(S$18-S$23)/5 -> 17.69
B21: 2019 | D21: =D20-(D$18-D$23)/5 -> 8.406 | E21: =E20-(E$18-E$23)/5 -> 0 | F21: =F20-(F$18-F$23)/5 -> 8.406 | G21: =G20-(G$18-G$23)/5 -> 0 | H21: =H20-(H$18-H$23)/5 -> 12.3 | I21: =I20-(I$18-I$23)/5 -> 10.1 | J21: =J20-(J$18-J$23)/5 -> 0 | K21: =K20-(K$18-K$23)/5 -> 8.97 | ... S21: =S20-(S$18-S$23)/5 -> 17.69
B22: 2020 | D22: =D21-(D$18-D$23)/5 -> 8.008 | E22: =E21-(E$18-E$23)/5 -> 0 | F22: =F21-(F$18-F$23)/5 -> 8.008 | G22: =G21-(G$18-G$23)/5 -> 0 | H22: =H21-(H$18-H$23)/5 -> 12.3 | I22: =I21-(I$18-I$23)/5 -> 10.1 | J22: =J21-(J$18-J$23)/5 -> 0 | K22: =K21-(K$18-K$23)/5 -> 8.97 | ... S22: =S21-(S$18-S$23)/5 -> 17.69
A23: 阶段4 | B23: 2021 | C23: 25 | D23: 7.61 | E23: 0 | F23: 7.61 | G23: 0 | H23: 12.3 | I23: 10.1 | J23: 0 | K23: 8.97 | L23: 0 | M23: 17.69 | N23: 0 | O23: 13.98 | P23: 0 | Q23: 31.16 | R23: 0 | S23: 17.69
B24: 2022 | D24: =D23-(D$23-D$28)/5 -> 6.888 | E24: =E23-(E$23-E$28)/5 -> 0 | F24: =F23-(F$23-F$28)/5 -> 6.888 | G24: =G23-(G$23-G$28)/5 -> 0 | H24: =H23-(H$23-H$28)/5 -> 11.93664 | I24: =I23-(I$23-I$28)/5 -> 9.8272 | J24: =J23-(J$23-J$28)/5 -> 0 | K24: =K23-(K$23-K$28)/5 -> 8.7547462 | ... S24: =S23-(S$23-S$28)/5 -> 16.7904
B25: 2023 | D25: =D24-(D$23-D$28)/5 -> 6.166 | E25: =E24-(E$23-E$28)/5 -> 0 | F25: =F24-(F$23-F$28)/5 -> 6.166 | G25: =G24-(G$23-G$28)/5 -> 0 | H25: =H24-(H$23-H$28)/5 -> 11.57328 | I25: =I24-(I$23-I$28)/5 -> 9.5544 | J25: =J24-(J$23-J$28)/5 -> 0 | K25: =K24-(K$23-K$28)/5 -> 8.5394923 | ... S25: =S24-(S$23-S$28)/5 -> 15.8908
B26: 2024 | D26: =D25-(D$23-D$28)/5 -> 5.444 | E26: =E25-(E$23-E$28)/5 -> 0 | F26: =F25-(F$23-F$28)/5 -> 5.444 | G26: =G25-(G$23-G$28)/5 -> 0 | H26: =H25-(H$23-H$28)/5 -> 11.20992 | I26: =I25-(I$23-I$28)/5 -> 9.2816 | J26: =J25-(J$23-J$28)/5 -> 0 | K26: =K25-(K$23-K$28)/5 -> 8.3242385 | ... S26: =S25-(S$23-S$28)/5 -> 14.9912
B27: 2025 | D27: =D26-(D$23-D$28)/5 -> 4.722 | E27: =E26-(E$23-E$28)/5 -> 0 | F27: =F26-(F$23-F$28)/5 -> 4.722 | G27: =G26-(G$23-G$28)/5 -> 0 | H27: =H26-(H$23-H$28)/5 -> 10.84656 | I27: =I26-(I$23-I$28)/5 -> 9.0088 | J27: =J26-(J$23-J$28)/5 -> 0 | K27: =K26-(K$23-K$28)/5 -> 8.1089846 | ... S27: =S26-(S$23-S$28)/5 -> 14.0916
A28: stage5 | B28: 2026 | C28: 30 | D28: 4 | E28: 0 | F28: 4 | G28: 0 | H28: 10.4832 | I28: 8.736 | J28: 0 | K28: 7.8937308 | L28: 0 | M28: 13.192 | N28: 0 | O28: 10.684882 | P28: 0 | Q28: 26.572 | R28: 0 | S28: 13.192
B29: 2027 | D29: =D28-(D$28-D$33)/5 -> 3.94 | E29: =E28-(E$28-E$33)/5 -> 0 | F29: =F28-(F$28-F$33)/5 -> 3.94 | G29: =G28-(G$28-G$33)/5 -> 0 | H29: =H28-(H$28-H$33)/5 -> 10.41408 | I29: =I28-(I$28-I$33)/5 -> 8.6784 | J29: =J28-(J$28-J$33)/5 -> 0 | K29: =K28-(K$28-K$33)/5 -> 7.7925291 | ... S29: =S28-(S$28-S$33)/5 -> 12.998
B30: 2028 | D30: =D29-(D$28-D$33)/5 -> 3.88 | E30: =E29-(E$28-E$33)/5 -> 0 | F30: =F29-(F$28-F$33)/5 -> 3.88 | G30: =G29-(G$28-G$33)/5 -> 0 | H30: =H29-(H$28-H$33)/5 -> 10.34496 | I30: =I29-(I$28-I$33)/5 -> 8.6208 | J30: =J29-(J$28-J$33)/5 -> 0 | K30: =K29-(K$28-K$33)/5 -> 7.6913274 | ... S30: =S29-(S$28-S$33)/5 -> 12.804
B31: 2029 | D31: =D30-(D$28-D$33)/5 -> 3.82 | E31: =E30-(E$28-E$33)/5 -> 0 | F31: =F30-(F$28-F$33)/5 -> 3.82 | G31: =G30-(G$28-G$33)/5 -> 0 | H31: =H30-(H$28-H$33)/5 -> 10.27584 | I31: =I30-(I$28-I$33)/5 -> 8.5632 | J31: =J30-(J$28-J$33)/5 -> 0 | K31: =K30-(K$28-K$33)/5 -> 7.5901258 | ... S31: =S30-(S$28-S$33)/5 -> 12.61
B32: 2030 | D32: =D31-(D$28-D$33)/5 -> 3.76 | E32: =E31-(E$28-E$33)/5 -> 0 | F32: =F31-(F$28-F$33)/5 -> 3.76 | G32: =G31-(G$28-G$33)/5 -> 0 | H32: =H31-(H$28-H$33)/5 -> 10.20672 | I32: =I31-(I$28-I$33)/5 -> 8.5056 | J32: =J31-(J$28-J$33)/5 -> 0 | K32: =K31-(K$28-K$33)/5 -> 7.4889241 | ... S32: =S31-(S$28-S$33)/5 -> 12.416
A33: stage6 | B33: 2031 | C33: 40 | D33: 3.7 | E33: 0 | F33: 3.7 | G33: 0 | H33: 10.1376 | I33: 8.448 | J33: 0 | K33: 7.3877224 | L33: 0 | M33: 12.222 | N33: 0 | O33: 10.251711 | P33: 0 | Q33: 25.696 | R33: 0 | S33: 12.222
B34: 2032 | D34: =D33-(D$33-D$43)/10 -> 3.66 | E34: =E33-(E$33-E$43)/10 -> 0 | F34: =F33-(F$33-F$43)/10 -> 3.66 | G34: =G33-(G$33-G$43)/10 -> 0 | H34: =H33-(H$33-H$43)/10 -> 10.08 | I34: =I33-(I$33-I$43)/10 -> 8.4 | J34: =J33-(J$33-J$43)/10 -> 0 | K34: =K33-(K$33-K$43)/10 -> 7.3371216 | ... S34: =S33-(S$33-S$43)/10 -> 12.125
B35: 2033 | D35: =D34-(D$33-D$43)/10 -> 3.62 | E35: =E34-(E$33-E$43)/10 -> 0 | F35: =F34-(F$33-F$43)/10 -> 3.62 | G35: =G34-(G$33-G$43)/10 -> 0 | H35: =H34-(H$33-H$43)/10 -> 10.0224 | I35: =I34-(I$33-I$43)/10 -> 8.352 | J35: =J34-(J$33-J$43)/10 -> 0 | K35: =K34-(K$33-K$43)/10 -> 7.2865207 | ... S35: =S34-(S$33-S$43)/10 -> 12.028
B36: 2034 | D36: =D35-(D$33-D$43)/10 -> 3.58 | E36: =E35-(E$33-E$43)/10 -> 0 | F36: =F35-(F$33-F$43)/10 -> 3.58 | G36: =G35-(G$33-G$43)/10 -> 0 | H36: =H35-(H$33-H$43)/10 -> 9.9648 | I36: =I35-(I$33-I$43)/10 -> 8.304 | J36: =J35-(J$33-J$43)/10 -> 0 | K36: =K35-(K$33-K$43)/10 -> 7.2359199 | ... S36: =S35-(S$33-S$43)/10 -> 11.931
B37: 2035 | D37: =D36-(D$33-D$43)/10 -> 3.54 | E37: =E36-(E$33-E$43)/10 -> 0 | F37: =F36-(F$33-F$43)/10 -> 3.54 | G37: =G36-(G$33-G$43)/10 -> 0 | H37: =H36-(H$33-H$43)/10 -> 9.9072 | I37: =I36-(I$33-I$43)/10 -> 8.256 | J37: =J36-(J$33-J$43)/10 -> 0 | K37: =K36-(K$33-K$43)/10 -> 7.185319 | ... S37: =S36-(S$33-S$43)/10 -> 11.834
B38: 2036 | D38: =D37-(D$33-D$43)/10 -> 3.5 | E38: =E37-(E$33-E$43)/10 -> 0 | F38: =F37-(F$33-F$43)/10 -> 3.5 | G38: =G37-(G$33-G$43)/10 -> 0 | H38: =H37-(H$33-H$43)/10 -> 9.8496 | I38: =I37-(I$33-I$43)/10 -> 8.208 | J38: =J37-(J$33-J$43)/10 -> 0 | K38: =K37-(K$33-K$43)/10 -> 7.1347182 | ... S38: =S37-(S$33-S$43)/10 -> 11.737
B39: 2037 | D39: =D38-(D$33-D$43)/10 -> 3.46 | E39: =E38-(E$33-E$43)/10 -> 0 | F39: =F38-(F$33-F$43)/10 -> 3.46 | G39: =G38-(G$33-G$43)/10 -> 0 | H39: =H38-(H$33-H$43)/10 -> 9.792 | I39: =I38-(I$33-I$43)/10 -> 8.16 | J39: =J38-(J$33-J$43)/10 -> 0 | K39: =K38-(K$33-K$43)/10 -> 7.0841174 | ... S39: =S38-(S$33-S$43)/10 -> 11.64
B40: 2038 | D40: =D39-(D$33-D$43)/10 -> 3.42 | E40: =E39-(E$33-E$43)/10 -> 0 | F40: =F39-(F$33-F$43)/10 -> 3.42 | G40: =G39-(G$33-G$43)/10 -> 0 | H40: =H39-(H$33-H$43)/10 -> 9.7344 | I40: =I39-(I$33-I$43)/10 -> 8.112 | J40: =J39-(J$33-J$43)/10 -> 0 | K40: =K39-(K$33-K$43)/10 -> 7.0335165 | ... S40: =S39-(S$33-S$43)/10 -> 11.543
...

Sheet 燃油经济性提升
A1: 手动输入区域 | B1: 起始年 | C1: 终止年 | D1: 乘用车 | F1: 出租车 | H1: 轻型货车 | J1: 中型公交车 | L1: 道路客车 | N1: 中型货车 | P1: 重型货车 | R1: 大型公交车
A2: stage | D2: PV(汽油) | E2: PV(柴油) | F2: Taxi(汽油) | G2: Taxi(柴油) | H2: l_Truck(汽油) | I2: l_Truck(柴油) | J2: city bus(汽油) | K2: city bus(柴油) | L2: road bus(汽油) | M2: road bus(柴油) | N2: h_Truck(汽油) | O2: h_Truck(柴油) | P2: h_Truck(汽油) | Q2: h_Truck(柴油) | R2: h_Truck(汽油) | S2: h_Truck(柴油)
A3: 阶段0 | B3: 2001 | C3: 5
B4: 2002
B5: 2003
B6: 2004
B7: 2005
A8: 阶段1 | B8: 2006 | C8: 10 | V8: 起始年数量 | W8: 汽油 | X8: 柴油 | Z8: 起始年占比 | AA8: 汽油 | AB8: 柴油
B9: 2007 | V9: 客运LDVs | W9: 261344177 | X9: 1843349 | Z9: 客运LDVs | AA9: =W9/(W9+X9) -> 0.99299606 | AB9: =1-AA9 -> 0.0070039376
B10: 2008 | V10: 客运HDVs | W10: 631888 | X10: 850154 | Z10: 客运HDVs | AA10: =W10/(W10+X10) -> 0.42636309 | AB10: =1-AA10 -> 0.57363691
B11: 2009 | V11: 货运LDVs | W11: 13054425 | X11: 9943096 | Z11: 货运LDVs | AA11: =W11/(W11+X11) -> 0.56764488 | AB11: =1-AA11 -> 0.43235512
B12: 2010 | V12: 货运HDVs | W12: 0 | X12: 8595806 | Z12: 货运HDVs | AA12: =W12/(W12+X12) -> 0 | AB12: =1-AA12 -> 1
A13: 阶段2 | B13: 2011 | C13: 15
B14: 2012
B15: 2013
B16: 2014
B17: 2015 | X17: 乘用车 | Y17: 销量 | Z17: 出租车 | AA17: 销量 | AB17: 轻型货车 | AC17: 销量 | AD17: 中型公交车 | AE17: 销量 | AF17: 道路客车 | AG17: 销量 | AH17: 中型货车 | AI17: 销量 | AJ17: 重型货车 | AK17: 销量 | AL17: 大型公交车 | AM17: 销量 | AP17: 客运LDV | AQ17: 客运HDV | AR17: 货运LDV | AS17: 货运HDV | AT17: Fopity | AU17: 客运LDV | AV17: 客运HDV | AW17: 货运LDV | AX17: 货运HDV
A18: 阶段3 | B18: 2016 | C18: 20 | D18: =IFERROR((BAU燃油经济性!D18-CNS燃油经济性!D18)/BAU燃油经济性!D18,0) -> 0 | E18: =IFERROR((BAU燃油经济性!E18-CNS燃油经济性!E18)/BAU燃油经济性!E18,0) -> 0 | F18: =IFERROR((BAU燃油经济性!F18-CNS燃油经济性!F18)/BAU燃油经济性!F18,0) -> 0 | G18: =IFERROR((BAU燃油经济性!G18-CNS燃油经济性!G18)/BAU燃油经济性!G18,0) -> 0 | H18: =IFERROR((BAU燃油经济性!H18-CNS燃油经济性!H18)/BAU燃油经济性!H18,0) -> 0 | I18: =IFERROR((BAU燃油经济性!I18-CNS燃油经济性!I18)/BAU燃油经济性!I18,0) -> 0.0019762846 | J18: =IFERROR((BAU燃油经济性!J18-CNS燃油经济性!J18)/BAU燃油经济性!J18,0) -> 0 | K18: =IFERROR((BAU燃油经济性!K18-CNS燃油经济性!K18)/BAU燃油经济性!K18,0) -> 0 | ... S18: =IFERROR((BAU燃油经济性!S18-CNS燃油经济性!S18)/BAU燃油经济性!S18,0) -> 0 | U18: 阶段3 | V18: 2016 | W18: 20 | X18: =D18*$AA$9+E18*$AB$9 -> 0 | Z18: =F18*$AA$9+G18*$AB$9 -> 0 | AB18: =H18*$AA$11+I18*$AB$11 -> 0.00085445676 | AD18: =J18*$AA$10+K18*$AB$10 -> 0 | AF18: =L18*$AA$10+M18*$AB$10 -> 0 | AH18: =O18 -> 0 | AJ18: =Q18 -> 0 | AL18: =R18*$AA$10+S18*$AB$10 -> 0 | AO18: 2016 | AP18: =X18 -> 0 | AR18: =AB18 -> 0.00085445676
B19: 2017 | D19: =IFERROR((BAU燃油经济性!D19-CNS燃油经济性!D19)/BAU燃油经济性!D19,0) -> -0.0002173913 | E19: =IFERROR((BAU燃油经济性!E19-CNS燃油经济性!E19)/BAU燃油经济性!E19,0) -> 0 | F19: =IFERROR((BAU燃油经济性!F19-CNS燃油经济性!F19)/BAU燃油经济性!F19,0) -> -0.0002173913 | G19: =IFERROR((BAU燃油经济性!G19-CNS燃油经济性!G19)/BAU燃油经济性!G19,0) -> 0 | H19: =IFERROR((BAU燃油经济性!H19-CNS燃油经济性!H19)/BAU燃油经济性!H19,0) -> 0 | I19: =IFERROR((BAU燃油经济性!I19-CNS燃油经济性!I19)/BAU燃油经济性!I19,0) -> 0 | J19: =IFERROR((BAU燃油经济性!J19-CNS燃油经济性!J19)/BAU燃油经济性!J19,0) -> 0 | K19: =IFERROR((BAU燃油经济性!K19-CNS燃油经济性!K19)/BAU燃油经济性!K19,0) -> 0 | ... S19: =IFERROR((BAU燃油经济性!S19-CNS燃油经济性!S19)/BAU燃油经济性!S19,0) -> 0 | V19: 2017 | X19: =D19*$AA$9+E19*$AB$9 -> -0.00021586871 | Z19: =F19*$AA$9+G19*$AB$9 -> -0.00021586871 | AB19: =H19*$AA$11+I19*$AB$11 -> 0 | AD19: =J19*$AA$10+K19*$AB$10 -> 0 | AF19: =L19*$AA$10+M19*$AB$10 -> 0 | AH19: =O19 -> 0 | AJ19: =Q19 -> 0 | AL19: =R19*$AA$10+S19*$AB$10 -> 0 | AO19: 2017 | AP19: =X19 -> -0.00021586871 | AR19: =AB19 -> 0
B20: 2018 | D20: =IFERROR((BAU燃油经济性!D20-CNS燃油经济性!D20)/BAU燃油经济性!D20,0) -> -0.00045454545 | E20: =IFERROR((BAU燃油经济性!E20-CNS燃油经济性!E20)/BAU燃油经济性!E20,0) -> 0 | F20: =IFERROR((BAU燃油经济性!F20-CNS燃油经济性!F20)/BAU燃油经济性!F20,0) -> -0.00045454545 | G20: =IFERROR((BAU燃油经济性!G20-CNS燃油经济性!G20)/BAU燃油经济性!G20,0) -> 0 | H20: =IFERROR((BAU燃油经济性!H20-CNS燃油经济性!H20)/BAU燃油经济性!H20,0) -> 0 | I20: =IFERROR((BAU燃油经济性!I20-CNS燃油经济性!I20)/BAU燃油经济性!I20,0) -> 0 | J20: =IFERROR((BAU燃油经济性!J20-CNS燃油经济性!J20)/BAU燃油经济性!J20,0) -> 0 | K20: =IFERROR((BAU燃油经济性!K20-CNS燃油经济性!K20)/BAU燃油经济性!K20,0) -> 0 | ... S20: =IFERROR((BAU燃油经济性!S20-CNS燃油经济性!S20)/BAU燃油经济性!S20,0) -> 0 | V20: 2018 | X20: =D20*$AA$9+E20*$AB$9 -> -0.00045136185 | Z20: =F20*$AA$9+G20*$AB$9 -> -0.00045136185 | AB20: =H20*$AA$11+I20*$AB$11 -> 0 | AD20: =J20*$AA$10+K20*$AB$10 -> 0 | AF20: =L20*$AA$10+M20*$AB$10 -> 0 | AH20: =O20 -> 0 | AJ20: =Q20 -> 0 | AL20: =R20*$AA$10+S20*$AB$10 -> 0 | AO20: 2018 | AP20: =X20 -> -0.00045136185 | AR20: =AB20 -> 0
B21: 2019 | D21: =IFERROR((BAU燃油经济性!D21-CNS燃油经济性!D21)/BAU燃油经济性!D21,0) -> -0.00071428571 | E21: =IFERROR((BAU燃油经济性!E21-CNS燃油经济性!E21)/BAU燃油经济性!E21,0) -> 0 | F21: =IFERROR((BAU燃油经济性!F21-CNS燃油经济性!F21)/BAU燃油经济性!F21,0) -> -0.00071428571 | G21: =IFERROR((BAU燃油经济性!G21-CNS燃油经济性!G21)/BAU燃油经济性!G21,0) -> 0 | H21: =IFERROR((BAU燃油经济性!H21-CNS燃油经济性!H21)/BAU燃油经济性!H21,0) -> 0 | I21: =IFERROR((BAU燃油经济性!I21-CNS燃油经济性!I21)/BAU燃油经济性!I21,0) -> 0 | J21: =IFERROR((BAU燃油经济性!J21-CNS燃油经济性!J21)/BAU燃油经济性!J21,0) -> 0 | K21: =IFERROR((BAU燃油经济性!K21-CNS燃油经济性!K21)/BAU燃油经济性!K21,0) -> 0 | ... S21: =IFERROR((BAU燃油经济性!S21-CNS燃油经济性!S21)/BAU燃油经济性!S21,0) -> 0 | V21: 2019 | X21: =D21*$AA$9+E21*$AB$9 -> -0.0007092829 | Z21: =F21*$AA$9+G21*$AB$9 -> -0.0007092829 | AB21: =H21*$AA$11+I21*$AB$11 -> 0 | AD21: =J21*$AA$10+K21*$AB$10 -> 0 | AF21: =L21*$AA$10+M21*$AB$10 -> 0 | AH21: =O21 -> 0 | AJ21: =Q21 -> 0 | AL21: =R21*$AA$10+S21*$AB$10 -> 0 | AO21: 2019 | AP21: =X21 -> -0.0007092829 | AR21: =AB21 -> 0
B22: 2020 | D22: =IFERROR((BAU燃油经济性!D22-CNS燃油经济性!D22)/BAU燃油经济性!D22,0) -> -0.001 | E22: =IFERROR((BAU燃油经济性!E22-CNS燃油经济性!E22)/BAU燃油经济性!E22,0) -> 0 | F22: =IFERROR((BAU燃油经济性!F22-CNS燃油经济性!F22)/BAU燃油经济性!F22,0) -> -0.001 | G22: =IFERROR((BAU燃油经济性!G22-CNS燃油经济性!G22)/BAU燃油经济性!G22,0) -> 0 | H22: =IFERROR((BAU燃油经济性!H22-CNS燃油经济性!H22)/BAU燃油经济性!H22,0) -> 0 | I22: =IFERROR((BAU燃油经济性!I22-CNS燃油经济性!I22)/BAU燃油经济性!I22,0) -> 0 | J22: =IFERROR((BAU燃油经济性!J22-CNS燃油经济性!J22)/BAU燃油经济性!J22,0) -> 0 | K22: =IFERROR((BAU燃油经济性!K22-CNS燃油经济性!K22)/BAU燃油经济性!K22,0) -> 0 | ... S22: =IFERROR((BAU燃油经济性!S22-CNS燃油经济性!S22)/BAU燃油经济性!S22,0) -> 0 | V22: 2020 | X22: =D22*$AA$9+E22*$AB$9 -> -0.00099299606 | Z22: =F22*$AA$9+G22*$AB$9 -> -0.00099299606 | AB22: =H22*$AA$11+I22*$AB$11 -> 0 | AD22: =J22*$AA$10+K22*$AB$10 -> 0 | AE22: 5275.9879 | AF22: =L22*$AA$10+M22*$AB$10 -> 0 | AG22: 124695.25 | AH22: =O22 -> 0 | AI22: 95769.559 | AJ22: =Q22 -> 0 | AK22: 1486078.8 | AL22: =R22*$AA$10+S22*$AB$10 -> 0 | AM22: 59319.679 | AO22: 2020 | AP22: =X22 -> -0.00099299606 | AR22: =AB22 -> 0
A23: 阶段4 | B23: 2021 | C23: 25 | D23: =IFERROR((BAU燃油经济性!D23-CNS燃油经济性!D23)/BAU燃油经济性!D23,0) -> 1.1671201e-16 | E23: =IFERROR((BAU燃油经济性!E23-CNS燃油经济性!E23)/BAU燃油经济性!E23,0) -> 0 | F23: =IFERROR((BAU燃油经济性!F23-CNS燃油经济性!F23)/BAU燃油经济性!F23,0) -> 0 | G23: =IFERROR((BAU燃油经济性!G23-CNS燃油经济性!G23)/BAU燃油经济性!G23,0) -> 0 | H23: =IFERROR((BAU燃油经济性!H23-CNS燃油经济性!H23)/BAU燃油经济性!H23,0) -> 0 | I23: =IFERROR((BAU燃油经济性!I23-CNS燃油经济性!I23)/BAU燃油经济性!I23,0) -> 0 | J23: =IFERROR((BAU燃油经济性!J23-CNS燃油经济性!J23)/BAU燃油经济性!J23,0) -> 0 | K23: =IFERROR((BAU燃油经济性!K23-CNS燃油经济性!K23)/BAU燃油经济性!K23,0) -> 0 | ... S23: =IFERROR((BAU燃油经济性!S23-CNS燃油经济性!S23)/BAU燃油经济性!S23,0) -> 0 | U23: 阶段4 | V23: 2021 | W23: 25 | X23: =D23*$AA$9+E23*$AB$9 -> 1.1589457e-16 | Z23: =F23*$AA$9+G23*$AB$9 -> 0 | AB23: =H23*$AA$11+I23*$AB$11 -> 0 | AD23: =J23*$AA$10+K23*$AB$10 -> 0 | AE23: 14786.569 | AF23: =L23*$AA$10+M23*$AB$10 -> 0 | AG23: -406.07578 | AH23: =O23 -> 0 | AI23: 34625.977 | AJ23: =Q23 -> 0 | AK23: 1443872.3 | AL23: =R23*$AA$10+S23*$AB$10 -> 0 | AM23: 166250.3 | AO23: 2021 | AP23: =X23 -> 1.1589457e-16 | AR23: =AB23 -> 0
B24: 2022 | D24: =IFERROR((BAU燃油经济性!D24-CNS燃油经济性!D24)/BAU燃油经济性!D24,0) -> 0.00029027576 | E24: =IFERROR((BAU燃油经济性!E24-CNS燃油经济性!E24)/BAU燃油经济性!E24,0) -> 0 | F24: =IFERROR((BAU燃油经济性!F24-CNS燃油经济性!F24)/BAU燃油经济性!F24,0) -> 0.00029027576 | G24: =IFERROR((BAU燃油经济性!G24-CNS燃油经济性!G24)/BAU燃油经济性!G24,0) -> 0 | H24: =IFERROR((BAU燃油经济性!H24-CNS燃油经济性!H24)/BAU燃油经济性!H24,0) -> 0.0019531773 | I24: =IFERROR((BAU燃油经济性!I24-CNS燃油经济性!I24)/BAU燃油经济性!I24,0) -> 0.001300813 | J24: =IFERROR((BAU燃油经济性!J24-CNS燃油经济性!J24)/BAU燃油经济性!J24,0) -> 0 | K24: =IFERROR((BAU燃油经济性!K24-CNS燃油经济性!K24)/BAU燃油经济性!K24,0) -> 0.0017393207 | ... S24: =IFERROR((BAU燃油经济性!S24-CNS燃油经济性!S24)/BAU燃油经济性!S24,0) -> -0.035805059 | V24: 2022 | X24: =D24*$AA$9+E24*$AB$9 -> 0.00028824269 | Z24: =F24*$AA$9+G24*$AB$9 -> 0.00028824269 | AB24: =H24*$AA$11+I24*$AB$11 -> 0.0016711242 | AD24: =J24*$AA$10+K24*$AB$10 -> 0.00099773856 | AE24: 5010.2423 | AF24: =L24*$AA$10+M24*$AB$10 -> -0.020539103 | AG24: 168080.94 | AH24: =O24 -> -0.0061160427 | AI24: 87157.395 | AJ24: =Q24 -> 0.0019009901 | AK24: 813781.62 | AL24: =R24*$AA$10+S24*$AB$10 -> -0.020539103 | AM24: 56331.814 | AO24: 2022 | AP24: =X24 -> 0.00028824269 | AQ24: =AD24*AE24/(AE24+AG24+AM24)+AF24*AG24/(AE24+AG24+AM24)+AL24*AM24/(AE24+AG24+AM24) -> -0.020068772 | AR24: =AB24 -> 0.0016711242 | AS24: =AH24*AI24/(AI24+AK24)+AJ24*AK24/(AI24+AK24) -> 0.0011254174 | AT24: 2022 | AU24: =AP24/AP$62 -> 0.001161103 | AV24: =AQ24/AQ$62 -> -4.425852 | AW24: =AR24/AR$62 -> 0.066844969 | AX24: =AS24/AS$62 -> 0.041758639
B25: 2023 | D25: =IFERROR((BAU燃油经济性!D25-CNS燃油经济性!D25)/BAU燃油经济性!D25,0) -> 0.00064829822 | E25: =IFERROR((BAU燃油经济性!E25-CNS燃油经济性!E25)/BAU燃油经济性!E25,0) -> 0 | F25: =IFERROR((BAU燃油经济性!F25-CNS燃油经济性!F25)/BAU燃油经济性!F25,0) -> 0.00064829822 | G25: =IFERROR((BAU燃油经济性!G25-CNS燃油经济性!G25)/BAU燃油经济性!G25,0) -> 0 | H25: =IFERROR((BAU燃油经济性!H25-CNS燃油经济性!H25)/BAU燃油经济性!H25,0) -> 0.004020654 | I25: =IFERROR((BAU燃油经济性!I25-CNS燃油经济性!I25)/BAU燃油经济性!I25,0) -> 0.0026722338 | J25: =IFERROR((BAU燃油经济性!J25-CNS燃油经济性!J25)/BAU燃油经济性!J25,0) -> 0 | K25: =IFERROR((BAU燃油经济性!K25-CNS燃油经济性!K25)/BAU燃油经济性!K25,0) -> 0.0035598232 | ... S25: =IFERROR((BAU燃油经济性!S25-CNS燃油经济性!S25)/BAU燃油经济性!S25,0) -> -0.07880516 | V25: 2023 | X25: =D25*$AA$9+E25*$AB$9 -> 0.00064375758 | Z25: =F25*$AA$9+G25*$AB$9 -> 0.00064375758 | AB25: =H25*$AA$11+I25*$AB$11 -> 0.0034376577 | AD25: =J25*$AA$10+K25*$AB$10 -> 0.002042046 | AE25: 4238.2229 | AF25: =L25*$AA$10+M25*$AB$10 -> -0.045205549 | AG25: 147765.97 | AH25: =O25 -> -0.012956225 | AI25: 52794.868 | AJ25: =Q25 -> 0.0039130435 | AK25: 728354.8 | AL25: =R25*$AA$10+S25*$AB$10 -> -0.045205549 | AM25: 47651.744 | AO25: 2023 | AP25: =X25 -> 0.00064375758 | AQ25: =AD25*AE25/(AE25+AG25+AM25)+AF25*AG25/(AE25+AG25+AM25)+AL25*AM25/(AE25+AG25+AM25) -> -0.044202594 | AR25: =AB25 -> 0.0034376577 | AS25: =AH25*AI25/(AI25+AK25)+AJ25*AK25/(AI25+AK25) -> 0.0027729152 | AT25: 2023 | AU25: =AP25/AP$62 -> 0.0025931929 | AV25: =AQ25/AQ$62 -> -9.7481868 | AW25: =AR25/AR$62 -> 0.13750631 | AX25: =AS25/AS$62 -> 0.10288909
B26: 2024 | D26: =IFERROR((BAU燃油经济性!D26-CNS燃油经济性!D26)/BAU燃油经济性!D26,0) -> 0.0011009174 | E26: =IFERROR((BAU燃油经济性!E26-CNS燃油经济性!E26)/BAU燃油经济性!E26,0) -> 0 | F26: =IFERROR((BAU燃油经济性!F26-CNS燃油经济性!F26)/BAU燃油经济性!F26,0) -> 0.0011009174 | G26: =IFERROR((BAU燃油经济性!G26-CNS燃油经济性!G26)/BAU燃油经济性!G26,0) -> 0 | H26: =IFERROR((BAU燃油经济性!H26-CNS燃油经济性!H26)/BAU燃油经济性!H26,0) -> 0.006212766 | I26: =IFERROR((BAU燃油经济性!I26-CNS燃油经济性!I26)/BAU燃油经济性!I26,0) -> 0.0041201717 | J26: =IFERROR((BAU燃油经济性!J26-CNS燃油经济性!J26)/BAU燃油经济性!J26,0) -> 0 | K26: =IFERROR((BAU燃油经济性!K26-CNS燃油经济性!K26)/BAU燃油经济性!K26,0) -> 0.0054673271 | ... S26: =IFERROR((BAU燃油经济性!S26-CNS燃油经济性!S26)/BAU燃油经济性!S26,0) -> -0.13141132 | V26: 2024 | X26: =D26*$AA$9+E26*$AB$9 -> 0.0010932067 | Z26: =F26*$AA$9+G26*$AB$9 -> 0.0010932067 | AB26: =H26*$AA$11+I26*$AB$11 -> 0.0053080221 | AD26: =J26*$AA$10+K26*$AB$10 -> 0.0031362606 | AE26: 3298.3662 | AF26: =L26*$AA$10+M26*$AB$10 -> -0.075382385 | AG26: 128583 | AH26: =O26 -> -0.020657246 | AI26: 54291.037 | AJ26: =Q26 -> 0.0060461861 | AK26: 834576.65 | AL26: =R26*$AA$10+S26*$AB$10 -> -0.075382385 | AM26: 37084.624 | AO26: 2024 | AP26: =X26 -> 0.0010932067 | AQ26: =AD26*AE26/(AE26+AG26+AM26)+AF26*AG26/(AE26+AG26+AM26)+AL26*AM26/(AE26+AG26+AM26) -> -0.073849631 | AR26: =AB26 -> 0.0053080221 | AS26: =AH26*AI26/(AI26+AK26)+AJ26*AK26/(AI26+AK26) -> 0.0044151706 | AT26: 2024 | AU26: =AP26/AP$62 -> 0.0044036697 | AV26: =AQ26/AQ$62 -> -16.286374 | AW26: =AR26/AR$62 -> 0.21232088 | AX26: =AS26/AS$62 -> 0.16382501
B27: 2025 | D27: =IFERROR((BAU燃油经济性!D27-CNS燃油经济性!D27)/BAU燃油经济性!D27,0) -> 0.0016913319 | E27: =IFERROR((BAU燃油经济性!E27-CNS燃油经济性!E27)/BAU燃油经济性!E27,0) -> 0 | F27: =IFERROR((BAU燃油经济性!F27-CNS燃油经济性!F27)/BAU燃油经济性!F27,0) -> 0.0016913319 | G27: =IFERROR((BAU燃油经济性!G27-CNS燃油经济性!G27)/BAU燃油经济性!G27,0) -> 0 | H27: =IFERROR((BAU燃油经济性!H27-CNS燃油经济性!H27)/BAU燃油经济性!H27,0) -> 0.0085411335 | I27: =IFERROR((BAU燃油经济性!I27-CNS燃油经济性!I27)/BAU燃油经济性!I27,0) -> 0.0056512141 | J27: =IFERROR((BAU燃油经济性!J27-CNS燃油经济性!J27)/BAU燃油经济性!J27,0) -> 0 | K27: =IFERROR((BAU燃油经济性!K27-CNS燃油经济性!K27)/BAU燃油经济性!K27,0) -> 0.0074682216 | ... S27: =IFERROR((BAU燃油经济性!S27-CNS燃油经济性!S27)/BAU燃油经济性!S27,0) -> -0.19724724 | V27: 2025 | X27: =D27*$AA$9+E27*$AB$9 -> 0.0016794859 | Z27: =F27*$AA$9+G27*$AB$9 -> 0.0016794859 | AB27: =H27*$AA$11+I27*$AB$11 -> 0.007291662 | AD27: =J27*$AA$10+K27*$AB$10 -> 0.0042840476 | AE27: 6762.943 | AF27: =L27*$AA$10+M27*$AB$10 -> -0.1131483 | AG27: 114572.3 | AH27: =O27 -> -0.029392525 | AI27: 82042.143 | AJ27: =Q27 -> 0.0083116883 | AK27: 959003.89 | AL27: =R27*$AA$10+S27*$AB$10 -> -0.1131483 | AM27: 76038.008 | AO27: 2025 | AP27: =X27 -> 0.0016794859 | AQ27: =AD27*AE27/(AE27+AG27+AM27)+AF27*AG27/(AE27+AG27+AM27)+AL27*AM27/(AE27+AG27+AM27) -> -0.10912451 | AR27: =AB27 -> 0.007291662 | AS27: =AH27*AI27/(AI27+AK27)+AJ27*AK27/(AI27+AK27) -> 0.0053403169 | AT27: 2025 | AU27: =AP27/AP$62 -> 0.0067653277 | AV27: =AQ27/AQ$62 -> -24.065694 | AW27: =AR27/AR$62 -> 0.29166648 | AX27: =AS27/AS$62 -> 0.19815258
A28: stage5 | B28: 2026 | C28: 30 | D28: =IFERROR((BAU燃油经济性!D28-CNS燃油经济性!D28)/BAU燃油经济性!D28,0) -> 0 | E28: =IFERROR((BAU燃油经济性!E28-CNS燃油经济性!E28)/BAU燃油经济性!E28,0) -> 0 | F28: =IFERROR((BAU燃油经济性!F28-CNS燃油经济性!F28)/BAU燃油经济性!F28,0) -> 0 | G28: =IFERROR((BAU燃油经济性!G28-CNS燃油经济性!G28)/BAU燃油经济性!G28,0) -> 0 | H28: =IFERROR((BAU燃油经济性!H28-CNS燃油经济性!H28)/BAU燃油经济性!H28,0) -> 0.010869565 | I28: =IFERROR((BAU燃油经济性!I28-CNS燃油经济性!I28)/BAU燃油经济性!I28,0) -> 0.0072727273 | J28: =IFERROR((BAU燃油经济性!J28-CNS燃油经济性!J28)/BAU燃油经济性!J28,0) -> 0 | K28: =IFERROR((BAU燃油经济性!K28-CNS燃油经济性!K28)/BAU燃油经济性!K28,0) -> 0.0095695374 | ... S28: =IFERROR((BAU燃油经济性!S28-CNS燃油经济性!S28)/BAU燃油经济性!S28,0) -> -0.2807767 | U28: stage5 | V28: 2026 | W28: 30 | X28: =D28*$AA$9+E28*$AB$9 -> 0 | Z28: =F28*$AA$9+G28*$AB$9 -> 0 | AB28: =H28*$AA$11+I28*$AB$11 -> 0.0093144539 | AD28: =J28*$AA$10+K28*$AB$10 -> 0.0054894399 | AE28: 8919.2059 | AF28: =L28*$AA$10+M28*$AB$10 -> -0.16106388 | AG28: 109688.21 | AH28: =O28 -> -0.037367187 | AI28: 115778.35 | AJ28: =Q28 -> 0.010869565 | AK28: 1008115.4 | AL28: =R28*$AA$10+S28*$AB$10 -> -0.16106388 | AM28: 100281.59 | AO28: 2026 | AP28: =X28 -> 0 | AQ28: =AD28*AE28/(AE28+AG28+AM28)+AF28*AG28/(AE28+AG28+AM28)+AL28*AM28/(AE28+AG28+AM28) -> -0.15427723 | AR28: =AB28 -> 0.0093144539 | AS28: =AH28*AI28/(AI28+AK28)+AJ28*AK28/(AI28+AK28) -> 0.0059004373 | AT28: 2026 | AU28: =AP28/AP$62 -> 0 | AV28: =AQ28/AQ$62 -> -34.023416 | AW28: =AR28/AR$62 -> 0.37257816 | AX28: =AS28/AS$62 -> 0.21893587
B29: 2027 | D29: =IFERROR((BAU燃油经济性!D29-CNS燃油经济性!D29)/BAU燃油经济性!D29,0) -> 0.015 | E29: =IFERROR((BAU燃油经济性!E29-CNS燃油经济性!E29)/BAU燃油经济性!E29,0) -> 0 | F29: =IFERROR((BAU燃油经济性!F29-CNS燃油经济性!F29)/BAU燃油经济性!F29,0) -> 0.015 | G29: =IFERROR((BAU燃油经济性!G29-CNS燃油经济性!G29)/BAU燃油经济性!G29,0) -> 0 | H29: =IFERROR((BAU燃油经济性!H29-CNS燃油经济性!H29)/BAU燃油经济性!H29,0) -> 0.013668738 | I29: =IFERROR((BAU燃油经济性!I29-CNS燃油经济性!I29)/BAU燃油经济性!I29,0) -> 0.0093150685 | J29: =IFERROR((BAU燃油经济性!J29-CNS燃油经济性!J29)/BAU燃油经济性!J29,0) -> 0 | K29: =IFERROR((BAU燃油经济性!K29-CNS燃油经济性!K29)/BAU燃油经济性!K29,0) -> 0.025933861 | ... S29: =IFERROR((BAU燃油经济性!S29-CNS燃油经济性!S29)/BAU燃油经济性!S29,0) -> -0.26194175 | V29: 2027 | X29: =D29*$AA$9+E29*$AB$9 -> 0.014894941 | Z29: =F29*$AA$9+G29*$AB$9 -> 0.014894941 | AB29: =H29*$AA$11+I29*$AB$11 -> 0.011786407 | AD29: =J29*$AA$10+K29*$AB$10 -> 0.01487662 | AE29: 5757.3191 | AF29: =L29*$AA$10+M29*$AB$10 -> -0.15025946 | AG29: 114661.91 | AH29: =O29 -> -0.028956102 | AI29: 141551.97 | AJ29: =Q29 -> 0.012982351 | AK29: 1091325.1 | AL29: =R29*$AA$10+S29*$AB$10 -> -0.15025946 | AM29: 64731.445 | AO29: 2027 | AP29: =X29 -> 0.014894941 | AQ29: =AD29*AE29/(AE29+AG29+AM29)+AF29*AG29/(AE29+AG29+AM29)+AL29*AM29/(AE29+AG29+AM29) -> -0.1451245 | AR29: =AB29 -> 0.011786407 | AS29: =AH29*AI29/(AI29+AK29)+AJ29*AK29/(AI29+AK29) -> 0.008167215 | AT29: 2027 | AU29: =AP29/AP$62 -> 0.06 | AV29: =AQ29/AQ$62 -> -32.004925 | AW29: =AR29/AR$62 -> 0.47145626 | AX29: =AS29/AS$62 -> 0.3030447
B30: 2028 | D30: =IFERROR((BAU燃油经济性!D30-CNS燃油经济性!D30)/BAU燃油经济性!D30,0) -> 0.03 | E30: =IFERROR((BAU燃油经济性!E30-CNS燃油经济性!E30)/BAU燃油经济性!E30,0) -> 0 | F30: =IFERROR((BAU燃油经济性!F30-CNS燃油经济性!F30)/BAU燃油经济性!F30,0) -> 0.03 | G30: =IFERROR((BAU燃油经济性!G30-CNS燃油经济性!G30)/BAU燃油经济性!G30,0) -> 0 | H30: =IFERROR((BAU燃油经济性!H30-CNS燃油经济性!H30)/BAU燃油经济性!H30,0) -> 0.0164892 | I30: =IFERROR((BAU燃油经济性!I30-CNS燃油经济性!I30)/BAU燃油经济性!I30,0) -> 0.011376147 | J30: =IFERROR((BAU燃油经济性!J30-CNS燃油经济性!J30)/BAU燃油经济性!J30,0) -> 0 | K30: =IFERROR((BAU燃油经济性!K30-CNS燃油经济性!K30)/BAU燃油经济性!K30,0) -> 0.038584071 | ... S30: =IFERROR((BAU燃油经济性!S30-CNS燃油经济性!S30)/BAU燃油经济性!S30,0) -> -0.2431068 | V30: 2028 | X30: =D30*$AA$9+E30*$AB$9 -> 0.029789882 | Z30: =F30*$AA$9+G30*$AB$9 -> 0.029789882 | AB30: =H30*$AA$11+I30*$AB$11 -> 0.014278545 | AD30: =J30*$AA$10+K30*$AB$10 -> 0.022133247 | AE30: 3393.0166 | AF30: =L30*$AA$10+M30*$AB$10 -> -0.13945503 | AG30: 125956.54 | AH30: =O30 -> -0.020545017 | AI30: 151334.27 | AJ30: =Q30 -> 0.015114183 | AK30: 1235508 | AL30: =R30*$AA$10+S30*$AB$10 -> -0.13945503 | AM30: 38148.809 | AO30: 2028 | AP30: =X30 -> 0.029789882 | AQ30: =AD30*AE30/(AE30+AG30+AM30)+AF30*AG30/(AE30+AG30+AM30)+AL30*AM30/(AE30+AG30+AM30) -> -0.13618174 | AR30: =AB30 -> 0.014278545 | AS30: =AH30*AI30/(AI30+AK30)+AJ30*AK30/(AI30+AK30) -> 0.011222998 | AT30: 2028 | AU30: =AP30/AP$62 -> 0.12 | AV30: =AQ30/AQ$62 -> -30.03274 | AW30: =AR30/AR$62 -> 0.57114181 | AX30: =AS30/AS$62 -> 0.41642961
B31: 2029 | D31: =IFERROR((BAU燃油经济性!D31-CNS燃油经济性!D31)/BAU燃油经济性!D31,0) -> 0.045 | E31: =IFERROR((BAU燃油经济性!E31-CNS燃油经济性!E31)/BAU燃油经济性!E31,0) -> 0 | F31: =IFERROR((BAU燃油经济性!F31-CNS燃油经济性!F31)/BAU燃油经济性!F31,0) -> 0.045 | G31: =IFERROR((BAU燃油经济性!G31-CNS燃油经济性!G31)/BAU燃油经济性!G31,0) -> 0 | H31: =IFERROR((BAU燃油经济性!H31-CNS燃油经济性!H31)/BAU燃油经济性!H31,0) -> 0.019331196 | I31: =IFERROR((BAU燃油经济性!I31-CNS燃油经济性!I31)/BAU燃油经济性!I31,0) -> 0.013456221 | J31: =IFERROR((BAU燃油经济性!J31-CNS燃油经济性!J31)/BAU燃油经济性!J31,0) -> 0 | K31: =IFERROR((BAU燃油经济性!K31-CNS燃油经济性!K31)/BAU燃油经济性!K31,0) -> 0.05123428 | ... S31: =IFERROR((BAU燃油经济性!S31-CNS燃油经济性!S31)/BAU燃油经济性!S31,0) -> -0.22427184 | V31: 2029 | X31: =D31*$AA$9+E31*$AB$9 -> 0.044684823 | Z31: =F31*$AA$9+G31*$AB$9 -> 0.044684823 | AB31: =H31*$AA$11+I31*$AB$11 -> 0.01679112 | AD31: =J31*$AA$10+K31*$AB$10 -> 0.029389875 | AE31: 4478.1881 | AF31: =L31*$AA$10+M31*$AB$10 -> -0.12865061 | AG31: 137936.1 | AH31: =O31 -> -0.012133931 | AI31: 141366.99 | AJ31: =Q31 -> 0.017265318 | AK31: 1284527.3 | AL31: =R31*$AA$10+S31*$AB$10 -> -0.12865061 | AM31: 50349.752 | AO31: 2029 | AP31: =X31 -> 0.044684823 | AQ31: =AD31*AE31/(AE31+AG31+AM31)+AF31*AG31/(AE31+AG31+AM31)+AL31*AM31/(AE31+AG31+AM31) -> -0.1249791 | AR31: =AB31 -> 0.01679112 | AS31: =AH31*AI31/(AI31+AK31)+AJ31*AK31/(AI31+AK31) -> 0.014350598 | AT31: 2029 | AU31: =AP31/AP$62 -> 0.18 | AV31: =AQ31/AQ$62 -> -27.562175 | AW31: =AR31/AR$62 -> 0.67164481 | AX31: =AS31/AS$62 -> 0.53247927
B32: 2030 | D32: =IFERROR((BAU燃油经济性!D32-CNS燃油经济性!D32)/BAU燃油经济性!D32,0) -> 0.06 | E32: =IFERROR((BAU燃油经济性!E32-CNS燃油经济性!E32)/BAU燃油经济性!E32,0) -> 0 | F32: =IFERROR((BAU燃油经济性!F32-CNS燃油经济性!F32)/BAU燃油经济性!F32,0) -> 0.06 | G32: =IFERROR((BAU燃油经济性!G32-CNS燃油经济性!G32)/BAU燃油经济性!G32,0) -> 0 | H32: =IFERROR((BAU燃油经济性!H32-CNS燃油经济性!H32)/BAU燃油经济性!H32,0) -> 0.022194972 | I32: =IFERROR((BAU燃油经济性!I32-CNS燃油经济性!I32)/BAU燃油经济性!I32,0) -> 0.015555556 | J32: =IFERROR((BAU燃油经济性!J32-CNS燃油经济性!J32)/BAU燃油经济性!J32,0) -> 0 | K32: =IFERROR((BAU燃油经济性!K32-CNS燃油经济性!K32)/BAU燃油经济性!K32,0) -> 0.06388449 | ... S32: =IFERROR((BAU燃油经济性!S32-CNS燃油经济性!S32)/BAU燃油经济性!S32,0) -> -0.20543689 | V32: 2030 | X32: =D32*$AA$9+E32*$AB$9 -> 0.059579764 | Z32: =F32*$AA$9+G32*$AB$9 -> 0.059579764 | AB32: =H32*$AA$11+I32*$AB$11 -> 0.019324387 | AD32: =J32*$AA$10+K32*$AB$10 -> 0.036646502 | AE32: 11070.36 | AF32: =L32*$AA$10+M32*$AB$10 -> -0.11784619 | AG32: 145747.51 | AH32: =O32 -> -0.003722846 | AI32: 118505.98 | AJ32: =Q32 -> 0.019436022 | AK32: 1197686.1 | AL32: =R32*$AA$10+S32*$AB$10 -> -0.11784619 | AM32: 124467.72 | AO32: 2030 | AP32: =X32 -> 0.059579764 | AQ32: =AD32*AE32/(AE32+AG32+AM32)+AF32*AG32/(AE32+AG32+AM32)+AL32*AM32/(AE32+AG32+AM32) -> -0.11176593 | AR32: =AB32 -> 0.019324387 | AS32: =AH32*AI32/(AI32+AK32)+AJ32*AK32/(AI32+AK32) -> 0.017350867 | AT32: 2030 | AU32: =AP32/AP$62 -> 0.24 | AV32: =AQ32/AQ$62 -> -24.648217 | AW32: =AR32/AR$62 -> 0.77297546 | AX32: =AS32/AS$62 -> 0.64380433
A33: stage6 | B33: 2031 | C33: 40 | D33: =IFERROR((BAU燃油经济性!D33-CNS燃油经济性!D33)/BAU燃油经济性!D33,0) -> 0.075 | E33: =IFERROR((BAU燃油经济性!E33-CNS燃油经济性!E33)/BAU燃油经济性!E33,0) -> 0 | F33: =IFERROR((BAU燃油经济性!F33-CNS燃油经济性!F33)/BAU燃油经济性!F33,0) -> 0.075 | G33: =IFERROR((BAU燃油经济性!G33-CNS燃油经济性!G33)/BAU燃油经济性!G33,0) -> 0 | H33: =IFERROR((BAU燃油经济性!H33-CNS燃油经济性!H33)/BAU燃油经济性!H33,0) -> 0.025080782 | I33: =IFERROR((BAU燃油经济性!I33-CNS燃油经济性!I33)/BAU燃油经济性!I33,0) -> 0.017674419 | J33: =IFERROR((BAU燃油经济性!J33-CNS燃油经济性!J33)/BAU燃油经济性!J33,0) -> 0 | K33: =IFERROR((BAU燃油经济性!K33-CNS燃油经济性!K33)/BAU燃油经济性!K33,0) -> 0.0765347 | ... S33: =IFERROR((BAU燃油经济性!S33-CNS燃油经济性!S33)/BAU燃油经济性!S33,0) -> -0.18660194 | U33: stage6 | V33: 2031 | W33: 40 | X33: =D33*$AA$9+E33*$AB$9 -> 0.074474705 | Z33: =F33*$AA$9+G33*$AB$9 -> 0.074474705 | AB33: =H33*$AA$11+I33*$AB$11 -> 0.021878603 | AD33: =J33*$AA$10+K33*$AB$10 -> 0.043903129 | AE33: 9006.5422 | AF33: =L33*$AA$10+M33*$AB$10 -> -0.10704176 | AG33: 146663.3 | AH33: =O33 -> 0.0046882393 | AI33: 95696.894 | AJ33: =Q33 -> 0.022222222 | AK33: 1144266.8 | AL33: =R33*$AA$10+S33*$AB$10 -> -0.10704176 | AM33: 101263.54 | AO33: 2031 | AP33: =X33 -> 0.074474705 | AQ33: =AD33*AE33/(AE33+AG33+AM33)+AF33*AG33/(AE33+AG33+AM33)+AL33*AM33/(AE33+AG33+AM33) -> -0.10175054 | AR33: =AB33 -> 0.021878603 | AS33: =AH33*AI33/(AI33+AK33)+AJ33*AK33/(AI33+AK33) -> 0.020868999 | AT33: 2031 | AU33: =AP33/AP$62 -> 0.3 | AV33: =AQ33/AQ$62 -> -22.439481 | AW33: =AR33/AR$62 -> 0.87514411 | AX33: =AS33/AS$62 -> 0.7743447
B34: 2032 | D34: =IFERROR((BAU燃油经济性!D34-CNS燃油经济性!D34)/BAU燃油经济性!D34,0) -> 0.085 | E34: =IFERROR((BAU燃油经济性!E34-CNS燃油经济性!E34)/BAU燃油经济性!E34,0) -> 0 | F34: =IFERROR((BAU燃油经济性!F34-CNS燃油经济性!F34)/BAU燃油经济性!F34,0) -> 0.085 | G34: =IFERROR((BAU燃油经济性!G34-CNS燃油经济性!G34)/BAU燃油经济性!G34,0) -> 0 | H34: =IFERROR((BAU燃油经济性!H34-CNS燃油经济性!H34)/BAU燃油经济性!H34,0) -> 0.024994196 | I34: =IFERROR((BAU燃油经济性!I34-CNS燃油经济性!I34)/BAU燃油经济性!I34,0) -> 0.018691589 | J34: =IFERROR((BAU燃油经济性!J34-CNS燃油经济性!J34)/BAU燃油经济性!J34,0) -> 0 | K34: =IFERROR((BAU燃油经济性!K34-CNS燃油经济性!K34)/BAU燃油经济性!K34,0) -> 0.082859804 | ... S34: =IFERROR((BAU燃油经济性!S34-CNS燃油经济性!S34)/BAU燃油经济性!S34,0) -> -0.17718447 | V34: 2032 | X34: =D34*$AA$9+E34*$AB$9 -> 0.084404665 | Z34: =F34*$AA$9+G34*$AB$9 -> 0.084404665 | AB34: =H34*$AA$11+I34*$AB$11 -> 0.022269232 | AD34: =J34*$AA$10+K34*$AB$10 -> 0.047531443 | AE34: 4630.3822 | AF34: =L34*$AA$10+M34*$AB$10 -> -0.10163955 | AG34: 140899.82 | AH34: =O34 -> 0.0074919344 | AI34: 82050.974 | AJ34: =Q34 -> 0.022196709 | AK34: 1100207.9 | AL34: =R34*$AA$10+S34*$AB$10 -> -0.10163955 | AM34: 52060.921 | AO34: 2032 | AP34: =X34 -> 0.084404665 | AQ34: =AD34*AE34/(AE34+AG34+AM34)+AF34*AG34/(AE34+AG34+AM34)+AL34*AM34/(AE34+AG34+AM34) -> -0.098143853 | AR34: =AB34 -> 0.022269232 | AS34: =AH34*AI34/(AI34+AK34)+AJ34*AK34/(AI34+AK34) -> 0.02117617 | AT34: 2032 | AU34: =AP34/AP$62 -> 0.34 | AV34: =AQ34/AQ$62 -> -21.644083 | AW34: =AR34/AR$62 -> 0.89076927 | AX34: =AS34/AS$62 -> 0.78574228
B35: 2033 | D35: =IFERROR((BAU燃油经济性!D35-CNS燃油经济性!D35)/BAU燃油经济性!D35,0) -> 0.095 | E35: =IFERROR((BAU燃油经济性!E35-CNS燃油经济性!E35)/BAU燃油经济性!E35,0) -> 0 | F35: =IFERROR((BAU燃油经济性!F35-CNS燃油经济性!F35)/BAU燃油经济性!F35,0) -> 0.095 | G35: =IFERROR((BAU燃油经济性!G35-CNS燃油经济性!G35)/BAU燃油经济性!G35,0) -> 0 | H35: =IFERROR((BAU燃油经济性!H35-CNS燃油经济性!H35)/BAU燃油经济性!H35,0) -> 0.0249066 | I35: =IFERROR((BAU燃油经济性!I35-CNS燃油经济性!I35)/BAU燃油经济性!I35,0) -> 0.01971831 | J35: =IFERROR((BAU燃油经济性!J35-CNS燃油经济性!J35)/BAU燃油经济性!J35,0) -> 0 | K35: =IFERROR((BAU燃油经济性!K35-CNS燃油经济性!K35)/BAU燃油经济性!K35,0) -> 0.089184909 | ... S35: =IFERROR((BAU燃油经济性!S35-CNS燃油经济性!S35)/BAU燃油经济性!S35,0) -> -0.16776699 | V35: 2033 | X35: =D35*$AA$9+E35*$AB$9 -> 0.094334626 | Z35: =F35*$AA$9+G35*$AB$9 -> 0.094334626 | AB35: =H35*$AA$11+I35*$AB$11 -> 0.022663416 | AD35: =J35*$AA$10+K35*$AB$10 -> 0.051159756 | AE35: 3755.8111 | AF35: =L35*$AA$10+M35*$AB$10 -> -0.096237339 | AG35: 132073.35 | AH35: =O35 -> 0.010295629 | AI35: 79744.378 | AJ35: =Q35 -> 0.022170901 | AK35: 1056949.4 | AL35: =R35*$AA$10+S35*$AB$10 -> -0.096237339 | AM35: 42227.828 | AO35: 2033 | AP35: =X35 -> 0.094334626 | AQ35: =AD35*AE35/(AE35+AG35+AM35)+AF35*AG35/(AE35+AG35+AM35)+AL35*AM35/(AE35+AG35+AM35) -> -0.093128246 | AR35: =AB35 -> 0.022663416 | AS35: =AH35*AI35/(AI35+AK35)+AJ35*AK35/(AI35+AK35) -> 0.021337795 | AT35: 2033 | AU35: =AP35/AP$62 -> 0.38 | AV35: =AQ35/AQ$62 -> -20.53797 | AW35: =AR35/AR$62 -> 0.90653665 | AX35: =AS35/AS$62 -> 0.79173938
B36: 2034 | D36: =IFERROR((BAU燃油经济性!D36-CNS燃油经济性!D36)/BAU燃油经济性!D36,0) -> 0.105 | E36: =IFERROR((BAU燃油经济性!E36-CNS燃油经济性!E36)/BAU燃油经济性!E36,0) -> 0 | F36: =IFERROR((BAU燃油经济性!F36-CNS燃油经济性!F36)/BAU燃油经济性!F36,0) -> 0.105 | G36: =IFERROR((BAU燃油经济性!G36-CNS燃油经济性!G36)/BAU燃油经济性!G36,0) -> 0 | H36: =IFERROR((BAU燃油经济性!H36-CNS燃油经济性!H36)/BAU燃油经济性!H36,0) -> 0.024817975 | I36: =IFERROR((BAU燃油经济性!I36-CNS燃油经济性!I36)/BAU燃油经济性!I36,0) -> 0.020754717 | J36: =IFERROR((BAU燃油经济性!J36-CNS燃油经济性!J36)/BAU燃油经济性!J36,0) -> 0 | K36: =IFERROR((BAU燃油经济性!K36-CNS燃油经济性!K36)/BAU燃油经济性!K36,0) -> 0.095510014 | ... S36: =IFERROR((BAU燃油经济性!S36-CNS燃油经济性!S36)/BAU燃油经济性!S36,0) -> -0.15834951 | V36: 2034 | X36: =D36*$AA$9+E36*$AB$9 -> 0.10426459 | Z36: =F36*$AA$9+G36*$AB$9 -> 0.10426459 | AB36: =H36*$AA$11+I36*$AB$11 -> 0.023061205 | AD36: =J36*$AA$10+K36*$AB$10 -> 0.05478807 | AE36: 5456.6019 | AF36: =L36*$AA$10+M36*$AB$10 -> -0.090835127 | AG36: 125100.96 | AH36: =O36 -> 0.013099325 | AI36: 86230.697 | AJ36: =Q36 -> 0.022144793 | AK36: 1029292.8 | AL36: =R36*$AA$10+S36*$AB$10 -> -0.090835127 | AM36: 61350.382 | AO36: 2034 | AP36: =X36 -> 0.10426459 | AQ36: =AD36*AE36/(AE36+AG36+AM36)+AF36*AG36/(AE36+AG36+AM36)+AL36*AM36/(AE36+AG36+AM36) -> -0.086694559 | AR36: =AB36 -> 0.023061205 | AS36: =AH36*AI36/(AI36+AK36)+AJ36*AK36/(AI36+AK36) -> 0.021445572 | AT36: 2034 | AU36: =AP36/AP$62 -> 0.42 | AV36: =AQ36/AQ$62 -> -19.119121 | AW36: =AR36/AR$62 -> 0.92244819 | AX36: =AS36/AS$62 -> 0.79573846
B37: 2035 | D37: =IFERROR((BAU燃油经济性!D37-CNS燃油经济性!D37)/BAU燃油经济性!D37,0) -> 0.115 | E37: =IFERROR((BAU燃油经济性!E37-CNS燃油经济性!E37)/BAU燃油经济性!E37,0) -> 0 | F37: =IFERROR((BAU燃油经济性!F37-CNS燃油经济性!F37)/BAU燃油经济性!F37,0) -> 0.115 | G37: =IFERROR((BAU燃油经济性!G37-CNS燃油经济性!G37)/BAU燃油经济性!G37,0) -> 0 | H37: =IFERROR((BAU燃油经济性!H37-CNS燃油经济性!H37)/BAU燃油经济性!H37,0) -> 0.024728304 | I37: =IFERROR((BAU燃油经济性!I37-CNS燃油经济性!I37)/BAU燃油经济性!I37,0) -> 0.021800948 | J37: =IFERROR((BAU燃油经济性!J37-CNS燃油经济性!J37)/BAU燃油经济性!J37,0) -> 0 | K37: =IFERROR((BAU燃油经济性!K37-CNS燃油经济性!K37)/BAU燃油经济性!K37,0) -> 0.10183512 | ... S37: =IFERROR((BAU燃油经济性!S37-CNS燃油经济性!S37)/BAU燃油经济性!S37,0) -> -0.14893204 | V37: 2035 | X37: =D37*$AA$9+E37*$AB$9 -> 0.11419455 | Z37: =F37*$AA$9+G37*$AB$9 -> 0.11419455 | AB37: =H37*$AA$11+I37*$AB$11 -> 0.023462646 | AD37: =J37*$AA$10+K37*$AB$10 -> 0.058416383 | AE37: 8134.1684 | AF37: =L37*$AA$10+M37*$AB$10 -> -0.085432915 | AG37: 122564.84 | AH37: =O37 -> 0.01590302 | AI37: 98312.86 | AJ37: =Q37 -> 0.02211838 | AK37: 1055976.8 | AL37: =R37*$AA$10+S37*$AB$10 -> -0.085432915 | AM37: 91455.149 | AO37: 2035 | AP37: =X37 -> 0.11419455 | AQ37: =AD37*AE37/(AE37+AG37+AM37)+AF37*AG37/(AE37+AG37+AM37)+AL37*AM37/(AE37+AG37+AM37) -> -0.080165877 | AR37: =AB37 -> 0.023462646 | AS37: =AH37*AI37/(AI37+AK37)+AJ37*AK37/(AI37+AK37) -> 0.021589007 | AT37: 2035 | AU37: =AP37/AP$62 -> 0.46 | AV37: =AQ37/AQ$62 -> -17.679323 | AW37: =AR37/AR$62 -> 0.93850586 | AX37: =AS37/AS$62 -> 0.80106061
B38: 2036 | D38: =IFERROR((BAU燃油经济性!D38-CNS燃油经济性!D38)/BAU燃油经济性!D38,0) -> 0.125 | E38: =IFERROR((BAU燃油经济性!E38-CNS燃油经济性!E38)/BAU燃油经济性!E38,0) -> 0 | F38: =IFERROR((BAU燃油经济性!F38-CNS燃油经济性!F38)/BAU燃油经济性!F38,0) -> 0.125 | G38: =IFERROR((BAU燃油经济性!G38-CNS燃油经济性!G38)/BAU燃油经济性!G38,0) -> 0 | H38: =IFERROR((BAU燃油经济性!H38-CNS燃油经济性!H38)/BAU燃油经济性!H38,0) -> 0.024637566 | I38: =IFERROR((BAU燃油经济性!I38-CNS燃油经济性!I38)/BAU燃油经济性!I38,0) -> 0.022857143 | J38: =IFERROR((BAU燃油经济性!J38-CNS燃油经济性!J38)/BAU燃油经济性!J38,0) -> 0 | K38: =IFERROR((BAU燃油经济性!K38-CNS燃油经济性!K38)/BAU燃油经济性!K38,0) -> 0.10816022 | ... S38: =IFERROR((BAU燃油经济性!S38-CNS燃油经济性!S38)/BAU燃油经济性!S38,0) -> -0.13951456 | V38: 2036 | X38: =D38*$AA$9+E38*$AB$9 -> 0.12412451 | Z38: =F38*$AA$9+G38*$AB$9 -> 0.12412451 | AB38: =H38*$AA$11+I38*$AB$11 -> 0.023867791 | AD38: =J38*$AA$10+K38*$AB$10 -> 0.062044697 | AE38: 7098.0455 | AF38: =L38*$AA$10+M38*$AB$10 -> -0.080030704 | AG38: 123349.66 | AH38: =O38 -> 0.018706715 | AI38: 112936.4 | AJ38: =Q38 -> 0.022091657 | AK38: 1117312.6 | AL38: =R38*$AA$10+S38*$AB$10 -> -0.080030704 | AM38: 79805.677 | AO38: 2036 | AP38: =X38 -> 0.12412451 | AQ38: =AD38*AE38/(AE38+AG38+AM38)+AF38*AG38/(AE38+AG38+AM38)+AL38*AM38/(AE38+AG38+AM38) -> -0.075234311 | AR38: =AB38 -> 0.023867791 | AS38: =AH38*AI38/(AI38+AK38)+AJ38*AK38/(AI38+AK38) -> 0.02178092 | AT38: 2036 | AU38: =AP38/AP$62 -> 0.5 | AV38: =AQ38/AQ$62 -> -16.591744 | AW38: =AR38/AR$62 -> 0.95471165 | AX38: =AS38/AS$62 -> 0.80818156
B39: 2037 | D39: =IFERROR((BAU燃油经济性!D39-CNS燃油经济性!D39)/BAU燃油经济性!D39,0) -> 0.135 | E39: =IFERROR((BAU燃油经济性!E39-CNS燃油经济性!E39)/BAU燃油经济性!E39,0) -> 0 | F39: =IFERROR((BAU燃油经济性!F39-CNS燃油经济性!F39)/BAU燃油经济性!F39,0) -> 0.135 | G39: =IFERROR((BAU燃油经济性!G39-CNS燃油经济性!G39)/BAU燃油经济性!G39,0) -> 0 | H39: =IFERROR((BAU燃油经济性!H39-CNS燃油经济性!H39)/BAU燃油经济性!H39,0) -> 0.024545744 | I39: =IFERROR((BAU燃油经济性!I39-CNS燃油经济性!I39)/BAU燃油经济性!I39,0) -> 0.023923445 | J39: =IFERROR((BAU燃油经济性!J39-CNS燃油经济性!J39)/BAU燃油经济性!J39,0) -> 0 | K39: =IFERROR((BAU燃油经济性!K39-CNS燃油经济性!K39)/BAU燃油经济性!K39,0) -> 0.11448533 | ... S39: =IFERROR((BAU燃油经济性!S39-CNS燃油经济性!S39)/BAU燃油经济性!S39,0) -> -0.13009709 | V39: 2037 | X39: =D39*$AA$9+E39*$AB$9 -> 0.13405447 | Z39: =F39*$AA$9+G39*$AB$9 -> 0.13405447 | AB39: =H39*$AA$11+I39*$AB$11 -> 0.02427669 | AD39: =J39*$AA$10+K39*$AB$10 -> 0.065673011 | AE39: 4412.9167 | AF39: =L39*$AA$10+M39*$AB$10 -> -0.074628492 | AG39: 124763.97 | AH39: =O39 -> 0.02151041 | AI39: 125568.87 | AJ39: =Q39 -> 0.022064618 | AK39: 1167491.6 | AL39: =R39*$AA$10+S39*$AB$10 -> -0.074628492 | AM39: 49615.883 | AO39: 2037 | AP39: =X39 -> 0.13405447 | AQ39: =AD39*AE39/(AE39+AG39+AM39)+AF39*AG39/(AE39+AG39+AM39)+AL39*AM39/(AE39+AG39+AM39) -> -0.071165607 | AR39: =AB39 -> 0.02427669 | AS39: =AH39*AI39/(AI39+AK39)+AJ39*AK39/(AI39+AK39) -> 0.022010799 | AT39: 2037 | AU39: =AP39/AP$62 -> 0.54 | AV39: =AQ39/AQ$62 -> -15.694455 | AW39: =AR39/AR$62 -> 0.9710676 | AX39: =AS39/AS$62 -> 0.81671121
B40: 2038 | D40: =IFERROR((BAU燃油经济性!D40-CNS燃油经济性!D40)/BAU燃油经济性!D40,0) -> 0.145 | E40: =IFERROR((BAU燃油经济性!E40-CNS燃油经济性!E40)/BAU燃油经济性!E40,0) -> 0 | F40: =IFERROR((BAU燃油经济性!F40-CNS燃油经济性!F40)/BAU燃油经济性!F40,0) -> 0.145 | G40: =IFERROR((BAU燃油经济性!G40-CNS燃油经济性!G40)/BAU燃油经济性!G40,0) -> 0 | H40: =IFERROR((BAU燃油经济性!H40-CNS燃油经济性!H40)/BAU燃油经济性!H40,0) -> 0.024452818 | I40: =IFERROR((BAU燃油经济性!I40-CNS燃油经济性!I40)/BAU燃油经济性!I40,0) -> 0.025 | J40: =IFERROR((BAU燃油经济性!J40-CNS燃油经济性!J40)/BAU燃油经济性!J40,0) -> 0 | K40: =IFERROR((BAU燃油经济性!K40-CNS燃油经济性!K40)/BAU燃油经济性!K40,0) -> 0.12081043 | ... S40: =IFERROR((BAU燃油经济性!S40-CNS燃油经济性!S40)/BAU燃油经济性!S40,0) -> -0.12067961 | V40: 2038 | X40: =D40*$AA$9+E40*$AB$9 -> 0.14398443 | Z40: =F40*$AA$9+G40*$AB$9 -> 0.14398443 | AB40: =H40*$AA$11+I40*$AB$11 -> 0.024689395 | AD40: =J40*$AA$10+K40*$AB$10 -> 0.069301324 | AE40: 4116.9419 | AF40: =L40*$AA$10+M40*$AB$10 -> -0.06922628 | AG40: 125588.54 | AH40: =O40 -> 0.024314105 | AI40: 131687.1 | AJ40: =Q40 -> 0.022037257 | AK40: 1190489.5 | AL40: =R40*$AA$10+S40*$AB$10 -> -0.06922628 | AM40: 46288.141 | AO40: 2038 | AP40: =X40 -> 0.14398443 | AQ40: =AD40*AE40/(AE40+AG40+AM40)+AF40*AG40/(AE40+AG40+AM40)+AL40*AM40/(AE40+AG40+AM40) -> -0.065985764 | AR40: =AB40 -> 0.024689395 | AS40: =AH40*AI40/(AI40+AK40)+AJ40*AK40/(AI40+AK40) -> 0.022264028 | AT40: 2038 | AU40: =AP40/AP$62 -> 0.58 | AV40: =AQ40/AQ$62 -> -14.552122 | AW40: =AR40/AR$62 -> 0.9875758 | AX40: =AS40/AS$62 -> 0.82610729
...
