Workbook
Name Eno_TM: '[1]1997 Table 1a Modified'!#REF!
Name Eno_Tons: '[1]1997 Table 1a Modified'!#REF!
Name Sum_T2: '[1]1997 Table 1a Modified'!#REF!
Name Sum_TTM: '[1]1997 Table 1a Modified'!#REF!
Name ti_tbl_50: #REF!
Name ti_tbl_69: #REF!

Sheet About
A1: AVMC Annual Vehicle Maintenance Cost | C1: 仅是维护成本，不考虑燃料成本
A3: Sources: | B3: Passenger LDVs (ICE and BEV)
B4: 西部担保West Guarantee
B5: 2020
B6: 动力电池产业链下游：从政策到市场，整车消费端已实现平价
B7: https://pdf.dfcfw.com/pdf/H3_AP202003201376728272_1.pdf?1584710037000.pdf
B8: P4
B9: Freight LDVs(ICE and BEV)
B10: 渤海证券 Bohai Secturities
B11: 2016
B12: 纯电动物流车迎来发展黄金时代——纯电动物流车行业专题报告
B13: http://pdf.dfcfw.com/pdf/H3_AP201607070016463141_1.pdf
B15: Freight HDVs(ICE and BEV)
B16: 丁倩
B17: 2019
B18: 新能源物流车的TCO竞争力分析
B19: http://www.autoinfo.org.cn/autoinfo_cn/content/news/20191216/1853501.html
B21: Freight HDVs
B22: Truck Driver Institute
B23: 2013
B24: What is the real cost of truck driving?
B25: https://www.drivebigtrucks.com/trucking-news/the-real-operating-cost-of-a-commercial-truck/
B26: Infographic
B28: Passenger HDVs
B29: 万剑, 季锦章, 王维锋WAN Jian, JI Jin-zhang, WANG Wei-fen
B30: 2015
B31: 考虑资金时间价值的新能源公交车经济性分析Analysis on Economy of New Energy Bus Considering Time Value of Funds
B32: http://html.rhhz.net/GLJTKJ/20150325.htm
B33: 电动车整体维护成本比燃油车低22％
B34: https://baijiahao.baidu.com/s?id=1740240141341962732&wfr=spider&for=pc
B35: Aircraft
B36: Airchina中国国际航空公司
B37: 2017
B38: 中国国际航空股份有限公司2017年报 | D38: 空难背后的东航，维修费用到底是降是增？
B39: https://pdf.dfcfw.com/pdf/H2_AN201803271111567559_1.pdf | D39: https://baike.baidu.com/tashuo/browse/content?id=12a0536158d3b7d313341214
B41: China Eastern
B42: 2018
B43: 中国国际航空股份有限公司2017年报
B44: http://www.ceair.com/upload/2019/3/602.pdf
B46: China Sourthern Airline
...

Sheet China-data
A2: Freight LDV
A10: ICE车型选取总质量4.5吨级别的江淮骏铃V6车型，EV车型选取江淮帅铃i5纯电动车型。
A12: Passenger LDV
K32: 成本 分类 | M32: 项目 | N32: 奇瑞 QQ | O32: 奇瑞 eQi | P32: 上汽大 众•朗逸 | Q32: 上汽大 众•朗逸 | R32: 奥迪Q2L 35TFSI | S32: 奥迪Q2L e-tron
K33: 指标 | M33: 车型 | N33: 燃油 A00 级 | O33: 纯电 A00级 | P33: 燃油A 级 | Q33: 纯电A 级 | R33: 燃油 SUV | S33: 纯电 SUV
M34: 电池容量（kWh） | O34: 38 | Q34: 38.1 | S34: 39.7
L35: 购 置 成 本 | M35: 厂商指导价（万元） | N35: 4.29 | O35: 5.97 | P35: 13.99 | Q35: 13.09 | R35: 26.85 | S35: 22.68
M36: 补贴后厂商指导价格（万元） | N36: 4.29 | O36: 5.97 | P36: 13.99 | Q36: 14.89 | R36: 26.85 | S36: 20.88
M37: 牌照费用（万元） | N37: 6 | O37: 0 | P37: 6 | Q37: 0 | R37: 6 | S37: 0
M38: 购置税（万元） | N38: 0.37 | O38: 0 | P38: 1.24 | Q38: 0 | R38: 2.38 | S38: 0
K39: 汽 车 生 命 周 期 成 本 | M39: 注册上牌费（万元） | N39: 0.03 | O39: 0.03 | P39: 0.03 | Q39: 0.03 | R39: 0.03 | S39: 0.03
L40: 合计 | N40: 10.69 | O40: 6 | P40: 21.26 | Q40: 14.92 | R40: 35.26 | S40: 22.71
L41: 使 用 维 护 成 本 | M41: 百公里能源消耗量（度、升/ 百公里） | N41: 5.9 | O41: 13 | P41: 5.5 | Q41: 13.2 | R41: 6.1 | S41: 13.9
M42: 能源价格（元/度、元/升） | N42: 6.79 | O42: 0.95 | P42: 6.79 | Q42: 0.95 | R42: 6.79 | S42: 0.95
M43: 年度行驶里程（百公里） | N43: 100 | O43: 100 | P43: 100 | Q43: 100 | R43: 100 | S43: 100
M44: 动力费用（万元） | N44: 0.401 | O44: 0.124 | P44: 373 | Q44: 0.125 | R44: 0.414 | S44: 0.132
M45: 维护成本（万元/年） | N45: 0.2 | O45: 0.1 | P45: 0.3 | Q45: 0.15 | R45: 0.4 | S45: 0.2
M46: 交强险（万元/年） | N46: 0.095 | O46: 0.095 | P46: 0.095 | Q46: 0.095 | R46: 0.095 | S46: 0.095
M47: 商业保险（万元/年） | N47: 0.144 | O47: 0.163 | P47: 0.25 | Q47: 0.26 | R47: 0.39 | S47: 0.344
M48: 车船税（万元/年） | N48: 0.024 | O48: 0 | P48: 0.024 | Q48: 0 | R48: 0.024 | S48: 0
L49: 合计 | N49: 0.864 | O49: 0.481 | P49: 1.042 | Q49: 0.63 | R49: 1.323 | S49: 0.771

Sheet China-Cost Data
A1: Overall Assumptions
A3: ICE | B3: We assume that internal combustion engine (ICE) costs apply to all of the following vehicle technologies:
B4: gasoline vehicle, diesel vehicle, natural gas vehicle, LPG vehicle, plug-in hybrid vehicle
B5: The assumption that plug-in hybrids (which contain an ICE engine) have similar annual maintenance costs
B6: to other ICE vehicles (e.g. the battery adds negligible cost)
A8: BEV | B8: We assume that battery electric vehicle (BEV) costs apply to all of the following vehicle technologies:
B9: battery electric vehicle, hydrogen vehicle
B10: Today, hydrogen vehicles are typically fuel cell vehicles (not internal combustion vehicles), and we assume they have
B11: similar maintenance costs to pure BEVs.
B12: We also use this category for electric rail, even though the locomotives are powered by third rail or catenary wire,
B13: rather than batteries.
A16: Freight-LDVs
B18: ICE | C18: 1800 | D18: 2700 | F18: =(C18+D18)/2 -> 2250
B19: BEV | C19: =C18/3 -> 600 | D19: =D18/3 -> 900 | E19: assumption: 30% of ICE | F19: =F18/3 -> 750
A22: Passenger LDVs
B23: CheryQQ-ICE | C23: Chery eQi-BEV | D23: Volkswagen Lavida-ICE | E23: Volkswagen Lavida-BEV | F23: Audi-ICE | G23: Audi-BEV
B24: 8640 | C24: 4810 | D24: 10420 | E24: 6300 | F24: 13230 | G24: 7710
B25: ICE | C25: =AVERAGE(B24,D24,F24) -> 10763.333
B26: BEV | C26: =AVERAGE(C24,E24,G24) -> 6273.3333
A28: HDVs (Trucks)
B29: ICE | C29: 65600 | D29: 2019 RMB/yr | E29: 4.8吨以上
B30: BEV | C30: 28800 | D30: 2019 RMB/yr
A32: HDVs (Buses)
B33: ICE-普通柴油公交车 | C33: 20000
B34: BEV-纯电动公交车 | C34: =C33*(1-0.22) -> 15600 | D34: BEV换电池算维护成本吗？说法不一，甚至有些维护费是车企出，这可能与国家补贴政策有关
A36: aircraft
A37: maintenance | C37: AirChina， 2017 | D37: China Eastern,2018 | E37: China southern airline,2018 | G37: 国航2000 | H37: 东航2020 | I37: 南航2020 | J37: 春秋2020 | K37: 吉祥2020
B38: 飞机数量the number of plane | C38: 655 | D38: 692 | E38: 840 | G38: 729 | H38: 758 | I38: 869 | J38: 108 | K38: 78
B39: Maintenance Cost飞机保养、维修和大修成本 | C39: 6213096000 | D39: 3738000000 | E39: 12704000000 | G39: 6423000000 | H39: 3451000000 | I39: 10286000000 | J39: 654000000 | K39: 538000000
B40: average maintenance cost per plane | C40: =C39/C38 -> 9485642.7 | D40: =D39/D38 -> 5401734.1 | E40: =E39/E38 -> 15123810 | G40: =G39/G38 -> 8810699.6 | H40: =H39/H38 -> 4552770.4 | I40: =I39/I38 -> 11836594 | J40: =J39/J38 -> 6055555.6 | K40: =K39/K38 -> 6897435.9
B41: Aircraft | C41: =AVERAGE(C40:E40,G40:K40) -> 8520530.2
E42: 维修成本每年都变化
A43: rail
A44: maintenance costs
A45: These maintenance costs are for the entire train, not just the locomotive.
B47: 三级维修level 3 Maintenance | C47: 四级维修level 4 Maintenance | D47: 五级维修level 5 Maintenance
A48: electric maintenance（动车组每年维修费用） | B48: 4000000 | C48: 13500000 | D48: 25000000
A49: Average electric maintenance | B49: =AVERAGE(B48:D48) -> 14166667
A50: diesel maintenance | B50: =B49/70% -> 20238095 | C50: Assumption: electric train is 70% of diesel train
A53: Motorbike (Motorcycle)
...

Sheet Cost Data
A1: Overall Assumptions
A3: ICE | B3: We assume that internal combustion engine (ICE) costs apply to all of the following vehicle technologies:
B4: gasoline vehicle, diesel vehicle, natural gas vehicle, LPG vehicle, plug-in hybrid vehicle
B5: The assumption that plug-in hybrids (which contain an ICE engine) have similar annual maintenance costs
B6: to other ICE vehicles (e.g. the battery adds negligible cost) is in line with U.S. DOE guidelines at:
B7: https://www.energy.gov/eere/electricvehicles/electric-car-safety-maintenance-and-battery-life
A9: BEV | B9: We assume that battery electric vehicle (BEV) costs apply to all of the following vehicle technologies:
B10: battery electric vehicle, hydrogen vehicle
B11: Today, hydrogen vehicles are typically fuel cell vehicles (not internal combustion vehicles), and we assume they have
B12: similar maintenance costs to pure BEVs. This is in line with the findings of an NREL study of BEV vs. fuel cell lift trucks:
B13: https://www.energy.gov/sites/prod/files/2014/03/f10/fuel_cell_mhe_cost.pdf
B14: We also use this category for electric rail, even though the locomotives are powered by third rail or catenary wire,
B15: rather than batteries.
A17: LDVs
A18: ICE | B18: 931 | C18: 2018 CAD/yr | D18: 2 Degrees Institute
A19: BEV | B19: 489 | C19: 2018 CAD/yr | D19: 2 Degrees Institute
A20: ICE | B20: =B18/About!#REF!*About!$A$90 -> #REF! | C20: 2012 USD/yr
A21: BEV | B21: =B19/About!#REF!*About!$A$90 -> #REF! | C21: 2012 USD/yr
A23: HDVs (Trucks)
A24: ICE | B24: 15000 | C24: 2012 USD/yr | D24: Truck Driver Institute
A26: HDVs (Buses)
A27: CNG | B27: 0.28 | C27: 2016 USD/mile | D27: CA Air Resources Board
A28: BEV | B28: 0.22 | C28: 2016 USD/mile | D28: CA Air Resources Board
A29: dist traveled | B29: 9270 | C29: miles/year | D29: see BAADTbVT
A30: CNG | B30: =$B$29*B27 -> 2595.6 | C30: 2016 USD/yr
A31: BEV | B31: =$B$29*B28 -> 2039.4 | C31: 2016 USD/yr
A32: CNG | B32: =B30*About!$A$92 -> 0 | C32: 2012 USD/yr
A33: BEV | B33: =B31*About!$A$92 -> 0 | C33: 2012 USD/yr
A35: aircraft
A36: maintenance | B36: 590 | C36: 2017 USD / block-hr | D36: ICAO
B37: =B36*About!$A$93 -> 0 | C37: 2012 USD / block-hr
B38: 11.3 | C38: block hrs/day | D38: ICAO
B39: 365 | C39: days/yr
B40: =B37*B38*B39 -> 0 | C40: 2012 USD/yr
A42: rail
A43: maintenance costs
A44: These maintenance costs are for the entire train, not just the locomotive.
A45: conventional diesel locomotive (79 mph) | B45: 14.36 | C45: 2008 USD/mile | D45: Rocky Mountain Rail Authority
A46: electric locomotive (150 mph) | B46: 10.49 | C46: 2008 USD/mile | D46: Rocky Mountain Rail Authority
A48: avg speed (24-hours) | B48: =AVERAGE(21.4,22.7,23.1,25.8,31.2) -> 24.84 | C48: miles/hour | D48: Upper Great Plains Transportation Institute
...

Sheet AVMC-passenger
A1: $/year | B1: battery electric vehicle | C1: natural gas vehicle | D1: gasoline vehicle | E1: diesel vehicle | F1: plugin hybrid vehicle | G1: LPG vehicle | H1: hydrogen vehicle
A2: LDVs | B2: ='China-Cost Data'!C80 -> 757.51071 | C2: ='China-Cost Data'!B80 -> 1299.6823 | D2: ='China-Cost Data'!B80 -> 1299.6823 | E2: ='China-Cost Data'!B80 -> 1299.6823 | F2: ='China-Cost Data'!B80 -> 1299.6823 | G2: ='China-Cost Data'!B80 -> 1299.6823 | H2: ='China-Cost Data'!C80 -> 757.51071
A3: HDVs | B3: ='China-Cost Data'!C81 -> 1883.7142 | C3: ='China-Cost Data'!B81 -> 2415.0182 | D3: ='China-Cost Data'!B81 -> 2415.0182 | E3: ='China-Cost Data'!B81 -> 2415.0182 | F3: ='China-Cost Data'!B81 -> 2415.0182 | G3: ='China-Cost Data'!B81 -> 2415.0182 | H3: ='China-Cost Data'!C81 -> 1883.7142
A4: aircraft | B4: 0 | C4: ='China-Cost Data'!B82 -> 1028861.8 | D4: ='China-Cost Data'!B82 -> 1028861.8 | E4: ='China-Cost Data'!B82 -> 1028861.8 | F4: ='China-Cost Data'!B82 -> 1028861.8 | G4: ='China-Cost Data'!B82 -> 1028861.8 | H4: 0
A5: rail | B5: ='China-Cost Data'!C83 -> 1737670.7 | C5: ='China-Cost Data'!B83 -> 2443768.4 | D5: ='China-Cost Data'!B83 -> 2443768.4 | E5: ='China-Cost Data'!B83 -> 2443768.4 | F5: ='China-Cost Data'!B83 -> 2443768.4 | G5: ='China-Cost Data'!B83 -> 2443768.4 | H5: ='China-Cost Data'!C83 -> 1737670.7
A6: ships | B6: 0 | C6: ='China-Cost Data'!B84 -> 3000 | D6: ='China-Cost Data'!B84 -> 3000 | E6: ='China-Cost Data'!B84 -> 3000 | F6: ='China-Cost Data'!B84 -> 3000 | G6: ='China-Cost Data'!B84 -> 3000 | H6: 0
A7: motorbikes | B7: ='China-Cost Data'!C85 -> 27.766672 | C7: ='China-Cost Data'!B85 -> 70.518531 | D7: ='China-Cost Data'!B85 -> 70.518531 | E7: ='China-Cost Data'!B85 -> 70.518531 | F7: ='China-Cost Data'!B85 -> 70.518531 | G7: ='China-Cost Data'!B85 -> 70.518531 | H7: ='China-Cost Data'!C85 -> 27.766672

Sheet AVMC-freight
A1: $/year | B1: battery electric vehicle | C1: natural gas vehicle | D1: gasoline vehicle | E1: diesel vehicle | F1: plugin hybrid vehicle | G1: LPG vehicle | H1: hydrogen vehicle
A2: LDVs | B2: ='China-Cost Data'!C89 -> 90.563182 | C2: ='China-Cost Data'!B89 -> 271.68955 | D2: ='China-Cost Data'!B89 -> 271.68955 | E2: ='China-Cost Data'!B89 -> 271.68955 | F2: ='China-Cost Data'!B89 -> 271.68955 | G2: ='China-Cost Data'!B89 -> 271.68955 | H2: ='China-Cost Data'!C89 -> 90.563182
A3: HDVs | B3: ='China-Cost Data'!C90 -> 3477.6262 | C3: ='China-Cost Data'!B90 -> 7921.2597 | D3: ='China-Cost Data'!B90 -> 7921.2597 | E3: ='China-Cost Data'!B90 -> 7921.2597 | F3: ='China-Cost Data'!B90 -> 7921.2597 | G3: ='China-Cost Data'!B90 -> 7921.2597 | H3: ='China-Cost Data'!C90 -> 3477.6262
A4: aircraft | B4: 0 | C4: ='China-Cost Data'!B91 -> 1028861.8 | D4: ='China-Cost Data'!B91 -> 1028861.8 | E4: ='China-Cost Data'!B91 -> 1028861.8 | F4: ='China-Cost Data'!B91 -> 1028861.8 | G4: ='China-Cost Data'!B91 -> 1028861.8 | H4: 0
A5: rail | B5: ='China-Cost Data'!C92 -> 1737670.7 | C5: ='China-Cost Data'!B92 -> 2443768.4 | D5: ='China-Cost Data'!B92 -> 2443768.4 | E5: ='China-Cost Data'!B92 -> 2443768.4 | F5: ='China-Cost Data'!B92 -> 2443768.4 | G5: ='China-Cost Data'!B92 -> 2443768.4 | H5: ='China-Cost Data'!C92 -> 1737670.7
A6: ships | B6: 0 | C6: ='Cost Data'!$B98 -> 1695890 | D6: ='Cost Data'!$B98 -> 1695890 | E6: ='Cost Data'!$B98 -> 1695890 | F6: ='Cost Data'!$B98 -> 1695890 | G6: ='Cost Data'!$B98 -> 1695890 | H6: 0
A7: motorbikes | B7: 0 | C7: 0 | D7: 0 | E7: 0 | F7: 0 | G7: 0 | H7: 0
