Workbook

Sheet Freeze
A1: Column1 | B1: 2025女 | C1: 2030女 | D1: 2035女 | E1: 2040女 | F1: 2045女 | G1: 2050女 | H1: 2055女 | I1: 2060女 | J1: 2025男 | K1: 2030男 | L1: 2035男 | M1: 2040男 | N1: 2045男 | O1: 2050男 | P1: 2055男 | Q1: 2060男
A2: 0-4岁 | B2: 28791081 | C2: 25167968 | D2: 23484084 | E2: 23914048 | F2: 24107803 | G2: 22441749 | H2: 19569389 | I2: 17018153 | J2: 30230635 | K2: 26426367 | L2: 24658288 | M2: 25109751 | N2: 25313193 | O2: 23563836 | P2: 20547858 | Q2: 17869060
A3: 5-9岁 | B3: 36807505 | C3: 28707587 | D3: 25094981 | E3: 23415980 | F3: 23844698 | G3: 24037891 | H3: 22376668 | I3: 19512638 | J3: 40825938 | K3: 30124828 | L3: 26333874 | M3: 24571984 | N3: 25021867 | O3: 25224597 | P3: 23481363 | Q3: 20475941
A4: 10-14岁 | B4: 42197039 | C4: 36781740 | D4: 28687491 | E4: 25077415 | F4: 23399589 | G4: 23828006 | H4: 24021064 | I4: 22361004 | J4: 47969441 | K4: 40785112 | L4: 30094703 | M4: 26307540 | N4: 24547412 | O4: 24996845 | P4: 25199373 | Q4: 23457881
A5: 15-19岁 | B5: 39609555 | C5: 42154842 | D5: 36744958 | E5: 28658804 | F5: 25052337 | G5: 23376189 | H5: 23804178 | I5: 23997043 | J5: 45547501 | K5: 47907080 | L5: 40732092 | M5: 30055580 | N5: 26273341 | O5: 24515500 | P5: 24964349 | Q5: 25166613
A6: 20-24岁 | B6: 33590440 | C6: 39562023 | D6: 42104257 | E6: 36700864 | F6: 28624413 | G6: 25022274 | H6: 23348138 | I6: 23775613 | J6: 38963520 | K6: 45442742 | L6: 47796894 | M6: 40638408 | N6: 29986452 | O6: 26212912 | P6: 24459115 | Q6: 24906931
A7: 25-29岁 | B7: 35219835 | C7: 33546772 | D7: 39510593 | E7: 42049521 | F7: 36653153 | G7: 28587202 | H7: 24989745 | I7: 23317785 | J7: 39568870 | K7: 38858319 | L7: 45320047 | M7: 47667842 | N7: 40528684 | O7: 29905488 | P7: 26142137 | Q7: 24393075
A8: 30-34岁 | B8: 43623903 | C8: 35170527 | D8: 33499807 | E8: 39455278 | F8: 41990652 | G8: 36601838 | H8: 28547180 | I8: 24954760 | J8: 48003335 | K8: 39438293 | L8: 38730086 | M8: 45170490 | N8: 47510538 | O8: 40394940 | P8: 29806800 | Q8: 26055868
A9: 35-39岁 | B9: 60158863 | C9: 43541017 | D9: 35103703 | E9: 33436157 | F9: 39380313 | G9: 41910869 | H9: 36532295 | I9: 28492940 | J9: 63590772 | K9: 47792120 | L9: 39264764 | M9: 38559674 | N9: 44971740 | O9: 47301492 | P9: 40217202 | Q9: 29675650
A10: 40-44岁 | B10: 47951077 | C10: 59996434 | D10: 43423457 | E10: 35008923 | F10: 33345880 | G10: 39273986 | H10: 41797710 | I10: 36433658 | J10: 50580606 | K10: 63151996 | L10: 47462354 | M10: 38993837 | N10: 38293612 | O10: 44661435 | P10: 46975112 | Q10: 39939703
A11: 45-49岁 | B11: 45127749 | C11: 47744887 | D11: 59738449 | E11: 43236736 | F11: 34858384 | G11: 33202492 | H11: 39105108 | I11: 41617980 | J11: 47108734 | K11: 50024219 | L11: 62457324 | M11: 46940268 | N11: 38564905 | O11: 37872382 | P11: 44170159 | Q11: 46458386
A12: 50-54岁 | B12: 55640969 | C12: 44811854 | D12: 47410673 | E12: 59320280 | F12: 42934079 | G12: 34614376 | H12: 32970075 | I12: 38831372 | J12: 57214066 | K12: 46317308 | L12: 49183812 | M12: 61408041 | N12: 46151672 | O12: 37917015 | P12: 37236126 | Q12: 43428101
A13: 55-59岁 | B13: 59368150 | C13: 55001097 | D13: 44296518 | E13: 46865450 | F13: 58638097 | G13: 42440337 | H13: 34216310 | I13: 32590919 | J13: 59528949 | K13: 55737943 | L13: 45122321 | M13: 47914870 | N13: 59823713 | O13: 44960959 | P13: 36938756 | Q13: 36275434
... A22: 100岁及以上 | B22: 118719.29 | C22: 159305.01 | D22: 234117.89 | E22: 288094.27 | F22: 351974.98 | G22: 492697.46 | H22: 693308.13 | I22: 652746.73 | J22: 61484.558 | K22: 87290.38 | L22: 124557.43 | M22: 156471.2 | N22: 189390.46 | O22: 262273.32 | P22: 356799.91 | Q22: 339589.2

Sheet Low_2040
A1: Column1 | B1: 2025女 | C1: 2030女 | D1: 2035女 | E1: 2040女 | F1: 2045女 | G1: 2050女 | H1: 2055女 | I1: 2060女 | J1: 2025男 | K1: 2030男 | L1: 2035男 | M1: 2040男 | N1: 2045男 | O1: 2050男 | P1: 2055男 | Q1: 2060男
A2: 0-4岁 | B2: 28791081 | C2: 19269554 | D2: 15943194 | E2: 14650386 | F2: 15834230 | G2: 16017107 | H2: 14392126 | I2: 11501712 | J2: 30230635 | K2: 20233032 | L2: 16740354 | M2: 15382906 | N2: 16625941 | O2: 16817962 | P2: 15111732 | Q2: 12076798
A3: 5-9岁 | B3: 36807505 | C3: 28710466 | D3: 19217526 | E3: 15901742 | F3: 14613760 | G3: 15796228 | H3: 15980268 | I3: 14360463 | J3: 40825938 | K3: 30130874 | L3: 20168286 | M3: 16690133 | N3: 15338295 | O3: 16579389 | P3: 16774236 | Q3: 15073953
A4: 10-14岁 | B4: 42197039 | C4: 36785420 | D4: 28696111 | E4: 19207918 | F4: 15895381 | G4: 14609376 | H4: 15791489 | I4: 15975473 | J4: 47969441 | K4: 40793278 | L4: 30109782 | M4: 20156185 | N4: 16681788 | O4: 15332160 | P4: 16572757 | Q4: 16769203
A5: 15-19岁 | B5: 39609555 | C5: 42163282 | D5: 36763349 | E5: 28681763 | F5: 19200235 | G5: 15890613 | H5: 14604993 | I5: 15788330 | J5: 45547501 | K5: 47921471 | L5: 40760643 | M5: 30091716 | N5: 20146107 | O5: 16675115 | P5: 15327560 | Q5: 16569442
A6: 20-24岁 | B6: 33590440 | C6: 39569945 | D6: 42125335 | E6: 36733938 | F6: 28661685 | G6: 19188714 | H6: 15882667 | I6: 14597691 | J6: 38963520 | K6: 45456406 | L6: 47835212 | M6: 40695426 | N6: 30049588 | O6: 20121932 | P6: 16656773 | Q6: 15312233
A7: 25-29岁 | B7: 35219835 | C7: 33550132 | D7: 39526418 | E7: 42078997 | F7: 36697204 | G7: 28635890 | H7: 19171445 | I7: 15869961 | J7: 39568870 | K7: 38862215 | L7: 45338220 | M7: 47715624 | N7: 40593687 | O7: 29974464 | P7: 20073639 | Q7: 16616796
A8: 30-34岁 | B8: 43623903 | C8: 35170527 | D8: 33506516 | E8: 39475034 | F8: 42024294 | G8: 36649498 | H8: 28598663 | I8: 19148439 | J8: 48003335 | K8: 39442249 | L8: 38745629 | M8: 45206739 | N8: 47582021 | O8: 40484084 | P8: 29896530 | Q8: 20023455
A9: 35-39岁 | B9: 60158863 | C9: 43545380 | D9: 35107220 | E9: 33449555 | F9: 39407926 | G9: 41952853 | H9: 36590859 | I9: 28552905 | J9: 63590772 | K9: 47806521 | L9: 39292369 | M9: 38610019 | N9: 45062077 | O9: 47439275 | P9: 40374777 | Q9: 29821789
A10: 40-44岁 | B10: 47951077 | C10: 60002450 | D10: 43436516 | E10: 35019452 | F10: 33369276 | G10: 39317288 | H10: 41856361 | I10: 36510359 | J10: 50580606 | K10: 63202868 | L10: 47553146 | M10: 39107695 | N10: 38451718 | O10: 44899854 | P10: 47287469 | Q10: 40261728
A11: 45-49岁 | B11: 45127749 | C11: 47754477 | D11: 59762440 | E11: 43271458 | F11: 34889880 | G11: 33249147 | H11: 39183609 | I11: 41718235 | J11: 47108734 | K11: 50095032 | L11: 62678285 | M11: 47210764 | N11: 38861316 | O11: 38240233 | P11: 44684334 | Q11: 47093590
A12: 50-54岁 | B12: 55640969 | C12: 44829906 | D12: 47453624 | E12: 59403865 | F12: 43024810 | G12: 34701475 | H12: 33079576 | I12: 38991610 | J12: 57214066 | K12: 46416236 | L12: 49448806 | M12: 61970020 | N12: 46743377 | O12: 38523223 | P12: 37949608 | Q12: 44384949
A13: 55-59岁 | B13: 59368150 | C13: 55045610 | D13: 44381606 | E13: 47012305 | F13: 58887051 | G13: 42676309 | H13: 34437743 | I13: 32844711 | J13: 59528949 | K13: 55903864 | L13: 45473986 | M13: 48558728 | N13: 60978500 | O13: 46079621 | P13: 38037830 | Q13: 37524572
... A22: 100岁及以上 | B22: 118719.29 | C22: 166810.37 | D22: 295593.64 | E22: 472219.38 | F22: 766623.34 | G22: 1410714.2 | H22: 2544464.5 | I22: 2983599.9 | J22: 61484.558 | K22: 80391.935 | L22: 110496.82 | M22: 140271.47 | N22: 176305.85 | O22: 253005.42 | P22: 347706.66 | Q22: 319509.93

Sheet Medium_2040
A1: Column1 | B1: 2025女 | C1: 2030女 | D1: 2035女 | E1: 2040女 | F1: 2045女 | G1: 2050女 | H1: 2055女 | I1: 2060女 | J1: 2025男 | K1: 2030男 | L1: 2035男 | M1: 2040男 | N1: 2045男 | O1: 2050男 | P1: 2055男 | Q1: 2060男
A2: 0-4岁 | B2: 28791081 | C2: 24265336 | D2: 23279491 | E2: 23727651 | F2: 25218361 | G2: 25274786 | H2: 22843471 | I2: 19533570 | J2: 30230635 | K2: 25478603 | L2: 24443465 | M2: 24914033 | N2: 26479279 | O2: 26538525 | P2: 23985645 | Q2: 20510249
A3: 5-9岁 | B3: 36807505 | C3: 28710466 | D3: 24199820 | E3: 23218964 | F3: 23668332 | G3: 25157837 | H3: 25216654 | I3: 22793216 | J3: 40825938 | K3: 30130874 | L3: 25397071 | M3: 24370135 | N3: 24841783 | O3: 26405137 | P3: 26469525 | Q3: 23925681
A4: 10-14岁 | B4: 42197039 | C4: 36785420 | D4: 28696111 | E4: 24187720 | F4: 23209677 | G4: 23661231 | H4: 25150290 | I4: 25209089 | J4: 47969441 | K4: 40793278 | L4: 30109782 | M4: 25381833 | N4: 24357950 | O4: 24831846 | P4: 26394575 | Q4: 26461584
A5: 15-19岁 | B5: 39609555 | C5: 42163282 | D5: 36763349 | E5: 28681763 | F5: 24178045 | G5: 23202714 | H5: 23654133 | I5: 25145259 | J5: 45547501 | K5: 47921471 | L5: 40760643 | M5: 30091716 | N5: 25369142 | O5: 24348207 | P5: 24824396 | Q5: 26389296
A6: 20-24岁 | B6: 33590440 | C6: 39569945 | D6: 42125335 | E6: 36733938 | F6: 28661685 | G6: 24163538 | H6: 23191112 | I6: 23642306 | J6: 38963520 | K6: 45456406 | L6: 47835212 | M6: 40695426 | N6: 30049588 | O6: 25338699 | P6: 24321424 | Q6: 24799572
A7: 25-29岁 | B7: 35219835 | C7: 33550132 | D7: 39526418 | E7: 42078997 | F7: 36697204 | G7: 28635890 | H7: 24141791 | I7: 23172559 | J7: 39568870 | K7: 38862215 | L7: 45338220 | M7: 47715624 | N7: 40593687 | O7: 29974464 | P7: 25277886 | Q7: 24263052
A8: 30-34岁 | B8: 43623903 | C8: 35170527 | D8: 33506516 | E8: 39475034 | F8: 42024294 | G8: 36649498 | H8: 28598663 | I8: 24112820 | J8: 48003335 | K8: 39442249 | L8: 38745629 | M8: 45206739 | N8: 47582021 | O8: 40484084 | P8: 29896530 | Q8: 25214692
A9: 35-39岁 | B9: 60158863 | C9: 43545380 | D9: 35107220 | E9: 33449555 | F9: 39407926 | G9: 41952853 | H9: 36590859 | I9: 28552905 | J9: 63590772 | K9: 47806521 | L9: 39292369 | M9: 38610019 | N9: 45062077 | O9: 47439275 | P9: 40374777 | Q9: 29821789
A10: 40-44岁 | B10: 47951077 | C10: 60002450 | D10: 43436516 | E10: 35019452 | F10: 33369276 | G10: 39317288 | H10: 41856361 | I10: 36510359 | J10: 50580606 | K10: 63202868 | L10: 47553146 | M10: 39107695 | N10: 38451718 | O10: 44899854 | P10: 47287469 | Q10: 40261728
A11: 45-49岁 | B11: 45127749 | C11: 47754477 | D11: 59762440 | E11: 43271458 | F11: 34889880 | G11: 33249147 | H11: 39183609 | I11: 41718235 | J11: 47108734 | K11: 50095032 | L11: 62678285 | M11: 47210764 | N11: 38861316 | O11: 38240233 | P11: 44684334 | Q11: 47093590
A12: 50-54岁 | B12: 55640969 | C12: 44829906 | D12: 47453624 | E12: 59403865 | F12: 43024810 | G12: 34701475 | H12: 33079576 | I12: 38991610 | J12: 57214066 | K12: 46416236 | L12: 49448806 | M12: 61970020 | N12: 46743377 | O12: 38523223 | P12: 37949608 | Q12: 44384949
A13: 55-59岁 | B13: 59368150 | C13: 55045610 | D13: 44381606 | E13: 47012305 | F13: 58887051 | G13: 42676309 | H13: 34437743 | I13: 32844711 | J13: 59528949 | K13: 55903864 | L13: 45473986 | M13: 48558728 | N13: 60978500 | O13: 46079621 | P13: 38037830 | Q13: 37524572
... A22: 100岁及以上 | B22: 118719.29 | C22: 166810.37 | D22: 295593.64 | E22: 472219.38 | F22: 766623.34 | G22: 1410714.2 | H22: 2544464.5 | I22: 2983599.9 | J22: 61484.558 | K22: 80391.935 | L22: 110496.82 | M22: 140271.47 | N22: 176305.85 | O22: 253005.42 | P22: 347706.66 | Q22: 319509.93

Sheet High_2040
A1: Column1 | B1: 2025女 | C1: 2030女 | D1: 2035女 | E1: 2040女 | F1: 2045女 | G1: 2050女 | H1: 2055女 | I1: 2060女 | J1: 2025男 | K1: 2030男 | L1: 2035男 | M1: 2040男 | N1: 2045男 | O1: 2050男 | P1: 2055男 | Q1: 2060男
A2: 0-4岁 | B2: 28791081 | C2: 29273063 | D2: 30704296 | E2: 32824225 | F2: 34246877 | G2: 34440826 | H2: 32233355 | I2: 29429198 | J2: 30230635 | K2: 30736716 | L2: 32239511 | M2: 34465436 | N2: 35959221 | O2: 36162867 | P2: 33845023 | Q2: 30900658
A3: 5-9岁 | B3: 36807505 | C3: 28710466 | D3: 29194026 | E3: 30624465 | F3: 32742164 | G3: 34164685 | H3: 34361612 | I3: 32162442 | J3: 40825938 | K3: 30130874 | L3: 30638359 | M3: 32142792 | N3: 34365487 | O3: 35858535 | P3: 36068844 | Q3: 33760411
A4: 10-14岁 | B4: 42197039 | C4: 36785420 | D4: 28696111 | E4: 29179429 | F4: 30612215 | G4: 32732342 | H4: 34154436 | I4: 34351304 | J4: 47969441 | K4: 40793278 | L4: 30109782 | M4: 30619976 | N4: 32126721 | O4: 34351740 | P4: 35844192 | Q4: 36058023
A5: 15-19岁 | B5: 39609555 | C5: 42163282 | D5: 36763349 | E5: 28681763 | F5: 29167757 | G5: 30603031 | H5: 32722522 | I5: 34147605 | J5: 45547501 | K5: 47921471 | L5: 40760643 | M5: 30091716 | N5: 30604666 | O5: 32113870 | P5: 34341435 | Q5: 35837023
A6: 20-24岁 | B6: 33590440 | C6: 39569945 | D6: 42125335 | E6: 36733938 | F6: 28661685 | G6: 29150256 | H6: 30587730 | I6: 32706161 | J6: 38963520 | K6: 45456406 | L6: 47835212 | M6: 40695426 | N6: 30049588 | O6: 30567940 | P6: 32078545 | Q6: 34307093
A7: 25-29岁 | B7: 35219835 | C7: 33550132 | D7: 39526418 | E7: 42078997 | F7: 36697204 | G7: 28635890 | H7: 29124021 | I7: 30563259 | J7: 39568870 | K7: 38862215 | L7: 45338220 | M7: 47715624 | N7: 40593687 | O7: 29974464 | P7: 30494577 | Q7: 32001556
A8: 30-34岁 | B8: 43623903 | C8: 35170527 | D8: 33506516 | E8: 39475034 | F8: 42024294 | G8: 36649498 | H8: 28598663 | I8: 29089072 | J8: 48003335 | K8: 39442249 | L8: 38745629 | M8: 45206739 | N8: 47582021 | O8: 40484084 | P8: 29896530 | Q8: 30418341
A9: 35-39岁 | B9: 60158863 | C9: 43545380 | D9: 35107220 | E9: 33449555 | F9: 39407926 | G9: 41952853 | H9: 36590859 | I9: 28552905 | J9: 63590772 | K9: 47806521 | L9: 39292369 | M9: 38610019 | N9: 45062077 | O9: 47439275 | P9: 40374777 | Q9: 29821789
A10: 40-44岁 | B10: 47951077 | C10: 60002450 | D10: 43436516 | E10: 35019452 | F10: 33369276 | G10: 39317288 | H10: 41856361 | I10: 36510359 | J10: 50580606 | K10: 63202868 | L10: 47553146 | M10: 39107695 | N10: 38451718 | O10: 44899854 | P10: 47287469 | Q10: 40261728
A11: 45-49岁 | B11: 45127749 | C11: 47754477 | D11: 59762440 | E11: 43271458 | F11: 34889880 | G11: 33249147 | H11: 39183609 | I11: 41718235 | J11: 47108734 | K11: 50095032 | L11: 62678285 | M11: 47210764 | N11: 38861316 | O11: 38240233 | P11: 44684334 | Q11: 47093590
A12: 50-54岁 | B12: 55640969 | C12: 44829906 | D12: 47453624 | E12: 59403865 | F12: 43024810 | G12: 34701475 | H12: 33079576 | I12: 38991610 | J12: 57214066 | K12: 46416236 | L12: 49448806 | M12: 61970020 | N12: 46743377 | O12: 38523223 | P12: 37949608 | Q12: 44384949
A13: 55-59岁 | B13: 59368150 | C13: 55045610 | D13: 44381606 | E13: 47012305 | F13: 58887051 | G13: 42676309 | H13: 34437743 | I13: 32844711 | J13: 59528949 | K13: 55903864 | L13: 45473986 | M13: 48558728 | N13: 60978500 | O13: 46079621 | P13: 38037830 | Q13: 37524572
... A22: 100岁及以上 | B22: 118719.29 | C22: 166810.37 | D22: 295593.64 | E22: 472219.38 | F22: 766623.34 | G22: 1410714.2 | H22: 2544464.5 | I22: 2983599.9 | J22: 61484.558 | K22: 80391.935 | L22: 110496.82 | M22: 140271.47 | N22: 176305.85 | O22: 253005.42 | P22: 347706.66 | Q22: 319509.93

Sheet Low_2060
A1: Column1 | B1: 2025女 | C1: 2030女 | D1: 2035女 | E1: 2040女 | F1: 2045女 | G1: 2050女 | H1: 2055女 | I1: 2060女 | J1: 2025男 | K1: 2030男 | L1: 2035男 | M1: 2040男 | N1: 2045男 | O1: 2050男 | P1: 2055男 | Q1: 2060男
A2: 0-4岁 | B2: 28791081 | C2: 19269554 | D2: 15942029 | E2: 14647877 | F2: 15829214 | G2: 16010239 | H2: 14383692 | I2: 11493066 | J2: 30230635 | K2: 20233032 | L2: 16739130 | M2: 15380271 | N2: 16620675 | O2: 16810751 | P2: 15102876 | Q2: 12067720
A3: 5-9岁 | B3: 36807505 | C3: 28710466 | D3: 19215600 | E3: 15898985 | F3: 14608328 | G3: 15788058 | H3: 15968612 | I3: 14347733 | J3: 40825938 | K3: 30127851 | L3: 20166263 | M3: 16683891 | N3: 15331054 | O3: 16569151 | P3: 16760319 | Q3: 15057568
A4: 10-14岁 | B4: 42197039 | C4: 36781740 | D4: 28693240 | E4: 19204070 | F4: 15891036 | G4: 14601023 | H4: 15780164 | I4: 15962225 | J4: 47969441 | K4: 40789195 | L4: 30103748 | M4: 20150130 | N4: 16672212 | O4: 15321855 | P4: 16559209 | Q4: 16751939
A5: 15-19岁 | B5: 39609555 | C5: 42159062 | D5: 36752314 | E5: 28673154 | F5: 19192548 | G5: 15881501 | H5: 14593723 | I5: 15773852 | J5: 45547501 | K5: 47911877 | L5: 40748406 | M5: 30076655 | N5: 20134010 | O5: 16660542 | P5: 15312662 | Q5: 16549274
A6: 20-24岁 | B6: 33590440 | C6: 39565984 | D6: 42116903 | E6: 36715562 | F6: 28647348 | G6: 19175274 | H6: 15868796 | I6: 14583507 | J6: 38963520 | K6: 45447297 | L6: 47816053 | M6: 40670984 | N6: 30022517 | O6: 20099782 | P6: 16633885 | Q6: 15289693
A7: 25-29岁 | B7: 35219835 | C7: 33546772 | D7: 39518505 | E7: 42066363 | F7: 36675175 | G7: 28615836 | H7: 19154182 | I7: 15852927 | J7: 39568870 | K7: 38858319 | L7: 45329134 | M7: 47691732 | N7: 40565239 | O7: 29944459 | P7: 20049533 | Q7: 16592300
A8: 30-34岁 | B8: 43623903 | C8: 35170527 | D8: 33499807 | E8: 39463179 | F8: 42011676 | G8: 36627497 | H8: 28578636 | I8: 19129281 | J8: 48003335 | K8: 39442249 | L8: 38733972 | M8: 45188613 | N8: 47548657 | O8: 40443544 | P8: 29857620 | Q8: 19991389
A9: 35-39岁 | B9: 60158863 | C9: 43541017 | D9: 35107220 | E9: 33439507 | F9: 39392145 | G9: 41936055 | H9: 36565230 | I9: 28530052 | J9: 63590772 | K9: 47801721 | L9: 39280536 | M9: 38582910 | N9: 45016897 | O9: 47377481 | P9: 40301991 | Q9: 29759090
A10: 40-44岁 | B10: 47951077 | C10: 59996434 | D10: 43427811 | E10: 35015941 | F10: 33355909 | G10: 39293665 | H10: 41831215 | I10: 36477474 | J10: 50580606 | K10: 63177432 | L10: 47510130 | M10: 39056637 | N10: 38378420 | O10: 44791812 | P10: 47154807 | Q10: 40124662
A11: 45-49岁 | B11: 45127749 | C11: 47749682 | D11: 59750448 | E11: 43249757 | F11: 34875877 | G11: 33225821 | H11: 39144349 | I11: 41672257 | J11: 47108734 | K11: 50059626 | L11: 62570929 | M11: 47087290 | N11: 38732467 | O11: 38079069 | P11: 44469311 | Q11: 46834155
A12: 50-54岁 | B12: 55640969 | C12: 44820880 | D12: 47434534 | E12: 59362070 | F12: 42977283 | G12: 34659647 | H12: 33026466 | I12: 38917312 | J12: 57214066 | K12: 46369127 | L12: 49323749 | M12: 61707450 | N12: 46479864 | O12: 38263804 | P12: 37648775 | Q12: 43997936
A13: 55-59岁 | B13: 59368150 | C13: 55023354 | D13: 44341297 | E13: 46941215 | F13: 58768450 | G13: 42560404 | H13: 34337312 | I13: 32729227 | J13: 59528949 | K13: 55823764 | L13: 45307274 | M13: 48258356 | N13: 60454789 | O13: 45592098 | P13: 37575056 | Q13: 37008746
... A22: 100岁及以上 | B22: 118719.29 | C22: 163057.69 | D22: 264409.55 | E22: 376013.92 | F22: 542034.02 | G22: 898588.02 | H22: 1488133.6 | I22: 1632439.8 | J22: 61484.558 | K22: 83860.426 | L22: 117970.42 | M22: 150341.02 | N22: 188798.82 | O22: 273861.98 | P22: 390405.49 | Q22: 387967.68

Sheet Medium_2060
A1: Column1 | B1: 2025女 | C1: 2030女 | D1: 2035女 | E1: 2040女 | F1: 2045女 | G1: 2050女 | H1: 2055女 | I1: 2060女 | J1: 2025男 | K1: 2030男 | L1: 2035男 | M1: 2040男 | N1: 2045男 | O1: 2050男 | P1: 2055男 | Q1: 2060男
A2: 0-4岁 | B2: 28791081 | C2: 24265336 | D2: 23277788 | E2: 23723586 | F2: 25210372 | G2: 25263955 | H2: 22830054 | I2: 19518676 | J2: 30230635 | K2: 25478603 | L2: 24441678 | M2: 24909766 | N2: 26470891 | O2: 26527153 | P2: 23971557 | Q2: 20494609
A3: 5-9岁 | B3: 36807505 | C3: 28710466 | D3: 24197393 | E3: 23214938 | F3: 23659533 | G3: 25144825 | H3: 25198269 | I3: 22772979 | J3: 40825938 | K3: 30127851 | L3: 25394523 | M3: 24361020 | N3: 24830054 | O3: 26388831 | P3: 26447571 | Q3: 23899642
A4: 10-14岁 | B4: 42197039 | C4: 36781740 | D4: 28693240 | E4: 24182875 | F4: 23203331 | G4: 23647703 | H4: 25132253 | I4: 25188189 | J4: 47969441 | K4: 40789195 | L4: 30103748 | M4: 25374208 | N4: 24343968 | O4: 24815156 | P4: 26372998 | Q4: 26434348
A5: 15-19岁 | B5: 39609555 | C5: 42159062 | D5: 36752314 | E5: 28673154 | F5: 24168365 | G5: 23189409 | H5: 23635879 | I5: 25122200 | J5: 45547501 | K5: 47911877 | L5: 40748406 | M5: 30076655 | N5: 25353908 | O5: 24326927 | P5: 24800267 | Q5: 26357174
A6: 20-24岁 | B6: 33590440 | C6: 39565984 | D6: 42116903 | E6: 36715562 | F6: 28647348 | G6: 24146613 | H6: 23170857 | I6: 23619334 | J6: 38963520 | K6: 45447297 | L6: 47816053 | M6: 40670984 | N6: 30022517 | O6: 25310807 | P6: 24288004 | Q6: 24763067
A7: 25-29岁 | B7: 35219835 | C7: 33546772 | D7: 39518505 | E7: 42066363 | F7: 36675175 | G7: 28615836 | H7: 24120052 | I7: 23147687 | J7: 39568870 | K7: 38858319 | L7: 45329134 | M7: 47691732 | N7: 40565239 | O7: 29944459 | P7: 25247530 | Q7: 24227284
A8: 30-34岁 | B8: 43623903 | C8: 35170527 | D8: 33499807 | E8: 39463179 | F8: 42011676 | G8: 36627497 | H8: 28578636 | I8: 24088696 | J8: 48003335 | K8: 39442249 | L8: 38733972 | M8: 45188613 | N8: 47548657 | O8: 40443544 | P8: 29857620 | Q8: 25174312
A9: 35-39岁 | B9: 60158863 | C9: 43541017 | D9: 35107220 | E9: 33439507 | F9: 39392145 | G9: 41936055 | H9: 36565230 | I9: 28530052 | J9: 63590772 | K9: 47801721 | L9: 39280536 | M9: 38582910 | N9: 45016897 | O9: 47377481 | P9: 40301991 | Q9: 29759090
A10: 40-44岁 | B10: 47951077 | C10: 59996434 | D10: 43427811 | E10: 35015941 | F10: 33355909 | G10: 39293665 | H10: 41831215 | I10: 36477474 | J10: 50580606 | K10: 63177432 | L10: 47510130 | M10: 39056637 | N10: 38378420 | O10: 44791812 | P10: 47154807 | Q10: 40124662
A11: 45-49岁 | B11: 45127749 | C11: 47749682 | D11: 59750448 | E11: 43249757 | F11: 34875877 | G11: 33225821 | H11: 39144349 | I11: 41672257 | J11: 47108734 | K11: 50059626 | L11: 62570929 | M11: 47087290 | N11: 38732467 | O11: 38079069 | P11: 44469311 | Q11: 46834155
A12: 50-54岁 | B12: 55640969 | C12: 44820880 | D12: 47434534 | E12: 59362070 | F12: 42977283 | G12: 34659647 | H12: 33026466 | I12: 38917312 | J12: 57214066 | K12: 46369127 | L12: 49323749 | M12: 61707450 | N12: 46479864 | O12: 38263804 | P12: 37648775 | Q12: 43997936
A13: 55-59岁 | B13: 59368150 | C13: 55023354 | D13: 44341297 | E13: 46941215 | F13: 58768450 | G13: 42560404 | H13: 34337312 | I13: 32729227 | J13: 59528949 | K13: 55823764 | L13: 45307274 | M13: 48258356 | N13: 60454789 | O13: 45592098 | P13: 37575056 | Q13: 37008746
... A22: 100岁及以上 | B22: 118719.29 | C22: 163057.69 | D22: 264409.55 | E22: 376013.92 | F22: 542034.02 | G22: 898588.02 | H22: 1488133.6 | I22: 1632439.8 | J22: 61484.558 | K22: 83860.426 | L22: 117970.42 | M22: 150341.02 | N22: 188798.82 | O22: 273861.98 | P22: 390405.49 | Q22: 387967.68

Sheet High_2060
A1: Column1 | B1: 2025女 | C1: 2030女 | D1: 2035女 | E1: 2040女 | F1: 2045女 | G1: 2050女 | H1: 2055女 | I1: 2060女 | J1: 2025男 | K1: 2030男 | L1: 2035男 | M1: 2040男 | N1: 2045男 | O1: 2050男 | P1: 2055男 | Q1: 2060男
A2: 0-4岁 | B2: 28791081 | C2: 29273063 | D2: 30702029 | E2: 32818598 | F2: 34236160 | G2: 34426126 | H2: 32214909 | I2: 29406951 | J2: 30230635 | K2: 30736716 | L2: 32237131 | M2: 34459528 | N2: 35947968 | O2: 36147432 | P2: 33825655 | Q2: 30877299
A3: 5-9岁 | B3: 36807505 | C3: 28710466 | D3: 29191099 | E3: 30619134 | F3: 32729988 | G3: 34147146 | H3: 34336618 | I3: 32134372 | J3: 40825938 | K3: 30127851 | L3: 30635285 | M3: 32130748 | N3: 34349257 | O3: 35836529 | P3: 36038990 | Q3: 33724178
A4: 10-14岁 | B4: 42197039 | C4: 36781740 | D4: 28693240 | E4: 29173584 | F4: 30603824 | G4: 32713623 | H4: 34130072 | I4: 34322884 | J4: 47969441 | K4: 40789195 | L4: 30103748 | M4: 30610777 | N4: 32108257 | O4: 34328648 | P4: 35815027 | Q4: 36020971
A5: 15-19岁 | B5: 39609555 | C5: 42159062 | D5: 36752314 | E5: 28673154 | F5: 29156080 | G5: 30585462 | H5: 32697266 | I5: 34116420 | J5: 45547501 | K5: 47911877 | L5: 40748406 | M5: 30076655 | N5: 30586288 | O5: 32085781 | P5: 34308051 | Q5: 35793538
A6: 20-24岁 | B6: 33590440 | C6: 39565984 | D6: 42116903 | E6: 36715562 | F6: 28647348 | G6: 29129839 | H6: 30560993 | I6: 32674378 | J6: 38963520 | K6: 45447297 | L6: 47816053 | M6: 40670984 | N6: 30022517 | O6: 30534292 | P6: 32034444 | Q6: 34256588
A7: 25-29岁 | B7: 35219835 | C7: 33546772 | D7: 39518505 | E7: 42066363 | F7: 36675175 | G7: 28615836 | H7: 29097796 | I7: 30530432 | J7: 39568870 | K7: 38858319 | L7: 45329134 | M7: 47691732 | N7: 40565239 | O7: 29944459 | P7: 30457956 | Q7: 31954357
A8: 30-34岁 | B8: 43623903 | C8: 35170527 | D8: 33499807 | E8: 39463179 | F8: 42011676 | G8: 36627497 | H8: 28578636 | I8: 29059969 | J8: 48003335 | K8: 39442249 | L8: 38733972 | M8: 45188613 | N8: 47548657 | O8: 40443544 | P8: 29857620 | Q8: 30369628
A9: 35-39岁 | B9: 60158863 | C9: 43541017 | D9: 35107220 | E9: 33439507 | F9: 39392145 | G9: 41936055 | H9: 36565230 | I9: 28530052 | J9: 63590772 | K9: 47801721 | L9: 39280536 | M9: 38582910 | N9: 45016897 | O9: 47377481 | P9: 40301991 | Q9: 29759090
A10: 40-44岁 | B10: 47951077 | C10: 59996434 | D10: 43427811 | E10: 35015941 | F10: 33355909 | G10: 39293665 | H10: 41831215 | I10: 36477474 | J10: 50580606 | K10: 63177432 | L10: 47510130 | M10: 39056637 | N10: 38378420 | O10: 44791812 | P10: 47154807 | Q10: 40124662
A11: 45-49岁 | B11: 45127749 | C11: 47749682 | D11: 59750448 | E11: 43249757 | F11: 34875877 | G11: 33225821 | H11: 39144349 | I11: 41672257 | J11: 47108734 | K11: 50059626 | L11: 62570929 | M11: 47087290 | N11: 38732467 | O11: 38079069 | P11: 44469311 | Q11: 46834155
A12: 50-54岁 | B12: 55640969 | C12: 44820880 | D12: 47434534 | E12: 59362070 | F12: 42977283 | G12: 34659647 | H12: 33026466 | I12: 38917312 | J12: 57214066 | K12: 46369127 | L12: 49323749 | M12: 61707450 | N12: 46479864 | O12: 38263804 | P12: 37648775 | Q12: 43997936
A13: 55-59岁 | B13: 59368150 | C13: 55023354 | D13: 44341297 | E13: 46941215 | F13: 58768450 | G13: 42560404 | H13: 34337312 | I13: 32729227 | J13: 59528949 | K13: 55823764 | L13: 45307274 | M13: 48258356 | N13: 60454789 | O13: 45592098 | P13: 37575056 | Q13: 37008746
... A22: 100岁及以上 | B22: 118719.29 | C22: 163057.69 | D22: 264409.55 | E22: 376013.92 | F22: 542034.02 | G22: 898588.02 | H22: 1488133.6 | I22: 1632439.8 | J22: 61484.558 | K22: 83860.426 | L22: 117970.42 | M22: 150341.02 | N22: 188798.82 | O22: 273861.98 | P22: 390405.49 | Q22: 387967.68

Sheet Freeze_0
A1: Column1 | B1: Column2 | C1: 2025女 | D1: 2030女 | E1: 2035女 | F1: 2040女 | G1: 2045女 | H1: 2050女 | I1: 2055女 | J1: 2060女 | K1: 2020男 | L1: 2025男 | M1: 2030男 | N1: 2035男 | O1: 2040男 | P1: 2045男 | Q1: 2050男 | R1: 2055男 | S1: 2060男 | V1: 2020 | W1: 2025 | X1: 2030 | Y1: 2035 | Z1: 2040 | AA1: 2045 | AB1: 2050 | AC1: 2055 | AD1: 2060
A2: 0-4岁 | B2: 36914557 | C2: =Freeze[[#This Row],[2025女]] -> 28791081 | D2: =Freeze[[#This Row],[2030女]] -> 25167968 | E2: =Freeze[[#This Row],[2035女]] -> 23484084 | F2: =Freeze[[#This Row],[2040女]] -> 23914048 | G2: =Freeze[[#This Row],[2045女]] -> 24107803 | H2: =Freeze[[#This Row],[2050女]] -> 22441749 | I2: =Freeze[[#This Row],[2055女]] -> 19569389 | J2: =Freeze[[#This Row],[2060女]] -> 17018153 | K2: 40969331 | L2: =Freeze[[#This Row],[2025男]] -> 30230635 | M2: =Freeze[[#This Row],[2030男]] -> 26426367 | N2: =Freeze[[#This Row],[2035男]] -> 24658288 | O2: =Freeze[[#This Row],[2040男]] -> 25109751 | P2: =Freeze[[#This Row],[2045男]] -> 25313193 | Q2: =Freeze[[#This Row],[2050男]] -> 23563836 | R2: =Freeze[[#This Row],[2055男]] -> 20547858 | S2: =Freeze[[#This Row],[2060男]] -> 17869060 | U2: 0 | V2: =(SUM(B$2:B2)+SUM(K$2:K2))/(SUM(B$2:B$22)+SUM(K$2:K$22)) -> 0.05524547 | W2: =(SUM(C$2:C2)+SUM(L$2:L2))/(SUM(C$2:C$22)+SUM(L$2:L$22)) -> 0.041484678 | X2: =(SUM(D$2:D2)+SUM(M$2:M2))/(SUM(D$2:D$22)+SUM(M$2:M$22)) -> 0.036378604 | Y2: =(SUM(E$2:E2)+SUM(N$2:N2))/(SUM(E$2:E$22)+SUM(N$2:N$22)) -> 0.034403225 | Z2: =(SUM(F$2:F2)+SUM(O$2:O2))/(SUM(F$2:F$22)+SUM(O$2:O$22)) -> 0.03578725 | AA2: =(SUM(G$2:G2)+SUM(P$2:P2))/(SUM(G$2:G$22)+SUM(P$2:P$22)) -> 0.037155252 | AB2: =(SUM(H$2:H2)+SUM(Q$2:Q2))/(SUM(H$2:H$22)+SUM(Q$2:Q$22)) -> 0.03599417 | AC2: =(SUM(I$2:I2)+SUM(R$2:R2))/(SUM(I$2:I$22)+SUM(R$2:R$22)) -> 0.033043063 | AD2: =(SUM(J$2:J2)+SUM(S$2:S2))/(SUM(J$2:J$22)+SUM(S$2:S$22)) -> 0.030541192 | AF2: {=sum} -> #NAME?
A3: 5-9岁 | B3: 42226598 | C3: =Freeze[[#This Row],[2025女]] -> 36807505 | D3: =Freeze[[#This Row],[2030女]] -> 28707587 | E3: =Freeze[[#This Row],[2035女]] -> 25094981 | F3: =Freeze[[#This Row],[2040女]] -> 23415980 | G3: =Freeze[[#This Row],[2045女]] -> 23844698 | H3: =Freeze[[#This Row],[2050女]] -> 24037891 | I3: =Freeze[[#This Row],[2055女]] -> 22376668 | J3: =Freeze[[#This Row],[2060女]] -> 19512638 | K3: 48017458 | L3: =Freeze[[#This Row],[2025男]] -> 40825938 | M3: =Freeze[[#This Row],[2030男]] -> 30124828 | N3: =Freeze[[#This Row],[2035男]] -> 26333874 | O3: =Freeze[[#This Row],[2040男]] -> 24571984 | P3: =Freeze[[#This Row],[2045男]] -> 25021867 | Q3: =Freeze[[#This Row],[2050男]] -> 25224597 | R3: =Freeze[[#This Row],[2055男]] -> 23481363 | S3: =Freeze[[#This Row],[2060男]] -> 20475941 | U3: 5 | V3: =(SUM(B$2:B3)+SUM(K$2:K3))/(SUM(B$2:B$22)+SUM(K$2:K$22)) -> 0.11925839 | W3: =(SUM(C$2:C3)+SUM(L$2:L3))/(SUM(C$2:C$22)+SUM(L$2:L$22)) -> 0.096051007 | X3: =(SUM(D$2:D3)+SUM(M$2:M3))/(SUM(D$2:D$22)+SUM(M$2:M$22)) -> 0.077860698 | Y3: =(SUM(E$2:E3)+SUM(N$2:N3))/(SUM(E$2:E$22)+SUM(N$2:N$22)) -> 0.071155018 | Z3: =(SUM(F$2:F3)+SUM(O$2:O3))/(SUM(F$2:F$22)+SUM(O$2:O$22)) -> 0.070818342 | AA3: =(SUM(G$2:G3)+SUM(P$2:P3))/(SUM(G$2:G$22)+SUM(P$2:P$22)) -> 0.073893676 | AB3: =(SUM(H$2:H3)+SUM(Q$2:Q3))/(SUM(H$2:H$22)+SUM(Q$2:Q$22)) -> 0.074536498 | AC3: =(SUM(I$2:I3)+SUM(R$2:R3))/(SUM(I$2:I$22)+SUM(R$2:R$22)) -> 0.070814592 | AD3: =(SUM(J$2:J3)+SUM(S$2:S3))/(SUM(J$2:J$22)+SUM(S$2:S$22)) -> 0.065548254
A4: 10-14岁 | B4: 39649204 | C4: =Freeze[[#This Row],[2025女]] -> 42197039 | D4: =Freeze[[#This Row],[2030女]] -> 36781740 | E4: =Freeze[[#This Row],[2035女]] -> 28687491 | F4: =Freeze[[#This Row],[2040女]] -> 25077415 | G4: =Freeze[[#This Row],[2045女]] -> 23399589 | H4: =Freeze[[#This Row],[2050女]] -> 23828006 | I4: =Freeze[[#This Row],[2055女]] -> 24021064 | J4: =Freeze[[#This Row],[2060女]] -> 22361004 | K4: 45606790 | L4: =Freeze[[#This Row],[2025男]] -> 47969441 | M4: =Freeze[[#This Row],[2030男]] -> 40785112 | N4: =Freeze[[#This Row],[2035男]] -> 30094703 | O4: =Freeze[[#This Row],[2040男]] -> 26307540 | P4: =Freeze[[#This Row],[2045男]] -> 24547412 | Q4: =Freeze[[#This Row],[2050男]] -> 24996845 | R4: =Freeze[[#This Row],[2055男]] -> 25199373 | S4: =Freeze[[#This Row],[2060男]] -> 23457881 | U4: 10 | V4: =(SUM(B$2:B4)+SUM(K$2:K4))/(SUM(B$2:B$22)+SUM(K$2:K$22)) -> 0.17973313 | W4: =(SUM(C$2:C4)+SUM(L$2:L4))/(SUM(C$2:C$22)+SUM(L$2:L$22)) -> 0.15942645 | X4: =(SUM(D$2:D4)+SUM(M$2:M4))/(SUM(D$2:D$22)+SUM(M$2:M$22)) -> 0.13255224 | Y4: =(SUM(E$2:E4)+SUM(N$2:N4))/(SUM(E$2:E$22)+SUM(N$2:N$22)) -> 0.11316161 | Z4: =(SUM(F$2:F4)+SUM(O$2:O4))/(SUM(F$2:F$22)+SUM(O$2:O$22)) -> 0.10832923 | AA4: =(SUM(G$2:G4)+SUM(P$2:P4))/(SUM(G$2:G$22)+SUM(P$2:P$22)) -> 0.10994076 | AB4: =(SUM(H$2:H4)+SUM(Q$2:Q4))/(SUM(H$2:H$22)+SUM(Q$2:Q$22)) -> 0.11273643 | AC4: =(SUM(I$2:I4)+SUM(R$2:R4))/(SUM(I$2:I$22)+SUM(R$2:R$22)) -> 0.11135561 | AD4: =(SUM(J$2:J4)+SUM(S$2:S4))/(SUM(J$2:J$22)+SUM(S$2:S$22)) -> 0.10565932
A5: 15-19岁 | B5: 33630797 | C5: =Freeze[[#This Row],[2025女]] -> 39609555 | D5: =Freeze[[#This Row],[2030女]] -> 42154842 | E5: =Freeze[[#This Row],[2035女]] -> 36744958 | F5: =Freeze[[#This Row],[2040女]] -> 28658804 | G5: =Freeze[[#This Row],[2045女]] -> 25052337 | H5: =Freeze[[#This Row],[2050女]] -> 23376189 | I5: =Freeze[[#This Row],[2055女]] -> 23804178 | J5: =Freeze[[#This Row],[2060女]] -> 23997043 | K5: 39053343 | L5: =Freeze[[#This Row],[2025男]] -> 45547501 | M5: =Freeze[[#This Row],[2030男]] -> 47907080 | N5: =Freeze[[#This Row],[2035男]] -> 40732092 | O5: =Freeze[[#This Row],[2040男]] -> 30055580 | P5: =Freeze[[#This Row],[2045男]] -> 26273341 | Q5: =Freeze[[#This Row],[2050男]] -> 24515500 | R5: =Freeze[[#This Row],[2055男]] -> 24964349 | S5: =Freeze[[#This Row],[2060男]] -> 25166613 | U5: 15 | V5: =(SUM(B$2:B5)+SUM(K$2:K5))/(SUM(B$2:B$22)+SUM(K$2:K$22)) -> 0.23129025 | W5: =(SUM(C$2:C5)+SUM(L$2:L5))/(SUM(C$2:C$22)+SUM(L$2:L$22)) -> 0.21928091 | X5: =(SUM(D$2:D5)+SUM(M$2:M5))/(SUM(D$2:D$22)+SUM(M$2:M$22)) -> 0.19605392 | Y5: =(SUM(E$2:E5)+SUM(N$2:N5))/(SUM(E$2:E$22)+SUM(N$2:N$22)) -> 0.16852781 | Z5: =(SUM(F$2:F5)+SUM(O$2:O5))/(SUM(F$2:F$22)+SUM(O$2:O$22)) -> 0.15119058 | AA5: =(SUM(G$2:G5)+SUM(P$2:P5))/(SUM(G$2:G$22)+SUM(P$2:P$22)) -> 0.14852798 | AB5: =(SUM(H$2:H5)+SUM(Q$2:Q5))/(SUM(H$2:H$22)+SUM(Q$2:Q$22)) -> 0.15020626 | AC5: =(SUM(I$2:I5)+SUM(R$2:R5))/(SUM(I$2:I$22)+SUM(R$2:R$22)) -> 0.15152441 | AD5: =(SUM(J$2:J5)+SUM(S$2:S5))/(SUM(J$2:J$22)+SUM(S$2:S$22)) -> 0.14869849
A6: 20-24岁 | B6: 35265680 | C6: =Freeze[[#This Row],[2025女]] -> 33590440 | D6: =Freeze[[#This Row],[2030女]] -> 39562023 | E6: =Freeze[[#This Row],[2035女]] -> 42104257 | F6: =Freeze[[#This Row],[2040女]] -> 36700864 | G6: =Freeze[[#This Row],[2045女]] -> 28624413 | H6: =Freeze[[#This Row],[2050女]] -> 25022274 | I6: =Freeze[[#This Row],[2055女]] -> 23348138 | J6: =Freeze[[#This Row],[2060女]] -> 23775613 | K6: 39675995 | L6: =Freeze[[#This Row],[2025男]] -> 38963520 | M6: =Freeze[[#This Row],[2030男]] -> 45442742 | N6: =Freeze[[#This Row],[2035男]] -> 47796894 | O6: =Freeze[[#This Row],[2040男]] -> 40638408 | P6: =Freeze[[#This Row],[2045男]] -> 29986452 | Q6: =Freeze[[#This Row],[2050男]] -> 26212912 | R6: =Freeze[[#This Row],[2055男]] -> 24459115 | S6: =Freeze[[#This Row],[2060男]] -> 24906931 | U6: 20 | V6: =(SUM(B$2:B6)+SUM(K$2:K6))/(SUM(B$2:B$22)+SUM(K$2:K$22)) -> 0.28444872 | W6: =(SUM(C$2:C6)+SUM(L$2:L6))/(SUM(C$2:C$22)+SUM(L$2:L$22)) -> 0.27027702 | X6: =(SUM(D$2:D6)+SUM(M$2:M6))/(SUM(D$2:D$22)+SUM(M$2:M$22)) -> 0.25598986 | Y6: =(SUM(E$2:E6)+SUM(N$2:N6))/(SUM(E$2:E$22)+SUM(N$2:N$22)) -> 0.23277246 | Z6: =(SUM(F$2:F6)+SUM(O$2:O6))/(SUM(F$2:F$22)+SUM(O$2:O$22)) -> 0.20764805 | AA6: =(SUM(G$2:G6)+SUM(P$2:P6))/(SUM(G$2:G$22)+SUM(P$2:P$22)) -> 0.19259227 | AB6: =(SUM(H$2:H6)+SUM(Q$2:Q6))/(SUM(H$2:H$22)+SUM(Q$2:Q$22)) -> 0.190292 | AC6: =(SUM(I$2:I6)+SUM(R$2:R6))/(SUM(I$2:I$22)+SUM(R$2:R$22)) -> 0.19090144 | AD6: =(SUM(J$2:J6)+SUM(S$2:S6))/(SUM(J$2:J$22)+SUM(S$2:S$22)) -> 0.19131648
A7: 25-29岁 | B7: 43685062 | C7: =Freeze[[#This Row],[2025女]] -> 35219835 | D7: =Freeze[[#This Row],[2030女]] -> 33546772 | E7: =Freeze[[#This Row],[2035女]] -> 39510593 | F7: =Freeze[[#This Row],[2040女]] -> 42049521 | G7: =Freeze[[#This Row],[2045女]] -> 36653153 | H7: =Freeze[[#This Row],[2050女]] -> 28587202 | I7: =Freeze[[#This Row],[2055女]] -> 24989745 | J7: =Freeze[[#This Row],[2060女]] -> 23317785 | K7: 48162270 | L7: =Freeze[[#This Row],[2025男]] -> 39568870 | M7: =Freeze[[#This Row],[2030男]] -> 38858319 | N7: =Freeze[[#This Row],[2035男]] -> 45320047 | O7: =Freeze[[#This Row],[2040男]] -> 47667842 | P7: =Freeze[[#This Row],[2045男]] -> 40528684 | Q7: =Freeze[[#This Row],[2050男]] -> 29905488 | R7: =Freeze[[#This Row],[2055男]] -> 26142137 | S7: =Freeze[[#This Row],[2060男]] -> 24393075 | U7: 25 | V7: =(SUM(B$2:B7)+SUM(K$2:K7))/(SUM(B$2:B$22)+SUM(K$2:K$22)) -> 0.3495989 | W7: =(SUM(C$2:C7)+SUM(L$2:L7))/(SUM(C$2:C$22)+SUM(L$2:L$22)) -> 0.32284386 | X7: =(SUM(D$2:D7)+SUM(M$2:M7))/(SUM(D$2:D$22)+SUM(M$2:M$22)) -> 0.3070419 | Y7: =(SUM(E$2:E7)+SUM(N$2:N7))/(SUM(E$2:E$22)+SUM(N$2:N$22)) -> 0.29339364 | Z7: =(SUM(F$2:F7)+SUM(O$2:O7))/(SUM(F$2:F$22)+SUM(O$2:O$22)) -> 0.2731415 | AA7: =(SUM(G$2:G7)+SUM(P$2:P7))/(SUM(G$2:G$22)+SUM(P$2:P$22)) -> 0.25061843 | AB7: =(SUM(H$2:H7)+SUM(Q$2:Q7))/(SUM(H$2:H$22)+SUM(Q$2:Q$22)) -> 0.23605592 | AC7: =(SUM(I$2:I7)+SUM(R$2:R7))/(SUM(I$2:I$22)+SUM(R$2:R$22)) -> 0.23301684 | AD7: =(SUM(J$2:J7)+SUM(S$2:S7))/(SUM(J$2:J$22)+SUM(S$2:S$22)) -> 0.23308384
A8: 30-34岁 | B8: 60273382 | C8: =Freeze[[#This Row],[2025女]] -> 43623903 | D8: =Freeze[[#This Row],[2030女]] -> 35170527 | E8: =Freeze[[#This Row],[2035女]] -> 33499807 | F8: =Freeze[[#This Row],[2040女]] -> 39455278 | G8: =Freeze[[#This Row],[2045女]] -> 41990652 | H8: =Freeze[[#This Row],[2050女]] -> 36601838 | I8: =Freeze[[#This Row],[2055女]] -> 28547180 | J8: =Freeze[[#This Row],[2060女]] -> 24954760 | K8: 63871808 | L8: =Freeze[[#This Row],[2025男]] -> 48003335 | M8: =Freeze[[#This Row],[2030男]] -> 39438293 | N8: =Freeze[[#This Row],[2035男]] -> 38730086 | O8: =Freeze[[#This Row],[2040男]] -> 45170490 | P8: =Freeze[[#This Row],[2045男]] -> 47510538 | Q8: =Freeze[[#This Row],[2050男]] -> 40394940 | R8: =Freeze[[#This Row],[2055男]] -> 29806800 | S8: =Freeze[[#This Row],[2060男]] -> 26055868 | U8: 30 | V8: =(SUM(B$2:B8)+SUM(K$2:K8))/(SUM(B$2:B$22)+SUM(K$2:K$22)) -> 0.43765895 | W8: =(SUM(C$2:C8)+SUM(L$2:L8))/(SUM(C$2:C$22)+SUM(L$2:L$22)) -> 0.38724603 | X8: =(SUM(D$2:D8)+SUM(M$2:M8))/(SUM(D$2:D$22)+SUM(M$2:M$22)) -> 0.35964776 | Y8: =(SUM(E$2:E8)+SUM(N$2:N8))/(SUM(E$2:E$22)+SUM(N$2:N$22)) -> 0.34501015 | Z8: =(SUM(F$2:F8)+SUM(O$2:O8))/(SUM(F$2:F$22)+SUM(O$2:O$22)) -> 0.3349181 | AA8: =(SUM(G$2:G8)+SUM(P$2:P8))/(SUM(G$2:G$22)+SUM(P$2:P$22)) -> 0.31790642 | AB8: =(SUM(H$2:H8)+SUM(Q$2:Q8))/(SUM(H$2:H$22)+SUM(Q$2:Q$22)) -> 0.29629719 | AC8: =(SUM(I$2:I8)+SUM(R$2:R8))/(SUM(I$2:I$22)+SUM(R$2:R$22)) -> 0.28108081 | AD8: =(SUM(J$2:J8)+SUM(S$2:S8))/(SUM(J$2:J$22)+SUM(S$2:S$22)) -> 0.27773989
A9: 35-39岁 | B9: 48080895 | C9: =Freeze[[#This Row],[2025女]] -> 60158863 | D9: =Freeze[[#This Row],[2030女]] -> 43541017 | E9: =Freeze[[#This Row],[2035女]] -> 35103703 | F9: =Freeze[[#This Row],[2040女]] -> 33436157 | G9: =Freeze[[#This Row],[2045女]] -> 39380313 | H9: =Freeze[[#This Row],[2050女]] -> 41910869 | I9: =Freeze[[#This Row],[2055女]] -> 36532295 | J9: =Freeze[[#This Row],[2060女]] -> 28492940 | K9: 50932037 | L9: =Freeze[[#This Row],[2025男]] -> 63590772 | M9: =Freeze[[#This Row],[2030男]] -> 47792120 | N9: =Freeze[[#This Row],[2035男]] -> 39264764 | O9: =Freeze[[#This Row],[2040男]] -> 38559674 | P9: =Freeze[[#This Row],[2045男]] -> 44971740 | Q9: =Freeze[[#This Row],[2050男]] -> 47301492 | R9: =Freeze[[#This Row],[2055男]] -> 40217202 | S9: =Freeze[[#This Row],[2060男]] -> 29675650 | U9: 35 | V9: =(SUM(B$2:B9)+SUM(K$2:K9))/(SUM(B$2:B$22)+SUM(K$2:K$22)) -> 0.50789191 | W9: =(SUM(C$2:C9)+SUM(L$2:L9))/(SUM(C$2:C$22)+SUM(L$2:L$22)) -> 0.47422611 | X9: =(SUM(D$2:D9)+SUM(M$2:M9))/(SUM(D$2:D$22)+SUM(M$2:M$22)) -> 0.42404576 | Y9: =(SUM(E$2:E9)+SUM(N$2:N9))/(SUM(E$2:E$22)+SUM(N$2:N$22)) -> 0.39815492 | Z9: =(SUM(F$2:F9)+SUM(O$2:O9))/(SUM(F$2:F$22)+SUM(O$2:O$22)) -> 0.38747488 | AA9: =(SUM(G$2:G9)+SUM(P$2:P9))/(SUM(G$2:G$22)+SUM(P$2:P$22)) -> 0.38132322 | AB9: =(SUM(H$2:H9)+SUM(Q$2:Q9))/(SUM(H$2:H$22)+SUM(Q$2:Q$22)) -> 0.36609578 | AC9: =(SUM(I$2:I9)+SUM(R$2:R9))/(SUM(I$2:I$22)+SUM(R$2:R$22)) -> 0.34429647 | AD9: =(SUM(J$2:J9)+SUM(S$2:S9))/(SUM(J$2:J$22)+SUM(S$2:S$22)) -> 0.32866222
A10: 40-44岁 | B10: 45322636 | C10: =Freeze[[#This Row],[2025女]] -> 47951077 | D10: =Freeze[[#This Row],[2030女]] -> 59996434 | E10: =Freeze[[#This Row],[2035女]] -> 43423457 | F10: =Freeze[[#This Row],[2040女]] -> 35008923 | G10: =Freeze[[#This Row],[2045女]] -> 33345880 | H10: =Freeze[[#This Row],[2050女]] -> 39273986 | I10: =Freeze[[#This Row],[2055女]] -> 41797710 | J10: =Freeze[[#This Row],[2060女]] -> 36433658 | K10: 47632694 | L10: =Freeze[[#This Row],[2025男]] -> 50580606 | M10: =Freeze[[#This Row],[2030男]] -> 63151996 | N10: =Freeze[[#This Row],[2035男]] -> 47462354 | O10: =Freeze[[#This Row],[2040男]] -> 38993837 | P10: =Freeze[[#This Row],[2045男]] -> 38293612 | Q10: =Freeze[[#This Row],[2050男]] -> 44661435 | R10: =Freeze[[#This Row],[2055男]] -> 46975112 | S10: =Freeze[[#This Row],[2060男]] -> 39939703 | U10: 40 | V10: =(SUM(B$2:B10)+SUM(K$2:K10))/(SUM(B$2:B$22)+SUM(K$2:K$22)) -> 0.57382802 | W10: =(SUM(C$2:C10)+SUM(L$2:L10))/(SUM(C$2:C$22)+SUM(L$2:L$22)) -> 0.54348122 | X10: =(SUM(D$2:D10)+SUM(M$2:M10))/(SUM(D$2:D$22)+SUM(M$2:M$22)) -> 0.51087638 | Y10: =(SUM(E$2:E10)+SUM(N$2:N10))/(SUM(E$2:E$22)+SUM(N$2:N$22)) -> 0.46310321 | Z10: =(SUM(F$2:F10)+SUM(O$2:O10))/(SUM(F$2:F$22)+SUM(O$2:O$22)) -> 0.4414967 | AA10: =(SUM(G$2:G10)+SUM(P$2:P10))/(SUM(G$2:G$22)+SUM(P$2:P$22)) -> 0.43518259 | AB10: =(SUM(H$2:H10)+SUM(Q$2:Q10))/(SUM(H$2:H$22)+SUM(Q$2:Q$22)) -> 0.43176576 | AC10: =(SUM(I$2:I10)+SUM(R$2:R10))/(SUM(I$2:I$22)+SUM(R$2:R$22)) -> 0.4174153 | AD10: =(SUM(J$2:J10)+SUM(S$2:S10))/(SUM(J$2:J$22)+SUM(S$2:S$22)) -> 0.39552149
A11: 45-49岁 | B11: 56033201 | C11: =Freeze[[#This Row],[2025女]] -> 45127749 | D11: =Freeze[[#This Row],[2030女]] -> 47744887 | E11: =Freeze[[#This Row],[2035女]] -> 59738449 | F11: =Freeze[[#This Row],[2040女]] -> 43236736 | G11: =Freeze[[#This Row],[2045女]] -> 34858384 | H11: =Freeze[[#This Row],[2050女]] -> 33202492 | I11: =Freeze[[#This Row],[2055女]] -> 39105108 | J11: =Freeze[[#This Row],[2060女]] -> 41617980 | K11: 58191686 | L11: =Freeze[[#This Row],[2025男]] -> 47108734 | M11: =Freeze[[#This Row],[2030男]] -> 50024219 | N11: =Freeze[[#This Row],[2035男]] -> 62457324 | O11: =Freeze[[#This Row],[2040男]] -> 46940268 | P11: =Freeze[[#This Row],[2045男]] -> 38564905 | Q11: =Freeze[[#This Row],[2050男]] -> 37872382 | R11: =Freeze[[#This Row],[2055男]] -> 44170159 | S11: =Freeze[[#This Row],[2060男]] -> 46458386 | U11: 45 | V11: =(SUM(B$2:B11)+SUM(K$2:K11))/(SUM(B$2:B$22)+SUM(K$2:K$22)) -> 0.6548513 | W11: =(SUM(C$2:C11)+SUM(L$2:L11))/(SUM(C$2:C$22)+SUM(L$2:L$22)) -> 0.6083116 | X11: =(SUM(D$2:D11)+SUM(M$2:M11))/(SUM(D$2:D$22)+SUM(M$2:M$22)) -> 0.57981231 | Y11: =(SUM(E$2:E11)+SUM(N$2:N11))/(SUM(E$2:E$22)+SUM(N$2:N$22)) -> 0.55042605 | Z11: =(SUM(F$2:F11)+SUM(O$2:O11))/(SUM(F$2:F$22)+SUM(O$2:O$22)) -> 0.50732569 | AA11: =(SUM(G$2:G11)+SUM(P$2:P11))/(SUM(G$2:G$22)+SUM(P$2:P$22)) -> 0.49038303 | AB11: =(SUM(H$2:H11)+SUM(Q$2:Q11))/(SUM(H$2:H$22)+SUM(Q$2:Q$22)) -> 0.48737382 | AC11: =(SUM(I$2:I11)+SUM(R$2:R11))/(SUM(I$2:I$22)+SUM(R$2:R$22)) -> 0.486006 | AD11: =(SUM(J$2:J11)+SUM(S$2:S11))/(SUM(J$2:J$22)+SUM(S$2:S$22)) -> 0.47262587
A12: 50-54岁 | B12: 60058826 | C12: =Freeze[[#This Row],[2025女]] -> 55640969 | D12: =Freeze[[#This Row],[2030女]] -> 44811854 | E12: =Freeze[[#This Row],[2035女]] -> 47410673 | F12: =Freeze[[#This Row],[2040女]] -> 59320280 | G12: =Freeze[[#This Row],[2045女]] -> 42934079 | H12: =Freeze[[#This Row],[2050女]] -> 34614376 | I12: =Freeze[[#This Row],[2055女]] -> 32970075 | J12: =Freeze[[#This Row],[2060女]] -> 38831372 | K12: 61105470 | L12: =Freeze[[#This Row],[2025男]] -> 57214066 | M12: =Freeze[[#This Row],[2030男]] -> 46317308 | N12: =Freeze[[#This Row],[2035男]] -> 49183812 | O12: =Freeze[[#This Row],[2040男]] -> 61408041 | P12: =Freeze[[#This Row],[2045男]] -> 46151672 | Q12: =Freeze[[#This Row],[2050男]] -> 37917015 | R12: =Freeze[[#This Row],[2055男]] -> 37236126 | S12: =Freeze[[#This Row],[2060男]] -> 43428101 | U12: 50 | V12: =(SUM(B$2:B12)+SUM(K$2:K12))/(SUM(B$2:B$22)+SUM(K$2:K$22)) -> 0.74079691 | W12: =(SUM(C$2:C12)+SUM(L$2:L12))/(SUM(C$2:C$22)+SUM(L$2:L$22)) -> 0.68763418 | X12: =(SUM(D$2:D12)+SUM(M$2:M12))/(SUM(D$2:D$22)+SUM(M$2:M$22)) -> 0.64406649 | Y12: =(SUM(E$2:E12)+SUM(N$2:N12))/(SUM(E$2:E$22)+SUM(N$2:N$22)) -> 0.61945385 | Z12: =(SUM(F$2:F12)+SUM(O$2:O12))/(SUM(F$2:F$22)+SUM(O$2:O$22)) -> 0.59545706 | AA12: =(SUM(G$2:G12)+SUM(P$2:P12))/(SUM(G$2:G$22)+SUM(P$2:P$22)) -> 0.55735868 | AB12: =(SUM(H$2:H12)+SUM(Q$2:Q12))/(SUM(H$2:H$22)+SUM(Q$2:Q$22)) -> 0.54412143 | AC12: =(SUM(I$2:I12)+SUM(R$2:R12))/(SUM(I$2:I$22)+SUM(R$2:R$22)) -> 0.54383219 | AD12: =(SUM(J$2:J12)+SUM(S$2:S12))/(SUM(J$2:J$22)+SUM(S$2:S$22)) -> 0.544638
A13: 55-59岁 | B13: 50584760 | C13: =Freeze[[#This Row],[2025女]] -> 59368150 | D13: =Freeze[[#This Row],[2030女]] -> 55001097 | E13: =Freeze[[#This Row],[2035女]] -> 44296518 | F13: =Freeze[[#This Row],[2040女]] -> 46865450 | G13: =Freeze[[#This Row],[2045女]] -> 58638097 | H13: =Freeze[[#This Row],[2050女]] -> 42440337 | I13: =Freeze[[#This Row],[2055女]] -> 34216310 | J13: =Freeze[[#This Row],[2060女]] -> 32590919 | K13: 50816026 | L13: =Freeze[[#This Row],[2025男]] -> 59528949 | M13: =Freeze[[#This Row],[2030男]] -> 55737943 | N13: =Freeze[[#This Row],[2035男]] -> 45122321 | O13: =Freeze[[#This Row],[2040男]] -> 47914870 | P13: =Freeze[[#This Row],[2045男]] -> 59823713 | Q13: =Freeze[[#This Row],[2050男]] -> 44960959 | R13: =Freeze[[#This Row],[2055男]] -> 36938756 | S13: =Freeze[[#This Row],[2060男]] -> 36275434 | U13: 55 | V13: =(SUM(B$2:B13)+SUM(K$2:K13))/(SUM(B$2:B$22)+SUM(K$2:K$22)) -> 0.81272365 | W13: =(SUM(C$2:C13)+SUM(L$2:L13))/(SUM(C$2:C$22)+SUM(L$2:L$22)) -> 0.77120356 | X13: =(SUM(D$2:D13)+SUM(M$2:M13))/(SUM(D$2:D$22)+SUM(M$2:M$22)) -> 0.72214738 | Y13: =(SUM(E$2:E13)+SUM(N$2:N13))/(SUM(E$2:E$22)+SUM(N$2:N$22)) -> 0.68335382 | Z13: =(SUM(F$2:F13)+SUM(O$2:O13))/(SUM(F$2:F$22)+SUM(O$2:O$22)) -> 0.66464645 | AA13: =(SUM(G$2:G13)+SUM(P$2:P13))/(SUM(G$2:G$22)+SUM(P$2:P$22)) -> 0.64641958 | AB13: =(SUM(H$2:H13)+SUM(Q$2:Q13))/(SUM(H$2:H$22)+SUM(Q$2:Q$22)) -> 0.61250307 | AC13: =(SUM(I$2:I13)+SUM(R$2:R13))/(SUM(I$2:I$22)+SUM(R$2:R$22)) -> 0.60243994 | AD13: =(SUM(J$2:J13)+SUM(S$2:S13))/(SUM(J$2:J$22)+SUM(S$2:S$22)) -> 0.60492543
A14: 60-64岁 | B14: 36511813 | C14: =Freeze[[#This Row],[2025女]] -> 49694468 | D14: =Freeze[[#This Row],[2030女]] -> 58323270 | E14: =Freeze[[#This Row],[2035女]] -> 54033078 | F14: =Freeze[[#This Row],[2040女]] -> 43516899 | G14: =Freeze[[#This Row],[2045女]] -> 46040618 | H14: =Freeze[[#This Row],[2050女]] -> 57606066 | I14: =Freeze[[#This Row],[2055女]] -> 41693387 | J14: =Freeze[[#This Row],[2060女]] -> 33614103 | K14: 36871125 | L14: =Freeze[[#This Row],[2025男]] -> 48768140 | M14: =Freeze[[#This Row],[2030男]] -> 57129932 | N14: =Freeze[[#This Row],[2035男]] -> 53491704 | O14: =Freeze[[#This Row],[2040男]] -> 43303892 | P14: =Freeze[[#This Row],[2045男]] -> 45983901 | Q14: =Freeze[[#This Row],[2050男]] -> 57412818 | R14: =Freeze[[#This Row],[2055男]] -> 43149032 | S14: =Freeze[[#This Row],[2060男]] -> 35450124 | U14: 60 | V14: =(SUM(B$2:B14)+SUM(K$2:K14))/(SUM(B$2:B$22)+SUM(K$2:K$22)) -> 0.86477645 | W14: =(SUM(C$2:C14)+SUM(L$2:L14))/(SUM(C$2:C$22)+SUM(L$2:L$22)) -> 0.84041011 | X14: =(SUM(D$2:D14)+SUM(M$2:M14))/(SUM(D$2:D$22)+SUM(M$2:M$22)) -> 0.80355218 | Y14: =(SUM(E$2:E14)+SUM(N$2:N14))/(SUM(E$2:E$22)+SUM(N$2:N$22)) -> 0.76019257 | Z14: =(SUM(F$2:F14)+SUM(O$2:O14))/(SUM(F$2:F$22)+SUM(O$2:O$22)) -> 0.72802541 | AA14: =(SUM(G$2:G14)+SUM(P$2:P14))/(SUM(G$2:G$22)+SUM(P$2:P$22)) -> 0.71560463 | AB14: =(SUM(H$2:H14)+SUM(Q$2:Q14))/(SUM(H$2:H$22)+SUM(Q$2:Q$22)) -> 0.70249234 | AC14: =(SUM(I$2:I14)+SUM(R$2:R14))/(SUM(I$2:I$22)+SUM(R$2:R$22)) -> 0.67232144 | AD14: =(SUM(J$2:J14)+SUM(S$2:S14))/(SUM(J$2:J$22)+SUM(S$2:S$22)) -> 0.66538609
... A22: 100岁及以上 | B22: 83737 | C22: =Freeze[[#This Row],[2025女]] -> 118719.29 | D22: =Freeze[[#This Row],[2030女]] -> 159305.01 | E22: =Freeze[[#This Row],[2035女]] -> 234117.89 | F22: =Freeze[[#This Row],[2040女]] -> 288094.27 | G22: =Freeze[[#This Row],[2045女]] -> 351974.98 | H22: =Freeze[[#This Row],[2050女]] -> 492697.46 | I22: =Freeze[[#This Row],[2055女]] -> 693308.13 | J22: =Freeze[[#This Row],[2060女]] -> 652746.73 | K22: 35129 | L22: =Freeze[[#This Row],[2025男]] -> 61484.558 | M22: =Freeze[[#This Row],[2030男]] -> 87290.38 | N22: =Freeze[[#This Row],[2035男]] -> 124557.43 | O22: =Freeze[[#This Row],[2040男]] -> 156471.2 | P22: =Freeze[[#This Row],[2045男]] -> 189390.46 | Q22: =Freeze[[#This Row],[2050男]] -> 262273.32 | R22: =Freeze[[#This Row],[2055男]] -> 356799.91 | S22: =Freeze[[#This Row],[2060男]] -> 339589.2 | U22: 100 | V22: =(SUM(B$2:B22)+SUM(K$2:K22))/(SUM(B$2:B$22)+SUM(K$2:K$22)) -> 1 | W22: =(SUM(C$2:C22)+SUM(L$2:L22))/(SUM(C$2:C$22)+SUM(L$2:L$22)) -> 1 | X22: =(SUM(D$2:D22)+SUM(M$2:M22))/(SUM(D$2:D$22)+SUM(M$2:M$22)) -> 1 | Y22: =(SUM(E$2:E22)+SUM(N$2:N22))/(SUM(E$2:E$22)+SUM(N$2:N$22)) -> 1 | Z22: =(SUM(F$2:F22)+SUM(O$2:O22))/(SUM(F$2:F$22)+SUM(O$2:O$22)) -> 1 | AA22: =(SUM(G$2:G22)+SUM(P$2:P22))/(SUM(G$2:G$22)+SUM(P$2:P$22)) -> 1 | AB22: =(SUM(H$2:H22)+SUM(Q$2:Q22))/(SUM(H$2:H$22)+SUM(Q$2:Q$22)) -> 1 | AC22: =(SUM(I$2:I22)+SUM(R$2:R22))/(SUM(I$2:I$22)+SUM(R$2:R$22)) -> 1 | AD22: =(SUM(J$2:J22)+SUM(S$2:S22))/(SUM(J$2:J$22)+SUM(S$2:S$22)) -> 1
U23: 中位年龄 | V23: =SUM(V24:V28) -> 39.438162 | W23: =SUM(W24:W28) -> 41.860793 | X23: =SUM(X24:X28) -> 44.373701 | Y23: =SUM(Y24:Y28) -> 47.112665 | Z23: =SUM(Z24:Z28) -> 49.443582 | AA23: =SUM(AA24:AA28) -> 50.717945 | AB23: =SUM(AB24:AB28) -> 51.112486 | AC23: =SUM(AC24:AC28) -> 51.210006 | AD23: =SUM(AD24:AD28) -> 51.900661
B24: 2020 | C24: 2025 | D24: 2030 | E24: 2035 | F24: 2040 | G24: 2045 | H24: 2050 | I24: 2055 | J24: 2060 | V24: =((0.5-V8)/(V9-V8)*5)+$U9 -> 39.438162
A25: 女性人口 | B25: =SUM(B2:B22)/100000000 -> 6.8836233 | C25: =SUM(C2:C22)/100000000 -> 6.9790684 | D25: =SUM(D2:D22)/100000000 -> 6.9913398 | E25: =SUM(E2:E22)/100000000 -> 6.933047 | F25: =SUM(F2:F22)/100000000 -> 6.819337 | G25: =SUM(G2:G22)/100000000 -> 6.648663 | H25: =SUM(H2:H22)/100000000 -> 6.410352 | I25: =SUM(I2:I22)/100000000 -> 6.1044167 | ... S25: =SUM(S2:S22)/100000000 -> 5.6714565 | W25: =((0.5-W9)/(W10-W9)*5)+$U10 -> 41.860793 | X25: =((0.5-X9)/(X10-X9)*5)+$U10 -> 44.373701
A26: 男性人口 | B26: =K25 -> 7.2141639 | C26: =L25 -> 7.2482847 | D26: =M25 -> 7.1912647 | E26: =N25 -> 7.0605167 | F26: =O25 -> 6.8793406 | G26: =P25 -> 6.6525511 | H26: =Q25 -> 6.371047 | I26: =R25 -> 6.0364818 | J26: =S25 -> 5.6714565 | Y26: =((0.5-Y10)/(Y11-Y10)*5)+$U11 -> 47.112665 | Z26: =((0.5-Z10)/(Z11-Z10)*5)+$U11 -> 49.443582
A27: 总人口 | B27: =B25+B26 -> 14.097787 | C27: =C25+C26 -> 14.227353 | D27: =D25+D26 -> 14.182605 | E27: =E25+E26 -> 13.993564 | F27: =F25+F26 -> 13.698678 | G27: =G25+G26 -> 13.301214 | H27: =H25+H26 -> 12.781399 | I27: =I25+I26 -> 12.140898 | J27: =J25+J26 -> 11.423003 | AA27: =((0.5-AA11)/(AA12-AA11)*5)+$U12 -> 50.717945 | AB27: =((0.5-AB11)/(AB12-AB11)*5)+$U12 -> 51.112486 | AC27: =((0.5-AC11)/(AC12-AC11)*5)+$U12 -> 51.210006 | AD27: =((0.5-AD11)/(AD12-AD11)*5)+$U12 -> 51.900661
A28: 男女比例 | B28: =K25/B25 -> 1.0480184 | C28: =L25/C25 -> 1.0385748 | D28: =M25/D25 -> 1.0285961 | E28: =N25/E25 -> 1.0183858 | F28: =O25/F25 -> 1.008799 | G28: =P25/G25 -> 1.0005848 | H28: =Q25/H25 -> 0.9938685 | I28: =R25/I25 -> 0.98887119 | J28: =S25/J25 -> 0.98607503
A29: 女性65+比例 | B29: =SUM(B15:B22)/(B25*10^8) -> 0.1454538 | C29: =SUM(C15:C22)/(C25*10^8) -> 0.17212355 | D29: =SUM(D15:D22)/(D25*10^8) -> 0.21258295 | E29: =SUM(E15:E22)/(E25*10^8) -> 0.25987513 | F29: =SUM(F15:F22)/(F25*10^8) -> 0.29515676 | G29: =SUM(G15:G22)/(G25*10^8) -> 0.30983115 | H29: =SUM(H15:H22)/(H25*10^8) -> 0.32461857 | I29: =SUM(I15:I22)/(I25*10^8) -> 0.35625094 | ... S29: =SUM(S15:S22)/(S25*10^8) -> 0.30608166
A30: 男性65+比例 | B30: =K29 -> 0.12546202 | C30: =L29 -> 0.14752175 | D30: =M29 -> 0.18076127 | E30: =N29 -> 0.22010204 | F30: =O29 -> 0.24899462 | G30: =P29 -> 0.25897445 | H30: =Q29 -> 0.27022949 | I30: =R29 -> 0.29878462 | J30: =S29 -> 0.30608166
A31: 总65+比例 | B31: =(SUM(B15:B22)+SUM(K15:K22))/(B27*10^8) -> 0.13522355 | C31: =(SUM(C15:C22)+SUM(L15:L22))/(C27*10^8) -> 0.15958989 | D31: =(SUM(D15:D22)+SUM(M15:M22))/(D27*10^8) -> 0.19644782 | E31: =(SUM(E15:E22)+SUM(N15:N22))/(E27*10^8) -> 0.23980743 | F31: =(SUM(F15:F22)+SUM(O15:O22))/(F27*10^8) -> 0.27197459 | G31: =(SUM(G15:G22)+SUM(P15:P22))/(G27*10^8) -> 0.28439537 | H31: =(SUM(H15:H22)+SUM(Q15:Q22))/(H27*10^8) -> 0.29750766 | I31: =(SUM(I15:I22)+SUM(R15:R22))/(I27*10^8) -> 0.32767856 | J31: =(SUM(J15:J22)+SUM(S15:S22))/(J27*10^8) -> 0.33461391
A32: 平均出生人口 | B32: 1200 | C32: =(C2+L2)/50000 -> 1180.4343 | D32: =(D2+M2)/50000 -> 1031.8867 | E32: =(E2+N2)/50000 -> 962.84744 | F32: =(F2+O2)/50000 -> 980.47599 | G32: =(G2+P2)/50000 -> 988.41993 | H32: =(H2+Q2)/50000 -> 920.1117 | I32: =(I2+R2)/50000 -> 802.34494 | J32: =(J2+S2)/50000 -> 697.74426
A33: 平均死亡人口 | B33: 996 | C33: =(SUM(B2:B22)-SUM(C3:C22)+SUM(K2:K22)-SUM(L3:L22))/50000 -> 921.30268 | D33: =(SUM(C2:C22)-SUM(D3:D22)+SUM(L2:L22)-SUM(M3:M22))/50000 -> 1121.3838 | E33: =(SUM(D2:D22)-SUM(E3:E22)+SUM(M2:M22)-SUM(N3:N22))/50000 -> 1340.929 | F33: =(SUM(E2:E22)-SUM(F3:F22)+SUM(N2:N22)-SUM(O3:O22))/50000 -> 1570.2484 | G33: =(SUM(F2:F22)-SUM(G3:G22)+SUM(O2:O22)-SUM(P3:P22))/50000 -> 1783.3468 | H33: =(SUM(G2:G22)-SUM(H3:H22)+SUM(P2:P22)-SUM(Q3:Q22))/50000 -> 1959.7418 | I33: =(SUM(H2:H22)-SUM(I3:I22)+SUM(Q2:Q22)-SUM(R3:R22))/50000 -> 2083.3462 | J33: =(SUM(I2:I22)-SUM(J3:J22)+SUM(R2:R22)-SUM(S3:S22))/50000 -> 2133.5349
B35: 2020 | C35: 2025 | D35: 2030 | E35: 2035 | F35: 2040 | G35: 2045 | H35: 2050 | I35: 2055 | J35: 2060 | K35: 2020 | L35: 2025 | M35: 2030 | N35: 2035 | O35: 2040 | P35: 2045 | Q35: 2050 | R35: 2055 | S35: 2060
A36: 0-14 | B36: =SUM(B2:B4)/10000 -> 11879.036 | C36: =SUM(C2:C4)/10000 -> 10779.563 | D36: =SUM(D2:D4)/10000 -> 9065.7294 | E36: =SUM(E2:E4)/10000 -> 7726.6556 | F36: =SUM(F2:F4)/10000 -> 7240.7443 | G36: =SUM(G2:G4)/10000 -> 7135.209 | H36: =SUM(H2:H4)/10000 -> 7030.7646 | I36: =SUM(I2:I4)/10000 -> 6596.712 | ... S36: =SUM(S2:S4)/10000 -> 6180.2882
A37: 15-64 | B37: =SUM(B5:B14)/10000 -> 46944.705 | C37: =SUM(C5:C14)/10000 -> 46998.501 | D37: =SUM(D5:D14)/10000 -> 45985.273 | E37: =SUM(E5:E14)/10000 -> 43586.549 | F37: =SUM(F5:F14)/10000 -> 40824.891 | G37: =SUM(G5:G14)/10000 -> 38751.793 | H37: =SUM(H5:H14)/10000 -> 36263.563 | I37: =SUM(I5:I14)/10000 -> 32700.413 | ... S37: =SUM(S5:S14)/10000 -> 33174.989
A38: 65+ | B38: =SUM(B15:B22)/10000 -> 10012.492 | C38: =SUM(C15:C22)/10000 -> 12012.621 | D38: =SUM(D15:D22)/10000 -> 14862.396 | E38: =SUM(E15:E22)/10000 -> 18017.265 | F38: =SUM(F15:F22)/10000 -> 20127.734 | G38: =SUM(G15:G22)/10000 -> 20599.629 | H38: =SUM(H15:H22)/10000 -> 20809.193 | I38: =SUM(I15:I22)/10000 -> 21747.042 | ... S38: =SUM(S15:S22)/10000 -> 17359.288
A39: 少儿抚养比 | B39: =(B36+K36)/(B37+K37)*100 -> 26.236753 | C39: =(C36+L36)/(C37+L37)*100 -> 23.4112 | D39: =(D36+M36)/(D37+M37)*100 -> 19.754434 | E39: =(E36+N36)/(E37+N37)*100 -> 17.489366 | F39: =(F36+O36)/(F37+O37)*100 -> 17.481023 | G39: =(G36+P36)/(G37+P37)*100 -> 18.152108 | H39: =(H36+Q36)/(H37+Q37)*100 -> 19.115777 | I39: =(I36+R36)/(I37+R37)*100 -> 19.850694 | J39: =(J36+S36)/(J37+S37)*100 -> 18.876946
A40: 老人抚养比 | B40: =(B38+K38)/(B37+K37)*100 -> 19.739415 | C40: =(C38+L38)/(C37+L37)*100 -> 23.435201 | D40: =(D38+M38)/(D37+M37)*100 -> 29.276876 | E40: =(E38+N38)/(E37+N37)*100 -> 37.062745 | F40: =(F38+O38)/(F37+O37)*100 -> 43.888376 | G40: =(G38+P38)/(G37+P37)*100 -> 46.955973 | H40: =(H38+Q38)/(H37+Q37)*100 -> 50.445896 | I40: =(I38+R38)/(I37+R37)*100 -> 58.413284 | J40: =(J38+S38)/(J37+S37)*100 -> 59.781653
B56: 1960 | C56: 1965 | D56: 1970 | E56: 1975 | F56: 1980 | G56: 1985 | H56: 1990 | I56: 1995 | J56: 2000 | K56: 2005 | L56: 2010 | M56: 2015 | N56: 2020 | O56: 2025 | P56: 2030 | Q56: 2035 | R56: 2040 | S56: 2045 | T56: 2050 | U56: 2055 | V56: 2060
A57: 总人口-median | N57: =B27 -> 14.097787 | O57: =C27 -> 14.227353 | P57: =D27 -> 14.182605 | Q57: =E27 -> 13.993564 | R57: =F27 -> 13.698678 | S57: =G27 -> 13.301214 | T57: =H27 -> 12.781399 | U57: =I27 -> 12.140898 | V57: =J27 -> 11.423003
A58: 总人口-high | N58: =High_40!B27 -> 14.097787 | O58: =High_40!C27 -> 14.227353 | P58: =High_40!D27 -> 14.326573 | Q58: =High_40!E27 -> 14.404566 | R58: =High_40!F27 -> 14.466844 | S58: =High_40!G27 -> 14.495343 | T58: =High_40!H27 -> 14.46542 | U58: =High_40!I27 -> 14.33056 | V58: =High_40!J27 -> 14.084631
A59: 总人口-past | B59: =HLOOKUP(B56,Past!$B$3:$BT$14,2,FALSE)/10000 -> 6.6207 | C59: =HLOOKUP(C56,Past!$B$3:$BT$14,2,FALSE)/10000 -> 7.2538 | D59: =HLOOKUP(D56,Past!$B$3:$BT$14,2,FALSE)/10000 -> 8.2992 | E59: =HLOOKUP(E56,Past!$B$3:$BT$14,2,FALSE)/10000 -> 9.242 | F59: =HLOOKUP(F56,Past!$B$3:$BT$14,2,FALSE)/10000 -> 9.8705 | G59: =HLOOKUP(G56,Past!$B$3:$BT$14,2,FALSE)/10000 -> 10.5851 | H59: =HLOOKUP(H56,Past!$B$3:$BT$14,2,FALSE)/10000 -> 11.4333 | I59: =HLOOKUP(I56,Past!$B$3:$BT$14,2,FALSE)/10000 -> 12.1121 | ... N59: =HLOOKUP(N56,Past!$B$3:$BT$14,2,FALSE)/10000 -> 14.1212
B61: 1960 | C61: 1965 | D61: 1970 | E61: 1975 | F61: 1980 | G61: 1985 | H61: 1990 | I61: 1995 | J61: 2000 | K61: 2005 | L61: 2010 | M61: 2015 | N61: 2020 | O61: 2025 | P61: 2030 | Q61: 2035 | R61: 2040 | S61: 2045 | T61: 2050 | U61: 2055 | V61: 2060
A62: 男性-median | N62: =B26 -> 7.2141639 | O62: =C26 -> 7.2482847 | P62: =D26 -> 7.1912647 | Q62: =E26 -> 7.0605167 | R62: =F26 -> 6.8793406 | S62: =G26 -> 6.6525511 | T62: =H26 -> 6.371047 | U62: =I26 -> 6.0364818 | V62: =J26 -> 5.6714565
A63: 男性-high | N63: =High_40!B26 -> 7.2141639 | O63: =High_40!C26 -> 7.2482847 | P63: =High_40!D26 -> 7.2630076 | Q63: =High_40!E26 -> 7.2642944 | R63: =High_40!F26 -> 7.2566124 | S63: =High_40!G26 -> 7.2335654 | T63: =High_40!H26 -> 7.1852155 | U63: =High_40!I26 -> 7.0887843 | V63: =High_40!J26 -> 6.9431864
A64: 男性-past | B64: =HLOOKUP(B56,Past!$B$3:$BT$14,3,FALSE)/10000 -> 3.4283 | C64: =HLOOKUP(C56,Past!$B$3:$BT$14,3,FALSE)/10000 -> 3.7128 | D64: =HLOOKUP(D56,Past!$B$3:$BT$14,3,FALSE)/10000 -> 4.2686 | E64: =HLOOKUP(E56,Past!$B$3:$BT$14,3,FALSE)/10000 -> 4.7564 | F64: =HLOOKUP(F56,Past!$B$3:$BT$14,3,FALSE)/10000 -> 5.0785 | G64: =HLOOKUP(G56,Past!$B$3:$BT$14,3,FALSE)/10000 -> 5.4725 | H64: =HLOOKUP(H56,Past!$B$3:$BT$14,3,FALSE)/10000 -> 5.8904 | I64: =HLOOKUP(I56,Past!$B$3:$BT$14,3,FALSE)/10000 -> 6.1808 | ... N64: =HLOOKUP(N56,Past!$B$3:$BT$14,3,FALSE)/10000 -> 7.2357
...

Sheet Freeze_1
A1: Column1 | B1: Column2 | C1: 2025女 | D1: 2030女 | E1: 2035女 | F1: 2040女 | G1: 2045女 | H1: 2050女 | I1: 2055女 | J1: 2060女 | K1: 2020男 | L1: 2025男 | M1: 2030男 | N1: 2035男 | O1: 2040男 | P1: 2045男 | Q1: 2050男 | R1: 2055男 | S1: 2060男 | V1: 2020 | W1: 2025 | X1: 2030 | Y1: 2035 | Z1: 2040 | AA1: 2045 | AB1: 2050 | AC1: 2055 | AD1: 2060
A2: 0-4岁 | B2: 36914557 | C2: 27615678 | D2: 24140480 | E2: 22525341 | F2: 22937437 | G2: 23091214 | H2: 21340327 | I2: 18363352 | J2: 15784108 | K2: 40969331 | L2: 31406037 | M2: 27453855 | N2: 25617031 | O2: 26085689 | P2: 26260573 | Q2: 24269370 | R2: 20883794 | S2: 17950538 | U2: 0 | V2: =(SUM(B$2:B2)+SUM(K$2:K2))/(SUM(B$2:B$22)+SUM(K$2:K$22)) -> 0.05524547 | W2: =(SUM(C$2:C2)+SUM(L$2:L2))/(SUM(C$2:C$22)+SUM(L$2:L$22)) -> 0.041484678 | X2: =(SUM(D$2:D2)+SUM(M$2:M2))/(SUM(D$2:D$22)+SUM(M$2:M$22)) -> 0.036378622 | Y2: =(SUM(E$2:E2)+SUM(N$2:N2))/(SUM(E$2:E$22)+SUM(N$2:N$22)) -> 0.034403266 | Z2: =(SUM(F$2:F2)+SUM(O$2:O2))/(SUM(F$2:F$22)+SUM(O$2:O$22)) -> 0.035786852 | AA2: =(SUM(G$2:G2)+SUM(P$2:P2))/(SUM(G$2:G$22)+SUM(P$2:P$22)) -> 0.037105319 | AB2: =(SUM(H$2:H2)+SUM(Q$2:Q2))/(SUM(H$2:H$22)+SUM(Q$2:Q$22)) -> 0.035697695 | AC2: =(SUM(I$2:I2)+SUM(R$2:R2))/(SUM(I$2:I$22)+SUM(R$2:R$22)) -> 0.032362363 | AD2: =(SUM(J$2:J2)+SUM(S$2:S2))/(SUM(J$2:J$22)+SUM(S$2:S$22)) -> 0.029597161
A3: 5-9岁 | B3: 42226598 | C3: 36807505 | D3: 27535593 | E3: 24070473 | F3: 22460017 | G3: 22870918 | H3: 23024250 | I3: 21278440 | J3: 18310099 | K3: 48017458 | L3: 40825938 | M3: 31296116 | N3: 27357766 | O3: 25527372 | P3: 25994389 | Q3: 26168661 | R3: 24184427 | S3: 20810700 | U3: 5 | V3: =(SUM(B$2:B3)+SUM(K$2:K3))/(SUM(B$2:B$22)+SUM(K$2:K$22)) -> 0.11925839 | W3: =(SUM(C$2:C3)+SUM(L$2:L3))/(SUM(C$2:C$22)+SUM(L$2:L$22)) -> 0.096051007 | X3: =(SUM(D$2:D3)+SUM(M$2:M3))/(SUM(D$2:D$22)+SUM(M$2:M$22)) -> 0.07786024 | Y3: =(SUM(E$2:E3)+SUM(N$2:N3))/(SUM(E$2:E$22)+SUM(N$2:N$22)) -> 0.071154662 | Z3: =(SUM(F$2:F3)+SUM(O$2:O3))/(SUM(F$2:F$22)+SUM(O$2:O$22)) -> 0.070817616 | AA3: =(SUM(G$2:G3)+SUM(P$2:P3))/(SUM(G$2:G$22)+SUM(P$2:P$22)) -> 0.073844877 | AB3: =(SUM(H$2:H3)+SUM(Q$2:Q3))/(SUM(H$2:H$22)+SUM(Q$2:Q$22)) -> 0.07419989 | AC3: =(SUM(I$2:I3)+SUM(R$2:R3))/(SUM(I$2:I$22)+SUM(R$2:R$22)) -> 0.069850078 | AD3: =(SUM(J$2:J3)+SUM(S$2:S3))/(SUM(J$2:J$22)+SUM(S$2:S$22)) -> 0.063919874
A4: 10-14岁 | B4: 39649204 | C4: 42197039 | D4: 36781740 | E4: 27516318 | F4: 24053623 | G4: 22444295 | H4: 22854909 | I4: 23008133 | J4: 21263546 | K4: 45606790 | L4: 47969441 | M4: 40785112 | N4: 31264820 | O4: 27330408 | P4: 25501844 | Q4: 25968395 | R4: 26142492 | S4: 24160243 | U4: 10 | V4: =(SUM(B$2:B4)+SUM(K$2:K4))/(SUM(B$2:B$22)+SUM(K$2:K$22)) -> 0.17973313 | W4: =(SUM(C$2:C4)+SUM(L$2:L4))/(SUM(C$2:C$22)+SUM(L$2:L$22)) -> 0.15942645 | X4: =(SUM(D$2:D4)+SUM(M$2:M4))/(SUM(D$2:D$22)+SUM(M$2:M$22)) -> 0.13255181 | Y4: =(SUM(E$2:E4)+SUM(N$2:N4))/(SUM(E$2:E$22)+SUM(N$2:N$22)) -> 0.11316055 | Z4: =(SUM(F$2:F4)+SUM(O$2:O4))/(SUM(F$2:F$22)+SUM(O$2:O$22)) -> 0.10832793 | AA4: =(SUM(G$2:G4)+SUM(P$2:P4))/(SUM(G$2:G$22)+SUM(P$2:P$22)) -> 0.10989335 | AB4: =(SUM(H$2:H4)+SUM(Q$2:Q4))/(SUM(H$2:H$22)+SUM(Q$2:Q$22)) -> 0.1124128 | AC4: =(SUM(I$2:I4)+SUM(R$2:R4))/(SUM(I$2:I$22)+SUM(R$2:R$22)) -> 0.11037864 | AD4: =(SUM(J$2:J4)+SUM(S$2:S4))/(SUM(J$2:J$22)+SUM(S$2:S$22)) -> 0.10377253
