Workbook

Sheet About
A1: CC Capital Cost of Eqpt to Sequester One Ton of CO2 per Year
A2: CC CCS Total O&M Cost per Ton Sequestered
A3: CC Energy Use per Ton CO2 Sequestered
A5: Source: | B5: Liu et al.
B6: 2022
B7: Techno-economic analysis of using carbon capture and storage (CCS) in decarbonizing China’s coal-fired power plants
B8: Journal of Cleaner Production
B9: https://doi.org/10.1016/j.jclepro.2022.131384
B10: Table 1, Table A2 and Table A3
B12: Pour et al.
B13: 2018
B14: Potential for using municipal solid waste as a resource for bioenergy with carbon capture and storage (BECCS)
B15: International Journal of Greenhouse Gas Control
B16: https://doi.org/10.1016/j.ijggc.2017.11.007
B17: Pour - Table 1
A39: Notes:
A40: This variable captures the capital and O&M costs and energy use of
A41: carbon capture and sequestration, for both the power and industry
A42: sectors. It also includes data on energy use per ton CO2 sequestered.
A44: The energy use value here should exclude any energy that is not additional
A45: to the energy already accounted for in indst/BIFUbC or the heat rates in the
A46: electricity sector. For example, if a steel mill has excess process heat that
A47: isn't being used, and they use it to power CCS, that heat should be excluded
A48: from here, since it does not increase the overall energy demand of the steel
A49: mill.
A51: We use coal to represent electric utilities (which are likely to primarily apply CCS to coal
A52: plants) and natural gas to represent industry.
A55: 0.97 | B55: 2015 to 2012 USD
A57: Constant price conversion | B57: https://stats.areppim.com/calc/calc_usdlrxdeflator.php

Sheet Data
A1: Capital Cost
A2: Table A | B2: coal electricity
A3: Capacity | B3: 1000 | C3: MW | D3: total cost | F3: https://doi.org/10.1016/j.jclepro.2022.131384
A4: Total CO2 | B4: 838 | C4: g/kWh | D4: =B3*10^3*(B8+B7)*0.88 -> 763215200
A5: Capture | B5: =B3*1000*B9*B4*B6/10^6/10^6 -> 3.3403518 | C5: Mt/a | D5: Capital cost | F5: From 2020 $ to 2012
A6: capture rate | B6: 0.9 | D6: =D4/B5/10^6 -> 228.48348 | F6: 0.88
A7: Initial investment | B7: 496.02 | C7: $/kW
A8: Initial capture cost | B8: 371.27 | C8: $/kW | D8: emission
A9: Operation hour | B9: 4429 | C9: h | D9: =B3*B9*1000*B4/10^6 -> 3711502
A12: Table A2 | B12: nature gas electricity
A13: Capacity | B13: 1000 | C13: MW | D13: total cost
A14: Total CO2 | B14: 428 | C14: g/kWh | D14: =B13*10^3*(B18+B17)*0.88 -> 837091200
A15: Capture | B15: =B13*1000*B19*B14*B16/10^6/10^6 -> 1.0214598 | C15: Mt/a | D15: Capital cost
A16: capture rate | B16: =13.8/15.3 -> 0.90196078 | D16: =D14/B15/10^6 -> 819.50482
A17: Initial investment | B17: 387.98 | C17: $/kW
A18: Initial capture cost | B18: 563.26 | C18: $/kW | D18: emission
A19: Operation hour | B19: 2646 | C19: h | D19: =B13*B19*1000*B14/10^6 -> 1132488
A22: Table A3 | B22: biomass electricity
A23: Capacity | B23: 1000 | C23: MW | D23: total cost
A24: Total CO2 | B24: 838 | C24: g/kWh | D24: =B23*10^3*(B28+B27)*0.88 -> 1969633600
A25: Capture | B25: =B23*1000*B29*B24*B26/10^6/10^6 -> 4.802578 | C25: Mt/a | D25: Capital cost
A26: capture rate | B26: =1 -> 1 | D26: =D24/B25/10^6 -> 410.12006
A27: Initial investment | B27: 1674.96 | C27: $/kW
A28: Initial capture cost | B28: 563.26 | C28: $/kW | D28: emission
A29: Operation hour | B29: 5731 | C29: h | D29: =B23*B29*1000*B24/10^6 -> 4802578
A31: Pour - Table 1 | B31: Waste electricity
A32: unit capture | B32: 0.9 | C32: t CO2/MWh | D32: total cost | F32: from 2015 $ to 2012
A33: Capacity | B33: 10 | C33: MW | D33: =B33*B35*10^3*F33 -> 58200000 | F33: 0.97
A34: Operation hour | B34: 8000 | C34: h | D34: Capital cost
A35: Capital | B35: 6000 | C35: $/kW | D35: =D33/(B32*B33*B34) -> 808.33333
A36: emission factor | B36: 0.39 | C36: Tco2/t
A39: cement | E39: capital cost | F39: https://doi.org/10.1016/j.enconman.2012.04.012
A40: annual cement production | B40: 1.998 | C40: million t | D40: process | E40: =B45/B47 -> 84.899813
A41: emission CO2-process | B41: 1.66 | C41: million t | D41: fuel | E41: =B46/B48 -> 107.27969
A42: emission CO2-fuel | B42: 0.87 | C42: million t | F42: https://ieaghg.org/publications/deployment-of-ccs-in-the-cement-industry/
A43: capture rate-process | B43: =(626-65)/626 -> 0.89616613 | F43: https://doi.org/10.1021/acs.est.2c05724
A44: capture rate-fuel | B44: 0.9
A45: capital cost-process | B45: 126.3 | C45: million $
A46: capital cost-fuel | B46: 84 | C46: million $
A47: capital quantity-process | B47: =B41*B43 -> 1.4876358 | C47: million t
...

Sheet Calculations
A1: Capital Cost of Eqpt to Sequester One Ton of CO2 per Year
B2: Capital cost ($/(metric ton CO2e*yr)) | D2: emission percentage
A3: coal electricity | B3: =Data!D6 -> 228.48348 | D3: 0.94 | E3: {=SUMPRODUCT(B3:B6,D3:D6)} -> 260.64734
A4: nature gas elec | B4: =Data!D16 -> 819.50482 | D4: 0.05
A5: biomass electricity | B5: =Data!D26 -> 410.12006 | D5: 0.008
A6: Waste electricity | B6: =Data!D35 -> 808.33333 | D6: 0.002
B7: Fuel-capital cost | C7: process-capital cost | D7: emission
A8: refined petroleum and coke | B8: =Data!B57*Data!I58 -> 78
A9: chemicals | B9: =C9/2 -> 29.842005 | C9: =Data!C52 -> 59.684011
A10: cement and other nonmetallic minerals | B10: =Data!E41 -> 107.27969 | C10: =Data!E40 -> 84.899813
A11: iron and steel | B11: =Data!C65 -> 71 | C11: =Data!D62 -> 95.598217
A12: energy pipelines and gas processing | C12: =Data!D68 -> 26.964
A15: CCS Total O&M Cost per Ton Sequestered
D16: emission percentage
A17: coal electricity | B17: =Data!E74*10^6/Data!D9*Data!F6 -> 8.9481832 | D17: 0.94 | E17: {=SUMPRODUCT(B17:B20,D17:D20)} -> 9.5909926
A18: nature gas elec | B18: =Data!E75*10^6/Data!D19*Data!F6 -> 21.244552 | D18: 0.05
A19: biomass electricity | B19: =Data!E77*10^6/Data!D29*Data!F6 -> 11.94142 | D19: 0.008
A20: Waste electricity | B20: =Data!E76*Data!B36*Data!F33 -> 10.9707 | D20: 0.002
A21: industry-fuel | B21: =Data!E79 -> 14.32425 | D21: =1/3 -> 0.33333333 | E21: {=SUMPRODUCT(B21:B22,D21:D22)} -> 8.7631814
A22: industry-process | B22: =Data!E82 -> 5.9826472 | D22: =2/3 -> 0.66666667
A28: Energy Use per Ton CO2 Sequestered
B29: energy demand | D29: emission percentage
A30: coal electricity | B30: =Data!B95 -> 244713.29 | D30: 0.94 | E30: {=SUMPRODUCT(B30:B33,D30:D33)} -> 246048.59
A31: nature gas elec | B31: =Data!B104 -> 228804.85 | D31: 0.05
A32: biomass electricity | B32: =Data!B113 -> 464181.61 | D32: 0.008
A33: Waste electricity | B33: =Data!B122 -> 432204.65 | D33: 0.002
A34: industry-fuel | B34: =Data!B132 -> 484524.16 | D34: =1/3 -> 0.33333333 | E34: {=SUMPRODUCT(B34:B35,D34:D35)} -> 778160.22
A35: industry-process | B35: =Data!B128 -> 924978.25 | D35: =2/3 -> 0.66666667

Sheet CC-CCoEtSOToCpY
B1: Capital cost ($/(metric ton CO2e*yr))
A2: electricity sector | B2: =Calculations!E3 -> 260.64734
A3: industry sector | B3: 81.452309

Sheet CC-TOMCpTS
B1: O&M Cost per Ton ($/metric ton CO2e)
A2: electricity sector | B2: =Calculations!E17 -> 9.5909926
A3: industry sector | B3: =Calculations!E21 -> 8.7631814

Sheet CC-EUpTCS
B1: Energy Use per Ton Sequestered (BTU/metric ton CO2e)
A2: electricity sector | B2: =Calculations!E30 -> 246048.59
A3: industry sector | B3: =Calculations!E34 -> 778160.22
