Workbook

Sheet 土地利用
B1: Time (Year) | C1: 2023 | D1: 2024 | E1: 2025 | F1: 2026 | G1: 2027 | H1: 2028 | I1: 2029 | J1: 2030 | K1: 2031 | L1: 2032 | M1: 2033 | N1: 2034 | O1: 2035 | P1: 2036 | Q1: 2037 | R1: 2038 | S1: 2039 | T1: 2040 | U1: 2041 | V1: 2042 | W1: 2043 | X1: 2044 | Y1: 2045 | Z1: 2046 | AA1: 2047 | AB1: 2048 | AC1: 2049 | AD1: 2050 | AE1: 2051 | AF1: 2052 | AG1: 2053 | AH1: 2054 | AI1: 2055 | AJ1: 2056 | AK1: 2057 | AL1: 2058 | AM1: 2059 | AN1: 2060
A2: CO2 impact | B2: BAU | C2: =landuse!C2 -> -1.22273e+15 | D2: =landuse!D2 -> -1.22273e+15 | E2: =landuse!E2 -> -1.22273e+15 | F2: =landuse!F2 -> -1.22273e+15 | G2: =landuse!G2 -> -1.22273e+15 | H2: =landuse!H2 -> -1.22273e+15 | I2: =landuse!I2 -> -1.22273e+15 | J2: =landuse!J2 -> -1.22273e+15 | ... AN2: =landuse!AN2 -> -1.22273e+15
B3: 快速转型CNS | C3: =landuse!C16 -> -1.22309e+15 | D3: =landuse!D16 -> -1.22367e+15 | E3: =landuse!E16 -> -1.22447e+15 | F3: =landuse!F16 -> -1.22552e+15 | G3: =landuse!G16 -> -1.22685e+15 | H3: =landuse!H16 -> -1.22846e+15 | I3: =landuse!I16 -> -1.23039e+15 | J3: =landuse!J16 -> -1.23265e+15 | ... AN3: =landuse!AN16 -> -1.45668e+15
B4: 渐进转型CNS | C4: =landuse!C30 -> -1.22309e+15 | D4: =landuse!D30 -> -1.22392e+15 | E4: =landuse!E30 -> -1.22509e+15 | F4: =landuse!F30 -> -1.22657e+15 | G4: =landuse!G30 -> -1.22838e+15 | H4: =landuse!H30 -> -1.23052e+15 | I4: =landuse!I30 -> -1.23299e+15 | J4: =landuse!J30 -> -1.23578e+15 | ... AN4: =landuse!AN30 -> -1.47125e+15
B5: 稳定发展CNS | C5: =landuse!C44 -> -1.22309e+15 | D5: =landuse!D44 -> -1.22394e+15 | E5: =landuse!E44 -> -1.22513e+15 | F5: =landuse!F44 -> -1.22667e+15 | G5: =landuse!G44 -> -1.22857e+15 | H5: =landuse!H44 -> -1.23083e+15 | I5: =landuse!I44 -> -1.23346e+15 | J5: =landuse!J44 -> -1.23647e+15 | ... AN5: =landuse!AN44 -> -1.48478e+15
B8: Time (Year) | C8: 2023 | D8: 2024 | E8: 2025 | F8: 2026 | G8: 2027 | H8: 2028 | I8: 2029 | J8: 2030 | K8: 2031 | L8: 2032 | M8: 2033 | N8: 2034 | O8: 2035 | P8: 2036 | Q8: 2037 | R8: 2038 | S8: 2039 | T8: 2040 | U8: 2041 | V8: 2042 | W8: 2043 | X8: 2044 | Y8: 2045 | Z8: 2046 | AA8: 2047 | AB8: 2048 | AC8: 2049 | AD8: 2050 | AE8: 2051 | AF8: 2052 | AG8: 2053 | AH8: 2054 | AI8: 2055 | AJ8: 2056 | AK8: 2057 | AL8: 2058 | AM8: 2059 | AN8: 2060
A9: CH4 and N2O impact | B9: BAU | C9: =landuse!C14 -> 859217000000 | D9: =landuse!D14 -> 859217000000 | E9: =landuse!E14 -> 859217000000 | F9: =landuse!F14 -> 859217000000 | G9: =landuse!G14 -> 859217000000 | H9: =landuse!H14 -> 859217000000 | I9: =landuse!I14 -> 859217000000 | J9: =landuse!J14 -> 859217000000 | ... AN9: =landuse!AN14 -> 859217000000
B10: 快速转型CNS | C10: =landuse!C28 -> 859470900000 | D10: =landuse!D28 -> 859875100000 | E10: =landuse!E28 -> 860440000000 | F10: =landuse!F28 -> 861180600000 | G10: =landuse!G28 -> 862110600000 | H10: =landuse!H28 -> 863244700000 | I10: =landuse!I28 -> 864597900000 | J10: =landuse!J28 -> 866183800000 | ... AN10: =landuse!AN28 -> 1023568200000
B11: 渐进转型CNS | C11: =landuse!C42 -> 859470900000 | D11: =landuse!D42 -> 860056000000 | E11: =landuse!E42 -> 860871700000 | F11: =landuse!F42 -> 861915900000 | G11: =landuse!G42 -> 863188700000 | H11: =landuse!H42 -> 864692000000 | I11: =landuse!I42 -> 866424000000 | J11: =landuse!J42 -> 868384400000 | ... AN11: =landuse!AN42 -> 1033805200000
B12: 稳定发展CNS | C12: =landuse!C56 -> 859470900000 | D12: =landuse!D56 -> 860065500000 | E12: =landuse!E56 -> 860902400000 | F12: =landuse!F56 -> 861984700000 | G12: =landuse!G56 -> 863317700000 | H12: =landuse!H56 -> 864905800000 | I12: =landuse!I56 -> 866754100000 | J12: =landuse!J56 -> 868866900000 | ... AN12: =landuse!AN56 -> 1043310100000

Sheet landuse
A1: BAU | B1: Time (Year) | C1: 2023 | D1: 2024 | E1: 2025 | F1: 2026 | G1: 2027 | H1: 2028 | I1: 2029 | J1: 2030 | K1: 2031 | L1: 2032 | M1: 2033 | N1: 2034 | O1: 2035 | P1: 2036 | Q1: 2037 | R1: 2038 | S1: 2039 | T1: 2040 | U1: 2041 | V1: 2042 | W1: 2043 | X1: 2044 | Y1: 2045 | Z1: 2046 | AA1: 2047 | AB1: 2048 | AC1: 2049 | AD1: 2050 | AE1: 2051 | AF1: 2052 | AG1: 2053 | AH1: 2054 | AI1: 2055 | AJ1: 2056 | AK1: 2057 | AL1: 2058 | AM1: 2059 | AN1: 2060
B2: LULUCF Anthropogenic Pollutant Emissions[CO2] : MostRecentRun | C2: -1.22273e+15 | D2: -1.22273e+15 | E2: -1.22273e+15 | F2: -1.22273e+15 | G2: -1.22273e+15 | H2: -1.22273e+15 | I2: -1.22273e+15 | J2: -1.22273e+15 | K2: -1.22273e+15 | L2: -1.22273e+15 | M2: -1.22273e+15 | N2: -1.22273e+15 | O2: -1.22273e+15 | P2: -1.22273e+15 | Q2: -1.22273e+15 | R2: -1.22273e+15 | S2: -1.22273e+15 | T2: -1.22273e+15 | U2: -1.22273e+15 | V2: -1.22273e+15 | W2: -1.22273e+15 | X2: -1.22273e+15 | Y2: -1.22273e+15 | Z2: -1.22273e+15 | AA2: -1.22273e+15 | AB2: -1.22273e+15 | AC2: -1.22273e+15 | AD2: -1.22273e+15 | AE2: -1.22273e+15 | AF2: -1.22273e+15 | AG2: -1.22273e+15 | AH2: -1.22273e+15 | AI2: -1.22273e+15 | AJ2: -1.22273e+15 | AK2: -1.22273e+15 | AL2: -1.22273e+15 | AM2: -1.22273e+15 | AN2: -1.22273e+15
B3: LULUCF Anthropogenic Pollutant Emissions[VOC] : MostRecentRun | C3: 0 | D3: 0 | E3: 0 | F3: 0 | G3: 0 | H3: 0 | I3: 0 | J3: 0 | K3: 0 | L3: 0 | M3: 0 | N3: 0 | O3: 0 | P3: 0 | Q3: 0 | R3: 0 | S3: 0 | T3: 0 | U3: 0 | V3: 0 | W3: 0 | X3: 0 | Y3: 0 | Z3: 0 | AA3: 0 | AB3: 0 | AC3: 0 | AD3: 0 | AE3: 0 | AF3: 0 | AG3: 0 | AH3: 0 | AI3: 0 | AJ3: 0 | AK3: 0 | AL3: 0 | AM3: 0 | AN3: 0
B4: LULUCF Anthropogenic Pollutant Emissions[CO] : MostRecentRun | C4: 0 | D4: 0 | E4: 0 | F4: 0 | G4: 0 | H4: 0 | I4: 0 | J4: 0 | K4: 0 | L4: 0 | M4: 0 | N4: 0 | O4: 0 | P4: 0 | Q4: 0 | R4: 0 | S4: 0 | T4: 0 | U4: 0 | V4: 0 | W4: 0 | X4: 0 | Y4: 0 | Z4: 0 | AA4: 0 | AB4: 0 | AC4: 0 | AD4: 0 | AE4: 0 | AF4: 0 | AG4: 0 | AH4: 0 | AI4: 0 | AJ4: 0 | AK4: 0 | AL4: 0 | AM4: 0 | AN4: 0
B5: LULUCF Anthropogenic Pollutant Emissions[NOx] : MostRecentRun | C5: 0 | D5: 0 | E5: 0 | F5: 0 | G5: 0 | H5: 0 | I5: 0 | J5: 0 | K5: 0 | L5: 0 | M5: 0 | N5: 0 | O5: 0 | P5: 0 | Q5: 0 | R5: 0 | S5: 0 | T5: 0 | U5: 0 | V5: 0 | W5: 0 | X5: 0 | Y5: 0 | Z5: 0 | AA5: 0 | AB5: 0 | AC5: 0 | AD5: 0 | AE5: 0 | AF5: 0 | AG5: 0 | AH5: 0 | AI5: 0 | AJ5: 0 | AK5: 0 | AL5: 0 | AM5: 0 | AN5: 0
B6: LULUCF Anthropogenic Pollutant Emissions[PM10] : MostRecentRun | C6: 0 | D6: 0 | E6: 0 | F6: 0 | G6: 0 | H6: 0 | I6: 0 | J6: 0 | K6: 0 | L6: 0 | M6: 0 | N6: 0 | O6: 0 | P6: 0 | Q6: 0 | R6: 0 | S6: 0 | T6: 0 | U6: 0 | V6: 0 | W6: 0 | X6: 0 | Y6: 0 | Z6: 0 | AA6: 0 | AB6: 0 | AC6: 0 | AD6: 0 | AE6: 0 | AF6: 0 | AG6: 0 | AH6: 0 | AI6: 0 | AJ6: 0 | AK6: 0 | AL6: 0 | AM6: 0 | AN6: 0
B7: LULUCF Anthropogenic Pollutant Emissions[PM25] : MostRecentRun | C7: 0 | D7: 0 | E7: 0 | F7: 0 | G7: 0 | H7: 0 | I7: 0 | J7: 0 | K7: 0 | L7: 0 | M7: 0 | N7: 0 | O7: 0 | P7: 0 | Q7: 0 | R7: 0 | S7: 0 | T7: 0 | U7: 0 | V7: 0 | W7: 0 | X7: 0 | Y7: 0 | Z7: 0 | AA7: 0 | AB7: 0 | AC7: 0 | AD7: 0 | AE7: 0 | AF7: 0 | AG7: 0 | AH7: 0 | AI7: 0 | AJ7: 0 | AK7: 0 | AL7: 0 | AM7: 0 | AN7: 0
B8: LULUCF Anthropogenic Pollutant Emissions[SOx] : MostRecentRun | C8: 0 | D8: 0 | E8: 0 | F8: 0 | G8: 0 | H8: 0 | I8: 0 | J8: 0 | K8: 0 | L8: 0 | M8: 0 | N8: 0 | O8: 0 | P8: 0 | Q8: 0 | R8: 0 | S8: 0 | T8: 0 | U8: 0 | V8: 0 | W8: 0 | X8: 0 | Y8: 0 | Z8: 0 | AA8: 0 | AB8: 0 | AC8: 0 | AD8: 0 | AE8: 0 | AF8: 0 | AG8: 0 | AH8: 0 | AI8: 0 | AJ8: 0 | AK8: 0 | AL8: 0 | AM8: 0 | AN8: 0
B9: LULUCF Anthropogenic Pollutant Emissions[BC] : MostRecentRun | C9: 0 | D9: 0 | E9: 0 | F9: 0 | G9: 0 | H9: 0 | I9: 0 | J9: 0 | K9: 0 | L9: 0 | M9: 0 | N9: 0 | O9: 0 | P9: 0 | Q9: 0 | R9: 0 | S9: 0 | T9: 0 | U9: 0 | V9: 0 | W9: 0 | X9: 0 | Y9: 0 | Z9: 0 | AA9: 0 | AB9: 0 | AC9: 0 | AD9: 0 | AE9: 0 | AF9: 0 | AG9: 0 | AH9: 0 | AI9: 0 | AJ9: 0 | AK9: 0 | AL9: 0 | AM9: 0 | AN9: 0
B10: LULUCF Anthropogenic Pollutant Emissions[OC] : MostRecentRun | C10: 0 | D10: 0 | E10: 0 | F10: 0 | G10: 0 | H10: 0 | I10: 0 | J10: 0 | K10: 0 | L10: 0 | M10: 0 | N10: 0 | O10: 0 | P10: 0 | Q10: 0 | R10: 0 | S10: 0 | T10: 0 | U10: 0 | V10: 0 | W10: 0 | X10: 0 | Y10: 0 | Z10: 0 | AA10: 0 | AB10: 0 | AC10: 0 | AD10: 0 | AE10: 0 | AF10: 0 | AG10: 0 | AH10: 0 | AI10: 0 | AJ10: 0 | AK10: 0 | AL10: 0 | AM10: 0 | AN10: 0
B11: LULUCF Anthropogenic Pollutant Emissions[CH4] : MostRecentRun | C11: 812106000000 | D11: 812106000000 | E11: 812106000000 | F11: 812106000000 | G11: 812106000000 | H11: 812106000000 | I11: 812106000000 | J11: 812106000000 | K11: 812106000000 | L11: 812106000000 | M11: 812106000000 | N11: 812106000000 | O11: 812106000000 | P11: 812106000000 | Q11: 812106000000 | R11: 812106000000 | S11: 812106000000 | T11: 812106000000 | U11: 812106000000 | V11: 812106000000 | W11: 812106000000 | X11: 812106000000 | Y11: 812106000000 | Z11: 812106000000 | AA11: 812106000000 | AB11: 812106000000 | AC11: 812106000000 | AD11: 812106000000 | AE11: 812106000000 | AF11: 812106000000 | AG11: 812106000000 | AH11: 812106000000 | AI11: 812106000000 | AJ11: 812106000000 | AK11: 812106000000 | AL11: 812106000000 | AM11: 812106000000 | AN11: 812106000000
B12: LULUCF Anthropogenic Pollutant Emissions[N2O] : MostRecentRun | C12: 47111000000 | D12: 47111000000 | E12: 47111000000 | F12: 47111000000 | G12: 47111000000 | H12: 47111000000 | I12: 47111000000 | J12: 47111000000 | K12: 47111000000 | L12: 47111000000 | M12: 47111000000 | N12: 47111000000 | O12: 47111000000 | P12: 47111000000 | Q12: 47111000000 | R12: 47111000000 | S12: 47111000000 | T12: 47111000000 | U12: 47111000000 | V12: 47111000000 | W12: 47111000000 | X12: 47111000000 | Y12: 47111000000 | Z12: 47111000000 | AA12: 47111000000 | AB12: 47111000000 | AC12: 47111000000 | AD12: 47111000000 | AE12: 47111000000 | AF12: 47111000000 | AG12: 47111000000 | AH12: 47111000000 | AI12: 47111000000 | AJ12: 47111000000 | AK12: 47111000000 | AL12: 47111000000 | AM12: 47111000000 | AN12: 47111000000
B13: LULUCF Anthropogenic Pollutant Emissions[F gases] : MostRecentRun | C13: 0 | D13: 0 | E13: 0 | F13: 0 | G13: 0 | H13: 0 | I13: 0 | J13: 0 | K13: 0 | L13: 0 | M13: 0 | N13: 0 | O13: 0 | P13: 0 | Q13: 0 | R13: 0 | S13: 0 | T13: 0 | U13: 0 | V13: 0 | W13: 0 | X13: 0 | Y13: 0 | Z13: 0 | AA13: 0 | AB13: 0 | AC13: 0 | AD13: 0 | AE13: 0 | AF13: 0 | AG13: 0 | AH13: 0 | AI13: 0 | AJ13: 0 | AK13: 0 | AL13: 0 | AM13: 0 | AN13: 0
B14: BAU CH4 and N2O impact | C14: =C11+C12 -> 859217000000 | D14: =D11+D12 -> 859217000000 | E14: =E11+E12 -> 859217000000 | F14: =F11+F12 -> 859217000000 | G14: =G11+G12 -> 859217000000 | H14: =H11+H12 -> 859217000000 | I14: =I11+I12 -> 859217000000 | J14: =J11+J12 -> 859217000000 | ... AN14: =AN11+AN12 -> 859217000000
A15: 快速转型CNS | B15: Time (Year) | C15: 2023 | D15: 2024 | E15: 2025 | F15: 2026 | G15: 2027 | H15: 2028 | I15: 2029 | J15: 2030 | K15: 2031 | L15: 2032 | M15: 2033 | N15: 2034 | O15: 2035 | P15: 2036 | Q15: 2037 | R15: 2038 | S15: 2039 | T15: 2040 | U15: 2041 | V15: 2042 | W15: 2043 | X15: 2044 | Y15: 2045 | Z15: 2046 | AA15: 2047 | AB15: 2048 | AC15: 2049 | AD15: 2050 | AE15: 2051 | AF15: 2052 | AG15: 2053 | AH15: 2054 | AI15: 2055 | AJ15: 2056 | AK15: 2057 | AL15: 2058 | AM15: 2059 | AN15: 2060
B16: LULUCF Anthropogenic Pollutant Emissions[CO2] : MostRecentRun | C16: -1.22309e+15 | D16: -1.22367e+15 | E16: -1.22447e+15 | F16: -1.22552e+15 | G16: -1.22685e+15 | H16: -1.22846e+15 | I16: -1.23039e+15 | J16: -1.23265e+15 | K16: -1.23526e+15 | L16: -1.23824e+15 | M16: -1.24162e+15 | N16: -1.24542e+15 | O16: -1.24965e+15 | P16: -1.25419e+15 | Q16: -1.25905e+15 | R16: -1.26421e+15 | S16: -1.26969e+15 | T16: -1.27548e+15 | U16: -1.28158e+15 | V16: -1.28799e+15 | W16: -1.29472e+15 | X16: -1.30175e+15 | Y16: -1.3091e+15 | Z16: -1.31676e+15 | AA16: -1.32473e+15 | AB16: -1.33301e+15 | AC16: -1.3416e+15 | AD16: -1.3505e+15 | AE16: -1.35972e+15 | AF16: -1.36925e+15 | AG16: -1.37909e+15 | AH16: -1.38924e+15 | AI16: -1.3997e+15 | AJ16: -1.41047e+15 | AK16: -1.42156e+15 | AL16: -1.43295e+15 | AM16: -1.44466e+15 | AN16: -1.45668e+15
B17: LULUCF Anthropogenic Pollutant Emissions[VOC] : MostRecentRun | C17: 0 | D17: 0 | E17: 0 | F17: 0 | G17: 0 | H17: 0 | I17: 0 | J17: 0 | K17: 0 | L17: 0 | M17: 0 | N17: 0 | O17: 0 | P17: 0 | Q17: 0 | R17: 0 | S17: 0 | T17: 0 | U17: 0 | V17: 0 | W17: 0 | X17: 0 | Y17: 0 | Z17: 0 | AA17: 0 | AB17: 0 | AC17: 0 | AD17: 0 | AE17: 0 | AF17: 0 | AG17: 0 | AH17: 0 | AI17: 0 | AJ17: 0 | AK17: 0 | AL17: 0 | AM17: 0 | AN17: 0
B18: LULUCF Anthropogenic Pollutant Emissions[CO] : MostRecentRun | C18: 0 | D18: 0 | E18: 0 | F18: 0 | G18: 0 | H18: 0 | I18: 0 | J18: 0 | K18: 0 | L18: 0 | M18: 0 | N18: 0 | O18: 0 | P18: 0 | Q18: 0 | R18: 0 | S18: 0 | T18: 0 | U18: 0 | V18: 0 | W18: 0 | X18: 0 | Y18: 0 | Z18: 0 | AA18: 0 | AB18: 0 | AC18: 0 | AD18: 0 | AE18: 0 | AF18: 0 | AG18: 0 | AH18: 0 | AI18: 0 | AJ18: 0 | AK18: 0 | AL18: 0 | AM18: 0 | AN18: 0
B19: LULUCF Anthropogenic Pollutant Emissions[NOx] : MostRecentRun | C19: 0 | D19: 0 | E19: 0 | F19: 0 | G19: 0 | H19: 0 | I19: 0 | J19: 0 | K19: 0 | L19: 0 | M19: 0 | N19: 0 | O19: 0 | P19: 0 | Q19: 0 | R19: 0 | S19: 0 | T19: 0 | U19: 0 | V19: 0 | W19: 0 | X19: 0 | Y19: 0 | Z19: 0 | AA19: 0 | AB19: 0 | AC19: 0 | AD19: 0 | AE19: 0 | AF19: 0 | AG19: 0 | AH19: 0 | AI19: 0 | AJ19: 0 | AK19: 0 | AL19: 0 | AM19: 0 | AN19: 0
B20: LULUCF Anthropogenic Pollutant Emissions[PM10] : MostRecentRun | C20: 0 | D20: 0 | E20: 0 | F20: 0 | G20: 0 | H20: 0 | I20: 0 | J20: 0 | K20: 0 | L20: 0 | M20: 0 | N20: 0 | O20: 0 | P20: 0 | Q20: 0 | R20: 0 | S20: 0 | T20: 0 | U20: 0 | V20: 0 | W20: 0 | X20: 0 | Y20: 0 | Z20: 0 | AA20: 0 | AB20: 0 | AC20: 0 | AD20: 0 | AE20: 0 | AF20: 0 | AG20: 0 | AH20: 0 | AI20: 0 | AJ20: 0 | AK20: 0 | AL20: 0 | AM20: 0 | AN20: 0
B21: LULUCF Anthropogenic Pollutant Emissions[PM25] : MostRecentRun | C21: 0 | D21: 0 | E21: 0 | F21: 0 | G21: 0 | H21: 0 | I21: 0 | J21: 0 | K21: 0 | L21: 0 | M21: 0 | N21: 0 | O21: 0 | P21: 0 | Q21: 0 | R21: 0 | S21: 0 | T21: 0 | U21: 0 | V21: 0 | W21: 0 | X21: 0 | Y21: 0 | Z21: 0 | AA21: 0 | AB21: 0 | AC21: 0 | AD21: 0 | AE21: 0 | AF21: 0 | AG21: 0 | AH21: 0 | AI21: 0 | AJ21: 0 | AK21: 0 | AL21: 0 | AM21: 0 | AN21: 0
B22: LULUCF Anthropogenic Pollutant Emissions[SOx] : MostRecentRun | C22: 0 | D22: 0 | E22: 0 | F22: 0 | G22: 0 | H22: 0 | I22: 0 | J22: 0 | K22: 0 | L22: 0 | M22: 0 | N22: 0 | O22: 0 | P22: 0 | Q22: 0 | R22: 0 | S22: 0 | T22: 0 | U22: 0 | V22: 0 | W22: 0 | X22: 0 | Y22: 0 | Z22: 0 | AA22: 0 | AB22: 0 | AC22: 0 | AD22: 0 | AE22: 0 | AF22: 0 | AG22: 0 | AH22: 0 | AI22: 0 | AJ22: 0 | AK22: 0 | AL22: 0 | AM22: 0 | AN22: 0
B23: LULUCF Anthropogenic Pollutant Emissions[BC] : MostRecentRun | C23: 0 | D23: 0 | E23: 0 | F23: 0 | G23: 0 | H23: 0 | I23: 0 | J23: 0 | K23: 0 | L23: 0 | M23: 0 | N23: 0 | O23: 0 | P23: 0 | Q23: 0 | R23: 0 | S23: 0 | T23: 0 | U23: 0 | V23: 0 | W23: 0 | X23: 0 | Y23: 0 | Z23: 0 | AA23: 0 | AB23: 0 | AC23: 0 | AD23: 0 | AE23: 0 | AF23: 0 | AG23: 0 | AH23: 0 | AI23: 0 | AJ23: 0 | AK23: 0 | AL23: 0 | AM23: 0 | AN23: 0
B24: LULUCF Anthropogenic Pollutant Emissions[OC] : MostRecentRun | C24: 0 | D24: 0 | E24: 0 | F24: 0 | G24: 0 | H24: 0 | I24: 0 | J24: 0 | K24: 0 | L24: 0 | M24: 0 | N24: 0 | O24: 0 | P24: 0 | Q24: 0 | R24: 0 | S24: 0 | T24: 0 | U24: 0 | V24: 0 | W24: 0 | X24: 0 | Y24: 0 | Z24: 0 | AA24: 0 | AB24: 0 | AC24: 0 | AD24: 0 | AE24: 0 | AF24: 0 | AG24: 0 | AH24: 0 | AI24: 0 | AJ24: 0 | AK24: 0 | AL24: 0 | AM24: 0 | AN24: 0
B25: LULUCF Anthropogenic Pollutant Emissions[CH4] : MostRecentRun | C25: 812346000000 | D25: 812728000000 | E25: 813262000000 | F25: 813962000000 | G25: 814841000000 | H25: 815913000000 | I25: 817192000000 | J25: 818691000000 | K25: 820425000000 | L25: 822407000000 | M25: 824651000000 | N25: 827171000000 | O25: 829981000000 | P25: 832997000000 | Q25: 836221000000 | R25: 839651000000 | S25: 843288000000 | T25: 847132000000 | U25: 851182000000 | V25: 855440000000 | W25: 859904000000 | X25: 864576000000 | Y25: 869454000000 | Z25: 874539000000 | AA25: 879831000000 | AB25: 885330000000 | AC25: 891035000000 | AD25: 896948000000 | AE25: 903067000000 | AF25: 909393000000 | AG25: 915926000000 | AH25: 922666000000 | AI25: 929613000000 | AJ25: 936767000000 | AK25: 944127000000 | AL25: 951695000000 | AM25: 959469000000 | AN25: 967450000000
B26: LULUCF Anthropogenic Pollutant Emissions[N2O] : MostRecentRun | C26: 47124900000 | D26: 47147100000 | E26: 47178000000 | F26: 47218600000 | G26: 47269600000 | H26: 47331700000 | I26: 47405900000 | J26: 47492800000 | K26: 47593300000 | L26: 47708300000 | M26: 47838400000 | N26: 47984500000 | O26: 48147400000 | P26: 48322300000 | Q26: 48509200000 | R26: 48708100000 | S26: 48919000000 | T26: 49141900000 | U26: 49376700000 | V26: 49623600000 | W26: 49882500000 | X26: 50153300000 | Y26: 50436200000 | Z26: 50731000000 | AA26: 51037800000 | AB26: 51356700000 | AC26: 51687500000 | AD26: 52030300000 | AE26: 52385100000 | AF26: 52751900000 | AG26: 53130700000 | AH26: 53521500000 | AI26: 53924300000 | AJ26: 54339100000 | AK26: 54765900000 | AL26: 55204600000 | AM26: 55655400000 | AN26: 56118200000
B27: LULUCF Anthropogenic Pollutant Emissions[F gases] : MostRecentRun | C27: 0 | D27: 0 | E27: 0 | F27: 0 | G27: 0 | H27: 0 | I27: 0 | J27: 0 | K27: 0 | L27: 0 | M27: 0 | N27: 0 | O27: 0 | P27: 0 | Q27: 0 | R27: 0 | S27: 0 | T27: 0 | U27: 0 | V27: 0 | W27: 0 | X27: 0 | Y27: 0 | Z27: 0 | AA27: 0 | AB27: 0 | AC27: 0 | AD27: 0 | AE27: 0 | AF27: 0 | AG27: 0 | AH27: 0 | AI27: 0 | AJ27: 0 | AK27: 0 | AL27: 0 | AM27: 0 | AN27: 0
B28: CNS CH4 and N2O impact | C28: =C25+C26 -> 859470900000 | D28: =D25+D26 -> 859875100000 | E28: =E25+E26 -> 860440000000 | F28: =F25+F26 -> 861180600000 | G28: =G25+G26 -> 862110600000 | H28: =H25+H26 -> 863244700000 | I28: =I25+I26 -> 864597900000 | J28: =J25+J26 -> 866183800000 | ... AN28: =AN25+AN26 -> 1023568200000
A29: 渐进转型CNS | B29: Time (Year) | C29: 2023 | D29: 2024 | E29: 2025 | F29: 2026 | G29: 2027 | H29: 2028 | I29: 2029 | J29: 2030 | K29: 2031 | L29: 2032 | M29: 2033 | N29: 2034 | O29: 2035 | P29: 2036 | Q29: 2037 | R29: 2038 | S29: 2039 | T29: 2040 | U29: 2041 | V29: 2042 | W29: 2043 | X29: 2044 | Y29: 2045 | Z29: 2046 | AA29: 2047 | AB29: 2048 | AC29: 2049 | AD29: 2050 | AE29: 2051 | AF29: 2052 | AG29: 2053 | AH29: 2054 | AI29: 2055 | AJ29: 2056 | AK29: 2057 | AL29: 2058 | AM29: 2059 | AN29: 2060
B30: LULUCF Anthropogenic Pollutant Emissions[CO2] : MostRecentRun | C30: -1.22309e+15 | D30: -1.22392e+15 | E30: -1.22509e+15 | F30: -1.22657e+15 | G30: -1.22838e+15 | H30: -1.23052e+15 | I30: -1.23299e+15 | J30: -1.23578e+15 | K30: -1.2389e+15 | L30: -1.24234e+15 | M30: -1.24611e+15 | N30: -1.25021e+15 | O30: -1.25463e+15 | P30: -1.25938e+15 | Q30: -1.26446e+15 | R30: -1.26986e+15 | S30: -1.27559e+15 | T30: -1.28164e+15 | U30: -1.28802e+15 | V30: -1.29473e+15 | W30: -1.30176e+15 | X30: -1.30912e+15 | Y30: -1.31681e+15 | Z30: -1.32482e+15 | AA30: -1.33316e+15 | AB30: -1.34183e+15 | AC30: -1.35082e+15 | AD30: -1.36013e+15 | AE30: -1.36978e+15 | AF30: -1.37975e+15 | AG30: -1.39004e+15 | AH30: -1.40067e+15 | AI30: -1.41162e+15 | AJ30: -1.42289e+15 | AK30: -1.43449e+15 | AL30: -1.44642e+15 | AM30: -1.45867e+15 | AN30: -1.47125e+15
B31: LULUCF Anthropogenic Pollutant Emissions[VOC] : MostRecentRun | C31: 0 | D31: 0 | E31: 0 | F31: 0 | G31: 0 | H31: 0 | I31: 0 | J31: 0 | K31: 0 | L31: 0 | M31: 0 | N31: 0 | O31: 0 | P31: 0 | Q31: 0 | R31: 0 | S31: 0 | T31: 0 | U31: 0 | V31: 0 | W31: 0 | X31: 0 | Y31: 0 | Z31: 0 | AA31: 0 | AB31: 0 | AC31: 0 | AD31: 0 | AE31: 0 | AF31: 0 | AG31: 0 | AH31: 0 | AI31: 0 | AJ31: 0 | AK31: 0 | AL31: 0 | AM31: 0 | AN31: 0
B32: LULUCF Anthropogenic Pollutant Emissions[CO] : MostRecentRun | C32: 0 | D32: 0 | E32: 0 | F32: 0 | G32: 0 | H32: 0 | I32: 0 | J32: 0 | K32: 0 | L32: 0 | M32: 0 | N32: 0 | O32: 0 | P32: 0 | Q32: 0 | R32: 0 | S32: 0 | T32: 0 | U32: 0 | V32: 0 | W32: 0 | X32: 0 | Y32: 0 | Z32: 0 | AA32: 0 | AB32: 0 | AC32: 0 | AD32: 0 | AE32: 0 | AF32: 0 | AG32: 0 | AH32: 0 | AI32: 0 | AJ32: 0 | AK32: 0 | AL32: 0 | AM32: 0 | AN32: 0
B33: LULUCF Anthropogenic Pollutant Emissions[NOx] : MostRecentRun | C33: 0 | D33: 0 | E33: 0 | F33: 0 | G33: 0 | H33: 0 | I33: 0 | J33: 0 | K33: 0 | L33: 0 | M33: 0 | N33: 0 | O33: 0 | P33: 0 | Q33: 0 | R33: 0 | S33: 0 | T33: 0 | U33: 0 | V33: 0 | W33: 0 | X33: 0 | Y33: 0 | Z33: 0 | AA33: 0 | AB33: 0 | AC33: 0 | AD33: 0 | AE33: 0 | AF33: 0 | AG33: 0 | AH33: 0 | AI33: 0 | AJ33: 0 | AK33: 0 | AL33: 0 | AM33: 0 | AN33: 0
B34: LULUCF Anthropogenic Pollutant Emissions[PM10] : MostRecentRun | C34: 0 | D34: 0 | E34: 0 | F34: 0 | G34: 0 | H34: 0 | I34: 0 | J34: 0 | K34: 0 | L34: 0 | M34: 0 | N34: 0 | O34: 0 | P34: 0 | Q34: 0 | R34: 0 | S34: 0 | T34: 0 | U34: 0 | V34: 0 | W34: 0 | X34: 0 | Y34: 0 | Z34: 0 | AA34: 0 | AB34: 0 | AC34: 0 | AD34: 0 | AE34: 0 | AF34: 0 | AG34: 0 | AH34: 0 | AI34: 0 | AJ34: 0 | AK34: 0 | AL34: 0 | AM34: 0 | AN34: 0
B35: LULUCF Anthropogenic Pollutant Emissions[PM25] : MostRecentRun | C35: 0 | D35: 0 | E35: 0 | F35: 0 | G35: 0 | H35: 0 | I35: 0 | J35: 0 | K35: 0 | L35: 0 | M35: 0 | N35: 0 | O35: 0 | P35: 0 | Q35: 0 | R35: 0 | S35: 0 | T35: 0 | U35: 0 | V35: 0 | W35: 0 | X35: 0 | Y35: 0 | Z35: 0 | AA35: 0 | AB35: 0 | AC35: 0 | AD35: 0 | AE35: 0 | AF35: 0 | AG35: 0 | AH35: 0 | AI35: 0 | AJ35: 0 | AK35: 0 | AL35: 0 | AM35: 0 | AN35: 0
B36: LULUCF Anthropogenic Pollutant Emissions[SOx] : MostRecentRun | C36: 0 | D36: 0 | E36: 0 | F36: 0 | G36: 0 | H36: 0 | I36: 0 | J36: 0 | K36: 0 | L36: 0 | M36: 0 | N36: 0 | O36: 0 | P36: 0 | Q36: 0 | R36: 0 | S36: 0 | T36: 0 | U36: 0 | V36: 0 | W36: 0 | X36: 0 | Y36: 0 | Z36: 0 | AA36: 0 | AB36: 0 | AC36: 0 | AD36: 0 | AE36: 0 | AF36: 0 | AG36: 0 | AH36: 0 | AI36: 0 | AJ36: 0 | AK36: 0 | AL36: 0 | AM36: 0 | AN36: 0
B37: LULUCF Anthropogenic Pollutant Emissions[BC] : MostRecentRun | C37: 0 | D37: 0 | E37: 0 | F37: 0 | G37: 0 | H37: 0 | I37: 0 | J37: 0 | K37: 0 | L37: 0 | M37: 0 | N37: 0 | O37: 0 | P37: 0 | Q37: 0 | R37: 0 | S37: 0 | T37: 0 | U37: 0 | V37: 0 | W37: 0 | X37: 0 | Y37: 0 | Z37: 0 | AA37: 0 | AB37: 0 | AC37: 0 | AD37: 0 | AE37: 0 | AF37: 0 | AG37: 0 | AH37: 0 | AI37: 0 | AJ37: 0 | AK37: 0 | AL37: 0 | AM37: 0 | AN37: 0
B38: LULUCF Anthropogenic Pollutant Emissions[OC] : MostRecentRun | C38: 0 | D38: 0 | E38: 0 | F38: 0 | G38: 0 | H38: 0 | I38: 0 | J38: 0 | K38: 0 | L38: 0 | M38: 0 | N38: 0 | O38: 0 | P38: 0 | Q38: 0 | R38: 0 | S38: 0 | T38: 0 | U38: 0 | V38: 0 | W38: 0 | X38: 0 | Y38: 0 | Z38: 0 | AA38: 0 | AB38: 0 | AC38: 0 | AD38: 0 | AE38: 0 | AF38: 0 | AG38: 0 | AH38: 0 | AI38: 0 | AJ38: 0 | AK38: 0 | AL38: 0 | AM38: 0 | AN38: 0
B39: LULUCF Anthropogenic Pollutant Emissions[CH4] : MostRecentRun | C39: 812346000000 | D39: 812899000000 | E39: 813670000000 | F39: 814657000000 | G39: 815860000000 | H39: 817281000000 | I39: 818918000000 | J39: 820771000000 | K39: 822842000000 | L39: 825129000000 | M39: 827632000000 | N39: 830353000000 | O39: 833290000000 | P39: 836443000000 | Q39: 839813000000 | R39: 843400000000 | S39: 847204000000 | T39: 851224000000 | U39: 855461000000 | V39: 859915000000 | W39: 864585000000 | X39: 869472000000 | Y39: 874575000000 | Z39: 879895000000 | AA39: 885432000000 | AB39: 891185000000 | AC39: 897156000000 | AD39: 903342000000 | AE39: 909746000000 | AF39: 916366000000 | AG39: 923203000000 | AH39: 930256000000 | AI39: 937526000000 | AJ39: 945013000000 | AK39: 952716000000 | AL39: 960636000000 | AM39: 968773000000 | AN39: 977126000000
B40: LULUCF Anthropogenic Pollutant Emissions[N2O] : MostRecentRun | C40: 47124900000 | D40: 47157000000 | E40: 47201700000 | F40: 47258900000 | G40: 47328700000 | H40: 47411000000 | I40: 47506000000 | J40: 47613400000 | K40: 47733500000 | L40: 47866100000 | M40: 48011300000 | N40: 48169000000 | O40: 48339300000 | P40: 48522100000 | Q40: 48717500000 | R40: 48925500000 | S40: 49146000000 | T40: 49379100000 | U40: 49624800000 | V40: 49883000000 | W40: 50153800000 | X40: 50437200000 | Y40: 50733100000 | Z40: 51041600000 | AA40: 51362600000 | AB40: 51696200000 | AC40: 52042300000 | AD40: 52401100000 | AE40: 52772300000 | AF40: 53156200000 | AG40: 53552600000 | AH40: 53961600000 | AI40: 54383100000 | AJ40: 54817200000 | AK40: 55263900000 | AL40: 55723100000 | AM40: 56194900000 | AN40: 56679200000
...
