Workbook

Sheet 分行业工业增加值（当年人民币）
A1: 全国（单位：亿元） | B1: 2019 | C1: 2020 | D1: 2021 | E1: 2022 | F1: 2023 | G1: 2024 | H1: 2025 | I1: 2026 | J1: 2027 | K1: 2028 | L1: 2029 | M1: 2030 | N1: 2031 | O1: 2032 | P1: 2033 | Q1: 2034 | R1: 2035 | S1: 2036 | T1: 2037 | U1: 2038 | V1: 2039 | W1: 2040 | X1: 2041 | Y1: 2042 | Z1: 2043 | AA1: 2044 | AB1: 2045 | AC1: 2046 | AD1: 2047 | AE1: 2048 | AF1: 2049 | AG1: 2050 | AH1: 2051 | AI1: 2052 | AJ1: 2053 | AK1: 2054 | AL1: 2055 | AM1: 2056 | AN1: 2057 | AO1: 2058 | AP1: 2059 | AQ1: 2060
A2: 地区生产总值 | B2: 982320.5 | C2: 1081134.6 | D2: 1169287.4 | E2: 1260898.9 | F2: 1356078.3 | G2: 1454268.8 | H2: 1556518.1 | I2: 1662039.5 | J2: 1770957.4 | K2: 1883818.3 | L2: 1999892.7 | M2: 2119738.5 | N2: 2243328.1 | O2: 2370251.9 | P2: 2501196.1 | Q2: 2635776.3 | R2: 2773804.6 | S2: 2916069.9 | T2: 3061915.7 | U2: 3212067.3 | V2: 3366153.4 | W2: 3523990.4 | X2: 3686274.5 | Y2: 3852797.5 | Z2: 4023521.8 | AA2: 4198628.9 | AB2: 4378278.9 | AC2: 4562763.8 | AD2: 4751741.8 | AE2: 4945364.6 | AF2: 5144486.9 | AG2: 5348376.4 | AH2: 5557591.5 | AI2: 5772275.4 | AJ2: 5992276.8 | AK2: 6218329.8 | AL2: 6450282.8 | AM2: 6688426.5 | AN2: 6933021.1 | AO2: 7184130.3 | AP2: 7442387 | AQ2: 7707658.2
A3: 农业 | B3: 73576.8 | C3: 81084.1 | D3: 86775.6 | E3: 92057.213 | F3: 97462.356 | G3: 102971.12 | H3: 108656.26 | I3: 114453.55 | J3: 120377.03 | K3: 126447.17 | L3: 132633.1 | M3: 138978.5 | N3: 145445.46 | O3: 152023.06 | P3: 158754.86 | Q3: 165608.08 | R3: 172572.11 | S3: 179676.88 | T3: 186898.79 | U3: 194283.67 | V3: 201788.05 | W3: 209402.38 | X3: 217169.55 | Y3: 225069.79 | Z3: 233095.75 | AA3: 241256.56 | AB3: 249561.41 | AC3: 258030.95 | AD3: 266636.86 | AE3: 275387.1 | AF3: 284326.32 | AG3: 293411.36 | AH3: 302677.82 | AI3: 312134.26 | AJ3: 321767.93 | AK3: 331614.6 | AL3: 341683.33 | AM3: 351986.8 | AN3: 362544.12 | AO3: 373357.5 | AP3: 384469.58 | AQ3: 395882.24
A4: 工业 | B4: 312419.9 | C4: 312866.3 | D4: 368569.7 | E4: 386900.01 | F4: 405000.62 | G4: 422886.84 | H4: 440581.01 | I4: 458110.24 | J4: 475504.51 | K4: 492795.29 | L4: 510014.47 | M4: 527193.66 | N4: 544363.63 | O4: 561554.04 | P4: 578793.25 | Q4: 596108.19 | R4: 613524.43 | S4: 631066.12 | T4: 648756.12 | U4: 666616.07 | V4: 684666.49 | W4: 702926.85 | X4: 721415.72 | Y4: 740150.83 | Z4: 759149.18 | AA4: 778427.13 | AB4: 798000.48 | AC4: 817884.53 | AD4: 838094.2 | AE4: 858644.01 | AF4: 879548.22 | AG4: 900820.85 | AH4: 922475.72 | AI4: 944526.48 | AJ4: 966986.72 | AK4: 989869.93 | AL4: 1013189.5 | AM4: 1036959 | AN4: 1061191.9 | AO4: 1085901.5 | AP4: 1111101.6 | AQ4: 1136805.8
A5: 建筑业 | B5: 70613.1 | C5: 73028.6 | D5: 80072.9 | E5: 85981.803 | F5: 92122.496 | G5: 98460.911 | H5: 105064.29 | I5: 111878.73 | J5: 118923.45 | K5: 126218.57 | L5: 133727.07 | M5: 141493.56 | N5: 149498.98 | O5: 157721.37 | P5: 166210.55 | Q5: 174939.55 | R5: 183897 | S5: 193120.64 | T5: 202587.34 | U5: 212332.89 | V5: 222325.28 | W5: 232563.02 | X5: 243082.31 | Y5: 253869.8 | Z5: 264931.3 | AA5: 276262.05 | AB5: 287887.56 | AC5: 299820.58 | AD5: 312036.5 | AE5: 324556.54 | AF5: 337422.52 | AG5: 350605.13 | AH5: 364139.62 | AI5: 378035.26 | AJ5: 392299.68 | AK5: 406968.24 | AL5: 422060.78 | AM5: 437608.29 | AN5: 453619.73 | AO5: 470138.68 | AP5: 487209.01 | AQ5: 504847.58
A6: 交运仓邮 | B6: 42852.8 | C6: 41590.3 | D6: 46748.7 | E6: 49571.436 | F6: 52454.766 | G6: 55386.594 | H6: 58398.458 | I6: 61466.791 | J6: 64591.12 | K6: 67787.09 | L6: 71035.669 | M6: 74350.123 | N6: 77727.933 | O6: 81156.438 | P6: 84653.559 | Q6: 88210.978 | R6: 91821.997 | S6: 95503.389 | T6: 99237.858 | U6: 103046.98 | V6: 106917.9 | W6: 110838.45 | X6: 114833.98 | Y6: 118898.6 | Z6: 123024.93 | AA6: 127219.16 | AB6: 131485.68 | AC6: 135827.57 | AD6: 140235.03 | AE6: 144714.49 | AF6: 149285.74 | AG6: 153927.21 | AH6: 158652.32 | AI6: 163467.79 | AJ6: 168364.26 | AK6: 173360.27 | AL6: 178454.44 | AM6: 183651.31 | AN6: 188958.1 | AO6: 194375.81 | AP6: 199922.33 | AQ6: 205591.2
A7: 批发零售 | B7: 95138.9 | C7: 95047.9 | D7: 110280 | E7: 118836.75 | F7: 127731.67 | G7: 136908.53 | H7: 146453.7 | I7: 156310.35 | J7: 166476.45 | K7: 177019.98 | L7: 187862.74 | M7: 199051.1 | N7: 210601.09 | O7: 222456.6 | P7: 234690.47 | Q7: 247269.51 | R7: 260165.62 | S7: 273466.74 | T7: 287105.83 | U7: 301143.11 | V7: 315558.84 | W7: 330325.8 | X7: 345508.6 | Y7: 361092.79 | Z7: 377069.21 | AA7: 393464.04 | AB7: 410285.37 | AC7: 427554.81 | AD7: 445251.24 | AE7: 463384.22 | AF7: 482040.34 | AG7: 501142.65 | AH7: 520751.71 | AI7: 540879.36 | AJ7: 561504.19 | AK7: 582712.9 | AL7: 604479.33 | AM7: 626833.87 | AN7: 649817.19 | AO7: 673421.17 | AP7: 697722.94 | AQ7: 722710.81
A8: 餐饮住宿 | B8: 17953.1 | C8: 15896.1 | D8: 17821.2 | E8: 19511.611 | F8: 21300.469 | G8: 23179.927 | H8: 25170.41 | I8: 27260.402 | J8: 29453.554 | K8: 31761.269 | L8: 34174.173 | M8: 36704.021 | N8: 39349.66 | O8: 42105.169 | P8: 44988.925 | Q8: 47994.641 | R8: 51116.123 | S8: 54373.326 | T8: 57757.202 | U8: 61283.098 | V8: 64942.415 | W8: 68735.023 | X8: 72677.751 | Y8: 76767.68 | Z8: 81005.033 | AA8: 85394.829 | AB8: 89944.542 | AC8: 94663.433 | AD8: 99548.313 | AE8: 104601.06 | AF8: 109849.2 | AG8: 115278.15 | AH8: 120906.48 | AI8: 126742.18 | AJ8: 132785.05 | AK8: 139060.12 | AL8: 145574.62 | AM8: 152340.74 | AN8: 159377.16 | AO8: 166692.11 | AP8: 174316.16 | AQ8: 182264.6
A9: 金融业 | B9: 76691.7 | C9: 84280.5 | D9: 91083.2 | E9: 100929.79 | F9: 111451.29 | G9: 122579.85 | H9: 134446.5 | I9: 146997.06 | J9: 160247.83 | K9: 174310.04 | L9: 189087.18 | M9: 204663.44 | N9: 221088.85 | O9: 238311.63 | P9: 256440.67 | Q9: 275470.02 | R9: 295373.01 | S9: 316316.13 | T9: 338205.51 | U9: 361167.02 | V9: 385200.11 | W9: 410290.38 | X9: 436566.85 | Y9: 464044.28 | Z9: 492725.08 | AA9: 522704.72 | AB9: 554002.9 | AC9: 586717.77 | AD9: 620827.6 | AE9: 656369.21 | AF9: 693549.69 | AG9: 732243.32 | AH9: 772583.62 | AI9: 814632.25 | AJ9: 858370.98 | AK9: 903986.11 | AL9: 951430.46 | AM9: 1000779.7 | AN9: 1052115.3 | AO9: 1105431.5 | AP9: 1160899.4 | AQ9: 1218426.3
A10: 房地产 | B10: 69436.5 | C10: 74547.7 | D10: 77516.4 | E10: 83624.512 | F10: 90001.797 | G10: 96616.651 | H10: 103540.35 | I10: 110732.13 | J10: 118196.6 | K10: 125967.34 | L10: 134005.24 | M10: 142345.59 | N10: 150994.13 | O10: 159922.27 | P10: 169174.6 | Q10: 178733.27 | R10: 188590.5 | S10: 198791.5 | T10: 209299.18 | U10: 220160.59 | V10: 231362.36 | W10: 242884.91 | X10: 254778.26 | Y10: 267033.78 | Z10: 279649.42 | AA10: 292639.15 | AB10: 306019 | AC10: 319808.89 | AD10: 333986.06 | AE10: 348577.22 | AF10: 363635.92 | AG10: 379117.46 | AH10: 395066.39 | AI10: 411504.49 | AJ10: 428426.88 | AK10: 445890.44 | AL10: 463899.81 | AM10: 482485.1 | AN10: 501684 | AO10: 521511.95 | AP10: 542027.33 | AQ10: 563251.86
A11: 其他三产 | B11: 223637.7 | C11: 302793.12 | D11: 290419.66 | E11: 323485.78 | F11: 358552.82 | G11: 395278.33 | H11: 434207.15 | I11: 474830.29 | J11: 517186.85 | K11: 561511.53 | L11: 607353.1 | M11: 654958.55 | N11: 704258.4 | O11: 755001.29 | P11: 807489.23 | Q11: 861442.08 | R11: 916743.85 | S11: 973755.21 | T11: 1032067.9 | U11: 1092033.9 | V11: 1153392 | W11: 1216023.6 | X11: 1280241.5 | Y11: 1345870 | Z11: 1412871.9 | AA11: 1481261.2 | AB11: 1551091.9 | AC11: 1622455.3 | AD11: 1695126 | AE11: 1769130.8 | AF11: 1844829 | AG11: 1921830.3 | AH11: 2000337.9 | AI11: 2080353.3 | AJ11: 2161771.1 | AK11: 2244867.2 | AL11: 2329510.5 | AM11: 2415781.6 | AN11: 2503713.6 | AO11: 2593300.1 | AP11: 2684718.6 | AQ11: 2777877.7
A13: 工业 | B13: 312419.9 | C13: 312866.3 | D13: 368569.7 | E13: 386900.01 | F13: 405000.62 | G13: 422886.84 | H13: 440581.01 | I13: 458110.24 | J13: 475504.51 | K13: 492795.29 | L13: 510014.47 | M13: 527193.66 | N13: 544363.63 | O13: 561554.04 | P13: 578793.25 | Q13: 596108.19 | R13: 613524.43 | S13: 631066.12 | T13: 648756.12 | U13: 666616.07 | V13: 684666.49 | W13: 702926.85 | X13: 721415.72 | Y13: 740150.83 | Z13: 759149.18 | AA13: 778427.13 | AB13: 798000.48 | AC13: 817884.53 | AD13: 838094.2 | AE13: 858644.01 | AF13: 879548.22 | AG13: 900820.85 | AH13: 922475.72 | AI13: 944526.48 | AJ13: 966986.72 | AK13: 989869.93 | AL13: 1013189.5 | AM13: 1036959 | AN13: 1061191.9 | AO13: 1085901.5 | AP13: 1111101.6 | AQ13: 1136805.8
... A54: 公共管理、社会保障和社会组织 | B54: 36437.514 | C54: 47083.393 | D54: 42219.521 | E54: 47061.047 | F54: 52204.852 | G54: 57619.809 | H54: 63377.017 | I54: 69405.888 | J54: 75717.926 | K54: 82332.301 | L54: 89197.261 | M54: 96341.219 | N54: 103757.67 | O54: 111411.59 | P54: 119335.05 | Q54: 127495.17 | R54: 135880.87 | S54: 144525.05 | T54: 153377.92 | U54: 162492.19 | V54: 171830.33 | W54: 181366.46 | X54: 191147.68 | Y54: 201155.59 | Z54: 211375.57 | AA54: 221807.69 | AB54: 232472.87 | AC54: 243374.16 | AD54: 254483.62 | AE54: 265805.52 | AF54: 277394 | AG54: 289193.58 | AH54: 301227.88 | AI54: 313522.63 | AJ54: 326052.92 | AK54: 338853.95 | AL54: 351931.78 | AM54: 365296.96 | AN54: 378965.84 | AO54: 392949.56 | AP54: 407272.04 | AQ54: 421942.91

Sheet About
A1: BPCiObIC BAU Percent Change in Output by ISIC Code
A3: Source:
B5: 2020年全国投入产出表
B6: 国家统计局
B7: 2020
B8: https://data.stats.gov.cn/files/html/quickSearch/trcc/trcc01.html
A10: Notes
A11: “2020年全国投入产出表”是根据我国2020年全年投入产出表中竞争型和非竞争型两张表结合美国EPS模型总结出来42个部门的投入产出表。政府消费支出是根据“2020年全国投入产出表”中各行业政府消费支出数额乘以当年2020年人民币相对2012美元的汇率得出。
A12: 默认分行业产出年变化率即为分行业工业增加值年变化率。先将分行业工业增加值拆分合并至EPS中42行业，再计算其年变化率即可。

Sheet 分行业工业增加值（2012年美元）
A1: 全国 | B1: 2019 | C1: 2020 | D1: 2021 | E1: 2022 | F1: 2023 | G1: 2024 | H1: 2025 | I1: 2026 | J1: 2027 | K1: 2028 | L1: 2029 | M1: 2030 | N1: 2031 | O1: 2032 | P1: 2033 | Q1: 2034 | R1: 2035 | S1: 2036 | T1: 2037 | U1: 2038 | V1: 2039 | W1: 2040 | X1: 2041 | Y1: 2042 | Z1: 2043 | AA1: 2044 | AB1: 2045 | AC1: 2046 | AD1: 2047 | AE1: 2048 | AF1: 2049 | AG1: 2050 | AH1: 2051 | AI1: 2052 | AJ1: 2053 | AK1: 2054 | AL1: 2055 | AM1: 2056 | AN1: 2057 | AO1: 2058 | AP1: 2059 | AQ1: 2060 | AR1: 100000000
A2: 地区生产总值 | B2: =('分行业工业增加值（当年人民币）'!B2*汇率!$B$2)*100000000 -> 1.3606245e+13 | C2: =('分行业工业增加值（当年人民币）'!C2*汇率!$C$2)*100000000 -> 1.4881891e+13 | D2: =('分行业工业增加值（当年人民币）'!D2*汇率!$D$2)*100000000 -> 1.5748845e+13 | E2: =('分行业工业增加值（当年人民币）'!E2*汇率!$E$2)*100000000 -> 16617161179164 | F2: =('分行业工业增加值（当年人民币）'!F2*汇率!$F$2)*100000000 -> 17486803562025 | G2: =('分行业工业增加值（当年人民币）'!G2*汇率!$G$2)*100000000 -> 1.8349298e+13 | H2: =('分行业工业增加值（当年人民币）'!H2*汇率!$H$2)*100000000 -> 1.9216667e+13 | I2: =('分行业工业增加值（当年人民币）'!I2*汇率!$I$2)*100000000 -> 2.0077717e+13 | J2: =('分行业工业增加值（当年人民币）'!J2*汇率!$J$2)*100000000 -> 2.0932939e+13 | K2: =('分行业工业增加值（当年人民币）'!K2*汇率!$K$2)*100000000 -> 2.178764e+13 | L2: =('分行业工业增加值（当年人民币）'!L2*汇率!$L$2)*100000000 -> 2.2632212e+13 | M2: =('分行业工业增加值（当年人民币）'!M2*汇率!$M$2)*100000000 -> 2.3472086e+13 | N2: =('分行业工业增加值（当年人民币）'!N2*汇率!$N$2)*100000000 -> 2.4305877e+13 | O2: =('分行业工业增加值（当年人民币）'!O2*汇率!$O$2)*100000000 -> 2.5128242e+13 | P2: =('分行业工业增加值（当年人民币）'!P2*汇率!$P$2)*100000000 -> 2.5945644e+13 | Q2: =('分行业工业增加值（当年人民币）'!Q2*汇率!$Q$2)*100000000 -> 2.6753116e+13 | R2: =('分行业工业增加值（当年人民币）'!R2*汇率!$R$2)*100000000 -> 2.7548045e+13 | S2: =('分行业工业增加值（当年人民币）'!S2*汇率!$S$2)*100000000 -> 2.8337528e+13 | T2: =('分行业工业增加值（当年人民币）'!T2*汇率!$T$2)*100000000 -> 2.9114301e+13 | U2: =('分行业工业增加值（当年人民币）'!U2*汇率!$U$2)*100000000 -> 29884560304797 | V2: =('分行业工业增加值（当年人民币）'!V2*汇率!$V$2)*100000000 -> 3.0643985e+13 | W2: =('分行业工业增加值（当年人民币）'!W2*汇率!$W$2)*100000000 -> 3.1390277e+13 | X2: =('分行业工业增加值（当年人民币）'!X2*汇率!$X$2)*100000000 -> 3.2129e+13 | Y2: =('分行业工业增加值（当年人民币）'!Y2*汇率!$Y$2)*100000000 -> 3.2857524e+13 | Z2: =('分行业工业增加值（当年人民币）'!Z2*汇率!$Z$2)*100000000 -> 3.3574853e+13 | AA2: =('分行业工业增加值（当年人民币）'!AA2*汇率!$AA$2)*100000000 -> 3.4281857e+13 | AB2: =('分行业工业增加值（当年人民币）'!AB2*汇率!$AB$2)*100000000 -> 3.497916e+13 | AC2: =('分行业工业增加值（当年人民币）'!AC2*汇率!$AC$2)*100000000 -> 3.5668353e+13 | AD2: =('分行业工业增加值（当年人民币）'!AD2*汇率!$AD$2)*100000000 -> 3.6346032e+13 | AE2: =('分行业工业增加值（当年人民币）'!AE2*汇率!$AE$2)*100000000 -> 3.701277e+13 | AF2: =('分行业工业增加值（当年人民币）'!AF2*汇率!$AF$2)*100000000 -> 37674235192435 | AG2: =('分行业工业增加值（当年人民币）'!AG2*汇率!$AG$2)*100000000 -> 3.8324231e+13 | AH2: =('分行业工业增加值（当年人民币）'!AH2*汇率!$AH$2)*100000000 -> 3.8966124e+13 | AI2: =('分行业工业增加值（当年人民币）'!AI2*汇率!$AI$2)*100000000 -> 3.9600141e+13 | AJ2: =('分行业工业增加值（当年人民币）'!AJ2*汇率!$AJ$2)*100000000 -> 4.02245e+13 | AK2: =('分行业工业增加值（当年人民币）'!AK2*汇率!$AK$2)*100000000 -> 4.0843378e+13 | AL2: =('分行业工业增加值（当年人民币）'!AL2*汇率!$AL$2)*100000000 -> 4.1454889e+13 | AM2: =('分行业工业增加值（当年人民币）'!AM2*汇率!$AM$2)*100000000 -> 4.2060077e+13 | AN2: =('分行业工业增加值（当年人民币）'!AN2*汇率!$AN$2)*100000000 -> 4.2659694e+13 | AO2: =('分行业工业增加值（当年人民币）'!AO2*汇率!$AO$2)*100000000 -> 4.3253227e+13 | AP2: =('分行业工业增加值（当年人民币）'!AP2*汇率!$AP$2)*100000000 -> 4.3843545e+13 | AQ2: =('分行业工业增加值（当年人民币）'!AQ2*汇率!$AQ$2)*100000000 -> 4.4428839e+13
A3: 农业 | B3: =('分行业工业增加值（当年人民币）'!B3*汇率!$B$2)*100000000 -> 1.0191215e+12 | C3: =('分行业工业增加值（当年人民币）'!C3*汇率!$C$2)*100000000 -> 1.1161281e+12 | D3: =('分行业工业增加值（当年人民币）'!D3*汇率!$D$2)*100000000 -> 1.1687593e+12 | E3: =('分行业工业增加值（当年人民币）'!E3*汇率!$E$2)*100000000 -> 1.2132055e+12 | F3: =('分行业工业增加值（当年人民币）'!F3*汇率!$F$2)*100000000 -> 1.2567896e+12 | G3: =('分行业工业增加值（当年人民币）'!G3*汇率!$G$2)*100000000 -> 1.2992424e+12 | H3: =('分行业工业增加值（当年人民币）'!H3*汇率!$H$2)*100000000 -> 1.3414628e+12 | I3: =('分行业工业增加值（当年人民币）'!I3*汇率!$I$2)*100000000 -> 1.3826182e+12 | J3: =('分行业工业增加值（当年人民币）'!J3*汇率!$J$2)*100000000 -> 1.4228716e+12 | K3: =('分行业工业增加值（当年人民币）'!K3*汇率!$K$2)*100000000 -> 1.4624476e+12 | L3: =('分行业工业增加值（当年人民币）'!L3*汇率!$L$2)*100000000 -> 1.5009707e+12 | M3: =('分行业工业增加值（当年人民币）'!M3*汇率!$M$2)*100000000 -> 1.5389234e+12 | N3: =('分行业工业增加值（当年人民币）'!N3*汇率!$N$2)*100000000 -> 1.5758637e+12 | O3: =('分行业工业增加值（当年人民币）'!O3*汇率!$O$2)*100000000 -> 1.6116736e+12 | P3: =('分行业工业增加值（当年人民币）'!P3*汇率!$P$2)*100000000 -> 1.6468109e+12 | Q3: =('分行业工业增加值（当年人民币）'!Q3*汇率!$Q$2)*100000000 -> 1.6809211e+12 | R3: =('分行业工业增加值（当年人民币）'!R3*汇率!$R$2)*100000000 -> 1.7139002e+12 | S3: =('分行业工业增加值（当年人民币）'!S3*汇率!$S$2)*100000000 -> 1.7460482e+12 | T3: =('分行业工业增加值（当年人民币）'!T3*汇率!$T$2)*100000000 -> 1.7771317e+12 | U3: =('分行业工业增加值（当年人民币）'!U3*汇率!$U$2)*100000000 -> 1.8075842e+12 | V3: =('分行业工业增加值（当年人民币）'!V3*汇率!$V$2)*100000000 -> 1.8369899e+12 | W3: =('分行业工业增加值（当年人民币）'!W3*汇率!$W$2)*100000000 -> 1.8652715e+12 | X3: =('分行业工业增加值（当年人民币）'!X3*汇率!$X$2)*100000000 -> 1.8928163e+12 | Y3: =('分行业工业增加值（当年人民币）'!Y3*汇率!$Y$2)*100000000 -> 1.9194458e+12 | Z3: =('分行业工业增加值（当年人民币）'!Z3*汇率!$Z$2)*100000000 -> 1.9451008e+12 | AA3: =('分行业工业增加值（当年人民币）'!AA3*汇率!$AA$2)*100000000 -> 1.9698629e+12 | AB3: =('分行业工业增加值（当年人民币）'!AB3*汇率!$AB$2)*100000000 -> 1.9938083e+12 | AC3: =('分行业工业增加值（当年人民币）'!AC3*汇率!$AC$2)*100000000 -> 2.0170974e+12 | AD3: =('分行业工业增加值（当年人民币）'!AD3*汇率!$AD$2)*100000000 -> 2.039503e+12 | AE3: =('分行业工业增加值（当年人民币）'!AE3*汇率!$AE$2)*100000000 -> 2.0610896e+12 | AF3: =('分行业工业增加值（当年人民币）'!AF3*汇率!$AF$2)*100000000 -> 2.0821856e+12 | AG3: =('分行业工业增加值（当年人民币）'!AG3*汇率!$AG$2)*100000000 -> 2.1024632e+12 | AH3: =('分行业工业增加值（当年人民币）'!AH3*汇率!$AH$2)*100000000 -> 2.1221749e+12 | AI3: =('分行业工业增加值（当年人民币）'!AI3*汇率!$AI$2)*100000000 -> 2.1413671e+12 | AJ3: =('分行业工业增加值（当年人民币）'!AJ3*汇率!$AJ$2)*100000000 -> 2.1599393e+12 | AK3: =('分行业工业增加值（当年人民币）'!AK3*汇率!$AK$2)*100000000 -> 2.1781187e+12 | AL3: =('分行业工业增加值（当年人民币）'!AL3*汇率!$AL$2)*100000000 -> 2.1959416e+12 | AM3: =('分行业工业增加值（当年人民币）'!AM3*汇率!$AM$2)*100000000 -> 2.2134641e+12 | AN3: =('分行业工业增加值（当年人民币）'!AN3*汇率!$AN$2)*100000000 -> 2.2307766e+12 | AO3: =('分行业工业增加值（当年人民币）'!AO3*汇率!$AO$2)*100000000 -> 2.2478597e+12 | AP3: =('分行业工业增加值（当年人民币）'!AP3*汇率!$AP$2)*100000000 -> 2.2649332e+12 | AQ3: =('分行业工业增加值（当年人民币）'!AQ3*汇率!$AQ$2)*100000000 -> 2.2819627e+12
A4: 工业 | B4: =('分行业工业增加值（当年人民币）'!B4*汇率!$B$2)*100000000 -> 4.3273675e+12 | C4: =('分行业工业增加值（当年人民币）'!C4*汇率!$C$2)*100000000 -> 4.3066258e+12 | D4: =('分行业工业增加值（当年人民币）'!D4*汇率!$D$2)*100000000 -> 4.9641751e+12 | E4: =('分行业工业增加值（当年人民币）'!E4*汇率!$E$2)*100000000 -> 5.098886e+12 | F4: =('分行业工业增加值（当年人民币）'!F4*汇率!$F$2)*100000000 -> 5.222535e+12 | G4: =('分行业工业增加值（当年人民币）'!G4*汇率!$G$2)*100000000 -> 5.3357926e+12 | H4: =('分行业工业增加值（当年人民币）'!H4*汇率!$H$2)*100000000 -> 5.4393831e+12 | I4: =('分行业工业增加值（当年人民币）'!I4*汇率!$I$2)*100000000 -> 5.5340487e+12 | J4: =('分行业工业增加值（当年人民币）'!J4*汇率!$J$2)*100000000 -> 5.6205229e+12 | K4: =('分行业工业增加值（当年人民币）'!K4*汇率!$K$2)*100000000 -> 5.6995128e+12 | L4: =('分行业工业增加值（当年人民币）'!L4*汇率!$L$2)*100000000 -> 5.7716873e+12 | M4: =('分行业工业增加值（当年人民币）'!M4*汇率!$M$2)*100000000 -> 5.8376704e+12 | N4: =('分行业工业增加值（当年人民币）'!N4*汇率!$N$2)*100000000 -> 5.8980385e+12 | O4: =('分行业工业增加值（当年人民币）'!O4*汇率!$O$2)*100000000 -> 5.9533191e+12 | P4: =('分行业工业增加值（当年人民币）'!P4*汇率!$P$2)*100000000 -> 6.0039928e+12 | Q4: =('分行业工业增加值（当年人民币）'!Q4*汇率!$Q$2)*100000000 -> 6.050495e+12 | R4: =('分行业工业增加值（当年人民币）'!R4*汇率!$R$2)*100000000 -> 6.0932188e+12 | S4: =('分行业工业增加值（当年人民币）'!S4*汇率!$S$2)*100000000 -> 6.1325187e+12 | T4: =('分行业工业增加值（当年人民币）'!T4*汇率!$T$2)*100000000 -> 6.1687134e+12 | U4: =('分行业工业增加值（当年人民币）'!U4*汇率!$U$2)*100000000 -> 6.2020893e+12 | V4: =('分行业工业增加值（当年人民币）'!V4*汇率!$V$2)*100000000 -> 6.2329036e+12 | W4: =('分行业工业增加值（当年人民币）'!W4*汇率!$W$2)*100000000 -> 6.2613874e+12 | X4: =('分行业工业增加值（当年人民币）'!X4*汇率!$X$2)*100000000 -> 6.2877482e+12 | Y4: =('分行业工业增加值（当年人民币）'!Y4*汇率!$Y$2)*100000000 -> 6.3121728e+12 | Z4: =('分行业工业增加值（当年人民币）'!Z4*汇率!$Z$2)*100000000 -> 6.3348287e+12 | AA4: =('分行业工业增加值（当年人民币）'!AA4*汇率!$AA$2)*100000000 -> 6.3558673e+12 | AB4: =('分行业工业增加值（当年人民币）'!AB4*汇率!$AB$2)*100000000 -> 6.3754245e+12 | AC4: =('分行业工业增加值（当年人民币）'!AC4*汇率!$AC$2)*100000000 -> 6.3936235e+12 | AD4: =('分行业工业增加值（当年人民币）'!AD4*汇率!$AD$2)*100000000 -> 6.4105752e+12 | AE4: =('分行业工业增加值（当年人民币）'!AE4*汇率!$AE$2)*100000000 -> 6.4263802e+12 | AF4: =('分行业工业增加值（当年人民币）'!AF4*汇率!$AF$2)*100000000 -> 6.4411295e+12 | AG4: =('分行业工业增加值（当年人民币）'!AG4*汇率!$AG$2)*100000000 -> 6.4549058e+12 | AH4: =('分行业工业增加值（当年人民币）'!AH4*汇率!$AH$2)*100000000 -> 6.4677843e+12 | AI4: =('分行业工业增加值（当年人民币）'!AI4*汇率!$AI$2)*100000000 -> 6.4798332e+12 | AJ4: =('分行业工业增加值（当年人民币）'!AJ4*汇率!$AJ$2)*100000000 -> 6.491115e+12 | AK4: =('分行业工业增加值（当年人民币）'!AK4*汇率!$AK$2)*100000000 -> 6.5016865e+12 | AL4: =('分行业工业增加值（当年人民币）'!AL4*汇率!$AL$2)*100000000 -> 6.5115998e+12 | AM4: =('分行业工业增加值（当年人民币）'!AM4*汇率!$AM$2)*100000000 -> 6.5209025e+12 | AN4: =('分行业工业增加值（当年人民币）'!AN4*汇率!$AN$2)*100000000 -> 6.5296382e+12 | AO4: =('分行业工业增加值（当年人民币）'!AO4*汇率!$AO$2)*100000000 -> 6.537847e+12 | AP4: =('分行业工业增加值（当年人民币）'!AP4*汇率!$AP$2)*100000000 -> 6.5455659e+12 | AQ4: =('分行业工业增加值（当年人民币）'!AQ4*汇率!$AQ$2)*100000000 -> 6.5528286e+12
A5: 建筑业 | B5: =('分行业工业增加值（当年人民币）'!B5*汇率!$B$2)*100000000 -> 9.7807096e+11 | C5: =('分行业工业增加值（当年人民币）'!C5*汇率!$C$2)*100000000 -> 1.0052436e+12 | D5: =('分行业工业增加值（当年人民币）'!D5*汇率!$D$2)*100000000 -> 1.0784823e+12 | E5: =('分行业工业增加值（当年人民币）'!E5*汇率!$E$2)*100000000 -> 1.1331388e+12 | F5: =('分行业工业增加值（当年人民币）'!F5*汇率!$F$2)*100000000 -> 1.1879314e+12 | G5: =('分行业工业增加值（当年人民币）'!G5*汇率!$G$2)*100000000 -> 1.2423347e+12 | H5: =('分行业工业增加值（当年人民币）'!H5*汇率!$H$2)*100000000 -> 1.2971166e+12 | I5: =('分行业工业增加值（当年人民币）'!I5*汇率!$I$2)*100000000 -> 1.3515139e+12 | J5: =('分行业工业增加值（当年人民币）'!J5*汇率!$J$2)*100000000 -> 1.4056901e+12 | K5: =('分行业工业增加值（当年人民币）'!K5*汇率!$K$2)*100000000 -> 1.4598036e+12 | L5: =('分行业工业增加值（当年人民币）'!L5*汇率!$L$2)*100000000 -> 1.5133508e+12 | M5: =('分行业工业增加值（当年人民币）'!M5*汇率!$M$2)*100000000 -> 1.566773e+12 | N5: =('分行业工业增加值（当年人民币）'!N5*汇率!$N$2)*100000000 -> 1.6197826e+12 | O5: =('分行业工业增加值（当年人民币）'!O5*汇率!$O$2)*100000000 -> 1.6720842e+12 | P5: =('分行业工业增加值（当年人民币）'!P5*汇率!$P$2)*100000000 -> 1.724151e+12 | Q5: =('分行业工业增加值（当年人民币）'!Q5*汇率!$Q$2)*100000000 -> 1.7756355e+12 | R5: =('分行业工业增加值（当年人民币）'!R5*汇率!$R$2)*100000000 -> 1.8263734e+12 | S5: =('分行业工业增加值（当年人民币）'!S5*汇率!$S$2)*100000000 -> 1.8766908e+12 | T5: =('分行业工业增加值（当年人民币）'!T5*汇率!$T$2)*100000000 -> 1.9263066e+12 | U5: =('分行业工业增加值（当年人民币）'!U5*汇率!$U$2)*100000000 -> 1.9755112e+12 | V5: =('分行业工业增加值（当年人民币）'!V5*汇率!$V$2)*100000000 -> 2.0239519e+12 | W5: =('分行业工业增加值（当年人民币）'!W5*汇率!$W$2)*100000000 -> 2.0715771e+12 | X5: =('分行业工业增加值（当年人民币）'!X5*汇率!$X$2)*100000000 -> 2.1186679e+12 | Y5: =('分行业工业增加值（当年人民币）'!Y5*汇率!$Y$2)*100000000 -> 2.1650587e+12 | Z5: =('分行业工业增加值（当年人民币）'!Z5*汇率!$Z$2)*100000000 -> 2.2107571e+12 | AA5: =('分行业工业增加值（当年人民币）'!AA5*汇率!$AA$2)*100000000 -> 2.2556831e+12 | AB5: =('分行业工业增加值（当年人民币）'!AB5*汇率!$AB$2)*100000000 -> 2.3000054e+12 | AC5: =('分行业工业增加值（当年人民币）'!AC5*汇率!$AC$2)*100000000 -> 2.3437782e+12 | AD5: =('分行业工业增加值（当年人民币）'!AD5*汇率!$AD$2)*100000000 -> 2.3867645e+12 | AE5: =('分行业工业增加值（当年人民币）'!AE5*汇率!$AE$2)*100000000 -> 2.4290902e+12 | AF5: =('分行业工业增加值（当年人民币）'!AF5*汇率!$AF$2)*100000000 -> 2.4710211e+12 | AG5: =('分行业工业增加值（当年人民币）'!AG5*汇率!$AG$2)*100000000 -> 2.5122898e+12 | AH5: =('分行业工业增加值（当年人民币）'!AH5*汇率!$AH$2)*100000000 -> 2.5531041e+12 | AI5: =('分行业工业增加值（当年人民币）'!AI5*汇率!$AI$2)*100000000 -> 2.5934746e+12 | AJ5: =('分行业工业增加值（当年人民币）'!AJ5*汇率!$AJ$2)*100000000 -> 2.6333995e+12 | AK5: =('分行业工业增加值（当年人民币）'!AK5*汇率!$AK$2)*100000000 -> 2.6730582e+12 | AL5: =('分行业工业增加值（当年人民币）'!AL5*汇率!$AL$2)*100000000 -> 2.7125141e+12 | AM5: =('分行业工业增加值（当年人民币）'!AM5*汇率!$AM$2)*100000000 -> 2.7518936e+12 | AN5: =('分行业工业增加值（当年人民币）'!AN5*汇率!$AN$2)*100000000 -> 2.7911755e+12 | AO5: =('分行业工业增加值（当年人民币）'!AO5*汇率!$AO$2)*100000000 -> 2.8305465e+12 | AP5: =('分行业工业增加值（当年人民币）'!AP5*汇率!$AP$2)*100000000 -> 2.8701774e+12 | AQ5: =('分行业工业增加值（当年人民币）'!AQ5*汇率!$AQ$2)*100000000 -> 2.9100658e+12
A6: 交运仓邮 | B6: =('分行业工业增加值（当年人民币）'!B6*汇率!$B$2)*100000000 -> 5.9355954e+11 | C6: =('分行业工业增加值（当年人民币）'!C6*汇率!$C$2)*100000000 -> 5.724933e+11 | D6: =('分行业工业增加值（当年人民币）'!D6*汇率!$D$2)*100000000 -> 6.296468e+11 | E6: =('分行业工业增加值（当年人民币）'!E6*汇率!$E$2)*100000000 -> 6.5329309e+11 | F6: =('分行业工业增加值（当年人民币）'!F6*汇率!$F$2)*100000000 -> 6.7641094e+11 | G6: =('分行业工业增加值（当年人民币）'!G6*汇率!$G$2)*100000000 -> 6.988427e+11 | H6: =('分行业工业增加值（当年人民币）'!H6*汇率!$H$2)*100000000 -> 7.2098339e+11 | I6: =('分行业工业增加值（当年人民币）'!I6*汇率!$I$2)*100000000 -> 7.4252917e+11 | J6: =('分行业工业增加值（当年人民币）'!J6*汇率!$J$2)*100000000 -> 7.6347514e+11 | K6: =('分行业工业增加值（当年人民币）'!K6*汇率!$K$2)*100000000 -> 7.8400382e+11 | L6: =('分行业工业增加值（当年人民币）'!L6*汇率!$L$2)*100000000 -> 8.0389026e+11 | M6: =('分行业工业增加值（当年人民币）'!M6*汇率!$M$2)*100000000 -> 8.2328668e+11 | N6: =('分行业工业增加值（当年人民币）'!N6*汇率!$N$2)*100000000 -> 8.4216195e+11 | O6: =('分行业工业增加值（当年人民币）'!O6*汇率!$O$2)*100000000 -> 8.6038055e+11 | P6: =('分行业工业增加值（当年人民币）'!P6*汇率!$P$2)*100000000 -> 8.781363e+11 | Q6: =('分行业工业增加值（当年人民币）'!Q6*汇率!$Q$2)*100000000 -> 8.9534096e+11 | R6: =('分行业工业增加值（当年人民币）'!R6*汇率!$R$2)*100000000 -> 9.1193031e+11 | S6: =('分行业工业增加值（当年人民币）'!S6*汇率!$S$2)*100000000 -> 9.2807442e+11 | T6: =('分行业工业增加值（当年人民币）'!T6*汇率!$T$2)*100000000 -> 9.436056e+11 | U6: =('分行业工业增加值（当年人民币）'!U6*汇率!$U$2)*100000000 -> 9.5873263e+11 | V6: =('分行业工业增加值（当年人民币）'!V6*汇率!$V$2)*100000000 -> 9.7333368e+11 | W6: =('分行业工业增加值（当年人民币）'!W6*汇率!$W$2)*100000000 -> 9.87304e+11 | X6: =('分行业工业增加值（当年人民币）'!X6*汇率!$X$2)*100000000 -> 1.0008753e+12 | Y6: =('分行业工业增加值（当年人民币）'!Y6*汇率!$Y$2)*100000000 -> 1.013994e+12 | Z6: =('分行业工业增加值（当年人民币）'!Z6*汇率!$Z$2)*100000000 -> 1.0265991e+12 | AA6: =('分行业工业增加值（当年人民币）'!AA6*汇率!$AA$2)*100000000 -> 1.038746e+12 | AB6: =('分行业工业增加值（当年人民币）'!AB6*汇率!$AB$2)*100000000 -> 1.0504719e+12 | AC6: =('分行业工业增加值（当年人民币）'!AC6*汇率!$AC$2)*100000000 -> 1.0618006e+12 | AD6: =('分行业工业增加值（当年人民币）'!AD6*汇率!$AD$2)*100000000 -> 1.0726565e+12 | AE6: =('分行业工业增加值（当年人民币）'!AE6*汇率!$AE$2)*100000000 -> 1.0830918e+12 | AF6: =('分行业工业增加值（当年人民币）'!AF6*汇率!$AF$2)*100000000 -> 1.093253e+12 | AG6: =('分行业工业增加值（当年人民币）'!AG6*汇率!$AG$2)*100000000 -> 1.1029781e+12 | AH6: =('分行业工业增加值（当年人民币）'!AH6*汇率!$AH$2)*100000000 -> 1.1123642e+12 | AI6: =('分行业工业增加值（当年人民币）'!AI6*汇率!$AI$2)*100000000 -> 1.121455e+12 | AJ6: =('分行业工业增加值（当年人民币）'!AJ6*汇率!$AJ$2)*100000000 -> 1.1301828e+12 | AK6: =('分行业工业增加值（当年人民币）'!AK6*汇率!$AK$2)*100000000 -> 1.1386689e+12 | AL6: =('分行业工业增加值（当年人民币）'!AL6*汇率!$AL$2)*100000000 -> 1.1468969e+12 | AM6: =('分行业工业增加值（当年人民币）'!AM6*汇率!$AM$2)*100000000 -> 1.1548887e+12 | AN6: =('分行业工业增加值（当年人民币）'!AN6*汇率!$AN$2)*100000000 -> 1.1626814e+12 | AO6: =('分行业工业增加值（当年人民币）'!AO6*汇率!$AO$2)*100000000 -> 1.1702713e+12 | AP6: =('分行业工业增加值（当年人民币）'!AP6*汇率!$AP$2)*100000000 -> 1.1777544e+12 | AQ6: =('分行业工业增加值（当年人民币）'!AQ6*汇率!$AQ$2)*100000000 -> 1.1850783e+12
A7: 批发零售 | B7: =('分行业工业增加值（当年人民币）'!B7*汇率!$B$2)*100000000 -> 1.3177809e+12 | C7: =('分行业工业增加值（当年人民币）'!C7*汇率!$C$2)*100000000 -> 1.3083408e+12 | D7: =('分行业工业增加值（当年人民币）'!D7*汇率!$D$2)*100000000 -> 1.4853343e+12 | E7: =('分行业工业增加值（当年人民币）'!E7*汇率!$E$2)*100000000 -> 1.5661282e+12 | F7: =('分行业工业增加值（当年人民币）'!F7*汇率!$F$2)*100000000 -> 1.6471163e+12 | G7: =('分行业工业增加值（当年人民币）'!G7*汇率!$G$2)*100000000 -> 1.7274492e+12 | H7: =('分行业工业增加值（当年人民币）'!H7*汇率!$H$2)*100000000 -> 1.8081074e+12 | I7: =('分行业工业增加值（当年人民币）'!I7*汇率!$I$2)*100000000 -> 1.8882553e+12 | J7: =('分行业工业增加值（当年人民币）'!J7*汇率!$J$2)*100000000 -> 1.9677725e+12 | K7: =('分行业工业增加值（当年人民币）'!K7*汇率!$K$2)*100000000 -> 2.0473566e+12 | L7: =('分行业工业增加值（当年人民币）'!L7*汇率!$L$2)*100000000 -> 2.1259887e+12 | M7: =('分行业工业增加值（当年人民币）'!M7*汇率!$M$2)*100000000 -> 2.2041136e+12 | N7: =('分行业工业增加值（当年人民币）'!N7*汇率!$N$2)*100000000 -> 2.2818081e+12 | O7: =('分行业工业增加值（当年人民币）'!O7*汇率!$O$2)*100000000 -> 2.3583752e+12 | P7: =('分行业工业增加值（当年人民币）'!P7*汇率!$P$2)*100000000 -> 2.4345134e+12 | Q7: =('分行业工业增加值（当年人民币）'!Q7*汇率!$Q$2)*100000000 -> 2.5097842e+12 | R7: =('分行业工业增加值（当年人民币）'!R7*汇率!$R$2)*100000000 -> 2.5838353e+12 | S7: =('分行业工业增加值（当年人民币）'!S7*汇率!$S$2)*100000000 -> 2.657471e+12 | T7: =('分行业工业增加值（当年人民币）'!T7*汇率!$T$2)*100000000 -> 2.7299528e+12 | U7: =('分行业工业增加值（当年人民币）'!U7*汇率!$U$2)*100000000 -> 2.8017873e+12 | V7: =('分行业工业增加值（当年人民币）'!V7*汇率!$V$2)*100000000 -> 2.8727093e+12 | W7: =('分行业工业增加值（当年人民币）'!W7*汇率!$W$2)*100000000 -> 2.9424082e+12 | X7: =('分行业工业增加值（当年人民币）'!X7*汇率!$X$2)*100000000 -> 3.0113997e+12 | Y7: =('分行业工业增加值（当年人民币）'!Y7*汇率!$Y$2)*100000000 -> 3.0794805e+12 | Z7: =('分行业工业增加值（当年人民币）'!Z7*汇率!$Z$2)*100000000 -> 3.1465079e+12 | AA7: =('分行业工业增加值（当年人民币）'!AA7*汇率!$AA$2)*100000000 -> 3.2126388e+12 | AB7: =('分行业工业增加值（当年人民币）'!AB7*汇率!$AB$2)*100000000 -> 3.277872e+12 | AC7: =('分行业工业增加值（当年人民币）'!AC7*汇率!$AC$2)*100000000 -> 3.342311e+12 | AD7: =('分行业工业增加值（当年人民币）'!AD7*汇率!$AD$2)*100000000 -> 3.4057229e+12 | AE7: =('分行业工业增加值（当年人民币）'!AE7*汇率!$AE$2)*100000000 -> 3.4681232e+12 | AF7: =('分行业工业增加值（当年人民币）'!AF7*汇率!$AF$2)*100000000 -> 3.5300899e+12 | AG7: =('分行业工业增加值（当年人民币）'!AG7*汇率!$AG$2)*100000000 -> 3.5909789e+12 | AH7: =('分行业工业增加值（当年人民币）'!AH7*汇率!$AH$2)*100000000 -> 3.6511636e+12 | AI7: =('分行业工业增加值（当年人民币）'!AI7*汇率!$AI$2)*100000000 -> 3.7106509e+12 | AJ7: =('分行业工业增加值（当年人民币）'!AJ7*汇率!$AJ$2)*100000000 -> 3.7692227e+12 | AK7: =('分行业工业增加值（当年人民币）'!AK7*汇率!$AK$2)*100000000 -> 3.8273883e+12 | AL7: =('分行业工业增加值（当年人民币）'!AL7*汇率!$AL$2)*100000000 -> 3.8848876e+12 | AM7: =('分行业工业增加值（当年人民币）'!AM7*汇率!$AM$2)*100000000 -> 3.9418361e+12 | AN7: =('分行业工业增加值（当年人民币）'!AN7*汇率!$AN$2)*100000000 -> 3.9984016e+12 | AO7: =('分行业工业增加值（当年人民币）'!AO7*汇率!$AO$2)*100000000 -> 4.0544419e+12 | AP7: =('分行业工业增加值（当年人民币）'!AP7*汇率!$AP$2)*100000000 -> 4.1103275e+12 | AQ7: =('分行业工业增加值（当年人民币）'!AQ7*汇率!$AQ$2)*100000000 -> 4.165883e+12
A8: 餐饮住宿 | B8: =('分行业工业增加值（当年人民币）'!B8*汇率!$B$2)*100000000 -> 2.4867065e+11 | C8: =('分行业工业增加值（当年人民币）'!C8*汇率!$C$2)*100000000 -> 2.1881089e+11 | D8: =('分行业工业增加值（当年人民币）'!D8*汇率!$D$2)*100000000 -> 2.4002938e+11 | E8: =('分行业工业增加值（当年人民币）'!E8*汇率!$E$2)*100000000 -> 2.5714004e+11 | F8: =('分行业工业增加值（当年人民币）'!F8*汇率!$F$2)*100000000 -> 2.7467229e+11 | G8: =('分行业工业增加值（当年人民币）'!G8*汇率!$G$2)*100000000 -> 2.9247372e+11 | H8: =('分行业工业增加值（当年人民币）'!H8*汇率!$H$2)*100000000 -> 3.1075217e+11 | I8: =('分行业工业增加值（当年人民币）'!I8*汇率!$I$2)*100000000 -> 3.2931024e+11 | J8: =('分行业工业增加值（当年人民币）'!J8*汇率!$J$2)*100000000 -> 3.481447e+11 | K8: =('分行业工业增加值（当年人民币）'!K8*汇率!$K$2)*100000000 -> 3.6734068e+11 | L8: =('分行业工业增加值（当年人民币）'!L8*汇率!$L$2)*100000000 -> 3.867393e+11 | M8: =('分行业工业增加值（当年人民币）'!M8*汇率!$M$2)*100000000 -> 4.0642746e+11 | N8: =('分行业工业增加值（当年人民币）'!N8*汇率!$N$2)*100000000 -> 4.2634334e+11 | O8: =('分行业工业增加值（当年人民币）'!O8*汇率!$O$2)*100000000 -> 4.4637825e+11 | P8: =('分行业工业增加值（当年人民币）'!P8*汇率!$P$2)*100000000 -> 4.6668337e+11 | Q8: =('分行业工业增加值（当年人民币）'!Q8*汇率!$Q$2)*100000000 -> 4.8714535e+11 | R8: =('分行业工业增加值（当年人民币）'!R8*汇率!$R$2)*100000000 -> 5.0765986e+11 | S8: =('分行业工业增加值（当年人民币）'!S8*汇率!$S$2)*100000000 -> 5.2838432e+11 | T8: =('分行业工业增加值（当年人民币）'!T8*汇率!$T$2)*100000000 -> 5.4918577e+11 | U8: =('分行业工业增加值（当年人民币）'!U8*汇率!$U$2)*100000000 -> 5.7016814e+11 | V8: =('分行业工业增加值（当年人民币）'!V8*汇率!$V$2)*100000000 -> 5.9120727e+11 | W8: =('分行业工业增加值（当年人民币）'!W8*汇率!$W$2)*100000000 -> 6.1226371e+11 | X8: =('分行业工业增加值（当年人民币）'!X8*汇率!$X$2)*100000000 -> 6.3344808e+11 | Y8: =('分行业工业增加值（当年人民币）'!Y8*汇率!$Y$2)*100000000 -> 6.5469204e+11 | Z8: =('分行业工业增加值（当年人民币）'!Z8*汇率!$Z$2)*100000000 -> 6.7595806e+11 | AA8: =('分行业工业增加值（当年人民币）'!AA8*汇率!$AA$2)*100000000 -> 6.9724985e+11 | AB8: =('分行业工业增加值（当年人民币）'!AB8*汇率!$AB$2)*100000000 -> 7.1858934e+11 | AC8: =('分行业工业增加值（当年人民币）'!AC8*汇率!$AC$2)*100000000 -> 7.4000953e+11 | AD8: =('分行业工业增加值（当年人民币）'!AD8*汇率!$AD$2)*100000000 -> 7.6144419e+11 | AE8: =('分行业工业增加值（当年人民币）'!AE8*汇率!$AE$2)*100000000 -> 7.8286946e+11 | AF8: =('分行业工业增加值（当年人民币）'!AF8*汇率!$AF$2)*100000000 -> 8.0445042e+11 | AG8: =('分行业工业增加值（当年人民币）'!AG8*汇率!$AG$2)*100000000 -> 8.2603504e+11 | AH8: =('分行业工业增加值（当年人民币）'!AH8*汇率!$AH$2)*100000000 -> 8.4771554e+11 | AI8: =('分行业工业增加值（当年人民币）'!AI8*汇率!$AI$2)*100000000 -> 8.6950257e+11 | AJ8: =('分行业工业增加值（当年人民币）'!AJ8*汇率!$AJ$2)*100000000 -> 8.9134941e+11 | AK8: =('分行业工业增加值（当年人民币）'!AK8*汇率!$AK$2)*100000000 -> 9.1337788e+11 | AL8: =('分行业工业增加值（当年人民币）'!AL8*汇率!$AL$2)*100000000 -> 9.3558376e+11 | AM8: =('分行业工业增加值（当年人民币）'!AM8*汇率!$AM$2)*100000000 -> 9.5799265e+11 | AN8: =('分行业工业增加值（当年人民币）'!AN8*汇率!$AN$2)*100000000 -> 9.806664e+11 | AO8: =('分行业工业增加值（当年人民币）'!AO8*汇率!$AO$2)*100000000 -> 1.003597e+12 | AP8: =('分行业工业增加值（当年人民币）'!AP8*汇率!$AP$2)*100000000 -> 1.0269069e+12 | AQ8: =('分行业工业增加值（当年人民币）'!AQ8*汇率!$AQ$2)*100000000 -> 1.050618e+12
A9: 金融业 | B9: =('分行业工业增加值（当年人民币）'!B9*汇率!$B$2)*100000000 -> 1.0622664e+12 | C9: =('分行业工业增加值（当年人民币）'!C9*汇率!$C$2)*100000000 -> 1.1601268e+12 | D9: =('分行业工业增加值（当年人民币）'!D9*汇率!$D$2)*100000000 -> 1.2267773e+12 | E9: =('分行业工业增加值（当年人民币）'!E9*汇率!$E$2)*100000000 -> 1.3301357e+12 | F9: =('分行业工业增加值（当年人民币）'!F9*汇率!$F$2)*100000000 -> 1.4371787e+12 | G9: =('分行业工业增加值（当年人民币）'!G9*汇率!$G$2)*100000000 -> 1.5466565e+12 | H9: =('分行业工业增加值（当年人民币）'!H9*汇率!$H$2)*100000000 -> 1.6598674e+12 | I9: =('分行业工业增加值（当年人民币）'!I9*汇率!$I$2)*100000000 -> 1.7757492e+12 | J9: =('分行业工业增加值（当年人民币）'!J9*汇率!$J$2)*100000000 -> 1.8941494e+12 | K9: =('分行业工业增加值（当年人民币）'!K9*汇率!$K$2)*100000000 -> 2.0160142e+12 | L9: =('分行业工业增加值（当年人民币）'!L9*汇率!$L$2)*100000000 -> 2.1398453e+12 | M9: =('分行业工业增加值（当年人民币）'!M9*汇率!$M$2)*100000000 -> 2.2662596e+12 | N9: =('分行业工业增加值（当年人民币）'!N9*汇率!$N$2)*100000000 -> 2.3954402e+12 | O9: =('分行业工业增加值（当年人民币）'!O9*汇率!$O$2)*100000000 -> 2.5264624e+12 | P9: =('分行业工业增加值（当年人民币）'!P9*汇率!$P$2)*100000000 -> 2.6601346e+12 | Q9: =('分行业工业增加值（当年人民币）'!Q9*汇率!$Q$2)*100000000 -> 2.7960193e+12 | R9: =('分行业工业增加值（当年人民币）'!R9*汇率!$R$2)*100000000 -> 2.9334975e+12 | S9: =('分行业工业增加值（当年人民币）'!S9*汇率!$S$2)*100000000 -> 3.0738691e+12 | T9: =('分行业工业增加值（当年人民币）'!T9*汇率!$T$2)*100000000 -> 3.2158353e+12 | U9: =('分行业工业增加值（当年人民币）'!U9*汇率!$U$2)*100000000 -> 3.3602401e+12 | V9: =('分行业工业增加值（当年人民币）'!V9*汇率!$V$2)*100000000 -> 3.5066929e+12 | W9: =('分行业工业增加值（当年人民币）'!W9*汇率!$W$2)*100000000 -> 3.6547003e+12 | X9: =('分行业工业增加值（当年人民币）'!X9*汇率!$X$2)*100000000 -> 3.8050493e+12 | Y9: =('分行业工业增加值（当年人民币）'!Y9*汇率!$Y$2)*100000000 -> 3.957474e+12 | Z9: =('分行业工业增加值（当年人民币）'!Z9*汇率!$Z$2)*100000000 -> 4.1116148e+12 | AA9: =('分行业工业增加值（当年人民币）'!AA9*汇率!$AA$2)*100000000 -> 4.2678906e+12 | AB9: =('分行业工业增加值（当年人民币）'!AB9*汇率!$AB$2)*100000000 -> 4.4260671e+12 | AC9: =('分行业工业增加值（当年人民币）'!AC9*汇率!$AC$2)*100000000 -> 4.5865307e+12 | AD9: =('分行业工业增加值（当年人民币）'!AD9*汇率!$AD$2)*100000000 -> 4.7487049e+12 | AE9: =('分行业工业增加值（当年人民币）'!AE9*汇率!$AE$2)*100000000 -> 4.9124877e+12 | AF9: =('分行业工业增加值（当年人民币）'!AF9*汇率!$AF$2)*100000000 -> 5.0790204e+12 | AG9: =('分行业工业增加值（当年人民币）'!AG9*汇率!$AG$2)*100000000 -> 5.2469497e+12 | AH9: =('分行业工业增加值（当年人民币）'!AH9*汇率!$AH$2)*100000000 -> 5.4168409e+12 | AI9: =('分行业工业增加值（当年人民币）'!AI9*汇率!$AI$2)*100000000 -> 5.5887063e+12 | AJ9: =('分行业工业增加值（当年人民币）'!AJ9*汇率!$AJ$2)*100000000 -> 5.7620075e+12 | AK9: =('分行业工业增加值（当年人民币）'!AK9*汇率!$AK$2)*100000000 -> 5.9375825e+12 | AL9: =('分行业工业增加值（当年人民币）'!AL9*汇率!$AL$2)*100000000 -> 6.1146845e+12 | AM9: =('分行业工业增加值（当年人民币）'!AM9*汇率!$AM$2)*100000000 -> 6.2933895e+12 | AN9: =('分行业工业增加值（当年人民币）'!AN9*汇率!$AN$2)*100000000 -> 6.4737889e+12 | AO9: =('分行业工业增加值（当年人民币）'!AO9*汇率!$AO$2)*100000000 -> 6.6554304e+12 | AP9: =('分行业工业增加值（当年人民币）'!AP9*汇率!$AP$2)*100000000 -> 6.8389275e+12 | AQ9: =('分行业工业增加值（当年人民币）'!AQ9*汇率!$AQ$2)*100000000 -> 7.0233092e+12
A10: 房地产 | B10: =('分行业工业增加值（当年人民币）'!B10*汇率!$B$2)*100000000 -> 9.6177372e+11 | C10: =('分行业工业增加值（当年人民币）'!C10*汇率!$C$2)*100000000 -> 1.0261541e+12 | D10: =('分行业工业增加值（当年人民币）'!D10*汇率!$D$2)*100000000 -> 1.0440494e+12 | E10: =('分行业工业增加值（当年人民币）'!E10*汇率!$E$2)*100000000 -> 1.1020725e+12 | F10: =('分行业工业增加值（当年人民币）'!F10*汇率!$F$2)*100000000 -> 1.1605847e+12 | G10: =('分行业工业增加值（当年人民币）'!G10*汇率!$G$2)*100000000 -> 1.2190647e+12 | H10: =('分行业工业增加值（当年人民币）'!H10*汇率!$H$2)*100000000 -> 1.2783021e+12 | I10: =('分行业工业增加值（当年人民币）'!I10*汇率!$I$2)*100000000 -> 1.3376627e+12 | J10: =('分行业工业增加值（当年人民币）'!J10*汇率!$J$2)*100000000 -> 1.3970986e+12 | K10: =('分行业工业增加值（当年人民币）'!K10*汇率!$K$2)*100000000 -> 1.456898e+12 | L10: =('分行业工业增加值（当年人民币）'!L10*汇率!$L$2)*100000000 -> 1.5164988e+12 | M10: =('分行业工业增加值（当年人民币）'!M10*汇率!$M$2)*100000000 -> 1.5762076e+12 | N10: =('分行业工业增加值（当年人民币）'!N10*汇率!$N$2)*100000000 -> 1.6359821e+12 | O10: =('分行业工业增加值（当年人民币）'!O10*汇率!$O$2)*100000000 -> 1.6954171e+12 | P10: =('分行业工业增加值（当年人民币）'!P10*汇率!$P$2)*100000000 -> 1.754898e+12 | Q10: =('分行业工业增加值（当年人民币）'!Q10*汇率!$Q$2)*100000000 -> 1.8141417e+12 | R10: =('分行业工业增加值（当年人民币）'!R10*汇率!$R$2)*100000000 -> 1.8729868e+12 | S10: =('分行业工业增加值（当年人民币）'!S10*汇率!$S$2)*100000000 -> 1.9317985e+12 | T10: =('分行业工业增加值（当年人民币）'!T10*汇率!$T$2)*100000000 -> 1.9901264e+12 | U10: =('分行业工业增加值（当年人民币）'!U10*汇率!$U$2)*100000000 -> 2.0483389e+12 | V10: =('分行业工业增加值（当年人民币）'!V10*汇率!$V$2)*100000000 -> 2.1062215e+12 | W10: =('分行业工业增加值（当年人民币）'!W10*汇率!$W$2)*100000000 -> 2.1635203e+12 | X10: =('分行业工业增加值（当年人民币）'!X10*汇率!$X$2)*100000000 -> 2.2206081e+12 | Y10: =('分行业工业增加值（当年人民币）'!Y10*汇率!$Y$2)*100000000 -> 2.2773241e+12 | Z10: =('分行业工业增加值（当年人民币）'!Z10*汇率!$Z$2)*100000000 -> 2.3335745e+12 | AA10: =('分行业工业增加值（当年人民币）'!AA10*汇率!$AA$2)*100000000 -> 2.3894024e+12 | AB10: =('分行业工业增加值（当年人民币）'!AB10*汇率!$AB$2)*100000000 -> 2.444862e+12 | AC10: =('分行业工业增加值（当年人民币）'!AC10*汇率!$AC$2)*100000000 -> 2.5000321e+12 | AD10: =('分行业工业增加值（当年人民币）'!AD10*汇率!$AD$2)*100000000 -> 2.5546564e+12 | AE10: =('分行业工业增加值（当年人民币）'!AE10*汇率!$AE$2)*100000000 -> 2.608869e+12 | AF10: =('分行业工业增加值（当年人民币）'!AF10*汇率!$AF$2)*100000000 -> 2.6629876e+12 | AG10: =('分行业工业增加值（当年人民币）'!AG10*汇率!$AG$2)*100000000 -> 2.7165973e+12 | AH10: =('分行业工业增加值（当年人民币）'!AH10*汇率!$AH$2)*100000000 -> 2.7699419e+12 | AI10: =('分行业工业增加值（当年人民币）'!AI10*汇率!$AI$2)*100000000 -> 2.8230871e+12 | AJ10: =('分行业工业增加值（当年人民币）'!AJ10*汇率!$AJ$2)*100000000 -> 2.8759114e+12 | AK10: =('分行业工业增加值（当年人民币）'!AK10*汇率!$AK$2)*100000000 -> 2.9287079e+12 | AL10: =('分行业工业增加值（当年人民币）'!AL10*汇率!$AL$2)*100000000 -> 2.9814065e+12 | AM10: =('分行业工业增加值（当年人民币）'!AM10*汇率!$AM$2)*100000000 -> 3.0341009e+12 | AN10: =('分行业工业增加值（当年人民币）'!AN10*汇率!$AN$2)*100000000 -> 3.0869206e+12 | AO10: =('分行业工业增加值（当年人民币）'!AO10*汇率!$AO$2)*100000000 -> 3.1398477e+12 | AP10: =('分行业工业增加值（当年人民币）'!AP10*汇率!$AP$2)*100000000 -> 3.1931153e+12 | AQ10: =('分行业工业增加值（当年人民币）'!AQ10*汇率!$AQ$2)*100000000 -> 3.2467224e+12
A11: 其他三产 | B11: =('分行业工业增加值（当年人民币）'!B11*汇率!$B$2)*100000000 -> 3.097634e+12 | C11: =('分行业工业增加值（当年人民币）'!C11*汇率!$C$2)*100000000 -> 4.1679679e+12 | D11: =('分行业工业增加值（当年人民币）'!D11*汇率!$D$2)*100000000 -> 3.9115913e+12 | E11: =('分行业工业增加值（当年人民币）'!E11*汇率!$E$2)*100000000 -> 4.2631613e+12 | F11: =('分行业工业增加值（当年人民币）'!F11*汇率!$F$2)*100000000 -> 4.6235846e+12 | G11: =('分行业工业增加值（当年人民币）'!G11*汇率!$G$2)*100000000 -> 4.9874411e+12 | H11: =('分行业工业增加值（当年人民币）'!H11*汇率!$H$2)*100000000 -> 5.3606919e+12 | I11: =('分行业工业增加值（当年人民币）'!I11*汇率!$I$2)*100000000 -> 5.7360297e+12 | J11: =('分行业工业增加值（当年人民币）'!J11*汇率!$J$2)*100000000 -> 6.1132135e+12 | K11: =('分行业工业增加值（当年人民币）'!K11*汇率!$K$2)*100000000 -> 6.4942629e+12 | L11: =('分行业工业增加值（当年人民币）'!L11*汇率!$L$2)*100000000 -> 6.8732406e+12 | M11: =('分行业工业增加值（当年人民币）'!M11*汇率!$M$2)*100000000 -> 7.2524244e+12 | N11: =('分行业工业增加值（当年人民币）'!N11*汇率!$N$2)*100000000 -> 7.6304568e+12 | O11: =('分行业工业增加值（当年人民币）'!O11*汇率!$O$2)*100000000 -> 8.0041514e+12 | P11: =('分行业工业增加值（当年人民币）'!P11*汇率!$P$2)*100000000 -> 8.3763236e+12 | Q11: =('分行业工业增加值（当年人民币）'!Q11*汇率!$Q$2)*100000000 -> 8743632496775 | R11: =('分行业工业增加值（当年人民币）'!R11*汇率!$R$2)*100000000 -> 9.104643e+12 | S11: =('分行业工业增加值（当年人民币）'!S11*汇率!$S$2)*100000000 -> 9.4626727e+12 | T11: =('分行业工业增加值（当年人民币）'!T11*汇率!$T$2)*100000000 -> 9.8134429e+12 | U11: =('分行业工业增加值（当年人民币）'!U11*汇率!$U$2)*100000000 -> 10160108529873 | V11: =('分行业工业增加值（当年人民币）'!V11*汇率!$V$2)*100000000 -> 1.0499975e+13 | W11: =('分行业工业增加值（当年人民币）'!W11*汇率!$W$2)*100000000 -> 1.0831845e+13 | X11: =('分行业工业增加值（当年人民币）'!X11*汇率!$X$2)*100000000 -> 1.1158388e+13 | Y11: =('分行业工业增加值（当年人民币）'!Y11*汇率!$Y$2)*100000000 -> 1.1477882e+13 | Z11: =('分行业工业增加值（当年人民币）'!Z11*汇率!$Z$2)*100000000 -> 1.1789912e+13 | AA11: =('分行业工业增加值（当年人民币）'!AA11*汇率!$AA$2)*100000000 -> 1.2094517e+13 | AB11: =('分行业工业增加值（当年人民币）'!AB11*汇率!$AB$2)*100000000 -> 1.239206e+13 | AC11: =('分行业工业增加值（当年人民币）'!AC11*汇率!$AC$2)*100000000 -> 1.268317e+13 | AD11: =('分行业工业增加值（当年人民币）'!AD11*汇率!$AD$2)*100000000 -> 1.2966004e+13 | AE11: =('分行业工业增加值（当年人民币）'!AE11*汇率!$AE$2)*100000000 -> 1.3240769e+13 | AF11: =('分行业工业增加值（当年人民币）'!AF11*汇率!$AF$2)*100000000 -> 1.3510098e+13 | AG11: =('分行业工业增加值（当年人民币）'!AG11*汇率!$AG$2)*100000000 -> 1.3771033e+13 | AH11: =('分行业工业增加值（当年人民币）'!AH11*汇率!$AH$2)*100000000 -> 1.4025034e+13 | AI11: =('分行业工业增加值（当年人民币）'!AI11*汇率!$AI$2)*100000000 -> 1.4272064e+13 | AJ11: =('分行业工业增加值（当年人民币）'!AJ11*汇率!$AJ$2)*100000000 -> 1.4511373e+13 | AK11: =('分行业工业增加值（当年人民币）'!AK11*汇率!$AK$2)*100000000 -> 1.4744789e+13 | AL11: =('分行业工业增加值（当年人民币）'!AL11*汇率!$AL$2)*100000000 -> 1.4971374e+13 | AM11: =('分行业工业增加值（当年人民币）'!AM11*汇率!$AM$2)*100000000 -> 1.5191609e+13 | AN11: =('分行业工业增加值（当年人民币）'!AN11*汇率!$AN$2)*100000000 -> 1.5405644e+13 | AO11: =('分行业工业增加值（当年人民币）'!AO11*汇率!$AO$2)*100000000 -> 1.5613386e+13 | AP11: =('分行业工业增加值（当年人民币）'!AP11*汇率!$AP$2)*100000000 -> 1.5815837e+13 | AQ11: =('分行业工业增加值（当年人民币）'!AQ11*汇率!$AQ$2)*100000000 -> 16012371254583
A13: 工业 | B13: =('分行业工业增加值（当年人民币）'!B13*汇率!$B$2)*100000000 -> 4.3273675e+12 | C13: =('分行业工业增加值（当年人民币）'!C13*汇率!$C$2)*100000000 -> 4.3066258e+12 | D13: =('分行业工业增加值（当年人民币）'!D13*汇率!$D$2)*100000000 -> 4.9641751e+12 | E13: =('分行业工业增加值（当年人民币）'!E13*汇率!$E$2)*100000000 -> 5.098886e+12 | F13: =('分行业工业增加值（当年人民币）'!F13*汇率!$F$2)*100000000 -> 5.222535e+12 | G13: =('分行业工业增加值（当年人民币）'!G13*汇率!$G$2)*100000000 -> 5.3357926e+12 | H13: =('分行业工业增加值（当年人民币）'!H13*汇率!$H$2)*100000000 -> 5.4393831e+12 | I13: =('分行业工业增加值（当年人民币）'!I13*汇率!$I$2)*100000000 -> 5.5340487e+12 | J13: =('分行业工业增加值（当年人民币）'!J13*汇率!$J$2)*100000000 -> 5.6205229e+12 | K13: =('分行业工业增加值（当年人民币）'!K13*汇率!$K$2)*100000000 -> 5.6995128e+12 | L13: =('分行业工业增加值（当年人民币）'!L13*汇率!$L$2)*100000000 -> 5.7716873e+12 | M13: =('分行业工业增加值（当年人民币）'!M13*汇率!$M$2)*100000000 -> 5.8376704e+12 | N13: =('分行业工业增加值（当年人民币）'!N13*汇率!$N$2)*100000000 -> 5.8980385e+12 | O13: =('分行业工业增加值（当年人民币）'!O13*汇率!$O$2)*100000000 -> 5.9533191e+12 | P13: =('分行业工业增加值（当年人民币）'!P13*汇率!$P$2)*100000000 -> 6.0039928e+12 | Q13: =('分行业工业增加值（当年人民币）'!Q13*汇率!$Q$2)*100000000 -> 6.050495e+12 | R13: =('分行业工业增加值（当年人民币）'!R13*汇率!$R$2)*100000000 -> 6.0932188e+12 | S13: =('分行业工业增加值（当年人民币）'!S13*汇率!$S$2)*100000000 -> 6.1325187e+12 | T13: =('分行业工业增加值（当年人民币）'!T13*汇率!$T$2)*100000000 -> 6.1687134e+12 | U13: =('分行业工业增加值（当年人民币）'!U13*汇率!$U$2)*100000000 -> 6.2020893e+12 | V13: =('分行业工业增加值（当年人民币）'!V13*汇率!$V$2)*100000000 -> 6.2329036e+12 | W13: =('分行业工业增加值（当年人民币）'!W13*汇率!$W$2)*100000000 -> 6.2613874e+12 | X13: =('分行业工业增加值（当年人民币）'!X13*汇率!$X$2)*100000000 -> 6.2877482e+12 | Y13: =('分行业工业增加值（当年人民币）'!Y13*汇率!$Y$2)*100000000 -> 6.3121728e+12 | Z13: =('分行业工业增加值（当年人民币）'!Z13*汇率!$Z$2)*100000000 -> 6.3348287e+12 | AA13: =('分行业工业增加值（当年人民币）'!AA13*汇率!$AA$2)*100000000 -> 6.3558673e+12 | AB13: =('分行业工业增加值（当年人民币）'!AB13*汇率!$AB$2)*100000000 -> 6.3754245e+12 | AC13: =('分行业工业增加值（当年人民币）'!AC13*汇率!$AC$2)*100000000 -> 6.3936235e+12 | AD13: =('分行业工业增加值（当年人民币）'!AD13*汇率!$AD$2)*100000000 -> 6.4105752e+12 | AE13: =('分行业工业增加值（当年人民币）'!AE13*汇率!$AE$2)*100000000 -> 6.4263802e+12 | AF13: =('分行业工业增加值（当年人民币）'!AF13*汇率!$AF$2)*100000000 -> 6.4411295e+12 | AG13: =('分行业工业增加值（当年人民币）'!AG13*汇率!$AG$2)*100000000 -> 6.4549058e+12 | AH13: =('分行业工业增加值（当年人民币）'!AH13*汇率!$AH$2)*100000000 -> 6.4677843e+12 | AI13: =('分行业工业增加值（当年人民币）'!AI13*汇率!$AI$2)*100000000 -> 6.4798332e+12 | AJ13: =('分行业工业增加值（当年人民币）'!AJ13*汇率!$AJ$2)*100000000 -> 6.491115e+12 | AK13: =('分行业工业增加值（当年人民币）'!AK13*汇率!$AK$2)*100000000 -> 6.5016865e+12 | AL13: =('分行业工业增加值（当年人民币）'!AL13*汇率!$AL$2)*100000000 -> 6.5115998e+12 | AM13: =('分行业工业增加值（当年人民币）'!AM13*汇率!$AM$2)*100000000 -> 6.5209025e+12 | AN13: =('分行业工业增加值（当年人民币）'!AN13*汇率!$AN$2)*100000000 -> 6.5296382e+12 | AO13: =('分行业工业增加值（当年人民币）'!AO13*汇率!$AO$2)*100000000 -> 6.537847e+12 | AP13: =('分行业工业增加值（当年人民币）'!AP13*汇率!$AP$2)*100000000 -> 6.5455659e+12 | AQ13: =('分行业工业增加值（当年人民币）'!AQ13*汇率!$AQ$2)*100000000 -> 6.5528286e+12
A14: 煤炭采选产品 | B14: =('分行业工业增加值（当年人民币）'!B14*汇率!$B$2)*100000000 -> 1.2104576e+11 | C14: =('分行业工业增加值（当年人民币）'!C14*汇率!$C$2)*100000000 -> 1.4374983e+11 | D14: =('分行业工业增加值（当年人民币）'!D14*汇率!$D$2)*100000000 -> 1.4549003e+11 | E14: =('分行业工业增加值（当年人民币）'!E14*汇率!$E$2)*100000000 -> 1.4704644e+11 | F14: =('分行业工业增加值（当年人民币）'!F14*汇率!$F$2)*100000000 -> 1.4834443e+11 | G14: =('分行业工业增加值（当年人民币）'!G14*汇率!$G$2)*100000000 -> 1.4941017e+11 | H14: =('分行业工业增加值（当年人民币）'!H14*汇率!$H$2)*100000000 -> 1.502693e+11 | I14: =('分行业工业增加值（当年人民币）'!I14*汇率!$I$2)*100000000 -> 1.5094615e+11 | J14: =('分行业工业增加值（当年人民币）'!J14*汇率!$J$2)*100000000 -> 1.5146334e+11 | K14: =('分行业工业增加值（当年人民币）'!K14*汇率!$K$2)*100000000 -> 1.5184151e+11 | L14: =('分行业工业增加值（当年人民币）'!L14*汇率!$L$2)*100000000 -> 1.5209928e+11 | M14: =('分行业工业增加值（当年人民币）'!M14*汇率!$M$2)*100000000 -> 1.5225325e+11 | N14: =('分行业工业增加值（当年人民币）'!N14*汇率!$N$2)*100000000 -> 1.5231809e+11 | O14: =('分行业工业增加值（当年人民币）'!O14*汇率!$O$2)*100000000 -> 1.5230671e+11 | P14: =('分行业工业增加值（当年人民币）'!P14*汇率!$P$2)*100000000 -> 1.5223041e+11 | Q14: =('分行业工业增加值（当年人民币）'!Q14*汇率!$Q$2)*100000000 -> 1.5209903e+11 | R14: =('分行业工业增加值（当年人民币）'!R14*汇率!$R$2)*100000000 -> 1.519211e+11 | S14: =('分行业工业增加值（当年人民币）'!S14*汇率!$S$2)*100000000 -> 1.5170403e+11 | T14: =('分行业工业增加值（当年人民币）'!T14*汇率!$T$2)*100000000 -> 1.5145421e+11 | U14: =('分行业工业增加值（当年人民币）'!U14*汇率!$U$2)*100000000 -> 1.5117716e+11 | V14: =('分行业工业增加值（当年人民币）'!V14*汇率!$V$2)*100000000 -> 1.5087764e+11 | W14: =('分行业工业增加值（当年人民币）'!W14*汇率!$W$2)*100000000 -> 1.5055973e+11 | X14: =('分行业工业增加值（当年人民币）'!X14*汇率!$X$2)*100000000 -> 1.5022696e+11 | Y14: =('分行业工业增加值（当年人民币）'!Y14*汇率!$Y$2)*100000000 -> 1.4988236e+11 | Z14: =('分行业工业增加值（当年人民币）'!Z14*汇率!$Z$2)*100000000 -> 1.4952852e+11 | AA14: =('分行业工业增加值（当年人民币）'!AA14*汇率!$AA$2)*100000000 -> 1.4916766e+11 | AB14: =('分行业工业增加值（当年人民币）'!AB14*汇率!$AB$2)*100000000 -> 1.4880171e+11 | AC14: =('分行业工业增加值（当年人民币）'!AC14*汇率!$AC$2)*100000000 -> 1.484323e+11 | AD14: =('分行业工业增加值（当年人民币）'!AD14*汇率!$AD$2)*100000000 -> 1.4806082e+11 | AE14: =('分行业工业增加值（当年人民币）'!AE14*汇率!$AE$2)*100000000 -> 1.4768847e+11 | AF14: =('分行业工业增加值（当年人民币）'!AF14*汇率!$AF$2)*100000000 -> 1.4731627e+11 | AG14: =('分行业工业增加值（当年人民币）'!AG14*汇率!$AG$2)*100000000 -> 1.4694508e+11 | AH14: =('分行业工业增加值（当年人民币）'!AH14*汇率!$AH$2)*100000000 -> 1.4657565e+11 | AI14: =('分行业工业增加值（当年人民币）'!AI14*汇率!$AI$2)*100000000 -> 1.462086e+11 | AJ14: =('分行业工业增加值（当年人民币）'!AJ14*汇率!$AJ$2)*100000000 -> 1.4584445e+11 | AK14: =('分行业工业增加值（当年人民币）'!AK14*汇率!$AK$2)*100000000 -> 1.4548364e+11 | AL14: =('分行业工业增加值（当年人民币）'!AL14*汇率!$AL$2)*100000000 -> 1.4512655e+11 | AM14: =('分行业工业增加值（当年人民币）'!AM14*汇率!$AM$2)*100000000 -> 1.4477349e+11 | AN14: =('分行业工业增加值（当年人民币）'!AN14*汇率!$AN$2)*100000000 -> 1.444247e+11 | AO14: =('分行业工业增加值（当年人民币）'!AO14*汇率!$AO$2)*100000000 -> 1.4408039e+11 | AP14: =('分行业工业增加值（当年人民币）'!AP14*汇率!$AP$2)*100000000 -> 1.4374073e+11 | AQ14: =('分行业工业增加值（当年人民币）'!AQ14*汇率!$AQ$2)*100000000 -> 1.4340585e+11
... A54: 公共管理、社会保障和社会组织 | B54: =('分行业工业增加值（当年人民币）'!B54*汇率!$B$2)*100000000 -> 5.0470061e+11 | C54: =('分行业工业增加值（当年人民币）'!C54*汇率!$C$2)*100000000 -> 6.481061e+11 | D54: =('分行业工业增加值（当年人民币）'!D54*汇率!$D$2)*100000000 -> 5.6864439e+11 | E54: =('分行业工业增加值（当年人民币）'!E54*汇率!$E$2)*100000000 -> 6.2020912e+11 | F54: =('分行业工业增加值（当年人民币）'!F54*汇率!$F$2)*100000000 -> 6.7318826e+11 | G54: =('分行业工业增加值（当年人民币）'!G54*汇率!$G$2)*100000000 -> 7.2702039e+11 | H54: =('分行业工业增加值（当年人民币）'!H54*汇率!$H$2)*100000000 -> 7.8244834e+11 | I54: =('分行业工业增加值（当年人民币）'!I54*汇率!$I$2)*100000000 -> 8.384348e+11 | J54: =('分行业工业增加值（当年人民币）'!J54*汇率!$J$2)*100000000 -> 8.9499539e+11 | K54: =('分行业工业增加值（当年人民币）'!K54*汇率!$K$2)*100000000 -> 9.5222908e+11 | L54: =('分行业工业增加值（当年人民币）'!L54*汇率!$L$2)*100000000 -> 1.0094198e+12 | M54: =('分行业工业增加值（当年人民币）'!M54*汇率!$M$2)*100000000 -> 1.0667964e+12 | N54: =('分行业工业增加值（当年人民币）'!N54*汇率!$N$2)*100000000 -> 1.1241874e+12 | O54: =('分行业工业增加值（当年人民币）'!O54*汇率!$O$2)*100000000 -> 1.1811308e+12 | P54: =('分行业工业增加值（当年人民币）'!P54*汇率!$P$2)*100000000 -> 1.2378976e+12 | Q54: =('分行业工业增加值（当年人民币）'!Q54*汇率!$Q$2)*100000000 -> 1.2940753e+12 | R54: =('分行业工业增加值（当年人民币）'!R54*汇率!$R$2)*100000000 -> 1.349501e+12 | S54: =('分行业工业增加值（当年人民币）'!S54*汇率!$S$2)*100000000 -> 1.4044528e+12 | T54: =('分行业工业增加值（当年人民币）'!T54*汇率!$T$2)*100000000 -> 1.4583977e+12 | U54: =('分行业工业增加值（当年人民币）'!U54*汇率!$U$2)*100000000 -> 1.5118014e+12 | V54: =('分行业工业增加值（当年人民币）'!V54*汇率!$V$2)*100000000 -> 1.564268e+12 | W54: =('分行业工业增加值（当年人民币）'!W54*汇率!$W$2)*100000000 -> 1.6155389e+12 | X54: =('分行业工业增加值（当年人民币）'!X54*汇率!$X$2)*100000000 -> 1.6660137e+12 | Y54: =('分行业工业增加值（当年人民币）'!Y54*汇率!$Y$2)*100000000 -> 1.7155001e+12 | Z54: =('分行业工业增加值（当年人民币）'!Z54*汇率!$Z$2)*100000000 -> 1.7638536e+12 | AA54: =('分行业工业增加值（当年人民币）'!AA54*汇率!$AA$2)*100000000 -> 1.8110625e+12 | AB54: =('分行业工业增加值（当年人民币）'!AB54*汇率!$AB$2)*100000000 -> 1.8572837e+12 | AC54: =('分行业工业增加值（当年人民币）'!AC54*汇率!$AC$2)*100000000 -> 1.9025213e+12 | AD54: =('分行业工业增加值（当年人民币）'!AD54*汇率!$AD$2)*100000000 -> 1.946543e+12 | AE54: =('分行业工业增加值（当年人民币）'!AE54*汇率!$AE$2)*100000000 -> 1.9893778e+12 | AF54: =('分行业工业增加值（当年人民币）'!AF54*汇率!$AF$2)*100000000 -> 2.0314187e+12 | AG54: =('分行业工业增加值（当年人民币）'!AG54*汇率!$AG$2)*100000000 -> 2.0722403e+12 | AH54: =('分行业工业增加值（当年人民币）'!AH54*汇率!$AH$2)*100000000 -> 2.112009e+12 | AI54: =('分行业工业增加值（当年人民币）'!AI54*汇率!$AI$2)*100000000 -> 2.1508919e+12 | AJ54: =('分行业工业增加值（当年人民币）'!AJ54*汇率!$AJ$2)*100000000 -> 2.1887033e+12 | AK54: =('分行业工业增加值（当年人民币）'!AK54*汇率!$AK$2)*100000000 -> 2.2256683e+12 | AL54: =('分行业工业增加值（当年人民币）'!AL54*汇率!$AL$2)*100000000 -> 2.2618067e+12 | AM54: =('分行业工业增加值（当年人民币）'!AM54*汇率!$AM$2)*100000000 -> 2.2971648e+12 | AN54: =('分行业工业增加值（当年人民币）'!AN54*汇率!$AN$2)*100000000 -> 2.3318214e+12 | AO54: =('分行业工业增加值（当年人民币）'!AO54*汇率!$AO$2)*100000000 -> 2.3658169e+12 | AP54: =('分行业工业增加值（当年人民币）'!AP54*汇率!$AP$2)*100000000 -> 2.3992639e+12 | AQ54: =('分行业工业增加值（当年人民币）'!AQ54*汇率!$AQ$2)*100000000 -> 2.4321828e+12

Sheet 汇率
A1: 人民币年份 | B1: 2019 | C1: 2020 | D1: 2021 | E1: 2022 | F1: 2023 | G1: 2024 | H1: 2025 | I1: 2026 | J1: 2027 | K1: 2028 | L1: 2029 | M1: 2030 | N1: 2031 | O1: 2032 | P1: 2033 | Q1: 2034 | R1: 2035 | S1: 2036 | T1: 2037 | U1: 2038 | V1: 2039 | W1: 2040 | X1: 2041 | Y1: 2042 | Z1: 2043 | AA1: 2044 | AB1: 2045 | AC1: 2046 | AD1: 2047 | AE1: 2048 | AF1: 2049 | AG1: 2050 | AH1: 2051 | AI1: 2052 | AJ1: 2053 | AK1: 2054 | AL1: 2055 | AM1: 2056 | AN1: 2057 | AO1: 2058 | AP1: 2059 | AQ1: 2060
A2: 当年人民币相对2012美元 | B2: 0.13851126 | C2: 0.13765068 | D2: 0.13468755 | E2: 0.13178821 | F2: 0.12895128 | G2: 0.12617542 | H2: 0.12345932 | I2: 0.12080168 | J2: 0.11820125 | K2: 0.1156568 | L2: 0.11316713 | M2: 0.11073104 | N2: 0.1083474 | O2: 0.10601507 | P2: 0.10373295 | Q2: 0.10149995 | R2: 0.099315016 | S2: 0.09717712 | T2: 0.095085244 | U2: 0.093038399 | V2: 0.091035616 | W2: 0.089075945 | X2: 0.087158459 | Y2: 0.085282249 | Z2: 0.083446428 | AA2: 0.081650125 | AB2: 0.079892491 | AC2: 0.078172691 | AD2: 0.076489913 | AE2: 0.074843359 | AF2: 0.07323225 | AG2: 0.071655822 | AH2: 0.070113329 | AI2: 0.06860404 | AJ2: 0.06712724 | AK2: 0.065682231 | AL2: 0.064268328 | AM2: 0.062884861 | AN2: 0.061531175 | AO2: 0.060206629 | AP2: 0.058910596 | AQ2: 0.057642462

Sheet 2020年全国投入产出表
A1: 2020年全国投入产出表
A2: (按当年生产者价格计算） （Data are calculated at producers' prices in 2020)
A3: 单位：万元
A4: 投入 产出 | C4: 部门名称 | AU4: 最终使用 | BE4: 进口 | BF4: 总产出
D5: 农林牧渔产品和服务 | E5: 煤炭开采和洗选产品 | F5: 石油和天然气开采产品 | G5: 金属矿采选产品&非金属矿 | H5: 开采辅助活动和其他采矿产品 | I5: 食品和烟草 | J5: 纺织品、纺织服装鞋帽皮革羽绒及其制品 | K5: 木材加工品和家具 | L5: 造纸印刷和文教体育用品 | M5: 石油、炼焦产品和核燃料加工品 | N5: 化学原料和化学制品制造业&化学纤维制造业 | O5: 医药制造业 | P5: 橡胶和塑料制品业 | Q5: 非金属矿物制品 | R5: 黑色金属冶炼和压延加工品 | S5: 有色金属冶炼和压延加工品 | T5: 金属制品 | U5: 通用设备 | V5: 专用设备 | W5: 汽车制造业 | X5: 铁路、船舶、航空航天和其他运输设备 | Y5: 电气机械和器材 | Z5: 通信设备、计算机和其他电子设备&仪器仪表 | AA5: 其他制造产品和废品废料、金属制品、机械和设备修理服务 | AB5: 电力、热力生产和供应 | AC5: 燃气生产和供应 | AD5: 水的生产和供应 | AE5: 建筑 | AF5: 批发和零售 | AG5: 交通运输、仓储和邮政 | AH5: 住宿和餐饮 | AI5: 信息传输、软件和信息技术服务 | AJ5: 金融 | AK5: 房地产 | AL5: 租赁和商务服务 | AM5: 研究和试验发展 | AN5: 综合技术服务 | AO5: 居民服务、修理和其他服务 | AP5: 教育 | AQ5: 卫生和社会工作 | AR5: 文化、体育和娱乐 | AS5: 水利、环境和公共设施管理、公共管理、社会保障和社会组织 | AT5: 中间使用合计 | AU5: 农村居民消费支出 | AV5: 城镇居民消费支出 | AW5: 居民消费支出 | AX5: 政府消费支出 | AY5: 消费支出合计 | AZ5: 固定资本形成总额 | BA5: 存货变动 | BB5: 资本形成总额 | BC5: 出口 | BD5: 最终使用合计
B6: 部门名称 | C6: 代码 | D6: ISIC 01T03 | E6: ISIC 05 | F6: ISIC 06 | G6: ISIC 07T08 | H6: ISIC 09 | I6: ISIC 10T12 | J6: ISIC 13T15 | K6: ISIC 16 | L6: ISIC 17T18 | M6: ISIC 19 | N6: ISIC 20 | O6: ISIC 21 | P6: ISIC 22 | Q6: ISIC 231 | R6: ISIC 241 | S6: ISIC 242 | T6: ISIC 25 | U6: ISIC 28 | V6: ISIC 239 | W6: ISIC 29 | X6: ISIC 30 | Y6: ISIC 27 | Z6: ISIC 26 | AA6: ISIC 31T33 | AB6: ISIC 351 | AC6: ISIC 352T353 | AD6: ISIC 36T39 | AE6: ISIC 41T43 | AF6: ISIC 45T47 | AG6: ISIC 49T53 | AH6: ISIC 55T56 | AI6: ISIC 58T60 | AJ6: ISIC 64T66 | AK6: ISIC 68 | AL6: ISIC 61 | AM6: ISIC 64T66 | AN6: ISIC 69T82 | AO6: ISIC 97T98 | AP6: ISIC 85 | AQ6: ISIC 86T88 | AR6: ISIC 90T96 | AS6: ISIC 84 | AT6: TIU | AU6: FU101 | AV6: FU102 | AW6: THC | AX6: FU103 | AY6: TC | AZ6: FU201 | BA6: FU202 | BB6: GCF | BC6: EX | BD6: TFU | BE6: IM | BF6: GO
B7: 农林牧渔产品和服务 | C7: ISIC 01T03 | D7: 1.8313377e+08 | E7: 203490.68 | F7: 2231.1266 | G7: 30366.118 | H7: 118.5489 | I7: 4.6758672e+08 | J7: 82006169 | K7: 31973463 | L7: 53736067 | M7: 15804.36 | N7: 11513733 | O7: 44821825 | P7: 7680873.6 | Q7: 218881.19 | R7: 20627.162 | S7: 15998.126 | T7: 97311.762 | U7: 27411.881 | V7: 79539.685 | W7: 26629.608 | X7: 12565.824 | Y7: 68073.761 | Z7: 2175.5736 | AA7: 3451035.2 | AB7: 101721.23 | AC7: 1310.7869 | AD7: 0 | AE7: 18834172 | AF7: 13768.593 | AG7: 154389.97 | AH7: 53857079 | AI7: 509534.92 | AJ7: 67279.739 | AK7: 336941.13 | AL7: 7363183.4 | AM7: 4230391.8 | AN7: 1149759.6 | AO7: 2268491.1 | AP7: 612269.39 | AQ7: 605609.6 | AR7: 477755.87 | AS7: 9519615.7 | AT7: 9.5485469e+08 | AU7: 1.0974545e+08 | AV7: 2.21055e+08 | AW7: 3.3080046e+08 | AX7: 19639628 | AY7: 3.5044008e+08 | AZ7: 17577340 | BA7: 54901502 | BB7: 72478841 | BC7: 18171672 | BD7: 4.410906e+08 | BE7: 64262038 | BF7: 1.3316833e+09
B8: 煤炭开采和洗选产品 | C8: ISIC 05 | D8: 601665.54 | E8: 36204794 | F8: 63785.09 | G8: 1725453.9 | H8: 60512.779 | I8: 2167450.2 | J8: 1809485.7 | K8: 280086.13 | L8: 3698845.9 | M8: 22001120 | N8: 21794626 | O8: 436019.62 | P8: 562146.69 | Q8: 34167884 | R8: 21281683 | S8: 3302161.3 | T8: 494727.51 | U8: 360707.78 | V8: 252507.67 | W8: 48318.135 | X8: 49904.046 | Y8: 214230.21 | Z8: 20070.619 | AA8: 178085.14 | AB8: 93800322 | AC8: 2360515.5 | AD8: 0 | AE8: 843243.22 | AF8: 45563.861 | AG8: 128090.52 | AH8: 50429.81 | AI8: 0 | AJ8: 17218.23 | AK8: 63307.69 | AL8: 64.301927 | AM8: 234549.27 | AN8: 170081.94 | AO8: 326757.73 | AP8: 607785.82 | AQ8: 360760.39 | AR8: 41612.685 | AS8: 603682.15 | AT8: 2.5115017e+08 | AU8: 753293.48 | AV8: 468986.1 | AW8: 1222279.6 | AX8: 0 | AY8: 1222279.6 | AZ8: 0 | BA8: -2627614.6 | BB8: -2627614.6 | BC8: 260795.54 | BD8: -1144539.5 | BE8: 14933018 | BF8: 2.3507261e+08
B9: 石油和天然气开采产品 | C9: ISIC 06 | D9: 0 | E9: 44377.409 | F9: 535454.39 | G9: 31524.519 | H9: 15664.728 | I9: 0 | J9: 0 | K9: 0 | L9: 59261.943 | M9: 1.8788629e+08 | N9: 16889360 | O9: 26683.811 | P9: 822898.06 | Q9: 1363725.2 | R9: 372310.78 | S9: 752409.26 | T9: 586961.7 | U9: 564473.99 | V9: 372468.27 | W9: 425241.53 | X9: 143883.1 | Y9: 68067.405 | Z9: 0 | AA9: 0 | AB9: 6735286.1 | AC9: 33825564 | AD9: 0 | AE9: 0 | AF9: 0 | AG9: 487.91953 | AH9: 0 | AI9: 0 | AJ9: 0 | AK9: 0 | AL9: 0 | AM9: 2507.1572 | AN9: 0 | AO9: 0 | AP9: 0 | AQ9: 34579.89 | AR9: 1756.0257 | AS9: 48307.892 | AT9: 2.5160955e+08 | AU9: 0 | AV9: 0 | AW9: 0 | AX9: 0 | AY9: 0 | AZ9: 0 | BA9: 288640.91 | BB9: 288640.91 | BC9: 1085317.4 | BD9: 1373958.3 | BE9: 1.4529394e+08 | BF9: 1.0768957e+08
B10: 金属矿采选产品&非金属矿 | C10: ISIC 07T08 | D10: 2307.8115 | E10: 45270.046 | F10: 20550.068 | G10: 12059565 | H10: 74468.261 | I10: 62486.304 | J10: 20915.922 | K10: 14130.601 | L10: 917816.89 | M10: 351666.07 | N10: 13663939 | O10: 218560.81 | P10: 57763.344 | Q10: 51091549 | R10: 1.3243884e+08 | S10: 78502943 | T10: 6503772.5 | U10: 64839.412 | V10: 122513 | W10: 165447.68 | X10: 51425.009 | Y10: 614877.85 | Z10: 90520.249 | AA10: 56747.979 | AB10: 106588.82 | AC10: 0 | AD10: 0 | AE10: 24113819 | AF10: 60555.457 | AG10: 179268.15 | AH10: 4016.8528 | AI10: 87.113672 | AJ10: 747.23883 | AK10: 376.87524 | AL10: 1678.8514 | AM10: 333550.56 | AN10: 3880.5923 | AO10: 3727.6437 | AP10: 2965.1177 | AQ10: 1023.0554 | AR10: 5435.0281 | AS10: 31541.554 | AT10: 3.2204805e+08 | AU10: 0 | AV10: 0 | AW10: 0 | AX10: 0 | AY10: 0 | AZ10: 0 | BA10: 2801192.3 | BB10: 2801192.3 | BC10: 3333103.9 | BD10: 6134296.2 | BE10: 1.3464774e+08 | BF10: 1.935346e+08
B11: 开采辅助活动和其他采矿产品 | C11: ISIC 09 | D11: 0 | E11: 1372272.6 | F11: 16942467 | G11: 1047957.7 | H11: 177012.62 | I11: 466046.59 | J11: 0 | K11: 0 | L11: 0 | M11: 0 | N11: 0 | O11: 0 | P11: 0 | Q11: 0 | R11: 0 | S11: 0 | T11: 0 | U11: 0 | V11: 0 | W11: 0 | X11: 0 | Y11: 0 | Z11: 12.672237 | AA11: 0 | AB11: 231004.91 | AC11: 0 | AD11: 0 | AE11: 0 | AF11: 0 | AG11: 0 | AH11: 0 | AI11: 0 | AJ11: 0 | AK11: 0 | AL11: 0 | AM11: 0 | AN11: 0 | AO11: 0 | AP11: 0 | AQ11: 0 | AR11: 0 | AS11: 0 | AT11: 20236774 | AU11: 0 | AV11: 0 | AW11: 0 | AX11: 0 | AY11: 0 | AZ11: 0 | BA11: 0 | BB11: 0 | BC11: 0 | BD11: 0 | BE11: 0 | BF11: 20236774
B12: 食品和烟草 | C12: ISIC 10T12 | D12: 1.0818487e+08 | E12: 413271.66 | F12: 79328.127 | G12: 942010.65 | H12: 15471.043 | I12: 2.4937249e+08 | J12: 14128692 | K12: 1247437.6 | L12: 3016090.2 | M12: 3256002.6 | N12: 25114335 | O12: 7560676.1 | P12: 750764.12 | Q12: 1766033.1 | R12: 3822314.4 | S12: 4171930.4 | T12: 2846827.7 | U12: 4402856.9 | V12: 2451141.6 | W12: 2157646.4 | X12: 1244965.2 | Y12: 4524092.6 | Z12: 7303684.3 | AA12: 618269.9 | AB12: 5006459.1 | AC12: 538269.51 | AD12: 432454.55 | AE12: 5743107.4 | AF12: 2301664 | AG12: 7651112.8 | AH12: 1.2774375e+08 | AI12: 5595412.7 | AJ12: 2856239.9 | AK12: 4673588.7 | AL12: 16568941 | AM12: 4782871.6 | AN12: 3289851.4 | AO12: 7513197.7 | AP12: 12503171 | AQ12: 7006157.7 | AR12: 9671567.6 | AS12: 7647553.5 | AT12: 6.7966914e+08 | AU12: 1.5618843e+08 | AV12: 4.5232673e+08 | AW12: 6.0851517e+08 | AX12: 0 | AY12: 6.0851517e+08 | AZ12: 0 | BA12: 8525640.2 | BB12: 8525640.2 | BC12: 35833494 | BD12: 6.528743e+08 | BE12: 81180640 | BF12: 1.2513628e+09
B13: 纺织品、纺织服装鞋帽皮革羽绒及其制品 | C13: ISIC 13T15 | D13: 255022.54 | E13: 1536716.5 | F13: 172891.15 | G13: 431377.15 | H13: 299060.73 | I13: 3696564.2 | J13: 3.1484617e+08 | K13: 8109575.9 | L13: 21141410 | M13: 892568.3 | N13: 3692227 | O13: 4066224.9 | P13: 3366898.1 | Q13: 4050298.9 | R13: 649060.66 | S13: 445858.55 | T13: 2025532.9 | U13: 1951908.6 | V13: 1960493.2 | W13: 5639280.4 | X13: 1374959.5 | Y13: 3039653 | Z13: 3035965.5 | AA13: 4187381.8 | AB13: 864761.17 | AC13: 343622.09 | AD13: 391871.28 | AE13: 4541077.5 | AF13: 3219495.3 | AG13: 5114728.6 | AH13: 3509705.2 | AI13: 999494.99 | AJ13: 4708210.4 | AK13: 2106065.8 | AL13: 16680635 | AM13: 2606793.1 | AN13: 1524598.3 | AO13: 2503390.6 | AP13: 1549810.4 | AQ13: 9533818.8 | AR13: 4734179.3 | AS13: 25315084 | AT13: 4.7300487e+08 | AU13: 23013748 | AV13: 1.0819378e+08 | AW13: 1.3120753e+08 | AX13: 0 | AY13: 1.3120753e+08 | AZ13: 0 | BA13: -3571111.2 | BB13: -3571111.2 | BC13: 1.8680114e+08 | BD13: 3.1443756e+08 | BE13: 30055498 | BF13: 7.5738693e+08
B14: 木材加工品和家具 | C14: ISIC 16 | D14: 336188.95 | E14: 3559037.5 | F14: 156891.3 | G14: 254624.37 | H14: 6327.7151 | I14: 845240.04 | J14: 918481.02 | K14: 81780667 | L14: 90084970 | M14: 186690.2 | N14: 1302287.3 | O14: 114696.06 | P14: 708459.64 | Q14: 1957227.2 | R14: 49068.256 | S14: 185262.26 | T14: 4792477.8 | U14: 931517.23 | V14: 637156.81 | W14: 5926683.2 | X14: 652732.73 | Y14: 1177748.8 | Z14: 1019650 | AA14: 1295524.2 | AB14: 201717.8 | AC14: 4011.8598 | AD14: 3316.5085 | AE14: 57246609 | AF14: 423651.48 | AG14: 934919.87 | AH14: 196032.43 | AI14: 922455.74 | AJ14: 474744.04 | AK14: 546486.36 | AL14: 599781.95 | AM14: 50562.204 | AN14: 401102.15 | AO14: 635895.59 | AP14: 342879.72 | AQ14: 75136.026 | AR14: 319747.38 | AS14: 3983063.1 | AT14: 1.8446106e+08 | AU14: 5007508 | AV14: 17646337 | AW14: 22653845 | AX14: 0 | AY14: 22653845 | AZ14: 21595789 | BA14: 1674063.1 | BB14: 23269852 | BC14: 44765297 | BD14: 90688994 | BE14: 9736870.7 | BF14: 2.6541318e+08
B15: 造纸印刷和文教体育用品 | C15: ISIC 17T18 | D15: 1025682.3 | E15: 31068.882 | F15: 9688.6354 | G15: 315134.03 | H15: 18042.408 | I15: 13214440 | J15: 3599305.4 | K15: 2513515.7 | L15: 1.0517187e+08 | M15: 357515.63 | N15: 4061404.6 | O15: 4907967.4 | P15: 1782237.4 | Q15: 8915729.5 | R15: 89427.25 | S15: 336660.37 | T15: 1916810.8 | U15: 1926288.9 | V15: 1841924.1 | W15: 1597372.5 | X15: 344645.46 | Y15: 5512884.5 | Z15: 5349964.6 | AA15: 807927.26 | AB15: 458088.57 | AC15: 13078.613 | AD15: 21179.986 | AE15: 5313847 | AF15: 8789370.8 | AG15: 4327923.9 | AH15: 1732626.8 | AI15: 27520721 | AJ15: 20038604 | AK15: 5345538.8 | AL15: 69510376 | AM15: 2605460.1 | AN15: 5513422.2 | AO15: 1759661.7 | AP15: 12646201 | AQ15: 288424.63 | AR15: 7453946.6 | AS15: 20046565 | AT15: 3.5651903e+08 | AU15: 6120942 | AV15: 29346782 | AW15: 35467724 | AX15: 0 | AY15: 35467724 | AZ15: 4281134.6 | BA15: -8038986.6 | BB15: -3757852 | BC15: 66074535 | BD15: 97784407 | BE15: 25910671 | BF15: 4.2839277e+08
B16: 石油、炼焦产品和核燃料加工品 | C16: ISIC 19 | D16: 4991926.8 | E16: 700362.55 | F16: 395976.19 | G16: 7776692.3 | H16: 799185.8 | I16: 1015050.6 | J16: 1120310.3 | K16: 1004346.3 | L16: 1858172.8 | M16: 22688076 | N16: 63847205 | O16: 474305.06 | P16: 2190479.3 | Q16: 19987604 | R16: 42144147 | S16: 7221065.2 | T16: 3078282.8 | U16: 2035296.8 | V16: 1035075.2 | W16: 1106854 | X16: 444478.82 | Y16: 1121539.9 | Z16: 1058861.3 | AA16: 836932.65 | AB16: 10310485 | AC16: 1882494.5 | AD16: 38463.432 | AE16: 37120733 | AF16: 3295901.8 | AG16: 96331786 | AH16: 1029117.6 | AI16: 1116149.6 | AJ16: 3729490.6 | AK16: 1528256.1 | AL16: 19256951 | AM16: 1475382.6 | AN16: 12374899 | AO16: 1218116.8 | AP16: 2786127.9 | AQ16: 239725.61 | AR16: 469119.18 | AS16: 5767314 | AT16: 3.8789839e+08 | AU16: 5745628.2 | AV16: 28313585 | AW16: 34059213 | AX16: 0 | AY16: 34059213 | AZ16: 0 | BA16: -5955399.2 | BB16: -5955399.2 | BC16: 15981224 | BD16: 44085038 | BE16: 22650148 | BF16: 4.0933328e+08
B17: 化学原料和化学制品制造业&化学纤维制造业 | C17: ISIC 20 | D17: 75932742 | E17: 2724058.2 | F17: 3946860.5 | G17: 9732267.1 | H17: 1246400.1 | I17: 5072727.7 | J17: 54593583 | K17: 16223100 | L17: 51348513 | M17: 14670765 | N17: 2.9296505e+08 | O17: 11936419 | P17: 1.1027181e+08 | Q17: 31280002 | R17: 3761259 | S17: 9341339.8 | T17: 10641344 | U17: 4653059.2 | V17: 2243331.6 | W17: 6970340.2 | X17: 2118210.8 | Y17: 26478745 | Z17: 15451768 | AA17: 5086887.6 | AB17: 221438.67 | AC17: 31293.166 | AD17: 2463333.3 | AE17: 75178170 | AF17: 101065.7 | AG17: 988410.01 | AH17: 2502380.8 | AI17: 1218070.3 | AJ17: 301378.84 | AK17: 339047.64 | AL17: 4302489.1 | AM17: 14442889 | AN17: 20348720 | AO17: 13522936 | AP17: 7517280.1 | AQ17: 538883.13 | AR17: 1609725.6 | AS17: 8727065.8 | AT17: 9.0682206e+08 | AU17: 2773014.2 | AV17: 19771297 | AW17: 22544311 | AX17: 0 | AY17: 22544311 | AZ17: 0 | BA17: -17407692 | BB17: -17407692 | BC17: 66207878 | BD17: 71344496 | BE17: 1.2306996e+08 | BF17: 8.5509659e+08
