Workbook

Sheet About
A1: DSCF Distributed Solar Cap Factor
A3: source: | B3: Distributed photovoltaic installed capacity and power generation in each province
B4: Energy Bureau photovoltaic data
B5: 2019
B6: China Energy Bureau
B7: https://www.nea.gov.cn/2019-08/23/c_138330885.htm
A10: note: | B10: Photovoltaic installed capacity data comes from the National Bureau of Statistics. Multiplied by the annual effective sunshine hours in each province, the annual photovoltaic power generation capacity is obtained. By consulting experts, the upper limit of photovoltaic coverage of each building is obtained, and then the expected changes in photovoltaic power generation are obtained.Divide the actual power generation by the installed capacity to get the capacity factor

Sheet Distributed photoelectric data
A1: 地区 | B1: 装机容量（万千瓦） | J1: 发电量（亿千瓦时） | R1: 容量因子
B2: 2017 | C2: 2018 | D2: 2019 | E2: 2020 | F2: 2021 | G2: 2022 | H2: 2023 | I2: 2024 | J2: 2017 | K2: 2018 | L2: 2019 | M2: 2020 | N2: 2021 | O2: 2022 | P2: 2023 | Q2: 2024 | R2: 2017 | S2: 2018 | T2: 2019 | U2: 2020 | V2: 2021 | W2: 2022 | X2: 2023 | Y2: 2024
A3: 全国 | B3: 3658 | C3: 5027 | D3: 6211 | E3: 7827 | F3: 10750.8 | G3: 15762 | H3: 25443.8 | I3: 37478 | J3: 154 | K3: 388 | L3: 541 | M3: 679 | N3: 925 | O3: 1437 | P3: 2082 | Q3: 3462 | R3: =J3*10^4/B3/8760 -> 0.048058799 | S3: =K3*10^4/C3/8760 -> 0.088108688 | T3: =L3*10^4/D3/8760 -> 0.099433249 | U3: =M3*10^4/E3/8760 -> 0.099030811 | V3: =N3*10^4/F3/8760 -> 0.098219302 | W3: =O3*10^4/G3/8760 -> 0.10407378 | X3: =P3*10^4/H3/8760 -> 0.093410274 | Y3: =Q3*10^4/I3/8760 -> 0.10544999
A4: 北京市 | B4: 22 | C4: 35 | D4: 46 | E4: 56 | F4: 75 | G4: 90.2 | J4: 1 | K4: 2 | L4: 4 | M4: 5 | N4: 5 | R4: =J4*10^4/B4/8760 -> 0.051888751 | S4: =K4*10^4/C4/8760 -> 0.065231572 | T4: =L4*10^4/D4/8760 -> 0.099265436 | U4: =M4*10^4/E4/8760 -> 0.10192433 | V4: =N4*10^4/F4/8760 -> 0.076103501
A5: 天津市 | B5: 15 | C5: 31 | D5: 38 | E5: 45 | F5: 58.9 | G5: 98.9 | J5: 1 | K5: 2 | L5: 3 | M5: 4 | N5: 4 | R5: =J5*10^4/B5/8760 -> 0.076103501 | S5: =K5*10^4/C5/8760 -> 0.073648549 | T5: =L5*10^4/D5/8760 -> 0.090122567 | U5: =M5*10^4/E5/8760 -> 0.10147133 | V5: =N5*10^4/F5/8760 -> 0.077524789
A6: 河北省 | B6: 351 | C6: 378 | D6: 513 | E6: 747 | F6: 1262.5 | G6: 1861.2 | J6: 11 | K6: 32 | L6: 53 | M6: 70 | N6: 114 | R6: =J6*10^4/B6/8760 -> 0.03577515 | S6: =K6*10^4/C6/8760 -> 0.096639366 | T6: =L6*10^4/D6/8760 -> 0.11793817 | U6: =M6*10^4/E6/8760 -> 0.10697279 | V6: =N6*10^4/F6/8760 -> 0.1030788
A7: 山西省 | B7: 60 | C7: 183 | D7: 231 | E7: 280 | F7: 355.9 | G7: 438.7 | J7: 5 | K7: 14 | L7: 25 | M7: 31 | N7: 40 | R7: =J7*10^4/B7/8760 -> 0.095129376 | S7: =K7*10^4/C7/8760 -> 0.087331886 | T7: =L7*10^4/D7/8760 -> 0.12354464 | U7: =M7*10^4/E7/8760 -> 0.12638617 | V7: =N7*10^4/F7/8760 -> 0.12830037
A8: 内蒙古自治区 | B8: 2 | C8: 13 | D8: 80 | E8: 88 | F8: 102.5 | G8: 121.2 | J8: 0.3 | K8: 1 | L8: 3 | M8: 13 | N8: 15 | R8: =J8*10^4/B8/8760 -> 0.17123288 | S8: =K8*10^4/C8/8760 -> 0.087811732 | T8: =L8*10^4/D8/8760 -> 0.042808219 | U8: =M8*10^4/E8/8760 -> 0.16863844 | V8: =N8*10^4/F8/8760 -> 0.16705647
A9: 辽宁省 | B9: 38 | C9: 83 | D9: 97 | E9: 118 | F9: 160 | G9: 219.3 | J9: 3 | K9: 7 | L9: 10 | M9: 12 | N9: 14 | R9: =J9*10^4/B9/8760 -> 0.090122567 | S9: =K9*10^4/C9/8760 -> 0.096275513 | T9: =L9*10^4/D9/8760 -> 0.11768583 | U9: =M9*10^4/E9/8760 -> 0.11609009 | V9: =N9*10^4/F9/8760 -> 0.099885845
A10: 吉林省 | B10: 52 | C10: 62 | D10: 69 | E10: 76 | F10: 80.1 | G10: 92 | J10: 2 | K10: 7 | L10: 9 | M10: 9 | N10: 10 | R10: =J10*10^4/B10/8760 -> 0.043905866 | S10: =K10*10^4/C10/8760 -> 0.12888496 | T10: =L10*10^4/D10/8760 -> 0.14889815 | U10: =M10*10^4/E10/8760 -> 0.13518385 | V10: =N10*10^4/F10/8760 -> 0.14251592
A11: 黑龙江省 | B11: 30 | C11: 74 | D11: 79 | E11: 83 | F11: 89.8 | G11: 108.4 | J11: 1 | K11: 5 | L11: 9 | M11: 10 | N11: 10 | R11: =J11*10^4/B11/8760 -> 0.03805175 | S11: =K11*10^4/C11/8760 -> 0.077131926 | T11: =L11*10^4/D11/8760 -> 0.13005029 | U11: =M11*10^4/E11/8760 -> 0.13753645 | V11: =N11*10^4/F11/8760 -> 0.12712166
A12: 上海市 | B12: 59 | C12: 82 | D12: 102 | E12: 117 | F12: 144.2 | G12: 170.9 | J12: 2 | K12: 5 | L12: 7 | M12: 9 | N12: 12 | R12: =J12*10^4/B12/8760 -> 0.038696695 | S12: =K12*10^4/C12/8760 -> 0.06960686 | T12: =L12*10^4/D12/8760 -> 0.078341839 | U12: =M12*10^4/E12/8760 -> 0.087811732 | V12: =N12*10^4/F12/8760 -> 0.094997435
A13: 江苏省 | B13: 327 | C13: 540 | D13: 664 | E13: 788 | F13: 974.9 | G13: 1555.2 | J13: 19 | K13: 40 | L13: 53 | M13: 61 | N13: 77 | R13: =J13*10^4/B13/8760 -> 0.066328739 | S13: =K13*10^4/C13/8760 -> 0.084559445 | T13: =L13*10^4/D13/8760 -> 0.091117896 | U13: =M13*10^4/E13/8760 -> 0.088368913 | V13: =N13*10^4/F13/8760 -> 0.090162625
A14: 浙江省 | B14: 499 | C14: 777 | D14: 925 | E14: 1067 | F14: 1264.8 | G14: 1925.5 | J14: 31 | K14: 63 | L14: 75 | M14: 88 | N14: 103 | R14: =J14*10^4/B14/8760 -> 0.070918092 | S14: =K14*10^4/C14/8760 -> 0.092558312 | T14: =L14*10^4/D14/8760 -> 0.092558312 | U14: =M14*10^4/E14/8760 -> 0.094148661 | V14: =N14*10^4/F14/8760 -> 0.092963242
A15: 安徽省 | B15: 323 | C15: 441 | D15: 480 | E15: 544 | F15: 759.8 | G15: 1090.3 | J15: 18 | K15: 36 | L15: 46 | M15: 45 | N15: 52 | R15: =J15*10^4/B15/8760 -> 0.063615929 | S15: =K15*10^4/C15/8760 -> 0.09318796 | T15: =L15*10^4/D15/8760 -> 0.10939878 | U15: =M15*10^4/E15/8760 -> 0.094429895 | V15: =N15*10^4/F15/8760 -> 0.078126784
... A26: 四川省 | B26: 19 | C26: 13 | D26: 19 | E26: 22 | F26: 26.9 | G26: 33.2 | J26: 1 | K26: 1 | L26: 2 | M26: 2 | N26: 2 | R26: =J26*10^4/B26/8760 -> 0.060081711 | S26: =K26*10^4/C26/8760 -> 0.087811732 | T26: =L26*10^4/D26/8760 -> 0.12016342 | U26: =M26*10^4/E26/8760 -> 0.1037775 | V26: =N26*10^4/F26/8760 -> 0.084873793
A27: 贵州省 | C27: 17 | D27: 19 | E27: 19 | F27: 19.4 | G27: 23.7 | K27: 1 | L27: 1 | M27: 1 | N27: 1 | R27: =J27*10^4/B27/8760 -> #DIV/0! | S27: =K27*10^4/C27/8760 -> 0.067150148 | T27: =L27*10^4/D27/8760 -> 0.060081711 | U27: =M27*10^4/E27/8760 -> 0.060081711 | V27: =N27*10^4/F27/8760 -> 0.058842913
A28: 云南省 | B28: 0.5 | C28: 14 | D28: 25 | E28: 38 | F28: 47.2 | G28: 60.1 | J28: 0.3 | K28: 1 | L28: 2 | M28: 3 | N28: 4 | R28: =S28 -> 0.081539465 | S28: =K28*10^4/C28/8760 -> 0.081539465 | T28: =L28*10^4/D28/8760 -> 0.091324201 | U28: =M28*10^4/E28/8760 -> 0.090122567 | V28: =N28*10^4/F28/8760 -> 0.096741738
A29: 西藏自治区 | F29: 2.2 | G29: 2.2 | N29: 0.2 | R29: =J29*10^4/B29/8760 -> #DIV/0! | S29: =K29*10^4/C29/8760 -> #DIV/0! | T29: =L29*10^4/D29/8760 -> #DIV/0! | U29: =M29*10^4/E29/8760 -> #DIV/0! | V29: =N29*10^4/F29/8760 -> 0.1037775
A30: 陕西省 | B30: 51 | C30: 76 | D30: 161 | E30: 194 | F30: 210.9 | G30: 322.5 | J30: 2 | K30: 6 | L30: 14 | M30: 16 | N30: 20 | R30: =J30*10^4/B30/8760 -> 0.044766765 | S30: =K30*10^4/C30/8760 -> 0.090122567 | T30: =L30*10^4/D30/8760 -> 0.099265436 | U30: =M30*10^4/E30/8760 -> 0.094148661 | V30: =N30*10^4/F30/8760 -> 0.10825534
A31: 甘肃省 | B31: 18 | C31: 49 | D31: 71 | E31: 74 | F31: 77.1 | G31: 85.5 | J31: 1 | K31: 2 | L31: 6 | M31: 9 | N31: 9 | R31: =J31*10^4/B31/8760 -> 0.063419584 | S31: =K31*10^4/C31/8760 -> 0.04659398 | T31: =L31*10^4/D31/8760 -> 0.096469226 | U31: =M31*10^4/E31/8760 -> 0.13883747 | V31: =N31*10^4/F31/8760 -> 0.13325516
A32: 青海省 | B32: 5 | C32: 10 | D32: 15 | E32: 17 | F32: 16 | G32: 15.7 | J32: 0.3 | K32: 1 | L32: 2 | M32: 2 | N32: 2 | R32: =J32*10^4/B32/8760 -> 0.068493151 | S32: =K32*10^4/C32/8760 -> 0.11415525 | T32: =L32*10^4/D32/8760 -> 0.152207 | U32: =M32*10^4/E32/8760 -> 0.1343003 | V32: =N32*10^4/F32/8760 -> 0.14269406
A33: 宁夏回族自治区 | B33: 33 | C33: 55 | D33: 74 | E33: 75 | F33: 80.6 | G33: 92.2 | J33: 3 | K33: 4 | L33: 8 | M33: 10 | N33: 10 | R33: =J33*10^4/B33/8760 -> 0.1037775 | S33: =K33*10^4/C33/8760 -> 0.083022001 | T33: =L33*10^4/D33/8760 -> 0.12341108 | U33: =M33*10^4/E33/8760 -> 0.152207 | V33: =N33*10^4/F33/8760 -> 0.14163183
A34: 新疆维吾尔自治区 | B34: 1 | C34: 2 | D34: 15 | E34: 16 | F34: 17.2 | G34: 26.9 | J34: 0.01 | K34: 0.1 | L34: 1 | M34: 2 | N34: 2 | R34: =J34*10^4/B34/8760 -> 0.011415525 | S34: =K34*10^4/C34/8760 -> 0.057077626 | T34: =L34*10^4/D34/8760 -> 0.076103501 | U34: =M34*10^4/E34/8760 -> 0.14269406 | V34: =N34*10^4/F34/8760 -> 0.13273866
A35: 新疆生产建设兵团 | C35: 0
C38: 北京 | D38: 北京市 | J38: 全国 | K38: 全国 | L38: 全国 | N38: =J38=K38 -> TRUE | O38: =K38=L38 -> TRUE
C39: 天津 | D39: 天津市 | J39: 北京市 | K39: 北京市 | L39: 北京市 | N39: =J39=K39 -> TRUE | O39: =K39=L39 -> TRUE
C40: 河北 | D40: 河北省 | J40: 天津市 | K40: 天津市 | L40: 天津市 | N40: =J40=K40 -> TRUE | O40: =K40=L40 -> TRUE
C41: 山西 | D41: 山西省 | J41: 河北省 | K41: 河北省 | L41: 河北省 | N41: =J41=K41 -> TRUE | O41: =K41=L41 -> TRUE
C42: 内蒙古 | D42: 内蒙古自治区 | J42: 山西省 | K42: 山西省 | L42: 山西省 | N42: =J42=K42 -> TRUE | O42: =K42=L42 -> TRUE
C43: 辽宁 | D43: 辽宁省 | J43: 内蒙古自治区 | K43: 内蒙古自治区 | L43: 内蒙古自治区 | N43: =J43=K43 -> TRUE | O43: =K43=L43 -> TRUE
C44: 吉林 | D44: 吉林省 | J44: 辽宁省 | K44: 辽宁省 | L44: 辽宁省 | N44: =J44=K44 -> TRUE | O44: =K44=L44 -> TRUE
C45: 黑龙江 | D45: 黑龙江省 | J45: 吉林省 | K45: 吉林省 | L45: 吉林省 | N45: =J45=K45 -> TRUE | O45: =K45=L45 -> TRUE
C46: 上海 | D46: 上海市 | J46: 黑龙江省 | K46: 黑龙江省 | L46: 黑龙江省 | N46: =J46=K46 -> TRUE | O46: =K46=L46 -> TRUE
C47: 江苏 | D47: 江苏省 | J47: 上海市 | K47: 上海市 | L47: 上海市 | N47: =J47=K47 -> TRUE | O47: =K47=L47 -> TRUE
C48: 浙江 | D48: 浙江省 | J48: 江苏省 | K48: 江苏省 | L48: 江苏省 | N48: =J48=K48 -> TRUE | O48: =K48=L48 -> TRUE
C49: 安徽 | D49: 安徽省 | J49: 浙江省 | K49: 浙江省 | L49: 浙江省 | N49: =J49=K49 -> TRUE | O49: =K49=L49 -> TRUE
... C70: 香港 | D70: 香港特别行政区 | J70: 新疆生产建设兵团 | K70: 新疆生产建设兵团 | L70: 新疆生产建设兵团 | N70: =J70=K70 -> TRUE | O70: =K70=L70 -> TRUE
C71: 澳门 | D71: 澳门特别行政区
C72: 新疆生产建设兵团 | D72: 新疆生产建设兵团

Sheet PV power generation data
A1: 地区 | B1: 装机容量（万千瓦） | O1: 发电量（亿千瓦时） | AB1: 运行小时数 | AE1: 运行小时折因子 | AH1: 容量因子
B2: 2010 | C2: 2011 | D2: 2012 | E2: 2013 | F2: 2014 | G2: 2015 | H2: 2016 | I2: 2017 | J2: 2018 | K2: 2019 | L2: 2020 | M2: 2021 | N2: 2022 | O2: 2010 | P2: 2011 | Q2: 2012 | R2: 2013 | S2: 2014 | T2: 2015 | U2: 2016 | V2: 2017 | W2: 2018 | X2: 2019 | Y2: 2020 | Z2: 2021 | AA2: 2022 | AB2: 2018年 | AC2: 2019年 | AD2: 2020年 | AE2: 2018年 | AF2: 2019年 | AG2: 2020年 | AH2: 2010 | AI2: 2011 | AJ2: 2012 | AK2: 2013 | AL2: 2014 | AM2: 2015 | AN2: 2016 | AO2: 2017 | AP2: 2018 | AQ2: 2019 | AR2: 2020 | AS2: 2021 | AT2: 2022
A3: 全国 | B3: 212.2 | C3: 240.9 | D3: 340.9 | E3: 1588.7 | F3: 2486.3 | G3: 4219 | H3: 7631 | I3: 13040 | J3: 17433 | K3: 20431 | L3: 25360 | M3: 30598.7 | N3: 39203.8 | O3: =SUM(O4:O35) -> 6.056 | P3: =SUM(P4:P35) -> 8.55 | Q3: =SUM(Q4:Q35) -> 36.6501 | R3: =SUM(R4:R35) -> 84.01 | S3: =SUM(S4:S35) -> 235.4 | T3: =SUM(T4:T35) -> 394.6 | U3: =SUM(U4:U35) -> 664.62 | V3: =SUM(V4:V35) -> 1178.4 | ... Z3: =SUM(Z4:Z35) -> 3271 | AB3: 1230 | AC3: 1291 | AD3: 1281 | AE3: =AB3/8760 -> 0.14041096 | AF3: =AC3/8760 -> 0.14737443 | AG3: =AD3/8760 -> 0.14623288 | AH3: =IFERROR(O3*10^4/B3/8760,"") -> 0.032578897 | AI3: =IFERROR(P3*10^4/C3/8760,"") -> 0.040515874 | AJ3: =IFERROR(Q3*10^4/D3/8760,"") -> 0.12272811 | AK3: =IFERROR(R3*10^4/E3/8760,"") -> 0.060364969 | AL3: =IFERROR(S3*10^4/F3/8760,"") -> 0.10808087 | AM3: =IFERROR(T3*10^4/G3/8760,"") -> 0.10676858 | AN3: =IFERROR(U3*10^4/H3/8760,"") -> 0.099423225 | AO3: =IFERROR(V3*10^4/I3/8760,"") -> 0.10315993 | ... AS3: =IFERROR(Z3*10^4/M3/8760,"") -> 0.12203193
A4: 北京市 | F4: 2.5 | G4: 8 | H4: 15 | I4: 25 | J4: 40 | K4: 51 | L4: 62 | M4: 80.1 | N4: 95.3 | S4: 0.2 | T4: 0.4 | U4: 1.1 | V4: 2 | W4: 3 | X4: 5 | Y4: 6 | Z4: 6 | AB4: 1261 | AC4: 1323 | AD4: 1242 | AE4: =AB4/8760 -> 0.14394977 | AF4: =AC4/8760 -> 0.1510274 | AG4: =AD4/8760 -> 0.14178082 | AH4: =IFERROR(O4*10^4/B4/8760,"") | AI4: =IFERROR(P4*10^4/C4/8760,"") | AJ4: =IFERROR(Q4*10^4/D4/8760,"") | AK4: =IFERROR(R4*10^4/E4/8760,"") | AL4: =IFERROR(S4*10^4/F4/8760,"") -> 0.091324201 | AM4: =IFERROR(T4*10^4/G4/8760,"") -> 0.057077626 | AN4: =IFERROR(U4*10^4/H4/8760,"") -> 0.083713851 | AO4: =IFERROR(V4*10^4/I4/8760,"") -> 0.091324201 | ... AS4: =IFERROR(Z4*10^4/M4/8760,"") -> 0.085509551
A5: 天津市 | D5: 0.2 | E5: 1.6 | F5: 4.7 | G5: 12 | H5: 60 | I5: 68 | J5: 128 | K5: 143 | L5: 164 | M5: 177.8 | N5: 220.6 | R5: 0.02 | S5: 0.3 | T5: 0.6 | U5: 3 | V5: 6.2 | W5: 8 | X5: 15 | Y5: 19 | Z5: 20 | AB5: 864 | AC5: 1144 | AD5: 1265 | AE5: =AB5/8760 -> 0.098630137 | AF5: =AC5/8760 -> 0.13059361 | AG5: =AD5/8760 -> 0.14440639 | AH5: =IFERROR(O5*10^4/B5/8760,"") | AI5: =IFERROR(P5*10^4/C5/8760,"") | AJ5: =IFERROR(Q5*10^4/D5/8760,"") -> 0 | AK5: =IFERROR(R5*10^4/E5/8760,"") -> 0.014269406 | AL5: =IFERROR(S5*10^4/F5/8760,"") -> 0.072865054 | AM5: =IFERROR(T5*10^4/G5/8760,"") -> 0.057077626 | AN5: =IFERROR(U5*10^4/H5/8760,"") -> 0.057077626 | AO5: =IFERROR(V5*10^4/I5/8760,"") -> 0.10408273 | ... AS5: =IFERROR(Z5*10^4/M5/8760,"") -> 0.12840861
A6: 河北省 | C6: 14.7 | E6: 25.1 | F6: 114.5 | G6: 222 | H6: 443 | I6: 868 | J6: 1234 | K6: 1474 | L6: 2190 | M6: 2921.3 | N6: 3855.3 | P6: 0.4 | R6: 1.1 | S6: 5.8 | T6: 16 | U6: 40 | V6: 77 | W6: 126 | X6: 176 | Y6: 211 | Z6: 279 | AB6: 1275 | AC6: 1379 | AD6: 1336 | AE6: =AB6/8760 -> 0.14554795 | AF6: =AC6/8760 -> 0.15742009 | AG6: =AD6/8760 -> 0.15251142 | AH6: =IFERROR(O6*10^4/B6/8760,"") | AI6: =IFERROR(P6*10^4/C6/8760,"") -> 0.031062653 | AJ6: =IFERROR(Q6*10^4/D6/8760,"") | AK6: =IFERROR(R6*10^4/E6/8760,"") -> 0.050028198 | AL6: =IFERROR(S6*10^4/F6/8760,"") -> 0.057825367 | AM6: =IFERROR(T6*10^4/G6/8760,"") -> 0.082274055 | AN6: =IFERROR(U6*10^4/H6/8760,"") -> 0.10307472 | AO6: =IFERROR(V6*10^4/I6/8760,"") -> 0.10126676 | ... AS6: =IFERROR(Z6*10^4/M6/8760,"") -> 0.10902446
A7: 山西省 | B7: 1.5 | C7: 2.7 | D7: 1.5 | E7: 3.5 | F7: 41.3 | G7: 111 | H7: 297 | I7: 590 | J7: 864 | K7: 1088 | L7: 1309 | M7: 1457.7 | N7: 1695.7 | O7: 0.006 | P7: 0.1 | Q7: 0.2 | R7: 0.5 | S7: 3.2 | T7: 8 | U7: 27 | V7: 56 | W7: 94 | X7: 128 | Y7: 159 | Z7: 189 | AB7: 1265 | AC7: 1307 | AD7: 1277 | AE7: =AB7/8760 -> 0.14440639 | AF7: =AC7/8760 -> 0.14920091 | AG7: =AD7/8760 -> 0.14577626 | AH7: =IFERROR(O7*10^4/B7/8760,"") -> 0.00456621 | AI7: =IFERROR(P7*10^4/C7/8760,"") -> 0.042279723 | AJ7: =IFERROR(Q7*10^4/D7/8760,"") -> 0.152207 | AK7: =IFERROR(R7*10^4/E7/8760,"") -> 0.16307893 | AL7: =IFERROR(S7*10^4/F7/8760,"") -> 0.088449589 | AM7: =IFERROR(T7*10^4/G7/8760,"") -> 0.082274055 | AN7: =IFERROR(U7*10^4/H7/8760,"") -> 0.1037775 | AO7: =IFERROR(V7*10^4/I7/8760,"") -> 0.10835075 | ... AS7: =IFERROR(Z7*10^4/M7/8760,"") -> 0.14800948
A8: 内蒙古自治区 | B8: 8.7 | C8: 8.7 | D8: 21 | E8: 136.8 | F8: 285.4 | G8: 471 | H8: 638 | I8: 743 | J8: 946 | K8: 1051 | L8: 1237 | M8: 1402 | N8: 1550.8 | O8: 0.1 | P8: 0.1 | Q8: 1.7 | R8: 6.2 | S8: 24.7 | T8: 57 | U8: 83 | V8: 113 | W8: 130 | X8: 163 | Y8: 188 | Z8: 212 | AB8: 1632 | AC8: 1663 | AD8: 1654 | AE8: =AB8/8760 -> 0.18630137 | AF8: =AC8/8760 -> 0.18984018 | AG8: =AD8/8760 -> 0.18881279 | AH8: =IFERROR(O8*10^4/B8/8760,"") -> 0.013121293 | AI8: =IFERROR(P8*10^4/C8/8760,"") -> 0.013121293 | AJ8: =IFERROR(Q8*10^4/D8/8760,"") -> 0.092411394 | AK8: =IFERROR(R8*10^4/E8/8760,"") -> 0.051737029 | AL8: =IFERROR(S8*10^4/F8/8760,"") -> 0.09879589 | AM8: =IFERROR(T8*10^4/G8/8760,"") -> 0.13814967 | AN8: =IFERROR(U8*10^4/H8/8760,"") -> 0.14850918 | AO8: =IFERROR(V8*10^4/I8/8760,"") -> 0.17361431 | ... AS8: =IFERROR(Z8*10^4/M8/8760,"") -> 0.17261707
A9: 辽宁省 | D9: 1 | E9: 2.3 | F9: 7 | G9: 16 | H9: 52 | I9: 223 | J9: 302 | K9: 343 | L9: 400 | M9: 477.5 | N9: 600.6 | Q9: 0.0001 | R9: 0.2 | S9: 0.7 | T9: 1 | U9: 4 | V9: 12 | W9: 32 | X9: 42 | Y9: 51 | Z9: 55 | AB9: 1235 | AC9: 1396 | AD9: 1453 | AE9: =AB9/8760 -> 0.14098174 | AF9: =AC9/8760 -> 0.15936073 | AG9: =AD9/8760 -> 0.16586758 | AH9: =IFERROR(O9*10^4/B9/8760,"") | AI9: =IFERROR(P9*10^4/C9/8760,"") | AJ9: =IFERROR(Q9*10^4/D9/8760,"") -> 0.00011415525 | AK9: =IFERROR(R9*10^4/E9/8760,"") -> 0.099265436 | AL9: =IFERROR(S9*10^4/F9/8760,"") -> 0.11415525 | AM9: =IFERROR(T9*10^4/G9/8760,"") -> 0.071347032 | AN9: =IFERROR(U9*10^4/H9/8760,"") -> 0.087811732 | AO9: =IFERROR(V9*10^4/I9/8760,"") -> 0.061428835 | ... AS9: =IFERROR(Z9*10^4/M9/8760,"") -> 0.13148772
A10: 吉林省 | E10: 1 | F10: 6.1 | G10: 7 | H10: 56 | I10: 159 | J10: 265 | K10: 274 | L10: 338 | M10: 345.9 | N10: 386.6 | R10: 0.03 | S10: 0.5 | T10: 1 | U10: 3 | V10: 13 | W10: 24 | X10: 40 | Y10: 45 | Z10: 52 | AB10: 1332 | AC10: 1504 | AD10: 1531 | AE10: =AB10/8760 -> 0.15205479 | AF10: =AC10/8760 -> 0.1716895 | AG10: =AD10/8760 -> 0.17477169 | AH10: =IFERROR(O10*10^4/B10/8760,"") | AI10: =IFERROR(P10*10^4/C10/8760,"") | AJ10: =IFERROR(Q10*10^4/D10/8760,"") | AK10: =IFERROR(R10*10^4/E10/8760,"") -> 0.034246575 | AL10: =IFERROR(S10*10^4/F10/8760,"") -> 0.093569878 | AM10: =IFERROR(T10*10^4/G10/8760,"") -> 0.16307893 | AN10: =IFERROR(U10*10^4/H10/8760,"") -> 0.061154599 | AO10: =IFERROR(V10*10^4/I10/8760,"") -> 0.093334482 | ... AS10: =IFERROR(Z10*10^4/M10/8760,"") -> 0.1716124
A11: 黑龙江省 | E11: 1.1 | F11: 1.1 | G11: 2 | H11: 17 | I11: 94 | J11: 215 | K11: 274 | L11: 318 | M11: 419.8 | N11: 475.3 | S11: 0.2 | T11: 0.2 | U11: 1.3 | V11: 6 | W11: 20 | X11: 32 | Y11: 43 | Z11: 51 | AB11: 1447 | AC11: 1566 | AD11: 1604 | AE11: =AB11/8760 -> 0.16518265 | AF11: =AC11/8760 -> 0.17876712 | AG11: =AD11/8760 -> 0.18310502 | AH11: =IFERROR(O11*10^4/B11/8760,"") | AI11: =IFERROR(P11*10^4/C11/8760,"") | AJ11: =IFERROR(Q11*10^4/D11/8760,"") | AK11: =IFERROR(R11*10^4/E11/8760,"") -> 0 | AL11: =IFERROR(S11*10^4/F11/8760,"") -> 0.207555 | AM11: =IFERROR(T11*10^4/G11/8760,"") -> 0.11415525 | AN11: =IFERROR(U11*10^4/H11/8760,"") -> 0.087295192 | AO11: =IFERROR(V11*10^4/I11/8760,"") -> 0.072865054 | ... AS11: =IFERROR(Z11*10^4/M11/8760,"") -> 0.13868313
A12: 上海市 | B12: 0.7 | C12: 1.4 | D12: 0.7 | E12: 0.7 | F12: 8.7 | G12: 21 | H12: 35 | I12: 58 | J12: 89 | K12: 109 | L12: 137 | M12: 168.3 | N12: 194.8 | O12: 0.1 | P12: 0.14 | Q12: 0.1 | R12: 0.1 | S12: 0.8 | T12: 1 | U12: 1 | V12: 3 | W12: 6 | X12: 8 | Y12: 10 | Z12: 15 | AB12: 946 | AC12: 867 | AD12: 861 | AE12: =AB12/8760 -> 0.10799087 | AF12: =AC12/8760 -> 0.098972603 | AG12: =AD12/8760 -> 0.098287671 | AH12: =IFERROR(O12*10^4/B12/8760,"") -> 0.16307893 | AI12: =IFERROR(P12*10^4/C12/8760,"") -> 0.11415525 | AJ12: =IFERROR(Q12*10^4/D12/8760,"") -> 0.16307893 | AK12: =IFERROR(R12*10^4/E12/8760,"") -> 0.16307893 | AL12: =IFERROR(S12*10^4/F12/8760,"") -> 0.10497035 | AM12: =IFERROR(T12*10^4/G12/8760,"") -> 0.054359643 | AN12: =IFERROR(U12*10^4/H12/8760,"") -> 0.032615786 | AO12: =IFERROR(V12*10^4/I12/8760,"") -> 0.05904582 | ... AS12: =IFERROR(Z12*10^4/M12/8760,"") -> 0.10174265
A13: 江苏省 | B13: 33 | C13: 39.6 | D13: 43 | E13: 104.6 | F13: 256.2 | G13: 422 | H13: 546 | I13: 907 | J13: 1332 | K13: 1486 | L13: 1684 | M13: 1916 | N13: 2508.5 | O13: 0.8 | P13: 1 | Q13: 4.2 | R13: 6 | S13: 13.9 | T13: 31 | U13: 47 | V13: 81 | W13: 120 | X13: 154 | Y13: 167 | Z13: 195 | AB13: 1059 | AC13: 1192 | AD13: 1165 | AE13: =AB13/8760 -> 0.12089041 | AF13: =AC13/8760 -> 0.13607306 | AG13: =AD13/8760 -> 0.13299087 | AH13: =IFERROR(O13*10^4/B13/8760,"") -> 0.027674 | AI13: =IFERROR(P13*10^4/C13/8760,"") -> 0.028827084 | AJ13: =IFERROR(Q13*10^4/D13/8760,"") -> 0.11150048 | AK13: =IFERROR(R13*10^4/E13/8760,"") -> 0.065481024 | AL13: =IFERROR(S13*10^4/F13/8760,"") -> 0.061934348 | AM13: =IFERROR(T13*10^4/G13/8760,"") -> 0.083858123 | AN13: =IFERROR(U13*10^4/H13/8760,"") -> 0.098265509 | AO13: =IFERROR(V13*10^4/I13/8760,"") -> 0.10194681 | ... AS13: =IFERROR(Z13*10^4/M13/8760,"") -> 0.11618097
A14: 浙江省 | C14: 0.8 | D14: 1.2 | E14: 18 | F14: 49.8 | G14: 164 | H14: 338 | I14: 814 | J14: 1138 | K14: 1339 | L14: 1517 | M14: 1841.8 | N14: 2539 | P14: 0.1 | Q14: 0.1 | R14: 0.8 | S14: 2.6 | T14: 8 | U14: 22 | V14: 56 | W14: 100 | X14: 119 | Y14: 131 | Z14: 155 | AB14: 1085 | AC14: 1104 | AD14: 998 | AE14: =AB14/8760 -> 0.12385845 | AF14: =AC14/8760 -> 0.1260274 | AG14: =AD14/8760 -> 0.11392694 | AH14: =IFERROR(O14*10^4/B14/8760,"") | AI14: =IFERROR(P14*10^4/C14/8760,"") -> 0.14269406 | AJ14: =IFERROR(Q14*10^4/D14/8760,"") -> 0.095129376 | AK14: =IFERROR(R14*10^4/E14/8760,"") -> 0.050735667 | AL14: =IFERROR(S14*10^4/F14/8760,"") -> 0.059599127 | AM14: =IFERROR(T14*10^4/G14/8760,"") -> 0.055685488 | AN14: =IFERROR(U14*10^4/H14/8760,"") -> 0.074302234 | AO14: =IFERROR(V14*10^4/I14/8760,"") -> 0.078534325 | ... AS14: =IFERROR(Z14*10^4/M14/8760,"") -> 0.09606941
A15: 安徽省 | C15: 0.4 | D15: 1.9 | E15: 5 | F15: 40 | G15: 121 | H15: 345 | I15: 888 | J15: 1118 | K15: 1254 | L15: 1370 | M15: 1706.8 | N15: 2154 | P15: 0.03 | Q15: 0.1 | R15: 0.3 | S15: 1 | T15: 4 | U15: 21 | V15: 62 | W15: 104 | X15: 125 | Y15: 130 | Z15: 155 | AB15: 1065 | AC15: 1102 | AD15: 1071 | AE15: =AB15/8760 -> 0.12157534 | AF15: =AC15/8760 -> 0.12579909 | AG15: =AD15/8760 -> 0.12226027 | AH15: =IFERROR(O15*10^4/B15/8760,"") | AI15: =IFERROR(P15*10^4/C15/8760,"") -> 0.085616438 | AJ15: =IFERROR(Q15*10^4/D15/8760,"") -> 0.060081711 | AK15: =IFERROR(R15*10^4/E15/8760,"") -> 0.068493151 | AL15: =IFERROR(S15*10^4/F15/8760,"") -> 0.028538813 | AM15: =IFERROR(T15*10^4/G15/8760,"") -> 0.037737273 | AN15: =IFERROR(U15*10^4/H15/8760,"") -> 0.069485805 | AO15: =IFERROR(V15*10^4/I15/8760,"") -> 0.079702991 | ... AS15: =IFERROR(Z15*10^4/M15/8760,"") -> 0.10366806
A16: 福建省 | D16: 0.1 | E16: 2.6 | F16: 7.8 | G16: 13 | H16: 27 | I16: 92 | J16: 148 | K16: 169 | L16: 202 | M16: 277 | N16: 464.9 | Q16: 0.02 | R16: 0.1 | S16: 0.5 | T16: 1 | U16: 1 | V16: 6 | W16: 14 | X16: 16 | Y16: 19 | Z16: 25 | AB16: 1099 | AC16: 1040 | AD16: 1063 | AE16: =AB16/8760 -> 0.12545662 | AF16: =AC16/8760 -> 0.11872146 | AG16: =AD16/8760 -> 0.12134703 | AH16: =IFERROR(O16*10^4/B16/8760,"") | AI16: =IFERROR(P16*10^4/C16/8760,"") | AJ16: =IFERROR(Q16*10^4/D16/8760,"") -> 0.2283105 | AK16: =IFERROR(R16*10^4/E16/8760,"") -> 0.043905866 | AL16: =IFERROR(S16*10^4/F16/8760,"") -> 0.073176443 | AM16: =IFERROR(T16*10^4/G16/8760,"") -> 0.087811732 | AN16: =IFERROR(U16*10^4/H16/8760,"") -> 0.042279723 | AO16: =IFERROR(V16*10^4/I16/8760,"") -> 0.074449077 | ... AS16: =IFERROR(Z16*10^4/M16/8760,"") -> 0.10302821
A17: 江西省 | C17: 0.7 | D17: 1.6 | E17: 8.5 | F17: 20.4 | G17: 43 | H17: 228 | I17: 449 | J17: 536 | K17: 630 | L17: 776 | M17: 911.1 | N17: 1201.9 | P17: 0.04 | Q17: 0.1 | R17: 0.4 | S17: 1 | T17: 2 | U17: 11 | V17: 30 | W17: 52 | X17: 56 | Y17: 62 | Z17: 80 | AB17: 1064 | AC17: 1004 | AD17: 917 | AE17: =AB17/8760 -> 0.12146119 | AF17: =AC17/8760 -> 0.11461187 | AG17: =AD17/8760 -> 0.10468037 | AH17: =IFERROR(O17*10^4/B17/8760,"") | AI17: =IFERROR(P17*10^4/C17/8760,"") -> 0.065231572 | AJ17: =IFERROR(Q17*10^4/D17/8760,"") -> 0.071347032 | AK17: =IFERROR(R17*10^4/E17/8760,"") -> 0.053720118 | AL17: =IFERROR(S17*10^4/F17/8760,"") -> 0.055958456 | AM17: =IFERROR(T17*10^4/G17/8760,"") -> 0.053095466 | AN17: =IFERROR(U17*10^4/H17/8760,"") -> 0.055074902 | AO17: =IFERROR(V17*10^4/I17/8760,"") -> 0.076272996 | ... AS17: =IFERROR(Z17*10^4/M17/8760,"") -> 0.1002351
A18: 山东省 | B18: 3.5 | C18: 3.7 | D18: 6.6 | E18: 11.8 | F18: 30.6 | G18: 133 | H18: 455 | I18: 1052 | J18: 1361 | K18: 1619 | L18: 2272 | M18: 3343.4 | N18: 4269.9 | O18: 0.4 | P18: 0.4 | Q18: 0.7 | R18: 1 | S18: 1.9 | T18: 7 | U18: 31 | V18: 73 | W18: 137 | X18: 167 | Y18: 206 | Z18: 310 | AB18: 1227 | AC18: 1284 | AD18: 1225 | AE18: =AB18/8760 -> 0.14006849 | AF18: =AC18/8760 -> 0.14657534 | AG18: =AD18/8760 -> 0.13984018 | AH18: =IFERROR(O18*10^4/B18/8760,"") -> 0.13046314 | AI18: =IFERROR(P18*10^4/C18/8760,"") -> 0.12341108 | AJ18: =IFERROR(Q18*10^4/D18/8760,"") -> 0.12107375 | AK18: =IFERROR(R18*10^4/E18/8760,"") -> 0.096741738 | AL18: =IFERROR(S18*10^4/F18/8760,"") -> 0.070880711 | AM18: =IFERROR(T18*10^4/G18/8760,"") -> 0.060081711 | AN18: =IFERROR(U18*10^4/H18/8760,"") -> 0.077776105 | AO18: =IFERROR(V18*10^4/I18/8760,"") -> 0.079214195 | ... AS18: =IFERROR(Z18*10^4/M18/8760,"") -> 0.10584473
A19: 河南省 | E19: 2 | F19: 20.1 | G19: 41 | H19: 284 | I19: 703 | J19: 991 | K19: 1054 | L19: 1175 | M19: 1555.6 | N19: 2333 | R19: 0.02 | S19: 0.5 | T19: 3.1 | U19: 12 | V19: 44 | W19: 84 | X19: 102 | Y19: 112 | Z19: 136 | AB19: 998 | AC19: 1061 | AD19: 1055 | AE19: =AB19/8760 -> 0.11392694 | AF19: =AC19/8760 -> 0.12111872 | AG19: =AD19/8760 -> 0.12043379 | AH19: =IFERROR(O19*10^4/B19/8760,"") | AI19: =IFERROR(P19*10^4/C19/8760,"") | AJ19: =IFERROR(Q19*10^4/D19/8760,"") | AK19: =IFERROR(R19*10^4/E19/8760,"") -> 0.011415525 | AL19: =IFERROR(S19*10^4/F19/8760,"") -> 0.028396829 | AM19: =IFERROR(T19*10^4/G19/8760,"") -> 0.086312507 | AN19: =IFERROR(U19*10^4/H19/8760,"") -> 0.048234613 | AO19: =IFERROR(V19*10^4/I19/8760,"") -> 0.071448521 | ... AS19: =IFERROR(Z19*10^4/M19/8760,"") -> 0.099801454
A20: 湖北省 | C20: 0.3 | D20: 1.2 | E20: 4.8 | F20: 8.6 | G20: 48 | H20: 187 | I20: 413 | J20: 510 | K20: 621 | L20: 698 | M20: 952.6 | N20: 1315.7 | P20: 0.03 | Q20: 0.1 | R20: 0.2 | S20: 0.6 | T20: 2 | U20: 11 | V20: 28 | W20: 49 | X20: 57 | Y20: 65 | Z20: 83 | AB20: 1115 | AC20: 1103 | AD20: 1013 | AE20: =AB20/8760 -> 0.12728311 | AF20: =AC20/8760 -> 0.12591324 | AG20: =AD20/8760 -> 0.11563927 | AH20: =IFERROR(O20*10^4/B20/8760,"") | AI20: =IFERROR(P20*10^4/C20/8760,"") -> 0.11415525 | AJ20: =IFERROR(Q20*10^4/D20/8760,"") -> 0.095129376 | AK20: =IFERROR(R20*10^4/E20/8760,"") -> 0.047564688 | AL20: =IFERROR(S20*10^4/F20/8760,"") -> 0.079643198 | AM20: =IFERROR(T20*10^4/G20/8760,"") -> 0.047564688 | AN20: =IFERROR(U20*10^4/H20/8760,"") -> 0.067150148 | AO20: =IFERROR(V20*10^4/I20/8760,"") -> 0.077393391 | ... AS20: =IFERROR(Z20*10^4/M20/8760,"") -> 0.099463425
A21: 湖南省 | E21: 0.1 | F21: 4.9 | G21: 17 | H21: 30 | I21: 176 | J21: 292 | K21: 344 | L21: 391 | M21: 451.1 | N21: 635.9 | R21: 0.03 | S21: 0.2 | T21: 0.8 | U21: 2 | V21: 6 | W21: 20 | X21: 26 | Y21: 30 | Z21: 38 | AB21: 933 | AC21: 905 | AD21: 902 | AE21: =AB21/8760 -> 0.10650685 | AF21: =AC21/8760 -> 0.1033105 | AG21: =AD21/8760 -> 0.10296804 | AH21: =IFERROR(O21*10^4/B21/8760,"") | AI21: =IFERROR(P21*10^4/C21/8760,"") | AJ21: =IFERROR(Q21*10^4/D21/8760,"") | AK21: =IFERROR(R21*10^4/E21/8760,"") -> 0.34246575 | AL21: =IFERROR(S21*10^4/F21/8760,"") -> 0.04659398 | AM21: =IFERROR(T21*10^4/G21/8760,"") -> 0.053720118 | AN21: =IFERROR(U21*10^4/H21/8760,"") -> 0.076103501 | AO21: =IFERROR(V21*10^4/I21/8760,"") -> 0.038916563 | ... AS21: =IFERROR(Z21*10^4/M21/8760,"") -> 0.096162703
A22: 广东省 | B22: 0.8 | C22: 0.8 | D22: 0.8 | E22: 4.4 | F22: 51.1 | G22: 62 | H22: 117 | I22: 332 | J22: 527 | K22: 610 | L22: 797 | M22: 1020.1 | N22: 1590.2 | O22: 0.01 | P22: 0.01 | Q22: 0.03 | R22: 0.1 | S22: 0.9 | T22: 4 | U22: 8 | V22: 20 | W22: 38 | X22: 53 | Y22: 74 | Z22: 103 | AB22: 884 | AC22: 915 | AD22: 1020 | AE22: =AB22/8760 -> 0.10091324 | AF22: =AC22/8760 -> 0.10445205 | AG22: =AD22/8760 -> 0.11643836 | AH22: =IFERROR(O22*10^4/B22/8760,"") -> 0.014269406 | AI22: =IFERROR(P22*10^4/C22/8760,"") -> 0.014269406 | AJ22: =IFERROR(Q22*10^4/D22/8760,"") -> 0.042808219 | AK22: =IFERROR(R22*10^4/E22/8760,"") -> 0.025944375 | AL22: =IFERROR(S22*10^4/F22/8760,"") -> 0.020105622 | AM22: =IFERROR(T22*10^4/G22/8760,"") -> 0.073648549 | AN22: =IFERROR(U22*10^4/H22/8760,"") -> 0.078054873 | AO22: =IFERROR(V22*10^4/I22/8760,"") -> 0.068768224 | ... AS22: =IFERROR(Z22*10^4/M22/8760,"") -> 0.11526312
A23: 广西壮族自治区 | E23: 4.2 | F23: 4.5 | G23: 12 | H23: 16 | I23: 78 | J23: 124 | K23: 135 | L23: 205 | M23: 311.7 | N23: 520.4 | R23: 0.3 | S23: 0.4 | T23: 0.5 | U23: 1.1 | V23: 4 | W23: 9 | X23: 14 | Y23: 19 | Z23: 29 | AB23: 1006 | AC23: 1097 | AD23: 1085 | AE23: =AB23/8760 -> 0.11484018 | AF23: =AC23/8760 -> 0.12522831 | AG23: =AD23/8760 -> 0.12385845 | AH23: =IFERROR(O23*10^4/B23/8760,"") | AI23: =IFERROR(P23*10^4/C23/8760,"") | AJ23: =IFERROR(Q23*10^4/D23/8760,"") | AK23: =IFERROR(R23*10^4/E23/8760,"") -> 0.081539465 | AL23: =IFERROR(S23*10^4/F23/8760,"") -> 0.10147133 | AM23: =IFERROR(T23*10^4/G23/8760,"") -> 0.047564688 | AN23: =IFERROR(U23*10^4/H23/8760,"") -> 0.078481735 | AO23: =IFERROR(V23*10^4/I23/8760,"") -> 0.058541154 | ... AS23: =IFERROR(Z23*10^4/M23/8760,"") -> 0.10620797
A24: 海南省 | B24: 2 | C24: 2.5 | D24: 2 | E24: 8.9 | F24: 13.9 | G24: 16 | H24: 29 | I24: 43 | J24: 136 | K24: 140 | L24: 143 | M24: 146.5 | N24: 245.8 | O24: 0.04 | P24: 0.2 | Q24: 0.3 | R24: 0.5 | S24: 1.7 | T24: 2 | U24: 3 | V24: 3 | W24: 6 | X24: 14 | Y24: 15 | Z24: 16 | AB24: 752 | AC24: 1023 | AD24: 1061 | AE24: =AB24/8760 -> 0.085844749 | AF24: =AC24/8760 -> 0.11678082 | AG24: =AD24/8760 -> 0.12111872 | AH24: =IFERROR(O24*10^4/B24/8760,"") -> 0.02283105 | AI24: =IFERROR(P24*10^4/C24/8760,"") -> 0.091324201 | AJ24: =IFERROR(Q24*10^4/D24/8760,"") -> 0.17123288 | AK24: =IFERROR(R24*10^4/E24/8760,"") -> 0.064132164 | AL24: =IFERROR(S24*10^4/F24/8760,"") -> 0.13961434 | AM24: =IFERROR(T24*10^4/G24/8760,"") -> 0.14269406 | AN24: =IFERROR(U24*10^4/H24/8760,"") -> 0.11809164 | AO24: =IFERROR(V24*10^4/I24/8760,"") -> 0.079643198 | ... AS24: =IFERROR(Z24*10^4/M24/8760,"") -> 0.12467468
A25: 重庆市 | H25: 0. 46 | I25: 12 | J25: 43 | K25: 65 | L25: 67 | M25: 63.4 | N25: 69.3 | U25: 0.02 | V25: 0.2 | W25: 2 | X25: 3 | Y25: 4 | Z25: 5 | AB25: 602 | AC25: 606 | AD25: 655 | AE25: =AB25/8760 -> 0.068721461 | AF25: =AC25/8760 -> 0.069178082 | AG25: =AD25/8760 -> 0.074771689 | AH25: =IFERROR(O25*10^4/B25/8760,"") | AI25: =IFERROR(P25*10^4/C25/8760,"") | AJ25: =IFERROR(Q25*10^4/D25/8760,"") | AK25: =IFERROR(R25*10^4/E25/8760,"") | AL25: =IFERROR(S25*10^4/F25/8760,"") | AM25: =IFERROR(T25*10^4/G25/8760,"") | AN25: =IFERROR(U25*10^4/H25/8760,"") | AO25: =IFERROR(V25*10^4/I25/8760,"") -> 0.019025875 | ... AS25: =IFERROR(Z25*10^4/M25/8760,"") -> 0.090027801
A26: 四川省 | E26: 3.3 | F26: 5.4 | G26: 36 | H26: 96 | I26: 135 | J26: 181 | K26: 188 | L26: 191 | M26: 195.9 | N26: 206.2 | R26: 0.01 | S26: 0.5 | T26: 2 | U26: 11 | V26: 16 | W26: 22 | X26: 28 | Y26: 27 | Z26: 30 | AB26: 1461 | AC26: 1554 | AD26: 1466 | AE26: =AB26/8760 -> 0.16678082 | AF26: =AC26/8760 -> 0.17739726 | AG26: =AD26/8760 -> 0.1673516 | AH26: =IFERROR(O26*10^4/B26/8760,"") | AI26: =IFERROR(P26*10^4/C26/8760,"") | AJ26: =IFERROR(Q26*10^4/D26/8760,"") | AK26: =IFERROR(R26*10^4/E26/8760,"") -> 0.00345925 | AL26: =IFERROR(S26*10^4/F26/8760,"") -> 0.10569931 | AM26: =IFERROR(T26*10^4/G26/8760,"") -> 0.063419584 | AN26: =IFERROR(U26*10^4/H26/8760,"") -> 0.13080289 | AO26: =IFERROR(V26*10^4/I26/8760,"") -> 0.13529511 | ... AS26: =IFERROR(Z26*10^4/M26/8760,"") -> 0.17481662
A27: 贵州省 | G27: 3 | H27: 46 | I27: 135 | J27: 178 | K27: 510 | L27: 1057 | M27: 1137 | N27: 1420.3 | T27: 0 | U27: 1.1 | V27: 6 | W27: 16 | X27: 20 | Y27: 45 | Z27: 83 | AB27: 932 | AC27: 1092 | AD27: 1032 | AE27: =AB27/8760 -> 0.10639269 | AF27: =AC27/8760 -> 0.12465753 | AG27: =AD27/8760 -> 0.11780822 | AH27: =IFERROR(O27*10^4/B27/8760,"") | AI27: =IFERROR(P27*10^4/C27/8760,"") | AJ27: =IFERROR(Q27*10^4/D27/8760,"") | AK27: =IFERROR(R27*10^4/E27/8760,"") | AL27: =IFERROR(S27*10^4/F27/8760,"") | AM27: =IFERROR(T27*10^4/G27/8760,"") -> 0 | AN27: =IFERROR(U27*10^4/H27/8760,"") -> 0.027297995 | AO27: =IFERROR(V27*10^4/I27/8760,"") -> 0.050735667 | ... AS27: =IFERROR(Z27*10^4/M27/8760,"") -> 0.083332329
A28: 云南省 | B28: 2 | C28: 2 | D28: 3 | E28: 11 | F28: 28.2 | G28: 117 | H28: 208 | I28: 238 | J28: 326 | K28: 375 | L28: 388 | M28: 397.1 | N28: 585.3 | O28: 0.3 | P28: 0.3 | Q28: 0.3 | R28: 0.9 | S28: 2.9 | T28: 6 | U28: 23 | V28: 28 | W28: 34 | X28: 48 | Y28: 50 | Z28: 51 | AB28: 1182 | AC28: 1350 | AD28: 1332 | AE28: =AB28/8760 -> 0.13493151 | AF28: =AC28/8760 -> 0.15410959 | AG28: =AD28/8760 -> 0.15205479 | AH28: =IFERROR(O28*10^4/B28/8760,"") -> 0.17123288 | AI28: =IFERROR(P28*10^4/C28/8760,"") -> 0.17123288 | AJ28: =IFERROR(Q28*10^4/D28/8760,"") -> 0.11415525 | AK28: =IFERROR(R28*10^4/E28/8760,"") -> 0.093399751 | AL28: =IFERROR(S28*10^4/F28/8760,"") -> 0.1173937 | AM28: =IFERROR(T28*10^4/G28/8760,"") -> 0.058541154 | AN28: =IFERROR(U28*10^4/H28/8760,"") -> 0.12622936 | AO28: =IFERROR(V28*10^4/I28/8760,"") -> 0.1343003 | ... AS28: =IFERROR(Z28*10^4/M28/8760,"") -> 0.14661087
A29: 西藏自治区 | B29: 4 | C29: 6.6 | D29: 8 | E29: 11 | F29: 13 | G29: 17 | H29: 33 | I29: 79 | J29: 98 | K29: 110 | L29: 137 | M29: 138.7 | N29: 178.1 | O29: 0.4 | P29: 1.8 | Q29: 0.8 | R29: 1.4 | S29: 1.8 | T29: 2 | U29: 4 | V29: 6 | W29: 8 | X29: 13 | Y29: 14 | Z29: 17 | AB29: 900 | AC29: 1210 | AD29: 1116 | AE29: =AB29/8760 -> 0.10273973 | AF29: =AC29/8760 -> 0.13812785 | AG29: =AD29/8760 -> 0.12739726 | AH29: =IFERROR(O29*10^4/B29/8760,"") -> 0.11415525 | AI29: =IFERROR(P29*10^4/C29/8760,"") -> 0.3113325 | AJ29: =IFERROR(Q29*10^4/D29/8760,"") -> 0.11415525 | AK29: =IFERROR(R29*10^4/E29/8760,"") -> 0.1452885 | AL29: =IFERROR(S29*10^4/F29/8760,"") -> 0.15806112 | AM29: =IFERROR(T29*10^4/G29/8760,"") -> 0.1343003 | AN29: =IFERROR(U29*10^4/H29/8760,"") -> 0.13837 | AO29: =IFERROR(V29*10^4/I29/8760,"") -> 0.086700191 | ... AS29: =IFERROR(Z29*10^4/M29/8760,"") -> 0.13991631
A30: 陕西省 | B30: 2 | C30: 2 | D30: 2.1 | E30: 6.3 | F30: 31.3 | G30: 72 | H30: 246 | I30: 535 | J30: 716 | K30: 939 | L30: 1089 | M30: 1313.7 | N30: 1516.2 | Q30: 0.3 | R30: 0.8 | S30: 0.9 | T30: 6 | U30: 20 | V30: 52 | W30: 71 | X30: 94 | Y30: 119 | Z30: 141 | AB30: 1274 | AC30: 1273 | AD30: 1392 | AE30: =AB30/8760 -> 0.14543379 | AF30: =AC30/8760 -> 0.14531963 | AG30: =AD30/8760 -> 0.15890411 | AH30: =IFERROR(O30*10^4/B30/8760,"") -> 0 | AI30: =IFERROR(P30*10^4/C30/8760,"") -> 0 | AJ30: =IFERROR(Q30*10^4/D30/8760,"") -> 0.16307893 | AK30: =IFERROR(R30*10^4/E30/8760,"") -> 0.14495905 | AL30: =IFERROR(S30*10^4/F30/8760,"") -> 0.032824194 | AM30: =IFERROR(T30*10^4/G30/8760,"") -> 0.095129376 | AN30: =IFERROR(U30*10^4/H30/8760,"") -> 0.092809147 | AO30: =IFERROR(V30*10^4/I30/8760,"") -> 0.11095464 | ... AS30: =IFERROR(Z30*10^4/M30/8760,"") -> 0.12252333
A31: 甘肃省 | B31: 11 | C31: 11.1 | D31: 38 | E31: 429.8 | F31: 517.3 | G31: 610 | H31: 686 | I31: 786 | J31: 839 | K31: 924 | L31: 982 | M31: 1124.8 | N31: 1396.4 | O31: 0.6 | P31: 0.6 | Q31: 3.1 | R31: 19 | S31: 40 | T31: 59 | U31: 60 | V31: 73 | W31: 95 | X31: 118 | Y31: 133 | Z31: 150 | AB31: 1336 | AC31: 1422 | AD31: 1511 | AE31: =AB31/8760 -> 0.15251142 | AF31: =AC31/8760 -> 0.16232877 | AG31: =AD31/8760 -> 0.17248858 | AH31: =IFERROR(O31*10^4/B31/8760,"") -> 0.062266501 | AI31: =IFERROR(P31*10^4/C31/8760,"") -> 0.061705541 | AJ31: =IFERROR(Q31*10^4/D31/8760,"") -> 0.093126652 | AK31: =IFERROR(R31*10^4/E31/8760,"") -> 0.050464164 | AL31: =IFERROR(S31*10^4/F31/8760,"") -> 0.088270057 | AM31: =IFERROR(T31*10^4/G31/8760,"") -> 0.11041246 | AN31: =IFERROR(U31*10^4/H31/8760,"") -> 0.099844243 | AO31: =IFERROR(V31*10^4/I31/8760,"") -> 0.10602205 | ... AS31: =IFERROR(Z31*10^4/M31/8760,"") -> 0.15223407
A32: 青海省 | B32: 94 | C32: 93.8 | D32: 136 | E32: 348.1 | F32: 412.4 | G32: 564 | H32: 682 | I32: 791 | J32: 962 | K32: 1122 | L32: 1601 | M32: 1610.8 | N32: 1821.1 | O32: 1.4 | P32: 1.4 | Q32: 15 | R32: 28.2 | S32: 58.2 | T32: 76 | U32: 90 | V32: 113 | W32: 131 | X32: 158 | Y32: 167 | Z32: 211 | AB32: 1464 | AC32: 1487 | AD32: 1376 | AE32: =AB32/8760 -> 0.16712329 | AF32: =AC32/8760 -> 0.16974886 | AG32: =AD32/8760 -> 0.15707763 | AH32: =IFERROR(O32*10^4/B32/8760,"") -> 0.017001846 | AI32: =IFERROR(P32*10^4/C32/8760,"") -> 0.017038097 | AJ32: =IFERROR(Q32*10^4/D32/8760,"") -> 0.12590653 | AK32: =IFERROR(R32*10^4/E32/8760,"") -> 0.092478543 | AL32: =IFERROR(S32*10^4/F32/8760,"") -> 0.16110174 | AM32: =IFERROR(T32*10^4/G32/8760,"") -> 0.15382622 | AN32: =IFERROR(U32*10^4/H32/8760,"") -> 0.15064476 | AO32: =IFERROR(V32*10^4/I32/8760,"") -> 0.16307893 | ... AS32: =IFERROR(Z32*10^4/M32/8760,"") -> 0.14953289
A33: 宁夏回族自治区 | B33: 49 | C33: 49.1 | D33: 53 | E33: 155.1 | F33: 173.4 | G33: 309 | H33: 526 | I33: 620 | J33: 816 | K33: 918 | L33: 1197 | M33: 1384 | N33: 1583.7 | O33: 1.9 | P33: 1.9 | Q33: 7.8 | R33: 10.5 | S33: 25.9 | T33: 36 | U33: 55 | V33: 76 | W33: 97 | X33: 115 | Y33: 136 | Z33: 183 | AB33: 1383 | AC33: 1371 | AD33: 1393 | AE33: =AB33/8760 -> 0.15787671 | AF33: =AC33/8760 -> 0.15650685 | AG33: =AD33/8760 -> 0.15901826 | AH33: =IFERROR(O33*10^4/B33/8760,"") -> 0.044264281 | AI33: =IFERROR(P33*10^4/C33/8760,"") -> 0.04417413 | AJ33: =IFERROR(Q33*10^4/D33/8760,"") -> 0.16800207 | AK33: =IFERROR(R33*10^4/E33/8760,"") -> 0.077281118 | AL33: =IFERROR(S33*10^4/F33/8760,"") -> 0.17050871 | AM33: =IFERROR(T33*10^4/G33/8760,"") -> 0.13299641 | AN33: =IFERROR(U33*10^4/H33/8760,"") -> 0.11936386 | AO33: =IFERROR(V33*10^4/I33/8760,"") -> 0.13993224 | ... AS33: =IFERROR(Z33*10^4/M33/8760,"") -> 0.15094228
A34: 新疆维吾尔自治区 | D34: 18 | E34: 277.1 | F34: 326.1 | G34: 529 | H34: 893 | I34: 934 | J34: 978 | K34: 1072 | L34: 1266 | M34: 1272 | N34: 1467.2 | Q34: 1.7 | R34: 5.3 | S34: 43.6 | T34: 57 | U34: 67 | V34: 107 | W34: 116 | X34: 132 | Y34: 157 | Z34: 196 | AB34: 1228 | AC34: 1284 | AD34: 1396 | AE34: =AB34/8760 -> 0.14018265 | AF34: =AC34/8760 -> 0.14657534 | AG34: =AD34/8760 -> 0.15936073 | AH34: =IFERROR(O34*10^4/B34/8760,"") | AI34: =IFERROR(P34*10^4/C34/8760,"") | AJ34: =IFERROR(Q34*10^4/D34/8760,"") -> 0.10781329 | AK34: =IFERROR(R34*10^4/E34/8760,"") -> 0.021834097 | AL34: =IFERROR(S34*10^4/F34/8760,"") -> 0.15262708 | AM34: =IFERROR(T34*10^4/G34/8760,"") -> 0.12300282 | AN34: =IFERROR(U34*10^4/H34/8760,"") -> 0.085648397 | AO34: =IFERROR(V34*10^4/I34/8760,"") -> 0.13077743 | ... AS34: =IFERROR(Z34*10^4/M34/8760,"") -> 0.1758996
A35: 新疆生产建设兵团 | M35: 77.2 | N35: 105.8
A37: 地区 | B37: 集中装机容量（万千瓦） | H37: 集中发电量（亿千瓦时） | N37: 容量因子
B38: 2017 | C38: 2018 | D38: 2019 | E38: 2020 | F38: 2021 | G38: 2022 | H38: 2017 | I38: 2018 | J38: 2019 | K38: 2020 | L38: 2021 | M38: 2022 | N38: 2017 | O38: 2018 | P38: 2019 | Q38: 2020 | R38: 2021 | S38: 2022
A39: 全国 | B39: 13040 | C39: 17433 | D39: 20431 | E39: 25360 | F39: 30598.7 | G39: 39203.8 | H39: =SUM(H40:H71) -> 1023.09 | I39: =SUM(I40:I71) -> 1378.9 | J39: =SUM(J40:J71) -> 1699.6 | K39: =SUM(K40:K71) -> 1935.6 | L39: =SUM(L40:L71) -> 2347.8 | N39: =IFERROR(H39*10^4/B39/8760,"") -> 0.089563724 | O39: =IFERROR(I39*10^4/C39/8760,"") -> 0.09029351 | P39: =IFERROR(J39*10^4/D39/8760,"") -> 0.094962687 | Q39: =IFERROR(K39*10^4/E39/8760,"") -> 0.087128905 | R39: =IFERROR(L39*10^4/F39/8760,"") -> 0.087589897
A40: 北京市 | B40: =MAX(I4-'Distributed photoelectric data'!B4,0) -> 3 | C40: =MAX(J4-'Distributed photoelectric data'!C4,0) -> 5 | D40: =MAX(K4-'Distributed photoelectric data'!D4,0) -> 5 | E40: =MAX(L4-'Distributed photoelectric data'!E4,0) -> 6 | F40: =MAX(M4-'Distributed photoelectric data'!F4,0) -> 5.1 | H40: =V4-'Distributed photoelectric data'!J4 -> 1 | I40: =W4-'Distributed photoelectric data'!K4 -> 1 | J40: =X4-'Distributed photoelectric data'!L4 -> 1 | K40: =Y4-'Distributed photoelectric data'!M4 -> 1 | L40: =Z4-'Distributed photoelectric data'!N4 -> 1 | N40: =IFERROR(H40*10^4/B40/8760,"") -> 0.3805175 | O40: =IFERROR(I40*10^4/C40/8760,"") -> 0.2283105 | P40: =IFERROR(J40*10^4/D40/8760,"") -> 0.2283105 | Q40: =IFERROR(K40*10^4/E40/8760,"") -> 0.19025875 | R40: =IFERROR(L40*10^4/F40/8760,"") -> 0.22383383
A41: 天津市 | B41: =MAX(I5-'Distributed photoelectric data'!B5,0) -> 53 | C41: =MAX(J5-'Distributed photoelectric data'!C5,0) -> 97 | D41: =MAX(K5-'Distributed photoelectric data'!D5,0) -> 105 | E41: =MAX(L5-'Distributed photoelectric data'!E5,0) -> 119 | F41: =MAX(M5-'Distributed photoelectric data'!F5,0) -> 118.9 | H41: =V5-'Distributed photoelectric data'!J5 -> 5.2 | I41: =W5-'Distributed photoelectric data'!K5 -> 6 | J41: =X5-'Distributed photoelectric data'!L5 -> 12 | K41: =Y5-'Distributed photoelectric data'!M5 -> 15 | L41: =Z5-'Distributed photoelectric data'!N5 -> 16 | N41: =IFERROR(H41*10^4/B41/8760,"") -> 0.11200138 | O41: =IFERROR(I41*10^4/C41/8760,"") -> 0.070611496 | P41: =IFERROR(J41*10^4/D41/8760,"") -> 0.13046314 | Q41: =IFERROR(K41*10^4/E41/8760,"") -> 0.14389317 | R41: =IFERROR(L41*10^4/F41/8760,"") -> 0.15361514
...

Sheet DSCF
B1: 2017 | C1: 2018 | D1: 2019 | E1: 2020 | F1: 2021 | G1: 2022 | H1: 2023 | I1: 2024 | J1: 2025 | K1: 2026 | L1: 2027 | M1: 2028 | N1: 2029 | O1: 2030 | P1: 2031 | Q1: 2032 | R1: 2033 | S1: 2034 | T1: 2035 | U1: 2036 | V1: 2037 | W1: 2038 | X1: 2039 | Y1: 2040 | Z1: 2041 | AA1: 2042 | AB1: 2043 | AC1: 2044 | AD1: 2045 | AE1: 2046 | AF1: 2047 | AG1: 2048 | AH1: 2049 | AI1: 2050 | AJ1: 2051 | AK1: 2052 | AL1: 2053 | AM1: 2054 | AN1: 2055 | AO1: 2056 | AP1: 2057 | AQ1: 2058 | AR1: 2059 | AS1: 2060
A2: Capacity Factor (dimensionless) | B2: ='Distributed photoelectric data'!R3 -> 0.048058799 | C2: ='Distributed photoelectric data'!S3 -> 0.088108688 | D2: ='Distributed photoelectric data'!T3 -> 0.099433249 | E2: ='Distributed photoelectric data'!U3 -> 0.099030811 | F2: ='Distributed photoelectric data'!V3 -> 0.098219302 | G2: ='Distributed photoelectric data'!W3 -> 0.10407378 | H2: ='Distributed photoelectric data'!X3 -> 0.093410274 | I2: ='Distributed photoelectric data'!Y3 -> 0.10544999 | J2: =MIN(I2+0.005,1500/8760) -> 0.11044999 | K2: =MIN(J2+0.005,1500/8760) -> 0.11544999 | L2: 0.11544999 | M2: 0.11544999 | N2: 0.11544999 | O2: 0.11544999 | P2: 0.11544999 | Q2: 0.11544999 | R2: 0.11544999 | S2: 0.11544999 | T2: 0.11544999 | U2: 0.11544999 | V2: 0.11544999 | W2: 0.11544999 | X2: 0.11544999 | Y2: 0.11544999 | Z2: 0.11544999 | AA2: 0.11544999 | AB2: 0.11544999 | AC2: 0.11544999 | AD2: 0.11544999 | AE2: 0.11544999 | AF2: 0.11544999 | AG2: 0.11544999 | AH2: 0.11544999 | AI2: 0.11544999 | AJ2: 0.11544999 | AK2: 0.11544999 | AL2: 0.11544999 | AM2: 0.11544999 | AN2: 0.11544999 | AO2: 0.11544999 | AP2: 0.11544999 | AQ2: 0.11544999 | AR2: 0.11544999 | AS2: 0.11544999
B3: =B2*8760 -> 420.99508 | C3: =C2*8760 -> 771.83211 | D3: =D2*8760 -> 871.03526 | E3: =E2*8760 -> 867.5099 | F3: =F2*8760 -> 860.40109 | G3: =G2*8760 -> 911.68633 | H3: =H2*8760 -> 818.274 | I3: =I2*8760 -> 923.74193 | ... AS3: =AS2*8760 -> 1011.3419
