Workbook

Sheet About
A1: Web App Data
A3: This spreadsheet contains data that is used to populate the web application interface
A4: for the Energy Policy Simulator. The data in other tabs in this spreadsheet are used
A5: to establish the policy levers, lever bounds, descriptive text for pop-over
A6: panels, output graphs, and reference scenarios available in the web app.
A8: A live version of the web application interface powered by a copy of this model
A9: can be found at:
A10: https://www.energypolicy.solutions
A12: You are unlikely to need to use or change the contents of this spreadsheet, unless
A13: you are adapting the Energy Policy Simulator to a new country and desire
A14: a web application interface customized for your country-specific model version.
A16: Checks for Policy ID Number Validity
A17: Max policy ID number in use | B17: =MAX(PolicyLevers!H:H) -> 1655
A18: Lowest duplicate ID number | B18: {=IF(MIN(IF(COUNTIF(PolicyLevers!$H$2:$H$1271,PolicyLevers!$H$2:$H$1271)>1,PolicyLevers!$H$2:$H$1271,""))=0,"No duplicate ID numbers",MIN(IF(COUNTIF(PolicyLevers!$H$2:$H$1271,PolicyLevers!$H$2:$H$1271)>1,PolicyLevers!$H$2:$H$1271,"")))} -> No duplicate ID numbers
A19: Row of first policy missing a valid ID number | B19: {=IF(MIN(IF((NOT(ISNUMBER(PolicyLevers!$H$2:$H$1271)))*(ISTEXT(PolicyLevers!$I$2:$I$1271)),ROW(PolicyLevers!$H$2:$H$1271)))=0,"No missing ID numbers",MIN(IF((NOT(ISNUMBER(PolicyLevers!$H$2:$H$1271)))*(ISTEXT(PolicyLevers!$I$2:$I$1271)),ROW(PolicyLevers!$H$2:$H$1271))))} -> No missing ID numbers
A21: Customizing Policy Levers
A22: Define most policy properties on the "Policy Characteristics" tab.
A23: Specify the subscripted elements of each policy and which are enabled/disabled on the "PolicyLevers" tab.
A24: On the PolicyLevers tab, only manually edit the cells under the green column headers. Simply extend the
A25: existing formulas up or down to fill cells under the red headers on that tab.
A27: Notes on Meaning of Blank Cells on the Policy Characteristics Tab
A28: Leave the "Policy Schedule Subscript" cell blank to deny the ability to edit the implementation
A29: schedule for a lever. This should generally only be done for levers that do not use an
A30: implementation schedule: the toggle to Non-BAU Mandated Capacity Construction
A31: (which has its own schedule built into its input data) and the Nuclear Lifetime Extension
A32: (which simply delays retirements that would occur in the BAU Retirements input data).
A34: Leave the "Policy Group" cell blank to exclude a lever from wedge diagrams and abatement cost curves.
... A53: step size (e.g. 1.5% is not a valid step size, but 1%, 2%, 0.5% and 0.05% are all valid).

Sheet Policy Characteristics
A1: This tab contains information about each policy that does not vary by subscripted element of that policy.
A2: It matches policies to the listing in the "PolicyLevers" tab using the "Vensim Variable Name" column.
A3: Sector | B3: Short Name | C3: Vensim Variable Name | D3: Policy Group | E3: Policy Schedule Subscript | F3: Min Slider Value | G3: Max Slider Value | H3: Slider Step Size | I3: Units | J3: Text for Pop-Over Panel Description | K3: URL for "How the model handles this policy" links | L3: URL for "How to design this policy well" links | M3: Source for Guidance Text (if any) | N3: Source for Max Slider Value (if any)
A4: Transportation | B4: Conventional Pollutant Standards | C4: Percentage Reduction of Separately Regulated Pollutants | D4: Conventional Pollutant Standard | E4: trans reduce regulated pollutants | F4: 0 | G4: 1 | H4: 0.02 | I4: % reduction in emissions | J4: **Description:** This policy represents strengthening standards for the selected pollutant(s) emitted by the selected vehicle type(s). Conventional pollutants' most important, harmful impacts are on human health rather than on climate change. // **Guidance for setting values:** By 2025, the concentration of fine particulate matter (PM2.5) in prefectural-level and above cities will be 10% lower than that in 2020, and the total emissions of volatile organic compounds (VOCs) and nitrogen oxides will be more than 10% lower than that in 2020 respectively. (Reference: Opinions of the CPC and the State Council on Further Combating Pollution and Preventing the Battle against Pollution) | K4: transportation-sector-main.html#conv-pol-stds | L4: conventional-pollutant-standards.html
A5: Transportation | B5: Electric Vehicle Charger Deployment | C5: EV Charger Deployment | D5: EV Charger Deployment | E5: trans EV charger deployment | F5: 0 | G5: 300 | H5: 5 | I5: chargers / 100k pop | J5: **Description:** This policy represents increasing the deployment of EV charging stations, including DC Fast and Level 2 charging stations. It is set in chargers per 100,000 people (cumulative, not per year), additional to chargers in the BAU case. This policy only affects passenger LDVs. // **Guidance for setting values:** The Implementation Program for Accelerating the Construction of Charging and Switching Infrastructure in the Inner Mongolia Autonomous Region (2021-2025) makes it clear that by 2025, all types of charging and switching facilities in the region will strive to reach about 40,000 units. | L5: ev-charger-deployment.html | M5: Number of EV chargers: https://evadoption.com/ev-charging-stations-statistics/ Number of gas stations: U.S. Census, Statistics of U.S. Businesses, https://www.census.gov/data/tables/2016/econ/susb/2016-susb-annual.html Pumps per station: https://247wallst.com/economy/2014/05/22/why-are-there-115000-or-150000-gas-stations-in-america/
A6: Transportation | B6: Electric Vehicle Range & Charging Time | C6: Reduce EV Range Anxiety and Charging Time | D6: EV Range & Charging Time | E6: trans reduce EV range anxiety and charging time | F6: 0 | G6: 1 | H6: 0.02 | I6: % reduction in concern | J6: **Description:** This policy specifies a percentage reduction in vehicle buyers' aversion to electric vehicles due to concerns over the vehicles' range (how far the EV can travel on a charge) and charging time. A 100% setting implies consumers are no more concerned about EV range and charging time than they are about range and fueling time of gasoline vehicles. It does not imply that range is infinite, nor that charging is instantaneous. This policy only affects passenger LDVs. // **Guidance for setting values:**Technology roadmap 2.0 proposes that by 2030, the high ratio of charging facilities will cover residential communities and surrounding areas, as well as unit parking Spaces, social parking lots, and main areas of cities above the county level, key areas of townships, intercity connections, and highway service areas. | L6: reduce-range-anxiety-charging-time.html | M6: Ranges: https://www.energy.gov/eere/vehicles/articles/fotw-1010-january-1-2018-all-electric-light-vehicle-ranges-can-exceed-those Charging Times: https://www.chargepoint.com/files/Quick_Guide_to_Fast_Charging.pdf
A7: Transportation | B7: Zero-Emission Vehicle Sales Standard | C7: Minimum Required ZEV Sales Percentage | D7: ZEV Sales Standard | E7: trans ZEV minimum | F7: 0 | G7: 1 | H7: 0.01 | I7: % of new vehicles sold | J7: **Description:** This policy requires the specified percentage of newly sold vehicles of the selected type(s) to consist of zero-emission vehicles (ZEV). If that percentage would already be achieved through BAU sales plus the effects of other policies, such as an EV subsidy, this policy has no effect. Manufactures may meet a sales standard through techniques such as more heavily marketing electric vehicles, lowering the price of electric vehicles, or raising the price of non-electric vehicles. This policy only applies to road vehicles, not aircraft, rail, or ships. The following descriptions detail the different vehicle types: // **Passenger cars and SUVs:** most light-duty road vehicles //**Light and Medium Commercial, Heavy Duty Trucks, and Heavy Heavy Duty Trucks:** commercial trucks carrying freight, not passengers // **Buses:** including school, transit, and intercity buses // **Heavy Heavy Duty Trucks:** all other heavy road vehicles (mostly freight trucks) // **Passenger motorbikes:** registered motorcycles // **Guidance for setting values:** // **Passenger LDVs:** China aims to achieve about 20% new sales of new energy vehicles (NEV) in 2025, and ensure that new NEV sales is the majority in 2035 (more than 50% of total sales). // **Freight Trucks:** Today, the share of electric freight trucks is very low, but electrification is particularly promising for certain types of trucks, such as those used to make deliveries within cities, those involved in port operations, garbage trucks, and others with frequent starts and stops. // **Passenger HDVs:**Nationally planning sets the goal of 100% electrification for public transportation, and total BEV+PHEV sales for passenger HDVs should reach 50% in 2035. // **Aircraft:** Electricity is commonly used by drones, and small, manned electric aircraft have been developed. However, limited payload and range may complicate the electrification potential of large, long-haul aircraft. Therefore, a low setting of this policy lever may be more realistic than a high setting. // **Rail:** Today, in China, electrification rate reaches 74.9%. Passenger rail has a higher electrification rate than freight and the rates will likely continue to rise. // **Passenger Ships:** Although only a small percentage of recreational boats are powered by electricity today, the market for electric recreational boats is growing rapidly and is projected to reach $20 billion / year globally by 2027. Batteries and electric motors are suitable for the typical travel distances and demand cycles of most small pleasure craft, and in some cases, it is possible to retrofit an existing boat with an electric outboard motor and batteries. Accordingly, a high setting of this policy lever may be reasonable. // **Freight Ships:** Today, few freight ships rely solely on electricity for energy. The large loads and long distances traveled by ocean-going vessels (with no opportunity to charge while underway) limit the suitability of electricity for these vessel types. However, there are freight vessels better-suited to electricity, including tug boats (which benefit from the high torque of electric motors) and offshore support vessels (which carry personnel and goods between offshore platforms and the mainland, and perform other support tasks), as these types of vessels travel predictable distances and may easily return to a dock to charge. Accordingly, a modest setting of this policy lever may be reasonable. // **Passenger Motorbikes:** Electric scooters are very prominent in China and therefore electrification rate is close to 100%. | K7: transportation-sector-main.html#ev-mandate | L7: ev-mandate.html | M7: https://autoalliance.org/energy-environment/state-electric-vehicle-mandate/ https://www.cnbc.com/2019/08/26/colorado-joins-california-in-requiring-automakers-to-sell-more-evs.html https://www.consumerreports.org/hybrids-evs/california-says-new-cars-sold-in-the-state-must-be-zero-emissions-by-2035/ https://www.greentechmedia.com/articles/read/electric-buses-are-going-to-dominate statistics from FoVObE variable https://www.prnewswire.com/news-releases/electric-boats-and-ships-2017-2027-300561222.html
A8: Transportation | B8: Non BAU ZEV Qualifying Vehicles | C8: Boolean Use Non BAU ZEV Qualifying Vehicle Defintions | D8: ZEV Sales Standard | E8: trans non BAU ZEV vehicle definitions | F8: 0 | G8: 1 | H8: 1 | I8: on/off | J8: **Description:** This lever changes which vehicles qualify under the ZEV standard. With the lever off, ZEV qualifying vehicles include: battery electric vehicles, plugin hybrid vehicles, and hydrogen fueled vehicles. With the lever on, only battery electric vehicles and hydrogen fueled vehicles qualify.
A9: Transportation | B9: Electric Vehicle Subsidy | C9: Additional EV Subsidy Percentage | D9: EV Subsidy | E9: trans EV subsidy | F9: 0 | G9: 0.5 | H9: 0.01 | I9: % of vehicle cost | J9: **Description:** This policy causes government to pay for the specified percentage of the purchase price of new battery electric passenger LDVs. This is in addition to EV subsidies that exist in the BAU case. // **Guidance for setting values:** According to the Notice of the Development and Reform Commission of the Ministry of Finance, Ministry of Industry and Information Technology on Improving the Financial Subsidy Policy for the Promotion and Application of New energy Vehicles (Caijian (2020) No. 86), the 2022 new energy vehicle purchase subsidy policy will be terminated on December 31, 2022, and vehicles registered after December 31, 2022 will no longer be subsidized. | K9: transportation-sector-main.html#ev-subsidy | L9: ev-subsidy.html | M9: https://www.fueleconomy.gov/feg/taxevb.shtml plus Chevrolet and Tesla websites
A10: Transportation | B10: Feebate | C10: LDVs Feebate Rate | D10: Feebate | E10: trans LDVs feebate | F10: 0 | G10: 1 | H10: 0.02 | I10: % of global best practice rate | J10: **Description:** This policy implements a fee on sales of inefficient light-duty vehicles (LDVs; namely cars and SUVs) that is rebated to buyers of efficient LDVs. The feebate policy is revenue-neutral, as the pivot point (the efficiency level that incurs neither a rebate nor a fee) is set such that the total of all fees equals the total of all rebates. // **Guidance for setting values:** The feebate is set as a fraction of the global best practice feebate rate. The global best practice feebate rate is $2000 per (hundredth gal/mile), which equates to a $2000 fee on an LDV that gets 20 mpg if the pivot point is 25 mpg. (To see this: 20 mpg is 0.04 gpm. 25 mpg is 0.05 gpm. The difference is -.01 gpm. So in order to levy a $2000 fee on the 20 mpg car when the pivot point is 25 mpg, we need a rate of $2000/.01 gpm.) China does not have feebate currently | K10: transportation-sector-main.html#feebate | L10: feebate.html | M10: Greene et al., 2005, "Feebates, rebates and gas-guzzler taxes: a study of incentives for increased fuel economy", Energy Policy, 33(6), 757-775, http://cta.ornl.gov/cta/Publications/Reports/FeebateEnergyPolicy_FINAL.pdf. | N10: John German and Dan Meszler, 2010, "Best Practices for Feebate Program Design and Implementation", ICCT, http://www.theicct.org/sites/default/files/publications/ICCT_feebates_may2010.pdf, Table 2
A11: Transportation | B11: Fuel Economy Standard | C11: Percentage Additional Improvement of Fuel Economy Std | D11: Vehicle Fuel Economy Standards | E11: trans fuel economy standards | F11: 0 | G11: =ROUND(MaxBoundCalculations!B88,1) -> 1 | H11: 0.01 | I11: % increase in miles/gal | J11: **Description:** This policy specifies a percentage improvement in fuel economy (distance traveled on the same quantity of fuel with the same cargo or passenger loading) due to fuel economy standards for newly sold vehicles of the selected type(s) with fossil fuel-burning engines. // **Guidance for setting values:** // **The Inner Mongolia Autonomous Region has not issued updated policies related to the economic fuel efficiency of vehicles. | K11: transportation-sector-main.html#fuel-econ-std | L11: fuel-economy-standard.html | M11: U. S. EPA, 2012, "Fact Sheet: EPA and NHTSA Set Standards to Reduce Greenhouse Gases and Improve Fuel Economy for Model Years 2017-2025 Cars and Light Trucks", https://nepis.epa.gov/Exe/ZyNET.exe/P100EZ7C.txt?ZyActionD=ZyDocument&Client=EPA&Index=2011%20Thru%202015&Docs=&Query=&Time=&EndTime=&SearchMethod=1&TocRestrict=n&Toc=&TocEntry=&QField=&QFieldYear=&QFieldMonth=&QFieldDay=&UseQField=&IntQFieldOp=0&ExtQFieldOp=0&XmlQuery=&File=D%3A%5CZYFILES%5CINDEX%20DATA%5C11THRU15%5CTXT%5C00000005%5CP100EZ7C.txt&User=ANONYMOUS&Password=anonymous&SortMethod=h%7C-&MaximumDocuments=1&FuzzyDegree=0&ImageQuality=r75g8/r75g8/x150y150g16/i425&Display=hpfr&DefSeekPage=x&SearchBack=ZyActionL&Back=ZyActionS&BackDesc=Results%20page&MaximumPages=1&ZyEntry=4, Table 1, Row 4. U.S. EPA, 2015, "EPA and NHTSA Propose Standards to Reduce Greenhouse Gas Emissions and Improve Fuel Efficiency of Medium- and Heavy-Duty Vehicles for Model Year 2018 and Beyond", https://nepis.epa.gov/Exe/ZyNET.exe/P100P7NL.txt?ZyActionD=ZyDocument&Client=EPA&Index=2016%20Thru%202020&Docs=&Query=&Time=&EndTime=&SearchMethod=1&TocRestrict=n&Toc=&TocEntry=&QField=&QFieldYear=&QFieldMonth=&QFieldDay=&UseQField=&IntQFieldOp=0&ExtQFieldOp=0&XmlQuery=&File=D%3A%5CZYFILES%5CINDEX%20DATA%5C16THRU20%5CTXT%5C00000002%5CP100P7NL.txt&User=ANONYMOUS&Password=anonymous&SortMethod=h%7C-&MaximumDocuments=1&FuzzyDegree=0&ImageQuality=r75g8/r75g8/x150y150g16/i425&Display=hpfr&DefSeekPage=x&SearchBack=ZyActionL&Back=ZyActionS&BackDesc=Results%20page&MaximumPages=1&ZyEntry=3, Page 3. https://theicct.org/sites/default/files/publications/ICCT_ShipEfficiency_20130723.pdf Others calculated from model input data. | N11: National Research Council, 2013, "Transitions to Alternative Vehicles and Fuels", https://www.nap.edu/catalog/18264/transitions-to-alternative-vehicles-and-fuels, Table 2.9, Fuel economy test mpg. U.S. DoE, 2013, "Potential for Energy Efficiency Improvement Beyond the Light-Duty-Vehicle Sector," http://www.nrel.gov/docs/fy13osti/55637.pdf, Table 2.2 and Section 3.4.5, Paragraph 1 David McCollum, Gregory Gould, and Davide Greene, 2009, "Greenhouse Gas Emissions from Aviation and Marine Transportation: Mitigation Potential and Policies", Pew Center on Global Climate Change, http://www.c2es.org/docUploads/aviation-and-marine-report-2009.pdf, Table 4 https://theicct.org/sites/default/files/publications/ICCT_ShipEfficiency_20130723.pdf
A12: Transportation | B12: Low Carbon Fuel Standard | C12: Additional LCFS Percentage | D12: Low Carbon Fuel Standard | E12: trans LCFS | F12: 0 | G12: 1 | H12: 0.01 | I12: % reduction in carbon emissions | J12: **Description:** This policy specifies the percentage reduction in carbon emissions from the transportation sector that must be achieved via fuel switching. This value is in addition to BAU requirements. // **Guidance for setting values:** China does not have LCFS. The U.S. National Renewable Fuel Standard equates to a BAU LCFS of 2.2% - 4.6% (varying by year). California adopted an LCFS that requires a 10% reduction in carbon intensity of the transportation fuel pool by 2020. | K12: transportation-sector-main.html#lcfs | L12: low-carbon-fuel-standard.html | M12: https://www.arb.ca.gov/fuels/lcfs/background/basics.htm
A13: Transportation | B13: Mode Shifting | C13: Percent of Travel Demand Shifted to Other Modes or Eliminated | D13: Mode Shifting | E13: trans mode shifting | F13: 0 | G13: =-ROUND(MaxBoundCalculations!$B$206,2) -> 0.26 | H13: 0.01 | I13: % of trips shifted | J13: **Description:** This policy represents a set of measures aimed at reducing demand for passenger or freight transportation in the selected vehicle type(s). **Passenger LDV** trips may be shifted to other travel modes, such as buses, rail, walking, biking, or eliminated through technology such as videoconferencing. Example measures include improved public transit systems, more walking and bike paths, zoning for higher density along transit corridors, zoning for mixed-use developments, roadway and congestion pricing, and increased parking fees. **Aircraft** trips may be shifted to inter-city rail or eliminated using technology such as videoconferencing. **Freight Truck** trips can be reduced through improved logistics that avoids backhauls and transporting empty shipping containers. // **Guidance for setting values:** The Inner Mongolia Autonomous Region has not issued any updated relevant official policies. | K13: transportation-sector-main.html#tdm | L13: transportation-demand-management.html | M13: International Energy Agency, 2009, "Transport, Energy and CO2: Moving toward Sustainability", http://www.iea.org/publications/freepublications/publication/transport2009.pdf "Freight Facts and Figures", 2013, https://ops.fhwa.dot.gov/freight/freight_analysis/nat_freight_stats/docs/13factsfigures/pdfs/fff2013_highres.pdf
A14: Buildings and Appliances | B14: Building Component Electrification | C14: Fraction of New Bldg Components Shifted to Other Fuels | D14: Building Component Electrification | E14: bldgs new component fuel shifting | F14: 0 | G14: 1 | H14: 0.01 | I14: % of newly sold non-electric building components | J14: **Description:** This policy replaces the specified fraction of newly sold non-electric building components of the selected type(s) in buildings of the selected type(s) with electricity-using components. // **Guidance for setting values:** The "Implementation Plan for Carbon Peaking in Urban and Rural Buildings" promotes the 100% electrification of newly-built public buildings, and encourages the electrification of heating, water heating, cooking, etc. in the building sector. By 2030, electricity accounts for more than 65% of building energy consumption. | K14: buildings-sector-main.html#component-elec | L14: building-component-electrification.html | M14: EIA AEO
A15: Buildings and Appliances | B15: Building Energy Efficiency Standards | C15: Reduction in E Use Allowed by Component Eff Std | D15: Building Energy Efficiency Standards | E15: bldgs efficiency standards | F15: 0 | G15: 1 | H15: 0.01 | I15: % reduction in energy use | J15: **Description:** This policy tightens energy efficiency standards for the selected component(s) in the selected building type(s). The policy only applies to newly sold components each year (whether for new buildings or replacement of old components of existing buildings). // **Guidance for setting values:** The average energy-saving rate of one-star green residential buildings is no higher than the mandatory energy-saving rate, while 10% higher for two-star and three-star buildings; According to the Technical Standards for Near-Zero Energy Buildings (GB/T51350-2019), ultra-low energy buildings are to save 50% more energy (residential and public buildings) on the compared to mandatory standards; near-zero energy buildings are to save 60%-75% more energy (75% for residential and 60% for public buildings). | K15: buildings-sector-main.html#eff-stds | L15: building-energy-efficiency-standards.html | M15: Edison Foundation, 2011, "Assessment of Electricity Savings in the U.S. Achievable through New Appliance/Equipment Efficiency Standards and Building Efficiency Codes (2010 - 2025)", http://www.edisonfoundation.net/iei/Documents/IEE_CodesandStandardsAssessment_2010-2025_UPDATE.pdf, Page B-2, Table B-1. | N15: Itron, 2007, "ASSESSMENT OF LONG-TERM ELECTRIC ENERGY EFFICIENCY POTENTIAL IN CALIFORNIA’S RESIDENTIAL SECTOR," http://www.energy.ca.gov/2007publications/CEC-500-2007-002/CEC-500-2007-002.PDF, p.33, Table 5-1
A16: Buildings and Appliances | B16: Contractor Training | C16: Boolean Improved Contractor Edu and Training | D16: Contractor Training | E16: bldgs contractor training | F16: 0 | G16: 1 | H16: 1 | I16: on/off | J16: **Description:** This policy represents a program to train contractors in energy-efficient products and installation practices. This covers activities such as air sealing, building framing, and choice and application of insulation. This policy affects newly sold building envelope components, which reduce the energy use of heating, cooling, and ventilation systems in buildings by 3.7% (based on a 2006 study from the Energy Center of Wisconsin). | K16: buildings-sector-main.html#contractor-ed | L16: contractor-training.html
A17: Buildings and Appliances | B17: Distributed Solar Carve-Out | C17: Min Fraction of Total Elec Demand to be Met by Distributed Solar PV | D17: Distributed Solar Promotion | E17: bldgs min fraction distributed solar | F17: 0 | G17: =ROUND(MaxBoundCalculations!B172,2) -> 0.24 | H17: 0.005 | I17: minimum % elec from solar | J17: **Description:** This policy requires at least the specified percentage of total retail electricity demand to be generated by residential and commercial buildings' distributed solar systems (typically rooftop PV). // **Guidance for setting values:**The proportion of electricity from rooftop PV in the total electricity consumption. | K17: buildings-sector-main.html#solar-carve-out | L17: solar-carve-out.html | M17: MASSACHUSETTS: http://www.mass.gov/eea/energy-utilities-clean-tech/renewable-energy/solar/rps-solar-carve-out/current-status-of-the-rps-solar-carve-out-program.html COLORADO: http://www.seia.org/research-resources/rps-solar-carve-out-colorado | N17: RMI, 2011, "Reinventing Fire Electricity Sector Methodology," http://www.rmi.org/cms/Download.aspx?id=10765&file=Reinventing+Fire+Electricity+Sector+Methodology.pdf&title=Reinventing+Fire+Electricity+Sector+Methodology, Page 11, 2050 Generation by Case
A18: Buildings and Appliances | B18: Distributed Solar Subsidy | C18: Perc Subsidy for Distributed Solar PV Capacity | D18: Distributed Solar Promotion | E18: bldgs distributed solar subsidy | F18: 0 | G18: 0.5 | H18: 0.01 | I18: % of PV system cost | J18: **Description:** This policy causes the government to reimburse building owners for a percentage of the cost of new distributed solar PV capacity that is installed on or around buildings. // **Guidance for setting values:** According to "Notice on matters related to the new energy feed-in tariff policy in 2021", from 2021 onwards for the new record of centralized photovoltaic power plants, commercial and industrial distributed photovoltaic projects and newly approved onshore wind power projects, the central government no longer subsidize. | K18: buildings-sector-main.html#distributed-solar-subsidy | L18: distributed-solar-subsidy.html | M18: Department of Energy. Business Energy Investment Tax Credit (ITC). http://energy.gov/savings/business-energy-investment-tax-credit-itc
A19: Buildings and Appliances | B19: Improved Labeling | C19: Boolean Improved Device Labeling | D19: Improved Labeling | E19: bldgs device labeling | F19: 0 | G19: 1 | H19: 1 | I19: on/off | J19: **Description:** This policy represents a program requiring newly sold heating systems, cooling and ventilation systems, and appliances to feature prominent, well-designed labels highlighting their energy efficiencies. The policy reduces energy consumption of newly sold building components of these types by 10%.// **Guidance for setting values:** China has implemented the "Energy Efficiency Labeling Management Measures" since 2016. | K19: buildings-sector-main.html#device-labeling | L19: improved-labeling.html | M19: none
A20: Buildings and Appliances | B20: Retrofit Existing Buildings | C20: Share of Preexisting Buildings Subject to Retrofitting | D20: Increased Retrofitting | E20: bldgs retrofitting | F20: 0 | G20: 0.5 | H20: 0.01 | I20: % of existing buildings | J20: **Description:** Each year, the specified percentage of the selected building type(s) that existed at the start of the model run will be retrofit with more efficient heating, cooling, and envelope components. // **Guidance for setting values:** China's target during 2020-2025 is around 0.1%, while the annual building retrofitting rate must increase to 2.5% by 2030 in developed economies to achieve net zero emission. | K20: buildings-sector-main.html#retrofitting | L20: increased-retrofitting.html | M20: Calculated from model data; see the relevant variable(s) in the InputData folder for source information.
A21: Buildings and Appliances | B21: Rebate for Efficient Products | C21: Boolean Rebate Program for Efficient Components | D21: Rebate for Efficient Products | E21: bldgs rebate | F21: 0 | G21: 1 | H21: 1 | I21: on/off | J21: **Description:** This policy represents a modest rebate paid to customers who purchase energy-efficient building equipment of the selected type(s). **Guidance for setting values:** After releasing Notice on Several Measures to Promote The Consumption of Green Smart Home Appliances, provincial and municipal implementation landed. | K21: buildings-sector-main.html#rebate | L21: rebate-for-efficient-products.html
A22: Electricity Supply | B22: Ban New Power Plants | C22: Boolean Ban New Power Plants | D22: Ban New Power Plants | E22: elec ban new power plants | F22: 0 | G22: 1 | H22: 1 | I22: on/off | J22: **Description:** This policy prevents new capacity of the selected type(s) from being built or deployed. | K22: electricity-sector-main.html#ban | L22: ban-new-capacity.html
A23: Electricity Supply | B23: Carbon Capture and Sequestration | C23: Electricity Sector Fraction of Potential Additional CCS Achieved | D23: Clean Electricity Standard | E23: elec CCS | F23: 0 | G23: 1 | H23: 0.01 | I23: % of CO2 captured | J23: **Description:** This policy specifies the fraction of CO2 emissions from power plants that is captured and stored, above the amount predicted in the business-as-usual scenario. // **Guidance for setting values:** As very few CCS-equipped power plants exist today, a value above 20% or so is likely very optimistic in most policy scenarios. The main exception would be a scenario in which most fossil power plants retire due to other policies, making it feasible to equip a high percentage of the few surviving fossil plants with CCS. | K23: ccs.html#ccs | L23: carbon-capture-and-sequestration.html
A24: Electricity Supply | B24: Renewable Energy | C24: Renewable Portfolio Std Percentage | D24: Renewable Energy | E24: elec renewable portfolio standards | F24: 0 | G24: 1 | H24: 0.01 | I24: % of electricity generation | J24: **Description:** This policy specifies an increase in the fraction of electricity generation that must come from qualifying carbon-free sources (wind, solar, biomass, nuclear, hydro, and geothermal) in 2060. This policy has no effect until the user-set value exceeds the existing fraction of carbon-free electricity and any carbon-free electricity standards reflected in BAU. // **Guidance for setting values:** China came out with new RPS policies to reach about 33% in 2025. A request for public opinion, a goal of 40% for all provinces except Tibet in 2030 was proposed. Inner Mongolia's Energy 14th FYP declared the that share of non-fossil power generation will rise from 17.3% in 2020, to 30% by 2035. When setting a high CES with this lever, users should also turn on supporting power sector policies (i.e., Grid-Scale Electricity Storage, Increase Transmission, and Demand Response) to avoid curtailment of renewables. At very high CES values, the associated policy costs are highly uncertain and should be complemented with other modeling. | K24: electricity-sector-main.html#ces | L24: clean-energy-standard.html | M24: White House, 2015, "Fact Sheet: President Obama to Announce Historic Carbon Pollution Standards for Power Plants", https://www.whitehouse.gov/the-press-office/2015/08/03/fact-sheet-president-obama-announce-historic-carbon-pollution-standards.
A25: Electricity Supply | B25: Change Electricity Exports | C25: Percent Change in Electricity Exports | D25: Electricity Imports and Exports | E25: elec change exports | F25: -0.5 | G25: 1 | H25: 0.02 | I25: % change in exports | J25: **Description:** This policy increases or decreases the amount of electricity exported from Shandong. It does not cause the construction or removal of transmission lines linking the province. // **Guidance for setting values:** Thanks to its vast land area, great solar and wind resource, and abundant coal reserve. Inner Mongolia has always been a major power provider in China, the construction of new export powerline enhances its capability to export. Between 2017 and 2021, Inner Mongolia's annual electricity export has increased from 156TWh to 247TWh, and is seeking to continuely increase its capacity to export renewable energy. | K25: electricity-sector-main.html#elec-exports | L25: electricity-imports-exports.html | M25: Energy Information Administation. 2016. Electric Power Annual. Table 2.13.
A26: Electricity Supply | B26: Change Electricity Imports | C26: Percent Change in Electricity Imports | D26: Electricity Imports and Exports | E26: elec change imports | F26: -0.5 | G26: 1 | H26: 0.02 | I26: % change in imports | J26: **Description:** This policy increases or decreases the amount of electricity imported to Shandong. It does not cause the construction or removal of transmission lines linking the province. // **Guidance for setting values:** Eastern Inner Mongolia accepts power from China's northeast regions, particular Jilin province, whereas western Inner Mongolia imports power from Shanxi and Ningxia Province, but its electricity import is much smaller than export. | K26: electricity-sector-main.html#elec-imports | L26: electricity-imports-exports.html | M26: Energy Information Administation. 2016. Electric Power Annual. Table 2.13.
A27: Electricity Supply | B27: Non BAU Guaranteed Dispatch | C27: Boolean Use Non BAU Guaranteed Dispatch Settings | D27: Non BAU Guaranteed Dispatch | E27: elec non BAU guaranteed dispatch | F27: 0 | G27: 1 | H27: 1 | I27: on/off | J27: **Description:** This policy uses an alternative garanteed dispatched percentage for each type of generation. // **Guidance for setting values:** China currently has a garanteed full purchase of renewable generation (wind, solar, biomass, geothermal and tidal energy). However, the policy may not be preferable as renewable penetration continues to grow. An alternative garanteed dispatch percentage is set at 80% for wind and solar, and 50% for all other renewable generation.
A28: Electricity Supply | B28: Demand Response | C28: Fraction of Additional Demand Response Potential Achieved | D28: Demand Response | E28: elec demand response | F28: 0 | G28: 1 | H28: 0.01 | I28: % of potential achieved | J28: **Description:** This policy represents regulations that cause more demand response (DR) capacity to be added to the electric grid. Demand response provides flexibility that allows for the integration of more wind and solar PV, if the electricity system is flexibility-constrained. // **Guidance for setting values:** A 100% setting provides will make Inner Mongolia's DR capacity to reach 20% of peak hour demand capacity by 2035, instead of the 3% requirement released in 2016. The announced policy scenario increases the DR capacity to 8% by 2030, as laid out in Western Inner Mongolia New Power System Action Plan. | K28: electricity-sector-main.html#dr | L28: demand-response.html | M28: Calculated from model data; see the relevant variable(s) in the InputData folder for source information.
A29: Electricity Supply | B29: Early Retirement of Power Plants | C29: Annual Additional Capacity Retired due to Early Retirement Policy | D29: Early Retirement of Power Plants | E29: elec early retirement | F29: 0 | G29: 25000 | H29: 500 | I29: MW/year | J29: **Description:** This policy causes the specified quantity of otherwise non-retiring capacity of the selected type(s) to be retired each year. | K29: electricity-sector-main.html#early-ret | L29: early-retirement-of-power-plants.html | M29: Energy Information Administration, 2014, "Annual Energy Outlook 2014", http://www.eia.gov/oiaf/aeo/tablebrowser/#release=AEO2014&subject=6-AEO2014&table=9-AEO2014&region=0-0&cases=hccstom-d012314a,ref2014-d102413a, Table Browser. Select Electric Power Sector, Electricity Generating Capacity (and check Reference and Accelerated coal retirements scenarios). | N29: The Brattle Group, 2012, "Potential Coal Plant Retirements: 2012 Update," http://greatlakeslegalfoundation.org/wwcms/wp-content/uploads/documents/regulatory/TrainWreck/12Oct15_BrattleStudy.pdf, Page 8, Table 4
A30: Electricity Supply | B30: Grid-Scale Electricity Storage | C30: Fraction of Additional Grid Battery Storage Potential Achieved | D30: Grid-Scale Electricity Storage | E30: elec storage growth | F30: 0 | G30: 1 | H30: 0.01 | I30: % of potential achieved | J30: **Description:** This policy causes grid-scale electricity storage from chemical batteries to increase above the amount predicted in the BAU Scenario. // **Guidance for setting values:** A 100% setting provides will double Inner Mongolia's grid side battery installation from 31 GW to 205 GW in 2060. | K30: electricity-sector-main.html#storage | L30: grid-scale-electricity-storage.html | M30: National Renewable Energy Laboratory, 2014, Renewable Electricity Futures Scenario Viewer, http://www.nrel.gov/analysis/re_futures/data_viewer/# 80% RE-ITI (2014) scenario
A31: Electricity Supply | B31: Increase Transmission | C31: Percentage Increase in Transmission Capacity vs BAU | D31: Increase Transmission | E31: elec transmission growth | F31: 0 | G31: =ROUND(MaxBoundCalculations!B181,2) -> 1.13 | H31: 0.01 | I31: % increase in transmission capacity | J31: **Description:** This policy causes additional transmission capacity to be built relative to the BAU case. Transmission increases the flexibility of the grid, allowing for the integration of more wind and solar PV, if the electricity system is flexibility-constrained. // **Guidance for setting values:** According to our current setting, Inner Mongolia's transmission capacity grows proportionally with its total generation capacity. The renewable generation growth generally is not constrained by transmission or system flexibility. Increasing transmission will not significantly alter the model's output. | K31: electricity-sector-main.html#transmission | L31: increase-transmission.html | M31: National Renewable Energy Laboratory, 2014, Renewable Electricity Futures (Vol. 1), http://www.nrel.gov/docs/fy12osti/52409-1.pdf, Page xli, Figure ES-8, 80% RE scenario. | N31: National Renewable Energy Laboratory, 2014, Renewable Electricity Futures (Vol. 1), http://www.nrel.gov/docs/fy12osti/52409-1.pdf, Page 2-10, 90% RE scenario.
A32: Electricity Supply | B32: Non BAU Capacity Retirement Schedule | C32: Boolean Use Non BAU Capacity Retirement Schedule | D32: Non BAU Capacity Retirement Schedule | F32: 0 | G32: 1 | H32: 1 | I32: on/off | J32: **Description:** This policy uses an alternative retirement schedule for existing capacity of the selected type(s). // **Guidance for setting values:** The alternative retirement schedule considers the additional capacity installed in the non BAU mandated capacity construction, so for a given type of generation, it is best to turn on/off retirement and construction schedule at the same time.
A33: Electricity Supply | B33: Non BAU Mandated Capacity Construction | C33: Boolean Use Non BAU Mandated Capacity Construction Schedule | D33: Non BAU Mandated Capacity Construction | F33: 0 | G33: 1 | H33: 1 | I33: on/off | J33: **Description:** The business-as-usual case includes all planned capacity additions. // **Guidance for setting values:** This policy includes all announced plant projects to date as well as the targets annouced in Inner Mongolia's 14th FYP. Since China has loosen its constraints in coal generation recently, the alternative schedule will include more coal capacity. The alternative retirement schedule considers the additional capacity installed in the non BAU mandated capacity construction, so for a given type of generation, it is best to turn on/off retirement and construction schedule at the same time.
A34: Electricity Supply | B34: Non BAU RPS Qualifying Resources | C34: Boolean Use Non BAU RPS Qualifying Resource Definitions | D34: Non BAU RPS Qualifying Resources | E34: elec non BAU RPS qualifying resources | F34: 0 | G34: 1 | H34: 1 | I34: on/off | J34: **Description:** This policy uses an alternative definition of what qualifies as renewable generation. // **Guidance for setting values:** Under BAU scenario, all non-fossil fuel generation are viewed as Renewable in China. Under alternative assumption, nuclear and hydro are excluded for environmental and safety concerns. Biomass and municipal solid waste generation are also excluded as they are not truly carbon-neutral.
A35: Electricity Supply | B35: Nuclear Plant Lifetime Extension | C35: Nuclear Capacity Lifetime Extension | D35: Nuclear Lifetime Extension | F35: 0 | G35: 20 | H35: 1 | I35: year(s) | J35: **Description:** This policy extends the lifetime of all nuclear plants by the specified number of years. | K35: electricity-sector-main.html#life-ext | L35: nuclear-lifetime-extension.html | M35: U.S. Energy Information Administration, 2014, "Almost all U.S. nuclear plants require life extension past 60 years to operate beyond 2050", http://www.eia.gov/todayinenergy/detail.cfm?id=19091. | N35: U.S. Energy Information Administration, 2014, "Almost all U.S. nuclear plants require life extension past 60 years to operate beyond 2050", http://www.eia.gov/todayinenergy/detail.cfm?id=19091.
A36: Electricity Supply | B36: Reduce Plant Downtime | C36: Percentage Reduction in Plant Downtime | D36: Reduce Plant Downtime | E36: elec reduce plant downtime | F36: 0 | G36: 0.6 | H36: 0.01 | I36: % reduction in downtime | J36: **Description:** This policy specifies the reduction in downtime (time spent not generating power) for plants of the selected type(s) that exist at the start of the model run. This policy increases these plants' target capacity factors, but it does not force them to be dispatched if it would be uneconomical to do so. // **Guidance for setting values:** // **Preexisting Natural Gas Nonpeaker:** Preexisting natural gas nonpeakers have an average capacity factor of 48%. As part of the proposed Clean Power Plan, the EPA assumed that nonpeaking natural gas plants could be reach a 75% capacity factor (ramping up to that value over a number of years). This would represent a 49% reduction in downtime. // **New Wind:** Availability of wind cannot be changed by policy, so the main method of increasing capacity factor is technological improvement of wind turbines. The National Renewable Energy Laboratory estimates that "near-future" wind technology could increase capacity factors by about 10 percentage points in most parts of the country. The average capacity factor of new turbines in the BAU case is roughly 47%, so an improvement to 57% might be represented as an 19% setting of this policy lever. // **New Solar PV:** Availability of sunlight cannot be changed by policy, so the main method of improvement is increasing the efficiency of solar cells. Typical crystalline silicon cells today have efficiencies of 20-25%, while today's best multi-junction cells (used primarily in concentrator PV and aerospace applications) have efficiencies of 40-45%. If the typical cells installed in 2050 will have efficiencies similar to today's best multi-junction cells, this might be represented as a 26% setting of this policy lever. | K36: electricity-sector-main.html#red-downtime | L36: reduce-downtime.html | M36: E&E Publishing. The Clean Power Plan - A Summary. http://www.eenews.net/interactive/clean_power_plan/fact_sheets/rule National Renewable Energy Laboratory. United States (48 Contiguous States) Potential Wind Capacity Cumulative Area vs. Gross Capacity Factor. http://apps2.eere.energy.gov/wind/windexchange/pdfs/wind_maps/us_contiguous_wind_potential_chart.pdf See the discussion of multi-junction solar cells on Wikipedia at https://en.wikipedia.org/wiki/Multi-junction_solar_cell. Also NREL has a useful chart at http://www.nrel.gov/ncpv/images/efficiency_chart.jpg.
A37: Electricity Supply | B37: Reduce Soft Costs | C37: Percent Reduction in Soft Costs of Capacity Construction | D37: Reduce Soft Costs | E37: elec reduce soft costs | F37: 0 | G37: 0.9 | H37: 0.01 | I37: % reduction in soft costs | J37: **Description:** This policy specifies a reduction in soft costs (costs for things other than capital equipment) for new plants of the selected type(s), such as the costs of permitting, financing, project management, assembly, etc. // **Guidance for setting values:** Costs of permitting and financing can be reduced by streamlining permitting processes, but some soft costs (such as labor) may be difficult to reduce via policy. A value of 50% would be an aggressive soft cost reduction. | K37: endogenous-learning.html#red-soft-costs | L37: reduce-soft-costs.html
A38: Electricity Supply | B38: Reduce Transmission & Distribution Losses | C38: Percentage TnD Losses Avoided | D38: Reduce T&D Losses | E38: elec avoid TND loss | F38: 0 | G38: 0.4 | H38: 0.01 | I38: % of losses avoided | J38: **Description:** This policy specifies the reduction in transmission and distribution losses that will be achieved by 2050. // **Guidance for setting values:** In 2020, Inner Mongolia's electricity transmission losses is about 3.82% according to statistics, which is lower than the national average by 1.4%. In its 14th FYP, the Autonomous Region announced to reduce losses to 3.5% by 2025, or 8.46% decrease compared to BAU. | K38: electricity-sector-main.html#red-tnd-losses | L38: reduce-tnd-losses.html | M38: The World Bank. Electric power transmission and distribution losses (% of output). http://data.worldbank.org/indicator/EG.ELC.LOSS.ZS
A39: Electricity Supply | B39: Subsidy for Capacity Construction | C39: Perc Subsidy for Elec Capacity Construction | D39: Subsidy for Capacity Construction | E39: elec capacity construction subsidy | F39: 0 | G39: 0.95 | H39: 0.01 | I39: % of construction cost | J39: **Description:** This policy is a subsidy paid by the government to electricity suppliers per unit of new capacity constructed. This only applies to utilities, not distributed systems (such as rooftop solar). // **Guidance for setting values:** Generally speaking, China is phasing out subsidy for renewables gradually. However, there might be local subsidies still in place. | K39: electricity-sector-main.html#subsidies | M39: https://www.energy.gov/articles/secretary-perry-announces-financial-close-additional-loan-guarantees-during-trip-vogtle https://www.energysage.com/solar/cost-benefit/solar-investment-tax-credit/ http://biomassmagazine.com/articles/8185/usda-loan-guarantees-support-3-biomass-power-plants
A40: Electricity Supply | B40: Subsidy for Electricity Production | C40: Subsidy for Elec Production by Fuel | D40: Subsidy for Electricity Production | E40: elec generation subsidy | F40: 0 | G40: 60 | H40: 1 | I40: =UnitControlCenter!$B$48 -> 2020 RMB / MWh | J40: **Description:** This policy is a subsidy paid by the government to suppliers of electricity per unit of electricity generated from the selected plant type(s). // **Guidance for setting values:** China is phasing out subsidy for renewables gradually. However, there are still subsidies for renewables in subnational regions. | K40: electricity-sector-main.html#subsidies | L40: subsidy-for-electricity-production.html | M40: PRODUCTION TAX CREDIT: Database of State Incentives for Renewables & Efficiency, 2013, "Renewable Energy Production Tax Credit (PTC)", http://dsireusa.org/incentives/incentive.cfm?Incentive_Code=US13F. STATE-LEVEL INCENTIVES: Energy Information Administration, 2013, "Feed-In Tariffs and similar programs", http://www.eia.gov/electricity/policies/provider_programs.cfm.
...

Sheet PolicyLevers
A1: Sector | B1: Short Name | C1: Vensim Variable Name | D1: Subscript 1 Value | E1: Subscript 2 Value | F1: Subscript 1 Display Name | G1: Subscript 2 Display Name | H1: Policy ID Number | I1: Include in Web App | J1: Policy Group | K1: Policy Schedule Subscript | L1: Min Slider Value | M1: Max Slider Value | N1: Slider Step Size | O1: Units | P1: Text for Pop-Over Panel Description | Q1: URL for "How the model handles this policy" links | R1: URL for "How to design this policy well" links
A2: =IF(ISBLANK(INDEX('Policy Characteristics'!A:A,MATCH($C2,'Policy Characteristics'!$C:$C,0))),"",INDEX('Policy Characteristics'!A:A,MATCH($C2,'Policy Characteristics'!$C:$C,0))) -> Transportation | B2: =IF(ISBLANK(INDEX('Policy Characteristics'!B:B,MATCH($C2,'Policy Characteristics'!$C:$C,0))),"",INDEX('Policy Characteristics'!B:B,MATCH($C2,'Policy Characteristics'!$C:$C,0))) -> Conventional Pollutant Standards | C2: Percentage Reduction of Separately Regulated Pollutants | D2: LDVs | E2: VOC | F2: Passenger cars, SUVs, Light and Medium Commercial Trucks | G2: VOCs | H2: 300 | I2: Yes | J2: =IF(ISBLANK(INDEX('Policy Characteristics'!D:D,MATCH($C2,'Policy Characteristics'!$C:$C,0))),"",INDEX('Policy Characteristics'!D:D,MATCH($C2,'Policy Characteristics'!$C:$C,0))) -> Conventional Pollutant Standard | K2: =IF(ISBLANK(INDEX('Policy Characteristics'!E:E,MATCH($C2,'Policy Characteristics'!$C:$C,0))),"",INDEX('Policy Characteristics'!E:E,MATCH($C2,'Policy Characteristics'!$C:$C,0))) -> trans reduce regulated pollutants | L2: =IF(ISBLANK(INDEX('Policy Characteristics'!F:F,MATCH($C2,'Policy Characteristics'!$C:$C,0))),"",INDEX('Policy Characteristics'!F:F,MATCH($C2,'Policy Characteristics'!$C:$C,0))) -> 0 | M2: =IF(ISBLANK(INDEX('Policy Characteristics'!G:G,MATCH($C2,'Policy Characteristics'!$C:$C,0))),"",INDEX('Policy Characteristics'!G:G,MATCH($C2,'Policy Characteristics'!$C:$C,0))) -> 1 | N2: =IF(ISBLANK(INDEX('Policy Characteristics'!H:H,MATCH($C2,'Policy Characteristics'!$C:$C,0))),"",INDEX('Policy Characteristics'!H:H,MATCH($C2,'Policy Characteristics'!$C:$C,0))) -> 0.02 | O2: =IF(ISBLANK(INDEX('Policy Characteristics'!I:I,MATCH($C2,'Policy Characteristics'!$C:$C,0))),"",INDEX('Policy Characteristics'!I:I,MATCH($C2,'Policy Characteristics'!$C:$C,0))) -> % reduction in emissions | P2: =IF(ISBLANK(INDEX('Policy Characteristics'!J:J,MATCH($C2,'Policy Characteristics'!$C:$C,0))),"",INDEX('Policy Characteristics'!J:J,MATCH($C2,'Policy Characteristics'!$C:$C,0))) -> **Description:** This policy represents strengthening standards for the selected pollutant(s) emitted by the selected vehicle type(s). Conventional pollutants' most important, harmful impacts are on human health rather than on climate change. // **Guidance for setting values:** By 2025, the concentration of fine particulate matter (PM2.5) in prefectural-level and above cities will be 10% lower than that in 2020, and the total emissions of volatile organic compounds (VOCs) and nitrogen oxides will be more than 10% lower than that in 2020 respectively. (Reference: Opinions of the CPC and the State Council on Further Combating Pollution and Preventing the Battle against Pollution) | Q2: =IF(ISBLANK(INDEX('Policy Characteristics'!K:K,MATCH($C2,'Policy Characteristics'!$C:$C,0))),"",INDEX('Policy Characteristics'!K:K,MATCH($C2,'Policy Characteristics'!$C:$C,0))) -> transportation-sector-main.html#conv-pol-stds | R2: =IF(ISBLANK(INDEX('Policy Characteristics'!L:L,MATCH($C2,'Policy Characteristics'!$C:$C,0))),"",INDEX('Policy Characteristics'!L:L,MATCH($C2,'Policy Characteristics'!$C:$C,0))) -> conventional-pollutant-standards.html
A3: =IF(ISBLANK(INDEX('Policy Characteristics'!A:A,MATCH($C3,'Policy Characteristics'!$C:$C,0))),"",INDEX('Policy Characteristics'!A:A,MATCH($C3,'Policy Characteristics'!$C:$C,0))) -> Transportation | B3: =IF(ISBLANK(INDEX('Policy Characteristics'!B:B,MATCH($C3,'Policy Characteristics'!$C:$C,0))),"",INDEX('Policy Characteristics'!B:B,MATCH($C3,'Policy Characteristics'!$C:$C,0))) -> Conventional Pollutant Standards | C3: =C$2 -> Percentage Reduction of Separately Regulated Pollutants | D3: LDVs | E3: CO | F3: Passenger cars, SUVs, Light and Medium Commercial Trucks | G3: CO | H3: 301 | I3: Yes | J3: =IF(ISBLANK(INDEX('Policy Characteristics'!D:D,MATCH($C3,'Policy Characteristics'!$C:$C,0))),"",INDEX('Policy Characteristics'!D:D,MATCH($C3,'Policy Characteristics'!$C:$C,0))) -> Conventional Pollutant Standard | K3: =IF(ISBLANK(INDEX('Policy Characteristics'!E:E,MATCH($C3,'Policy Characteristics'!$C:$C,0))),"",INDEX('Policy Characteristics'!E:E,MATCH($C3,'Policy Characteristics'!$C:$C,0))) -> trans reduce regulated pollutants | L3: =IF(ISBLANK(INDEX('Policy Characteristics'!F:F,MATCH($C3,'Policy Characteristics'!$C:$C,0))),"",INDEX('Policy Characteristics'!F:F,MATCH($C3,'Policy Characteristics'!$C:$C,0))) -> 0 | M3: =IF(ISBLANK(INDEX('Policy Characteristics'!G:G,MATCH($C3,'Policy Characteristics'!$C:$C,0))),"",INDEX('Policy Characteristics'!G:G,MATCH($C3,'Policy Characteristics'!$C:$C,0))) -> 1 | N3: =IF(ISBLANK(INDEX('Policy Characteristics'!H:H,MATCH($C3,'Policy Characteristics'!$C:$C,0))),"",INDEX('Policy Characteristics'!H:H,MATCH($C3,'Policy Characteristics'!$C:$C,0))) -> 0.02 | O3: =IF(ISBLANK(INDEX('Policy Characteristics'!I:I,MATCH($C3,'Policy Characteristics'!$C:$C,0))),"",INDEX('Policy Characteristics'!I:I,MATCH($C3,'Policy Characteristics'!$C:$C,0))) -> % reduction in emissions | P3: =IF(ISBLANK(INDEX('Policy Characteristics'!J:J,MATCH($C3,'Policy Characteristics'!$C:$C,0))),"",INDEX('Policy Characteristics'!J:J,MATCH($C3,'Policy Characteristics'!$C:$C,0))) -> **Description:** This policy represents strengthening standards for the selected pollutant(s) emitted by the selected vehicle type(s). Conventional pollutants' most important, harmful impacts are on human health rather than on climate change. // **Guidance for setting values:** By 2025, the concentration of fine particulate matter (PM2.5) in prefectural-level and above cities will be 10% lower than that in 2020, and the total emissions of volatile organic compounds (VOCs) and nitrogen oxides will be more than 10% lower than that in 2020 respectively. (Reference: Opinions of the CPC and the State Council on Further Combating Pollution and Preventing the Battle against Pollution) | Q3: =IF(ISBLANK(INDEX('Policy Characteristics'!K:K,MATCH($C3,'Policy Characteristics'!$C:$C,0))),"",INDEX('Policy Characteristics'!K:K,MATCH($C3,'Policy Characteristics'!$C:$C,0))) -> transportation-sector-main.html#conv-pol-stds | R3: =IF(ISBLANK(INDEX('Policy Characteristics'!L:L,MATCH($C3,'Policy Characteristics'!$C:$C,0))),"",INDEX('Policy Characteristics'!L:L,MATCH($C3,'Policy Characteristics'!$C:$C,0))) -> conventional-pollutant-standards.html
A4: =IF(ISBLANK(INDEX('Policy Characteristics'!A:A,MATCH($C4,'Policy Characteristics'!$C:$C,0))),"",INDEX('Policy Characteristics'!A:A,MATCH($C4,'Policy Characteristics'!$C:$C,0))) -> Transportation | B4: =IF(ISBLANK(INDEX('Policy Characteristics'!B:B,MATCH($C4,'Policy Characteristics'!$C:$C,0))),"",INDEX('Policy Characteristics'!B:B,MATCH($C4,'Policy Characteristics'!$C:$C,0))) -> Conventional Pollutant Standards | C4: =C$2 -> Percentage Reduction of Separately Regulated Pollutants | D4: LDVs | E4: NOx | F4: Passenger cars, SUVs, Light and Medium Commercial Trucks | G4: NOx | H4: 302 | I4: Yes | J4: =IF(ISBLANK(INDEX('Policy Characteristics'!D:D,MATCH($C4,'Policy Characteristics'!$C:$C,0))),"",INDEX('Policy Characteristics'!D:D,MATCH($C4,'Policy Characteristics'!$C:$C,0))) -> Conventional Pollutant Standard | K4: =IF(ISBLANK(INDEX('Policy Characteristics'!E:E,MATCH($C4,'Policy Characteristics'!$C:$C,0))),"",INDEX('Policy Characteristics'!E:E,MATCH($C4,'Policy Characteristics'!$C:$C,0))) -> trans reduce regulated pollutants | L4: =IF(ISBLANK(INDEX('Policy Characteristics'!F:F,MATCH($C4,'Policy Characteristics'!$C:$C,0))),"",INDEX('Policy Characteristics'!F:F,MATCH($C4,'Policy Characteristics'!$C:$C,0))) -> 0 | M4: =IF(ISBLANK(INDEX('Policy Characteristics'!G:G,MATCH($C4,'Policy Characteristics'!$C:$C,0))),"",INDEX('Policy Characteristics'!G:G,MATCH($C4,'Policy Characteristics'!$C:$C,0))) -> 1 | N4: =IF(ISBLANK(INDEX('Policy Characteristics'!H:H,MATCH($C4,'Policy Characteristics'!$C:$C,0))),"",INDEX('Policy Characteristics'!H:H,MATCH($C4,'Policy Characteristics'!$C:$C,0))) -> 0.02 | O4: =IF(ISBLANK(INDEX('Policy Characteristics'!I:I,MATCH($C4,'Policy Characteristics'!$C:$C,0))),"",INDEX('Policy Characteristics'!I:I,MATCH($C4,'Policy Characteristics'!$C:$C,0))) -> % reduction in emissions | P4: =IF(ISBLANK(INDEX('Policy Characteristics'!J:J,MATCH($C4,'Policy Characteristics'!$C:$C,0))),"",INDEX('Policy Characteristics'!J:J,MATCH($C4,'Policy Characteristics'!$C:$C,0))) -> **Description:** This policy represents strengthening standards for the selected pollutant(s) emitted by the selected vehicle type(s). Conventional pollutants' most important, harmful impacts are on human health rather than on climate change. // **Guidance for setting values:** By 2025, the concentration of fine particulate matter (PM2.5) in prefectural-level and above cities will be 10% lower than that in 2020, and the total emissions of volatile organic compounds (VOCs) and nitrogen oxides will be more than 10% lower than that in 2020 respectively. (Reference: Opinions of the CPC and the State Council on Further Combating Pollution and Preventing the Battle against Pollution) | Q4: =IF(ISBLANK(INDEX('Policy Characteristics'!K:K,MATCH($C4,'Policy Characteristics'!$C:$C,0))),"",INDEX('Policy Characteristics'!K:K,MATCH($C4,'Policy Characteristics'!$C:$C,0))) -> transportation-sector-main.html#conv-pol-stds | R4: =IF(ISBLANK(INDEX('Policy Characteristics'!L:L,MATCH($C4,'Policy Characteristics'!$C:$C,0))),"",INDEX('Policy Characteristics'!L:L,MATCH($C4,'Policy Characteristics'!$C:$C,0))) -> conventional-pollutant-standards.html
