Workbook
Name BAU: [1]参数数据库!#REF!
Name CH4_Ar4_to_AR5: [2]Overview!$B$25
Name gal_per_barrel: [3]About!$A$63
Name gal_per_barrel: [3]About!$A$63
Name gal_per_barrel: About!$A$72
Name HHV_Adjust: [4]About!$A$203
Name IQ_CH: 110000
Name IQ_CQ: 5000
Name IQ_CY: 10000
Name IQ_DAILY: 500000
Name IQ_FH: 100000
Name IQ_FQ: 500
Name IQ_FY: 1000
Name IQ_LTM: 2000
Name IQ_MONTH: 15000
Name IQ_NTM: 6000
Name IQ_WEEK: 50000
Name IQ_YTD: 3000
Name metricton_to_shortton: [2]Overview!$B$19
Name million: [2]Overview!$B$22
Name N2O_AR4_to_AR5: [2]Overview!$B$26
Name quadrillion: [4]About!$A$215
Name shorttons_to_grams: [4]About!$A$214
Name trillion: [4]About!$A$216
Name use_lifecycle_biofuel_EIs: [4]About!$A$89
Name 情景二: [1]参数数据库!#REF!
Name 情景一: [1]参数数据库!#REF!
Name 手动输入: [1]参数数据库!#REF!

Sheet About
A1: BCF BTU per Small Fuel Output Unit
A2: BCF BTU per Large Fuel Output Unit
A3: BCF Vehicle Fuel Economy Unit Conversion Factors
A4: BCF BTU per Energy Import Export Output Unit
A6: Source: | B6: hard coal, natural gas, petroleum fuels, liquid biofuels | E6: Chinese Fuel Heat Value
B7: Energy Information Administration | E7: China State Administration for Market Regulation
B8: 2019 | E8: 国家市场监督管理总局
B9: Annual Energy Outlook 2019 | E9: 2021
B10: http://www.eia.gov/forecasts/aeo/supplement/excel/suptab_73.xlsx | E10: GB/T 2589-2020 General Rules for Calculation of the Comprehensive Energy Consumption
B11: Table 73 | E11: GB/T 2589-2020 综合能耗计算通则
E12: http://c.gb688.cn/bzgk/gb/showGb?type=online&hcno=53D1440B68E6D50B8BA0CCAB619B6B3E
B13: Lignite, Biomass, LPG, municipal solid waste, hydrogen | E13: Appendix A
B14: Argonne National Laboratory
B15: 2019 | E15: China Fuel Consumption and Additional Heat Values
B16: GREET1 2019 | E16: National Buearu of Statistics
B17: https://greet.es.anl.gov/ | E17: 国家统计局
B18: Tab "Fuel_Specs" | E18: 2021
E19: China Energy Statistical Yearbook
A20: Notes and Methodology | E20: 中国能源统计年鉴
A21: The most commonly used standardized energy unit used in China is standard coal equivalent (ce) | E21: Page 96-101 Table 5.1； Page 355-356
A22: China Energy Statistical Yearbook and National Standard GB/T 2589 defines the value of standard coal equivalent
A23: as well as the average low heat value of different fuels.
A24: As the Fuel Type used in the EPS model could match with multiple types of fuel listed in the China Energy
A25: Statistical Yearbook, we used the weighted average value of total consumption for each individual fuel types
A27: Note on Coal Gas: Coal Gas is a important component of China's energy consumption, but its heat content varies
A28: greatly based on how its produced and its hard to align with a EPS Fuel. Although it could be treated as either
A29: LPG or Natural Gas, we decided not to take it into account in calculating the BCF
A31: The Fuel Economy Output Unit is used to help compare fuel economy of different technologies of the same vehicle
A32: type (e.g. electric vs. gasoline LDVs). They will use a common unit, such as miles per gallon, even though electric
A33: LDVs do not use liquid fuel. The only fuel types that need data for Fuel Economy Output Unit are the "reference"
A34: fuel types that are used as the basis for comparing all of the vehicles of a given type, across technologies.
A35: This could be: petroleum gasoline (for LDVs and motorbikes), jet fuel (for aircraft), and petroleum diesel
... A45: Unit Conversion from US EPS of China Provincial EPS by Smart Trans
A46: Large Fuel Output Units | B46: US EPS | C46: CN Provincial EPS - En | D46: CN Provincial EPS - 中文
A47: electricity, district heat | B47: TWh | C47: TWh | D47: 十亿千瓦时 | E47: large output unit not used for these fuels
A48: hard coal, lignite, biomass, municipal solid waste | B48: millions of short tons | C48: 10,000 tonnes | D48: 万吨
A49: natural gas | B49: trillion cubic feet | C49: 100 million cubic meter | D49: 亿立方米
A50: hydrogen | B50: thousand metric tons | C50: 10,000 tonnes | D50: 万吨
A51: petroleum gasoline, petroleum diesel, biofuel gasoline, biofuel diesel, jet fuel or kerosene, crude oil, heavy fuel oil | B51: million barrels of oil | C51: 10,000 tonnes | D51: 万吨
A52: LPG/propane/butane | B52: million gallons | C52: 10,000 tonnes | D52: 万吨
...

Sheet GBT2589
A1: GB/T 2589-2020 综合能耗计算通则 General Rules for Calculation of the Comprehensive Energy Consumption
A2: 8.1计算综合能耗时，各种能源应折算为标准煤
A3: 8.2实际消耗的燃料能源应以其收到基低位发热量为计算依据折算为标准煤量。按照GB/T 3102.4国际蒸汽表卡换算，低位发热量等于29307.6千焦（kJ）[7000千卡(kcal)]的燃料，称为1千克标准煤(1kgce)
D4: 1kgce | E4: = | F4: 29307.6 | G4: kJ
A14: 附录A 各种能源折标准煤系数（参考值）
A15: Appendix A Fuel Coal Equivalent Conversion Coefficient
A16: 燃料品种 | B16: Fuel Type | C16: 单位 | D16: 低位发热量(kj) | F16: 低位发热量(kcal) | H16: 折标煤系数
A17: 原煤 | B17: Raw Coal | C17: kg | D17: 20934 | F17: 5000 | H17: 0.7143
A18: 洗精煤 | B18: Cleaned Coal | C18: kg | D18: 26377 | F18: 6300 | H18: 0.9
A19: 洗中煤 | B19: Middlings | C19: kg | D19: 8374 | F19: 2000 | H19: 0.2857
A20: 煤泥 | B20: Slime | C20: kg | D20: 8374 | E20: 12560 | F20: 2000 | G20: 3000 | H20: 0.2857 | I20: 0.4286
A21: 煤矸石（用作能源） | B21: Gangue | C21: kg | D21: 8374 | F21: 2000 | H21: 0.2857
A22: 焦炭（干全焦） | B22: Coke | C22: kg | D22: 28470 | F22: 6800 | H22: 0.9714
A23: 煤焦油 | B23: Coal Tar | C23: kg | D23: 33494 | F23: 8000 | H23: 1.1429
A24: 原油 | B24: Crude Oil | C24: kg | D24: 41868 | F24: 10000 | H24: 1.4286
A25: 燃料油 | B25: Fuel Oil | C25: kg | D25: 41868 | F25: 10000 | H25: 1.4286
A26: 汽油 | B26: Gasoline | C26: kg | D26: 43124 | F26: 10300 | H26: 1.4714
A27: 煤油 | B27: Kerosene | C27: kg | D27: 43124 | F27: 10300 | H27: 1.4714
A28: 柴油 | B28: Diesel | C28: kg | D28: 42705 | F28: 10200 | H28: 1.4571
A29: 天然气 | B29: Natural Gas | C29: m3 | D29: 32238 | E29: 38979 | F29: 7700 | G29: 9310 | H29: 1.1 | I29: 1.33
A30: 液化天然气 | B30: Liquefied Natural Gas | C30: kg | D30: 51498 | F30: 12300 | H30: 1.7572
A31: 液化石油气 | B31: Liquefied Petroleum Gas | C31: kg | D31: 50242 | F31: 12000 | H31: 1.7143
A32: 炼厂干气 | B32: Refinery Gas | C32: kg | D32: 46055 | F32: 11000 | H32: 1.5714
A33: 焦炉煤气 | B33: Coke Oven Gas | C33: m3 | D33: 16747 | E33: 18003 | F33: 4000 | G33: 4300 | H33: 0.5714 | I33: 0.6143
A34: 高炉煤气 | B34: Blast Furnance Gas | C34: m3 | D34: 3768 | F34: 900 | H34: 0.1286
A35: 发生炉煤气 | B35: Furnance Producer Gas | C35: m3 | D35: 5234 | F35: 1250 | H35: 0.1786
A36: 重油催化裂解煤气 | B36: Heavy Oil Catalytic Cracking Gas | C36: m3 | D36: 19259 | F36: 4600 | H36: 0.6571
A37: 重油热裂解煤气 | B37: Catalytic Pyrolysis Process Gas | C37: m3 | D37: 35588 | F37: 8500 | H37: 1.2143
A38: 焦炭制气 | B38: Coke Gas | C38: m3 | D38: 16329 | F38: 3900 | H38: 0.5571
A39: 压力气化煤气 | B39: Pressurized Gasified Coal Gas | C39: m3 | D39: 15072 | F39: 3600 | H39: 0.5143
A40: 水煤气 | B40: Water Gas | C40: m3 | D40: 10467 | F40: 2500 | H40: 0.3571
A41: 粗苯 | B41: Crude Benzene | C41: kg | D41: 41868 | F41: 10000 | H41: 1.4286
A42: 甲醇（用作燃料） | B42: Methanol | C42: kg | D42: 19913 | F42: 4756 | H42: 0.6794
A43: 乙醇（用作燃料） | B43: Ethanol | C43: kg | D43: 26800 | F43: 6401 | H43: 0.9144
A44: 氢气（用作燃料，密度未0.082kg/m3) | B44: Hydrogen | C44: m3 | D44: 9756 | F44: 2330 | H44: 0.3329
A45: 沼气 | B45: Biogas | C45: m3 | D45: 20934 | E45: 24238 | F45: 5000 | G45: 8000 | H45: 0.7143 | I45: 0.8286

Sheet Statistical Yearbook
A2: 各种能源折标准煤参考系数
A3: Conversion Factors from Physical Units to Coal Equivalent
A4: 能源名称 | B4: 平均低位发热量 | C4: 折标准煤系数 | D4: Energy | E4: Average Low Calorific Value | F4: Conversion Factor
A5: 原煤 | B5: 20 908千焦/(5 000千卡)/千克 | C5: 0.7143千克标准煤/千克 | D5: Raw Coal | E5: 20 908 kjoule/(5 000 kcal)/kg | F5: 0.7143 kgce/kg
A6: 洗精煤 | B6: 26 344千焦/(6 300千卡)/千克 | C6: 0.9000千克标准煤/千克 | D6: Cleaned Coal | E6: 26 344 kjoule/(6 300 kcal) / kg | F6: 0.9000 kgce/kg
A7: 其他洗煤 | D7: Other Washed Coal
A8: 洗中煤 | B8: 8 363千焦/(2 000千卡)/千克 | C8: 0.2857千克标准煤/千克 | D8: Middlings | E8: 8 363 kjoule/(2 000 kcal)/kg | F8: 0.2857 kgce/kg
A9: 煤泥 | B9: 8 363～12 545千焦/(2 000～3 000千卡)/千克 | C9: 0.2857～0.4286千克标准煤/千克 | D9: Slimes | E9: 8 363～12 545 kjoule/(2 000～3 000kcal)/kg | F9: 0.2857～0.4286 kgce/kg
A10: 焦炭 | B10: 28 435千焦/(6 800千卡)/千克 | C10: 0.9714千克标准煤/千克 | D10: Coke | E10: 28 435 kjoule/(6 800 kcal)/kg | F10: 0.9714 kgce/kg
A11: 原油 | B11: 41 816千焦/(10 000千卡)/千克 | C11: 1.4286千克标准煤/千克 | D11: Crude Oil | E11: 41 816 kjoule/(10 000 kcal)/kg | F11: 1.4286 kgce / kg
A12: 燃料油 | B12: 41 816千焦/(10 000千卡)/千克 | C12: 1.4286千克标准煤/千克 | D12: Fuel Oil | E12: 41 816 kjoule/(10 000 kcal)/kg | F12: 1.4286 kgce/kg
A13: 汽油 | B13: 43 070千焦/(10 300千卡)/千克 | C13: 1.4714千克标准煤/千克 | D13: Gasoline | E13: 43 070 kjoule/(10 300 kcal)/kg | F13: 1.4714 kgce/kg
A14: 煤油 | B14: 43 070千焦/(10 300千卡)/千克 | C14: 1.4714千克标准煤/千克 | D14: Kerosene | E14: 43 070 kjoule/(10 300 kcal)/kg | F14: 1.4714 kgce/kg
A15: 柴油 | B15: 42 652千焦/(10 200千卡)/千克 | C15: 1.4571千克标准煤/千克 | D15: Diesel | E15: 42 652 kjoule/(10 200 kcal)/kg | F15: 1.4571 kgce/kg
A16: 液化石油气 | B16: 50 179千焦/(12 000千卡)/千克 | C16: 1.7143千克标准煤/千克 | D16: Liquefied Petroleum Gas | E16: 50 179 kjoule/(12 000 kcal)/kg | F16: 1.7143 kgce/kg
A17: 炼厂干气 | B17: 45 998千焦/(11 000千卡)/千克 | C17: 1.5714千克标准煤/千克 | D17: Refinery Gas | E17: 45 998 kjoule/(11 000 kcal)/kg | F17: 1.5714 kgce/kg
A18: 天然气 | B18: 32 238～38 931千焦/(7 700～9 310千卡)/立方米 | C18: 1.1000～1.3300千克标准煤/立方米 | D18: Natural Gas | E18: 32 238～38 931kjoule/(7 700～9 310 kcal)/ cu.m | F18: 1.1000～1.3300 kgce/cu.m
A19: 焦炉煤气 | B19: 16 726～17 981千焦/(4 000～4 300千卡)/立方米 | C19: 0.5714～0.6143千克标准煤/立方米 | D19: Coke Oven Gas | E19: 16 726～17 981kKjoule/(4 000～ 4 300kcal)/cu.m | F19: 0.5714～0.6143 kgce/cu.m
A20: 其他煤气 | D20: Other Coal Gas
A21: 发生炉煤气 | B21: 5 227千焦/(1 250千卡)/立方米 | C21: 0.1786千克标准煤/立方米 | D21: By Gas Furnace | E21: 5 227 kjoule/(1 250 kcal)/ cu.m | F21: 0.1786 kgce/cu.m
A22: 重油催化裂解煤气 | B22: 19 235千焦/(4 600千卡)/立方米 | C22: 0.6571千克标准煤/立方米 | D22: By Heavy Oil Catalytic Cracking | E22: 19 235 kjoule/(4 600 kcal)/cu.m | F22: 0.6571 kgce/ cu.m
A23: 重油热裂解煤气 | B23: 35 544千焦/(8 500千卡)/立方米 | C23: 1.2143千克标准煤/立方米 | D23: By Heavy Oil Thermal Cracking | E23: 35 544 kjoule/(8 500 kcal) / cu.m1.2143 kgce/cu.m
A24: 焦炭制气 | B24: 16 308千焦/(3 900千卡)/立方米 | C24: 0.5571千克标准煤/立方米 | D24: Coke Gas | E24: 16 308 kjoule/(3 900 kcal)/cu.m | F24: 0.5571 kgce/cu.m
A25: 压力气化煤气 | B25: 15 054千焦/(3 600千卡)/立方米 | C25: 0.5143千克标准煤/立方米 | D25: By Pressure Gasification | E25: 15 054 kjoule/(3 600 kcal)/cu.m | F25: 0.5143 kgce/cu.m
A26: 水煤气 | B26: 10 454千焦/(2 500千卡)/立方米 | C26: 0.3571千克标准煤/立方米 | D26: Water Coal Gas | E26: 10 454 kjoule/(2 500 kcal)/cu.m | F26: 0.3571 kgce/cu.m
A27: 煤焦油 | B27: 33 453千焦/(8 000千卡)/千克 | C27: 1.1429千克标准煤/千克 | D27: Coal Tar | E27: 33 453 kjoule/(8 000 kcal)/kg | F27: 1.1429 kgce/kg
A28: 粗苯 | B28: 41 816千焦/(10 000千卡)/千克 | C28: 1.4286千克标准煤/千克 | D28: Benzene | E28: 41 816 kjoule/(10 000 kcal)/kg | F28: 1.4286 kgce/kg
A29: 热力(当量) | C29: 0.03412千克标准煤/百万焦耳 | D29: Heat (in calorific value) | E29: 0.03412 kgce/Mjoule | F29: (0.14286 kgce/1000 kcal)
C30: (0.14286千克标准煤/1000千卡) | D30: Electricity (in calorific value) | E30: 3 600 kjoule/(860 kcal)/ kW-h | F30: 0.1229 kgce/kW-h
A31: 电力(当量) | B31: 3 600千焦/(860千卡)/千瓦小时 | C31: 0.1229千克标准煤/千瓦小时 | D31: (in coal equivalent) | E31: calculated by average coal input for
A32: (等价) | B32: 按当年火电发电标准煤耗计算 | E32: thermal power generation in the year
A33: 生物质能 | D33: Biomass Energy
A34: 人粪 | B34: 18 817千焦/(4 500千卡)/千克 | C34: 0.643千克标准煤/千克 | D34: Night Soil | E34: 18 817 kjoule/(4 500 kcal)/kg | F34: 0.643 kgce/kg
A35: 牛粪 | B35: 13 799千焦/(3 300千卡)/千克 | C35: 0.471千克标准煤/千克 | D35: Cow Dung | E35: 13 799 kjoule/(3 300 kcal)/kg | F35: 0.471 kgce/kg
A36: 猪粪 | B36: 12 545千焦/(3 000千卡)/千克 | C36: 0.429千克标准煤/千克 | D36: Pig Dung | E36: 12 545 kjoule/(3 000 kcal)/kg | F36: 0.429 kgce/kg
A37: 羊、驴、马、骡粪 | B37: 15 472千焦/(3 700千卡)/千克 | C37: 0.529千克标准煤/千克 | D37: Sheep/Donkey/Horse/Mule Dung | E37: 15 472 kjoule/(3 700 kcal) / kg | F37: 0.529 kgce/kg
A38: 鸡粪 | B38: 18 817千焦/(4 500千卡)/千克 | C38: 0.643千克标准煤/千克 | D38: Poultry Manure | E38: 18 817 kjoule/(4 500 kcal)/kg | F38: 0.643 kgce/kg
A39: 大豆秆、棉花秆 | B39: 15 890千焦/(3 800千卡)/千克 | C39: 0.543千克标准煤/千克 | D39: Soybean Stalk,Cotton Stalk | E39: 15 890 kjoule/(3 800 kcal)/kg | F39: 0.543 kgce/kg
A40: 稻秆 | B40: 12 545千焦/(3 000千卡)/千克 | C40: 0.429千克标准煤/千克 | D40: Paddy Stalk | E40: 12 545 kjoule/(3 000 kcal) / kg | F40: 0.429 kgce/kg
A41: 麦秆 | B41: 14 635千焦/(3 500千卡)/千克 | C41: 0.500千克标准煤/千克 | D41: Wheat stalk | E41: 14 635 kjoule/(3 500 kcal)/kg | F41: 0.500 kgce/kg
...

Sheet Heat Value
A1: 序号 Index | B1: 能源名称 Fuel Type | C1: 实物量单位 Physical Unit | D1: 平均低位发热量 Average Lower Heat Value
D2: TJ/单位 | E2: 万tce/单位 | F2: BTU/单位
A3: 1 | B3: 煤合计
A4: 2 | B4: 原煤 | C4: 万吨 | D4: 209.08 | E4: =D4/293.07 -> 0.71341318 | F4: =D4*10^12/About!$A$75 -> 1.981696e+11
A5: 3 | B5: 洗精煤 | C5: 万吨 | D5: 263.44 | E5: =D5/293.07 -> 0.89889787 | F5: =D5*10^12/About!$A$75 -> 2.4969294e+11
A6: 4 | B6: 其他洗煤 | C6: 万吨 | D6: 83.63 | E6: =D6/293.07 -> 0.28535845 | F6: =D6*10^12/About!$A$75 -> 7.9265946e+10
A7: 5 | B7: 型煤 | C7: 万吨 | D7: 154.73 | E7: =D7/293.07 -> 0.5279626 | F7: =D7*10^12/About!$A$75 -> 1.4665574e+11
A8: 6 | B8: 煤矸石 | C8: 万吨 | D8: 83.74 | E8: =D8/293.07 -> 0.28573378 | F8: =D8*10^12/About!$A$75 -> 7.9370206e+10
A9: 7 | B9: 焦炭 | C9: 万吨 | D9: 284.35 | E9: =D9/293.07 -> 0.97024602 | F9: =D9*10^12/About!$A$75 -> 2.695118e+11
A10: 8 | B10: 焦炉煤气 | C10: 亿立方米 | D10: 1735.35 | E10: =D10/293.07 -> 5.9212816 | F10: =D10*10^12/About!$A$75 -> 1.6447944e+12
A11: 9 | B11: 高炉煤气 | C11: 亿立方米 | D11: 376.3 | E11: =D11/293.07 -> 1.2839936 | F11: =D11*10^12/About!$A$75 -> 3.5666358e+11
A12: 10 | B12: 转炉煤气 | C12: 亿立方米 | D12: 794.5 | E12: =D12/293.07 -> 2.7109564 | F12: =D12*10^12/About!$A$75 -> 7.530407e+11
A13: 11 | B13: 其他煤气 | C13: 亿立方米 | D13: 522.7 | E13: =D13/293.07 -> 1.7835329 | F13: =D13*10^12/About!$A$75 -> 4.9542401e+11
A14: 12 | B14: 其他焦化产品 | C14: 万吨 | D14: 334.53 | E14: =D14/293.07 -> 1.1414679 | F14: =D14*10^12/About!$A$75 -> 3.1707326e+11
A15: 13 | B15: 油品合计
A16: 14 | B16: 原油 | C16: 万吨 | D16: 418.16 | E16: =D16/293.07 -> 1.4268264 | F16: =D16*10^12/About!$A$75 -> 3.9633921e+11
A17: 15 | B17: 汽油 | C17: 万吨 | D17: 430.7 | E17: =D17/293.07 -> 1.4696148 | F17: =D17*10^12/About!$A$75 -> 4.0822483e+11
A18: 16 | B18: 煤油 | C18: 万吨 | D18: 430.7 | E18: =D18/293.07 -> 1.4696148 | F18: =D18*10^12/About!$A$75 -> 4.0822483e+11
A19: 17 | B19: 柴油 | C19: 万吨 | D19: 426.52 | E19: =D19/293.07 -> 1.455352 | F19: =D19*10^12/About!$A$75 -> 4.0426296e+11
A20: 18 | B20: 燃料油 | C20: 万吨 | D20: 418.16 | E20: =D20/293.07 -> 1.4268264 | F20: =D20*10^12/About!$A$75 -> 3.9633921e+11
A21: 19 | B21: 石脑油 | C21: 万吨 | D21: 439.07 | E21: =D21/293.07 -> 1.4981745 | F21: =D21*10^12/About!$A$75 -> 4.1615806e+11
A22: 20 | B22: 润滑油 | C22: 万吨 | D22: 413.98 | E22: =D22/293.07 -> 1.4125636 | F22: =D22*10^12/About!$A$75 -> 3.9237733e+11
A23: 21 | B23: 石蜡 | C23: 万吨 | D23: 399.25 | E23: =D23/293.07 -> 1.3623025 | F23: =D23*10^12/About!$A$75 -> 3.7841599e+11
A24: 22 | B24: 溶剂油 | C24: 万吨 | D24: 429.45 | E24: =D24/293.07 -> 1.4653496 | F24: =D24*10^12/About!$A$75 -> 4.0704006e+11
A25: 23 | B25: 石油沥青 | C25: 万吨 | D25: 389.31 | E25: =D25/293.07 -> 1.3283857 | F25: =D25*10^12/About!$A$75 -> 3.6899468e+11
A26: 24 | B26: 石油焦 | C26: 万吨 | D26: 319.47 | E26: =D26/293.07 -> 1.0900809 | F26: =D26*10^12/About!$A$75 -> 3.0279914e+11
A27: 25 | B27: 液化石油气 | C27: 万吨 | D27: 501.79 | E27: =D27/293.07 -> 1.7121848 | F27: =D27*10^12/About!$A$75 -> 4.7560515e+11
... A34: 32 | B34: 其他能源 | C34: 万吨标准煤 | D34: 292.71 | E34: =D34/293.07 -> 0.99877162 | F34: =D34*10^12/About!$A$75 -> 2.7743555e+11

Sheet Start Year Energy Balance
A1: 5-1 全国能源平衡表(实物量)-2019
A2: Energy Balance of China (Physical Quantity)-2019 | N2: 5-1 续表1 | AA2: 5-1续表2
A3: 项 目 | B3: Item | C3: 煤合计_x000D_ (万吨)_x000D_ Coal Total_x000D_ (104 tons) | D3: 原煤_x000D_ (万吨)_x000D_ Raw Coal_x000D_ (104 tons) | E3: 洗精煤_x000D_ (万吨)_x000D_ Cleaned_x000D_ Coal_x000D_ (104 tons) | F3: 其他洗煤_x000D_ (万吨)_x000D_ Other_x000D_ Washed_x000D_ Coal_x000D_ (104 tons) | G3: 煤制品_x000D_ (万吨)_x000D_ Briquettes_x000D_ (104 tons) | H3: 煤矸石_x000D_ (万吨)_x000D_ Gangue_x000D_ (104 tons) | I3: 焦炭_x000D_ (万吨)_x000D_ Coke_x000D_ (104 tons) | J3: 焦炉煤气_x000D_ (亿立方米)_x000D_ Coke Oven_x000D_ Gas_x000D_ (108 cu.m) | K3: 高炉煤气_x000D_ (亿立方米)_x000D_ Blast Furnace_x000D_ Gas_x000D_ (108 cu.m) | L3: 转炉煤气_x000D_ (亿立方米)_x000D_ Converter_x000D_ Gas_x000D_ (108 cu.m) | M3: 其他煤气_x000D_ (亿立方米)_x000D_ Other Gas_x000D_ (108 cu.m) | N3: 项 目 | O3: Item | P3: 其他焦化产品_x000D_ (万吨)_x000D_ Other_x000D_ Coking_x000D_ Products_x000D_ (104 tons) | Q3: 油品合计_x000D_ (万吨)_x000D_ Petroleum_x000D_ Products_x000D_ Total_x000D_ (104 tons) | R3: 原油_x000D_ (万吨)_x000D_ Crude Oil_x000D_ (104 tons) | S3: 汽油_x000D_ (万吨)_x000D_ Gasoline_x000D_ (104 tons) | T3: 煤油_x000D_ (万吨)_x000D_ Kerosene_x000D_ (104 tons) | U3: 柴油_x000D_ (万吨)_x000D_ Diesel Oil_x000D_ (104 tons) | V3: 燃料油_x000D_ (万吨)_x000D_ Fuel Oil_x000D_ (104 tons) | W3: 石脑油_x000D_ (万吨)_x000D_ Naphtha_x000D_ (104 tons) | X3: 润滑油_x000D_ (万吨)_x000D_ Lubricants_x000D_ (104 tons) | Y3: 石蜡_x000D_ (万吨)_x000D_ Paraffin_x000D_ Waxes_x000D_ (104 tons) | Z3: 溶剂油_x000D_ (万吨)_x000D_ White Spirit_x000D_ (104 tons) | AA3: 项 目 | AB3: Item | AC3: 石油沥青_x000D_ (万吨)_x000D_ Bitumen_x000D_ Asphalt_x000D_ (104 tons) | AD3: 石油焦_x000D_ (万吨)_x000D_ Petroleum_x000D_ Coke_x000D_ (104 tons) | AE3: 液化石油气_x000D_ (万吨)_x000D_ Liquefied_x000D_ Petroleum Gas_x000D_ (104 tons) | AF3: 炼厂干气_x000D_ (万吨)_x000D_ Refinery_x000D_ Gas_x000D_ (104 tons) | AG3: 其他石油制品_x000D_ (万吨)_x000D_ Other_x000D_ Petroleum_x000D_ Products_x000D_ (104 tons) | AH3: 天然气_x000D_ (亿立方米)_x000D_ Natural Gas_x000D_ (108 cu.m) | AI3: 液化天然气_x000D_ (万吨)_x000D_ Liquefied_x000D_ Natural Gas_x000D_ (104 tons) | AJ3: 热力_x000D_ (万百万千焦)_x000D_ Heat_x000D_ (1010 kJ) | AK3: 电力_x000D_ (亿千瓦小时)_x000D_ Electricity_x000D_ (108 kW·h) | AL3: 其他能源_x000D_ (万吨标准煤)_x000D_ Other_x000D_ Energy_x000D_ (104 tce)
A4: 一.可供本地区消费的能源量 | B4: Total Primary Energy Supply | C4: 405537.18 | D4: 404267.01 | E4: 1359.01 | F4: -70 | G4: -18.84 | I4: -762.13 | N4: 一.可供本地区消费的能源量 | O4: Total Primary Energy Supply | Q4: 66900.85 | R4: 68007.48 | S4: -1190.41 | T4: -1319.79 | U4: -1948.68 | V4: 344.98 | W4: 657.9 | X4: 17.85 | Y4: -35.93 | Z4: 4.32 | AA4: 一.可供本地区消费的能源量 | AB4: Total Primary Energy Supply | AC4: 274.38 | AD4: 590.42 | AE4: 1950.61 | AG4: -452.28 | AH4: 2227.84 | AI4: 6011.71 | AK4: 22664.83 | AL4: 7164.43
A5: 1.一次能源生产量 | B5: Indigenous Production | C5: 384633.2 | D5: 384633.2 | N5: 1.一次能源生产量 | O5: Indigenous Production | Q5: 19101.41 | R5: 19101.41 | AA5: 1.一次能源生产量 | AB5: Indigenous Production | AH5: 1761.74 | AK5: 22832.8 | AL5: 7164.43
A6: 水电 | B6: Hydro Power | N6: 水电 | O6: Hydro Power | AA6: 水电 | AB6: Hydro Power | AK6: 13044.38
A7: 核电 | B7: Nuclear Power | N7: 核电 | O7: Nuclear Power | AA7: 核电 | AB7: Nuclear Power | AK7: 3483.55
A8: 风电 | B8: Wind Power | N8: 风电 | O8: Wind Power | AA8: 风电 | AB8: Wind Power | AK8: 4060.32
A9: 2.进口量 | B9: Import | C9: 29976.88 | D9: 29976.88 | I9: 52.3 | N9: 2.进口量 | O9: Import | Q9: 56970.47 | R9: 50567.6 | S9: 33.34 | T9: 366.75 | U9: 119.02 | V9: 1485.51 | W9: 702.22 | X9: 29.16 | Y9: 9.85 | Z9: 3.77 | AA9: 2.进口量 | AB9: Import | AC9: 428.39 | AD9: 830.52 | AE9: 2109.33 | AG9: 285 | AH9: 501.14 | AI9: 6019.12 | AK9: 48.58
A10: 3.境内飞机和轮船在境外的加油量 | B10: Domestic Airplanes&Ships Refueling Abroad | N10: 3.境内飞机和轮船在境外的加油量 | O10: Domestic Airplanes&Ships Refueling Abroad | Q10: 1131.69 | T10: 563.28 | U10: 25.44 | V10: 542.97 | AA10: 3.境内飞机和轮船在境外的加油量 | AB10: Domestic Airplanes&Ships Refueling Abroad
A11: 4.出口量(-) | B11: Export (-) | C11: 602.86 | D11: 599.37 | G11: 3.5 | I11: 652.26 | N11: 4.出口量(-) | O11: Export (-) | Q11: 7251.41 | R11: 81 | S11: 1637.06 | T11: 1761.48 | U11: 2138.26 | V11: 1117.66 | X11: 11.25 | Y11: 60.17 | Z11: 0.26 | AA11: 4.出口量(-) | AB11: Export (-) | AC11: 65.62 | AD11: 228.96 | AE11: 140.89 | AG11: 8.79 | AH11: 35.03 | AI11: 7.4 | AK11: 216.55
A12: 5.境外飞机和轮船在境内的加油量(-) | B12: Oversea Airplanes&Ships Refueling Domestically (-) | N12: 5.境外飞机和轮船在境内的加油量(-) | O12: Oversea Airplanes&Ships Refueling Domestically (-) | Q12: 959.95 | T12: 478.33 | U12: 50.81 | V12: 430.81 | AA12: 5.境外飞机和轮船在境内的加油量(-) | AB12: Oversea Airplanes&Ships Refueling Domestically (-)
A13: 6.库存增(-)、减(+)量 | B13: Stock Change | C13: -8470.04 | D13: -9743.71 | E13: 1359.01 | F13: -70 | G13: -15.34 | I13: -162.17 | N13: 6.库存增(-)、减(+)量 | O13: Stock Change | Q13: -2091.35 | R13: -1580.53 | S13: 413.31 | T13: -10.02 | U13: 95.93 | V13: -135.04 | W13: -44.32 | X13: -0.06 | Y13: 14.39 | Z13: 0.81 | AA13: 6.库存增(-)、减(+)量 | AB13: Stock Change | AC13: -88.39 | AD13: -11.13 | AE13: -17.83 | AG13: -728.49
A14: 二.加工转换投入(-)产出(+)量 | B14: Input(-) & Output(+) of Transformation | C14: -328465.29 | D14: -341871.85 | E14: -1847.3 | F14: 13863.38 | G14: 1390.48 | H14: -16.05 | I14: 47206.48 | J14: 685.06 | K14: 8106.13 | L14: 587.04 | M14: 183.26 | N14: 二.加工转换投入(-)产出(+)量 | O14: Input(-) & Output(+) of Transformation | P14: 1077.95 | Q14: -3453.63 | R14: -66907.95 | S14: 14852.09 | T14: 5322.59 | U14: 17195.94 | V14: 2111.07 | W14: 5096.12 | X14: 230.11 | Y14: 302.72 | Z14: 8236 | AA14: 二.加工转换投入(-)产出(+)量 | AB14: Input(-) & Output(+) of Transformation | AC14: 2970.43 | AD14: 2425.3 | AE14: 3606.75 | AF14: 1846.02 | AG14: 7412.81 | AH14: -676.86 | AI14: 900.26 | AJ14: 550106.3 | AK14: 52201.48 | AL14: -967.2
A15: 1.火力发电 | B15: Thermal Power | C15: -210158.99 | D15: -205517.23 | F15: -4641.77 | H15: -2467.05 | I15: -25.3 | J15: -208.01 | K15: -2451.35 | L15: -329.03 | M15: -0.13 | N15: 1.火力发电 | O15: Thermal Power | Q15: -308.27 | R15: -16.01 | U15: -24.18 | V15: -13.94 | W15: -12.01 | AA15: 1.火力发电 | AB15: Thermal Power | AD15: -181.18 | AE15: -0.11 | AF15: -52.59 | AG15: -8.25 | AH15: -391.87 | AI15: -231.28 | AJ15: -111630.52 | AK15: 52201.48 | AL15: -1567.97
A16: 2.供热 | B16: Heating Supply | C16: -34441.79 | D16: -33027.91 | F16: -1413.87 | H16: -646.29 | I16: -47.51 | J16: -62.54 | K16: -573.41 | L16: -45.52 | M16: -1.2 | N16: 2.供热 | O16: Heating Supply | Q16: -653.79 | S16: -0.05 | U16: -5.3 | V16: -60.21 | W16: -163.1 | AA16: 2.供热 | AB16: Heating Supply | AD16: -224.18 | AE16: -4.05 | AF16: -173.99 | AG16: -22.9 | AH16: -143.19 | AI16: -33.51 | AJ16: 565138.68 | AL16: -391.96
A17: 3.煤炭洗选 | B17: Coal Washing | C17: -12213.46 | D17: -87588.72 | E17: 53863.4 | F17: 21511.86 | H17: 3097.3 | N17: 3.煤炭洗选 | O17: Coal Washing | AA17: 3.煤炭洗选 | AB17: Coal Washing
A18: 4.炼焦 | B18: Coking | C18: -65672.62 | D18: -9961.92 | E18: -55710.7 | I18: 47295.8 | J18: 955.61 | N18: 4.炼焦 | O18: Coking | P18: 1387.39 | AA18: 4.炼焦 | AB18: Coking
A19: 5.炼油及煤制油 | B19: Petroleum Refining and Coal-to-liquids | C19: -3239.84 | D19: -3087.01 | F19: -152.83 | N19: 5.炼油及煤制油 | O19: Petroleum Refining and Coal-to-liquids | P19: -309.44 | Q19: 9842.42 | R19: -66891.93 | S19: 14880.68 | T19: 5322.59 | U19: 17308.27 | V19: 4506.05 | W19: 6620.07 | X19: 232.36 | Y19: 308.88 | Z19: 82.36 | AA19: 5.炼油及煤制油- | AB19: Petroleum Refining and Coal-to-liquids | AC19: 3313.86 | AD19: 2838.81 | AE19: 4210.01 | AF19: 2187.92 | AG19: 14922.52 | AH19: -32.35 | AL19: -138.98
A20: #油品再投入量(-) | B20: Petroleum Products Input (-) | N20: #油品再投入量(-) | O20: Petroleum Products Input (-) | Q20: -12330.3 | S20: -28.54 | U20: -82.86 | V20: -2320.83 | W20: -1348.83 | X20: -2.25 | Y20: -6.15 | AA20: #油品再投入量(-) | AB20: Petroleum Products Input (-) | AC20: -343.42 | AD20: -8.15 | AE20: -595.4 | AF20: -115.31 | AG20: -7478.56
A21: 6.制气 | B21: Gas Works | C21: -2458.7 | D21: -2293.81 | F21: -164.89 | M21: 184.58 | N21: 6.制气 | O21: Gas Works | Q21: -3.69 | AA21: 6.制气 | AB21: Gas Works | AE21: -3.69 | AH21: 64.73
A22: #焦炭再投入量(-) | B22: Coke Input (-) | I22: -16.51 | N22: #焦炭再投入量(-) | O22: Coke Input (-) | AA22: #焦炭再投入量(-) | AB22: Coke Input (-)
A23: 7.天然气液化 | B23: Natural Gas Liquefaction | L23: -0.12 | N23: 7.天然气液化 | O23: Natural Gas Liquefaction | AA23: 7.天然气液化 | AB23: Natural Gas Liquefaction | AH23: -174.19 | AI23: 1165.05
A24: 8.煤制品加工 | B24: Briquettes | C24: -279.88 | D24: -395.25 | F24: -1275.11 | G24: 1390.48 | N24: 8.煤制品加工 | O24: Briquettes | AA24: 8.煤制品加工 | AB24: Briquettes
A25: 9.回收能 | B25: Recovery of Energy | K25: 11130.88 | L25: 961.71 | N25: 9.回收能 | O25: Recovery of Energy | AA25: 9.回收能 | AB25: Recovery of Energy | AJ25: 96598.13 | AL25: 1131.7
A26: 三.损失量 | B26: Loss | N26: 三.损失量 | O26: Loss | Q26: 34.46 | R26: 33.83 | AA26: 三.损失量 | AB26: Loss | AE26: 0.63 | AH26: 20.95 | AI26: 6.26 | AJ26: 5297.62 | AK26: 3330.1
A27: 四.终端消费量 | B27: Total Final Consumption | C27: 73449.39 | D27: 58985.75 | F27: 13101.54 | G27: 1362.1 | I27: 46336.64 | J27: 710.6 | K27: 8339.48 | L27: 581.53 | M27: 190.06 | N27: 四.终端消费量 | O27: Total Final Consumption | P27: 1133.12 | Q27: 61018.45 | R27: 326.5 | S27: 13599.38 | T27: 3950.23 | U27: 14805.62 | V27: 2295.37 | W27: 5747.08 | X27: 248.37 | Y27: 257.1 | Z27: 91.74 | AA27: 四.终端消费量 | AB27: Total Final Consumption | AC27: 3256.43 | AD27: 3030.97 | AE27: 5462.48 | AF27: 1830.56 | AG27: 6116.62 | AH27: 1531.78 | AI27: 6909.09 | AJ27: 544808.39 | AK27: 71536.02 | AL27: 6091.03
A28: 1.农、林、牧、渔业 | B28: Agriculture,Forestry,Animal Husbandry and Fishery | C28: 2202.07 | D28: 2110.86 | F28: 91.21 | I28: 59.67 | N28: 1.农、林、牧、渔业 | O28: Agriculture,Forestry,Animal Husbandry and Fishery | Q28: 1748.2 | S28: 253.18 | T28: 10.95 | U28: 1475.05 | V28: 1.19 | AA28: 1.农、林、牧、渔业 | AB28: Agriculture,Forestry,Animal Husbandry and Fishery | AE28: 7.82 | AH28: 1.24 | AJ28: 69.88 | AK28: 1336.2 | AL28: 675.84
A29: 2.工业 | B29: Industry | C29: 58802.35 | D29: 45514.41 | F29: 12410.86 | G29: 877.09 | I29: 46230.86 | J29: 701.86 | K29: 8339.48 | L29: 581.53 | M29: 140.92 | N29: 2.工业 | O29: Industry | P29: 1133.12 | Q29: 21732.37 | R29: 326.5 | S29: 233.41 | T29: 10.97 | U29: 1178.27 | V29: 217.56 | W29: 5747.08 | X29: 248.37 | Y29: 257.1 | Z29: 91.74 | AA29: 2.工业 | AB29: Industry | AC29: 264.42 | AD29: 3030.97 | AE29: 2266.99 | AF29: 1830.56 | AG29: 6028.41 | AH29: 631.02 | AI29: 6508.45 | AJ29: 380696.5 | AK29: 47368.2 | AL29: 976.87
A30: #用作原料、材料 | B30: Non-Energy Use | C30: 12689.15 | D30: 10880.31 | F30: 1738.76 | G30: 70.08 | I30: 1474.76 | N30: #用作原料、材料 | O30: Non-Energy Use | P30: 448.04 | Q30: 11507.24 | S30: 2.15 | T30: 1.17 | U30: 17.4 | V30: 31.3 | W30: 5505.3 | X30: 227.2 | Y30: 252.77 | Z30: 88.61 | AA30: #用作原料、材料 | AB30: Non-Energy Use | AC30: 206.89 | AD30: 2276.35 | AE30: 503.89 | AF30: 50.35 | AG30: 2343.85 | AH30: 92.44 | AI30: 94.35
A31: 3.建筑业 | B31: Construction | C31: 639.81 | D31: 596.64 | F31: 43.17 | I31: 9.7 | N31: 3.建筑业 | O31: Construction | Q31: 4055.13 | S31: 499.89 | T31: 16.03 | U31: 530.27 | V31: 31.84 | AA31: 3.建筑业 | AB31: Construction | AC31: 2874.87 | AE31: 14.03 | AG31: 88.21 | AH31: 2.81 | AJ31: 2300.23 | AK31: 991.19 | AL31: 30.41
A32: 4.交通运输、仓储和邮政业 | B32: Transport,Storage and Post | C32: 282.61 | D32: 263.5 | F32: 19.11 | I32: 0.36 | N32: 4.交通运输、仓储和邮政业 | O32: Transport,Storage and Post | Q32: 22099.75 | S32: 6244.92 | T32: 3689.21 | U32: 9867.31 | V32: 2025.31 | AA32: 4.交通运输、仓储和邮政业 | AB32: Transport,Storage and Post | AC32: 117.14 | AE32: 155.85 | AH32: 274.62 | AI32: 400.64 | AJ32: 4152.02 | AK32: 1752.34 | AL32: 1486.9
A33: 5.批发和零售业、住宿和餐饮业 | B33: Wholesale and Retail Trades,Hotels and Catering Services | C33: 2377.77 | D33: 2309.25 | F33: 39.92 | G33: 28.59 | I33: 16.91 | J33: 0.95 | M33: 9.43 | N33: 5.批发和零售业、住宿和餐饮业 | O33: Wholesale and Retail Trades,Hotels and Catering Services | Q33: 608.41 | S33: 287.95 | T33: 15.47 | U33: 203.88 | V33: 10.22 | AA33: 5.批发和零售业、住宿和餐饮业 | AB33: Wholesale and Retail Trades,Hotels and Catering Services | AE33: 90.89 | AH33: 62.46 | AJ33: 9533.06 | AK33: 3187.1 | AL33: 67.01
A34: 6.其他 | B34: Others | C34: 2598.18 | D34: 2500.19 | F34: 89.23 | G34: 8.76 | I34: 6.32 | J34: 1.23 | N34: 6.其他 | O34: Others | Q34: 3460.61 | S34: 2240.92 | T34: 184.17 | U34: 954.04 | V34: 9.25 | AA34: 6.其他 | AB34: Others | AE34: 72.23 | AH34: 57.32 | AJ34: 19224.64 | AK34: 6263.78 | AL34: 271.88
A35: 7.居民生活 | B35: Residential | C35: 6546.6 | D35: 5690.91 | F35: 408.04 | G35: 447.65 | I35: 12.81 | J35: 6.56 | M35: 39.71 | N35: 7.居民生活 | O35: Residential | Q35: 7313.99 | S35: 3839.1 | T35: 23.43 | U35: 596.79 | AA35: 7.居民生活 | AB35: Residential | AE35: 2854.67 | AH35: 502.32 | AJ35: 128832.05 | AK35: 10637.21 | AL35: 2582.12
A36: 城镇 | B36: Urban | C36: 800.99 | D36: 623.77 | F36: 55.82 | G36: 121.4 | I36: 2.9 | J36: 5.02 | M36: 39.55 | N36: 城镇 | O36: Urban | Q36: 4960.36 | S36: 2570.09 | T36: 0.36 | U36: 274.46 | AA36: 城镇 | AB36: Urban | AE36: 2115.45 | AH36: 497.4 | AJ36: 128832.05 | AK36: 5838.25 | AL36: 242.26
A37: 乡村 | B37: Rural | C37: 5745.61 | D37: 5067.14 | F37: 352.22 | G37: 326.25 | I37: 9.91 | J37: 1.54 | M37: 0.16 | N37: 乡村 | O37: Rural | Q37: 2353.63 | S37: 1269.01 | T37: 23.07 | U37: 322.33 | AA37: 乡村 | AB37: Rural | AE37: 739.22 | AH37: 4.92 | AK37: 4798.96 | AL37: 2339.86
A38: 五.平衡差额 | B38: Statistical Difference | C38: 3622.5 | D38: 3409.41 | E38: -488.29 | F38: 691.85 | G38: 9.54 | H38: -16.05 | I38: 107.72 | J38: -25.54 | K38: -233.36 | L38: 5.51 | M38: -6.81 | N38: 五.平衡差额 | O38: Statistical Difference | P38: -55.16 | Q38: 2394.31 | R38: 739.21 | S38: 62.3 | T38: 52.56 | U38: 441.65 | V38: 160.68 | W38: 6.93 | X38: -0.41 | Y38: 9.7 | Z38: -5,07 | AA38: 五.平衡差额 | AB38: Statistical Difference | AC38: -11.62 | AD38: -15.24 | AE38: 94.25 | AF38: 15.46 | AG38: 843.91 | AH38: -1.75 | AI38: -338 | AJ38: 0.29 | AK38: 0.19 | AL38: 106.2
A39: 六.消费量合计 | B39: Total Energy Consumption | C39: 401914.68 | D39: 400857.6 | E39: 55710.7 | F39: 20750.01 | G39: 1362.1 | H39: 3113.34 | I39: 46425.96 | J39: 981.15 | K39: 11364.24 | L39: 956.08 | M39: 191.39 | N39: 六.消费量合计 | O39: Total Energy Consumption | P39: 1442.56 | Q39: 64506.54 | R39: 67268.27 | S39: 13627.97 | T39: 3950.23 | U39: 14917.95 | V39: 4690.34 | W39: 7271.04 | X39: 259.63 | Y39: 263.25 | Z39: 91.74 | AA39: 六.消费量合计 | AB39: Total Energy Consumption | AC39: 3599.85 | AD39: 3444.47 | AE39: 6066.37 | AF39: 2172.45 | AG39: 13626.33 | AH39: 2068.82 | AI39: 7180.14 | AJ39: 661736.52 | AK39: 74866.12 | AL39: 8189.93
A41: Total Consumption in Physical Units | C41: =ABS(MIN(C15,0)+MIN(C16,0))+C27-C30 -> 305361.02 | D41: =ABS(MIN(D15,0)+MIN(D16,0))+D27-D30 -> 286650.58 | E41: =ABS(MIN(E15,0)+MIN(E16,0))+E27-E30 -> 0 | F41: =ABS(MIN(F15,0)+MIN(F16,0))+F27-F30 -> 17418.42 | G41: =ABS(MIN(G15,0)+MIN(G16,0))+G27-G30 -> 1292.02 | H41: =ABS(MIN(H15,0)+MIN(H16,0))+H27-H30 -> 3113.34 | I41: =ABS(MIN(I15,0)+MIN(I16,0))+I27-I30 -> 44934.69 | J41: =ABS(MIN(J15,0)+MIN(J16,0))+J27-J30 -> 981.15 | ... M41: =ABS(MIN(M15,0)+MIN(M16,0))+M27-M30 -> 191.39 | P41: =ABS(MIN(P15,0)+MIN(P16,0))+P27-P30 -> 685.08 | Q41: =ABS(MIN(Q15,0)+MIN(Q16,0))+Q27-Q30 -> 50473.27 | R41: =ABS(MIN(R15,0)+MIN(R16,0))+R27-R30 -> 342.51 | S41: =ABS(MIN(S15,0)+MIN(S16,0))+S27-S30 -> 13597.28 | T41: =ABS(MIN(T15,0)+MIN(T16,0))+T27-T30 -> 3949.06 | U41: =ABS(MIN(U15,0)+MIN(U16,0))+U27-U30 -> 14817.7 | V41: =ABS(MIN(V15,0)+MIN(V16,0))+V27-V30 -> 2338.22 | W41: =ABS(MIN(W15,0)+MIN(W16,0))+W27-W30 -> 416.89 | ... AL41: =ABS(MIN(AL15,0)+MIN(AL16,0))+AL27-AL30 -> 8050.96

Sheet AEO Table 73
B1: ref2019.d111618a | C1: 2017 | D1: 2018 | E1: 2019 | F1: 2020 | G1: 2021 | H1: 2022 | I1: 2023 | J1: 2024 | K1: 2025 | L1: 2026 | M1: 2027 | N1: 2028 | O1: 2029 | P1: 2030 | Q1: 2031 | R1: 2032 | S1: 2033 | T1: 2034 | U1: 2035 | V1: 2036 | W1: 2037 | X1: 2038 | Y1: 2039 | Z1: 2040 | AA1: 2041 | AB1: 2042 | AC1: 2043 | AD1: 2044 | AE1: 2045 | AF1: 2046 | AG1: 2047 | AH1: 2048 | AI1: 2049 | AJ1: 2050
C3: Report | D3: Annual Energy Outlook 2019
C4: Scenario | D4: ref2019 | G4: Reference case
C5: Datekey | D5: d111618a
C6: Release Date | E6: January 2019
A10: CNV000 | B10: 73. Conversion Factors
B11: (from physical units to million Btu)
AK12: 2018-
C13: 2017 | D13: 2018 | E13: 2019 | F13: 2020 | G13: 2021 | H13: 2022 | I13: 2023 | J13: 2024 | K13: 2025 | L13: 2026 | M13: 2027 | N13: 2028 | O13: 2029 | P13: 2030 | Q13: 2031 | R13: 2032 | S13: 2033 | T13: 2034 | U13: 2035 | V13: 2036 | W13: 2037 | X13: 2038 | Y13: 2039 | Z13: 2040 | AA13: 2041 | AB13: 2042 | AC13: 2043 | AD13: 2044 | AE13: 2045 | AF13: 2046 | AG13: 2047 | AH13: 2048 | AI13: 2049 | AJ13: 2050 | AK13: 2050
B14: Petroleum and Other Liquids
B15: (million Btu per barrel)
A16: CNV000:aa_AsphaltandRoa | B16: Asphalt and Road Oil | C16: 6.636 | D16: 6.636 | E16: 6.636 | F16: 6.636 | G16: 6.636 | H16: 6.636 | I16: 6.636 | J16: 6.636 | K16: 6.636 | L16: 6.636 | M16: 6.636 | N16: 6.636 | O16: 6.636 | P16: 6.636 | Q16: 6.636 | R16: 6.636 | S16: 6.636 | T16: 6.636 | U16: 6.636 | V16: 6.636 | W16: 6.636 | X16: 6.636 | Y16: 6.636 | Z16: 6.636 | AA16: 6.636 | AB16: 6.636 | AC16: 6.636 | AD16: 6.636 | AE16: 6.636 | AF16: 6.636 | AG16: 6.636 | AH16: 6.636 | AI16: 6.636 | AJ16: 6.636 | AK16: 0
A17: CNV000:aa_AviationGasol | B17: Aviation Gasoline | C17: 5.048 | D17: 5.048 | E17: 5.048 | F17: 5.048 | G17: 5.048 | H17: 5.048 | I17: 5.048 | J17: 5.048 | K17: 5.048 | L17: 5.048 | M17: 5.048 | N17: 5.048 | O17: 5.048 | P17: 5.048 | Q17: 5.048 | R17: 5.048 | S17: 5.048 | T17: 5.048 | U17: 5.048 | V17: 5.048 | W17: 5.048 | X17: 5.048 | Y17: 5.048 | Z17: 5.048 | AA17: 5.048 | AB17: 5.048 | AC17: 5.048 | AD17: 5.048 | AE17: 5.048 | AF17: 5.048 | AG17: 5.048 | AH17: 5.048 | AI17: 5.048 | AJ17: 5.048 | AK17: 0
A18: CNV000:ea_Biodiesel | B18: Biodiesel | C18: 5.359 | D18: 5.359 | E18: 5.359 | F18: 5.359 | G18: 5.359 | H18: 5.359 | I18: 5.359 | J18: 5.359 | K18: 5.359 | L18: 5.359 | M18: 5.359 | N18: 5.359 | O18: 5.359 | P18: 5.359 | Q18: 5.359 | R18: 5.359 | S18: 5.359 | T18: 5.359 | U18: 5.359 | V18: 5.359 | W18: 5.359 | X18: 5.359 | Y18: 5.359 | Z18: 5.359 | AA18: 5.359 | AB18: 5.359 | AC18: 5.359 | AD18: 5.359 | AE18: 5.359 | AF18: 5.359 | AG18: 5.359 | AH18: 5.359 | AI18: 5.359 | AJ18: 5.359 | AK18: 0
A19: CNV000:aa_Distillate | B19: Distillate Fuel Oil | C19: 5.825 | D19: 5.825 | E19: 5.825 | F19: 5.825 | G19: 5.825 | H19: 5.825 | I19: 5.825 | J19: 5.825 | K19: 5.825 | L19: 5.825 | M19: 5.825 | N19: 5.825 | O19: 5.825 | P19: 5.825 | Q19: 5.825 | R19: 5.825 | S19: 5.825 | T19: 5.825 | U19: 5.825 | V19: 5.825 | W19: 5.825 | X19: 5.825 | Y19: 5.825 | Z19: 5.825 | AA19: 5.825 | AB19: 5.825 | AC19: 5.825 | AD19: 5.825 | AE19: 5.825 | AF19: 5.825 | AG19: 5.825 | AH19: 5.825 | AI19: 5.825 | AJ19: 5.825 | AK19: 0
A20: CNV000:aa_Residential | B20: Residential | C20: 5.774651 | D20: 5.773824 | E20: 5.773629 | F20: 5.772928 | G20: 5.773119 | H20: 5.773727 | I20: 5.772429 | J20: 5.773784 | K20: 5.772606 | L20: 5.773323 | M20: 5.774547 | N20: 5.774744 | O20: 5.773522 | P20: 5.773616 | Q20: 5.773581 | R20: 5.773493 | S20: 5.774485 | T20: 5.773373 | U20: 5.773317 | V20: 5.772994 | W20: 5.773236 | X20: 5.773163 | Y20: 5.773045 | Z20: 5.773002 | AA20: 5.772993 | AB20: 5.772738 | AC20: 5.772945 | AD20: 5.772616 | AE20: 5.772657 | AF20: 5.772504 | AG20: 5.772273 | AH20: 5.772147 | AI20: 5.771948 | AJ20: 5.771775 | AK20: -1.1e-05
A21: CNV000:aa_Commercial | B21: Commercial | C21: 5.774651 | D21: 5.773824 | E21: 5.773629 | F21: 5.772928 | G21: 5.773119 | H21: 5.773727 | I21: 5.772429 | J21: 5.773784 | K21: 5.772606 | L21: 5.773323 | M21: 5.774547 | N21: 5.774744 | O21: 5.773522 | P21: 5.773616 | Q21: 5.773581 | R21: 5.773493 | S21: 5.774485 | T21: 5.773373 | U21: 5.773317 | V21: 5.772994 | W21: 5.773236 | X21: 5.773163 | Y21: 5.773045 | Z21: 5.773002 | AA21: 5.772993 | AB21: 5.772738 | AC21: 5.772945 | AD21: 5.772616 | AE21: 5.772657 | AF21: 5.772504 | AG21: 5.772273 | AH21: 5.772147 | AI21: 5.771948 | AJ21: 5.771775 | AK21: -1.1e-05
A22: CNV000:aa_Transportatio | B22: Transportation | C22: 5.774651 | D22: 5.773824 | E22: 5.773629 | F22: 5.772928 | G22: 5.773119 | H22: 5.773727 | I22: 5.772429 | J22: 5.773784 | K22: 5.772606 | L22: 5.773323 | M22: 5.774547 | N22: 5.774744 | O22: 5.773522 | P22: 5.773616 | Q22: 5.773581 | R22: 5.773493 | S22: 5.774485 | T22: 5.773373 | U22: 5.773317 | V22: 5.772994 | W22: 5.773236 | X22: 5.773163 | Y22: 5.773045 | Z22: 5.773002 | AA22: 5.772993 | AB22: 5.772738 | AC22: 5.772945 | AD22: 5.772616 | AE22: 5.772657 | AF22: 5.772504 | AG22: 5.772273 | AH22: 5.772147 | AI22: 5.771948 | AJ22: 5.771775 | AK22: -1.1e-05
A23: CNV000:aa_Industrial | B23: Industrial | C23: 5.774651 | D23: 5.773824 | E23: 5.773629 | F23: 5.772928 | G23: 5.773119 | H23: 5.773727 | I23: 5.772429 | J23: 5.773784 | K23: 5.772606 | L23: 5.773323 | M23: 5.774547 | N23: 5.774744 | O23: 5.773522 | P23: 5.773616 | Q23: 5.773581 | R23: 5.773493 | S23: 5.774485 | T23: 5.773373 | U23: 5.773317 | V23: 5.772994 | W23: 5.773236 | X23: 5.773163 | Y23: 5.773045 | Z23: 5.773002 | AA23: 5.772993 | AB23: 5.772738 | AC23: 5.772945 | AD23: 5.772616 | AE23: 5.772657 | AF23: 5.772504 | AG23: 5.772273 | AH23: 5.772147 | AI23: 5.771948 | AJ23: 5.771775 | AK23: -1.1e-05
A24: CNV000:aa_ElectricPower | B24: Electric Power | C24: 5.774651 | D24: 5.773824 | E24: 5.773629 | F24: 5.772928 | G24: 5.773119 | H24: 5.773727 | I24: 5.772429 | J24: 5.773784 | K24: 5.772606 | L24: 5.773323 | M24: 5.774547 | N24: 5.774744 | O24: 5.773522 | P24: 5.773616 | Q24: 5.773581 | R24: 5.773493 | S24: 5.774485 | T24: 5.773373 | U24: 5.773317 | V24: 5.772994 | W24: 5.773236 | X24: 5.773163 | Y24: 5.773045 | Z24: 5.773002 | AA24: 5.772993 | AB24: 5.772738 | AC24: 5.772945 | AD24: 5.772616 | AE24: 5.772657 | AF24: 5.772504 | AG24: 5.772273 | AH24: 5.772147 | AI24: 5.771948 | AJ24: 5.771775 | AK24: -1.1e-05
A25: CNV000:aa_TotalDistilla | B25: Total Distillate | C25: 5.774651 | D25: 5.773824 | E25: 5.773628 | F25: 5.772927 | G25: 5.773119 | H25: 5.773727 | I25: 5.772429 | J25: 5.773784 | K25: 5.772606 | L25: 5.773322 | M25: 5.774548 | N25: 5.774744 | O25: 5.773522 | P25: 5.773616 | Q25: 5.77358 | R25: 5.773493 | S25: 5.774485 | T25: 5.773373 | U25: 5.773317 | V25: 5.772994 | W25: 5.773236 | X25: 5.773162 | Y25: 5.773044 | Z25: 5.773002 | AA25: 5.772993 | AB25: 5.772738 | AC25: 5.772945 | AD25: 5.772617 | AE25: 5.772656 | AF25: 5.772504 | AG25: 5.772274 | AH25: 5.772147 | AI25: 5.771948 | AJ25: 5.771775 | AK25: -1.1e-05
A26: CNV000:aa_DistLowSulf | B26: Distillate Fuel Oil - Low Sulfur Diesel | C26: 5.817 | D26: 5.817 | E26: 5.817 | F26: 5.817 | G26: 5.817 | H26: 5.817 | I26: 5.817 | J26: 5.817 | K26: 5.817 | L26: 5.817 | M26: 5.817 | N26: 5.817 | O26: 5.817 | P26: 5.817 | Q26: 5.817 | R26: 5.817 | S26: 5.817 | T26: 5.817 | U26: 5.817 | V26: 5.817 | W26: 5.817 | X26: 5.817 | Y26: 5.817 | Z26: 5.817 | AA26: 5.817 | AB26: 5.817 | AC26: 5.817 | AD26: 5.817 | AE26: 5.817 | AF26: 5.817 | AG26: 5.817 | AH26: 5.817 | AI26: 5.817 | AJ26: 5.817 | AK26: 0
A27: CNV000:aa_DistUltraLow | B27: Distillate Fuel Oil - Ultra Low Sulfur Diesel | C27: 5.77 | D27: 5.77 | E27: 5.77 | F27: 5.77 | G27: 5.77 | H27: 5.77 | I27: 5.77 | J27: 5.77 | K27: 5.77 | L27: 5.77 | M27: 5.77 | N27: 5.77 | O27: 5.77 | P27: 5.77 | Q27: 5.77 | R27: 5.77 | S27: 5.77 | T27: 5.77 | U27: 5.77 | V27: 5.77 | W27: 5.77 | X27: 5.77 | Y27: 5.77 | Z27: 5.77 | AA27: 5.77 | AB27: 5.77 | AC27: 5.77 | AD27: 5.77 | AE27: 5.77 | AF27: 5.77 | AG27: 5.77 | AH27: 5.77 | AI27: 5.77 | AJ27: 5.77 | AK27: 0
... A46: CNV000:aa_Exports | B46: Petroleum Product Exports | C46: 5.151 | D46: 5.274418 | E46: 5.250621 | F46: 5.275748 | G46: 5.243052 | H46: 5.234149 | I46: 5.231354 | J46: 5.245845 | K46: 5.231759 | L46: 5.195461 | M46: 5.187126 | N46: 5.189112 | O46: 5.179728 | P46: 5.182778 | Q46: 5.171607 | R46: 5.172073 | S46: 5.166301 | T46: 5.159403 | U46: 5.153961 | V46: 5.156905 | W46: 5.147167 | X46: 5.14539 | Y46: 5.135945 | Z46: 5.139299 | AA46: 5.137618 | AB46: 5.122315 | AC46: 5.131875 | AD46: 5.13061 | AE46: 5.139469 | AF46: 5.128032 | AG46: 5.124009 | AH46: 5.121249 | AI46: 5.111982 | AJ46: 5.1061 | AK46: -0.001013
B47: Crude Oil
A48: CNV000:aa_CrudeOilProdu | B48: Production | C48: 5.723 | D48: 5.719936 | E48: 5.709374 | F48: 5.702021 | G48: 5.699036 | H48: 5.702903 | I48: 5.701469 | J48: 5.697845 | K48: 5.696569 | L48: 5.695571 | M48: 5.691691 | N48: 5.689583 | O48: 5.687317 | P48: 5.686403 | Q48: 5.685931 | R48: 5.686055 | S48: 5.686259 | T48: 5.685382 | U48: 5.685214 | V48: 5.685896 | W48: 5.686885 | X48: 5.687922 | Y48: 5.69017 | Z48: 5.690964 | AA48: 5.689439 | AB48: 5.688754 | AC48: 5.686469 | AD48: 5.684444 | AE48: 5.683516 | AF48: 5.682888 | AG48: 5.681393 | AH48: 5.679274 | AI48: 5.678185 | AJ48: 5.676202 | AK48: -0.00024
A49: CNV000:aa_CrudeOilImpor | B49: Imports | C49: 6.05 | D49: 6.134721 | E49: 6.118438 | F49: 6.117281 | G49: 6.117947 | H49: 6.10254 | I49: 6.103374 | J49: 6.107163 | K49: 6.106585 | L49: 6.124556 | M49: 6.090179 | N49: 6.118682 | O49: 6.080531 | P49: 6.103808 | Q49: 6.113566 | R49: 6.107624 | S49: 6.084678 | T49: 6.134057 | U49: 6.131942 | V49: 6.08976 | W49: 6.138575 | X49: 6.138392 | Y49: 6.136396 | Z49: 6.138 | AA49: 6.141398 | AB49: 6.105396 | AC49: 6.119062 | AD49: 6.132329 | AE49: 6.140251 | AF49: 6.144131 | AG49: 6.141787 | AH49: 6.139135 | AI49: 6.137544 | AJ49: 6.134161 | AK49: -3e-06
A50: CNV000:aa_CrudeOilExpor | B50: Exports | C50: 5.738 | D50: 5.55477 | E50: 5.557237 | F50: 5.558167 | G50: 5.565951 | H50: 5.562354 | I50: 5.563715 | J50: 5.562271 | K50: 5.566788 | L50: 5.565995 | M50: 5.557513 | N50: 5.560513 | O50: 5.560773 | P50: 5.561747 | Q50: 5.562641 | R50: 5.562265 | S50: 5.569706 | T50: 5.594789 | U50: 5.596409 | V50: 5.603838 | W50: 5.603039 | X50: 5.612446 | Y50: 5.616357 | Z50: 5.622301 | AA50: 5.617278 | AB50: 5.611703 | AC50: 5.598722 | AD50: 5.586086 | AE50: 5.576109 | AF50: 5.561272 | AG50: 5.559134 | AH50: 5.558311 | AI50: 5.558477 | AJ50: 5.558816 | AK50: 2.3e-05
A51: CNV000:aa_NaturalGasPla | B51: Natural Gas Plant Liquids | C51: 3.699432 | D51: 3.680335 | E51: 3.675178 | F51: 3.67226 | G51: 3.661632 | H51: 3.661705 | I51: 3.660451 | J51: 3.65821 | K51: 3.656909 | L51: 3.655905 | M51: 3.655815 | N51: 3.654926 | O51: 3.65379 | P51: 3.654275 | Q51: 3.654194 | R51: 3.65518 | S51: 3.655222 | T51: 3.655784 | U51: 3.655432 | V51: 3.656329 | W51: 3.656425 | X51: 3.65846 | Y51: 3.659478 | Z51: 3.660426 | AA51: 3.659603 | AB51: 3.659032 | AC51: 3.657537 | AD51: 3.655983 | AE51: 3.654918 | AF51: 3.653574 | AG51: 3.651659 | AH51: 3.650127 | AI51: 3.64905 | AJ51: 3.6478 | AK51: -0.000277
B53: Natural Gas (thousand Btu per cubic foot)
A54: CNV000:ba_Consumption | B54: Consumption | C54: 1.037 | D54: 1.037 | E54: 1.037 | F54: 1.037 | G54: 1.037 | H54: 1.037 | I54: 1.037 | J54: 1.037 | K54: 1.037 | L54: 1.037 | M54: 1.037 | N54: 1.037 | O54: 1.037 | P54: 1.037 | Q54: 1.037 | R54: 1.037 | S54: 1.037 | T54: 1.037 | U54: 1.037 | V54: 1.037 | W54: 1.037 | X54: 1.037 | Y54: 1.037 | Z54: 1.037 | AA54: 1.037 | AB54: 1.037 | AC54: 1.037 | AD54: 1.037 | AE54: 1.037 | AF54: 1.037 | AG54: 1.037 | AH54: 1.037 | AI54: 1.037 | AJ54: 1.037 | AK54: 0
A55: CNV000:ba_Utility | B55: Electric Power Sector 2/ | C55: 1.033 | D55: 1.033 | E55: 1.033 | F55: 1.033 | G55: 1.033 | H55: 1.033 | I55: 1.033 | J55: 1.033 | K55: 1.033 | L55: 1.033 | M55: 1.033 | N55: 1.033 | O55: 1.033 | P55: 1.033 | Q55: 1.033 | R55: 1.033 | S55: 1.033 | T55: 1.033 | U55: 1.033 | V55: 1.033 | W55: 1.033 | X55: 1.033 | Y55: 1.033 | Z55: 1.033 | AA55: 1.033 | AB55: 1.033 | AC55: 1.033 | AD55: 1.033 | AE55: 1.033 | AF55: 1.033 | AG55: 1.033 | AH55: 1.033 | AI55: 1.033 | AJ55: 1.033 | AK55: 0
A56: CNV000:ba_Nonutility | B56: End-use Sector | C56: 1.039 | D56: 1.039 | E56: 1.039 | F56: 1.039 | G56: 1.039 | H56: 1.039 | I56: 1.039 | J56: 1.039 | K56: 1.039 | L56: 1.039 | M56: 1.039 | N56: 1.039 | O56: 1.039 | P56: 1.039 | Q56: 1.039 | R56: 1.039 | S56: 1.039 | T56: 1.039 | U56: 1.039 | V56: 1.039 | W56: 1.039 | X56: 1.039 | Y56: 1.039 | Z56: 1.039 | AA56: 1.039 | AB56: 1.039 | AC56: 1.039 | AD56: 1.039 | AE56: 1.039 | AF56: 1.039 | AG56: 1.039 | AH56: 1.039 | AI56: 1.039 | AJ56: 1.039 | AK56: 0
A57: CNV000:ba_Production | B57: Production | C57: 1.037 | D57: 1.037 | E57: 1.037 | F57: 1.037 | G57: 1.037 | H57: 1.037 | I57: 1.037 | J57: 1.037 | K57: 1.037 | L57: 1.037 | M57: 1.037 | N57: 1.037 | O57: 1.037 | P57: 1.037 | Q57: 1.037 | R57: 1.037 | S57: 1.037 | T57: 1.037 | U57: 1.037 | V57: 1.037 | W57: 1.037 | X57: 1.037 | Y57: 1.037 | Z57: 1.037 | AA57: 1.037 | AB57: 1.037 | AC57: 1.037 | AD57: 1.037 | AE57: 1.037 | AF57: 1.037 | AG57: 1.037 | AH57: 1.037 | AI57: 1.037 | AJ57: 1.037 | AK57: 0
A58: CNV000:ba_Imports | B58: Imports | C58: 1.025 | D58: 1.025 | E58: 1.025 | F58: 1.025 | G58: 1.025 | H58: 1.025 | I58: 1.025 | J58: 1.025 | K58: 1.025 | L58: 1.025 | M58: 1.025 | N58: 1.025 | O58: 1.025 | P58: 1.025 | Q58: 1.025 | R58: 1.025 | S58: 1.025 | T58: 1.025 | U58: 1.025 | V58: 1.025 | W58: 1.025 | X58: 1.025 | Y58: 1.025 | Z58: 1.025 | AA58: 1.025 | AB58: 1.025 | AC58: 1.025 | AD58: 1.025 | AE58: 1.025 | AF58: 1.025 | AG58: 1.025 | AH58: 1.025 | AI58: 1.025 | AJ58: 1.025 | AK58: 0
A59: CNV000:ba_Exports | B59: Exports | C59: 1.009 | D59: 1.009 | E59: 1.009 | F59: 1.009 | G59: 1.009 | H59: 1.009 | I59: 1.009 | J59: 1.009 | K59: 1.009 | L59: 1.009 | M59: 1.009 | N59: 1.009 | O59: 1.009 | P59: 1.009 | Q59: 1.009 | R59: 1.009 | S59: 1.009 | T59: 1.009 | U59: 1.009 | V59: 1.009 | W59: 1.009 | X59: 1.009 | Y59: 1.009 | Z59: 1.009 | AA59: 1.009 | AB59: 1.009 | AC59: 1.009 | AD59: 1.009 | AE59: 1.009 | AF59: 1.009 | AG59: 1.009 | AH59: 1.009 | AI59: 1.009 | AJ59: 1.009 | AK59: 0
A60: CNV000:ba_CompressedNat | B60: Compressed/Liquefied Natural Gas | C60: 0.96 | D60: 0.96 | E60: 0.96 | F60: 0.96 | G60: 0.96 | H60: 0.96 | I60: 0.96 | J60: 0.96 | K60: 0.96 | L60: 0.96 | M60: 0.96 | N60: 0.96 | O60: 0.96 | P60: 0.96 | Q60: 0.96 | R60: 0.96 | S60: 0.96 | T60: 0.96 | U60: 0.96 | V60: 0.96 | W60: 0.96 | X60: 0.96 | Y60: 0.96 | Z60: 0.96 | AA60: 0.96 | AB60: 0.96 | AC60: 0.96 | AD60: 0.96 | AE60: 0.96 | AF60: 0.96 | AG60: 0.96 | AH60: 0.96 | AI60: 0.96 | AJ60: 0.96 | AK60: 0
B62: Coal (million Btu per short ton)
A63: CNV000:ca_Production | B63: Production | C63: 20.53714 | D63: 20.439445 | E63: 20.349045 | F63: 20.46627 | G63: 20.363602 | H63: 20.554329 | I63: 20.653105 | J63: 20.626196 | K63: 20.621487 | L63: 20.64123 | M63: 20.627844 | N63: 20.53694 | O63: 20.501505 | P63: 20.413282 | Q63: 20.399071 | R63: 20.458256 | S63: 20.429285 | T63: 20.364529 | U63: 20.373262 | V63: 20.367174 | W63: 20.397617 | X63: 20.405455 | Y63: 20.39472 | Z63: 20.372593 | AA63: 20.382772 | AB63: 20.366734 | AC63: 20.354519 | AD63: 20.35523 | AE63: 20.38698 | AF63: 20.356945 | AG63: 20.336355 | AH63: 20.357395 | AI63: 20.34404 | AJ63: 20.347267 | AK63: -0.000141
A64: CNV000:ca_EastoftheMiss | B64: East of the Mississippi | C64: 25.416302 | D64: 25.057079 | E64: 25.074783 | F64: 25.042177 | G64: 24.938278 | H64: 24.964016 | I64: 24.911818 | J64: 24.91433 | K64: 24.898243 | L64: 24.920572 | M64: 24.903049 | N64: 24.81945 | O64: 24.850803 | P64: 24.769541 | Q64: 24.735579 | R64: 24.729204 | S64: 24.688946 | T64: 24.612101 | U64: 24.600828 | V64: 24.592125 | W64: 24.569109 | X64: 24.53866 | Y64: 24.501373 | Z64: 24.474424 | AA64: 24.491461 | AB64: 24.462055 | AC64: 24.426752 | AD64: 24.399635 | AE64: 24.40773 | AF64: 24.328617 | AG64: 24.285736 | AH64: 24.280874 | AI64: 24.244131 | AJ64: 24.25634 | AK64: -0.001014
...

Sheet GREET1 Fuel_Specs
A1: Specifications of Fuels, Global Warming Potentials of Greenhouse Gases, and Carbon and Sulfur Ratios of Pollutants
A2: 1) Specifications of Fuels
A3: Fuel | B3: Heating Value | E3: Density | F3: C ratio | G3: S ratio | H3: S ratio
B4: Calculation: LHV | C4: LHV | D4: HHV | F4: (% by wt) | G4: (ppm by wt) | H4: Actual ratio by wt | I4: LHV/HHV
A5: Use LHV or HHV in calculations? | B5: 1 | C5: 1 -- LHV; 2 -- HHV
A6: Liquid Fuels: | B6: Btu/gal | C6: Btu/gal | D6: Btu/gal | E6: grams/gal
A7: Crude oil | B7: 129670 | C7: 129670 | D7: 138350 | E7: 3205 | F7: 0.853 | G7: 16000 | H7: 0.016 | I7: 0.93726057
A8: Synthetic crude oil (SCO) | B8: 135084.91 | C8: 135084.91 | D8: 144475.84 | E8: 3266 | F8: 0.85562069 | G8: 1800 | H8: 0.0018 | I8: 0.935
A9: Bitumen | B9: 152370.9 | C9: 152370.9 | D9: 162963.53 | E9: 3839.6821 | F9: 0.83 | G9: 48000 | H9: 0.048 | I9: 0.935
A10: Dilbit (After Recovery) | B10: 152370.9 | C10: 152370.9 | D10: 162963.53 | E10: 3839.6821 | F10: 0.83 | G10: 48000 | H10: 0.048 | I10: 0.935
A11: Dilbit (Before Recovery) | B11: 145194.19 | C11: 145194.19 | D11: 155287.9 | E11: 3500.4775 | F11: 0.83245886 | G11: 37227.39 | H11: 0.03722739 | I11: 0.935
A12: Diluent | B12: 128448.53 | C12: 128448.53 | D12: 137378.1 | E12: 2709 | F12: 0.84059084 | G12: 1600 | H12: 0.0016 | I12: 0.935
A13: Shale Oil (Bakken) | B13: 125600.91 | C13: 125600.91 | D13: 134008.53 | E13: 3087.2372 | F13: 0.853 | G13: 16000 | H13: 0.016 | I13: 0.93726057
A14: Shale Oil (Eagle Ford) | B14: 122492.61 | C14: 122492.61 | D14: 130692.16 | E14: 2984.0427 | F14: 0.853 | G14: 16000 | H14: 0.016 | I14: 0.93726057
A15: Gasoline blendstock | B15: 116090 | C15: 116090 | D15: 124340 | E15: 2819 | F15: 0.863 | G15: 10 | H15: 1e-05 | I15: 0.93364967
A16: Gasoline | B16: 112193.52 | C16: 112193.52 | D16: 120438.62 | E16: 2835.562 | F16: 0.82778547 | G16: 9.0261788 | H16: 9.0261788e-06 | I16: 0.93154106
A17: CA gasoline | B17: 112193.52 | C17: 112193.52 | D17: 120438.62 | E17: 2835.562 | F17: 0.82778547 | G17: 9.0261788 | H17: 9.0261788e-06 | I17: 0.93154106
A18: High Octane Fuel (E25) | B18: 106150 | C18: 106150 | D18: 114387.5 | E18: 2861.25 | F18: 0.77775 | G18: 7.6425 | H18: 7.6425e-06 | I18: 0.92798601
... A20: U.S. conventional diesel | B20: 128450 | C20: 128450 | D20: 137380 | E20: 3167 | F20: 0.865 | G20: 200 | H20: 0.0002 | I20: 0.93499782
A21: CA diesel | B21: 129487.85 | C21: 129487.85 | D21: 138490 | E21: 3206 | F21: 0.871 | G21: 11 | H21: 1.1e-05
A22: Diesel for non-road engines | B22: 128450 | C22: 128450 | D22: 137380 | E22: 3167 | F22: 0.865 | G22: 11 | H22: 1.1e-05 | I22: 0.93499782
A23: Low-sulfur diesel | B23: 129487.85 | C23: 129487.85 | D23: 138490 | E23: 3206 | F23: 0.871 | G23: 11 | H23: 1.1e-05 | I23: 0.93499782
A24: Petroleum naphtha | B24: 116920 | C24: 116920 | D24: 125080 | E24: 2745 | F24: 0.85 | G24: 1 | H24: 1e-06 | I24: 0.93476175
A25: Low Octane Gasoline-Like Fuel (LOF) | B25: 118237.43 | C25: 118237.43 | D25: 126586.16 | E25: 2833.857 | F25: 0.85315639 | G25: 10 | H25: 1e-05 | I25: 0.93404711
A26: Conventional Jet Fuel | B26: 124307.03 | C26: 124307.03 | D26: 132948.69 | E26: 3035.8996 | F26: 0.862 | G26: 700 | H26: 0.0007 | I26: 0.93500004
A27: ULS Jet Fuel | B27: 123041.23 | C27: 123041.23 | D27: 131594.89 | E27: 2998.0455 | F27: 0.86 | G27: 11 | H27: 1.1e-05 | I27: 0.93500004
A28: NG-based FT naphtha | B28: 111520 | C28: 111520 | D28: 119740 | E28: 2651 | F28: 0.842 | G28: 0 | H28: 0 | I28: 0.93135126
A29: Residual oil | B29: 140352.52 | C29: 140352.52 | D29: 150110 | E29: 3752 | F29: 0.868 | G29: 5000 | H29: 0.005 | I29: 0.93499782
A30: Bunker fuel for ocean tanker | B30: 140352.52 | C30: 140352.52 | D30: 150110 | E30: 3752 | F30: 0.868 | G30: 27000 | H30: 0.027 | I30: 0.93499782
A31: Methanol | B31: 57250 | C31: 57250 | D31: 65200 | E31: 3006 | F31: 0.375 | G31: 0 | H31: 0 | I31: 0.87806748
A32: Ethanol | B32: 76330 | C32: 76330 | D32: 84530 | E32: 2988 | F32: 0.522 | G32: 0.57000011 | H32: 5.7000011e-07 | I32: 0.90299302
A33: Butanol | B33: 99837 | C33: 99837 | D33: 108458 | E33: 3065 | F33: 0.6486 | G33: 0 | H33: 0 | I33: 0.92051301
... A35: E-Diesel Additives | B35: 116090 | C35: 116090 | D35: 124340 | E35: 2819 | F35: 0.863 | G35: 10 | H35: 1e-05 | I35: 0.93364967
A36: Liquefied petroleum gas (LPG) | B36: 84950 | C36: 84950 | D36: 91410 | E36: 1923 | F36: 0.82 | G36: 0 | H36: 0 | I36: 0.9293294 | K36: =D36/E36*10^10 -> 4.7535101e+11
A37: Liquefied natural gas (LNG) | B37: 74720 | C37: 74720 | D37: 84820 | E37: 1621 | F37: 0.75 | G37: 0 | H37: 0 | I37: 0.88092431
A38: Dimethyl ether (DME) | B38: 68930 | C38: 68930 | D38: 75610 | E38: 2518 | F38: 0.522 | G38: 0 | H38: 0 | I38: 0.9116519
A39: Dimethoxy methane (DMM) | B39: 72200 | C39: 72200 | D39: 79196.895 | E39: 3255 | F39: 0.474 | G39: 0 | H39: 0 | I39: 0.9116519
A40: Methyl ester (biodiesel, BD) | B40: 119550 | C40: 119550 | D40: 127960 | E40: 3361 | F40: 0.776 | G40: 0 | H40: 0 | I40: 0.93427634
A41: Fischer-Tropsch diesel (FTD) | B41: 123670 | C41: 123670 | D41: 130030 | E41: 3017 | F41: 0.853 | G41: 0 | H41: 0 | I41: 0.95108821
A42: Renewable Diesel I (SuperCetane) | B42: 117059 | C42: 117059 | D42: 125293.77 | E42: 2835 | F42: 0.871 | G42: 0 | H42: 0 | I42: 0.93427634
...

Sheet EPS Fuel Crosswalk
A1: 燃料品种 | B1: Fuel Type | C1: EPS Overall | D1: Building | E1: Industrial | F1: Transport | G1: Electricity
A2: 原煤 | B2: Raw Coal | C2: coal | D2: coal | E2: coal | F2: NA | G2: coal
A3: 洗精煤 | B3: Cleaned Coal | C3: coal | D3: coal | E3: coal | F3: NA | G3: coal
A4: 型煤 | B4: Briquettes | C4: coal | D4: coal | E4: coal | F4: NA | G4: coal
A5: 煤制品 | B5: Briquettes | C5: coal | D5: coal | E5: coal | F5: NA | G5: coal
A6: 其他洗煤 | B6: Other Washed Coal | C6: lignite | D6: coal | E6: coal | F6: NA | G6: lignite
A7: 煤矸石 | B7: Gangue | C7: lignite | D7: coal | E7: coal | F7: NA | G7: lignite
A8: 焦炭 | B8: Coke Oven Gas | C8: coal | D8: coal | E8: coal | F8: NA | G8: coal
A9: 焦炉煤气 | B9: Coke Oven Gas | C9: natural gas | D9: LPG propane or butane | E9: LPG propane or butane | F9: NA | G9: natural gas
A10: 高炉煤气 | B10: Blast Furnance Gas | C10: natural gas | D10: LPG propane or butane | E10: LPG propane or butane | F10: NA | G10: natural gas
A11: 转炉煤气 | B11: Linz-Donawitz Converter Gas | C11: natural gas | D11: LPG propane or butane | E11: LPG propane or butane | F11: NA | G11: natural gas
A12: 其他煤气 | B12: Other Gas | C12: natural gas | D12: LPG propane or butane | E12: LPG propane or butane | F12: NA | G12: natural gas
... A38: 生物质汽油 | B38: biofuel gasoline | C38: biofuel gasoline | D38: NA | E38: NA | F38: biofuel gasoline | G38: NA

Sheet Calculation
B1: Physical Unit in Statistical Yearbook | C1: Physical Quantity Consumed in 2019 | D1: BTU Energy per physical unit | E1: total BTU Energy Consumed | F1: EPS Fuel Type | G1: Desired Large Fuel Output Unit | J1: Desired Small Fuel Output Unit | N1: EPS Fuel Type | O1: Total BTU Consumed | P1: Total Large Fuel Output Unit Consumed | Q1: BpLFOU | R1: BpSFOU
A2: 原煤 | B2: 万吨 | C2: {=TRANSPOSE('Start Year Energy Balance'!D41:M41)} -> 286650.58 | D2: =VLOOKUP(A2,'Heat Value'!$B$3:$F$34,5,0) -> 1.981696e+11 | E2: =C2*D2 -> 5.6805432e+16 | F2: =VLOOKUP(A2,'EPS Fuel Crosswalk'!A$2:JA$37,3,FALSE) -> coal | G2: 10,000 tonnes | H2: 万吨 | I2: =C2 -> 286650.58 | J2: tonne | K2: 吨 | L2: =10000 -> 10000 | N2: coal | O2: =SUMIFS(E$2:E$31,F$2:F$31,N2) -> 6.9105343e+16 | P2: =SUMIFS(I$2:I$31,F$2:F$31,N2) -> 332877.29 | Q2: =O2/P2 -> 2.0760005e+11 | R2: =Q2/10000 -> 20760005
A3: 洗精煤 | B3: 万吨 | C3: 0 | D3: =VLOOKUP(A3,'Heat Value'!$B$3:$F$34,5,0) -> 2.4969294e+11 | E3: =C3*D3 -> 0 | F3: =VLOOKUP(A3,'EPS Fuel Crosswalk'!A$2:JA$37,3,FALSE) -> coal | G3: 10,000 tonnes | H3: 万吨 | I3: =C3 -> 0 | J3: tonne | K3: 吨 | L3: =10000 -> 10000 | N3: lignite | O3: =SUMIFS(E$2:E$31,F$2:F$31,N3) -> 1.627794e+15 | P3: =SUMIFS(I$2:I$31,F$2:F$31,N3) -> 20531.76 | Q3: =O3/P3 -> 7.9281755e+10 | R3: =Q3/10000 -> 7928175.5
A4: 其他洗煤 | B4: 万吨 | C4: 17418.42 | D4: =VLOOKUP(A4,'Heat Value'!$B$3:$F$34,5,0) -> 7.9265946e+10 | E4: =C4*D4 -> 1.3806875e+15 | F4: =VLOOKUP(A4,'EPS Fuel Crosswalk'!A$2:JA$37,3,FALSE) -> lignite | G4: 10,000 tonnes | H4: 万吨 | I4: =C4 -> 17418.42 | J4: tonne | K4: 吨 | L4: =10000 -> 10000 | N4: natural gas | O4: =SUMIFS(E$2:E$31,F$2:F$31,N4) -> 1.011045e+16 | P4: =SUMIFS(I$2:I$31,F$2:F$31,N4) -> 2961.2316 | Q4: =O4/P4 -> 3.4142718e+12 | R4: =Q4/10000 -> 3.4142718e+08
A5: 型煤 | B5: 万吨 | C5: 1292.02 | D5: =VLOOKUP(A5,'Heat Value'!$B$3:$F$34,5,0) -> 1.4665574e+11 | E5: =C5*D5 -> 1.8948215e+14 | F5: =VLOOKUP(A5,'EPS Fuel Crosswalk'!A$2:JA$37,3,FALSE) -> coal | G5: 10,000 tonnes | H5: 万吨 | I5: =C5 -> 1292.02 | J5: tonne | K5: 吨 | L5: =10000 -> 10000 | N5: petroleum diesel | O5: =SUMIFS(E$2:E$31,F$2:F$31,N5) -> 6.2074678e+15 | P5: =SUMIFS(I$2:I$31,F$2:F$31,N5) -> 15502.78 | Q5: =O5/P5 -> 4.0040998e+11 | R5: =Q5/10000 -> 40040998
A6: 煤矸石 | B6: 万吨 | C6: 3113.34 | D6: =VLOOKUP(A6,'Heat Value'!$B$3:$F$34,5,0) -> 7.9370206e+10 | E6: =C6*D6 -> 2.4710644e+14 | F6: =VLOOKUP(A6,'EPS Fuel Crosswalk'!A$2:JA$37,3,FALSE) -> lignite | G6: 10,000 tonnes | H6: 万吨 | I6: =C6 -> 3113.34 | J6: tonne | K6: 吨 | L6: =10000 -> 10000 | N6: crude oil | O6: =SUMIFS(E$2:E$31,F$2:F$31,N6) -> 1.3575014e+14 | P6: =SUMIFS(I$2:I$31,F$2:F$31,N6) -> 342.51 | Q6: =O6/P6 -> 3.9633921e+11 | R6: =Q6/10000 -> 39633921
A7: 焦炭 | B7: 万吨 | C7: 44934.69 | D7: =VLOOKUP(A7,'Heat Value'!$B$3:$F$34,5,0) -> 2.695118e+11 | E7: =C7*D7 -> 1.2110429e+16 | F7: =VLOOKUP(A7,'EPS Fuel Crosswalk'!A$2:JA$37,3,FALSE) -> coal | G7: 10,000 tonnes | H7: 万吨 | I7: =C7 -> 44934.69 | J7: tonne | K7: 吨 | L7: =10000 -> 10000 | N7: petroleum gasoline | O7: =SUMIFS(E$2:E$31,F$2:F$31,N7) -> 5.5507474e+15 | P7: =SUMIFS(I$2:I$31,F$2:F$31,N7) -> 13597.28 | Q7: =O7/P7 -> 4.0822483e+11 | R7: =Q7/10000 -> 40822483
A8: 焦炉煤气 | B8: 亿立方米 | C8: 981.15 | D8: =VLOOKUP(A8,'Heat Value'!$B$3:$F$34,5,0) -> 1.6447944e+12 | E8: =C8*D8 -> 1.6137901e+15 | G8: 100 million cubic meter | H8: 亿立方米 | I8: =C8 -> 981.15 | J8: 10 thousand cubic meter | K8: 万立方米 | L8: =10000 -> 10000 | N8: jet fuel or kerosene | O8: =SUMIFS(E$2:E$31,F$2:F$31,N8) -> 1.6121044e+15 | P8: =SUMIFS(I$2:I$31,F$2:F$31,N8) -> 3949.06 | Q8: =O8/P8 -> 4.0822483e+11 | R8: =Q8/10000 -> 40822483
A9: 高炉煤气 | B9: 亿立方米 | C9: 11364.24 | D9: =VLOOKUP(A9,'Heat Value'!$B$3:$F$34,5,0) -> 3.5666358e+11 | E9: =C9*D9 -> 4.0532106e+15 | G9: 100 million cubic meter | H9: 亿立方米 | I9: =C9 -> 11364.24 | J9: 10 thousand cubic meter | K9: 万立方米 | L9: =10000 -> 10000 | N9: heavy fuel oil | O9: =SUMIFS(E$2:E$31,F$2:F$31,N9) -> 2.7583831e+15 | P9: =SUMIFS(I$2:I$31,F$2:F$31,N9) -> 7309.58 | Q9: =O9/P9 -> 3.7736547e+11 | R9: =Q9/10000 -> 37736547
A10: 转炉煤气 | B10: 亿立方米 | C10: 956.08 | D10: =VLOOKUP(A10,'Heat Value'!$B$3:$F$34,5,0) -> 7.530407e+11 | E10: =C10*D10 -> 7.1996716e+14 | G10: 100 million cubic meter | H10: 亿立方米 | I10: =C10 -> 956.08 | J10: 10 thousand cubic meter | K10: 万立方米 | L10: =10000 -> 10000 | N10: LPG propane or butane | O10: =SUMIFS(E$2:E$31,F$2:F$31,N10) -> 3.4170224e+15 | P10: =SUMIFS(I$2:I$31,F$2:F$31,N10) -> 7407.6 | Q10: =O10/P10 -> 4.6128603e+11 | R10: =Q10/10000 -> 46128603
A11: 其他煤气 | B11: 亿立方米 | C11: 191.39 | D11: =VLOOKUP(A11,'Heat Value'!$B$3:$F$34,5,0) -> 4.9542401e+11 | E11: =C11*D11 -> 9.4819201e+13 | G11: 100 million cubic meter | H11: 亿立方米 | I11: =C11 -> 191.39 | J11: 10 thousand cubic meter | K11: 万立方米 | L11: =10000 -> 10000 | N11: heat | O11: =SUMIFS(E$2:E$31,F$2:F$31,N11) -> 6.2218404e+15 | P11: =SUMIFS(I$2:I$31,F$2:F$31,N11) -> 1823.4414 | Q11: =O11/P11 -> 3.4121416e+12 | R11: =Q11/1000000 -> 3412141.6
A12: 其他焦化产品 | B12: 万吨 | C12: ='Start Year Energy Balance'!P41 -> 685.08 | D12: =VLOOKUP(A12,'Heat Value'!$B$3:$F$34,5,0) -> 3.1707326e+11 | E12: =C12*D12 -> 2.1722055e+14 | F12: =VLOOKUP(A12,'EPS Fuel Crosswalk'!A$2:JA$37,3,FALSE) -> petroleum diesel | G12: 10,000 tonnes | H12: 万吨 | I12: =C12 -> 685.08 | J12: tonne | K12: 吨 | L12: =10000 -> 10000 | N12: electricity | O12: =SUMIFS(E$2:E$31,F$2:F$31,N12) -> 2.4409103e+16 | P12: =SUMIFS(I$2:I$31,F$2:F$31,N12) -> 7153.602 | Q12: =O12/P12 -> 3.4121416e+12 | R12: =Q12/1000000 -> 3412141.6
A13: 原油 | B13: 万吨 | C13: {=TRANSPOSE('Start Year Energy Balance'!R41:Z41)} -> 342.51 | D13: =VLOOKUP(A13,'Heat Value'!$B$3:$F$34,5,0) -> 3.9633921e+11 | E13: =C13*D13 -> 1.3575014e+14 | F13: =VLOOKUP(A13,'EPS Fuel Crosswalk'!A$2:JA$37,3,FALSE) -> crude oil | G13: 10,000 tonnes | H13: 万吨 | I13: =C13 -> 342.51 | J13: tonne | K13: 吨 | L13: =10000 -> 10000 | N13: biomass | O13: =SUMIFS(E$2:E$31,F$2:F$31,N13) -> 2.2336225e+15 | P13: =SUMIFS(I$2:I$31,F$2:F$31,N13) -> 15651.166 | Q13: =O13/P13 -> 1.4271285e+11 | R13: =Q13/10000 -> 14271285
A14: 汽油 | B14: 万吨 | C14: 13597.28 | D14: =VLOOKUP(A14,'Heat Value'!$B$3:$F$34,5,0) -> 4.0822483e+11 | E14: =C14*D14 -> 5.5507474e+15 | F14: =VLOOKUP(A14,'EPS Fuel Crosswalk'!A$2:JA$37,3,FALSE) -> petroleum gasoline | G14: 10,000 tonnes | H14: 万吨 | I14: =C14 -> 13597.28 | J14: tonne | K14: 吨 | L14: =10000 -> 10000
