Workbook
Name acres_per_hectare: #REF!
Name acres_per_million_hectares: #REF!
Name C_to_CO2: '[1]Conversion Factors'!$A$4
Name grams_per_ton: #REF!

Sheet About
A1: PLANAbPiaSY Potential Land Area Newly Affected by Policy in a Single Year
A3: Sources: | B3: afforestation, reforestation, improved management & restoration
B4: China Environmental Statistical Yearbook
B5: 2013-2023
B7: Report on the state of land greening in China 2023
B8: 2023年中国国土绿化状况公报 (people.com.cn)
B9: Provincial Forestry Activity
B12: Area of Land Forest by Type
B13: Forest Knowledge Service System
B14: 2018
B15: Trend Data
B16: 中国森林资源清查 (ckcest.cn)
B19: Peatland Restoration
B20: ICF International
B21: 2016
B22: Managing Agricultural Land for Greenhouse Gas Mitigation within the United States
B23: https://www.usda.gov/sites/default/files/documents/White_Paper_WEB71816.pdf
B24: pages 36-37
A26: Notes | B26: forest set asides is the value calculated in 2018

Sheet Aforestation by province
A1: 8-3 各地区造林情况(2022年) | N1: 植树造林和在造林 afforestation and reforestation=人工造林（manual planting）+飞播造林（Airplane planting）+人工更新（artificial regeneration）
A2: A_x000D_ rea of Afforestation by Region (2022) | N2: 改善森林管理improved forest management =封山育林 (Closed Hillsides for Afforestation)
A3: 单位:公顷 | N3: 森林恢复(forest restoration) = 退化林修复 (Restoration of Degraded Forest)
A4: (hectare)
A5: 地 区 | B5: Region | C5: year | D5: 造 林_x000D_ 总面积_x000D_ Total_x000D_ Area of_x000D_ Afforestation | E5: 按造林方式分 By Approach | P5: 2021-2050
E6: 人工造林_x000D_ Manual_x000D_ Planting | F6: 飞播造林_x000D_ Airplane_x000D_ Planting | G6: 人工更新_x000D_ Artificial_x000D_ Regeneration | H6: 封山育林_x000D_ Closed_x000D_ Hillsides for_x000D_ Afforestation | I6: 退化林修复_x000D_ Restoration_x000D_ of Degraded_x000D_ Forest | J6: 植树造林和在造林 afforestation and reforestation | K6: 改善森林管理improved forest management | L6: 森林恢复forest restoration | P6: 植树造林和在造林 afforestation and reforestation | Q6: 改善森林管理improved forest management | R6: 森林恢复forest restoration
A7: 全 国 | B7: National Total | C7: 2021 | D7: 4202790 | J7: 1562538 | K7: 1057316 | L7: 1582935 | P7: =(P11+Q11)*R11 -> 73781300 | Q7: =P14*R14 -> 271750000 | R7: =Q14*R14 -> 48750000
A8: 北京 | B8: Beijing | C8: 2021 | D8: 3481 | J8: 3482
A9: 天津 | B9: Tianjin | C9: 2021 | D9: 5458 | J9: 0 | K9: 5458
A10: 河北 | B10: Hebei | C10: 2021 | D10: 193707 | J10: 77533 | K10: 85294 | L10: 30880 | P10: 造林 | Q10: 更新造林 | R10: 单位（百公顷）
A11: 山 西 | B11: Shanxi | C11: 2021 | D11: 362017 | J11: 243564 | K11: 63654 | L11: 54798 | P11: 494908 | Q11: 242905 | R11: 100
A12: 内蒙古 | B12: Inner Mongolia | C12: 2021 | D12: 261710 | J12: 118881 | K12: 30543 | L12: 112285
A13: 辽宁 | B13: Liaoning | C13: 2021 | D13: 67403 | J13: 32583 | K13: 3334 | L13: 31487 | P13: 森林抚育 | Q13: 退化林修复 | R13: 单位（百公顷）
A14: 吉 林 | B14: Jilin | C14: 2021 | D14: 131037 | J14: 16907 | K14: 5105 | L14: 109026 | P14: 2717500 | Q14: 487500 | R14: 100
A15: 黑龙江 | B15: Heilongjiang | C15: 2021 | D15: 75470 | J15: 14527 | K15: 27212 | L15: 33732
A16: 上海 | B16: Shanghai | C16: 2021 | D16: 35 | J16: 35 | O16: 公顷到英亩 | P16: 2.47
A17: 江苏 | B17: Jiangsu | C17: 2021 | D17: 2588 | J17: 2206 | L17: 382 | O17: 年份 | P17: 29
A18: 浙 江 | B18: Zhejiang | C18: 2021 | D18: 13632 | J18: 8424 | L18: 5208
A19: 安 徽 | B19: Anhui | C19: 2021 | D19: 37964 | J19: 10433 | K19: 14160 | L19: 13372
A20: 福建 | B20: Fujian | C20: 2021 | D20: 111123 | J20: 45674 | K20: 32579 | L20: 32870
A21: 江西 | B21: Jiangxi | C21: 2021 | D21: 257812 | J21: 71450 | K21: 46506 | L21: 139855
A22: 山 东 | B22: Shandong | C22: 2021 | D22: 15491 | J22: 8010 | L22: 7481
A23: 河南 | B23: Henan | C23: 2021 | D23: 114527 | J23: 63057 | K23: 22335 | L23: 29135
A24: 湖 北 | B24: Hubei | C24: 2021 | D24: 176322 | J24: 50094 | K24: 64218 | L24: 62009
A25: 湖 南 | B25: Hunan | C25: 2021 | D25: 300184 | J25: 103447 | K25: 70462 | L25: 126275
A26: 广 东 | B26: Guangdong | C26: 2021 | D26: 175918 | J26: 103284 | K26: 29129 | L26: 43504
A27: 广西 | B27: Guangxi | C27: 2021 | D27: 119183 | J27: 85109 | K27: 3122 | L27: 30952
A28: 海南 | B28: Hainan | C28: 2021 | D28: 10517 | J28: 10510 | L28: 8
A29: 重 庆 | B29: Chongqing | C29: 2021 | D29: 133463 | J29: 19889 | K29: 28533 | L29: 85042
A30: 四 川 | B30: Sichuan | C30: 2021 | D30: 163238 | J30: 21557 | K30: 69580 | L30: 72101
A31: 贵州 | B31: Guizhou | C31: 2021 | D31: 184517 | J31: 49212 | K31: 3332 | L31: 131974
A32: 云 南 | B32: Yunnan | C32: 2021 | D32: 186903 | J32: 33263 | K32: 64804 | L32: 88836
A33: 西藏 | B33: Tibet | C33: 2021 | D33: 66937 | J33: 65681 | K33: 1256
A34: 陕西 | B34: Shaanxi | C34: 2021 | D34: 381952 | J34: 97336 | K34: 174312 | L34: 110305
A35: 甘 肃 | B35: Gansu | C35: 2021 | D35: 252005 | J35: 103002 | K35: 52080 | L35: 96923
A36: 青海 | B36: Qinghai | C36: 2021 | D36: 146631 | J36: 22737 | K36: 80750 | L36: 43143
A37: 宁 夏 | B37: Ningxia | C37: 2021 | D37: 109814 | J37: 52691 | K37: 4723 | L37: 52401
A38: 新疆 | B38: Xinjiang | C38: 2021 | D38: 128487 | J38: 27680 | K38: 74834 | L38: 25974
A39: 大兴安岭 | B39: Daxinganling | C39: 2021 | D39: 13261 | J39: 285 | L39: 12977
A43: 8-3 各地区造林情况(2021年)
...

Sheet 2020-2023national total
A1: 年份year | B1: Region | C1: 植树造林和在造林 afforestation and reforestation | D1: 改善森林管理improved forest management | E1: 森林恢复forest restoration
A2: 2020 | B2: National Total | C2: =VLOOKUP(B2,'Aforestation by province'!$B$90:$L$122,9,0) -> 3539440 | D2: =VLOOKUP(B2,'Aforestation by province'!$B$90:$L$122,10,0) -> 1774608 | E2: =IFERROR(VLOOKUP(B2,'Aforestation by province'!$B$90:$L$122,11,0),0) -> 1619648 | H2: unit conversion=
A3: 2021 | B3: National Total | C3: =VLOOKUP(B3,'Aforestation by province'!$B$49:$L$81,9,0) -> 1507927 | D3: =VLOOKUP(B3,'Aforestation by province'!$B$49:$L$81,10,0) -> 1235098 | E3: =IFERROR(VLOOKUP(B3,'Aforestation by province'!$B$49:$L$81,11,0),0) -> 1011349 | H3: 1 hectare=2.47 acres
A4: 2022 | B4: National Total | C4: =VLOOKUP(B4,'Aforestation by province'!$B$7:$L$39,9,0) -> 1562538 | D4: =VLOOKUP(B4,'Aforestation by province'!$B$7:$L$39,10,0) -> 1057316 | E4: =IFERROR(VLOOKUP(B4,'Aforestation by province'!$B$7:$L$39,11,0),0) -> 1582935
A5: 2023 | B5: National Total | C5: 1400000 | D5: 1073000 | E5: 1525000

Sheet set asides_2014to2018
A1: Forest Area by Function | B1: Area（unit） | C1: Area | D1: Share of total
A2: 2014-2018 | B2: hundred hectares | C2: sq.km | D2: %
A3: Total forest | C3: 26651 | H3: Unit conversion
A4: Commercial forest （用材林） | B4: 680336 | C4: 680336 | D4: =C4/C3 -> 25.527597 | H4: acres per square kilometer | I4: 247.105
A5: Economic forest （经济林）
A11: Note
A12: We also assume that "commercial forest" is the forest currently being cut by the timber industry,
A13: and "economic forest" is the forst that would be cost-effective to cut.
A15: How many of these acres are available annually for set-asides?
A16: This depends on the speed with which timber harvesting could be scaled
A17: down in a given year, given the need to find replacement materials for forest products.
A18: It also is likely not desirable to completely cease timber harvesting,
A19: as wood is a renewable resource and may be better than fabricating
A20: certain replacement materials. Lacking good data on this,
A21: we will assume that timber harvesting could be reduced from its
A22: present scale by 2% of its current level per year. The model run
... A26: by the end.
A28: 0.02 | B28: potential reduction in timber harvesting achievable per year
A29: =C4*I4*A28 -> 3362288.5 | B29: acres potentially available for forest set-asides per year
A33: source: https://forest.ckcest.cn/sd/si/zgslzy.html

Sheet PLANAbPiaSY
A1: Potential Land Area (acres/year) | B1: 2020 | C1: 2021 | D1: 2022 | E1: 2023 | F1: 2024 | G1: 2025 | H1: 2026 | I1: 2027 | J1: 2028 | K1: 2029 | L1: 2030 | M1: 2031 | N1: 2032 | O1: 2033 | P1: 2034 | Q1: 2035 | R1: 2036 | S1: 2037 | T1: 2038 | U1: 2039 | V1: 2040 | W1: 2041 | X1: 2042 | Y1: 2043 | Z1: 2044 | AA1: 2045 | AB1: 2046 | AC1: 2047 | AD1: 2048 | AE1: 2049 | AF1: 2050 | AG1: 2051 | AH1: 2052 | AI1: 2053 | AJ1: 2054 | AK1: 2055 | AL1: 2056 | AM1: 2057 | AN1: 2058 | AO1: 2059 | AP1: 2060
A2: forest set asides | B2: ='set asides_2014to2018'!A29 -> 3362288.5 | C2: =$B2 -> 3362288.5 | D2: =$C2 -> 3362288.5 | E2: =$C2 -> 3362288.5 | F2: =$C2 -> 3362288.5 | G2: =$C2 -> 3362288.5 | H2: =$C2 -> 3362288.5 | I2: =$C2 -> 3362288.5 | J2: =$C2 -> 3362288.5 | K2: =$C2 -> 3362288.5 | ... AP2: =$C2 -> 3362288.5
A3: afforestation and reforestation | B3: {=TRANSPOSE(('2020-2023national total'!C2:C5)*2.47)} -> 8742416.8 | C3: 3724579.7 | D3: 3859468.9 | E3: 3458000 | F3: 6284131 | G3: 6284131 | H3: 6284131 | I3: 6284131 | J3: 6284131 | K3: 6284131 | L3: 6284131 | M3: 6284131 | N3: 6284131 | O3: 6284131 | P3: 6284131 | Q3: 6284131 | R3: 6284131 | S3: 6284131 | T3: 6284131 | U3: 6284131 | V3: 6284131 | W3: 6284131 | X3: 6284131 | Y3: 6284131 | Z3: 6284131 | AA3: 6284131 | AB3: 6284131 | AC3: 6284131 | AD3: 6284131 | AE3: 6284131 | AF3: 6284131 | AG3: 6284131 | AH3: 6284131 | AI3: 6284131 | AJ3: 6284131 | AK3: 6284131 | AL3: 6284131 | AM3: 6284131 | AN3: 6284131 | AO3: 6284131 | AP3: 6284131
A4: improved forest management | B4: {=TRANSPOSE(('2020-2023national total'!D2:D5)*2.47)} -> 4383281.8 | C4: 3050692.1 | D4: 2611570.5 | E4: 2650310 | F4: =E4 -> 2650310 | G4: =$E4 -> 2650310 | H4: =$E4 -> 2650310 | I4: =$E4 -> 2650310 | J4: =$E4 -> 2650310 | K4: =$E4 -> 2650310 | L4: =$E4 -> 2650310 | M4: =$E4 -> 2650310 | N4: =$E4 -> 2650310 | ... AP4: =$E4 -> 2650310
A5: avoid deforestation | B5: 0 | C5: 0 | D5: =$C5 -> 0 | E5: =$C5 -> 0 | F5: =$C5 -> 0 | G5: =$C5 -> 0 | H5: =$C5 -> 0 | I5: =$C5 -> 0 | J5: =$C5 -> 0 | K5: =$C5 -> 0 | ... AP5: =$C5 -> 0
A6: peatland restoration | B6: 0 | C6: 0 | D6: =$C6 -> 0 | E6: =$C6 -> 0 | F6: =$C6 -> 0 | G6: =$C6 -> 0 | H6: =$C6 -> 0 | I6: =$C6 -> 0 | J6: =$C6 -> 0 | K6: =$C6 -> 0 | ... AP6: =$C6 -> 0
A7: forest restoration | B7: {=TRANSPOSE(('2020-2023national total'!E2:E5)*2.47)} -> 4000530.6 | C7: 2498032 | D7: 3909849.5 | E7: 3766750 | F7: ='Aforestation by province'!R7*'Aforestation by province'!P16/'Aforestation by province'!P17 -> 4152155.2 | G7: =F7 -> 4152155.2 | H7: =G7 -> 4152155.2 | I7: =H7 -> 4152155.2 | J7: =I7 -> 4152155.2 | K7: =J7 -> 4152155.2 | L7: =K7 -> 4152155.2 | M7: =L7 -> 4152155.2 | N7: =M7 -> 4152155.2 | ... AP7: =AO7 -> 4152155.2
