Workbook
Name acres_per_hectare: #REF!
Name acres_per_million_hectares: #REF!
Name C_to_CO2: '[1]Conversion Factors'!$A$4
Name grams_per_ton: #REF!

Sheet About
A1: PLANAbPiaSY Potential Land Area Newly Affected by Policy in a Single Year
A3: Sources: | B3: afforestation, reforestation, improved management & restoration
B4: China Environmental Statistical Yearbook
B5: 2013-2023
B7: Report on the state of land greening in China 2023
B8: 2023年中国国土绿化状况公报 (people.com.cn)
B9: Provincial Forestry Activity
B12: Area of Land Forest by Type
B13: Forest Knowledge Service System
B14: 2018
B15: Trend Data
B16: 中国森林资源清查 (ckcest.cn)
B19: Peatland Restoration
B20: ICF International
B21: 2016
B22: Managing Agricultural Land for Greenhouse Gas Mitigation within the United States
B23: https://www.usda.gov/sites/default/files/documents/White_Paper_WEB71816.pdf
B24: pages 36-37
A26: Notes | B26: forest set asides is the value calculated in 2018

Sheet Aforestation by province
A1: 8-3 各地区造林情况(2022年) | N1: 植树造林和在造林 afforestation and reforestation=人工造林（manual planting）+飞播造林（Airplane planting）+人工更新（artificial regeneration）
A2: A_x000D_ rea of Afforestation by Region (2022) | N2: 改善森林管理improved forest management =封山育林 (Closed Hillsides for Afforestation)
A3: 单位:公顷 | N3: 森林恢复(forest restoration) = 退化林修复 (Restoration of Degraded Forest)
A4: (hectare)
A5: 地 区 | B5: Region | C5: year | D5: 造 林_x000D_ 总面积_x000D_ Total_x000D_ Area of_x000D_ Afforestation | E5: 按造林方式分 By Approach | P5: 2021-2050
E6: 人工造林_x000D_ Manual_x000D_ Planting | F6: 飞播造林_x000D_ Airplane_x000D_ Planting | G6: 人工更新_x000D_ Artificial_x000D_ Regeneration | H6: 封山育林_x000D_ Closed_x000D_ Hillsides for_x000D_ Afforestation | I6: 退化林修复_x000D_ Restoration_x000D_ of Degraded_x000D_ Forest | J6: 植树造林和在造林 afforestation and reforestation | K6: 改善森林管理improved forest management | L6: 森林恢复forest restoration | P6: 植树造林和在造林 afforestation and reforestation | Q6: 改善森林管理improved forest management | R6: 森林恢复forest restoration
A7: 全 国 | B7: National Total | C7: 2021 | D7: 4202790 | J7: 1562538 | K7: 1057316 | L7: 1582935 | P7: =(P11+Q11)*R11 -> 73781300 | Q7: =P14*R14 -> 271750000 | R7: =Q14*R14 -> 48750000
A8: 北京 | B8: Beijing | C8: 2021 | D8: 3481 | J8: 3482
A9: 天津 | B9: Tianjin | C9: 2021 | D9: 5458 | J9: 0 | K9: 5458
A10: 河北 | B10: Hebei | C10: 2021 | D10: 193707 | J10: 77533 | K10: 85294 | L10: 30880 | P10: 造林 | Q10: 更新造林 | R10: 单位（百公顷）
A11: 山 西 | B11: Shanxi | C11: 2021 | D11: 362017 | J11: 243564 | K11: 63654 | L11: 54798 | P11: 494908 | Q11: 242905 | R11: 100
A12: 内蒙古 | B12: Inner Mongolia | C12: 2021 | D12: 261710 | J12: 118881 | K12: 30543 | L12: 112285
A13: 辽宁 | B13: Liaoning | C13: 2021 | D13: 67403 | J13: 32583 | K13: 3334 | L13: 31487 | P13: 森林抚育 | Q13: 退化林修复 | R13: 单位（百公顷）
A14: 吉 林 | B14: Jilin | C14: 2021 | D14: 131037 | J14: 16907 | K14: 5105 | L14: 109026 | P14: 2717500 | Q14: 487500 | R14: 100
A15: 黑龙江 | B15: Heilongjiang | C15: 2021 | D15: 75470 | J15: 14527 | K15: 27212 | L15: 33732
A16: 上海 | B16: Shanghai | C16: 2021 | D16: 35 | J16: 35 | O16: 公顷到英亩 | P16: 2.47
A17: 江苏 | B17: Jiangsu | C17: 2021 | D17: 2588 | J17: 2206 | L17: 382 | O17: 年份 | P17: 29
A18: 浙 江 | B18: Zhejiang | C18: 2021 | D18: 13632 | J18: 8424 | L18: 5208
A19: 安 徽 | B19: Anhui | C19: 2021 | D19: 37964 | J19: 10433 | K19: 14160 | L19: 13372
A20: 福建 | B20: Fujian | C20: 2021 | D20: 111123 | J20: 45674 | K20: 32579 | L20: 32870
A21: 江西 | B21: Jiangxi | C21: 2021 | D21: 257812 | J21: 71450 | K21: 46506 | L21: 139855
A22: 山 东 | B22: Shandong | C22: 2021 | D22: 15491 | J22: 8010 | L22: 7481
A23: 河南 | B23: Henan | C23: 2021 | D23: 114527 | J23: 63057 | K23: 22335 | L23: 29135
A24: 湖 北 | B24: Hubei | C24: 2021 | D24: 176322 | J24: 50094 | K24: 64218 | L24: 62009
A25: 湖 南 | B25: Hunan | C25: 2021 | D25: 300184 | J25: 103447 | K25: 70462 | L25: 126275
A26: 广 东 | B26: Guangdong | C26: 2021 | D26: 175918 | J26: 103284 | K26: 29129 | L26: 43504
A27: 广西 | B27: Guangxi | C27: 2021 | D27: 119183 | J27: 85109 | K27: 3122 | L27: 30952
A28: 海南 | B28: Hainan | C28: 2021 | D28: 10517 | J28: 10510 | L28: 8
A29: 重 庆 | B29: Chongqing | C29: 2021 | D29: 133463 | J29: 19889 | K29: 28533 | L29: 85042
A30: 四 川 | B30: Sichuan | C30: 2021 | D30: 163238 | J30: 21557 | K30: 69580 | L30: 72101
A31: 贵州 | B31: Guizhou | C31: 2021 | D31: 184517 | J31: 49212 | K31: 3332 | L31: 131974
A32: 云 南 | B32: Yunnan | C32: 2021 | D32: 186903 | J32: 33263 | K32: 64804 | L32: 88836
A33: 西藏 | B33: Tibet | C33: 2021 | D33: 66937 | J33: 65681 | K33: 1256
A34: 陕西 | B34: Shaanxi | C34: 2021 | D34: 381952 | J34: 97336 | K34: 174312 | L34: 110305
A35: 甘 肃 | B35: Gansu | C35: 2021 | D35: 252005 | J35: 103002 | K35: 52080 | L35: 96923
A36: 青海 | B36: Qinghai | C36: 2021 | D36: 146631 | J36: 22737 | K36: 80750 | L36: 43143
A37: 宁 夏 | B37: Ningxia | C37: 2021 | D37: 109814 | J37: 52691 | K37: 4723 | L37: 52401
A38: 新疆 | B38: Xinjiang | C38: 2021 | D38: 128487 | J38: 27680 | K38: 74834 | L38: 25974
A39: 大兴安岭 | B39: Daxinganling | C39: 2021 | D39: 13261 | J39: 285 | L39: 12977
A43: 8-3 各地区造林情况(2021年)
...

Sheet 2020-2023national total
A1: 年份year | B1: Region | C1: 植树造林和在造林 afforestation and reforestation | D1: 改善森林管理improved forest management | E1: 森林恢复forest restoration
A2: 2020 | B2: National Total | C2: =VLOOKUP(B2,'Aforestation by province'!$B$90:$L$122,9,0) -> 3539440 | D2: =VLOOKUP(B2,'Aforestation by province'!$B$90:$L$122,10,0) -> 1774608 | E2: =IFERROR(VLOOKUP(B2,'Aforestation by province'!$B$90:$L$122,11,0),0) -> 1619648
A3: 2021 | B3: National Total | C3: =VLOOKUP(B3,'Aforestation by province'!$B$49:$L$81,9,0) -> 1507927 | D3: =VLOOKUP(B3,'Aforestation by province'!$B$49:$L$81,10,0) -> 1235098 | E3: =IFERROR(VLOOKUP(B3,'Aforestation by province'!$B$49:$L$81,11,0),0) -> 1011349
A4: 2022 | B4: National Total | C4: =VLOOKUP(B4,'Aforestation by province'!$B$7:$L$39,9,0) -> 1562538 | D4: =VLOOKUP(B4,'Aforestation by province'!$B$7:$L$39,10,0) -> 1057316 | E4: =IFERROR(VLOOKUP(B4,'Aforestation by province'!$B$7:$L$39,11,0),0) -> 1582935
A5: 2023 | B5: National Total | C5: 1400000 | D5: 1073000 | E5: 1525000

Sheet set asides_2014to2018
A1: Forest Area by Function | B1: Area（unit） | C1: Area | D1: Share of total
A2: 2014-2018 | B2: hundred hectares | C2: sq.km | D2: %
A3: Total forest | C3: 26651 | H3: Unit conversion
A4: Commercial forest （用材林） | B4: 680336 | C4: 680336 | D4: =C4/C3 -> 25.527597 | H4: acres per square kilometer | I4: 247.105
A5: Economic forest （经济林）
A11: Note
A12: We also assume that "commercial forest" is the forest currently being cut by the timber industry,
A13: and "economic forest" is the forst that would be cost-effective to cut.
A15: How many of these acres are available annually for set-asides?
A16: This depends on the speed with which timber harvesting could be scaled
A17: down in a given year, given the need to find replacement materials for forest products.
A18: It also is likely not desirable to completely cease timber harvesting,
A19: as wood is a renewable resource and may be better than fabricating
A20: certain replacement materials. Lacking good data on this,
A21: we will assume that timber harvesting could be reduced from its
A22: present scale by 2% of its current level per year. The model run
... A26: by the end.
A28: 0.02 | B28: potential reduction in timber harvesting achievable per year
A29: =ROUND(C4*I4*A28,0) -> 3362289 | B29: acres potentially available for forest set-asides per year
A33: source: https://forest.ckcest.cn/sd/si/zgslzy.html

Sheet Forestry Statistics
A1: 指标名称 | C1: 2000年 | D1: 2001年 | E1: 2002年 | F1: 2003年 | G1: 2004年 | H1: 2005年 | I1: 2006年 | J1: 2007年 | K1: 2008年 | L1: 2009年 | M1: 2010年 | N1: 2011年 | O1: 2012年 | P1: 2013年 | Q1: 2014年 | R1: 2015年 | S1: 2016年 | T1: 2017年 | U1: 2018年 | V1: 2019年 | W1: 2020年 | X1: 2021年 | Y1: 2022年 | Z1: 2023年 | AA1: 2024年 | AB1: 2025年
A2: 总造林面积 | B2: 公顷 | C2: =C4+C8+C11+C15+C23 -> 12154978 | D2: =D4+D8+D11+D15+D23 -> 11290268 | E2: =E4+E8+E11+E15+E23 -> 10711332 | F2: =F4+F8+F11+F15+F23 -> 11222230 | G2: =G4+G8+G11+G15+G23 -> 7919530 | H2: =H4+H8+H11+H15+H23 -> 6691949 | I2: =I4+I8+I11+I15+I23 -> 4597818 | J2: =J4+J8+J11+J15+J23 -> 4682213 | ... AB2: =AB4+AB8+AB11+AB15+AB23 -> 3563000
A3: 造林面积（当年/荒山） | B3: 公顷 | C3: 5105138 | D3: 4953038 | E3: 7770971 | F3: 9118894 | G3: 5598079 | H3: 3637681 | I3: 3838794 | J3: 3907711 | K3: 5353735 | L3: 6262330 | M3: 5909919 | N3: 5996613 | O3: 5595791 | P3: 6100057 | Q3: 5549612 | R3: 7681952 | S3: 7203509 | T3: 7680711 | U3: 7299473
A4: 人工造林 | B4: 公顷 | C4: 4345008 | D4: 3977324 | E4: 6896041 | F4: 8432486 | G4: 5018885 | H4: 3221295 | I4: 2446122 | J4: 2738521 | K4: 3684261 | L4: 4156293 | M4: 3872762 | N4: 4065693 | O4: 3820704 | P4: 4209686 | Q4: 4052912 | R4: 4361827 | S4: 3823656 | T4: 4295890 | U4: 3677952 | V4: 3458315 | W4: 3000060 | X4: 1085095 | Y4: 930860 | Z4: 1014361 | AA4: 797680 | AB4: 830000
A5: 其中:新造混交林面积 | B5: 公顷 | Q5: - | R5: 1145826 | S5: 765451 | T5: 1416817 | U5: 876206
A6: 其中:新造灌木林面积 | B6: 公顷 | Q6: 311569 | R6: 327282 | S6: 293437 | T6: 372593 | U6: 440023
A7: 其中:新造竹林面积 | B7: 公顷 | C7: 79800 | D7: 106909 | E7: 128521 | F7: 178901 | G7: 82058 | H7: 87533 | I7: 45071 | J7: 64227 | K7: 80711 | L7: 87468 | M7: 69978 | N7: 74580 | O7: 41424 | P7: 47794 | Q7: 46903 | R7: 37204 | S7: 31334 | T7: 27319 | U7: 56470
A8: 飞播造林 | B8: 公顷 | C8: 760130 | D8: 975714 | E8: 874930 | F8: 686408 | G8: 579194 | H8: 416386 | I8: 271803 | J8: 118671 | K8: 154065 | L8: 226337 | M8: 195948 | N8: 196931 | O8: 136409 | P8: 154400 | Q8: 109654 | R8: 128390 | S8: 162322 | T8: 141220 | U8: 135429 | V8: 125565 | W8: 151496 | X8: 172239 | Y8: 166099 | Z8: 66997 | AA8: 67612 | AB8: 48080.135
A9: 荒山飞播造林面积 | B9: 公顷 | Q9: 108055 | R9: 127724 | S9: 156391 | T9: 136954 | U9: 125907
A10: 飞播营林面积 | B10: 公顷 | J10: 5022 | Q10: 1599 | R10: 666 | S10: 5931 | T10: 4266 | U10: 9522
A11: 人工更新（原迹地更新）面积 | B11: 公顷 | C11: 919799 | D11: 515293 | E11: 378999 | F11: 285994 | G11: 319310 | H11: 407546 | I11: 408240 | J11: 390911 | K11: 424003 | L11: 344254 | M11: 306708 | N11: 326641 | O11: 305065 | P11: 303086 | Q11: 292453 | R11: 299577 | S11: 272805 | T11: 305439 | U11: 371859 | V11: 370223 | W11: 387884 | X11: 250593 | Y11: 465579 | Z11: 625911 | AA11: 624231 | AB11: 443902.13
A12: 其中：人工更新面积 | B12: 公顷 | C12: 568309 | D12: 386571 | E12: 298369 | F12: 220866 | G12: 271262 | H12: 326952 | I12: 300202 | J12: —
A13: 其中:新造混交林面积 | B13: 公顷 | R13: 54541 | S13: 44782 | T13: 45936 | U13: 31913
A14: 其中:人工促进天然更新面积 | B14: 公顷 | R14: 56825 | S14: 46979 | T14: 36295 | U14: 189794
A15: 退化林修复 | B15: 公顷 | R15: 739334 | S15: 991088 | T15: 1280993 | U15: 1329166 | V15: 1537877 | W15: 1619648 | X15: 1011349 | Y15: 1582935 | Z15: 1795750 | AA15: 1884367 | AB15: 1340008
A16: 其中:纯林改造混交林面积 | B16: 公顷 | R16: 29491 | S16: 46291 | T16: 93056 | U16: 69309
A17: (1)低效林改造面积 | B17: 公顷 | C17: 1073420 | D17: 703774 | E17: 575934 | F17: 264040 | G17: 279516 | H17: 328060 | I17: 296056 | J17: 290609 | K17: 395861 | L17: 543412 | M17: 665598 | N17: 788810 | O17: 707499 | P17: 758327 | Q17: 687375 | R17: 684752 | S17: 718305 | T17: 764190 | U17: 846156
A18: (2)退化林防护林改造面积 | B18: 公顷 | R18: 54529 | S18: 272783 | T18: 516803 | U18: 483010
A19: 年末实有封山育林面积 | B19: 公顷 | C19: 32584372 | D19: 35426636 | E19: 29301513 | F19: 23055394 | G19: 21585588 | H19: 21994790 | I19: 20202327 | J19: 20643218 | K19: 21526252 | L19: 21537816 | M19: 23938134 | N19: 23481113 | O19: 24140908 | P19: 25178730 | Q19: 24719474 | R19: 27509897 | S19: 25497053 | T19: 24682804 | U19: 24596091
A20: 无林地和疏林地封育面积 | B20: 公顷 | G20: 9002889 | H20: 9992981 | I20: 9433425
A21: 有林地封育面积 | B21: 公顷 | G21: 7432555 | H21: 7272836 | I21: 6526637
A22: 灌木林封育面积 | B22: 公顷 | G22: 5150144 | H22: 4728972 | I22: 4242265
A23: 其中：本年新封面积 | B23: 公顷 | C23: 6130041 | D23: 5821937 | E23: 2561362 | F23: 1817342 | G23: 2002141 | H23: 2646722 | I23: 1471653 | J23: =J24+J25+J28 -> 1434110 | K23: =K24+K25+K28 -> 1744691 | L23: =L24+L25+L28 -> 2205799 | M23: =M24+M25+M28 -> 2152875 | N23: =N24+N25+N28 -> 2030477 | O23: =O24+O25+O28 -> 2069714 | P23: =P24+P25+P28 -> 2254605 | Q23: 1853832 | R23: 2152877 | S23: 1953638 | T23: 1657169 | U23: 1785067 | V23: 1898314 | W23: 1774608 | X23: 1235098 | Y23: 1057316 | Z23: 1133101 | AA23: 1267032 | AB23: 901009.74
A24: 无林地和疏林地新封 | B24: 公顷 | C24: 6130041 | D24: 5821937 | E24: 2561362 | F24: 1817342 | G24: 1196546 | H24: 1762999 | I24: 1120869 | J24: 1050519 | K24: 1515409 | L24: 1879700 | M24: 1841209 | N24: 1733989 | O24: 1638678 | P24: 1735971 | Q24: 1388645 | R24: 1544074 | S24: 1399471 | T24: 984741 | U24: 1034079 | V24: 1072561 | W24: 1025026
A25: 有林地和灌木林地新封 | B25: 公顷 | C25: — | D25: — | E25: — | F25: — | G25: =G26+G27 -> 805595 | H25: =H26+H27 -> 883723 | I25: =I26+I27 -> 350784 | J25: 383591 | K25: 229282 | L25: 326099 | M25: 311666 | N25: 296488 | O25: 431036 | P25: 518634 | Q25: 465187 | R25: 608803 | S25: 554167 | T25: 672428 | U25: 750988 | V25: 781476 | W25: 680500
A26: 有林地新封面积 | B26: 公顷 | G26: 518419 | H26: 546220 | I26: 244278
A27: 灌木林封育面积 | B27: 公顷 | G27: 287176 | H27: 337503 | I27: 106506
A28: 新造幼林地封山育林 | B28: 公顷 | V28: 44277 | W28: 69082
A30: 零星（四旁）植树 | B30: 万株 | C30: 300504 | D30: 280448 | E30: 264031 | F30: 301341 | G30: 271139 | H30: 214246 | I30: 232487 | J30: 245438 | K30: 235499 | L30: 245555 | M30: 246930 | N30: 245776 | O30: 239418 | P30: 235734 | Q30: 205721 | R30: 212374 | S30: 183094 | T30: 174799 | U30: 173967
A31: 退耕地造林面积 | B31: 公顷 | C31: 751731 | D31: 653269 | E31: — | F31: — | G31: — | H31: — | I31: — | J31: —
A32: 森林管护面积 | B32: 公顷 | C32: 21514468 | D32: 120225687 | E32: 134058184 | F32: — | G32: — | H32: — | I32: — | J32: —
A34: 森林抚育总面积 | B34: 公顷 | C34: 5013000 | D34: 4574400 | E34: 4816800 | F34: 4577700 | G34: 5271500 | H34: 5010600 | I34: 5509600 | J34: 6497600 | K34: 6235300 | L34: 6362600 | M34: 6661700 | N34: 7334500 | O34: 7661700 | P34: 7847200 | Q34: 9019600 | R34: 7812600 | S34: 8500400 | T34: 8856398 | U34: 8675957 | V34: 8477587 | W34: 9115824 | X34: 6422133 | Y34: 5737514 | Z34: 6471079
A35: 抚育采伐 | B35: 公顷 | Y35: 1223827 | Z35: 1143776
A36: 补植抚育 | B36: 公顷 | Y36: 372882 | Z36: 361251
A37: 人工促进天然更新 | B37: 公顷 | R37: =R14 -> 56825 | S37: =S14 -> 46979 | T37: =T14 -> 36295 | U37: =U14 -> 189794 | Y37: 206524 | Z37: 110140
A38: 其他综合抚育 | B38: 公顷 | Y38: 3934281 | Z38: 4855912
A39: 低产（低效）林改造面积 | B39: 公顷 | C39: 1073420 | D39: 703774 | E39: 575934 | F39: 264040 | G39: 279516 | H39: 328060 | I39: 296056 | J39: 290609 | K39: 395861 | L39: 543412 | M39: 665598 | N39: 788810 | O39: 707499 | P39: 758327 | Q39: 687375 | R39: 684752 | S39: 718305 | T39: 764190 | U39: 846156
A40: 幼林抚育
A41: 幼林抚育作业面积 | B41: 公顷次 | C41: 11825322 | D41: 15955330 | E41: 11746879 | F41: 13879481 | G41: 14778920 | H41: 17327735 | I41: 17637976 | J41: 16263151 | K41: 15042955 | L41: 14878720 | M41: 13011459 | N41: 12800526 | O41: 9396281 | P41: 7751527 | Q41: 6966646
A42: 幼林抚育实际面积 | B42: 公顷 | C42: 7105272 | D42: 7055335 | E42: 6929253 | F42: 7988515 | G42: 8994905 | H42: 9879241 | I42: 9582760 | J42: 9746176 | K42: 9281807 | L42: 9555999 | M42: 7769016 | N42: 7349667
...

Sheet Calculation
A1: Region | B1: Year | C1: 造 林_x000D_ 总面积_x000D_ Total_x000D_ Area of_x000D_ Afforestation | D1: 按造林方式分 By Approach | M1: In Acres | P1: Cumulative | Q1: unit conversion=
D2: 人工造林_x000D_ Manual_x000D_ Planting | E2: 飞播造林_x000D_ Airplane_x000D_ Planting | F2: 封山育林_x000D_ Closed_x000D_ Hillsides for_x000D_ Afforestation | G2: 退化林修复_x000D_ Restoration_x000D_ of Degraded_x000D_ Forest | H2: 人工更新_x000D_ Artificial_x000D_ Regeneration | I2: 森林（中幼龄木）抚育面积 | J2: 植树造林和在造林 afforestation and reforestation | K2: 改善森林管理improved forest management | L2: 森林恢复forest restoration | M2: 植树造林和在造林 afforestation and reforestation | N2: 改善森林管理improved forest management | O2: 森林恢复forest restoration | P2: 改善森林管理improved forest management | Q2: 1 hectare=2.47 acres
A3: 全国 | B3: 2015 | C3: 7683695 | D3: {=TRANSPOSE('Forestry Statistics'!$R$4:$AB$4)} -> 4361827 | E3: {=TRANSPOSE('Forestry Statistics'!$R$8:$AB$8)} -> 128390 | F3: {=TRANSPOSE('Forestry Statistics'!R23:AB23)} -> 2152877 | G3: {=TRANSPOSE('Forestry Statistics'!R15:AB15)} -> 739334 | H3: {=TRANSPOSE('Forestry Statistics'!R11:AB11)} -> 299577 | I3: {=TRANSPOSE('Forestry Statistics'!R34:AB34)} -> 7812600 | J3: =D3+E3+H3 -> 4789794 | K3: =I3 -> 7812600 | L3: =G3+F3 -> 2892211 | M3: =ROUND(J3*2.47,0) -> 11830791 | N3: =ROUND(K3*2.47,0) -> 19297122 | O3: =ROUND(L3*2.47,0) -> 7143761
A4: 全国 | B4: 2016 | C4: 7203509 | D4: 3823656 | E4: 162322 | F4: 1953638 | G4: 991088 | H4: 272805 | I4: 8500400 | J4: =D4+E4+H4 -> 4258783 | K4: =I4 -> 8500400 | L4: =G4+F4 -> 2944726 | M4: =ROUND(J4*2.47,0) -> 10519194 | N4: =ROUND(K4*2.47,0) -> 20995988 | O4: =ROUND(L4*2.47,0) -> 7273473
A5: 全国 | B5: 2017 | C5: 7680711 | D5: 4295890 | E5: 141220 | F5: 1657169 | G5: 1280993 | H5: 305439 | I5: 8856398 | J5: =D5+E5+H5 -> 4742549 | K5: =I5 -> 8856398 | L5: =G5+F5 -> 2938162 | M5: =ROUND(J5*2.47,0) -> 11714096 | N5: =ROUND(K5*2.47,0) -> 21875303 | O5: =ROUND(L5*2.47,0) -> 7257260
A6: 全国 | B6: 2018 | C6: 7299473 | D6: 3677952 | E6: 135429 | F6: 1785067 | G6: 1329166 | H6: 371859 | I6: 8675957 | J6: =D6+E6+H6 -> 4185240 | K6: =I6 -> 8675957 | L6: =G6+F6 -> 3114233 | M6: =ROUND(J6*2.47,0) -> 10337543 | N6: =ROUND(K6*2.47,0) -> 21429614 | O6: =ROUND(L6*2.47,0) -> 7692156
A7: 全国 | B7: 2019 | C7: 7390294 | D7: 3458315 | E7: 125565 | F7: 1898314 | G7: 1537877 | H7: 370223 | I7: 8477587 | J7: =D7+E7+H7 -> 3954103 | K7: =I7 -> 8477587 | L7: =G7+F7 -> 3436191 | M7: =ROUND(J7*2.47,0) -> 9766634 | N7: =ROUND(K7*2.47,0) -> 20939640 | O7: =ROUND(L7*2.47,0) -> 8487392
A8: 全国 | B8: 2020 | C8: 6933696 | D8: 3000060 | E8: 151496 | F8: 1774608 | G8: 1619648 | H8: 387884 | I8: 9115824 | J8: =D8+E8+H8 -> 3539440 | K8: =I8 -> 9115824 | L8: =G8+F8 -> 3394256 | M8: =ROUND(J8*2.47,0) -> 8742417 | N8: =ROUND(K8*2.47,0) -> 22516085 | O8: =ROUND(L8*2.47,0) -> 8383812 | P8: =N8 -> 22516085
A9: 全国 | B9: 2021 | C9: 3754373 | D9: 1085095 | E9: 172239 | F9: 1235098 | G9: 1011349 | H9: 250593 | I9: 6422133 | J9: =D9+E9+H9 -> 1507927 | K9: =I9 -> 6422133 | L9: =G9+F9 -> 2246447 | M9: =ROUND(J9*2.47,0) -> 3724580 | N9: =ROUND(K9*2.47,0) -> 15862669 | O9: =ROUND(L9*2.47,0) -> 5548724 | P9: =N9+P8 -> 38378754
A10: 全国 | B10: 2022 | C10: 4202790 | D10: 930860 | E10: 166099 | F10: 1057316 | G10: 1582935 | H10: 465579 | I10: 5737514 | J10: =D10+E10+H10 -> 1562538 | K10: =I10 -> 5737514 | L10: =G10+F10 -> 2640251 | M10: =ROUND(J10*2.47,0) -> 3859469 | N10: =ROUND(K10*2.47,0) -> 14171660 | O10: =ROUND(L10*2.47,0) -> 6521420 | P10: =N10+P9 -> 52550414
A11: 全国 | B11: 2023 | C11: 4636119 | D11: 1014361 | E11: 66997 | F11: 1133101 | G11: 1795750 | H11: 625911 | I11: 6471079 | J11: =D11+E11+H11 -> 1707269 | K11: =I11 -> 6471079 | L11: =G11+F11 -> 2928851 | M11: =ROUND(J11*2.47,0) -> 4216954 | N11: =ROUND(K11*2.47,0) -> 15983565 | O11: =ROUND(L11*2.47,0) -> 7234262 | P11: =N11+P10 -> 68533979
A12: 全国 | B12: 2024 | C12: 4640922 | D12: 797680 | E12: 67612 | F12: 1267032 | G12: 1884367 | H12: 624231 | I12: 0 | J12: =D12+E12+H12 -> 1489523 | K12: =I12 -> 0 | L12: =G12+F12 -> 3151399 | M12: =ROUND(J12*2.47,0) -> 3679122 | N12: =ROUND(K12*2.47,0) -> 0 | O12: =ROUND(L12*2.47,0) -> 7783956 | P12: =N12+P11 -> 68533979
A13: 全国 | B13: 2025 | C13: 3563000 | D13: 830000 | E13: 48080.135 | F13: 901009.74 | G13: 1340008 | H13: 443902.13 | I13: 0 | J13: =D13+E13+H13 -> 1321982.3 | K13: =I13 -> 0 | L13: =G13+F13 -> 2241017.7 | M13: =ROUND(J13*2.47,0) -> 3265296 | N13: =ROUND(K13*2.47,0) -> 0 | O13: =ROUND(L13*2.47,0) -> 5535314 | P13: =N13+P12 -> 68533979
A15: Potential Maximum | C15: =MAX(C3:C13,1.25*MAX(C8:C13)) -> 8667120 | D15: =MAX(D3:D13,1.25*MAX(D8:D13)) -> 4361827 | E15: =MAX(E3:E13,1.25*MAX(E8:E13)) -> 215298.75 | F15: =MAX(F3:F13,1.25*MAX(F8:F13)) -> 2218260 | G15: =MAX(G3:G13,1.25*MAX(G8:G13)) -> 2355458.8 | H15: =MAX(H3:H13,1.25*MAX(H8:H13)) -> 782388.75 | J15: =ROUND(MAX(J3:J13,1.25*MAX(J8:J13)),0) -> 4789794 | K15: =ROUND(MAX(K3:K13,1.25*MAX(K8:K13)),0) -> 11394780 | L15: =ROUND(MAX(L3:L13,1.25*MAX(L8:L13)),0) -> 4242820 | M15: =ROUND(MAX(M3:M13,1.25*MAX(M8:M13)),0) -> 11830791 | N15: =ROUND(MAX(N3:N13,1.25*MAX(N8:N13)),0) -> 28145106 | O15: =ROUND(MAX(O3:O13,1.25*MAX(O8:O13)),0) -> 10479765 | P15: =_xlfn.FORECAST.LINEAR(2060,P8:P13,B8:B13) -> 4.1375172e+08
A17: Policy Action Achieved | C17: 植树造林和在造林 afforestation and reforestation | D17: 改善森林管理improved forest management | E17: 森林恢复forest restoration | L17: Policy Value for 14th FYP | M17: 植树造林和在造林 afforestation and reforestation | N17: 改善森林管理improved forest management | O17: 森林恢复forest restoration
A18: 全国 | B18: 2015 | C18: =ROUND(J3/J$15,6) -> 1 | D18: =ROUND(K3/K$15,6) -> 0.68563 | E18: =ROUND(L3/L$15,6) -> 0.681672
A19: 全国 | B19: 2016 | C19: =ROUND(J4/J$15,6) -> 0.889137 | D19: =ROUND(K4/K$15,6) -> 0.745991 | E19: =ROUND(L4/L$15,6) -> 0.694049
A20: 全国 | B20: 2017 | C20: =ROUND(J5/J$15,6) -> 0.990136 | D20: =ROUND(K5/K$15,6) -> 0.777233 | E20: =ROUND(L5/L$15,6) -> 0.692502
A21: 全国 | B21: 2018 | C21: =ROUND(J6/J$15,6) -> 0.873783 | D21: =ROUND(K6/K$15,6) -> 0.761397 | E21: =ROUND(L6/L$15,6) -> 0.734001
A22: 全国 | B22: 2019 | C22: =ROUND(J7/J$15,6) -> 0.825527 | D22: =ROUND(K7/K$15,6) -> 0.743989 | E22: =ROUND(L7/L$15,6) -> 0.809884 | M22: =MAX(C$23:C$28) -> 0.738955 | N22: 1 | O22: =MAX(E$23:E$28) -> 0.8
A23: 全国 | B23: 2020 | C23: =ROUND(J8/J$15,6) -> 0.738955 | D23: =ROUND(K8/K$15,6) -> 0.8 | E23: =ROUND(L8/L$15,6) -> 0.8 | L23: FOPITY Value | M23: =ROUND(C23/M$22,6) -> 1 | N23: =P8/P$15 -> 0.054419314 | O23: =ROUND(E23/O$22,6) -> 1
A24: 全国 | B24: 2021 | C24: =ROUND(J9/J$15,6) -> 0.314821 | D24: =ROUND(K9/K$15,6) -> 0.563603 | E24: =ROUND(L9/L$15,6) -> 0.52947 | M24: =ROUND(C24/M$22,6) -> 0.426035 | N24: =P9/P$15 -> 0.092757932 | O24: =ROUND(E24/O$22,6) -> 0.661838
A25: 全国 | B25: 2022 | C25: =ROUND(J10/J$15,6) -> 0.326222 | D25: =ROUND(K10/K$15,6) -> 0.503521 | E25: =ROUND(L10/L$15,6) -> 0.622287 | M25: =ROUND(C25/M$22,6) -> 0.441464 | N25: =P10/P$15 -> 0.12700954 | O25: =ROUND(E25/O$22,6) -> 0.777859
A26: 全国 | B26: 2023 | C26: =ROUND(J11/J$15,6) -> 0.356439 | D26: =ROUND(K11/K$15,6) -> 0.567899 | E26: =ROUND(L11/L$15,6) -> 0.690308 | M26: =ROUND(C26/M$22,6) -> 0.482355 | N26: =P11/P$15 -> 0.16564035 | O26: =ROUND(E26/O$22,6) -> 0.862885
A27: 全国 | B27: 2024 | C27: =ROUND(J12/J$15,6) -> 0.310979 | D27: =ROUND(K12/K$15,6) -> 0 | E27: =ROUND(L12/L$15,6) -> 0.74276 | M27: =ROUND(C27/M$22,6) -> 0.420836 | N27: =P12/P$15 -> 0.16564035 | O27: =ROUND(E27/O$22,6) -> 0.92845
A28: 全国 | B28: 2025 | C28: =ROUND(J13/J$15,6) -> 0.276 | D28: =ROUND(K13/K$15,6) -> 0 | E28: =ROUND(L13/L$15,6) -> 0.528191 | M28: =ROUND(C28/M$22,6) -> 0.3735 | N28: =P13/P$15 -> 0.16564035 | O28: =ROUND(E28/O$22,6) -> 0.660239

Sheet Yearbook Stats
C1: 造林总面积 | D1: 人工造林 | E1: 飞播造林 | F1: 封山育林 | G1: 退化林修复 | H1: 人工更新 | I1: 种草改良面积合计 | J1: 人工种草 | K1: 飞播种草 | L1: 草原改良 | M1: 围栏封育 | N1: 治理沙化石漠化
A2: 全国 | B2: 2025 | C2: 3563000 | D2: 830000 | I2: 4927 | N2: 2783
A3: 全国 | B3: 2024 | C3: =6669*2000/3 -> 4446000 | D3: 1180000 | I3: 3224
A4: 全国 | B4: 2023 | C4: 4636119 | D4: 1014361 | E4: 66997 | F4: 1133101 | G4: 1795750 | H4: 625911 | I4: 4378.4 | J4: 1053.6 | L4: 1063.8 | M4: 2261.1 | N4: 1905
A5: 北京 | B5: 2023 | C5: 847 | D5: 389 | G5: 459
A6: 天津 | B6: 2023 | C6: 5149 | D6: 66 | F6: 4760 | G6: 12 | H6: 312
A7: 河北 | B7: 2023 | C7: 173678 | D7: 58828 | E7: 3333 | F7: 70392 | G7: 39578 | H7: 1546 | I7: 49.2 | J7: 16.2 | L7: 14.8 | M7: 18.1
A8: 山西 | B8: 2023 | C8: 306235 | D8: 204068 | E8: 10000 | F8: 53613 | G8: 38553 | I8: 76.7 | J8: 36.1 | L8: 18.3 | M8: 22.3
A9: 内蒙古 | B9: 2023 | C9: 314383 | D9: 127237 | E9: 10667 | F9: 21379 | G9: 152431 | H9: 2668 | I9: 586.2 | J9: 180.1 | L9: 182.7 | M9: 223.3
A10: 辽宁 | B10: 2023 | C10: 63901 | D10: 30766 | F10: 2001 | G10: 26321 | H10: 4813 | I10: 21.9 | J10: 19.9 | L10: 0.9 | M10: 1.1
A11: 吉林 | B11: 2023 | C11: 88263 | D11: 415 | F11: 576 | G11: 72429 | H11: 14842 | I11: 19.9 | J11: 3.3 | L11: 7.4 | M11: 9.1
A12: 黑龙江 | B12: 2023 | C12: 82981 | D12: 2765 | F12: 32103 | G12: 41915 | H12: 6198 | I12: 18.4 | J12: 7.1 | L12: 5.1 | M12: 6.2
A13: 上海 | B13: 2023 | C13: 200 | D13: 200
A14: 江苏 | B14: 2023 | C14: 2266 | D14: 1009 | F14: 67 | G14: 482 | H14: 708
A15: 浙江 | B15: 2023 | C15: 20074 | D15: 3135 | G15: 10683 | H15: 6256
A16: 安徽 | B16: 2023 | C16: 137922 | D16: 6541 | F16: 70396 | G16: 47728 | H16: 13257
A17: 福建 | B17: 2023 | C17: 152503 | D17: 3251 | F17: 31988 | G17: 70599 | H17: 46664
A18: 江西 | B18: 2023 | C18: 252818 | D18: 18089 | F18: 36805 | G18: 124555 | H18: 73369
A19: 山东 | B19: 2023 | C19: 17647 | D19: 6493 | G19: 8788 | H19: 2367
A20: 河南 | B20: 2023 | C20: 122113 | D20: 20916 | E20: 16361 | F20: 30352 | G20: 34480 | H20: 20005 | I20: 2 | J20: 2
A21: 湖北 | B21: 2023 | C21: 193950 | D21: 30596 | F21: 37358 | G21: 111265 | H21: 14732
A22: 湖南 | B22: 2023 | C22: 425039 | D22: 104337 | F22: 125411 | G22: 172653 | H22: 22637 | I22: 13.8 | J22: 8 | L22: 2.6 | M22: 3.2
A23: 广东 | B23: 2023 | C23: 153001 | D23: 11021 | F23: 34287 | G23: 58201 | H23: 49492
A24: 广西 | B24: 2023 | C24: 324309 | D24: 20634 | F24: 5106 | G24: 42064 | H24: 256506 | I24: 0.9 | J24: 0.2 | L24: 0.3 | M24: 0.4
A25: 海南 | B25: 2023 | C25: 12837 | D25: 812 | H25: 12026
A26: 重庆 | B26: 2023 | C26: 137423 | D26: 23182 | F26: 40111 | G26: 70231 | H26: 3899
A27: 四川 | B27: 2023 | C27: 123086 | D27: 20943 | F27: 21222 | G27: 66159 | H27: 14762 | I27: 254.2 | J27: 37.7 | L27: 97.4 | M27: 119.1
A28: 贵州 | B28: 2023 | C28: 230473 | D28: 7250 | F28: 32191 | G28: 182809 | H28: 8223 | I28: 7.9 | J28: 4.3 | L28: 1.6 | M28: 2
A29: 云南 | B29: 2023 | C29: 287370 | D29: 42185 | F29: 90488 | G29: 117575 | H29: 37122 | I29: 36.7 | J29: 29.4 | L29: 3.3 | M29: 4
A30: 西藏 | B30: 2023 | C30: 44942 | D30: 4176 | E30: 3660 | F30: 33981 | G30: 2839 | H30: 285 | I30: 409.5 | J30: 165.3 | L30: 109.9 | M30: 134.3
A31: 陕西 | B31: 2023 | C31: 352245 | D31: 62026 | E31: 22249 | F31: 154011 | G31: 108145 | H31: 5814 | I31: 22.6 | J31: 9.4 | L31: 5.9 | M31: 7.2
A32: 甘肃 | B32: 2023 | C32: 269597 | D32: 130044 | E32: 727 | F32: 64448 | G32: 74361 | H32: 17 | I32: 627.6 | J32: 296.9 | L32: 148.8 | M32: 181.9
A33: 青海 | B33: 2023 | C33: 104677 | D33: 16301 | F33: 68207 | G33: 20169 | I33: 1876.7 | J33: 147.1 | L33: 345.9 | M33: 1383.6
A34: 宁夏 | B34: 2023 | C34: 84271 | D34: 23999 | F34: 5339 | G34: 54933 | I34: 21.4 | J34: 21.1 | L34: 0.2 | M34: 0.2
A35: 新疆 | B35: 2023 | C35: 136538 | D35: 32688 | F35: 66509 | G35: 29946 | H35: 7394 | I35: 333 | J35: 69.5 | L35: 118.6 | M35: 144.9
A36: 大兴安岭 | B36: 2023 | C36: 15385 | G36: 15385
A37: 全国 | B37: 2022 | C37: 4202790 | D37: 930860 | E37: 166099 | F37: 1057316 | G37: 1582935 | H37: 465579 | I37: 3214.1 | J37: 481.6 | L37: 722.3 | M37: 2010.2
A38: 北京 | B38: 2022 | C38: 3481 | D38: 3481 | H38: 1
A39: 天津 | B39: 2022 | C39: 5458 | F39: 5458
A40: 河北 | B40: 2022 | C40: 193707 | D40: 56685 | E40: 17762 | F40: 85294 | G40: 30880 | H40: 3086 | I40: 26.6 | J40: 2 | L40: 3.1 | M40: 21.5
...

Sheet PLANAbPiaSY
A1: Potential Land Area (acres/year) | B1: 2018 | C1: 2019 | D1: 2020 | E1: 2021 | F1: 2022 | G1: 2023 | H1: 2024 | I1: 2025 | J1: 2026 | K1: 2027 | L1: 2028 | M1: 2029 | N1: 2030 | O1: 2031 | P1: 2032 | Q1: 2033 | R1: 2034 | S1: 2035 | T1: 2036 | U1: 2037 | V1: 2038 | W1: 2039 | X1: 2040 | Y1: 2041 | Z1: 2042 | AA1: 2043 | AB1: 2044 | AC1: 2045 | AD1: 2046 | AE1: 2047 | AF1: 2048 | AG1: 2049 | AH1: 2050 | AI1: 2051 | AJ1: 2052 | AK1: 2053 | AL1: 2054 | AM1: 2055 | AN1: 2056 | AO1: 2057 | AP1: 2058 | AQ1: 2059 | AR1: 2060
A2: forest set asides | B2: ='set asides_2014to2018'!$A$29 -> 3362289 | C2: =$B2 -> 3362289 | D2: =$B2 -> 3362289 | E2: =$B2 -> 3362289 | F2: =$B2 -> 3362289 | G2: =$B2 -> 3362289 | H2: =$B2 -> 3362289 | I2: =$B2 -> 3362289 | J2: =$B2 -> 3362289 | ... AR2: =$B2 -> 3362289
A3: afforestation and reforestation | B3: =Calculation!$M$15 -> 11830791 | C3: =$B3 -> 11830791 | D3: =$B3 -> 11830791 | E3: =$B3 -> 11830791 | F3: =$B3 -> 11830791 | G3: =$B3 -> 11830791 | H3: =$B3 -> 11830791 | I3: =$B3 -> 11830791 | J3: =$B3 -> 11830791 | ... AR3: =$B3 -> 11830791
A4: improved forest management | B4: =Calculation!N15 -> 28145106 | C4: =$B4 -> 28145106 | D4: =$B4 -> 28145106 | E4: =$B4 -> 28145106 | F4: =$B4 -> 28145106 | G4: =$B4 -> 28145106 | H4: =$B4 -> 28145106 | I4: =$B4 -> 28145106 | J4: =$B4 -> 28145106 | ... AR4: =$B4 -> 28145106
A5: avoid deforestation | B5: 0 | C5: =$B5 -> 0 | D5: =$B5 -> 0 | E5: =$B5 -> 0 | F5: =$B5 -> 0 | G5: =$B5 -> 0 | H5: =$B5 -> 0 | I5: =$B5 -> 0 | J5: =$B5 -> 0 | ... AR5: =$B5 -> 0
A6: peatland restoration | B6: 0 | C6: =$B6 -> 0 | D6: =$B6 -> 0 | E6: =$B6 -> 0 | F6: =$B6 -> 0 | G6: =$B6 -> 0 | H6: =$B6 -> 0 | I6: =$B6 -> 0 | J6: =$B6 -> 0 | ... AR6: =$B6 -> 0
A7: forest restoration | B7: =Calculation!$O$15 -> 10479765 | C7: =$B7 -> 10479765 | D7: =$B7 -> 10479765 | E7: =$B7 -> 10479765 | F7: =$B7 -> 10479765 | G7: =$B7 -> 10479765 | H7: =$B7 -> 10479765 | I7: =$B7 -> 10479765 | J7: =$B7 -> 10479765 | ... AR7: =$B7 -> 10479765
