Workbook
Name cpi_2019_to_2012: [1]About!$A$98
Name cpi_2020_to_2012: [1]About!$A$100

Sheet About
A1: TCCpUCD Transmission Construction Cost per Unit Capacity Distance
A3: Sources: | B3: Capacity by Linetype
B4: China Electricity Council
B5: 中国电力工业统计资料汇编
B6: Compilation of China Power Sector Statistics
B7: 2015-2021
B8: Chapter 4 Table 4-11
B10: Infrastructure Investment
B11: China Electricity Council
B12: 中国电力工业统计资料汇编
B13: Compilation of China Power Sector Statistics
B14: 2015-2021
B15: Chapter 4 Table 4-1
A17: Note:
A18: We adjust 2021 dollars to 2012 dollars using the following conversion factor:
A19: 0.84730413
A20: See "cpi.xlsx" in the InputData folder for source information.

Sheet Capacity by Linetype
A1: Index | B1: Item | C1: Year | D1: 建设规模 | F1: 本年施工规模 | H1: 本年新开工规模 | J1: 累计新增能力 | L1: 本年新增能力 | O1: Item | P1: 电流 | Q1: 电压 | R1: 容量长度比 | S1: 建设规模 | U1: 本年施工规模 | W1: 本年新开工规模 | Y1: 累计新增能力 | AA1: 本年新增能力
D2: 容量 | E2: 长度 | F2: 容量 | G2: 长度 | H2: 容量 | I2: 长度 | J2: 容量 | K2: 长度 | L2: 容量 | M2: 长度 | S2: 容量 | T2: 长度 | U2: 容量 | V2: 长度 | W2: 容量 | X2: 长度 | Y2: 容量 | Z2: 长度 | AA2: 容量 | AB2: 长度
A3: 1 | B3: 全国 | C3: 2020 | E3: 176608 | G3: 150404 | I3: 61102 | K3: 67542 | M3: 62653 | O3: ±400千伏 | P3: 直流 | Q3: 400 | R3: =Y3/Z3 -> 0.58023477 | W3: 30712 | X3: 57829 | Y3: 46019 | Z3: 79311 | AA3: 34585 | AB3: 56679
A4: 2 | B4: 1、直流工程 | C4: 2020 | D4: 12600 | E4: 13148 | F4: 12600 | G4: 13147 | H4: 3800 | I4: 3890 | J4: 5200 | K4: 4444 | L4: 5200 | M4: 4444 | O4: ±500千伏 | P4: 直流 | Q4: 500 | R4: =S4/T4 -> 0.86128544 | S4: 7960 | T4: 9242 | U4: 6180 | V4: 5669 | W4: 2200 | X4: 1738 | Y4: 4920 | Z4: 5733 | AA4: 3040 | AB4: 2726
A5: 3 | B5: ±1100千伏 | C5: 2020 | E5: 1768 | G5: 1768 | O5: ±800千伏 | P5: 直流 | Q5: 800 | R5: =S5/T5 -> 1.0694016 | S5: 58600 | T5: 54797 | U5: 53500 | V5: 45979 | W5: 15800 | X5: 14147 | Y5: 18800 | Z5: 22255 | AA5: 13300 | AB5: 13448
A6: 4 | B6: ±800千伏 | C6: 2020 | D6: 11400 | E6: 10321 | F6: 11400 | G6: 10321 | H6: 3200 | I6: 3224 | J6: 4000 | K6: 3389 | L6: 4000 | M6: 3389 | O6: ±1100千伏 | P6: 直流 | Q6: 1100 | R6: =S6/T6 -> 0.53169734 | S6: 7800 | T6: 14670 | U6: 7800 | V6: 14670 | W6: 2400 | X6: 3325 | Y6: 3000 | Z6: 4882 | AA6: 1200 | AB6: 3325
A7: 5 | B7: ±660千伏 | C7: 2020 | O7: 110千伏（含66千伏） | P7: 交流 | Q7: 110 | R7: =S7/T7 -> 0.40852675 | S7: 162371 | T7: 397455 | U7: 136277 | V7: 349867 | W7: 53565 | X7: 142503 | Y7: 67057 | Z7: 181742 | AA7: 51476 | AB7: 141344
A8: 6 | B8: ±500千伏 | C8: 2020 | D8: 1200 | E8: 1059 | F8: 1200 | G8: 1059 | H8: 600 | I8: 666 | J8: 1200 | K8: 1055 | L8: 1200 | M8: 1055 | O8: 220千伏 | P8: 交流 | Q8: 220 | R8: =S8/T8 -> 0.49348482 | S8: 196896 | T8: 398991 | U8: 158637 | V8: 332070 | W8: 56126 | X8: 116833 | Y8: 80364 | Z8: 159030 | AA8: 55578 | AB8: 116982
A9: 7 | B9: ±400千伏 | C9: 2020 | O9: 330千伏 | P9: 交流 | Q9: 330 | R9: =S9/T9 -> 0.43640528 | S9: 16195 | T9: 37110 | U9: 14658 | V9: 34085 | W9: 6076 | X9: 11740 | Y9: 7089 | Z9: 18263 | AA9: 5238 | AB9: 13840
A10: 8 | B10: 2、交流工程（110千伏及以上） | C10: 2020 | D10: 104095 | E10: 163460 | F10: 87746 | G10: 137257 | H10: 35202 | I10: 57213 | J10: 34042 | K10: 63098 | L10: 31597 | M10: 58208 | O10: 500千伏 | P10: 交流 | Q10: 500 | R10: =S10/T10 -> 1.0290553 | S10: 165717 | T10: 161038 | U10: 150031 | V10: 142497 | W10: 52630 | X10: 52609 | Y10: 64080 | Z10: 63440 | AA10: 52380 | AB10: 49668
A11: 9 | B11: 1000千伏 | C11: 2020 | D11: 6000 | E11: 3411 | F11: 5400 | G11: 2806 | H11: 3300 | I11: 690 | J11: 1800 | K11: 1736 | L11: 1800 | M11: 1736 | O11: 750千伏 | P11: 交流 | Q11: 750 | R11: =S11/T11 -> 1.1160547 | S11: 41640 | T11: 37310 | U11: 39810 | V11: 37106 | W11: 12415 | X11: 11771 | Y11: 17035 | Z11: 13469 | AA11: 14175 | AB11: 12090
A12: 10 | B12: 750千伏 | C12: 2020 | D12: 6850 | E12: 6153 | F12: 6430 | G12: 6051 | H12: 1520 | I12: 2038 | J12: 2620 | K12: 1818 | L12: 2620 | M12: 1760 | O12: 1000千伏 | P12: 交流 | Q12: 1000 | R12: =S12/T12 -> 1.1443442 | S12: 32100 | T12: 28051 | U12: 30300 | V12: 25909 | W12: 13200 | X12: 8149 | Y12: 12900 | Z12: 11693 | AA12: 12300 | AB12: 11063
A13: 11 | B13: 500千伏 | C13: 2020 | D13: 25436 | E13: 22532 | F13: 21568 | G13: 17874 | H13: 8580 | I13: 8676 | J13: 8355 | K13: 8137 | L13: 7705 | M13: 7214 | O13: 35千伏 | P13: 交流 | Q13: 35 | R13: =S14*Q13^2+T14*Q13+U14 -> 0.18034631
A14: 12 | B14: 330千伏 | C14: 2020 | D14: 4330 | E14: 7010 | F14: 4114 | G14: 6982 | H14: 2008 | I14: 3004 | J14: 1674 | K14: 3014 | L14: 1458 | M14: 2815 | S14: -9.262524e-07 | T14: 0.001990639 | U14: 0.1118086
A15: 13 | B15: 220千伏 | C15: 2020 | D15: 31777 | E15: 61314 | F15: 25303 | G15: 48944 | H15: 10920 | I15: 20330 | J15: 10576 | K15: 21107 | L15: 9533 | M15: 18511
A16: 14 | B16: 110千伏（含66千伏） | C16: 2020 | D16: 29701 | E16: 63040 | F16: 24931 | G16: 54600 | H16: 8874 | I16: 22474 | J16: 9017 | K16: 27286 | L16: 8481 | M16: 26173
A17: 15 | B17: 全国 | C17: 2019 | E17: 177201 | G17: 160164 | I17: 58731 | K17: 71109 | M17: 57935
A18: 16 | B18: 1、直流工程 | C18: 2019 | D18: 9700 | E18: 11027 | F18: 9000 | G18: 9075 | H18: 1900 | I18: 1295 | J18: 3800 | K18: 3510 | L18: 2200
A19: 17 | B19: ±1100千伏 | C19: 2019 | D19: 1800 | E19: 4010 | F19: 1800 | G19: 4010 | J19: 1800 | K19: 1557 | L19: 1200
A20: 18 | B20: ±800千伏 | C20: 2019 | D20: 6000 | E20: 5945 | F20: 5000 | G20: 3992 | H20: 1600 | I20: 909 | J20: 1000 | K20: 1953
A21: 19 | B21: ±660千伏 | C21: 2019
A22: 20 | B22: ±500千伏 | C22: 2019 | D22: 900 | E22: 1073 | F22: 1200 | G22: 1074 | H22: 300 | I22: 386
A23: 21 | B23: ±400千伏 | C23: 2019 | D23: 1000 | F23: 1000 | J23: 1000 | L23: 1000
A24: 22 | B24: 2、交流工程（110千伏及以上） | C24: 2019 | D24: 95307 | E24: 166174 | F24: 88187 | G24: 151088 | H24: 34390 | I24: 57436 | J24: 37608 | K24: 67599 | L24: 31915 | M24: 57935
A25: 23 | B25: 1000千伏 | C25: 2019 | D25: 4800 | E25: 4316 | F25: 4800 | G25: 4316 | H25: 2100 | I25: 1128 | J25: 1500 | K25: 2100 | L25: 1500 | M25: 2100
A26: 24 | B26: 750千伏 | C26: 2019 | D26: 8840 | E26: 8350 | F26: 8630 | G26: 8350 | H26: 2615 | I26: 1386 | J26: 3455 | K26: 4566 | L26: 3245 | M26: 4406
A27: 25 | B27: 500千伏 | C27: 2019 | D27: 25333 | E27: 22478 | F27: 23603 | G27: 19409 | H27: 9493 | I27: 8563 | J27: 9995 | K27: 8095 | L27: 8645 | M27: 5595
A28: 26 | B28: 330千伏 | C28: 2019 | D28: 3705 | E28: 7328 | F28: 3489 | G28: 7300 | H28: 1188 | I28: 1810 | J28: 1623 | K28: 4245 | L28: 1263 | M28: 3989
A29: 27 | B29: 220千伏 | C29: 2019 | D29: 29630 | E29: 62940 | F29: 26136 | G29: 54343 | H29: 10163 | I29: 18694 | J29: 11775 | K29: 24284 | L29: 9161 | M29: 19822
A30: 28 | B30: 110千伏（含66千伏） | C30: 2019 | D30: 22999 | E30: 60762 | F30: 21528 | G30: 57370 | H30: 8831 | I30: 25855 | J30: 9260 | K30: 24310 | L30: 8100 | M30: 22023
A31: 29 | B31: 全国 | C31: 2018 | E31: 202586 | G31: 162751 | I31: 54031 | K31: 80787 | M31: 60298
A32: 30 | B32: 1、直流工程 | C32: 2018 | D32: 11500 | E32: 13919 | F32: 9400 | G32: 8637 | H32: 2500 | I32: 2253 | J32: 4700 | K32: 7118 | L32: 3200 | M32: 3325
A33: 31 | B33: ±1100千伏 | C33: 2018 | D33: 2400 | E33: 4010 | F33: 2400 | G33: 4010 | J33: 1200 | K33: 3325 | L33: 1200 | M33: 3325
A34: 32 | B34: ±800千伏 | C34: 2018 | D34: 8200 | E34: 8658 | F34: 6100 | G34: 3938 | H34: 1600 | I34: 1604 | J34: 3500 | K34: 3231 | L34: 2000
A35: 33 | B35: ±660千伏 | C35: 2018
A36: 34 | B36: ±500千伏 | C36: 2018 | D36: 900 | E36: 1251 | F36: 900 | G36: 689 | H36: 900 | I36: 649 | K36: 562
A37: 35 | B37: ±400千伏 | C37: 2018
A38: 36 | B38: 2、交流工程（110千伏及以上） | C38: 2018 | D38: 103483 | E38: 188668 | F38: 85931 | G38: 154115 | H38: 30872 | I38: 51778 | J38: 40730 | K38: 73669 | L38: 31024 | M38: 56973
A39: 37 | B39: 1000千伏 | C39: 2018 | D39: 2400 | E39: 2399 | F39: 2100 | G39: 2399 | H39: 1500 | I39: 2169 | J39: 900 | K39: 129 | L39: 900 | M39: 129
A40: 38 | B40: 750千伏 | C40: 2018 | D40: 6570 | E40: 6525 | F40: 5370 | G40: 6423 | H40: 1800 | I40: 2163 | J40: 2340 | K40: 1733 | L40: 1140 | M40: 1573
...

Sheet Power Infrastructure Investment
B1: 年份 | C1: 投资项目 | D1: Type | E1: Investment | H1: 投资项目 | I1: 本年完成投资
A2: 725 | B2: 2010 | C2: 其他费用 | D2: 其他电源 | E2: 61
A3: 422 | B3: 2010 | C3: 建筑工程 | D3: 燃油 | E3: 139 | H3: Sum of Investment | I3: Column Labels
A4: 723 | B4: 2010 | C4: 安装工程 | D4: 其他电源 | E4: 600 | H4: Row Labels | I4: 2010 | J4: 2011 | K4: 2012 | L4: 2013 | M4: 2014 | N4: 2015 | O4: 2016 | P4: 2017 | Q4: 2018 | R4: 2019 | S4: 2020 | T4: 2021 | U4: 2022 | V4: Grand Total
A5: 724 | B5: 2010 | C5: 设备工器具购置 | D5: 其他电源 | E5: 600 | H5: ±1100千伏 | O5: 320467 | P5: 1209686 | Q5: 1133628 | V5: 2663781
A6: 1325 | B6: 2010 | C6: 其他费用 | D6: 1000千伏 | E6: 1076 | H6: ±400千伏 | I6: 146229 | J6: 471993 | R6: 10000 | V6: 628222
A7: 721 | B7: 2010 | C7: 本年完成投资 | D7: 其他电源 | E7: 1261 | H7: ±500千伏 | I7: 814627 | J7: 464780 | K7: 508508 | L7: 450100 | M7: 419762 | N7: 674846 | O7: 224890 | P7: 92607 | Q7: 975208 | R7: 292105 | S7: 331380 | T7: 42202 | V7: 5291015
A8: 1204 | B8: 2010 | C8: 设备工器具购置 | D8: ±400千伏 | E8: 1646 | H8: ±660千伏 | I8: 713955 | J8: 210334 | V8: 924289
A9: 424 | B9: 2010 | C9: 设备工器具购置 | D9: 燃油 | E9: 2275 | H9: ±800千伏 | I9: 1160549 | J9: 1073559 | K9: 2263016 | L9: 3094331 | M9: 1257639 | N9: 1487310 | O9: 4402192 | P9: 7287037 | Q9: 3095849 | R9: 2192823 | S9: 4991902 | T9: 3759669 | V9: 36065876
A10: 421 | B10: 2010 | C10: 本年完成投资 | D10: 燃油 | E10: 2414 | H10: 1、直流工程 | I10: 2835360 | J10: 2220666 | K10: 2776524 | L10: 3544431 | M10: 1677401 | N10: 2162156 | O10: 4947549 | P10: 8589331 | Q10: 5204685 | R10: 2494928 | S10: 5323282 | T10: 3801871 | V10: 45578184
A11: 483 | B11: 2010 | C11: 安装工程 | D11: 其他火电 | E11: 13469 | H11: 1000千伏 | I11: 19700 | J11: 534551 | K11: 600237 | L11: 1598466 | M11: 2150971 | N11: 3153489 | O11: 3980497 | P11: 1675549 | Q11: 1837307 | R11: 1599741 | S11: 897924 | T11: 1515392 | V11: 19563824
A12: 1142 | B12: 2010 | C12: 建筑工程 | D12: ±500千伏 | E12: 16157 | H12: 110千伏(含66千伏) | I12: 6120373 | J12: 7900261 | K12: 8044052 | L12: 7114356 | M12: 6961974 | N12: 7137732 | O12: 7969259 | P12: 6476099 | Q12: 6494009 | R12: 6464522 | S12: 6228067 | T12: 7339507 | V12: 84250211
A13: 1202 | B13: 2010 | C13: 建筑工程 | D13: ±400千伏 | E13: 16506 | H13: 2、交流工程 | I13: 30549189 | J13: 32754506 | K13: 31803134 | L13: 34131122 | M13: 38252240 | N13: 42975798 | O13: 47867543 | P13: 42762421 | Q13: 46127730 | R13: 45298308 | S13: 41883339 | T13: 43834772 | V13: 478240102
A14: 363 | B14: 2010 | C14: 安装工程 | D14: 燃气 | E14: 16741 | H14: 220千伏 | I14: 10831615 | J14: 10858299 | K14: 8766223 | L14: 7921906 | M14: 9239712 | N14: 8873227 | O14: 6629426 | P14: 6275211 | Q14: 6612618 | R14: 6200893 | S14: 6380481 | T14: 7428260 | V14: 96017871
A15: 1082 | B15: 2010 | C15: 建筑工程 | D15: ±660千伏 | E15: 17255 | H15: 330千伏 | I15: 372515 | J15: 195155 | K15: 288121 | L15: 427820 | M15: 498628 | N15: 553664 | O15: 522861 | P15: 413040 | Q15: 419812 | R15: 353628 | S15: 455553 | T15: 486926 | V15: 4987723
A16: 665 | B16: 2010 | C16: 其他费用 | D16: 太阳能 | E16: 18462 | H16: 500千伏 | I16: 4441326 | J16: 3637078 | K16: 2632474 | L16: 4028707 | M16: 4559539 | N16: 4629443 | O16: 4277281 | P16: 4848558 | Q16: 4852910 | R16: 3596383 | S16: 4736655 | T16: 4960172 | V16: 51200526
A17: 1324 | B17: 2010 | C17: 设备工器具购置 | D17: 1000千伏 | E17: 18624 | H17: 750千伏 | I17: 1738513 | J17: 809047 | K17: 590970 | L17: 1200399 | M17: 900030 | N17: 1355619 | O17: 967071 | P17: 931099 | Q17: 927776 | R17: 981154 | S17: 999720 | T17: 895250 | V17: 12296648
A18: 1321 | B18: 2010 | C18: 本年完成投资 | D18: 1000千伏 | E18: 19700 | H18: 电网投资 | I18: 34481024 | J18: 36865661 | K18: 36611324 | L18: 38562130 | M18: 41193217 | N18: 46398109 | O18: 54314885 | P18: 53388841 | Q18: 53738169 | R18: 50117312 | S18: 48963113 | T18: 49162538 | V18: 543796323
A19: 1022 | B19: 2010 | C19: 建筑工程 | D19: ±800千伏 | E19: 20215 | H19: 电源投资 | I19: 39693629 | J19: 39274019 | K19: 37318220 | L19: 38719325 | M19: 36861339 | N19: 39362341 | O19: 34083732 | P19: 28998394 | Q19: 27871417 | R19: 32832718 | S19: 52924357 | T19: 58700921 | V19: 466640412
A20: 183 | B20: 2010 | C20: 安装工程 | D20: 其中抽水蓄能 | E20: 21059 | H20: 风电 | I20: 10375540 | J20: 9024369 | K20: 6073750 | L20: 6496073 | M20: 9154985 | N20: 12002448 | O20: 9266583 | P20: 6810730 | Q20: 6461876 | R20: 12443671 | S20: 26531184 | T20: 25894681 | V20: 140535890
... A24: 365 | B24: 2010 | C24: 其他费用 | D24: 燃气 | E24: 33290 | H24: 其他电网(含小型基建) | I24: 1096475 | J24: 1890489 | K24: 2031666 | L24: 886578 | M24: 1263574 | N24: 1260154 | O24: 1499792 | P24: 2037090 | Q24: 2405754 | R24: 2324077 | S24: 1756491 | T24: 1525894 | V24: 19978034
A25: 662 | B25: 2010 | C25: 建筑工程 | D25: 太阳能 | E25: 35254 | H25: 其他电源 | I25: 1261 | J25: 24847 | T25: 7659 | V25: 33767
A26: 1085 | B26: 2010 | C26: 其他费用 | D26: ±660千伏 | E26: 36289 | H26: 其他火电 | I26: 146270 | J26: 491750 | K26: 93803 | L26: 49821 | M26: 6215 | N26: 2324 | O26: 4484 | P26: 71336 | Q26: 5094 | R26: 232325 | S26: 416868 | T26: 397853 | V26: 1918143
A27: 362 | B27: 2010 | C27: 建筑工程 | D27: 燃气 | E27: 37158 | H27: 其中抽水蓄能 | I27: 533713 | J27: 651550 | K27: 675223 | L27: 829034 | M27: 902442 | N27: 1078834 | O27: 842336 | P27: 1419891 | Q27: 1624779 | R27: 1720815 | S27: 2380584 | T27: 2930658 | V27: 15589859
A28: 482 | B28: 2010 | C28: 建筑工程 | D28: 其他火电 | E28: 43763 | H28: 燃煤 | I28: 13814964 | J28: 9803615 | K28: 8291699 | L28: 8049324 | M28: 9583471 | N28: 10614335 | O28: 9731986 | P28: 7062506 | Q28: 6443114 | R28: 5062824 | S28: 4003760 | T28: 5524354 | V28: 97985952
A29: 1205 | B29: 2010 | C29: 其他费用 | D29: ±400千伏 | E29: 47446 | H29: 燃气 | I29: 297775 | J29: 728775 | K29: 1639250 | L29: 2062628 | M29: 1859270 | N29: 1016683 | O29: 1456302 | P29: 1443278 | Q29: 1415968 | R29: 1042352 | S29: 1153936 | T29: 1154590 | V29: 15270807
A30: 1505 | B30: 2010 | C30: 其他费用 | D30: 330千伏 | E30: 58875 | H30: 燃油 | I30: 2414 | J30: 802138 | V30: 804552
A31: 484 | B31: 2010 | C31: 设备工器具购置 | D31: 其他火电 | E31: 62987 | H31: 水电 | I31: 8191792 | J31: 9705297 | K31: 12387838 | L31: 12229379 | M31: 9425799 | N31: 7891269 | O31: 6171433 | P31: 6216184 | Q31: 7002561 | R31: 8387272 | S31: 10670182 | T31: 11726064 | V31: 110005070
A32: 902 | B32: 2010 | C32: 建筑工程 | D32: 1、直流工程 | E32: 70133 | H32: 送变电 | I32: 33384549 | J32: 34975172 | K32: 34579658 | L32: 37675553 | M32: 39929642 | N32: 45137954 | O32: 52815092 | P32: 51351751 | Q32: 51332415 | R32: 47793236 | S32: 47206622 | T32: 47636644 | V32: 523818288
A33: 1203 | B33: 2010 | C33: 安装工程 | D33: ±400千伏 | E33: 80631 | H33: 太阳能 | I33: 275997 | J33: 1546649 | K33: 987037 | L33: 3230193 | M33: 1504358 | N33: 2184479 | O33: 2412271 | P33: 2852208 | Q33: 2071185 | R33: 1840289 | S33: 6251356 | T33: 8607122 | V33: 33763144
A34: 1683 | B34: 2010 | C34: 安装工程 | D34: 其他电网(含小型基建) | E34: 100080 | H34: Grand Total | I34: 296951086 | J34: 302027097 | K34: 290761865 | L34: 306346811 | M34: 312432962 | N34: 342996809 | O34: 359339994 | P34: 337719355 | Q34: 331999245 | R34: 326392891 | S34: 385845862 | T34: 407661853 | V34: 4000475830
A35: 1145 | B35: 2010 | C35: 其他费用 | D35: ±500千伏 | E35: 111204
A36: 1503 | B36: 2010 | C36: 安装工程 | D36: 330千伏 | E36: 115076
A37: 1201 | B37: 2010 | C37: 本年完成投资 | D37: ±400千伏 | E37: 146229
A38: 481 | B38: 2010 | C38: 本年完成投资 | D38: 其他火电 | E38: 146270
A39: 1685 | B39: 2010 | C39: 其他费用 | D39: 其他电网(含小型基建) | E39: 148200
A40: 184 | B40: 2010 | C40: 设备工器具购置 | D40: 其中抽水蓄能 | E40: 154731
A41: 1504 | B41: 2010 | C41: 设备工器具购置 | D41: 330千伏 | E41: 169560
A42: 185 | B42: 2010 | C42: 其他费用 | D42: 其中抽水蓄能 | E42: 172575
A43: 182 | B43: 2010 | C43: 建筑工程 | D43: 其中抽水蓄能 | E43: 185350
...

Sheet Calculation
A1: Investment Completed (10000RMB) | B1: 当年完成投资额(百万元人民币) | C1: 2015 | D1: 2016 | E1: 2017 | F1: 2018 | G1: 2019 | H1: 2020 | I1: 2021
A2: DC Transmission | B2: 1、直流工程 | C2: =VLOOKUP($B2,'Power Infrastructure Investment'!$H$5:$T$33,C$1-2008,FALSE)/100 -> 21621.56 | D2: =VLOOKUP($B2,'Power Infrastructure Investment'!$H$5:$T$33,D$1-2008,FALSE)/100 -> 49475.49 | E2: =VLOOKUP($B2,'Power Infrastructure Investment'!$H$5:$T$33,E$1-2008,FALSE)/100 -> 85893.31 | F2: =VLOOKUP($B2,'Power Infrastructure Investment'!$H$5:$T$33,F$1-2008,FALSE)/100 -> 52046.85 | G2: =VLOOKUP($B2,'Power Infrastructure Investment'!$H$5:$T$33,G$1-2008,FALSE)/100 -> 24949.28 | H2: =VLOOKUP($B2,'Power Infrastructure Investment'!$H$5:$T$33,H$1-2008,FALSE)/100 -> 53232.82 | I2: =VLOOKUP($B2,'Power Infrastructure Investment'!$H$5:$T$33,I$1-2008,FALSE)/100 -> 38018.71
B3: ±400千伏 | C3: =VLOOKUP($B3,'Power Infrastructure Investment'!$H$5:$T$33,C$1-2008,FALSE)/100 -> 0 | D3: =VLOOKUP($B3,'Power Infrastructure Investment'!$H$5:$T$33,D$1-2008,FALSE)/100 -> 0 | E3: =VLOOKUP($B3,'Power Infrastructure Investment'!$H$5:$T$33,E$1-2008,FALSE)/100 -> 0 | F3: =VLOOKUP($B3,'Power Infrastructure Investment'!$H$5:$T$33,F$1-2008,FALSE)/100 -> 0 | G3: =VLOOKUP($B3,'Power Infrastructure Investment'!$H$5:$T$33,G$1-2008,FALSE)/100 -> 100 | H3: =VLOOKUP($B3,'Power Infrastructure Investment'!$H$5:$T$33,H$1-2008,FALSE)/100 -> 0 | I3: =VLOOKUP($B3,'Power Infrastructure Investment'!$H$5:$T$33,I$1-2008,FALSE)/100 -> 0
B4: ±500千伏 | C4: =VLOOKUP($B4,'Power Infrastructure Investment'!$H$5:$T$33,C$1-2008,FALSE)/100 -> 6748.46 | D4: =VLOOKUP($B4,'Power Infrastructure Investment'!$H$5:$T$33,D$1-2008,FALSE)/100 -> 2248.9 | E4: =VLOOKUP($B4,'Power Infrastructure Investment'!$H$5:$T$33,E$1-2008,FALSE)/100 -> 926.07 | F4: =VLOOKUP($B4,'Power Infrastructure Investment'!$H$5:$T$33,F$1-2008,FALSE)/100 -> 9752.08 | G4: =VLOOKUP($B4,'Power Infrastructure Investment'!$H$5:$T$33,G$1-2008,FALSE)/100 -> 2921.05 | H4: =VLOOKUP($B4,'Power Infrastructure Investment'!$H$5:$T$33,H$1-2008,FALSE)/100 -> 3313.8 | I4: =VLOOKUP($B4,'Power Infrastructure Investment'!$H$5:$T$33,I$1-2008,FALSE)/100 -> 422.02
B5: ±660千伏 | C5: =VLOOKUP($B5,'Power Infrastructure Investment'!$H$5:$T$33,C$1-2008,FALSE)/100 -> 0 | D5: =VLOOKUP($B5,'Power Infrastructure Investment'!$H$5:$T$33,D$1-2008,FALSE)/100 -> 0 | E5: =VLOOKUP($B5,'Power Infrastructure Investment'!$H$5:$T$33,E$1-2008,FALSE)/100 -> 0 | F5: =VLOOKUP($B5,'Power Infrastructure Investment'!$H$5:$T$33,F$1-2008,FALSE)/100 -> 0 | G5: =VLOOKUP($B5,'Power Infrastructure Investment'!$H$5:$T$33,G$1-2008,FALSE)/100 -> 0 | H5: =VLOOKUP($B5,'Power Infrastructure Investment'!$H$5:$T$33,H$1-2008,FALSE)/100 -> 0 | I5: =VLOOKUP($B5,'Power Infrastructure Investment'!$H$5:$T$33,I$1-2008,FALSE)/100 -> 0
B6: ±800千伏 | C6: =VLOOKUP($B6,'Power Infrastructure Investment'!$H$5:$T$33,C$1-2008,FALSE)/100 -> 14873.1 | D6: =VLOOKUP($B6,'Power Infrastructure Investment'!$H$5:$T$33,D$1-2008,FALSE)/100 -> 44021.92 | E6: =VLOOKUP($B6,'Power Infrastructure Investment'!$H$5:$T$33,E$1-2008,FALSE)/100 -> 72870.37 | F6: =VLOOKUP($B6,'Power Infrastructure Investment'!$H$5:$T$33,F$1-2008,FALSE)/100 -> 30958.49 | G6: =VLOOKUP($B6,'Power Infrastructure Investment'!$H$5:$T$33,G$1-2008,FALSE)/100 -> 21928.23 | H6: =VLOOKUP($B6,'Power Infrastructure Investment'!$H$5:$T$33,H$1-2008,FALSE)/100 -> 49919.02 | I6: =VLOOKUP($B6,'Power Infrastructure Investment'!$H$5:$T$33,I$1-2008,FALSE)/100 -> 37596.69
B7: ±1100千伏 | C7: =VLOOKUP($B7,'Power Infrastructure Investment'!$H$5:$T$33,C$1-2008,FALSE)/100 -> 0 | D7: =VLOOKUP($B7,'Power Infrastructure Investment'!$H$5:$T$33,D$1-2008,FALSE)/100 -> 3204.67 | E7: =VLOOKUP($B7,'Power Infrastructure Investment'!$H$5:$T$33,E$1-2008,FALSE)/100 -> 12096.86 | F7: =VLOOKUP($B7,'Power Infrastructure Investment'!$H$5:$T$33,F$1-2008,FALSE)/100 -> 11336.28 | G7: =VLOOKUP($B7,'Power Infrastructure Investment'!$H$5:$T$33,G$1-2008,FALSE)/100 -> 0 | H7: =VLOOKUP($B7,'Power Infrastructure Investment'!$H$5:$T$33,H$1-2008,FALSE)/100 -> 0 | I7: =VLOOKUP($B7,'Power Infrastructure Investment'!$H$5:$T$33,I$1-2008,FALSE)/100 -> 0
A8: AC Transmission | B8: 2、交流工程 | C8: =VLOOKUP($B8,'Power Infrastructure Investment'!$H$5:$T$33,C$1-2008,FALSE)/100 -> 429757.98 | D8: =VLOOKUP($B8,'Power Infrastructure Investment'!$H$5:$T$33,D$1-2008,FALSE)/100 -> 478675.43 | E8: =VLOOKUP($B8,'Power Infrastructure Investment'!$H$5:$T$33,E$1-2008,FALSE)/100 -> 427624.21 | F8: =VLOOKUP($B8,'Power Infrastructure Investment'!$H$5:$T$33,F$1-2008,FALSE)/100 -> 461277.3 | G8: =VLOOKUP($B8,'Power Infrastructure Investment'!$H$5:$T$33,G$1-2008,FALSE)/100 -> 452983.08 | H8: =VLOOKUP($B8,'Power Infrastructure Investment'!$H$5:$T$33,H$1-2008,FALSE)/100 -> 418833.39 | I8: =VLOOKUP($B8,'Power Infrastructure Investment'!$H$5:$T$33,I$1-2008,FALSE)/100 -> 438347.72
B9: 110千伏(含66千伏) | C9: =VLOOKUP($B9,'Power Infrastructure Investment'!$H$5:$T$33,C$1-2008,FALSE)/100 -> 71377.32 | D9: =VLOOKUP($B9,'Power Infrastructure Investment'!$H$5:$T$33,D$1-2008,FALSE)/100 -> 79692.59 | E9: =VLOOKUP($B9,'Power Infrastructure Investment'!$H$5:$T$33,E$1-2008,FALSE)/100 -> 64760.99 | F9: =VLOOKUP($B9,'Power Infrastructure Investment'!$H$5:$T$33,F$1-2008,FALSE)/100 -> 64940.09 | G9: =VLOOKUP($B9,'Power Infrastructure Investment'!$H$5:$T$33,G$1-2008,FALSE)/100 -> 64645.22 | H9: =VLOOKUP($B9,'Power Infrastructure Investment'!$H$5:$T$33,H$1-2008,FALSE)/100 -> 62280.67 | I9: =VLOOKUP($B9,'Power Infrastructure Investment'!$H$5:$T$33,I$1-2008,FALSE)/100 -> 73395.07
B10: 220千伏 | C10: =VLOOKUP($B10,'Power Infrastructure Investment'!$H$5:$T$33,C$1-2008,FALSE)/100 -> 88732.27 | D10: =VLOOKUP($B10,'Power Infrastructure Investment'!$H$5:$T$33,D$1-2008,FALSE)/100 -> 66294.26 | E10: =VLOOKUP($B10,'Power Infrastructure Investment'!$H$5:$T$33,E$1-2008,FALSE)/100 -> 62752.11 | F10: =VLOOKUP($B10,'Power Infrastructure Investment'!$H$5:$T$33,F$1-2008,FALSE)/100 -> 66126.18 | G10: =VLOOKUP($B10,'Power Infrastructure Investment'!$H$5:$T$33,G$1-2008,FALSE)/100 -> 62008.93 | H10: =VLOOKUP($B10,'Power Infrastructure Investment'!$H$5:$T$33,H$1-2008,FALSE)/100 -> 63804.81 | I10: =VLOOKUP($B10,'Power Infrastructure Investment'!$H$5:$T$33,I$1-2008,FALSE)/100 -> 74282.6
B11: 330千伏 | C11: =VLOOKUP($B11,'Power Infrastructure Investment'!$H$5:$T$33,C$1-2008,FALSE)/100 -> 5536.64 | D11: =VLOOKUP($B11,'Power Infrastructure Investment'!$H$5:$T$33,D$1-2008,FALSE)/100 -> 5228.61 | E11: =VLOOKUP($B11,'Power Infrastructure Investment'!$H$5:$T$33,E$1-2008,FALSE)/100 -> 4130.4 | F11: =VLOOKUP($B11,'Power Infrastructure Investment'!$H$5:$T$33,F$1-2008,FALSE)/100 -> 4198.12 | G11: =VLOOKUP($B11,'Power Infrastructure Investment'!$H$5:$T$33,G$1-2008,FALSE)/100 -> 3536.28 | H11: =VLOOKUP($B11,'Power Infrastructure Investment'!$H$5:$T$33,H$1-2008,FALSE)/100 -> 4555.53 | I11: =VLOOKUP($B11,'Power Infrastructure Investment'!$H$5:$T$33,I$1-2008,FALSE)/100 -> 4869.26
B12: 500千伏 | C12: =VLOOKUP($B12,'Power Infrastructure Investment'!$H$5:$T$33,C$1-2008,FALSE)/100 -> 46294.43 | D12: =VLOOKUP($B12,'Power Infrastructure Investment'!$H$5:$T$33,D$1-2008,FALSE)/100 -> 42772.81 | E12: =VLOOKUP($B12,'Power Infrastructure Investment'!$H$5:$T$33,E$1-2008,FALSE)/100 -> 48485.58 | F12: =VLOOKUP($B12,'Power Infrastructure Investment'!$H$5:$T$33,F$1-2008,FALSE)/100 -> 48529.1 | G12: =VLOOKUP($B12,'Power Infrastructure Investment'!$H$5:$T$33,G$1-2008,FALSE)/100 -> 35963.83 | H12: =VLOOKUP($B12,'Power Infrastructure Investment'!$H$5:$T$33,H$1-2008,FALSE)/100 -> 47366.55 | I12: =VLOOKUP($B12,'Power Infrastructure Investment'!$H$5:$T$33,I$1-2008,FALSE)/100 -> 49601.72
B13: 750千伏 | C13: =VLOOKUP($B13,'Power Infrastructure Investment'!$H$5:$T$33,C$1-2008,FALSE)/100 -> 13556.19 | D13: =VLOOKUP($B13,'Power Infrastructure Investment'!$H$5:$T$33,D$1-2008,FALSE)/100 -> 9670.71 | E13: =VLOOKUP($B13,'Power Infrastructure Investment'!$H$5:$T$33,E$1-2008,FALSE)/100 -> 9310.99 | F13: =VLOOKUP($B13,'Power Infrastructure Investment'!$H$5:$T$33,F$1-2008,FALSE)/100 -> 9277.76 | G13: =VLOOKUP($B13,'Power Infrastructure Investment'!$H$5:$T$33,G$1-2008,FALSE)/100 -> 9811.54 | H13: =VLOOKUP($B13,'Power Infrastructure Investment'!$H$5:$T$33,H$1-2008,FALSE)/100 -> 9997.2 | I13: =VLOOKUP($B13,'Power Infrastructure Investment'!$H$5:$T$33,I$1-2008,FALSE)/100 -> 8952.5
B14: 1000千伏 | C14: =VLOOKUP($B14,'Power Infrastructure Investment'!$H$5:$T$33,C$1-2008,FALSE)/100 -> 31534.89 | D14: =VLOOKUP($B14,'Power Infrastructure Investment'!$H$5:$T$33,D$1-2008,FALSE)/100 -> 39804.97 | E14: =VLOOKUP($B14,'Power Infrastructure Investment'!$H$5:$T$33,E$1-2008,FALSE)/100 -> 16755.49 | F14: =VLOOKUP($B14,'Power Infrastructure Investment'!$H$5:$T$33,F$1-2008,FALSE)/100 -> 18373.07 | G14: =VLOOKUP($B14,'Power Infrastructure Investment'!$H$5:$T$33,G$1-2008,FALSE)/100 -> 15997.41 | H14: =VLOOKUP($B14,'Power Infrastructure Investment'!$H$5:$T$33,H$1-2008,FALSE)/100 -> 8979.24 | I14: =VLOOKUP($B14,'Power Infrastructure Investment'!$H$5:$T$33,I$1-2008,FALSE)/100 -> 15153.92
A15: Total | B15: 电网投资 | C15: =VLOOKUP($B15,'Power Infrastructure Investment'!$H$5:$T$33,C$1-2008,FALSE)/100 -> 463981.09 | D15: =VLOOKUP($B15,'Power Infrastructure Investment'!$H$5:$T$33,D$1-2008,FALSE)/100 -> 543148.85 | E15: =VLOOKUP($B15,'Power Infrastructure Investment'!$H$5:$T$33,E$1-2008,FALSE)/100 -> 533888.41 | F15: =VLOOKUP($B15,'Power Infrastructure Investment'!$H$5:$T$33,F$1-2008,FALSE)/100 -> 537381.69 | G15: =VLOOKUP($B15,'Power Infrastructure Investment'!$H$5:$T$33,G$1-2008,FALSE)/100 -> 501173.12 | H15: =VLOOKUP($B15,'Power Infrastructure Investment'!$H$5:$T$33,H$1-2008,FALSE)/100 -> 489631.13 | I15: =VLOOKUP($B15,'Power Infrastructure Investment'!$H$5:$T$33,I$1-2008,FALSE)/100 -> 491625.38
A16: Total USD Investment | B16: 电网投资（million 2012USD） | C16: =C15*'Exchange Rate'!U2 -> 71212.074 | D16: =D15*'Exchange Rate'!V2 -> 82205.864 | E16: =E15*'Exchange Rate'!W2 -> 77522.99 | F16: =F15*'Exchange Rate'!X2 -> 75391.711 | G16: =G15*'Exchange Rate'!Y2 -> 69418.121 | H16: =H15*'Exchange Rate'!Z2 -> 67398.057 | I16: =I15*'Exchange Rate'!AA2 -> 64832.098
A18: Added Capacity (MW*mile) | B18: 本年新增能力（MW*mile） | C18: 2015 | D18: 2016 | E18: 2017 | F18: 2018 | G18: 2019 | H18: 2020 | I18: 2021
A19: DC Transmission | B19: ='Capacity by Linetype'!B74 -> 1、直流工程 | C19: =SUMIFS('Capacity by Linetype'!$L$3:$L$99,'Capacity by Linetype'!$B$3:$B$99,$B19,'Capacity by Linetype'!$C$3:$C$99,C$18)*10/1.609344 -> 1553.428 | D19: =SUMIFS('Capacity by Linetype'!$L$3:$L$99,'Capacity by Linetype'!$B$3:$B$99,$B19,'Capacity by Linetype'!$C$3:$C$99,D$18)*10/1.609344 -> 20132.427 | E19: =SUMIFS('Capacity by Linetype'!$L$3:$L$99,'Capacity by Linetype'!$B$3:$B$99,$B19,'Capacity by Linetype'!$C$3:$C$99,E$18)*10/1.609344 -> 49088.324 | F19: =SUMIFS('Capacity by Linetype'!$L$3:$L$99,'Capacity by Linetype'!$B$3:$B$99,$B19,'Capacity by Linetype'!$C$3:$C$99,F$18)*10/1.609344 -> 19883.878 | G19: =SUMIFS('Capacity by Linetype'!$L$3:$L$99,'Capacity by Linetype'!$B$3:$B$99,$B19,'Capacity by Linetype'!$C$3:$C$99,G$18)*10/1.609344 -> 13670.166 | H19: =SUMIFS('Capacity by Linetype'!$L$3:$L$99,'Capacity by Linetype'!$B$3:$B$99,$B19,'Capacity by Linetype'!$C$3:$C$99,H$18)*10/1.609344 -> 32311.302 | I19: =SUMIFS('Capacity by Linetype'!$L$3:$L$99,'Capacity by Linetype'!$B$3:$B$99,$B19,'Capacity by Linetype'!$C$3:$C$99,I$18)*10/1.609344 -> 19883.878
B20: ±400千伏 | C20: =SUMIFS('Capacity by Linetype'!$L$3:$L$99,'Capacity by Linetype'!$B$3:$B$99,$B20,'Capacity by Linetype'!$C$3:$C$99,C$18)*10/1.609344 -> 0 | D20: =SUMIFS('Capacity by Linetype'!$L$3:$L$99,'Capacity by Linetype'!$B$3:$B$99,$B20,'Capacity by Linetype'!$C$3:$C$99,D$18)*10/1.609344 -> 214901.23 | E20: =SUMIFS('Capacity by Linetype'!$L$3:$L$99,'Capacity by Linetype'!$B$3:$B$99,$B20,'Capacity by Linetype'!$C$3:$C$99,E$18)*10/1.609344 -> 0 | F20: =SUMIFS('Capacity by Linetype'!$L$3:$L$99,'Capacity by Linetype'!$B$3:$B$99,$B20,'Capacity by Linetype'!$C$3:$C$99,F$18)*10/1.609344 -> 0 | G20: =SUMIFS('Capacity by Linetype'!$L$3:$L$99,'Capacity by Linetype'!$B$3:$B$99,$B20,'Capacity by Linetype'!$C$3:$C$99,G$18)*10/1.609344 -> 6213.7119 | H20: =SUMIFS('Capacity by Linetype'!$L$3:$L$99,'Capacity by Linetype'!$B$3:$B$99,$B20,'Capacity by Linetype'!$C$3:$C$99,H$18)*10/1.609344 -> 0 | I20: =SUMIFS('Capacity by Linetype'!$L$3:$L$99,'Capacity by Linetype'!$B$3:$B$99,$B20,'Capacity by Linetype'!$C$3:$C$99,I$18)*10/1.609344 -> 0
B21: ±500千伏 | C21: =SUMIFS('Capacity by Linetype'!$L$3:$L$99,'Capacity by Linetype'!$B$3:$B$99,$B21,'Capacity by Linetype'!$C$3:$C$99,C$18)*10/1.609344 -> 0 | D21: =SUMIFS('Capacity by Linetype'!$L$3:$L$99,'Capacity by Linetype'!$B$3:$B$99,$B21,'Capacity by Linetype'!$C$3:$C$99,D$18)*10/1.609344 -> 10190.488 | E21: =SUMIFS('Capacity by Linetype'!$L$3:$L$99,'Capacity by Linetype'!$B$3:$B$99,$B21,'Capacity by Linetype'!$C$3:$C$99,E$18)*10/1.609344 -> 1242.7424 | F21: =SUMIFS('Capacity by Linetype'!$L$3:$L$99,'Capacity by Linetype'!$B$3:$B$99,$B21,'Capacity by Linetype'!$C$3:$C$99,F$18)*10/1.609344 -> 0 | G21: =SUMIFS('Capacity by Linetype'!$L$3:$L$99,'Capacity by Linetype'!$B$3:$B$99,$B21,'Capacity by Linetype'!$C$3:$C$99,G$18)*10/1.609344 -> 0 | H21: =SUMIFS('Capacity by Linetype'!$L$3:$L$99,'Capacity by Linetype'!$B$3:$B$99,$B21,'Capacity by Linetype'!$C$3:$C$99,H$18)*10/1.609344 -> 7456.4543 | I21: =SUMIFS('Capacity by Linetype'!$L$3:$L$99,'Capacity by Linetype'!$B$3:$B$99,$B21,'Capacity by Linetype'!$C$3:$C$99,I$18)*10/1.609344 -> 0
B22: ±660千伏 | C22: =SUMIFS('Capacity by Linetype'!$L$3:$L$99,'Capacity by Linetype'!$B$3:$B$99,$B22,'Capacity by Linetype'!$C$3:$C$99,C$18)*10/1.609344 -> 0 | D22: =SUMIFS('Capacity by Linetype'!$L$3:$L$99,'Capacity by Linetype'!$B$3:$B$99,$B22,'Capacity by Linetype'!$C$3:$C$99,D$18)*10/1.609344 -> 0 | E22: =SUMIFS('Capacity by Linetype'!$L$3:$L$99,'Capacity by Linetype'!$B$3:$B$99,$B22,'Capacity by Linetype'!$C$3:$C$99,E$18)*10/1.609344 -> 0 | F22: =SUMIFS('Capacity by Linetype'!$L$3:$L$99,'Capacity by Linetype'!$B$3:$B$99,$B22,'Capacity by Linetype'!$C$3:$C$99,F$18)*10/1.609344 -> 0 | G22: =SUMIFS('Capacity by Linetype'!$L$3:$L$99,'Capacity by Linetype'!$B$3:$B$99,$B22,'Capacity by Linetype'!$C$3:$C$99,G$18)*10/1.609344 -> 0 | H22: =SUMIFS('Capacity by Linetype'!$L$3:$L$99,'Capacity by Linetype'!$B$3:$B$99,$B22,'Capacity by Linetype'!$C$3:$C$99,H$18)*10/1.609344 -> 0 | I22: =SUMIFS('Capacity by Linetype'!$L$3:$L$99,'Capacity by Linetype'!$B$3:$B$99,$B22,'Capacity by Linetype'!$C$3:$C$99,I$18)*10/1.609344 -> 0
B23: ±800千伏 | C23: =SUMIFS('Capacity by Linetype'!$L$3:$L$99,'Capacity by Linetype'!$B$3:$B$99,$B23,'Capacity by Linetype'!$C$3:$C$99,C$18)*10/1.609344 -> 1553.428 | D23: =SUMIFS('Capacity by Linetype'!$L$3:$L$99,'Capacity by Linetype'!$B$3:$B$99,$B23,'Capacity by Linetype'!$C$3:$C$99,D$18)*10/1.609344 -> 9941.9391 | E23: =SUMIFS('Capacity by Linetype'!$L$3:$L$99,'Capacity by Linetype'!$B$3:$B$99,$B23,'Capacity by Linetype'!$C$3:$C$99,E$18)*10/1.609344 -> 47845.582 | F23: =SUMIFS('Capacity by Linetype'!$L$3:$L$99,'Capacity by Linetype'!$B$3:$B$99,$B23,'Capacity by Linetype'!$C$3:$C$99,F$18)*10/1.609344 -> 12427.424 | G23: =SUMIFS('Capacity by Linetype'!$L$3:$L$99,'Capacity by Linetype'!$B$3:$B$99,$B23,'Capacity by Linetype'!$C$3:$C$99,G$18)*10/1.609344 -> 0 | H23: =SUMIFS('Capacity by Linetype'!$L$3:$L$99,'Capacity by Linetype'!$B$3:$B$99,$B23,'Capacity by Linetype'!$C$3:$C$99,H$18)*10/1.609344 -> 24854.848 | I23: =SUMIFS('Capacity by Linetype'!$L$3:$L$99,'Capacity by Linetype'!$B$3:$B$99,$B23,'Capacity by Linetype'!$C$3:$C$99,I$18)*10/1.609344 -> 19883.878
B24: ±1100千伏 | C24: =SUMIFS('Capacity by Linetype'!$L$3:$L$99,'Capacity by Linetype'!$B$3:$B$99,$B24,'Capacity by Linetype'!$C$3:$C$99,C$18)*10/1.609344 -> 0 | D24: =SUMIFS('Capacity by Linetype'!$L$3:$L$99,'Capacity by Linetype'!$B$3:$B$99,$B24,'Capacity by Linetype'!$C$3:$C$99,D$18)*10/1.609344 -> 0 | E24: =SUMIFS('Capacity by Linetype'!$L$3:$L$99,'Capacity by Linetype'!$B$3:$B$99,$B24,'Capacity by Linetype'!$C$3:$C$99,E$18)*10/1.609344 -> 0 | F24: =SUMIFS('Capacity by Linetype'!$L$3:$L$99,'Capacity by Linetype'!$B$3:$B$99,$B24,'Capacity by Linetype'!$C$3:$C$99,F$18)*10/1.609344 -> 7456.4543 | G24: =SUMIFS('Capacity by Linetype'!$L$3:$L$99,'Capacity by Linetype'!$B$3:$B$99,$B24,'Capacity by Linetype'!$C$3:$C$99,G$18)*10/1.609344 -> 7456.4543 | H24: =SUMIFS('Capacity by Linetype'!$L$3:$L$99,'Capacity by Linetype'!$B$3:$B$99,$B24,'Capacity by Linetype'!$C$3:$C$99,H$18)*10/1.609344 -> 0 | I24: =SUMIFS('Capacity by Linetype'!$L$3:$L$99,'Capacity by Linetype'!$B$3:$B$99,$B24,'Capacity by Linetype'!$C$3:$C$99,I$18)*10/1.609344 -> 0
A25: AC Transmission | B25: ='Capacity by Linetype'!B79 -> 2、交流工程（110千伏及以上） | C25: =SUMIFS('Capacity by Linetype'!$L$3:$L$99,'Capacity by Linetype'!$B$3:$B$99,$B25,'Capacity by Linetype'!$C$3:$C$99,C$18)*10/1.609344 -> 182881.97 | D25: =SUMIFS('Capacity by Linetype'!$L$3:$L$99,'Capacity by Linetype'!$B$3:$B$99,$B25,'Capacity by Linetype'!$C$3:$C$99,D$18)*10/1.609344 -> 214901.23 | E25: =SUMIFS('Capacity by Linetype'!$L$3:$L$99,'Capacity by Linetype'!$B$3:$B$99,$B25,'Capacity by Linetype'!$C$3:$C$99,E$18)*10/1.609344 -> 202535.94 | F25: =SUMIFS('Capacity by Linetype'!$L$3:$L$99,'Capacity by Linetype'!$B$3:$B$99,$B25,'Capacity by Linetype'!$C$3:$C$99,F$18)*10/1.609344 -> 192774.2 | G25: =SUMIFS('Capacity by Linetype'!$L$3:$L$99,'Capacity by Linetype'!$B$3:$B$99,$B25,'Capacity by Linetype'!$C$3:$C$99,G$18)*10/1.609344 -> 198310.62 | H25: =SUMIFS('Capacity by Linetype'!$L$3:$L$99,'Capacity by Linetype'!$B$3:$B$99,$B25,'Capacity by Linetype'!$C$3:$C$99,H$18)*10/1.609344 -> 196334.66 | I25: =SUMIFS('Capacity by Linetype'!$L$3:$L$99,'Capacity by Linetype'!$B$3:$B$99,$B25,'Capacity by Linetype'!$C$3:$C$99,I$18)*10/1.609344 -> 209315.1
B26: ='Capacity by Linetype'!B72 -> 110千伏（含66千伏） | C26: =SUMIFS('Capacity by Linetype'!$L$3:$L$99,'Capacity by Linetype'!$B$3:$B$99,$B26,'Capacity by Linetype'!$C$3:$C$99,C$18)*10/1.609344 -> 46789.251 | D26: =SUMIFS('Capacity by Linetype'!$L$3:$L$99,'Capacity by Linetype'!$B$3:$B$99,$B26,'Capacity by Linetype'!$C$3:$C$99,D$18)*10/1.609344 -> 63323.938 | E26: =SUMIFS('Capacity by Linetype'!$L$3:$L$99,'Capacity by Linetype'!$B$3:$B$99,$B26,'Capacity by Linetype'!$C$3:$C$99,E$18)*10/1.609344 -> 51971.487 | F26: =SUMIFS('Capacity by Linetype'!$L$3:$L$99,'Capacity by Linetype'!$B$3:$B$99,$B26,'Capacity by Linetype'!$C$3:$C$99,F$18)*10/1.609344 -> 54742.802 | G26: =SUMIFS('Capacity by Linetype'!$L$3:$L$99,'Capacity by Linetype'!$B$3:$B$99,$B26,'Capacity by Linetype'!$C$3:$C$99,G$18)*10/1.609344 -> 50331.067 | H26: =SUMIFS('Capacity by Linetype'!$L$3:$L$99,'Capacity by Linetype'!$B$3:$B$99,$B26,'Capacity by Linetype'!$C$3:$C$99,H$18)*10/1.609344 -> 52698.491 | I26: =SUMIFS('Capacity by Linetype'!$L$3:$L$99,'Capacity by Linetype'!$B$3:$B$99,$B26,'Capacity by Linetype'!$C$3:$C$99,I$18)*10/1.609344 -> 58334.328
B27: 220千伏 | C27: =SUMIFS('Capacity by Linetype'!$L$3:$L$99,'Capacity by Linetype'!$B$3:$B$99,$B27,'Capacity by Linetype'!$C$3:$C$99,C$18)*10/1.609344 -> 54742.802 | D27: =SUMIFS('Capacity by Linetype'!$L$3:$L$99,'Capacity by Linetype'!$B$3:$B$99,$B27,'Capacity by Linetype'!$C$3:$C$99,D$18)*10/1.609344 -> 57408.484 | E27: =SUMIFS('Capacity by Linetype'!$L$3:$L$99,'Capacity by Linetype'!$B$3:$B$99,$B27,'Capacity by Linetype'!$C$3:$C$99,E$18)*10/1.609344 -> 64827.656 | F27: =SUMIFS('Capacity by Linetype'!$L$3:$L$99,'Capacity by Linetype'!$B$3:$B$99,$B27,'Capacity by Linetype'!$C$3:$C$99,F$18)*10/1.609344 -> 52207.608 | G27: =SUMIFS('Capacity by Linetype'!$L$3:$L$99,'Capacity by Linetype'!$B$3:$B$99,$B27,'Capacity by Linetype'!$C$3:$C$99,G$18)*10/1.609344 -> 56923.815 | H27: =SUMIFS('Capacity by Linetype'!$L$3:$L$99,'Capacity by Linetype'!$B$3:$B$99,$B27,'Capacity by Linetype'!$C$3:$C$99,H$18)*10/1.609344 -> 59235.316 | I27: =SUMIFS('Capacity by Linetype'!$L$3:$L$99,'Capacity by Linetype'!$B$3:$B$99,$B27,'Capacity by Linetype'!$C$3:$C$99,I$18)*10/1.609344 -> 60732.82
B28: 330千伏 | C28: =SUMIFS('Capacity by Linetype'!$L$3:$L$99,'Capacity by Linetype'!$B$3:$B$99,$B28,'Capacity by Linetype'!$C$3:$C$99,C$18)*10/1.609344 -> 3989.2031 | D28: =SUMIFS('Capacity by Linetype'!$L$3:$L$99,'Capacity by Linetype'!$B$3:$B$99,$B28,'Capacity by Linetype'!$C$3:$C$99,D$18)*10/1.609344 -> 2982.5817 | E28: =SUMIFS('Capacity by Linetype'!$L$3:$L$99,'Capacity by Linetype'!$B$3:$B$99,$B28,'Capacity by Linetype'!$C$3:$C$99,E$18)*10/1.609344 -> 4865.3364 | F28: =SUMIFS('Capacity by Linetype'!$L$3:$L$99,'Capacity by Linetype'!$B$3:$B$99,$B28,'Capacity by Linetype'!$C$3:$C$99,F$18)*10/1.609344 -> 3802.7917 | G28: =SUMIFS('Capacity by Linetype'!$L$3:$L$99,'Capacity by Linetype'!$B$3:$B$99,$B28,'Capacity by Linetype'!$C$3:$C$99,G$18)*10/1.609344 -> 7847.9182 | H28: =SUMIFS('Capacity by Linetype'!$L$3:$L$99,'Capacity by Linetype'!$B$3:$B$99,$B28,'Capacity by Linetype'!$C$3:$C$99,H$18)*10/1.609344 -> 9059.592 | I28: =SUMIFS('Capacity by Linetype'!$L$3:$L$99,'Capacity by Linetype'!$B$3:$B$99,$B28,'Capacity by Linetype'!$C$3:$C$99,I$18)*10/1.609344 -> 3579.0981
B29: 500千伏 | C29: =SUMIFS('Capacity by Linetype'!$L$3:$L$99,'Capacity by Linetype'!$B$3:$B$99,$B29,'Capacity by Linetype'!$C$3:$C$99,C$18)*10/1.609344 -> 55177.762 | D29: =SUMIFS('Capacity by Linetype'!$L$3:$L$99,'Capacity by Linetype'!$B$3:$B$99,$B29,'Capacity by Linetype'!$C$3:$C$99,D$18)*10/1.609344 -> 47938.787 | E29: =SUMIFS('Capacity by Linetype'!$L$3:$L$99,'Capacity by Linetype'!$B$3:$B$99,$B29,'Capacity by Linetype'!$C$3:$C$99,E$18)*10/1.609344 -> 51418.466 | F29: =SUMIFS('Capacity by Linetype'!$L$3:$L$99,'Capacity by Linetype'!$B$3:$B$99,$B29,'Capacity by Linetype'!$C$3:$C$99,F$18)*10/1.609344 -> 69345.025 | G29: =SUMIFS('Capacity by Linetype'!$L$3:$L$99,'Capacity by Linetype'!$B$3:$B$99,$B29,'Capacity by Linetype'!$C$3:$C$99,G$18)*10/1.609344 -> 53717.54 | H29: =SUMIFS('Capacity by Linetype'!$L$3:$L$99,'Capacity by Linetype'!$B$3:$B$99,$B29,'Capacity by Linetype'!$C$3:$C$99,H$18)*10/1.609344 -> 47876.65 | I29: =SUMIFS('Capacity by Linetype'!$L$3:$L$99,'Capacity by Linetype'!$B$3:$B$99,$B29,'Capacity by Linetype'!$C$3:$C$99,I$18)*10/1.609344 -> 64299.491
B30: 750千伏 | C30: =SUMIFS('Capacity by Linetype'!$L$3:$L$99,'Capacity by Linetype'!$B$3:$B$99,$B30,'Capacity by Linetype'!$C$3:$C$99,C$18)*10/1.609344 -> 22182.952 | D30: =SUMIFS('Capacity by Linetype'!$L$3:$L$99,'Capacity by Linetype'!$B$3:$B$99,$B30,'Capacity by Linetype'!$C$3:$C$99,D$18)*10/1.609344 -> 11557.504 | E30: =SUMIFS('Capacity by Linetype'!$L$3:$L$99,'Capacity by Linetype'!$B$3:$B$99,$B30,'Capacity by Linetype'!$C$3:$C$99,E$18)*10/1.609344 -> 10811.859 | F30: =SUMIFS('Capacity by Linetype'!$L$3:$L$99,'Capacity by Linetype'!$B$3:$B$99,$B30,'Capacity by Linetype'!$C$3:$C$99,F$18)*10/1.609344 -> 7083.6316 | G30: =SUMIFS('Capacity by Linetype'!$L$3:$L$99,'Capacity by Linetype'!$B$3:$B$99,$B30,'Capacity by Linetype'!$C$3:$C$99,G$18)*10/1.609344 -> 20163.495 | H30: =SUMIFS('Capacity by Linetype'!$L$3:$L$99,'Capacity by Linetype'!$B$3:$B$99,$B30,'Capacity by Linetype'!$C$3:$C$99,H$18)*10/1.609344 -> 16279.925 | I30: =SUMIFS('Capacity by Linetype'!$L$3:$L$99,'Capacity by Linetype'!$B$3:$B$99,$B30,'Capacity by Linetype'!$C$3:$C$99,I$18)*10/1.609344 -> 11184.681
B31: 1000千伏 | C31: =SUMIFS('Capacity by Linetype'!$L$3:$L$99,'Capacity by Linetype'!$B$3:$B$99,$B31,'Capacity by Linetype'!$C$3:$C$99,C$18)*10/1.609344 -> 0 | D31: =SUMIFS('Capacity by Linetype'!$L$3:$L$99,'Capacity by Linetype'!$B$3:$B$99,$B31,'Capacity by Linetype'!$C$3:$C$99,D$18)*10/1.609344 -> 31689.931 | E31: =SUMIFS('Capacity by Linetype'!$L$3:$L$99,'Capacity by Linetype'!$B$3:$B$99,$B31,'Capacity by Linetype'!$C$3:$C$99,E$18)*10/1.609344 -> 18641.136 | F31: =SUMIFS('Capacity by Linetype'!$L$3:$L$99,'Capacity by Linetype'!$B$3:$B$99,$B31,'Capacity by Linetype'!$C$3:$C$99,F$18)*10/1.609344 -> 5592.3407 | G31: =SUMIFS('Capacity by Linetype'!$L$3:$L$99,'Capacity by Linetype'!$B$3:$B$99,$B31,'Capacity by Linetype'!$C$3:$C$99,G$18)*10/1.609344 -> 9320.5679 | H31: =SUMIFS('Capacity by Linetype'!$L$3:$L$99,'Capacity by Linetype'!$B$3:$B$99,$B31,'Capacity by Linetype'!$C$3:$C$99,H$18)*10/1.609344 -> 11184.681 | I31: =SUMIFS('Capacity by Linetype'!$L$3:$L$99,'Capacity by Linetype'!$B$3:$B$99,$B31,'Capacity by Linetype'!$C$3:$C$99,I$18)*10/1.609344 -> 11184.681
A32: Total | B32: 电网新增容量 | C32: =C19+C25 -> 184435.4 | D32: =D19+D25 -> 235033.65 | E32: =E19+E25 -> 251624.26 | F32: =F19+F25 -> 212658.08 | G32: =G19+G25 -> 211980.78 | H32: =H19+H25 -> 228645.96 | I32: =I19+I25 -> 229198.98
B34: $ / MW-mile | C34: =C16*10^6/C32 -> 386108.5 | D34: =D16*10^6/D32 -> 349762.1 | E34: =E16*10^6/E32 -> 308090.28 | F34: =F16*10^6/F32 -> 354520.8 | G34: =G16*10^6/G32 -> 327473.65 | H34: =H16*10^6/H32 -> 294770.39 | I34: =I16*10^6/I32 -> 282863.82

Sheet Exchange Rate
A1: 人民币年份 | B1: 当年人民币相对2012美元 | C1: 2012美元相对当年人民币价格 | E1: {=TRANSPOSE(A1:C24)} -> 人民币年份 | F1: 2000 | G1: 2001 | H1: 2002 | I1: 2003 | J1: 2004 | K1: 2005 | L1: 2006 | M1: 2007 | N1: 2008 | O1: 2009 | P1: 2010 | Q1: 2011 | R1: 2012 | S1: 2013 | T1: 2014 | U1: 2015 | V1: 2016 | W1: 2017 | X1: 2018 | Y1: 2019 | Z1: 2020 | AA1: 2021 | AB1: 2022
A2: 2000 | B2: 0.26402732 | C2: 3.7874869 | E2: 当年人民币相对2012美元 | F2: 0.26402732 | G2: 0.25873097 | H2: 0.25718247 | I2: 0.25065742 | J2: 0.23436442 | K2: 0.22555917 | L2: 0.2170371 | M2: 0.20142713 | N2: 0.18686069 | O2: 0.18725305 | P2: 0.17519707 | Q2: 0.16210591 | R2: 0.15841296 | S2: 0.15505847 | T2: 0.15347603 | U2: 0.15348055 | V2: 0.15135053 | W2: 0.14520448 | X2: 0.14029453 | Y2: 0.13851126 | Z2: 0.13765068 | AA2: 0.13187297 | AB2: 0.12836129
A3: 2001 | B3: 0.25873097 | C3: 3.8650186 | E3: 2012美元相对当年人民币价格 | F3: 3.7874869 | G3: 3.8650186 | H3: 3.8882898 | I3: 3.9895089 | J3: 4.2668593 | K3: 4.4334266 | L3: 4.6075073 | M3: 4.9645746 | N3: 5.3515804 | O3: 5.340367 | P3: 5.707858 | Q3: 6.1688066 | R3: 6.3126149 | S3: 6.4491801 | T3: 6.5156753 | U3: 6.5154835 | V3: 6.6071789 | W3: 6.8868397 | X3: 7.1278617 | Y3: 7.2196295 | Z3: 7.2647663 | AA3: 7.5830552 | AB3: 7.7905106
A4: 2002 | B4: 0.25718247 | C4: 3.8882898
A5: 2003 | B5: 0.25065742 | C5: 3.9895089
A6: 2004 | B6: 0.23436442 | C6: 4.2668593
A7: 2005 | B7: 0.22555917 | C7: 4.4334266
A8: 2006 | B8: 0.2170371 | C8: 4.6075073
A9: 2007 | B9: 0.20142713 | C9: 4.9645746
A10: 2008 | B10: 0.18686069 | C10: 5.3515804
A11: 2009 | B11: 0.18725305 | C11: 5.340367
A12: 2010 | B12: 0.17519707 | C12: 5.707858
A13: 2011 | B13: 0.16210591 | C13: 6.1688066
A14: 2012 | B14: 0.15841296 | C14: 6.3126149
A15: 2013 | B15: 0.15505847 | C15: 6.4491801
... A19: 2017 | B19: 0.14520448 | C19: 6.8868397
A20: 2018 | B20: 0.14029453 | C20: 7.1278617 | E20: Nominal GDP | F20: Growth | G20: Deflator
A21: 2019 | B21: 0.13851126 | C21: 7.2196295 | E21: 986515
A22: 2020 | B22: 0.13765068 | C22: 7.2647663 | E22: 1013567 | F22: 0.022 | G22: =(1+F22)/(E22/E21) -> 0.99472292
A23: 2021 | B23: =B22*G23 -> 0.13187297 | C23: =1/B23 -> 7.5830552 | E23: 1143670 | F23: 0.081 | G23: =(1+F23)/(E23/E22) -> 0.95802629
A24: 2022 | B24: =B23*G24 -> 0.12836129 | C24: =1/B24 -> 7.7905106 | E24: 1210207 | F24: 0.03 | G24: =(1+F24)/(E24/E23) -> 0.97337075

Sheet TCCpUCD
B1: Cost per Unit Capacity Distance (2012$/(circuit mile))
A2: Transmission Construction | B2: =Calculation!G34 -> 327473.65
