Workbook
Name billion_kw_to_MW: #REF!
Name billion_kw_to_MW: #REF!
Name billion_kw_to_MW: #REF!
Name billion_kw_to_MW: #REF!
Name billion_kw_to_MW: #REF!
Name billion_kw_to_MW: #REF!
Name billion_kw_to_MW: #REF!
Name gigwatt_to_megawatt: #REF!
Name gigwatt_to_megawatt: #REF!
Name gigwatt_to_megawatt: #REF!
Name gigwatt_to_megawatt: #REF!
Name gigwatt_to_megawatt: #REF!
Name gigwatt_to_megawatt: #REF!
Name gigwatt_to_megawatt: #REF!
Name IQ_CH: 110000
Name IQ_CQ: 5000
Name IQ_CY: 10000
Name IQ_DAILY: 500000
Name IQ_FH: 100000
Name IQ_FQ: 500
Name IQ_FY: 1000
Name IQ_LTM: 2000
Name IQ_MONTH: 15000
Name IQ_NTM: 6000
Name IQ_WEEK: 50000
Name IQ_YTD: 3000
Name Percent_rural: #REF!
Name Percent_Urban: #REF!
Name Percent_Urban: #REF!
Name Percent_Urban: #REF!
Name Percent_Urban: #REF!
Name Percent_Urban: #REF!
Name Percent_Urban: #REF!
Name Percent_Urban: #REF!

Sheet About
A1: BCRbQ BAU Capacity Retirements before Quantization
A2: CRbQ Capacity Retirements before Quantization
A4: Source: | B4: Project Based Data Source | D4: Statsitics Based Data Source | F4: Other Data Source
B5: historic generation capacity and annual increase 2008-2001 | D5: historic generation capacity and annual increase 2008-2001 | F5: Fossil Fuel Survival Rate
B6: China Electricity Council | D6: China Electricity Council | F6: Global Energy Monitor
B7: 中国电力工业统计资料汇编 （Compilation of China Power Sector Statistics) | D7: 中国电力工业统计资料汇编 （Compilation of China Power Sector Statistics) | F7: Tracker for Coal Plants, Natural Gas
B8: 2008-2021 | D8: 2008-2021 | F8: 2023
B9: Chapter 6 (List of Completed Construction Projects) | D9: Chapter 2 (Power Generation) | F9: https://globalenergymonitor.org/projects/global-coal-plant-tracker/
F10: https://globalenergymonitor.org/projects/global-oil-gas-plant-tracker/
B11: Offshore Wind | D11: historic generation capacity and annual increase 1993-2007
B12: Global Energy Monitor | D12: China Electricity Council | F12: Annual Plant Shutdown
B13: Tracker for Offshore Plants | D13: 中国电力年鉴（Statistical Yearbook of China Electricity Sector) | F13: China Electricity Council
B14: 2023 | D14: 1993-2007 | F14: 中国电力工业统计资料汇编 （Compilation of China Power Sector Statistics)
B15: https://globalenergymonitor.org/projects/global-wind-power-tracker/ | D15: Statistics and Resources | F15: 2005-2021
F16: Chapter 2 (Power Generation)
B17: Solar Projects | D17: Solar Capacity
B18: China Electricity Council | D18: National Energy Administation
B19: 中国电力工业统计资料汇编 （Compilation of China Power Sector Statistics) | D19: Annual Solar Generation and Cosntruction Statistics
B20: 2010-2012 | D20: 2013年光伏发电统计数据---国家能源局 (nea.gov.cn)
B21: Production Status of Major Solar Stations | D21: 2014年光伏发电统计信息---国家能源局 (nea.gov.cn)
D22: 2015年光伏发电相关统计数据---国家能源局 (nea.gov.cn)
B23: Solar Thermal | D23: 2016年光伏发电统计信息---国家能源局 (nea.gov.cn)
B24: China Solar Thermal Allaince (CNSTE) | D24: https://www.nea.gov.cn/2020-02/28/c_138827923.htm
B25: 中国太阳能热发电行业蓝皮书 | D25: https://www.nea.gov.cn/2022-03/09/c_1310508114.htm
B26: Blue Book of Concentrating Solar Power Industry (Chinese) | D26: https://www.nea.gov.cn/2023-02/17/c_1310698128.htm
B27: 2021-2022
B28: http://www.cnste.org/uploads/soft/230131/1_0841264311.pdf | D28: Geothermal Development
B29: http://mediacdn.mengliaoba.cn/download/2021%E4%B8%AD%E5%9B%BD%E5%A4%AA%E9%98%B3%E8%83%BD%E7%83%AD%E5%8F%91%E7%94%B5%E8%A1%8C%E4%B8%9A%E8%93%9D%E7%9A%AE%E4%B9%A6.pdf | D29: National Energy Adminstration
D30: 地热能开发利用“十三五”规划
B31: Pumped Hydro, Nuclear, and Natural Gas Projects | D31: 13 FYP Geothermal Development Plan
B32: Compiled Database from various online sources and statistics | D32: 2017
D33: https://www.gov.cn/xinwen/2017-02/06/5165321/files/19f10bae3ba5463f833c954de2d06a8f.pdf
A35: Notes: | B35: This file is used for calculating the values for BCRbQ (BAU Capacity Retirements before Quantization) , and CRbQ (Capacity Retirements before Quantization)
B36: The file backtraces generation installation, and provide a method that dissembles Start Year Capacity (SYC) into annual additions between 1990-2019.
B37: The using the lifetime data provided in BGCL (BAU Generation Capacity Lifetime), the expected year of retirement is calculated.
B39: For fossil fuel plants BAU retirement, instead of BGCL, a weibull survival curve is calculated using data from Global Energy Monitor Database, and is used to track
B40: retirement.
B42: For BCRbQ and CRbQ, future constructions listed in BPMCCS and PMCCS and considered to calculate the corresponding retirement schedule. Therefore, when the
B43: alternative installation schedule is used for a type of generation, the alternative retirement shedule should also be used.
B45: Due to either unannounced projects, or unannounced capacity expansions, using a bottom up project based tally of generation capaicty addition often doesn’t
...

Sheet Province Selector
A1: Code | B1: Name | C1: Name Chinese
A2: 00 | B2: 全国 National | C2: 全国
A3: 11 | B3: 北京市 Beijing | C3: 北京市
A4: 12 | B4: 天津市 Tianjin | C4: 天津市
A5: 13 | B5: 河北省 Hebei | C5: 河北省
A6: 14 | B6: 山西省 Shanxi | C6: 山西省
A7: 15 | B7: 内蒙古自治区 Inner Mongolia | C7: 内蒙古自治区
A8: 21 | B8: 辽宁省 Liaoning | C8: 辽宁省
A9: 22 | B9: 吉林省 Jilin | C9: 吉林省
A10: 23 | B10: 黑龙江省 Heilongjiang | C10: 黑龙江省
A11: 31 | B11: 上海市 Shanghai | C11: 上海市
A12: 32 | B12: 江苏省 Jiangsu | C12: 江苏省
A13: 33 | B13: 浙江省 Zhejiang | C13: 浙江省
A14: 34 | B14: 安徽省 Anhui | C14: 安徽省
... A33: 65 | B33: 新疆维吾尔自治区 Xijiang | C33: 新疆维吾尔自治区

Sheet 93-07workbook
A2: Gen Type | B2: Region | C2: 1993 | D2: 1994 | E2: 1995 | F2: 1996 | G2: 1997 | H2: 1998 | I2: 1999 | J2: 2000 | K2: 2001 | L2: 2002 | M2: 2003 | N2: 2004 | O2: 2005 | P2: 2006 | Q2: 2007 | R2: 1993 | S2: 1994 | T2: 1995 | U2: 1996 | V2: 1997 | W2: 1998 | X2: 1999 | Y2: 2000 | Z2: 2001 | AA2: 2002 | AB2: 2003 | AC2: 2004 | AD2: 2005 | AE2: 2006 | AF2: 2007 | AG2: 1993 | AH2: 1994 | AI2: 1995 | AJ2: 1996 | AK2: 1997 | AL2: 1998 | AM2: 1999 | AN2: 2000 | AO2: 2001 | AP2: 2002 | AQ2: 2003 | AR2: 2004 | AS2: 2005 | AT2: 2006 | AU2: 2007 | AV2: 1993 | AW2: 1994 | AX2: 1995 | AY2: 1996 | AZ2: 1997 | BA2: 1998 | BB2: 1999 | BC2: 2000 | BD2: 2001 | BE2: 2002 | BF2: 2003 | BG2: 2004 | BH2: 2005 | BI2: 2006 | BJ2: 2007 | BK2: 1998 | BL2: 1999 | BM2: 2000 | BN2: 2001 | BO2: 2002 | BP2: 2003 | BQ2: 2004 | BR2: 2005 | BS2: 2006 | BT2: 2007 | BU2: 2005 | BV2: 2006 | BW2: 2007
C3: 总计 | D3: 总计 | E3: 总计 | F3: 总计 | G3: 总计 | H3: 总计 | I3: 总计 | J3: 总计 | K3: 总计 | L3: 总计 | M3: 总计 | N3: 总计 | O3: 总计 | P3: 总计 | Q3: 总计 | R3: 水电 | S3: 水电 | T3: 水电 | U3: 水电 | V3: 水电 | W3: 水电 | X3: 水电 | Y3: 水电 | Z3: 水电 | AA3: 水电 | AB3: 水电 | AC3: 水电 | AD3: 水电 | AE3: 水电 | AF3: 水电 | AG3: 火电 | AH3: 火电 | AI3: 火电 | AJ3: 火电 | AK3: 火电 | AL3: 火电 | AM3: 火电 | AN3: 火电 | AO3: 火电 | AP3: 火电 | AQ3: 火电 | AR3: 火电 | AS3: 火电 | AT3: 火电 | AU3: 火电 | AV3: 核电 | AW3: 核电 | AX3: 核电 | AY3: 核电 | AZ3: 核电 | BA3: 核电 | BB3: 核电 | BC3: 核电 | BD3: 核电 | BE3: 核电 | BF3: 核电 | BG3: 核电 | BH3: 核电 | BI3: 核电 | BJ3: 核电 | BK3: 其他 | BL3: 其他 | BM3: 其他 | BN3: 其他 | BO3: 其他 | BP3: 其他 | BQ3: 其他 | BR3: 其他 | BS3: 其他 | BT3: 其他 | BU3: 风电 | BV3: 风电 | BW3: 风电
A4: Total Capacity Tally (10000KW) | B4: 全国 | C4: 18321.07 | D4: 19989.72 | E4: 21722.42 | F4: 23654.16 | G4: 25423.82 | H4: 27728.9 | I4: 29876.79 | J4: 31932.09 | K4: 33861.19 | L4: 35657.09 | M4: 39140.78 | N4: 44238.73 | O4: 51718.5 | P4: 62369.8 | Q4: 71822 | R4: 4459.25 | S4: 4906.08 | T4: 5218.36 | U4: 5557.79 | V4: 5973.02 | W4: 6506.5 | X4: 7297.08 | Y4: 7935.22 | Z4: 8300.64 | AA4: 8607.46 | AB4: 9489.62 | AC4: 10524.16 | AD4: 11738.8 | AE4: 13029.2 | AF4: 14823 | AG4: 13831.82 | AH4: 14873.64 | AI4: 16294.06 | AJ4: 17886.37 | AK4: 19240.8 | AL4: 20988.35 | AM4: 22343.4 | AN4: 23754.02 | AO4: 25313.7 | AP4: 26554.67 | AQ4: 28977.09 | AR4: 32948.3 | AS4: 39137.6 | AT4: 48382.2 | AU4: 55607 | AV4: 30 | AW4: 210 | AX4: 210 | AY4: 210 | AZ4: 210 | BA4: 210 | BB4: 210 | BC4: 210 | BD4: 210 | BE4: 446.8 | BF4: 618.6 | BG4: 683.6 | BH4: 684.6 | BI4: 684.6 | BJ4: 885 | BK4: 24.05 | BL4: 26.31 | BM4: 32.85 | BN4: 36.86 | BO4: 48.18 | BP4: 55.45 | BQ4: 81.97 | BR4: 51.9 | BS4: 66.5 | BT4: 86.53 | BU4: 105.6 | BV4: 207.2 | BW4: 420
B5: 北京市 | C5: 275.25 | D5: 270.52 | E5: 299.92 | F5: 339.52 | G5: 379.79 | H5: 407.89 | I5: 491.57 | J5: 445.16 | K5: 447.06 | L5: 444.6 | M5: 440.56 | N5: 451.44 | O5: 491.1 | P5: 506.1 | Q5: 495 | R5: 27.09 | S5: 27.09 | T5: 27.09 | U5: 66.69 | V5: 106.96 | W5: 106.96 | X5: 105.81 | Y5: 105.81 | Z5: 105.81 | AA5: 103.85 | AB5: 105.81 | AC5: 105.59 | AD5: 105.3 | AE5: 105.3 | AF5: 105 | AG5: 248.16 | AH5: 243.43 | AI5: 272.83 | AJ5: 272.83 | AK5: 272.83 | AL5: 300.93 | AM5: 385.76 | AN5: 339.35 | AO5: 341.25 | AP5: 340.75 | AQ5: 334.75 | AR5: 345.85 | AS5: 383.4 | AT5: 398.4 | AU5: 390 | BR5: 2.4 | BS5: 2.4 | BT5: 0.27
B6: 天津市 | C6: 319.6 | D6: 332.9 | E6: 338.65 | F6: 447.93 | G6: 447.68 | H6: 477.28 | I6: 504.75 | J6: 503.6 | K6: 563.7 | L6: 625.05 | M6: 601.35 | N6: 601.35 | O6: 617.9 | P6: 654.1 | Q6: 693 | R6: 0.5 | S6: 0.05 | T6: 0.5 | U6: 0.58 | V6: 0.58 | W6: 0.58 | X6: 0.5 | Y6: 0.5 | Z6: 0.5 | AA6: 0.5 | AB6: 0.5 | AC6: 0.5 | AD6: 0.5 | AE6: 0.5 | AF6: 1 | AG6: 319.1 | AH6: 332.85 | AI6: 338.15 | AJ6: 447.35 | AK6: 447.1 | AL6: 476.7 | AM6: 503.95 | AN6: 502.8 | AO6: 563.2 | AP6: 624.55 | AQ6: 600.85 | AR6: 600.85 | AS6: 617.4 | AT6: 651.2 | AU6: 692 | BL6: 0.3 | BM6: 0.3 | BS6: 2.4
B7: 河北省 | C7: 911.3 | D7: 979.2 | E7: 1103.57 | F7: 1176.44 | G7: 1257.53 | H7: 1328.41 | I7: 1458.9 | J7: 1583.07 | K7: 1722.74 | L7: 1753.51 | M7: 1847.64 | N7: 2073 | O7: 2316.6 | P7: 2709 | Q7: 3021 | R7: 67.37 | S7: 68.82 | T7: 66.19 | U7: 67.22 | V7: 68.33 | W7: 69.5 | X7: 71.99 | Y7: 72.72 | Z7: 74.26 | AA7: 77.59 | AB7: 76.43 | AC7: 78.38 | AD7: 78.5 | AE7: 78.5 | AF7: 78 | AG7: 843.93 | AH7: 910.38 | AI7: 1037.38 | AJ7: 1109.22 | AK7: 1189.2 | AL7: 1258.91 | AM7: 1385.92 | AN7: 1509.37 | AO7: 1647.49 | AP7: 1674.57 | AQ7: 1769.87 | AR7: 1993.27 | AS7: 2233.3 | AT7: 2608.7 | AU7: 2902 | BL7: 0.99 | BM7: 0.98 | BN7: 0.99 | BO7: 1.35 | BP7: 1.35 | BQ7: 1.35 | BU7: 4.8 | BV7: 21.8 | BW7: 41
B8: 山西省 | C8: 852.23 | D8: 896.95 | E8: 916.02 | F8: 960.68 | G8: 994.32 | H8: 1096.61 | I8: 1164.7 | J8: 1274.85 | K8: 1421.18 | L8: 1512.31 | M8: 1583.15 | N8: 1848.05 | O8: 2307.5 | P8: 2745.1 | Q8: 3174 | R8: 27.4 | S8: 25.84 | T8: 25.84 | U8: 25.91 | V8: 25.9 | W8: 43.79 | X8: 61.78 | Y8: 97.77 | Z8: 79.59 | AA8: 79.53 | AB8: 79.57 | AC8: 78.73 | AD8: 78.3 | AE8: 79 | AF8: 79 | AG8: 824.83 | AH8: 871.11 | AI8: 890.18 | AJ8: 934.77 | AK8: 968.42 | AL8: 1052.81 | AM8: 1102.91 | AN8: 1177.08 | AO8: 1341.59 | AP8: 1432.78 | AQ8: 1503.58 | AR8: 1769.33 | AS8: 2229.2 | AT8: 2666.1 | AU8: 3095
B9: 内蒙古自治区 | C9: 476.76 | D9: 505.99 | E9: 588.79 | F9: 625.2 | G9: 632.25 | H9: 780.34 | I9: 881.37 | J9: 895.9 | K9: 951.12 | L9: 1044.74 | M9: 1209.04 | N9: 1432.12 | O9: 1995 | P9: 3028.1 | Q9: 4179 | R9: 4.37 | S9: 4.36 | T9: 4.36 | U9: 4.9 | V9: 4.67 | W9: 5.02 | X9: 23.02 | Y9: 41.06 | Z9: 56.62 | AA9: 59.21 | AB9: 59.21 | AC9: 56.79 | AD9: 56.8 | AE9: 81.8 | AF9: 83 | AG9: 472.39 | AH9: 501.63 | AI9: 584.43 | AJ9: 620.3 | AK9: 627.58 | AL9: 771.33 | AM9: 854.33 | AN9: 850.29 | AO9: 889.83 | AP9: 977.87 | AQ9: 1142.17 | AR9: 1364.15 | AS9: 1917.3 | AT9: 2889.9 | AU9: 3987 | BK9: 3.99 | BL9: 4.02 | BM9: 4.55 | BN9: 4.67 | BO9: 7.66 | BP9: 7.66 | BQ9: 11.17 | BS9: 1.7 | BT9: 1.65 | BU9: 20.9 | BV9: 54.8 | BW9: 108
B10: 辽宁省 | C10: 1021.49 | D10: 1069.4 | E10: 1087.62 | F10: 1228.09 | G10: 1241.19 | H10: 1380.04 | I10: 1368.86 | J10: 1523.03 | K10: 1540.38 | L10: 1572.98 | M10: 1635.01 | N10: 1650.64 | O10: 1753.8 | P10: 1833.8 | Q10: 2150 | R10: 118.37 | S10: 119.25 | T10: 123.25 | U10: 122.09 | V10: 122.09 | W10: 122.31 | X10: 124 | Y10: 124.85 | Z10: 126.18 | AA10: 126.14 | AB10: 139.62 | AC10: 140.41 | AD10: 140.4 | AE10: 140.1 | AF10: 141 | AG10: 903.12 | AH10: 950.15 | AI10: 964.37 | AJ10: 1106 | AK10: 1119.1 | AL10: 1256.03 | AM10: 1242.57 | AN10: 1393.79 | AO10: 1407.8 | AP10: 1438.99 | AQ10: 1481.64 | AR10: 1496.03 | AS10: 1599.9 | AT10: 1672.1 | AU10: 1972 | BK10: 1.7 | BL10: 2.29 | BM10: 4.39 | BN10: 6.4 | BO10: 7.85 | BP10: 13.75 | BQ10: 14.2 | BR10: 0.9 | BS10: 0.9 | BT10: 0.9 | BU10: 12.6 | BV10: 20.7 | BW10: 35
B11: 吉林省 | C11: 632.22 | D11: 666.5 | E11: 700.49 | F11: 701.52 | G11: 749.92 | H11: 790.33 | I11: 809.13 | J11: 846.13 | K11: 887.53 | L11: 893.91 | M11: 940.85 | N11: 959.59 | O11: 1016.6 | P11: 1113.1 | Q11: 1198 | R11: 298.56 | S11: 299.89 | T11: 300.48 | U11: 301.51 | V11: 324.61 | W11: 347.47 | X11: 350.82 | Y11: 353.67 | Z11: 357.56 | AA11: 357.39 | AB11: 358.58 | AC11: 360.12 | AD11: 372.1 | AE11: 387.2 | AF11: 389 | AG11: 333.66 | AH11: 366.61 | AI11: 400.01 | AJ11: 400.01 | AK11: 425.31 | AL11: 442.86 | AM11: 458.31 | AN11: 492.47 | AO11: 529.97 | AP11: 533.52 | AQ11: 579.26 | AR11: 595.87 | AS11: 635.9 | AT11: 703.9 | AU11: 758 | BO11: 3.01 | BP11: 3.01 | BQ11: 3.61 | BR11: 0.6 | BS11: 1.3 | BT11: 4.4 | BU11: 7.9 | BV11: 20.8 | BW11: 47
B12: 黑龙江省 | C12: 776.02 | D12: 780.74 | E12: 786.47 | F12: 870.73 | G12: 943.2 | H12: 990.05 | I12: 1090.25 | J12: 1088.47 | K12: 1127.67 | L12: 1162.09 | M12: 1188.9 | N12: 1214.3 | O12: 1247.5 | P12: 1342.5 | Q12: 1518 | R12: 21.03 | S12: 21.03 | T12: 21.03 | U12: 33.93 | V12: 63.79 | W12: 78.45 | X12: 77.45 | Y12: 81.48 | Z12: 81.48 | AA12: 81.49 | AB12: 83.46 | AC12: 84.46 | AD12: 84.7 | AE12: 85.3 | AF12: 87 | AG12: 754.99 | AH12: 759.71 | AI12: 765.44 | AJ12: 836.8 | AK12: 879.41 | AL12: 911.6 | AM12: 1012.81 | AN12: 1006.99 | AO12: 1046.2 | AP12: 1080.6 | AQ12: 1105.44 | AR12: 1125.91 | AS12: 1157.6 | AT12: 1245.6 | AU12: 1408 | BQ12: 3.93 | BU12: 5.2 | BV12: 11.5 | BW12: 23
B13: 上海市 | C13: 764.74 | D13: 758.79 | E13: 806.4 | F13: 882.08 | G13: 956.77 | H13: 952.65 | I13: 996.43 | J13: 1060.43 | K13: 1123.27 | L13: 1138.26 | M13: 1109.26 | N13: 1201.83 | O13: 1336.7 | P13: 1478 | Q13: 1442 | AC13: 0 | AE13: 0 | AG13: 764.74 | AH13: 758.79 | AI13: 806.4 | AJ13: 882.08 | AK13: 956.77 | AL13: 952.65 | AM13: 996.43 | AN13: 1060.43 | AO13: 1123.27 | AP13: 1138.26 | AQ13: 1109.26 | AR13: 1201.49 | AS13: 1311.4 | AT13: 1452.6 | AU13: 1415 | BQ13: 0.34 | BR13: 22.9 | BS13: 22.9 | BT13: 24.88 | BU13: 2.4 | BV13: 2.4 | BW13: 2
B14: 江苏省 | C14: 1249.04 | D14: 1396.2 | E14: 1500.23 | F14: 1388.43 | G14: 1465.33 | H14: 1627.42 | I14: 1845.73 | J14: 1925.22 | K14: 1970.15 | L14: 2073.62 | M14: 2238.27 | N14: 2843.36 | O14: 4270.8 | P14: 5207.3 | Q14: 5599 | R14: 2.9 | S14: 2.82 | T14: 2.79 | U14: 2.79 | V14: 2.86 | W14: 2.97 | X14: 3.06 | Y14: 3.36 | Z14: 3.37 | AA14: 13.72 | AB14: 13.78 | AC14: 12.65 | AD14: 14.3 | AE14: 13.6 | AF14: 14 | AG14: 1246.14 | AH14: 1393.38 | AI14: 1497.44 | AJ14: 1385.64 | AK14: 1462.47 | AL14: 1624.45 | AM14: 1842.67 | AN14: 1921.86 | AO14: 1966.78 | AP14: 2059.9 | AQ14: 2224.5 | AR14: 2828.95 | AS14: 4250.6 | AT14: 5177.6 | AU14: 5334 | BJ14: 200 | BQ14: 1.75 | BR14: 5.9 | BS14: 14.7 | BT14: 26.78 | BV14: 1.5 | BW14: 25
B15: 浙江省 | C15: 802.54 | D15: 903.19 | E15: 1012.93 | F15: 1101.15 | G15: 1258.32 | H15: 1433.88 | I15: 1556.42 | J15: 1808.44 | K15: 1881.89 | L15: 2067.74 | M15: 2382.14 | N15: 3095.39 | O15: 3774.3 | P15: 4687 | Q15: 5112 | R15: 244.03 | S15: 250.15 | T15: 258.18 | U15: 279.16 | V15: 296.24 | W15: 382.91 | X15: 457.95 | Y15: 542.03 | Z15: 573.25 | AA15: 586.68 | AB15: 605.45 | AC15: 641.84 | AD15: 695.2 | AE15: 836.9 | AF15: 852 | AG15: 528.51 | AH15: 623.04 | AI15: 724.75 | AJ15: 791.99 | AK15: 932.08 | AL15: 1017.3 | AM15: 1064.8 | AN15: 1232.59 | AO15: 1273.62 | AP15: 1308.24 | AQ15: 1532.12 | AR15: 2143.98 | AS15: 2768.2 | AT15: 3539.1 | AU15: 3949 | AV15: 30 | AW15: 30 | AX15: 30 | AY15: 30 | AZ15: 30 | BA15: 30 | BB15: 30 | BC15: 30 | BD15: 30 | BE15: 167.8 | BF15: 240.6 | BG15: 305.6 | BH15: 306.6 | BI15: 306.6 | BJ15: 307 | BK15: 3.67 | BL15: 3.67 | BM15: 3.82 | BN15: 5.02 | BO15: 5.02 | BP15: 3.97 | BQ15: 3.97 | BR15: 0.6 | BS15: 0.6 | BU15: 3.7 | BV15: 3.7 | BW15: 4
B16: 安徽省 | C16: 529.21 | D16: 557.6 | E16: 593.1 | F16: 674.16 | G16: 712.81 | H16: 743.91 | I16: 800.06 | J16: 872.24 | K16: 956.91 | L16: 970.54 | M16: 993.4 | N16: 1005.73 | O16: 1224.8 | P16: 1513.5 | Q16: 1927 | R16: 49.81 | S16: 55.08 | T16: 55.58 | U16: 56.14 | V16: 56.75 | W16: 57.9 | X16: 45.5 | Y16: 54.63 | Z16: 60.88 | AA16: 64.91 | AB16: 64.91 | AC16: 69.28 | AD16: 74 | AE16: 100.1 | AF16: 151 | AG16: 479.4 | AH16: 502.52 | AI16: 537.52 | AJ16: 618.02 | AK16: 656.06 | AL16: 686.01 | AM16: 754.56 | AN16: 817.61 | AO16: 896.03 | AP16: 905.63 | AQ16: 928.49 | AR16: 936.45 | AS16: 1150.8 | AT16: 1413.4 | AU16: 1776
B17: 福建省 | C17: 427.78 | D17: 538.07 | E17: 646.96 | F17: 737.39 | G17: 765.33 | H17: 810.27 | I17: 968.42 | J17: 1043.66 | K17: 1261.69 | L17: 1352.39 | M17: 1386.58 | N17: 1550.75 | O17: 1762.2 | P17: 2204.7 | Q17: 2398 | R17: 254.52 | S17: 336.21 | T17: 398.58 | U17: 437.65 | V17: 455.82 | W17: 475.82 | X17: 506.99 | Y17: 532.49 | Z17: 618 | AA17: 651.2 | AB17: 676.11 | AC17: 718.01 | AD17: 822.5 | AE17: 895.7 | AF17: 980 | AG17: 173.26 | AH17: 201.86 | AI17: 248.38 | AJ17: 299.74 | AK17: 309.51 | AL17: 334.45 | AM17: 461.43 | AN17: 509.88 | AO17: 642.4 | AP17: 699.99 | AQ17: 709.28 | AR17: 831.54 | AS17: 934.5 | AT17: 1300.1 | AU17: 1391 | BM17: 1.29 | BN17: 1.29 | BO17: 1.2 | BP17: 1.2 | BQ17: 1.2 | BT17: 3.9 | BU17: 5.2 | BV17: 8.9 | BW17: 23
B18: 江西省 | C18: 384.58 | D18: 410.37 | E18: 451.37 | F18: 478.89 | G18: 542.58 | H18: 572.64 | I18: 555.63 | J18: 632.03 | K18: 693.76 | L18: 732.62 | M18: 771.52 | N18: 804.59 | O18: 892.5 | P18: 985.6 | Q18: 1284 | R18: 148.84 | S18: 149.44 | T18: 156.89 | U18: 162.91 | V18: 166.6 | W18: 170.95 | X18: 173.45 | Y18: 184.6 | Z18: 206.78 | AA18: 219.74 | AB18: 230.74 | AC18: 254.99 | AD18: 301.9 | AE18: 328.8 | AF18: 357 | AG18: 235.74 | AH18: 260.93 | AI18: 294.48 | AJ18: 315.98 | AK18: 375.98 | AL18: 401.69 | AM18: 382.18 | AN18: 447.43 | AO18: 486.98 | AP18: 512.88 | AQ18: 540.78 | AR18: 549.6 | AS18: 590.6 | AT18: 656.8 | AU18: 927
B19: 山东省 | C19: 1124.93 | D19: 1205.63 | E19: 1281.2 | F19: 1416.88 | G19: 1687.27 | H19: 1789.64 | I19: 1807.03 | J19: 2001 | K19: 2101.39 | L19: 2515.31 | M19: 3054.52 | N19: 3292.36 | O19: 3742.7 | P19: 5005.5 | Q19: 5540 | R19: 7.55 | S19: 7.58 | T19: 7.87 | U19: 6.96 | V19: 6.75 | W19: 6.62 | X19: 4.99 | Y19: 8.41 | Z19: 5.62 | AA19: 5.08 | AB19: 5.08 | AC19: 5.08 | AD19: 5.2 | AE19: 55.3 | AF19: 105 | AG19: 1117.38 | AH19: 1198.05 | AI19: 1273.33 | AJ19: 1409.92 | AK19: 1680.52 | AL19: 1783.02 | AM19: 1802.04 | AN19: 1992.6 | AO19: 2095.77 | AP19: 2510.24 | AQ19: 3049.44 | AR19: 3286.04 | AS19: 3733.8 | AT19: 4939.5 | AU19: 5414 | BQ19: 1.23 | BU19: 3.7 | BV19: 10.6 | BW19: 21
B20: 河南省 | C20: 830.85 | D20: 847.36 | E20: 1006.96 | F20: 1106.97 | G20: 1173.97 | H20: 1378.44 | I20: 1477.36 | J20: 1531.7 | K20: 1778.7 | L20: 1834.25 | M20: 2007.35 | N20: 2422.65 | O20: 2880.8 | P20: 3515.6 | Q20: 4129 | R20: 57.27 | S20: 54.52 | T20: 54.52 | U20: 55.48 | V20: 63.58 | W20: 62.8 | X20: 92.8 | Y20: 152.8 | Z20: 243.8 | AA20: 243.8 | AB20: 243.8 | AC20: 243.8 | AD20: 254 | AE20: 255.3 | AF20: 274 | AG20: 773.58 | AH20: 792.84 | AI20: 952.44 | AJ20: 1051.49 | AK20: 1110.39 | AL20: 1315.64 | AM20: 1384.56 | AN20: 1378.9 | AO20: 1534.9 | AP20: 1590.45 | AQ20: 1763.55 | AR20: 2178.85 | AS20: 2626.8 | AT20: 3260.3 | AU20: 3854
B21: 湖北省 | C21: 904.75 | D21: 981.36 | E21: 1000.01 | F21: 1077.49 | G21: 1178.1 | H21: 1317.23 | I21: 1449.32 | J21: 1510.93 | K21: 1520.29 | L21: 1536.17 | M21: 1971.05 | N21: 2462.44 | O21: 2741.5 | P21: 2994.4 | Q21: 3708 | R21: 548.09 | S21: 621.15 | T21: 628.75 | U21: 634.43 | V21: 639.89 | W21: 653.17 | X21: 657.72 | Y21: 707.05 | Z21: 712.56 | AA21: 721.39 | AB21: 1153.72 | AC21: 1511.51 | AD21: 1788.9 | AE21: 1832.1 | AF21: 2402 | AG21: 356.66 | AH21: 360.21 | AI21: 371.26 | AJ21: 443.06 | AK21: 538.21 | AL21: 664.06 | AM21: 791.6 | AN21: 803.88 | AO21: 807.73 | AP21: 814.78 | AQ21: 817.33 | AR21: 950.93 | AS21: 952.6 | AT21: 1162.3 | AU21: 1304 | BW21: 1
B22: 湖南省 | C22: 665.77 | D22: 711.09 | E22: 775.55 | F22: 889.89 | G22: 909.77 | H22: 992.03 | I22: 1026.41 | J22: 1033.54 | K22: 1096.38 | L22: 1111.09 | M22: 1304.99 | N22: 1422.78 | O22: 1506 | P22: 1938 | Q22: 2260 | R22: 329.6 | S22: 367.86 | T22: 421.13 | U22: 481.82 | V22: 500.99 | W22: 510.32 | X22: 571.47 | Y22: 585.8 | Z22: 596.61 | AA22: 613.53 | AB22: 660.31 | AC22: 744.82 | AD22: 784.9 | AE22: 864.8 | AF22: 922 | AG22: 336.17 | AH22: 343.23 | AI22: 354.42 | AJ22: 408.07 | AK22: 408.78 | AL22: 481.71 | AM22: 454.94 | AN22: 447.74 | AO22: 499.78 | AP22: 497.56 | AQ22: 644.67 | AR22: 677.95 | AS22: 721.2 | AT22: 1071.5 | AU22: 1336 | BS22: 1.7 | BT22: 1.7
B23: 广东省 | C23: 1475.89 | D23: 1981.62 | E23: 2271.75 | F23: 2630.83 | G23: 2812.63 | H23: 2906.95 | I23: 3033.37 | J23: 3189.56 | K23: 3360.07 | L23: 3587.99 | M23: 3920.2 | N23: 4262.1 | O23: 4808.2 | P23: 5389.9 | Q23: 5886 | R23: 402.08 | S23: 454.34 | T23: 465.71 | U23: 478.5 | V23: 498.87 | W23: 551.2 | X23: 655.4 | Y23: 701.55 | Z23: 730.28 | AA23: 777.53 | AB23: 810.72 | AC23: 858.46 | AD23: 903.6 | AE23: 932 | AF23: 1011 | AG23: 1073.81 | AH23: 1347.28 | AI23: 1626.04 | AJ23: 1972.33 | AK23: 2133.75 | AL23: 2171.57 | AM23: 2193.71 | AN23: 2301.32 | AO23: 2443.1 | AP23: 2523.78 | AQ23: 2723.14 | AR23: 3017.29 | AS23: 3518.3 | AT23: 4061.5 | AU23: 471 | AW23: 180 | AX23: 180 | AY23: 180 | AZ23: 180 | BA23: 180 | BB23: 180 | BC23: 180 | BD23: 180 | BE23: 279 | BF23: 378 | BG23: 378 | BH23: 378 | BI23: 378 | BJ23: 378 | BK23: 4.18 | BL23: 4.26 | BM23: 6.69 | BN23: 6.69 | BO23: 7.68 | BP23: 8.34 | BQ23: 8.34 | BU23: 8.3 | BV23: 18.3 | BW23: 25
B24: 广西壮族自治区 | C24: 480.1 | D24: 546.25 | E24: 602.36 | F24: 626.57 | G24: 687.92 | H24: 728.56 | I24: 782.67 | J24: 993.82 | K24: 986.18 | L24: 1003.95 | M24: 1023.53 | N24: 941.85 | O24: 1101.7 | P24: 1305.8 | Q24: 1975 | R24: 309.88 | S24: 346.83 | T24: 382.92 | U24: 402.41 | V24: 456.82 | W24: 493.27 | X24: 550.42 | Y24: 668.32 | Z24: 676.37 | AA24: 688.33 | AB24: 704.52 | AC24: 504.04 | AD24: 608.5 | AE24: 762.4 | AF24: 1044 | AG24: 170.22 | AH24: 199.42 | AI24: 219.44 | AJ24: 224.16 | AK24: 231.1 | AL24: 235.28 | AM24: 232.25 | AN24: 325.5 | AO24: 309.81 | AP24: 315.62 | AQ24: 319.01 | AR24: 437.81 | AS24: 493.1 | AT24: 543.4 | AU24: 931
B25: 海南省 | C25: 89.72 | D25: 105.73 | E25: 151.85 | F25: 156.05 | G25: 156.07 | H25: 153.67 | I25: 166.36 | J25: 179.13 | K25: 191.76 | L25: 178.04 | M25: 175.96 | N25: 217.04 | O25: 211.5 | P25: 258 | Q25: 302 | R25: 35.99 | S25: 47.35 | T25: 50.73 | U25: 50.93 | V25: 50.74 | W25: 53.34 | X25: 53.5 | Y25: 53.69 | Z25: 53.82 | AA25: 54.75 | AB25: 55.14 | AC25: 56.22 | AD25: 57.4 | AE25: 58.9 | AF25: 59 | AG25: 53.73 | AH25: 58.38 | AI25: 101.12 | AJ25: 105.12 | AK25: 105.32 | AL25: 99.47 | AM25: 111.98 | AN25: 124.56 | AO25: 137.06 | AP25: 122.41 | AQ25: 119.95 | AR25: 159.95 | AS25: 153.2 | AT25: 198.2 | AU25: 240 | BK25: 0.86 | BL25: 0.88 | BM25: 0.88 | BN25: 0.88 | BO25: 0.88 | BP25: 0.87 | BQ25: 0.87 | BT25: 1.4 | BU25: 0.9 | BV25: 0.9 | BW25: 1
B26: 重庆市 | G26: 310.89 | H26: 390.52 | I26: 425.34 | J26: 432.2 | K26: 416.63 | L26: 420 | M26: 445.6 | N26: 467.9 | O26: 567.6 | P26: 759.7 | Q26: 863 | V26: 83.56 | W26: 83.64 | X26: 107.03 | Y26: 132.7 | Z26: 126.8 | AA26: 119.55 | AB26: 132.98 | AC26: 140.79 | AD26: 191.2 | AE26: 197.9 | AF26: 224 | AK26: 227.33 | AL26: 306.88 | AM26: 318.31 | AN26: 299.5 | AO26: 289.83 | AP26: 300.45 | AQ26: 312.62 | AR26: 327.11 | AS26: 374.1 | AT26: 559.4 | AU26: 637 | BR26: 2.4 | BS26: 2.4 | BT26: 2.4
B27: 四川省 | C27: 1052.71 | D27: 1137.59 | E27: 1215.16 | F27: 1356.94 | G27: 1110.74 | H27: 1284.1 | I27: 1584.49 | J27: 1709.84 | K27: 1790.85 | L27: 1799.66 | M27: 1844.54 | N27: 2028.32 | O27: 2245.6 | P27: 2728.5 | Q27: 3186 | R27: 455.89 | S27: 505.43 | T27: 559.04 | U27: 642.42 | V27: 608.24 | W27: 770.59 | X27: 1041.69 | Y27: 1100.83 | Z27: 1153.15 | AA27: 1185.46 | AB27: 1234.15 | AC27: 1338.29 | AD27: 1496 | AE27: 1773 | AF27: 1986 | AG27: 596.82 | AH27: 632.16 | AI27: 656.12 | AJ27: 714.52 | AK27: 502.5 | AL27: 513.51 | AM27: 542.8 | AN27: 609.01 | AO27: 637.7 | AP27: 614.2 | AQ27: 610.4 | AR27: 690.03 | AS27: 749.6 | AT27: 955.5 | AU27: 1200
B28: 贵州省 | C28: 317.08 | D28: 385.05 | E28: 427.05 | F28: 464.74 | G28: 479.31 | H28: 528.09 | I28: 602.86 | J28: 606.36 | K28: 665.01 | L28: 706.86 | M28: 1017.95 | N28: 1469.83 | O28: 1686.8 | P28: 2188.3 | Q28: 2417 | R28: 139.41 | S28: 183.99 | T28: 205.87 | U28: 220.9 | V28: 217.98 | W28: 223.51 | X28: 231.01 | Y28: 235.81 | Z28: 240.96 | AA28: 242.61 | AB28: 371.37 | AC28: 689.65 | AD28: 723.3 | AE28: 753.4 | AF28: 821 | AG28: 177.67 | AH28: 201.06 | AI28: 221.18 | AJ28: 243.84 | AK28: 261.33 | AL28: 304.58 | AM28: 371.85 | AN28: 370.55 | AO28: 424.05 | AP28: 464.25 | AQ28: 646.58 | AR28: 780.18 | AS28: 963.5 | AT28: 1435 | AU28: 1596
B29: 云南省 | C29: 451.61 | D29: 495.13 | E29: 530.01 | F29: 551.64 | G29: 574.16 | H29: 661.09 | I29: 712.2 | J29: 741.41 | K29: 794.19 | L29: 876.91 | M29: 1010 | N29: 1136.55 | O29: 1275.2 | P29: 1826.1 | Q29: 2221 | R29: 310.15 | S29: 361.51 | T29: 396.08 | U29: 397.36 | V29: 407.48 | W29: 427.91 | X29: 467.69 | Y29: 494.72 | Z29: 499.56 | AA29: 583.63 | AB29: 654.32 | AC29: 705.86 | AD29: 799.9 | AE29: 969.8 | AF29: 1158 | AG29: 141.46 | AH29: 133.62 | AI29: 133.93 | AJ29: 154.28 | AK29: 166.68 | AL29: 233.18 | AM29: 244.52 | AN29: 246.69 | AO29: 294.63 | AP29: 293.27 | AQ29: 355.68 | AR29: 430.69 | AS29: 475.2 | AT29: 856.4 | AU29: 1063
B30: 西藏自治区 | C30: 16.66 | D30: 17.66 | E30: 17.66 | F30: 18.51 | G30: 29.38 | H30: 30.14 | I30: 33.16 | J30: 35.72 | K30: 36.08 | L30: 36.33 | M30: 37.62 | N30: 46.92 | O30: 48.2 | P30: 37.9 | Q30: 42 | R30: 12.09 | S30: 12.95 | T30: 12.95 | U30: 12.94 | V30: 23.76 | W30: 24.25 | X30: 27.25 | Y30: 29.48 | Z30: 29.6 | AA30: 29.85 | AB30: 31.14 | AC30: 40.35 | AD30: 41.9 | AE30: 34.3 | AF30: 39 | AG30: 4.57 | AH30: 4.71 | AI30: 4.71 | AJ30: 5.57 | AK30: 5.62 | AL30: 5.89 | AM30: 3.15 | AN30: 3.48 | AO30: 3.46 | AP30: 3.46 | AQ30: 3.46 | AR30: 3.46 | AS30: 3.2 | AT30: 1.2 | AU30: 1 | BL30: 2.76 | BM30: 2.76 | BN30: 3.02 | BO30: 3.02 | BP30: 3.02 | BQ30: 2.42 | BR30: 3 | BS30: 2.4 | BT30: 2.4
B31: 陕西省 | C31: 443.07 | D31: 431.25 | E31: 498.74 | F31: 545.96 | G31: 547.76 | H31: 635.31 | I31: 667.45 | J31: 737.56 | K31: 775.31 | L31: 819.77 | M31: 878.87 | N31: 951.69 | O31: 1166.4 | P31: 1193.4 | Q31: 1416 | R31: 119.8 | S31: 116.8 | T31: 118.19 | U31: 123.36 | V31: 123.36 | W31: 124.91 | X31: 129.2 | Y31: 145.12 | Z31: 145.07 | AA31: 146.23 | AB31: 146.23 | AC31: 187.65 | AD31: 197.8 | AE31: 216.5 | AF31: 179 | AG31: 323.27 | AH31: 314.45 | AI31: 380.55 | AJ31: 422.6 | AK31: 424.4 | AL31: 510.4 | AM31: 538.25 | AN31: 592.44 | AO31: 630.24 | AP31: 673.54 | AQ31: 732.64 | AR31: 764.04 | AS31: 964 | AT31: 972.3 | AU31: 1229 | BR31: 4.6 | BS31: 4.6 | BT31: 7.25
B32: 甘肃省 | C32: 453.25 | D32: 451.67 | E32: 455.24 | F32: 498.6 | G32: 556.3 | H32: 591.35 | I32: 612.82 | J32: 655.22 | K32: 700.15 | L32: 712.88 | M32: 804.72 | N32: 867.99 | O32: 985.7 | P32: 1093.9 | Q32: 1259 | R32: 235.77 | S32: 230.69 | T32: 232.32 | U32: 244.67 | V32: 265.16 | W32: 281.02 | X32: 286.8 | Y32: 295.15 | Z32: 311.83 | AA32: 323.86 | AB32: 328.06 | AC32: 356.61 | AD32: 400.6 | AE32: 429.1 | AF32: 440 | AG32: 217.48 | AH32: 220.98 | AI32: 222.92 | AJ32: 253.93 | AK32: 291.15 | AL32: 310.21 | AM32: 325.9 | AN32: 359.95 | AO32: 387.48 | AP32: 388.18 | AQ32: 474.5 | AR32: 497.56 | AS32: 571.3 | AT32: 644.8 | AU32: 784 | BK32: 0.12 | BL32: 0.12 | BM32: 0.12 | BN32: 0.84 | BO32: 0.84 | BP32: 2.16 | BQ32: 13.82 | BR32: 8.6 | BS32: 8.6 | BT32: 8.6 | BU32: 5.2 | BV32: 11.3 | BW32: 26
B33: 青海省 | C33: 172.36 | D33: 173.53 | E33: 186.88 | F33: 199.83 | G33: 281.91 | H33: 324.12 | I33: 379.6 | J33: 395.37 | K33: 389.41 | L33: 401 | M33: 424.69 | N33: 494.32 | O33: 571.2 | P33: 694 | Q33: 774 | R33: 138.51 | S33: 139.38 | T33: 140.23 | U33: 140.97 | V33: 223.78 | W33: 265.85 | X33: 307.52 | Y33: 311.39 | Z33: 312.74 | AA33: 320.63 | AB33: 334.11 | AC33: 405.34 | AD33: 482.5 | AE33: 542.3 | AF33: 583 | AG33: 33.85 | AH33: 34.15 | AI33: 46.65 | AJ33: 58.86 | AK33: 58.14 | AL33: 58.27 | AM33: 72.08 | AN33: 83.98 | AO33: 76.68 | AP33: 80.38 | AQ33: 90.58 | AR33: 88.98 | AS33: 88.7 | AT33: 151.7 | AU33: 190
B34: 宁夏回族自治区 | C34: 164.23 | D34: 165.43 | E34: 168.73 | F34: 169.93 | G34: 230.23 | H34: 230.23 | I34: 227.23 | J34: 230.63 | K34: 235.39 | L34: 269.39 | M34: 342.02 | N34: 419.07 | O34: 518.3 | P34: 644.1 | Q34: 751 | R34: 27.63 | S34: 27.63 | T34: 30.63 | U34: 30.63 | V34: 30.63 | W34: 30.63 | X34: 30.63 | Y34: 30.63 | Z34: 30.79 | AA34: 30.79 | AB34: 30.82 | AC34: 36.62 | AD34: 42.9 | AE34: 42.9 | AF34: 43 | AG34: 136.6 | AH34: 137.8 | AI34: 138.1 | AJ34: 139.3 | AK34: 199.6 | AL34: 199.6 | AM34: 196.6 | AN34: 200 | AO34: 204.6 | AP34: 238.6 | AQ34: 310.2 | AR34: 378.2 | AS34: 464.2 | AT34: 600.2 | AU34: 703 | BP34: 1 | BQ34: 4.25 | BU34: 11.2 | BV34: 1.1 | BW34: 5
B35: 新疆维吾尔自治区 | C35: 255.33 | D35: 286.51 | E35: 300.75 | F35: 330.84 | G35: 350.38 | H35: 395.73 | I35: 396.9 | J35: 445.86 | K35: 474.36 | L35: 503.14 | M35: 549.5 | N35: 602.8 | O35: 654 | P35: 789.2 | Q35: 903 | R35: 64.75 | S35: 67.59 | T35: 70.66 | U35: 72.26 | V35: 76.22 | W35: 78.85 | X35: 79.65 | Y35: 86.81 | Z35: 86.81 | AA35: 98.48 | AB35: 98.98 | AC35: 97.3 | AD35: 136 | AE35: 176.6 | AF35: 214 | AG35: 190.58 | AH35: 218.92 | AI35: 230.09 | AJ35: 258.58 | AK35: 274.16 | AL35: 310.11 | AM35: 310.24 | AN35: 351.99 | AO35: 380.49 | AP35: 394.99 | AQ35: 441.35 | AR35: 495.97 | AS35: 504.7 | AT35: 593.7 | AU35: 656 | BK35: 6.77 | BL35: 6.77 | BM35: 7.06 | BN35: 7.06 | BO35: 9.67 | BP35: 9.13 | BQ35: 9.53 | BU35: 13.4 | BV35: 18.9 | BW35: 33
A37: Gen Type | B37: Region | C37: 1993 | D37: 1994 | E37: 1995 | F37: 1996 | G37: 1997 | H37: 1998 | I37: 1999 | J37: 2000 | K37: 2001 | L37: 2002 | M37: 2003 | N37: 2004 | O37: 2005 | P37: 2006 | Q37: 2007 | R37: 1993 | S37: 1994 | T37: 1995 | U37: 1996 | V37: 1997 | W37: 1998 | X37: 1999 | Y37: 2000 | Z37: 2001 | AA37: 2002 | AB37: 2003 | AC37: 2004 | AD37: 2005 | AE37: 2006 | AF37: 2007 | AG37: 1993 | AH37: 1994 | AI37: 1995 | AJ37: 1996 | AK37: 1997 | AL37: 1998 | AM37: 1999 | AN37: 2000 | AO37: 2001 | AP37: 2002 | AQ37: 2003 | AR37: 2004 | AS37: 2005 | AT37: 2006 | AU37: 2007 | AV37: 1993 | AW37: 1994 | AX37: 1995 | AY37: 1996 | AZ37: 1997 | BA37: 1998 | BB37: 1999 | BC37: 2000 | BD37: 2001 | BE37: 2002 | BF37: 2003 | BG37: 2004 | BH37: 2005 | BI37: 2006 | BJ37: 2007 | BK37: 1998 | BL37: 1999 | BM37: 2000 | BN37: 2001 | BO37: 2002 | BP37: 2003 | BQ37: 2004 | BR37: 2005 | BS37: 2006 | BT37: 2007 | BU37: 2005 | BV37: 2006 | BW37: 2007
C38: 总计 | D38: 总计 | E38: 总计 | F38: 总计 | G38: 总计 | H38: 总计 | I38: 总计 | J38: 总计 | K38: 总计 | L38: 总计 | M38: 总计 | N38: 总计 | O38: 总计 | P38: 总计 | Q38: 合计 | R38: 水电 | S38: 水电 | T38: 水电 | U38: 水电 | V38: 水电 | W38: 水电 | X38: 水电 | Y38: 水电 | Z38: 水电 | AA38: 水电 | AB38: 水电 | AC38: 水电 | AD38: 水电 | AE38: 水电 | AF38: 水电 | AG38: 火电 | AH38: 火电 | AI38: 火电 | AJ38: 火电 | AK38: 火电 | AL38: 火电 | AM38: 火电 | AN38: 火电 | AO38: 火电 | AP38: 火电 | AQ38: 火电 | AR38: 火电 | AS38: 火电 | AT38: 火电 | AU38: 火电 | AV38: 核电 | AW38: 核电 | AX38: 核电 | AY38: 核电 | AZ38: 核电 | BA38: 核电 | BB38: 核电 | BC38: 核电 | BD38: 核电 | BE38: 核电 | BF38: 核电 | BG38: 核电 | BH38: 核电 | BI38: 核电 | BJ38: 核电 | BK38: 其他 | BL38: 其他 | BM38: 其他 | BN38: 其他 | BO38: 其他 | BP38: 其他 | BQ38: 其他 | BR38: 其他 | BS38: 其他 | BT38: 其他 | BU38: 风电 | BV38: 风电 | BW38: 风电
A39: Annual Capaicty Addition (10000KW) | B39: 全国 | C39: 1499.22 | D39: 1643.71 | E39: 1528.96 | F39: 1682.42 | G39: 1490.09 | H39: 1999.55 | I39: 2052.3 | J39: 2012.04 | K39: 1586.87 | L39: 1193.01 | N39: 5322.54 | O39: 7128.6 | P39: 10424 | Q39: 10190 | R39: 368.42 | S39: 397.15 | T39: 257.3 | U39: 269.35 | V39: 340.33 | W39: 450.24 | X39: 628.66 | Y39: 452.41 | Z39: 289.55 | AA39: 148.22 | AC39: 1150.08 | AD39: 1226.89 | AE39: 1100 | AF39: 1307 | AG39: 1130.8 | AH39: 1036.56 | AI39: 1271.66 | AJ39: 1413.07 | AK39: 1149.76 | AL39: 1549.31 | AM39: 1423.64 | AN39: 1559.63 | AO39: 1297.32 | AP39: 1044.79 | AR39: 4026.49 | AS39: 5774.24 | AT39: 9207 | AU39: 8360 | AW39: 210 | BJ39: 200 | BS39: 6 | BT39: 18 | BV39: 110 | BW39: 304
B40: 北京市 | E40: 40 | F40: 40 | G40: 20 | H40: 46.5 | I40: 18.5 | O40: 56 | T40: 20 | U40: 40 | V40: 20 | AI40: 20 | AL40: 46.5 | AM40: 18.5 | AS40: 56
B41: 天津市 | C41: 25 | D41: 2.5 | E41: 52.5 | F41: 50 | H41: 30 | I41: 30 | K41: 60 | L41: 60 | O41: 40.4 | P41: 30 | Q41: 30 | AG41: 25 | AH41: 2.5 | AI41: 52.5 | AJ41: 50 | AL41: 30 | AM41: 30 | AO41: 60 | AP41: 60 | AS41: 38 | AT41: 30 | AU41: 30
B42: 河北省 | C42: 62.5 | D42: 62.5 | E42: 90 | F42: 60 | G42: 60 | H42: 30 | I42: 125 | J42: 131 | K42: 101.38 | N42: 269.98 | O42: 250.2 | P42: 386 | Q42: 395 | Z42: 5.38 | AC42: 0.88 | AE42: 19 | AG42: 62.5 | AH42: 62.5 | AI42: 90 | AJ42: 60 | AK42: 60 | AL42: 30 | AM42: 125 | AN42: 131 | AO42: 96 | AR42: 269.1 | AS42: 241.9 | AT42: 352 | AU42: 382 | BS42: 1 | BT42: 5 | BV42: 14 | BW42: 8
...

Sheet 08-21addition
A1: Region | B1: Year | C1: Wind | D1: Nuclear | E1: Biomass | F1: Municipal Solid Waste | G1: Waste Heat | H1: Hard Coal | I1: Lignite | J1: Natural Gas | K1: Natural Gas | L1: Biomass | M1: Oil | N1: Energy Storage | O1: Hydro | P1: Pumped Hydro | Q1: Solar
A2: 地区 | B2: 年份 | C2: 风电 | D2: 核电 | E2: 火电-其他火电-秸杆、蔗渣、林木质发电 | F2: 火电-其他火电-垃圾焚烧发电 | G2: 火电-其他火电-余温、余压、余气发电 | H2: 火电-燃煤-常规燃煤 | I2: 火电-燃煤-煤矸石发电 | J2: 火电-燃气-常规燃气 | K2: 火电-燃气-煤层气发电 | L2: 火电-燃气-沼气发电 | M2: 火电-燃油 | N2: 其他-其他 | O2: 水电-常规水电 | P2: 水电-抽水蓄能 | Q2: 太阳能
A3: 安徽省 | B3: 2008 | H3: 744 | O3: 0
A4: 安徽省 | B4: 2009 | E4: 4.9 | G4: 3.7 | H4: 214.5 | O4: 7.8
A5: 安徽省 | B5: 2010 | C5: 19.8 | E5: 3.6 | G5: 8.5 | H5: 66.9 | O5: 0
A6: 安徽省 | B6: 2011 | C6: 9.9 | E6: 12 | G6: 6.3 | H6: 168.5 | O6: 0 | P6: 25
A7: 安徽省 | B7: 2012 | C7: 5 | E7: 3 | F7: 0.1 | G7: 2.4 | H7: 263.2 | O7: 2 | P7: 75 | Q7: 1.46
A8: 安徽省 | B8: 2013 | C8: 22.25 | E8: 12 | G8: 4.32 | H8: 393 | I8: 30 | O8: 0.55 | Q8: 3.14
A9: 安徽省 | B9: 2014 | C9: 52.31 | E9: 11.4 | F9: 6 | G9: 27.8 | H9: 264 | K9: 7.64 | O9: 6.81 | Q9: 33.23
A10: 安徽省 | B10: 2015 | C10: 49.37 | E10: 3 | F10: 1.2 | G10: 10.55 | H10: 718 | Q10: 50.25
A11: 安徽省 | B11: 2016 | C11: 44.55 | G11: 4.7 | H11: 296 | O11: 4.8 | Q11: 152.8
A12: 安徽省 | B12: 2017 | C12: 42.53 | E12: 19 | F12: 9.8 | G12: 17.4 | H12: 101.8 | I12: 0.2 | O12: 15.53 | Q12: 758.29
A13: 安徽省 | B13: 2018 | C13: 23.65 | E13: 36.72 | F13: 10.8 | G13: 2.15 | H13: 302.37 | K13: 1.2 | O13: 1.7 | Q13: 344.9
A14: 安徽省 | B14: 2019 | C14: 30.15 | E14: 10.85 | F14: 9.75 | G14: 19.2 | H14: 100 | O14: 5.58 | P14: 30 | Q14: 137.28
A15: 安徽省 | B15: 2020 | C15: 133.89 | E15: 14 | F15: 10.15 | G15: 28.73 | H15: 6 | I15: 1.8 | O15: 15.89 | P15: 120 | Q15: 115.85
A16: 安徽省 | B16: 2021 | C16: 99.7 | E16: 7.2 | F16: 19.28 | G16: 27.66 | H16: 19.8 | O16: 4.23 | P16: 30 | Q16: 337.2
A17: 北京市 | B17: 2008 | H17: 16 | J17: 129 | O17: 0
A18: 北京市 | B18: 2009 | O18: 0
A19: 北京市 | B19: 2010 | C19: 8.55 | H19: 0 | O19: 0
A20: 北京市 | B20: 2011 | J20: 92.34 | O20: 0
A21: 北京市 | B21: 2012
A22: 北京市 | B22: 2013 | J22: 83.8
A23: 北京市 | B23: 2014 | J23: 378.7
A24: 北京市 | B24: 2015 | J24: 95 | Q24: 4.57
A25: 北京市 | B25: 2016 | C25: 7.2 | G25: 4.75 | J25: 1.33 | Q25: 18.3
A26: 北京市 | B26: 2017 | C26: 0.25 | F26: 6.5 | J26: 99.8 | Q26: 14.78
A27: 北京市 | B27: 2018 | F27: 7 | J27: 34.1 | Q27: 15.05
A28: 北京市 | B28: 2019 | F28: 10.5 | J28: 15.5 | Q28: 11.26
A29: 北京市 | B29: 2020 | C29: 4.97 | F29: 2 | J29: 6.7 | Q29: 10.56
A30: 北京市 | B30: 2021 | C30: 4.95 | L30: 0.62 | Q30: 18.52
A31: 福建省 | B31: 2008 | C31: 15 | H31: 246 | J31: 70 | O31: 41
A32: 福建省 | B32: 2009 | C32: 6.95 | H32: 161 | J32: 105 | O32: 0
A33: 福建省 | B33: 2010 | C33: 13.4 | H33: 227 | J33: 105 | O33: 3
A34: 福建省 | B34: 2011 | C34: 15.4 | H34: 127 | O34: 0
A35: 福建省 | B35: 2012 | C35: 9.78 | H35: 127
A36: 福建省 | B36: 2013 | C36: 12.8 | D36: 108.9 | O36: 14 | P36: 120
A37: 福建省 | B37: 2014 | C37: 10.25 | D37: 217.8 | E37: 1.5 | Q37: 3
A38: 福建省 | B38: 2015 | C38: 19.55 | D38: 217.8 | F38: 1.2 | G38: 10.1 | H38: 200 | O38: 22.15 | Q38: 3
A39: 福建省 | B39: 2016 | C39: 62.15 | D39: 217.8 | F39: 0.6 | G39: 31.9 | O39: 5.86 | Q39: 19.55
A40: 福建省 | B40: 2017 | C40: 69.09 | D40: 108.9 | F40: 8.7 | G40: 8.2 | H40: 205.21 | J40: 3.18 | O40: 41.48 | Q40: 79.27
...

Sheet 06-23Closure
B1: 水电 | C1: 水电 | D1: 水电 | E1: 火电 | F1: 火电 | G1: 火电 | H1: 火电 | I1: 火电 | J1: 火电 | K1: 火电 | L1: 火电 | M1: 火电 | N1: 火电 | O1: 火电 | P1: 火电 | Q1: 火电 | R1: 火电 | S1: 火电 | T1: 火电 | U1: 火电 | V1: 火电
B2: 2006 | C2: 2007 | D2: 2008 | E2: 2006 | F2: 2007 | G2: 2008 | H2: 2009 | I2: 2010 | J2: 2011 | K2: 2012 | L2: 2013 | M2: 2014 | N2: 2015 | O2: 2016 | P2: 2017 | Q2: 2018 | R2: 2019 | S2: 2020 | T2: 2021 | U2: 2022 | V2: 2023
A3: 全国 | B3: 73.8 | C3: 292.1665 | D3: 42.047 | E3: 367.8 | F3: 2043.9088 | G3: 1850.5049 | H3: 1812.793 | I3: 1305 | J3: 954.5 | K3: 615.8 | L3: =SUM(L4:L34) -> 803.3 | M3: =SUM(M4:M34) -> 908.7 | N3: =SUM(N4:N34) -> 1090.8 | O3: =SUM(O4:O34) -> 573 | P3: =SUM(P4:P34) -> 931 | Q3: =SUM(Q4:Q34) -> 1198 | R3: =SUM(R4:R34) -> 1026.2 | S3: =SUM(S4:S34) -> 1469.3 | T3: =SUM(T4:T34) -> 499.3 | U3: 704 | V3: 727
A4: 北京市 | B4: 0.1 | F4: 20.6 | G4: 38.04 | H4: 24.67 | I4: 0.3 | J4: 0.9 | L4: 24.2 | M4: 23.8 | N4: 102.2
A5: 天津市 | G5: 2.5 | H5: 15 | I5: 15 | J5: 20 | N5: 88.5 | O5: 89 | P5: 89 | Q5: 86 | R5: 1 | S5: 0.3 | T5: 5 | U5: 26 | V5: 77
A6: 河北省 | B6: 0.2 | C6: 0.42 | E6: 11.7 | F6: 101.475 | G6: 151.3 | H6: 63.57 | I6: 61 | J6: 3.3 | K6: 1.2 | L6: 55.3 | M6: 11.5 | N6: 106.7 | O6: 27 | P6: 51 | Q6: 69 | R6: 58 | S6: 44 | T6: 25 | U6: 51
A7: 山西省 | B7: 0.4 | D7: 0.941 | E7: 8.8 | F7: 129.45 | G7: 56.652 | H7: 103.175 | I7: 57 | J7: 103.3 | K7: 78.4 | L7: 24.6 | M7: 57.4 | N7: 65 | O7: 3 | P7: 43 | Q7: 60 | R7: 216 | S7: 174 | T7: 19 | U7: 70 | V7: 139
A8: 内蒙古自治区 | E8: 10 | F8: 70.45 | G8: 15.25 | H8: 28.35 | I8: 53 | J8: 41.5 | K8: 11.6 | L8: 0.8 | M8: 22.1 | N8: 5.4 | O8: 18 | P8: 14 | Q8: 4 | R8: 4 | S8: 9 | T8: 8 | U8: 21
A9: 辽宁省 | B9: 0.3 | E9: 0.9 | F9: 58.2 | G9: 57.1684 | H9: 66.491 | I9: 91 | J9: 43.9 | K9: 67.2 | L9: 61.2 | M9: 15.6 | N9: 10.6 | P9: 15 | Q9: 24 | T9: 15 | U9: 20
A10: 吉林省 | E10: 0.8 | F10: 69 | H10: 45.2 | I10: 1 | J10: 3.6 | L10: 55 | M10: 13 | N10: 1.8 | O10: 20 | R10: 60 | T10: 26 | U10: 1 | V10: 4
A11: 黑龙江省 | C11: 4.95 | E11: 28.6 | F11: 34.9 | G11: 11.4 | H11: 50.9 | I11: 62 | J11: 49.7 | K11: 5.9 | L11: 2.3 | M11: 4.5 | N11: 0.9 | O11: 11 | P11: 31 | Q11: 29 | R11: 21 | S11: 10 | T11: 25 | U11: 8 | V11: 3
A12: 上海市 | F12: 42.55 | G12: 27.5 | H12: 34 | I12: 75 | J12: 27.5 | K12: 0.4 | L12: 0.9 | M12: 0.2 | N12: 0.2 | O12: 5 | R12: 5 | U12: 10 | V12: 65
A13: 江苏省 | E13: 0.6 | F13: 113.95 | G13: 456.996 | H13: 108.85 | I13: 58 | J13: 84.9 | K13: 130.3 | L13: 134 | M13: 51.2 | N13: 76.3 | O13: 30 | P13: 137 | Q13: 58 | R13: 58 | S13: 25 | U13: 17
A14: 浙江省 | B14: 5.9 | C14: 4 | D14: 4.8704 | E14: 115.7 | F14: 39.956 | G14: 232.0613 | H14: 89.58 | I14: 159 | J14: 65.7 | K14: 28.7 | L14: 43.9 | M14: 110.3 | N14: 103.8 | O14: 32 | P14: 18 | Q14: 60 | R14: 66 | S14: 141 | T14: 76 | U14: 7 | V14: 4
A15: 安徽省 | C15: 0.5 | D15: 1.753 | E15: 2.7 | F15: 230.1 | G15: 49.8 | H15: 7.6 | I15: 30 | J15: 1.2 | K15: 19.8 | L15: 33 | M15: 69 | N15: 7 | O15: 8 | P15: 46 | Q15: 38 | R15: 12 | S15: 67 | T15: 27
A16: 福建省 | B16: 1.3 | C16: 8.4051 | E16: 0.8 | F16: 43.655 | G16: 40.2168 | H16: 2.7 | I16: 16 | J16: 0.8 | K16: 24.9 | L16: 1.9 | M16: 30.6 | N16: 6.4 | O16: 6 | P16: 54 | Q16: 2 | R16: 0.2 | S16: 2 | T16: 15 | U16: 79 | V16: 1
A17: 江西省 | B17: 26.1 | C17: 7.2112 | D17: 7.6575 | E17: 0.5 | F17: 11.95 | G17: 65.5 | H17: 39.1 | I17: 3 | J17: 66.7 | K17: 36.2 | L17: 37 | M17: 21.1 | N17: 12.3 | P17: 2 | R17: 2 | S17: 31 | T17: 7 | U17: 49 | V17: 45
A18: 山东省 | B18: 0.3 | E18: 33.5 | F18: 178.22 | G18: 97 | H18: 151.5 | I18: 115 | J18: 122.9 | K18: 42.4 | L18: 50.4 | M18: 93 | N18: 146.5 | O18: 94 | P18: 89 | Q18: 87 | R18: 127 | S18: 306 | T18: 110 | U18: 97 | V18: 183
A19: 河南省 | E19: 10.2 | F19: 283.982 | G19: 63.344 | H19: 385.35 | I19: 123 | J19: 194.4 | K19: 7.4 | L19: 11.8 | M19: 128.6 | N19: 142.5 | P19: 114 | Q19: 282 | R19: 169 | S19: 243 | T19: 46 | U19: 43 | V19: 4
A20: 湖北省 | C20: 0.16 | D20: 1.5185 | E20: 23.6 | F20: 43.4 | G20: 21.5 | H20: 24.9 | I20: 22 | J20: 5.6 | K20: 0.9 | L20: 92 | M20: 3.4 | N20: 8.3 | O20: 2 | P20: 26 | Q20: 7 | R20: 5 | S20: 224 | T20: 2 | U20: 2 | V20: 8
A21: 湖南省 | B21: 14.8 | C21: 27.4515 | D21: 2.993 | E21: 4.1 | F21: 50.025 | G21: 41.35 | H21: 22.35 | I21: 14 | J21: 8.2 | K21: 5.2 | L21: 17 | M21: 9.2 | N21: 16.9 | O21: 4 | P21: 74 | Q21: 10 | R21: 11 | S21: 2 | T21: 4 | U21: 1 | V21: 4
A22: 广东省 | B22: 9.7 | C22: 6.5291 | D22: 8.6506 | E22: 39.6 | F22: 284.3583 | G22: 234.8384 | H22: 333.757 | I22: 71 | J22: 26.9 | K22: 22.3 | L22: 64.5 | N22: 1.2 | P22: 53 | Q22: 97 | R22: 115 | S22: 40 | T22: 15 | U22: 10
A23: 广西壮族自治区 | B23: 3.7 | C23: 1.4152 | D23: 9.3373 | E23: 3.2 | F23: 55.837 | G23: 2.838 | H23: 0.8 | I23: 67 | J23: 4.5 | K23: 10.7 | L23: 5.7 | M23: 1.8 | N23: 0.7 | O23: 31 | P23: 10 | Q23: 57 | R23: 6 | S23: 5 | T23: 5 | U23: 22 | V23: 12
A24: 海南省 | I24: 14 | L24: 13.8 | S24: 28 | U24: 12
A25: 重庆市 | B25: 2.1 | C25: 4.45 | E25: 17.7 | F25: 15.26 | G25: 1.85 | H25: 2.4 | I25: 6 | J25: 14.4 | L25: 5.8 | M25: 26.5 | N25: 45.5 | O25: 9 | P25: 2 | Q25: 14 | R25: 1 | S25: 58 | T25: 7 | U25: 1 | V25: 4
A26: 四川省 | B26: 8.5 | C26: 225.3699 | D26: 2.5325 | E26: 52.5 | F26: 71.8905 | G26: 36.75 | H26: 57.65 | J26: 48 | K26: 54.2 | L26: 39.2 | M26: 60.4 | N26: 2.4 | O26: 40 | P26: 1 | Q26: 73 | R26: 30 | S26: 2 | T26: 8 | U26: 2
A27: 贵州省 | E27: 2.4 | F27: 23 | G27: 0 | H27: 75 | I27: 40 | K27: 40 | M27: 60 | V27: 54
A28: 云南省 | B28: 0.5 | C28: 1.1695 | D28: 1.8032 | E28: 0.2 | F28: 10.3 | G28: 80.75 | I28: 10 | K28: 17.8 | L28: 4.2 | M28: 0.1 | N28: 5.6 | T28: 0.3 | V28: 120
A29: 西藏自治区 | G29: 0 | I29: 1 | J29: 0.2 | O29: 2 | P29: 1
A30: 陕西省 | C30: 0.135 | F30: 37.6 | G30: 33.3 | H30: 44.9 | I30: 41 | L30: 22 | M30: 0.2 | N30: 15.6 | P30: 58 | Q30: 13 | R30: 1 | S30: 2 | T30: 28 | U30: 6
A31: 甘肃省 | F31: 13.8 | G31: 24.7 | H31: 10 | I31: 30 | R31: 34 | T31: 6
A32: 青海省 | H32: 5 | N32: 25
A33: 宁夏回族自治区 | F33: 10 | H33: 10 | I33: 44 | N33: 11.6 | Q33: 18 | R33: 18 | S33: 27 | U33: 141
A34: 新疆维吾尔自治区 | G34: 7.9 | H34: 10 | I34: 26 | J34: 16.7 | K34: 10.6 | L34: 2.8 | M34: 95.2 | N34: 81.9 | O34: 142 | P34: 3 | Q34: 110 | R34: 6 | S34: 29 | T34: 20 | U34: 8
A36: Source:
A37: 6地方淘汰超30台煤电机组，汇总名单来了！-北极星火力发电网 (bjx.com.cn)
A38: 山东省能源局 通知公告 关于山东省2022年淘汰关停燃煤机组的公示 (shandong.gov.cn)
A39: 山东省公示2023年已淘汰关停燃煤机组名单-北极星电力新闻网 (bjx.com.cn)

Sheet Solar10-12
A1: 2010年主要全国太阳能电站生产情况 | E1: 2011年全国主要太阳能电站生产情况 | I1: 2012年全国主要太阳能电站生产情况
A2: 名称 | B2: 装机容量 (千瓦) | C2: 发电量 (万千瓦时) | E2: 名称 | F2: 装机容量 (千瓦) | G2: 发电量 (万千瓦时) | I2: 名称 | J2: 装机容量 (千瓦) | K2: 发电量 (万千瓦时) | O2: 2010装机容量（千瓦） | P2: 2011装机容量（千瓦） | Q2: 2012装机容量（千瓦）
A3: 合计 | B3: 205018 | C3: 10010 | E3: 全国 | F3: 2123228 | G3: 60492 | I3: 全国 | J3: 3287794 | K3: 348254 | M3: 全国 | N3: 全国 | O3: =SUM(O4:O20) -> 205018 | P3: =SUM(P4:P20) -> 2123228 | Q3: =SUM(Q4:Q20) -> 3287794 | T3: 甘肃 | U3: 475
A4: 上海市 | E4: 山西 | I4: 山西 | M4: 山西 | N4: =VLOOKUP("*"&M4&"*",'Solar Station Addition'!$A$3:$A$34,1,FALSE) -> 山西省 | P4: =SUM(F5:F6) -> 15000 | Q4: =J6+J5 -> 15000 | T4: 青海 | U4: 2140
A5: 中国节能投资公司(虹桥客站) | B5: 6688 | C5: 327 | E5: 右卫光伏发电站 | F5: 10000 | G5: 36 | I5: 平鲁阻虎发电站 | J5: 5000 | K5: 666 | M5: 内蒙古 | N5: =VLOOKUP("*"&M5&"*",'Solar Station Addition'!$A$3:$A$34,1,FALSE) -> 内蒙古自治区 | P5: =SUM(F8:F11) -> 87000 | Q5: =SUM(J8:J13) -> 196000 | T5: 新疆 | U5: 250
A6: 江苏省 | E6: 阻虎发电站 | F6: 5000 | G6: 22 | I6: 右卫光伏发电站 | J6: 10000 | K6: 1465 | M6: 辽宁 | N6: =VLOOKUP("*"&M6&"*",'Solar Station Addition'!$A$3:$A$34,1,FALSE) -> 辽宁省 | Q6: =J15 -> 10000 | T6: 宁夏 | U6: 431
A7: 徐州光伏协鑫发电公司 | B7: 20000 | C7: 2173 | E7: 内蒙古 | I7: 内蒙古 | M7: 上海 | N7: =VLOOKUP("*"&M7&"*",'Solar Station Addition'!$A$3:$A$34,1,FALSE) -> 上海市 | O7: =B5 -> 6688 | P7: =F13 -> 6688 | Q7: =J17 -> 6688 | T7: 内蒙古 | U7: 272
A8: 中节能太阳能射阳发电有限公司 | B8: 20000 | C8: 13 | E8: 国电四子王旗光伏发电有限公司 | F8: 40000 | G8: 27 | I8: 后旗盾安光伏电站 | J8: 10000 | K8: 13 | M8: 江苏 | N8: =VLOOKUP("*"&M8&"*",'Solar Station Addition'!$A$3:$A$34,1,FALSE) -> 江苏省 | O8: =SUM(B7:B10) -> 70000 | P8: =SUM(F15:F32) -> 331010 | Q8: =SUM(J19:J37) -> 361010 | T8: 江苏 | U8: 260
A9: 中电投大丰光伏发电有限公司 | B9: 20000 | E9: 锡盟华电二连光伏发电厂 | F9: 22000 | G9: 66 | I9: 磴口光伏电站 | J9: 20000 | K9: 18 | M9: 安徽 | N9: =VLOOKUP("*"&M9&"*",'Solar Station Addition'!$A$3:$A$34,1,FALSE) -> 安徽省 | Q9: =J39 -> 14600 | T9: 新疆建设兵团 | U9: 0
A10: 华电尚德东台太阳能发电有限公司 | B10: 10000 | C10: 39 | E10: 国电光伏 | F10: 15000 | G10: 665 | I10: 国电四子王旗光伏发电有限公司 | J10: 99000 | K10: 7081 | M10: 山东 | N10: =VLOOKUP("*"&M10&"*",'Solar Station Addition'!$A$3:$A$34,1,FALSE) -> 山东省 | O10: =B12 -> 18000 | P10: =SUM(F34:F36) -> 35000 | Q10: =SUM(J41:J46) -> 61500 | T10: 河北 | U10: 63
A11: 山东省 | E11: 中节节能光伏 | F11: 10000 | G11: 564 | I11: 锡盟华电二连光伏发电厂 | J11: 22000 | K11: 4002 | M11: 湖北 | N11: =VLOOKUP("*"&M11&"*",'Solar Station Addition'!$A$3:$A$34,1,FALSE) -> 湖北省 | Q11: =J48 -> 8966 | T11: 山西 | U11: 5
A12: 华翰十里营光伏电站 | B12: 18000 | C12: 307 | E12: 上海 | I12: 国电光伏电站 | J12: 35000 | K12: 2415 | M12: 广东 | N12: =VLOOKUP("*"&M12&"*",'Solar Station Addition'!$A$3:$A$34,1,FALSE) -> 广东省 | P12: =F38 -> 8100 | Q12: =J50 -> 8100 | T12: 陕西 | U12: 60
A13: 云南省 | E13: 中国节能投资公司(虹桥客站) | F13: 6688 | G13: 656 | I13: 中节节能光伏电站 | J13: 10000 | K13: 1545 | M13: 海南 | N13: =VLOOKUP("*"&M13&"*",'Solar Station Addition'!$A$3:$A$34,1,FALSE) -> 海南省 | P13: =F40 -> 20000 | Q13: =J52 -> 20000 | T13: 云南 | U13: 20
A14: 云南电投新能源开发有限公司石林光伏发电站 | B14: 10000 | C14: 381 | E14: 江苏 | I14: 辽宁 | M14: 云南 | N14: =VLOOKUP("*"&M14&"*",'Solar Station Addition'!$A$3:$A$34,1,FALSE) -> 云南省 | O14: =B14+B15 -> 20000 | P14: =F42+F43 -> 20000 | Q14: =SUM(J54:J56) -> 30000 | T14: 山东 | U14: 79
A15: 云南华能澜沧江水电有限公司石林光伏发电示范项目 | B15: 10000 | C15: 840 | E15: 徐州协鑫光伏电力有限公司 | F15: 20000 | G15: 2180 | I15: 锦州阳光能源10兆瓦地面光伏发电站 | J15: 10000 | K15: 1 | M15: 西藏 | N15: =VLOOKUP("*"&M15&"*",'Solar Station Addition'!$A$3:$A$34,1,FALSE) -> 西藏自治区 | P15: =SUM(F45:F48) -> 40100 | Q15: =SUM(J58:J64) -> 80100 | T15: 西藏 | U15: 100
A16: 宁夏区 | E16: 中节能太阳能射阳发电有限公司 | F16: 20000 | G16: 2273 | I16: 上海 | M16: 陕西 | N16: =VLOOKUP("*"&M16&"*",'Solar Station Addition'!$A$3:$A$34,1,FALSE) -> 陕西省 | P16: =F50 -> 20000 | Q16: =J66 -> 20000 | T16: 海南 | U16: 10
A17: 平罗光伏电站国电阿特斯一期 | B17: 10000 | E17: 中电投大丰光伏发电有限公司 | F17: 20000 | G17: 1953 | I17: 中国节能投资公司虹桥客站光伏电站 | J17: 6688 | K17: 671 | M17: 甘肃 | N17: =VLOOKUP("*"&M17&"*",'Solar Station Addition'!$A$3:$A$34,1,FALSE) -> 甘肃省 | P17: =SUM(F52:F61) -> 111000 | Q17: =SUM(J68:J92) -> 382000 | T17: 辽宁 | U17: 10
A18: 石嘴山光伏电站正泰一期 | B18: 10000 | E18: 华电尚德东台太阳能发电有限公司 | F18: 30000 | G18: 1196 | I18: 江苏 | M18: 青海 | N18: =VLOOKUP("*"&M18&"*",'Solar Station Addition'!$A$3:$A$34,1,FALSE) -> 青海省 | P18: =SUM(F63:F96) -> 938000 | Q18: =SUM(J94:J141) -> 1363000 | T18: 四川 | U18: 0
A19: 宁夏发电集团太阳能试验电站 | B19: 330 | C19: 48 | E19: 中电投洪泽光伏发电有限公司 | F19: 20000 | G19: 12 | I19: 徐州协鑫光伏电力有限公司 | J19: 20000 | K19: 2134 | M19: 宁夏 | N19: =VLOOKUP("*"&M19&"*",'Solar Station Addition'!$A$3:$A$34,1,FALSE) -> 宁夏回族自治区 | O19: =SUM(B17:B26) -> 90330 | P19: =SUM(F98:F127) -> 491330 | Q19: =SUM(J143:J175) -> 530830 | T19: 江西 | U19: 5
A20: 宁夏发电集团太阳山光伏发电厂 | B20: 10000 | C20: 1644 | E20: 大唐新能源沭阳光伏电厂 | F20: 8900 | G20: 1 | I20: 中节能太阳能射阳发电有限公司 | J20: 20000 | K20: 2367 | M20: 新疆 | N20: =VLOOKUP("*"&M20&"*",'Solar Station Addition'!$A$3:$A$34,1,FALSE) -> 新疆维吾尔自治区 | Q20: =SUM(J177:J185) -> 180000 | T20: 上海 | U20: 16
A21: 华电宁夏宁东光伏电站 | B21: 10000 | C21: 1130 | E21: 南站光伏发电有限公司 | F21: 6980 | I21: 中电投大丰光伏发电有限公司 | J21: 20000 | K21: 2142 | T21: 吉林 | U21: 0
A22: 宁夏电力投资集团太阳山光伏电站 | B22: 10000 | E22: 国信泗阳光伏发电厂(2期) | F22: 9800 | G22: 17 | I22: 华电尚德东台太阳能发电有限公司 | J22: 30000 | K22: 3533 | T22: 黑龙江 | U22: 0
A23: 中节能太阳山光伏电站 | B23: 10000 | C23: 1629 | E23: 中电投建湖光伏发电有限公司 | F23: 20000 | G23: 11 | I23: 中电投洪泽光伏发电有限公司 | J23: 20000 | K23: 2453 | T23: 河南 | U23: 0
A24: 中节能石嘴山光伏电站 | B24: 10000 | C24: 1479 | E24: 宿迁光大洋河光伏发电厂(2期) | F24: 6430 | G24: 7 | I24: 大唐新能源沭阳光伏电厂 | J24: 8900 | K24: 897 | T24: 安徽 | U24: 2
A25: 青铜峡光伏电站大唐国际一期 | B25: 10000 | E25: 宿迁协合新能源电厂 | F25: 9300 | G25: 4 | I25: 南站光伏发电有限公司 | J25: 6980
A26: 中卫光伏电站国电一期 | B26: 10000 | E26: 中电投常熟光伏发电有限公司 | F26: 9800 | I26: 国信泗阳光伏发电厂（2期） | J26: 9800 | K26: 1224
E27: 江苏吉阳电力有限公司光伏电站 | F27: 30000 | G27: 4 | I27: 中电投建湖光伏发电有限公司 | J27: 20000 | K27: 2465
E28: 丰县晖泽光伏能源有限公司 | F28: 20000 | G28: 1 | I28: 宿迁光大洋河光伏发电厂（2期） | J28: 6430 | K28: 509
E29: 国华(江苏)风电有限公司光伏电站 | F29: 20000 | G29: 21 | I29: 宿迁协合新能源电厂 | J29: 9300 | K29: 917
E30: 中节能东台太阳能发电有限公司 | F30: 60000 | G30: 4 | I30: 中电投常熟光伏发电有限公司 | J30: 9800 | K30: 1042
E31: 江苏金宇新能源科技有限公司 | F31: 10000 | I31: 江苏吉阳电力有限公司光伏电站 | J31: 30000 | K31: 3090
E32: 光大光伏能源(镇江)有限公司(二期) | F32: 9800 | G32: 11 | I32: 丰县阵泽光伏能源有限公司 | J32: 20000 | K32: 2304
E33: 山东 | I33: 国华（江苏）风电有限公司光伏电站 | J33: 20000 | K33: 2276
E34: 东营泰和光伏太阳能有限公司 | F34: 7000 | G34: 807 | I34: 中节能东台太阳能发电有限公司 | J34: 60000 | K34: 7625
E35: 华翰十里营光伏电站 | F35: 18000 | G35: 2037 | I35: 江苏金宇新能源科技有限公司 | J35: 10000
E36: 中节能太阳能发电(德州) | F36: 10000 | G36: 1265 | I36: 光大光伏能源（镇江）有限公司（二期） | J36: 9800 | K36: 883
E37: 广东 | I37: 汉能却州市太阳能发电有限公司 | J37: 30000 | K37: 22
E38: 广东国华太阳能光伏发电站 | F38: 8100 | G38: 143 | I38: 安徽
E39: 海南 | I39: “金太阳”光伏电站 | J39: 14600 | K39: 179
E40: 临高光伏电厂 | F40: 20000 | G40: 352 | I40: 山东
...

Sheet Solar12-13
A1: 各省（区、市）并网光伏电站统计表 | M1: 各省（区、市）分布式光伏发电统计表
A2: 序号 | B2: 省份 | C2: 2012年底累计 | F2: 2013年新增 | I2: 2013年底累计 | M2: 序号 | N2: 省 （区、市） | O2: 2012年底累计（MWp) | P2: 2013年新增 | R2: 2013年底累计
C3: 并网容量（MWp) | D3: 电站个数 | E3: 市场份额 | F3: 并网容量（MWp) | G3: 电站个数 | H3: 市场份额 | I3: 并网容量（MWp) | J3: 电站个数 | K3: 市场份额 | P3: 并网容量（MWp) | Q3: 市场份额 | R3: 并网容量（MWp) | S3: 市场份额
A4: 1 | B4: 甘肃 | C4: 475 | D4: 46 | E4: 0.113 | F4: 3842 | G4: 93 | H4: 0.317 | I4: 4317 | J4: 139 | K4: 0.265 | M4: 1 | N4: 浙江 | O4: 260 | P4: 165 | Q4: 0.206 | R4: 425 | S4: 0.137
A5: 2 | B5: 青海 | C5: 2140 | D5: 99 | E5: 0.51 | F5: 963 | G5: 20 | H5: 0.08 | I5: 3103 | J5: 119 | K5: 0.19 | M5: 2 | N5: 湖南 | O5: 234 | P5: 66 | Q5: 0.082 | R5: 300 | S5: 0.097
A6: 3 | B6: 新疆 | C6: 250 | D6: 11 | E6: 0.06 | F6: 2320 | G6: 110 | H6: 0.191 | I6: 2570 | J6: 121 | K6: 0.158 | M6: 3 | N6: 广东 | O6: 185 | P6: 115 | Q6: 0.144 | R6: 300 | S6: 0.097
A7: 4 | B7: 宁夏 | C7: 431 | D7: 31 | E7: 0.103 | F7: 1183 | G7: 47 | H7: 0.098 | I7: 1614 | J7: 78 | K7: 0.099 | M7: 4 | N7: 江苏 | O7: 218 | P7: 37 | Q7: 0.046 | R7: 255 | S7: 0.082
A8: 5 | B8: 内蒙古 | C8: 272 | D8: 18 | E8: 0.065 | F8: 1133 | G8: 38 | H8: 0.094 | I8: 1405 | J8: 56 | K8: 0.086 | M8: 5 | N8: 山东 | O8: 163 | P8: 42 | Q8: 0.052 | R8: 205 | S8: 0.066
A9: 6 | B9: 江苏 | C9: 260 | D9: 21 | E9: 0.062 | F9: 789 | G9: 90 | H9: 0.065 | I9: 1049 | J9: 111 | K9: 0.064 | M9: 6 | N9: 上海 | O9: 140 | P9: 49 | Q9: 0.061 | R9: 189 | S9: 0.061
A10: 7 | B10: 新疆建设兵团 | C10: 0 | D10: 0 | E10: 0 | F10: 641 | G10: 24 | H10: 0.053 | I10: 641 | J10: 27 | K10: 0.039 | M10: 7 | N10: 河北 | O10: 112 | P10: 74 | Q10: 0.092 | R10: 186 | S10: 0.06
A11: 8 | B11: 河北 | C11: 63 | D11: 3 | E11: 0.015 | F11: 398 | G11: 11 | H11: 0.033 | I11: 461 | J11: 14 | K11: 0.028 | M11: 8 | N11: 江西 | O11: 118 | P11: 40 | Q11: 0.05 | R11: 158 | S11: 0.051
A12: 9 | B12: 山西 | C12: 5 | D12: 2 | E12: 0.001 | F12: 270 | G12: 8 | H12: 0.022 | I12: 275 | J12: 10 | K12: 0.017 | M12: 9 | N12: 内蒙古 | O12: 107 | P12: 46 | Q12: 0.058 | R12: 153 | S12: 0.049
A13: 10 | B13: 陕西 | C13: 60 | D13: 5 | E13: 0.014 | F13: 210 | G13: 5 | H13: 0.017 | I13: 270 | J13: 10 | K13: 0.017 | M13: 10 | N13: 安徽 | O13: 124 | P13: 26 | Q13: 0.032 | R13: 150 | S13: 0.048
A14: 11 | B14: 云南 | C14: 20 | D14: 3 | E14: 0.005 | F14: 160 | G14: 6 | H14: 0.013 | I14: 180 | J14: 9 | K14: 0.011 | M14: 11 | N14: 湖北 | O14: 65 | P14: 35 | Q14: 0.043 | R14: 100 | S14: 0.032
A15: 12 | B15: 山东 | C15: 79 | D15: 8 | E15: 0.019 | F15: 33 | G15: 5 | H15: 0.003 | I15: 112 | J15: 13 | K15: 0.007 | M15: 12 | N15: 陕西 | O15: 61 | P15: 29 | Q15: 0.036 | R15: 90 | S15: 0.029
... A25: 22 | B25: 安徽 | C25: 2 | D25: 1 | E25: 0.001 | F25: 0 | G25: 0 | H25: 0 | I25: 2 | J25: 1 | K25: 0 | M25: 22 | N25: 黑龙江 | O25: 27 | P25: 0.1 | Q25: 0 | R25: 27 | S25: 0.009
A26: 合计 | C26: 4198 | D26: 273 | E26: 1 | F26: 12119 | G26: 468 | H26: 1 | I26: 16317 | J26: 741 | K26: 1 | M26: 23 | N26: 云南 | O26: 11 | P26: 3 | Q26: 0.003 | R26: 14 | S26: 0.004
M27: 24 | N27: 甘肃 | O27: 11 | P27: 0.3 | Q27: 0 | R27: 11 | S27: 0.004
A28: Source | B28: 2013年光伏发电统计数据---国家能源局 (nea.gov.cn) | M28: 25 | N28: 四川 | O28: 5 | P28: 4 | Q28: 0.005 | R28: 9 | S28: 0.003
M29: 26 | N29: 西藏 | O29: 0 | P29: 1 | Q29: 0.001 | R29: 1 | S29: 0
C30: =C26-SUM(C4:C25) -> 0 | D30: =D26-SUM(D4:D25) -> 3 | E30: =E26-SUM(E4:E25) -> -0.001 | F30: =F26-SUM(F4:F25) -> 0.7 | G30: =G26-SUM(G4:G25) -> 0 | H30: =H26-SUM(H4:H25) -> -0.002 | I30: =I26-SUM(I4:I25) -> 1 | J30: =J26-SUM(J4:J25) -> 0 | K30: =K26-SUM(K4:K25) -> -0.002 | M30: 27 | N30: 青海 | O30: 0 | P30: 0.6 | Q30: 0.001 | R30: 0.6 | S30: 0
M31: 28 | N31: 重庆 | O31: 0 | P31: 0.02 | Q31: 0 | R31: 0.02 | S31: 0
M32: 合计 | O32: 2300 | P32: 801 | Q32: 1 | R32: 3101 | S32: 1
M33: 注：西藏、吉林等部分省份统计不完全。
O34: =O32-SUM(O4:O31) -> 0 | P34: =P32-SUM(P4:P31) -> -1.62 | Q34: =Q32-SUM(Q4:Q31) -> 0.001 | R34: =R32-SUM(R4:R31) -> -0.62 | S34: =S32-SUM(S4:S31) -> 0

Sheet Solar14-16
A1: 2014年光伏发电统计信息 | G1: 2015年光伏发电统计信息 | M1: 2016年光伏发电统计信息
A2: 省（区、市） | B2: 累计装机容量 | D2: 新增装机容量 | G2: 省（区、市） | H2: 累计装机容量 | J2: 新增装机容量 | M2: 省（区、市） | N2: 累计装机容量 | P2: 新增装机容量
C3: 其中：分布式光伏 | E3: 其中：分布式光伏 | I3: 其中：光伏电站 | K3: 其中：光伏电站 | O3: 其中：光伏电站 | Q3: 其中：光伏电站 | T3: 2012 | U3: 2013 | V3: 2013 | W3: 2014 | X3: 2014 | Y3: 2015 | Z3: 2015 | AA3: 2016
A4: 总计 | B4: 2805 | C4: 467 | D4: 1060 | E4: 205 | G4: 总计 | H4: 4318 | I4: 3712 | J4: 1513 | K4: 1374 | M4: 总计 | N4: 7742 | O4: 6710 | P4: 3454 | Q4: 3031 | S4: 全国 | T4: =SUM(T5:T35) -> 419.8 | U4: =SUM(U5:U35) -> 1631.6 | V4: =SUM(V5:V35) -> 1483 | W4: =SUM(W5:W35) -> 2339 | X4: =SUM(X5:X35) -> 2338 | Y4: =SUM(Y5:Y35) -> 3713 | Z4: =SUM(Z5:Z35) -> 3682 | AA4: =SUM(AA5:AA35) -> 6712 | AC4: =V4-U4 -> -148.6 | AD4: =W4-X4 -> 1 | AE4: =Y4-Z4 -> 31
A5: 北京 | B5: 14 | C5: 14 | D5: 5 | E5: 5 | G5: 北京 | H5: 16 | I5: 2 | J5: 2 | K5: 2 | M5: 北京 | N5: 24 | O5: 5 | P5: 8 | Q5: 3 | S5: =VLOOKUP("*"&M5&"*",'Solar Station Addition'!$A$3:$A$34,1,FALSE) -> 北京市 | T5: =IFERROR(VLOOKUP($M5,'Solar12-13'!$B$4:$I$25,2,FALSE),0)/10 -> 0 | U5: =IFERROR(VLOOKUP($M5,'Solar12-13'!$B$4:$I$25,8,FALSE),0)/10 -> 0 | V5: =(B5-D5)-(C5-E5) -> 0 | W5: =B5-C5 -> 0 | X5: =I5-K5 -> 0 | Y5: =I5 -> 2 | Z5: =O5-Q5 -> 2 | AA5: =O5 -> 5 | AC5: =V5-U5 -> 0 | AD5: =W5-X5 -> 0 | AE5: =Y5-Z5 -> 0
A6: 天津 | B6: 10 | C6: 7 | D6: 8 | E6: 5 | G6: 天津 | H6: 12 | I6: 3 | J6: 3 | K6: 0 | M6: 天津 | N6: 60 | O6: 48 | P6: 47 | Q6: 44 | S6: =VLOOKUP("*"&M6&"*",'Solar Station Addition'!$A$3:$A$34,1,FALSE) -> 天津市 | T6: =IFERROR(VLOOKUP($M6,'Solar12-13'!$B$4:$I$25,2,FALSE),0)/10 -> 0 | U6: =IFERROR(VLOOKUP($M6,'Solar12-13'!$B$4:$I$25,8,FALSE),0)/10 -> 0 | V6: =(B6-D6)-(C6-E6) -> 0 | W6: =B6-C6 -> 3 | X6: =I6-K6 -> 3 | Y6: =I6 -> 3 | Z6: =O6-Q6 -> 4 | AA6: =O6 -> 48 | AC6: =V6-U6 -> 0 | AD6: =W6-X6 -> 0 | AE6: =Y6-Z6 -> -1
A7: 河北 | B7: 150 | C7: 27 | D7: 97 | E7: 8 | G7: 河北 | H7: 239 | I7: 212 | J7: 89 | K7: 89 | M7: 河北 | N7: 443 | O7: 404 | P7: 203 | Q7: 192 | S7: =VLOOKUP("*"&M7&"*",'Solar Station Addition'!$A$3:$A$34,1,FALSE) -> 河北省 | T7: =IFERROR(VLOOKUP($M7,'Solar12-13'!$B$4:$I$25,2,FALSE),0)/10 -> 6.3 | U7: =IFERROR(VLOOKUP($M7,'Solar12-13'!$B$4:$I$25,8,FALSE),0)/10 -> 46.1 | V7: =(B7-D7)-(C7-E7) -> 34 | W7: =B7-C7 -> 123 | X7: =I7-K7 -> 123 | Y7: =I7 -> 212 | Z7: =O7-Q7 -> 212 | AA7: =O7 -> 404 | AC7: =V7-U7 -> -12.1 | AD7: =W7-X7 -> 0 | AE7: =Y7-Z7 -> 0
A8: 山西 | B8: 44 | C8: 1 | D8: 23 | E8: 1 | G8: 山西 | H8: 113 | I8: 111 | J8: 69 | K8: 68 | M8: 山西 | N8: 297 | O8: 284 | P8: 183 | Q8: 172 | S8: =VLOOKUP("*"&M8&"*",'Solar Station Addition'!$A$3:$A$34,1,FALSE) -> 山西省 | T8: =IFERROR(VLOOKUP($M8,'Solar12-13'!$B$4:$I$25,2,FALSE),0)/10 -> 0.5 | U8: =IFERROR(VLOOKUP($M8,'Solar12-13'!$B$4:$I$25,8,FALSE),0)/10 -> 27.5 | V8: =(B8-D8)-(C8-E8) -> 21 | W8: =B8-C8 -> 43 | X8: =I8-K8 -> 43 | Y8: =I8 -> 111 | Z8: =O8-Q8 -> 112 | AA8: =O8 -> 284 | AC8: =V8-U8 -> -6.5 | AD8: =W8-X8 -> 0 | AE8: =Y8-Z8 -> -1
A9: 内蒙古 | B9: 302 | C9: 18 | D9: 164 | E9: 4 | G9: 内蒙古 | H9: 489 | I9: 471 | J9: 187 | K9: 187 | M9: 内蒙古 | N9: 637 | O9: 637 | P9: 148 | Q9: 166 | S9: =VLOOKUP("*"&M9&"*",'Solar Station Addition'!$A$3:$A$34,1,FALSE) -> 内蒙古自治区 | T9: =IFERROR(VLOOKUP($M9,'Solar12-13'!$B$4:$I$25,2,FALSE),0)/10 -> 27.2 | U9: =IFERROR(VLOOKUP($M9,'Solar12-13'!$B$4:$I$25,8,FALSE),0)/10 -> 140.5 | V9: =(B9-D9)-(C9-E9) -> 124 | W9: =B9-C9 -> 284 | X9: =I9-K9 -> 284 | Y9: =I9 -> 471 | Z9: =O9-Q9 -> 471 | AA9: =O9 -> 637 | AC9: =V9-U9 -> -16.5 | AD9: =W9-X9 -> 0 | AE9: =Y9-Z9 -> 0
A10: 辽宁 | B10: 10 | C10: 6 | D10: 5 | E10: 4 | G10: 辽宁 | H10: 16 | I10: 7 | J10: 6 | K10: 3 | M10: 辽宁 | N10: 52 | O10: 36 | P10: 36 | Q10: 29 | S10: =VLOOKUP("*"&M10&"*",'Solar Station Addition'!$A$3:$A$34,1,FALSE) -> 辽宁省 | T10: =IFERROR(VLOOKUP($M10,'Solar12-13'!$B$4:$I$25,2,FALSE),0)/10 -> 1 | U10: =IFERROR(VLOOKUP($M10,'Solar12-13'!$B$4:$I$25,8,FALSE),0)/10 -> 3 | V10: =(B10-D10)-(C10-E10) -> 3 | W10: =B10-C10 -> 4 | X10: =I10-K10 -> 4 | Y10: =I10 -> 7 | Z10: =O10-Q10 -> 7 | AA10: =O10 -> 36 | AC10: =V10-U10 -> 0 | AD10: =W10-X10 -> 0 | AE10: =Y10-Z10 -> 0
A11: 吉林 | B11: 6 | C11: 0 | D11: 5 | E11: 0 | G11: 吉林 | H11: 7 | I11: 6 | J11: 1 | M11: 吉林 | N11: 56 | O11: 51 | P11: 49 | Q11: 45 | S11: =VLOOKUP("*"&M11&"*",'Solar Station Addition'!$A$3:$A$34,1,FALSE) -> 吉林省 | T11: =IFERROR(VLOOKUP($M11,'Solar12-13'!$B$4:$I$25,2,FALSE),0)/10 -> 0 | U11: =IFERROR(VLOOKUP($M11,'Solar12-13'!$B$4:$I$25,8,FALSE),0)/10 -> 1 | V11: =(B11-D11)-(C11-E11) -> 1 | W11: =B11-C11 -> 6 | X11: =I11-K11 -> 6 | Y11: =I11 -> 6 | Z11: =O11-Q11 -> 6 | AA11: =O11 -> 51 | AC11: =V11-U11 -> 0 | AD11: =W11-X11 -> 0 | AE11: =Y11-Z11 -> 0
A12: 黑龙江 | B12: 1 | C12: 0 | D12: 0 | E12: 0 | G12: 黑龙江 | H12: 2 | I12: 1 | J12: 1 | M12: 黑龙江 | N12: 17 | O12: 12 | P12: 15 | Q12: 11 | S12: =VLOOKUP("*"&M12&"*",'Solar Station Addition'!$A$3:$A$34,1,FALSE) -> 黑龙江省 | T12: =IFERROR(VLOOKUP($M12,'Solar12-13'!$B$4:$I$25,2,FALSE),0)/10 -> 0 | U12: =IFERROR(VLOOKUP($M12,'Solar12-13'!$B$4:$I$25,8,FALSE),0)/10 -> 1 | V12: =(B12-D12)-(C12-E12) -> 1 | W12: =B12-C12 -> 1 | X12: =I12-K12 -> 1 | Y12: =I12 -> 1 | Z12: =O12-Q12 -> 1 | AA12: =O12 -> 12 | AC12: =V12-U12 -> 0 | AD12: =W12-X12 -> 0 | AE12: =Y12-Z12 -> 0
A13: 上海 | B13: 18 | C13: 16 | D13: 0 | E13: 0 | G13: 上海 | H13: 21 | I13: 2 | J13: 4 | M13: 上海 | N13: 35 | O13: 2 | P13: 14 | Q13: 0 | S13: =VLOOKUP("*"&M13&"*",'Solar Station Addition'!$A$3:$A$34,1,FALSE) -> 上海市 | T13: =IFERROR(VLOOKUP($M13,'Solar12-13'!$B$4:$I$25,2,FALSE),0)/10 -> 1.6 | U13: =IFERROR(VLOOKUP($M13,'Solar12-13'!$B$4:$I$25,8,FALSE),0)/10 -> 1.6 | V13: =(B13-D13)-(C13-E13) -> 2 | W13: =B13-C13 -> 2 | X13: =I13-K13 -> 2 | Y13: =I13 -> 2 | Z13: =O13-Q13 -> 2 | AA13: =O13 -> 2 | AC13: =V13-U13 -> 0.4 | AD13: =W13-X13 -> 0 | AE13: =Y13-Z13 -> 0
A14: 江苏 | B14: 257 | C14: 85 | D14: 152 | E14: 57 | G14: 江苏 | H14: 422 | I14: 304 | J14: 165 | K14: 132 | M14: 江苏 | N14: 546 | O14: 373 | P14: 123 | Q14: 70 | S14: =VLOOKUP("*"&M14&"*",'Solar Station Addition'!$A$3:$A$34,1,FALSE) -> 江苏省 | T14: =IFERROR(VLOOKUP($M14,'Solar12-13'!$B$4:$I$25,2,FALSE),0)/10 -> 26 | U14: =IFERROR(VLOOKUP($M14,'Solar12-13'!$B$4:$I$25,8,FALSE),0)/10 -> 104.9 | V14: =(B14-D14)-(C14-E14) -> 77 | W14: =B14-C14 -> 172 | X14: =I14-K14 -> 172 | Y14: =I14 -> 304 | Z14: =O14-Q14 -> 303 | AA14: =O14 -> 373 | AC14: =V14-U14 -> -27.9 | AD14: =W14-X14 -> 0 | AE14: =Y14-Z14 -> 1
